{
    size: [5, 7, 5],
    data: [
        {pos: [0, 0, 0], state: "minecraft:red_terracotta"},
        {pos: [0, 0, 1], state: "minecraft:red_terracotta"},
        {pos: [0, 0, 2], state: "minecraft:red_terracotta"},
        {pos: [0, 0, 3], state: "minecraft:red_terracotta"},
        {pos: [0, 0, 4], state: "minecraft:red_terracotta"},
        {pos: [1, 0, 0], state: "minecraft:red_terracotta"},
        {pos: [1, 0, 1], state: "minecraft:red_terracotta"},
        {pos: [1, 0, 2], state: "minecraft:red_terracotta"},
        {pos: [1, 0, 3], state: "minecraft:red_terracotta"},
        {pos: [1, 0, 4], state: "minecraft:red_terracotta"},
        {pos: [2, 0, 0], state: "minecraft:red_terracotta"},
        {pos: [2, 0, 1], state: "minecraft:red_terracotta"},
        {pos: [2, 0, 2], state: "minecraft:red_terracotta"},
        {pos: [2, 0, 3], state: "minecraft:red_terracotta"},
        {pos: [2, 0, 4], state: "minecraft:red_terracotta"},
        {pos: [3, 0, 1], state: "minecraft:red_terracotta"},
        {pos: [3, 0, 2], state: "minecraft:red_terracotta"},
        {pos: [3, 0, 3], state: "minecraft:red_terracotta"},
        {pos: [3, 0, 4], state: "minecraft:red_terracotta"},
        {pos: [4, 0, 2], state: "minecraft:red_terracotta"},
        {pos: [4, 0, 3], state: "minecraft:red_terracotta"},
        {pos: [4, 0, 4], state: "minecraft:red_terracotta"},
        {pos: [0, 1, 0], state: "minecraft:red_terracotta"},
        {pos: [0, 1, 1], state: "minecraft:sand"},
        {pos: [0, 1, 2], state: "minecraft:sand"},
        {pos: [0, 1, 3], state: "minecraft:yellow_terracotta"},
        {pos: [0, 1, 4], state: "minecraft:sand"},
        {pos: [1, 1, 0], state: "minecraft:red_terracotta"},
        {pos: [1, 1, 1], state: "minecraft:sand"},
        {pos: [1, 1, 2], state: "minecraft:sand"},
        {pos: [1, 1, 3], state: "minecraft:yellow_terracotta"},
        {pos: [1, 1, 4], state: "minecraft:sand"},
        {pos: [2, 1, 0], state: "minecraft:red_terracotta"},
        {pos: [2, 1, 1], state: "minecraft:sand"},
        {pos: [2, 1, 2], state: "minecraft:sand"},
        {pos: [2, 1, 3], state: "minecraft:sand"},
        {pos: [2, 1, 4], state: "minecraft:sand"},
        {pos: [3, 1, 1], state: "minecraft:red_terracotta"},
        {pos: [3, 1, 2], state: "minecraft:sand"},
        {pos: [3, 1, 3], state: "minecraft:sand"},
        {pos: [3, 1, 4], state: "minecraft:sand"},
        {pos: [4, 1, 2], state: "minecraft:red_terracotta"},
        {pos: [4, 1, 3], state: "minecraft:red_terracotta"},
        {pos: [4, 1, 4], state: "minecraft:red_terracotta"},
        {pos: [0, 2, 0], state: "minecraft:red_terracotta"},
        {pos: [0, 2, 1], state: "minecraft:sand"},
        {pos: [0, 2, 2], state: "minecraft:jigsaw{orientation:west_up}", nbt: {final_state: "minecraft:sand", id: "minecraft:jigsaw", joint: "rollable", name: "minecraft:room_connector", pool: "minecraft:trail_ruins/buildings/grouped", target: "minecraft:room_connector"}},
        {pos: [0, 2, 3], state: "minecraft:sand"},
        {pos: [0, 2, 4], state: "minecraft:sand"},
        {pos: [1, 2, 0], state: "minecraft:sand"},
        {pos: [1, 2, 1], state: "minecraft:sand"},
        {pos: [1, 2, 2], state: "minecraft:sand"},
        {pos: [1, 2, 3], state: "minecraft:sand"},
        {pos: [1, 2, 4], state: "minecraft:sand"},
        {pos: [2, 2, 0], state: "minecraft:red_terracotta"},
        {pos: [2, 2, 1], state: "minecraft:sand"},
        {pos: [2, 2, 2], state: "minecraft:sand"},
        {pos: [2, 2, 3], state: "minecraft:sand"},
        {pos: [2, 2, 4], state: "minecraft:jigsaw{orientation:south_up}", nbt: {final_state: "minecraft:sand", id: "minecraft:jigsaw", joint: "rollable", name: "minecraft:room_front", pool: "minecraft:trail_ruins/buildings/grouped", target: "minecraft:entrance_front"}},
        {pos: [3, 2, 1], state: "minecraft:red_terracotta"},
        {pos: [3, 2, 2], state: "minecraft:air"},
        {pos: [3, 2, 3], state: "minecraft:air"},
        {pos: [3, 2, 4], state: "minecraft:sand"},
        {pos: [4, 2, 2], state: "minecraft:red_terracotta"},
        {pos: [4, 2, 3], state: "minecraft:red_terracotta"},
        {pos: [4, 2, 4], state: "minecraft:red_terracotta"},
        {pos: [0, 3, 0], state: "minecraft:red_terracotta"},
        {pos: [0, 3, 1], state: "minecraft:sand"},
        {pos: [0, 3, 2], state: "minecraft:sand"},
        {pos: [0, 3, 3], state: "minecraft:sand"},
        {pos: [0, 3, 4], state: "minecraft:sand"},
        {pos: [1, 3, 0], state: "minecraft:red_terracotta"},
        {pos: [1, 3, 1], state: "minecraft:sand"},
        {pos: [1, 3, 2], state: "minecraft:sand"},
        {pos: [1, 3, 3], state: "minecraft:sand"},
        {pos: [1, 3, 4], state: "minecraft:sand"},
        {pos: [2, 3, 0], state: "minecraft:red_terracotta"},
        {pos: [2, 3, 1], state: "minecraft:air"},
        {pos: [2, 3, 2], state: "minecraft:sand"},
        {pos: [2, 3, 3], state: "minecraft:sand"},
        {pos: [2, 3, 4], state: "minecraft:sand"},
        {pos: [3, 3, 1], state: "minecraft:red_terracotta"},
        {pos: [3, 3, 2], state: "minecraft:air"},
        {pos: [3, 3, 3], state: "minecraft:air"},
        {pos: [3, 3, 4], state: "minecraft:sand"},
        {pos: [4, 3, 2], state: "minecraft:red_terracotta"},
        {pos: [4, 3, 3], state: "minecraft:red_terracotta"},
        {pos: [4, 3, 4], state: "minecraft:red_terracotta"},
        {pos: [0, 4, 0], state: "minecraft:yellow_terracotta"},
        {pos: [0, 4, 1], state: "minecraft:sand"},
        {pos: [0, 4, 2], state: "minecraft:sand"},
        {pos: [0, 4, 3], state: "minecraft:sand"},
        {pos: [0, 4, 4], state: "minecraft:air"},
        {pos: [1, 4, 1], state: "minecraft:sand"},
        {pos: [1, 4, 2], state: "minecraft:sand"},
        {pos: [1, 4, 3], state: "minecraft:sand"},
        {pos: [1, 4, 4], state: "minecraft:air"},
        {pos: [2, 4, 1], state: "minecraft:yellow_terracotta"},
        {pos: [2, 4, 2], state: "minecraft:yellow_terracotta"},
        {pos: [2, 4, 3], state: "minecraft:yellow_terracotta"},
        {pos: [2, 4, 4], state: "minecraft:air"},
        {pos: [3, 4, 2], state: "minecraft:yellow_terracotta"},
        {pos: [3, 4, 3], state: "minecraft:yellow_terracotta"},
        {pos: [3, 4, 4], state: "minecraft:air"},
        {pos: [4, 4, 4], state: "minecraft:red_terracotta"},
        {pos: [0, 5, 2], state: "minecraft:sand"},
        {pos: [0, 5, 3], state: "minecraft:sand"},
        {pos: [0, 5, 4], state: "minecraft:yellow_terracotta"},
        {pos: [1, 5, 3], state: "minecraft:sand"},
        {pos: [1, 5, 4], state: "minecraft:yellow_terracotta"},
        {pos: [2, 5, 4], state: "minecraft:yellow_terracotta"},
        {pos: [3, 5, 4], state: "minecraft:yellow_terracotta"}
    ],
    entities: [],
    palette: [
        "minecraft:red_terracotta",
        "minecraft:sand",
        "minecraft:yellow_terracotta",
        "minecraft:air",
        "minecraft:jigsaw{orientation:west_up}",
        "minecraft:jigsaw{orientation:south_up}"
    ]
}
