{
    size: [4, 5, 5],
    data: [
        {pos: [0, 0, 0], state: "minecraft:blue_terracotta"},
        {pos: [0, 0, 1], state: "minecraft:blue_terracotta"},
        {pos: [0, 0, 2], state: "minecraft:blue_terracotta"},
        {pos: [0, 0, 3], state: "minecraft:blue_terracotta"},
        {pos: [0, 0, 4], state: "minecraft:blue_terracotta"},
        {pos: [1, 0, 0], state: "minecraft:blue_terracotta"},
        {pos: [1, 0, 1], state: "minecraft:blue_terracotta"},
        {pos: [1, 0, 2], state: "minecraft:blue_terracotta"},
        {pos: [1, 0, 3], state: "minecraft:blue_terracotta"},
        {pos: [1, 0, 4], state: "minecraft:blue_terracotta"},
        {pos: [2, 0, 0], state: "minecraft:blue_terracotta"},
        {pos: [2, 0, 1], state: "minecraft:blue_terracotta"},
        {pos: [2, 0, 2], state: "minecraft:blue_terracotta"},
        {pos: [2, 0, 3], state: "minecraft:blue_terracotta"},
        {pos: [2, 0, 4], state: "minecraft:blue_terracotta"},
        {pos: [3, 0, 1], state: "minecraft:blue_terracotta"},
        {pos: [3, 0, 2], state: "minecraft:blue_terracotta"},
        {pos: [3, 0, 3], state: "minecraft:blue_terracotta"},
        {pos: [0, 1, 0], state: "minecraft:blue_terracotta"},
        {pos: [0, 1, 1], state: "minecraft:sand"},
        {pos: [0, 1, 2], state: "minecraft:brick_stairs{facing:west,half:bottom,shape:straight,waterlogged:false}"},
        {pos: [0, 1, 3], state: "minecraft:sand"},
        {pos: [0, 1, 4], state: "minecraft:blue_terracotta"},
        {pos: [1, 1, 0], state: "minecraft:blue_terracotta"},
        {pos: [1, 1, 1], state: "minecraft:blue_terracotta"},
        {pos: [1, 1, 2], state: "minecraft:sand"},
        {pos: [1, 1, 3], state: "minecraft:sand"},
        {pos: [1, 1, 4], state: "minecraft:blue_terracotta"},
        {pos: [2, 1, 0], state: "minecraft:blue_terracotta"},
        {pos: [2, 1, 2], state: "minecraft:sand"},
        {pos: [2, 1, 3], state: "minecraft:blue_terracotta"},
        {pos: [2, 1, 4], state: "minecraft:blue_terracotta"},
        {pos: [3, 1, 1], state: "minecraft:blue_terracotta"},
        {pos: [3, 1, 2], state: "minecraft:blue_terracotta"},
        {pos: [3, 1, 3], state: "minecraft:blue_terracotta"},
        {pos: [0, 2, 0], state: "minecraft:blue_terracotta"},
        {pos: [0, 2, 1], state: "minecraft:sand"},
        {pos: [0, 2, 2], state: "minecraft:jigsaw{orientation:west_up}", nbt: {final_state: "minecraft:sand", id: "minecraft:jigsaw", joint: "rollable", name: "minecraft:room_right", pool: "minecraft:trail_ruins/buildings/grouped", target: "minecraft:entrance_right"}},
        {pos: [0, 2, 3], state: "minecraft:sand"},
        {pos: [0, 2, 4], state: "minecraft:blue_terracotta"},
        {pos: [1, 2, 0], state: "minecraft:blue_terracotta"},
        {pos: [1, 2, 1], state: "minecraft:blue_terracotta"},
        {pos: [1, 2, 2], state: "minecraft:sand"},
        {pos: [1, 2, 3], state: "minecraft:sand"},
        {pos: [1, 2, 4], state: "minecraft:blue_terracotta"},
        {pos: [2, 2, 0], state: "minecraft:blue_terracotta"},
        {pos: [2, 2, 1], state: "minecraft:blue_terracotta"},
        {pos: [2, 2, 2], state: "minecraft:sand"},
        {pos: [2, 2, 3], state: "minecraft:sand"},
        {pos: [2, 2, 4], state: "minecraft:blue_terracotta"},
        {pos: [3, 2, 1], state: "minecraft:blue_terracotta"},
        {pos: [3, 2, 2], state: "minecraft:blue_terracotta"},
        {pos: [3, 2, 3], state: "minecraft:blue_terracotta"},
        {pos: [0, 3, 0], state: "minecraft:blue_terracotta"},
        {pos: [0, 3, 1], state: "minecraft:sand"},
        {pos: [0, 3, 2], state: "minecraft:sand"},
        {pos: [0, 3, 3], state: "minecraft:sand"},
        {pos: [1, 3, 0], state: "minecraft:blue_terracotta"},
        {pos: [1, 3, 1], state: "minecraft:sand"},
        {pos: [1, 3, 2], state: "minecraft:sand"},
        {pos: [1, 3, 3], state: "minecraft:sand"},
        {pos: [1, 3, 4], state: "minecraft:blue_terracotta"},
        {pos: [2, 3, 0], state: "minecraft:blue_terracotta"},
        {pos: [2, 3, 1], state: "minecraft:sand"},
        {pos: [2, 3, 2], state: "minecraft:sand"},
        {pos: [2, 3, 3], state: "minecraft:sand"},
        {pos: [2, 3, 4], state: "minecraft:blue_terracotta"},
        {pos: [3, 3, 1], state: "minecraft:blue_terracotta"},
        {pos: [3, 3, 2], state: "minecraft:blue_terracotta"},
        {pos: [0, 4, 1], state: "minecraft:light_blue_terracotta"},
        {pos: [0, 4, 2], state: "minecraft:sand"},
        {pos: [1, 4, 1], state: "minecraft:light_blue_terracotta"},
        {pos: [2, 4, 1], state: "minecraft:light_blue_terracotta"}
    ],
    entities: [],
    palette: [
        "minecraft:blue_terracotta",
        "minecraft:sand",
        "minecraft:light_blue_terracotta",
        "minecraft:brick_stairs{facing:west,half:bottom,shape:straight,waterlogged:false}",
        "minecraft:jigsaw{orientation:west_up}"
    ]
}
