{
    size: [15, 15, 11],
    data: [
        {pos: [5, 3, 0], state: "minecraft:mud_bricks"},
        {pos: [5, 3, 1], state: "minecraft:mud_bricks"},
        {pos: [5, 3, 2], state: "minecraft:mud_bricks"},
        {pos: [5, 3, 3], state: "minecraft:mud_bricks"},
        {pos: [5, 3, 4], state: "minecraft:mud_bricks"},
        {pos: [5, 3, 5], state: "minecraft:mud_bricks"},
        {pos: [5, 3, 6], state: "minecraft:mud_bricks"},
        {pos: [5, 3, 7], state: "minecraft:mud_bricks"},
        {pos: [5, 3, 8], state: "minecraft:mud_bricks"},
        {pos: [5, 3, 10], state: "minecraft:mud_bricks"},
        {pos: [6, 3, 0], state: "minecraft:mud_bricks"},
        {pos: [6, 3, 1], state: "minecraft:mud_bricks"},
        {pos: [6, 3, 2], state: "minecraft:mud_bricks"},
        {pos: [6, 3, 3], state: "minecraft:mud_bricks"},
        {pos: [6, 3, 4], state: "minecraft:mud_bricks"},
        {pos: [6, 3, 5], state: "minecraft:mud_bricks"},
        {pos: [6, 3, 6], state: "minecraft:mud_bricks"},
        {pos: [6, 3, 7], state: "minecraft:mud_bricks"},
        {pos: [6, 3, 8], state: "minecraft:mud_bricks"},
        {pos: [6, 3, 9], state: "minecraft:mud_bricks"},
        {pos: [6, 3, 10], state: "minecraft:mud_bricks"},
        {pos: [7, 3, 0], state: "minecraft:mud_bricks"},
        {pos: [7, 3, 1], state: "minecraft:mud_bricks"},
        {pos: [7, 3, 2], state: "minecraft:mud_bricks"},
        {pos: [7, 3, 3], state: "minecraft:mud_bricks"},
        {pos: [7, 3, 4], state: "minecraft:mud_bricks"},
        {pos: [7, 3, 5], state: "minecraft:mud_bricks"},
        {pos: [7, 3, 6], state: "minecraft:mud_bricks"},
        {pos: [7, 3, 7], state: "minecraft:mud_bricks"},
        {pos: [7, 3, 8], state: "minecraft:mud_bricks"},
        {pos: [7, 3, 9], state: "minecraft:mud_bricks"},
        {pos: [7, 3, 10], state: "minecraft:mud_bricks"},
        {pos: [8, 3, 0], state: "minecraft:mud_bricks"},
        {pos: [8, 3, 1], state: "minecraft:mud_bricks"},
        {pos: [8, 3, 2], state: "minecraft:mud_bricks"},
        {pos: [8, 3, 3], state: "minecraft:mud_bricks"},
        {pos: [8, 3, 4], state: "minecraft:mud_bricks"},
        {pos: [8, 3, 5], state: "minecraft:mud_bricks"},
        {pos: [8, 3, 6], state: "minecraft:mud_bricks"},
        {pos: [8, 3, 7], state: "minecraft:mud_bricks"},
        {pos: [8, 3, 8], state: "minecraft:mud_bricks"},
        {pos: [8, 3, 9], state: "minecraft:mud_bricks"},
        {pos: [8, 3, 10], state: "minecraft:mud_bricks"},
        {pos: [9, 3, 0], state: "minecraft:mud_bricks"},
        {pos: [9, 3, 1], state: "minecraft:mud_bricks"},
        {pos: [9, 3, 2], state: "minecraft:mud_bricks"},
        {pos: [9, 3, 3], state: "minecraft:mud_bricks"},
        {pos: [9, 3, 4], state: "minecraft:mud_bricks"},
        {pos: [9, 3, 5], state: "minecraft:mud_bricks"},
        {pos: [9, 3, 6], state: "minecraft:mud_bricks"},
        {pos: [9, 3, 7], state: "minecraft:mud_bricks"},
        {pos: [9, 3, 8], state: "minecraft:mud_bricks"},
        {pos: [9, 3, 9], state: "minecraft:mud_bricks"},
        {pos: [9, 3, 10], state: "minecraft:mud_bricks"},
        {pos: [5, 4, 0], state: "minecraft:mud_bricks"},
        {pos: [5, 4, 1], state: "minecraft:mud_bricks"},
        {pos: [5, 4, 2], state: "minecraft:mud_bricks"},
        {pos: [5, 4, 3], state: "minecraft:mud_bricks"},
        {pos: [5, 4, 4], state: "minecraft:mud_bricks"},
        {pos: [5, 4, 5], state: "minecraft:mud_bricks"},
        {pos: [5, 4, 6], state: "minecraft:mud_bricks"},
        {pos: [5, 4, 7], state: "minecraft:mud_bricks"},
        {pos: [5, 4, 8], state: "minecraft:mud_bricks"},
        {pos: [5, 4, 9], state: "minecraft:mud_bricks"},
        {pos: [5, 4, 10], state: "minecraft:mud_bricks"},
        {pos: [6, 4, 0], state: "minecraft:mud_bricks"},
        {pos: [6, 4, 1], state: "minecraft:mud_bricks"},
        {pos: [6, 4, 2], state: "minecraft:mud_bricks"},
        {pos: [6, 4, 3], state: "minecraft:light_gray_glazed_terracotta{facing:east}"},
        {pos: [6, 4, 4], state: "minecraft:mud_bricks"},
        {pos: [6, 4, 5], state: "minecraft:light_gray_glazed_terracotta{facing:east}"},
        {pos: [6, 4, 6], state: "minecraft:mud_bricks"},
        {pos: [6, 4, 7], state: "minecraft:light_gray_glazed_terracotta{facing:east}"},
        {pos: [6, 4, 8], state: "minecraft:mud_bricks"},
        {pos: [6, 4, 9], state: "minecraft:mud_bricks"},
        {pos: [6, 4, 10], state: "minecraft:mud_bricks"},
        {pos: [7, 4, 0], state: "minecraft:mud_bricks"},
        {pos: [7, 4, 1], state: "minecraft:mud_bricks"},
        {pos: [7, 4, 2], state: "minecraft:mud_bricks"},
        {pos: [7, 4, 3], state: "minecraft:light_gray_glazed_terracotta{facing:south}"},
        {pos: [7, 4, 4], state: "minecraft:light_gray_glazed_terracotta{facing:east}"},
        {pos: [7, 4, 5], state: "minecraft:light_gray_terracotta"},
        {pos: [7, 4, 6], state: "minecraft:gravel"},
        {pos: [7, 4, 7], state: "minecraft:light_gray_glazed_terracotta{facing:south}"},
        {pos: [7, 4, 8], state: "minecraft:light_gray_glazed_terracotta{facing:west}"},
        {pos: [7, 4, 9], state: "minecraft:mud_bricks"},
        {pos: [7, 4, 10], state: "minecraft:mud_bricks"},
        {pos: [8, 4, 0], state: "minecraft:mud_bricks"},
        {pos: [8, 4, 1], state: "minecraft:mud_bricks"},
        {pos: [8, 4, 2], state: "minecraft:mud_bricks"},
        {pos: [8, 4, 3], state: "minecraft:mud_bricks"},
        {pos: [8, 4, 4], state: "minecraft:light_gray_glazed_terracotta{facing:south}"},
        {pos: [8, 4, 5], state: "minecraft:mud_bricks"},
        {pos: [8, 4, 6], state: "minecraft:gravel"},
        {pos: [8, 4, 7], state: "minecraft:mud_bricks"},
        {pos: [8, 4, 8], state: "minecraft:light_gray_glazed_terracotta{facing:south}"},
        {pos: [8, 4, 9], state: "minecraft:mud_bricks"},
        {pos: [8, 4, 10], state: "minecraft:mud_bricks"},
        {pos: [9, 4, 0], state: "minecraft:mud_bricks"},
        {pos: [9, 4, 1], state: "minecraft:mud_bricks"},
        {pos: [9, 4, 2], state: "minecraft:mud_bricks"},
        {pos: [9, 4, 3], state: "minecraft:mud_bricks"},
        {pos: [9, 4, 4], state: "minecraft:mud_bricks"},
        {pos: [9, 4, 5], state: "minecraft:mud_bricks"},
        {pos: [9, 4, 6], state: "minecraft:mud_bricks"},
        {pos: [9, 4, 7], state: "minecraft:mud_bricks"},
        {pos: [9, 4, 8], state: "minecraft:mud_bricks"},
        {pos: [9, 4, 9], state: "minecraft:mud_bricks"},
        {pos: [9, 4, 10], state: "minecraft:mud_bricks"},
        {pos: [5, 5, 0], state: "minecraft:gravel"},
        {pos: [5, 5, 1], state: "minecraft:mud_bricks"},
        {pos: [5, 5, 2], state: "minecraft:gravel"},
        {pos: [5, 5, 3], state: "minecraft:jigsaw{orientation:west_up}", nbt: {final_state: "minecraft:dirt", id: "minecraft:jigsaw", joint: "rollable", name: "minecraft:hall", pool: "minecraft:trail_ruins/buildings/grouped", target: "minecraft:room"}},
        {pos: [5, 5, 4], state: "minecraft:gravel"},
        {pos: [5, 5, 5], state: "minecraft:gravel"},
        {pos: [5, 5, 6], state: "minecraft:gravel"},
        {pos: [5, 5, 7], state: "minecraft:gravel"},
        {pos: [5, 5, 8], state: "minecraft:jigsaw{orientation:west_up}", nbt: {final_state: "minecraft:dirt", id: "minecraft:jigsaw", joint: "rollable", name: "minecraft:hall", pool: "minecraft:trail_ruins/buildings/grouped", target: "minecraft:room"}},
        {pos: [5, 5, 9], state: "minecraft:gravel"},
        {pos: [5, 5, 10], state: "minecraft:mud_bricks"},
        {pos: [6, 5, 0], state: "minecraft:gravel"},
        {pos: [6, 5, 1], state: "minecraft:gravel"},
        {pos: [6, 5, 2], state: "minecraft:mud_bricks"},
        {pos: [6, 5, 3], state: "minecraft:gravel"},
        {pos: [6, 5, 4], state: "minecraft:gravel"},
        {pos: [6, 5, 5], state: "minecraft:mud_bricks"},
        {pos: [6, 5, 6], state: "minecraft:mud_bricks"},
        {pos: [6, 5, 7], state: "minecraft:gravel"},
        {pos: [6, 5, 8], state: "minecraft:gravel"},
        {pos: [6, 5, 9], state: "minecraft:gravel"},
        {pos: [6, 5, 10], state: "minecraft:mud_bricks"},
        {pos: [7, 5, 0], state: "minecraft:jigsaw{orientation:north_up}", nbt: {final_state: "minecraft:dirt", id: "minecraft:jigsaw", joint: "rollable", name: "minecraft:building_anchor", pool: "minecraft:trail_ruins/roads", target: "minecraft:road_anchor"}},
        {pos: [7, 5, 1], state: "minecraft:gravel"},
        {pos: [7, 5, 2], state: "minecraft:gravel"},
        {pos: [7, 5, 3], state: "minecraft:gravel"},
        {pos: [7, 5, 4], state: "minecraft:gravel"},
        {pos: [7, 5, 5], state: "minecraft:gravel"},
        {pos: [7, 5, 6], state: "minecraft:gravel"},
        {pos: [7, 5, 7], state: "minecraft:gravel"},
        {pos: [7, 5, 8], state: "minecraft:gravel"},
        {pos: [7, 5, 9], state: "minecraft:composter{level:0}"},
        {pos: [7, 5, 10], state: "minecraft:mud_bricks"},
        {pos: [8, 5, 0], state: "minecraft:gravel"},
        {pos: [8, 5, 1], state: "minecraft:gravel"},
        {pos: [8, 5, 2], state: "minecraft:mud_bricks"},
        {pos: [8, 5, 3], state: "minecraft:gravel"},
        {pos: [8, 5, 4], state: "minecraft:gravel"},
        {pos: [8, 5, 5], state: "minecraft:mud_bricks"},
        {pos: [8, 5, 6], state: "minecraft:gravel"},
        {pos: [8, 5, 7], state: "minecraft:gravel"},
        {pos: [8, 5, 8], state: "minecraft:gravel"},
        {pos: [8, 5, 9], state: "minecraft:gravel"},
        {pos: [8, 5, 10], state: "minecraft:mud_bricks"},
        {pos: [9, 5, 0], state: "minecraft:gravel"},
        {pos: [9, 5, 1], state: "minecraft:mud_bricks"},
        {pos: [9, 5, 2], state: "minecraft:gravel"},
        {pos: [9, 5, 3], state: "minecraft:jigsaw{orientation:east_up}", nbt: {final_state: "minecraft:dirt", id: "minecraft:jigsaw", joint: "rollable", name: "minecraft:hall", pool: "minecraft:trail_ruins/buildings/grouped", target: "minecraft:room"}},
        {pos: [9, 5, 4], state: "minecraft:gravel"},
        {pos: [9, 5, 5], state: "minecraft:gravel"},
        {pos: [9, 5, 6], state: "minecraft:gravel"},
        {pos: [9, 5, 7], state: "minecraft:gravel"},
        {pos: [9, 5, 8], state: "minecraft:jigsaw{orientation:east_up}", nbt: {final_state: "minecraft:dirt", id: "minecraft:jigsaw", joint: "rollable", name: "minecraft:hall", pool: "minecraft:trail_ruins/buildings/grouped", target: "minecraft:room"}},
        {pos: [9, 5, 9], state: "minecraft:gravel"},
        {pos: [9, 5, 10], state: "minecraft:mud_bricks"},
        {pos: [5, 6, 0], state: "minecraft:gravel"},
        {pos: [5, 6, 1], state: "minecraft:cyan_terracotta"},
        {pos: [5, 6, 2], state: "minecraft:gravel"},
        {pos: [5, 6, 3], state: "minecraft:gravel"},
        {pos: [5, 6, 4], state: "minecraft:gravel"},
        {pos: [5, 6, 5], state: "minecraft:gravel"},
        {pos: [5, 6, 6], state: "minecraft:gravel"},
        {pos: [5, 6, 7], state: "minecraft:gravel"},
        {pos: [5, 6, 8], state: "minecraft:gravel"},
        {pos: [5, 6, 9], state: "minecraft:gravel"},
        {pos: [5, 6, 10], state: "minecraft:cyan_terracotta"},
        {pos: [6, 6, 0], state: "minecraft:gravel"},
        {pos: [6, 6, 1], state: "minecraft:gravel"},
        {pos: [6, 6, 2], state: "minecraft:gravel"},
        {pos: [6, 6, 3], state: "minecraft:gravel"},
        {pos: [6, 6, 4], state: "minecraft:gravel"},
        {pos: [6, 6, 5], state: "minecraft:gravel"},
        {pos: [6, 6, 6], state: "minecraft:gravel"},
        {pos: [6, 6, 7], state: "minecraft:gravel"},
        {pos: [6, 6, 8], state: "minecraft:gravel"},
        {pos: [6, 6, 9], state: "minecraft:gravel"},
        {pos: [6, 6, 10], state: "minecraft:cyan_terracotta"},
        {pos: [7, 6, 0], state: "minecraft:gravel"},
        {pos: [7, 6, 1], state: "minecraft:gravel"},
        {pos: [7, 6, 2], state: "minecraft:gravel"},
        {pos: [7, 6, 3], state: "minecraft:gravel"},
        {pos: [7, 6, 4], state: "minecraft:gravel"},
        {pos: [7, 6, 5], state: "minecraft:gravel"},
        {pos: [7, 6, 6], state: "minecraft:gravel"},
        {pos: [7, 6, 7], state: "minecraft:gravel"},
        {pos: [7, 6, 8], state: "minecraft:gravel"},
        {pos: [7, 6, 9], state: "minecraft:gravel"},
        {pos: [7, 6, 10], state: "minecraft:cyan_terracotta"},
        {pos: [8, 6, 0], state: "minecraft:gravel"},
        {pos: [8, 6, 1], state: "minecraft:gravel"},
        {pos: [8, 6, 2], state: "minecraft:cyan_terracotta"},
        {pos: [8, 6, 3], state: "minecraft:gravel"},
        {pos: [8, 6, 4], state: "minecraft:gravel"},
        {pos: [8, 6, 5], state: "minecraft:gravel"},
        {pos: [8, 6, 6], state: "minecraft:gravel"},
        {pos: [8, 6, 7], state: "minecraft:gravel"},
        {pos: [8, 6, 8], state: "minecraft:gravel"},
        {pos: [8, 6, 9], state: "minecraft:gravel"},
        {pos: [8, 6, 10], state: "minecraft:cyan_terracotta"},
        {pos: [9, 6, 0], state: "minecraft:gravel"},
        {pos: [9, 6, 1], state: "minecraft:cyan_terracotta"},
        {pos: [9, 6, 2], state: "minecraft:gravel"},
        {pos: [9, 6, 3], state: "minecraft:gravel"},
        {pos: [9, 6, 4], state: "minecraft:gravel"},
        {pos: [9, 6, 5], state: "minecraft:gravel"},
        {pos: [9, 6, 6], state: "minecraft:gravel"},
        {pos: [9, 6, 7], state: "minecraft:gravel"},
        {pos: [9, 6, 8], state: "minecraft:gravel"},
        {pos: [9, 6, 9], state: "minecraft:gravel"},
        {pos: [9, 6, 10], state: "minecraft:cyan_terracotta"},
        {pos: [14, 6, 1], state: "minecraft:air"},
        {pos: [5, 7, 0], state: "minecraft:mud_brick_stairs{facing:south,half:top,shape:straight,waterlogged:false}"},
        {pos: [5, 7, 1], state: "minecraft:mud_bricks"},
        {pos: [5, 7, 3], state: "minecraft:gravel"},
        {pos: [5, 7, 4], state: "minecraft:gravel"},
        {pos: [5, 7, 5], state: "minecraft:gravel"},
        {pos: [5, 7, 6], state: "minecraft:gravel"},
        {pos: [5, 7, 7], state: "minecraft:gravel"},
        {pos: [5, 7, 8], state: "minecraft:gravel"},
        {pos: [5, 7, 9], state: "minecraft:gravel"},
        {pos: [5, 7, 10], state: "minecraft:gravel"},
        {pos: [6, 7, 0], state: "minecraft:gravel"},
        {pos: [6, 7, 1], state: "minecraft:gravel"},
        {pos: [6, 7, 2], state: "minecraft:mud_bricks"},
        {pos: [6, 7, 3], state: "minecraft:gravel"},
        {pos: [6, 7, 4], state: "minecraft:gravel"},
        {pos: [6, 7, 5], state: "minecraft:gravel"},
        {pos: [6, 7, 6], state: "minecraft:gravel"},
        {pos: [6, 7, 7], state: "minecraft:gravel"},
        {pos: [6, 7, 8], state: "minecraft:gravel"},
        {pos: [6, 7, 9], state: "minecraft:gravel"},
        {pos: [6, 7, 10], state: "minecraft:gravel"},
        {pos: [7, 7, 0], state: "minecraft:gravel"},
        {pos: [7, 7, 1], state: "minecraft:gravel"},
        {pos: [7, 7, 2], state: "minecraft:mud_bricks"},
        {pos: [7, 7, 3], state: "minecraft:gravel"},
        {pos: [7, 7, 4], state: "minecraft:gravel"},
        {pos: [7, 7, 5], state: "minecraft:gravel"},
        {pos: [7, 7, 6], state: "minecraft:gravel"},
        {pos: [7, 7, 7], state: "minecraft:gravel"},
        {pos: [7, 7, 8], state: "minecraft:gravel"},
        {pos: [7, 7, 9], state: "minecraft:gravel"},
        {pos: [7, 7, 10], state: "minecraft:gravel"},
        {pos: [8, 7, 0], state: "minecraft:gravel"},
        {pos: [8, 7, 1], state: "minecraft:gravel"},
        {pos: [8, 7, 2], state: "minecraft:mud_bricks"},
        {pos: [8, 7, 3], state: "minecraft:gravel"},
        {pos: [8, 7, 4], state: "minecraft:gravel"},
        {pos: [8, 7, 5], state: "minecraft:gravel"},
        {pos: [8, 7, 6], state: "minecraft:gravel"},
        {pos: [8, 7, 7], state: "minecraft:gravel"},
        {pos: [8, 7, 8], state: "minecraft:gravel"},
        {pos: [8, 7, 9], state: "minecraft:gravel"},
        {pos: [8, 7, 10], state: "minecraft:gravel"},
        {pos: [9, 7, 0], state: "minecraft:mud_brick_stairs{facing:south,half:top,shape:straight,waterlogged:false}"},
        {pos: [9, 7, 1], state: "minecraft:mud_bricks"},
        {pos: [9, 7, 2], state: "minecraft:gravel"},
        {pos: [9, 7, 3], state: "minecraft:gravel"},
        {pos: [9, 7, 4], state: "minecraft:gravel"},
        {pos: [9, 7, 5], state: "minecraft:gravel"},
        {pos: [9, 7, 6], state: "minecraft:gravel"},
        {pos: [9, 7, 7], state: "minecraft:gravel"},
        {pos: [9, 7, 8], state: "minecraft:gravel"},
        {pos: [9, 7, 9], state: "minecraft:gravel"},
        {pos: [9, 7, 10], state: "minecraft:mud_bricks"},
        {pos: [5, 8, 0], state: "minecraft:light_gray_terracotta"},
        {pos: [5, 8, 1], state: "minecraft:light_gray_terracotta"},
        {pos: [5, 8, 2], state: "minecraft:light_gray_terracotta"},
        {pos: [5, 8, 3], state: "minecraft:gravel"},
        {pos: [5, 8, 4], state: "minecraft:gravel"},
        {pos: [5, 8, 5], state: "minecraft:gravel"},
        {pos: [5, 8, 6], state: "minecraft:gravel"},
        {pos: [5, 8, 7], state: "minecraft:gravel"},
        {pos: [5, 8, 8], state: "minecraft:gravel"},
        {pos: [5, 8, 9], state: "minecraft:gravel"},
        {pos: [5, 8, 10], state: "minecraft:gravel"},
        {pos: [6, 8, 0], state: "minecraft:light_gray_terracotta"},
        {pos: [6, 8, 1], state: "minecraft:light_gray_terracotta"},
        {pos: [6, 8, 2], state: "minecraft:light_gray_terracotta"},
        {pos: [6, 8, 3], state: "minecraft:gravel"},
        {pos: [6, 8, 4], state: "minecraft:gravel"},
        {pos: [6, 8, 5], state: "minecraft:gravel"},
        {pos: [6, 8, 6], state: "minecraft:gravel"},
        {pos: [6, 8, 7], state: "minecraft:gravel"},
        {pos: [6, 8, 8], state: "minecraft:gravel"},
        {pos: [6, 8, 9], state: "minecraft:gravel"},
        {pos: [6, 8, 10], state: "minecraft:gravel"},
        {pos: [7, 8, 0], state: "minecraft:light_gray_terracotta"},
        {pos: [7, 8, 1], state: "minecraft:light_gray_terracotta"},
        {pos: [7, 8, 2], state: "minecraft:light_gray_terracotta"},
        {pos: [7, 8, 3], state: "minecraft:gravel"},
        {pos: [7, 8, 4], state: "minecraft:gravel"},
        {pos: [7, 8, 5], state: "minecraft:gravel"},
        {pos: [7, 8, 6], state: "minecraft:gravel"},
        {pos: [7, 8, 7], state: "minecraft:gravel"},
        {pos: [7, 8, 8], state: "minecraft:gravel"},
        {pos: [7, 8, 9], state: "minecraft:gravel"},
        {pos: [8, 8, 0], state: "minecraft:light_gray_terracotta"},
        {pos: [8, 8, 1], state: "minecraft:light_gray_terracotta"},
        {pos: [8, 8, 2], state: "minecraft:light_gray_terracotta"},
        {pos: [8, 8, 3], state: "minecraft:gravel"},
        {pos: [8, 8, 4], state: "minecraft:gravel"},
        {pos: [8, 8, 5], state: "minecraft:gravel"},
        {pos: [8, 8, 6], state: "minecraft:gravel"},
        {pos: [8, 8, 7], state: "minecraft:gravel"},
        {pos: [8, 8, 8], state: "minecraft:gravel"},
        {pos: [8, 8, 9], state: "minecraft:gravel"},
        {pos: [8, 8, 10], state: "minecraft:light_gray_terracotta"},
        {pos: [9, 8, 0], state: "minecraft:light_gray_terracotta"},
        {pos: [9, 8, 1], state: "minecraft:light_gray_terracotta"},
        {pos: [9, 8, 2], state: "minecraft:gravel"},
        {pos: [9, 8, 3], state: "minecraft:gravel"},
        {pos: [9, 8, 4], state: "minecraft:gravel"},
        {pos: [9, 8, 5], state: "minecraft:gravel"},
        {pos: [9, 8, 6], state: "minecraft:gravel"},
        {pos: [9, 8, 7], state: "minecraft:gravel"},
        {pos: [9, 8, 8], state: "minecraft:gravel"},
        {pos: [9, 8, 9], state: "minecraft:gravel"},
        {pos: [9, 8, 10], state: "minecraft:light_gray_terracotta"},
        {pos: [5, 9, 1], state: "minecraft:light_gray_terracotta"},
        {pos: [5, 9, 2], state: "minecraft:light_gray_terracotta"},
        {pos: [5, 9, 3], state: "minecraft:mud_bricks"},
        {pos: [5, 9, 4], state: "minecraft:light_gray_terracotta"},
        {pos: [5, 9, 5], state: "minecraft:light_gray_terracotta"},
        {pos: [5, 9, 6], state: "minecraft:light_gray_terracotta"},
        {pos: [5, 9, 7], state: "minecraft:light_gray_terracotta"},
        {pos: [5, 9, 8], state: "minecraft:mud_bricks"},
        {pos: [5, 9, 9], state: "minecraft:light_gray_terracotta"},
        {pos: [6, 9, 1], state: "minecraft:light_gray_terracotta"},
        {pos: [6, 9, 2], state: "minecraft:mud_bricks"},
        {pos: [6, 9, 3], state: "minecraft:mud_bricks"},
        {pos: [6, 9, 4], state: "minecraft:gravel"},
        {pos: [6, 9, 5], state: "minecraft:gravel"},
        {pos: [6, 9, 7], state: "minecraft:mud_bricks"},
        {pos: [6, 9, 8], state: "minecraft:mud_bricks"},
        {pos: [6, 9, 9], state: "minecraft:light_gray_terracotta"},
        {pos: [7, 9, 1], state: "minecraft:light_gray_terracotta"},
        {pos: [7, 9, 2], state: "minecraft:mud_bricks"},
        {pos: [7, 9, 3], state: "minecraft:mud_bricks"},
        {pos: [7, 9, 4], state: "minecraft:mud_bricks"},
        {pos: [7, 9, 5], state: "minecraft:gravel"},
        {pos: [7, 9, 6], state: "minecraft:gravel"},
        {pos: [7, 9, 7], state: "minecraft:mud_bricks"},
        {pos: [7, 9, 8], state: "minecraft:mud_bricks"},
        {pos: [7, 9, 9], state: "minecraft:light_gray_terracotta"},
        {pos: [8, 9, 1], state: "minecraft:light_gray_terracotta"},
        {pos: [8, 9, 2], state: "minecraft:mud_bricks"},
        {pos: [8, 9, 3], state: "minecraft:mud_bricks"},
        {pos: [8, 9, 4], state: "minecraft:mud_bricks"},
        {pos: [8, 9, 5], state: "minecraft:gravel"},
        {pos: [8, 9, 6], state: "minecraft:gravel"},
        {pos: [8, 9, 7], state: "minecraft:mud_bricks"},
        {pos: [8, 9, 8], state: "minecraft:mud_bricks"},
        {pos: [8, 9, 9], state: "minecraft:light_gray_terracotta"},
        {pos: [9, 9, 1], state: "minecraft:light_gray_terracotta"},
        {pos: [9, 9, 2], state: "minecraft:light_gray_terracotta"},
        {pos: [9, 9, 3], state: "minecraft:mud_bricks"},
        {pos: [9, 9, 4], state: "minecraft:light_gray_terracotta"},
        {pos: [9, 9, 5], state: "minecraft:light_gray_terracotta"},
        {pos: [9, 9, 6], state: "minecraft:light_gray_terracotta"},
        {pos: [9, 9, 7], state: "minecraft:light_gray_terracotta"},
        {pos: [9, 9, 8], state: "minecraft:mud_bricks"},
        {pos: [9, 9, 9], state: "minecraft:light_gray_terracotta"}
    ],
    entities: [],
    palette: [
        "minecraft:mud_bricks",
        "minecraft:light_gray_glazed_terracotta{facing:east}",
        "minecraft:light_gray_glazed_terracotta{facing:south}",
        "minecraft:light_gray_terracotta",
        "minecraft:gravel",
        "minecraft:light_gray_glazed_terracotta{facing:west}",
        "minecraft:cyan_terracotta",
        "minecraft:composter{level:0}",
        "minecraft:air",
        "minecraft:mud_brick_stairs{facing:south,half:top,shape:straight,waterlogged:false}",
        "minecraft:jigsaw{orientation:west_up}",
        "minecraft:jigsaw{orientation:north_up}",
        "minecraft:jigsaw{orientation:east_up}"
    ]
}
