{
    size: [14, 7, 11],
    data: [
        {pos: [5, 0, 5], state: "minecraft:red_terracotta"},
        {pos: [5, 0, 6], state: "minecraft:red_terracotta"},
        {pos: [5, 0, 7], state: "minecraft:red_terracotta"},
        {pos: [5, 0, 8], state: "minecraft:red_terracotta"},
        {pos: [5, 0, 9], state: "minecraft:red_terracotta"},
        {pos: [6, 0, 5], state: "minecraft:red_terracotta"},
        {pos: [6, 0, 6], state: "minecraft:red_terracotta"},
        {pos: [6, 0, 7], state: "minecraft:red_terracotta"},
        {pos: [6, 0, 8], state: "minecraft:red_terracotta"},
        {pos: [6, 0, 9], state: "minecraft:red_terracotta"},
        {pos: [6, 0, 10], state: "minecraft:red_terracotta"},
        {pos: [7, 0, 5], state: "minecraft:red_terracotta"},
        {pos: [7, 0, 6], state: "minecraft:red_terracotta"},
        {pos: [7, 0, 7], state: "minecraft:red_terracotta"},
        {pos: [7, 0, 8], state: "minecraft:red_terracotta"},
        {pos: [7, 0, 9], state: "minecraft:red_terracotta"},
        {pos: [7, 0, 10], state: "minecraft:red_terracotta"},
        {pos: [8, 0, 5], state: "minecraft:red_terracotta"},
        {pos: [8, 0, 6], state: "minecraft:red_terracotta"},
        {pos: [8, 0, 7], state: "minecraft:red_terracotta"},
        {pos: [8, 0, 8], state: "minecraft:red_terracotta"},
        {pos: [8, 0, 9], state: "minecraft:red_terracotta"},
        {pos: [8, 0, 10], state: "minecraft:red_terracotta"},
        {pos: [9, 0, 5], state: "minecraft:red_terracotta"},
        {pos: [9, 0, 6], state: "minecraft:red_terracotta"},
        {pos: [9, 0, 7], state: "minecraft:red_terracotta"},
        {pos: [9, 0, 8], state: "minecraft:red_terracotta"},
        {pos: [9, 0, 9], state: "minecraft:red_terracotta"},
        {pos: [5, 1, 5], state: "minecraft:sand"},
        {pos: [5, 1, 6], state: "minecraft:mud_bricks"},
        {pos: [5, 1, 7], state: "minecraft:mud_bricks"},
        {pos: [5, 1, 8], state: "minecraft:mud_bricks"},
        {pos: [5, 1, 9], state: "minecraft:mud_bricks"},
        {pos: [6, 1, 5], state: "minecraft:mud_bricks"},
        {pos: [6, 1, 6], state: "minecraft:mud_bricks"},
        {pos: [6, 1, 7], state: "minecraft:mud_bricks"},
        {pos: [6, 1, 8], state: "minecraft:mud_bricks"},
        {pos: [6, 1, 9], state: "minecraft:mud_bricks"},
        {pos: [6, 1, 10], state: "minecraft:red_terracotta"},
        {pos: [7, 1, 5], state: "minecraft:mud_bricks"},
        {pos: [7, 1, 6], state: "minecraft:mud_bricks"},
        {pos: [7, 1, 7], state: "minecraft:mud_bricks"},
        {pos: [7, 1, 8], state: "minecraft:mud_bricks"},
        {pos: [7, 1, 9], state: "minecraft:mud_bricks"},
        {pos: [7, 1, 10], state: "minecraft:mud_bricks"},
        {pos: [8, 1, 5], state: "minecraft:mud_bricks"},
        {pos: [8, 1, 6], state: "minecraft:mud_bricks"},
        {pos: [8, 1, 7], state: "minecraft:mud_bricks"},
        {pos: [8, 1, 8], state: "minecraft:mud_bricks"},
        {pos: [8, 1, 9], state: "minecraft:mud_bricks"},
        {pos: [8, 1, 10], state: "minecraft:red_terracotta"},
        {pos: [9, 1, 5], state: "minecraft:mud_bricks"},
        {pos: [9, 1, 6], state: "minecraft:mud_bricks"},
        {pos: [9, 1, 7], state: "minecraft:mud_bricks"},
        {pos: [9, 1, 8], state: "minecraft:mud_bricks"},
        {pos: [9, 1, 9], state: "minecraft:mud_bricks"},
        {pos: [5, 2, 5], state: "minecraft:sand"},
        {pos: [5, 2, 6], state: "minecraft:sand"},
        {pos: [5, 2, 7], state: "minecraft:jigsaw{orientation:west_up}", nbt: {final_state: "minecraft:sand", id: "minecraft:jigsaw", joint: "rollable", name: "minecraft:entrance_left", pool: "minecraft:trail_ruins/buildings/grouped", target: "minecraft:room_left"}},
        {pos: [5, 2, 8], state: "minecraft:sand"},
        {pos: [5, 2, 9], state: "minecraft:mud_bricks"},
        {pos: [6, 2, 5], state: "minecraft:sand"},
        {pos: [6, 2, 6], state: "minecraft:air"},
        {pos: [6, 2, 7], state: "minecraft:sand"},
        {pos: [6, 2, 8], state: "minecraft:sand"},
        {pos: [6, 2, 9], state: "minecraft:sand"},
        {pos: [6, 2, 10], state: "minecraft:mud_bricks"},
        {pos: [7, 2, 5], state: "minecraft:jigsaw{orientation:north_up}", nbt: {final_state: "minecraft:sand", id: "minecraft:jigsaw", joint: "rollable", name: "minecraft:entrance_front", pool: "minecraft:trail_ruins/buildings/grouped", target: "minecraft:room_front"}},
        {pos: [7, 2, 6], state: "minecraft:sand"},
        {pos: [7, 2, 7], state: "minecraft:sand"},
        {pos: [7, 2, 8], state: "minecraft:sand"},
        {pos: [7, 2, 9], state: "minecraft:sand"},
        {pos: [7, 2, 10], state: "minecraft:jigsaw{orientation:south_up}", nbt: {final_state: "minecraft:sand", id: "minecraft:jigsaw", joint: "rollable", name: "minecraft:building_anchor", pool: "minecraft:trail_ruins/roads", target: "minecraft:road_anchor"}},
        {pos: [8, 2, 5], state: "minecraft:sand"},
        {pos: [8, 2, 6], state: "minecraft:sand"},
        {pos: [8, 2, 7], state: "minecraft:sand"},
        {pos: [8, 2, 8], state: "minecraft:sand"},
        {pos: [8, 2, 9], state: "minecraft:sand"},
        {pos: [8, 2, 10], state: "minecraft:mud_bricks"},
        {pos: [9, 2, 5], state: "minecraft:sand"},
        {pos: [9, 2, 6], state: "minecraft:sand"},
        {pos: [9, 2, 7], state: "minecraft:jigsaw{orientation:east_up}", nbt: {final_state: "minecraft:sand", id: "minecraft:jigsaw", joint: "rollable", name: "minecraft:entrance_right", pool: "minecraft:trail_ruins/buildings/grouped", target: "minecraft:room_right"}},
        {pos: [9, 2, 8], state: "minecraft:sand"},
        {pos: [9, 2, 9], state: "minecraft:mud_bricks"},
        {pos: [5, 3, 5], state: "minecraft:sand"},
        {pos: [5, 3, 6], state: "minecraft:sand"},
        {pos: [5, 3, 7], state: "minecraft:sand"},
        {pos: [5, 3, 8], state: "minecraft:sand"},
        {pos: [5, 3, 9], state: "minecraft:yellow_terracotta"},
        {pos: [6, 3, 5], state: "minecraft:sand"},
        {pos: [6, 3, 6], state: "minecraft:air"},
        {pos: [6, 3, 7], state: "minecraft:sand"},
        {pos: [6, 3, 8], state: "minecraft:sand"},
        {pos: [6, 3, 9], state: "minecraft:sand"},
        {pos: [6, 3, 10], state: "minecraft:mud_bricks"},
        {pos: [7, 3, 5], state: "minecraft:sand"},
        {pos: [7, 3, 6], state: "minecraft:sand"},
        {pos: [7, 3, 7], state: "minecraft:sand"},
        {pos: [7, 3, 8], state: "minecraft:sand"},
        {pos: [7, 3, 9], state: "minecraft:sand"},
        {pos: [7, 3, 10], state: "minecraft:sand"},
        {pos: [8, 3, 5], state: "minecraft:sand"},
        {pos: [8, 3, 6], state: "minecraft:sand"},
        {pos: [8, 3, 7], state: "minecraft:sand"},
        {pos: [8, 3, 8], state: "minecraft:sand"},
        {pos: [8, 3, 9], state: "minecraft:sand"},
        {pos: [8, 3, 10], state: "minecraft:sand"},
        {pos: [9, 3, 5], state: "minecraft:sand"},
        {pos: [9, 3, 6], state: "minecraft:sand"},
        {pos: [9, 3, 7], state: "minecraft:sand"},
        {pos: [9, 3, 8], state: "minecraft:sand"},
        {pos: [9, 3, 9], state: "minecraft:mud_bricks"},
        {pos: [5, 4, 5], state: "minecraft:air"},
        {pos: [5, 4, 6], state: "minecraft:air"},
        {pos: [5, 4, 7], state: "minecraft:air"},
        {pos: [5, 4, 8], state: "minecraft:air"},
        {pos: [5, 4, 9], state: "minecraft:yellow_terracotta"},
        {pos: [6, 4, 5], state: "minecraft:air"},
        {pos: [6, 4, 6], state: "minecraft:air"},
        {pos: [6, 4, 7], state: "minecraft:air"},
        {pos: [6, 4, 8], state: "minecraft:sand"},
        {pos: [6, 4, 9], state: "minecraft:sand"},
        {pos: [6, 4, 10], state: "minecraft:sand"},
        {pos: [7, 4, 5], state: "minecraft:air"},
        {pos: [7, 4, 6], state: "minecraft:air"},
        {pos: [7, 4, 7], state: "minecraft:sand"},
        {pos: [7, 4, 8], state: "minecraft:sand"},
        {pos: [7, 4, 9], state: "minecraft:sand"},
        {pos: [8, 4, 5], state: "minecraft:air"},
        {pos: [8, 4, 6], state: "minecraft:air"},
        {pos: [8, 4, 7], state: "minecraft:sand"},
        {pos: [8, 4, 8], state: "minecraft:sand"},
        {pos: [8, 4, 9], state: "minecraft:sand"},
        {pos: [9, 4, 5], state: "minecraft:red_terracotta"},
        {pos: [9, 4, 6], state: "minecraft:air"},
        {pos: [9, 4, 7], state: "minecraft:sand"},
        {pos: [9, 4, 8], state: "minecraft:sand"},
        {pos: [9, 4, 9], state: "minecraft:yellow_terracotta"},
        {pos: [5, 5, 5], state: "minecraft:yellow_terracotta"},
        {pos: [5, 5, 6], state: "minecraft:yellow_terracotta"},
        {pos: [5, 5, 7], state: "minecraft:yellow_terracotta"},
        {pos: [5, 5, 8], state: "minecraft:yellow_terracotta"},
        {pos: [5, 5, 9], state: "minecraft:air"},
        {pos: [6, 5, 5], state: "minecraft:yellow_terracotta"},
        {pos: [6, 5, 6], state: "minecraft:air"},
        {pos: [6, 5, 7], state: "minecraft:air"},
        {pos: [6, 5, 8], state: "minecraft:sand"},
        {pos: [6, 5, 9], state: "minecraft:yellow_terracotta"},
        {pos: [7, 5, 5], state: "minecraft:yellow_terracotta"},
        {pos: [7, 5, 6], state: "minecraft:air"},
        {pos: [7, 5, 7], state: "minecraft:air"},
        {pos: [7, 5, 8], state: "minecraft:sand"},
        {pos: [7, 5, 9], state: "minecraft:sand"},
        {pos: [8, 5, 5], state: "minecraft:yellow_terracotta"},
        {pos: [8, 5, 6], state: "minecraft:air"},
        {pos: [8, 5, 7], state: "minecraft:air"},
        {pos: [8, 5, 8], state: "minecraft:sand"},
        {pos: [9, 5, 5], state: "minecraft:yellow_terracotta"},
        {pos: [9, 5, 6], state: "minecraft:yellow_terracotta"},
        {pos: [9, 5, 7], state: "minecraft:yellow_terracotta"},
        {pos: [9, 5, 8], state: "minecraft:yellow_terracotta"},
        {pos: [9, 5, 9], state: "minecraft:sand"},
        {pos: [6, 6, 6], state: "minecraft:red_terracotta"},
        {pos: [6, 6, 7], state: "minecraft:red_terracotta"},
        {pos: [6, 6, 8], state: "minecraft:red_terracotta"},
        {pos: [7, 6, 5], state: "minecraft:sand"},
        {pos: [7, 6, 6], state: "minecraft:red_terracotta"},
        {pos: [7, 6, 7], state: "minecraft:red_terracotta"},
        {pos: [8, 6, 5], state: "minecraft:sand"},
        {pos: [8, 6, 6], state: "minecraft:red_terracotta"},
        {pos: [8, 6, 7], state: "minecraft:red_terracotta"},
        {pos: [9, 6, 5], state: "minecraft:sand"},
        {pos: [9, 6, 7], state: "minecraft:sand"}
    ],
    entities: [],
    palette: [
        "minecraft:red_terracotta",
        "minecraft:sand",
        "minecraft:mud_bricks",
        "minecraft:yellow_terracotta",
        "minecraft:air",
        "minecraft:jigsaw{orientation:west_up}",
        "minecraft:jigsaw{orientation:north_up}",
        "minecraft:jigsaw{orientation:south_up}",
        "minecraft:jigsaw{orientation:east_up}"
    ]
}
