{
    size: [9, 6, 11],
    data: [
        {pos: [0, 0, 0], state: "minecraft:bricks"},
        {pos: [0, 0, 1], state: "minecraft:bricks"},
        {pos: [0, 0, 2], state: "minecraft:bricks"},
        {pos: [0, 0, 3], state: "minecraft:bricks"},
        {pos: [0, 0, 4], state: "minecraft:bricks"},
        {pos: [0, 0, 5], state: "minecraft:bricks"},
        {pos: [0, 0, 6], state: "minecraft:bricks"},
        {pos: [0, 0, 7], state: "minecraft:bricks"},
        {pos: [0, 0, 8], state: "minecraft:bricks"},
        {pos: [1, 0, 0], state: "minecraft:bricks"},
        {pos: [1, 0, 1], state: "minecraft:bricks"},
        {pos: [1, 0, 2], state: "minecraft:bricks"},
        {pos: [1, 0, 3], state: "minecraft:bricks"},
        {pos: [1, 0, 4], state: "minecraft:bricks"},
        {pos: [1, 0, 5], state: "minecraft:bricks"},
        {pos: [1, 0, 6], state: "minecraft:bricks"},
        {pos: [1, 0, 7], state: "minecraft:bricks"},
        {pos: [1, 0, 8], state: "minecraft:bricks"},
        {pos: [1, 0, 9], state: "minecraft:bricks"},
        {pos: [2, 0, 0], state: "minecraft:bricks"},
        {pos: [2, 0, 1], state: "minecraft:bricks"},
        {pos: [2, 0, 2], state: "minecraft:bricks"},
        {pos: [2, 0, 3], state: "minecraft:bricks"},
        {pos: [2, 0, 4], state: "minecraft:bricks"},
        {pos: [2, 0, 5], state: "minecraft:bricks"},
        {pos: [2, 0, 6], state: "minecraft:bricks"},
        {pos: [2, 0, 7], state: "minecraft:bricks"},
        {pos: [2, 0, 8], state: "minecraft:bricks"},
        {pos: [2, 0, 9], state: "minecraft:bricks"},
        {pos: [3, 0, 0], state: "minecraft:bricks"},
        {pos: [3, 0, 1], state: "minecraft:bricks"},
        {pos: [3, 0, 2], state: "minecraft:bricks"},
        {pos: [3, 0, 3], state: "minecraft:bricks"},
        {pos: [3, 0, 4], state: "minecraft:bricks"},
        {pos: [3, 0, 5], state: "minecraft:bricks"},
        {pos: [3, 0, 6], state: "minecraft:bricks"},
        {pos: [3, 0, 7], state: "minecraft:bricks"},
        {pos: [3, 0, 8], state: "minecraft:bricks"},
        {pos: [3, 0, 9], state: "minecraft:bricks"},
        {pos: [4, 0, 0], state: "minecraft:bricks"},
        {pos: [4, 0, 1], state: "minecraft:bricks"},
        {pos: [4, 0, 2], state: "minecraft:bricks"},
        {pos: [4, 0, 3], state: "minecraft:bricks"},
        {pos: [4, 0, 4], state: "minecraft:bricks"},
        {pos: [4, 0, 5], state: "minecraft:bricks"},
        {pos: [4, 0, 6], state: "minecraft:bricks"},
        {pos: [4, 0, 7], state: "minecraft:bricks"},
        {pos: [4, 0, 8], state: "minecraft:bricks"},
        {pos: [4, 0, 9], state: "minecraft:bricks"},
        {pos: [4, 0, 10], state: "minecraft:bricks"},
        {pos: [5, 0, 0], state: "minecraft:bricks"},
        {pos: [5, 0, 1], state: "minecraft:bricks"},
        {pos: [5, 0, 2], state: "minecraft:bricks"},
        {pos: [5, 0, 3], state: "minecraft:bricks"},
        {pos: [5, 0, 4], state: "minecraft:bricks"},
        {pos: [5, 0, 5], state: "minecraft:bricks"},
        {pos: [5, 0, 6], state: "minecraft:bricks"},
        {pos: [5, 0, 7], state: "minecraft:bricks"},
        {pos: [5, 0, 8], state: "minecraft:bricks"},
        {pos: [5, 0, 9], state: "minecraft:bricks"},
        {pos: [5, 0, 10], state: "minecraft:bricks"},
        {pos: [6, 0, 0], state: "minecraft:bricks"},
        {pos: [6, 0, 1], state: "minecraft:bricks"},
        {pos: [6, 0, 2], state: "minecraft:bricks"},
        {pos: [6, 0, 3], state: "minecraft:bricks"},
        {pos: [6, 0, 4], state: "minecraft:bricks"},
        {pos: [6, 0, 5], state: "minecraft:bricks"},
        {pos: [6, 0, 6], state: "minecraft:bricks"},
        {pos: [6, 0, 7], state: "minecraft:bricks"},
        {pos: [6, 0, 8], state: "minecraft:bricks"},
        {pos: [6, 0, 9], state: "minecraft:bricks"},
        {pos: [6, 0, 10], state: "minecraft:bricks"},
        {pos: [7, 0, 4], state: "minecraft:bricks"},
        {pos: [7, 0, 5], state: "minecraft:bricks"},
        {pos: [7, 0, 6], state: "minecraft:bricks"},
        {pos: [7, 0, 7], state: "minecraft:bricks"},
        {pos: [7, 0, 8], state: "minecraft:bricks"},
        {pos: [7, 0, 9], state: "minecraft:bricks"},
        {pos: [7, 0, 10], state: "minecraft:bricks"},
        {pos: [8, 0, 5], state: "minecraft:bricks"},
        {pos: [8, 0, 6], state: "minecraft:bricks"},
        {pos: [8, 0, 7], state: "minecraft:bricks"},
        {pos: [8, 0, 8], state: "minecraft:bricks"},
        {pos: [8, 0, 9], state: "minecraft:bricks"},
        {pos: [8, 0, 10], state: "minecraft:bricks"},
        {pos: [0, 1, 1], state: "minecraft:stone_bricks"},
        {pos: [0, 1, 2], state: "minecraft:blue_terracotta"},
        {pos: [0, 1, 3], state: "minecraft:blue_terracotta"},
        {pos: [0, 1, 4], state: "minecraft:blue_terracotta"},
        {pos: [0, 1, 5], state: "minecraft:blue_terracotta"},
        {pos: [0, 1, 6], state: "minecraft:blue_terracotta"},
        {pos: [0, 1, 7], state: "minecraft:blue_terracotta"},
        {pos: [0, 1, 8], state: "minecraft:blue_terracotta"},
        {pos: [1, 1, 1], state: "minecraft:purple_glazed_terracotta{facing:south}"},
        {pos: [1, 1, 2], state: "minecraft:purple_glazed_terracotta{facing:east}"},
        {pos: [1, 1, 3], state: "minecraft:sand"},
        {pos: [1, 1, 4], state: "minecraft:sand"},
        {pos: [1, 1, 5], state: "minecraft:blue_terracotta"},
        {pos: [1, 1, 6], state: "minecraft:sand"},
        {pos: [1, 1, 7], state: "minecraft:sand"},
        {pos: [1, 1, 8], state: "minecraft:sand"},
        {pos: [1, 1, 9], state: "minecraft:blue_terracotta"},
        {pos: [2, 1, 0], state: "minecraft:bricks"},
        {pos: [2, 1, 1], state: "minecraft:purple_glazed_terracotta{facing:west}"},
        {pos: [2, 1, 2], state: "minecraft:purple_glazed_terracotta{facing:north}"},
        {pos: [2, 1, 3], state: "minecraft:sand"},
        {pos: [2, 1, 4], state: "minecraft:sand"},
        {pos: [2, 1, 5], state: "minecraft:cauldron"},
        {pos: [2, 1, 6], state: "minecraft:sand"},
        {pos: [2, 1, 7], state: "minecraft:blue_terracotta"},
        {pos: [2, 1, 8], state: "minecraft:smooth_stone"},
        {pos: [2, 1, 9], state: "minecraft:blue_terracotta"},
        {pos: [3, 1, 0], state: "minecraft:bricks"},
        {pos: [3, 1, 1], state: "minecraft:gray_terracotta"},
        {pos: [3, 1, 2], state: "minecraft:gray_terracotta"},
        {pos: [3, 1, 3], state: "minecraft:brick_stairs{facing:north,half:bottom,shape:straight,waterlogged:false}"},
        {pos: [3, 1, 4], state: "minecraft:sand"},
        {pos: [3, 1, 5], state: "minecraft:smithing_table"},
        {pos: [3, 1, 6], state: "minecraft:sand"},
        {pos: [3, 1, 7], state: "minecraft:sand"},
        {pos: [3, 1, 8], state: "minecraft:stonecutter{facing:north}"},
        {pos: [3, 1, 9], state: "minecraft:blue_terracotta"},
        {pos: [4, 1, 0], state: "minecraft:bricks"},
        {pos: [4, 1, 1], state: "minecraft:purple_glazed_terracotta{facing:south}"},
        {pos: [4, 1, 2], state: "minecraft:purple_glazed_terracotta{facing:east}"},
        {pos: [4, 1, 3], state: "minecraft:sand"},
        {pos: [4, 1, 4], state: "minecraft:sand"},
        {pos: [4, 1, 5], state: "minecraft:smooth_stone_slab{type:double,waterlogged:false}"},
        {pos: [4, 1, 6], state: "minecraft:blue_terracotta"},
        {pos: [4, 1, 7], state: "minecraft:sand"},
        {pos: [4, 1, 8], state: "minecraft:smooth_stone_slab{type:bottom,waterlogged:false}"},
        {pos: [4, 1, 9], state: "minecraft:sand"},
        {pos: [4, 1, 10], state: "minecraft:blue_terracotta"},
        {pos: [5, 1, 0], state: "minecraft:stone_bricks"},
        {pos: [5, 1, 1], state: "minecraft:purple_glazed_terracotta{facing:west}"},
        {pos: [5, 1, 2], state: "minecraft:purple_glazed_terracotta{facing:north}"},
        {pos: [5, 1, 4], state: "minecraft:blue_terracotta"},
        {pos: [5, 1, 6], state: "minecraft:sand"},
        {pos: [5, 1, 7], state: "minecraft:sand"},
        {pos: [5, 1, 9], state: "minecraft:sand"},
        {pos: [5, 1, 10], state: "minecraft:blue_terracotta"},
        {pos: [6, 1, 1], state: "minecraft:stone_bricks"},
        {pos: [6, 1, 2], state: "minecraft:blue_terracotta"},
        {pos: [6, 1, 3], state: "minecraft:blue_terracotta"},
        {pos: [6, 1, 5], state: "minecraft:blue_terracotta"},
        {pos: [6, 1, 6], state: "minecraft:sand"},
        {pos: [6, 1, 8], state: "minecraft:bricks"},
        {pos: [6, 1, 9], state: "minecraft:bricks"},
        {pos: [6, 1, 10], state: "minecraft:bricks"},
        {pos: [7, 1, 4], state: "minecraft:blue_terracotta"},
        {pos: [7, 1, 5], state: "minecraft:sand"},
        {pos: [7, 1, 7], state: "minecraft:sand"},
        {pos: [7, 1, 8], state: "minecraft:bricks"},
        {pos: [7, 1, 9], state: "minecraft:sand"},
        {pos: [7, 1, 10], state: "minecraft:bricks"},
        {pos: [8, 1, 5], state: "minecraft:blue_terracotta"},
        {pos: [8, 1, 6], state: "minecraft:blue_terracotta"},
        {pos: [8, 1, 7], state: "minecraft:blue_terracotta"},
        {pos: [8, 1, 8], state: "minecraft:bricks"},
        {pos: [8, 1, 9], state: "minecraft:bricks"},
        {pos: [8, 1, 10], state: "minecraft:bricks"},
        {pos: [0, 2, 1], state: "minecraft:blue_terracotta"},
        {pos: [0, 2, 2], state: "minecraft:blue_terracotta"},
        {pos: [0, 2, 3], state: "minecraft:blue_terracotta"},
        {pos: [0, 2, 4], state: "minecraft:blue_terracotta"},
        {pos: [0, 2, 5], state: "minecraft:cyan_terracotta"},
        {pos: [0, 2, 6], state: "minecraft:cyan_terracotta"},
        {pos: [0, 2, 7], state: "minecraft:cyan_terracotta"},
        {pos: [0, 2, 8], state: "minecraft:cyan_terracotta"},
        {pos: [1, 2, 0], state: "minecraft:blue_terracotta"},
        {pos: [1, 2, 1], state: "minecraft:sand"},
        {pos: [1, 2, 2], state: "minecraft:sand"},
        {pos: [1, 2, 3], state: "minecraft:sand"},
        {pos: [1, 2, 4], state: "minecraft:sand"},
        {pos: [1, 2, 5], state: "minecraft:sand"},
        {pos: [1, 2, 6], state: "minecraft:sand"},
        {pos: [1, 2, 7], state: "minecraft:sand"},
        {pos: [1, 2, 8], state: "minecraft:sand"},
        {pos: [1, 2, 9], state: "minecraft:cyan_terracotta"},
        {pos: [2, 2, 0], state: "minecraft:blue_terracotta"},
        {pos: [2, 2, 1], state: "minecraft:sand"},
        {pos: [2, 2, 2], state: "minecraft:sand"},
        {pos: [2, 2, 4], state: "minecraft:sand"},
        {pos: [2, 2, 5], state: "minecraft:sand"},
        {pos: [2, 2, 6], state: "minecraft:sand"},
        {pos: [2, 2, 7], state: "minecraft:sand"},
        {pos: [2, 2, 8], state: "minecraft:sand"},
        {pos: [3, 2, 0], state: "minecraft:jigsaw{orientation:north_up}", nbt: {final_state: "minecraft:sand", id: "minecraft:jigsaw", joint: "rollable", name: "minecraft:building_anchor", pool: "minecraft:trail_ruins/roads", target: "minecraft:road_anchor"}},
        {pos: [3, 2, 1], state: "minecraft:sand"},
        {pos: [3, 2, 2], state: "minecraft:sand"},
        {pos: [3, 2, 6], state: "minecraft:sand"},
        {pos: [3, 2, 7], state: "minecraft:sand"},
        {pos: [3, 2, 8], state: "minecraft:sand"},
        {pos: [3, 2, 9], state: "minecraft:cyan_terracotta"},
        {pos: [4, 2, 0], state: "minecraft:sand"},
        {pos: [4, 2, 1], state: "minecraft:sand"},
        {pos: [4, 2, 2], state: "minecraft:sand"},
        {pos: [4, 2, 3], state: "minecraft:sand"},
        {pos: [4, 2, 4], state: "minecraft:sand"},
        {pos: [4, 2, 5], state: "minecraft:sand"},
        {pos: [4, 2, 6], state: "minecraft:sand"},
        {pos: [4, 2, 7], state: "minecraft:sand"},
        {pos: [4, 2, 8], state: "minecraft:sand"},
        {pos: [5, 2, 0], state: "minecraft:sand"},
        {pos: [5, 2, 1], state: "minecraft:sand"},
        {pos: [5, 2, 2], state: "minecraft:sand"},
        {pos: [5, 2, 4], state: "minecraft:sand"},
        {pos: [5, 2, 7], state: "minecraft:sand"},
        {pos: [5, 2, 9], state: "minecraft:sand"},
        {pos: [5, 2, 10], state: "minecraft:cyan_terracotta"},
        {pos: [6, 2, 1], state: "minecraft:blue_terracotta"},
        {pos: [6, 2, 2], state: "minecraft:blue_terracotta"},
        {pos: [6, 2, 3], state: "minecraft:blue_terracotta"},
        {pos: [6, 2, 5], state: "minecraft:sand"},
        {pos: [6, 2, 6], state: "minecraft:sand"},
        {pos: [6, 2, 8], state: "minecraft:sand"},
        {pos: [6, 2, 10], state: "minecraft:bricks"},
        {pos: [7, 2, 4], state: "minecraft:cyan_terracotta"},
        {pos: [7, 2, 7], state: "minecraft:sand"},
        {pos: [7, 2, 8], state: "minecraft:blast_furnace{facing:west,lit:false}", nbt: {BurnTime: 0s, CookTime: 0s, CookTimeTotal: 0s, Items: [], RecipesUsed: {}, id: "minecraft:blast_furnace"}},
        {pos: [7, 2, 10], state: "minecraft:iron_bars{east:true,north:false,south:false,waterlogged:false,west:true}"},
        {pos: [8, 2, 5], state: "minecraft:cyan_terracotta"},
        {pos: [8, 2, 7], state: "minecraft:cyan_terracotta"},
        {pos: [8, 2, 8], state: "minecraft:bricks"},
        {pos: [8, 2, 9], state: "minecraft:bricks"},
        {pos: [8, 2, 10], state: "minecraft:bricks"},
        {pos: [0, 3, 1], state: "minecraft:cyan_terracotta"},
        {pos: [0, 3, 2], state: "minecraft:cyan_terracotta"},
        {pos: [0, 3, 3], state: "minecraft:cyan_terracotta"},
        {pos: [0, 3, 4], state: "minecraft:cyan_terracotta"},
        {pos: [0, 3, 6], state: "minecraft:cyan_terracotta"},
        {pos: [1, 3, 0], state: "minecraft:sand"},
        {pos: [1, 3, 2], state: "minecraft:sand"},
        {pos: [1, 3, 3], state: "minecraft:sand"},
        {pos: [1, 3, 4], state: "minecraft:sand"},
        {pos: [1, 3, 5], state: "minecraft:sand"},
        {pos: [1, 3, 6], state: "minecraft:sand"},
        {pos: [1, 3, 9], state: "minecraft:cyan_terracotta"},
        {pos: [2, 3, 0], state: "minecraft:sand"},
        {pos: [2, 3, 4], state: "minecraft:sand"},
        {pos: [2, 3, 5], state: "minecraft:sand"},
        {pos: [2, 3, 6], state: "minecraft:sand"},
        {pos: [2, 3, 7], state: "minecraft:sand"},
        {pos: [3, 3, 6], state: "minecraft:sand"},
        {pos: [3, 3, 7], state: "minecraft:sand"},
        {pos: [3, 3, 9], state: "minecraft:cyan_terracotta"},
        {pos: [4, 3, 1], state: "minecraft:sand"},
        {pos: [4, 3, 5], state: "minecraft:sand"},
        {pos: [4, 3, 6], state: "minecraft:sand"},
        {pos: [5, 3, 7], state: "minecraft:sand"},
        {pos: [5, 3, 10], state: "minecraft:cyan_terracotta"},
        {pos: [6, 3, 1], state: "minecraft:cyan_terracotta"},
        {pos: [6, 3, 2], state: "minecraft:cyan_terracotta"},
        {pos: [6, 3, 3], state: "minecraft:cyan_terracotta"},
        {pos: [6, 3, 8], state: "minecraft:sand"},
        {pos: [6, 3, 10], state: "minecraft:bricks"},
        {pos: [7, 3, 8], state: "minecraft:furnace{facing:west,lit:false}", nbt: {BurnTime: 0s, CookTime: 0s, CookTimeTotal: 0s, Items: [], RecipesUsed: {}, id: "minecraft:furnace"}},
        {pos: [7, 3, 10], state: "minecraft:iron_bars{east:true,north:false,south:false,waterlogged:false,west:true}"},
        {pos: [8, 3, 5], state: "minecraft:cyan_terracotta"},
        {pos: [8, 3, 7], state: "minecraft:cyan_terracotta"},
        {pos: [8, 3, 8], state: "minecraft:bricks"},
        {pos: [8, 3, 9], state: "minecraft:bricks"},
        {pos: [8, 3, 10], state: "minecraft:bricks"},
        {pos: [0, 4, 2], state: "minecraft:cyan_terracotta"},
        {pos: [0, 4, 4], state: "minecraft:cyan_terracotta"},
        {pos: [0, 4, 6], state: "minecraft:cyan_terracotta"},
        {pos: [1, 4, 3], state: "minecraft:sand"},
        {pos: [6, 4, 2], state: "minecraft:cyan_terracotta"},
        {pos: [6, 4, 8], state: "minecraft:sand"},
        {pos: [6, 4, 10], state: "minecraft:bricks"},
        {pos: [8, 4, 9], state: "minecraft:bricks"},
        {pos: [0, 5, 4], state: "minecraft:cyan_terracotta"},
        {pos: [0, 5, 6], state: "minecraft:cyan_terracotta"},
        {pos: [8, 5, 9], state: "minecraft:bricks"},
        {pos: [8, 5, 10], state: "minecraft:bricks"}
    ],
    entities: [],
    palette: [
        "minecraft:bricks",
        "minecraft:stone_bricks",
        "minecraft:blue_terracotta",
        "minecraft:purple_glazed_terracotta{facing:south}",
        "minecraft:purple_glazed_terracotta{facing:east}",
        "minecraft:sand",
        "minecraft:purple_glazed_terracotta{facing:west}",
        "minecraft:purple_glazed_terracotta{facing:north}",
        "minecraft:smooth_stone",
        "minecraft:gray_terracotta",
        "minecraft:smithing_table",
        "minecraft:smooth_stone_slab{type:double,waterlogged:false}",
        "minecraft:cyan_terracotta",
        "minecraft:cauldron",
        "minecraft:brick_stairs{facing:north,half:bottom,shape:straight,waterlogged:false}",
        "minecraft:stonecutter{facing:north}",
        "minecraft:smooth_stone_slab{type:bottom,waterlogged:false}",
        "minecraft:iron_bars{east:true,north:false,south:false,waterlogged:false,west:true}",
        "minecraft:jigsaw{orientation:north_up}",
        "minecraft:blast_furnace{facing:west,lit:false}",
        "minecraft:furnace{facing:west,lit:false}"
    ]
}
