{
    size: [7, 10, 7],
    data: [
        {pos: [0, 0, 2], state: "minecraft:bricks"},
        {pos: [0, 0, 3], state: "minecraft:bricks"},
        {pos: [0, 0, 4], state: "minecraft:bricks"},
        {pos: [1, 0, 1], state: "minecraft:bricks"},
        {pos: [1, 0, 2], state: "minecraft:bricks"},
        {pos: [1, 0, 3], state: "minecraft:bricks"},
        {pos: [1, 0, 4], state: "minecraft:bricks"},
        {pos: [1, 0, 5], state: "minecraft:bricks"},
        {pos: [2, 0, 0], state: "minecraft:bricks"},
        {pos: [2, 0, 1], state: "minecraft:bricks"},
        {pos: [2, 0, 2], state: "minecraft:bricks"},
        {pos: [2, 0, 3], state: "minecraft:bricks"},
        {pos: [2, 0, 4], state: "minecraft:bricks"},
        {pos: [2, 0, 5], state: "minecraft:bricks"},
        {pos: [2, 0, 6], state: "minecraft:bricks"},
        {pos: [3, 0, 0], state: "minecraft:bricks"},
        {pos: [3, 0, 1], state: "minecraft:bricks"},
        {pos: [3, 0, 2], state: "minecraft:bricks"},
        {pos: [3, 0, 3], state: "minecraft:bricks"},
        {pos: [3, 0, 4], state: "minecraft:bricks"},
        {pos: [3, 0, 5], state: "minecraft:bricks"},
        {pos: [3, 0, 6], state: "minecraft:bricks"},
        {pos: [4, 0, 0], state: "minecraft:bricks"},
        {pos: [4, 0, 1], state: "minecraft:bricks"},
        {pos: [4, 0, 2], state: "minecraft:bricks"},
        {pos: [4, 0, 3], state: "minecraft:bricks"},
        {pos: [4, 0, 4], state: "minecraft:bricks"},
        {pos: [4, 0, 5], state: "minecraft:bricks"},
        {pos: [4, 0, 6], state: "minecraft:bricks"},
        {pos: [5, 0, 1], state: "minecraft:bricks"},
        {pos: [5, 0, 2], state: "minecraft:bricks"},
        {pos: [5, 0, 3], state: "minecraft:bricks"},
        {pos: [5, 0, 4], state: "minecraft:bricks"},
        {pos: [5, 0, 5], state: "minecraft:bricks"},
        {pos: [6, 0, 2], state: "minecraft:bricks"},
        {pos: [6, 0, 3], state: "minecraft:bricks"},
        {pos: [6, 0, 4], state: "minecraft:bricks"},
        {pos: [0, 1, 2], state: "minecraft:bricks"},
        {pos: [0, 1, 3], state: "minecraft:bricks"},
        {pos: [0, 1, 4], state: "minecraft:bricks"},
        {pos: [1, 1, 1], state: "minecraft:bricks"},
        {pos: [1, 1, 2], state: "minecraft:bricks"},
        {pos: [1, 1, 3], state: "minecraft:bricks"},
        {pos: [1, 1, 4], state: "minecraft:bricks"},
        {pos: [1, 1, 5], state: "minecraft:bricks"},
        {pos: [2, 1, 0], state: "minecraft:bricks"},
        {pos: [2, 1, 1], state: "minecraft:bricks"},
        {pos: [2, 1, 2], state: "minecraft:bricks"},
        {pos: [2, 1, 3], state: "minecraft:bricks"},
        {pos: [2, 1, 4], state: "minecraft:bricks"},
        {pos: [2, 1, 5], state: "minecraft:bricks"},
        {pos: [2, 1, 6], state: "minecraft:bricks"},
        {pos: [3, 1, 0], state: "minecraft:bricks"},
        {pos: [3, 1, 1], state: "minecraft:bricks"},
        {pos: [3, 1, 2], state: "minecraft:bricks"},
        {pos: [3, 1, 3], state: "minecraft:bricks"},
        {pos: [3, 1, 4], state: "minecraft:bricks"},
        {pos: [3, 1, 5], state: "minecraft:bricks"},
        {pos: [3, 1, 6], state: "minecraft:bricks"},
        {pos: [4, 1, 0], state: "minecraft:bricks"},
        {pos: [4, 1, 1], state: "minecraft:bricks"},
        {pos: [4, 1, 2], state: "minecraft:bricks"},
        {pos: [4, 1, 3], state: "minecraft:bricks"},
        {pos: [4, 1, 4], state: "minecraft:bricks"},
        {pos: [4, 1, 5], state: "minecraft:bricks"},
        {pos: [4, 1, 6], state: "minecraft:bricks"},
        {pos: [5, 1, 1], state: "minecraft:bricks"},
        {pos: [5, 1, 2], state: "minecraft:bricks"},
        {pos: [5, 1, 3], state: "minecraft:bricks"},
        {pos: [5, 1, 4], state: "minecraft:bricks"},
        {pos: [5, 1, 5], state: "minecraft:bricks"},
        {pos: [6, 1, 2], state: "minecraft:bricks"},
        {pos: [6, 1, 3], state: "minecraft:bricks"},
        {pos: [6, 1, 4], state: "minecraft:bricks"},
        {pos: [0, 2, 2], state: "minecraft:blue_terracotta"},
        {pos: [0, 2, 3], state: "minecraft:blue_terracotta"},
        {pos: [0, 2, 4], state: "minecraft:blue_terracotta"},
        {pos: [1, 2, 1], state: "minecraft:blue_terracotta"},
        {pos: [1, 2, 2], state: "minecraft:gravel"},
        {pos: [1, 2, 3], state: "minecraft:brick_slab{type:top,waterlogged:false}"},
        {pos: [1, 2, 4], state: "minecraft:brick_stairs{facing:west,half:bottom,shape:straight,waterlogged:false}"},
        {pos: [1, 2, 5], state: "minecraft:blue_terracotta"},
        {pos: [2, 2, 0], state: "minecraft:blue_terracotta"},
        {pos: [2, 2, 1], state: "minecraft:gravel"},
        {pos: [2, 2, 2], state: "minecraft:gravel"},
        {pos: [2, 2, 3], state: "minecraft:light_gray_terracotta"},
        {pos: [2, 2, 4], state: "minecraft:light_gray_terracotta"},
        {pos: [2, 2, 5], state: "minecraft:gravel"},
        {pos: [2, 2, 6], state: "minecraft:blue_terracotta"},
        {pos: [3, 2, 0], state: "minecraft:blue_terracotta"},
        {pos: [3, 2, 1], state: "minecraft:white_terracotta"},
        {pos: [3, 2, 2], state: "minecraft:gravel"},
        {pos: [3, 2, 3], state: "minecraft:gravel"},
        {pos: [3, 2, 4], state: "minecraft:gravel"},
        {pos: [3, 2, 5], state: "minecraft:gravel"},
        {pos: [3, 2, 6], state: "minecraft:jigsaw{orientation:south_up}", nbt: {final_state: "minecraft:dirt", id: "minecraft:jigsaw", joint: "rollable", name: "minecraft:building_anchor", pool: "minecraft:trail_ruins/roads", target: "minecraft:road_anchor"}},
        {pos: [4, 2, 0], state: "minecraft:gravel"},
        {pos: [4, 2, 1], state: "minecraft:gravel"},
        {pos: [4, 2, 2], state: "minecraft:bricks"},
        {pos: [4, 2, 3], state: "minecraft:gravel"},
        {pos: [4, 2, 4], state: "minecraft:brick_stairs{facing:east,half:bottom,shape:straight,waterlogged:false}"},
        {pos: [4, 2, 5], state: "minecraft:gravel"},
        {pos: [4, 2, 6], state: "minecraft:blue_terracotta"},
        {pos: [5, 2, 1], state: "minecraft:blue_terracotta"},
        {pos: [5, 2, 2], state: "minecraft:bricks"},
        {pos: [5, 2, 3], state: "minecraft:bricks"},
        {pos: [5, 2, 4], state: "minecraft:bricks"},
        {pos: [5, 2, 5], state: "minecraft:blue_terracotta"},
        {pos: [6, 2, 2], state: "minecraft:blue_terracotta"},
        {pos: [6, 2, 3], state: "minecraft:blue_terracotta"},
        {pos: [6, 2, 4], state: "minecraft:blue_terracotta"},
        {pos: [0, 3, 2], state: "minecraft:blue_terracotta"},
        {pos: [0, 3, 3], state: "minecraft:white_terracotta"},
        {pos: [0, 3, 4], state: "minecraft:blue_terracotta"},
        {pos: [1, 3, 1], state: "minecraft:blue_terracotta"},
        {pos: [1, 3, 2], state: "minecraft:gravel"},
        {pos: [1, 3, 3], state: "minecraft:gravel"},
        {pos: [1, 3, 4], state: "minecraft:white_terracotta"},
        {pos: [1, 3, 5], state: "minecraft:blue_terracotta"},
        {pos: [2, 3, 0], state: "minecraft:blue_terracotta"},
        {pos: [2, 3, 1], state: "minecraft:gravel"},
        {pos: [2, 3, 2], state: "minecraft:gravel"},
        {pos: [2, 3, 3], state: "minecraft:gravel"},
        {pos: [2, 3, 4], state: "minecraft:gravel"},
        {pos: [2, 3, 5], state: "minecraft:gravel"},
        {pos: [2, 3, 6], state: "minecraft:blue_terracotta"},
        {pos: [3, 3, 0], state: "minecraft:gravel"},
        {pos: [3, 3, 1], state: "minecraft:gravel"},
        {pos: [3, 3, 2], state: "minecraft:gravel"},
        {pos: [3, 3, 3], state: "minecraft:gravel"},
        {pos: [3, 3, 4], state: "minecraft:gravel"},
        {pos: [3, 3, 5], state: "minecraft:gravel"},
        {pos: [3, 3, 6], state: "minecraft:gravel"},
        {pos: [4, 3, 0], state: "minecraft:blue_terracotta"},
        {pos: [4, 3, 1], state: "minecraft:gravel"},
        {pos: [4, 3, 2], state: "minecraft:bricks"},
        {pos: [4, 3, 3], state: "minecraft:gravel"},
        {pos: [4, 3, 4], state: "minecraft:gravel"},
        {pos: [4, 3, 5], state: "minecraft:gravel"},
        {pos: [4, 3, 6], state: "minecraft:blue_terracotta"},
        {pos: [5, 3, 1], state: "minecraft:blue_terracotta"},
        {pos: [5, 3, 2], state: "minecraft:bricks"},
        {pos: [5, 3, 3], state: "minecraft:brick_stairs{facing:north,half:bottom,shape:straight,waterlogged:false}"},
        {pos: [5, 3, 4], state: "minecraft:gravel"},
        {pos: [5, 3, 5], state: "minecraft:blue_terracotta"},
        {pos: [6, 3, 2], state: "minecraft:blue_terracotta"},
        {pos: [6, 3, 3], state: "minecraft:white_terracotta"},
        {pos: [6, 3, 4], state: "minecraft:blue_terracotta"},
        {pos: [0, 4, 2], state: "minecraft:white_terracotta"},
        {pos: [0, 4, 3], state: "minecraft:white_terracotta"},
        {pos: [0, 4, 4], state: "minecraft:white_terracotta"},
        {pos: [1, 4, 1], state: "minecraft:white_terracotta"},
        {pos: [1, 4, 2], state: "minecraft:gravel"},
        {pos: [1, 4, 3], state: "minecraft:gravel"},
        {pos: [1, 4, 4], state: "minecraft:gravel"},
        {pos: [1, 4, 5], state: "minecraft:white_terracotta"},
        {pos: [2, 4, 0], state: "minecraft:white_terracotta"},
        {pos: [2, 4, 1], state: "minecraft:gravel"},
        {pos: [2, 4, 2], state: "minecraft:gravel"},
        {pos: [2, 4, 3], state: "minecraft:gravel"},
        {pos: [2, 4, 4], state: "minecraft:gravel"},
        {pos: [2, 4, 5], state: "minecraft:gravel"},
        {pos: [2, 4, 6], state: "minecraft:white_terracotta"},
        {pos: [3, 4, 0], state: "minecraft:gravel"},
        {pos: [3, 4, 1], state: "minecraft:gravel"},
        {pos: [3, 4, 2], state: "minecraft:bricks"},
        {pos: [3, 4, 3], state: "minecraft:gravel"},
        {pos: [3, 4, 4], state: "minecraft:gravel"},
        {pos: [3, 4, 5], state: "minecraft:gravel"},
        {pos: [3, 4, 6], state: "minecraft:white_terracotta"},
        {pos: [4, 4, 0], state: "minecraft:gravel"},
        {pos: [4, 4, 1], state: "minecraft:gravel"},
        {pos: [4, 4, 2], state: "minecraft:gravel"},
        {pos: [4, 4, 3], state: "minecraft:gravel"},
        {pos: [4, 4, 4], state: "minecraft:gravel"},
        {pos: [4, 4, 5], state: "minecraft:gravel"},
        {pos: [4, 4, 6], state: "minecraft:white_terracotta"},
        {pos: [5, 4, 1], state: "minecraft:gravel"},
        {pos: [5, 4, 2], state: "minecraft:gravel"},
        {pos: [5, 4, 3], state: "minecraft:gravel"},
        {pos: [5, 4, 4], state: "minecraft:gravel"},
        {pos: [5, 4, 5], state: "minecraft:white_terracotta"},
        {pos: [6, 4, 2], state: "minecraft:white_terracotta"},
        {pos: [6, 4, 3], state: "minecraft:white_terracotta"},
        {pos: [6, 4, 4], state: "minecraft:white_terracotta"},
        {pos: [0, 5, 2], state: "minecraft:white_terracotta"},
        {pos: [0, 5, 3], state: "minecraft:blue_terracotta"},
        {pos: [0, 5, 4], state: "minecraft:white_terracotta"},
        {pos: [1, 5, 1], state: "minecraft:white_terracotta"},
        {pos: [1, 5, 2], state: "minecraft:gravel"},
        {pos: [1, 5, 3], state: "minecraft:gravel"},
        {pos: [1, 5, 4], state: "minecraft:gravel"},
        {pos: [1, 5, 5], state: "minecraft:white_terracotta"},
        {pos: [2, 5, 0], state: "minecraft:white_terracotta"},
        {pos: [2, 5, 1], state: "minecraft:gravel"},
        {pos: [2, 5, 2], state: "minecraft:bricks"},
        {pos: [2, 5, 3], state: "minecraft:bricks"},
        {pos: [2, 5, 4], state: "minecraft:gravel"},
        {pos: [2, 5, 5], state: "minecraft:gravel"},
        {pos: [2, 5, 6], state: "minecraft:white_terracotta"},
        {pos: [3, 5, 0], state: "minecraft:gravel"},
        {pos: [3, 5, 1], state: "minecraft:gravel"},
        {pos: [3, 5, 2], state: "minecraft:brick_stairs{facing:west,half:bottom,shape:straight,waterlogged:false}"},
        {pos: [3, 5, 3], state: "minecraft:gravel"},
        {pos: [3, 5, 4], state: "minecraft:gravel"},
        {pos: [3, 5, 5], state: "minecraft:gravel"},
        {pos: [3, 5, 6], state: "minecraft:blue_terracotta"},
        {pos: [4, 5, 0], state: "minecraft:gravel"},
        {pos: [4, 5, 1], state: "minecraft:gravel"},
        {pos: [4, 5, 2], state: "minecraft:gravel"},
        {pos: [4, 5, 3], state: "minecraft:gravel"},
        {pos: [4, 5, 4], state: "minecraft:gravel"},
        {pos: [4, 5, 5], state: "minecraft:gravel"},
        {pos: [4, 5, 6], state: "minecraft:white_terracotta"},
        {pos: [5, 5, 1], state: "minecraft:gravel"},
        {pos: [5, 5, 2], state: "minecraft:gravel"},
        {pos: [5, 5, 3], state: "minecraft:gravel"},
        {pos: [5, 5, 4], state: "minecraft:gravel"},
        {pos: [5, 5, 5], state: "minecraft:white_terracotta"},
        {pos: [6, 5, 2], state: "minecraft:white_terracotta"},
        {pos: [6, 5, 3], state: "minecraft:blue_terracotta"},
        {pos: [6, 5, 4], state: "minecraft:white_terracotta"},
        {pos: [0, 6, 2], state: "minecraft:white_terracotta"},
        {pos: [0, 6, 3], state: "minecraft:white_terracotta"},
        {pos: [0, 6, 4], state: "minecraft:white_terracotta"},
        {pos: [1, 6, 1], state: "minecraft:white_terracotta"},
        {pos: [1, 6, 2], state: "minecraft:light_gray_terracotta"},
        {pos: [1, 6, 3], state: "minecraft:gravel"},
        {pos: [1, 6, 4], state: "minecraft:gravel"},
        {pos: [1, 6, 5], state: "minecraft:white_terracotta"},
        {pos: [2, 6, 0], state: "minecraft:white_terracotta"},
        {pos: [2, 6, 1], state: "minecraft:light_gray_terracotta"},
        {pos: [2, 6, 2], state: "minecraft:gravel"},
        {pos: [2, 6, 3], state: "minecraft:brick_stairs{facing:south,half:bottom,shape:straight,waterlogged:false}"},
        {pos: [2, 6, 4], state: "minecraft:gravel"},
        {pos: [2, 6, 5], state: "minecraft:light_gray_terracotta"},
        {pos: [2, 6, 6], state: "minecraft:white_terracotta"},
        {pos: [3, 6, 0], state: "minecraft:gravel"},
        {pos: [3, 6, 1], state: "minecraft:gravel"},
        {pos: [3, 6, 2], state: "minecraft:gravel"},
        {pos: [3, 6, 3], state: "minecraft:light_gray_terracotta"},
        {pos: [3, 6, 4], state: "minecraft:light_gray_terracotta"},
        {pos: [3, 6, 5], state: "minecraft:light_gray_terracotta"},
        {pos: [3, 6, 6], state: "minecraft:white_terracotta"},
        {pos: [4, 6, 0], state: "minecraft:gravel"},
        {pos: [4, 6, 1], state: "minecraft:gravel"},
        {pos: [4, 6, 2], state: "minecraft:gravel"},
        {pos: [4, 6, 3], state: "minecraft:light_gray_terracotta"},
        {pos: [4, 6, 4], state: "minecraft:light_gray_terracotta"},
        {pos: [4, 6, 5], state: "minecraft:light_gray_terracotta"},
        {pos: [4, 6, 6], state: "minecraft:white_terracotta"},
        {pos: [5, 6, 1], state: "minecraft:gravel"},
        {pos: [5, 6, 2], state: "minecraft:gravel"},
        {pos: [5, 6, 3], state: "minecraft:light_gray_terracotta"},
        {pos: [5, 6, 4], state: "minecraft:light_gray_terracotta"},
        {pos: [5, 6, 5], state: "minecraft:white_terracotta"},
        {pos: [6, 6, 2], state: "minecraft:white_terracotta"},
        {pos: [6, 6, 3], state: "minecraft:white_terracotta"},
        {pos: [6, 6, 4], state: "minecraft:white_terracotta"},
        {pos: [1, 7, 2], state: "minecraft:light_gray_terracotta"},
        {pos: [1, 7, 3], state: "minecraft:white_terracotta"},
        {pos: [1, 7, 4], state: "minecraft:gravel"},
        {pos: [2, 7, 1], state: "minecraft:light_gray_terracotta"},
        {pos: [2, 7, 2], state: "minecraft:gravel"},
        {pos: [2, 7, 3], state: "minecraft:gravel"},
        {pos: [2, 7, 4], state: "minecraft:gravel"},
        {pos: [2, 7, 5], state: "minecraft:light_gray_terracotta"},
        {pos: [3, 7, 1], state: "minecraft:white_terracotta"},
        {pos: [3, 7, 2], state: "minecraft:gravel"},
        {pos: [3, 7, 3], state: "minecraft:cartography_table"},
        {pos: [3, 7, 4], state: "minecraft:gravel"},
        {pos: [3, 7, 5], state: "minecraft:white_terracotta"},
        {pos: [4, 7, 1], state: "minecraft:gravel"},
        {pos: [4, 7, 2], state: "minecraft:gravel"},
        {pos: [4, 7, 3], state: "minecraft:gravel"},
        {pos: [4, 7, 4], state: "minecraft:gravel"},
        {pos: [4, 7, 5], state: "minecraft:light_gray_terracotta"},
        {pos: [5, 7, 1], state: "minecraft:gravel"},
        {pos: [5, 7, 2], state: "minecraft:gravel"},
        {pos: [5, 7, 3], state: "minecraft:white_terracotta"},
        {pos: [5, 7, 4], state: "minecraft:light_gray_terracotta"},
        {pos: [1, 8, 2], state: "minecraft:white_terracotta"},
        {pos: [1, 8, 3], state: "minecraft:light_gray_terracotta"},
        {pos: [1, 8, 4], state: "minecraft:white_terracotta"},
        {pos: [2, 8, 1], state: "minecraft:white_terracotta"},
        {pos: [2, 8, 2], state: "minecraft:gravel"},
        {pos: [2, 8, 3], state: "minecraft:gravel"},
        {pos: [2, 8, 4], state: "minecraft:gravel"},
        {pos: [2, 8, 5], state: "minecraft:white_terracotta"},
        {pos: [3, 8, 1], state: "minecraft:light_gray_terracotta"},
        {pos: [3, 8, 2], state: "minecraft:gravel"},
        {pos: [3, 8, 3], state: "minecraft:gravel"},
        {pos: [3, 8, 4], state: "minecraft:gravel"},
        {pos: [3, 8, 5], state: "minecraft:light_gray_terracotta"},
        {pos: [4, 8, 1], state: "minecraft:gravel"},
        {pos: [4, 8, 2], state: "minecraft:gravel"},
        {pos: [4, 8, 3], state: "minecraft:gravel"},
        {pos: [4, 8, 4], state: "minecraft:gravel"},
        {pos: [4, 8, 5], state: "minecraft:white_terracotta"},
        {pos: [5, 8, 2], state: "minecraft:gravel"},
        {pos: [5, 8, 3], state: "minecraft:light_gray_terracotta"},
        {pos: [5, 8, 4], state: "minecraft:white_terracotta"},
        {pos: [2, 9, 2], state: "minecraft:white_terracotta"},
        {pos: [2, 9, 3], state: "minecraft:white_terracotta"},
        {pos: [2, 9, 4], state: "minecraft:white_terracotta"},
        {pos: [3, 9, 2], state: "minecraft:gravel"},
        {pos: [3, 9, 3], state: "minecraft:gravel"},
        {pos: [3, 9, 4], state: "minecraft:white_terracotta"},
        {pos: [4, 9, 2], state: "minecraft:gravel"},
        {pos: [4, 9, 3], state: "minecraft:gravel"},
        {pos: [4, 9, 4], state: "minecraft:white_terracotta"}
    ],
    entities: [],
    palette: [
        "minecraft:bricks",
        "minecraft:blue_terracotta",
        "minecraft:gravel",
        "minecraft:light_gray_terracotta",
        "minecraft:white_terracotta",
        "minecraft:cartography_table",
        "minecraft:brick_slab{type:top,waterlogged:false}",
        "minecraft:brick_stairs{facing:west,half:bottom,shape:straight,waterlogged:false}",
        "minecraft:brick_stairs{facing:east,half:bottom,shape:straight,waterlogged:false}",
        "minecraft:brick_stairs{facing:north,half:bottom,shape:straight,waterlogged:false}",
        "minecraft:brick_stairs{facing:south,half:bottom,shape:straight,waterlogged:false}",
        "minecraft:jigsaw{orientation:south_up}"
    ]
}
