{
    size: [7, 7, 7],
    data: [
        {pos: [0, 0, 2], state: "minecraft:red_terracotta"},
        {pos: [0, 0, 3], state: "minecraft:red_terracotta"},
        {pos: [0, 0, 4], state: "minecraft:red_terracotta"},
        {pos: [1, 0, 1], state: "minecraft:red_terracotta"},
        {pos: [1, 0, 2], state: "minecraft:red_terracotta"},
        {pos: [1, 0, 3], state: "minecraft:red_terracotta"},
        {pos: [1, 0, 4], state: "minecraft:red_terracotta"},
        {pos: [1, 0, 5], state: "minecraft:red_terracotta"},
        {pos: [2, 0, 0], state: "minecraft:red_terracotta"},
        {pos: [2, 0, 1], state: "minecraft:red_terracotta"},
        {pos: [2, 0, 2], state: "minecraft:red_terracotta"},
        {pos: [2, 0, 3], state: "minecraft:red_terracotta"},
        {pos: [2, 0, 4], state: "minecraft:red_terracotta"},
        {pos: [2, 0, 5], state: "minecraft:red_terracotta"},
        {pos: [2, 0, 6], state: "minecraft:red_terracotta"},
        {pos: [3, 0, 0], state: "minecraft:red_terracotta"},
        {pos: [3, 0, 1], state: "minecraft:red_terracotta"},
        {pos: [3, 0, 2], state: "minecraft:red_terracotta"},
        {pos: [3, 0, 3], state: "minecraft:red_terracotta"},
        {pos: [3, 0, 4], state: "minecraft:red_terracotta"},
        {pos: [3, 0, 5], state: "minecraft:red_terracotta"},
        {pos: [3, 0, 6], state: "minecraft:red_terracotta"},
        {pos: [4, 0, 0], state: "minecraft:red_terracotta"},
        {pos: [4, 0, 1], state: "minecraft:red_terracotta"},
        {pos: [4, 0, 2], state: "minecraft:red_terracotta"},
        {pos: [4, 0, 3], state: "minecraft:red_terracotta"},
        {pos: [4, 0, 4], state: "minecraft:red_terracotta"},
        {pos: [4, 0, 5], state: "minecraft:red_terracotta"},
        {pos: [4, 0, 6], state: "minecraft:red_terracotta"},
        {pos: [5, 0, 1], state: "minecraft:red_terracotta"},
        {pos: [5, 0, 2], state: "minecraft:red_terracotta"},
        {pos: [5, 0, 3], state: "minecraft:red_terracotta"},
        {pos: [5, 0, 4], state: "minecraft:red_terracotta"},
        {pos: [5, 0, 5], state: "minecraft:red_terracotta"},
        {pos: [6, 0, 2], state: "minecraft:red_terracotta"},
        {pos: [6, 0, 3], state: "minecraft:red_terracotta"},
        {pos: [6, 0, 4], state: "minecraft:red_terracotta"},
        {pos: [0, 1, 2], state: "minecraft:red_terracotta"},
        {pos: [0, 1, 3], state: "minecraft:mud_bricks"},
        {pos: [0, 1, 4], state: "minecraft:red_terracotta"},
        {pos: [1, 1, 1], state: "minecraft:mud_bricks"},
        {pos: [1, 1, 2], state: "minecraft:sand"},
        {pos: [1, 1, 3], state: "minecraft:sand"},
        {pos: [1, 1, 4], state: "minecraft:sand"},
        {pos: [1, 1, 5], state: "minecraft:mud_bricks"},
        {pos: [2, 1, 0], state: "minecraft:red_terracotta"},
        {pos: [2, 1, 1], state: "minecraft:sand"},
        {pos: [2, 1, 2], state: "minecraft:sand"},
        {pos: [2, 1, 3], state: "minecraft:sand"},
        {pos: [2, 1, 4], state: "minecraft:sand"},
        {pos: [2, 1, 5], state: "minecraft:red_terracotta"},
        {pos: [2, 1, 6], state: "minecraft:red_terracotta"},
        {pos: [3, 1, 0], state: "minecraft:mud_bricks"},
        {pos: [3, 1, 1], state: "minecraft:sand"},
        {pos: [3, 1, 2], state: "minecraft:sand"},
        {pos: [3, 1, 3], state: "minecraft:sand"},
        {pos: [3, 1, 4], state: "minecraft:sand"},
        {pos: [3, 1, 5], state: "minecraft:red_terracotta"},
        {pos: [3, 1, 6], state: "minecraft:mud_bricks"},
        {pos: [4, 1, 0], state: "minecraft:red_terracotta"},
        {pos: [4, 1, 2], state: "minecraft:sand"},
        {pos: [4, 1, 3], state: "minecraft:red_terracotta"},
        {pos: [4, 1, 4], state: "minecraft:red_terracotta"},
        {pos: [4, 1, 5], state: "minecraft:red_terracotta"},
        {pos: [4, 1, 6], state: "minecraft:red_terracotta"},
        {pos: [5, 1, 1], state: "minecraft:mud_bricks"},
        {pos: [5, 1, 2], state: "minecraft:sand"},
        {pos: [5, 1, 3], state: "minecraft:sand"},
        {pos: [5, 1, 4], state: "minecraft:red_terracotta"},
        {pos: [5, 1, 5], state: "minecraft:mud_bricks"},
        {pos: [6, 1, 2], state: "minecraft:red_terracotta"},
        {pos: [6, 1, 3], state: "minecraft:mud_bricks"},
        {pos: [6, 1, 4], state: "minecraft:red_terracotta"},
        {pos: [0, 2, 2], state: "minecraft:mud_bricks"},
        {pos: [0, 2, 3], state: "minecraft:mud_bricks"},
        {pos: [0, 2, 4], state: "minecraft:mud_bricks"},
        {pos: [1, 2, 1], state: "minecraft:mud_bricks"},
        {pos: [1, 2, 2], state: "minecraft:sand"},
        {pos: [1, 2, 3], state: "minecraft:sand"},
        {pos: [1, 2, 4], state: "minecraft:sand"},
        {pos: [1, 2, 5], state: "minecraft:mud_bricks"},
        {pos: [2, 2, 0], state: "minecraft:mud_bricks"},
        {pos: [2, 2, 1], state: "minecraft:sand"},
        {pos: [2, 2, 2], state: "minecraft:sand"},
        {pos: [2, 2, 3], state: "minecraft:sand"},
        {pos: [2, 2, 4], state: "minecraft:sand"},
        {pos: [2, 2, 5], state: "minecraft:red_terracotta"},
        {pos: [2, 2, 6], state: "minecraft:mud_bricks"},
        {pos: [3, 2, 0], state: "minecraft:mud_bricks"},
        {pos: [3, 2, 1], state: "minecraft:sand"},
        {pos: [3, 2, 2], state: "minecraft:sand"},
        {pos: [3, 2, 3], state: "minecraft:sand"},
        {pos: [3, 2, 4], state: "minecraft:sand"},
        {pos: [3, 2, 5], state: "minecraft:sand"},
        {pos: [3, 2, 6], state: "minecraft:jigsaw{orientation:south_up}", nbt: {final_state: "minecraft:sand", id: "minecraft:jigsaw", joint: "rollable", name: "minecraft:building_anchor", pool: "minecraft:trail_ruins/roads", target: "minecraft:road_anchor"}},
        {pos: [4, 2, 0], state: "minecraft:mud_bricks"},
        {pos: [4, 2, 2], state: "minecraft:sand"},
        {pos: [4, 2, 3], state: "minecraft:red_terracotta"},
        {pos: [4, 2, 4], state: "minecraft:sand"},
        {pos: [4, 2, 5], state: "minecraft:sand"},
        {pos: [4, 2, 6], state: "minecraft:mud_bricks"},
        {pos: [5, 2, 1], state: "minecraft:mud_bricks"},
        {pos: [5, 2, 2], state: "minecraft:sand"},
        {pos: [5, 2, 3], state: "minecraft:sand"},
        {pos: [5, 2, 4], state: "minecraft:red_terracotta"},
        {pos: [5, 2, 5], state: "minecraft:mud_bricks"},
        {pos: [6, 2, 2], state: "minecraft:mud_bricks"},
        {pos: [6, 2, 3], state: "minecraft:mud_bricks"},
        {pos: [6, 2, 4], state: "minecraft:mud_bricks"},
        {pos: [0, 3, 2], state: "minecraft:mud_bricks"},
        {pos: [0, 3, 3], state: "minecraft:yellow_terracotta"},
        {pos: [0, 3, 4], state: "minecraft:mud_bricks"},
        {pos: [1, 3, 1], state: "minecraft:yellow_terracotta"},
        {pos: [1, 3, 2], state: "minecraft:red_terracotta"},
        {pos: [1, 3, 3], state: "minecraft:red_terracotta"},
        {pos: [1, 3, 4], state: "minecraft:red_terracotta"},
        {pos: [1, 3, 5], state: "minecraft:yellow_terracotta"},
        {pos: [2, 3, 0], state: "minecraft:mud_bricks"},
        {pos: [2, 3, 1], state: "minecraft:red_terracotta"},
        {pos: [2, 3, 2], state: "minecraft:red_terracotta"},
        {pos: [2, 3, 3], state: "minecraft:red_terracotta"},
        {pos: [2, 3, 4], state: "minecraft:red_terracotta"},
        {pos: [2, 3, 5], state: "minecraft:red_terracotta"},
        {pos: [2, 3, 6], state: "minecraft:mud_bricks"},
        {pos: [3, 3, 0], state: "minecraft:sand"},
        {pos: [3, 3, 1], state: "minecraft:sand"},
        {pos: [3, 3, 2], state: "minecraft:red_terracotta"},
        {pos: [3, 3, 3], state: "minecraft:sand"},
        {pos: [3, 3, 4], state: "minecraft:sand"},
        {pos: [3, 3, 5], state: "minecraft:sand"},
        {pos: [3, 3, 6], state: "minecraft:sand"},
        {pos: [4, 3, 0], state: "minecraft:mud_bricks"},
        {pos: [4, 3, 1], state: "minecraft:red_terracotta"},
        {pos: [4, 3, 2], state: "minecraft:red_terracotta"},
        {pos: [4, 3, 3], state: "minecraft:sand"},
        {pos: [4, 3, 4], state: "minecraft:sand"},
        {pos: [4, 3, 5], state: "minecraft:sand"},
        {pos: [4, 3, 6], state: "minecraft:mud_bricks"},
        {pos: [5, 3, 2], state: "minecraft:red_terracotta"},
        {pos: [5, 3, 3], state: "minecraft:red_terracotta"},
        {pos: [5, 3, 4], state: "minecraft:red_terracotta"},
        {pos: [5, 3, 5], state: "minecraft:yellow_terracotta"},
        {pos: [6, 3, 2], state: "minecraft:mud_bricks"},
        {pos: [6, 3, 3], state: "minecraft:sand"},
        {pos: [6, 3, 4], state: "minecraft:mud_bricks"},
        {pos: [0, 4, 2], state: "minecraft:yellow_terracotta"},
        {pos: [0, 4, 3], state: "minecraft:red_terracotta"},
        {pos: [0, 4, 4], state: "minecraft:yellow_terracotta"},
        {pos: [1, 4, 1], state: "minecraft:red_terracotta"},
        {pos: [1, 4, 2], state: "minecraft:sand"},
        {pos: [1, 4, 3], state: "minecraft:sand"},
        {pos: [1, 4, 4], state: "minecraft:sand"},
        {pos: [1, 4, 5], state: "minecraft:red_terracotta"},
        {pos: [2, 4, 0], state: "minecraft:yellow_terracotta"},
        {pos: [2, 4, 2], state: "minecraft:sand"},
        {pos: [2, 4, 3], state: "minecraft:sand"},
        {pos: [2, 4, 4], state: "minecraft:sand"},
        {pos: [2, 4, 6], state: "minecraft:yellow_terracotta"},
        {pos: [3, 4, 0], state: "minecraft:red_terracotta"},
        {pos: [3, 4, 2], state: "minecraft:sand"},
        {pos: [3, 4, 3], state: "minecraft:sand"},
        {pos: [3, 4, 4], state: "minecraft:sand"},
        {pos: [3, 4, 5], state: "minecraft:sand"},
        {pos: [3, 4, 6], state: "minecraft:orange_glazed_terracotta{facing:south}"},
        {pos: [4, 4, 2], state: "minecraft:sand"},
        {pos: [4, 4, 3], state: "minecraft:sand"},
        {pos: [4, 4, 4], state: "minecraft:sand"},
        {pos: [4, 4, 5], state: "minecraft:sand"},
        {pos: [4, 4, 6], state: "minecraft:yellow_terracotta"},
        {pos: [5, 4, 2], state: "minecraft:sand"},
        {pos: [5, 4, 3], state: "minecraft:sand"},
        {pos: [5, 4, 4], state: "minecraft:sand"},
        {pos: [5, 4, 5], state: "minecraft:red_terracotta"},
        {pos: [6, 4, 2], state: "minecraft:sand"},
        {pos: [6, 4, 3], state: "minecraft:sand"},
        {pos: [6, 4, 4], state: "minecraft:yellow_terracotta"},
        {pos: [0, 5, 2], state: "minecraft:yellow_terracotta"},
        {pos: [0, 5, 4], state: "minecraft:yellow_terracotta"},
        {pos: [1, 5, 1], state: "minecraft:red_terracotta"},
        {pos: [1, 5, 5], state: "minecraft:red_terracotta"},
        {pos: [2, 5, 3], state: "minecraft:sand"},
        {pos: [2, 5, 5], state: "minecraft:yellow_terracotta"},
        {pos: [3, 5, 3], state: "minecraft:sand"},
        {pos: [3, 5, 5], state: "minecraft:yellow_terracotta"},
        {pos: [3, 5, 6], state: "minecraft:yellow_terracotta"},
        {pos: [4, 5, 5], state: "minecraft:yellow_terracotta"},
        {pos: [5, 5, 4], state: "minecraft:yellow_terracotta"},
        {pos: [0, 6, 3], state: "minecraft:yellow_terracotta"},
        {pos: [1, 6, 2], state: "minecraft:red_terracotta"},
        {pos: [1, 6, 3], state: "minecraft:red_terracotta"},
        {pos: [1, 6, 4], state: "minecraft:red_terracotta"},
        {pos: [2, 6, 3], state: "minecraft:sand"},
        {pos: [2, 6, 4], state: "minecraft:red_terracotta"},
        {pos: [3, 6, 3], state: "minecraft:sand"},
        {pos: [3, 6, 4], state: "minecraft:red_terracotta"},
        {pos: [4, 6, 4], state: "minecraft:red_terracotta"}
    ],
    entities: [],
    palette: [
        "minecraft:red_terracotta",
        "minecraft:mud_bricks",
        "minecraft:sand",
        "minecraft:yellow_terracotta",
        "minecraft:orange_glazed_terracotta{facing:south}",
        "minecraft:jigsaw{orientation:south_up}"
    ]
}
