{
    DataVersion: 2856,
    size: [4, 3, 4],
    data: [
        {pos: [0, 0, 0], state: "minecraft:cobblestone"},
        {pos: [0, 0, 1], state: "minecraft:cobblestone"},
        {pos: [0, 0, 2], state: "minecraft:cobblestone"},
        {pos: [0, 0, 3], state: "minecraft:cobblestone"},
        {pos: [1, 0, 0], state: "minecraft:cobblestone"},
        {pos: [1, 0, 1], state: "minecraft:cobblestone"},
        {pos: [1, 0, 2], state: "minecraft:cobblestone"},
        {pos: [1, 0, 3], state: "minecraft:cobblestone"},
        {pos: [2, 0, 0], state: "minecraft:cobblestone"},
        {pos: [2, 0, 1], state: "minecraft:cobblestone"},
        {pos: [2, 0, 2], state: "minecraft:cobblestone"},
        {pos: [2, 0, 3], state: "minecraft:cobblestone"},
        {pos: [3, 0, 0], state: "minecraft:cobblestone"},
        {pos: [3, 0, 1], state: "minecraft:cobblestone"},
        {pos: [3, 0, 2], state: "minecraft:cobblestone"},
        {pos: [3, 0, 3], state: "minecraft:cobblestone"},
        {pos: [0, 1, 0], state: "minecraft:cobblestone"},
        {pos: [0, 1, 1], state: "minecraft:cobblestone"},
        {pos: [0, 1, 2], state: "minecraft:cobblestone"},
        {pos: [0, 1, 3], state: "minecraft:cobblestone"},
        {pos: [1, 1, 0], state: "minecraft:cobblestone"},
        {pos: [1, 1, 1], state: "minecraft:water{level:0}"},
        {pos: [1, 1, 2], state: "minecraft:water{level:0}"},
        {pos: [1, 1, 3], state: "minecraft:cobblestone"},
        {pos: [2, 1, 0], state: "minecraft:cobblestone"},
        {pos: [2, 1, 1], state: "minecraft:water{level:0}"},
        {pos: [2, 1, 2], state: "minecraft:water{level:0}"},
        {pos: [2, 1, 3], state: "minecraft:cobblestone"},
        {pos: [3, 1, 0], state: "minecraft:cobblestone"},
        {pos: [3, 1, 1], state: "minecraft:cobblestone"},
        {pos: [3, 1, 2], state: "minecraft:cobblestone"},
        {pos: [3, 1, 3], state: "minecraft:cobblestone"},
        {pos: [0, 2, 0], state: "minecraft:cobblestone"},
        {pos: [0, 2, 1], state: "minecraft:cobblestone"},
        {pos: [0, 2, 2], state: "minecraft:cobblestone"},
        {pos: [0, 2, 3], state: "minecraft:cobblestone"},
        {pos: [1, 2, 0], state: "minecraft:cobblestone"},
        {pos: [1, 2, 1], state: "minecraft:water{level:0}"},
        {pos: [1, 2, 2], state: "minecraft:water{level:0}"},
        {pos: [1, 2, 3], state: "minecraft:cobblestone"},
        {pos: [2, 2, 0], state: "minecraft:cobblestone"},
        {pos: [2, 2, 1], state: "minecraft:water{level:0}"},
        {pos: [2, 2, 2], state: "minecraft:water{level:0}"},
        {pos: [2, 2, 3], state: "minecraft:cobblestone"},
        {pos: [3, 2, 0], state: "minecraft:jigsaw{orientation:up_north}", nbt: {final_state: "minecraft:cobblestone", id: "minecraft:jigsaw", joint: "rollable", name: "minecraft:bottom", pool: "minecraft:village/common/well_bottoms", target: "minecraft:bottom"}},
        {pos: [3, 2, 1], state: "minecraft:cobblestone"},
        {pos: [3, 2, 2], state: "minecraft:cobblestone"},
        {pos: [3, 2, 3], state: "minecraft:cobblestone"}
    ],
    entities: [],
    palette: [
        "minecraft:cobblestone",
        "minecraft:water{level:0}",
        "minecraft:jigsaw{orientation:up_north}"
    ]
}
