{
    DataVersion: 2856,
    size: [7, 7, 7],
    data: [
        {pos: [0, 0, 1], state: "minecraft:jigsaw{orientation:up_north}", nbt: {final_state: "minecraft:grass_block", id: "minecraft:jigsaw", joint: "rollable", name: "minecraft:bottom", pool: "minecraft:village/common/cats", target: "minecraft:bottom"}},
        {pos: [0, 0, 2], state: "minecraft:dirt_path"},
        {pos: [0, 0, 3], state: "minecraft:dirt_path"},
        {pos: [0, 0, 4], state: "minecraft:dirt_path"},
        {pos: [1, 0, 0], state: "minecraft:jigsaw{orientation:up_north}", nbt: {final_state: "minecraft:grass_block", id: "minecraft:jigsaw", joint: "rollable", name: "minecraft:bottom", pool: "minecraft:village/common/iron_golem", target: "minecraft:bottom"}},
        {pos: [1, 0, 1], state: "minecraft:jigsaw{orientation:up_north}", nbt: {final_state: "minecraft:dirt_path", id: "minecraft:jigsaw", joint: "rollable", name: "minecraft:bottom", pool: "minecraft:village/snowy/villagers", target: "minecraft:bottom"}},
        {pos: [1, 0, 2], state: "minecraft:dirt_path"},
        {pos: [1, 0, 3], state: "minecraft:dirt_path"},
        {pos: [1, 0, 4], state: "minecraft:dirt_path"},
        {pos: [1, 0, 5], state: "minecraft:jigsaw{orientation:up_north}", nbt: {final_state: "minecraft:dirt_path", id: "minecraft:jigsaw", joint: "rollable", name: "minecraft:bottom", pool: "minecraft:village/snowy/villagers", target: "minecraft:bottom"}},
        {pos: [2, 0, 0], state: "minecraft:dirt_path"},
        {pos: [2, 0, 1], state: "minecraft:dirt_path"},
        {pos: [2, 0, 2], state: "minecraft:grass_block{snowy:false}"},
        {pos: [2, 0, 3], state: "minecraft:dirt_path"},
        {pos: [2, 0, 4], state: "minecraft:grass_block{snowy:false}"},
        {pos: [2, 0, 5], state: "minecraft:dirt_path"},
        {pos: [2, 0, 6], state: "minecraft:dirt_path"},
        {pos: [3, 0, 0], state: "minecraft:dirt_path"},
        {pos: [3, 0, 1], state: "minecraft:dirt_path"},
        {pos: [3, 0, 2], state: "minecraft:dirt_path"},
        {pos: [3, 0, 3], state: "minecraft:dirt_path"},
        {pos: [3, 0, 4], state: "minecraft:dirt_path"},
        {pos: [3, 0, 5], state: "minecraft:dirt_path"},
        {pos: [3, 0, 6], state: "minecraft:dirt_path"},
        {pos: [4, 0, 0], state: "minecraft:dirt_path"},
        {pos: [4, 0, 1], state: "minecraft:dirt_path"},
        {pos: [4, 0, 2], state: "minecraft:grass_block{snowy:false}"},
        {pos: [4, 0, 3], state: "minecraft:dirt_path"},
        {pos: [4, 0, 4], state: "minecraft:grass_block{snowy:false}"},
        {pos: [4, 0, 5], state: "minecraft:dirt_path"},
        {pos: [4, 0, 6], state: "minecraft:dirt_path"},
        {pos: [5, 0, 1], state: "minecraft:dirt_path"},
        {pos: [5, 0, 2], state: "minecraft:dirt_path"},
        {pos: [5, 0, 3], state: "minecraft:dirt_path"},
        {pos: [5, 0, 4], state: "minecraft:dirt_path"},
        {pos: [5, 0, 5], state: "minecraft:dirt_path"},
        {pos: [6, 0, 2], state: "minecraft:dirt_path"},
        {pos: [6, 0, 3], state: "minecraft:dirt_path"},
        {pos: [6, 0, 4], state: "minecraft:dirt_path"},
        {pos: [6, 0, 6], state: "minecraft:jigsaw{orientation:up_north}", nbt: {final_state: "minecraft:grass_block", id: "minecraft:jigsaw", joint: "rollable", name: "minecraft:bottom", pool: "minecraft:village/common/cats", target: "minecraft:bottom"}},
        {pos: [0, 1, 3], state: "minecraft:jigsaw{orientation:west_up}", nbt: {final_state: "minecraft:structure_void", id: "minecraft:jigsaw", joint: "aligned", name: "minecraft:street", pool: "minecraft:village/snowy/streets", target: "minecraft:street"}},
        {pos: [2, 1, 2], state: "minecraft:spruce_fence{east:false,north:false,south:false,waterlogged:false,west:false}"},
        {pos: [2, 1, 4], state: "minecraft:spruce_fence{east:false,north:false,south:false,waterlogged:false,west:false}"},
        {pos: [3, 1, 0], state: "minecraft:jigsaw{orientation:north_up}", nbt: {final_state: "minecraft:structure_void", id: "minecraft:jigsaw", joint: "aligned", name: "minecraft:street", pool: "minecraft:village/snowy/streets", target: "minecraft:street"}},
        {pos: [3, 1, 6], state: "minecraft:jigsaw{orientation:south_up}", nbt: {final_state: "minecraft:structure_void", id: "minecraft:jigsaw", joint: "aligned", name: "minecraft:street", pool: "minecraft:village/snowy/streets", target: "minecraft:street"}},
        {pos: [4, 1, 2], state: "minecraft:spruce_fence{east:false,north:false,south:false,waterlogged:false,west:false}"},
        {pos: [4, 1, 4], state: "minecraft:spruce_fence{east:false,north:false,south:false,waterlogged:false,west:false}"},
        {pos: [6, 1, 3], state: "minecraft:jigsaw{orientation:east_up}", nbt: {final_state: "minecraft:structure_void", id: "minecraft:jigsaw", joint: "aligned", name: "minecraft:street", pool: "minecraft:village/snowy/streets", target: "minecraft:street"}},
        {pos: [2, 2, 2], state: "minecraft:spruce_fence{east:false,north:false,south:false,waterlogged:false,west:false}"},
        {pos: [2, 2, 4], state: "minecraft:spruce_fence{east:false,north:false,south:false,waterlogged:false,west:false}"},
        {pos: [4, 2, 2], state: "minecraft:spruce_fence{east:false,north:false,south:false,waterlogged:false,west:false}"},
        {pos: [4, 2, 4], state: "minecraft:spruce_fence{east:false,north:false,south:false,waterlogged:false,west:false}"},
        {pos: [1, 3, 3], state: "minecraft:lantern{hanging:true,waterlogged:false}"},
        {pos: [2, 3, 2], state: "minecraft:spruce_fence{east:false,north:false,south:false,waterlogged:false,west:false}"},
        {pos: [2, 3, 4], state: "minecraft:spruce_fence{east:false,north:false,south:false,waterlogged:false,west:false}"},
        {pos: [3, 3, 1], state: "minecraft:lantern{hanging:true,waterlogged:false}"},
        {pos: [3, 3, 3], state: "minecraft:bell{attachment:ceiling,facing:east,powered:false}", nbt: {id: "minecraft:bell"}},
        {pos: [3, 3, 5], state: "minecraft:lantern{hanging:true,waterlogged:false}"},
        {pos: [4, 3, 2], state: "minecraft:spruce_fence{east:false,north:false,south:false,waterlogged:false,west:false}"},
        {pos: [4, 3, 4], state: "minecraft:spruce_fence{east:false,north:false,south:false,waterlogged:false,west:false}"},
        {pos: [5, 3, 3], state: "minecraft:lantern{hanging:true,waterlogged:false}"},
        {pos: [1, 4, 3], state: "minecraft:spruce_fence{east:true,north:false,south:false,waterlogged:false,west:false}"},
        {pos: [2, 4, 2], state: "minecraft:stripped_spruce_wood{axis:z}"},
        {pos: [2, 4, 3], state: "minecraft:stripped_spruce_wood{axis:z}"},
        {pos: [2, 4, 4], state: "minecraft:stripped_spruce_wood{axis:z}"},
        {pos: [3, 4, 1], state: "minecraft:spruce_fence{east:false,north:false,south:true,waterlogged:false,west:false}"},
        {pos: [3, 4, 2], state: "minecraft:stripped_spruce_wood{axis:x}"},
        {pos: [3, 4, 3], state: "minecraft:stripped_spruce_wood{axis:z}"},
        {pos: [3, 4, 4], state: "minecraft:stripped_spruce_wood{axis:x}"},
        {pos: [3, 4, 5], state: "minecraft:spruce_fence{east:false,north:true,south:false,waterlogged:false,west:false}"},
        {pos: [4, 4, 2], state: "minecraft:stripped_spruce_wood{axis:x}"},
        {pos: [4, 4, 3], state: "minecraft:stripped_spruce_wood{axis:z}"},
        {pos: [4, 4, 4], state: "minecraft:stripped_spruce_wood{axis:z}"},
        {pos: [5, 4, 3], state: "minecraft:spruce_fence{east:false,north:false,south:false,waterlogged:false,west:true}"},
        {pos: [3, 5, 3], state: "minecraft:stripped_spruce_wood{axis:z}"}
    ],
    entities: [],
    palette: [
        "minecraft:grass_block{snowy:false}",
        "minecraft:stripped_spruce_wood{axis:z}",
        "minecraft:stripped_spruce_wood{axis:x}",
        "minecraft:dirt_path",
        "minecraft:spruce_fence{east:false,north:false,south:false,waterlogged:false,west:false}",
        "minecraft:lantern{hanging:true,waterlogged:false}",
        "minecraft:spruce_fence{east:true,north:false,south:false,waterlogged:false,west:false}",
        "minecraft:spruce_fence{east:false,north:false,south:true,waterlogged:false,west:false}",
        "minecraft:spruce_fence{east:false,north:true,south:false,waterlogged:false,west:false}",
        "minecraft:spruce_fence{east:false,north:false,south:false,waterlogged:false,west:true}",
        "minecraft:jigsaw{orientation:up_north}",
        "minecraft:jigsaw{orientation:west_up}",
        "minecraft:jigsaw{orientation:north_up}",
        "minecraft:jigsaw{orientation:south_up}",
        "minecraft:jigsaw{orientation:east_up}",
        "minecraft:bell{attachment:ceiling,facing:east,powered:false}"
    ]
}
