{
    size: [19, 10, 15],
    data: [
        {pos: [0, 0, 5], state: "minecraft:cobbled_deepslate"},
        {pos: [0, 0, 10], state: "minecraft:cobbled_deepslate"},
        {pos: [1, 0, 0], state: "minecraft:deepslate_bricks"},
        {pos: [1, 0, 1], state: "minecraft:deepslate_bricks"},
        {pos: [1, 0, 13], state: "minecraft:deepslate_bricks"},
        {pos: [1, 0, 14], state: "minecraft:deepslate_bricks"},
        {pos: [2, 0, 0], state: "minecraft:deepslate_bricks"},
        {pos: [2, 0, 1], state: "minecraft:deepslate_bricks"},
        {pos: [2, 0, 5], state: "minecraft:deepslate_bricks"},
        {pos: [2, 0, 13], state: "minecraft:deepslate_bricks"},
        {pos: [2, 0, 14], state: "minecraft:deepslate_bricks"},
        {pos: [3, 0, 0], state: "minecraft:deepslate_bricks"},
        {pos: [3, 0, 1], state: "minecraft:deepslate_bricks"},
        {pos: [3, 0, 2], state: "minecraft:deepslate_bricks"},
        {pos: [3, 0, 3], state: "minecraft:deepslate_bricks"},
        {pos: [3, 0, 4], state: "minecraft:deepslate_bricks"},
        {pos: [3, 0, 5], state: "minecraft:deepslate_bricks"},
        {pos: [3, 0, 6], state: "minecraft:deepslate_tiles"},
        {pos: [3, 0, 7], state: "minecraft:deepslate_tiles"},
        {pos: [3, 0, 8], state: "minecraft:deepslate_tiles"},
        {pos: [3, 0, 10], state: "minecraft:deepslate_bricks"},
        {pos: [3, 0, 11], state: "minecraft:deepslate_bricks"},
        {pos: [3, 0, 12], state: "minecraft:deepslate_bricks"},
        {pos: [3, 0, 13], state: "minecraft:deepslate_bricks"},
        {pos: [3, 0, 14], state: "minecraft:deepslate_bricks"},
        {pos: [4, 0, 1], state: "minecraft:deepslate_bricks"},
        {pos: [4, 0, 2], state: "minecraft:cobbled_deepslate"},
        {pos: [4, 0, 3], state: "minecraft:cobbled_deepslate"},
        {pos: [4, 0, 4], state: "minecraft:cobbled_deepslate"},
        {pos: [4, 0, 5], state: "minecraft:cobbled_deepslate"},
        {pos: [4, 0, 6], state: "minecraft:deepslate_tiles"},
        {pos: [4, 0, 7], state: "minecraft:deepslate_tiles"},
        {pos: [4, 0, 8], state: "minecraft:deepslate_tiles"},
        {pos: [4, 0, 9], state: "minecraft:deepslate_tiles"},
        {pos: [4, 0, 10], state: "minecraft:cobbled_deepslate"},
        {pos: [4, 0, 11], state: "minecraft:cobbled_deepslate"},
        {pos: [4, 0, 12], state: "minecraft:cobbled_deepslate"},
        {pos: [4, 0, 13], state: "minecraft:deepslate_bricks"},
        {pos: [5, 0, 1], state: "minecraft:deepslate_bricks"},
        {pos: [5, 0, 2], state: "minecraft:cobbled_deepslate"},
        {pos: [5, 0, 3], state: "minecraft:cobbled_deepslate"},
        {pos: [5, 0, 4], state: "minecraft:cobbled_deepslate"},
        {pos: [5, 0, 11], state: "minecraft:cobbled_deepslate"},
        {pos: [5, 0, 12], state: "minecraft:cobbled_deepslate"},
        {pos: [5, 0, 13], state: "minecraft:deepslate_bricks"},
        {pos: [6, 0, 1], state: "minecraft:deepslate_bricks"},
        {pos: [6, 0, 2], state: "minecraft:cobbled_deepslate"},
        {pos: [6, 0, 3], state: "minecraft:cobbled_deepslate"},
        {pos: [6, 0, 4], state: "minecraft:cobbled_deepslate"},
        {pos: [6, 0, 5], state: "minecraft:cobbled_deepslate"},
        {pos: [6, 0, 6], state: "minecraft:cobbled_deepslate"},
        {pos: [6, 0, 7], state: "minecraft:cobbled_deepslate"},
        {pos: [6, 0, 8], state: "minecraft:cobbled_deepslate"},
        {pos: [6, 0, 9], state: "minecraft:cobbled_deepslate"},
        {pos: [6, 0, 10], state: "minecraft:cobbled_deepslate"},
        {pos: [6, 0, 11], state: "minecraft:cobbled_deepslate"},
        {pos: [6, 0, 12], state: "minecraft:cobbled_deepslate"},
        {pos: [6, 0, 13], state: "minecraft:deepslate_bricks"},
        {pos: [7, 0, 1], state: "minecraft:deepslate_bricks"},
        {pos: [7, 0, 2], state: "minecraft:cobbled_deepslate"},
        {pos: [7, 0, 3], state: "minecraft:deepslate_bricks"},
        {pos: [7, 0, 4], state: "minecraft:deepslate_bricks"},
        {pos: [7, 0, 5], state: "minecraft:deepslate_bricks"},
        {pos: [7, 0, 6], state: "minecraft:deepslate_bricks"},
        {pos: [7, 0, 7], state: "minecraft:deepslate_bricks"},
        {pos: [7, 0, 8], state: "minecraft:deepslate_bricks"},
        {pos: [7, 0, 9], state: "minecraft:cobbled_deepslate"},
        {pos: [7, 0, 10], state: "minecraft:cobbled_deepslate"},
        {pos: [7, 0, 11], state: "minecraft:cobbled_deepslate"},
        {pos: [7, 0, 12], state: "minecraft:cobbled_deepslate"},
        {pos: [7, 0, 13], state: "minecraft:deepslate_bricks"},
        {pos: [8, 0, 1], state: "minecraft:deepslate_bricks"},
        {pos: [8, 0, 2], state: "minecraft:cobbled_deepslate"},
        {pos: [8, 0, 3], state: "minecraft:deepslate_bricks"},
        {pos: [8, 0, 4], state: "minecraft:deepslate_bricks"},
        {pos: [8, 0, 5], state: "minecraft:deepslate_bricks"},
        {pos: [8, 0, 6], state: "minecraft:deepslate_bricks"},
        {pos: [8, 0, 7], state: "minecraft:deepslate_bricks"},
        {pos: [8, 0, 8], state: "minecraft:deepslate_bricks"},
        {pos: [8, 0, 9], state: "minecraft:deepslate_bricks"},
        {pos: [8, 0, 10], state: "minecraft:cobbled_deepslate"},
        {pos: [8, 0, 11], state: "minecraft:cobbled_deepslate"},
        {pos: [8, 0, 12], state: "minecraft:cobbled_deepslate"},
        {pos: [8, 0, 13], state: "minecraft:deepslate_bricks"},
        {pos: [9, 0, 1], state: "minecraft:deepslate_bricks"},
        {pos: [9, 0, 2], state: "minecraft:cobbled_deepslate"},
        {pos: [9, 0, 3], state: "minecraft:deepslate_bricks"},
        {pos: [9, 0, 4], state: "minecraft:deepslate_bricks"},
        {pos: [9, 0, 5], state: "minecraft:deepslate_bricks"},
        {pos: [9, 0, 6], state: "minecraft:deepslate_bricks"},
        {pos: [9, 0, 7], state: "minecraft:deepslate_bricks"},
        {pos: [9, 0, 8], state: "minecraft:deepslate_bricks"},
        {pos: [9, 0, 9], state: "minecraft:deepslate_bricks"},
        {pos: [9, 0, 10], state: "minecraft:cobbled_deepslate"},
        {pos: [9, 0, 11], state: "minecraft:cobbled_deepslate"},
        {pos: [9, 0, 12], state: "minecraft:cobbled_deepslate"},
        {pos: [9, 0, 13], state: "minecraft:deepslate_bricks"},
        {pos: [10, 0, 1], state: "minecraft:deepslate_bricks"},
        {pos: [10, 0, 2], state: "minecraft:cobbled_deepslate"},
        {pos: [10, 0, 3], state: "minecraft:deepslate_bricks"},
        {pos: [10, 0, 4], state: "minecraft:deepslate_bricks"},
        {pos: [10, 0, 5], state: "minecraft:deepslate_bricks"},
        {pos: [10, 0, 6], state: "minecraft:deepslate_bricks"},
        {pos: [10, 0, 7], state: "minecraft:deepslate_bricks"},
        {pos: [10, 0, 8], state: "minecraft:deepslate_bricks"},
        {pos: [10, 0, 9], state: "minecraft:cobbled_deepslate"},
        {pos: [10, 0, 10], state: "minecraft:deepslate_bricks"},
        {pos: [10, 0, 11], state: "minecraft:deepslate_bricks"},
        {pos: [10, 0, 12], state: "minecraft:cobbled_deepslate"},
        {pos: [10, 0, 13], state: "minecraft:deepslate_bricks"},
        {pos: [11, 0, 1], state: "minecraft:deepslate_bricks"},
        {pos: [11, 0, 2], state: "minecraft:cobbled_deepslate"},
        {pos: [11, 0, 3], state: "minecraft:deepslate_bricks"},
        {pos: [11, 0, 4], state: "minecraft:deepslate_bricks"},
        {pos: [11, 0, 5], state: "minecraft:deepslate_bricks"},
        {pos: [11, 0, 6], state: "minecraft:deepslate_bricks"},
        {pos: [11, 0, 7], state: "minecraft:deepslate_bricks"},
        {pos: [11, 0, 8], state: "minecraft:deepslate_bricks"},
        {pos: [11, 0, 9], state: "minecraft:deepslate_bricks"},
        {pos: [11, 0, 10], state: "minecraft:deepslate_bricks"},
        {pos: [11, 0, 11], state: "minecraft:deepslate_bricks"},
        {pos: [11, 0, 12], state: "minecraft:cobbled_deepslate"},
        {pos: [11, 0, 13], state: "minecraft:deepslate_bricks"},
        {pos: [12, 0, 1], state: "minecraft:deepslate_bricks"},
        {pos: [12, 0, 2], state: "minecraft:cobbled_deepslate"},
        {pos: [12, 0, 3], state: "minecraft:deepslate_bricks"},
        {pos: [12, 0, 4], state: "minecraft:cobbled_deepslate"},
        {pos: [12, 0, 5], state: "minecraft:cobbled_deepslate"},
        {pos: [12, 0, 6], state: "minecraft:jigsaw{orientation:up_west}", nbt: {final_state: "minecraft:deepslate", id: "minecraft:jigsaw", joint: "rollable", name: "minecraft:bottom", pool: "minecraft:ancient_city/sculk", target: "minecraft:bottom"}},
        {pos: [12, 0, 7], state: "minecraft:deepslate_bricks"},
        {pos: [12, 0, 8], state: "minecraft:deepslate_bricks"},
        {pos: [12, 0, 9], state: "minecraft:deepslate_bricks"},
        {pos: [12, 0, 12], state: "minecraft:cobbled_deepslate"},
        {pos: [12, 0, 13], state: "minecraft:deepslate_bricks"},
        {pos: [13, 0, 1], state: "minecraft:deepslate_bricks"},
        {pos: [13, 0, 2], state: "minecraft:cobbled_deepslate"},
        {pos: [13, 0, 3], state: "minecraft:deepslate_bricks"},
        {pos: [13, 0, 4], state: "minecraft:cobbled_deepslate"},
        {pos: [13, 0, 5], state: "minecraft:cobbled_deepslate"},
        {pos: [13, 0, 6], state: "minecraft:cobbled_deepslate"},
        {pos: [13, 0, 7], state: "minecraft:deepslate_bricks"},
        {pos: [13, 0, 8], state: "minecraft:deepslate_bricks"},
        {pos: [13, 0, 9], state: "minecraft:deepslate_bricks"},
        {pos: [13, 0, 10], state: "minecraft:deepslate_bricks"},
        {pos: [13, 0, 12], state: "minecraft:cobbled_deepslate"},
        {pos: [13, 0, 13], state: "minecraft:deepslate_bricks"},
        {pos: [14, 0, 2], state: "minecraft:cobbled_deepslate"},
        {pos: [14, 0, 3], state: "minecraft:cobbled_deepslate"},
        {pos: [14, 0, 4], state: "minecraft:cobbled_deepslate"},
        {pos: [14, 0, 5], state: "minecraft:cobbled_deepslate"},
        {pos: [14, 0, 6], state: "minecraft:cobbled_deepslate"},
        {pos: [14, 0, 7], state: "minecraft:deepslate_bricks"},
        {pos: [14, 0, 8], state: "minecraft:deepslate_bricks"},
        {pos: [14, 0, 9], state: "minecraft:cobbled_deepslate"},
        {pos: [14, 0, 10], state: "minecraft:deepslate_bricks"},
        {pos: [14, 0, 12], state: "minecraft:cobbled_deepslate"},
        {pos: [14, 0, 13], state: "minecraft:deepslate_bricks"},
        {pos: [15, 0, 1], state: "minecraft:deepslate_bricks"},
        {pos: [15, 0, 2], state: "minecraft:deepslate_bricks"},
        {pos: [15, 0, 3], state: "minecraft:cobbled_deepslate"},
        {pos: [15, 0, 4], state: "minecraft:cobbled_deepslate"},
        {pos: [15, 0, 5], state: "minecraft:deepslate_bricks"},
        {pos: [15, 0, 6], state: "minecraft:deepslate_bricks"},
        {pos: [15, 0, 7], state: "minecraft:deepslate_bricks"},
        {pos: [15, 0, 8], state: "minecraft:deepslate_bricks"},
        {pos: [15, 0, 9], state: "minecraft:cobbled_deepslate"},
        {pos: [15, 0, 10], state: "minecraft:deepslate_bricks"},
        {pos: [15, 0, 12], state: "minecraft:cobbled_deepslate"},
        {pos: [15, 0, 13], state: "minecraft:deepslate_bricks"},
        {pos: [16, 0, 1], state: "minecraft:deepslate_bricks"},
        {pos: [16, 0, 2], state: "minecraft:deepslate_bricks"},
        {pos: [16, 0, 3], state: "minecraft:cobbled_deepslate"},
        {pos: [16, 0, 4], state: "minecraft:cobbled_deepslate"},
        {pos: [16, 0, 5], state: "minecraft:deepslate_bricks"},
        {pos: [16, 0, 6], state: "minecraft:deepslate_bricks"},
        {pos: [16, 0, 8], state: "minecraft:deepslate_bricks"},
        {pos: [16, 0, 9], state: "minecraft:deepslate_bricks"},
        {pos: [16, 0, 12], state: "minecraft:cobbled_deepslate"},
        {pos: [16, 0, 13], state: "minecraft:deepslate_bricks"},
        {pos: [17, 0, 1], state: "minecraft:deepslate_bricks"},
        {pos: [17, 0, 2], state: "minecraft:cobbled_deepslate"},
        {pos: [17, 0, 3], state: "minecraft:cobbled_deepslate"},
        {pos: [17, 0, 4], state: "minecraft:cobbled_deepslate"},
        {pos: [17, 0, 5], state: "minecraft:cobbled_deepslate"},
        {pos: [17, 0, 6], state: "minecraft:deepslate_bricks"},
        {pos: [17, 0, 7], state: "minecraft:cobbled_deepslate"},
        {pos: [17, 0, 8], state: "minecraft:deepslate_bricks"},
        {pos: [17, 0, 9], state: "minecraft:cobbled_deepslate"},
        {pos: [17, 0, 10], state: "minecraft:cobbled_deepslate"},
        {pos: [17, 0, 11], state: "minecraft:cobbled_deepslate"},
        {pos: [17, 0, 12], state: "minecraft:cobbled_deepslate"},
        {pos: [17, 0, 13], state: "minecraft:deepslate_bricks"},
        {pos: [18, 0, 1], state: "minecraft:deepslate_bricks"},
        {pos: [18, 0, 2], state: "minecraft:cobbled_deepslate"},
        {pos: [18, 0, 3], state: "minecraft:cobbled_deepslate"},
        {pos: [18, 0, 4], state: "minecraft:cobbled_deepslate"},
        {pos: [18, 0, 5], state: "minecraft:cobbled_deepslate"},
        {pos: [18, 0, 6], state: "minecraft:cobbled_deepslate"},
        {pos: [18, 0, 7], state: "minecraft:jigsaw{orientation:east_up}", nbt: {final_state: "minecraft:structure_void", id: "minecraft:jigsaw", joint: "rollable", name: "minecraft:connect_structure", pool: "minecraft:empty", target: "minecraft:empty"}},
        {pos: [18, 0, 8], state: "minecraft:cobbled_deepslate"},
        {pos: [18, 0, 9], state: "minecraft:cobbled_deepslate"},
        {pos: [18, 0, 10], state: "minecraft:cobbled_deepslate"},
        {pos: [18, 0, 11], state: "minecraft:cobbled_deepslate"},
        {pos: [18, 0, 12], state: "minecraft:cobbled_deepslate"},
        {pos: [18, 0, 13], state: "minecraft:deepslate_bricks"},
        {pos: [0, 1, 5], state: "minecraft:cobbled_deepslate"},
        {pos: [0, 1, 10], state: "minecraft:cobbled_deepslate"},
        {pos: [1, 1, 0], state: "minecraft:deepslate_bricks"},
        {pos: [1, 1, 1], state: "minecraft:deepslate_bricks"},
        {pos: [1, 1, 13], state: "minecraft:deepslate_bricks"},
        {pos: [1, 1, 14], state: "minecraft:deepslate_bricks"},
        {pos: [2, 1, 0], state: "minecraft:deepslate_bricks"},
        {pos: [2, 1, 1], state: "minecraft:deepslate_bricks"},
        {pos: [2, 1, 5], state: "minecraft:deepslate_bricks"},
        {pos: [2, 1, 13], state: "minecraft:deepslate_bricks"},
        {pos: [2, 1, 14], state: "minecraft:deepslate_bricks"},
        {pos: [3, 1, 0], state: "minecraft:deepslate_bricks"},
        {pos: [3, 1, 1], state: "minecraft:deepslate_bricks"},
        {pos: [3, 1, 2], state: "minecraft:cobbled_deepslate"},
        {pos: [3, 1, 3], state: "minecraft:cobbled_deepslate"},
        {pos: [3, 1, 4], state: "minecraft:cobbled_deepslate"},
        {pos: [3, 1, 5], state: "minecraft:deepslate_bricks"},
        {pos: [3, 1, 6], state: "minecraft:deepslate_tiles"},
        {pos: [3, 1, 7], state: "minecraft:deepslate_tiles"},
        {pos: [3, 1, 8], state: "minecraft:deepslate_tiles"},
        {pos: [3, 1, 11], state: "minecraft:deepslate_bricks"},
        {pos: [3, 1, 12], state: "minecraft:deepslate_tiles"},
        {pos: [3, 1, 13], state: "minecraft:deepslate_bricks"},
        {pos: [3, 1, 14], state: "minecraft:deepslate_bricks"},
        {pos: [4, 1, 1], state: "minecraft:cobbled_deepslate"},
        {pos: [4, 1, 2], state: "minecraft:cobbled_deepslate"},
        {pos: [4, 1, 3], state: "minecraft:cobbled_deepslate"},
        {pos: [4, 1, 4], state: "minecraft:cobbled_deepslate"},
        {pos: [4, 1, 5], state: "minecraft:chiseled_deepslate"},
        {pos: [4, 1, 6], state: "minecraft:deepslate_tiles"},
        {pos: [4, 1, 7], state: "minecraft:deepslate_tiles"},
        {pos: [4, 1, 8], state: "minecraft:deepslate_tiles"},
        {pos: [4, 1, 9], state: "minecraft:deepslate_tiles"},
        {pos: [4, 1, 10], state: "minecraft:chiseled_deepslate"},
        {pos: [4, 1, 11], state: "minecraft:cobbled_deepslate"},
        {pos: [4, 1, 12], state: "minecraft:cobbled_deepslate"},
        {pos: [4, 1, 13], state: "minecraft:cobbled_deepslate"},
        {pos: [5, 1, 1], state: "minecraft:cobbled_deepslate"},
        {pos: [5, 1, 2], state: "minecraft:cobbled_deepslate"},
        {pos: [5, 1, 3], state: "minecraft:cobbled_deepslate"},
        {pos: [5, 1, 4], state: "minecraft:cobbled_deepslate"},
        {pos: [5, 1, 5], state: "minecraft:cobbled_deepslate"},
        {pos: [5, 1, 6], state: "minecraft:deepslate_tiles"},
        {pos: [5, 1, 7], state: "minecraft:deepslate_tiles"},
        {pos: [5, 1, 9], state: "minecraft:deepslate_tiles"},
        {pos: [5, 1, 10], state: "minecraft:cobbled_deepslate"},
        {pos: [5, 1, 11], state: "minecraft:cobbled_deepslate"},
        {pos: [5, 1, 12], state: "minecraft:cobbled_deepslate"},
        {pos: [5, 1, 13], state: "minecraft:cobbled_deepslate"},
        {pos: [6, 1, 1], state: "minecraft:cobbled_deepslate"},
        {pos: [6, 1, 2], state: "minecraft:cobbled_deepslate"},
        {pos: [6, 1, 3], state: "minecraft:cobbled_deepslate"},
        {pos: [6, 1, 4], state: "minecraft:cobbled_deepslate"},
        {pos: [6, 1, 11], state: "minecraft:cobbled_deepslate"},
        {pos: [6, 1, 12], state: "minecraft:cobbled_deepslate"},
        {pos: [6, 1, 13], state: "minecraft:deepslate_bricks"},
        {pos: [7, 1, 1], state: "minecraft:cobbled_deepslate"},
        {pos: [7, 1, 2], state: "minecraft:cobbled_deepslate"},
        {pos: [7, 1, 12], state: "minecraft:cobbled_deepslate"},
        {pos: [7, 1, 13], state: "minecraft:deepslate_bricks"},
        {pos: [8, 1, 1], state: "minecraft:cobbled_deepslate"},
        {pos: [8, 1, 2], state: "minecraft:cobbled_deepslate"},
        {pos: [8, 1, 12], state: "minecraft:cobbled_deepslate"},
        {pos: [8, 1, 13], state: "minecraft:cobbled_deepslate"},
        {pos: [9, 1, 1], state: "minecraft:cobbled_deepslate"},
        {pos: [9, 1, 2], state: "minecraft:cobbled_deepslate"},
        {pos: [9, 1, 12], state: "minecraft:cobbled_deepslate"},
        {pos: [9, 1, 13], state: "minecraft:cobbled_deepslate"},
        {pos: [10, 1, 1], state: "minecraft:cobbled_deepslate"},
        {pos: [10, 1, 2], state: "minecraft:cobbled_deepslate"},
        {pos: [10, 1, 12], state: "minecraft:cobbled_deepslate"},
        {pos: [10, 1, 13], state: "minecraft:cobbled_deepslate"},
        {pos: [11, 1, 1], state: "minecraft:cobbled_deepslate"},
        {pos: [11, 1, 2], state: "minecraft:cobbled_deepslate"},
        {pos: [11, 1, 12], state: "minecraft:cobbled_deepslate"},
        {pos: [12, 1, 1], state: "minecraft:cobbled_deepslate"},
        {pos: [12, 1, 2], state: "minecraft:cobbled_deepslate"},
        {pos: [12, 1, 10], state: "minecraft:deepslate_bricks"},
        {pos: [12, 1, 11], state: "minecraft:deepslate_bricks"},
        {pos: [12, 1, 12], state: "minecraft:cobbled_deepslate"},
        {pos: [12, 1, 13], state: "minecraft:cobbled_deepslate"},
        {pos: [13, 1, 1], state: "minecraft:cobbled_deepslate"},
        {pos: [13, 1, 2], state: "minecraft:cobbled_deepslate"},
        {pos: [13, 1, 11], state: "minecraft:cobbled_deepslate"},
        {pos: [13, 1, 12], state: "minecraft:cobbled_deepslate"},
        {pos: [13, 1, 13], state: "minecraft:cobbled_deepslate"},
        {pos: [14, 1, 2], state: "minecraft:cobbled_deepslate"},
        {pos: [14, 1, 11], state: "minecraft:cobbled_deepslate"},
        {pos: [14, 1, 12], state: "minecraft:cobbled_deepslate"},
        {pos: [14, 1, 13], state: "minecraft:cobbled_deepslate"},
        {pos: [15, 1, 1], state: "minecraft:cobbled_deepslate"},
        {pos: [15, 1, 11], state: "minecraft:cobbled_deepslate"},
        {pos: [15, 1, 12], state: "minecraft:cobbled_deepslate"},
        {pos: [15, 1, 13], state: "minecraft:cobbled_deepslate"},
        {pos: [16, 1, 1], state: "minecraft:cobbled_deepslate"},
        {pos: [16, 1, 7], state: "minecraft:cobbled_deepslate"},
        {pos: [16, 1, 10], state: "minecraft:deepslate_bricks"},
        {pos: [16, 1, 11], state: "minecraft:cobbled_deepslate"},
        {pos: [16, 1, 12], state: "minecraft:cobbled_deepslate"},
        {pos: [16, 1, 13], state: "minecraft:cobbled_deepslate"},
        {pos: [17, 1, 1], state: "minecraft:cobbled_deepslate"},
        {pos: [17, 1, 2], state: "minecraft:cobbled_deepslate"},
        {pos: [17, 1, 5], state: "minecraft:cobbled_deepslate"},
        {pos: [17, 1, 7], state: "minecraft:cobbled_deepslate"},
        {pos: [17, 1, 9], state: "minecraft:cobbled_deepslate"},
        {pos: [17, 1, 10], state: "minecraft:cobbled_deepslate"},
        {pos: [17, 1, 11], state: "minecraft:cobbled_deepslate"},
        {pos: [17, 1, 12], state: "minecraft:cobbled_deepslate"},
        {pos: [17, 1, 13], state: "minecraft:cobbled_deepslate"},
        {pos: [18, 1, 2], state: "minecraft:cobbled_deepslate"},
        {pos: [18, 1, 3], state: "minecraft:cobbled_deepslate"},
        {pos: [18, 1, 4], state: "minecraft:cobbled_deepslate"},
        {pos: [18, 1, 5], state: "minecraft:cobbled_deepslate"},
        {pos: [18, 1, 6], state: "minecraft:cobbled_deepslate"},
        {pos: [18, 1, 7], state: "minecraft:cobbled_deepslate"},
        {pos: [18, 1, 8], state: "minecraft:cobbled_deepslate"},
        {pos: [18, 1, 9], state: "minecraft:cobbled_deepslate"},
        {pos: [18, 1, 10], state: "minecraft:cobbled_deepslate"},
        {pos: [18, 1, 11], state: "minecraft:cobbled_deepslate"},
        {pos: [18, 1, 12], state: "minecraft:cobbled_deepslate"},
        {pos: [18, 1, 13], state: "minecraft:cobbled_deepslate"},
        {pos: [0, 2, 5], state: "minecraft:chiseled_deepslate"},
        {pos: [0, 2, 10], state: "minecraft:chiseled_deepslate"},
        {pos: [2, 2, 0], state: "minecraft:deepslate_bricks"},
        {pos: [2, 2, 1], state: "minecraft:deepslate_bricks"},
        {pos: [2, 2, 13], state: "minecraft:deepslate_bricks"},
        {pos: [2, 2, 14], state: "minecraft:deepslate_bricks"},
        {pos: [3, 2, 0], state: "minecraft:deepslate_bricks"},
        {pos: [3, 2, 1], state: "minecraft:deepslate_bricks"},
        {pos: [3, 2, 3], state: "minecraft:cobbled_deepslate"},
        {pos: [3, 2, 4], state: "minecraft:cobbled_deepslate"},
        {pos: [3, 2, 5], state: "minecraft:deepslate_bricks"},
        {pos: [3, 2, 11], state: "minecraft:cobbled_deepslate"},
        {pos: [3, 2, 12], state: "minecraft:cobbled_deepslate"},
        {pos: [3, 2, 13], state: "minecraft:deepslate_bricks"},
        {pos: [3, 2, 14], state: "minecraft:deepslate_bricks"},
        {pos: [4, 2, 1], state: "minecraft:cobbled_deepslate"},
        {pos: [4, 2, 2], state: "minecraft:cobbled_deepslate"},
        {pos: [4, 2, 3], state: "minecraft:cobbled_deepslate"},
        {pos: [4, 2, 4], state: "minecraft:cobbled_deepslate"},
        {pos: [4, 2, 5], state: "minecraft:chiseled_deepslate"},
        {pos: [4, 2, 6], state: "minecraft:deepslate_tiles"},
        {pos: [4, 2, 7], state: "minecraft:deepslate_tiles"},
        {pos: [4, 2, 9], state: "minecraft:deepslate_tiles"},
        {pos: [4, 2, 11], state: "minecraft:cobbled_deepslate"},
        {pos: [4, 2, 12], state: "minecraft:cobbled_deepslate"},
        {pos: [4, 2, 13], state: "minecraft:cobbled_deepslate"},
        {pos: [5, 2, 1], state: "minecraft:cobbled_deepslate"},
        {pos: [5, 2, 2], state: "minecraft:cobbled_deepslate"},
        {pos: [5, 2, 3], state: "minecraft:cobbled_deepslate"},
        {pos: [5, 2, 4], state: "minecraft:cobbled_deepslate"},
        {pos: [5, 2, 5], state: "minecraft:deepslate_bricks"},
        {pos: [5, 2, 6], state: "minecraft:deepslate_tiles"},
        {pos: [5, 2, 7], state: "minecraft:deepslate_tiles"},
        {pos: [5, 2, 9], state: "minecraft:deepslate_tiles"},
        {pos: [5, 2, 10], state: "minecraft:deepslate_tiles"},
        {pos: [5, 2, 11], state: "minecraft:cobbled_deepslate"},
        {pos: [5, 2, 12], state: "minecraft:cobbled_deepslate"},
        {pos: [5, 2, 13], state: "minecraft:cobbled_deepslate"},
        {pos: [6, 2, 1], state: "minecraft:cobbled_deepslate"},
        {pos: [6, 2, 2], state: "minecraft:cobbled_deepslate"},
        {pos: [6, 2, 3], state: "minecraft:cobbled_deepslate"},
        {pos: [6, 2, 4], state: "minecraft:cobbled_deepslate"},
        {pos: [6, 2, 11], state: "minecraft:cobbled_deepslate"},
        {pos: [6, 2, 12], state: "minecraft:cobbled_deepslate"},
        {pos: [6, 2, 13], state: "minecraft:cobbled_deepslate"},
        {pos: [7, 2, 1], state: "minecraft:cobbled_deepslate"},
        {pos: [7, 2, 2], state: "minecraft:cobbled_deepslate"},
        {pos: [7, 2, 12], state: "minecraft:cobbled_deepslate"},
        {pos: [7, 2, 13], state: "minecraft:cobbled_deepslate"},
        {pos: [8, 2, 1], state: "minecraft:cobbled_deepslate"},
        {pos: [8, 2, 2], state: "minecraft:cobbled_deepslate"},
        {pos: [8, 2, 12], state: "minecraft:cobbled_deepslate"},
        {pos: [8, 2, 13], state: "minecraft:cobbled_deepslate"},
        {pos: [9, 2, 1], state: "minecraft:cobbled_deepslate"},
        {pos: [9, 2, 2], state: "minecraft:cobbled_deepslate"},
        {pos: [9, 2, 12], state: "minecraft:cobbled_deepslate"},
        {pos: [9, 2, 13], state: "minecraft:cobbled_deepslate"},
        {pos: [10, 2, 1], state: "minecraft:cobbled_deepslate"},
        {pos: [10, 2, 2], state: "minecraft:cobbled_deepslate"},
        {pos: [10, 2, 12], state: "minecraft:cobbled_deepslate"},
        {pos: [10, 2, 13], state: "minecraft:cobbled_deepslate"},
        {pos: [11, 2, 1], state: "minecraft:cobbled_deepslate"},
        {pos: [11, 2, 2], state: "minecraft:cobbled_deepslate"},
        {pos: [11, 2, 12], state: "minecraft:cobbled_deepslate"},
        {pos: [11, 2, 13], state: "minecraft:cobbled_deepslate"},
        {pos: [12, 2, 1], state: "minecraft:cobbled_deepslate"},
        {pos: [12, 2, 2], state: "minecraft:cobbled_deepslate"},
        {pos: [12, 2, 10], state: "minecraft:deepslate_bricks"},
        {pos: [12, 2, 11], state: "minecraft:deepslate_bricks"},
        {pos: [12, 2, 12], state: "minecraft:cobbled_deepslate"},
        {pos: [12, 2, 13], state: "minecraft:cobbled_deepslate"},
        {pos: [13, 2, 1], state: "minecraft:cobbled_deepslate"},
        {pos: [13, 2, 2], state: "minecraft:cobbled_deepslate"},
        {pos: [13, 2, 10], state: "minecraft:deepslate_tiles"},
        {pos: [13, 2, 11], state: "minecraft:deepslate_tiles"},
        {pos: [13, 2, 12], state: "minecraft:cobbled_deepslate"},
        {pos: [13, 2, 13], state: "minecraft:cobbled_deepslate"},
        {pos: [14, 2, 1], state: "minecraft:cobbled_deepslate"},
        {pos: [14, 2, 2], state: "minecraft:cobbled_deepslate"},
        {pos: [14, 2, 10], state: "minecraft:deepslate_tiles"},
        {pos: [14, 2, 11], state: "minecraft:deepslate_tiles"},
        {pos: [14, 2, 12], state: "minecraft:cobbled_deepslate"},
        {pos: [15, 2, 1], state: "minecraft:cobbled_deepslate"},
        {pos: [15, 2, 2], state: "minecraft:cobbled_deepslate"},
        {pos: [15, 2, 10], state: "minecraft:deepslate_tiles"},
        {pos: [15, 2, 11], state: "minecraft:deepslate_tiles"},
        {pos: [15, 2, 12], state: "minecraft:cobbled_deepslate"},
        {pos: [16, 2, 1], state: "minecraft:cobbled_deepslate"},
        {pos: [16, 2, 2], state: "minecraft:cobbled_deepslate"},
        {pos: [16, 2, 7], state: "minecraft:cobbled_deepslate"},
        {pos: [16, 2, 10], state: "minecraft:deepslate_bricks"},
        {pos: [16, 2, 11], state: "minecraft:deepslate_bricks"},
        {pos: [16, 2, 12], state: "minecraft:cobbled_deepslate"},
        {pos: [16, 2, 13], state: "minecraft:cobbled_deepslate"},
        {pos: [17, 2, 1], state: "minecraft:cobbled_deepslate"},
        {pos: [17, 2, 2], state: "minecraft:cobbled_deepslate"},
        {pos: [17, 2, 3], state: "minecraft:cobbled_deepslate"},
        {pos: [17, 2, 4], state: "minecraft:cobbled_deepslate"},
        {pos: [17, 2, 5], state: "minecraft:cobbled_deepslate"},
        {pos: [17, 2, 7], state: "minecraft:cobbled_deepslate"},
        {pos: [17, 2, 9], state: "minecraft:cobbled_deepslate"},
        {pos: [17, 2, 10], state: "minecraft:cobbled_deepslate"},
        {pos: [17, 2, 11], state: "minecraft:cobbled_deepslate"},
        {pos: [17, 2, 12], state: "minecraft:cobbled_deepslate"},
        {pos: [17, 2, 13], state: "minecraft:cobbled_deepslate"},
        {pos: [18, 2, 1], state: "minecraft:cobbled_deepslate"},
        {pos: [18, 2, 2], state: "minecraft:cobbled_deepslate"},
        {pos: [18, 2, 3], state: "minecraft:cobbled_deepslate"},
        {pos: [18, 2, 4], state: "minecraft:cobbled_deepslate"},
        {pos: [18, 2, 5], state: "minecraft:cobbled_deepslate"},
        {pos: [18, 2, 6], state: "minecraft:cobbled_deepslate"},
        {pos: [18, 2, 7], state: "minecraft:cobbled_deepslate"},
        {pos: [18, 2, 8], state: "minecraft:cobbled_deepslate"},
        {pos: [18, 2, 9], state: "minecraft:cobbled_deepslate"},
        {pos: [18, 2, 10], state: "minecraft:cobbled_deepslate"},
        {pos: [18, 2, 11], state: "minecraft:cobbled_deepslate"},
        {pos: [18, 2, 12], state: "minecraft:cobbled_deepslate"},
        {pos: [18, 2, 13], state: "minecraft:cobbled_deepslate"},
        {pos: [0, 3, 5], state: "minecraft:deepslate_bricks"},
        {pos: [0, 3, 10], state: "minecraft:deepslate_bricks"},
        {pos: [1, 3, 0], state: "minecraft:deepslate_bricks"},
        {pos: [1, 3, 1], state: "minecraft:deepslate_bricks"},
        {pos: [1, 3, 13], state: "minecraft:deepslate_bricks"},
        {pos: [1, 3, 14], state: "minecraft:deepslate_bricks"},
        {pos: [2, 3, 0], state: "minecraft:deepslate_bricks"},
        {pos: [2, 3, 1], state: "minecraft:deepslate_bricks"},
        {pos: [2, 3, 14], state: "minecraft:deepslate_bricks"},
        {pos: [3, 3, 0], state: "minecraft:deepslate_bricks"},
        {pos: [3, 3, 1], state: "minecraft:deepslate_bricks"},
        {pos: [3, 3, 3], state: "minecraft:cobbled_deepslate"},
        {pos: [3, 3, 5], state: "minecraft:chiseled_deepslate"},
        {pos: [3, 3, 11], state: "minecraft:cobbled_deepslate"},
        {pos: [3, 3, 13], state: "minecraft:deepslate_bricks"},
        {pos: [3, 3, 14], state: "minecraft:deepslate_bricks"},
        {pos: [4, 3, 2], state: "minecraft:cobbled_deepslate"},
        {pos: [4, 3, 3], state: "minecraft:cobbled_deepslate"},
        {pos: [4, 3, 4], state: "minecraft:cobbled_deepslate"},
        {pos: [4, 3, 5], state: "minecraft:chiseled_deepslate"},
        {pos: [4, 3, 6], state: "minecraft:deepslate_tiles"},
        {pos: [4, 3, 7], state: "minecraft:deepslate_tiles"},
        {pos: [4, 3, 9], state: "minecraft:deepslate_tiles"},
        {pos: [4, 3, 11], state: "minecraft:cobbled_deepslate"},
        {pos: [5, 3, 1], state: "minecraft:jigsaw{orientation:up_west}", nbt: {final_state: "minecraft:deepslate", id: "minecraft:jigsaw", joint: "rollable", name: "minecraft:bottom", pool: "minecraft:ancient_city/sculk", target: "minecraft:bottom"}},
        {pos: [5, 3, 2], state: "minecraft:cobbled_deepslate"},
        {pos: [5, 3, 3], state: "minecraft:cobbled_deepslate"},
        {pos: [5, 3, 4], state: "minecraft:cobbled_deepslate"},
        {pos: [5, 3, 5], state: "minecraft:deepslate_bricks"},
        {pos: [5, 3, 6], state: "minecraft:deepslate_tiles"},
        {pos: [5, 3, 7], state: "minecraft:deepslate_tiles"},
        {pos: [5, 3, 9], state: "minecraft:deepslate_tiles"},
        {pos: [5, 3, 10], state: "minecraft:deepslate_tiles"},
        {pos: [5, 3, 11], state: "minecraft:cobbled_deepslate"},
        {pos: [5, 3, 12], state: "minecraft:cobbled_deepslate"},
        {pos: [5, 3, 13], state: "minecraft:cobbled_deepslate"},
        {pos: [6, 3, 1], state: "minecraft:cobbled_deepslate"},
        {pos: [6, 3, 2], state: "minecraft:cobbled_deepslate"},
        {pos: [6, 3, 3], state: "minecraft:cobbled_deepslate"},
        {pos: [6, 3, 4], state: "minecraft:cobbled_deepslate"},
        {pos: [6, 3, 11], state: "minecraft:cobbled_deepslate"},
        {pos: [6, 3, 12], state: "minecraft:cobbled_deepslate"},
        {pos: [6, 3, 13], state: "minecraft:cobbled_deepslate"},
        {pos: [7, 3, 1], state: "minecraft:cobbled_deepslate"},
        {pos: [7, 3, 2], state: "minecraft:cobbled_deepslate"},
        {pos: [7, 3, 12], state: "minecraft:cobbled_deepslate"},
        {pos: [7, 3, 13], state: "minecraft:cobbled_deepslate"},
        {pos: [8, 3, 1], state: "minecraft:cobbled_deepslate"},
        {pos: [8, 3, 2], state: "minecraft:cobbled_deepslate"},
        {pos: [8, 3, 12], state: "minecraft:cobbled_deepslate"},
        {pos: [8, 3, 13], state: "minecraft:cobbled_deepslate"},
        {pos: [9, 3, 1], state: "minecraft:cobbled_deepslate"},
        {pos: [9, 3, 2], state: "minecraft:cobbled_deepslate"},
        {pos: [9, 3, 12], state: "minecraft:cobbled_deepslate"},
        {pos: [9, 3, 13], state: "minecraft:cobbled_deepslate"},
        {pos: [10, 3, 1], state: "minecraft:cobbled_deepslate"},
        {pos: [10, 3, 2], state: "minecraft:cobbled_deepslate"},
        {pos: [10, 3, 12], state: "minecraft:cobbled_deepslate"},
        {pos: [10, 3, 13], state: "minecraft:cobbled_deepslate"},
        {pos: [11, 3, 1], state: "minecraft:cobbled_deepslate"},
        {pos: [11, 3, 2], state: "minecraft:cobbled_deepslate"},
        {pos: [11, 3, 12], state: "minecraft:cobbled_deepslate"},
        {pos: [11, 3, 13], state: "minecraft:cobbled_deepslate"},
        {pos: [12, 3, 1], state: "minecraft:cobbled_deepslate"},
        {pos: [12, 3, 2], state: "minecraft:cobbled_deepslate"},
        {pos: [12, 3, 12], state: "minecraft:cobbled_deepslate"},
        {pos: [12, 3, 13], state: "minecraft:cobbled_deepslate"},
        {pos: [13, 3, 1], state: "minecraft:cobbled_deepslate"},
        {pos: [13, 3, 2], state: "minecraft:cobbled_deepslate"},
        {pos: [13, 3, 12], state: "minecraft:cobbled_deepslate"},
        {pos: [13, 3, 13], state: "minecraft:cobbled_deepslate"},
        {pos: [14, 3, 1], state: "minecraft:cobbled_deepslate"},
        {pos: [14, 3, 2], state: "minecraft:cobbled_deepslate"},
        {pos: [14, 3, 11], state: "minecraft:chest{facing:north,type:single,waterlogged:false}", nbt: {LootTable: "minecraft:chests/ancient_city", LootTableSeed: 8430409379697247167L, id: "minecraft:chest"}},
        {pos: [14, 3, 12], state: "minecraft:cobbled_deepslate"},
        {pos: [14, 3, 13], state: "minecraft:cobbled_deepslate"},
        {pos: [15, 3, 1], state: "minecraft:cobbled_deepslate"},
        {pos: [15, 3, 12], state: "minecraft:cobbled_deepslate"},
        {pos: [15, 3, 13], state: "minecraft:cobbled_deepslate"},
        {pos: [16, 3, 1], state: "minecraft:cobbled_deepslate"},
        {pos: [16, 3, 2], state: "minecraft:cobbled_deepslate"},
        {pos: [16, 3, 7], state: "minecraft:chiseled_deepslate"},
        {pos: [16, 3, 12], state: "minecraft:cobbled_deepslate"},
        {pos: [16, 3, 13], state: "minecraft:cobbled_deepslate"},
        {pos: [17, 3, 1], state: "minecraft:cobbled_deepslate"},
        {pos: [17, 3, 2], state: "minecraft:cobbled_deepslate"},
        {pos: [17, 3, 3], state: "minecraft:cobbled_deepslate"},
        {pos: [17, 3, 4], state: "minecraft:cobbled_deepslate"},
        {pos: [17, 3, 5], state: "minecraft:cobbled_deepslate"},
        {pos: [17, 3, 7], state: "minecraft:cobbled_deepslate"},
        {pos: [17, 3, 9], state: "minecraft:cobbled_deepslate"},
        {pos: [17, 3, 10], state: "minecraft:cobbled_deepslate"},
        {pos: [17, 3, 11], state: "minecraft:cobbled_deepslate"},
        {pos: [17, 3, 12], state: "minecraft:cobbled_deepslate"},
        {pos: [17, 3, 13], state: "minecraft:cobbled_deepslate"},
        {pos: [18, 3, 1], state: "minecraft:cobbled_deepslate"},
        {pos: [18, 3, 2], state: "minecraft:cobbled_deepslate"},
        {pos: [18, 3, 3], state: "minecraft:cobbled_deepslate"},
        {pos: [18, 3, 4], state: "minecraft:cobbled_deepslate"},
        {pos: [18, 3, 5], state: "minecraft:cobbled_deepslate"},
        {pos: [18, 3, 6], state: "minecraft:cobbled_deepslate"},
        {pos: [18, 3, 7], state: "minecraft:cobbled_deepslate"},
        {pos: [18, 3, 8], state: "minecraft:cobbled_deepslate"},
        {pos: [18, 3, 9], state: "minecraft:cobbled_deepslate"},
        {pos: [18, 3, 10], state: "minecraft:cobbled_deepslate"},
        {pos: [18, 3, 11], state: "minecraft:cobbled_deepslate"},
        {pos: [18, 3, 12], state: "minecraft:cobbled_deepslate"},
        {pos: [1, 4, 0], state: "minecraft:deepslate_bricks"},
        {pos: [1, 4, 1], state: "minecraft:deepslate_bricks"},
        {pos: [1, 4, 13], state: "minecraft:deepslate_bricks"},
        {pos: [1, 4, 14], state: "minecraft:deepslate_bricks"},
        {pos: [2, 4, 0], state: "minecraft:deepslate_bricks"},
        {pos: [2, 4, 1], state: "minecraft:deepslate_bricks"},
        {pos: [2, 4, 14], state: "minecraft:deepslate_bricks"},
        {pos: [3, 4, 0], state: "minecraft:deepslate_bricks"},
        {pos: [3, 4, 1], state: "minecraft:deepslate_bricks"},
        {pos: [3, 4, 13], state: "minecraft:deepslate_bricks"},
        {pos: [3, 4, 14], state: "minecraft:deepslate_bricks"},
        {pos: [4, 4, 4], state: "minecraft:cobbled_deepslate"},
        {pos: [4, 4, 5], state: "minecraft:deepslate_tiles"},
        {pos: [5, 4, 3], state: "minecraft:cobbled_deepslate"},
        {pos: [5, 4, 4], state: "minecraft:cobbled_deepslate"},
        {pos: [5, 4, 5], state: "minecraft:deepslate_tiles"},
        {pos: [5, 4, 6], state: "minecraft:deepslate_tiles"},
        {pos: [5, 4, 10], state: "minecraft:deepslate_tiles"},
        {pos: [6, 4, 3], state: "minecraft:cobbled_deepslate"},
        {pos: [6, 4, 4], state: "minecraft:cobbled_deepslate"},
        {pos: [10, 4, 12], state: "minecraft:chiseled_deepslate"},
        {pos: [11, 4, 1], state: "minecraft:cobbled_deepslate"},
        {pos: [11, 4, 12], state: "minecraft:deepslate_tiles"},
        {pos: [12, 4, 1], state: "minecraft:cobbled_deepslate"},
        {pos: [12, 4, 2], state: "minecraft:cobbled_deepslate"},
        {pos: [12, 4, 12], state: "minecraft:deepslate_bricks"},
        {pos: [13, 4, 1], state: "minecraft:cobbled_deepslate"},
        {pos: [13, 4, 2], state: "minecraft:cobbled_deepslate"},
        {pos: [13, 4, 12], state: "minecraft:cobbled_deepslate"},
        {pos: [14, 4, 2], state: "minecraft:cobbled_deepslate"},
        {pos: [14, 4, 12], state: "minecraft:cobbled_deepslate"},
        {pos: [15, 4, 1], state: "minecraft:cobbled_deepslate"},
        {pos: [15, 4, 2], state: "minecraft:cobbled_deepslate"},
        {pos: [16, 4, 1], state: "minecraft:cobbled_deepslate"},
        {pos: [16, 4, 2], state: "minecraft:cobbled_deepslate"},
        {pos: [16, 4, 7], state: "minecraft:deepslate_bricks"},
        {pos: [16, 4, 12], state: "minecraft:cobbled_deepslate"},
        {pos: [17, 4, 1], state: "minecraft:cobbled_deepslate"},
        {pos: [17, 4, 2], state: "minecraft:cobbled_deepslate"},
        {pos: [17, 4, 3], state: "minecraft:cobbled_deepslate"},
        {pos: [17, 4, 4], state: "minecraft:cobbled_deepslate"},
        {pos: [17, 4, 5], state: "minecraft:cobbled_deepslate"},
        {pos: [17, 4, 6], state: "minecraft:cobbled_deepslate"},
        {pos: [17, 4, 7], state: "minecraft:cobbled_deepslate"},
        {pos: [17, 4, 10], state: "minecraft:cobbled_deepslate"},
        {pos: [17, 4, 11], state: "minecraft:cobbled_deepslate"},
        {pos: [17, 4, 12], state: "minecraft:cobbled_deepslate"},
        {pos: [18, 4, 2], state: "minecraft:cobbled_deepslate"},
        {pos: [18, 4, 3], state: "minecraft:cobbled_deepslate"},
        {pos: [18, 4, 4], state: "minecraft:cobbled_deepslate"},
        {pos: [18, 4, 5], state: "minecraft:cobbled_deepslate"},
        {pos: [1, 5, 13], state: "minecraft:deepslate_bricks"},
        {pos: [1, 5, 14], state: "minecraft:deepslate_bricks"},
        {pos: [2, 5, 1], state: "minecraft:chiseled_deepslate"},
        {pos: [2, 5, 13], state: "minecraft:deepslate_bricks"},
        {pos: [3, 5, 13], state: "minecraft:deepslate_bricks"},
        {pos: [3, 5, 14], state: "minecraft:deepslate_bricks"},
        {pos: [4, 5, 5], state: "minecraft:deepslate_tiles"},
        {pos: [4, 5, 10], state: "minecraft:deepslate_bricks"},
        {pos: [5, 5, 4], state: "minecraft:cobbled_deepslate"},
        {pos: [5, 5, 5], state: "minecraft:deepslate_tiles"},
        {pos: [5, 5, 10], state: "minecraft:deepslate_bricks"},
        {pos: [6, 5, 4], state: "minecraft:cobbled_deepslate"},
        {pos: [11, 5, 12], state: "minecraft:cobbled_deepslate"},
        {pos: [12, 5, 2], state: "minecraft:cobbled_deepslate"},
        {pos: [12, 5, 12], state: "minecraft:cobbled_deepslate"},
        {pos: [13, 5, 2], state: "minecraft:cobbled_deepslate"},
        {pos: [13, 5, 12], state: "minecraft:cobbled_deepslate"},
        {pos: [14, 5, 2], state: "minecraft:cobbled_deepslate"},
        {pos: [14, 5, 12], state: "minecraft:cobbled_deepslate"},
        {pos: [16, 5, 1], state: "minecraft:cobbled_deepslate"},
        {pos: [16, 5, 2], state: "minecraft:cobbled_deepslate"},
        {pos: [17, 5, 1], state: "minecraft:cobbled_deepslate"},
        {pos: [17, 5, 2], state: "minecraft:cobbled_deepslate"},
        {pos: [17, 5, 3], state: "minecraft:cobbled_deepslate"},
        {pos: [18, 5, 2], state: "minecraft:cobbled_deepslate"},
        {pos: [18, 5, 3], state: "minecraft:cobbled_deepslate"},
        {pos: [1, 6, 13], state: "minecraft:deepslate_bricks"},
        {pos: [1, 6, 14], state: "minecraft:deepslate_bricks"},
        {pos: [2, 6, 1], state: "minecraft:deepslate_bricks"},
        {pos: [2, 6, 13], state: "minecraft:deepslate_bricks"},
        {pos: [2, 6, 14], state: "minecraft:deepslate_bricks"},
        {pos: [3, 6, 13], state: "minecraft:deepslate_bricks"},
        {pos: [3, 6, 14], state: "minecraft:deepslate_bricks"},
        {pos: [4, 6, 5], state: "minecraft:deepslate_tiles"},
        {pos: [4, 6, 10], state: "minecraft:deepslate_bricks"},
        {pos: [5, 6, 5], state: "minecraft:deepslate_tiles"},
        {pos: [5, 6, 6], state: "minecraft:deepslate_tiles"},
        {pos: [5, 6, 9], state: "minecraft:deepslate_tiles"},
        {pos: [5, 6, 10], state: "minecraft:deepslate_bricks"},
        {pos: [1, 7, 13], state: "minecraft:deepslate_bricks"},
        {pos: [2, 7, 13], state: "minecraft:deepslate_bricks"},
        {pos: [2, 7, 14], state: "minecraft:deepslate_bricks"},
        {pos: [3, 7, 13], state: "minecraft:deepslate_bricks"},
        {pos: [3, 7, 14], state: "minecraft:deepslate_bricks"},
        {pos: [4, 7, 5], state: "minecraft:deepslate_tiles"},
        {pos: [4, 7, 10], state: "minecraft:deepslate_bricks"},
        {pos: [5, 7, 5], state: "minecraft:deepslate_tiles"},
        {pos: [5, 7, 10], state: "minecraft:deepslate_bricks"},
        {pos: [4, 8, 5], state: "minecraft:deepslate_tiles"},
        {pos: [4, 8, 10], state: "minecraft:deepslate_bricks"},
        {pos: [5, 8, 5], state: "minecraft:deepslate_tiles"},
        {pos: [5, 8, 6], state: "minecraft:deepslate_tiles"},
        {pos: [5, 8, 9], state: "minecraft:deepslate_tiles"},
        {pos: [5, 8, 10], state: "minecraft:deepslate_bricks"},
        {pos: [4, 9, 6], state: "minecraft:deepslate_tiles"},
        {pos: [4, 9, 7], state: "minecraft:deepslate_tiles"},
        {pos: [4, 9, 8], state: "minecraft:deepslate_tiles"},
        {pos: [4, 9, 9], state: "minecraft:deepslate_tiles"},
        {pos: [5, 9, 5], state: "minecraft:deepslate_tiles"},
        {pos: [5, 9, 6], state: "minecraft:deepslate_tiles"},
        {pos: [5, 9, 7], state: "minecraft:deepslate_tiles"},
        {pos: [5, 9, 8], state: "minecraft:deepslate_tiles"},
        {pos: [5, 9, 9], state: "minecraft:deepslate_tiles"}
    ],
    entities: [],
    palette: [
        "minecraft:cobbled_deepslate",
        "minecraft:deepslate_bricks",
        "minecraft:deepslate_tiles",
        "minecraft:chiseled_deepslate",
        "minecraft:jigsaw{orientation:up_west}",
        "minecraft:jigsaw{orientation:east_up}",
        "minecraft:chest{facing:north,type:single,waterlogged:false}"
    ]
}
