{
    size: [10, 6, 11],
    data: [
        {pos: [0, 0, 1], state: "minecraft:deepslate_bricks"},
        {pos: [0, 0, 9], state: "minecraft:deepslate_bricks"},
        {pos: [1, 0, 0], state: "minecraft:deepslate_bricks"},
        {pos: [1, 0, 1], state: "minecraft:deepslate_bricks"},
        {pos: [1, 0, 2], state: "minecraft:deepslate_bricks"},
        {pos: [1, 0, 7], state: "minecraft:deepslate_bricks"},
        {pos: [1, 0, 8], state: "minecraft:deepslate_bricks"},
        {pos: [1, 0, 9], state: "minecraft:deepslate_bricks"},
        {pos: [1, 0, 10], state: "minecraft:deepslate_bricks"},
        {pos: [2, 0, 0], state: "minecraft:deepslate_bricks"},
        {pos: [2, 0, 1], state: "minecraft:cobbled_deepslate"},
        {pos: [2, 0, 2], state: "minecraft:cobbled_deepslate"},
        {pos: [2, 0, 3], state: "minecraft:deepslate_bricks"},
        {pos: [2, 0, 4], state: "minecraft:deepslate_bricks"},
        {pos: [2, 0, 6], state: "minecraft:deepslate_bricks"},
        {pos: [2, 0, 7], state: "minecraft:cobbled_deepslate"},
        {pos: [2, 0, 8], state: "minecraft:cobbled_deepslate"},
        {pos: [2, 0, 9], state: "minecraft:cobbled_deepslate"},
        {pos: [2, 0, 10], state: "minecraft:deepslate_bricks"},
        {pos: [3, 0, 0], state: "minecraft:deepslate_bricks"},
        {pos: [3, 0, 3], state: "minecraft:deepslate_bricks"},
        {pos: [3, 0, 4], state: "minecraft:deepslate_bricks"},
        {pos: [3, 0, 6], state: "minecraft:deepslate_bricks"},
        {pos: [3, 0, 9], state: "minecraft:cobbled_deepslate"},
        {pos: [3, 0, 10], state: "minecraft:deepslate_bricks"},
        {pos: [4, 0, 0], state: "minecraft:deepslate_bricks"},
        {pos: [4, 0, 1], state: "minecraft:cobbled_deepslate"},
        {pos: [4, 0, 3], state: "minecraft:deepslate_tiles"},
        {pos: [4, 0, 4], state: "minecraft:deepslate_tiles"},
        {pos: [4, 0, 5], state: "minecraft:deepslate_tiles"},
        {pos: [4, 0, 6], state: "minecraft:deepslate_tiles"},
        {pos: [4, 0, 7], state: "minecraft:jigsaw{orientation:up_north}", nbt: {final_state: "minecraft:deepslate", id: "minecraft:jigsaw", joint: "rollable", name: "minecraft:bottom", pool: "minecraft:ancient_city/sculk", target: "minecraft:bottom"}},
        {pos: [4, 0, 9], state: "minecraft:cobbled_deepslate"},
        {pos: [4, 0, 10], state: "minecraft:deepslate_bricks"},
        {pos: [5, 0, 0], state: "minecraft:deepslate_bricks"},
        {pos: [5, 0, 1], state: "minecraft:cobbled_deepslate"},
        {pos: [5, 0, 3], state: "minecraft:deepslate_tiles"},
        {pos: [5, 0, 4], state: "minecraft:deepslate_tiles"},
        {pos: [5, 0, 5], state: "minecraft:deepslate_tiles"},
        {pos: [5, 0, 6], state: "minecraft:deepslate_tiles"},
        {pos: [5, 0, 7], state: "minecraft:deepslate_tiles"},
        {pos: [5, 0, 9], state: "minecraft:cobbled_deepslate"},
        {pos: [5, 0, 10], state: "minecraft:deepslate_bricks"},
        {pos: [6, 0, 0], state: "minecraft:deepslate_bricks"},
        {pos: [6, 0, 1], state: "minecraft:cobbled_deepslate"},
        {pos: [6, 0, 3], state: "minecraft:deepslate_tiles"},
        {pos: [6, 0, 4], state: "minecraft:deepslate_tiles"},
        {pos: [6, 0, 5], state: "minecraft:deepslate_tiles"},
        {pos: [6, 0, 6], state: "minecraft:deepslate_tiles"},
        {pos: [6, 0, 7], state: "minecraft:deepslate_tiles"},
        {pos: [6, 0, 9], state: "minecraft:cobbled_deepslate"},
        {pos: [6, 0, 10], state: "minecraft:deepslate_bricks"},
        {pos: [7, 0, 0], state: "minecraft:deepslate_bricks"},
        {pos: [7, 0, 1], state: "minecraft:cobbled_deepslate"},
        {pos: [7, 0, 3], state: "minecraft:deepslate_tiles"},
        {pos: [7, 0, 4], state: "minecraft:deepslate_tiles"},
        {pos: [7, 0, 5], state: "minecraft:deepslate_tiles"},
        {pos: [7, 0, 6], state: "minecraft:deepslate_tiles"},
        {pos: [7, 0, 7], state: "minecraft:deepslate_tiles"},
        {pos: [7, 0, 8], state: "minecraft:cobbled_deepslate"},
        {pos: [7, 0, 9], state: "minecraft:cobbled_deepslate"},
        {pos: [7, 0, 10], state: "minecraft:deepslate_bricks"},
        {pos: [8, 0, 0], state: "minecraft:deepslate_bricks"},
        {pos: [8, 0, 1], state: "minecraft:cobbled_deepslate"},
        {pos: [8, 0, 2], state: "minecraft:deepslate_bricks"},
        {pos: [8, 0, 3], state: "minecraft:deepslate_bricks"},
        {pos: [8, 0, 4], state: "minecraft:deepslate_bricks"},
        {pos: [8, 0, 5], state: "minecraft:deepslate_bricks"},
        {pos: [8, 0, 6], state: "minecraft:deepslate_bricks"},
        {pos: [8, 0, 7], state: "minecraft:deepslate_bricks"},
        {pos: [8, 0, 8], state: "minecraft:cobbled_deepslate"},
        {pos: [8, 0, 9], state: "minecraft:cobbled_deepslate"},
        {pos: [8, 0, 10], state: "minecraft:deepslate_bricks"},
        {pos: [9, 0, 0], state: "minecraft:deepslate_bricks"},
        {pos: [9, 0, 1], state: "minecraft:cobbled_deepslate"},
        {pos: [9, 0, 2], state: "minecraft:deepslate_bricks"},
        {pos: [9, 0, 3], state: "minecraft:deepslate_bricks"},
        {pos: [9, 0, 4], state: "minecraft:deepslate_bricks"},
        {pos: [9, 0, 5], state: "minecraft:jigsaw{orientation:east_up}", nbt: {final_state: "minecraft:structure_void", id: "minecraft:jigsaw", joint: "rollable", name: "minecraft:connect_structure", pool: "minecraft:empty", target: "minecraft:empty"}},
        {pos: [9, 0, 6], state: "minecraft:deepslate_bricks"},
        {pos: [9, 0, 7], state: "minecraft:deepslate_bricks"},
        {pos: [9, 0, 8], state: "minecraft:cobbled_deepslate"},
        {pos: [9, 0, 9], state: "minecraft:cobbled_deepslate"},
        {pos: [9, 0, 10], state: "minecraft:deepslate_bricks"},
        {pos: [0, 1, 1], state: "minecraft:deepslate_tiles"},
        {pos: [0, 1, 9], state: "minecraft:deepslate_tiles"},
        {pos: [1, 1, 0], state: "minecraft:cobbled_deepslate"},
        {pos: [1, 1, 1], state: "minecraft:cobbled_deepslate"},
        {pos: [1, 1, 2], state: "minecraft:deepslate_tiles"},
        {pos: [1, 1, 8], state: "minecraft:deepslate_bricks"},
        {pos: [1, 1, 9], state: "minecraft:deepslate_tiles"},
        {pos: [1, 1, 10], state: "minecraft:deepslate_tiles"},
        {pos: [2, 1, 0], state: "minecraft:cobbled_deepslate"},
        {pos: [2, 1, 1], state: "minecraft:cobbled_deepslate"},
        {pos: [2, 1, 2], state: "minecraft:cobbled_deepslate"},
        {pos: [2, 1, 3], state: "minecraft:deepslate_bricks"},
        {pos: [2, 1, 7], state: "minecraft:deepslate_bricks"},
        {pos: [2, 1, 8], state: "minecraft:cobbled_deepslate"},
        {pos: [2, 1, 9], state: "minecraft:cobbled_deepslate"},
        {pos: [2, 1, 10], state: "minecraft:cobbled_deepslate"},
        {pos: [3, 1, 0], state: "minecraft:cobbled_deepslate"},
        {pos: [3, 1, 1], state: "minecraft:cobbled_deepslate"},
        {pos: [3, 1, 2], state: "minecraft:deepslate_bricks"},
        {pos: [3, 1, 3], state: "minecraft:deepslate_bricks"},
        {pos: [3, 1, 7], state: "minecraft:deepslate_bricks"},
        {pos: [3, 1, 8], state: "minecraft:deepslate_bricks"},
        {pos: [3, 1, 10], state: "minecraft:cobbled_deepslate"},
        {pos: [4, 1, 0], state: "minecraft:cobbled_deepslate"},
        {pos: [4, 1, 2], state: "minecraft:deepslate_bricks"},
        {pos: [4, 1, 8], state: "minecraft:deepslate_bricks"},
        {pos: [4, 1, 9], state: "minecraft:cobbled_deepslate"},
        {pos: [4, 1, 10], state: "minecraft:cobbled_deepslate"},
        {pos: [5, 1, 0], state: "minecraft:cobbled_deepslate"},
        {pos: [5, 1, 1], state: "minecraft:cobbled_deepslate"},
        {pos: [5, 1, 2], state: "minecraft:deepslate_bricks"},
        {pos: [5, 1, 8], state: "minecraft:deepslate_bricks"},
        {pos: [5, 1, 10], state: "minecraft:cobbled_deepslate"},
        {pos: [6, 1, 0], state: "minecraft:cobbled_deepslate"},
        {pos: [6, 1, 2], state: "minecraft:deepslate_bricks"},
        {pos: [6, 1, 8], state: "minecraft:deepslate_bricks"},
        {pos: [6, 1, 9], state: "minecraft:cobbled_deepslate"},
        {pos: [6, 1, 10], state: "minecraft:cobbled_deepslate"},
        {pos: [7, 1, 0], state: "minecraft:cobbled_deepslate"},
        {pos: [7, 1, 1], state: "minecraft:cobbled_deepslate"},
        {pos: [7, 1, 2], state: "minecraft:deepslate_bricks"},
        {pos: [7, 1, 5], state: "minecraft:chest{facing:west,type:single,waterlogged:false}", nbt: {LootTable: "minecraft:chests/ancient_city", id: "minecraft:chest"}},
        {pos: [7, 1, 8], state: "minecraft:deepslate_bricks"},
        {pos: [7, 1, 10], state: "minecraft:cobbled_deepslate"},
        {pos: [8, 1, 0], state: "minecraft:deepslate_bricks"},
        {pos: [8, 1, 1], state: "minecraft:cobbled_deepslate"},
        {pos: [8, 1, 2], state: "minecraft:deepslate_bricks"},
        {pos: [8, 1, 3], state: "minecraft:deepslate_bricks"},
        {pos: [8, 1, 4], state: "minecraft:deepslate_bricks"},
        {pos: [8, 1, 5], state: "minecraft:deepslate_bricks"},
        {pos: [8, 1, 6], state: "minecraft:deepslate_bricks"},
        {pos: [8, 1, 7], state: "minecraft:deepslate_bricks"},
        {pos: [8, 1, 8], state: "minecraft:deepslate_bricks"},
        {pos: [8, 1, 9], state: "minecraft:cobbled_deepslate"},
        {pos: [8, 1, 10], state: "minecraft:cobbled_deepslate"},
        {pos: [9, 1, 0], state: "minecraft:deepslate_bricks"},
        {pos: [9, 1, 1], state: "minecraft:cobbled_deepslate"},
        {pos: [9, 1, 2], state: "minecraft:deepslate_bricks"},
        {pos: [9, 1, 3], state: "minecraft:deepslate_bricks"},
        {pos: [9, 1, 4], state: "minecraft:deepslate_bricks"},
        {pos: [9, 1, 5], state: "minecraft:deepslate_bricks"},
        {pos: [9, 1, 6], state: "minecraft:deepslate_bricks"},
        {pos: [9, 1, 7], state: "minecraft:deepslate_bricks"},
        {pos: [9, 1, 8], state: "minecraft:deepslate_bricks"},
        {pos: [9, 1, 9], state: "minecraft:cobbled_deepslate"},
        {pos: [9, 1, 10], state: "minecraft:cobbled_deepslate"},
        {pos: [0, 2, 1], state: "minecraft:cobbled_deepslate"},
        {pos: [0, 2, 9], state: "minecraft:deepslate_tiles"},
        {pos: [1, 2, 0], state: "minecraft:cobbled_deepslate"},
        {pos: [1, 2, 1], state: "minecraft:cobbled_deepslate"},
        {pos: [1, 2, 2], state: "minecraft:deepslate_tiles"},
        {pos: [1, 2, 8], state: "minecraft:deepslate_tiles"},
        {pos: [1, 2, 9], state: "minecraft:cobbled_deepslate"},
        {pos: [1, 2, 10], state: "minecraft:deepslate_tiles"},
        {pos: [2, 2, 1], state: "minecraft:cobbled_deepslate"},
        {pos: [2, 2, 2], state: "minecraft:cobbled_deepslate"},
        {pos: [2, 2, 8], state: "minecraft:cobbled_deepslate"},
        {pos: [2, 2, 9], state: "minecraft:cobbled_deepslate"},
        {pos: [8, 2, 1], state: "minecraft:cobbled_deepslate"},
        {pos: [9, 2, 1], state: "minecraft:cobbled_deepslate"},
        {pos: [9, 2, 2], state: "minecraft:cobbled_deepslate"},
        {pos: [9, 2, 3], state: "minecraft:deepslate_tiles"},
        {pos: [9, 2, 4], state: "minecraft:deepslate_tiles"},
        {pos: [9, 2, 5], state: "minecraft:deepslate_tiles"},
        {pos: [9, 2, 6], state: "minecraft:deepslate_tiles"},
        {pos: [9, 2, 7], state: "minecraft:deepslate_tiles"},
        {pos: [9, 2, 8], state: "minecraft:deepslate_tiles"},
        {pos: [9, 2, 9], state: "minecraft:cobbled_deepslate"},
        {pos: [0, 3, 1], state: "minecraft:cobbled_deepslate"},
        {pos: [0, 3, 9], state: "minecraft:deepslate_tiles"},
        {pos: [1, 3, 0], state: "minecraft:cobbled_deepslate"},
        {pos: [1, 3, 1], state: "minecraft:chiseled_deepslate"},
        {pos: [1, 3, 2], state: "minecraft:cobbled_deepslate"},
        {pos: [1, 3, 8], state: "minecraft:cobbled_deepslate"},
        {pos: [1, 3, 9], state: "minecraft:cobbled_deepslate"},
        {pos: [1, 3, 10], state: "minecraft:cobbled_deepslate"},
        {pos: [2, 3, 1], state: "minecraft:cobbled_deepslate"},
        {pos: [2, 3, 2], state: "minecraft:cobbled_deepslate"},
        {pos: [2, 3, 8], state: "minecraft:cobbled_deepslate"},
        {pos: [2, 3, 9], state: "minecraft:cobbled_deepslate"},
        {pos: [9, 3, 3], state: "minecraft:cobbled_deepslate"},
        {pos: [9, 3, 4], state: "minecraft:deepslate_tiles"},
        {pos: [9, 3, 5], state: "minecraft:deepslate_tiles"},
        {pos: [9, 3, 6], state: "minecraft:deepslate_tiles"},
        {pos: [9, 3, 7], state: "minecraft:cobbled_deepslate"},
        {pos: [9, 3, 8], state: "minecraft:deepslate_tiles"},
        {pos: [9, 3, 9], state: "minecraft:cobbled_deepslate"},
        {pos: [0, 4, 1], state: "minecraft:chiseled_deepslate"},
        {pos: [0, 4, 9], state: "minecraft:chiseled_deepslate"},
        {pos: [1, 4, 1], state: "minecraft:cobbled_deepslate"},
        {pos: [9, 4, 4], state: "minecraft:cobbled_deepslate"},
        {pos: [9, 4, 5], state: "minecraft:cobbled_deepslate"},
        {pos: [9, 4, 6], state: "minecraft:cobbled_deepslate"},
        {pos: [9, 4, 7], state: "minecraft:deepslate_tiles"},
        {pos: [9, 4, 8], state: "minecraft:cobbled_deepslate"},
        {pos: [9, 4, 9], state: "minecraft:cobbled_deepslate"},
        {pos: [0, 5, 1], state: "minecraft:deepslate_bricks"},
        {pos: [0, 5, 9], state: "minecraft:deepslate_bricks"},
        {pos: [9, 5, 5], state: "minecraft:cobbled_deepslate"},
        {pos: [9, 5, 6], state: "minecraft:cobbled_deepslate"},
        {pos: [9, 5, 7], state: "minecraft:cobbled_deepslate"},
        {pos: [9, 5, 8], state: "minecraft:cobbled_deepslate"}
    ],
    entities: [],
    palette: [
        "minecraft:deepslate_bricks",
        "minecraft:cobbled_deepslate",
        "minecraft:deepslate_tiles",
        "minecraft:chiseled_deepslate",
        "minecraft:jigsaw{orientation:up_north}",
        "minecraft:jigsaw{orientation:east_up}",
        "minecraft:chest{facing:west,type:single,waterlogged:false}"
    ]
}
