{
    size: [7, 11, 8],
    data: [
        {pos: [1, 0, 2], state: "minecraft:deepslate{axis:y}"},
        {pos: [1, 0, 3], state: "minecraft:deepslate{axis:y}"},
        {pos: [1, 0, 4], state: "minecraft:deepslate{axis:y}"},
        {pos: [1, 0, 5], state: "minecraft:deepslate{axis:y}"},
        {pos: [2, 0, 2], state: "minecraft:deepslate{axis:y}"},
        {pos: [2, 0, 3], state: "minecraft:deepslate{axis:y}"},
        {pos: [2, 0, 4], state: "minecraft:deepslate{axis:y}"},
        {pos: [2, 0, 5], state: "minecraft:deepslate{axis:y}"},
        {pos: [3, 0, 2], state: "minecraft:deepslate{axis:y}"},
        {pos: [3, 0, 3], state: "minecraft:deepslate{axis:y}"},
        {pos: [3, 0, 4], state: "minecraft:deepslate{axis:y}"},
        {pos: [3, 0, 5], state: "minecraft:deepslate{axis:y}"},
        {pos: [4, 0, 2], state: "minecraft:deepslate{axis:y}"},
        {pos: [4, 0, 3], state: "minecraft:deepslate{axis:y}"},
        {pos: [4, 0, 4], state: "minecraft:deepslate{axis:y}"},
        {pos: [4, 0, 5], state: "minecraft:deepslate{axis:y}"},
        {pos: [6, 0, 3], state: "minecraft:jigsaw{orientation:east_up}", nbt: {final_state: "minecraft:structure_void", id: "minecraft:jigsaw", joint: "rollable", name: "minecraft:connect_structure", pool: "minecraft:empty", target: "minecraft:empty"}},
        {pos: [6, 0, 4], state: "minecraft:jigsaw{orientation:east_up}", nbt: {final_state: "minecraft:structure_void", id: "minecraft:jigsaw", joint: "rollable", name: "minecraft:connect_structure", pool: "minecraft:empty", target: "minecraft:empty"}},
        {pos: [1, 1, 2], state: "minecraft:deepslate_tile_stairs{facing:south,half:bottom,shape:outer_left,waterlogged:false}"},
        {pos: [1, 1, 3], state: "minecraft:deepslate_tile_stairs{facing:east,half:bottom,shape:straight,waterlogged:false}"},
        {pos: [1, 1, 4], state: "minecraft:deepslate_tile_stairs{facing:east,half:bottom,shape:straight,waterlogged:false}"},
        {pos: [1, 1, 5], state: "minecraft:deepslate_tile_stairs{facing:east,half:bottom,shape:outer_left,waterlogged:false}"},
        {pos: [2, 1, 2], state: "minecraft:deepslate_tile_stairs{facing:south,half:bottom,shape:straight,waterlogged:false}"},
        {pos: [2, 1, 3], state: "minecraft:deepslate{axis:y}"},
        {pos: [2, 1, 4], state: "minecraft:deepslate{axis:y}"},
        {pos: [2, 1, 5], state: "minecraft:deepslate_tile_stairs{facing:north,half:bottom,shape:straight,waterlogged:false}"},
        {pos: [3, 1, 2], state: "minecraft:deepslate_tile_stairs{facing:south,half:bottom,shape:straight,waterlogged:false}"},
        {pos: [3, 1, 3], state: "minecraft:deepslate{axis:y}"},
        {pos: [3, 1, 4], state: "minecraft:deepslate{axis:y}"},
        {pos: [3, 1, 5], state: "minecraft:deepslate_tile_stairs{facing:north,half:bottom,shape:straight,waterlogged:false}"},
        {pos: [4, 1, 2], state: "minecraft:deepslate_tile_slab{type:bottom,waterlogged:false}"},
        {pos: [4, 1, 4], state: "minecraft:skeleton_skull{rotation:2}", nbt: {id: "minecraft:skull"}},
        {pos: [4, 1, 5], state: "minecraft:deepslate_tile_slab{type:bottom,waterlogged:false}"},
        {pos: [2, 2, 3], state: "minecraft:deepslate{axis:y}"},
        {pos: [2, 2, 4], state: "minecraft:deepslate{axis:y}"},
        {pos: [3, 2, 3], state: "minecraft:deepslate{axis:y}"},
        {pos: [3, 2, 4], state: "minecraft:deepslate{axis:y}"},
        {pos: [2, 3, 3], state: "minecraft:polished_deepslate"},
        {pos: [2, 3, 4], state: "minecraft:polished_deepslate"},
        {pos: [3, 3, 3], state: "minecraft:polished_deepslate"},
        {pos: [3, 3, 4], state: "minecraft:polished_deepslate"},
        {pos: [2, 4, 3], state: "minecraft:chiseled_deepslate"},
        {pos: [2, 4, 4], state: "minecraft:chiseled_deepslate"},
        {pos: [3, 4, 3], state: "minecraft:chiseled_deepslate"},
        {pos: [3, 4, 4], state: "minecraft:chiseled_deepslate"},
        {pos: [2, 5, 3], state: "minecraft:deepslate_tiles"},
        {pos: [2, 5, 4], state: "minecraft:deepslate_tiles"},
        {pos: [3, 5, 3], state: "minecraft:deepslate_tiles"},
        {pos: [3, 5, 4], state: "minecraft:deepslate_tiles"},
        {pos: [2, 6, 3], state: "minecraft:polished_deepslate"},
        {pos: [2, 6, 4], state: "minecraft:polished_deepslate"},
        {pos: [3, 6, 3], state: "minecraft:polished_deepslate"},
        {pos: [3, 6, 4], state: "minecraft:polished_deepslate"},
        {pos: [2, 7, 3], state: "minecraft:deepslate{axis:y}"},
        {pos: [2, 7, 4], state: "minecraft:deepslate{axis:y}"},
        {pos: [3, 7, 3], state: "minecraft:deepslate{axis:y}"},
        {pos: [3, 7, 4], state: "minecraft:deepslate{axis:y}"},
        {pos: [1, 8, 2], state: "minecraft:deepslate_tile_stairs{facing:south,half:top,shape:outer_left,waterlogged:false}"},
        {pos: [1, 8, 3], state: "minecraft:deepslate_tile_stairs{facing:east,half:top,shape:straight,waterlogged:false}"},
        {pos: [1, 8, 4], state: "minecraft:deepslate_tile_stairs{facing:east,half:top,shape:straight,waterlogged:false}"},
        {pos: [1, 8, 5], state: "minecraft:deepslate_tile_stairs{facing:north,half:top,shape:outer_right,waterlogged:false}"},
        {pos: [2, 8, 2], state: "minecraft:deepslate_tile_stairs{facing:south,half:top,shape:straight,waterlogged:false}"},
        {pos: [2, 8, 3], state: "minecraft:deepslate{axis:y}"},
        {pos: [2, 8, 4], state: "minecraft:deepslate{axis:y}"},
        {pos: [2, 8, 5], state: "minecraft:deepslate_tile_stairs{facing:north,half:top,shape:straight,waterlogged:false}"},
        {pos: [3, 8, 2], state: "minecraft:deepslate_tile_stairs{facing:south,half:top,shape:straight,waterlogged:false}"},
        {pos: [3, 8, 3], state: "minecraft:deepslate{axis:y}"},
        {pos: [3, 8, 4], state: "minecraft:deepslate{axis:y}"},
        {pos: [3, 8, 5], state: "minecraft:deepslate_tile_stairs{facing:north,half:top,shape:straight,waterlogged:false}"},
        {pos: [4, 8, 2], state: "minecraft:deepslate_tile_stairs{facing:west,half:top,shape:outer_left,waterlogged:false}"},
        {pos: [4, 8, 3], state: "minecraft:deepslate_tile_stairs{facing:west,half:top,shape:straight,waterlogged:false}"},
        {pos: [4, 8, 4], state: "minecraft:deepslate_tile_stairs{facing:west,half:top,shape:straight,waterlogged:false}"},
        {pos: [4, 8, 5], state: "minecraft:deepslate_tile_stairs{facing:west,half:top,shape:outer_right,waterlogged:false}"},
        {pos: [0, 9, 3], state: "minecraft:deepslate{axis:y}"},
        {pos: [0, 9, 4], state: "minecraft:deepslate{axis:y}"},
        {pos: [0, 9, 5], state: "minecraft:deepslate{axis:y}"},
        {pos: [0, 9, 6], state: "minecraft:deepslate{axis:y}"},
        {pos: [1, 9, 2], state: "minecraft:polished_deepslate"},
        {pos: [1, 9, 3], state: "minecraft:deepslate{axis:y}"},
        {pos: [1, 9, 4], state: "minecraft:deepslate{axis:y}"},
        {pos: [1, 9, 5], state: "minecraft:deepslate{axis:y}"},
        {pos: [1, 9, 6], state: "minecraft:deepslate{axis:y}"},
        {pos: [2, 9, 1], state: "minecraft:deepslate{axis:y}"},
        {pos: [2, 9, 2], state: "minecraft:deepslate{axis:y}"},
        {pos: [2, 9, 3], state: "minecraft:deepslate{axis:y}"},
        {pos: [2, 9, 4], state: "minecraft:deepslate{axis:y}"},
        {pos: [2, 9, 5], state: "minecraft:deepslate{axis:y}"},
        {pos: [2, 9, 6], state: "minecraft:deepslate{axis:y}"},
        {pos: [3, 9, 0], state: "minecraft:deepslate{axis:z}"},
        {pos: [3, 9, 1], state: "minecraft:deepslate{axis:y}"},
        {pos: [3, 9, 2], state: "minecraft:deepslate{axis:y}"},
        {pos: [3, 9, 3], state: "minecraft:deepslate{axis:y}"},
        {pos: [3, 9, 4], state: "minecraft:deepslate{axis:y}"},
        {pos: [3, 9, 5], state: "minecraft:deepslate{axis:y}"},
        {pos: [3, 9, 6], state: "minecraft:deepslate{axis:y}"},
        {pos: [4, 9, 1], state: "minecraft:deepslate{axis:y}"},
        {pos: [4, 9, 2], state: "minecraft:polished_deepslate"},
        {pos: [4, 9, 3], state: "minecraft:deepslate{axis:y}"},
        {pos: [4, 9, 4], state: "minecraft:deepslate{axis:y}"},
        {pos: [4, 9, 5], state: "minecraft:deepslate{axis:y}"},
        {pos: [5, 9, 3], state: "minecraft:deepslate{axis:y}"},
        {pos: [5, 9, 4], state: "minecraft:deepslate{axis:y}"},
        {pos: [5, 9, 5], state: "minecraft:deepslate{axis:y}"},
        {pos: [6, 9, 3], state: "minecraft:deepslate{axis:y}"},
        {pos: [6, 9, 4], state: "minecraft:deepslate{axis:y}"},
        {pos: [0, 10, 5], state: "minecraft:deepslate{axis:y}"},
        {pos: [0, 10, 6], state: "minecraft:deepslate{axis:y}"},
        {pos: [0, 10, 7], state: "minecraft:deepslate{axis:y}"},
        {pos: [1, 10, 3], state: "minecraft:deepslate{axis:y}"},
        {pos: [1, 10, 4], state: "minecraft:deepslate{axis:y}"},
        {pos: [1, 10, 5], state: "minecraft:deepslate{axis:y}"},
        {pos: [1, 10, 6], state: "minecraft:deepslate{axis:y}"},
        {pos: [1, 10, 7], state: "minecraft:deepslate{axis:y}"},
        {pos: [2, 10, 2], state: "minecraft:deepslate{axis:y}"},
        {pos: [2, 10, 3], state: "minecraft:deepslate{axis:y}"},
        {pos: [2, 10, 4], state: "minecraft:deepslate{axis:y}"},
        {pos: [2, 10, 5], state: "minecraft:deepslate{axis:y}"},
        {pos: [2, 10, 6], state: "minecraft:deepslate{axis:y}"},
        {pos: [2, 10, 7], state: "minecraft:deepslate{axis:y}"},
        {pos: [3, 10, 2], state: "minecraft:deepslate{axis:y}"},
        {pos: [3, 10, 3], state: "minecraft:deepslate{axis:y}"},
        {pos: [3, 10, 4], state: "minecraft:deepslate{axis:y}"},
        {pos: [3, 10, 5], state: "minecraft:deepslate{axis:y}"},
        {pos: [4, 10, 3], state: "minecraft:deepslate{axis:y}"},
        {pos: [4, 10, 4], state: "minecraft:deepslate{axis:y}"},
        {pos: [4, 10, 5], state: "minecraft:deepslate{axis:y}"},
        {pos: [5, 10, 3], state: "minecraft:deepslate{axis:y}"},
        {pos: [5, 10, 4], state: "minecraft:deepslate{axis:y}"},
        {pos: [5, 10, 5], state: "minecraft:deepslate{axis:y}"},
        {pos: [6, 10, 3], state: "minecraft:deepslate{axis:y}"}
    ],
    entities: [],
    palette: [
        "minecraft:deepslate{axis:y}",
        "minecraft:polished_deepslate",
        "minecraft:chiseled_deepslate",
        "minecraft:deepslate_tiles",
        "minecraft:deepslate{axis:z}",
        "minecraft:deepslate_tile_stairs{facing:south,half:bottom,shape:outer_left,waterlogged:false}",
        "minecraft:deepslate_tile_stairs{facing:east,half:bottom,shape:straight,waterlogged:false}",
        "minecraft:deepslate_tile_stairs{facing:east,half:bottom,shape:outer_left,waterlogged:false}",
        "minecraft:deepslate_tile_stairs{facing:south,half:bottom,shape:straight,waterlogged:false}",
        "minecraft:deepslate_tile_stairs{facing:north,half:bottom,shape:straight,waterlogged:false}",
        "minecraft:deepslate_tile_slab{type:bottom,waterlogged:false}",
        "minecraft:deepslate_tile_stairs{facing:south,half:top,shape:outer_left,waterlogged:false}",
        "minecraft:deepslate_tile_stairs{facing:east,half:top,shape:straight,waterlogged:false}",
        "minecraft:deepslate_tile_stairs{facing:north,half:top,shape:outer_right,waterlogged:false}",
        "minecraft:deepslate_tile_stairs{facing:south,half:top,shape:straight,waterlogged:false}",
        "minecraft:deepslate_tile_stairs{facing:north,half:top,shape:straight,waterlogged:false}",
        "minecraft:deepslate_tile_stairs{facing:west,half:top,shape:outer_left,waterlogged:false}",
        "minecraft:deepslate_tile_stairs{facing:west,half:top,shape:straight,waterlogged:false}",
        "minecraft:deepslate_tile_stairs{facing:west,half:top,shape:outer_right,waterlogged:false}",
        "minecraft:jigsaw{orientation:east_up}",
        "minecraft:skeleton_skull{rotation:2}"
    ]
}
