{
    size: [29, 10, 37],
    data: [
        {pos: [0, 0, 0], state: "minecraft:deepslate_bricks"},
        {pos: [0, 0, 13], state: "minecraft:deepslate_bricks"},
        {pos: [0, 0, 14], state: "minecraft:deepslate_bricks"},
        {pos: [0, 0, 15], state: "minecraft:deepslate_bricks"},
        {pos: [0, 0, 16], state: "minecraft:deepslate_bricks"},
        {pos: [0, 0, 17], state: "minecraft:deepslate_bricks"},
        {pos: [0, 0, 18], state: "minecraft:deepslate_bricks"},
        {pos: [0, 0, 19], state: "minecraft:deepslate_bricks"},
        {pos: [0, 0, 20], state: "minecraft:deepslate_bricks"},
        {pos: [0, 0, 21], state: "minecraft:deepslate_bricks"},
        {pos: [0, 0, 22], state: "minecraft:deepslate_bricks"},
        {pos: [0, 0, 23], state: "minecraft:deepslate_bricks"},
        {pos: [0, 0, 24], state: "minecraft:deepslate_bricks"},
        {pos: [0, 0, 25], state: "minecraft:deepslate_bricks"},
        {pos: [0, 0, 26], state: "minecraft:deepslate_bricks"},
        {pos: [0, 0, 27], state: "minecraft:deepslate_bricks"},
        {pos: [1, 0, 0], state: "minecraft:deepslate_bricks"},
        {pos: [1, 0, 1], state: "minecraft:deepslate_bricks"},
        {pos: [1, 0, 2], state: "minecraft:deepslate_bricks"},
        {pos: [1, 0, 14], state: "minecraft:deepslate_bricks"},
        {pos: [1, 0, 15], state: "minecraft:deepslate_bricks"},
        {pos: [1, 0, 16], state: "minecraft:deepslate_bricks"},
        {pos: [1, 0, 17], state: "minecraft:deepslate_bricks"},
        {pos: [1, 0, 18], state: "minecraft:deepslate_bricks"},
        {pos: [1, 0, 19], state: "minecraft:deepslate_bricks"},
        {pos: [1, 0, 20], state: "minecraft:deepslate_bricks"},
        {pos: [1, 0, 21], state: "minecraft:deepslate_bricks"},
        {pos: [1, 0, 22], state: "minecraft:deepslate_bricks"},
        {pos: [1, 0, 23], state: "minecraft:deepslate_bricks"},
        {pos: [1, 0, 24], state: "minecraft:deepslate_bricks"},
        {pos: [1, 0, 25], state: "minecraft:deepslate_bricks"},
        {pos: [1, 0, 26], state: "minecraft:deepslate_bricks"},
        {pos: [1, 0, 27], state: "minecraft:deepslate_bricks"},
        {pos: [2, 0, 0], state: "minecraft:deepslate_bricks"},
        {pos: [2, 0, 1], state: "minecraft:deepslate_bricks"},
        {pos: [2, 0, 2], state: "minecraft:deepslate_bricks"},
        {pos: [2, 0, 3], state: "minecraft:deepslate_bricks"},
        {pos: [2, 0, 4], state: "minecraft:deepslate_bricks"},
        {pos: [2, 0, 12], state: "minecraft:cracked_deepslate_bricks"},
        {pos: [2, 0, 13], state: "minecraft:deepslate_bricks"},
        {pos: [2, 0, 14], state: "minecraft:deepslate_bricks"},
        {pos: [2, 0, 15], state: "minecraft:deepslate_bricks"},
        {pos: [2, 0, 16], state: "minecraft:cracked_deepslate_bricks"},
        {pos: [2, 0, 17], state: "minecraft:deepslate_bricks"},
        {pos: [2, 0, 18], state: "minecraft:deepslate_bricks"},
        {pos: [2, 0, 19], state: "minecraft:deepslate_bricks"},
        {pos: [2, 0, 20], state: "minecraft:deepslate_bricks"},
        {pos: [2, 0, 21], state: "minecraft:deepslate_bricks"},
        {pos: [2, 0, 22], state: "minecraft:deepslate_bricks"},
        {pos: [2, 0, 23], state: "minecraft:deepslate_bricks"},
        {pos: [2, 0, 24], state: "minecraft:cracked_deepslate_bricks"},
        {pos: [2, 0, 25], state: "minecraft:cracked_deepslate_bricks"},
        {pos: [2, 0, 26], state: "minecraft:deepslate_bricks"},
        {pos: [2, 0, 27], state: "minecraft:deepslate_bricks"},
        {pos: [3, 0, 0], state: "minecraft:deepslate_bricks"},
        {pos: [3, 0, 1], state: "minecraft:deepslate_bricks"},
        {pos: [3, 0, 2], state: "minecraft:deepslate_bricks"},
        {pos: [3, 0, 3], state: "minecraft:deepslate_bricks"},
        {pos: [3, 0, 4], state: "minecraft:deepslate_bricks"},
        {pos: [3, 0, 5], state: "minecraft:deepslate_bricks"},
        {pos: [3, 0, 11], state: "minecraft:cracked_deepslate_bricks"},
        {pos: [3, 0, 12], state: "minecraft:cracked_deepslate_bricks"},
        {pos: [3, 0, 13], state: "minecraft:cracked_deepslate_bricks"},
        {pos: [3, 0, 14], state: "minecraft:deepslate_bricks"},
        {pos: [3, 0, 15], state: "minecraft:cracked_deepslate_bricks"},
        {pos: [3, 0, 16], state: "minecraft:deepslate_bricks"},
        {pos: [3, 0, 17], state: "minecraft:deepslate_bricks"},
        {pos: [3, 0, 18], state: "minecraft:cracked_deepslate_bricks"},
        {pos: [3, 0, 19], state: "minecraft:deepslate_bricks"},
        {pos: [3, 0, 20], state: "minecraft:cracked_deepslate_bricks"},
        {pos: [3, 0, 21], state: "minecraft:cracked_deepslate_bricks"},
        {pos: [3, 0, 22], state: "minecraft:deepslate_bricks"},
        {pos: [3, 0, 23], state: "minecraft:cracked_deepslate_bricks"},
        {pos: [3, 0, 24], state: "minecraft:deepslate_bricks"},
        {pos: [3, 0, 25], state: "minecraft:cracked_deepslate_bricks"},
        {pos: [3, 0, 26], state: "minecraft:cracked_deepslate_bricks"},
        {pos: [4, 0, 0], state: "minecraft:deepslate_bricks"},
        {pos: [4, 0, 1], state: "minecraft:deepslate_bricks"},
        {pos: [4, 0, 2], state: "minecraft:deepslate_bricks"},
        {pos: [4, 0, 3], state: "minecraft:deepslate_bricks"},
        {pos: [4, 0, 4], state: "minecraft:deepslate_bricks"},
        {pos: [4, 0, 5], state: "minecraft:deepslate_bricks"},
        {pos: [4, 0, 10], state: "minecraft:cracked_deepslate_bricks"},
        {pos: [4, 0, 11], state: "minecraft:deepslate{axis:y}"},
        {pos: [4, 0, 12], state: "minecraft:deepslate_bricks"},
        {pos: [4, 0, 13], state: "minecraft:deepslate_bricks"},
        {pos: [4, 0, 14], state: "minecraft:cracked_deepslate_bricks"},
        {pos: [4, 0, 15], state: "minecraft:deepslate_bricks"},
        {pos: [4, 0, 16], state: "minecraft:deepslate_bricks"},
        {pos: [4, 0, 17], state: "minecraft:cracked_deepslate_bricks"},
        {pos: [4, 0, 18], state: "minecraft:deepslate_bricks"},
        {pos: [4, 0, 19], state: "minecraft:deepslate_bricks"},
        {pos: [4, 0, 20], state: "minecraft:deepslate_bricks"},
        {pos: [4, 0, 21], state: "minecraft:cracked_deepslate_bricks"},
        {pos: [4, 0, 22], state: "minecraft:cracked_deepslate_bricks"},
        {pos: [4, 0, 23], state: "minecraft:cracked_deepslate_bricks"},
        {pos: [4, 0, 24], state: "minecraft:cracked_deepslate_bricks"},
        {pos: [4, 0, 25], state: "minecraft:deepslate_bricks"},
        {pos: [4, 0, 27], state: "minecraft:cracked_deepslate_bricks"},
        {pos: [4, 0, 28], state: "minecraft:deepslate_bricks"},
        {pos: [5, 0, 0], state: "minecraft:deepslate_bricks"},
        {pos: [5, 0, 1], state: "minecraft:deepslate_bricks"},
        {pos: [5, 0, 2], state: "minecraft:deepslate_bricks"},
        {pos: [5, 0, 3], state: "minecraft:deepslate_bricks"},
        {pos: [5, 0, 4], state: "minecraft:deepslate_bricks"},
        {pos: [5, 0, 5], state: "minecraft:deepslate_bricks"},
        {pos: [5, 0, 6], state: "minecraft:deepslate_bricks"},
        {pos: [5, 0, 7], state: "minecraft:deepslate_bricks"},
        {pos: [5, 0, 8], state: "minecraft:deepslate_bricks"},
        {pos: [5, 0, 9], state: "minecraft:cracked_deepslate_bricks"},
        {pos: [5, 0, 10], state: "minecraft:cracked_deepslate_bricks"},
        {pos: [5, 0, 11], state: "minecraft:deepslate{axis:y}"},
        {pos: [5, 0, 12], state: "minecraft:deepslate{axis:y}"},
        {pos: [5, 0, 13], state: "minecraft:deepslate_bricks"},
        {pos: [5, 0, 14], state: "minecraft:deepslate_bricks"},
        {pos: [5, 0, 15], state: "minecraft:deepslate_bricks"},
        {pos: [5, 0, 16], state: "minecraft:deepslate_bricks"},
        {pos: [5, 0, 17], state: "minecraft:deepslate_bricks"},
        {pos: [5, 0, 18], state: "minecraft:deepslate_bricks"},
        {pos: [5, 0, 19], state: "minecraft:deepslate_bricks"},
        {pos: [5, 0, 20], state: "minecraft:deepslate_bricks"},
        {pos: [5, 0, 21], state: "minecraft:deepslate_bricks"},
        {pos: [5, 0, 22], state: "minecraft:deepslate_bricks"},
        {pos: [5, 0, 23], state: "minecraft:deepslate_bricks"},
        {pos: [5, 0, 24], state: "minecraft:deepslate_bricks"},
        {pos: [5, 0, 25], state: "minecraft:deepslate_bricks"},
        {pos: [5, 0, 26], state: "minecraft:jigsaw{orientation:up_east}", nbt: {final_state: "minecraft:deepslate", id: "minecraft:jigsaw", joint: "rollable", name: "minecraft:bottom", pool: "minecraft:ancient_city/sculk", target: "minecraft:bottom"}},
        {pos: [5, 0, 27], state: "minecraft:deepslate_bricks"},
        {pos: [5, 0, 28], state: "minecraft:deepslate_bricks"},
        {pos: [5, 0, 29], state: "minecraft:deepslate_bricks"},
        {pos: [6, 0, 0], state: "minecraft:deepslate_bricks"},
        {pos: [6, 0, 1], state: "minecraft:deepslate_bricks"},
        {pos: [6, 0, 2], state: "minecraft:deepslate_bricks"},
        {pos: [6, 0, 3], state: "minecraft:deepslate_bricks"},
        {pos: [6, 0, 4], state: "minecraft:deepslate_bricks"},
        {pos: [6, 0, 5], state: "minecraft:deepslate_bricks"},
        {pos: [6, 0, 6], state: "minecraft:deepslate_bricks"},
        {pos: [6, 0, 7], state: "minecraft:deepslate_bricks"},
        {pos: [6, 0, 8], state: "minecraft:deepslate_bricks"},
        {pos: [6, 0, 9], state: "minecraft:deepslate_bricks"},
        {pos: [6, 0, 10], state: "minecraft:deepslate_bricks"},
        {pos: [6, 0, 11], state: "minecraft:deepslate{axis:y}"},
        {pos: [6, 0, 12], state: "minecraft:deepslate{axis:y}"},
        {pos: [6, 0, 13], state: "minecraft:deepslate_bricks"},
        {pos: [6, 0, 14], state: "minecraft:cracked_deepslate_bricks"},
        {pos: [6, 0, 15], state: "minecraft:deepslate_bricks"},
        {pos: [6, 0, 16], state: "minecraft:deepslate{axis:y}"},
        {pos: [6, 0, 17], state: "minecraft:deepslate{axis:y}"},
        {pos: [6, 0, 18], state: "minecraft:deepslate{axis:y}"},
        {pos: [6, 0, 19], state: "minecraft:deepslate{axis:y}"},
        {pos: [6, 0, 20], state: "minecraft:deepslate{axis:y}"},
        {pos: [6, 0, 21], state: "minecraft:deepslate{axis:y}"},
        {pos: [6, 0, 22], state: "minecraft:cracked_deepslate_bricks"},
        {pos: [6, 0, 23], state: "minecraft:cracked_deepslate_bricks"},
        {pos: [6, 0, 24], state: "minecraft:deepslate_bricks"},
        {pos: [6, 0, 25], state: "minecraft:deepslate_tiles"},
        {pos: [6, 0, 26], state: "minecraft:deepslate_tiles"},
        {pos: [6, 0, 27], state: "minecraft:deepslate_tiles"},
        {pos: [6, 0, 28], state: "minecraft:deepslate_tiles"},
        {pos: [6, 0, 29], state: "minecraft:deepslate_bricks"},
        {pos: [6, 0, 30], state: "minecraft:cracked_deepslate_bricks"},
        {pos: [7, 0, 0], state: "minecraft:deepslate_bricks"},
        {pos: [7, 0, 1], state: "minecraft:deepslate_bricks"},
        {pos: [7, 0, 2], state: "minecraft:deepslate_bricks"},
        {pos: [7, 0, 3], state: "minecraft:deepslate_tiles"},
        {pos: [7, 0, 4], state: "minecraft:deepslate_tiles"},
        {pos: [7, 0, 5], state: "minecraft:deepslate_tiles"},
        {pos: [7, 0, 6], state: "minecraft:deepslate_tiles"},
        {pos: [7, 0, 7], state: "minecraft:deepslate_tiles"},
        {pos: [7, 0, 8], state: "minecraft:deepslate_tiles"},
        {pos: [7, 0, 9], state: "minecraft:deepslate_tiles"},
        {pos: [7, 0, 10], state: "minecraft:deepslate_bricks"},
        {pos: [7, 0, 11], state: "minecraft:deepslate_bricks"},
        {pos: [7, 0, 12], state: "minecraft:deepslate{axis:y}"},
        {pos: [7, 0, 13], state: "minecraft:deepslate_bricks"},
        {pos: [7, 0, 14], state: "minecraft:deepslate_bricks"},
        {pos: [7, 0, 15], state: "minecraft:deepslate_bricks"},
        {pos: [7, 0, 16], state: "minecraft:deepslate{axis:y}"},
        {pos: [7, 0, 17], state: "minecraft:deepslate{axis:y}"},
        {pos: [7, 0, 18], state: "minecraft:deepslate{axis:y}"},
        {pos: [7, 0, 19], state: "minecraft:deepslate{axis:y}"},
        {pos: [7, 0, 20], state: "minecraft:deepslate{axis:y}"},
        {pos: [7, 0, 21], state: "minecraft:deepslate{axis:y}"},
        {pos: [7, 0, 22], state: "minecraft:deepslate_bricks"},
        {pos: [7, 0, 23], state: "minecraft:cracked_deepslate_bricks"},
        {pos: [7, 0, 24], state: "minecraft:deepslate_bricks"},
        {pos: [7, 0, 25], state: "minecraft:deepslate_tiles"},
        {pos: [7, 0, 26], state: "minecraft:deepslate_tiles"},
        {pos: [7, 0, 27], state: "minecraft:deepslate_tiles"},
        {pos: [7, 0, 28], state: "minecraft:deepslate_tiles"},
        {pos: [7, 0, 29], state: "minecraft:deepslate_bricks"},
        {pos: [7, 0, 30], state: "minecraft:deepslate_bricks"},
        {pos: [7, 0, 31], state: "minecraft:deepslate_bricks"},
        {pos: [8, 0, 0], state: "minecraft:deepslate_bricks"},
        {pos: [8, 0, 1], state: "minecraft:deepslate_bricks"},
        {pos: [8, 0, 2], state: "minecraft:deepslate_bricks"},
        {pos: [8, 0, 3], state: "minecraft:deepslate_tiles"},
        {pos: [8, 0, 4], state: "minecraft:deepslate_tiles"},
        {pos: [8, 0, 5], state: "minecraft:deepslate_tiles"},
        {pos: [8, 0, 6], state: "minecraft:deepslate_tiles"},
        {pos: [8, 0, 7], state: "minecraft:deepslate_tiles"},
        {pos: [8, 0, 8], state: "minecraft:deepslate_tiles"},
        {pos: [8, 0, 9], state: "minecraft:deepslate_tiles"},
        {pos: [8, 0, 10], state: "minecraft:deepslate_bricks"},
        {pos: [8, 0, 11], state: "minecraft:deepslate_bricks"},
        {pos: [8, 0, 12], state: "minecraft:jigsaw{orientation:up_west}", nbt: {final_state: "minecraft:deepslate", id: "minecraft:jigsaw", joint: "rollable", name: "minecraft:bottom", pool: "minecraft:ancient_city/sculk", target: "minecraft:bottom"}},
        {pos: [8, 0, 13], state: "minecraft:deepslate_bricks"},
        {pos: [8, 0, 14], state: "minecraft:deepslate_bricks"},
        {pos: [8, 0, 15], state: "minecraft:deepslate_bricks"},
        {pos: [8, 0, 16], state: "minecraft:deepslate{axis:y}"},
        {pos: [8, 0, 17], state: "minecraft:deepslate{axis:y}"},
        {pos: [8, 0, 18], state: "minecraft:deepslate{axis:y}"},
        {pos: [8, 0, 19], state: "minecraft:deepslate{axis:y}"},
        {pos: [8, 0, 20], state: "minecraft:deepslate{axis:y}"},
        {pos: [8, 0, 21], state: "minecraft:deepslate{axis:y}"},
        {pos: [8, 0, 22], state: "minecraft:deepslate_bricks"},
        {pos: [8, 0, 23], state: "minecraft:deepslate_bricks"},
        {pos: [8, 0, 24], state: "minecraft:deepslate_bricks"},
        {pos: [8, 0, 25], state: "minecraft:deepslate_tiles"},
        {pos: [8, 0, 26], state: "minecraft:deepslate_tiles"},
        {pos: [8, 0, 27], state: "minecraft:deepslate_tiles"},
        {pos: [8, 0, 28], state: "minecraft:deepslate_tiles"},
        {pos: [8, 0, 29], state: "minecraft:deepslate_bricks"},
        {pos: [8, 0, 30], state: "minecraft:deepslate_bricks"},
        {pos: [8, 0, 31], state: "minecraft:deepslate{axis:y}"},
        {pos: [8, 0, 32], state: "minecraft:deepslate{axis:y}"},
        {pos: [8, 0, 33], state: "minecraft:deepslate_bricks"},
        {pos: [8, 0, 34], state: "minecraft:deepslate_bricks"},
        {pos: [9, 0, 0], state: "minecraft:deepslate_bricks"},
        {pos: [9, 0, 1], state: "minecraft:deepslate_bricks"},
        {pos: [9, 0, 2], state: "minecraft:deepslate_bricks"},
        {pos: [9, 0, 3], state: "minecraft:deepslate_tiles"},
        {pos: [9, 0, 4], state: "minecraft:deepslate_tiles"},
        {pos: [9, 0, 5], state: "minecraft:deepslate_tiles"},
        {pos: [9, 0, 6], state: "minecraft:deepslate_tiles"},
        {pos: [9, 0, 7], state: "minecraft:deepslate_tiles"},
        {pos: [9, 0, 8], state: "minecraft:deepslate_tiles"},
        {pos: [9, 0, 9], state: "minecraft:deepslate_tiles"},
        {pos: [9, 0, 10], state: "minecraft:deepslate_bricks"},
        {pos: [9, 0, 11], state: "minecraft:deepslate_bricks"},
        {pos: [9, 0, 12], state: "minecraft:deepslate_bricks"},
        {pos: [9, 0, 13], state: "minecraft:deepslate_bricks"},
        {pos: [9, 0, 14], state: "minecraft:deepslate_bricks"},
        {pos: [9, 0, 15], state: "minecraft:deepslate_bricks"},
        {pos: [9, 0, 16], state: "minecraft:deepslate{axis:y}"},
        {pos: [9, 0, 17], state: "minecraft:deepslate{axis:y}"},
        {pos: [9, 0, 18], state: "minecraft:deepslate{axis:y}"},
        {pos: [9, 0, 19], state: "minecraft:deepslate{axis:y}"},
        {pos: [9, 0, 20], state: "minecraft:deepslate{axis:y}"},
        {pos: [9, 0, 21], state: "minecraft:deepslate{axis:y}"},
        {pos: [9, 0, 22], state: "minecraft:deepslate_bricks"},
        {pos: [9, 0, 23], state: "minecraft:cracked_deepslate_bricks"},
        {pos: [9, 0, 24], state: "minecraft:deepslate_bricks"},
        {pos: [9, 0, 25], state: "minecraft:deepslate_tiles"},
        {pos: [9, 0, 26], state: "minecraft:deepslate_tiles"},
        {pos: [9, 0, 27], state: "minecraft:deepslate_tiles"},
        {pos: [9, 0, 28], state: "minecraft:deepslate_tiles"},
        {pos: [9, 0, 29], state: "minecraft:deepslate_bricks"},
        {pos: [9, 0, 30], state: "minecraft:deepslate_bricks"},
        {pos: [9, 0, 31], state: "minecraft:deepslate_bricks"},
        {pos: [9, 0, 32], state: "minecraft:cracked_deepslate_bricks"},
        {pos: [9, 0, 33], state: "minecraft:deepslate_bricks"},
        {pos: [9, 0, 34], state: "minecraft:deepslate_bricks"},
        {pos: [9, 0, 35], state: "minecraft:deepslate_bricks"},
        {pos: [9, 0, 36], state: "minecraft:deepslate_bricks"},
        {pos: [10, 0, 0], state: "minecraft:deepslate_bricks"},
        {pos: [10, 0, 1], state: "minecraft:deepslate_bricks"},
        {pos: [10, 0, 2], state: "minecraft:deepslate_bricks"},
        {pos: [10, 0, 3], state: "minecraft:deepslate_tiles"},
        {pos: [10, 0, 4], state: "minecraft:deepslate_tiles"},
        {pos: [10, 0, 5], state: "minecraft:deepslate_tiles"},
        {pos: [10, 0, 6], state: "minecraft:deepslate_tiles"},
        {pos: [10, 0, 7], state: "minecraft:deepslate_tiles"},
        {pos: [10, 0, 8], state: "minecraft:deepslate_tiles"},
        {pos: [10, 0, 9], state: "minecraft:deepslate_tiles"},
        {pos: [10, 0, 10], state: "minecraft:deepslate_bricks"},
        {pos: [10, 0, 11], state: "minecraft:deepslate_bricks"},
        {pos: [10, 0, 12], state: "minecraft:deepslate_bricks"},
        {pos: [10, 0, 13], state: "minecraft:cracked_deepslate_bricks"},
        {pos: [10, 0, 14], state: "minecraft:deepslate_bricks"},
        {pos: [10, 0, 15], state: "minecraft:deepslate_bricks"},
        {pos: [10, 0, 16], state: "minecraft:deepslate{axis:y}"},
        {pos: [10, 0, 17], state: "minecraft:deepslate{axis:y}"},
        {pos: [10, 0, 18], state: "minecraft:deepslate{axis:y}"},
        {pos: [10, 0, 19], state: "minecraft:deepslate{axis:y}"},
        {pos: [10, 0, 20], state: "minecraft:deepslate{axis:y}"},
        {pos: [10, 0, 21], state: "minecraft:deepslate{axis:y}"},
        {pos: [10, 0, 22], state: "minecraft:cracked_deepslate_bricks"},
        {pos: [10, 0, 23], state: "minecraft:deepslate_bricks"},
        {pos: [10, 0, 24], state: "minecraft:deepslate_bricks"},
        {pos: [10, 0, 25], state: "minecraft:deepslate_bricks"},
        {pos: [10, 0, 26], state: "minecraft:deepslate_bricks"},
        {pos: [10, 0, 27], state: "minecraft:deepslate_bricks"},
        {pos: [10, 0, 28], state: "minecraft:deepslate_bricks"},
        {pos: [10, 0, 29], state: "minecraft:deepslate_bricks"},
        {pos: [10, 0, 30], state: "minecraft:deepslate_bricks"},
        {pos: [10, 0, 31], state: "minecraft:cracked_deepslate_bricks"},
        {pos: [10, 0, 32], state: "minecraft:deepslate_bricks"},
        {pos: [10, 0, 33], state: "minecraft:deepslate_bricks"},
        {pos: [10, 0, 34], state: "minecraft:deepslate_bricks"},
        {pos: [10, 0, 35], state: "minecraft:deepslate_bricks"},
        {pos: [10, 0, 36], state: "minecraft:deepslate_bricks"},
        {pos: [11, 0, 0], state: "minecraft:deepslate_bricks"},
        {pos: [11, 0, 1], state: "minecraft:deepslate_bricks"},
        {pos: [11, 0, 2], state: "minecraft:deepslate_bricks"},
        {pos: [11, 0, 3], state: "minecraft:deepslate_tiles"},
        {pos: [11, 0, 4], state: "minecraft:deepslate_tiles"},
        {pos: [11, 0, 5], state: "minecraft:deepslate_tiles"},
        {pos: [11, 0, 6], state: "minecraft:deepslate_tiles"},
        {pos: [11, 0, 7], state: "minecraft:deepslate_tiles"},
        {pos: [11, 0, 8], state: "minecraft:deepslate_tiles"},
        {pos: [11, 0, 9], state: "minecraft:deepslate_tiles"},
        {pos: [11, 0, 10], state: "minecraft:deepslate_bricks"},
        {pos: [11, 0, 11], state: "minecraft:deepslate_bricks"},
        {pos: [11, 0, 12], state: "minecraft:deepslate_bricks"},
        {pos: [11, 0, 13], state: "minecraft:cracked_deepslate_bricks"},
        {pos: [11, 0, 14], state: "minecraft:deepslate_bricks"},
        {pos: [11, 0, 15], state: "minecraft:deepslate_bricks"},
        {pos: [11, 0, 16], state: "minecraft:deepslate{axis:y}"},
        {pos: [11, 0, 17], state: "minecraft:deepslate{axis:y}"},
        {pos: [11, 0, 18], state: "minecraft:deepslate{axis:y}"},
        {pos: [11, 0, 19], state: "minecraft:deepslate{axis:y}"},
        {pos: [11, 0, 20], state: "minecraft:deepslate{axis:y}"},
        {pos: [11, 0, 21], state: "minecraft:deepslate{axis:y}"},
        {pos: [11, 0, 22], state: "minecraft:cracked_deepslate_bricks"},
        {pos: [11, 0, 23], state: "minecraft:deepslate_tiles"},
        {pos: [11, 0, 24], state: "minecraft:deepslate_tiles"},
        {pos: [11, 0, 25], state: "minecraft:deepslate_tiles"},
        {pos: [11, 0, 26], state: "minecraft:deepslate_tiles"},
        {pos: [11, 0, 27], state: "minecraft:deepslate_tiles"},
        {pos: [11, 0, 28], state: "minecraft:deepslate_tiles"},
        {pos: [11, 0, 29], state: "minecraft:deepslate_tiles"},
        {pos: [11, 0, 30], state: "minecraft:deepslate_bricks"},
        {pos: [11, 0, 31], state: "minecraft:deepslate_bricks"},
        {pos: [11, 0, 32], state: "minecraft:deepslate_bricks"},
        {pos: [11, 0, 33], state: "minecraft:deepslate_bricks"},
        {pos: [11, 0, 34], state: "minecraft:deepslate_bricks"},
        {pos: [11, 0, 35], state: "minecraft:deepslate_bricks"},
        {pos: [11, 0, 36], state: "minecraft:deepslate_bricks"},
        {pos: [12, 0, 0], state: "minecraft:deepslate_bricks"},
        {pos: [12, 0, 1], state: "minecraft:deepslate_bricks"},
        {pos: [12, 0, 2], state: "minecraft:deepslate_bricks"},
        {pos: [12, 0, 3], state: "minecraft:deepslate_tiles"},
        {pos: [12, 0, 4], state: "minecraft:deepslate_tiles"},
        {pos: [12, 0, 5], state: "minecraft:deepslate_tiles"},
        {pos: [12, 0, 6], state: "minecraft:deepslate_tiles"},
        {pos: [12, 0, 7], state: "minecraft:deepslate_tiles"},
        {pos: [12, 0, 8], state: "minecraft:deepslate_tiles"},
        {pos: [12, 0, 9], state: "minecraft:deepslate_tiles"},
        {pos: [12, 0, 10], state: "minecraft:deepslate_bricks"},
        {pos: [12, 0, 11], state: "minecraft:deepslate_bricks"},
        {pos: [12, 0, 12], state: "minecraft:deepslate_bricks"},
        {pos: [12, 0, 13], state: "minecraft:deepslate_bricks"},
        {pos: [12, 0, 14], state: "minecraft:deepslate_bricks"},
        {pos: [12, 0, 15], state: "minecraft:deepslate_bricks"},
        {pos: [12, 0, 16], state: "minecraft:deepslate{axis:y}"},
        {pos: [12, 0, 17], state: "minecraft:deepslate{axis:y}"},
        {pos: [12, 0, 18], state: "minecraft:deepslate{axis:y}"},
        {pos: [12, 0, 19], state: "minecraft:deepslate{axis:y}"},
        {pos: [12, 0, 20], state: "minecraft:deepslate{axis:y}"},
        {pos: [12, 0, 21], state: "minecraft:deepslate{axis:y}"},
        {pos: [12, 0, 22], state: "minecraft:deepslate_bricks"},
        {pos: [12, 0, 23], state: "minecraft:deepslate_tiles"},
        {pos: [12, 0, 24], state: "minecraft:deepslate_tile_stairs{facing:west,half:bottom,shape:straight,waterlogged:true}"},
        {pos: [12, 0, 25], state: "minecraft:deepslate_tile_stairs{facing:west,half:bottom,shape:straight,waterlogged:true}"},
        {pos: [12, 0, 26], state: "minecraft:deepslate_tile_stairs{facing:west,half:bottom,shape:straight,waterlogged:true}"},
        {pos: [12, 0, 27], state: "minecraft:deepslate_tile_stairs{facing:west,half:bottom,shape:straight,waterlogged:true}"},
        {pos: [12, 0, 28], state: "minecraft:deepslate_tile_stairs{facing:west,half:bottom,shape:straight,waterlogged:true}"},
        {pos: [12, 0, 29], state: "minecraft:deepslate_tiles"},
        {pos: [12, 0, 30], state: "minecraft:deepslate_bricks"},
        {pos: [12, 0, 31], state: "minecraft:deepslate_bricks"},
        {pos: [12, 0, 32], state: "minecraft:deepslate_bricks"},
        {pos: [12, 0, 33], state: "minecraft:deepslate_bricks"},
        {pos: [12, 0, 34], state: "minecraft:deepslate_bricks"},
        {pos: [12, 0, 35], state: "minecraft:deepslate_bricks"},
        {pos: [12, 0, 36], state: "minecraft:deepslate_bricks"},
        {pos: [13, 0, 0], state: "minecraft:deepslate_bricks"},
        {pos: [13, 0, 1], state: "minecraft:deepslate_bricks"},
        {pos: [13, 0, 2], state: "minecraft:deepslate_bricks"},
        {pos: [13, 0, 3], state: "minecraft:deepslate_tiles"},
        {pos: [13, 0, 4], state: "minecraft:deepslate_tiles"},
        {pos: [13, 0, 5], state: "minecraft:deepslate_tiles"},
        {pos: [13, 0, 6], state: "minecraft:deepslate_tiles"},
        {pos: [13, 0, 7], state: "minecraft:deepslate_tiles"},
        {pos: [13, 0, 8], state: "minecraft:deepslate_tiles"},
        {pos: [13, 0, 9], state: "minecraft:deepslate_tiles"},
        {pos: [13, 0, 10], state: "minecraft:deepslate_bricks"},
        {pos: [13, 0, 11], state: "minecraft:deepslate_bricks"},
        {pos: [13, 0, 12], state: "minecraft:deepslate_bricks"},
        {pos: [13, 0, 13], state: "minecraft:cracked_deepslate_bricks"},
        {pos: [13, 0, 14], state: "minecraft:deepslate_bricks"},
        {pos: [13, 0, 15], state: "minecraft:deepslate_bricks"},
        {pos: [13, 0, 16], state: "minecraft:deepslate{axis:y}"},
        {pos: [13, 0, 17], state: "minecraft:deepslate{axis:y}"},
        {pos: [13, 0, 18], state: "minecraft:deepslate{axis:y}"},
        {pos: [13, 0, 19], state: "minecraft:deepslate{axis:y}"},
        {pos: [13, 0, 20], state: "minecraft:deepslate{axis:y}"},
        {pos: [13, 0, 21], state: "minecraft:deepslate{axis:y}"},
        {pos: [13, 0, 22], state: "minecraft:deepslate_bricks"},
        {pos: [13, 0, 23], state: "minecraft:deepslate_tiles"},
        {pos: [13, 0, 24], state: "minecraft:water{level:0}"},
        {pos: [13, 0, 25], state: "minecraft:water{level:0}"},
        {pos: [13, 0, 26], state: "minecraft:water{level:0}"},
        {pos: [13, 0, 27], state: "minecraft:water{level:0}"},
        {pos: [13, 0, 28], state: "minecraft:water{level:0}"},
        {pos: [13, 0, 29], state: "minecraft:deepslate_tiles"},
        {pos: [13, 0, 30], state: "minecraft:deepslate_bricks"},
        {pos: [13, 0, 31], state: "minecraft:deepslate_bricks"},
        {pos: [13, 0, 32], state: "minecraft:deepslate_bricks"},
        {pos: [13, 0, 33], state: "minecraft:deepslate_bricks"},
        {pos: [13, 0, 34], state: "minecraft:deepslate_bricks"},
        {pos: [13, 0, 35], state: "minecraft:deepslate_bricks"},
        {pos: [13, 0, 36], state: "minecraft:deepslate_bricks"},
        {pos: [14, 0, 0], state: "minecraft:deepslate_bricks"},
        {pos: [14, 0, 1], state: "minecraft:deepslate_bricks"},
        {pos: [14, 0, 2], state: "minecraft:deepslate_bricks"},
        {pos: [14, 0, 3], state: "minecraft:deepslate_tiles"},
        {pos: [14, 0, 4], state: "minecraft:deepslate_tiles"},
        {pos: [14, 0, 5], state: "minecraft:deepslate_tiles"},
        {pos: [14, 0, 6], state: "minecraft:deepslate_tiles"},
        {pos: [14, 0, 7], state: "minecraft:deepslate_tiles"},
        {pos: [14, 0, 8], state: "minecraft:deepslate_tiles"},
        {pos: [14, 0, 9], state: "minecraft:deepslate_tiles"},
        {pos: [14, 0, 10], state: "minecraft:deepslate_bricks"},
        {pos: [14, 0, 11], state: "minecraft:deepslate_bricks"},
        {pos: [14, 0, 12], state: "minecraft:cracked_deepslate_bricks"},
        {pos: [14, 0, 13], state: "minecraft:cracked_deepslate_bricks"},
        {pos: [14, 0, 14], state: "minecraft:cracked_deepslate_bricks"},
        {pos: [14, 0, 15], state: "minecraft:cracked_deepslate_bricks"},
        {pos: [14, 0, 16], state: "minecraft:deepslate_bricks"},
        {pos: [14, 0, 17], state: "minecraft:cracked_deepslate_bricks"},
        {pos: [14, 0, 18], state: "minecraft:cracked_deepslate_bricks"},
        {pos: [14, 0, 19], state: "minecraft:deepslate_bricks"},
        {pos: [14, 0, 20], state: "minecraft:cracked_deepslate_bricks"},
        {pos: [14, 0, 21], state: "minecraft:cracked_deepslate_bricks"},
        {pos: [14, 0, 22], state: "minecraft:cracked_deepslate_bricks"},
        {pos: [14, 0, 23], state: "minecraft:deepslate_tiles"},
        {pos: [14, 0, 24], state: "minecraft:water{level:0}"},
        {pos: [14, 0, 25], state: "minecraft:water{level:0}"},
        {pos: [14, 0, 26], state: "minecraft:water{level:0}"},
        {pos: [14, 0, 27], state: "minecraft:water{level:0}"},
        {pos: [14, 0, 28], state: "minecraft:water{level:0}"},
        {pos: [14, 0, 29], state: "minecraft:deepslate_tiles"},
        {pos: [14, 0, 30], state: "minecraft:deepslate_bricks"},
        {pos: [14, 0, 31], state: "minecraft:deepslate_bricks"},
        {pos: [14, 0, 32], state: "minecraft:deepslate_bricks"},
        {pos: [14, 0, 33], state: "minecraft:deepslate_bricks"},
        {pos: [14, 0, 34], state: "minecraft:deepslate_bricks"},
        {pos: [14, 0, 35], state: "minecraft:deepslate_bricks"},
        {pos: [14, 0, 36], state: "minecraft:deepslate_bricks"},
        {pos: [15, 0, 0], state: "minecraft:deepslate_bricks"},
        {pos: [15, 0, 1], state: "minecraft:deepslate_bricks"},
        {pos: [15, 0, 2], state: "minecraft:deepslate_bricks"},
        {pos: [15, 0, 3], state: "minecraft:deepslate_tiles"},
        {pos: [15, 0, 4], state: "minecraft:deepslate_tiles"},
        {pos: [15, 0, 5], state: "minecraft:deepslate_tiles"},
        {pos: [15, 0, 6], state: "minecraft:deepslate_tiles"},
        {pos: [15, 0, 7], state: "minecraft:deepslate_tiles"},
        {pos: [15, 0, 8], state: "minecraft:deepslate_tiles"},
        {pos: [15, 0, 9], state: "minecraft:deepslate_tiles"},
        {pos: [15, 0, 10], state: "minecraft:deepslate_bricks"},
        {pos: [15, 0, 11], state: "minecraft:deepslate_bricks"},
        {pos: [15, 0, 12], state: "minecraft:deepslate_bricks"},
        {pos: [15, 0, 13], state: "minecraft:cracked_deepslate_bricks"},
        {pos: [15, 0, 14], state: "minecraft:cracked_deepslate_bricks"},
        {pos: [15, 0, 15], state: "minecraft:deepslate_bricks"},
        {pos: [15, 0, 16], state: "minecraft:deepslate{axis:y}"},
        {pos: [15, 0, 17], state: "minecraft:deepslate{axis:y}"},
        {pos: [15, 0, 18], state: "minecraft:deepslate{axis:y}"},
        {pos: [15, 0, 19], state: "minecraft:deepslate{axis:y}"},
        {pos: [15, 0, 20], state: "minecraft:deepslate{axis:y}"},
        {pos: [15, 0, 21], state: "minecraft:cracked_deepslate_bricks"},
        {pos: [15, 0, 22], state: "minecraft:cracked_deepslate_bricks"},
        {pos: [15, 0, 23], state: "minecraft:deepslate_tiles"},
        {pos: [15, 0, 24], state: "minecraft:water{level:0}"},
        {pos: [15, 0, 25], state: "minecraft:water{level:0}"},
        {pos: [15, 0, 26], state: "minecraft:water{level:0}"},
        {pos: [15, 0, 27], state: "minecraft:water{level:0}"},
        {pos: [15, 0, 28], state: "minecraft:water{level:0}"},
        {pos: [15, 0, 29], state: "minecraft:deepslate_tiles"},
        {pos: [15, 0, 30], state: "minecraft:deepslate_bricks"},
        {pos: [15, 0, 31], state: "minecraft:deepslate_bricks"},
        {pos: [15, 0, 32], state: "minecraft:deepslate_bricks"},
        {pos: [15, 0, 33], state: "minecraft:deepslate_bricks"},
        {pos: [15, 0, 34], state: "minecraft:deepslate_bricks"},
        {pos: [15, 0, 35], state: "minecraft:deepslate_bricks"},
        {pos: [15, 0, 36], state: "minecraft:deepslate_bricks"},
        {pos: [16, 0, 0], state: "minecraft:deepslate_bricks"},
        {pos: [16, 0, 1], state: "minecraft:deepslate_bricks"},
        {pos: [16, 0, 2], state: "minecraft:deepslate_bricks"},
        {pos: [16, 0, 3], state: "minecraft:deepslate_tiles"},
        {pos: [16, 0, 4], state: "minecraft:deepslate_tiles"},
        {pos: [16, 0, 5], state: "minecraft:deepslate_tiles"},
        {pos: [16, 0, 6], state: "minecraft:deepslate_tiles"},
        {pos: [16, 0, 7], state: "minecraft:deepslate_tiles"},
        {pos: [16, 0, 8], state: "minecraft:deepslate_tiles"},
        {pos: [16, 0, 9], state: "minecraft:deepslate_tiles"},
        {pos: [16, 0, 10], state: "minecraft:deepslate_bricks"},
        {pos: [16, 0, 11], state: "minecraft:deepslate_bricks"},
        {pos: [16, 0, 12], state: "minecraft:deepslate_bricks"},
        {pos: [16, 0, 13], state: "minecraft:deepslate_bricks"},
        {pos: [16, 0, 14], state: "minecraft:deepslate_bricks"},
        {pos: [16, 0, 15], state: "minecraft:deepslate_bricks"},
        {pos: [16, 0, 16], state: "minecraft:deepslate{axis:y}"},
        {pos: [16, 0, 17], state: "minecraft:deepslate{axis:y}"},
        {pos: [16, 0, 18], state: "minecraft:deepslate{axis:y}"},
        {pos: [16, 0, 19], state: "minecraft:deepslate_bricks"},
        {pos: [16, 0, 20], state: "minecraft:deepslate_bricks"},
        {pos: [16, 0, 21], state: "minecraft:deepslate_bricks"},
        {pos: [16, 0, 22], state: "minecraft:cracked_deepslate_bricks"},
        {pos: [16, 0, 23], state: "minecraft:deepslate_tiles"},
        {pos: [16, 0, 24], state: "minecraft:water{level:0}"},
        {pos: [16, 0, 25], state: "minecraft:water{level:0}"},
        {pos: [16, 0, 26], state: "minecraft:water{level:0}"},
        {pos: [16, 0, 27], state: "minecraft:water{level:0}"},
        {pos: [16, 0, 28], state: "minecraft:water{level:0}"},
        {pos: [16, 0, 29], state: "minecraft:deepslate_tiles"},
        {pos: [16, 0, 30], state: "minecraft:deepslate_bricks"},
        {pos: [16, 0, 31], state: "minecraft:deepslate_bricks"},
        {pos: [16, 0, 32], state: "minecraft:deepslate_bricks"},
        {pos: [16, 0, 33], state: "minecraft:deepslate_bricks"},
        {pos: [16, 0, 34], state: "minecraft:deepslate_bricks"},
        {pos: [16, 0, 35], state: "minecraft:deepslate_bricks"},
        {pos: [16, 0, 36], state: "minecraft:deepslate_bricks"},
        {pos: [17, 0, 0], state: "minecraft:deepslate_bricks"},
        {pos: [17, 0, 1], state: "minecraft:deepslate_bricks"},
        {pos: [17, 0, 2], state: "minecraft:deepslate_bricks"},
        {pos: [17, 0, 3], state: "minecraft:deepslate_tiles"},
        {pos: [17, 0, 4], state: "minecraft:deepslate_tiles"},
        {pos: [17, 0, 5], state: "minecraft:deepslate_tiles"},
        {pos: [17, 0, 6], state: "minecraft:deepslate_tiles"},
        {pos: [17, 0, 7], state: "minecraft:deepslate_tiles"},
        {pos: [17, 0, 8], state: "minecraft:deepslate_tiles"},
        {pos: [17, 0, 9], state: "minecraft:deepslate_tiles"},
        {pos: [17, 0, 10], state: "minecraft:deepslate_bricks"},
        {pos: [17, 0, 11], state: "minecraft:deepslate_bricks"},
        {pos: [17, 0, 12], state: "minecraft:deepslate_bricks"},
        {pos: [17, 0, 13], state: "minecraft:deepslate_bricks"},
        {pos: [17, 0, 14], state: "minecraft:cracked_deepslate_bricks"},
        {pos: [17, 0, 15], state: "minecraft:deepslate_bricks"},
        {pos: [17, 0, 16], state: "minecraft:deepslate_tiles"},
        {pos: [17, 0, 17], state: "minecraft:deepslate{axis:y}"},
        {pos: [17, 0, 18], state: "minecraft:deepslate{axis:y}"},
        {pos: [17, 0, 19], state: "minecraft:deepslate_tiles"},
        {pos: [17, 0, 20], state: "minecraft:deepslate_tiles"},
        {pos: [17, 0, 21], state: "minecraft:deepslate_bricks"},
        {pos: [17, 0, 22], state: "minecraft:cracked_deepslate_bricks"},
        {pos: [17, 0, 23], state: "minecraft:deepslate_tiles"},
        {pos: [17, 0, 24], state: "minecraft:water{level:0}"},
        {pos: [17, 0, 25], state: "minecraft:water{level:0}"},
        {pos: [17, 0, 26], state: "minecraft:water{level:0}"},
        {pos: [17, 0, 27], state: "minecraft:water{level:0}"},
        {pos: [17, 0, 28], state: "minecraft:water{level:0}"},
        {pos: [17, 0, 29], state: "minecraft:deepslate_tiles"},
        {pos: [17, 0, 30], state: "minecraft:deepslate_bricks"},
        {pos: [17, 0, 31], state: "minecraft:deepslate_bricks"},
        {pos: [17, 0, 32], state: "minecraft:deepslate_bricks"},
        {pos: [17, 0, 33], state: "minecraft:deepslate_bricks"},
        {pos: [17, 0, 34], state: "minecraft:deepslate_bricks"},
        {pos: [17, 0, 35], state: "minecraft:deepslate_bricks"},
        {pos: [17, 0, 36], state: "minecraft:deepslate_bricks"},
        {pos: [18, 0, 0], state: "minecraft:deepslate_bricks"},
        {pos: [18, 0, 1], state: "minecraft:deepslate_bricks"},
        {pos: [18, 0, 2], state: "minecraft:deepslate_bricks"},
        {pos: [18, 0, 3], state: "minecraft:deepslate_tiles"},
        {pos: [18, 0, 4], state: "minecraft:deepslate_tiles"},
        {pos: [18, 0, 5], state: "minecraft:deepslate_tiles"},
        {pos: [18, 0, 6], state: "minecraft:deepslate_tiles"},
        {pos: [18, 0, 7], state: "minecraft:deepslate_tiles"},
        {pos: [18, 0, 8], state: "minecraft:deepslate_tiles"},
        {pos: [18, 0, 9], state: "minecraft:deepslate_tiles"},
        {pos: [18, 0, 10], state: "minecraft:deepslate_bricks"},
        {pos: [18, 0, 11], state: "minecraft:deepslate_bricks"},
        {pos: [18, 0, 12], state: "minecraft:deepslate_bricks"},
        {pos: [18, 0, 13], state: "minecraft:deepslate_bricks"},
        {pos: [18, 0, 14], state: "minecraft:cracked_deepslate_bricks"},
        {pos: [18, 0, 15], state: "minecraft:deepslate_bricks"},
        {pos: [18, 0, 16], state: "minecraft:deepslate_tiles"},
        {pos: [18, 0, 17], state: "minecraft:deepslate{axis:y}"},
        {pos: [18, 0, 18], state: "minecraft:deepslate{axis:y}"},
        {pos: [18, 0, 19], state: "minecraft:deepslate_tiles"},
        {pos: [18, 0, 20], state: "minecraft:deepslate_tiles"},
        {pos: [18, 0, 21], state: "minecraft:deepslate_bricks"},
        {pos: [18, 0, 22], state: "minecraft:deepslate_bricks"},
        {pos: [18, 0, 23], state: "minecraft:deepslate_tiles"},
        {pos: [18, 0, 24], state: "minecraft:water{level:0}"},
        {pos: [18, 0, 25], state: "minecraft:water{level:0}"},
        {pos: [18, 0, 26], state: "minecraft:water{level:0}"},
        {pos: [18, 0, 27], state: "minecraft:water{level:0}"},
        {pos: [18, 0, 28], state: "minecraft:water{level:0}"},
        {pos: [18, 0, 29], state: "minecraft:deepslate_tiles"},
        {pos: [18, 0, 30], state: "minecraft:deepslate_bricks"},
        {pos: [18, 0, 31], state: "minecraft:deepslate_bricks"},
        {pos: [18, 0, 32], state: "minecraft:deepslate_bricks"},
        {pos: [18, 0, 33], state: "minecraft:jigsaw{orientation:up_west}", nbt: {final_state: "minecraft:deepslate", id: "minecraft:jigsaw", joint: "rollable", name: "minecraft:bottom", pool: "minecraft:ancient_city/sculk", target: "minecraft:bottom"}},
        {pos: [18, 0, 34], state: "minecraft:deepslate_bricks"},
        {pos: [18, 0, 35], state: "minecraft:deepslate_bricks"},
        {pos: [18, 0, 36], state: "minecraft:deepslate_bricks"},
        {pos: [19, 0, 0], state: "minecraft:deepslate_bricks"},
        {pos: [19, 0, 1], state: "minecraft:deepslate_bricks"},
        {pos: [19, 0, 2], state: "minecraft:deepslate_bricks"},
        {pos: [19, 0, 3], state: "minecraft:deepslate_tiles"},
        {pos: [19, 0, 4], state: "minecraft:deepslate_tiles"},
        {pos: [19, 0, 5], state: "minecraft:deepslate_tiles"},
        {pos: [19, 0, 6], state: "minecraft:deepslate_tiles"},
        {pos: [19, 0, 7], state: "minecraft:deepslate_tiles"},
        {pos: [19, 0, 8], state: "minecraft:deepslate_tiles"},
        {pos: [19, 0, 9], state: "minecraft:deepslate_tiles"},
        {pos: [19, 0, 10], state: "minecraft:deepslate_bricks"},
        {pos: [19, 0, 11], state: "minecraft:deepslate_bricks"},
        {pos: [19, 0, 12], state: "minecraft:cracked_deepslate_bricks"},
        {pos: [19, 0, 13], state: "minecraft:deepslate_bricks"},
        {pos: [19, 0, 14], state: "minecraft:deepslate_bricks"},
        {pos: [19, 0, 15], state: "minecraft:deepslate_bricks"},
        {pos: [19, 0, 16], state: "minecraft:deepslate_tiles"},
        {pos: [19, 0, 17], state: "minecraft:deepslate_tiles"},
        {pos: [19, 0, 18], state: "minecraft:deepslate{axis:y}"},
        {pos: [19, 0, 19], state: "minecraft:deepslate_tiles"},
        {pos: [19, 0, 20], state: "minecraft:deepslate_tiles"},
        {pos: [19, 0, 21], state: "minecraft:deepslate_bricks"},
        {pos: [19, 0, 22], state: "minecraft:deepslate_bricks"},
        {pos: [19, 0, 23], state: "minecraft:deepslate_tiles"},
        {pos: [19, 0, 24], state: "minecraft:water{level:0}"},
        {pos: [19, 0, 25], state: "minecraft:water{level:0}"},
        {pos: [19, 0, 26], state: "minecraft:water{level:0}"},
        {pos: [19, 0, 27], state: "minecraft:water{level:0}"},
        {pos: [19, 0, 28], state: "minecraft:water{level:0}"},
        {pos: [19, 0, 29], state: "minecraft:deepslate_tiles"},
        {pos: [19, 0, 30], state: "minecraft:deepslate_bricks"},
        {pos: [19, 0, 31], state: "minecraft:deepslate_bricks"},
        {pos: [19, 0, 32], state: "minecraft:deepslate_bricks"},
        {pos: [19, 0, 33], state: "minecraft:deepslate_bricks"},
        {pos: [19, 0, 34], state: "minecraft:deepslate_bricks"},
        {pos: [19, 0, 35], state: "minecraft:deepslate_bricks"},
        {pos: [19, 0, 36], state: "minecraft:deepslate_bricks"},
        {pos: [20, 0, 0], state: "minecraft:deepslate_bricks"},
        {pos: [20, 0, 1], state: "minecraft:cracked_deepslate_bricks"},
        {pos: [20, 0, 2], state: "minecraft:deepslate_bricks"},
        {pos: [20, 0, 3], state: "minecraft:deepslate_tiles"},
        {pos: [20, 0, 4], state: "minecraft:deepslate_tiles"},
        {pos: [20, 0, 5], state: "minecraft:deepslate_tiles"},
        {pos: [20, 0, 6], state: "minecraft:deepslate_tiles"},
        {pos: [20, 0, 7], state: "minecraft:deepslate_tiles"},
        {pos: [20, 0, 8], state: "minecraft:deepslate_tiles"},
        {pos: [20, 0, 9], state: "minecraft:deepslate_tiles"},
        {pos: [20, 0, 10], state: "minecraft:deepslate_bricks"},
        {pos: [20, 0, 11], state: "minecraft:cracked_deepslate_bricks"},
        {pos: [20, 0, 12], state: "minecraft:deepslate_bricks"},
        {pos: [20, 0, 13], state: "minecraft:deepslate_bricks"},
        {pos: [20, 0, 14], state: "minecraft:deepslate_bricks"},
        {pos: [20, 0, 15], state: "minecraft:deepslate_bricks"},
        {pos: [20, 0, 16], state: "minecraft:deepslate_tiles"},
        {pos: [20, 0, 17], state: "minecraft:deepslate_tiles"},
        {pos: [20, 0, 18], state: "minecraft:deepslate_tiles"},
        {pos: [20, 0, 19], state: "minecraft:deepslate_tiles"},
        {pos: [20, 0, 20], state: "minecraft:deepslate_tiles"},
        {pos: [20, 0, 21], state: "minecraft:deepslate_bricks"},
        {pos: [20, 0, 22], state: "minecraft:cracked_deepslate_bricks"},
        {pos: [20, 0, 23], state: "minecraft:deepslate_tiles"},
        {pos: [20, 0, 24], state: "minecraft:water{level:0}"},
        {pos: [20, 0, 25], state: "minecraft:water{level:0}"},
        {pos: [20, 0, 26], state: "minecraft:water{level:0}"},
        {pos: [20, 0, 27], state: "minecraft:water{level:0}"},
        {pos: [20, 0, 28], state: "minecraft:water{level:0}"},
        {pos: [20, 0, 29], state: "minecraft:deepslate_tiles"},
        {pos: [20, 0, 30], state: "minecraft:deepslate_bricks"},
        {pos: [20, 0, 31], state: "minecraft:deepslate_bricks"},
        {pos: [20, 0, 32], state: "minecraft:deepslate_bricks"},
        {pos: [20, 0, 33], state: "minecraft:deepslate_bricks"},
        {pos: [20, 0, 34], state: "minecraft:deepslate_bricks"},
        {pos: [20, 0, 35], state: "minecraft:cracked_deepslate_bricks"},
        {pos: [20, 0, 36], state: "minecraft:deepslate_bricks"},
        {pos: [21, 0, 0], state: "minecraft:deepslate_bricks"},
        {pos: [21, 0, 1], state: "minecraft:deepslate_bricks"},
        {pos: [21, 0, 2], state: "minecraft:deepslate_bricks"},
        {pos: [21, 0, 3], state: "minecraft:deepslate_tiles"},
        {pos: [21, 0, 4], state: "minecraft:deepslate_tiles"},
        {pos: [21, 0, 5], state: "minecraft:deepslate_tiles"},
        {pos: [21, 0, 6], state: "minecraft:deepslate_tiles"},
        {pos: [21, 0, 7], state: "minecraft:deepslate_tiles"},
        {pos: [21, 0, 8], state: "minecraft:deepslate_tiles"},
        {pos: [21, 0, 9], state: "minecraft:jigsaw{orientation:up_west}", nbt: {final_state: "minecraft:deepslate", id: "minecraft:jigsaw", joint: "rollable", name: "minecraft:bottom", pool: "minecraft:ancient_city/sculk", target: "minecraft:bottom"}},
        {pos: [21, 0, 10], state: "minecraft:deepslate_bricks"},
        {pos: [21, 0, 11], state: "minecraft:deepslate_bricks"},
        {pos: [21, 0, 12], state: "minecraft:cracked_deepslate_bricks"},
        {pos: [21, 0, 13], state: "minecraft:deepslate_bricks"},
        {pos: [21, 0, 14], state: "minecraft:deepslate_bricks"},
        {pos: [21, 0, 15], state: "minecraft:deepslate_bricks"},
        {pos: [21, 0, 16], state: "minecraft:deepslate_tiles"},
        {pos: [21, 0, 17], state: "minecraft:deepslate_tiles"},
        {pos: [21, 0, 18], state: "minecraft:deepslate_tiles"},
        {pos: [21, 0, 19], state: "minecraft:deepslate_tiles"},
        {pos: [21, 0, 20], state: "minecraft:deepslate_tiles"},
        {pos: [21, 0, 21], state: "minecraft:deepslate_bricks"},
        {pos: [21, 0, 22], state: "minecraft:cracked_deepslate_bricks"},
        {pos: [21, 0, 23], state: "minecraft:deepslate_tiles"},
        {pos: [21, 0, 24], state: "minecraft:deepslate_tiles"},
        {pos: [21, 0, 25], state: "minecraft:deepslate_tiles"},
        {pos: [21, 0, 26], state: "minecraft:deepslate_tiles"},
        {pos: [21, 0, 27], state: "minecraft:deepslate_tiles"},
        {pos: [21, 0, 28], state: "minecraft:deepslate_tiles"},
        {pos: [21, 0, 29], state: "minecraft:deepslate_tiles"},
        {pos: [21, 0, 30], state: "minecraft:deepslate_bricks"},
        {pos: [21, 0, 31], state: "minecraft:deepslate_bricks"},
        {pos: [21, 0, 32], state: "minecraft:deepslate_bricks"},
        {pos: [21, 0, 33], state: "minecraft:deepslate_bricks"},
        {pos: [21, 0, 34], state: "minecraft:deepslate_bricks"},
        {pos: [21, 0, 35], state: "minecraft:cracked_deepslate_bricks"},
        {pos: [21, 0, 36], state: "minecraft:cracked_deepslate_bricks"},
        {pos: [22, 0, 0], state: "minecraft:deepslate_bricks"},
        {pos: [22, 0, 1], state: "minecraft:cracked_deepslate_bricks"},
        {pos: [22, 0, 2], state: "minecraft:cracked_deepslate_bricks"},
        {pos: [22, 0, 3], state: "minecraft:cracked_deepslate_bricks"},
        {pos: [22, 0, 4], state: "minecraft:deepslate_bricks"},
        {pos: [22, 0, 5], state: "minecraft:deepslate_bricks"},
        {pos: [22, 0, 6], state: "minecraft:deepslate_bricks"},
        {pos: [22, 0, 7], state: "minecraft:deepslate_bricks"},
        {pos: [22, 0, 8], state: "minecraft:deepslate_bricks"},
        {pos: [22, 0, 9], state: "minecraft:deepslate_bricks"},
        {pos: [22, 0, 10], state: "minecraft:deepslate_bricks"},
        {pos: [22, 0, 11], state: "minecraft:deepslate_bricks"},
        {pos: [22, 0, 12], state: "minecraft:deepslate_bricks"},
        {pos: [22, 0, 13], state: "minecraft:cracked_deepslate_bricks"},
        {pos: [22, 0, 14], state: "minecraft:deepslate_bricks"},
        {pos: [22, 0, 15], state: "minecraft:deepslate_bricks"},
        {pos: [22, 0, 16], state: "minecraft:deepslate_bricks"},
        {pos: [22, 0, 17], state: "minecraft:deepslate_bricks"},
        {pos: [22, 0, 18], state: "minecraft:deepslate_bricks"},
        {pos: [22, 0, 19], state: "minecraft:deepslate_bricks"},
        {pos: [22, 0, 20], state: "minecraft:deepslate_bricks"},
        {pos: [22, 0, 21], state: "minecraft:deepslate_bricks"},
        {pos: [22, 0, 22], state: "minecraft:deepslate_bricks"},
        {pos: [22, 0, 23], state: "minecraft:deepslate_bricks"},
        {pos: [22, 0, 24], state: "minecraft:deepslate_bricks"},
        {pos: [22, 0, 25], state: "minecraft:deepslate_bricks"},
        {pos: [22, 0, 26], state: "minecraft:deepslate_bricks"},
        {pos: [22, 0, 27], state: "minecraft:deepslate_bricks"},
        {pos: [22, 0, 28], state: "minecraft:deepslate_bricks"},
        {pos: [22, 0, 29], state: "minecraft:deepslate_bricks"},
        {pos: [22, 0, 30], state: "minecraft:deepslate_bricks"},
        {pos: [22, 0, 31], state: "minecraft:deepslate_bricks"},
        {pos: [22, 0, 32], state: "minecraft:deepslate_bricks"},
        {pos: [22, 0, 33], state: "minecraft:deepslate_bricks"},
        {pos: [22, 0, 34], state: "minecraft:deepslate_bricks"},
        {pos: [22, 0, 35], state: "minecraft:cracked_deepslate_bricks"},
        {pos: [23, 0, 0], state: "minecraft:cracked_deepslate_bricks"},
        {pos: [23, 0, 2], state: "minecraft:cracked_deepslate_bricks"},
        {pos: [23, 0, 3], state: "minecraft:cracked_deepslate_bricks"},
        {pos: [23, 0, 4], state: "minecraft:cracked_deepslate_bricks"},
        {pos: [23, 0, 5], state: "minecraft:cracked_deepslate_bricks"},
        {pos: [23, 0, 6], state: "minecraft:deepslate_bricks"},
        {pos: [23, 0, 7], state: "minecraft:deepslate_bricks"},
        {pos: [23, 0, 8], state: "minecraft:deepslate_bricks"},
        {pos: [23, 0, 9], state: "minecraft:deepslate_bricks"},
        {pos: [23, 0, 10], state: "minecraft:deepslate_bricks"},
        {pos: [23, 0, 11], state: "minecraft:deepslate_bricks"},
        {pos: [23, 0, 12], state: "minecraft:deepslate_bricks"},
        {pos: [23, 0, 13], state: "minecraft:cracked_deepslate_bricks"},
        {pos: [23, 0, 14], state: "minecraft:deepslate_bricks"},
        {pos: [23, 0, 15], state: "minecraft:deepslate_bricks"},
        {pos: [23, 0, 16], state: "minecraft:deepslate_bricks"},
        {pos: [23, 0, 17], state: "minecraft:deepslate_bricks"},
        {pos: [23, 0, 18], state: "minecraft:deepslate_bricks"},
        {pos: [23, 0, 19], state: "minecraft:deepslate_bricks"},
        {pos: [23, 0, 20], state: "minecraft:deepslate_bricks"},
        {pos: [23, 0, 21], state: "minecraft:cracked_deepslate_bricks"},
        {pos: [23, 0, 22], state: "minecraft:cracked_deepslate_bricks"},
        {pos: [23, 0, 23], state: "minecraft:deepslate_bricks"},
        {pos: [23, 0, 24], state: "minecraft:deepslate_bricks"},
        {pos: [23, 0, 25], state: "minecraft:deepslate_bricks"},
        {pos: [23, 0, 26], state: "minecraft:deepslate_bricks"},
        {pos: [23, 0, 27], state: "minecraft:deepslate_bricks"},
        {pos: [23, 0, 28], state: "minecraft:deepslate_bricks"},
        {pos: [23, 0, 29], state: "minecraft:deepslate_bricks"},
        {pos: [23, 0, 30], state: "minecraft:deepslate_bricks"},
        {pos: [23, 0, 31], state: "minecraft:deepslate_bricks"},
        {pos: [23, 0, 32], state: "minecraft:deepslate_bricks"},
        {pos: [23, 0, 33], state: "minecraft:deepslate_bricks"},
        {pos: [23, 0, 34], state: "minecraft:deepslate_bricks"},
        {pos: [23, 0, 35], state: "minecraft:cracked_deepslate_bricks"},
        {pos: [23, 0, 36], state: "minecraft:cracked_deepslate_bricks"},
        {pos: [24, 0, 2], state: "minecraft:cracked_deepslate_bricks"},
        {pos: [24, 0, 3], state: "minecraft:cracked_deepslate_bricks"},
        {pos: [24, 0, 4], state: "minecraft:cracked_deepslate_bricks"},
        {pos: [24, 0, 5], state: "minecraft:cracked_deepslate_bricks"},
        {pos: [24, 0, 6], state: "minecraft:deepslate_bricks"},
        {pos: [24, 0, 7], state: "minecraft:deepslate_bricks"},
        {pos: [24, 0, 8], state: "minecraft:deepslate_bricks"},
        {pos: [24, 0, 9], state: "minecraft:deepslate_bricks"},
        {pos: [24, 0, 10], state: "minecraft:deepslate_bricks"},
        {pos: [24, 0, 11], state: "minecraft:deepslate_bricks"},
        {pos: [24, 0, 12], state: "minecraft:deepslate_bricks"},
        {pos: [24, 0, 13], state: "minecraft:cracked_deepslate_bricks"},
        {pos: [24, 0, 14], state: "minecraft:deepslate_bricks"},
        {pos: [24, 0, 15], state: "minecraft:cracked_deepslate_bricks"},
        {pos: [24, 0, 16], state: "minecraft:cracked_deepslate_bricks"},
        {pos: [24, 0, 17], state: "minecraft:deepslate_bricks"},
        {pos: [24, 0, 18], state: "minecraft:cracked_deepslate_bricks"},
        {pos: [24, 0, 19], state: "minecraft:cracked_deepslate_bricks"},
        {pos: [24, 0, 20], state: "minecraft:cracked_deepslate_bricks"},
        {pos: [24, 0, 21], state: "minecraft:cracked_deepslate_bricks"},
        {pos: [24, 0, 22], state: "minecraft:cracked_deepslate_bricks"},
        {pos: [24, 0, 23], state: "minecraft:cracked_deepslate_bricks"},
        {pos: [24, 0, 24], state: "minecraft:cracked_deepslate_bricks"},
        {pos: [24, 0, 25], state: "minecraft:cracked_deepslate_bricks"},
        {pos: [24, 0, 26], state: "minecraft:cracked_deepslate_bricks"},
        {pos: [24, 0, 27], state: "minecraft:cracked_deepslate_bricks"},
        {pos: [24, 0, 30], state: "minecraft:deepslate_bricks"},
        {pos: [24, 0, 31], state: "minecraft:deepslate_bricks"},
        {pos: [24, 0, 32], state: "minecraft:deepslate_bricks"},
        {pos: [24, 0, 33], state: "minecraft:deepslate_bricks"},
        {pos: [24, 0, 34], state: "minecraft:deepslate_bricks"},
        {pos: [24, 0, 35], state: "minecraft:deepslate_bricks"},
        {pos: [24, 0, 36], state: "minecraft:deepslate_bricks"},
        {pos: [25, 0, 2], state: "minecraft:deepslate_bricks"},
        {pos: [25, 0, 3], state: "minecraft:deepslate_bricks"},
        {pos: [25, 0, 4], state: "minecraft:deepslate_bricks"},
        {pos: [25, 0, 5], state: "minecraft:cracked_deepslate_bricks"},
        {pos: [25, 0, 6], state: "minecraft:deepslate_bricks"},
        {pos: [25, 0, 7], state: "minecraft:deepslate_bricks"},
        {pos: [25, 0, 8], state: "minecraft:deepslate_bricks"},
        {pos: [25, 0, 9], state: "minecraft:deepslate_bricks"},
        {pos: [25, 0, 10], state: "minecraft:deepslate_bricks"},
        {pos: [25, 0, 11], state: "minecraft:deepslate_bricks"},
        {pos: [25, 0, 12], state: "minecraft:deepslate_bricks"},
        {pos: [25, 0, 13], state: "minecraft:cracked_deepslate_bricks"},
        {pos: [25, 0, 14], state: "minecraft:deepslate_bricks"},
        {pos: [25, 0, 15], state: "minecraft:deepslate_bricks"},
        {pos: [25, 0, 16], state: "minecraft:deepslate_bricks"},
        {pos: [25, 0, 17], state: "minecraft:cracked_deepslate_bricks"},
        {pos: [25, 0, 18], state: "minecraft:cracked_deepslate_bricks"},
        {pos: [25, 0, 21], state: "minecraft:cracked_deepslate_bricks"},
        {pos: [25, 0, 24], state: "minecraft:cracked_deepslate_bricks"},
        {pos: [25, 0, 25], state: "minecraft:cracked_deepslate_bricks"},
        {pos: [25, 0, 26], state: "minecraft:cracked_deepslate_bricks"},
        {pos: [25, 0, 27], state: "minecraft:cracked_deepslate_bricks"},
        {pos: [25, 0, 30], state: "minecraft:deepslate_bricks"},
        {pos: [25, 0, 31], state: "minecraft:deepslate_bricks"},
        {pos: [25, 0, 32], state: "minecraft:deepslate_bricks"},
        {pos: [25, 0, 33], state: "minecraft:deepslate_bricks"},
        {pos: [25, 0, 34], state: "minecraft:deepslate_bricks"},
        {pos: [25, 0, 35], state: "minecraft:deepslate_bricks"},
        {pos: [25, 0, 36], state: "minecraft:deepslate_bricks"},
        {pos: [26, 0, 3], state: "minecraft:deepslate_bricks"},
        {pos: [26, 0, 4], state: "minecraft:deepslate_bricks"},
        {pos: [26, 0, 5], state: "minecraft:deepslate_bricks"},
        {pos: [26, 0, 6], state: "minecraft:deepslate_bricks"},
        {pos: [26, 0, 7], state: "minecraft:deepslate_bricks"},
        {pos: [26, 0, 8], state: "minecraft:deepslate_bricks"},
        {pos: [26, 0, 9], state: "minecraft:deepslate_bricks"},
        {pos: [26, 0, 10], state: "minecraft:deepslate_bricks"},
        {pos: [26, 0, 11], state: "minecraft:deepslate_bricks"},
        {pos: [26, 0, 12], state: "minecraft:deepslate_bricks"},
        {pos: [26, 0, 13], state: "minecraft:deepslate_bricks"},
        {pos: [26, 0, 14], state: "minecraft:deepslate_bricks"},
        {pos: [26, 0, 15], state: "minecraft:deepslate_bricks"},
        {pos: [26, 0, 16], state: "minecraft:cracked_deepslate_bricks"},
        {pos: [26, 0, 17], state: "minecraft:cracked_deepslate_bricks"},
        {pos: [26, 0, 21], state: "minecraft:cracked_deepslate_bricks"},
        {pos: [26, 0, 26], state: "minecraft:cracked_deepslate_bricks"},
        {pos: [26, 0, 27], state: "minecraft:cracked_deepslate_bricks"},
        {pos: [26, 0, 29], state: "minecraft:deepslate_bricks"},
        {pos: [26, 0, 30], state: "minecraft:deepslate_bricks"},
        {pos: [26, 0, 31], state: "minecraft:deepslate_bricks"},
        {pos: [26, 0, 32], state: "minecraft:deepslate_bricks"},
        {pos: [26, 0, 33], state: "minecraft:deepslate_bricks"},
        {pos: [26, 0, 34], state: "minecraft:deepslate_bricks"},
        {pos: [26, 0, 35], state: "minecraft:deepslate_bricks"},
        {pos: [26, 0, 36], state: "minecraft:deepslate_bricks"},
        {pos: [27, 0, 2], state: "minecraft:deepslate_bricks"},
        {pos: [27, 0, 3], state: "minecraft:deepslate_bricks"},
        {pos: [27, 0, 4], state: "minecraft:deepslate_bricks"},
        {pos: [27, 0, 5], state: "minecraft:deepslate_bricks"},
        {pos: [27, 0, 6], state: "minecraft:deepslate_bricks"},
        {pos: [27, 0, 7], state: "minecraft:deepslate_bricks"},
        {pos: [27, 0, 8], state: "minecraft:deepslate_bricks"},
        {pos: [27, 0, 9], state: "minecraft:deepslate_bricks"},
        {pos: [27, 0, 10], state: "minecraft:deepslate_bricks"},
        {pos: [27, 0, 11], state: "minecraft:deepslate_bricks"},
        {pos: [27, 0, 12], state: "minecraft:deepslate_bricks"},
        {pos: [27, 0, 13], state: "minecraft:deepslate_bricks"},
        {pos: [27, 0, 14], state: "minecraft:deepslate_bricks"},
        {pos: [27, 0, 15], state: "minecraft:deepslate_bricks"},
        {pos: [27, 0, 16], state: "minecraft:deepslate_bricks"},
        {pos: [27, 0, 17], state: "minecraft:cracked_deepslate_bricks"},
        {pos: [27, 0, 21], state: "minecraft:cracked_deepslate_bricks"},
        {pos: [27, 0, 26], state: "minecraft:cracked_deepslate_bricks"},
        {pos: [27, 0, 27], state: "minecraft:deepslate_bricks"},
        {pos: [27, 0, 28], state: "minecraft:deepslate_bricks"},
        {pos: [27, 0, 29], state: "minecraft:deepslate_bricks"},
        {pos: [27, 0, 30], state: "minecraft:deepslate_bricks"},
        {pos: [27, 0, 31], state: "minecraft:deepslate_bricks"},
        {pos: [27, 0, 32], state: "minecraft:deepslate_bricks"},
        {pos: [27, 0, 33], state: "minecraft:deepslate_bricks"},
        {pos: [27, 0, 34], state: "minecraft:deepslate_bricks"},
        {pos: [27, 0, 35], state: "minecraft:deepslate_bricks"},
        {pos: [27, 0, 36], state: "minecraft:deepslate_bricks"},
        {pos: [28, 0, 2], state: "minecraft:deepslate_bricks"},
        {pos: [28, 0, 3], state: "minecraft:deepslate_bricks"},
        {pos: [28, 0, 4], state: "minecraft:deepslate_bricks"},
        {pos: [28, 0, 5], state: "minecraft:deepslate_bricks"},
        {pos: [28, 0, 6], state: "minecraft:deepslate_bricks"},
        {pos: [28, 0, 7], state: "minecraft:deepslate_bricks"},
        {pos: [28, 0, 8], state: "minecraft:deepslate_bricks"},
        {pos: [28, 0, 9], state: "minecraft:deepslate_bricks"},
        {pos: [28, 0, 10], state: "minecraft:deepslate_bricks"},
        {pos: [28, 0, 11], state: "minecraft:deepslate_bricks"},
        {pos: [28, 0, 12], state: "minecraft:deepslate_bricks"},
        {pos: [28, 0, 13], state: "minecraft:deepslate_bricks"},
        {pos: [28, 0, 14], state: "minecraft:deepslate_bricks"},
        {pos: [28, 0, 15], state: "minecraft:deepslate_bricks"},
        {pos: [28, 0, 16], state: "minecraft:deepslate_bricks"},
        {pos: [28, 0, 17], state: "minecraft:deepslate_bricks"},
        {pos: [28, 0, 21], state: "minecraft:jigsaw{orientation:east_up}", nbt: {final_state: "minecraft:structure_void", id: "minecraft:jigsaw", joint: "rollable", name: "minecraft:connect_structure", pool: "minecraft:empty", target: "minecraft:empty"}},
        {pos: [28, 0, 26], state: "minecraft:deepslate_bricks"},
        {pos: [28, 0, 27], state: "minecraft:deepslate_bricks"},
        {pos: [28, 0, 28], state: "minecraft:deepslate_bricks"},
        {pos: [28, 0, 29], state: "minecraft:deepslate_bricks"},
        {pos: [28, 0, 30], state: "minecraft:deepslate_bricks"},
        {pos: [28, 0, 31], state: "minecraft:deepslate_bricks"},
        {pos: [28, 0, 32], state: "minecraft:deepslate_bricks"},
        {pos: [28, 0, 33], state: "minecraft:deepslate_bricks"},
        {pos: [28, 0, 34], state: "minecraft:deepslate_bricks"},
        {pos: [28, 0, 35], state: "minecraft:deepslate_bricks"},
        {pos: [28, 0, 36], state: "minecraft:deepslate_bricks"},
        {pos: [0, 1, 14], state: "minecraft:deepslate_bricks"},
        {pos: [0, 1, 15], state: "minecraft:cracked_deepslate_tiles"},
        {pos: [0, 1, 16], state: "minecraft:deepslate_tiles"},
        {pos: [0, 1, 17], state: "minecraft:deepslate_bricks"},
        {pos: [0, 1, 18], state: "minecraft:deepslate_bricks"},
        {pos: [0, 1, 19], state: "minecraft:deepslate_bricks"},
        {pos: [0, 1, 26], state: "minecraft:deepslate_bricks"},
        {pos: [0, 1, 27], state: "minecraft:deepslate_bricks"},
        {pos: [1, 1, 0], state: "minecraft:deepslate_bricks"},
        {pos: [1, 1, 15], state: "minecraft:cracked_deepslate_tiles"},
        {pos: [1, 1, 16], state: "minecraft:deepslate_tiles"},
        {pos: [1, 1, 18], state: "minecraft:deepslate_bricks"},
        {pos: [1, 1, 19], state: "minecraft:deepslate_bricks"},
        {pos: [1, 1, 26], state: "minecraft:deepslate_bricks"},
        {pos: [1, 1, 27], state: "minecraft:deepslate_bricks"},
        {pos: [2, 1, 0], state: "minecraft:deepslate_bricks"},
        {pos: [2, 1, 2], state: "minecraft:cracked_deepslate_tiles"},
        {pos: [2, 1, 3], state: "minecraft:deepslate_tiles"},
        {pos: [3, 1, 0], state: "minecraft:deepslate_bricks"},
        {pos: [3, 1, 2], state: "minecraft:cracked_deepslate_tiles"},
        {pos: [3, 1, 3], state: "minecraft:deepslate_tiles"},
        {pos: [4, 1, 0], state: "minecraft:deepslate_bricks"},
        {pos: [5, 1, 0], state: "minecraft:deepslate_bricks"},
        {pos: [6, 1, 0], state: "minecraft:deepslate_bricks"},
        {pos: [6, 1, 16], state: "minecraft:deepslate_bricks"},
        {pos: [6, 1, 17], state: "minecraft:deepslate_bricks"},
        {pos: [6, 1, 20], state: "minecraft:deepslate_bricks"},
        {pos: [6, 1, 21], state: "minecraft:deepslate_bricks"},
        {pos: [6, 1, 24], state: "minecraft:deepslate_bricks"},
        {pos: [6, 1, 25], state: "minecraft:deepslate_bricks"},
        {pos: [6, 1, 28], state: "minecraft:deepslate_bricks"},
        {pos: [6, 1, 29], state: "minecraft:deepslate_bricks"},
        {pos: [7, 1, 0], state: "minecraft:deepslate_bricks"},
        {pos: [7, 1, 2], state: "minecraft:cracked_deepslate_tiles"},
        {pos: [7, 1, 3], state: "minecraft:deepslate_tiles"},
        {pos: [7, 1, 16], state: "minecraft:deepslate_bricks"},
        {pos: [7, 1, 21], state: "minecraft:deepslate_bricks"},
        {pos: [7, 1, 24], state: "minecraft:deepslate_bricks"},
        {pos: [7, 1, 25], state: "minecraft:deepslate_bricks"},
        {pos: [7, 1, 28], state: "minecraft:deepslate_bricks"},
        {pos: [7, 1, 29], state: "minecraft:deepslate_bricks"},
        {pos: [8, 1, 0], state: "minecraft:deepslate_bricks"},
        {pos: [8, 1, 2], state: "minecraft:cracked_deepslate_tiles"},
        {pos: [8, 1, 3], state: "minecraft:deepslate_tiles"},
        {pos: [8, 1, 7], state: "minecraft:deepslate_tile_stairs{facing:east,half:bottom,shape:straight,waterlogged:false}"},
        {pos: [8, 1, 8], state: "minecraft:deepslate_tile_stairs{facing:east,half:bottom,shape:straight,waterlogged:false}"},
        {pos: [8, 1, 16], state: "minecraft:cracked_deepslate_bricks"},
        {pos: [8, 1, 21], state: "minecraft:deepslate_bricks"},
        {pos: [8, 1, 24], state: "minecraft:deepslate_bricks"},
        {pos: [8, 1, 25], state: "minecraft:white_candle{candles:3,lit:true,waterlogged:false}"},
        {pos: [8, 1, 28], state: "minecraft:white_candle{candles:2,lit:true,waterlogged:false}"},
        {pos: [8, 1, 29], state: "minecraft:deepslate_bricks"},
        {pos: [9, 1, 0], state: "minecraft:deepslate_bricks"},
        {pos: [9, 1, 4], state: "minecraft:deepslate_tiles"},
        {pos: [9, 1, 5], state: "minecraft:deepslate_tiles"},
        {pos: [9, 1, 6], state: "minecraft:deepslate_tiles"},
        {pos: [9, 1, 7], state: "minecraft:deepslate_tiles"},
        {pos: [9, 1, 8], state: "minecraft:deepslate_tiles"},
        {pos: [9, 1, 16], state: "minecraft:cracked_deepslate_bricks"},
        {pos: [9, 1, 21], state: "minecraft:deepslate_bricks"},
        {pos: [9, 1, 24], state: "minecraft:deepslate_bricks"},
        {pos: [9, 1, 29], state: "minecraft:deepslate_bricks"},
        {pos: [10, 1, 0], state: "minecraft:deepslate_bricks"},
        {pos: [10, 1, 4], state: "minecraft:deepslate_tiles"},
        {pos: [10, 1, 5], state: "minecraft:deepslate_tiles"},
        {pos: [10, 1, 6], state: "minecraft:deepslate_tiles"},
        {pos: [10, 1, 7], state: "minecraft:deepslate_tiles"},
        {pos: [10, 1, 8], state: "minecraft:deepslate_tiles"},
        {pos: [10, 1, 16], state: "minecraft:deepslate_bricks"},
        {pos: [10, 1, 21], state: "minecraft:deepslate_bricks"},
        {pos: [11, 1, 0], state: "minecraft:deepslate_bricks"},
        {pos: [11, 1, 4], state: "minecraft:deepslate_tiles"},
        {pos: [11, 1, 5], state: "minecraft:deepslate_tiles"},
        {pos: [11, 1, 6], state: "minecraft:deepslate_tiles"},
        {pos: [11, 1, 7], state: "minecraft:deepslate_tiles"},
        {pos: [11, 1, 8], state: "minecraft:deepslate_tiles"},
        {pos: [11, 1, 9], state: "minecraft:deepslate_tiles"},
        {pos: [11, 1, 16], state: "minecraft:deepslate_bricks"},
        {pos: [11, 1, 21], state: "minecraft:deepslate_bricks"},
        {pos: [11, 1, 36], state: "minecraft:deepslate_bricks"},
        {pos: [12, 1, 0], state: "minecraft:cracked_deepslate_bricks"},
        {pos: [12, 1, 4], state: "minecraft:deepslate_tiles"},
        {pos: [12, 1, 5], state: "minecraft:deepslate_tiles"},
        {pos: [12, 1, 6], state: "minecraft:deepslate_tiles"},
        {pos: [12, 1, 7], state: "minecraft:deepslate_tiles"},
        {pos: [12, 1, 8], state: "minecraft:deepslate_tiles"},
        {pos: [12, 1, 9], state: "minecraft:deepslate_tiles"},
        {pos: [12, 1, 18], state: "minecraft:white_candle{candles:2,lit:true,waterlogged:false}"},
        {pos: [12, 1, 19], state: "minecraft:chest{facing:west,type:single,waterlogged:false}", nbt: {LootTable: "minecraft:chests/ancient_city", id: "minecraft:chest"}},
        {pos: [12, 1, 21], state: "minecraft:deepslate_bricks"},
        {pos: [12, 1, 31], state: "minecraft:deepslate_bricks"},
        {pos: [12, 1, 32], state: "minecraft:deepslate_bricks"},
        {pos: [12, 1, 33], state: "minecraft:deepslate_bricks"},
        {pos: [12, 1, 36], state: "minecraft:deepslate_bricks"},
        {pos: [13, 1, 0], state: "minecraft:cracked_deepslate_bricks"},
        {pos: [13, 1, 6], state: "minecraft:white_candle{candles:2,lit:true,waterlogged:false}"},
        {pos: [13, 1, 7], state: "minecraft:deepslate_tiles"},
        {pos: [13, 1, 8], state: "minecraft:deepslate_tile_stairs{facing:north,half:bottom,shape:straight,waterlogged:false}"},
        {pos: [13, 1, 16], state: "minecraft:deepslate_bricks"},
        {pos: [13, 1, 17], state: "minecraft:deepslate_tile_slab{type:bottom,waterlogged:false}"},
        {pos: [13, 1, 18], state: "minecraft:deepslate_bricks"},
        {pos: [13, 1, 19], state: "minecraft:deepslate_bricks"},
        {pos: [13, 1, 20], state: "minecraft:deepslate_bricks"},
        {pos: [13, 1, 21], state: "minecraft:deepslate_bricks"},
        {pos: [13, 1, 31], state: "minecraft:white_candle{candles:1,lit:true,waterlogged:false}"},
        {pos: [13, 1, 32], state: "minecraft:deepslate_bricks"},
        {pos: [13, 1, 33], state: "minecraft:deepslate_bricks"},
        {pos: [13, 1, 36], state: "minecraft:deepslate_bricks"},
        {pos: [14, 1, 0], state: "minecraft:cracked_deepslate_bricks"},
        {pos: [14, 1, 6], state: "minecraft:white_candle{candles:2,lit:true,waterlogged:false}"},
        {pos: [14, 1, 7], state: "minecraft:deepslate_tiles"},
        {pos: [14, 1, 8], state: "minecraft:deepslate_tile_slab{type:top,waterlogged:false}"},
        {pos: [14, 1, 32], state: "minecraft:deepslate_bricks"},
        {pos: [14, 1, 33], state: "minecraft:deepslate_bricks"},
        {pos: [14, 1, 36], state: "minecraft:deepslate_bricks"},
        {pos: [15, 1, 6], state: "minecraft:white_candle{candles:1,lit:true,waterlogged:false}"},
        {pos: [15, 1, 7], state: "minecraft:deepslate_tiles"},
        {pos: [15, 1, 8], state: "minecraft:deepslate_tile_stairs{facing:north,half:bottom,shape:straight,waterlogged:false}"},
        {pos: [15, 1, 32], state: "minecraft:deepslate_bricks"},
        {pos: [15, 1, 33], state: "minecraft:deepslate_bricks"},
        {pos: [15, 1, 36], state: "minecraft:deepslate_bricks"},
        {pos: [16, 1, 0], state: "minecraft:cracked_deepslate_bricks"},
        {pos: [16, 1, 4], state: "minecraft:deepslate_tiles"},
        {pos: [16, 1, 5], state: "minecraft:deepslate_tiles"},
        {pos: [16, 1, 6], state: "minecraft:deepslate_tiles"},
        {pos: [16, 1, 7], state: "minecraft:deepslate_tiles"},
        {pos: [16, 1, 8], state: "minecraft:deepslate_tiles"},
        {pos: [16, 1, 9], state: "minecraft:deepslate_tiles"},
        {pos: [16, 1, 19], state: "minecraft:deepslate_bricks"},
        {pos: [16, 1, 20], state: "minecraft:deepslate_bricks"},
        {pos: [16, 1, 21], state: "minecraft:deepslate_bricks"},
        {pos: [16, 1, 32], state: "minecraft:white_candle{candles:2,lit:true,waterlogged:false}"},
        {pos: [16, 1, 33], state: "minecraft:deepslate_bricks"},
        {pos: [16, 1, 36], state: "minecraft:deepslate_bricks"},
        {pos: [17, 1, 0], state: "minecraft:deepslate_bricks"},
        {pos: [17, 1, 4], state: "minecraft:deepslate_tiles"},
        {pos: [17, 1, 5], state: "minecraft:deepslate_tiles"},
        {pos: [17, 1, 6], state: "minecraft:deepslate_tiles"},
        {pos: [17, 1, 7], state: "minecraft:deepslate_tiles"},
        {pos: [17, 1, 8], state: "minecraft:deepslate_tiles"},
        {pos: [17, 1, 9], state: "minecraft:deepslate_tiles"},
        {pos: [17, 1, 15], state: "minecraft:deepslate_bricks"},
        {pos: [17, 1, 20], state: "minecraft:white_candle{candles:2,lit:false,waterlogged:false}"},
        {pos: [17, 1, 21], state: "minecraft:deepslate_bricks"},
        {pos: [17, 1, 36], state: "minecraft:deepslate_bricks"},
        {pos: [18, 1, 0], state: "minecraft:deepslate_bricks"},
        {pos: [18, 1, 4], state: "minecraft:deepslate_tiles"},
        {pos: [18, 1, 5], state: "minecraft:deepslate_tiles"},
        {pos: [18, 1, 6], state: "minecraft:deepslate_tiles"},
        {pos: [18, 1, 7], state: "minecraft:deepslate_tiles"},
        {pos: [18, 1, 8], state: "minecraft:deepslate_tiles"},
        {pos: [18, 1, 15], state: "minecraft:deepslate_bricks"},
        {pos: [18, 1, 21], state: "minecraft:deepslate_bricks"},
        {pos: [18, 1, 36], state: "minecraft:deepslate_bricks"},
        {pos: [19, 1, 0], state: "minecraft:deepslate_bricks"},
        {pos: [19, 1, 4], state: "minecraft:deepslate_tiles"},
        {pos: [19, 1, 5], state: "minecraft:deepslate_tiles"},
        {pos: [19, 1, 6], state: "minecraft:deepslate_tiles"},
        {pos: [19, 1, 7], state: "minecraft:deepslate_tiles"},
        {pos: [19, 1, 15], state: "minecraft:deepslate_bricks"},
        {pos: [19, 1, 21], state: "minecraft:deepslate_tile_slab{type:bottom,waterlogged:false}"},
        {pos: [19, 1, 36], state: "minecraft:deepslate_bricks"},
        {pos: [20, 1, 0], state: "minecraft:deepslate_bricks"},
        {pos: [20, 1, 2], state: "minecraft:cracked_deepslate_tiles"},
        {pos: [20, 1, 3], state: "minecraft:deepslate_tiles"},
        {pos: [20, 1, 4], state: "minecraft:deepslate_tile_stairs{facing:west,half:bottom,shape:straight,waterlogged:false}"},
        {pos: [20, 1, 5], state: "minecraft:deepslate_tile_stairs{facing:west,half:bottom,shape:straight,waterlogged:false}"},
        {pos: [20, 1, 6], state: "minecraft:deepslate_tile_stairs{facing:west,half:bottom,shape:straight,waterlogged:false}"},
        {pos: [20, 1, 7], state: "minecraft:deepslate_tile_stairs{facing:west,half:bottom,shape:straight,waterlogged:false}"},
        {pos: [20, 1, 15], state: "minecraft:deepslate_bricks"},
        {pos: [20, 1, 21], state: "minecraft:deepslate_bricks"},
        {pos: [20, 1, 32], state: "minecraft:deepslate_bricks"},
        {pos: [20, 1, 33], state: "minecraft:deepslate_bricks"},
        {pos: [20, 1, 36], state: "minecraft:deepslate_bricks"},
        {pos: [21, 1, 0], state: "minecraft:deepslate_bricks"},
        {pos: [21, 1, 2], state: "minecraft:cracked_deepslate_tiles"},
        {pos: [21, 1, 3], state: "minecraft:deepslate_tiles"},
        {pos: [21, 1, 15], state: "minecraft:deepslate_bricks"},
        {pos: [21, 1, 18], state: "minecraft:chest{facing:west,type:single,waterlogged:false}", nbt: {LootTable: "minecraft:chests/ancient_city", id: "minecraft:chest"}},
        {pos: [21, 1, 21], state: "minecraft:deepslate_bricks"},
        {pos: [21, 1, 32], state: "minecraft:deepslate_bricks"},
        {pos: [21, 1, 33], state: "minecraft:deepslate_bricks"},
        {pos: [22, 1, 0], state: "minecraft:deepslate_bricks"},
        {pos: [22, 1, 15], state: "minecraft:deepslate_bricks"},
        {pos: [22, 1, 16], state: "minecraft:cracked_deepslate_bricks"},
        {pos: [22, 1, 17], state: "minecraft:deepslate_bricks"},
        {pos: [22, 1, 18], state: "minecraft:deepslate_bricks"},
        {pos: [22, 1, 19], state: "minecraft:deepslate_bricks"},
        {pos: [22, 1, 20], state: "minecraft:deepslate_bricks"},
        {pos: [22, 1, 21], state: "minecraft:deepslate_bricks"},
        {pos: [22, 1, 32], state: "minecraft:deepslate_bricks"},
        {pos: [22, 1, 33], state: "minecraft:deepslate_bricks"},
        {pos: [23, 1, 10], state: "minecraft:deepslate_bricks"},
        {pos: [23, 1, 11], state: "minecraft:deepslate_bricks"},
        {pos: [23, 1, 23], state: "minecraft:deepslate_bricks"},
        {pos: [23, 1, 24], state: "minecraft:deepslate_bricks"},
        {pos: [23, 1, 25], state: "minecraft:deepslate_bricks"},
        {pos: [23, 1, 26], state: "minecraft:deepslate_bricks"},
        {pos: [23, 1, 27], state: "minecraft:deepslate_bricks"},
        {pos: [23, 1, 28], state: "minecraft:deepslate_bricks"},
        {pos: [23, 1, 29], state: "minecraft:deepslate_bricks"},
        {pos: [23, 1, 30], state: "minecraft:deepslate_bricks"},
        {pos: [23, 1, 31], state: "minecraft:deepslate_bricks"},
        {pos: [23, 1, 32], state: "minecraft:deepslate_bricks"},
        {pos: [23, 1, 33], state: "minecraft:deepslate_bricks"},
        {pos: [24, 1, 8], state: "minecraft:deepslate_bricks"},
        {pos: [24, 1, 11], state: "minecraft:deepslate_bricks"},
        {pos: [25, 1, 2], state: "minecraft:cracked_deepslate_tiles"},
        {pos: [25, 1, 3], state: "minecraft:deepslate_tiles"},
        {pos: [25, 1, 8], state: "minecraft:deepslate_bricks"},
        {pos: [25, 1, 10], state: "minecraft:chest{facing:west,type:single,waterlogged:false}", nbt: {LootTable: "minecraft:chests/ancient_city", id: "minecraft:chest"}},
        {pos: [25, 1, 11], state: "minecraft:deepslate_bricks"},
        {pos: [25, 1, 36], state: "minecraft:cracked_deepslate_bricks"},
        {pos: [26, 1, 3], state: "minecraft:deepslate_tiles"},
        {pos: [26, 1, 8], state: "minecraft:deepslate_bricks"},
        {pos: [26, 1, 9], state: "minecraft:deepslate_bricks"},
        {pos: [26, 1, 10], state: "minecraft:deepslate_bricks"},
        {pos: [26, 1, 11], state: "minecraft:deepslate_bricks"},
        {pos: [26, 1, 36], state: "minecraft:cracked_deepslate_bricks"},
        {pos: [27, 1, 15], state: "minecraft:cracked_deepslate_tiles"},
        {pos: [27, 1, 16], state: "minecraft:deepslate_tiles"},
        {pos: [27, 1, 29], state: "minecraft:cracked_deepslate_tiles"},
        {pos: [27, 1, 30], state: "minecraft:deepslate_tiles"},
        {pos: [27, 1, 36], state: "minecraft:deepslate_bricks"},
        {pos: [28, 1, 4], state: "minecraft:deepslate_bricks"},
        {pos: [28, 1, 5], state: "minecraft:deepslate_bricks"},
        {pos: [28, 1, 6], state: "minecraft:deepslate_bricks"},
        {pos: [28, 1, 7], state: "minecraft:deepslate_bricks"},
        {pos: [28, 1, 8], state: "minecraft:deepslate_bricks"},
        {pos: [28, 1, 9], state: "minecraft:deepslate_bricks"},
        {pos: [28, 1, 10], state: "minecraft:deepslate_bricks"},
        {pos: [28, 1, 11], state: "minecraft:deepslate_bricks"},
        {pos: [28, 1, 12], state: "minecraft:deepslate_bricks"},
        {pos: [28, 1, 13], state: "minecraft:deepslate_bricks"},
        {pos: [28, 1, 14], state: "minecraft:deepslate_bricks"},
        {pos: [28, 1, 15], state: "minecraft:cracked_deepslate_tiles"},
        {pos: [28, 1, 16], state: "minecraft:deepslate_tiles"},
        {pos: [28, 1, 17], state: "minecraft:deepslate_bricks"},
        {pos: [28, 1, 26], state: "minecraft:deepslate_bricks"},
        {pos: [28, 1, 27], state: "minecraft:deepslate_bricks"},
        {pos: [28, 1, 28], state: "minecraft:deepslate_bricks"},
        {pos: [28, 1, 29], state: "minecraft:cracked_deepslate_tiles"},
        {pos: [28, 1, 30], state: "minecraft:deepslate_tiles"},
        {pos: [28, 1, 31], state: "minecraft:deepslate_bricks"},
        {pos: [28, 1, 32], state: "minecraft:deepslate_bricks"},
        {pos: [28, 1, 33], state: "minecraft:deepslate_bricks"},
        {pos: [28, 1, 34], state: "minecraft:deepslate_bricks"},
        {pos: [28, 1, 35], state: "minecraft:deepslate_bricks"},
        {pos: [28, 1, 36], state: "minecraft:deepslate_bricks"},
        {pos: [0, 2, 14], state: "minecraft:deepslate_bricks"},
        {pos: [0, 2, 15], state: "minecraft:chiseled_deepslate"},
        {pos: [0, 2, 16], state: "minecraft:chiseled_deepslate"},
        {pos: [0, 2, 17], state: "minecraft:deepslate_bricks"},
        {pos: [0, 2, 18], state: "minecraft:deepslate_bricks"},
        {pos: [0, 2, 19], state: "minecraft:deepslate_bricks"},
        {pos: [0, 2, 26], state: "minecraft:deepslate_bricks"},
        {pos: [0, 2, 27], state: "minecraft:deepslate_bricks"},
        {pos: [1, 2, 15], state: "minecraft:chiseled_deepslate"},
        {pos: [1, 2, 16], state: "minecraft:chiseled_deepslate"},
        {pos: [1, 2, 18], state: "minecraft:deepslate_bricks"},
        {pos: [1, 2, 19], state: "minecraft:deepslate_bricks"},
        {pos: [1, 2, 26], state: "minecraft:deepslate_bricks"},
        {pos: [1, 2, 27], state: "minecraft:deepslate_bricks"},
        {pos: [2, 2, 0], state: "minecraft:deepslate_bricks"},
        {pos: [2, 2, 2], state: "minecraft:chiseled_deepslate"},
        {pos: [2, 2, 3], state: "minecraft:chiseled_deepslate"},
        {pos: [3, 2, 0], state: "minecraft:deepslate_bricks"},
        {pos: [3, 2, 2], state: "minecraft:chiseled_deepslate"},
        {pos: [4, 2, 0], state: "minecraft:deepslate_bricks"},
        {pos: [5, 2, 0], state: "minecraft:deepslate_bricks"},
        {pos: [6, 2, 0], state: "minecraft:deepslate_bricks"},
        {pos: [6, 2, 16], state: "minecraft:deepslate_bricks"},
        {pos: [6, 2, 17], state: "minecraft:deepslate_bricks"},
        {pos: [6, 2, 20], state: "minecraft:deepslate_bricks"},
        {pos: [6, 2, 21], state: "minecraft:cracked_deepslate_bricks"},
        {pos: [6, 2, 24], state: "minecraft:deepslate_bricks"},
        {pos: [6, 2, 29], state: "minecraft:white_candle{candles:2,lit:false,waterlogged:false}"},
        {pos: [7, 2, 0], state: "minecraft:deepslate_bricks"},
        {pos: [7, 2, 2], state: "minecraft:chiseled_deepslate"},
        {pos: [7, 2, 3], state: "minecraft:chiseled_deepslate"},
        {pos: [7, 2, 16], state: "minecraft:deepslate_bricks"},
        {pos: [7, 2, 21], state: "minecraft:deepslate_bricks"},
        {pos: [7, 2, 24], state: "minecraft:deepslate_bricks"},
        {pos: [7, 2, 25], state: "minecraft:white_candle{candles:1,lit:true,waterlogged:false}"},
        {pos: [7, 2, 29], state: "minecraft:deepslate_bricks"},
        {pos: [8, 2, 0], state: "minecraft:deepslate_bricks"},
        {pos: [8, 2, 2], state: "minecraft:chiseled_deepslate"},
        {pos: [8, 2, 3], state: "minecraft:chiseled_deepslate"},
        {pos: [8, 2, 21], state: "minecraft:deepslate_bricks"},
        {pos: [8, 2, 24], state: "minecraft:deepslate_bricks"},
        {pos: [8, 2, 29], state: "minecraft:deepslate_bricks"},
        {pos: [9, 2, 0], state: "minecraft:deepslate_bricks"},
        {pos: [9, 2, 4], state: "minecraft:deepslate_tile_stairs{facing:east,half:bottom,shape:straight,waterlogged:false}"},
        {pos: [9, 2, 5], state: "minecraft:deepslate_tile_stairs{facing:east,half:bottom,shape:straight,waterlogged:false}"},
        {pos: [9, 2, 8], state: "minecraft:deepslate_tile_stairs{facing:east,half:bottom,shape:straight,waterlogged:false}"},
        {pos: [9, 2, 21], state: "minecraft:deepslate_bricks"},
        {pos: [9, 2, 24], state: "minecraft:deepslate_bricks"},
        {pos: [9, 2, 29], state: "minecraft:deepslate_bricks"},
        {pos: [10, 2, 0], state: "minecraft:deepslate_bricks"},
        {pos: [10, 2, 4], state: "minecraft:deepslate_tiles"},
        {pos: [10, 2, 5], state: "minecraft:deepslate_tiles"},
        {pos: [10, 2, 6], state: "minecraft:deepslate_tiles"},
        {pos: [10, 2, 7], state: "minecraft:deepslate_tiles"},
        {pos: [10, 2, 8], state: "minecraft:deepslate_tiles"},
        {pos: [10, 2, 16], state: "minecraft:white_candle{candles:1,lit:false,waterlogged:false}"},
        {pos: [10, 2, 21], state: "minecraft:deepslate_bricks"},
        {pos: [11, 2, 0], state: "minecraft:cracked_deepslate_bricks"},
        {pos: [11, 2, 4], state: "minecraft:deepslate_tiles"},
        {pos: [11, 2, 5], state: "minecraft:deepslate_tiles"},
        {pos: [11, 2, 6], state: "minecraft:deepslate_tiles"},
        {pos: [11, 2, 7], state: "minecraft:deepslate_tiles"},
        {pos: [11, 2, 8], state: "minecraft:deepslate_tiles"},
        {pos: [11, 2, 9], state: "minecraft:white_candle{candles:1,lit:true,waterlogged:false}"},
        {pos: [11, 2, 16], state: "minecraft:deepslate_bricks"},
        {pos: [11, 2, 21], state: "minecraft:deepslate_bricks"},
        {pos: [11, 2, 33], state: "minecraft:cracked_deepslate_bricks"},
        {pos: [12, 2, 0], state: "minecraft:cracked_deepslate_bricks"},
        {pos: [12, 2, 4], state: "minecraft:deepslate_tiles"},
        {pos: [12, 2, 5], state: "minecraft:deepslate_tiles"},
        {pos: [12, 2, 6], state: "minecraft:deepslate_tiles"},
        {pos: [12, 2, 7], state: "minecraft:deepslate_tiles"},
        {pos: [12, 2, 8], state: "minecraft:deepslate_tile_stairs{facing:north,half:bottom,shape:straight,waterlogged:false}"},
        {pos: [12, 2, 9], state: "minecraft:white_candle{candles:2,lit:true,waterlogged:false}"},
        {pos: [12, 2, 16], state: "minecraft:deepslate_bricks"},
        {pos: [12, 2, 21], state: "minecraft:deepslate_bricks"},
        {pos: [12, 2, 31], state: "minecraft:deepslate_bricks"},
        {pos: [12, 2, 32], state: "minecraft:deepslate_bricks"},
        {pos: [12, 2, 33], state: "minecraft:deepslate_bricks"},
        {pos: [13, 2, 0], state: "minecraft:cracked_deepslate_bricks"},
        {pos: [13, 2, 7], state: "minecraft:white_candle{candles:1,lit:true,waterlogged:false}"},
        {pos: [13, 2, 8], state: "minecraft:deepslate_tile_stairs{facing:north,half:bottom,shape:straight,waterlogged:false}"},
        {pos: [13, 2, 16], state: "minecraft:cracked_deepslate_bricks"},
        {pos: [13, 2, 18], state: "minecraft:deepslate_bricks"},
        {pos: [13, 2, 19], state: "minecraft:deepslate_bricks"},
        {pos: [13, 2, 20], state: "minecraft:deepslate_bricks"},
        {pos: [13, 2, 21], state: "minecraft:deepslate_bricks"},
        {pos: [13, 2, 33], state: "minecraft:deepslate_bricks"},
        {pos: [14, 2, 0], state: "minecraft:cracked_deepslate_bricks"},
        {pos: [14, 2, 7], state: "minecraft:white_candle{candles:2,lit:true,waterlogged:false}"},
        {pos: [14, 2, 8], state: "minecraft:chiseled_deepslate"},
        {pos: [14, 2, 33], state: "minecraft:deepslate_bricks"},
        {pos: [15, 2, 7], state: "minecraft:white_candle{candles:4,lit:true,waterlogged:false}"},
        {pos: [15, 2, 8], state: "minecraft:deepslate_tile_stairs{facing:north,half:bottom,shape:straight,waterlogged:false}"},
        {pos: [15, 2, 33], state: "minecraft:deepslate_bricks"},
        {pos: [15, 2, 36], state: "minecraft:deepslate_bricks"},
        {pos: [16, 2, 4], state: "minecraft:deepslate_tiles"},
        {pos: [16, 2, 5], state: "minecraft:deepslate_tiles"},
        {pos: [16, 2, 6], state: "minecraft:deepslate_tiles"},
        {pos: [16, 2, 7], state: "minecraft:deepslate_tiles"},
        {pos: [16, 2, 8], state: "minecraft:deepslate_tile_stairs{facing:north,half:bottom,shape:straight,waterlogged:false}"},
        {pos: [16, 2, 9], state: "minecraft:white_candle{candles:1,lit:true,waterlogged:false}"},
        {pos: [16, 2, 19], state: "minecraft:deepslate_bricks"},
        {pos: [16, 2, 20], state: "minecraft:deepslate_bricks"},
        {pos: [16, 2, 21], state: "minecraft:deepslate_bricks"},
        {pos: [16, 2, 33], state: "minecraft:deepslate_bricks"},
        {pos: [17, 2, 0], state: "minecraft:cracked_deepslate_bricks"},
        {pos: [17, 2, 4], state: "minecraft:deepslate_tiles"},
        {pos: [17, 2, 5], state: "minecraft:deepslate_tiles"},
        {pos: [17, 2, 6], state: "minecraft:deepslate_tiles"},
        {pos: [17, 2, 7], state: "minecraft:deepslate_tiles"},
        {pos: [17, 2, 8], state: "minecraft:deepslate_tiles"},
        {pos: [17, 2, 9], state: "minecraft:white_candle{candles:3,lit:true,waterlogged:false}"},
        {pos: [17, 2, 15], state: "minecraft:cracked_deepslate_bricks"},
        {pos: [17, 2, 21], state: "minecraft:deepslate_bricks"},
        {pos: [17, 2, 36], state: "minecraft:deepslate_bricks"},
        {pos: [18, 2, 0], state: "minecraft:deepslate_bricks"},
        {pos: [18, 2, 4], state: "minecraft:deepslate_tiles"},
        {pos: [18, 2, 5], state: "minecraft:deepslate_tiles"},
        {pos: [18, 2, 6], state: "minecraft:deepslate_tiles"},
        {pos: [18, 2, 7], state: "minecraft:deepslate_tiles"},
        {pos: [18, 2, 15], state: "minecraft:cracked_deepslate_bricks"},
        {pos: [18, 2, 21], state: "minecraft:deepslate_bricks"},
        {pos: [18, 2, 36], state: "minecraft:deepslate_bricks"},
        {pos: [19, 2, 0], state: "minecraft:deepslate_bricks"},
        {pos: [19, 2, 4], state: "minecraft:deepslate_tile_stairs{facing:west,half:bottom,shape:straight,waterlogged:false}"},
        {pos: [19, 2, 5], state: "minecraft:deepslate_tile_stairs{facing:west,half:bottom,shape:straight,waterlogged:false}"},
        {pos: [19, 2, 6], state: "minecraft:deepslate_tile_stairs{facing:west,half:bottom,shape:straight,waterlogged:false}"},
        {pos: [19, 2, 15], state: "minecraft:deepslate_bricks"},
        {pos: [19, 2, 36], state: "minecraft:deepslate_bricks"},
        {pos: [20, 2, 0], state: "minecraft:cracked_deepslate_bricks"},
        {pos: [20, 2, 2], state: "minecraft:chiseled_deepslate"},
        {pos: [20, 2, 3], state: "minecraft:chiseled_deepslate"},
        {pos: [20, 2, 15], state: "minecraft:deepslate_bricks"},
        {pos: [20, 2, 21], state: "minecraft:deepslate_bricks"},
        {pos: [20, 2, 33], state: "minecraft:deepslate_bricks"},
        {pos: [21, 2, 2], state: "minecraft:chiseled_deepslate"},
        {pos: [21, 2, 3], state: "minecraft:chiseled_deepslate"},
        {pos: [21, 2, 15], state: "minecraft:cracked_deepslate_bricks"},
        {pos: [21, 2, 21], state: "minecraft:deepslate_bricks"},
        {pos: [21, 2, 33], state: "minecraft:deepslate_bricks"},
        {pos: [22, 2, 0], state: "minecraft:deepslate_bricks"},
        {pos: [22, 2, 15], state: "minecraft:cracked_deepslate_bricks"},
        {pos: [22, 2, 16], state: "minecraft:cracked_deepslate_bricks"},
        {pos: [22, 2, 17], state: "minecraft:deepslate_bricks"},
        {pos: [22, 2, 18], state: "minecraft:deepslate_bricks"},
        {pos: [22, 2, 19], state: "minecraft:deepslate_bricks"},
        {pos: [22, 2, 20], state: "minecraft:deepslate_bricks"},
        {pos: [22, 2, 21], state: "minecraft:deepslate_bricks"},
        {pos: [22, 2, 32], state: "minecraft:white_candle{candles:2,lit:true,waterlogged:false}"},
        {pos: [22, 2, 33], state: "minecraft:deepslate_bricks"},
        {pos: [23, 2, 10], state: "minecraft:deepslate_bricks"},
        {pos: [23, 2, 11], state: "minecraft:deepslate_bricks"},
        {pos: [23, 2, 23], state: "minecraft:deepslate_bricks"},
        {pos: [23, 2, 24], state: "minecraft:deepslate_bricks"},
        {pos: [23, 2, 25], state: "minecraft:deepslate_bricks"},
        {pos: [23, 2, 26], state: "minecraft:deepslate_bricks"},
        {pos: [23, 2, 27], state: "minecraft:deepslate_bricks"},
        {pos: [23, 2, 29], state: "minecraft:white_candle{candles:1,lit:true,waterlogged:false}"},
        {pos: [23, 2, 30], state: "minecraft:deepslate_bricks"},
        {pos: [23, 2, 31], state: "minecraft:deepslate_bricks"},
        {pos: [23, 2, 32], state: "minecraft:deepslate_bricks"},
        {pos: [23, 2, 33], state: "minecraft:deepslate_bricks"},
        {pos: [24, 2, 11], state: "minecraft:deepslate_bricks"},
        {pos: [25, 2, 2], state: "minecraft:chiseled_deepslate"},
        {pos: [25, 2, 3], state: "minecraft:chiseled_deepslate"},
        {pos: [25, 2, 8], state: "minecraft:deepslate_bricks"},
        {pos: [25, 2, 11], state: "minecraft:deepslate_bricks"},
        {pos: [26, 2, 2], state: "minecraft:chiseled_deepslate"},
        {pos: [26, 2, 3], state: "minecraft:chiseled_deepslate"},
        {pos: [26, 2, 8], state: "minecraft:deepslate_bricks"},
        {pos: [26, 2, 9], state: "minecraft:deepslate_bricks"},
        {pos: [26, 2, 10], state: "minecraft:deepslate_bricks"},
        {pos: [26, 2, 11], state: "minecraft:deepslate_bricks"},
        {pos: [27, 2, 15], state: "minecraft:chiseled_deepslate"},
        {pos: [27, 2, 16], state: "minecraft:chiseled_deepslate"},
        {pos: [27, 2, 27], state: "minecraft:deepslate_bricks"},
        {pos: [27, 2, 29], state: "minecraft:chiseled_deepslate"},
        {pos: [27, 2, 30], state: "minecraft:chiseled_deepslate"},
        {pos: [27, 2, 36], state: "minecraft:cracked_deepslate_bricks"},
        {pos: [28, 2, 4], state: "minecraft:deepslate_bricks"},
        {pos: [28, 2, 5], state: "minecraft:deepslate_bricks"},
        {pos: [28, 2, 6], state: "minecraft:deepslate_bricks"},
        {pos: [28, 2, 7], state: "minecraft:deepslate_bricks"},
        {pos: [28, 2, 8], state: "minecraft:deepslate_bricks"},
        {pos: [28, 2, 9], state: "minecraft:deepslate_bricks"},
        {pos: [28, 2, 10], state: "minecraft:deepslate_bricks"},
        {pos: [28, 2, 11], state: "minecraft:deepslate_bricks"},
        {pos: [28, 2, 12], state: "minecraft:deepslate_bricks"},
        {pos: [28, 2, 13], state: "minecraft:deepslate_bricks"},
        {pos: [28, 2, 14], state: "minecraft:deepslate_bricks"},
        {pos: [28, 2, 15], state: "minecraft:chiseled_deepslate"},
        {pos: [28, 2, 16], state: "minecraft:chiseled_deepslate"},
        {pos: [28, 2, 17], state: "minecraft:deepslate_bricks"},
        {pos: [28, 2, 26], state: "minecraft:deepslate_bricks"},
        {pos: [28, 2, 27], state: "minecraft:deepslate_bricks"},
        {pos: [28, 2, 28], state: "minecraft:deepslate_bricks"},
        {pos: [28, 2, 29], state: "minecraft:chiseled_deepslate"},
        {pos: [28, 2, 30], state: "minecraft:chiseled_deepslate"},
        {pos: [28, 2, 31], state: "minecraft:deepslate_bricks"},
        {pos: [28, 2, 35], state: "minecraft:deepslate_bricks"},
        {pos: [28, 2, 36], state: "minecraft:deepslate_bricks"},
        {pos: [0, 3, 14], state: "minecraft:deepslate_bricks"},
        {pos: [0, 3, 15], state: "minecraft:deepslate_tiles"},
        {pos: [0, 3, 16], state: "minecraft:deepslate_tiles"},
        {pos: [0, 3, 17], state: "minecraft:deepslate_bricks"},
        {pos: [0, 3, 18], state: "minecraft:deepslate_bricks"},
        {pos: [0, 3, 19], state: "minecraft:deepslate_bricks"},
        {pos: [0, 3, 26], state: "minecraft:deepslate_bricks"},
        {pos: [0, 3, 27], state: "minecraft:deepslate_bricks"},
        {pos: [1, 3, 15], state: "minecraft:cracked_deepslate_tiles"},
        {pos: [1, 3, 18], state: "minecraft:deepslate_bricks"},
        {pos: [1, 3, 19], state: "minecraft:deepslate_bricks"},
        {pos: [1, 3, 26], state: "minecraft:deepslate_bricks"},
        {pos: [1, 3, 27], state: "minecraft:deepslate_bricks"},
        {pos: [2, 3, 2], state: "minecraft:deepslate_tiles"},
        {pos: [3, 3, 2], state: "minecraft:cracked_deepslate_tiles"},
        {pos: [4, 3, 0], state: "minecraft:deepslate_bricks"},
        {pos: [5, 3, 0], state: "minecraft:deepslate_bricks"},
        {pos: [6, 3, 0], state: "minecraft:deepslate_bricks"},
        {pos: [6, 3, 16], state: "minecraft:deepslate_bricks"},
        {pos: [6, 3, 17], state: "minecraft:cracked_deepslate_bricks"},
        {pos: [6, 3, 20], state: "minecraft:cracked_deepslate_bricks"},
        {pos: [6, 3, 21], state: "minecraft:deepslate_bricks"},
        {pos: [6, 3, 24], state: "minecraft:deepslate_bricks"},
        {pos: [7, 3, 0], state: "minecraft:deepslate_bricks"},
        {pos: [7, 3, 16], state: "minecraft:cracked_deepslate_bricks"},
        {pos: [7, 3, 20], state: "minecraft:cracked_deepslate_bricks"},
        {pos: [7, 3, 24], state: "minecraft:deepslate_bricks"},
        {pos: [8, 3, 0], state: "minecraft:deepslate_bricks"},
        {pos: [8, 3, 2], state: "minecraft:cracked_deepslate_tiles"},
        {pos: [8, 3, 21], state: "minecraft:deepslate_bricks"},
        {pos: [8, 3, 24], state: "minecraft:cracked_deepslate_bricks"},
        {pos: [8, 3, 29], state: "minecraft:deepslate_bricks"},
        {pos: [9, 3, 0], state: "minecraft:deepslate_bricks"},
        {pos: [9, 3, 21], state: "minecraft:deepslate_bricks"},
        {pos: [9, 3, 24], state: "minecraft:deepslate_bricks"},
        {pos: [9, 3, 25], state: "minecraft:deepslate_bricks"},
        {pos: [9, 3, 26], state: "minecraft:deepslate_bricks"},
        {pos: [9, 3, 27], state: "minecraft:deepslate_bricks"},
        {pos: [9, 3, 28], state: "minecraft:deepslate_bricks"},
        {pos: [9, 3, 29], state: "minecraft:deepslate_bricks"},
        {pos: [10, 3, 0], state: "minecraft:deepslate_bricks"},
        {pos: [10, 3, 4], state: "minecraft:deepslate_tile_stairs{facing:east,half:bottom,shape:straight,waterlogged:false}"},
        {pos: [10, 3, 5], state: "minecraft:deepslate_tile_stairs{facing:east,half:bottom,shape:straight,waterlogged:false}"},
        {pos: [10, 3, 6], state: "minecraft:deepslate_tile_stairs{facing:east,half:bottom,shape:straight,waterlogged:false}"},
        {pos: [11, 3, 0], state: "minecraft:deepslate_bricks"},
        {pos: [11, 3, 4], state: "minecraft:deepslate_tiles"},
        {pos: [11, 3, 5], state: "minecraft:deepslate_tiles"},
        {pos: [11, 3, 6], state: "minecraft:deepslate_tiles"},
        {pos: [11, 3, 7], state: "minecraft:deepslate_tiles"},
        {pos: [11, 3, 21], state: "minecraft:deepslate_brick_slab{type:bottom,waterlogged:false}"},
        {pos: [12, 3, 0], state: "minecraft:deepslate_bricks"},
        {pos: [12, 3, 4], state: "minecraft:deepslate_tiles"},
        {pos: [12, 3, 5], state: "minecraft:deepslate_tiles"},
        {pos: [12, 3, 6], state: "minecraft:deepslate_tiles"},
        {pos: [12, 3, 7], state: "minecraft:deepslate_tiles"},
        {pos: [12, 3, 8], state: "minecraft:deepslate_tiles"},
        {pos: [12, 3, 16], state: "minecraft:cracked_deepslate_bricks"},
        {pos: [12, 3, 31], state: "minecraft:deepslate_bricks"},
        {pos: [12, 3, 32], state: "minecraft:deepslate_bricks"},
        {pos: [12, 3, 36], state: "minecraft:deepslate_bricks"},
        {pos: [13, 3, 0], state: "minecraft:deepslate_bricks"},
        {pos: [13, 3, 4], state: "minecraft:deepslate_tiles"},
        {pos: [13, 3, 5], state: "minecraft:deepslate_tiles"},
        {pos: [13, 3, 6], state: "minecraft:deepslate_tiles"},
        {pos: [13, 3, 7], state: "minecraft:deepslate_tiles"},
        {pos: [13, 3, 8], state: "minecraft:deepslate_tiles"},
        {pos: [13, 3, 16], state: "minecraft:cracked_deepslate_bricks"},
        {pos: [13, 3, 17], state: "minecraft:deepslate_bricks"},
        {pos: [13, 3, 18], state: "minecraft:deepslate_bricks"},
        {pos: [13, 3, 33], state: "minecraft:deepslate_bricks"},
        {pos: [13, 3, 36], state: "minecraft:deepslate_bricks"},
        {pos: [14, 3, 0], state: "minecraft:deepslate_bricks"},
        {pos: [14, 3, 4], state: "minecraft:deepslate_tiles"},
        {pos: [14, 3, 5], state: "minecraft:deepslate_tiles"},
        {pos: [14, 3, 6], state: "minecraft:deepslate_tiles"},
        {pos: [14, 3, 7], state: "minecraft:deepslate_tiles"},
        {pos: [14, 3, 8], state: "minecraft:deepslate_tiles"},
        {pos: [14, 3, 33], state: "minecraft:deepslate_bricks"},
        {pos: [14, 3, 36], state: "minecraft:deepslate_bricks"},
        {pos: [15, 3, 0], state: "minecraft:deepslate_bricks"},
        {pos: [15, 3, 4], state: "minecraft:deepslate_tiles"},
        {pos: [15, 3, 5], state: "minecraft:deepslate_tiles"},
        {pos: [15, 3, 6], state: "minecraft:deepslate_tiles"},
        {pos: [15, 3, 7], state: "minecraft:deepslate_tiles"},
        {pos: [15, 3, 8], state: "minecraft:deepslate_tiles"},
        {pos: [15, 3, 33], state: "minecraft:deepslate_bricks"},
        {pos: [15, 3, 36], state: "minecraft:deepslate_bricks"},
        {pos: [16, 3, 4], state: "minecraft:deepslate_tiles"},
        {pos: [16, 3, 5], state: "minecraft:deepslate_tiles"},
        {pos: [16, 3, 6], state: "minecraft:deepslate_tiles"},
        {pos: [16, 3, 7], state: "minecraft:deepslate_tiles"},
        {pos: [16, 3, 8], state: "minecraft:deepslate_tiles"},
        {pos: [16, 3, 33], state: "minecraft:deepslate_bricks"},
        {pos: [16, 3, 36], state: "minecraft:deepslate_bricks"},
        {pos: [17, 3, 0], state: "minecraft:cracked_deepslate_bricks"},
        {pos: [17, 3, 4], state: "minecraft:deepslate_tiles"},
        {pos: [17, 3, 5], state: "minecraft:deepslate_tiles"},
        {pos: [17, 3, 6], state: "minecraft:deepslate_tiles"},
        {pos: [17, 3, 7], state: "minecraft:deepslate_tiles"},
        {pos: [17, 3, 8], state: "minecraft:deepslate_tiles"},
        {pos: [17, 3, 21], state: "minecraft:deepslate_bricks"},
        {pos: [17, 3, 36], state: "minecraft:deepslate_bricks"},
