{
    size: [14, 24, 41],
    data: [
        {pos: [0, 0, 0], state: "minecraft:deepslate{axis:y}"},
        {pos: [0, 0, 1], state: "minecraft:deepslate{axis:y}"},
        {pos: [0, 0, 2], state: "minecraft:deepslate{axis:y}"},
        {pos: [0, 0, 3], state: "minecraft:deepslate{axis:y}"},
        {pos: [0, 0, 4], state: "minecraft:deepslate{axis:y}"},
        {pos: [0, 0, 5], state: "minecraft:deepslate{axis:y}"},
        {pos: [0, 0, 6], state: "minecraft:deepslate{axis:y}"},
        {pos: [0, 0, 7], state: "minecraft:deepslate{axis:y}"},
        {pos: [0, 0, 8], state: "minecraft:deepslate{axis:y}"},
        {pos: [0, 0, 9], state: "minecraft:deepslate{axis:y}"},
        {pos: [0, 0, 10], state: "minecraft:deepslate{axis:y}"},
        {pos: [0, 0, 11], state: "minecraft:deepslate{axis:y}"},
        {pos: [0, 0, 12], state: "minecraft:deepslate{axis:y}"},
        {pos: [0, 0, 13], state: "minecraft:deepslate{axis:y}"},
        {pos: [0, 0, 14], state: "minecraft:deepslate{axis:y}"},
        {pos: [0, 0, 15], state: "minecraft:deepslate{axis:y}"},
        {pos: [0, 0, 16], state: "minecraft:deepslate{axis:y}"},
        {pos: [0, 0, 17], state: "minecraft:deepslate{axis:y}"},
        {pos: [0, 0, 18], state: "minecraft:deepslate{axis:y}"},
        {pos: [0, 0, 19], state: "minecraft:deepslate{axis:y}"},
        {pos: [0, 0, 20], state: "minecraft:jigsaw{orientation:west_up}", nbt: {final_state: "minecraft:deepslate", id: "minecraft:jigsaw", joint: "rollable", name: "minecraft:empty", pool: "minecraft:ancient_city/city/entrance", target: "minecraft:entrance_start"}},
        {pos: [0, 0, 21], state: "minecraft:deepslate{axis:y}"},
        {pos: [0, 0, 22], state: "minecraft:deepslate{axis:y}"},
        {pos: [0, 0, 23], state: "minecraft:deepslate{axis:y}"},
        {pos: [0, 0, 24], state: "minecraft:deepslate{axis:y}"},
        {pos: [0, 0, 25], state: "minecraft:deepslate{axis:y}"},
        {pos: [0, 0, 26], state: "minecraft:deepslate{axis:y}"},
        {pos: [0, 0, 27], state: "minecraft:deepslate{axis:y}"},
        {pos: [0, 0, 28], state: "minecraft:deepslate{axis:y}"},
        {pos: [0, 0, 29], state: "minecraft:deepslate{axis:y}"},
        {pos: [0, 0, 30], state: "minecraft:deepslate{axis:y}"},
        {pos: [0, 0, 31], state: "minecraft:deepslate{axis:y}"},
        {pos: [0, 0, 32], state: "minecraft:deepslate{axis:y}"},
        {pos: [0, 0, 33], state: "minecraft:deepslate{axis:y}"},
        {pos: [0, 0, 34], state: "minecraft:deepslate{axis:y}"},
        {pos: [0, 0, 35], state: "minecraft:deepslate{axis:y}"},
        {pos: [0, 0, 36], state: "minecraft:deepslate{axis:y}"},
        {pos: [0, 0, 37], state: "minecraft:deepslate{axis:y}"},
        {pos: [0, 0, 38], state: "minecraft:deepslate{axis:y}"},
        {pos: [0, 0, 39], state: "minecraft:deepslate{axis:y}"},
        {pos: [0, 0, 40], state: "minecraft:deepslate{axis:y}"},
        {pos: [1, 0, 0], state: "minecraft:deepslate_bricks"},
        {pos: [1, 0, 1], state: "minecraft:deepslate_bricks"},
        {pos: [1, 0, 2], state: "minecraft:deepslate_bricks"},
        {pos: [1, 0, 3], state: "minecraft:deepslate_bricks"},
        {pos: [1, 0, 4], state: "minecraft:deepslate_bricks"},
        {pos: [1, 0, 5], state: "minecraft:deepslate_bricks"},
        {pos: [1, 0, 6], state: "minecraft:deepslate_bricks"},
        {pos: [1, 0, 7], state: "minecraft:deepslate_bricks"},
        {pos: [1, 0, 8], state: "minecraft:deepslate_bricks"},
        {pos: [1, 0, 9], state: "minecraft:deepslate_bricks"},
        {pos: [1, 0, 10], state: "minecraft:deepslate_bricks"},
        {pos: [1, 0, 11], state: "minecraft:deepslate_bricks"},
        {pos: [1, 0, 12], state: "minecraft:deepslate_bricks"},
        {pos: [1, 0, 13], state: "minecraft:deepslate_bricks"},
        {pos: [1, 0, 14], state: "minecraft:deepslate_bricks"},
        {pos: [1, 0, 15], state: "minecraft:deepslate_bricks"},
        {pos: [1, 0, 16], state: "minecraft:deepslate_bricks"},
        {pos: [1, 0, 17], state: "minecraft:deepslate_bricks"},
        {pos: [1, 0, 18], state: "minecraft:deepslate_bricks"},
        {pos: [1, 0, 19], state: "minecraft:deepslate_bricks"},
        {pos: [1, 0, 20], state: "minecraft:deepslate_bricks"},
        {pos: [1, 0, 21], state: "minecraft:deepslate_bricks"},
        {pos: [1, 0, 22], state: "minecraft:deepslate_bricks"},
        {pos: [1, 0, 23], state: "minecraft:deepslate_bricks"},
        {pos: [1, 0, 24], state: "minecraft:deepslate_bricks"},
        {pos: [1, 0, 25], state: "minecraft:deepslate_bricks"},
        {pos: [1, 0, 26], state: "minecraft:deepslate_bricks"},
        {pos: [1, 0, 27], state: "minecraft:deepslate_bricks"},
        {pos: [1, 0, 28], state: "minecraft:deepslate_bricks"},
        {pos: [1, 0, 29], state: "minecraft:deepslate_bricks"},
        {pos: [1, 0, 30], state: "minecraft:deepslate_bricks"},
        {pos: [1, 0, 31], state: "minecraft:deepslate_bricks"},
        {pos: [1, 0, 32], state: "minecraft:deepslate_bricks"},
        {pos: [1, 0, 33], state: "minecraft:deepslate_bricks"},
        {pos: [1, 0, 34], state: "minecraft:deepslate_bricks"},
        {pos: [1, 0, 35], state: "minecraft:deepslate_bricks"},
        {pos: [1, 0, 36], state: "minecraft:deepslate_bricks"},
        {pos: [1, 0, 37], state: "minecraft:deepslate_bricks"},
        {pos: [1, 0, 38], state: "minecraft:deepslate_bricks"},
        {pos: [1, 0, 39], state: "minecraft:deepslate_bricks"},
        {pos: [1, 0, 40], state: "minecraft:deepslate_bricks"},
        {pos: [2, 0, 0], state: "minecraft:deepslate_bricks"},
        {pos: [2, 0, 1], state: "minecraft:deepslate_bricks"},
        {pos: [2, 0, 2], state: "minecraft:deepslate_bricks"},
        {pos: [2, 0, 3], state: "minecraft:deepslate_bricks"},
        {pos: [2, 0, 4], state: "minecraft:deepslate_bricks"},
        {pos: [2, 0, 5], state: "minecraft:deepslate_bricks"},
        {pos: [2, 0, 6], state: "minecraft:deepslate_bricks"},
        {pos: [2, 0, 7], state: "minecraft:deepslate_bricks"},
        {pos: [2, 0, 8], state: "minecraft:deepslate_bricks"},
        {pos: [2, 0, 9], state: "minecraft:deepslate_bricks"},
        {pos: [2, 0, 10], state: "minecraft:deepslate_bricks"},
        {pos: [2, 0, 11], state: "minecraft:deepslate_bricks"},
        {pos: [2, 0, 12], state: "minecraft:deepslate_bricks"},
        {pos: [2, 0, 13], state: "minecraft:deepslate_bricks"},
        {pos: [2, 0, 14], state: "minecraft:deepslate_bricks"},
        {pos: [2, 0, 15], state: "minecraft:deepslate_bricks"},
        {pos: [2, 0, 16], state: "minecraft:deepslate_bricks"},
        {pos: [2, 0, 17], state: "minecraft:deepslate_bricks"},
        {pos: [2, 0, 18], state: "minecraft:deepslate_bricks"},
        {pos: [2, 0, 19], state: "minecraft:deepslate_bricks"},
        {pos: [2, 0, 20], state: "minecraft:deepslate_bricks"},
        {pos: [2, 0, 21], state: "minecraft:deepslate_bricks"},
        {pos: [2, 0, 22], state: "minecraft:deepslate_bricks"},
        {pos: [2, 0, 23], state: "minecraft:deepslate_bricks"},
        {pos: [2, 0, 24], state: "minecraft:deepslate_bricks"},
        {pos: [2, 0, 25], state: "minecraft:deepslate_bricks"},
        {pos: [2, 0, 26], state: "minecraft:deepslate_bricks"},
        {pos: [2, 0, 27], state: "minecraft:deepslate_bricks"},
        {pos: [2, 0, 28], state: "minecraft:deepslate_bricks"},
        {pos: [2, 0, 29], state: "minecraft:deepslate_bricks"},
        {pos: [2, 0, 30], state: "minecraft:deepslate_bricks"},
        {pos: [2, 0, 31], state: "minecraft:deepslate_bricks"},
        {pos: [2, 0, 32], state: "minecraft:deepslate_bricks"},
        {pos: [2, 0, 33], state: "minecraft:deepslate_bricks"},
        {pos: [2, 0, 34], state: "minecraft:deepslate_bricks"},
        {pos: [2, 0, 35], state: "minecraft:deepslate_bricks"},
        {pos: [2, 0, 36], state: "minecraft:deepslate_bricks"},
        {pos: [2, 0, 37], state: "minecraft:deepslate_bricks"},
        {pos: [2, 0, 38], state: "minecraft:deepslate_bricks"},
        {pos: [2, 0, 39], state: "minecraft:deepslate_bricks"},
        {pos: [2, 0, 40], state: "minecraft:deepslate_bricks"},
        {pos: [3, 0, 0], state: "minecraft:deepslate_bricks"},
        {pos: [3, 0, 1], state: "minecraft:deepslate_bricks"},
        {pos: [3, 0, 2], state: "minecraft:deepslate_bricks"},
        {pos: [3, 0, 3], state: "minecraft:deepslate_bricks"},
        {pos: [3, 0, 4], state: "minecraft:deepslate_bricks"},
        {pos: [3, 0, 5], state: "minecraft:deepslate_bricks"},
        {pos: [3, 0, 6], state: "minecraft:deepslate_bricks"},
        {pos: [3, 0, 7], state: "minecraft:deepslate_bricks"},
        {pos: [3, 0, 8], state: "minecraft:deepslate_bricks"},
        {pos: [3, 0, 9], state: "minecraft:deepslate_bricks"},
        {pos: [3, 0, 10], state: "minecraft:deepslate_bricks"},
        {pos: [3, 0, 11], state: "minecraft:deepslate_bricks"},
        {pos: [3, 0, 12], state: "minecraft:deepslate_bricks"},
        {pos: [3, 0, 13], state: "minecraft:deepslate_bricks"},
        {pos: [3, 0, 14], state: "minecraft:deepslate_bricks"},
        {pos: [3, 0, 15], state: "minecraft:deepslate_bricks"},
        {pos: [3, 0, 16], state: "minecraft:deepslate_bricks"},
        {pos: [3, 0, 17], state: "minecraft:deepslate_bricks"},
        {pos: [3, 0, 18], state: "minecraft:deepslate_bricks"},
        {pos: [3, 0, 19], state: "minecraft:deepslate_bricks"},
        {pos: [3, 0, 20], state: "minecraft:deepslate_bricks"},
        {pos: [3, 0, 21], state: "minecraft:deepslate_bricks"},
        {pos: [3, 0, 22], state: "minecraft:deepslate_bricks"},
        {pos: [3, 0, 23], state: "minecraft:deepslate_bricks"},
        {pos: [3, 0, 24], state: "minecraft:deepslate_bricks"},
        {pos: [3, 0, 25], state: "minecraft:deepslate_bricks"},
        {pos: [3, 0, 26], state: "minecraft:deepslate_bricks"},
        {pos: [3, 0, 27], state: "minecraft:deepslate_bricks"},
        {pos: [3, 0, 28], state: "minecraft:deepslate_bricks"},
        {pos: [3, 0, 29], state: "minecraft:deepslate_bricks"},
        {pos: [3, 0, 30], state: "minecraft:deepslate_bricks"},
        {pos: [3, 0, 31], state: "minecraft:deepslate_bricks"},
        {pos: [3, 0, 32], state: "minecraft:deepslate_bricks"},
        {pos: [3, 0, 33], state: "minecraft:deepslate_bricks"},
        {pos: [3, 0, 34], state: "minecraft:deepslate_bricks"},
        {pos: [3, 0, 35], state: "minecraft:deepslate_bricks"},
        {pos: [3, 0, 36], state: "minecraft:deepslate_bricks"},
        {pos: [3, 0, 37], state: "minecraft:deepslate_bricks"},
        {pos: [3, 0, 38], state: "minecraft:deepslate_bricks"},
        {pos: [3, 0, 39], state: "minecraft:deepslate_bricks"},
        {pos: [3, 0, 40], state: "minecraft:deepslate_bricks"},
        {pos: [4, 0, 0], state: "minecraft:deepslate_bricks"},
        {pos: [4, 0, 1], state: "minecraft:deepslate_bricks"},
        {pos: [4, 0, 2], state: "minecraft:deepslate_bricks"},
        {pos: [4, 0, 3], state: "minecraft:deepslate_bricks"},
        {pos: [4, 0, 4], state: "minecraft:deepslate_bricks"},
        {pos: [4, 0, 5], state: "minecraft:deepslate_bricks"},
        {pos: [4, 0, 6], state: "minecraft:deepslate_bricks"},
        {pos: [4, 0, 7], state: "minecraft:deepslate_bricks"},
        {pos: [4, 0, 8], state: "minecraft:deepslate_bricks"},
        {pos: [4, 0, 9], state: "minecraft:deepslate_bricks"},
        {pos: [4, 0, 10], state: "minecraft:deepslate_bricks"},
        {pos: [4, 0, 11], state: "minecraft:deepslate_bricks"},
        {pos: [4, 0, 12], state: "minecraft:deepslate_bricks"},
        {pos: [4, 0, 13], state: "minecraft:deepslate_bricks"},
        {pos: [4, 0, 14], state: "minecraft:deepslate_bricks"},
        {pos: [4, 0, 15], state: "minecraft:deepslate_bricks"},
        {pos: [4, 0, 16], state: "minecraft:deepslate_bricks"},
        {pos: [4, 0, 17], state: "minecraft:deepslate_bricks"},
        {pos: [4, 0, 18], state: "minecraft:deepslate_bricks"},
        {pos: [4, 0, 19], state: "minecraft:deepslate_bricks"},
        {pos: [4, 0, 20], state: "minecraft:deepslate_bricks"},
        {pos: [4, 0, 21], state: "minecraft:deepslate_bricks"},
        {pos: [4, 0, 22], state: "minecraft:deepslate_bricks"},
        {pos: [4, 0, 23], state: "minecraft:deepslate_bricks"},
        {pos: [4, 0, 24], state: "minecraft:deepslate_bricks"},
        {pos: [4, 0, 25], state: "minecraft:deepslate_bricks"},
        {pos: [4, 0, 26], state: "minecraft:deepslate_bricks"},
        {pos: [4, 0, 27], state: "minecraft:deepslate_bricks"},
        {pos: [4, 0, 28], state: "minecraft:deepslate_bricks"},
        {pos: [4, 0, 29], state: "minecraft:deepslate_bricks"},
        {pos: [4, 0, 30], state: "minecraft:deepslate_bricks"},
        {pos: [4, 0, 31], state: "minecraft:deepslate_bricks"},
        {pos: [4, 0, 32], state: "minecraft:deepslate_bricks"},
        {pos: [4, 0, 33], state: "minecraft:deepslate_bricks"},
        {pos: [4, 0, 34], state: "minecraft:deepslate_bricks"},
        {pos: [4, 0, 35], state: "minecraft:deepslate_bricks"},
        {pos: [4, 0, 36], state: "minecraft:deepslate_bricks"},
        {pos: [4, 0, 37], state: "minecraft:deepslate_bricks"},
        {pos: [4, 0, 38], state: "minecraft:deepslate_bricks"},
        {pos: [4, 0, 39], state: "minecraft:deepslate_bricks"},
        {pos: [4, 0, 40], state: "minecraft:deepslate_bricks"},
        {pos: [5, 0, 0], state: "minecraft:deepslate_bricks"},
        {pos: [5, 0, 1], state: "minecraft:deepslate_bricks"},
        {pos: [5, 0, 2], state: "minecraft:deepslate_bricks"},
        {pos: [5, 0, 3], state: "minecraft:deepslate_bricks"},
        {pos: [5, 0, 4], state: "minecraft:deepslate_bricks"},
        {pos: [5, 0, 5], state: "minecraft:deepslate_bricks"},
        {pos: [5, 0, 6], state: "minecraft:deepslate_bricks"},
        {pos: [5, 0, 7], state: "minecraft:deepslate_bricks"},
        {pos: [5, 0, 8], state: "minecraft:deepslate_bricks"},
        {pos: [5, 0, 9], state: "minecraft:deepslate_bricks"},
        {pos: [5, 0, 10], state: "minecraft:deepslate_bricks"},
        {pos: [5, 0, 11], state: "minecraft:deepslate_bricks"},
        {pos: [5, 0, 12], state: "minecraft:deepslate{axis:y}"},
        {pos: [5, 0, 13], state: "minecraft:deepslate{axis:y}"},
        {pos: [5, 0, 14], state: "minecraft:deepslate{axis:y}"},
        {pos: [5, 0, 15], state: "minecraft:deepslate_bricks"},
        {pos: [5, 0, 16], state: "minecraft:deepslate_bricks"},
        {pos: [5, 0, 17], state: "minecraft:deepslate_bricks"},
        {pos: [5, 0, 18], state: "minecraft:deepslate_bricks"},
        {pos: [5, 0, 19], state: "minecraft:deepslate_bricks"},
        {pos: [5, 0, 20], state: "minecraft:deepslate{axis:y}"},
        {pos: [5, 0, 21], state: "minecraft:deepslate{axis:y}"},
        {pos: [5, 0, 22], state: "minecraft:deepslate{axis:y}"},
        {pos: [5, 0, 23], state: "minecraft:deepslate_bricks"},
        {pos: [5, 0, 24], state: "minecraft:deepslate_bricks"},
        {pos: [5, 0, 25], state: "minecraft:deepslate_bricks"},
        {pos: [5, 0, 26], state: "minecraft:deepslate{axis:y}"},
        {pos: [5, 0, 27], state: "minecraft:deepslate{axis:y}"},
        {pos: [5, 0, 28], state: "minecraft:deepslate_bricks"},
        {pos: [5, 0, 29], state: "minecraft:deepslate_bricks"},
        {pos: [5, 0, 30], state: "minecraft:deepslate_bricks"},
        {pos: [5, 0, 31], state: "minecraft:deepslate_bricks"},
        {pos: [5, 0, 32], state: "minecraft:deepslate{axis:y}"},
        {pos: [5, 0, 33], state: "minecraft:deepslate{axis:y}"},
        {pos: [5, 0, 34], state: "minecraft:deepslate_bricks"},
        {pos: [5, 0, 35], state: "minecraft:deepslate_bricks"},
        {pos: [5, 0, 36], state: "minecraft:deepslate_bricks"},
        {pos: [5, 0, 37], state: "minecraft:deepslate_bricks"},
        {pos: [5, 0, 38], state: "minecraft:deepslate_bricks"},
        {pos: [5, 0, 39], state: "minecraft:deepslate_bricks"},
        {pos: [5, 0, 40], state: "minecraft:deepslate_bricks"},
        {pos: [6, 0, 0], state: "minecraft:deepslate{axis:y}"},
        {pos: [6, 0, 1], state: "minecraft:deepslate{axis:y}"},
        {pos: [6, 0, 2], state: "minecraft:deepslate_bricks"},
        {pos: [6, 0, 3], state: "minecraft:deepslate{axis:y}"},
        {pos: [6, 0, 4], state: "minecraft:deepslate_bricks"},
        {pos: [6, 0, 5], state: "minecraft:deepslate_bricks"},
        {pos: [6, 0, 6], state: "minecraft:deepslate_bricks"},
        {pos: [6, 0, 7], state: "minecraft:deepslate{axis:y}"},
        {pos: [6, 0, 8], state: "minecraft:deepslate{axis:y}"},
        {pos: [6, 0, 9], state: "minecraft:deepslate{axis:y}"},
        {pos: [6, 0, 10], state: "minecraft:deepslate_bricks"},
        {pos: [6, 0, 11], state: "minecraft:deepslate{axis:y}"},
        {pos: [6, 0, 12], state: "minecraft:deepslate{axis:y}"},
        {pos: [6, 0, 13], state: "minecraft:deepslate{axis:y}"},
        {pos: [6, 0, 14], state: "minecraft:deepslate{axis:y}"},
        {pos: [6, 0, 15], state: "minecraft:deepslate{axis:y}"},
        {pos: [6, 0, 16], state: "minecraft:deepslate{axis:y}"},
        {pos: [6, 0, 17], state: "minecraft:deepslate_bricks"},
        {pos: [6, 0, 18], state: "minecraft:deepslate_bricks"},
        {pos: [6, 0, 19], state: "minecraft:deepslate_bricks"},
        {pos: [6, 0, 20], state: "minecraft:deepslate{axis:y}"},
        {pos: [6, 0, 21], state: "minecraft:deepslate{axis:y}"},
        {pos: [6, 0, 22], state: "minecraft:deepslate{axis:y}"},
        {pos: [6, 0, 23], state: "minecraft:deepslate{axis:y}"},
        {pos: [6, 0, 24], state: "minecraft:deepslate_bricks"},
        {pos: [6, 0, 25], state: "minecraft:deepslate_bricks"},
        {pos: [6, 0, 26], state: "minecraft:deepslate_bricks"},
        {pos: [6, 0, 27], state: "minecraft:deepslate{axis:y}"},
        {pos: [6, 0, 28], state: "minecraft:deepslate_bricks"},
        {pos: [6, 0, 29], state: "minecraft:deepslate{axis:y}"},
        {pos: [6, 0, 30], state: "minecraft:deepslate{axis:y}"},
        {pos: [6, 0, 31], state: "minecraft:deepslate_bricks"},
        {pos: [6, 0, 32], state: "minecraft:deepslate_bricks"},
        {pos: [6, 0, 33], state: "minecraft:deepslate_bricks"},
        {pos: [6, 0, 34], state: "minecraft:deepslate_bricks"},
        {pos: [6, 0, 35], state: "minecraft:deepslate_bricks"},
        {pos: [6, 0, 36], state: "minecraft:deepslate_bricks"},
        {pos: [6, 0, 37], state: "minecraft:deepslate{axis:y}"},
        {pos: [6, 0, 38], state: "minecraft:deepslate{axis:y}"},
        {pos: [6, 0, 39], state: "minecraft:deepslate_bricks"},
        {pos: [6, 0, 40], state: "minecraft:deepslate_bricks"},
        {pos: [7, 0, 0], state: "minecraft:jigsaw{orientation:north_up}", nbt: {final_state: "minecraft:deepslate_bricks", id: "minecraft:jigsaw", joint: "rollable", name: "minecraft:empty", pool: "minecraft:ancient_city/city_center/walls", target: "minecraft:connect_bottom_left_corner"}},
        {pos: [7, 0, 1], state: "minecraft:deepslate{axis:y}"},
        {pos: [7, 0, 2], state: "minecraft:deepslate_bricks"},
        {pos: [7, 0, 3], state: "minecraft:deepslate_bricks"},
        {pos: [7, 0, 4], state: "minecraft:deepslate_bricks"},
        {pos: [7, 0, 5], state: "minecraft:deepslate{axis:y}"},
        {pos: [7, 0, 6], state: "minecraft:deepslate_bricks"},
        {pos: [7, 0, 7], state: "minecraft:deepslate_bricks"},
        {pos: [7, 0, 8], state: "minecraft:deepslate{axis:y}"},
        {pos: [7, 0, 9], state: "minecraft:deepslate{axis:y}"},
        {pos: [7, 0, 10], state: "minecraft:deepslate_bricks"},
        {pos: [7, 0, 11], state: "minecraft:deepslate{axis:y}"},
        {pos: [7, 0, 12], state: "minecraft:deepslate{axis:y}"},
        {pos: [7, 0, 13], state: "minecraft:deepslate{axis:y}"},
        {pos: [7, 0, 14], state: "minecraft:deepslate{axis:y}"},
        {pos: [7, 0, 15], state: "minecraft:deepslate{axis:y}"},
        {pos: [7, 0, 16], state: "minecraft:deepslate_bricks"},
        {pos: [7, 0, 17], state: "minecraft:deepslate_bricks"},
        {pos: [7, 0, 18], state: "minecraft:deepslate{axis:y}"},
        {pos: [7, 0, 19], state: "minecraft:deepslate_bricks"},
        {pos: [7, 0, 20], state: "minecraft:deepslate{axis:y}"},
        {pos: [7, 0, 21], state: "minecraft:deepslate{axis:y}"},
        {pos: [7, 0, 22], state: "minecraft:deepslate{axis:y}"},
        {pos: [7, 0, 23], state: "minecraft:deepslate{axis:y}"},
        {pos: [7, 0, 24], state: "minecraft:deepslate{axis:y}"},
        {pos: [7, 0, 25], state: "minecraft:deepslate_bricks"},
        {pos: [7, 0, 26], state: "minecraft:deepslate{axis:y}"},
        {pos: [7, 0, 27], state: "minecraft:deepslate{axis:y}"},
        {pos: [7, 0, 28], state: "minecraft:deepslate{axis:y}"},
        {pos: [7, 0, 29], state: "minecraft:deepslate{axis:y}"},
        {pos: [7, 0, 30], state: "minecraft:deepslate{axis:y}"},
        {pos: [7, 0, 31], state: "minecraft:deepslate{axis:y}"},
        {pos: [7, 0, 32], state: "minecraft:deepslate_bricks"},
        {pos: [7, 0, 33], state: "minecraft:deepslate_bricks"},
        {pos: [7, 0, 34], state: "minecraft:deepslate{axis:y}"},
        {pos: [7, 0, 35], state: "minecraft:deepslate{axis:y}"},
        {pos: [7, 0, 36], state: "minecraft:deepslate{axis:y}"},
        {pos: [7, 0, 37], state: "minecraft:deepslate{axis:y}"},
        {pos: [7, 0, 38], state: "minecraft:deepslate_bricks"},
        {pos: [7, 0, 39], state: "minecraft:deepslate_bricks"},
        {pos: [7, 0, 40], state: "minecraft:jigsaw{orientation:south_up}", nbt: {final_state: "minecraft:deepslate_bricks", id: "minecraft:jigsaw", joint: "rollable", name: "minecraft:empty", pool: "minecraft:ancient_city/city_center/walls", target: "minecraft:connect_bottom_right_corner"}},
        {pos: [8, 0, 0], state: "minecraft:deepslate_bricks"},
        {pos: [8, 0, 1], state: "minecraft:deepslate_bricks"},
        {pos: [8, 0, 2], state: "minecraft:deepslate{axis:y}"},
        {pos: [8, 0, 3], state: "minecraft:deepslate{axis:y}"},
        {pos: [8, 0, 4], state: "minecraft:deepslate_bricks"},
        {pos: [8, 0, 5], state: "minecraft:deepslate_bricks"},
        {pos: [8, 0, 6], state: "minecraft:deepslate{axis:y}"},
        {pos: [8, 0, 7], state: "minecraft:deepslate_bricks"},
        {pos: [8, 0, 8], state: "minecraft:deepslate_bricks"},
        {pos: [8, 0, 9], state: "minecraft:deepslate_bricks"},
        {pos: [8, 0, 10], state: "minecraft:deepslate_bricks"},
        {pos: [8, 0, 11], state: "minecraft:deepslate_bricks"},
        {pos: [8, 0, 12], state: "minecraft:deepslate{axis:y}"},
        {pos: [8, 0, 13], state: "minecraft:deepslate{axis:y}"},
        {pos: [8, 0, 14], state: "minecraft:deepslate_bricks"},
        {pos: [8, 0, 15], state: "minecraft:deepslate_bricks"},
        {pos: [8, 0, 16], state: "minecraft:deepslate_bricks"},
        {pos: [8, 0, 17], state: "minecraft:deepslate{axis:y}"},
        {pos: [8, 0, 18], state: "minecraft:deepslate{axis:y}"},
        {pos: [8, 0, 19], state: "minecraft:deepslate_bricks"},
        {pos: [8, 0, 20], state: "minecraft:deepslate_bricks"},
        {pos: [8, 0, 21], state: "minecraft:deepslate{axis:y}"},
        {pos: [8, 0, 22], state: "minecraft:deepslate{axis:y}"},
        {pos: [8, 0, 23], state: "minecraft:deepslate_bricks"},
        {pos: [8, 0, 24], state: "minecraft:deepslate_bricks"},
        {pos: [8, 0, 25], state: "minecraft:deepslate_bricks"},
        {pos: [8, 0, 26], state: "minecraft:deepslate{axis:y}"},
        {pos: [8, 0, 27], state: "minecraft:deepslate{axis:y}"},
        {pos: [8, 0, 28], state: "minecraft:deepslate{axis:y}"},
        {pos: [8, 0, 29], state: "minecraft:deepslate{axis:y}"},
        {pos: [8, 0, 30], state: "minecraft:deepslate{axis:y}"},
        {pos: [8, 0, 31], state: "minecraft:deepslate_bricks"},
        {pos: [8, 0, 32], state: "minecraft:deepslate_bricks"},
        {pos: [8, 0, 33], state: "minecraft:deepslate_bricks"},
        {pos: [8, 0, 34], state: "minecraft:deepslate_bricks"},
        {pos: [8, 0, 35], state: "minecraft:deepslate{axis:y}"},
        {pos: [8, 0, 36], state: "minecraft:deepslate{axis:y}"},
        {pos: [8, 0, 37], state: "minecraft:deepslate_bricks"},
        {pos: [8, 0, 38], state: "minecraft:deepslate_bricks"},
        {pos: [8, 0, 39], state: "minecraft:deepslate_bricks"},
        {pos: [8, 0, 40], state: "minecraft:deepslate_bricks"},
        {pos: [9, 0, 0], state: "minecraft:deepslate_bricks"},
        {pos: [9, 0, 1], state: "minecraft:deepslate_bricks"},
        {pos: [9, 0, 2], state: "minecraft:deepslate_bricks"},
        {pos: [9, 0, 3], state: "minecraft:deepslate_bricks"},
        {pos: [9, 0, 4], state: "minecraft:deepslate_bricks"},
        {pos: [9, 0, 5], state: "minecraft:deepslate_bricks"},
        {pos: [9, 0, 6], state: "minecraft:deepslate_bricks"},
        {pos: [9, 0, 7], state: "minecraft:deepslate_bricks"},
        {pos: [9, 0, 8], state: "minecraft:deepslate_bricks"},
        {pos: [9, 0, 9], state: "minecraft:deepslate_bricks"},
        {pos: [9, 0, 10], state: "minecraft:deepslate_bricks"},
        {pos: [9, 0, 11], state: "minecraft:deepslate_bricks"},
        {pos: [9, 0, 12], state: "minecraft:deepslate_bricks"},
        {pos: [9, 0, 13], state: "minecraft:deepslate_bricks"},
        {pos: [9, 0, 14], state: "minecraft:deepslate_bricks"},
        {pos: [9, 0, 15], state: "minecraft:deepslate_bricks"},
        {pos: [9, 0, 16], state: "minecraft:deepslate_bricks"},
        {pos: [9, 0, 17], state: "minecraft:deepslate_bricks"},
        {pos: [9, 0, 18], state: "minecraft:deepslate_bricks"},
        {pos: [9, 0, 19], state: "minecraft:deepslate_bricks"},
        {pos: [9, 0, 20], state: "minecraft:deepslate_bricks"},
        {pos: [9, 0, 21], state: "minecraft:deepslate_bricks"},
        {pos: [9, 0, 22], state: "minecraft:deepslate_bricks"},
        {pos: [9, 0, 23], state: "minecraft:deepslate_bricks"},
        {pos: [9, 0, 24], state: "minecraft:deepslate_bricks"},
        {pos: [9, 0, 25], state: "minecraft:deepslate_bricks"},
        {pos: [9, 0, 26], state: "minecraft:deepslate_bricks"},
        {pos: [9, 0, 27], state: "minecraft:deepslate_bricks"},
        {pos: [9, 0, 28], state: "minecraft:deepslate_bricks"},
        {pos: [9, 0, 29], state: "minecraft:deepslate_bricks"},
        {pos: [9, 0, 30], state: "minecraft:deepslate_bricks"},
        {pos: [9, 0, 31], state: "minecraft:deepslate_bricks"},
        {pos: [9, 0, 32], state: "minecraft:deepslate_bricks"},
        {pos: [9, 0, 33], state: "minecraft:deepslate_bricks"},
        {pos: [9, 0, 34], state: "minecraft:deepslate_bricks"},
        {pos: [9, 0, 35], state: "minecraft:deepslate_bricks"},
        {pos: [9, 0, 36], state: "minecraft:deepslate_bricks"},
        {pos: [9, 0, 37], state: "minecraft:deepslate_bricks"},
        {pos: [9, 0, 38], state: "minecraft:deepslate_bricks"},
        {pos: [9, 0, 39], state: "minecraft:deepslate_bricks"},
        {pos: [9, 0, 40], state: "minecraft:deepslate_bricks"},
        {pos: [10, 0, 0], state: "minecraft:deepslate_bricks"},
        {pos: [10, 0, 1], state: "minecraft:deepslate_bricks"},
        {pos: [10, 0, 2], state: "minecraft:deepslate_bricks"},
        {pos: [10, 0, 3], state: "minecraft:deepslate_bricks"},
        {pos: [10, 0, 4], state: "minecraft:deepslate_bricks"},
        {pos: [10, 0, 5], state: "minecraft:deepslate_bricks"},
        {pos: [10, 0, 6], state: "minecraft:deepslate_bricks"},
        {pos: [10, 0, 7], state: "minecraft:deepslate_bricks"},
        {pos: [10, 0, 8], state: "minecraft:deepslate_bricks"},
        {pos: [10, 0, 9], state: "minecraft:deepslate_bricks"},
        {pos: [10, 0, 10], state: "minecraft:deepslate_bricks"},
        {pos: [10, 0, 11], state: "minecraft:deepslate_bricks"},
        {pos: [10, 0, 12], state: "minecraft:deepslate_bricks"},
        {pos: [10, 0, 13], state: "minecraft:deepslate_bricks"},
        {pos: [10, 0, 14], state: "minecraft:deepslate_bricks"},
        {pos: [10, 0, 15], state: "minecraft:deepslate_bricks"},
        {pos: [10, 0, 16], state: "minecraft:deepslate_bricks"},
        {pos: [10, 0, 17], state: "minecraft:deepslate_bricks"},
        {pos: [10, 0, 18], state: "minecraft:deepslate_bricks"},
        {pos: [10, 0, 19], state: "minecraft:deepslate_bricks"},
        {pos: [10, 0, 20], state: "minecraft:deepslate_bricks"},
        {pos: [10, 0, 21], state: "minecraft:deepslate_bricks"},
        {pos: [10, 0, 22], state: "minecraft:deepslate_bricks"},
        {pos: [10, 0, 23], state: "minecraft:deepslate_bricks"},
        {pos: [10, 0, 24], state: "minecraft:deepslate_bricks"},
        {pos: [10, 0, 25], state: "minecraft:deepslate_bricks"},
        {pos: [10, 0, 26], state: "minecraft:deepslate_bricks"},
        {pos: [10, 0, 27], state: "minecraft:deepslate_bricks"},
        {pos: [10, 0, 28], state: "minecraft:deepslate_bricks"},
        {pos: [10, 0, 29], state: "minecraft:deepslate_bricks"},
        {pos: [10, 0, 30], state: "minecraft:deepslate_bricks"},
        {pos: [10, 0, 31], state: "minecraft:deepslate_bricks"},
        {pos: [10, 0, 32], state: "minecraft:deepslate_bricks"},
        {pos: [10, 0, 33], state: "minecraft:deepslate_bricks"},
        {pos: [10, 0, 34], state: "minecraft:deepslate_bricks"},
        {pos: [10, 0, 35], state: "minecraft:deepslate_bricks"},
        {pos: [10, 0, 36], state: "minecraft:deepslate_bricks"},
        {pos: [10, 0, 37], state: "minecraft:deepslate_bricks"},
        {pos: [10, 0, 38], state: "minecraft:deepslate_bricks"},
        {pos: [10, 0, 39], state: "minecraft:deepslate_bricks"},
        {pos: [10, 0, 40], state: "minecraft:deepslate_bricks"},
        {pos: [11, 0, 0], state: "minecraft:deepslate_bricks"},
        {pos: [11, 0, 1], state: "minecraft:deepslate_bricks"},
        {pos: [11, 0, 2], state: "minecraft:deepslate_bricks"},
        {pos: [11, 0, 3], state: "minecraft:deepslate_bricks"},
        {pos: [11, 0, 4], state: "minecraft:deepslate_bricks"},
        {pos: [11, 0, 5], state: "minecraft:deepslate_bricks"},
        {pos: [11, 0, 6], state: "minecraft:deepslate_bricks"},
        {pos: [11, 0, 7], state: "minecraft:deepslate_bricks"},
        {pos: [11, 0, 8], state: "minecraft:deepslate_bricks"},
        {pos: [11, 0, 9], state: "minecraft:deepslate_bricks"},
        {pos: [11, 0, 10], state: "minecraft:deepslate_bricks"},
        {pos: [11, 0, 11], state: "minecraft:deepslate_bricks"},
        {pos: [11, 0, 12], state: "minecraft:deepslate_bricks"},
        {pos: [11, 0, 13], state: "minecraft:deepslate_bricks"},
        {pos: [11, 0, 14], state: "minecraft:deepslate_bricks"},
        {pos: [11, 0, 15], state: "minecraft:deepslate_bricks"},
        {pos: [11, 0, 16], state: "minecraft:deepslate_bricks"},
        {pos: [11, 0, 17], state: "minecraft:deepslate_bricks"},
        {pos: [11, 0, 18], state: "minecraft:deepslate_bricks"},
        {pos: [11, 0, 19], state: "minecraft:deepslate_bricks"},
        {pos: [11, 0, 20], state: "minecraft:deepslate_bricks"},
        {pos: [11, 0, 21], state: "minecraft:deepslate_bricks"},
        {pos: [11, 0, 22], state: "minecraft:deepslate_bricks"},
        {pos: [11, 0, 23], state: "minecraft:deepslate_bricks"},
        {pos: [11, 0, 24], state: "minecraft:deepslate_bricks"},
        {pos: [11, 0, 25], state: "minecraft:deepslate_bricks"},
        {pos: [11, 0, 26], state: "minecraft:deepslate_bricks"},
        {pos: [11, 0, 27], state: "minecraft:deepslate_bricks"},
        {pos: [11, 0, 28], state: "minecraft:deepslate_bricks"},
        {pos: [11, 0, 29], state: "minecraft:deepslate_bricks"},
        {pos: [11, 0, 30], state: "minecraft:deepslate_bricks"},
        {pos: [11, 0, 31], state: "minecraft:deepslate_bricks"},
        {pos: [11, 0, 32], state: "minecraft:deepslate_bricks"},
        {pos: [11, 0, 33], state: "minecraft:deepslate_bricks"},
        {pos: [11, 0, 34], state: "minecraft:deepslate_bricks"},
        {pos: [11, 0, 35], state: "minecraft:deepslate_bricks"},
        {pos: [11, 0, 36], state: "minecraft:deepslate_bricks"},
        {pos: [11, 0, 37], state: "minecraft:deepslate_bricks"},
        {pos: [11, 0, 38], state: "minecraft:deepslate_bricks"},
        {pos: [11, 0, 39], state: "minecraft:deepslate_bricks"},
        {pos: [11, 0, 40], state: "minecraft:deepslate_bricks"},
        {pos: [12, 0, 0], state: "minecraft:deepslate_bricks"},
        {pos: [12, 0, 1], state: "minecraft:deepslate_bricks"},
        {pos: [12, 0, 2], state: "minecraft:deepslate_bricks"},
        {pos: [12, 0, 3], state: "minecraft:deepslate_bricks"},
        {pos: [12, 0, 4], state: "minecraft:deepslate_bricks"},
        {pos: [12, 0, 5], state: "minecraft:deepslate_bricks"},
        {pos: [12, 0, 6], state: "minecraft:deepslate_bricks"},
        {pos: [12, 0, 7], state: "minecraft:deepslate_bricks"},
        {pos: [12, 0, 8], state: "minecraft:deepslate_bricks"},
        {pos: [12, 0, 9], state: "minecraft:deepslate_bricks"},
        {pos: [12, 0, 10], state: "minecraft:deepslate_bricks"},
        {pos: [12, 0, 11], state: "minecraft:deepslate_bricks"},
        {pos: [12, 0, 12], state: "minecraft:deepslate_bricks"},
        {pos: [12, 0, 13], state: "minecraft:deepslate_bricks"},
        {pos: [12, 0, 14], state: "minecraft:deepslate_bricks"},
        {pos: [12, 0, 15], state: "minecraft:deepslate_bricks"},
        {pos: [12, 0, 16], state: "minecraft:deepslate_bricks"},
        {pos: [12, 0, 17], state: "minecraft:deepslate_bricks"},
        {pos: [12, 0, 18], state: "minecraft:deepslate_bricks"},
        {pos: [12, 0, 19], state: "minecraft:deepslate_bricks"},
        {pos: [12, 0, 20], state: "minecraft:deepslate_bricks"},
        {pos: [12, 0, 21], state: "minecraft:deepslate_bricks"},
        {pos: [12, 0, 22], state: "minecraft:deepslate_bricks"},
        {pos: [12, 0, 23], state: "minecraft:deepslate_bricks"},
        {pos: [12, 0, 24], state: "minecraft:deepslate_bricks"},
        {pos: [12, 0, 25], state: "minecraft:deepslate_bricks"},
        {pos: [12, 0, 26], state: "minecraft:deepslate_bricks"},
        {pos: [12, 0, 27], state: "minecraft:deepslate_bricks"},
        {pos: [12, 0, 28], state: "minecraft:deepslate_bricks"},
        {pos: [12, 0, 29], state: "minecraft:deepslate_bricks"},
        {pos: [12, 0, 30], state: "minecraft:deepslate_bricks"},
        {pos: [12, 0, 31], state: "minecraft:deepslate_bricks"},
        {pos: [12, 0, 32], state: "minecraft:deepslate_bricks"},
        {pos: [12, 0, 33], state: "minecraft:deepslate_bricks"},
        {pos: [12, 0, 34], state: "minecraft:deepslate_bricks"},
        {pos: [12, 0, 35], state: "minecraft:deepslate_bricks"},
        {pos: [12, 0, 36], state: "minecraft:deepslate_bricks"},
        {pos: [12, 0, 37], state: "minecraft:deepslate_bricks"},
        {pos: [12, 0, 38], state: "minecraft:deepslate_bricks"},
        {pos: [12, 0, 39], state: "minecraft:deepslate_bricks"},
        {pos: [12, 0, 40], state: "minecraft:deepslate_bricks"},
        {pos: [13, 0, 0], state: "minecraft:jigsaw{orientation:east_up}", nbt: {final_state: "minecraft:deepslate_bricks", id: "minecraft:jigsaw", joint: "rollable", name: "minecraft:connect_bottom", pool: "minecraft:empty", target: "minecraft:empty"}},
        {pos: [13, 0, 1], state: "minecraft:deepslate{axis:y}"},
        {pos: [13, 0, 2], state: "minecraft:deepslate{axis:y}"},
        {pos: [13, 0, 3], state: "minecraft:deepslate{axis:y}"},
        {pos: [13, 0, 4], state: "minecraft:deepslate{axis:y}"},
        {pos: [13, 0, 5], state: "minecraft:deepslate{axis:y}"},
        {pos: [13, 0, 6], state: "minecraft:deepslate{axis:y}"},
        {pos: [13, 0, 7], state: "minecraft:deepslate{axis:y}"},
        {pos: [13, 0, 8], state: "minecraft:deepslate{axis:y}"},
        {pos: [13, 0, 9], state: "minecraft:deepslate{axis:y}"},
        {pos: [13, 0, 10], state: "minecraft:deepslate{axis:y}"},
        {pos: [13, 0, 11], state: "minecraft:deepslate{axis:y}"},
        {pos: [13, 0, 12], state: "minecraft:deepslate{axis:y}"},
        {pos: [13, 0, 13], state: "minecraft:deepslate{axis:y}"},
        {pos: [13, 0, 14], state: "minecraft:deepslate{axis:y}"},
        {pos: [13, 0, 15], state: "minecraft:deepslate{axis:y}"},
        {pos: [13, 0, 16], state: "minecraft:deepslate{axis:y}"},
        {pos: [13, 0, 17], state: "minecraft:deepslate{axis:y}"},
        {pos: [13, 0, 18], state: "minecraft:deepslate{axis:y}"},
        {pos: [13, 0, 19], state: "minecraft:deepslate{axis:y}"},
        {pos: [13, 0, 20], state: "minecraft:deepslate{axis:y}"},
        {pos: [13, 0, 21], state: "minecraft:deepslate{axis:y}"},
        {pos: [13, 0, 22], state: "minecraft:deepslate{axis:y}"},
        {pos: [13, 0, 23], state: "minecraft:deepslate{axis:y}"},
        {pos: [13, 0, 24], state: "minecraft:deepslate{axis:y}"},
        {pos: [13, 0, 25], state: "minecraft:deepslate{axis:y}"},
        {pos: [13, 0, 26], state: "minecraft:deepslate{axis:y}"},
        {pos: [13, 0, 27], state: "minecraft:deepslate{axis:y}"},
        {pos: [13, 0, 28], state: "minecraft:deepslate{axis:y}"},
        {pos: [13, 0, 29], state: "minecraft:deepslate{axis:y}"},
        {pos: [13, 0, 30], state: "minecraft:deepslate{axis:y}"},
        {pos: [13, 0, 31], state: "minecraft:deepslate{axis:y}"},
        {pos: [13, 0, 32], state: "minecraft:deepslate{axis:y}"},
        {pos: [13, 0, 33], state: "minecraft:deepslate{axis:y}"},
        {pos: [13, 0, 34], state: "minecraft:deepslate{axis:y}"},
        {pos: [13, 0, 35], state: "minecraft:deepslate{axis:y}"},
        {pos: [13, 0, 36], state: "minecraft:deepslate{axis:y}"},
        {pos: [13, 0, 37], state: "minecraft:deepslate{axis:y}"},
        {pos: [13, 0, 38], state: "minecraft:deepslate{axis:y}"},
        {pos: [13, 0, 39], state: "minecraft:deepslate{axis:y}"},
        {pos: [13, 0, 40], state: "minecraft:deepslate{axis:y}"},
        {pos: [0, 1, 0], state: "minecraft:deepslate{axis:y}"},
        {pos: [0, 1, 1], state: "minecraft:deepslate{axis:y}"},
        {pos: [0, 1, 2], state: "minecraft:deepslate{axis:y}"},
        {pos: [0, 1, 3], state: "minecraft:deepslate_bricks"},
        {pos: [0, 1, 4], state: "minecraft:deepslate_bricks"},
        {pos: [0, 1, 5], state: "minecraft:deepslate_bricks"},
        {pos: [0, 1, 6], state: "minecraft:deepslate_bricks"},
        {pos: [0, 1, 7], state: "minecraft:deepslate{axis:y}"},
        {pos: [0, 1, 8], state: "minecraft:deepslate{axis:y}"},
        {pos: [0, 1, 9], state: "minecraft:deepslate{axis:y}"},
        {pos: [0, 1, 10], state: "minecraft:deepslate{axis:y}"},
        {pos: [0, 1, 11], state: "minecraft:deepslate{axis:y}"},
        {pos: [0, 1, 12], state: "minecraft:deepslate_bricks"},
        {pos: [0, 1, 13], state: "minecraft:deepslate_bricks"},
        {pos: [0, 1, 14], state: "minecraft:deepslate_bricks"},
        {pos: [0, 1, 15], state: "minecraft:deepslate_bricks"},
        {pos: [0, 1, 16], state: "minecraft:deepslate{axis:y}"},
        {pos: [0, 1, 17], state: "minecraft:deepslate{axis:y}"},
        {pos: [0, 1, 18], state: "minecraft:deepslate{axis:y}"},
        {pos: [0, 1, 19], state: "minecraft:deepslate{axis:y}"},
        {pos: [0, 1, 20], state: "minecraft:deepslate{axis:y}"},
        {pos: [0, 1, 21], state: "minecraft:deepslate{axis:y}"},
        {pos: [0, 1, 22], state: "minecraft:deepslate{axis:y}"},
        {pos: [0, 1, 23], state: "minecraft:deepslate{axis:y}"},
        {pos: [0, 1, 24], state: "minecraft:deepslate{axis:y}"},
        {pos: [0, 1, 25], state: "minecraft:deepslate_bricks"},
        {pos: [0, 1, 26], state: "minecraft:deepslate_bricks"},
        {pos: [0, 1, 27], state: "minecraft:deepslate_bricks"},
        {pos: [0, 1, 28], state: "minecraft:deepslate_bricks"},
        {pos: [0, 1, 29], state: "minecraft:deepslate{axis:y}"},
        {pos: [0, 1, 30], state: "minecraft:deepslate{axis:y}"},
        {pos: [0, 1, 31], state: "minecraft:deepslate{axis:y}"},
        {pos: [0, 1, 32], state: "minecraft:deepslate{axis:y}"},
        {pos: [0, 1, 33], state: "minecraft:deepslate{axis:y}"},
        {pos: [0, 1, 34], state: "minecraft:deepslate_bricks"},
        {pos: [0, 1, 35], state: "minecraft:deepslate_bricks"},
        {pos: [0, 1, 36], state: "minecraft:deepslate_bricks"},
        {pos: [0, 1, 37], state: "minecraft:cracked_deepslate_bricks"},
        {pos: [0, 1, 38], state: "minecraft:deepslate{axis:y}"},
        {pos: [0, 1, 39], state: "minecraft:deepslate{axis:y}"},
        {pos: [0, 1, 40], state: "minecraft:deepslate{axis:y}"},
        {pos: [1, 1, 0], state: "minecraft:gray_wool"},
        {pos: [1, 1, 1], state: "minecraft:gray_wool"},
        {pos: [1, 1, 2], state: "minecraft:gray_wool"},
        {pos: [1, 1, 3], state: "minecraft:gray_wool"},
        {pos: [1, 1, 4], state: "minecraft:gray_wool"},
        {pos: [1, 1, 5], state: "minecraft:gray_wool"},
        {pos: [1, 1, 6], state: "minecraft:gray_wool"},
        {pos: [1, 1, 7], state: "minecraft:gray_wool"},
        {pos: [1, 1, 8], state: "minecraft:gray_wool"},
        {pos: [1, 1, 9], state: "minecraft:gray_wool"},
        {pos: [1, 1, 10], state: "minecraft:gray_wool"},
        {pos: [1, 1, 11], state: "minecraft:gray_wool"},
        {pos: [1, 1, 12], state: "minecraft:gray_wool"},
        {pos: [1, 1, 13], state: "minecraft:gray_wool"},
        {pos: [1, 1, 14], state: "minecraft:gray_wool"},
        {pos: [1, 1, 15], state: "minecraft:gray_wool"},
        {pos: [1, 1, 16], state: "minecraft:gray_wool"},
        {pos: [1, 1, 17], state: "minecraft:gray_wool"},
        {pos: [1, 1, 18], state: "minecraft:gray_wool"},
        {pos: [1, 1, 19], state: "minecraft:gray_wool"},
        {pos: [1, 1, 20], state: "minecraft:gray_wool"},
        {pos: [1, 1, 21], state: "minecraft:gray_wool"},
        {pos: [1, 1, 22], state: "minecraft:gray_wool"},
        {pos: [1, 1, 23], state: "minecraft:gray_wool"},
        {pos: [1, 1, 24], state: "minecraft:gray_wool"},
        {pos: [1, 1, 25], state: "minecraft:gray_wool"},
        {pos: [1, 1, 26], state: "minecraft:gray_wool"},
        {pos: [1, 1, 27], state: "minecraft:gray_wool"},
        {pos: [1, 1, 28], state: "minecraft:gray_wool"},
        {pos: [1, 1, 29], state: "minecraft:gray_wool"},
        {pos: [1, 1, 30], state: "minecraft:gray_wool"},
        {pos: [1, 1, 31], state: "minecraft:gray_wool"},
        {pos: [1, 1, 32], state: "minecraft:gray_wool"},
        {pos: [1, 1, 33], state: "minecraft:gray_wool"},
        {pos: [1, 1, 34], state: "minecraft:gray_wool"},
        {pos: [1, 1, 35], state: "minecraft:gray_wool"},
        {pos: [1, 1, 36], state: "minecraft:gray_wool"},
        {pos: [1, 1, 37], state: "minecraft:gray_wool"},
        {pos: [1, 1, 38], state: "minecraft:gray_wool"},
        {pos: [1, 1, 39], state: "minecraft:gray_wool"},
        {pos: [1, 1, 40], state: "minecraft:gray_wool"},
        {pos: [2, 1, 0], state: "minecraft:gray_wool"},
        {pos: [2, 1, 1], state: "minecraft:gray_wool"},
        {pos: [2, 1, 2], state: "minecraft:gray_wool"},
        {pos: [2, 1, 3], state: "minecraft:gray_wool"},
        {pos: [2, 1, 4], state: "minecraft:gray_wool"},
        {pos: [2, 1, 5], state: "minecraft:gray_wool"},
        {pos: [2, 1, 6], state: "minecraft:gray_wool"},
        {pos: [2, 1, 7], state: "minecraft:gray_wool"},
        {pos: [2, 1, 8], state: "minecraft:gray_wool"},
        {pos: [2, 1, 9], state: "minecraft:gray_wool"},
        {pos: [2, 1, 10], state: "minecraft:gray_wool"},
        {pos: [2, 1, 11], state: "minecraft:deepslate{axis:y}"},
        {pos: [2, 1, 12], state: "minecraft:gray_wool"},
        {pos: [2, 1, 13], state: "minecraft:gray_wool"},
        {pos: [2, 1, 14], state: "minecraft:gray_wool"},
        {pos: [2, 1, 15], state: "minecraft:gray_wool"},
        {pos: [2, 1, 16], state: "minecraft:gray_wool"},
        {pos: [2, 1, 17], state: "minecraft:gray_wool"},
        {pos: [2, 1, 18], state: "minecraft:gray_wool"},
        {pos: [2, 1, 19], state: "minecraft:gray_wool"},
        {pos: [2, 1, 20], state: "minecraft:gray_wool"},
        {pos: [2, 1, 21], state: "minecraft:gray_wool"},
        {pos: [2, 1, 22], state: "minecraft:gray_wool"},
        {pos: [2, 1, 23], state: "minecraft:gray_wool"},
        {pos: [2, 1, 24], state: "minecraft:gray_wool"},
        {pos: [2, 1, 25], state: "minecraft:gray_wool"},
        {pos: [2, 1, 26], state: "minecraft:gray_wool"},
        {pos: [2, 1, 27], state: "minecraft:gray_wool"},
        {pos: [2, 1, 28], state: "minecraft:gray_wool"},
        {pos: [2, 1, 29], state: "minecraft:deepslate{axis:y}"},
        {pos: [2, 1, 30], state: "minecraft:gray_wool"},
        {pos: [2, 1, 31], state: "minecraft:gray_wool"},
        {pos: [2, 1, 32], state: "minecraft:gray_wool"},
        {pos: [2, 1, 33], state: "minecraft:gray_wool"},
        {pos: [2, 1, 34], state: "minecraft:gray_wool"},
        {pos: [2, 1, 35], state: "minecraft:gray_wool"},
        {pos: [2, 1, 36], state: "minecraft:gray_wool"},
        {pos: [2, 1, 37], state: "minecraft:gray_wool"},
        {pos: [2, 1, 38], state: "minecraft:gray_wool"},
        {pos: [2, 1, 39], state: "minecraft:gray_wool"},
        {pos: [2, 1, 40], state: "minecraft:gray_wool"},
        {pos: [3, 1, 0], state: "minecraft:deepslate_bricks"},
        {pos: [3, 1, 1], state: "minecraft:deepslate_bricks"},
        {pos: [3, 1, 2], state: "minecraft:gray_wool"},
        {pos: [3, 1, 3], state: "minecraft:deepslate_bricks"},
        {pos: [3, 1, 4], state: "minecraft:deepslate_bricks"},
        {pos: [3, 1, 5], state: "minecraft:gray_wool"},
        {pos: [3, 1, 6], state: "minecraft:deepslate_bricks"},
        {pos: [3, 1, 7], state: "minecraft:deepslate_bricks"},
        {pos: [3, 1, 8], state: "minecraft:gray_wool"},
        {pos: [3, 1, 9], state: "minecraft:deepslate_bricks"},
        {pos: [3, 1, 10], state: "minecraft:deepslate_bricks"},
        {pos: [3, 1, 11], state: "minecraft:polished_deepslate_stairs{facing:west,half:bottom,shape:straight,waterlogged:false}"},
        {pos: [3, 1, 12], state: "minecraft:deepslate_brick_stairs{facing:north,half:bottom,shape:outer_left,waterlogged:false}"},
        {pos: [3, 1, 14], state: "minecraft:deepslate_brick_stairs{facing:south,half:bottom,shape:straight,waterlogged:false}"},
        {pos: [3, 1, 15], state: "minecraft:gray_wool"},
        {pos: [3, 1, 16], state: "minecraft:deepslate_bricks"},
        {pos: [3, 1, 17], state: "minecraft:deepslate_bricks"},
        {pos: [3, 1, 18], state: "minecraft:gray_wool"},
        {pos: [3, 1, 19], state: "minecraft:deepslate_brick_stairs{facing:north,half:bottom,shape:straight,waterlogged:false}"},
        {pos: [3, 1, 21], state: "minecraft:deepslate_brick_stairs{facing:south,half:bottom,shape:straight,waterlogged:false}"},
        {pos: [3, 1, 22], state: "minecraft:gray_wool"},
        {pos: [3, 1, 23], state: "minecraft:deepslate_bricks"},
        {pos: [3, 1, 24], state: "minecraft:deepslate_bricks"},
        {pos: [3, 1, 25], state: "minecraft:gray_wool"},
        {pos: [3, 1, 26], state: "minecraft:deepslate_brick_stairs{facing:north,half:bottom,shape:straight,waterlogged:false}"},
        {pos: [3, 1, 28], state: "minecraft:deepslate_brick_stairs{facing:south,half:bottom,shape:straight,waterlogged:false}"},
        {pos: [3, 1, 29], state: "minecraft:deepslate{axis:y}"},
        {pos: [3, 1, 30], state: "minecraft:deepslate_bricks"},
        {pos: [3, 1, 31], state: "minecraft:deepslate_bricks"},
        {pos: [3, 1, 32], state: "minecraft:gray_wool"},
        {pos: [3, 1, 33], state: "minecraft:deepslate_bricks"},
        {pos: [3, 1, 34], state: "minecraft:deepslate_bricks"},
        {pos: [3, 1, 35], state: "minecraft:gray_wool"},
        {pos: [3, 1, 36], state: "minecraft:deepslate_bricks"},
        {pos: [3, 1, 37], state: "minecraft:deepslate_bricks"},
        {pos: [3, 1, 38], state: "minecraft:gray_wool"},
        {pos: [3, 1, 39], state: "minecraft:deepslate_bricks"},
        {pos: [3, 1, 40], state: "minecraft:deepslate_bricks"},
        {pos: [4, 1, 0], state: "minecraft:deepslate_brick_stairs{facing:west,half:bottom,shape:straight,waterlogged:false}"},
        {pos: [4, 1, 1], state: "minecraft:deepslate_brick_stairs{facing:west,half:bottom,shape:straight,waterlogged:false}"},
        {pos: [4, 1, 3], state: "minecraft:deepslate_brick_stairs{facing:west,half:bottom,shape:straight,waterlogged:false}"},
        {pos: [4, 1, 4], state: "minecraft:deepslate_brick_stairs{facing:west,half:bottom,shape:straight,waterlogged:false}"},
        {pos: [4, 1, 6], state: "minecraft:deepslate_brick_stairs{facing:west,half:bottom,shape:straight,waterlogged:false}"},
        {pos: [4, 1, 7], state: "minecraft:deepslate_brick_stairs{facing:west,half:bottom,shape:straight,waterlogged:false}"},
        {pos: [4, 1, 9], state: "minecraft:deepslate_brick_stairs{facing:west,half:bottom,shape:straight,waterlogged:false}"},
        {pos: [4, 1, 10], state: "minecraft:deepslate_brick_stairs{facing:west,half:bottom,shape:straight,waterlogged:false}"},
        {pos: [4, 1, 16], state: "minecraft:deepslate_brick_stairs{facing:west,half:bottom,shape:straight,waterlogged:false}"},
        {pos: [4, 1, 17], state: "minecraft:deepslate_brick_stairs{facing:west,half:bottom,shape:straight,waterlogged:false}"},
        {pos: [4, 1, 23], state: "minecraft:deepslate_brick_stairs{facing:west,half:bottom,shape:straight,waterlogged:false}"},
        {pos: [4, 1, 24], state: "minecraft:deepslate_brick_stairs{facing:west,half:bottom,shape:straight,waterlogged:false}"},
        {pos: [4, 1, 29], state: "minecraft:deepslate_tile_stairs{facing:west,half:bottom,shape:straight,waterlogged:false}"},
        {pos: [4, 1, 30], state: "minecraft:deepslate_brick_stairs{facing:west,half:bottom,shape:straight,waterlogged:false}"},
        {pos: [4, 1, 31], state: "minecraft:deepslate_brick_stairs{facing:west,half:bottom,shape:straight,waterlogged:false}"},
        {pos: [4, 1, 33], state: "minecraft:deepslate_brick_stairs{facing:west,half:bottom,shape:straight,waterlogged:false}"},
        {pos: [4, 1, 34], state: "minecraft:deepslate_brick_stairs{facing:west,half:bottom,shape:straight,waterlogged:false}"},
        {pos: [4, 1, 36], state: "minecraft:deepslate_brick_stairs{facing:west,half:bottom,shape:straight,waterlogged:false}"},
        {pos: [4, 1, 37], state: "minecraft:deepslate_brick_stairs{facing:west,half:bottom,shape:straight,waterlogged:false}"},
        {pos: [4, 1, 39], state: "minecraft:deepslate_brick_stairs{facing:west,half:bottom,shape:straight,waterlogged:false}"},
        {pos: [4, 1, 40], state: "minecraft:deepslate_brick_stairs{facing:west,half:bottom,shape:straight,waterlogged:false}"},
        {pos: [10, 1, 0], state: "minecraft:deepslate_brick_stairs{facing:south,half:bottom,shape:straight,waterlogged:false}"},
        {pos: [10, 1, 1], state: "minecraft:gray_wool"},
        {pos: [10, 1, 2], state: "minecraft:gray_wool"},
        {pos: [10, 1, 3], state: "minecraft:gray_wool"},
        {pos: [10, 1, 4], state: "minecraft:gray_wool"},
        {pos: [10, 1, 5], state: "minecraft:deepslate_brick_stairs{facing:north,half:bottom,shape:straight,waterlogged:false}"},
        {pos: [10, 1, 7], state: "minecraft:deepslate_brick_stairs{facing:south,half:bottom,shape:straight,waterlogged:false}"},
        {pos: [10, 1, 8], state: "minecraft:gray_wool"},
        {pos: [10, 1, 9], state: "minecraft:gray_wool"},
        {pos: [10, 1, 10], state: "minecraft:gray_wool"},
        {pos: [10, 1, 11], state: "minecraft:gray_wool"},
        {pos: [10, 1, 12], state: "minecraft:deepslate_brick_stairs{facing:north,half:bottom,shape:straight,waterlogged:false}"},
        {pos: [10, 1, 14], state: "minecraft:deepslate_brick_stairs{facing:south,half:bottom,shape:straight,waterlogged:false}"},
        {pos: [10, 1, 15], state: "minecraft:gray_wool"},
        {pos: [10, 1, 16], state: "minecraft:gray_wool"},
        {pos: [10, 1, 17], state: "minecraft:gray_wool"},
        {pos: [10, 1, 18], state: "minecraft:gray_wool"},
        {pos: [10, 1, 19], state: "minecraft:deepslate_brick_stairs{facing:north,half:bottom,shape:straight,waterlogged:false}"},
        {pos: [10, 1, 21], state: "minecraft:deepslate_brick_stairs{facing:south,half:bottom,shape:straight,waterlogged:false}"},
        {pos: [10, 1, 22], state: "minecraft:gray_wool"},
        {pos: [10, 1, 23], state: "minecraft:gray_wool"},
        {pos: [10, 1, 24], state: "minecraft:gray_wool"},
        {pos: [10, 1, 25], state: "minecraft:gray_wool"},
        {pos: [10, 1, 26], state: "minecraft:deepslate_brick_stairs{facing:north,half:bottom,shape:straight,waterlogged:false}"},
        {pos: [10, 1, 28], state: "minecraft:deepslate_brick_stairs{facing:south,half:bottom,shape:straight,waterlogged:false}"},
        {pos: [10, 1, 29], state: "minecraft:gray_wool"},
        {pos: [10, 1, 30], state: "minecraft:gray_wool"},
        {pos: [10, 1, 31], state: "minecraft:gray_wool"},
        {pos: [10, 1, 32], state: "minecraft:gray_wool"},
        {pos: [10, 1, 33], state: "minecraft:deepslate_brick_stairs{facing:north,half:bottom,shape:straight,waterlogged:false}"},
        {pos: [10, 1, 35], state: "minecraft:deepslate_brick_stairs{facing:south,half:bottom,shape:straight,waterlogged:false}"},
        {pos: [10, 1, 36], state: "minecraft:gray_wool"},
        {pos: [10, 1, 37], state: "minecraft:gray_wool"},
        {pos: [10, 1, 38], state: "minecraft:gray_wool"},
        {pos: [10, 1, 39], state: "minecraft:gray_wool"},
        {pos: [10, 1, 40], state: "minecraft:deepslate_brick_stairs{facing:north,half:bottom,shape:straight,waterlogged:false}"},
        {pos: [11, 1, 0], state: "minecraft:deepslate{axis:y}"},
        {pos: [11, 1, 1], state: "minecraft:deepslate{axis:y}"},
        {pos: [11, 1, 2], state: "minecraft:deepslate{axis:y}"},
        {pos: [11, 1, 3], state: "minecraft:deepslate{axis:y}"},
        {pos: [11, 1, 4], state: "minecraft:deepslate{axis:y}"},
        {pos: [11, 1, 5], state: "minecraft:deepslate{axis:y}"},
        {pos: [11, 1, 6], state: "minecraft:deepslate{axis:y}"},
        {pos: [11, 1, 7], state: "minecraft:deepslate{axis:y}"},
        {pos: [11, 1, 8], state: "minecraft:deepslate{axis:y}"},
        {pos: [11, 1, 9], state: "minecraft:deepslate{axis:y}"},
        {pos: [11, 1, 10], state: "minecraft:deepslate{axis:y}"},
        {pos: [11, 1, 11], state: "minecraft:deepslate{axis:y}"},
        {pos: [11, 1, 12], state: "minecraft:deepslate{axis:y}"},
        {pos: [11, 1, 13], state: "minecraft:deepslate{axis:y}"},
        {pos: [11, 1, 14], state: "minecraft:deepslate{axis:y}"},
        {pos: [11, 1, 15], state: "minecraft:deepslate{axis:y}"},
        {pos: [11, 1, 16], state: "minecraft:deepslate{axis:y}"},
        {pos: [11, 1, 17], state: "minecraft:deepslate{axis:y}"},
        {pos: [11, 1, 18], state: "minecraft:deepslate{axis:y}"},
        {pos: [11, 1, 19], state: "minecraft:deepslate{axis:y}"},
        {pos: [11, 1, 20], state: "minecraft:deepslate{axis:y}"},
        {pos: [11, 1, 21], state: "minecraft:deepslate{axis:y}"},
        {pos: [11, 1, 22], state: "minecraft:deepslate{axis:y}"},
        {pos: [11, 1, 23], state: "minecraft:deepslate{axis:y}"},
        {pos: [11, 1, 24], state: "minecraft:deepslate{axis:y}"},
        {pos: [11, 1, 25], state: "minecraft:deepslate{axis:y}"},
        {pos: [11, 1, 26], state: "minecraft:deepslate{axis:y}"},
        {pos: [11, 1, 27], state: "minecraft:deepslate{axis:y}"},
        {pos: [11, 1, 28], state: "minecraft:deepslate{axis:y}"},
        {pos: [11, 1, 29], state: "minecraft:deepslate{axis:y}"},
        {pos: [11, 1, 30], state: "minecraft:deepslate{axis:y}"},
        {pos: [11, 1, 31], state: "minecraft:deepslate{axis:y}"},
        {pos: [11, 1, 32], state: "minecraft:deepslate{axis:y}"},
        {pos: [11, 1, 33], state: "minecraft:deepslate{axis:y}"},
        {pos: [11, 1, 34], state: "minecraft:deepslate{axis:y}"},
        {pos: [11, 1, 35], state: "minecraft:deepslate{axis:y}"},
        {pos: [11, 1, 36], state: "minecraft:deepslate{axis:y}"},
        {pos: [11, 1, 37], state: "minecraft:deepslate{axis:y}"},
        {pos: [11, 1, 38], state: "minecraft:deepslate{axis:y}"},
        {pos: [11, 1, 39], state: "minecraft:deepslate{axis:y}"},
        {pos: [11, 1, 40], state: "minecraft:deepslate{axis:y}"},
        {pos: [12, 1, 0], state: "minecraft:gray_wool"},
        {pos: [12, 1, 1], state: "minecraft:gray_wool"},
        {pos: [12, 1, 2], state: "minecraft:gray_wool"},
        {pos: [12, 1, 3], state: "minecraft:gray_wool"},
        {pos: [12, 1, 4], state: "minecraft:gray_wool"},
        {pos: [12, 1, 5], state: "minecraft:gray_wool"},
        {pos: [12, 1, 6], state: "minecraft:gray_wool"},
        {pos: [12, 1, 7], state: "minecraft:gray_wool"},
        {pos: [12, 1, 8], state: "minecraft:gray_wool"},
        {pos: [12, 1, 9], state: "minecraft:gray_wool"},
        {pos: [12, 1, 10], state: "minecraft:gray_wool"},
        {pos: [12, 1, 11], state: "minecraft:gray_wool"},
        {pos: [12, 1, 12], state: "minecraft:gray_wool"},
        {pos: [12, 1, 13], state: "minecraft:gray_wool"},
        {pos: [12, 1, 14], state: "minecraft:gray_wool"},
        {pos: [12, 1, 15], state: "minecraft:gray_wool"},
        {pos: [12, 1, 16], state: "minecraft:gray_wool"},
        {pos: [12, 1, 17], state: "minecraft:gray_wool"},
        {pos: [12, 1, 18], state: "minecraft:gray_wool"},
        {pos: [12, 1, 19], state: "minecraft:gray_wool"},
        {pos: [12, 1, 20], state: "minecraft:gray_wool"},
        {pos: [12, 1, 21], state: "minecraft:gray_wool"},
        {pos: [12, 1, 22], state: "minecraft:gray_wool"},
        {pos: [12, 1, 23], state: "minecraft:gray_wool"},
        {pos: [12, 1, 24], state: "minecraft:gray_wool"},
        {pos: [12, 1, 25], state: "minecraft:gray_wool"},
        {pos: [12, 1, 26], state: "minecraft:gray_wool"},
        {pos: [12, 1, 27], state: "minecraft:gray_wool"},
        {pos: [12, 1, 28], state: "minecraft:gray_wool"},
        {pos: [12, 1, 29], state: "minecraft:gray_wool"},
        {pos: [12, 1, 30], state: "minecraft:gray_wool"},
        {pos: [12, 1, 31], state: "minecraft:gray_wool"},
        {pos: [12, 1, 32], state: "minecraft:gray_wool"},
        {pos: [12, 1, 33], state: "minecraft:gray_wool"},
        {pos: [12, 1, 34], state: "minecraft:gray_wool"},
        {pos: [12, 1, 35], state: "minecraft:gray_wool"},
        {pos: [12, 1, 36], state: "minecraft:gray_wool"},
        {pos: [12, 1, 37], state: "minecraft:gray_wool"},
        {pos: [12, 1, 38], state: "minecraft:gray_wool"},
        {pos: [12, 1, 39], state: "minecraft:gray_wool"},
        {pos: [12, 1, 40], state: "minecraft:gray_wool"},
        {pos: [13, 1, 1], state: "minecraft:deepslate{axis:y}"},
        {pos: [13, 1, 2], state: "minecraft:deepslate{axis:y}"},
        {pos: [13, 1, 3], state: "minecraft:deepslate{axis:y}"},
        {pos: [13, 1, 4], state: "minecraft:deepslate{axis:y}"},
        {pos: [13, 1, 5], state: "minecraft:deepslate{axis:y}"},
        {pos: [13, 1, 6], state: "minecraft:deepslate{axis:y}"},
        {pos: [13, 1, 7], state: "minecraft:deepslate{axis:y}"},
        {pos: [13, 1, 8], state: "minecraft:deepslate{axis:y}"},
        {pos: [13, 1, 9], state: "minecraft:deepslate{axis:y}"},
        {pos: [13, 1, 10], state: "minecraft:deepslate{axis:y}"},
        {pos: [13, 1, 11], state: "minecraft:deepslate{axis:y}"},
        {pos: [13, 1, 12], state: "minecraft:deepslate{axis:y}"},
        {pos: [13, 1, 13], state: "minecraft:deepslate{axis:y}"},
        {pos: [13, 1, 14], state: "minecraft:deepslate{axis:y}"},
        {pos: [13, 1, 15], state: "minecraft:deepslate{axis:y}"},
        {pos: [13, 1, 16], state: "minecraft:deepslate{axis:y}"},
        {pos: [13, 1, 17], state: "minecraft:deepslate{axis:y}"},
        {pos: [13, 1, 18], state: "minecraft:deepslate{axis:y}"},
        {pos: [13, 1, 19], state: "minecraft:deepslate{axis:y}"},
        {pos: [13, 1, 20], state: "minecraft:deepslate{axis:y}"},
        {pos: [13, 1, 21], state: "minecraft:deepslate{axis:y}"},
        {pos: [13, 1, 22], state: "minecraft:deepslate{axis:y}"},
        {pos: [13, 1, 23], state: "minecraft:deepslate{axis:y}"},
        {pos: [13, 1, 24], state: "minecraft:deepslate{axis:y}"},
        {pos: [13, 1, 25], state: "minecraft:deepslate{axis:y}"},
        {pos: [13, 1, 26], state: "minecraft:deepslate{axis:y}"},
        {pos: [13, 1, 27], state: "minecraft:deepslate{axis:y}"},
        {pos: [13, 1, 28], state: "minecraft:deepslate{axis:y}"},
        {pos: [13, 1, 29], state: "minecraft:deepslate{axis:y}"},
        {pos: [13, 1, 30], state: "minecraft:deepslate{axis:y}"},
        {pos: [13, 1, 31], state: "minecraft:deepslate{axis:y}"},
        {pos: [13, 1, 32], state: "minecraft:deepslate{axis:y}"},
        {pos: [13, 1, 33], state: "minecraft:deepslate{axis:y}"},
        {pos: [13, 1, 34], state: "minecraft:deepslate{axis:y}"},
        {pos: [13, 1, 35], state: "minecraft:deepslate{axis:y}"},
        {pos: [13, 1, 36], state: "minecraft:deepslate{axis:y}"},
        {pos: [13, 1, 37], state: "minecraft:deepslate{axis:y}"},
        {pos: [13, 1, 38], state: "minecraft:deepslate{axis:y}"},
        {pos: [13, 1, 39], state: "minecraft:deepslate{axis:y}"},
        {pos: [13, 1, 40], state: "minecraft:deepslate{axis:y}"},
        {pos: [0, 2, 0], state: "minecraft:deepslate_tiles"},
        {pos: [0, 2, 1], state: "minecraft:deepslate_tiles"},
        {pos: [0, 2, 2], state: "minecraft:deepslate_tiles"},
        {pos: [0, 2, 3], state: "minecraft:deepslate_bricks"},
        {pos: [0, 2, 4], state: "minecraft:chiseled_deepslate"},
        {pos: [0, 2, 5], state: "minecraft:chiseled_deepslate"},
        {pos: [0, 2, 6], state: "minecraft:deepslate_bricks"},
        {pos: [0, 2, 7], state: "minecraft:deepslate_tiles"},
        {pos: [0, 2, 8], state: "minecraft:deepslate_tiles"},
        {pos: [0, 2, 9], state: "minecraft:deepslate_tiles"},
        {pos: [0, 2, 10], state: "minecraft:deepslate_tiles"},
        {pos: [0, 2, 11], state: "minecraft:deepslate_tiles"},
        {pos: [0, 2, 12], state: "minecraft:deepslate_bricks"},
        {pos: [0, 2, 13], state: "minecraft:chiseled_deepslate"},
        {pos: [0, 2, 14], state: "minecraft:chiseled_deepslate"},
        {pos: [0, 2, 15], state: "minecraft:deepslate_bricks"},
        {pos: [0, 2, 16], state: "minecraft:deepslate_tiles"},
        {pos: [0, 2, 17], state: "minecraft:deepslate_tiles"},
        {pos: [0, 2, 18], state: "minecraft:deepslate_bricks"},
        {pos: [0, 2, 19], state: "minecraft:deepslate_bricks"},
        {pos: [0, 2, 20], state: "minecraft:deepslate_bricks"},
        {pos: [0, 2, 21], state: "minecraft:deepslate_bricks"},
        {pos: [0, 2, 22], state: "minecraft:deepslate_bricks"},
        {pos: [0, 2, 23], state: "minecraft:deepslate_tiles"},
        {pos: [0, 2, 24], state: "minecraft:cracked_deepslate_tiles"},
        {pos: [0, 2, 25], state: "minecraft:deepslate_bricks"},
        {pos: [0, 2, 26], state: "minecraft:chiseled_deepslate"},
        {pos: [0, 2, 27], state: "minecraft:chiseled_deepslate"},
        {pos: [0, 2, 28], state: "minecraft:deepslate_bricks"},
        {pos: [0, 2, 29], state: "minecraft:cracked_deepslate_tiles"},
        {pos: [0, 2, 30], state: "minecraft:deepslate_tiles"},
        {pos: [0, 2, 31], state: "minecraft:deepslate_tiles"},
        {pos: [0, 2, 32], state: "minecraft:cracked_deepslate_tiles"},
        {pos: [0, 2, 33], state: "minecraft:deepslate_tiles"},
        {pos: [0, 2, 34], state: "minecraft:cracked_deepslate_bricks"},
        {pos: [0, 2, 35], state: "minecraft:chiseled_deepslate"},
        {pos: [0, 2, 36], state: "minecraft:chiseled_deepslate"},
        {pos: [0, 2, 37], state: "minecraft:deepslate_bricks"},
        {pos: [0, 2, 38], state: "minecraft:cracked_deepslate_tiles"},
        {pos: [0, 2, 39], state: "minecraft:cracked_deepslate_tiles"},
        {pos: [0, 2, 40], state: "minecraft:cracked_deepslate_tiles"},
        {pos: [1, 2, 0], state: "minecraft:gray_wool"},
        {pos: [1, 2, 1], state: "minecraft:gray_wool"},
        {pos: [1, 2, 2], state: "minecraft:gray_wool"},
        {pos: [1, 2, 3], state: "minecraft:gray_wool"},
        {pos: [1, 2, 4], state: "minecraft:gray_wool"},
        {pos: [1, 2, 5], state: "minecraft:gray_wool"},
        {pos: [1, 2, 6], state: "minecraft:gray_wool"},
        {pos: [1, 2, 7], state: "minecraft:gray_wool"},
        {pos: [1, 2, 8], state: "minecraft:gray_wool"},
        {pos: [1, 2, 9], state: "minecraft:gray_wool"},
        {pos: [1, 2, 10], state: "minecraft:gray_wool"},
        {pos: [1, 2, 11], state: "minecraft:gray_wool"},
        {pos: [1, 2, 12], state: "minecraft:gray_wool"},
        {pos: [1, 2, 13], state: "minecraft:gray_wool"},
        {pos: [1, 2, 14], state: "minecraft:gray_wool"},
        {pos: [1, 2, 15], state: "minecraft:gray_wool"},
        {pos: [1, 2, 16], state: "minecraft:gray_wool"},
        {pos: [1, 2, 17], state: "minecraft:gray_wool"},
        {pos: [1, 2, 18], state: "minecraft:gray_wool"},
        {pos: [1, 2, 19], state: "minecraft:gray_wool"},
        {pos: [1, 2, 20], state: "minecraft:gray_wool"},
        {pos: [1, 2, 21], state: "minecraft:gray_wool"},
        {pos: [1, 2, 22], state: "minecraft:gray_wool"},
        {pos: [1, 2, 23], state: "minecraft:gray_wool"},
        {pos: [1, 2, 24], state: "minecraft:gray_wool"},
        {pos: [1, 2, 25], state: "minecraft:gray_wool"},
        {pos: [1, 2, 26], state: "minecraft:gray_wool"},
        {pos: [1, 2, 27], state: "minecraft:gray_wool"},
        {pos: [1, 2, 28], state: "minecraft:gray_wool"},
        {pos: [1, 2, 29], state: "minecraft:gray_wool"},
        {pos: [1, 2, 30], state: "minecraft:gray_wool"},
        {pos: [1, 2, 31], state: "minecraft:gray_wool"},
        {pos: [1, 2, 32], state: "minecraft:gray_wool"},
        {pos: [1, 2, 33], state: "minecraft:gray_wool"},
        {pos: [1, 2, 34], state: "minecraft:gray_wool"},
        {pos: [1, 2, 35], state: "minecraft:gray_wool"},
        {pos: [1, 2, 36], state: "minecraft:gray_wool"},
        {pos: [1, 2, 37], state: "minecraft:gray_wool"},
        {pos: [1, 2, 38], state: "minecraft:gray_wool"},
        {pos: [1, 2, 39], state: "minecraft:gray_wool"},
        {pos: [1, 2, 40], state: "minecraft:gray_wool"},
        {pos: [2, 2, 0], state: "minecraft:gray_wool"},
        {pos: [2, 2, 1], state: "minecraft:gray_wool"},
        {pos: [2, 2, 2], state: "minecraft:gray_wool"},
        {pos: [2, 2, 3], state: "minecraft:gray_wool"},
        {pos: [2, 2, 4], state: "minecraft:gray_wool"},
        {pos: [2, 2, 5], state: "minecraft:gray_wool"},
        {pos: [2, 2, 6], state: "minecraft:gray_wool"},
        {pos: [2, 2, 7], state: "minecraft:gray_wool"},
        {pos: [2, 2, 8], state: "minecraft:gray_wool"},
        {pos: [2, 2, 9], state: "minecraft:gray_wool"},
        {pos: [2, 2, 10], state: "minecraft:gray_wool"},
        {pos: [2, 2, 11], state: "minecraft:deepslate_tile_stairs{facing:west,half:bottom,shape:straight,waterlogged:false}"},
        {pos: [2, 2, 12], state: "minecraft:gray_wool"},
        {pos: [2, 2, 13], state: "minecraft:gray_wool"},
        {pos: [2, 2, 14], state: "minecraft:gray_wool"},
        {pos: [2, 2, 15], state: "minecraft:gray_wool"},
        {pos: [2, 2, 16], state: "minecraft:gray_wool"},
        {pos: [2, 2, 17], state: "minecraft:gray_wool"},
        {pos: [2, 2, 18], state: "minecraft:gray_wool"},
        {pos: [2, 2, 19], state: "minecraft:gray_wool"},
        {pos: [2, 2, 20], state: "minecraft:gray_wool"},
        {pos: [2, 2, 21], state: "minecraft:gray_wool"},
        {pos: [2, 2, 22], state: "minecraft:gray_wool"},
        {pos: [2, 2, 23], state: "minecraft:gray_wool"},
        {pos: [2, 2, 24], state: "minecraft:gray_wool"},
        {pos: [2, 2, 25], state: "minecraft:gray_wool"},
        {pos: [2, 2, 26], state: "minecraft:gray_wool"},
        {pos: [2, 2, 27], state: "minecraft:gray_wool"},
        {pos: [2, 2, 28], state: "minecraft:gray_wool"},
        {pos: [2, 2, 29], state: "minecraft:deepslate_bricks"},
        {pos: [2, 2, 30], state: "minecraft:gray_wool"},
        {pos: [2, 2, 31], state: "minecraft:gray_wool"},
        {pos: [2, 2, 32], state: "minecraft:gray_wool"},
        {pos: [2, 2, 33], state: "minecraft:gray_wool"},
        {pos: [2, 2, 34], state: "minecraft:gray_wool"},
        {pos: [2, 2, 35], state: "minecraft:gray_wool"},
        {pos: [2, 2, 36], state: "minecraft:gray_wool"},
        {pos: [2, 2, 37], state: "minecraft:gray_wool"},
        {pos: [2, 2, 38], state: "minecraft:gray_wool"},
        {pos: [2, 2, 39], state: "minecraft:gray_wool"},
        {pos: [2, 2, 40], state: "minecraft:gray_wool"},
        {pos: [3, 2, 0], state: "minecraft:chiseled_deepslate"},
        {pos: [3, 2, 1], state: "minecraft:chiseled_deepslate"},
        {pos: [3, 2, 2], state: "minecraft:gray_wool"},
        {pos: [3, 2, 3], state: "minecraft:chiseled_deepslate"},
        {pos: [3, 2, 4], state: "minecraft:chiseled_deepslate"},
        {pos: [3, 2, 5], state: "minecraft:gray_wool"},
        {pos: [3, 2, 6], state: "minecraft:chiseled_deepslate"},
        {pos: [3, 2, 7], state: "minecraft:chiseled_deepslate"},
        {pos: [3, 2, 8], state: "minecraft:gray_wool"},
        {pos: [3, 2, 9], state: "minecraft:chiseled_deepslate"},
        {pos: [3, 2, 10], state: "minecraft:chiseled_deepslate"},
        {pos: [3, 2, 15], state: "minecraft:gray_wool"},
        {pos: [3, 2, 16], state: "minecraft:chiseled_deepslate"},
        {pos: [3, 2, 17], state: "minecraft:chiseled_deepslate"},
        {pos: [3, 2, 18], state: "minecraft:gray_wool"},
        {pos: [3, 2, 22], state: "minecraft:gray_wool"},
        {pos: [3, 2, 23], state: "minecraft:chiseled_deepslate"},
        {pos: [3, 2, 24], state: "minecraft:chiseled_deepslate"},
        {pos: [3, 2, 25], state: "minecraft:gray_wool"},
        {pos: [3, 2, 29], state: "minecraft:deepslate_tile_stairs{facing:west,half:bottom,shape:straight,waterlogged:false}"},
        {pos: [3, 2, 30], state: "minecraft:chiseled_deepslate"},
        {pos: [3, 2, 31], state: "minecraft:chiseled_deepslate"},
        {pos: [3, 2, 32], state: "minecraft:gray_wool"},
        {pos: [3, 2, 33], state: "minecraft:chiseled_deepslate"},
        {pos: [3, 2, 34], state: "minecraft:chiseled_deepslate"},
        {pos: [3, 2, 35], state: "minecraft:gray_wool"},
        {pos: [3, 2, 36], state: "minecraft:chiseled_deepslate"},
        {pos: [3, 2, 37], state: "minecraft:chiseled_deepslate"},
        {pos: [3, 2, 38], state: "minecraft:gray_wool"},
        {pos: [3, 2, 39], state: "minecraft:chiseled_deepslate"},
        {pos: [3, 2, 40], state: "minecraft:chiseled_deepslate"},
        {pos: [10, 2, 1], state: "minecraft:gray_wool"},
        {pos: [10, 2, 2], state: "minecraft:gray_wool"},
        {pos: [10, 2, 3], state: "minecraft:gray_wool"},
        {pos: [10, 2, 4], state: "minecraft:gray_wool"},
        {pos: [10, 2, 8], state: "minecraft:gray_wool"},
        {pos: [10, 2, 9], state: "minecraft:gray_wool"},
        {pos: [10, 2, 10], state: "minecraft:gray_wool"},
        {pos: [10, 2, 11], state: "minecraft:gray_wool"},
        {pos: [10, 2, 15], state: "minecraft:gray_wool"},
        {pos: [10, 2, 16], state: "minecraft:gray_wool"},
        {pos: [10, 2, 17], state: "minecraft:gray_wool"},
        {pos: [10, 2, 18], state: "minecraft:gray_wool"},
        {pos: [10, 2, 22], state: "minecraft:gray_wool"},
        {pos: [10, 2, 23], state: "minecraft:gray_wool"},
        {pos: [10, 2, 24], state: "minecraft:gray_wool"},
        {pos: [10, 2, 25], state: "minecraft:gray_wool"},
        {pos: [10, 2, 29], state: "minecraft:gray_wool"},
        {pos: [10, 2, 30], state: "minecraft:gray_wool"},
        {pos: [10, 2, 31], state: "minecraft:gray_wool"},
        {pos: [10, 2, 32], state: "minecraft:gray_wool"},
        {pos: [10, 2, 36], state: "minecraft:gray_wool"},
        {pos: [10, 2, 37], state: "minecraft:gray_wool"},
        {pos: [10, 2, 38], state: "minecraft:gray_wool"},
        {pos: [10, 2, 39], state: "minecraft:gray_wool"},
        {pos: [11, 2, 0], state: "minecraft:deepslate_bricks"},
        {pos: [11, 2, 1], state: "minecraft:deepslate_bricks"},
        {pos: [11, 2, 2], state: "minecraft:deepslate_bricks"},
        {pos: [11, 2, 3], state: "minecraft:deepslate_bricks"},
        {pos: [11, 2, 4], state: "minecraft:deepslate_bricks"},
        {pos: [11, 2, 5], state: "minecraft:deepslate_bricks"},
        {pos: [11, 2, 6], state: "minecraft:deepslate_bricks"},
        {pos: [11, 2, 7], state: "minecraft:deepslate_bricks"},
        {pos: [11, 2, 8], state: "minecraft:deepslate_bricks"},
        {pos: [11, 2, 9], state: "minecraft:deepslate_bricks"},
        {pos: [11, 2, 10], state: "minecraft:deepslate_bricks"},
        {pos: [11, 2, 11], state: "minecraft:deepslate_bricks"},
        {pos: [11, 2, 12], state: "minecraft:deepslate_bricks"},
        {pos: [11, 2, 13], state: "minecraft:deepslate_bricks"},
        {pos: [11, 2, 14], state: "minecraft:deepslate_bricks"},
        {pos: [11, 2, 15], state: "minecraft:deepslate_bricks"},
        {pos: [11, 2, 16], state: "minecraft:deepslate_bricks"},
        {pos: [11, 2, 17], state: "minecraft:deepslate_bricks"},
        {pos: [11, 2, 18], state: "minecraft:deepslate_bricks"},
        {pos: [11, 2, 19], state: "minecraft:deepslate_bricks"},
        {pos: [11, 2, 20], state: "minecraft:deepslate_bricks"},
        {pos: [11, 2, 21], state: "minecraft:deepslate_bricks"},
        {pos: [11, 2, 22], state: "minecraft:deepslate_bricks"},
        {pos: [11, 2, 23], state: "minecraft:deepslate_bricks"},
        {pos: [11, 2, 24], state: "minecraft:deepslate_bricks"},
        {pos: [11, 2, 25], state: "minecraft:deepslate_bricks"},
        {pos: [11, 2, 26], state: "minecraft:deepslate_bricks"},
        {pos: [11, 2, 27], state: "minecraft:deepslate_bricks"},
        {pos: [11, 2, 28], state: "minecraft:deepslate_bricks"},
        {pos: [11, 2, 29], state: "minecraft:deepslate_bricks"},
        {pos: [11, 2, 30], state: "minecraft:deepslate_bricks"},
        {pos: [11, 2, 31], state: "minecraft:deepslate_bricks"},
        {pos: [11, 2, 32], state: "minecraft:deepslate_bricks"},
        {pos: [11, 2, 33], state: "minecraft:deepslate_bricks"},
        {pos: [11, 2, 34], state: "minecraft:deepslate_bricks"},
        {pos: [11, 2, 35], state: "minecraft:deepslate_bricks"},
        {pos: [11, 2, 36], state: "minecraft:deepslate_bricks"},
        {pos: [11, 2, 37], state: "minecraft:deepslate_bricks"},
        {pos: [11, 2, 38], state: "minecraft:deepslate_bricks"},
        {pos: [11, 2, 39], state: "minecraft:deepslate_bricks"},
        {pos: [11, 2, 40], state: "minecraft:deepslate_bricks"},
        {pos: [12, 2, 0], state: "minecraft:gray_wool"},
        {pos: [12, 2, 1], state: "minecraft:gray_wool"},
        {pos: [12, 2, 2], state: "minecraft:gray_wool"},
        {pos: [12, 2, 3], state: "minecraft:gray_wool"},
        {pos: [12, 2, 4], state: "minecraft:gray_wool"},
        {pos: [12, 2, 5], state: "minecraft:gray_wool"},
        {pos: [12, 2, 6], state: "minecraft:gray_wool"},
        {pos: [12, 2, 7], state: "minecraft:gray_wool"},
        {pos: [12, 2, 8], state: "minecraft:gray_wool"},
        {pos: [12, 2, 9], state: "minecraft:gray_wool"},
        {pos: [12, 2, 10], state: "minecraft:gray_wool"},
        {pos: [12, 2, 11], state: "minecraft:gray_wool"},
        {pos: [12, 2, 12], state: "minecraft:gray_wool"},
        {pos: [12, 2, 13], state: "minecraft:gray_wool"},
        {pos: [12, 2, 14], state: "minecraft:gray_wool"},
        {pos: [12, 2, 15], state: "minecraft:gray_wool"},
        {pos: [12, 2, 16], state: "minecraft:gray_wool"},
        {pos: [12, 2, 17], state: "minecraft:gray_wool"},
        {pos: [12, 2, 18], state: "minecraft:gray_wool"},
        {pos: [12, 2, 19], state: "minecraft:gray_wool"},
        {pos: [12, 2, 20], state: "minecraft:gray_wool"},
        {pos: [12, 2, 21], state: "minecraft:gray_wool"},
        {pos: [12, 2, 22], state: "minecraft:gray_wool"},
        {pos: [12, 2, 23], state: "minecraft:gray_wool"},
        {pos: [12, 2, 24], state: "minecraft:gray_wool"},
        {pos: [12, 2, 25], state: "minecraft:gray_wool"},
        {pos: [12, 2, 26], state: "minecraft:gray_wool"},
        {pos: [12, 2, 27], state: "minecraft:gray_wool"},
        {pos: [12, 2, 28], state: "minecraft:gray_wool"},
        {pos: [12, 2, 29], state: "minecraft:gray_wool"},
        {pos: [12, 2, 30], state: "minecraft:gray_wool"},
        {pos: [12, 2, 31], state: "minecraft:gray_wool"},
        {pos: [12, 2, 32], state: "minecraft:gray_wool"},
        {pos: [12, 2, 33], state: "minecraft:gray_wool"},
        {pos: [12, 2, 34], state: "minecraft:gray_wool"},
        {pos: [12, 2, 35], state: "minecraft:gray_wool"},
        {pos: [12, 2, 36], state: "minecraft:gray_wool"},
        {pos: [12, 2, 37], state: "minecraft:gray_wool"},
        {pos: [12, 2, 38], state: "minecraft:gray_wool"},
        {pos: [12, 2, 39], state: "minecraft:gray_wool"},
        {pos: [12, 2, 40], state: "minecraft:gray_wool"},
        {pos: [13, 2, 1], state: "minecraft:deepslate{axis:y}"},
        {pos: [13, 2, 2], state: "minecraft:deepslate{axis:y}"},
        {pos: [13, 2, 3], state: "minecraft:deepslate{axis:y}"},
        {pos: [13, 2, 4], state: "minecraft:deepslate{axis:y}"},
        {pos: [13, 2, 5], state: "minecraft:deepslate{axis:y}"},
        {pos: [13, 2, 6], state: "minecraft:deepslate{axis:y}"},
        {pos: [13, 2, 7], state: "minecraft:deepslate{axis:y}"},
        {pos: [13, 2, 8], state: "minecraft:deepslate{axis:y}"},
        {pos: [13, 2, 9], state: "minecraft:deepslate{axis:y}"},
        {pos: [13, 2, 10], state: "minecraft:deepslate{axis:y}"},
        {pos: [13, 2, 11], state: "minecraft:deepslate{axis:y}"},
        {pos: [13, 2, 12], state: "minecraft:deepslate{axis:y}"},
        {pos: [13, 2, 13], state: "minecraft:deepslate{axis:y}"},
        {pos: [13, 2, 14], state: "minecraft:deepslate{axis:y}"},
        {pos: [13, 2, 15], state: "minecraft:deepslate{axis:y}"},
        {pos: [13, 2, 16], state: "minecraft:deepslate{axis:y}"},
        {pos: [13, 2, 17], state: "minecraft:deepslate{axis:y}"},
        {pos: [13, 2, 18], state: "minecraft:deepslate{axis:y}"},
        {pos: [13, 2, 19], state: "minecraft:deepslate{axis:y}"},
        {pos: [13, 2, 20], state: "minecraft:deepslate{axis:y}"},
        {pos: [13, 2, 21], state: "minecraft:deepslate{axis:y}"},
        {pos: [13, 2, 22], state: "minecraft:deepslate{axis:y}"},
        {pos: [13, 2, 23], state: "minecraft:deepslate{axis:y}"},
        {pos: [13, 2, 24], state: "minecraft:deepslate{axis:y}"},
        {pos: [13, 2, 25], state: "minecraft:deepslate{axis:y}"},
        {pos: [13, 2, 26], state: "minecraft:deepslate{axis:y}"},
        {pos: [13, 2, 27], state: "minecraft:deepslate{axis:y}"},
        {pos: [13, 2, 28], state: "minecraft:deepslate{axis:y}"},
        {pos: [13, 2, 29], state: "minecraft:deepslate{axis:y}"},
        {pos: [13, 2, 30], state: "minecraft:deepslate{axis:y}"},
        {pos: [13, 2, 31], state: "minecraft:deepslate{axis:y}"},
        {pos: [13, 2, 32], state: "minecraft:deepslate{axis:y}"},
        {pos: [13, 2, 33], state: "minecraft:deepslate{axis:y}"},
        {pos: [13, 2, 34], state: "minecraft:deepslate{axis:y}"},
        {pos: [13, 2, 35], state: "minecraft:deepslate{axis:y}"},
        {pos: [13, 2, 36], state: "minecraft:deepslate{axis:y}"},
        {pos: [13, 2, 37], state: "minecraft:deepslate{axis:y}"},
        {pos: [13, 2, 38], state: "minecraft:deepslate{axis:y}"},
        {pos: [13, 2, 39], state: "minecraft:deepslate{axis:y}"},
        {pos: [13, 2, 40], state: "minecraft:deepslate{axis:y}"},
        {pos: [0, 3, 0], state: "minecraft:deepslate_tile_stairs{facing:east,half:bottom,shape:straight,waterlogged:false}"},
        {pos: [0, 3, 1], state: "minecraft:deepslate_tile_stairs{facing:east,half:bottom,shape:straight,waterlogged:false}"},
        {pos: [0, 3, 2], state: "minecraft:deepslate_tile_stairs{facing:east,half:bottom,shape:straight,waterlogged:false}"},
        {pos: [0, 3, 3], state: "minecraft:deepslate_bricks"},
        {pos: [0, 3, 4], state: "minecraft:chiseled_deepslate"},
        {pos: [0, 3, 5], state: "minecraft:chiseled_deepslate"},
        {pos: [0, 3, 6], state: "minecraft:deepslate_bricks"},
        {pos: [0, 3, 7], state: "minecraft:deepslate_tile_stairs{facing:east,half:bottom,shape:straight,waterlogged:false}"},
        {pos: [0, 3, 8], state: "minecraft:deepslate_tile_stairs{facing:east,half:bottom,shape:straight,waterlogged:false}"},
        {pos: [0, 3, 9], state: "minecraft:deepslate_tile_stairs{facing:east,half:bottom,shape:straight,waterlogged:false}"},
        {pos: [0, 3, 10], state: "minecraft:deepslate_tile_stairs{facing:east,half:bottom,shape:straight,waterlogged:false}"},
        {pos: [0, 3, 11], state: "minecraft:deepslate_tile_stairs{facing:east,half:bottom,shape:straight,waterlogged:false}"},
        {pos: [0, 3, 12], state: "minecraft:deepslate_bricks"},
        {pos: [0, 3, 13], state: "minecraft:chiseled_deepslate"},
        {pos: [0, 3, 14], state: "minecraft:chiseled_deepslate"},
        {pos: [0, 3, 15], state: "minecraft:deepslate_bricks"},
        {pos: [0, 3, 16], state: "minecraft:deepslate_tile_stairs{facing:east,half:bottom,shape:straight,waterlogged:false}"},
        {pos: [0, 3, 17], state: "minecraft:deepslate_tile_stairs{facing:east,half:bottom,shape:straight,waterlogged:false}"},
        {pos: [0, 3, 18], state: "minecraft:deepslate_bricks"},
        {pos: [0, 3, 19], state: "minecraft:deepslate_bricks"},
        {pos: [0, 3, 20], state: "minecraft:deepslate_bricks"},
        {pos: [0, 3, 21], state: "minecraft:deepslate_bricks"},
        {pos: [0, 3, 22], state: "minecraft:deepslate_bricks"},
        {pos: [0, 3, 23], state: "minecraft:deepslate_tile_stairs{facing:east,half:bottom,shape:straight,waterlogged:false}"},
        {pos: [0, 3, 24], state: "minecraft:deepslate_tile_stairs{facing:east,half:bottom,shape:straight,waterlogged:false}"},
        {pos: [0, 3, 25], state: "minecraft:deepslate_bricks"},
        {pos: [0, 3, 26], state: "minecraft:chiseled_deepslate"},
        {pos: [0, 3, 27], state: "minecraft:chiseled_deepslate"},
        {pos: [0, 3, 28], state: "minecraft:deepslate_bricks"},
        {pos: [0, 3, 29], state: "minecraft:cracked_deepslate_tiles"},
        {pos: [0, 3, 30], state: "minecraft:deepslate_tile_stairs{facing:east,half:bottom,shape:outer_right,waterlogged:false}"},
        {pos: [0, 3, 31], state: "minecraft:deepslate_tile_stairs{facing:east,half:bottom,shape:straight,waterlogged:false}"},
        {pos: [0, 3, 32], state: "minecraft:deepslate_tile_stairs{facing:east,half:bottom,shape:straight,waterlogged:false}"},
        {pos: [0, 3, 33], state: "minecraft:deepslate_tile_stairs{facing:east,half:bottom,shape:straight,waterlogged:false}"},
        {pos: [0, 3, 34], state: "minecraft:deepslate_bricks"},
        {pos: [0, 3, 35], state: "minecraft:chiseled_deepslate"},
        {pos: [0, 3, 36], state: "minecraft:chiseled_deepslate"},
        {pos: [0, 3, 37], state: "minecraft:deepslate_bricks"},
        {pos: [0, 3, 38], state: "minecraft:deepslate_tile_stairs{facing:east,half:bottom,shape:straight,waterlogged:false}"},
        {pos: [0, 3, 39], state: "minecraft:deepslate_tile_stairs{facing:east,half:bottom,shape:straight,waterlogged:false}"},
        {pos: [0, 3, 40], state: "minecraft:deepslate_tile_stairs{facing:east,half:bottom,shape:straight,waterlogged:false}"},
        {pos: [1, 3, 0], state: "minecraft:gray_wool"},
        {pos: [1, 3, 1], state: "minecraft:gray_wool"},
        {pos: [1, 3, 2], state: "minecraft:gray_wool"},
        {pos: [1, 3, 3], state: "minecraft:gray_wool"},
        {pos: [1, 3, 4], state: "minecraft:gray_wool"},
        {pos: [1, 3, 5], state: "minecraft:gray_wool"},
        {pos: [1, 3, 6], state: "minecraft:gray_wool"},
        {pos: [1, 3, 7], state: "minecraft:gray_wool"},
        {pos: [1, 3, 8], state: "minecraft:gray_wool"},
        {pos: [1, 3, 9], state: "minecraft:gray_wool"},
        {pos: [1, 3, 10], state: "minecraft:deepslate_tile_stairs{facing:north,half:bottom,shape:straight,waterlogged:false}"},
        {pos: [1, 3, 12], state: "minecraft:deepslate_tile_stairs{facing:south,half:bottom,shape:straight,waterlogged:false}"},
        {pos: [1, 3, 13], state: "minecraft:gray_wool"},
        {pos: [1, 3, 14], state: "minecraft:gray_wool"},
        {pos: [1, 3, 15], state: "minecraft:gray_wool"},
        {pos: [1, 3, 16], state: "minecraft:gray_wool"},
        {pos: [1, 3, 17], state: "minecraft:gray_wool"},
        {pos: [1, 3, 18], state: "minecraft:gray_wool"},
        {pos: [1, 3, 19], state: "minecraft:gray_wool"},
        {pos: [1, 3, 20], state: "minecraft:gray_wool"},
        {pos: [1, 3, 21], state: "minecraft:gray_wool"},
        {pos: [1, 3, 22], state: "minecraft:gray_wool"},
        {pos: [1, 3, 23], state: "minecraft:gray_wool"},
        {pos: [1, 3, 24], state: "minecraft:gray_wool"},
        {pos: [1, 3, 25], state: "minecraft:gray_wool"},
        {pos: [1, 3, 26], state: "minecraft:gray_wool"},
        {pos: [1, 3, 27], state: "minecraft:deepslate_bricks"},
        {pos: [1, 3, 28], state: "minecraft:deepslate_tile_stairs{facing:north,half:bottom,shape:straight,waterlogged:false}"},
        {pos: [1, 3, 30], state: "minecraft:deepslate_tile_stairs{facing:south,half:bottom,shape:straight,waterlogged:false}"},
        {pos: [1, 3, 31], state: "minecraft:gray_wool"},
        {pos: [1, 3, 32], state: "minecraft:gray_wool"},
        {pos: [1, 3, 33], state: "minecraft:gray_wool"},
        {pos: [1, 3, 34], state: "minecraft:gray_wool"},
        {pos: [1, 3, 35], state: "minecraft:gray_wool"},
        {pos: [1, 3, 36], state: "minecraft:gray_wool"},
        {pos: [1, 3, 37], state: "minecraft:gray_wool"},
        {pos: [1, 3, 38], state: "minecraft:gray_wool"},
        {pos: [1, 3, 39], state: "minecraft:gray_wool"},
        {pos: [1, 3, 40], state: "minecraft:gray_wool"},
        {pos: [2, 3, 0], state: "minecraft:gray_wool"},
        {pos: [2, 3, 1], state: "minecraft:gray_wool"},
        {pos: [2, 3, 2], state: "minecraft:gray_wool"},
        {pos: [2, 3, 3], state: "minecraft:gray_wool"},
        {pos: [2, 3, 4], state: "minecraft:gray_wool"},
        {pos: [2, 3, 5], state: "minecraft:gray_wool"},
        {pos: [2, 3, 6], state: "minecraft:gray_wool"},
        {pos: [2, 3, 7], state: "minecraft:gray_wool"},
        {pos: [2, 3, 8], state: "minecraft:gray_wool"},
        {pos: [2, 3, 9], state: "minecraft:gray_wool"},
        {pos: [2, 3, 10], state: "minecraft:gray_wool"},
        {pos: [2, 3, 12], state: "minecraft:gray_wool"},
        {pos: [2, 3, 13], state: "minecraft:gray_wool"},
        {pos: [2, 3, 14], state: "minecraft:gray_wool"},
        {pos: [2, 3, 15], state: "minecraft:gray_wool"},
        {pos: [2, 3, 16], state: "minecraft:gray_wool"},
        {pos: [2, 3, 17], state: "minecraft:gray_wool"},
        {pos: [2, 3, 18], state: "minecraft:gray_wool"},
        {pos: [2, 3, 19], state: "minecraft:gray_wool"},
        {pos: [2, 3, 20], state: "minecraft:gray_wool"},
        {pos: [2, 3, 21], state: "minecraft:gray_wool"},
        {pos: [2, 3, 22], state: "minecraft:gray_wool"},
        {pos: [2, 3, 23], state: "minecraft:gray_wool"},
        {pos: [2, 3, 24], state: "minecraft:gray_wool"},
        {pos: [2, 3, 25], state: "minecraft:gray_wool"},
        {pos: [2, 3, 26], state: "minecraft:gray_wool"},
        {pos: [2, 3, 27], state: "minecraft:gray_wool"},
        {pos: [2, 3, 28], state: "minecraft:gray_wool"},
        {pos: [2, 3, 30], state: "minecraft:gray_wool"},
        {pos: [2, 3, 31], state: "minecraft:gray_wool"},
        {pos: [2, 3, 32], state: "minecraft:gray_wool"},
        {pos: [2, 3, 33], state: "minecraft:gray_wool"},
        {pos: [2, 3, 34], state: "minecraft:gray_wool"},
        {pos: [2, 3, 35], state: "minecraft:gray_wool"},
        {pos: [2, 3, 36], state: "minecraft:gray_wool"},
        {pos: [2, 3, 37], state: "minecraft:gray_wool"},
        {pos: [2, 3, 38], state: "minecraft:gray_wool"},
        {pos: [2, 3, 39], state: "minecraft:gray_wool"},
        {pos: [2, 3, 40], state: "minecraft:gray_wool"},
        {pos: [3, 3, 0], state: "minecraft:deepslate_tile_stairs{facing:west,half:bottom,shape:straight,waterlogged:false}"},
        {pos: [3, 3, 1], state: "minecraft:deepslate_tile_stairs{facing:west,half:bottom,shape:straight,waterlogged:false}"},
        {pos: [3, 3, 2], state: "minecraft:gray_wool"},
        {pos: [3, 3, 3], state: "minecraft:deepslate_tile_stairs{facing:west,half:bottom,shape:straight,waterlogged:false}"},
        {pos: [3, 3, 4], state: "minecraft:deepslate_tile_stairs{facing:west,half:bottom,shape:straight,waterlogged:false}"},
        {pos: [3, 3, 5], state: "minecraft:gray_wool"},
        {pos: [3, 3, 6], state: "minecraft:deepslate_tile_stairs{facing:west,half:bottom,shape:straight,waterlogged:false}"},
        {pos: [3, 3, 7], state: "minecraft:deepslate_tile_stairs{facing:west,half:bottom,shape:straight,waterlogged:false}"},
        {pos: [3, 3, 8], state: "minecraft:gray_wool"},
        {pos: [3, 3, 9], state: "minecraft:deepslate_tile_stairs{facing:west,half:bottom,shape:straight,waterlogged:false}"},
        {pos: [3, 3, 10], state: "minecraft:deepslate_tile_stairs{facing:west,half:bottom,shape:straight,waterlogged:false}"},
        {pos: [3, 3, 12], state: "minecraft:deepslate_tile_stairs{facing:west,half:top,shape:straight,waterlogged:false}"},
        {pos: [3, 3, 13], state: "minecraft:chiseled_deepslate"},
        {pos: [3, 3, 14], state: "minecraft:deepslate_tile_stairs{facing:west,half:top,shape:straight,waterlogged:false}"},
        {pos: [3, 3, 15], state: "minecraft:gray_wool"},
        {pos: [3, 3, 16], state: "minecraft:deepslate_tile_stairs{facing:west,half:bottom,shape:straight,waterlogged:false}"},
        {pos: [3, 3, 17], state: "minecraft:deepslate_tile_stairs{facing:west,half:bottom,shape:straight,waterlogged:false}"},
        {pos: [3, 3, 18], state: "minecraft:gray_wool"},
        {pos: [3, 3, 19], state: "minecraft:deepslate_tile_stairs{facing:west,half:top,shape:straight,waterlogged:false}"},
        {pos: [3, 3, 20], state: "minecraft:chiseled_deepslate"},
        {pos: [3, 3, 21], state: "minecraft:deepslate_tile_stairs{facing:west,half:top,shape:straight,waterlogged:false}"},
        {pos: [3, 3, 22], state: "minecraft:gray_wool"},
        {pos: [3, 3, 23], state: "minecraft:deepslate_tile_stairs{facing:west,half:bottom,shape:straight,waterlogged:false}"},
        {pos: [3, 3, 24], state: "minecraft:deepslate_tile_stairs{facing:west,half:bottom,shape:straight,waterlogged:false}"},
        {pos: [3, 3, 25], state: "minecraft:gray_wool"},
        {pos: [3, 3, 26], state: "minecraft:deepslate_tile_stairs{facing:west,half:top,shape:straight,waterlogged:false}"},
        {pos: [3, 3, 27], state: "minecraft:chiseled_deepslate"},
        {pos: [3, 3, 28], state: "minecraft:deepslate_tile_stairs{facing:west,half:top,shape:straight,waterlogged:false}"},
        {pos: [3, 3, 30], state: "minecraft:deepslate_tile_stairs{facing:west,half:bottom,shape:straight,waterlogged:false}"},
        {pos: [3, 3, 31], state: "minecraft:deepslate_tile_stairs{facing:west,half:bottom,shape:straight,waterlogged:false}"},
        {pos: [3, 3, 32], state: "minecraft:gray_wool"},
        {pos: [3, 3, 33], state: "minecraft:deepslate_tile_stairs{facing:west,half:bottom,shape:straight,waterlogged:false}"},
        {pos: [3, 3, 34], state: "minecraft:deepslate_tile_stairs{facing:west,half:bottom,shape:straight,waterlogged:false}"},
        {pos: [3, 3, 35], state: "minecraft:gray_wool"},
        {pos: [3, 3, 36], state: "minecraft:deepslate_tile_stairs{facing:west,half:bottom,shape:straight,waterlogged:false}"},
        {pos: [3, 3, 37], state: "minecraft:deepslate_tile_stairs{facing:west,half:bottom,shape:straight,waterlogged:false}"},
        {pos: [3, 3, 38], state: "minecraft:gray_wool"},
        {pos: [3, 3, 39], state: "minecraft:deepslate_tile_stairs{facing:west,half:bottom,shape:straight,waterlogged:false}"},
        {pos: [3, 3, 40], state: "minecraft:deepslate_tile_stairs{facing:west,half:bottom,shape:straight,waterlogged:false}"},
        {pos: [10, 3, 0], state: "minecraft:deepslate_tile_stairs{facing:east,half:top,shape:straight,waterlogged:false}"},
        {pos: [10, 3, 1], state: "minecraft:gray_wool"},
        {pos: [10, 3, 2], state: "minecraft:gray_wool"},
        {pos: [10, 3, 3], state: "minecraft:gray_wool"},
        {pos: [10, 3, 4], state: "minecraft:gray_wool"},
        {pos: [10, 3, 5], state: "minecraft:deepslate_tile_stairs{facing:east,half:top,shape:straight,waterlogged:false}"},
        {pos: [10, 3, 6], state: "minecraft:chiseled_deepslate"},
        {pos: [10, 3, 7], state: "minecraft:deepslate_tile_stairs{facing:east,half:top,shape:straight,waterlogged:false}"},
        {pos: [10, 3, 8], state: "minecraft:gray_wool"},
        {pos: [10, 3, 9], state: "minecraft:gray_wool"},
        {pos: [10, 3, 10], state: "minecraft:gray_wool"},
        {pos: [10, 3, 11], state: "minecraft:gray_wool"},
        {pos: [10, 3, 12], state: "minecraft:deepslate_tile_stairs{facing:east,half:top,shape:straight,waterlogged:false}"},
        {pos: [10, 3, 13], state: "minecraft:chiseled_deepslate"},
        {pos: [10, 3, 14], state: "minecraft:deepslate_tile_stairs{facing:east,half:top,shape:straight,waterlogged:false}"},
        {pos: [10, 3, 15], state: "minecraft:gray_wool"},
        {pos: [10, 3, 16], state: "minecraft:gray_wool"},
        {pos: [10, 3, 17], state: "minecraft:gray_wool"},
        {pos: [10, 3, 18], state: "minecraft:gray_wool"},
        {pos: [10, 3, 19], state: "minecraft:deepslate_tile_stairs{facing:east,half:top,shape:straight,waterlogged:false}"},
        {pos: [10, 3, 20], state: "minecraft:chiseled_deepslate"},
        {pos: [10, 3, 21], state: "minecraft:deepslate_tile_stairs{facing:east,half:top,shape:straight,waterlogged:false}"},
        {pos: [10, 3, 22], state: "minecraft:gray_wool"},
        {pos: [10, 3, 23], state: "minecraft:gray_wool"},
        {pos: [10, 3, 24], state: "minecraft:gray_wool"},
        {pos: [10, 3, 25], state: "minecraft:gray_wool"},
        {pos: [10, 3, 26], state: "minecraft:deepslate_tile_stairs{facing:east,half:top,shape:straight,waterlogged:false}"},
        {pos: [10, 3, 27], state: "minecraft:chiseled_deepslate"},
        {pos: [10, 3, 28], state: "minecraft:deepslate_tile_stairs{facing:east,half:top,shape:straight,waterlogged:false}"},
        {pos: [10, 3, 29], state: "minecraft:gray_wool"},
        {pos: [10, 3, 30], state: "minecraft:gray_wool"},
        {pos: [10, 3, 31], state: "minecraft:gray_wool"},
        {pos: [10, 3, 32], state: "minecraft:gray_wool"},
        {pos: [10, 3, 33], state: "minecraft:deepslate_tile_stairs{facing:east,half:top,shape:straight,waterlogged:false}"},
        {pos: [10, 3, 34], state: "minecraft:chiseled_deepslate"},
        {pos: [10, 3, 35], state: "minecraft:deepslate_tile_stairs{facing:east,half:top,shape:straight,waterlogged:false}"},
        {pos: [10, 3, 36], state: "minecraft:gray_wool"},
        {pos: [10, 3, 37], state: "minecraft:gray_wool"},
        {pos: [10, 3, 38], state: "minecraft:gray_wool"},
        {pos: [10, 3, 39], state: "minecraft:gray_wool"},
        {pos: [10, 3, 40], state: "minecraft:deepslate_tile_stairs{facing:east,half:top,shape:straight,waterlogged:false}"},
        {pos: [11, 3, 0], state: "minecraft:deepslate_bricks"},
        {pos: [11, 3, 1], state: "minecraft:deepslate_bricks"},
        {pos: [11, 3, 2], state: "minecraft:deepslate_bricks"},
        {pos: [11, 3, 3], state: "minecraft:deepslate_bricks"},
        {pos: [11, 3, 4], state: "minecraft:deepslate_bricks"},
        {pos: [11, 3, 5], state: "minecraft:deepslate_bricks"},
        {pos: [11, 3, 6], state: "minecraft:deepslate_bricks"},
        {pos: [11, 3, 7], state: "minecraft:deepslate_bricks"},
        {pos: [11, 3, 8], state: "minecraft:deepslate_bricks"},
        {pos: [11, 3, 9], state: "minecraft:deepslate_bricks"},
        {pos: [11, 3, 10], state: "minecraft:deepslate_bricks"},
        {pos: [11, 3, 11], state: "minecraft:deepslate_bricks"},
        {pos: [11, 3, 12], state: "minecraft:deepslate_bricks"},
        {pos: [11, 3, 13], state: "minecraft:deepslate_bricks"},
        {pos: [11, 3, 14], state: "minecraft:deepslate_bricks"},
        {pos: [11, 3, 15], state: "minecraft:deepslate_bricks"},
        {pos: [11, 3, 16], state: "minecraft:deepslate_bricks"},
        {pos: [11, 3, 17], state: "minecraft:deepslate_bricks"},
        {pos: [11, 3, 18], state: "minecraft:deepslate_bricks"},
        {pos: [11, 3, 19], state: "minecraft:deepslate_bricks"},
        {pos: [11, 3, 20], state: "minecraft:deepslate_bricks"},
        {pos: [11, 3, 21], state: "minecraft:deepslate_bricks"},
        {pos: [11, 3, 22], state: "minecraft:deepslate_bricks"},
        {pos: [11, 3, 23], state: "minecraft:deepslate_bricks"},
        {pos: [11, 3, 24], state: "minecraft:deepslate_bricks"},
        {pos: [11, 3, 25], state: "minecraft:deepslate_bricks"},
        {pos: [11, 3, 26], state: "minecraft:deepslate_bricks"},
        {pos: [11, 3, 27], state: "minecraft:deepslate_bricks"},
        {pos: [11, 3, 28], state: "minecraft:deepslate_bricks"},
        {pos: [11, 3, 29], state: "minecraft:deepslate_bricks"},
        {pos: [11, 3, 30], state: "minecraft:deepslate_bricks"},
        {pos: [11, 3, 31], state: "minecraft:deepslate_bricks"},
        {pos: [11, 3, 32], state: "minecraft:deepslate_bricks"},
        {pos: [11, 3, 33], state: "minecraft:deepslate_bricks"},
        {pos: [11, 3, 34], state: "minecraft:deepslate_bricks"},
        {pos: [11, 3, 35], state: "minecraft:deepslate_bricks"},
        {pos: [11, 3, 36], state: "minecraft:deepslate_bricks"},
        {pos: [11, 3, 37], state: "minecraft:deepslate_bricks"},
        {pos: [11, 3, 38], state: "minecraft:deepslate_bricks"},
        {pos: [11, 3, 39], state: "minecraft:deepslate_bricks"},
        {pos: [11, 3, 40], state: "minecraft:deepslate_bricks"},
        {pos: [12, 3, 0], state: "minecraft:gray_wool"},
        {pos: [12, 3, 1], state: "minecraft:gray_wool"},
        {pos: [12, 3, 2], state: "minecraft:gray_wool"},
        {pos: [12, 3, 3], state: "minecraft:gray_wool"},
        {pos: [12, 3, 4], state: "minecraft:gray_wool"},
        {pos: [12, 3, 5], state: "minecraft:gray_wool"},
        {pos: [12, 3, 6], state: "minecraft:gray_wool"},
        {pos: [12, 3, 7], state: "minecraft:gray_wool"},
        {pos: [12, 3, 8], state: "minecraft:gray_wool"},
        {pos: [12, 3, 9], state: "minecraft:gray_wool"},
        {pos: [12, 3, 10], state: "minecraft:gray_wool"},
        {pos: [12, 3, 11], state: "minecraft:gray_wool"},
        {pos: [12, 3, 12], state: "minecraft:gray_wool"},
        {pos: [12, 3, 13], state: "minecraft:gray_wool"},
        {pos: [12, 3, 14], state: "minecraft:gray_wool"},
        {pos: [12, 3, 15], state: "minecraft:gray_wool"},
        {pos: [12, 3, 16], state: "minecraft:gray_wool"},
        {pos: [12, 3, 17], state: "minecraft:gray_wool"},
        {pos: [12, 3, 18], state: "minecraft:gray_wool"},
        {pos: [12, 3, 19], state: "minecraft:gray_wool"},
        {pos: [12, 3, 20], state: "minecraft:gray_wool"},
        {pos: [12, 3, 21], state: "minecraft:gray_wool"},
        {pos: [12, 3, 22], state: "minecraft:gray_wool"},
        {pos: [12, 3, 23], state: "minecraft:gray_wool"},
        {pos: [12, 3, 24], state: "minecraft:gray_wool"},
        {pos: [12, 3, 25], state: "minecraft:gray_wool"},
        {pos: [12, 3, 26], state: "minecraft:gray_wool"},
        {pos: [12, 3, 27], state: "minecraft:gray_wool"},
        {pos: [12, 3, 28], state: "minecraft:gray_wool"},
        {pos: [12, 3, 29], state: "minecraft:gray_wool"},
        {pos: [12, 3, 30], state: "minecraft:gray_wool"},
