{
    size: [18, 24, 14],
    data: [
        {pos: [0, 0, 0], state: "minecraft:jigsaw{orientation:north_up}", nbt: {final_state: "minecraft:deepslate", id: "minecraft:jigsaw", joint: "rollable", name: "minecraft:connect_right", pool: "minecraft:empty", target: "minecraft:empty"}},
        {pos: [0, 0, 1], state: "minecraft:deepslate_bricks"},
        {pos: [0, 0, 2], state: "minecraft:deepslate_bricks"},
        {pos: [0, 0, 3], state: "minecraft:deepslate_bricks"},
        {pos: [0, 0, 4], state: "minecraft:deepslate_bricks"},
        {pos: [0, 0, 5], state: "minecraft:deepslate_bricks"},
        {pos: [0, 0, 6], state: "minecraft:deepslate_bricks"},
        {pos: [0, 0, 7], state: "minecraft:deepslate_bricks"},
        {pos: [0, 0, 8], state: "minecraft:deepslate_bricks"},
        {pos: [0, 0, 9], state: "minecraft:deepslate_bricks"},
        {pos: [0, 0, 10], state: "minecraft:deepslate_bricks"},
        {pos: [0, 0, 11], state: "minecraft:deepslate_bricks"},
        {pos: [0, 0, 12], state: "minecraft:deepslate{axis:y}"},
        {pos: [1, 0, 0], state: "minecraft:deepslate{axis:y}"},
        {pos: [1, 0, 1], state: "minecraft:deepslate_bricks"},
        {pos: [1, 0, 2], state: "minecraft:deepslate_bricks"},
        {pos: [1, 0, 3], state: "minecraft:deepslate_bricks"},
        {pos: [1, 0, 4], state: "minecraft:deepslate_bricks"},
        {pos: [1, 0, 5], state: "minecraft:deepslate{axis:y}"},
        {pos: [1, 0, 6], state: "minecraft:deepslate{axis:y}"},
        {pos: [1, 0, 7], state: "minecraft:deepslate_bricks"},
        {pos: [1, 0, 8], state: "minecraft:deepslate_bricks"},
        {pos: [1, 0, 9], state: "minecraft:deepslate_bricks"},
        {pos: [1, 0, 10], state: "minecraft:deepslate_bricks"},
        {pos: [1, 0, 11], state: "minecraft:deepslate_bricks"},
        {pos: [1, 0, 12], state: "minecraft:deepslate{axis:y}"},
        {pos: [2, 0, 0], state: "minecraft:deepslate{axis:y}"},
        {pos: [2, 0, 1], state: "minecraft:deepslate_bricks"},
        {pos: [2, 0, 2], state: "minecraft:deepslate_bricks"},
        {pos: [2, 0, 3], state: "minecraft:deepslate_bricks"},
        {pos: [2, 0, 4], state: "minecraft:deepslate_bricks"},
        {pos: [2, 0, 5], state: "minecraft:deepslate{axis:y}"},
        {pos: [2, 0, 6], state: "minecraft:deepslate{axis:y}"},
        {pos: [2, 0, 7], state: "minecraft:deepslate{axis:y}"},
        {pos: [2, 0, 8], state: "minecraft:deepslate_bricks"},
        {pos: [2, 0, 9], state: "minecraft:deepslate_bricks"},
        {pos: [2, 0, 10], state: "minecraft:deepslate_bricks"},
        {pos: [2, 0, 11], state: "minecraft:deepslate_bricks"},
        {pos: [2, 0, 12], state: "minecraft:deepslate{axis:y}"},
        {pos: [3, 0, 0], state: "minecraft:deepslate{axis:y}"},
        {pos: [3, 0, 1], state: "minecraft:deepslate_bricks"},
        {pos: [3, 0, 2], state: "minecraft:deepslate_bricks"},
        {pos: [3, 0, 3], state: "minecraft:deepslate_bricks"},
        {pos: [3, 0, 4], state: "minecraft:deepslate{axis:y}"},
        {pos: [3, 0, 5], state: "minecraft:deepslate{axis:y}"},
        {pos: [3, 0, 6], state: "minecraft:deepslate{axis:y}"},
        {pos: [3, 0, 7], state: "minecraft:deepslate{axis:y}"},
        {pos: [3, 0, 8], state: "minecraft:deepslate_bricks"},
        {pos: [3, 0, 9], state: "minecraft:deepslate_bricks"},
        {pos: [3, 0, 10], state: "minecraft:deepslate_bricks"},
        {pos: [3, 0, 11], state: "minecraft:deepslate_bricks"},
        {pos: [3, 0, 12], state: "minecraft:deepslate{axis:y}"},
        {pos: [4, 0, 0], state: "minecraft:deepslate{axis:y}"},
        {pos: [4, 0, 1], state: "minecraft:deepslate_bricks"},
        {pos: [4, 0, 2], state: "minecraft:deepslate_bricks"},
        {pos: [4, 0, 3], state: "minecraft:deepslate_bricks"},
        {pos: [4, 0, 4], state: "minecraft:deepslate{axis:y}"},
        {pos: [4, 0, 5], state: "minecraft:deepslate{axis:y}"},
        {pos: [4, 0, 6], state: "minecraft:deepslate{axis:y}"},
        {pos: [4, 0, 7], state: "minecraft:deepslate_bricks"},
        {pos: [4, 0, 8], state: "minecraft:deepslate_bricks"},
        {pos: [4, 0, 9], state: "minecraft:deepslate_bricks"},
        {pos: [4, 0, 10], state: "minecraft:deepslate_bricks"},
        {pos: [4, 0, 11], state: "minecraft:deepslate_bricks"},
        {pos: [4, 0, 12], state: "minecraft:deepslate{axis:y}"},
        {pos: [5, 0, 0], state: "minecraft:deepslate{axis:y}"},
        {pos: [5, 0, 1], state: "minecraft:deepslate_bricks"},
        {pos: [5, 0, 2], state: "minecraft:deepslate_bricks"},
        {pos: [5, 0, 3], state: "minecraft:deepslate_bricks"},
        {pos: [5, 0, 4], state: "minecraft:deepslate_bricks"},
        {pos: [5, 0, 5], state: "minecraft:deepslate_bricks"},
        {pos: [5, 0, 6], state: "minecraft:deepslate_bricks"},
        {pos: [5, 0, 7], state: "minecraft:deepslate_bricks"},
        {pos: [5, 0, 8], state: "minecraft:deepslate_bricks"},
        {pos: [5, 0, 9], state: "minecraft:deepslate_bricks"},
        {pos: [5, 0, 10], state: "minecraft:deepslate_bricks"},
        {pos: [5, 0, 11], state: "minecraft:deepslate_bricks"},
        {pos: [5, 0, 12], state: "minecraft:deepslate{axis:y}"},
        {pos: [5, 0, 13], state: "minecraft:polished_deepslate_stairs{facing:east,half:bottom,shape:straight,waterlogged:false}"},
        {pos: [6, 0, 0], state: "minecraft:deepslate{axis:y}"},
        {pos: [6, 0, 1], state: "minecraft:deepslate_bricks"},
        {pos: [6, 0, 2], state: "minecraft:deepslate_bricks"},
        {pos: [6, 0, 3], state: "minecraft:deepslate_bricks"},
        {pos: [6, 0, 4], state: "minecraft:deepslate_bricks"},
        {pos: [6, 0, 5], state: "minecraft:deepslate{axis:y}"},
        {pos: [6, 0, 6], state: "minecraft:deepslate{axis:y}"},
        {pos: [6, 0, 7], state: "minecraft:deepslate_bricks"},
        {pos: [6, 0, 8], state: "minecraft:deepslate_bricks"},
        {pos: [6, 0, 9], state: "minecraft:deepslate_bricks"},
        {pos: [6, 0, 10], state: "minecraft:deepslate_bricks"},
        {pos: [6, 0, 11], state: "minecraft:deepslate_bricks"},
        {pos: [6, 0, 12], state: "minecraft:deepslate{axis:y}"},
        {pos: [6, 0, 13], state: "minecraft:deepslate_bricks"},
        {pos: [7, 0, 0], state: "minecraft:deepslate{axis:y}"},
        {pos: [7, 0, 1], state: "minecraft:deepslate_bricks"},
        {pos: [7, 0, 2], state: "minecraft:deepslate_bricks"},
        {pos: [7, 0, 3], state: "minecraft:deepslate_bricks"},
        {pos: [7, 0, 4], state: "minecraft:deepslate_bricks"},
        {pos: [7, 0, 5], state: "minecraft:deepslate{axis:y}"},
        {pos: [7, 0, 6], state: "minecraft:deepslate{axis:y}"},
        {pos: [7, 0, 7], state: "minecraft:deepslate_bricks"},
        {pos: [7, 0, 8], state: "minecraft:deepslate_bricks"},
        {pos: [7, 0, 9], state: "minecraft:deepslate_bricks"},
        {pos: [7, 0, 10], state: "minecraft:deepslate_bricks"},
        {pos: [7, 0, 11], state: "minecraft:deepslate_bricks"},
        {pos: [7, 0, 12], state: "minecraft:deepslate_bricks"},
        {pos: [7, 0, 13], state: "minecraft:deepslate_bricks"},
        {pos: [8, 0, 0], state: "minecraft:deepslate{axis:y}"},
        {pos: [8, 0, 1], state: "minecraft:deepslate_bricks"},
        {pos: [8, 0, 2], state: "minecraft:deepslate_bricks"},
        {pos: [8, 0, 3], state: "minecraft:deepslate_bricks"},
        {pos: [8, 0, 4], state: "minecraft:deepslate{axis:y}"},
        {pos: [8, 0, 5], state: "minecraft:deepslate{axis:y}"},
        {pos: [8, 0, 6], state: "minecraft:deepslate{axis:y}"},
        {pos: [8, 0, 7], state: "minecraft:deepslate_bricks"},
        {pos: [8, 0, 8], state: "minecraft:deepslate_bricks"},
        {pos: [8, 0, 9], state: "minecraft:deepslate_bricks"},
        {pos: [8, 0, 10], state: "minecraft:deepslate_bricks"},
        {pos: [8, 0, 11], state: "minecraft:deepslate_bricks"},
        {pos: [8, 0, 12], state: "minecraft:deepslate_bricks"},
        {pos: [8, 0, 13], state: "minecraft:jigsaw{orientation:south_up}", nbt: {final_state: "minecraft:deepslate_bricks", id: "minecraft:jigsaw", joint: "rollable", name: "minecraft:empty", pool: "minecraft:ancient_city/walls", target: "minecraft:connect_wall"}},
        {pos: [9, 0, 0], state: "minecraft:deepslate{axis:y}"},
        {pos: [9, 0, 1], state: "minecraft:deepslate_bricks"},
        {pos: [9, 0, 2], state: "minecraft:deepslate_bricks"},
        {pos: [9, 0, 3], state: "minecraft:deepslate_bricks"},
        {pos: [9, 0, 4], state: "minecraft:deepslate{axis:y}"},
        {pos: [9, 0, 5], state: "minecraft:deepslate{axis:y}"},
        {pos: [9, 0, 6], state: "minecraft:deepslate_bricks"},
        {pos: [9, 0, 7], state: "minecraft:deepslate_bricks"},
        {pos: [9, 0, 8], state: "minecraft:deepslate_bricks"},
        {pos: [9, 0, 9], state: "minecraft:deepslate_bricks"},
        {pos: [9, 0, 10], state: "minecraft:deepslate_bricks"},
        {pos: [9, 0, 11], state: "minecraft:deepslate_bricks"},
        {pos: [9, 0, 12], state: "minecraft:deepslate_bricks"},
        {pos: [9, 0, 13], state: "minecraft:deepslate_bricks"},
        {pos: [10, 0, 0], state: "minecraft:deepslate{axis:y}"},
        {pos: [10, 0, 1], state: "minecraft:deepslate_bricks"},
        {pos: [10, 0, 2], state: "minecraft:deepslate_bricks"},
        {pos: [10, 0, 3], state: "minecraft:deepslate_bricks"},
        {pos: [10, 0, 4], state: "minecraft:deepslate_bricks"},
        {pos: [10, 0, 5], state: "minecraft:deepslate_bricks"},
        {pos: [10, 0, 6], state: "minecraft:deepslate_bricks"},
        {pos: [10, 0, 7], state: "minecraft:deepslate_bricks"},
        {pos: [10, 0, 8], state: "minecraft:deepslate_bricks"},
        {pos: [10, 0, 9], state: "minecraft:deepslate_bricks"},
        {pos: [10, 0, 10], state: "minecraft:deepslate_bricks"},
        {pos: [10, 0, 11], state: "minecraft:deepslate_bricks"},
        {pos: [10, 0, 12], state: "minecraft:deepslate{axis:y}"},
        {pos: [10, 0, 13], state: "minecraft:deepslate_bricks"},
        {pos: [11, 0, 0], state: "minecraft:deepslate{axis:y}"},
        {pos: [11, 0, 1], state: "minecraft:deepslate_bricks"},
        {pos: [11, 0, 2], state: "minecraft:deepslate_bricks"},
        {pos: [11, 0, 3], state: "minecraft:deepslate_bricks"},
        {pos: [11, 0, 4], state: "minecraft:deepslate_bricks"},
        {pos: [11, 0, 5], state: "minecraft:deepslate_bricks"},
        {pos: [11, 0, 6], state: "minecraft:deepslate_bricks"},
        {pos: [11, 0, 7], state: "minecraft:deepslate{axis:y}"},
        {pos: [11, 0, 8], state: "minecraft:deepslate{axis:y}"},
        {pos: [11, 0, 9], state: "minecraft:deepslate_bricks"},
        {pos: [11, 0, 10], state: "minecraft:deepslate_bricks"},
        {pos: [11, 0, 11], state: "minecraft:deepslate_bricks"},
        {pos: [11, 0, 12], state: "minecraft:deepslate{axis:y}"},
        {pos: [11, 0, 13], state: "minecraft:polished_deepslate_stairs{facing:west,half:bottom,shape:straight,waterlogged:false}"},
        {pos: [12, 0, 0], state: "minecraft:deepslate{axis:y}"},
        {pos: [12, 0, 1], state: "minecraft:deepslate_bricks"},
        {pos: [12, 0, 2], state: "minecraft:deepslate_bricks"},
        {pos: [12, 0, 3], state: "minecraft:deepslate_bricks"},
        {pos: [12, 0, 4], state: "minecraft:deepslate_bricks"},
        {pos: [12, 0, 5], state: "minecraft:deepslate_bricks"},
        {pos: [12, 0, 6], state: "minecraft:deepslate{axis:y}"},
        {pos: [12, 0, 7], state: "minecraft:deepslate{axis:y}"},
        {pos: [12, 0, 8], state: "minecraft:deepslate{axis:y}"},
        {pos: [12, 0, 9], state: "minecraft:deepslate_bricks"},
        {pos: [12, 0, 10], state: "minecraft:deepslate_bricks"},
        {pos: [12, 0, 11], state: "minecraft:deepslate_bricks"},
        {pos: [12, 0, 12], state: "minecraft:deepslate{axis:y}"},
        {pos: [13, 0, 0], state: "minecraft:deepslate{axis:y}"},
        {pos: [13, 0, 1], state: "minecraft:deepslate_bricks"},
        {pos: [13, 0, 2], state: "minecraft:deepslate_bricks"},
        {pos: [13, 0, 3], state: "minecraft:deepslate_bricks"},
        {pos: [13, 0, 4], state: "minecraft:deepslate_bricks"},
        {pos: [13, 0, 5], state: "minecraft:deepslate_bricks"},
        {pos: [13, 0, 6], state: "minecraft:deepslate_bricks"},
        {pos: [13, 0, 7], state: "minecraft:deepslate{axis:y}"},
        {pos: [13, 0, 8], state: "minecraft:deepslate{axis:y}"},
        {pos: [13, 0, 9], state: "minecraft:deepslate{axis:y}"},
        {pos: [13, 0, 10], state: "minecraft:deepslate_bricks"},
        {pos: [13, 0, 11], state: "minecraft:deepslate_bricks"},
        {pos: [13, 0, 12], state: "minecraft:deepslate{axis:y}"},
        {pos: [14, 0, 0], state: "minecraft:deepslate{axis:y}"},
        {pos: [14, 0, 1], state: "minecraft:deepslate_bricks"},
        {pos: [14, 0, 2], state: "minecraft:deepslate_bricks"},
        {pos: [14, 0, 3], state: "minecraft:deepslate_bricks"},
        {pos: [14, 0, 4], state: "minecraft:deepslate_bricks"},
        {pos: [14, 0, 5], state: "minecraft:deepslate{axis:y}"},
        {pos: [14, 0, 6], state: "minecraft:deepslate_bricks"},
        {pos: [14, 0, 7], state: "minecraft:deepslate_bricks"},
        {pos: [14, 0, 8], state: "minecraft:deepslate{axis:y}"},
        {pos: [14, 0, 9], state: "minecraft:deepslate{axis:y}"},
        {pos: [14, 0, 10], state: "minecraft:deepslate_bricks"},
        {pos: [14, 0, 11], state: "minecraft:deepslate_bricks"},
        {pos: [14, 0, 12], state: "minecraft:deepslate{axis:y}"},
        {pos: [15, 0, 0], state: "minecraft:deepslate{axis:y}"},
        {pos: [15, 0, 1], state: "minecraft:deepslate_bricks"},
        {pos: [15, 0, 2], state: "minecraft:deepslate_bricks"},
        {pos: [15, 0, 3], state: "minecraft:deepslate_bricks"},
        {pos: [15, 0, 4], state: "minecraft:deepslate{axis:y}"},
        {pos: [15, 0, 5], state: "minecraft:deepslate{axis:y}"},
        {pos: [15, 0, 6], state: "minecraft:deepslate_bricks"},
        {pos: [15, 0, 7], state: "minecraft:deepslate_bricks"},
        {pos: [15, 0, 8], state: "minecraft:deepslate_bricks"},
        {pos: [15, 0, 9], state: "minecraft:deepslate_bricks"},
        {pos: [15, 0, 10], state: "minecraft:deepslate_bricks"},
        {pos: [15, 0, 11], state: "minecraft:deepslate_bricks"},
        {pos: [15, 0, 12], state: "minecraft:deepslate{axis:y}"},
        {pos: [16, 0, 0], state: "minecraft:deepslate{axis:y}"},
        {pos: [16, 0, 1], state: "minecraft:deepslate_bricks"},
        {pos: [16, 0, 2], state: "minecraft:deepslate_bricks"},
        {pos: [16, 0, 3], state: "minecraft:deepslate_bricks"},
        {pos: [16, 0, 4], state: "minecraft:deepslate{axis:y}"},
        {pos: [16, 0, 5], state: "minecraft:deepslate{axis:y}"},
        {pos: [16, 0, 6], state: "minecraft:deepslate{axis:y}"},
        {pos: [16, 0, 7], state: "minecraft:deepslate_bricks"},
        {pos: [16, 0, 8], state: "minecraft:deepslate_bricks"},
        {pos: [16, 0, 9], state: "minecraft:deepslate_bricks"},
        {pos: [16, 0, 10], state: "minecraft:deepslate_bricks"},
        {pos: [16, 0, 11], state: "minecraft:deepslate_bricks"},
        {pos: [16, 0, 12], state: "minecraft:deepslate{axis:y}"},
        {pos: [17, 0, 0], state: "minecraft:deepslate{axis:y}"},
        {pos: [17, 0, 1], state: "minecraft:deepslate_bricks"},
        {pos: [17, 0, 2], state: "minecraft:deepslate_bricks"},
        {pos: [17, 0, 3], state: "minecraft:deepslate_bricks"},
        {pos: [17, 0, 4], state: "minecraft:deepslate_bricks"},
        {pos: [17, 0, 5], state: "minecraft:deepslate_bricks"},
        {pos: [17, 0, 6], state: "minecraft:deepslate_bricks"},
        {pos: [17, 0, 7], state: "minecraft:deepslate_bricks"},
        {pos: [17, 0, 8], state: "minecraft:deepslate_bricks"},
        {pos: [17, 0, 9], state: "minecraft:deepslate_bricks"},
        {pos: [17, 0, 10], state: "minecraft:deepslate_bricks"},
        {pos: [17, 0, 11], state: "minecraft:deepslate_bricks"},
        {pos: [17, 0, 12], state: "minecraft:deepslate{axis:y}"},
        {pos: [0, 1, 1], state: "minecraft:gray_wool"},
        {pos: [0, 1, 2], state: "minecraft:deepslate{axis:y}"},
        {pos: [0, 1, 3], state: "minecraft:deepslate_brick_stairs{facing:east,half:bottom,shape:straight,waterlogged:false}"},
        {pos: [0, 1, 9], state: "minecraft:deepslate_brick_stairs{facing:south,half:bottom,shape:straight,waterlogged:false}"},
        {pos: [0, 1, 10], state: "minecraft:deepslate_bricks"},
        {pos: [0, 1, 11], state: "minecraft:gray_wool"},
        {pos: [0, 1, 12], state: "minecraft:deepslate{axis:y}"},
        {pos: [1, 1, 0], state: "minecraft:deepslate{axis:y}"},
        {pos: [1, 1, 1], state: "minecraft:gray_wool"},
        {pos: [1, 1, 2], state: "minecraft:deepslate{axis:y}"},
        {pos: [1, 1, 3], state: "minecraft:gray_wool"},
        {pos: [1, 1, 9], state: "minecraft:deepslate_brick_stairs{facing:south,half:bottom,shape:straight,waterlogged:false}"},
        {pos: [1, 1, 10], state: "minecraft:deepslate_bricks"},
        {pos: [1, 1, 11], state: "minecraft:gray_wool"},
        {pos: [1, 1, 12], state: "minecraft:deepslate{axis:y}"},
        {pos: [2, 1, 0], state: "minecraft:deepslate{axis:y}"},
        {pos: [2, 1, 1], state: "minecraft:gray_wool"},
        {pos: [2, 1, 2], state: "minecraft:deepslate{axis:y}"},
        {pos: [2, 1, 3], state: "minecraft:gray_wool"},
        {pos: [2, 1, 10], state: "minecraft:gray_wool"},
        {pos: [2, 1, 11], state: "minecraft:gray_wool"},
        {pos: [2, 1, 12], state: "minecraft:deepslate{axis:y}"},
        {pos: [3, 1, 0], state: "minecraft:deepslate{axis:y}"},
        {pos: [3, 1, 1], state: "minecraft:gray_wool"},
        {pos: [3, 1, 2], state: "minecraft:deepslate{axis:y}"},
        {pos: [3, 1, 3], state: "minecraft:gray_wool"},
        {pos: [3, 1, 9], state: "minecraft:deepslate_brick_stairs{facing:south,half:bottom,shape:straight,waterlogged:false}"},
        {pos: [3, 1, 10], state: "minecraft:deepslate_bricks"},
        {pos: [3, 1, 11], state: "minecraft:gray_wool"},
        {pos: [3, 1, 12], state: "minecraft:deepslate_bricks"},
        {pos: [4, 1, 0], state: "minecraft:deepslate{axis:y}"},
        {pos: [4, 1, 1], state: "minecraft:gray_wool"},
        {pos: [4, 1, 2], state: "minecraft:deepslate{axis:y}"},
        {pos: [4, 1, 3], state: "minecraft:gray_wool"},
        {pos: [4, 1, 9], state: "minecraft:deepslate_brick_stairs{facing:south,half:bottom,shape:straight,waterlogged:false}"},
        {pos: [4, 1, 10], state: "minecraft:deepslate_bricks"},
        {pos: [4, 1, 11], state: "minecraft:gray_wool"},
        {pos: [4, 1, 12], state: "minecraft:deepslate_bricks"},
        {pos: [5, 1, 0], state: "minecraft:deepslate{axis:y}"},
        {pos: [5, 1, 1], state: "minecraft:gray_wool"},
        {pos: [5, 1, 2], state: "minecraft:deepslate{axis:y}"},
        {pos: [5, 1, 3], state: "minecraft:deepslate_brick_stairs{facing:west,half:bottom,shape:straight,waterlogged:false}"},
        {pos: [5, 1, 10], state: "minecraft:gray_wool"},
        {pos: [5, 1, 11], state: "minecraft:gray_wool"},
        {pos: [5, 1, 12], state: "minecraft:deepslate_bricks"},
        {pos: [6, 1, 0], state: "minecraft:deepslate{axis:y}"},
        {pos: [6, 1, 1], state: "minecraft:gray_wool"},
        {pos: [6, 1, 2], state: "minecraft:deepslate{axis:y}"},
        {pos: [6, 1, 9], state: "minecraft:deepslate_brick_stairs{facing:south,half:bottom,shape:straight,waterlogged:false}"},
        {pos: [6, 1, 10], state: "minecraft:deepslate_bricks"},
        {pos: [6, 1, 11], state: "minecraft:gray_wool"},
        {pos: [6, 1, 12], state: "minecraft:deepslate_bricks"},
        {pos: [6, 1, 13], state: "minecraft:polished_deepslate_stairs{facing:east,half:bottom,shape:straight,waterlogged:false}"},
        {pos: [7, 1, 0], state: "minecraft:deepslate{axis:y}"},
        {pos: [7, 1, 1], state: "minecraft:gray_wool"},
        {pos: [7, 1, 2], state: "minecraft:deepslate{axis:y}"},
        {pos: [7, 1, 3], state: "minecraft:deepslate_brick_stairs{facing:east,half:bottom,shape:straight,waterlogged:false}"},
        {pos: [7, 1, 12], state: "minecraft:polished_deepslate_stairs{facing:south,half:bottom,shape:straight,waterlogged:false}"},
        {pos: [7, 1, 13], state: "minecraft:gray_wool"},
        {pos: [8, 1, 0], state: "minecraft:deepslate{axis:y}"},
        {pos: [8, 1, 1], state: "minecraft:gray_wool"},
        {pos: [8, 1, 2], state: "minecraft:deepslate{axis:y}"},
        {pos: [8, 1, 3], state: "minecraft:gray_wool"},
        {pos: [8, 1, 12], state: "minecraft:polished_deepslate_stairs{facing:south,half:bottom,shape:straight,waterlogged:false}"},
        {pos: [8, 1, 13], state: "minecraft:gray_wool"},
        {pos: [9, 1, 0], state: "minecraft:deepslate{axis:y}"},
        {pos: [9, 1, 1], state: "minecraft:gray_wool"},
        {pos: [9, 1, 2], state: "minecraft:deepslate{axis:y}"},
        {pos: [9, 1, 3], state: "minecraft:gray_wool"},
        {pos: [9, 1, 12], state: "minecraft:polished_deepslate_stairs{facing:south,half:bottom,shape:straight,waterlogged:false}"},
        {pos: [9, 1, 13], state: "minecraft:gray_wool"},
        {pos: [10, 1, 0], state: "minecraft:deepslate{axis:y}"},
        {pos: [10, 1, 1], state: "minecraft:gray_wool"},
        {pos: [10, 1, 2], state: "minecraft:deepslate{axis:y}"},
        {pos: [10, 1, 3], state: "minecraft:deepslate_brick_stairs{facing:west,half:bottom,shape:straight,waterlogged:false}"},
        {pos: [10, 1, 9], state: "minecraft:deepslate_brick_stairs{facing:south,half:bottom,shape:straight,waterlogged:false}"},
        {pos: [10, 1, 10], state: "minecraft:deepslate_bricks"},
        {pos: [10, 1, 11], state: "minecraft:gray_wool"},
        {pos: [10, 1, 12], state: "minecraft:deepslate{axis:y}"},
        {pos: [10, 1, 13], state: "minecraft:polished_deepslate_stairs{facing:west,half:bottom,shape:straight,waterlogged:false}"},
        {pos: [11, 1, 0], state: "minecraft:deepslate{axis:y}"},
        {pos: [11, 1, 1], state: "minecraft:gray_wool"},
        {pos: [11, 1, 2], state: "minecraft:deepslate{axis:y}"},
        {pos: [11, 1, 10], state: "minecraft:polished_deepslate_stairs{facing:south,half:bottom,shape:straight,waterlogged:false}"},
        {pos: [11, 1, 11], state: "minecraft:deepslate{axis:y}"},
        {pos: [11, 1, 12], state: "minecraft:deepslate{axis:y}"},
        {pos: [12, 1, 0], state: "minecraft:deepslate{axis:y}"},
        {pos: [12, 1, 1], state: "minecraft:gray_wool"},
        {pos: [12, 1, 2], state: "minecraft:deepslate{axis:y}"},
        {pos: [12, 1, 3], state: "minecraft:deepslate_brick_stairs{facing:east,half:bottom,shape:straight,waterlogged:false}"},
        {pos: [12, 1, 10], state: "minecraft:deepslate_brick_stairs{facing:west,half:bottom,shape:outer_left,waterlogged:false}"},
        {pos: [12, 1, 11], state: "minecraft:gray_wool"},
        {pos: [12, 1, 12], state: "minecraft:deepslate_bricks"},
        {pos: [13, 1, 0], state: "minecraft:deepslate{axis:y}"},
        {pos: [13, 1, 1], state: "minecraft:gray_wool"},
        {pos: [13, 1, 2], state: "minecraft:deepslate{axis:y}"},
        {pos: [13, 1, 3], state: "minecraft:gray_wool"},
        {pos: [13, 1, 11], state: "minecraft:gray_wool"},
        {pos: [13, 1, 12], state: "minecraft:deepslate_bricks"},
        {pos: [14, 1, 0], state: "minecraft:deepslate{axis:y}"},
        {pos: [14, 1, 1], state: "minecraft:gray_wool"},
        {pos: [14, 1, 2], state: "minecraft:deepslate{axis:y}"},
        {pos: [14, 1, 3], state: "minecraft:gray_wool"},
        {pos: [14, 1, 10], state: "minecraft:deepslate_brick_stairs{facing:east,half:bottom,shape:straight,waterlogged:false}"},
        {pos: [14, 1, 11], state: "minecraft:gray_wool"},
        {pos: [14, 1, 12], state: "minecraft:deepslate_bricks"},
        {pos: [15, 1, 0], state: "minecraft:deepslate{axis:y}"},
        {pos: [15, 1, 1], state: "minecraft:gray_wool"},
        {pos: [15, 1, 2], state: "minecraft:deepslate{axis:y}"},
        {pos: [15, 1, 3], state: "minecraft:gray_wool"},
        {pos: [15, 1, 10], state: "minecraft:gray_wool"},
        {pos: [15, 1, 11], state: "minecraft:gray_wool"},
        {pos: [15, 1, 12], state: "minecraft:deepslate_bricks"},
        {pos: [16, 1, 0], state: "minecraft:deepslate{axis:y}"},
        {pos: [16, 1, 1], state: "minecraft:gray_wool"},
        {pos: [16, 1, 2], state: "minecraft:deepslate{axis:y}"},
        {pos: [16, 1, 3], state: "minecraft:gray_wool"},
        {pos: [16, 1, 9], state: "minecraft:deepslate_brick_stairs{facing:south,half:bottom,shape:straight,waterlogged:false}"},
        {pos: [16, 1, 10], state: "minecraft:deepslate_bricks"},
        {pos: [16, 1, 11], state: "minecraft:gray_wool"},
        {pos: [16, 1, 12], state: "minecraft:deepslate{axis:y}"},
        {pos: [17, 1, 0], state: "minecraft:deepslate{axis:y}"},
        {pos: [17, 1, 1], state: "minecraft:gray_wool"},
        {pos: [17, 1, 2], state: "minecraft:deepslate{axis:y}"},
        {pos: [17, 1, 3], state: "minecraft:deepslate_brick_stairs{facing:west,half:bottom,shape:straight,waterlogged:false}"},
        {pos: [17, 1, 9], state: "minecraft:deepslate_brick_stairs{facing:south,half:bottom,shape:straight,waterlogged:false}"},
        {pos: [17, 1, 10], state: "minecraft:deepslate_bricks"},
        {pos: [17, 1, 11], state: "minecraft:gray_wool"},
        {pos: [17, 1, 12], state: "minecraft:deepslate{axis:y}"},
        {pos: [0, 2, 1], state: "minecraft:gray_wool"},
        {pos: [0, 2, 2], state: "minecraft:deepslate_bricks"},
        {pos: [0, 2, 10], state: "minecraft:chiseled_deepslate"},
        {pos: [0, 2, 11], state: "minecraft:gray_wool"},
        {pos: [0, 2, 12], state: "minecraft:deepslate_tiles"},
        {pos: [1, 2, 0], state: "minecraft:deepslate{axis:y}"},
        {pos: [1, 2, 1], state: "minecraft:gray_wool"},
        {pos: [1, 2, 2], state: "minecraft:deepslate_bricks"},
        {pos: [1, 2, 3], state: "minecraft:gray_wool"},
        {pos: [1, 2, 10], state: "minecraft:chiseled_deepslate"},
        {pos: [1, 2, 11], state: "minecraft:gray_wool"},
        {pos: [1, 2, 12], state: "minecraft:deepslate_tiles"},
        {pos: [2, 2, 0], state: "minecraft:deepslate{axis:y}"},
        {pos: [2, 2, 1], state: "minecraft:gray_wool"},
        {pos: [2, 2, 2], state: "minecraft:deepslate_bricks"},
        {pos: [2, 2, 3], state: "minecraft:gray_wool"},
        {pos: [2, 2, 10], state: "minecraft:gray_wool"},
        {pos: [2, 2, 11], state: "minecraft:gray_wool"},
        {pos: [2, 2, 12], state: "minecraft:deepslate_tiles"},
        {pos: [3, 2, 0], state: "minecraft:deepslate{axis:y}"},
        {pos: [3, 2, 1], state: "minecraft:gray_wool"},
        {pos: [3, 2, 2], state: "minecraft:deepslate_bricks"},
        {pos: [3, 2, 3], state: "minecraft:gray_wool"},
        {pos: [3, 2, 10], state: "minecraft:chiseled_deepslate"},
        {pos: [3, 2, 11], state: "minecraft:gray_wool"},
        {pos: [3, 2, 12], state: "minecraft:deepslate_bricks"},
        {pos: [4, 2, 0], state: "minecraft:deepslate{axis:y}"},
        {pos: [4, 2, 1], state: "minecraft:gray_wool"},
        {pos: [4, 2, 2], state: "minecraft:deepslate_bricks"},
        {pos: [4, 2, 3], state: "minecraft:gray_wool"},
        {pos: [4, 2, 10], state: "minecraft:chiseled_deepslate"},
        {pos: [4, 2, 11], state: "minecraft:gray_wool"},
        {pos: [4, 2, 12], state: "minecraft:chiseled_deepslate"},
        {pos: [5, 2, 0], state: "minecraft:deepslate{axis:y}"},
        {pos: [5, 2, 1], state: "minecraft:gray_wool"},
        {pos: [5, 2, 2], state: "minecraft:deepslate_bricks"},
        {pos: [5, 2, 10], state: "minecraft:gray_wool"},
        {pos: [5, 2, 11], state: "minecraft:gray_wool"},
        {pos: [5, 2, 12], state: "minecraft:chiseled_deepslate"},
        {pos: [6, 2, 0], state: "minecraft:deepslate{axis:y}"},
        {pos: [6, 2, 1], state: "minecraft:gray_wool"},
        {pos: [6, 2, 2], state: "minecraft:deepslate_bricks"},
        {pos: [6, 2, 10], state: "minecraft:chiseled_deepslate"},
        {pos: [6, 2, 11], state: "minecraft:gray_wool"},
        {pos: [6, 2, 12], state: "minecraft:deepslate_bricks"},
        {pos: [7, 2, 0], state: "minecraft:deepslate{axis:y}"},
        {pos: [7, 2, 1], state: "minecraft:gray_wool"},
        {pos: [7, 2, 2], state: "minecraft:deepslate_bricks"},
        {pos: [8, 2, 0], state: "minecraft:deepslate{axis:y}"},
        {pos: [8, 2, 1], state: "minecraft:gray_wool"},
        {pos: [8, 2, 2], state: "minecraft:deepslate_bricks"},
        {pos: [8, 2, 3], state: "minecraft:gray_wool"},
        {pos: [9, 2, 0], state: "minecraft:deepslate{axis:y}"},
        {pos: [9, 2, 1], state: "minecraft:gray_wool"},
        {pos: [9, 2, 2], state: "minecraft:deepslate_bricks"},
        {pos: [9, 2, 3], state: "minecraft:gray_wool"},
        {pos: [10, 2, 0], state: "minecraft:deepslate{axis:y}"},
        {pos: [10, 2, 1], state: "minecraft:gray_wool"},
        {pos: [10, 2, 2], state: "minecraft:deepslate_bricks"},
        {pos: [10, 2, 10], state: "minecraft:chiseled_deepslate"},
        {pos: [10, 2, 11], state: "minecraft:gray_wool"},
        {pos: [10, 2, 12], state: "minecraft:deepslate_tiles"},
        {pos: [11, 2, 0], state: "minecraft:deepslate{axis:y}"},
        {pos: [11, 2, 1], state: "minecraft:gray_wool"},
        {pos: [11, 2, 2], state: "minecraft:deepslate_bricks"},
        {pos: [11, 2, 11], state: "minecraft:deepslate_tile_stairs{facing:south,half:bottom,shape:straight,waterlogged:false}"},
        {pos: [11, 2, 12], state: "minecraft:deepslate_tiles"},
        {pos: [12, 2, 0], state: "minecraft:deepslate{axis:y}"},
        {pos: [12, 2, 1], state: "minecraft:gray_wool"},
        {pos: [12, 2, 2], state: "minecraft:deepslate_bricks"},
        {pos: [12, 2, 11], state: "minecraft:gray_wool"},
        {pos: [12, 2, 12], state: "minecraft:deepslate_bricks"},
        {pos: [13, 2, 0], state: "minecraft:deepslate{axis:y}"},
        {pos: [13, 2, 1], state: "minecraft:gray_wool"},
        {pos: [13, 2, 2], state: "minecraft:deepslate_bricks"},
        {pos: [13, 2, 3], state: "minecraft:gray_wool"},
        {pos: [13, 2, 11], state: "minecraft:gray_wool"},
        {pos: [13, 2, 12], state: "minecraft:chiseled_deepslate"},
        {pos: [14, 2, 0], state: "minecraft:deepslate{axis:y}"},
        {pos: [14, 2, 1], state: "minecraft:gray_wool"},
        {pos: [14, 2, 2], state: "minecraft:deepslate_bricks"},
        {pos: [14, 2, 3], state: "minecraft:gray_wool"},
        {pos: [14, 2, 11], state: "minecraft:gray_wool"},
        {pos: [14, 2, 12], state: "minecraft:chiseled_deepslate"},
        {pos: [15, 2, 0], state: "minecraft:deepslate{axis:y}"},
        {pos: [15, 2, 1], state: "minecraft:gray_wool"},
        {pos: [15, 2, 2], state: "minecraft:deepslate_bricks"},
        {pos: [15, 2, 3], state: "minecraft:gray_wool"},
        {pos: [15, 2, 10], state: "minecraft:gray_wool"},
        {pos: [15, 2, 11], state: "minecraft:gray_wool"},
        {pos: [15, 2, 12], state: "minecraft:deepslate_bricks"},
        {pos: [16, 2, 0], state: "minecraft:deepslate{axis:y}"},
        {pos: [16, 2, 1], state: "minecraft:gray_wool"},
        {pos: [16, 2, 2], state: "minecraft:deepslate_bricks"},
        {pos: [16, 2, 3], state: "minecraft:gray_wool"},
        {pos: [16, 2, 10], state: "minecraft:chiseled_deepslate"},
        {pos: [16, 2, 11], state: "minecraft:gray_wool"},
        {pos: [16, 2, 12], state: "minecraft:deepslate_tiles"},
        {pos: [17, 2, 0], state: "minecraft:deepslate{axis:y}"},
        {pos: [17, 2, 1], state: "minecraft:gray_wool"},
        {pos: [17, 2, 2], state: "minecraft:deepslate_bricks"},
        {pos: [17, 2, 10], state: "minecraft:chiseled_deepslate"},
        {pos: [17, 2, 11], state: "minecraft:gray_wool"},
        {pos: [17, 2, 12], state: "minecraft:deepslate_tiles"},
        {pos: [0, 3, 1], state: "minecraft:gray_wool"},
        {pos: [0, 3, 2], state: "minecraft:deepslate_bricks"},
        {pos: [0, 3, 3], state: "minecraft:deepslate_tile_stairs{facing:north,half:top,shape:straight,waterlogged:false}"},
        {pos: [0, 3, 10], state: "minecraft:deepslate_tile_stairs{facing:south,half:bottom,shape:straight,waterlogged:false}"},
        {pos: [0, 3, 11], state: "minecraft:gray_wool"},
        {pos: [0, 3, 12], state: "minecraft:deepslate_tile_stairs{facing:north,half:bottom,shape:straight,waterlogged:false}"},
        {pos: [1, 3, 0], state: "minecraft:deepslate_bricks"},
        {pos: [1, 3, 1], state: "minecraft:gray_wool"},
        {pos: [1, 3, 2], state: "minecraft:deepslate_bricks"},
        {pos: [1, 3, 3], state: "minecraft:gray_wool"},
        {pos: [1, 3, 10], state: "minecraft:deepslate_tile_stairs{facing:south,half:bottom,shape:straight,waterlogged:false}"},
        {pos: [1, 3, 11], state: "minecraft:gray_wool"},
        {pos: [1, 3, 12], state: "minecraft:deepslate_tile_stairs{facing:north,half:bottom,shape:straight,waterlogged:false}"},
        {pos: [2, 3, 0], state: "minecraft:deepslate_bricks"},
        {pos: [2, 3, 1], state: "minecraft:gray_wool"},
        {pos: [2, 3, 2], state: "minecraft:deepslate_bricks"},
        {pos: [2, 3, 3], state: "minecraft:gray_wool"},
        {pos: [2, 3, 10], state: "minecraft:gray_wool"},
        {pos: [2, 3, 11], state: "minecraft:gray_wool"},
        {pos: [2, 3, 12], state: "minecraft:deepslate_tile_stairs{facing:north,half:bottom,shape:straight,waterlogged:false}"},
        {pos: [3, 3, 0], state: "minecraft:deepslate_bricks"},
        {pos: [3, 3, 1], state: "minecraft:gray_wool"},
        {pos: [3, 3, 2], state: "minecraft:deepslate_bricks"},
        {pos: [3, 3, 3], state: "minecraft:gray_wool"},
        {pos: [3, 3, 10], state: "minecraft:deepslate_tile_stairs{facing:south,half:bottom,shape:straight,waterlogged:false}"},
        {pos: [3, 3, 11], state: "minecraft:gray_wool"},
        {pos: [3, 3, 12], state: "minecraft:deepslate_bricks"},
        {pos: [4, 3, 0], state: "minecraft:deepslate_bricks"},
        {pos: [4, 3, 1], state: "minecraft:gray_wool"},
        {pos: [4, 3, 2], state: "minecraft:deepslate_bricks"},
        {pos: [4, 3, 3], state: "minecraft:gray_wool"},
        {pos: [4, 3, 10], state: "minecraft:deepslate_tile_stairs{facing:south,half:bottom,shape:straight,waterlogged:false}"},
        {pos: [4, 3, 11], state: "minecraft:gray_wool"},
        {pos: [4, 3, 12], state: "minecraft:chiseled_deepslate"},
        {pos: [5, 3, 0], state: "minecraft:deepslate_bricks"},
        {pos: [5, 3, 1], state: "minecraft:gray_wool"},
        {pos: [5, 3, 2], state: "minecraft:deepslate_bricks"},
        {pos: [5, 3, 3], state: "minecraft:deepslate_tile_stairs{facing:north,half:top,shape:straight,waterlogged:false}"},
        {pos: [5, 3, 10], state: "minecraft:gray_wool"},
        {pos: [5, 3, 11], state: "minecraft:gray_wool"},
        {pos: [5, 3, 12], state: "minecraft:chiseled_deepslate"},
        {pos: [6, 3, 0], state: "minecraft:deepslate_bricks"},
        {pos: [6, 3, 1], state: "minecraft:gray_wool"},
        {pos: [6, 3, 2], state: "minecraft:deepslate_bricks"},
        {pos: [6, 3, 3], state: "minecraft:chiseled_deepslate"},
        {pos: [6, 3, 10], state: "minecraft:deepslate_tile_stairs{facing:south,half:bottom,shape:straight,waterlogged:false}"},
        {pos: [6, 3, 11], state: "minecraft:gray_wool"},
        {pos: [6, 3, 12], state: "minecraft:deepslate_bricks"},
        {pos: [7, 3, 0], state: "minecraft:deepslate_bricks"},
        {pos: [7, 3, 1], state: "minecraft:gray_wool"},
        {pos: [7, 3, 2], state: "minecraft:deepslate_bricks"},
        {pos: [7, 3, 3], state: "minecraft:deepslate_tile_stairs{facing:north,half:top,shape:straight,waterlogged:false}"},
        {pos: [8, 3, 0], state: "minecraft:deepslate_bricks"},
        {pos: [8, 3, 1], state: "minecraft:gray_wool"},
        {pos: [8, 3, 2], state: "minecraft:deepslate_bricks"},
        {pos: [8, 3, 3], state: "minecraft:gray_wool"},
        {pos: [9, 3, 0], state: "minecraft:deepslate_bricks"},
        {pos: [9, 3, 1], state: "minecraft:gray_wool"},
        {pos: [9, 3, 2], state: "minecraft:deepslate_bricks"},
        {pos: [9, 3, 3], state: "minecraft:gray_wool"},
        {pos: [10, 3, 0], state: "minecraft:deepslate_bricks"},
        {pos: [10, 3, 1], state: "minecraft:gray_wool"},
        {pos: [10, 3, 2], state: "minecraft:deepslate_bricks"},
        {pos: [10, 3, 3], state: "minecraft:deepslate_tile_stairs{facing:north,half:top,shape:straight,waterlogged:false}"},
        {pos: [10, 3, 10], state: "minecraft:deepslate_tile_stairs{facing:south,half:bottom,shape:straight,waterlogged:false}"},
        {pos: [10, 3, 11], state: "minecraft:gray_wool"},
        {pos: [10, 3, 12], state: "minecraft:deepslate_tile_stairs{facing:north,half:bottom,shape:straight,waterlogged:false}"},
        {pos: [11, 3, 0], state: "minecraft:deepslate_bricks"},
        {pos: [11, 3, 1], state: "minecraft:gray_wool"},
        {pos: [11, 3, 2], state: "minecraft:deepslate_bricks"},
        {pos: [11, 3, 3], state: "minecraft:chiseled_deepslate"},
        {pos: [11, 3, 12], state: "minecraft:deepslate_tile_stairs{facing:north,half:bottom,shape:straight,waterlogged:false}"},
        {pos: [12, 3, 0], state: "minecraft:deepslate_bricks"},
        {pos: [12, 3, 1], state: "minecraft:gray_wool"},
        {pos: [12, 3, 2], state: "minecraft:deepslate_bricks"},
        {pos: [12, 3, 3], state: "minecraft:deepslate_tile_stairs{facing:north,half:top,shape:straight,waterlogged:false}"},
        {pos: [12, 3, 10], state: "minecraft:deepslate_tile_stairs{facing:south,half:top,shape:straight,waterlogged:false}"},
        {pos: [12, 3, 11], state: "minecraft:gray_wool"},
        {pos: [12, 3, 12], state: "minecraft:deepslate_bricks"},
        {pos: [13, 3, 0], state: "minecraft:deepslate_bricks"},
        {pos: [13, 3, 1], state: "minecraft:gray_wool"},
        {pos: [13, 3, 2], state: "minecraft:deepslate_bricks"},
        {pos: [13, 3, 3], state: "minecraft:gray_wool"},
        {pos: [13, 3, 10], state: "minecraft:chiseled_deepslate"},
        {pos: [13, 3, 11], state: "minecraft:gray_wool"},
        {pos: [13, 3, 12], state: "minecraft:chiseled_deepslate"},
        {pos: [14, 3, 0], state: "minecraft:deepslate_bricks"},
        {pos: [14, 3, 1], state: "minecraft:gray_wool"},
        {pos: [14, 3, 2], state: "minecraft:deepslate_bricks"},
        {pos: [14, 3, 3], state: "minecraft:gray_wool"},
        {pos: [14, 3, 10], state: "minecraft:deepslate_tile_stairs{facing:south,half:top,shape:straight,waterlogged:false}"},
        {pos: [14, 3, 11], state: "minecraft:gray_wool"},
        {pos: [14, 3, 12], state: "minecraft:chiseled_deepslate"},
        {pos: [15, 3, 0], state: "minecraft:deepslate_bricks"},
        {pos: [15, 3, 1], state: "minecraft:gray_wool"},
        {pos: [15, 3, 2], state: "minecraft:deepslate_bricks"},
        {pos: [15, 3, 3], state: "minecraft:gray_wool"},
        {pos: [15, 3, 10], state: "minecraft:gray_wool"},
        {pos: [15, 3, 11], state: "minecraft:gray_wool"},
        {pos: [15, 3, 12], state: "minecraft:deepslate_bricks"},
        {pos: [16, 3, 0], state: "minecraft:deepslate_bricks"},
        {pos: [16, 3, 1], state: "minecraft:gray_wool"},
        {pos: [16, 3, 2], state: "minecraft:deepslate_bricks"},
        {pos: [16, 3, 3], state: "minecraft:gray_wool"},
        {pos: [16, 3, 10], state: "minecraft:deepslate_tile_stairs{facing:south,half:bottom,shape:straight,waterlogged:false}"},
        {pos: [16, 3, 11], state: "minecraft:gray_wool"},
        {pos: [16, 3, 12], state: "minecraft:deepslate_tile_stairs{facing:north,half:bottom,shape:straight,waterlogged:false}"},
        {pos: [17, 3, 0], state: "minecraft:deepslate_bricks"},
        {pos: [17, 3, 1], state: "minecraft:gray_wool"},
        {pos: [17, 3, 2], state: "minecraft:deepslate_bricks"},
        {pos: [17, 3, 3], state: "minecraft:deepslate_tile_stairs{facing:north,half:top,shape:straight,waterlogged:false}"},
        {pos: [17, 3, 10], state: "minecraft:deepslate_tile_stairs{facing:south,half:bottom,shape:straight,waterlogged:false}"},
        {pos: [17, 3, 11], state: "minecraft:gray_wool"},
        {pos: [17, 3, 12], state: "minecraft:deepslate_tile_stairs{facing:north,half:bottom,shape:straight,waterlogged:false}"},
        {pos: [0, 4, 1], state: "minecraft:gray_wool"},
        {pos: [0, 4, 2], state: "minecraft:deepslate_bricks"},
        {pos: [0, 4, 3], state: "minecraft:deepslate_tile_stairs{facing:north,half:bottom,shape:straight,waterlogged:false}"},
        {pos: [0, 4, 10], state: "minecraft:deepslate_tile_stairs{facing:south,half:top,shape:straight,waterlogged:false}"},
        {pos: [0, 4, 11], state: "minecraft:gray_wool"},
        {pos: [0, 4, 12], state: "minecraft:gray_wool"},
        {pos: [0, 4, 13], state: "minecraft:deepslate_tile_stairs{facing:north,half:top,shape:straight,waterlogged:false}"},
        {pos: [1, 4, 0], state: "minecraft:deepslate_bricks"},
        {pos: [1, 4, 1], state: "minecraft:gray_wool"},
        {pos: [1, 4, 2], state: "minecraft:deepslate_bricks"},
        {pos: [1, 4, 3], state: "minecraft:gray_wool"},
        {pos: [1, 4, 10], state: "minecraft:deepslate_tile_stairs{facing:south,half:top,shape:straight,waterlogged:false}"},
        {pos: [1, 4, 11], state: "minecraft:gray_wool"},
        {pos: [1, 4, 12], state: "minecraft:gray_wool"},
        {pos: [1, 4, 13], state: "minecraft:deepslate_tile_stairs{facing:north,half:top,shape:straight,waterlogged:false}"},
        {pos: [2, 4, 0], state: "minecraft:deepslate_bricks"},
        {pos: [2, 4, 1], state: "minecraft:gray_wool"},
        {pos: [2, 4, 2], state: "minecraft:deepslate_bricks"},
        {pos: [2, 4, 3], state: "minecraft:gray_wool"},
        {pos: [2, 4, 10], state: "minecraft:gray_wool"},
        {pos: [2, 4, 11], state: "minecraft:gray_wool"},
        {pos: [2, 4, 12], state: "minecraft:gray_wool"},
        {pos: [2, 4, 13], state: "minecraft:deepslate_tile_stairs{facing:north,half:top,shape:straight,waterlogged:false}"},
        {pos: [3, 4, 0], state: "minecraft:deepslate_bricks"},
        {pos: [3, 4, 1], state: "minecraft:gray_wool"},
        {pos: [3, 4, 2], state: "minecraft:deepslate_bricks"},
        {pos: [3, 4, 3], state: "minecraft:gray_wool"},
        {pos: [3, 4, 10], state: "minecraft:deepslate_tile_stairs{facing:south,half:top,shape:straight,waterlogged:false}"},
        {pos: [3, 4, 11], state: "minecraft:gray_wool"},
        {pos: [3, 4, 12], state: "minecraft:gray_wool"},
        {pos: [3, 4, 13], state: "minecraft:deepslate_bricks"},
        {pos: [4, 4, 0], state: "minecraft:deepslate_bricks"},
        {pos: [4, 4, 1], state: "minecraft:gray_wool"},
        {pos: [4, 4, 2], state: "minecraft:deepslate_bricks"},
        {pos: [4, 4, 3], state: "minecraft:gray_wool"},
        {pos: [4, 4, 10], state: "minecraft:deepslate_tile_stairs{facing:south,half:top,shape:straight,waterlogged:false}"},
        {pos: [4, 4, 11], state: "minecraft:gray_wool"},
        {pos: [4, 4, 12], state: "minecraft:gray_wool"},
        {pos: [4, 4, 13], state: "minecraft:deepslate_bricks"},
        {pos: [5, 4, 0], state: "minecraft:deepslate_bricks"},
        {pos: [5, 4, 1], state: "minecraft:gray_wool"},
        {pos: [5, 4, 2], state: "minecraft:deepslate_bricks"},
        {pos: [5, 4, 3], state: "minecraft:deepslate_tile_stairs{facing:north,half:bottom,shape:straight,waterlogged:false}"},
        {pos: [5, 4, 10], state: "minecraft:gray_wool"},
        {pos: [5, 4, 11], state: "minecraft:gray_wool"},
        {pos: [5, 4, 12], state: "minecraft:gray_wool"},
        {pos: [5, 4, 13], state: "minecraft:deepslate_bricks"},
        {pos: [6, 4, 0], state: "minecraft:deepslate_bricks"},
        {pos: [6, 4, 1], state: "minecraft:gray_wool"},
        {pos: [6, 4, 2], state: "minecraft:deepslate_bricks"},
        {pos: [6, 4, 3], state: "minecraft:deepslate_tile_stairs{facing:north,half:bottom,shape:straight,waterlogged:false}"},
        {pos: [6, 4, 10], state: "minecraft:deepslate_tile_stairs{facing:south,half:top,shape:straight,waterlogged:false}"},
        {pos: [6, 4, 11], state: "minecraft:gray_wool"},
        {pos: [6, 4, 12], state: "minecraft:gray_wool"},
        {pos: [6, 4, 13], state: "minecraft:deepslate_bricks"},
        {pos: [7, 4, 0], state: "minecraft:deepslate_bricks"},
        {pos: [7, 4, 1], state: "minecraft:gray_wool"},
        {pos: [7, 4, 2], state: "minecraft:deepslate_bricks"},
        {pos: [7, 4, 3], state: "minecraft:deepslate_tile_stairs{facing:north,half:bottom,shape:straight,waterlogged:false}"},
        {pos: [7, 4, 10], state: "minecraft:deepslate_tile_stairs{facing:west,half:top,shape:outer_left,waterlogged:false}"},
        {pos: [8, 4, 0], state: "minecraft:deepslate_bricks"},
        {pos: [8, 4, 1], state: "minecraft:gray_wool"},
        {pos: [8, 4, 2], state: "minecraft:deepslate_bricks"},
        {pos: [8, 4, 3], state: "minecraft:gray_wool"},
        {pos: [9, 4, 0], state: "minecraft:deepslate_bricks"},
        {pos: [9, 4, 1], state: "minecraft:gray_wool"},
        {pos: [9, 4, 2], state: "minecraft:deepslate_bricks"},
        {pos: [9, 4, 3], state: "minecraft:gray_wool"},
        {pos: [9, 4, 10], state: "minecraft:deepslate_tile_stairs{facing:east,half:top,shape:outer_right,waterlogged:false}"},
        {pos: [10, 4, 0], state: "minecraft:deepslate_bricks"},
        {pos: [10, 4, 1], state: "minecraft:gray_wool"},
        {pos: [10, 4, 2], state: "minecraft:deepslate_bricks"},
        {pos: [10, 4, 3], state: "minecraft:deepslate_tile_stairs{facing:north,half:bottom,shape:straight,waterlogged:false}"},
        {pos: [10, 4, 10], state: "minecraft:deepslate_tile_stairs{facing:south,half:top,shape:straight,waterlogged:false}"},
        {pos: [10, 4, 11], state: "minecraft:gray_wool"},
        {pos: [10, 4, 13], state: "minecraft:deepslate_tile_stairs{facing:north,half:top,shape:straight,waterlogged:false}"},
        {pos: [11, 4, 0], state: "minecraft:deepslate_bricks"},
        {pos: [11, 4, 1], state: "minecraft:gray_wool"},
        {pos: [11, 4, 2], state: "minecraft:deepslate_bricks"},
        {pos: [11, 4, 3], state: "minecraft:deepslate_tile_stairs{facing:north,half:bottom,shape:straight,waterlogged:false}"},
        {pos: [11, 4, 13], state: "minecraft:deepslate_tile_stairs{facing:north,half:top,shape:straight,waterlogged:false}"},
        {pos: [12, 4, 0], state: "minecraft:deepslate_bricks"},
        {pos: [12, 4, 1], state: "minecraft:gray_wool"},
        {pos: [12, 4, 2], state: "minecraft:deepslate_bricks"},
        {pos: [12, 4, 3], state: "minecraft:deepslate_tile_stairs{facing:north,half:bottom,shape:straight,waterlogged:false}"},
        {pos: [12, 4, 10], state: "minecraft:gray_wool"},
        {pos: [12, 4, 11], state: "minecraft:gray_wool"},
        {pos: [12, 4, 13], state: "minecraft:deepslate_bricks"},
        {pos: [13, 4, 0], state: "minecraft:deepslate_bricks"},
        {pos: [13, 4, 1], state: "minecraft:gray_wool"},
        {pos: [13, 4, 2], state: "minecraft:deepslate_bricks"},
        {pos: [13, 4, 3], state: "minecraft:gray_wool"},
        {pos: [13, 4, 10], state: "minecraft:gray_wool"},
        {pos: [13, 4, 11], state: "minecraft:gray_wool"},
        {pos: [13, 4, 12], state: "minecraft:deepslate_tile_stairs{facing:east,half:bottom,shape:straight,waterlogged:false}"},
        {pos: [13, 4, 13], state: "minecraft:deepslate_bricks"},
        {pos: [14, 4, 0], state: "minecraft:cracked_deepslate_bricks"},
        {pos: [14, 4, 1], state: "minecraft:gray_wool"},
        {pos: [14, 4, 2], state: "minecraft:deepslate_bricks"},
        {pos: [14, 4, 3], state: "minecraft:gray_wool"},
        {pos: [14, 4, 10], state: "minecraft:gray_wool"},
        {pos: [14, 4, 11], state: "minecraft:gray_wool"},
        {pos: [14, 4, 12], state: "minecraft:gray_wool"},
        {pos: [14, 4, 13], state: "minecraft:deepslate_bricks"},
        {pos: [15, 4, 0], state: "minecraft:deepslate_bricks"},
        {pos: [15, 4, 1], state: "minecraft:gray_wool"},
        {pos: [15, 4, 2], state: "minecraft:deepslate_bricks"},
        {pos: [15, 4, 3], state: "minecraft:gray_wool"},
        {pos: [15, 4, 10], state: "minecraft:gray_wool"},
        {pos: [15, 4, 11], state: "minecraft:gray_wool"},
        {pos: [15, 4, 12], state: "minecraft:gray_wool"},
        {pos: [15, 4, 13], state: "minecraft:deepslate_bricks"},
        {pos: [16, 4, 0], state: "minecraft:deepslate_bricks"},
        {pos: [16, 4, 1], state: "minecraft:gray_wool"},
        {pos: [16, 4, 2], state: "minecraft:deepslate_bricks"},
        {pos: [16, 4, 3], state: "minecraft:gray_wool"},
        {pos: [16, 4, 10], state: "minecraft:deepslate_tile_stairs{facing:south,half:top,shape:straight,waterlogged:false}"},
        {pos: [16, 4, 11], state: "minecraft:gray_wool"},
        {pos: [16, 4, 12], state: "minecraft:gray_wool"},
        {pos: [16, 4, 13], state: "minecraft:deepslate_tile_stairs{facing:north,half:top,shape:straight,waterlogged:false}"},
        {pos: [17, 4, 0], state: "minecraft:deepslate_bricks"},
        {pos: [17, 4, 1], state: "minecraft:gray_wool"},
        {pos: [17, 4, 2], state: "minecraft:deepslate_bricks"},
        {pos: [17, 4, 3], state: "minecraft:deepslate_tile_stairs{facing:north,half:bottom,shape:straight,waterlogged:false}"},
        {pos: [17, 4, 10], state: "minecraft:deepslate_tile_stairs{facing:south,half:top,shape:straight,waterlogged:false}"},
        {pos: [17, 4, 11], state: "minecraft:gray_wool"},
        {pos: [17, 4, 12], state: "minecraft:gray_wool"},
        {pos: [17, 4, 13], state: "minecraft:deepslate_tile_stairs{facing:north,half:top,shape:straight,waterlogged:false}"},
        {pos: [0, 5, 1], state: "minecraft:gray_wool"},
        {pos: [0, 5, 3], state: "minecraft:deepslate_tile_stairs{facing:north,half:top,shape:straight,waterlogged:false}"},
        {pos: [0, 5, 10], state: "minecraft:chiseled_deepslate"},
        {pos: [0, 5, 13], state: "minecraft:deepslate_tile_wall{east:low,north:none,south:none,up:true,waterlogged:false,west:none}"},
        {pos: [1, 5, 1], state: "minecraft:gray_wool"},
        {pos: [1, 5, 3], state: "minecraft:gray_wool"},
        {pos: [1, 5, 10], state: "minecraft:chiseled_deepslate"},
        {pos: [1, 5, 13], state: "minecraft:chiseled_deepslate"},
        {pos: [2, 5, 1], state: "minecraft:gray_wool"},
        {pos: [2, 5, 3], state: "minecraft:gray_wool"},
        {pos: [2, 5, 10], state: "minecraft:deepslate_tile_stairs{facing:north,half:bottom,shape:straight,waterlogged:false}"},
        {pos: [2, 5, 13], state: "minecraft:chiseled_deepslate"},
        {pos: [3, 5, 1], state: "minecraft:gray_wool"},
        {pos: [3, 5, 3], state: "minecraft:gray_wool"},
        {pos: [3, 5, 10], state: "minecraft:chiseled_deepslate"},
        {pos: [3, 5, 13], state: "minecraft:deepslate_tile_wall{east:low,north:none,south:none,up:false,waterlogged:false,west:low}"},
        {pos: [4, 5, 1], state: "minecraft:gray_wool"},
        {pos: [4, 5, 3], state: "minecraft:gray_wool"},
        {pos: [4, 5, 10], state: "minecraft:chiseled_deepslate"},
        {pos: [4, 5, 13], state: "minecraft:chiseled_deepslate"},
        {pos: [5, 5, 1], state: "minecraft:gray_wool"},
        {pos: [5, 5, 3], state: "minecraft:deepslate_tile_stairs{facing:north,half:top,shape:straight,waterlogged:false}"},
        {pos: [5, 5, 10], state: "minecraft:deepslate_tile_stairs{facing:north,half:bottom,shape:straight,waterlogged:false}"},
        {pos: [5, 5, 13], state: "minecraft:chiseled_deepslate"},
        {pos: [6, 5, 1], state: "minecraft:gray_wool"},
        {pos: [6, 5, 3], state: "minecraft:deepslate_tile_stairs{facing:north,half:top,shape:straight,waterlogged:false}"},
        {pos: [6, 5, 10], state: "minecraft:chiseled_deepslate"},
        {pos: [6, 5, 13], state: "minecraft:deepslate_tile_wall{east:low,north:none,south:none,up:false,waterlogged:false,west:low}"},
        {pos: [7, 5, 1], state: "minecraft:gray_wool"},
        {pos: [7, 5, 3], state: "minecraft:deepslate_tile_stairs{facing:north,half:top,shape:straight,waterlogged:false}"},
        {pos: [7, 5, 10], state: "minecraft:chiseled_deepslate"},
        {pos: [7, 5, 11], state: "minecraft:gray_wool"},
        {pos: [7, 5, 12], state: "minecraft:gray_wool"},
        {pos: [7, 5, 13], state: "minecraft:chiseled_deepslate"},
        {pos: [8, 5, 1], state: "minecraft:gray_wool"},
        {pos: [8, 5, 3], state: "minecraft:gray_wool"},
        {pos: [8, 5, 10], state: "minecraft:deepslate_tile_stairs{facing:north,half:bottom,shape:straight,waterlogged:false}"},
        {pos: [8, 5, 11], state: "minecraft:gray_wool"},
        {pos: [8, 5, 12], state: "minecraft:gray_wool"},
        {pos: [8, 5, 13], state: "minecraft:chiseled_deepslate"},
        {pos: [9, 5, 1], state: "minecraft:gray_wool"},
        {pos: [9, 5, 3], state: "minecraft:gray_wool"},
        {pos: [9, 5, 10], state: "minecraft:chiseled_deepslate"},
        {pos: [9, 5, 11], state: "minecraft:gray_wool"},
        {pos: [9, 5, 12], state: "minecraft:gray_wool"},
        {pos: [9, 5, 13], state: "minecraft:deepslate_tile_wall{east:low,north:low,south:none,up:true,waterlogged:false,west:low}"},
        {pos: [10, 5, 1], state: "minecraft:gray_wool"},
        {pos: [10, 5, 3], state: "minecraft:deepslate_tile_stairs{facing:north,half:top,shape:straight,waterlogged:false}"},
        {pos: [10, 5, 10], state: "minecraft:chiseled_deepslate"},
        {pos: [10, 5, 13], state: "minecraft:chiseled_deepslate"},
        {pos: [11, 5, 1], state: "minecraft:gray_wool"},
        {pos: [11, 5, 3], state: "minecraft:deepslate_tile_stairs{facing:north,half:top,shape:straight,waterlogged:false}"},
        {pos: [11, 5, 13], state: "minecraft:chiseled_deepslate"},
        {pos: [12, 5, 1], state: "minecraft:gray_wool"},
        {pos: [12, 5, 3], state: "minecraft:deepslate_tile_stairs{facing:north,half:top,shape:straight,waterlogged:false}"},
        {pos: [12, 5, 13], state: "minecraft:deepslate_tile_wall{east:low,north:none,south:none,up:false,waterlogged:false,west:low}"},
        {pos: [13, 5, 1], state: "minecraft:gray_wool"},
        {pos: [13, 5, 3], state: "minecraft:gray_wool"},
        {pos: [13, 5, 13], state: "minecraft:chiseled_deepslate"},
        {pos: [14, 5, 1], state: "minecraft:gray_wool"},
        {pos: [14, 5, 3], state: "minecraft:gray_wool"},
        {pos: [14, 5, 13], state: "minecraft:chiseled_deepslate"},
        {pos: [15, 5, 1], state: "minecraft:gray_wool"},
        {pos: [15, 5, 3], state: "minecraft:gray_wool"},
        {pos: [15, 5, 10], state: "minecraft:deepslate_tile_stairs{facing:north,half:bottom,shape:straight,waterlogged:false}"},
        {pos: [15, 5, 13], state: "minecraft:deepslate_tile_wall{east:low,north:none,south:none,up:false,waterlogged:false,west:low}"},
        {pos: [16, 5, 1], state: "minecraft:gray_wool"},
        {pos: [16, 5, 3], state: "minecraft:gray_wool"},
        {pos: [16, 5, 10], state: "minecraft:chiseled_deepslate"},
        {pos: [16, 5, 13], state: "minecraft:chiseled_deepslate"},
        {pos: [17, 5, 1], state: "minecraft:gray_wool"},
        {pos: [17, 5, 3], state: "minecraft:deepslate_tile_stairs{facing:north,half:top,shape:straight,waterlogged:false}"},
        {pos: [17, 5, 10], state: "minecraft:chiseled_deepslate"},
        {pos: [17, 5, 13], state: "minecraft:chiseled_deepslate"},
        {pos: [0, 6, 10], state: "minecraft:deepslate_tile_stairs{facing:north,half:bottom,shape:straight,waterlogged:false}"},
        {pos: [1, 6, 1], state: "minecraft:gray_wool"},
        {pos: [1, 6, 10], state: "minecraft:deepslate_tile_stairs{facing:north,half:bottom,shape:straight,waterlogged:false}"},
        {pos: [1, 6, 13], state: "minecraft:deepslate_tile_stairs{facing:north,half:bottom,shape:straight,waterlogged:false}"},
        {pos: [2, 6, 3], state: "minecraft:gray_wool"},
        {pos: [2, 6, 13], state: "minecraft:deepslate_tile_stairs{facing:north,half:bottom,shape:straight,waterlogged:false}"},
        {pos: [3, 6, 1], state: "minecraft:gray_wool"},
        {pos: [3, 6, 10], state: "minecraft:deepslate_tile_stairs{facing:north,half:bottom,shape:straight,waterlogged:false}"},
        {pos: [4, 6, 3], state: "minecraft:gray_wool"},
        {pos: [4, 6, 10], state: "minecraft:deepslate_tile_stairs{facing:north,half:bottom,shape:straight,waterlogged:false}"},
        {pos: [4, 6, 13], state: "minecraft:deepslate_tile_stairs{facing:north,half:bottom,shape:straight,waterlogged:false}"},
        {pos: [5, 6, 1], state: "minecraft:gray_wool"},
        {pos: [5, 6, 13], state: "minecraft:deepslate_tile_stairs{facing:north,half:bottom,shape:straight,waterlogged:false}"},
        {pos: [6, 6, 3], state: "minecraft:deepslate_tile_stairs{facing:north,half:bottom,shape:straight,waterlogged:false}"},
        {pos: [6, 6, 10], state: "minecraft:deepslate_tile_stairs{facing:north,half:bottom,shape:straight,waterlogged:false}"},
        {pos: [7, 6, 1], state: "minecraft:gray_wool"},
        {pos: [7, 6, 10], state: "minecraft:deepslate_tile_stairs{facing:north,half:bottom,shape:straight,waterlogged:false}"},
        {pos: [7, 6, 13], state: "minecraft:deepslate_tile_stairs{facing:north,half:bottom,shape:straight,waterlogged:false}"},
        {pos: [8, 6, 3], state: "minecraft:gray_wool"},
        {pos: [8, 6, 13], state: "minecraft:deepslate_tile_stairs{facing:north,half:bottom,shape:straight,waterlogged:false}"},
        {pos: [9, 6, 1], state: "minecraft:gray_wool"},
        {pos: [9, 6, 3], state: "minecraft:gray_wool"},
        {pos: [9, 6, 10], state: "minecraft:deepslate_tile_stairs{facing:north,half:bottom,shape:straight,waterlogged:false}"},
        {pos: [10, 6, 10], state: "minecraft:deepslate_tile_stairs{facing:north,half:bottom,shape:straight,waterlogged:false}"},
        {pos: [10, 6, 13], state: "minecraft:deepslate_tile_stairs{facing:north,half:bottom,shape:straight,waterlogged:false}"},
        {pos: [11, 6, 1], state: "minecraft:gray_wool"},
        {pos: [11, 6, 3], state: "minecraft:deepslate_tile_stairs{facing:north,half:bottom,shape:straight,waterlogged:false}"},
        {pos: [11, 6, 13], state: "minecraft:deepslate_tile_stairs{facing:north,half:bottom,shape:straight,waterlogged:false}"},
        {pos: [13, 6, 1], state: "minecraft:gray_wool"},
        {pos: [13, 6, 3], state: "minecraft:gray_wool"},
        {pos: [13, 6, 13], state: "minecraft:deepslate_tile_stairs{facing:north,half:bottom,shape:straight,waterlogged:false}"},
        {pos: [14, 6, 13], state: "minecraft:deepslate_tile_stairs{facing:north,half:bottom,shape:straight,waterlogged:false}"},
        {pos: [15, 6, 1], state: "minecraft:gray_wool"},
        {pos: [15, 6, 3], state: "minecraft:gray_wool"},
        {pos: [16, 6, 10], state: "minecraft:deepslate_tile_stairs{facing:north,half:bottom,shape:straight,waterlogged:false}"},
        {pos: [16, 6, 13], state: "minecraft:deepslate_tile_stairs{facing:north,half:bottom,shape:straight,waterlogged:false}"},
        {pos: [17, 6, 1], state: "minecraft:gray_wool"},
        {pos: [17, 6, 10], state: "minecraft:deepslate_tile_stairs{facing:north,half:bottom,shape:straight,waterlogged:false}"},
        {pos: [17, 6, 13], state: "minecraft:deepslate_tile_stairs{facing:north,half:bottom,shape:straight,waterlogged:false}"},
        {pos: [1, 7, 13], state: "minecraft:deepslate_tile_stairs{facing:west,half:bottom,shape:straight,waterlogged:false}"},
        {pos: [2, 7, 13], state: "minecraft:deepslate_tile_stairs{facing:east,half:bottom,shape:straight,waterlogged:false}"},
        {pos: [3, 7, 10], state: "minecraft:deepslate_tile_stairs{facing:west,half:bottom,shape:straight,waterlogged:false}"},
        {pos: [4, 7, 10], state: "minecraft:deepslate_tile_stairs{facing:east,half:bottom,shape:straight,waterlogged:false}"},
        {pos: [7, 7, 13], state: "minecraft:deepslate_tile_stairs{facing:west,half:bottom,shape:straight,waterlogged:false}"},
        {pos: [8, 7, 13], state: "minecraft:deepslate_tile_stairs{facing:east,half:bottom,shape:straight,waterlogged:false}"},
        {pos: [9, 7, 10], state: "minecraft:deepslate_tile_stairs{facing:west,half:bottom,shape:straight,waterlogged:false}"},
        {pos: [10, 7, 10], state: "minecraft:deepslate_tile_stairs{facing:east,half:bottom,shape:straight,waterlogged:false}"},
        {pos: [13, 7, 13], state: "minecraft:deepslate_tile_stairs{facing:west,half:bottom,shape:straight,waterlogged:false}"},
        {pos: [14, 7, 13], state: "minecraft:deepslate_tile_stairs{facing:east,half:bottom,shape:straight,waterlogged:false}"},
        {pos: [16, 7, 10], state: "minecraft:deepslate_tile_stairs{facing:west,half:bottom,shape:straight,waterlogged:false}"},
        {pos: [17, 7, 10], state: "minecraft:deepslate_tile_stairs{facing:east,half:bottom,shape:straight,waterlogged:false}"}
    ],
    entities: [],
    palette: [
        "minecraft:deepslate_bricks",
        "minecraft:deepslate{axis:y}",
        "minecraft:gray_wool",
        "minecraft:chiseled_deepslate",
        "minecraft:deepslate_tiles",
        "minecraft:cracked_deepslate_bricks",
        "minecraft:polished_deepslate_stairs{facing:east,half:bottom,shape:straight,waterlogged:false}",
        "minecraft:polished_deepslate_stairs{facing:west,half:bottom,shape:straight,waterlogged:false}",
        "minecraft:deepslate_brick_stairs{facing:east,half:bottom,shape:straight,waterlogged:false}",
        "minecraft:deepslate_brick_stairs{facing:south,half:bottom,shape:straight,waterlogged:false}",
        "minecraft:deepslate_brick_stairs{facing:west,half:bottom,shape:straight,waterlogged:false}",
        "minecraft:polished_deepslate_stairs{facing:south,half:bottom,shape:straight,waterlogged:false}",
        "minecraft:deepslate_brick_stairs{facing:west,half:bottom,shape:outer_left,waterlogged:false}",
        "minecraft:deepslate_tile_stairs{facing:south,half:bottom,shape:straight,waterlogged:false}",
        "minecraft:deepslate_tile_stairs{facing:north,half:top,shape:straight,waterlogged:false}",
        "minecraft:deepslate_tile_stairs{facing:north,half:bottom,shape:straight,waterlogged:false}",
        "minecraft:deepslate_tile_stairs{facing:south,half:top,shape:straight,waterlogged:false}",
        "minecraft:deepslate_tile_stairs{facing:west,half:top,shape:outer_left,waterlogged:false}",
        "minecraft:deepslate_tile_stairs{facing:east,half:top,shape:outer_right,waterlogged:false}",
        "minecraft:deepslate_tile_stairs{facing:east,half:bottom,shape:straight,waterlogged:false}",
        "minecraft:deepslate_tile_wall{east:low,north:none,south:none,up:true,waterlogged:false,west:none}",
        "minecraft:deepslate_tile_wall{east:low,north:none,south:none,up:false,waterlogged:false,west:low}",
        "minecraft:deepslate_tile_wall{east:low,north:low,south:none,up:true,waterlogged:false,west:low}",
        "minecraft:deepslate_tile_stairs{facing:west,half:bottom,shape:straight,waterlogged:false}",
        "minecraft:jigsaw{orientation:north_up}",
        "minecraft:jigsaw{orientation:south_up}"
    ]
}
