{
    DataVersion: 2856,
    size: [4, 4, 4],
    data: [
        {pos: [0, 0, 0], state: "minecraft:bone_block{axis:y}"},
        {pos: [1, 0, 1], state: "minecraft:bone_block{axis:x}"},
        {pos: [1, 0, 2], state: "minecraft:bone_block{axis:x}"},
        {pos: [2, 0, 1], state: "minecraft:bone_block{axis:x}"},
        {pos: [2, 0, 2], state: "minecraft:bone_block{axis:x}"},
        {pos: [3, 0, 0], state: "minecraft:bone_block{axis:y}"},
        {pos: [0, 1, 0], state: "minecraft:bone_block{axis:y}"},
        {pos: [0, 1, 1], state: "minecraft:bone_block{axis:y}"},
        {pos: [0, 1, 2], state: "minecraft:bone_block{axis:y}"},
        {pos: [1, 1, 0], state: "minecraft:bone_block{axis:x}"},
        {pos: [1, 1, 3], state: "minecraft:bone_block{axis:y}"},
        {pos: [2, 1, 0], state: "minecraft:bone_block{axis:x}"},
        {pos: [2, 1, 3], state: "minecraft:bone_block{axis:y}"},
        {pos: [3, 1, 0], state: "minecraft:bone_block{axis:y}"},
        {pos: [3, 1, 1], state: "minecraft:bone_block{axis:y}"},
        {pos: [3, 1, 2], state: "minecraft:bone_block{axis:y}"},
        {pos: [0, 2, 0], state: "minecraft:bone_block{axis:y}"},
        {pos: [0, 2, 1], state: "minecraft:bone_block{axis:y}"},
        {pos: [0, 2, 2], state: "minecraft:bone_block{axis:y}"},
        {pos: [1, 2, 3], state: "minecraft:bone_block{axis:y}"},
        {pos: [2, 2, 3], state: "minecraft:bone_block{axis:y}"},
        {pos: [3, 2, 0], state: "minecraft:bone_block{axis:y}"},
        {pos: [3, 2, 1], state: "minecraft:bone_block{axis:y}"},
        {pos: [3, 2, 2], state: "minecraft:bone_block{axis:y}"},
        {pos: [0, 3, 0], state: "minecraft:bone_block{axis:x}"},
        {pos: [1, 3, 0], state: "minecraft:bone_block{axis:x}"},
        {pos: [1, 3, 1], state: "minecraft:bone_block{axis:x}"},
        {pos: [1, 3, 2], state: "minecraft:bone_block{axis:x}"},
        {pos: [2, 3, 0], state: "minecraft:bone_block{axis:x}"},
        {pos: [2, 3, 1], state: "minecraft:bone_block{axis:x}"},
        {pos: [2, 3, 2], state: "minecraft:bone_block{axis:x}"},
        {pos: [3, 3, 0], state: "minecraft:bone_block{axis:x}"}
    ],
    entities: [],
    palette: [
        "minecraft:bone_block{axis:y}",
        "minecraft:bone_block{axis:x}"
    ]
}
