{
    DataVersion: 2856,
    size: [5, 4, 5],
    data: [
        {pos: [0, 0, 0], state: "minecraft:bone_block{axis:y}"},
        {pos: [1, 0, 1], state: "minecraft:bone_block{axis:x}"},
        {pos: [1, 0, 2], state: "minecraft:bone_block{axis:x}"},
        {pos: [1, 0, 3], state: "minecraft:bone_block{axis:x}"},
        {pos: [1, 0, 4], state: "minecraft:bone_block{axis:x}"},
        {pos: [2, 0, 1], state: "minecraft:bone_block{axis:x}"},
        {pos: [2, 0, 2], state: "minecraft:bone_block{axis:x}"},
        {pos: [2, 0, 3], state: "minecraft:bone_block{axis:x}"},
        {pos: [2, 0, 4], state: "minecraft:bone_block{axis:x}"},
        {pos: [3, 0, 1], state: "minecraft:bone_block{axis:x}"},
        {pos: [3, 0, 2], state: "minecraft:bone_block{axis:x}"},
        {pos: [3, 0, 3], state: "minecraft:bone_block{axis:x}"},
        {pos: [3, 0, 4], state: "minecraft:bone_block{axis:x}"},
        {pos: [4, 0, 0], state: "minecraft:bone_block{axis:y}"},
        {pos: [0, 1, 0], state: "minecraft:bone_block{axis:y}"},
        {pos: [0, 1, 1], state: "minecraft:bone_block{axis:z}"},
        {pos: [0, 1, 2], state: "minecraft:bone_block{axis:z}"},
        {pos: [0, 1, 3], state: "minecraft:bone_block{axis:z}"},
        {pos: [0, 1, 4], state: "minecraft:bone_block{axis:y}"},
        {pos: [1, 1, 0], state: "minecraft:bone_block{axis:x}"},
        {pos: [1, 1, 4], state: "minecraft:bone_block{axis:x}"},
        {pos: [2, 1, 0], state: "minecraft:bone_block{axis:x}"},
        {pos: [2, 1, 4], state: "minecraft:bone_block{axis:x}"},
        {pos: [3, 1, 0], state: "minecraft:bone_block{axis:x}"},
        {pos: [3, 1, 4], state: "minecraft:bone_block{axis:x}"},
        {pos: [4, 1, 0], state: "minecraft:bone_block{axis:y}"},
        {pos: [4, 1, 1], state: "minecraft:bone_block{axis:z}"},
        {pos: [4, 1, 2], state: "minecraft:bone_block{axis:z}"},
        {pos: [4, 1, 3], state: "minecraft:bone_block{axis:z}"},
        {pos: [4, 1, 4], state: "minecraft:bone_block{axis:y}"},
        {pos: [0, 2, 0], state: "minecraft:bone_block{axis:y}"},
        {pos: [0, 2, 1], state: "minecraft:bone_block{axis:z}"},
        {pos: [0, 2, 2], state: "minecraft:bone_block{axis:z}"},
        {pos: [0, 2, 3], state: "minecraft:bone_block{axis:z}"},
        {pos: [0, 2, 4], state: "minecraft:bone_block{axis:y}"},
        {pos: [1, 2, 4], state: "minecraft:bone_block{axis:x}"},
        {pos: [2, 2, 0], state: "minecraft:bone_block{axis:y}"},
        {pos: [2, 2, 4], state: "minecraft:bone_block{axis:x}"},
        {pos: [3, 2, 4], state: "minecraft:bone_block{axis:x}"},
        {pos: [4, 2, 0], state: "minecraft:bone_block{axis:y}"},
        {pos: [4, 2, 1], state: "minecraft:bone_block{axis:z}"},
        {pos: [4, 2, 2], state: "minecraft:bone_block{axis:z}"},
        {pos: [4, 2, 3], state: "minecraft:bone_block{axis:z}"},
        {pos: [4, 2, 4], state: "minecraft:bone_block{axis:y}"},
        {pos: [0, 3, 0], state: "minecraft:bone_block{axis:x}"},
        {pos: [1, 3, 0], state: "minecraft:bone_block{axis:x}"},
        {pos: [1, 3, 1], state: "minecraft:bone_block{axis:x}"},
        {pos: [1, 3, 2], state: "minecraft:bone_block{axis:x}"},
        {pos: [1, 3, 3], state: "minecraft:bone_block{axis:x}"},
        {pos: [2, 3, 0], state: "minecraft:bone_block{axis:x}"},
        {pos: [2, 3, 1], state: "minecraft:bone_block{axis:x}"},
        {pos: [2, 3, 2], state: "minecraft:bone_block{axis:x}"},
        {pos: [2, 3, 3], state: "minecraft:bone_block{axis:x}"},
        {pos: [3, 3, 0], state: "minecraft:bone_block{axis:x}"},
        {pos: [3, 3, 1], state: "minecraft:bone_block{axis:x}"},
        {pos: [3, 3, 2], state: "minecraft:bone_block{axis:x}"},
        {pos: [3, 3, 3], state: "minecraft:bone_block{axis:x}"},
        {pos: [4, 3, 0], state: "minecraft:bone_block{axis:x}"}
    ],
    entities: [],
    palette: [
        "minecraft:bone_block{axis:y}",
        "minecraft:bone_block{axis:x}",
        "minecraft:bone_block{axis:z}"
    ]
}
