{
    DataVersion: 2856,
    size: [7, 5, 5],
    data: [
        {pos: [1, 0, 1], state: "minecraft:bone_block{axis:x}"},
        {pos: [1, 0, 2], state: "minecraft:bone_block{axis:x}"},
        {pos: [1, 0, 3], state: "minecraft:bone_block{axis:x}"},
        {pos: [2, 0, 1], state: "minecraft:bone_block{axis:x}"},
        {pos: [2, 0, 2], state: "minecraft:bone_block{axis:x}"},
        {pos: [2, 0, 3], state: "minecraft:bone_block{axis:x}"},
        {pos: [3, 0, 1], state: "minecraft:bone_block{axis:x}"},
        {pos: [3, 0, 2], state: "minecraft:bone_block{axis:x}"},
        {pos: [3, 0, 3], state: "minecraft:bone_block{axis:x}"},
        {pos: [4, 0, 1], state: "minecraft:bone_block{axis:x}"},
        {pos: [4, 0, 2], state: "minecraft:bone_block{axis:x}"},
        {pos: [4, 0, 3], state: "minecraft:bone_block{axis:x}"},
        {pos: [5, 0, 1], state: "minecraft:bone_block{axis:x}"},
        {pos: [5, 0, 2], state: "minecraft:bone_block{axis:x}"},
        {pos: [5, 0, 3], state: "minecraft:bone_block{axis:x}"},
        {pos: [0, 1, 1], state: "minecraft:bone_block{axis:y}"},
        {pos: [0, 1, 2], state: "minecraft:bone_block{axis:z}"},
        {pos: [0, 1, 3], state: "minecraft:bone_block{axis:y}"},
        {pos: [1, 1, 0], state: "minecraft:bone_block{axis:y}"},
        {pos: [1, 1, 4], state: "minecraft:bone_block{axis:y}"},
        {pos: [2, 1, 4], state: "minecraft:bone_block{axis:x}"},
        {pos: [3, 1, 4], state: "minecraft:bone_block{axis:x}"},
        {pos: [4, 1, 4], state: "minecraft:bone_block{axis:x}"},
        {pos: [5, 1, 0], state: "minecraft:bone_block{axis:y}"},
        {pos: [5, 1, 4], state: "minecraft:bone_block{axis:y}"},
        {pos: [6, 1, 1], state: "minecraft:bone_block{axis:y}"},
        {pos: [6, 1, 2], state: "minecraft:bone_block{axis:z}"},
        {pos: [6, 1, 3], state: "minecraft:bone_block{axis:y}"},
        {pos: [0, 2, 1], state: "minecraft:bone_block{axis:y}"},
        {pos: [0, 2, 2], state: "minecraft:bone_block{axis:z}"},
        {pos: [0, 2, 3], state: "minecraft:bone_block{axis:y}"},
        {pos: [1, 2, 0], state: "minecraft:bone_block{axis:y}"},
        {pos: [1, 2, 4], state: "minecraft:bone_block{axis:y}"},
        {pos: [2, 2, 0], state: "minecraft:bone_block{axis:x}"},
        {pos: [2, 2, 4], state: "minecraft:bone_block{axis:x}"},
        {pos: [3, 2, 0], state: "minecraft:bone_block{axis:x}"},
        {pos: [3, 2, 4], state: "minecraft:bone_block{axis:x}"},
        {pos: [4, 2, 0], state: "minecraft:bone_block{axis:x}"},
        {pos: [4, 2, 4], state: "minecraft:bone_block{axis:x}"},
        {pos: [5, 2, 0], state: "minecraft:bone_block{axis:y}"},
        {pos: [5, 2, 4], state: "minecraft:bone_block{axis:y}"},
        {pos: [6, 2, 1], state: "minecraft:bone_block{axis:y}"},
        {pos: [6, 2, 2], state: "minecraft:bone_block{axis:z}"},
        {pos: [6, 2, 3], state: "minecraft:bone_block{axis:y}"},
        {pos: [0, 3, 1], state: "minecraft:bone_block{axis:y}"},
        {pos: [0, 3, 2], state: "minecraft:bone_block{axis:z}"},
        {pos: [0, 3, 3], state: "minecraft:bone_block{axis:y}"},
        {pos: [1, 3, 0], state: "minecraft:bone_block{axis:y}"},
        {pos: [1, 3, 4], state: "minecraft:bone_block{axis:y}"},
        {pos: [2, 3, 4], state: "minecraft:bone_block{axis:x}"},
        {pos: [3, 3, 0], state: "minecraft:bone_block{axis:y}"},
        {pos: [3, 3, 4], state: "minecraft:bone_block{axis:x}"},
        {pos: [4, 3, 4], state: "minecraft:bone_block{axis:x}"},
        {pos: [5, 3, 0], state: "minecraft:bone_block{axis:y}"},
        {pos: [5, 3, 4], state: "minecraft:bone_block{axis:y}"},
        {pos: [6, 3, 1], state: "minecraft:bone_block{axis:y}"},
        {pos: [6, 3, 2], state: "minecraft:bone_block{axis:z}"},
        {pos: [6, 3, 3], state: "minecraft:bone_block{axis:y}"},
        {pos: [1, 4, 1], state: "minecraft:bone_block{axis:x}"},
        {pos: [1, 4, 2], state: "minecraft:bone_block{axis:x}"},
        {pos: [1, 4, 3], state: "minecraft:bone_block{axis:x}"},
        {pos: [2, 4, 0], state: "minecraft:bone_block{axis:x}"},
        {pos: [2, 4, 1], state: "minecraft:bone_block{axis:x}"},
        {pos: [2, 4, 2], state: "minecraft:bone_block{axis:x}"},
        {pos: [2, 4, 3], state: "minecraft:bone_block{axis:x}"},
        {pos: [3, 4, 1], state: "minecraft:bone_block{axis:x}"},
        {pos: [3, 4, 2], state: "minecraft:bone_block{axis:x}"},
        {pos: [3, 4, 3], state: "minecraft:bone_block{axis:x}"},
        {pos: [4, 4, 0], state: "minecraft:bone_block{axis:x}"},
        {pos: [4, 4, 1], state: "minecraft:bone_block{axis:x}"},
        {pos: [4, 4, 2], state: "minecraft:bone_block{axis:x}"},
        {pos: [4, 4, 3], state: "minecraft:bone_block{axis:x}"},
        {pos: [5, 4, 1], state: "minecraft:bone_block{axis:x}"},
        {pos: [5, 4, 2], state: "minecraft:bone_block{axis:x}"},
        {pos: [5, 4, 3], state: "minecraft:bone_block{axis:x}"}
    ],
    entities: [],
    palette: [
        "minecraft:bone_block{axis:x}",
        "minecraft:bone_block{axis:y}",
        "minecraft:bone_block{axis:z}"
    ]
}
