{
    DataVersion: 2856,
    size: [5, 4, 13],
    data: [
        {pos: [1, 0, 1], state: "minecraft:coal_ore"},
        {pos: [1, 0, 3], state: "minecraft:coal_ore"},
        {pos: [1, 0, 5], state: "minecraft:coal_ore"},
        {pos: [1, 0, 7], state: "minecraft:coal_ore"},
        {pos: [1, 0, 9], state: "minecraft:coal_ore"},
        {pos: [1, 0, 11], state: "minecraft:coal_ore"},
        {pos: [3, 0, 1], state: "minecraft:coal_ore"},
        {pos: [3, 0, 3], state: "minecraft:coal_ore"},
        {pos: [3, 0, 5], state: "minecraft:coal_ore"},
        {pos: [3, 0, 7], state: "minecraft:coal_ore"},
        {pos: [3, 0, 9], state: "minecraft:coal_ore"},
        {pos: [3, 0, 11], state: "minecraft:coal_ore"},
        {pos: [0, 1, 1], state: "minecraft:coal_ore"},
        {pos: [0, 1, 3], state: "minecraft:coal_ore"},
        {pos: [0, 1, 5], state: "minecraft:coal_ore"},
        {pos: [0, 1, 7], state: "minecraft:coal_ore"},
        {pos: [0, 1, 9], state: "minecraft:coal_ore"},
        {pos: [0, 1, 11], state: "minecraft:coal_ore"},
        {pos: [4, 1, 1], state: "minecraft:coal_ore"},
        {pos: [4, 1, 3], state: "minecraft:coal_ore"},
        {pos: [4, 1, 5], state: "minecraft:coal_ore"},
        {pos: [4, 1, 7], state: "minecraft:coal_ore"},
        {pos: [4, 1, 9], state: "minecraft:coal_ore"},
        {pos: [4, 1, 11], state: "minecraft:coal_ore"},
        {pos: [0, 2, 1], state: "minecraft:coal_ore"},
        {pos: [0, 2, 3], state: "minecraft:coal_ore"},
        {pos: [0, 2, 5], state: "minecraft:coal_ore"},
        {pos: [0, 2, 7], state: "minecraft:coal_ore"},
        {pos: [0, 2, 9], state: "minecraft:coal_ore"},
        {pos: [0, 2, 11], state: "minecraft:coal_ore"},
        {pos: [4, 2, 1], state: "minecraft:coal_ore"},
        {pos: [4, 2, 3], state: "minecraft:coal_ore"},
        {pos: [4, 2, 5], state: "minecraft:coal_ore"},
        {pos: [4, 2, 7], state: "minecraft:coal_ore"},
        {pos: [4, 2, 9], state: "minecraft:coal_ore"},
        {pos: [4, 2, 11], state: "minecraft:coal_ore"},
        {pos: [1, 3, 1], state: "minecraft:coal_ore"},
        {pos: [1, 3, 3], state: "minecraft:coal_ore"},
        {pos: [1, 3, 5], state: "minecraft:coal_ore"},
        {pos: [1, 3, 7], state: "minecraft:coal_ore"},
        {pos: [1, 3, 9], state: "minecraft:coal_ore"},
        {pos: [1, 3, 11], state: "minecraft:coal_ore"},
        {pos: [2, 3, 0], state: "minecraft:coal_ore"},
        {pos: [2, 3, 1], state: "minecraft:coal_ore"},
        {pos: [2, 3, 2], state: "minecraft:coal_ore"},
        {pos: [2, 3, 3], state: "minecraft:coal_ore"},
        {pos: [2, 3, 4], state: "minecraft:coal_ore"},
        {pos: [2, 3, 5], state: "minecraft:coal_ore"},
        {pos: [2, 3, 6], state: "minecraft:coal_ore"},
        {pos: [2, 3, 7], state: "minecraft:coal_ore"},
        {pos: [2, 3, 8], state: "minecraft:coal_ore"},
        {pos: [2, 3, 9], state: "minecraft:coal_ore"},
        {pos: [2, 3, 10], state: "minecraft:coal_ore"},
        {pos: [2, 3, 11], state: "minecraft:coal_ore"},
        {pos: [2, 3, 12], state: "minecraft:coal_ore"},
        {pos: [3, 3, 1], state: "minecraft:coal_ore"},
        {pos: [3, 3, 3], state: "minecraft:coal_ore"},
        {pos: [3, 3, 5], state: "minecraft:coal_ore"},
        {pos: [3, 3, 7], state: "minecraft:coal_ore"},
        {pos: [3, 3, 9], state: "minecraft:coal_ore"},
        {pos: [3, 3, 11], state: "minecraft:coal_ore"}
    ],
    entities: [],
    palette: [
        "minecraft:coal_ore"
    ]
}
