{
    size: [5, 4, 13],
    data: [
        {pos: [1, 0, 1], state: "minecraft:bone_block{axis:x}"},
        {pos: [1, 0, 3], state: "minecraft:bone_block{axis:x}"},
        {pos: [1, 0, 5], state: "minecraft:bone_block{axis:x}"},
        {pos: [1, 0, 7], state: "minecraft:bone_block{axis:x}"},
        {pos: [1, 0, 9], state: "minecraft:bone_block{axis:x}"},
        {pos: [1, 0, 11], state: "minecraft:bone_block{axis:x}"},
        {pos: [3, 0, 1], state: "minecraft:bone_block{axis:x}"},
        {pos: [3, 0, 3], state: "minecraft:bone_block{axis:x}"},
        {pos: [3, 0, 5], state: "minecraft:bone_block{axis:x}"},
        {pos: [3, 0, 7], state: "minecraft:bone_block{axis:x}"},
        {pos: [3, 0, 9], state: "minecraft:bone_block{axis:x}"},
        {pos: [3, 0, 11], state: "minecraft:bone_block{axis:x}"},
        {pos: [0, 1, 1], state: "minecraft:bone_block{axis:y}"},
        {pos: [0, 1, 3], state: "minecraft:bone_block{axis:y}"},
        {pos: [0, 1, 5], state: "minecraft:bone_block{axis:y}"},
        {pos: [0, 1, 7], state: "minecraft:bone_block{axis:y}"},
        {pos: [0, 1, 9], state: "minecraft:bone_block{axis:y}"},
        {pos: [0, 1, 11], state: "minecraft:bone_block{axis:y}"},
        {pos: [4, 1, 1], state: "minecraft:bone_block{axis:y}"},
        {pos: [4, 1, 3], state: "minecraft:bone_block{axis:y}"},
        {pos: [4, 1, 5], state: "minecraft:bone_block{axis:y}"},
        {pos: [4, 1, 7], state: "minecraft:bone_block{axis:y}"},
        {pos: [4, 1, 9], state: "minecraft:bone_block{axis:y}"},
        {pos: [4, 1, 11], state: "minecraft:bone_block{axis:y}"},
        {pos: [0, 2, 1], state: "minecraft:bone_block{axis:y}"},
        {pos: [0, 2, 3], state: "minecraft:bone_block{axis:y}"},
        {pos: [0, 2, 5], state: "minecraft:bone_block{axis:y}"},
        {pos: [0, 2, 7], state: "minecraft:bone_block{axis:y}"},
        {pos: [0, 2, 9], state: "minecraft:bone_block{axis:y}"},
        {pos: [0, 2, 11], state: "minecraft:bone_block{axis:y}"},
        {pos: [4, 2, 1], state: "minecraft:bone_block{axis:y}"},
        {pos: [4, 2, 3], state: "minecraft:bone_block{axis:y}"},
        {pos: [4, 2, 5], state: "minecraft:bone_block{axis:y}"},
        {pos: [4, 2, 7], state: "minecraft:bone_block{axis:y}"},
        {pos: [4, 2, 9], state: "minecraft:bone_block{axis:y}"},
        {pos: [4, 2, 11], state: "minecraft:bone_block{axis:y}"},
        {pos: [1, 3, 1], state: "minecraft:bone_block{axis:x}"},
        {pos: [1, 3, 3], state: "minecraft:bone_block{axis:x}"},
        {pos: [1, 3, 5], state: "minecraft:bone_block{axis:x}"},
        {pos: [1, 3, 7], state: "minecraft:bone_block{axis:x}"},
        {pos: [1, 3, 9], state: "minecraft:bone_block{axis:x}"},
        {pos: [1, 3, 11], state: "minecraft:bone_block{axis:x}"},
        {pos: [2, 3, 0], state: "minecraft:bone_block{axis:z}"},
        {pos: [2, 3, 1], state: "minecraft:bone_block{axis:z}"},
        {pos: [2, 3, 2], state: "minecraft:bone_block{axis:z}"},
        {pos: [2, 3, 3], state: "minecraft:bone_block{axis:z}"},
        {pos: [2, 3, 4], state: "minecraft:bone_block{axis:z}"},
        {pos: [2, 3, 5], state: "minecraft:bone_block{axis:z}"},
        {pos: [2, 3, 6], state: "minecraft:bone_block{axis:z}"},
        {pos: [2, 3, 7], state: "minecraft:bone_block{axis:z}"},
        {pos: [2, 3, 8], state: "minecraft:bone_block{axis:z}"},
        {pos: [2, 3, 9], state: "minecraft:bone_block{axis:z}"},
        {pos: [2, 3, 10], state: "minecraft:bone_block{axis:z}"},
        {pos: [2, 3, 11], state: "minecraft:bone_block{axis:z}"},
        {pos: [2, 3, 12], state: "minecraft:bone_block{axis:z}"},
        {pos: [3, 3, 1], state: "minecraft:bone_block{axis:x}"},
        {pos: [3, 3, 3], state: "minecraft:bone_block{axis:x}"},
        {pos: [3, 3, 5], state: "minecraft:bone_block{axis:x}"},
        {pos: [3, 3, 7], state: "minecraft:bone_block{axis:x}"},
        {pos: [3, 3, 9], state: "minecraft:bone_block{axis:x}"},
        {pos: [3, 3, 11], state: "minecraft:bone_block{axis:x}"}
    ],
    entities: [],
    palette: [
        "minecraft:bone_block{axis:x}",
        "minecraft:bone_block{axis:y}",
        "minecraft:bone_block{axis:z}"
    ]
}
