{
    DataVersion: 2856,
    size: [3, 3, 13],
    data: [
        {pos: [0, 0, 1], state: "minecraft:coal_ore"},
        {pos: [0, 0, 3], state: "minecraft:coal_ore"},
        {pos: [0, 0, 5], state: "minecraft:coal_ore"},
        {pos: [0, 0, 7], state: "minecraft:coal_ore"},
        {pos: [0, 0, 9], state: "minecraft:coal_ore"},
        {pos: [0, 0, 11], state: "minecraft:coal_ore"},
        {pos: [2, 0, 1], state: "minecraft:coal_ore"},
        {pos: [2, 0, 3], state: "minecraft:coal_ore"},
        {pos: [2, 0, 5], state: "minecraft:coal_ore"},
        {pos: [2, 0, 7], state: "minecraft:coal_ore"},
        {pos: [2, 0, 9], state: "minecraft:coal_ore"},
        {pos: [2, 0, 11], state: "minecraft:coal_ore"},
        {pos: [0, 1, 1], state: "minecraft:coal_ore"},
        {pos: [0, 1, 3], state: "minecraft:coal_ore"},
        {pos: [0, 1, 5], state: "minecraft:coal_ore"},
        {pos: [0, 1, 7], state: "minecraft:coal_ore"},
        {pos: [0, 1, 9], state: "minecraft:coal_ore"},
        {pos: [0, 1, 11], state: "minecraft:coal_ore"},
        {pos: [2, 1, 1], state: "minecraft:coal_ore"},
        {pos: [2, 1, 3], state: "minecraft:coal_ore"},
        {pos: [2, 1, 5], state: "minecraft:coal_ore"},
        {pos: [2, 1, 7], state: "minecraft:coal_ore"},
        {pos: [2, 1, 9], state: "minecraft:coal_ore"},
        {pos: [2, 1, 11], state: "minecraft:coal_ore"},
        {pos: [1, 2, 0], state: "minecraft:coal_ore"},
        {pos: [1, 2, 1], state: "minecraft:coal_ore"},
        {pos: [1, 2, 2], state: "minecraft:coal_ore"},
        {pos: [1, 2, 3], state: "minecraft:coal_ore"},
        {pos: [1, 2, 4], state: "minecraft:coal_ore"},
        {pos: [1, 2, 5], state: "minecraft:coal_ore"},
        {pos: [1, 2, 6], state: "minecraft:coal_ore"},
        {pos: [1, 2, 7], state: "minecraft:coal_ore"},
        {pos: [1, 2, 8], state: "minecraft:coal_ore"},
        {pos: [1, 2, 9], state: "minecraft:coal_ore"},
        {pos: [1, 2, 10], state: "minecraft:coal_ore"},
        {pos: [1, 2, 11], state: "minecraft:coal_ore"},
        {pos: [1, 2, 12], state: "minecraft:coal_ore"}
    ],
    entities: [],
    palette: [
        "minecraft:coal_ore"
    ]
}
