{
    size: [10, 10, 10],
    data: [
        {pos: [0, 0, 0], state: "minecraft:grass_block{snowy:false}"},
        {pos: [0, 0, 1], state: "minecraft:grass_block{snowy:false}"},
        {pos: [0, 0, 2], state: "minecraft:grass_block{snowy:false}"},
        {pos: [0, 0, 3], state: "minecraft:grass_block{snowy:false}"},
        {pos: [0, 0, 4], state: "minecraft:dirt"},
        {pos: [0, 0, 5], state: "minecraft:dirt"},
        {pos: [0, 0, 6], state: "minecraft:dirt"},
        {pos: [0, 0, 7], state: "minecraft:grass_block{snowy:false}"},
        {pos: [0, 0, 8], state: "minecraft:grass_block{snowy:false}"},
        {pos: [0, 0, 9], state: "minecraft:grass_block{snowy:false}"},
        {pos: [1, 0, 0], state: "minecraft:grass_block{snowy:false}"},
        {pos: [1, 0, 1], state: "minecraft:dirt"},
        {pos: [1, 0, 2], state: "minecraft:dirt"},
        {pos: [1, 0, 3], state: "minecraft:dirt"},
        {pos: [1, 0, 4], state: "minecraft:cobblestone"},
        {pos: [1, 0, 5], state: "minecraft:sand"},
        {pos: [1, 0, 6], state: "minecraft:sand"},
        {pos: [1, 0, 7], state: "minecraft:sand"},
        {pos: [1, 0, 8], state: "minecraft:dirt"},
        {pos: [1, 0, 9], state: "minecraft:grass_block{snowy:false}"},
        {pos: [2, 0, 0], state: "minecraft:grass_block{snowy:false}"},
        {pos: [2, 0, 1], state: "minecraft:dirt"},
        {pos: [2, 0, 2], state: "minecraft:dirt"},
        {pos: [2, 0, 3], state: "minecraft:sand"},
        {pos: [2, 0, 4], state: "minecraft:sand"},
        {pos: [2, 0, 5], state: "minecraft:cobblestone"},
        {pos: [2, 0, 6], state: "minecraft:sand"},
        {pos: [2, 0, 7], state: "minecraft:dirt"},
        {pos: [2, 0, 8], state: "minecraft:dirt"},
        {pos: [2, 0, 9], state: "minecraft:grass_block{snowy:false}"},
        {pos: [3, 0, 0], state: "minecraft:grass_block{snowy:false}"},
        {pos: [3, 0, 1], state: "minecraft:dirt"},
        {pos: [3, 0, 2], state: "minecraft:dirt"},
        {pos: [3, 0, 3], state: "minecraft:sand"},
        {pos: [3, 0, 4], state: "minecraft:cobblestone"},
        {pos: [3, 0, 5], state: "minecraft:sand"},
        {pos: [3, 0, 6], state: "minecraft:sand"},
        {pos: [3, 0, 7], state: "minecraft:dirt"},
        {pos: [3, 0, 8], state: "minecraft:dirt"},
        {pos: [3, 0, 9], state: "minecraft:grass_block{snowy:false}"},
        {pos: [4, 0, 0], state: "minecraft:grass_block{snowy:false}"},
        {pos: [4, 0, 1], state: "minecraft:dirt"},
        {pos: [4, 0, 2], state: "minecraft:dirt"},
        {pos: [4, 0, 3], state: "minecraft:sand"},
        {pos: [4, 0, 4], state: "minecraft:sand"},
        {pos: [4, 0, 5], state: "minecraft:sand"},
        {pos: [4, 0, 6], state: "minecraft:dirt"},
        {pos: [4, 0, 7], state: "minecraft:dirt"},
        {pos: [4, 0, 8], state: "minecraft:dirt"},
        {pos: [4, 0, 9], state: "minecraft:grass_block{snowy:false}"},
        {pos: [5, 0, 0], state: "minecraft:grass_block{snowy:false}"},
        {pos: [5, 0, 1], state: "minecraft:dirt"},
        {pos: [5, 0, 2], state: "minecraft:dirt"},
        {pos: [5, 0, 3], state: "minecraft:dirt"},
        {pos: [5, 0, 4], state: "minecraft:sand"},
        {pos: [5, 0, 5], state: "minecraft:dirt"},
        {pos: [5, 0, 6], state: "minecraft:dirt"},
        {pos: [5, 0, 7], state: "minecraft:dirt"},
        {pos: [5, 0, 8], state: "minecraft:dirt"},
        {pos: [5, 0, 9], state: "minecraft:grass_block{snowy:false}"},
        {pos: [6, 0, 0], state: "minecraft:grass_block{snowy:false}"},
        {pos: [6, 0, 1], state: "minecraft:dirt"},
        {pos: [6, 0, 2], state: "minecraft:dirt"},
        {pos: [6, 0, 3], state: "minecraft:dirt"},
        {pos: [6, 0, 4], state: "minecraft:dirt"},
        {pos: [6, 0, 5], state: "minecraft:dirt"},
        {pos: [6, 0, 6], state: "minecraft:dirt"},
        {pos: [6, 0, 7], state: "minecraft:dirt"},
        {pos: [6, 0, 8], state: "minecraft:dirt"},
        {pos: [6, 0, 9], state: "minecraft:grass_block{snowy:false}"},
        {pos: [7, 0, 0], state: "minecraft:grass_block{snowy:false}"},
        {pos: [7, 0, 1], state: "minecraft:dirt"},
        {pos: [7, 0, 2], state: "minecraft:dirt"},
        {pos: [7, 0, 3], state: "minecraft:dirt"},
        {pos: [7, 0, 4], state: "minecraft:dirt"},
        {pos: [7, 0, 5], state: "minecraft:dirt"},
        {pos: [7, 0, 6], state: "minecraft:dirt"},
        {pos: [7, 0, 7], state: "minecraft:dirt"},
        {pos: [7, 0, 8], state: "minecraft:dirt"},
        {pos: [7, 0, 9], state: "minecraft:grass_block{snowy:false}"},
        {pos: [8, 0, 0], state: "minecraft:grass_block{snowy:false}"},
        {pos: [8, 0, 1], state: "minecraft:dirt"},
        {pos: [8, 0, 2], state: "minecraft:dirt"},
        {pos: [8, 0, 3], state: "minecraft:dirt"},
        {pos: [8, 0, 4], state: "minecraft:dirt"},
        {pos: [8, 0, 5], state: "minecraft:dirt"},
        {pos: [8, 0, 6], state: "minecraft:dirt"},
        {pos: [8, 0, 7], state: "minecraft:dirt"},
        {pos: [8, 0, 8], state: "minecraft:grass_block{snowy:false}"},
        {pos: [8, 0, 9], state: "minecraft:grass_block{snowy:false}"},
        {pos: [9, 0, 0], state: "minecraft:grass_block{snowy:false}"},
        {pos: [9, 0, 1], state: "minecraft:grass_block{snowy:false}"},
        {pos: [9, 0, 2], state: "minecraft:dirt"},
        {pos: [9, 0, 3], state: "minecraft:dirt"},
        {pos: [9, 0, 4], state: "minecraft:dirt"},
        {pos: [9, 0, 5], state: "minecraft:dirt"},
        {pos: [9, 0, 6], state: "minecraft:dirt"},
        {pos: [9, 0, 7], state: "minecraft:dirt"},
        {pos: [9, 0, 8], state: "minecraft:grass_block{snowy:false}"},
        {pos: [9, 0, 9], state: "minecraft:grass_block{snowy:false}"},
        {pos: [0, 1, 4], state: "minecraft:cobblestone"},
        {pos: [0, 1, 5], state: "minecraft:cobblestone"},
        {pos: [0, 1, 6], state: "minecraft:mossy_cobblestone"},
        {pos: [1, 1, 1], state: "minecraft:grass_block{snowy:false}"},
        {pos: [1, 1, 2], state: "minecraft:grass_block{snowy:false}"},
        {pos: [1, 1, 3], state: "minecraft:mossy_cobblestone"},
        {pos: [1, 1, 4], state: "minecraft:water{level:0}"},
        {pos: [1, 1, 5], state: "minecraft:water{level:0}"},
        {pos: [1, 1, 6], state: "minecraft:water{level:0}"},
        {pos: [1, 1, 7], state: "minecraft:mossy_cobblestone"},
        {pos: [1, 1, 8], state: "minecraft:grass_block{snowy:false}"},
        {pos: [2, 1, 1], state: "minecraft:grass_block{snowy:false}"},
        {pos: [2, 1, 2], state: "minecraft:sand"},
        {pos: [2, 1, 3], state: "minecraft:water{level:0}"},
        {pos: [2, 1, 4], state: "minecraft:water{level:0}"},
        {pos: [2, 1, 5], state: "minecraft:water{level:0}"},
        {pos: [2, 1, 6], state: "minecraft:water{level:0}"},
        {pos: [2, 1, 7], state: "minecraft:cobblestone"},
        {pos: [2, 1, 8], state: "minecraft:grass_block{snowy:false}"},
        {pos: [3, 1, 1], state: "minecraft:grass_block{snowy:false}"},
        {pos: [3, 1, 2], state: "minecraft:sand"},
        {pos: [3, 1, 3], state: "minecraft:water{level:0}"},
        {pos: [3, 1, 4], state: "minecraft:water{level:0}"},
        {pos: [3, 1, 5], state: "minecraft:water{level:0}"},
        {pos: [3, 1, 6], state: "minecraft:water{level:0}"},
        {pos: [3, 1, 7], state: "minecraft:cobblestone"},
        {pos: [3, 1, 8], state: "minecraft:grass_block{snowy:false}"},
        {pos: [4, 1, 1], state: "minecraft:grass_block{snowy:false}"},
        {pos: [4, 1, 2], state: "minecraft:sand"},
        {pos: [4, 1, 3], state: "minecraft:water{level:0}"},
        {pos: [4, 1, 4], state: "minecraft:water{level:0}"},
        {pos: [4, 1, 5], state: "minecraft:water{level:0}"},
        {pos: [4, 1, 6], state: "minecraft:grass_block{snowy:false}"},
        {pos: [4, 1, 7], state: "minecraft:sand"},
        {pos: [4, 1, 8], state: "minecraft:grass_block{snowy:false}"},
        {pos: [5, 1, 1], state: "minecraft:grass_block{snowy:false}"},
        {pos: [5, 1, 2], state: "minecraft:grass_block{snowy:false}"},
        {pos: [5, 1, 3], state: "minecraft:cobblestone"},
        {pos: [5, 1, 4], state: "minecraft:mossy_cobblestone"},
        {pos: [5, 1, 5], state: "minecraft:mossy_cobblestone"},
        {pos: [5, 1, 6], state: "minecraft:sand"},
        {pos: [5, 1, 7], state: "minecraft:grass_block{snowy:false}"},
        {pos: [5, 1, 8], state: "minecraft:grass_block{snowy:false}"},
        {pos: [6, 1, 1], state: "minecraft:grass_block{snowy:false}"},
        {pos: [6, 1, 2], state: "minecraft:grass_block{snowy:false}"},
        {pos: [6, 1, 3], state: "minecraft:grass_block{snowy:false}"},
        {pos: [6, 1, 4], state: "minecraft:dirt_path"},
        {pos: [6, 1, 5], state: "minecraft:dirt_path"},
        {pos: [6, 1, 6], state: "minecraft:dirt_path"},
        {pos: [6, 1, 7], state: "minecraft:grass_block{snowy:false}"},
        {pos: [6, 1, 8], state: "minecraft:grass_block{snowy:false}"},
        {pos: [7, 1, 1], state: "minecraft:grass_block{snowy:false}"},
        {pos: [7, 1, 2], state: "minecraft:grass_block{snowy:false}"},
        {pos: [7, 1, 3], state: "minecraft:dirt_path"},
        {pos: [7, 1, 4], state: "minecraft:dirt_path"},
        {pos: [7, 1, 5], state: "minecraft:dirt_path"},
        {pos: [7, 1, 6], state: "minecraft:dirt_path"},
        {pos: [7, 1, 7], state: "minecraft:grass_block{snowy:false}"},
        {pos: [7, 1, 8], state: "minecraft:grass_block{snowy:false}"},
        {pos: [8, 1, 1], state: "minecraft:grass_block{snowy:false}"},
        {pos: [8, 1, 2], state: "minecraft:dirt_path"},
        {pos: [8, 1, 3], state: "minecraft:dirt_path"},
        {pos: [8, 1, 4], state: "minecraft:dirt"},
        {pos: [8, 1, 5], state: "minecraft:dirt"},
        {pos: [8, 1, 6], state: "minecraft:dirt_path"},
        {pos: [8, 1, 7], state: "minecraft:dirt_path"},
        {pos: [9, 1, 2], state: "minecraft:dirt_path"},
        {pos: [9, 1, 3], state: "minecraft:dirt_path"},
        {pos: [9, 1, 4], state: "minecraft:jigsaw{orientation:east_up}", nbt: {components: {}, final_state: "minecraft:dirt_path", id: "minecraft:jigsaw", joint: "rollable", name: "minecraft:end_connector", placement_priority: 0, pool: "minecraft:empty", selection_priority: 0, target: "minecraft:connector"}},
        {pos: [9, 1, 5], state: "minecraft:dirt_path"},
        {pos: [9, 1, 6], state: "minecraft:dirt_path"},
        {pos: [9, 1, 7], state: "minecraft:dirt_path"},
        {pos: [1, 2, 1], state: "minecraft:tall_grass{half:lower}"},
        {pos: [1, 2, 2], state: "minecraft:firefly_bush"},
        {pos: [1, 2, 8], state: "minecraft:short_grass"},
        {pos: [2, 2, 1], state: "minecraft:short_grass"},
        {pos: [2, 2, 8], state: "minecraft:tall_grass{half:lower}"},
        {pos: [3, 2, 1], state: "minecraft:short_grass"},
        {pos: [3, 2, 8], state: "minecraft:short_grass"},
        {pos: [4, 2, 1], state: "minecraft:tall_grass{half:lower}"},
        {pos: [4, 2, 6], state: "minecraft:firefly_bush"},
        {pos: [4, 2, 8], state: "minecraft:tall_grass{half:lower}"},
        {pos: [5, 2, 1], state: "minecraft:short_grass"},
        {pos: [5, 2, 2], state: "minecraft:dandelion"},
        {pos: [5, 2, 7], state: "minecraft:short_grass"},
        {pos: [5, 2, 8], state: "minecraft:short_grass"},
        {pos: [6, 2, 1], state: "minecraft:short_grass"},
        {pos: [6, 2, 2], state: "minecraft:short_grass"},
        {pos: [6, 2, 3], state: "minecraft:short_grass"},
        {pos: [6, 2, 7], state: "minecraft:dandelion"},
        {pos: [6, 2, 8], state: "minecraft:tall_grass{half:lower}"},
        {pos: [7, 2, 1], state: "minecraft:short_grass"},
        {pos: [7, 2, 2], state: "minecraft:tall_grass{half:lower}"},
        {pos: [7, 2, 7], state: "minecraft:chest{facing:north,type:single,waterlogged:false}", nbt: {Items: [], LootTable: "minecraft:chests/abandoned_camp_common_chest", components: {}, id: "minecraft:chest"}},
        {pos: [7, 2, 8], state: "minecraft:short_grass"},
        {pos: [8, 2, 1], state: "minecraft:tall_grass{half:lower}"},
        {pos: [8, 2, 4], state: "minecraft:campfire{facing:south,lit:false,signal_fire:false,waterlogged:false}", nbt: {CookingTimes: [I; 0, 0, 0, 0], CookingTotalTimes: [I; 0, 0, 0, 0], Items: [], components: {}, id: "minecraft:campfire"}},
        {pos: [1, 3, 1], state: "minecraft:tall_grass{half:upper}"},
        {pos: [2, 3, 8], state: "minecraft:tall_grass{half:upper}"},
        {pos: [4, 3, 1], state: "minecraft:tall_grass{half:upper}"},
        {pos: [4, 3, 8], state: "minecraft:tall_grass{half:upper}"},
        {pos: [6, 3, 8], state: "minecraft:tall_grass{half:upper}"},
        {pos: [7, 3, 2], state: "minecraft:tall_grass{half:upper}"},
        {pos: [8, 3, 1], state: "minecraft:tall_grass{half:upper}"}
    ],
    entities: [
        {blockPos: [7, 1, 3], pos: [7.5d, 1.9375d, 3.5d], nbt: {Air: 300s, Fire: 0s, Invulnerable: 0b, Motion: [0.0d, 0.0d, 0.0d], OnGround: 0b, PortalCooldown: 0, Pos: [-86.5d, -60.0625d, 435.5d], Rotation: [90.0f, 0.0f], UUID: [I; -1712488859, 1380732627, -1085873756, 636090340], block_pos: [I; -87, -61, 435], color: "yellow", fall_distance: 0.0d, id: "minecraft:cushion"}},
        {blockPos: [8, 2, 5], pos: [8.5d, 2.0d, 5.5d], nbt: {Air: 300s, Fire: 0s, Invulnerable: 0b, Motion: [0.0d, 0.0d, 0.0d], OnGround: 0b, PortalCooldown: 0, Pos: [-85.5d, -60.0d, 437.5d], Rotation: [90.0f, 0.0f], UUID: [I; -1019721426, -675790397, -2099720551, -1881715076], block_pos: [I; -86, -60, 437], color: "lime", fall_distance: 0.0d, id: "minecraft:cushion"}}
    ],
    palette: [
        "minecraft:grass_block{snowy:false}",
        "minecraft:dirt",
        "minecraft:cobblestone",
        "minecraft:sand",
        "minecraft:mossy_cobblestone",
        "minecraft:water{level:0}",
        "minecraft:dirt_path",
        "minecraft:tall_grass{half:lower}",
        "minecraft:firefly_bush",
        "minecraft:short_grass",
        "minecraft:dandelion",
        "minecraft:tall_grass{half:upper}",
        "minecraft:jigsaw{orientation:east_up}",
        "minecraft:chest{facing:north,type:single,waterlogged:false}",
        "minecraft:campfire{facing:south,lit:false,signal_fire:false,waterlogged:false}"
    ]
}
