{
    size: [11, 10, 11],
    data: [
        {pos: [1, 0, 3], state: "minecraft:dirt"},
        {pos: [1, 0, 4], state: "minecraft:dirt"},
        {pos: [1, 0, 5], state: "minecraft:dirt"},
        {pos: [2, 0, 1], state: "minecraft:grass_block{snowy:false}"},
        {pos: [2, 0, 2], state: "minecraft:grass_block{snowy:false}"},
        {pos: [2, 0, 3], state: "minecraft:dirt"},
        {pos: [2, 0, 4], state: "minecraft:dirt"},
        {pos: [2, 0, 5], state: "minecraft:dirt"},
        {pos: [2, 0, 6], state: "minecraft:grass_block{snowy:false}"},
        {pos: [2, 0, 7], state: "minecraft:grass_block{snowy:false}"},
        {pos: [2, 0, 8], state: "minecraft:grass_block{snowy:false}"},
        {pos: [3, 0, 1], state: "minecraft:grass_block{snowy:false}"},
        {pos: [3, 0, 2], state: "minecraft:dirt"},
        {pos: [3, 0, 3], state: "minecraft:dirt"},
        {pos: [3, 0, 4], state: "minecraft:dirt"},
        {pos: [3, 0, 5], state: "minecraft:dirt"},
        {pos: [3, 0, 6], state: "minecraft:dirt"},
        {pos: [3, 0, 7], state: "minecraft:grass_block{snowy:false}"},
        {pos: [3, 0, 8], state: "minecraft:grass_block{snowy:false}"},
        {pos: [4, 0, 1], state: "minecraft:dirt"},
        {pos: [4, 0, 2], state: "minecraft:dirt"},
        {pos: [4, 0, 3], state: "minecraft:dirt"},
        {pos: [4, 0, 4], state: "minecraft:dirt_path"},
        {pos: [4, 0, 5], state: "minecraft:dirt_path"},
        {pos: [4, 0, 6], state: "minecraft:dirt"},
        {pos: [4, 0, 7], state: "minecraft:dirt"},
        {pos: [4, 0, 8], state: "minecraft:grass_block{snowy:false}"},
        {pos: [5, 0, 1], state: "minecraft:dirt"},
        {pos: [5, 0, 2], state: "minecraft:dirt"},
        {pos: [5, 0, 3], state: "minecraft:grass_block{snowy:false}"},
        {pos: [5, 0, 4], state: "minecraft:dirt"},
        {pos: [5, 0, 5], state: "minecraft:dirt_path"},
        {pos: [5, 0, 6], state: "minecraft:dirt_path"},
        {pos: [5, 0, 7], state: "minecraft:oxidized_copper_chest{facing:north,type:single,waterlogged:false}", nbt: {LootTable: "minecraft:chests/abandoned_camp_secret_chest", components: {}, id: "minecraft:chest"}},
        {pos: [5, 0, 8], state: "minecraft:dirt"},
        {pos: [6, 0, 2], state: "minecraft:dirt"},
        {pos: [6, 0, 3], state: "minecraft:dirt_path"},
        {pos: [6, 0, 4], state: "minecraft:dirt_path"},
        {pos: [6, 0, 5], state: "minecraft:barrel{facing:up,open:false}", nbt: {LootTable: "minecraft:barrels/abandoned_camp_barrel", components: {}, id: "minecraft:barrel"}},
        {pos: [6, 0, 6], state: "minecraft:dirt_path"},
        {pos: [6, 0, 7], state: "minecraft:dirt"},
        {pos: [6, 0, 8], state: "minecraft:dirt"},
        {pos: [6, 0, 9], state: "minecraft:dirt"},
        {pos: [7, 0, 2], state: "minecraft:dirt"},
        {pos: [7, 0, 3], state: "minecraft:dirt_path"},
        {pos: [7, 0, 4], state: "minecraft:dirt_path"},
        {pos: [7, 0, 5], state: "minecraft:grass_block{snowy:false}"},
        {pos: [7, 0, 6], state: "minecraft:dirt_path"},
        {pos: [7, 0, 7], state: "minecraft:dirt"},
        {pos: [7, 0, 8], state: "minecraft:dirt"},
        {pos: [7, 0, 9], state: "minecraft:dirt"},
        {pos: [7, 0, 10], state: "minecraft:grass_block{snowy:false}"},
        {pos: [8, 0, 1], state: "minecraft:grass_block{snowy:false}"},
        {pos: [8, 0, 2], state: "minecraft:grass_block{snowy:false}"},
        {pos: [8, 0, 3], state: "minecraft:dirt"},
        {pos: [8, 0, 4], state: "minecraft:dirt_path"},
        {pos: [8, 0, 5], state: "minecraft:dirt_path"},
        {pos: [8, 0, 6], state: "minecraft:dirt_path"},
        {pos: [8, 0, 8], state: "minecraft:dirt"},
        {pos: [8, 0, 9], state: "minecraft:dirt"},
        {pos: [8, 0, 10], state: "minecraft:grass_block{snowy:false}"},
        {pos: [9, 0, 1], state: "minecraft:grass_block{snowy:false}"},
        {pos: [9, 0, 2], state: "minecraft:grass_block{snowy:false}"},
        {pos: [9, 0, 4], state: "minecraft:dirt_path"},
        {pos: [9, 0, 5], state: "minecraft:dirt_path"},
        {pos: [9, 0, 6], state: "minecraft:dirt_path"},
        {pos: [9, 0, 8], state: "minecraft:grass_block{snowy:false}"},
        {pos: [9, 0, 10], state: "minecraft:grass_block{snowy:false}"},
        {pos: [10, 0, 4], state: "minecraft:jigsaw{orientation:east_up}", nbt: {components: {}, final_state: "minecraft:dirt_path", id: "minecraft:jigsaw", joint: "rollable", name: "minecraft:end_connector", placement_priority: 0, pool: "minecraft:empty", selection_priority: 0, target: "minecraft:connector"}},
        {pos: [10, 0, 5], state: "minecraft:dirt_path"},
        {pos: [10, 0, 6], state: "minecraft:dirt_path"},
        {pos: [1, 1, 3], state: "minecraft:grass_block{snowy:false}"},
        {pos: [1, 1, 4], state: "minecraft:grass_block{snowy:false}"},
        {pos: [1, 1, 5], state: "minecraft:grass_block{snowy:false}"},
        {pos: [2, 1, 1], state: "minecraft:short_grass"},
        {pos: [2, 1, 2], state: "minecraft:tall_grass{half:lower}"},
        {pos: [2, 1, 3], state: "minecraft:grass_block{snowy:false}"},
        {pos: [2, 1, 4], state: "minecraft:jigsaw{orientation:up_north}", nbt: {components: {}, final_state: "minecraft:dirt", id: "minecraft:jigsaw", joint: "rollable", name: "minecraft:down", placement_priority: 0, pool: "minecraft:abandoned_camp/trees/super_birch_bees", selection_priority: 0, target: "minecraft:down"}},
        {pos: [2, 1, 5], state: "minecraft:grass_block{snowy:false}"},
        {pos: [2, 1, 6], state: "minecraft:short_grass"},
        {pos: [2, 1, 7], state: "minecraft:bush"},
        {pos: [2, 1, 8], state: "minecraft:bush"},
        {pos: [3, 1, 1], state: "minecraft:short_grass"},
        {pos: [3, 1, 2], state: "minecraft:grass_block{snowy:false}"},
        {pos: [3, 1, 3], state: "minecraft:grass_block{snowy:false}"},
        {pos: [3, 1, 4], state: "minecraft:grass_block{snowy:false}"},
        {pos: [3, 1, 5], state: "minecraft:grass_block{snowy:false}"},
        {pos: [3, 1, 6], state: "minecraft:grass_block{snowy:false}"},
        {pos: [3, 1, 7], state: "minecraft:short_grass"},
        {pos: [3, 1, 8], state: "minecraft:short_grass"},
        {pos: [4, 1, 1], state: "minecraft:grass_block{snowy:false}"},
        {pos: [4, 1, 2], state: "minecraft:grass_block{snowy:false}"},
        {pos: [4, 1, 3], state: "minecraft:grass_block{snowy:false}"},
        {pos: [4, 1, 6], state: "minecraft:grass_block{snowy:false}"},
        {pos: [4, 1, 7], state: "minecraft:grass_block{snowy:false}"},
        {pos: [4, 1, 8], state: "minecraft:tall_grass{half:lower}"},
        {pos: [5, 1, 1], state: "minecraft:grass_block{snowy:false}"},
        {pos: [5, 1, 2], state: "minecraft:grass_block{snowy:false}"},
        {pos: [5, 1, 3], state: "minecraft:cobweb"},
        {pos: [5, 1, 4], state: "minecraft:barrel{facing:up,open:false}", nbt: {LootTable: "minecraft:barrels/abandoned_camp_barrel", components: {}, id: "minecraft:barrel"}},
        {pos: [5, 1, 7], state: "minecraft:gravel"},
        {pos: [5, 1, 8], state: "minecraft:grass_block{snowy:false}"},
        {pos: [6, 1, 1], state: "minecraft:cobweb"},
        {pos: [6, 1, 2], state: "minecraft:grass_block{snowy:false}"},
        {pos: [6, 1, 5], state: "minecraft:campfire{facing:west,lit:false,signal_fire:false,waterlogged:false}", nbt: {CookingTimes: [I; 0, 0, 0, 0], CookingTotalTimes: [I; 0, 0, 0, 0], Items: [], components: {}, id: "minecraft:campfire"}},
        {pos: [6, 1, 7], state: "minecraft:grass_block{snowy:false}"},
        {pos: [6, 1, 8], state: "minecraft:grass_block{snowy:false}"},
        {pos: [6, 1, 9], state: "minecraft:grass_block{snowy:false}"},
        {pos: [7, 1, 1], state: "minecraft:cobweb"},
        {pos: [7, 1, 2], state: "minecraft:grass_block{snowy:false}"},
        {pos: [7, 1, 5], state: "minecraft:short_grass"},
        {pos: [7, 1, 7], state: "minecraft:grass_block{snowy:false}"},
        {pos: [7, 1, 8], state: "minecraft:jigsaw{orientation:up_south}", nbt: {components: {}, final_state: "minecraft:dirt", id: "minecraft:jigsaw", joint: "rollable", name: "minecraft:down", placement_priority: 0, pool: "minecraft:abandoned_camp/trees/super_birch_bees", selection_priority: 0, target: "minecraft:down"}},
        {pos: [7, 1, 9], state: "minecraft:grass_block{snowy:false}"},
        {pos: [7, 1, 10], state: "minecraft:short_grass"},
        {pos: [8, 1, 1], state: "minecraft:short_grass"},
        {pos: [8, 1, 2], state: "minecraft:tall_grass{half:lower}"},
        {pos: [8, 1, 3], state: "minecraft:grass_block{snowy:false}"},
        {pos: [8, 1, 7], state: "minecraft:cobweb"},
        {pos: [8, 1, 8], state: "minecraft:grass_block{snowy:false}"},
        {pos: [8, 1, 9], state: "minecraft:grass_block{snowy:false}"},
        {pos: [8, 1, 10], state: "minecraft:short_grass"},
        {pos: [9, 1, 1], state: "minecraft:dandelion"},
        {pos: [9, 1, 2], state: "minecraft:tall_grass{half:lower}"},
        {pos: [9, 1, 7], state: "minecraft:cobweb"},
        {pos: [9, 1, 8], state: "minecraft:bush"},
        {pos: [9, 1, 9], state: "minecraft:cobweb"},
        {pos: [9, 1, 10], state: "minecraft:short_grass"},
        {pos: [2, 2, 2], state: "minecraft:tall_grass{half:upper}"},
        {pos: [2, 2, 5], state: "minecraft:tall_grass{half:lower}"},
        {pos: [3, 2, 2], state: "minecraft:dandelion"},
        {pos: [3, 2, 3], state: "minecraft:short_grass"},
        {pos: [3, 2, 4], state: "minecraft:short_grass"},
        {pos: [3, 2, 5], state: "minecraft:short_grass"},
        {pos: [3, 2, 6], state: "minecraft:tall_grass{half:lower}"},
        {pos: [4, 2, 2], state: "minecraft:cobweb"},
        {pos: [4, 2, 3], state: "minecraft:short_grass"},
        {pos: [4, 2, 6], state: "minecraft:short_grass"},
        {pos: [4, 2, 7], state: "minecraft:cobweb"},
        {pos: [4, 2, 8], state: "minecraft:tall_grass{half:upper}"},
        {pos: [5, 2, 1], state: "minecraft:short_grass"},
        {pos: [5, 2, 2], state: "minecraft:short_grass"},
        {pos: [5, 2, 8], state: "minecraft:bush"},
        {pos: [6, 2, 2], state: "minecraft:short_grass"},
        {pos: [6, 2, 9], state: "minecraft:short_grass"},
        {pos: [7, 2, 2], state: "minecraft:cobweb"},
        {pos: [7, 2, 9], state: "minecraft:short_grass"},
        {pos: [8, 2, 2], state: "minecraft:tall_grass{half:upper}"},
        {pos: [8, 2, 3], state: "minecraft:short_grass"},
        {pos: [8, 2, 8], state: "minecraft:cobweb"},
        {pos: [8, 2, 9], state: "minecraft:bush"},
        {pos: [9, 2, 2], state: "minecraft:tall_grass{half:upper}"},
        {pos: [2, 3, 5], state: "minecraft:tall_grass{half:upper}"},
        {pos: [3, 3, 6], state: "minecraft:tall_grass{half:upper}"}
    ],
    entities: [
        {blockPos: [6, 0, 4], pos: [6.5d, 0.9375d, 4.5d], nbt: {Air: 300s, Fire: 0s, Invulnerable: 0b, Motion: [0.0d, 0.0d, 0.0d], OnGround: 0b, PortalCooldown: 0, Pos: [-88.5d, -60.0625d, 421.5d], Rotation: [90.0f, 0.0f], UUID: [I; -252785038, -756071455, -1138101800, 1523051467], block_pos: [I; -89, -61, 421], color: "yellow", fall_distance: 0.0d, id: "minecraft:cushion"}},
        {blockPos: [6, 0, 6], pos: [6.5d, 0.9375d, 6.5d], nbt: {Air: 300s, Fire: 0s, Invulnerable: 0b, Motion: [0.0d, 0.0d, 0.0d], OnGround: 0b, PortalCooldown: 0, Pos: [-88.5d, -60.0625d, 423.5d], Rotation: [0.0f, 0.0f], UUID: [I; 1146233982, 1100628816, -2103194428, 376659841], block_pos: [I; -89, -61, 423], color: "yellow", fall_distance: 0.0d, id: "minecraft:cushion"}}
    ],
    palette: [
        "minecraft:dirt",
        "minecraft:grass_block{snowy:false}",
        "minecraft:gravel",
        "minecraft:dirt_path",
        "minecraft:short_grass",
        "minecraft:tall_grass{half:lower}",
        "minecraft:bush",
        "minecraft:cobweb",
        "minecraft:dandelion",
        "minecraft:tall_grass{half:upper}",
        "minecraft:oxidized_copper_chest{facing:north,type:single,waterlogged:false}",
        "minecraft:barrel{facing:up,open:false}",
        "minecraft:jigsaw{orientation:east_up}",
        "minecraft:jigsaw{orientation:up_north}",
        "minecraft:campfire{facing:west,lit:false,signal_fire:false,waterlogged:false}",
        "minecraft:jigsaw{orientation:up_south}"
    ]
}
