{
    size: [5, 7, 5],
    data: [
        {pos: [0, 0, 0], state: "minecraft:sandstone"},
        {pos: [0, 0, 1], state: "minecraft:sandstone"},
        {pos: [0, 0, 2], state: "minecraft:sandstone"},
        {pos: [0, 0, 3], state: "minecraft:sandstone"},
        {pos: [0, 0, 4], state: "minecraft:sandstone"},
        {pos: [1, 0, 0], state: "minecraft:sandstone"},
        {pos: [1, 0, 1], state: "minecraft:sandstone"},
        {pos: [1, 0, 2], state: "minecraft:sandstone"},
        {pos: [1, 0, 3], state: "minecraft:sandstone"},
        {pos: [1, 0, 4], state: "minecraft:sandstone"},
        {pos: [2, 0, 0], state: "minecraft:sandstone"},
        {pos: [2, 0, 1], state: "minecraft:sandstone"},
        {pos: [2, 0, 2], state: "minecraft:sandstone"},
        {pos: [2, 0, 3], state: "minecraft:sandstone"},
        {pos: [2, 0, 4], state: "minecraft:sandstone"},
        {pos: [3, 0, 0], state: "minecraft:sandstone"},
        {pos: [3, 0, 1], state: "minecraft:sandstone"},
        {pos: [3, 0, 2], state: "minecraft:sandstone"},
        {pos: [3, 0, 3], state: "minecraft:sandstone"},
        {pos: [3, 0, 4], state: "minecraft:sandstone"},
        {pos: [4, 0, 0], state: "minecraft:sandstone"},
        {pos: [4, 0, 1], state: "minecraft:sandstone"},
        {pos: [4, 0, 2], state: "minecraft:sandstone"},
        {pos: [4, 0, 3], state: "minecraft:sandstone"},
        {pos: [4, 0, 4], state: "minecraft:sandstone"},
        {pos: [0, 1, 0], state: "minecraft:sandstone"},
        {pos: [0, 1, 1], state: "minecraft:sandstone"},
        {pos: [0, 1, 2], state: "minecraft:sandstone"},
        {pos: [0, 1, 3], state: "minecraft:sandstone"},
        {pos: [0, 1, 4], state: "minecraft:sandstone"},
        {pos: [1, 1, 0], state: "minecraft:sandstone"},
        {pos: [1, 1, 1], state: "minecraft:sandstone"},
        {pos: [1, 1, 2], state: "minecraft:sand"},
        {pos: [1, 1, 3], state: "minecraft:sandstone"},
        {pos: [1, 1, 4], state: "minecraft:sandstone"},
        {pos: [2, 1, 0], state: "minecraft:sandstone"},
        {pos: [2, 1, 1], state: "minecraft:sand"},
        {pos: [2, 1, 2], state: "minecraft:sand"},
        {pos: [2, 1, 3], state: "minecraft:sand"},
        {pos: [2, 1, 4], state: "minecraft:sandstone"},
        {pos: [3, 1, 0], state: "minecraft:sandstone"},
        {pos: [3, 1, 1], state: "minecraft:sandstone"},
        {pos: [3, 1, 2], state: "minecraft:sand"},
        {pos: [3, 1, 3], state: "minecraft:sandstone"},
        {pos: [3, 1, 4], state: "minecraft:sandstone"},
        {pos: [4, 1, 0], state: "minecraft:sandstone"},
        {pos: [4, 1, 1], state: "minecraft:sandstone"},
        {pos: [4, 1, 2], state: "minecraft:sandstone"},
        {pos: [4, 1, 3], state: "minecraft:sandstone"},
        {pos: [4, 1, 4], state: "minecraft:sandstone"},
        {pos: [0, 2, 0], state: "minecraft:sandstone"},
        {pos: [0, 2, 1], state: "minecraft:sandstone"},
        {pos: [0, 2, 2], state: "minecraft:sandstone"},
        {pos: [0, 2, 3], state: "minecraft:sandstone"},
        {pos: [0, 2, 4], state: "minecraft:sandstone"},
        {pos: [1, 2, 0], state: "minecraft:sandstone"},
        {pos: [1, 2, 1], state: "minecraft:sandstone"},
        {pos: [1, 2, 2], state: "minecraft:water{level:0}"},
        {pos: [1, 2, 3], state: "minecraft:sandstone"},
        {pos: [1, 2, 4], state: "minecraft:sandstone"},
        {pos: [2, 2, 0], state: "minecraft:sandstone"},
        {pos: [2, 2, 1], state: "minecraft:water{level:0}"},
        {pos: [2, 2, 2], state: "minecraft:water{level:0}"},
        {pos: [2, 2, 3], state: "minecraft:water{level:0}"},
        {pos: [2, 2, 4], state: "minecraft:sandstone"},
        {pos: [3, 2, 0], state: "minecraft:sandstone"},
        {pos: [3, 2, 1], state: "minecraft:sandstone"},
        {pos: [3, 2, 2], state: "minecraft:water{level:0}"},
        {pos: [3, 2, 3], state: "minecraft:sandstone"},
        {pos: [3, 2, 4], state: "minecraft:sandstone"},
        {pos: [4, 2, 0], state: "minecraft:sandstone"},
        {pos: [4, 2, 1], state: "minecraft:sandstone"},
        {pos: [4, 2, 2], state: "minecraft:sandstone"},
        {pos: [4, 2, 3], state: "minecraft:sandstone"},
        {pos: [4, 2, 4], state: "minecraft:sandstone"},
        {pos: [0, 3, 0], state: "minecraft:sandstone"},
        {pos: [0, 3, 1], state: "minecraft:sandstone"},
        {pos: [0, 3, 2], state: "minecraft:sandstone_slab{type:bottom,waterlogged:false}"},
        {pos: [0, 3, 3], state: "minecraft:sandstone"},
        {pos: [0, 3, 4], state: "minecraft:sandstone"},
        {pos: [1, 3, 0], state: "minecraft:sandstone"},
        {pos: [1, 3, 1], state: "minecraft:sandstone"},
        {pos: [1, 3, 2], state: "minecraft:air"},
        {pos: [1, 3, 3], state: "minecraft:sandstone"},
        {pos: [1, 3, 4], state: "minecraft:sandstone"},
        {pos: [2, 3, 0], state: "minecraft:sandstone_slab{type:bottom,waterlogged:false}"},
        {pos: [2, 3, 1], state: "minecraft:air"},
        {pos: [2, 3, 2], state: "minecraft:air"},
        {pos: [2, 3, 3], state: "minecraft:air"},
        {pos: [2, 3, 4], state: "minecraft:sandstone_slab{type:bottom,waterlogged:false}"},
        {pos: [3, 3, 0], state: "minecraft:sandstone"},
        {pos: [3, 3, 1], state: "minecraft:sandstone"},
        {pos: [3, 3, 2], state: "minecraft:air"},
        {pos: [3, 3, 3], state: "minecraft:sandstone"},
        {pos: [3, 3, 4], state: "minecraft:sandstone"},
        {pos: [4, 3, 0], state: "minecraft:sandstone"},
        {pos: [4, 3, 1], state: "minecraft:sandstone"},
        {pos: [4, 3, 2], state: "minecraft:sandstone_slab{type:bottom,waterlogged:false}"},
        {pos: [4, 3, 3], state: "minecraft:sandstone"},
        {pos: [4, 3, 4], state: "minecraft:sandstone"},
        {pos: [1, 4, 1], state: "minecraft:sandstone"},
        {pos: [1, 4, 2], state: "minecraft:air"},
        {pos: [1, 4, 3], state: "minecraft:sandstone"},
        {pos: [2, 4, 1], state: "minecraft:air"},
        {pos: [2, 4, 2], state: "minecraft:air"},
        {pos: [2, 4, 3], state: "minecraft:air"},
        {pos: [3, 4, 1], state: "minecraft:sandstone"},
        {pos: [3, 4, 2], state: "minecraft:air"},
        {pos: [3, 4, 3], state: "minecraft:sandstone"},
        {pos: [1, 5, 1], state: "minecraft:sandstone"},
        {pos: [1, 5, 2], state: "minecraft:air"},
        {pos: [1, 5, 3], state: "minecraft:sandstone"},
        {pos: [2, 5, 1], state: "minecraft:air"},
        {pos: [2, 5, 2], state: "minecraft:air"},
        {pos: [2, 5, 3], state: "minecraft:air"},
        {pos: [3, 5, 1], state: "minecraft:sandstone"},
        {pos: [3, 5, 2], state: "minecraft:air"},
        {pos: [3, 5, 3], state: "minecraft:sandstone"},
        {pos: [1, 6, 1], state: "minecraft:sandstone_slab{type:bottom,waterlogged:false}"},
        {pos: [1, 6, 2], state: "minecraft:sandstone_slab{type:bottom,waterlogged:false}"},
        {pos: [1, 6, 3], state: "minecraft:sandstone_slab{type:bottom,waterlogged:false}"},
        {pos: [2, 6, 1], state: "minecraft:sandstone_slab{type:bottom,waterlogged:false}"},
        {pos: [2, 6, 2], state: "minecraft:sandstone"},
        {pos: [2, 6, 3], state: "minecraft:sandstone_slab{type:bottom,waterlogged:false}"},
        {pos: [3, 6, 1], state: "minecraft:sandstone_slab{type:bottom,waterlogged:false}"},
        {pos: [3, 6, 2], state: "minecraft:sandstone_slab{type:bottom,waterlogged:false}"},
        {pos: [3, 6, 3], state: "minecraft:sandstone_slab{type:bottom,waterlogged:false}"}
    ],
    entities: [],
    palette: [
        "minecraft:sandstone",
        "minecraft:sand",
        "minecraft:water{level:0}",
        "minecraft:sandstone_slab{type:bottom,waterlogged:false}",
        "minecraft:air"
    ]
}
