{
    size: [4, 4, 4],
    data: [
        {pos: [1, 0, 0], state: "minecraft:cobblestone"},
        {pos: [1, 0, 1], state: "minecraft:cobblestone"},
        {pos: [1, 0, 2], state: "minecraft:cobblestone"},
        {pos: [2, 0, 0], state: "minecraft:cobblestone"},
        {pos: [2, 0, 1], state: "minecraft:cobblestone"},
        {pos: [2, 0, 2], state: "minecraft:cobblestone"},
        {pos: [3, 0, 0], state: "minecraft:air"},
        {pos: [3, 0, 1], state: "minecraft:cobblestone"},
        {pos: [3, 0, 2], state: "minecraft:cobblestone"},
        {pos: [1, 1, 0], state: "minecraft:dark_oak_planks"},
        {pos: [1, 1, 1], state: "minecraft:dark_oak_planks"},
        {pos: [1, 1, 2], state: "minecraft:dark_oak_planks"},
        {pos: [2, 1, 0], state: "minecraft:dark_oak_planks"},
        {pos: [2, 1, 1], state: "minecraft:dark_oak_planks"},
        {pos: [2, 1, 2], state: "minecraft:dark_oak_planks"},
        {pos: [3, 1, 0], state: "minecraft:dark_oak_stairs{facing:south,half:bottom,shape:straight,waterlogged:false}"},
        {pos: [3, 1, 1], state: "minecraft:dark_oak_planks"},
        {pos: [3, 1, 2], state: "minecraft:dark_oak_planks"},
        {pos: [0, 2, 0], state: "minecraft:dark_oak_stairs{facing:east,half:top,shape:straight,waterlogged:false}"},
        {pos: [0, 2, 1], state: "minecraft:dark_oak_stairs{facing:east,half:top,shape:straight,waterlogged:false}"},
        {pos: [0, 2, 2], state: "minecraft:dark_oak_stairs{facing:east,half:top,shape:straight,waterlogged:false}"},
        {pos: [0, 2, 3], state: "minecraft:dark_oak_stairs{facing:north,half:top,shape:outer_right,waterlogged:false}"},
        {pos: [1, 2, 0], state: "minecraft:dark_oak_planks"},
        {pos: [1, 2, 1], state: "minecraft:dark_oak_planks"},
        {pos: [1, 2, 2], state: "minecraft:dark_oak_planks"},
        {pos: [1, 2, 3], state: "minecraft:dark_oak_stairs{facing:north,half:top,shape:straight,waterlogged:false}"},
        {pos: [2, 2, 0], state: "minecraft:dark_oak_stairs{facing:west,half:bottom,shape:straight,waterlogged:false}"},
        {pos: [2, 2, 1], state: "minecraft:dark_oak_stairs{facing:south,half:bottom,shape:inner_right,waterlogged:false}"},
        {pos: [2, 2, 2], state: "minecraft:dark_oak_planks"},
        {pos: [2, 2, 3], state: "minecraft:dark_oak_stairs{facing:north,half:top,shape:straight,waterlogged:false}"},
        {pos: [3, 2, 0], state: "minecraft:air"},
        {pos: [3, 2, 1], state: "minecraft:dark_oak_stairs{facing:south,half:bottom,shape:straight,waterlogged:false}"},
        {pos: [3, 2, 2], state: "minecraft:dark_oak_planks"},
        {pos: [3, 2, 3], state: "minecraft:dark_oak_stairs{facing:north,half:top,shape:straight,waterlogged:false}"},
        {pos: [0, 3, 0], state: "minecraft:dark_oak_planks"},
        {pos: [0, 3, 1], state: "minecraft:dark_oak_planks"},
        {pos: [0, 3, 2], state: "minecraft:dark_oak_planks"},
        {pos: [0, 3, 3], state: "minecraft:dark_oak_planks"},
        {pos: [1, 3, 0], state: "minecraft:dark_oak_stairs{facing:west,half:bottom,shape:straight,waterlogged:false}"},
        {pos: [1, 3, 1], state: "minecraft:dark_oak_stairs{facing:west,half:bottom,shape:straight,waterlogged:false}"},
        {pos: [1, 3, 2], state: "minecraft:dark_oak_stairs{facing:south,half:bottom,shape:inner_right,waterlogged:false}"},
        {pos: [1, 3, 3], state: "minecraft:dark_oak_planks"},
        {pos: [2, 3, 0], state: "minecraft:air"},
        {pos: [2, 3, 1], state: "minecraft:air"},
        {pos: [2, 3, 2], state: "minecraft:dark_oak_stairs{facing:south,half:bottom,shape:straight,waterlogged:false}"},
        {pos: [2, 3, 3], state: "minecraft:dark_oak_planks"},
        {pos: [3, 3, 0], state: "minecraft:air"},
        {pos: [3, 3, 1], state: "minecraft:air"},
        {pos: [3, 3, 2], state: "minecraft:dark_oak_stairs{facing:south,half:bottom,shape:straight,waterlogged:false}"},
        {pos: [3, 3, 3], state: "minecraft:dark_oak_planks"}
    ],
    entities: [],
    palette: [
        "minecraft:cobblestone",
        "minecraft:dark_oak_planks",
        "minecraft:air",
        "minecraft:dark_oak_stairs{facing:south,half:bottom,shape:straight,waterlogged:false}",
        "minecraft:dark_oak_stairs{facing:east,half:top,shape:straight,waterlogged:false}",
        "minecraft:dark_oak_stairs{facing:north,half:top,shape:outer_right,waterlogged:false}",
        "minecraft:dark_oak_stairs{facing:north,half:top,shape:straight,waterlogged:false}",
        "minecraft:dark_oak_stairs{facing:west,half:bottom,shape:straight,waterlogged:false}",
        "minecraft:dark_oak_stairs{facing:south,half:bottom,shape:inner_right,waterlogged:false}"
    ]
}
