{
    size: [4, 4, 8],
    data: [
        {pos: [0, 0, 0], state: "minecraft:air"},
        {pos: [0, 0, 1], state: "minecraft:air"},
        {pos: [0, 0, 2], state: "minecraft:air"},
        {pos: [0, 0, 3], state: "minecraft:air"},
        {pos: [0, 0, 4], state: "minecraft:air"},
        {pos: [0, 0, 5], state: "minecraft:air"},
        {pos: [0, 0, 6], state: "minecraft:air"},
        {pos: [1, 0, 0], state: "minecraft:cobblestone"},
        {pos: [1, 0, 1], state: "minecraft:cobblestone"},
        {pos: [1, 0, 2], state: "minecraft:cobblestone"},
        {pos: [1, 0, 3], state: "minecraft:cobblestone"},
        {pos: [1, 0, 4], state: "minecraft:cobblestone"},
        {pos: [1, 0, 5], state: "minecraft:cobblestone"},
        {pos: [1, 0, 6], state: "minecraft:cobblestone"},
        {pos: [1, 0, 7], state: "minecraft:cobblestone"},
        {pos: [2, 0, 0], state: "minecraft:cobblestone"},
        {pos: [2, 0, 1], state: "minecraft:cobblestone"},
        {pos: [2, 0, 2], state: "minecraft:cobblestone"},
        {pos: [2, 0, 3], state: "minecraft:cobblestone"},
        {pos: [2, 0, 4], state: "minecraft:cobblestone"},
        {pos: [2, 0, 5], state: "minecraft:cobblestone"},
        {pos: [2, 0, 6], state: "minecraft:cobblestone"},
        {pos: [2, 0, 7], state: "minecraft:cobblestone"},
        {pos: [3, 0, 0], state: "minecraft:air"},
        {pos: [3, 0, 1], state: "minecraft:air"},
        {pos: [3, 0, 2], state: "minecraft:air"},
        {pos: [3, 0, 3], state: "minecraft:air"},
        {pos: [3, 0, 4], state: "minecraft:air"},
        {pos: [3, 0, 5], state: "minecraft:air"},
        {pos: [3, 0, 6], state: "minecraft:air"},
        {pos: [3, 0, 7], state: "minecraft:air"},
        {pos: [0, 1, 0], state: "minecraft:air"},
        {pos: [0, 1, 1], state: "minecraft:air"},
        {pos: [0, 1, 2], state: "minecraft:air"},
        {pos: [0, 1, 3], state: "minecraft:air"},
        {pos: [0, 1, 4], state: "minecraft:air"},
        {pos: [0, 1, 5], state: "minecraft:air"},
        {pos: [0, 1, 6], state: "minecraft:air"},
        {pos: [1, 1, 0], state: "minecraft:dark_oak_planks"},
        {pos: [1, 1, 1], state: "minecraft:dark_oak_planks"},
        {pos: [1, 1, 2], state: "minecraft:dark_oak_planks"},
        {pos: [1, 1, 3], state: "minecraft:dark_oak_planks"},
        {pos: [1, 1, 4], state: "minecraft:dark_oak_planks"},
        {pos: [1, 1, 5], state: "minecraft:dark_oak_planks"},
        {pos: [1, 1, 6], state: "minecraft:dark_oak_planks"},
        {pos: [1, 1, 7], state: "minecraft:dark_oak_planks"},
        {pos: [2, 1, 0], state: "minecraft:dark_oak_planks"},
        {pos: [2, 1, 1], state: "minecraft:dark_oak_planks"},
        {pos: [2, 1, 2], state: "minecraft:dark_oak_planks"},
        {pos: [2, 1, 3], state: "minecraft:dark_oak_planks"},
        {pos: [2, 1, 4], state: "minecraft:dark_oak_planks"},
        {pos: [2, 1, 5], state: "minecraft:dark_oak_planks"},
        {pos: [2, 1, 6], state: "minecraft:dark_oak_planks"},
        {pos: [2, 1, 7], state: "minecraft:dark_oak_planks"},
        {pos: [3, 1, 0], state: "minecraft:dark_oak_stairs{facing:west,half:bottom,shape:straight,waterlogged:false}"},
        {pos: [3, 1, 1], state: "minecraft:dark_oak_stairs{facing:west,half:bottom,shape:straight,waterlogged:false}"},
        {pos: [3, 1, 2], state: "minecraft:dark_oak_stairs{facing:west,half:bottom,shape:straight,waterlogged:false}"},
        {pos: [3, 1, 3], state: "minecraft:dark_oak_stairs{facing:west,half:bottom,shape:straight,waterlogged:false}"},
        {pos: [3, 1, 4], state: "minecraft:dark_oak_stairs{facing:west,half:bottom,shape:straight,waterlogged:false}"},
        {pos: [3, 1, 5], state: "minecraft:dark_oak_stairs{facing:west,half:bottom,shape:straight,waterlogged:false}"},
        {pos: [3, 1, 6], state: "minecraft:dark_oak_stairs{facing:west,half:bottom,shape:straight,waterlogged:false}"},
        {pos: [3, 1, 7], state: "minecraft:dark_oak_stairs{facing:west,half:bottom,shape:straight,waterlogged:false}"},
        {pos: [0, 2, 0], state: "minecraft:dark_oak_stairs{facing:east,half:top,shape:straight,waterlogged:false}"},
        {pos: [0, 2, 1], state: "minecraft:dark_oak_stairs{facing:east,half:top,shape:straight,waterlogged:false}"},
        {pos: [0, 2, 2], state: "minecraft:dark_oak_stairs{facing:east,half:top,shape:straight,waterlogged:false}"},
        {pos: [0, 2, 3], state: "minecraft:dark_oak_stairs{facing:east,half:top,shape:straight,waterlogged:false}"},
        {pos: [0, 2, 4], state: "minecraft:dark_oak_stairs{facing:east,half:top,shape:straight,waterlogged:false}"},
        {pos: [0, 2, 5], state: "minecraft:dark_oak_stairs{facing:east,half:top,shape:straight,waterlogged:false}"},
        {pos: [0, 2, 6], state: "minecraft:dark_oak_stairs{facing:east,half:top,shape:straight,waterlogged:false}"},
        {pos: [0, 2, 7], state: "minecraft:dark_oak_stairs{facing:east,half:top,shape:straight,waterlogged:false}"},
        {pos: [1, 2, 0], state: "minecraft:dark_oak_planks"},
        {pos: [1, 2, 1], state: "minecraft:dark_oak_planks"},
        {pos: [1, 2, 2], state: "minecraft:dark_oak_planks"},
        {pos: [1, 2, 3], state: "minecraft:dark_oak_planks"},
        {pos: [1, 2, 4], state: "minecraft:dark_oak_planks"},
        {pos: [1, 2, 5], state: "minecraft:dark_oak_planks"},
        {pos: [1, 2, 6], state: "minecraft:dark_oak_planks"},
        {pos: [1, 2, 7], state: "minecraft:dark_oak_planks"},
        {pos: [2, 2, 0], state: "minecraft:dark_oak_stairs{facing:west,half:bottom,shape:straight,waterlogged:false}"},
        {pos: [2, 2, 1], state: "minecraft:dark_oak_stairs{facing:west,half:bottom,shape:straight,waterlogged:false}"},
        {pos: [2, 2, 2], state: "minecraft:dark_oak_stairs{facing:west,half:bottom,shape:straight,waterlogged:false}"},
        {pos: [2, 2, 3], state: "minecraft:dark_oak_stairs{facing:west,half:bottom,shape:straight,waterlogged:false}"},
        {pos: [2, 2, 4], state: "minecraft:dark_oak_stairs{facing:west,half:bottom,shape:straight,waterlogged:false}"},
        {pos: [2, 2, 5], state: "minecraft:dark_oak_stairs{facing:west,half:bottom,shape:straight,waterlogged:false}"},
        {pos: [2, 2, 6], state: "minecraft:dark_oak_stairs{facing:west,half:bottom,shape:straight,waterlogged:false}"},
        {pos: [2, 2, 7], state: "minecraft:dark_oak_stairs{facing:west,half:bottom,shape:straight,waterlogged:false}"},
        {pos: [3, 2, 0], state: "minecraft:air"},
        {pos: [3, 2, 1], state: "minecraft:air"},
        {pos: [3, 2, 2], state: "minecraft:air"},
        {pos: [3, 2, 3], state: "minecraft:air"},
        {pos: [3, 2, 4], state: "minecraft:air"},
        {pos: [3, 2, 5], state: "minecraft:air"},
        {pos: [3, 2, 6], state: "minecraft:air"},
        {pos: [3, 2, 7], state: "minecraft:air"},
        {pos: [0, 3, 0], state: "minecraft:dark_oak_planks"},
        {pos: [0, 3, 1], state: "minecraft:dark_oak_planks"},
        {pos: [0, 3, 2], state: "minecraft:dark_oak_planks"},
        {pos: [0, 3, 3], state: "minecraft:dark_oak_planks"},
        {pos: [0, 3, 4], state: "minecraft:dark_oak_planks"},
        {pos: [0, 3, 5], state: "minecraft:dark_oak_planks"},
        {pos: [0, 3, 6], state: "minecraft:dark_oak_planks"},
        {pos: [0, 3, 7], state: "minecraft:dark_oak_planks"},
        {pos: [1, 3, 0], state: "minecraft:dark_oak_stairs{facing:west,half:bottom,shape:straight,waterlogged:false}"},
        {pos: [1, 3, 1], state: "minecraft:dark_oak_stairs{facing:west,half:bottom,shape:straight,waterlogged:false}"},
        {pos: [1, 3, 2], state: "minecraft:dark_oak_stairs{facing:west,half:bottom,shape:straight,waterlogged:false}"},
        {pos: [1, 3, 3], state: "minecraft:dark_oak_stairs{facing:west,half:bottom,shape:straight,waterlogged:false}"},
        {pos: [1, 3, 4], state: "minecraft:dark_oak_stairs{facing:west,half:bottom,shape:straight,waterlogged:false}"},
        {pos: [1, 3, 5], state: "minecraft:dark_oak_stairs{facing:west,half:bottom,shape:straight,waterlogged:false}"},
        {pos: [1, 3, 6], state: "minecraft:dark_oak_stairs{facing:west,half:bottom,shape:straight,waterlogged:false}"},
        {pos: [1, 3, 7], state: "minecraft:dark_oak_stairs{facing:west,half:bottom,shape:straight,waterlogged:false}"},
        {pos: [2, 3, 0], state: "minecraft:air"},
        {pos: [2, 3, 1], state: "minecraft:air"},
        {pos: [2, 3, 2], state: "minecraft:air"},
        {pos: [2, 3, 3], state: "minecraft:air"},
        {pos: [2, 3, 4], state: "minecraft:air"},
        {pos: [2, 3, 5], state: "minecraft:air"},
        {pos: [2, 3, 6], state: "minecraft:air"},
        {pos: [2, 3, 7], state: "minecraft:air"},
        {pos: [3, 3, 0], state: "minecraft:air"},
        {pos: [3, 3, 1], state: "minecraft:air"},
        {pos: [3, 3, 2], state: "minecraft:air"},
        {pos: [3, 3, 3], state: "minecraft:air"},
        {pos: [3, 3, 4], state: "minecraft:air"},
        {pos: [3, 3, 5], state: "minecraft:air"},
        {pos: [3, 3, 6], state: "minecraft:air"},
        {pos: [3, 3, 7], state: "minecraft:air"}
    ],
    entities: [],
    palette: [
        "minecraft:cobblestone",
        "minecraft:dark_oak_planks",
        "minecraft:air",
        "minecraft:dark_oak_stairs{facing:west,half:bottom,shape:straight,waterlogged:false}",
        "minecraft:dark_oak_stairs{facing:east,half:top,shape:straight,waterlogged:false}"
    ]
}
