{
    size: [5, 17, 15],
    data: [
        {pos: [0, 0, 0], state: "minecraft:tuff_bricks"},
        {pos: [0, 0, 1], state: "minecraft:waxed_oxidized_copper"},
        {pos: [0, 0, 2], state: "minecraft:waxed_oxidized_copper"},
        {pos: [0, 0, 3], state: "minecraft:waxed_oxidized_copper"},
        {pos: [0, 0, 4], state: "minecraft:tuff_bricks"},
        {pos: [0, 0, 5], state: "minecraft:tuff_bricks"},
        {pos: [0, 0, 6], state: "minecraft:tuff_bricks"},
        {pos: [0, 0, 7], state: "minecraft:tuff_bricks"},
        {pos: [0, 0, 8], state: "minecraft:tuff_bricks"},
        {pos: [0, 0, 9], state: "minecraft:tuff_bricks"},
        {pos: [0, 0, 10], state: "minecraft:tuff_bricks"},
        {pos: [0, 0, 11], state: "minecraft:tuff_bricks"},
        {pos: [0, 0, 12], state: "minecraft:tuff_bricks"},
        {pos: [0, 0, 13], state: "minecraft:tuff_bricks"},
        {pos: [0, 0, 14], state: "minecraft:tuff_bricks"},
        {pos: [1, 0, 0], state: "minecraft:waxed_oxidized_copper"},
        {pos: [1, 0, 1], state: "minecraft:waxed_oxidized_copper"},
        {pos: [1, 0, 2], state: "minecraft:waxed_oxidized_copper"},
        {pos: [1, 0, 3], state: "minecraft:waxed_oxidized_copper"},
        {pos: [1, 0, 4], state: "minecraft:waxed_oxidized_copper"},
        {pos: [1, 0, 5], state: "minecraft:tuff_bricks"},
        {pos: [1, 0, 6], state: "minecraft:tuff_bricks"},
        {pos: [1, 0, 7], state: "minecraft:tuff_bricks"},
        {pos: [1, 0, 8], state: "minecraft:tuff_bricks"},
        {pos: [1, 0, 9], state: "minecraft:tuff_bricks"},
        {pos: [1, 0, 10], state: "minecraft:tuff_bricks"},
        {pos: [1, 0, 11], state: "minecraft:tuff_bricks"},
        {pos: [1, 0, 12], state: "minecraft:tuff_bricks"},
        {pos: [1, 0, 13], state: "minecraft:tuff_bricks"},
        {pos: [1, 0, 14], state: "minecraft:tuff_bricks"},
        {pos: [2, 0, 0], state: "minecraft:waxed_oxidized_copper"},
        {pos: [2, 0, 1], state: "minecraft:waxed_oxidized_copper"},
        {pos: [2, 0, 2], state: "minecraft:waxed_oxidized_copper"},
        {pos: [2, 0, 3], state: "minecraft:waxed_oxidized_copper"},
        {pos: [2, 0, 4], state: "minecraft:waxed_oxidized_copper"},
        {pos: [2, 0, 5], state: "minecraft:tuff_bricks"},
        {pos: [2, 0, 6], state: "minecraft:tuff_bricks"},
        {pos: [2, 0, 7], state: "minecraft:tuff_bricks"},
        {pos: [2, 0, 8], state: "minecraft:tuff_bricks"},
        {pos: [2, 0, 9], state: "minecraft:tuff_bricks"},
        {pos: [2, 0, 10], state: "minecraft:tuff_bricks"},
        {pos: [2, 0, 11], state: "minecraft:tuff_bricks"},
        {pos: [2, 0, 12], state: "minecraft:tuff_bricks"},
        {pos: [2, 0, 13], state: "minecraft:tuff_bricks"},
        {pos: [2, 0, 14], state: "minecraft:tuff_bricks"},
        {pos: [3, 0, 0], state: "minecraft:waxed_oxidized_copper"},
        {pos: [3, 0, 1], state: "minecraft:waxed_oxidized_copper"},
        {pos: [3, 0, 2], state: "minecraft:waxed_oxidized_copper"},
        {pos: [3, 0, 3], state: "minecraft:waxed_oxidized_copper"},
        {pos: [3, 0, 4], state: "minecraft:waxed_oxidized_copper"},
        {pos: [3, 0, 5], state: "minecraft:tuff_bricks"},
        {pos: [3, 0, 6], state: "minecraft:tuff_bricks"},
        {pos: [3, 0, 7], state: "minecraft:tuff_bricks"},
        {pos: [3, 0, 8], state: "minecraft:tuff_bricks"},
        {pos: [3, 0, 9], state: "minecraft:tuff_bricks"},
        {pos: [3, 0, 10], state: "minecraft:tuff_bricks"},
        {pos: [3, 0, 11], state: "minecraft:tuff_bricks"},
        {pos: [3, 0, 12], state: "minecraft:tuff_bricks"},
        {pos: [3, 0, 13], state: "minecraft:tuff_bricks"},
        {pos: [3, 0, 14], state: "minecraft:tuff_bricks"},
        {pos: [4, 0, 0], state: "minecraft:waxed_oxidized_copper"},
        {pos: [4, 0, 1], state: "minecraft:waxed_oxidized_copper"},
        {pos: [4, 0, 2], state: "minecraft:waxed_oxidized_copper"},
        {pos: [4, 0, 3], state: "minecraft:waxed_oxidized_copper"},
        {pos: [4, 0, 4], state: "minecraft:tuff_bricks"},
        {pos: [4, 0, 5], state: "minecraft:tuff_bricks"},
        {pos: [4, 0, 6], state: "minecraft:tuff_bricks"},
        {pos: [4, 0, 7], state: "minecraft:tuff_bricks"},
        {pos: [4, 0, 8], state: "minecraft:tuff_bricks"},
        {pos: [4, 0, 9], state: "minecraft:tuff_bricks"},
        {pos: [4, 0, 10], state: "minecraft:tuff_bricks"},
        {pos: [4, 0, 11], state: "minecraft:tuff_bricks"},
        {pos: [4, 0, 12], state: "minecraft:tuff_bricks"},
        {pos: [4, 0, 13], state: "minecraft:tuff_bricks"},
        {pos: [4, 0, 14], state: "minecraft:tuff_bricks"},
        {pos: [0, 1, 0], state: "minecraft:waxed_copper_block"},
        {pos: [0, 1, 4], state: "minecraft:waxed_copper_block"},
        {pos: [0, 1, 5], state: "minecraft:waxed_copper_block"},
        {pos: [0, 1, 6], state: "minecraft:tuff_bricks"},
        {pos: [0, 1, 7], state: "minecraft:tuff_bricks"},
        {pos: [0, 1, 8], state: "minecraft:tuff_bricks"},
        {pos: [0, 1, 9], state: "minecraft:tuff_bricks"},
        {pos: [0, 1, 10], state: "minecraft:tuff_bricks"},
        {pos: [0, 1, 11], state: "minecraft:tuff_bricks"},
        {pos: [0, 1, 12], state: "minecraft:tuff_bricks"},
        {pos: [0, 1, 13], state: "minecraft:tuff_bricks"},
        {pos: [0, 1, 14], state: "minecraft:tuff_bricks"},
        {pos: [1, 1, 5], state: "minecraft:waxed_copper_block"},
        {pos: [1, 1, 6], state: "minecraft:tuff_bricks"},
        {pos: [1, 1, 7], state: "minecraft:tuff_bricks"},
        {pos: [1, 1, 8], state: "minecraft:tuff_bricks"},
        {pos: [1, 1, 9], state: "minecraft:tuff_bricks"},
        {pos: [1, 1, 10], state: "minecraft:tuff_bricks"},
        {pos: [1, 1, 11], state: "minecraft:tuff_bricks"},
        {pos: [1, 1, 12], state: "minecraft:tuff_bricks"},
        {pos: [1, 1, 13], state: "minecraft:tuff_bricks"},
        {pos: [1, 1, 14], state: "minecraft:tuff_bricks"},
        {pos: [2, 1, 5], state: "minecraft:waxed_copper_block"},
        {pos: [2, 1, 6], state: "minecraft:tuff_bricks"},
        {pos: [2, 1, 7], state: "minecraft:tuff_bricks"},
        {pos: [2, 1, 8], state: "minecraft:tuff_bricks"},
        {pos: [2, 1, 9], state: "minecraft:tuff_bricks"},
        {pos: [2, 1, 10], state: "minecraft:tuff_bricks"},
        {pos: [2, 1, 11], state: "minecraft:tuff_bricks"},
        {pos: [2, 1, 12], state: "minecraft:tuff_bricks"},
        {pos: [2, 1, 13], state: "minecraft:tuff_bricks"},
        {pos: [2, 1, 14], state: "minecraft:tuff_bricks"},
        {pos: [3, 1, 5], state: "minecraft:waxed_copper_block"},
        {pos: [3, 1, 6], state: "minecraft:tuff_bricks"},
        {pos: [3, 1, 7], state: "minecraft:tuff_bricks"},
        {pos: [3, 1, 8], state: "minecraft:tuff_bricks"},
        {pos: [3, 1, 9], state: "minecraft:tuff_bricks"},
        {pos: [3, 1, 10], state: "minecraft:tuff_bricks"},
        {pos: [3, 1, 11], state: "minecraft:tuff_bricks"},
        {pos: [3, 1, 12], state: "minecraft:tuff_bricks"},
        {pos: [3, 1, 13], state: "minecraft:tuff_bricks"},
        {pos: [3, 1, 14], state: "minecraft:tuff_bricks"},
        {pos: [4, 1, 4], state: "minecraft:waxed_copper_block"},
        {pos: [4, 1, 5], state: "minecraft:waxed_copper_block"},
        {pos: [4, 1, 6], state: "minecraft:waxed_copper_block"},
        {pos: [4, 1, 7], state: "minecraft:waxed_copper_block"},
        {pos: [4, 1, 8], state: "minecraft:waxed_copper_block"},
        {pos: [4, 1, 9], state: "minecraft:waxed_copper_block"},
        {pos: [4, 1, 10], state: "minecraft:waxed_copper_block"},
        {pos: [4, 1, 11], state: "minecraft:waxed_copper_block"},
        {pos: [4, 1, 12], state: "minecraft:waxed_copper_block"},
        {pos: [4, 1, 13], state: "minecraft:waxed_copper_block"},
        {pos: [4, 1, 14], state: "minecraft:waxed_copper_block"},
        {pos: [0, 2, 0], state: "minecraft:tuff_bricks"},
        {pos: [0, 2, 1], state: "minecraft:air"},
        {pos: [0, 2, 2], state: "minecraft:air"},
        {pos: [0, 2, 3], state: "minecraft:air"},
        {pos: [0, 2, 4], state: "minecraft:tuff_bricks"},
        {pos: [0, 2, 5], state: "minecraft:tuff_bricks"},
        {pos: [0, 2, 6], state: "minecraft:tuff_bricks"},
        {pos: [0, 2, 7], state: "minecraft:tuff_bricks"},
        {pos: [0, 2, 8], state: "minecraft:tuff_bricks"},
        {pos: [0, 2, 9], state: "minecraft:tuff_bricks"},
        {pos: [0, 2, 10], state: "minecraft:tuff_bricks"},
        {pos: [0, 2, 11], state: "minecraft:tuff_bricks"},
        {pos: [0, 2, 12], state: "minecraft:tuff_bricks"},
        {pos: [0, 2, 13], state: "minecraft:tuff_bricks"},
        {pos: [0, 2, 14], state: "minecraft:tuff_bricks"},
        {pos: [1, 2, 0], state: "minecraft:air"},
        {pos: [1, 2, 1], state: "minecraft:air"},
        {pos: [1, 2, 2], state: "minecraft:air"},
        {pos: [1, 2, 3], state: "minecraft:air"},
        {pos: [1, 2, 4], state: "minecraft:air"},
        {pos: [1, 2, 5], state: "minecraft:tuff_bricks"},
        {pos: [1, 2, 6], state: "minecraft:tuff_bricks"},
        {pos: [1, 2, 7], state: "minecraft:tuff_bricks"},
        {pos: [1, 2, 8], state: "minecraft:tuff_bricks"},
        {pos: [1, 2, 9], state: "minecraft:tuff_bricks"},
        {pos: [1, 2, 10], state: "minecraft:tuff_bricks"},
        {pos: [1, 2, 11], state: "minecraft:tuff_bricks"},
        {pos: [1, 2, 12], state: "minecraft:tuff_bricks"},
        {pos: [1, 2, 13], state: "minecraft:tuff_bricks"},
        {pos: [1, 2, 14], state: "minecraft:tuff_bricks"},
        {pos: [2, 2, 0], state: "minecraft:air"},
        {pos: [2, 2, 1], state: "minecraft:air"},
        {pos: [2, 2, 2], state: "minecraft:air"},
        {pos: [2, 2, 3], state: "minecraft:air"},
        {pos: [2, 2, 4], state: "minecraft:air"},
        {pos: [2, 2, 5], state: "minecraft:waxed_copper_bulb{lit:true,powered:false}"},
        {pos: [2, 2, 6], state: "minecraft:tuff_bricks"},
        {pos: [2, 2, 7], state: "minecraft:tuff_bricks"},
        {pos: [2, 2, 8], state: "minecraft:tuff_bricks"},
        {pos: [2, 2, 9], state: "minecraft:tuff_bricks"},
        {pos: [2, 2, 10], state: "minecraft:tuff_bricks"},
        {pos: [2, 2, 11], state: "minecraft:tuff_bricks"},
        {pos: [2, 2, 12], state: "minecraft:tuff_bricks"},
        {pos: [2, 2, 13], state: "minecraft:tuff_bricks"},
        {pos: [2, 2, 14], state: "minecraft:tuff_bricks"},
        {pos: [3, 2, 0], state: "minecraft:air"},
        {pos: [3, 2, 1], state: "minecraft:air"},
        {pos: [3, 2, 2], state: "minecraft:air"},
        {pos: [3, 2, 3], state: "minecraft:air"},
        {pos: [3, 2, 4], state: "minecraft:air"},
        {pos: [3, 2, 5], state: "minecraft:tuff_bricks"},
        {pos: [3, 2, 6], state: "minecraft:tuff_bricks"},
        {pos: [3, 2, 7], state: "minecraft:tuff_bricks"},
        {pos: [3, 2, 8], state: "minecraft:tuff_bricks"},
        {pos: [3, 2, 9], state: "minecraft:tuff_bricks"},
        {pos: [3, 2, 10], state: "minecraft:tuff_bricks"},
        {pos: [3, 2, 11], state: "minecraft:tuff_bricks"},
        {pos: [3, 2, 12], state: "minecraft:tuff_bricks"},
        {pos: [3, 2, 13], state: "minecraft:tuff_bricks"},
        {pos: [3, 2, 14], state: "minecraft:tuff_bricks"},
        {pos: [4, 2, 0], state: "minecraft:air"},
        {pos: [4, 2, 1], state: "minecraft:air"},
        {pos: [4, 2, 2], state: "minecraft:air"},
        {pos: [4, 2, 3], state: "minecraft:air"},
        {pos: [4, 2, 4], state: "minecraft:tuff_bricks"},
        {pos: [4, 2, 5], state: "minecraft:tuff_bricks"},
        {pos: [4, 2, 6], state: "minecraft:tuff_bricks"},
        {pos: [4, 2, 7], state: "minecraft:waxed_copper_bulb{lit:true,powered:false}"},
        {pos: [4, 2, 8], state: "minecraft:jigsaw{orientation:down_east}", nbt: {final_state: "minecraft:tuff_bricks", id: "minecraft:jigsaw", joint: "aligned", name: "minecraft:empty", placement_priority: 0, pool: "minecraft:trial_chambers/dispensers/chamber", selection_priority: 0, target: "minecraft:copper_dispenser"}},
        {pos: [4, 2, 9], state: "minecraft:tuff_bricks"},
        {pos: [4, 2, 10], state: "minecraft:tuff_bricks"},
        {pos: [4, 2, 11], state: "minecraft:tuff_bricks"},
        {pos: [4, 2, 12], state: "minecraft:tuff_bricks"},
        {pos: [4, 2, 13], state: "minecraft:tuff_bricks"},
        {pos: [4, 2, 14], state: "minecraft:tuff_bricks"},
        {pos: [0, 3, 0], state: "minecraft:chiseled_tuff_bricks"},
        {pos: [0, 3, 1], state: "minecraft:air"},
        {pos: [0, 3, 2], state: "minecraft:air"},
        {pos: [0, 3, 3], state: "minecraft:air"},
        {pos: [0, 3, 4], state: "minecraft:chiseled_tuff_bricks"},
        {pos: [0, 3, 5], state: "minecraft:chiseled_tuff_bricks"},
        {pos: [0, 3, 6], state: "minecraft:tuff_bricks"},
        {pos: [0, 3, 7], state: "minecraft:tuff_bricks"},
        {pos: [0, 3, 8], state: "minecraft:tuff_bricks"},
        {pos: [0, 3, 9], state: "minecraft:tuff_bricks"},
        {pos: [0, 3, 10], state: "minecraft:tuff_bricks"},
        {pos: [0, 3, 11], state: "minecraft:tuff_bricks"},
        {pos: [0, 3, 12], state: "minecraft:tuff_bricks"},
        {pos: [0, 3, 13], state: "minecraft:tuff_bricks"},
        {pos: [0, 3, 14], state: "minecraft:tuff_bricks"},
        {pos: [1, 3, 0], state: "minecraft:air"},
        {pos: [1, 3, 1], state: "minecraft:air"},
        {pos: [1, 3, 2], state: "minecraft:air"},
        {pos: [1, 3, 3], state: "minecraft:air"},
        {pos: [1, 3, 4], state: "minecraft:air"},
        {pos: [1, 3, 5], state: "minecraft:chiseled_tuff_bricks"},
        {pos: [1, 3, 6], state: "minecraft:tuff_bricks"},
        {pos: [1, 3, 7], state: "minecraft:tuff_bricks"},
        {pos: [1, 3, 8], state: "minecraft:tuff_bricks"},
        {pos: [1, 3, 9], state: "minecraft:tuff_bricks"},
        {pos: [1, 3, 10], state: "minecraft:tuff_bricks"},
        {pos: [1, 3, 11], state: "minecraft:tuff_bricks"},
        {pos: [1, 3, 12], state: "minecraft:tuff_bricks"},
        {pos: [1, 3, 13], state: "minecraft:tuff_bricks"},
        {pos: [1, 3, 14], state: "minecraft:tuff_bricks"},
        {pos: [2, 3, 0], state: "minecraft:air"},
        {pos: [2, 3, 1], state: "minecraft:air"},
        {pos: [2, 3, 2], state: "minecraft:air"},
        {pos: [2, 3, 3], state: "minecraft:air"},
        {pos: [2, 3, 4], state: "minecraft:air"},
        {pos: [2, 3, 5], state: "minecraft:chiseled_tuff_bricks"},
        {pos: [2, 3, 6], state: "minecraft:tuff_bricks"},
        {pos: [2, 3, 7], state: "minecraft:tuff_bricks"},
        {pos: [2, 3, 8], state: "minecraft:tuff_bricks"},
        {pos: [2, 3, 9], state: "minecraft:tuff_bricks"},
        {pos: [2, 3, 10], state: "minecraft:tuff_bricks"},
        {pos: [2, 3, 11], state: "minecraft:tuff_bricks"},
        {pos: [2, 3, 12], state: "minecraft:tuff_bricks"},
        {pos: [2, 3, 13], state: "minecraft:tuff_bricks"},
        {pos: [2, 3, 14], state: "minecraft:tuff_bricks"},
        {pos: [3, 3, 0], state: "minecraft:air"},
        {pos: [3, 3, 1], state: "minecraft:air"},
        {pos: [3, 3, 2], state: "minecraft:air"},
        {pos: [3, 3, 3], state: "minecraft:air"},
        {pos: [3, 3, 4], state: "minecraft:air"},
        {pos: [3, 3, 5], state: "minecraft:chiseled_tuff_bricks"},
        {pos: [3, 3, 6], state: "minecraft:tuff_bricks"},
        {pos: [3, 3, 7], state: "minecraft:tuff_bricks"},
        {pos: [3, 3, 8], state: "minecraft:tuff_bricks"},
        {pos: [3, 3, 9], state: "minecraft:tuff_bricks"},
        {pos: [3, 3, 10], state: "minecraft:tuff_bricks"},
        {pos: [3, 3, 11], state: "minecraft:tuff_bricks"},
        {pos: [3, 3, 12], state: "minecraft:tuff_bricks"},
        {pos: [3, 3, 13], state: "minecraft:tuff_bricks"},
        {pos: [3, 3, 14], state: "minecraft:tuff_bricks"},
        {pos: [4, 3, 0], state: "minecraft:air"},
        {pos: [4, 3, 1], state: "minecraft:air"},
        {pos: [4, 3, 2], state: "minecraft:air"},
        {pos: [4, 3, 3], state: "minecraft:air"},
        {pos: [4, 3, 4], state: "minecraft:chiseled_tuff_bricks"},
        {pos: [4, 3, 5], state: "minecraft:chiseled_tuff_bricks"},
        {pos: [4, 3, 6], state: "minecraft:chiseled_tuff_bricks"},
        {pos: [4, 3, 7], state: "minecraft:chiseled_tuff_bricks"},
        {pos: [4, 3, 8], state: "minecraft:chiseled_tuff_bricks"},
        {pos: [4, 3, 9], state: "minecraft:chiseled_tuff_bricks"},
        {pos: [4, 3, 10], state: "minecraft:chiseled_tuff_bricks"},
        {pos: [4, 3, 11], state: "minecraft:chiseled_tuff_bricks"},
        {pos: [4, 3, 12], state: "minecraft:chiseled_tuff_bricks"},
        {pos: [4, 3, 13], state: "minecraft:chiseled_tuff_bricks"},
        {pos: [4, 3, 14], state: "minecraft:chiseled_tuff_bricks"},
        {pos: [0, 4, 0], state: "minecraft:tuff_bricks"},
        {pos: [0, 4, 1], state: "minecraft:air"},
        {pos: [0, 4, 2], state: "minecraft:air"},
        {pos: [0, 4, 3], state: "minecraft:air"},
        {pos: [0, 4, 4], state: "minecraft:tuff_bricks"},
        {pos: [0, 4, 5], state: "minecraft:tuff_bricks"},
        {pos: [0, 4, 6], state: "minecraft:tuff_bricks"},
        {pos: [0, 4, 7], state: "minecraft:tuff_bricks"},
        {pos: [0, 4, 8], state: "minecraft:tuff_bricks"},
        {pos: [0, 4, 9], state: "minecraft:tuff_bricks"},
        {pos: [0, 4, 10], state: "minecraft:tuff_bricks"},
        {pos: [0, 4, 11], state: "minecraft:tuff_bricks"},
        {pos: [0, 4, 12], state: "minecraft:tuff_bricks"},
        {pos: [0, 4, 13], state: "minecraft:tuff_bricks"},
        {pos: [0, 4, 14], state: "minecraft:tuff_bricks"},
        {pos: [1, 4, 0], state: "minecraft:air"},
        {pos: [1, 4, 1], state: "minecraft:air"},
        {pos: [1, 4, 2], state: "minecraft:air"},
        {pos: [1, 4, 3], state: "minecraft:air"},
        {pos: [1, 4, 4], state: "minecraft:air"},
        {pos: [1, 4, 5], state: "minecraft:tuff_bricks"},
        {pos: [1, 4, 6], state: "minecraft:tuff_bricks"},
        {pos: [1, 4, 7], state: "minecraft:tuff_bricks"},
        {pos: [1, 4, 8], state: "minecraft:tuff_bricks"},
        {pos: [1, 4, 9], state: "minecraft:tuff_bricks"},
        {pos: [1, 4, 10], state: "minecraft:tuff_bricks"},
        {pos: [1, 4, 11], state: "minecraft:tuff_bricks"},
        {pos: [1, 4, 12], state: "minecraft:tuff_bricks"},
        {pos: [1, 4, 13], state: "minecraft:tuff_bricks"},
        {pos: [1, 4, 14], state: "minecraft:tuff_bricks"},
        {pos: [2, 4, 0], state: "minecraft:air"},
        {pos: [2, 4, 1], state: "minecraft:air"},
        {pos: [2, 4, 2], state: "minecraft:air"},
        {pos: [2, 4, 3], state: "minecraft:air"},
        {pos: [2, 4, 4], state: "minecraft:air"},
        {pos: [2, 4, 5], state: "minecraft:tuff_bricks"},
        {pos: [2, 4, 6], state: "minecraft:tuff_bricks"},
        {pos: [2, 4, 7], state: "minecraft:tuff_bricks"},
        {pos: [2, 4, 8], state: "minecraft:tuff_bricks"},
        {pos: [2, 4, 9], state: "minecraft:tuff_bricks"},
        {pos: [2, 4, 10], state: "minecraft:tuff_bricks"},
        {pos: [2, 4, 11], state: "minecraft:tuff_bricks"},
        {pos: [2, 4, 12], state: "minecraft:tuff_bricks"},
        {pos: [2, 4, 13], state: "minecraft:tuff_bricks"},
        {pos: [2, 4, 14], state: "minecraft:tuff_bricks"},
        {pos: [3, 4, 0], state: "minecraft:air"},
        {pos: [3, 4, 1], state: "minecraft:air"},
        {pos: [3, 4, 2], state: "minecraft:air"},
        {pos: [3, 4, 3], state: "minecraft:air"},
        {pos: [3, 4, 4], state: "minecraft:air"},
        {pos: [3, 4, 5], state: "minecraft:tuff_bricks"},
        {pos: [3, 4, 6], state: "minecraft:tuff_bricks"},
        {pos: [3, 4, 7], state: "minecraft:tuff_bricks"},
        {pos: [3, 4, 8], state: "minecraft:tuff_bricks"},
        {pos: [3, 4, 9], state: "minecraft:tuff_bricks"},
        {pos: [3, 4, 10], state: "minecraft:tuff_bricks"},
        {pos: [3, 4, 11], state: "minecraft:tuff_bricks"},
        {pos: [3, 4, 12], state: "minecraft:tuff_bricks"},
        {pos: [3, 4, 13], state: "minecraft:tuff_bricks"},
        {pos: [3, 4, 14], state: "minecraft:tuff_bricks"},
        {pos: [4, 4, 0], state: "minecraft:air"},
        {pos: [4, 4, 1], state: "minecraft:air"},
        {pos: [4, 4, 2], state: "minecraft:air"},
        {pos: [4, 4, 3], state: "minecraft:air"},
        {pos: [4, 4, 4], state: "minecraft:tuff_bricks"},
        {pos: [4, 4, 5], state: "minecraft:tuff_bricks"},
        {pos: [4, 4, 6], state: "minecraft:tuff_bricks"},
        {pos: [4, 4, 7], state: "minecraft:tuff_bricks"},
        {pos: [4, 4, 8], state: "minecraft:tuff_bricks"},
        {pos: [4, 4, 9], state: "minecraft:tuff_bricks"},
        {pos: [4, 4, 10], state: "minecraft:tuff_bricks"},
        {pos: [4, 4, 11], state: "minecraft:tuff_bricks"},
        {pos: [4, 4, 12], state: "minecraft:tuff_bricks"},
        {pos: [4, 4, 13], state: "minecraft:tuff_bricks"},
        {pos: [4, 4, 14], state: "minecraft:tuff_bricks"},
        {pos: [0, 5, 0], state: "minecraft:tuff_bricks"},
        {pos: [0, 5, 1], state: "minecraft:air"},
        {pos: [0, 5, 2], state: "minecraft:air"},
        {pos: [0, 5, 3], state: "minecraft:air"},
        {pos: [0, 5, 4], state: "minecraft:tuff_bricks"},
        {pos: [0, 5, 5], state: "minecraft:tuff_bricks"},
        {pos: [0, 5, 6], state: "minecraft:tuff_bricks"},
        {pos: [0, 5, 7], state: "minecraft:tuff_bricks"},
        {pos: [0, 5, 8], state: "minecraft:tuff_bricks"},
        {pos: [0, 5, 9], state: "minecraft:tuff_bricks"},
        {pos: [0, 5, 10], state: "minecraft:tuff_bricks"},
        {pos: [0, 5, 11], state: "minecraft:tuff_bricks"},
        {pos: [0, 5, 12], state: "minecraft:tuff_bricks"},
        {pos: [0, 5, 13], state: "minecraft:tuff_bricks"},
        {pos: [0, 5, 14], state: "minecraft:tuff_bricks"},
        {pos: [1, 5, 0], state: "minecraft:air"},
        {pos: [1, 5, 1], state: "minecraft:air"},
        {pos: [1, 5, 2], state: "minecraft:air"},
        {pos: [1, 5, 3], state: "minecraft:air"},
        {pos: [1, 5, 4], state: "minecraft:air"},
        {pos: [1, 5, 5], state: "minecraft:tuff_bricks"},
        {pos: [1, 5, 6], state: "minecraft:tuff_bricks"},
        {pos: [1, 5, 7], state: "minecraft:tuff_bricks"},
        {pos: [1, 5, 8], state: "minecraft:tuff_bricks"},
        {pos: [1, 5, 9], state: "minecraft:tuff_bricks"},
        {pos: [1, 5, 10], state: "minecraft:tuff_bricks"},
        {pos: [1, 5, 11], state: "minecraft:tuff_bricks"},
        {pos: [1, 5, 12], state: "minecraft:tuff_bricks"},
        {pos: [1, 5, 13], state: "minecraft:tuff_bricks"},
        {pos: [1, 5, 14], state: "minecraft:tuff_bricks"},
        {pos: [2, 5, 0], state: "minecraft:air"},
        {pos: [2, 5, 1], state: "minecraft:air"},
        {pos: [2, 5, 2], state: "minecraft:air"},
        {pos: [2, 5, 3], state: "minecraft:air"},
        {pos: [2, 5, 4], state: "minecraft:air"},
        {pos: [2, 5, 5], state: "minecraft:tuff_bricks"},
        {pos: [2, 5, 6], state: "minecraft:tuff_bricks"},
        {pos: [2, 5, 7], state: "minecraft:tuff_bricks"},
        {pos: [2, 5, 8], state: "minecraft:tuff_bricks"},
        {pos: [2, 5, 9], state: "minecraft:tuff_bricks"},
        {pos: [2, 5, 10], state: "minecraft:tuff_bricks"},
        {pos: [2, 5, 11], state: "minecraft:tuff_bricks"},
        {pos: [2, 5, 12], state: "minecraft:tuff_bricks"},
        {pos: [2, 5, 13], state: "minecraft:tuff_bricks"},
        {pos: [2, 5, 14], state: "minecraft:tuff_bricks"},
        {pos: [3, 5, 0], state: "minecraft:air"},
        {pos: [3, 5, 1], state: "minecraft:air"},
        {pos: [3, 5, 2], state: "minecraft:air"},
        {pos: [3, 5, 3], state: "minecraft:air"},
        {pos: [3, 5, 4], state: "minecraft:air"},
        {pos: [3, 5, 5], state: "minecraft:tuff_bricks"},
        {pos: [3, 5, 6], state: "minecraft:tuff_bricks"},
        {pos: [3, 5, 7], state: "minecraft:tuff_bricks"},
        {pos: [3, 5, 8], state: "minecraft:tuff_bricks"},
        {pos: [3, 5, 9], state: "minecraft:tuff_bricks"},
        {pos: [3, 5, 10], state: "minecraft:tuff_bricks"},
        {pos: [3, 5, 11], state: "minecraft:tuff_bricks"},
        {pos: [3, 5, 12], state: "minecraft:tuff_bricks"},
        {pos: [3, 5, 13], state: "minecraft:tuff_bricks"},
        {pos: [3, 5, 14], state: "minecraft:tuff_bricks"},
        {pos: [4, 5, 0], state: "minecraft:air"},
        {pos: [4, 5, 1], state: "minecraft:air"},
        {pos: [4, 5, 2], state: "minecraft:air"},
        {pos: [4, 5, 3], state: "minecraft:air"},
        {pos: [4, 5, 4], state: "minecraft:tuff_bricks"},
        {pos: [4, 5, 5], state: "minecraft:tuff_bricks"},
        {pos: [4, 5, 6], state: "minecraft:tuff_bricks"},
        {pos: [4, 5, 7], state: "minecraft:tuff_bricks"},
        {pos: [4, 5, 8], state: "minecraft:tuff_bricks"},
        {pos: [4, 5, 9], state: "minecraft:tuff_bricks"},
        {pos: [4, 5, 10], state: "minecraft:tuff_bricks"},
        {pos: [4, 5, 11], state: "minecraft:tuff_bricks"},
        {pos: [4, 5, 12], state: "minecraft:tuff_bricks"},
        {pos: [4, 5, 13], state: "minecraft:tuff_bricks"},
        {pos: [4, 5, 14], state: "minecraft:tuff_bricks"},
        {pos: [0, 6, 0], state: "minecraft:waxed_copper_block"},
        {pos: [0, 6, 1], state: "minecraft:air"},
        {pos: [0, 6, 2], state: "minecraft:air"},
        {pos: [0, 6, 3], state: "minecraft:air"},
        {pos: [0, 6, 4], state: "minecraft:waxed_copper_block"},
        {pos: [0, 6, 5], state: "minecraft:waxed_copper_block"},
        {pos: [0, 6, 6], state: "minecraft:tuff_bricks"},
        {pos: [0, 6, 7], state: "minecraft:tuff_bricks"},
        {pos: [0, 6, 8], state: "minecraft:tuff_bricks"},
        {pos: [0, 6, 9], state: "minecraft:tuff_bricks"},
        {pos: [0, 6, 10], state: "minecraft:tuff_bricks"},
        {pos: [0, 6, 11], state: "minecraft:tuff_bricks"},
        {pos: [0, 6, 12], state: "minecraft:tuff_bricks"},
        {pos: [0, 6, 13], state: "minecraft:tuff_bricks"},
        {pos: [0, 6, 14], state: "minecraft:tuff_bricks"},
        {pos: [1, 6, 0], state: "minecraft:air"},
        {pos: [1, 6, 1], state: "minecraft:air"},
        {pos: [1, 6, 2], state: "minecraft:air"},
        {pos: [1, 6, 3], state: "minecraft:air"},
        {pos: [1, 6, 4], state: "minecraft:air"},
        {pos: [1, 6, 5], state: "minecraft:waxed_copper_block"},
        {pos: [1, 6, 6], state: "minecraft:tuff_bricks"},
        {pos: [1, 6, 7], state: "minecraft:tuff_bricks"},
        {pos: [1, 6, 8], state: "minecraft:tuff_bricks"},
        {pos: [1, 6, 9], state: "minecraft:tuff_bricks"},
        {pos: [1, 6, 10], state: "minecraft:tuff_bricks"},
        {pos: [1, 6, 11], state: "minecraft:tuff_bricks"},
        {pos: [1, 6, 12], state: "minecraft:tuff_bricks"},
        {pos: [1, 6, 13], state: "minecraft:tuff_bricks"},
        {pos: [1, 6, 14], state: "minecraft:tuff_bricks"},
        {pos: [2, 6, 0], state: "minecraft:air"},
        {pos: [2, 6, 1], state: "minecraft:air"},
        {pos: [2, 6, 2], state: "minecraft:air"},
        {pos: [2, 6, 3], state: "minecraft:air"},
        {pos: [2, 6, 4], state: "minecraft:air"},
        {pos: [2, 6, 5], state: "minecraft:waxed_copper_block"},
        {pos: [2, 6, 6], state: "minecraft:tuff_bricks"},
        {pos: [2, 6, 7], state: "minecraft:tuff_bricks"},
        {pos: [2, 6, 8], state: "minecraft:tuff_bricks"},
        {pos: [2, 6, 9], state: "minecraft:tuff_bricks"},
        {pos: [2, 6, 10], state: "minecraft:tuff_bricks"},
        {pos: [2, 6, 11], state: "minecraft:tuff_bricks"},
        {pos: [2, 6, 12], state: "minecraft:tuff_bricks"},
        {pos: [2, 6, 13], state: "minecraft:tuff_bricks"},
        {pos: [2, 6, 14], state: "minecraft:tuff_bricks"},
        {pos: [3, 6, 0], state: "minecraft:air"},
        {pos: [3, 6, 1], state: "minecraft:air"},
        {pos: [3, 6, 2], state: "minecraft:air"},
        {pos: [3, 6, 3], state: "minecraft:air"},
        {pos: [3, 6, 4], state: "minecraft:air"},
        {pos: [3, 6, 5], state: "minecraft:waxed_copper_block"},
        {pos: [3, 6, 6], state: "minecraft:tuff_bricks"},
        {pos: [3, 6, 7], state: "minecraft:tuff_bricks"},
        {pos: [3, 6, 8], state: "minecraft:tuff_bricks"},
        {pos: [3, 6, 9], state: "minecraft:tuff_bricks"},
        {pos: [3, 6, 10], state: "minecraft:tuff_bricks"},
        {pos: [3, 6, 11], state: "minecraft:tuff_bricks"},
        {pos: [3, 6, 12], state: "minecraft:tuff_bricks"},
        {pos: [3, 6, 13], state: "minecraft:tuff_bricks"},
        {pos: [3, 6, 14], state: "minecraft:tuff_bricks"},
        {pos: [4, 6, 0], state: "minecraft:air"},
        {pos: [4, 6, 1], state: "minecraft:air"},
        {pos: [4, 6, 2], state: "minecraft:air"},
        {pos: [4, 6, 3], state: "minecraft:air"},
        {pos: [4, 6, 4], state: "minecraft:waxed_copper_block"},
        {pos: [4, 6, 5], state: "minecraft:waxed_copper_block"},
        {pos: [4, 6, 6], state: "minecraft:waxed_copper_block"},
        {pos: [4, 6, 7], state: "minecraft:waxed_copper_block"},
        {pos: [4, 6, 8], state: "minecraft:waxed_copper_block"},
        {pos: [4, 6, 9], state: "minecraft:waxed_copper_block"},
        {pos: [4, 6, 10], state: "minecraft:waxed_copper_block"},
        {pos: [4, 6, 11], state: "minecraft:waxed_copper_block"},
        {pos: [4, 6, 12], state: "minecraft:waxed_copper_block"},
        {pos: [4, 6, 13], state: "minecraft:waxed_copper_block"},
        {pos: [4, 6, 14], state: "minecraft:waxed_copper_block"},
        {pos: [0, 7, 0], state: "minecraft:tuff_bricks"},
        {pos: [0, 7, 1], state: "minecraft:air"},
        {pos: [0, 7, 2], state: "minecraft:air"},
        {pos: [0, 7, 3], state: "minecraft:air"},
        {pos: [0, 7, 4], state: "minecraft:tuff_bricks"},
        {pos: [0, 7, 5], state: "minecraft:tuff_bricks"},
        {pos: [0, 7, 6], state: "minecraft:tuff_bricks"},
        {pos: [0, 7, 7], state: "minecraft:tuff_bricks"},
        {pos: [0, 7, 8], state: "minecraft:tuff_bricks"},
        {pos: [0, 7, 9], state: "minecraft:tuff_bricks"},
        {pos: [0, 7, 10], state: "minecraft:tuff_bricks"},
        {pos: [0, 7, 11], state: "minecraft:tuff_bricks"},
        {pos: [0, 7, 12], state: "minecraft:tuff_bricks"},
        {pos: [0, 7, 13], state: "minecraft:tuff_bricks"},
        {pos: [0, 7, 14], state: "minecraft:tuff_bricks"},
        {pos: [1, 7, 0], state: "minecraft:air"},
        {pos: [1, 7, 1], state: "minecraft:air"},
        {pos: [1, 7, 2], state: "minecraft:air"},
        {pos: [1, 7, 3], state: "minecraft:air"},
        {pos: [1, 7, 4], state: "minecraft:air"},
        {pos: [1, 7, 5], state: "minecraft:tuff_bricks"},
        {pos: [1, 7, 6], state: "minecraft:tuff_bricks"},
        {pos: [1, 7, 7], state: "minecraft:tuff_bricks"},
        {pos: [1, 7, 8], state: "minecraft:tuff_bricks"},
        {pos: [1, 7, 9], state: "minecraft:tuff_bricks"},
        {pos: [1, 7, 10], state: "minecraft:tuff_bricks"},
        {pos: [1, 7, 11], state: "minecraft:tuff_bricks"},
        {pos: [1, 7, 12], state: "minecraft:tuff_bricks"},
        {pos: [1, 7, 13], state: "minecraft:tuff_bricks"},
        {pos: [1, 7, 14], state: "minecraft:tuff_bricks"},
        {pos: [2, 7, 0], state: "minecraft:air"},
        {pos: [2, 7, 1], state: "minecraft:air"},
        {pos: [2, 7, 2], state: "minecraft:air"},
        {pos: [2, 7, 3], state: "minecraft:air"},
        {pos: [2, 7, 4], state: "minecraft:air"},
        {pos: [2, 7, 5], state: "minecraft:tuff_bricks"},
        {pos: [2, 7, 6], state: "minecraft:tuff_bricks"},
        {pos: [2, 7, 7], state: "minecraft:tuff_bricks"},
        {pos: [2, 7, 8], state: "minecraft:tuff_bricks"},
        {pos: [2, 7, 9], state: "minecraft:tuff_bricks"},
        {pos: [2, 7, 10], state: "minecraft:tuff_bricks"},
        {pos: [2, 7, 11], state: "minecraft:tuff_bricks"},
        {pos: [2, 7, 12], state: "minecraft:tuff_bricks"},
        {pos: [2, 7, 13], state: "minecraft:tuff_bricks"},
        {pos: [2, 7, 14], state: "minecraft:tuff_bricks"},
        {pos: [3, 7, 0], state: "minecraft:air"},
        {pos: [3, 7, 1], state: "minecraft:air"},
        {pos: [3, 7, 2], state: "minecraft:air"},
        {pos: [3, 7, 3], state: "minecraft:air"},
        {pos: [3, 7, 4], state: "minecraft:air"},
        {pos: [3, 7, 5], state: "minecraft:tuff_bricks"},
        {pos: [3, 7, 6], state: "minecraft:tuff_bricks"},
        {pos: [3, 7, 7], state: "minecraft:tuff_bricks"},
        {pos: [3, 7, 8], state: "minecraft:tuff_bricks"},
        {pos: [3, 7, 9], state: "minecraft:tuff_bricks"},
        {pos: [3, 7, 10], state: "minecraft:tuff_bricks"},
        {pos: [3, 7, 11], state: "minecraft:tuff_bricks"},
        {pos: [3, 7, 12], state: "minecraft:tuff_bricks"},
        {pos: [3, 7, 13], state: "minecraft:tuff_bricks"},
        {pos: [3, 7, 14], state: "minecraft:tuff_bricks"},
        {pos: [4, 7, 0], state: "minecraft:air"},
        {pos: [4, 7, 1], state: "minecraft:air"},
        {pos: [4, 7, 2], state: "minecraft:air"},
        {pos: [4, 7, 3], state: "minecraft:air"},
        {pos: [4, 7, 4], state: "minecraft:tuff_bricks"},
        {pos: [4, 7, 5], state: "minecraft:tuff_bricks"},
        {pos: [4, 7, 6], state: "minecraft:tuff_bricks"},
        {pos: [4, 7, 7], state: "minecraft:tuff_bricks"},
        {pos: [4, 7, 8], state: "minecraft:tuff_bricks"},
        {pos: [4, 7, 9], state: "minecraft:tuff_bricks"},
        {pos: [4, 7, 10], state: "minecraft:tuff_bricks"},
        {pos: [4, 7, 11], state: "minecraft:tuff_bricks"},
        {pos: [4, 7, 12], state: "minecraft:tuff_bricks"},
        {pos: [4, 7, 13], state: "minecraft:tuff_bricks"},
        {pos: [4, 7, 14], state: "minecraft:tuff_bricks"},
        {pos: [0, 8, 0], state: "minecraft:tuff_bricks"},
        {pos: [0, 8, 1], state: "minecraft:air"},
        {pos: [0, 8, 2], state: "minecraft:air"},
        {pos: [0, 8, 3], state: "minecraft:air"},
        {pos: [0, 8, 4], state: "minecraft:tuff_bricks"},
        {pos: [0, 8, 5], state: "minecraft:tuff_bricks"},
        {pos: [0, 8, 6], state: "minecraft:tuff_bricks"},
        {pos: [0, 8, 7], state: "minecraft:tuff_bricks"},
        {pos: [0, 8, 8], state: "minecraft:tuff_bricks"},
        {pos: [0, 8, 9], state: "minecraft:tuff_bricks"},
        {pos: [0, 8, 10], state: "minecraft:tuff_bricks"},
        {pos: [0, 8, 11], state: "minecraft:tuff_bricks"},
        {pos: [0, 8, 12], state: "minecraft:tuff_bricks"},
        {pos: [0, 8, 13], state: "minecraft:tuff_bricks"},
        {pos: [0, 8, 14], state: "minecraft:tuff_bricks"},
        {pos: [1, 8, 0], state: "minecraft:air"},
        {pos: [1, 8, 1], state: "minecraft:air"},
        {pos: [1, 8, 2], state: "minecraft:air"},
        {pos: [1, 8, 3], state: "minecraft:air"},
        {pos: [1, 8, 4], state: "minecraft:air"},
        {pos: [1, 8, 5], state: "minecraft:tuff_bricks"},
        {pos: [1, 8, 6], state: "minecraft:tuff_bricks"},
        {pos: [1, 8, 7], state: "minecraft:tuff_bricks"},
        {pos: [1, 8, 8], state: "minecraft:tuff_bricks"},
        {pos: [1, 8, 9], state: "minecraft:tuff_bricks"},
        {pos: [1, 8, 10], state: "minecraft:tuff_bricks"},
        {pos: [1, 8, 11], state: "minecraft:tuff_bricks"},
        {pos: [1, 8, 12], state: "minecraft:tuff_bricks"},
        {pos: [1, 8, 13], state: "minecraft:tuff_bricks"},
        {pos: [1, 8, 14], state: "minecraft:tuff_bricks"},
        {pos: [2, 8, 0], state: "minecraft:air"},
        {pos: [2, 8, 1], state: "minecraft:air"},
        {pos: [2, 8, 2], state: "minecraft:air"},
        {pos: [2, 8, 3], state: "minecraft:air"},
        {pos: [2, 8, 4], state: "minecraft:air"},
        {pos: [2, 8, 5], state: "minecraft:tuff_bricks"},
        {pos: [2, 8, 6], state: "minecraft:tuff_bricks"},
        {pos: [2, 8, 7], state: "minecraft:tuff_bricks"},
        {pos: [2, 8, 8], state: "minecraft:tuff_bricks"},
        {pos: [2, 8, 9], state: "minecraft:tuff_bricks"},
        {pos: [2, 8, 10], state: "minecraft:tuff_bricks"},
        {pos: [2, 8, 11], state: "minecraft:tuff_bricks"},
        {pos: [2, 8, 12], state: "minecraft:tuff_bricks"},
        {pos: [2, 8, 13], state: "minecraft:tuff_bricks"},
        {pos: [2, 8, 14], state: "minecraft:tuff_bricks"},
        {pos: [3, 8, 0], state: "minecraft:air"},
        {pos: [3, 8, 1], state: "minecraft:air"},
        {pos: [3, 8, 2], state: "minecraft:air"},
        {pos: [3, 8, 3], state: "minecraft:air"},
        {pos: [3, 8, 4], state: "minecraft:air"},
        {pos: [3, 8, 5], state: "minecraft:tuff_bricks"},
        {pos: [3, 8, 6], state: "minecraft:tuff_bricks"},
        {pos: [3, 8, 7], state: "minecraft:tuff_bricks"},
        {pos: [3, 8, 8], state: "minecraft:tuff_bricks"},
        {pos: [3, 8, 9], state: "minecraft:tuff_bricks"},
        {pos: [3, 8, 10], state: "minecraft:tuff_bricks"},
        {pos: [3, 8, 11], state: "minecraft:tuff_bricks"},
        {pos: [3, 8, 12], state: "minecraft:tuff_bricks"},
        {pos: [3, 8, 13], state: "minecraft:tuff_bricks"},
        {pos: [3, 8, 14], state: "minecraft:tuff_bricks"},
        {pos: [4, 8, 0], state: "minecraft:air"},
        {pos: [4, 8, 1], state: "minecraft:air"},
        {pos: [4, 8, 2], state: "minecraft:air"},
        {pos: [4, 8, 3], state: "minecraft:air"},
        {pos: [4, 8, 4], state: "minecraft:tuff_bricks"},
        {pos: [4, 8, 5], state: "minecraft:tuff_bricks"},
        {pos: [4, 8, 6], state: "minecraft:tuff_bricks"},
        {pos: [4, 8, 7], state: "minecraft:tuff_bricks"},
        {pos: [4, 8, 8], state: "minecraft:tuff_bricks"},
        {pos: [4, 8, 9], state: "minecraft:tuff_bricks"},
        {pos: [4, 8, 10], state: "minecraft:tuff_bricks"},
        {pos: [4, 8, 11], state: "minecraft:tuff_bricks"},
        {pos: [4, 8, 12], state: "minecraft:tuff_bricks"},
        {pos: [4, 8, 13], state: "minecraft:tuff_bricks"},
        {pos: [4, 8, 14], state: "minecraft:tuff_bricks"},
        {pos: [0, 9, 0], state: "minecraft:chiseled_tuff_bricks"},
        {pos: [0, 9, 1], state: "minecraft:polished_tuff"},
        {pos: [0, 9, 2], state: "minecraft:polished_tuff"},
        {pos: [0, 9, 3], state: "minecraft:polished_tuff"},
        {pos: [0, 9, 4], state: "minecraft:chiseled_tuff_bricks"},
        {pos: [0, 9, 5], state: "minecraft:chiseled_tuff_bricks"},
        {pos: [0, 9, 6], state: "minecraft:tuff_bricks"},
        {pos: [0, 9, 7], state: "minecraft:tuff_bricks"},
        {pos: [0, 9, 8], state: "minecraft:tuff_bricks"},
        {pos: [0, 9, 9], state: "minecraft:tuff_bricks"},
        {pos: [0, 9, 10], state: "minecraft:tuff_bricks"},
        {pos: [0, 9, 11], state: "minecraft:tuff_bricks"},
        {pos: [0, 9, 12], state: "minecraft:tuff_bricks"},
        {pos: [0, 9, 13], state: "minecraft:tuff_bricks"},
        {pos: [0, 9, 14], state: "minecraft:tuff_bricks"},
        {pos: [1, 9, 0], state: "minecraft:air"},
        {pos: [1, 9, 1], state: "minecraft:air"},
        {pos: [1, 9, 2], state: "minecraft:air"},
        {pos: [1, 9, 3], state: "minecraft:air"},
        {pos: [1, 9, 4], state: "minecraft:air"},
        {pos: [1, 9, 5], state: "minecraft:chiseled_tuff_bricks"},
        {pos: [1, 9, 6], state: "minecraft:tuff_bricks"},
        {pos: [1, 9, 7], state: "minecraft:tuff_bricks"},
        {pos: [1, 9, 8], state: "minecraft:tuff_bricks"},
        {pos: [1, 9, 9], state: "minecraft:tuff_bricks"},
        {pos: [1, 9, 10], state: "minecraft:tuff_bricks"},
        {pos: [1, 9, 11], state: "minecraft:tuff_bricks"},
        {pos: [1, 9, 12], state: "minecraft:tuff_bricks"},
        {pos: [1, 9, 13], state: "minecraft:tuff_bricks"},
        {pos: [1, 9, 14], state: "minecraft:tuff_bricks"},
        {pos: [2, 9, 0], state: "minecraft:air"},
        {pos: [2, 9, 1], state: "minecraft:air"},
        {pos: [2, 9, 2], state: "minecraft:air"},
        {pos: [2, 9, 3], state: "minecraft:air"},
        {pos: [2, 9, 4], state: "minecraft:air"},
        {pos: [2, 9, 5], state: "minecraft:chiseled_tuff_bricks"},
        {pos: [2, 9, 6], state: "minecraft:tuff_bricks"},
        {pos: [2, 9, 7], state: "minecraft:tuff_bricks"},
        {pos: [2, 9, 8], state: "minecraft:tuff_bricks"},
        {pos: [2, 9, 9], state: "minecraft:tuff_bricks"},
        {pos: [2, 9, 10], state: "minecraft:tuff_bricks"},
        {pos: [2, 9, 11], state: "minecraft:tuff_bricks"},
        {pos: [2, 9, 12], state: "minecraft:tuff_bricks"},
        {pos: [2, 9, 13], state: "minecraft:tuff_bricks"},
        {pos: [2, 9, 14], state: "minecraft:tuff_bricks"},
        {pos: [3, 9, 0], state: "minecraft:air"},
        {pos: [3, 9, 1], state: "minecraft:air"},
        {pos: [3, 9, 2], state: "minecraft:air"},
        {pos: [3, 9, 3], state: "minecraft:air"},
        {pos: [3, 9, 4], state: "minecraft:air"},
        {pos: [3, 9, 5], state: "minecraft:chiseled_tuff_bricks"},
        {pos: [3, 9, 6], state: "minecraft:tuff_bricks"},
        {pos: [3, 9, 7], state: "minecraft:tuff_bricks"},
        {pos: [3, 9, 8], state: "minecraft:tuff_bricks"},
        {pos: [3, 9, 9], state: "minecraft:tuff_bricks"},
        {pos: [3, 9, 10], state: "minecraft:tuff_bricks"},
        {pos: [3, 9, 11], state: "minecraft:tuff_bricks"},
        {pos: [3, 9, 12], state: "minecraft:tuff_bricks"},
        {pos: [3, 9, 13], state: "minecraft:tuff_bricks"},
        {pos: [3, 9, 14], state: "minecraft:tuff_bricks"},
        {pos: [4, 9, 0], state: "minecraft:air"},
        {pos: [4, 9, 1], state: "minecraft:air"},
        {pos: [4, 9, 2], state: "minecraft:air"},
        {pos: [4, 9, 3], state: "minecraft:air"},
        {pos: [4, 9, 4], state: "minecraft:chiseled_tuff_bricks"},
        {pos: [4, 9, 5], state: "minecraft:chiseled_tuff_bricks"},
        {pos: [4, 9, 6], state: "minecraft:chiseled_tuff_bricks"},
        {pos: [4, 9, 7], state: "minecraft:chiseled_tuff_bricks"},
        {pos: [4, 9, 8], state: "minecraft:chiseled_tuff_bricks"},
        {pos: [4, 9, 9], state: "minecraft:chiseled_tuff_bricks"},
        {pos: [4, 9, 10], state: "minecraft:chiseled_tuff_bricks"},
        {pos: [4, 9, 11], state: "minecraft:chiseled_tuff_bricks"},
        {pos: [4, 9, 12], state: "minecraft:chiseled_tuff_bricks"},
        {pos: [4, 9, 13], state: "minecraft:chiseled_tuff_bricks"},
        {pos: [4, 9, 14], state: "minecraft:chiseled_tuff_bricks"},
        {pos: [0, 10, 0], state: "minecraft:tuff_bricks"},
        {pos: [0, 10, 1], state: "minecraft:waxed_oxidized_copper"},
        {pos: [0, 10, 2], state: "minecraft:waxed_oxidized_copper"},
        {pos: [0, 10, 3], state: "minecraft:waxed_oxidized_copper"},
        {pos: [0, 10, 4], state: "minecraft:tuff_bricks"},
        {pos: [0, 10, 5], state: "minecraft:tuff_bricks"},
        {pos: [0, 10, 6], state: "minecraft:tuff_bricks"},
        {pos: [0, 10, 7], state: "minecraft:tuff_bricks"},
        {pos: [0, 10, 8], state: "minecraft:tuff_bricks"},
        {pos: [0, 10, 9], state: "minecraft:tuff_bricks"},
        {pos: [0, 10, 10], state: "minecraft:tuff_bricks"},
        {pos: [0, 10, 11], state: "minecraft:tuff_bricks"},
        {pos: [0, 10, 12], state: "minecraft:tuff_bricks"},
        {pos: [0, 10, 13], state: "minecraft:tuff_bricks"},
        {pos: [0, 10, 14], state: "minecraft:tuff_bricks"},
        {pos: [1, 10, 0], state: "minecraft:air"},
        {pos: [1, 10, 1], state: "minecraft:air"},
        {pos: [1, 10, 2], state: "minecraft:air"},
        {pos: [1, 10, 3], state: "minecraft:air"},
        {pos: [1, 10, 4], state: "minecraft:air"},
        {pos: [1, 10, 5], state: "minecraft:tuff_bricks"},
        {pos: [1, 10, 6], state: "minecraft:tuff_bricks"},
        {pos: [1, 10, 7], state: "minecraft:tuff_bricks"},
        {pos: [1, 10, 8], state: "minecraft:tuff_bricks"},
        {pos: [1, 10, 9], state: "minecraft:tuff_bricks"},
        {pos: [1, 10, 10], state: "minecraft:tuff_bricks"},
        {pos: [1, 10, 11], state: "minecraft:tuff_bricks"},
        {pos: [1, 10, 12], state: "minecraft:tuff_bricks"},
        {pos: [1, 10, 13], state: "minecraft:tuff_bricks"},
        {pos: [1, 10, 14], state: "minecraft:tuff_bricks"},
        {pos: [2, 10, 0], state: "minecraft:air"},
        {pos: [2, 10, 1], state: "minecraft:air"},
        {pos: [2, 10, 2], state: "minecraft:air"},
        {pos: [2, 10, 3], state: "minecraft:air"},
        {pos: [2, 10, 4], state: "minecraft:air"},
        {pos: [2, 10, 5], state: "minecraft:tuff_bricks"},
        {pos: [2, 10, 6], state: "minecraft:tuff_bricks"},
        {pos: [2, 10, 7], state: "minecraft:tuff_bricks"},
        {pos: [2, 10, 8], state: "minecraft:tuff_bricks"},
        {pos: [2, 10, 9], state: "minecraft:tuff_bricks"},
        {pos: [2, 10, 10], state: "minecraft:tuff_bricks"},
        {pos: [2, 10, 11], state: "minecraft:tuff_bricks"},
        {pos: [2, 10, 12], state: "minecraft:tuff_bricks"},
        {pos: [2, 10, 13], state: "minecraft:tuff_bricks"},
        {pos: [2, 10, 14], state: "minecraft:tuff_bricks"},
        {pos: [3, 10, 0], state: "minecraft:air"},
        {pos: [3, 10, 1], state: "minecraft:air"},
        {pos: [3, 10, 2], state: "minecraft:air"},
        {pos: [3, 10, 3], state: "minecraft:air"},
        {pos: [3, 10, 4], state: "minecraft:air"},
        {pos: [3, 10, 5], state: "minecraft:tuff_bricks"},
        {pos: [3, 10, 6], state: "minecraft:tuff_bricks"},
        {pos: [3, 10, 7], state: "minecraft:tuff_bricks"},
        {pos: [3, 10, 8], state: "minecraft:tuff_bricks"},
        {pos: [3, 10, 9], state: "minecraft:tuff_bricks"},
        {pos: [3, 10, 10], state: "minecraft:tuff_bricks"},
        {pos: [3, 10, 11], state: "minecraft:tuff_bricks"},
        {pos: [3, 10, 12], state: "minecraft:tuff_bricks"},
        {pos: [3, 10, 13], state: "minecraft:tuff_bricks"},
        {pos: [3, 10, 14], state: "minecraft:tuff_bricks"},
        {pos: [4, 10, 0], state: "minecraft:air"},
        {pos: [4, 10, 1], state: "minecraft:air"},
        {pos: [4, 10, 2], state: "minecraft:air"},
        {pos: [4, 10, 3], state: "minecraft:air"},
        {pos: [4, 10, 4], state: "minecraft:tuff_bricks"},
        {pos: [4, 10, 5], state: "minecraft:tuff_bricks"},
        {pos: [4, 10, 6], state: "minecraft:tuff_bricks"},
        {pos: [4, 10, 7], state: "minecraft:tuff_bricks"},
        {pos: [4, 10, 8], state: "minecraft:tuff_bricks"},
        {pos: [4, 10, 9], state: "minecraft:tuff_bricks"},
        {pos: [4, 10, 10], state: "minecraft:tuff_bricks"},
        {pos: [4, 10, 11], state: "minecraft:tuff_bricks"},
        {pos: [4, 10, 12], state: "minecraft:tuff_bricks"},
        {pos: [4, 10, 13], state: "minecraft:tuff_bricks"},
        {pos: [4, 10, 14], state: "minecraft:tuff_bricks"},
        {pos: [0, 11, 0], state: "minecraft:waxed_copper_block"},
        {pos: [0, 11, 1], state: "minecraft:air"},
        {pos: [0, 11, 2], state: "minecraft:air"},
        {pos: [0, 11, 3], state: "minecraft:air"},
        {pos: [0, 11, 4], state: "minecraft:waxed_copper_block"},
        {pos: [0, 11, 5], state: "minecraft:waxed_copper_block"},
        {pos: [0, 11, 6], state: "minecraft:tuff_bricks"},
        {pos: [0, 11, 7], state: "minecraft:tuff_bricks"},
        {pos: [0, 11, 8], state: "minecraft:tuff_bricks"},
        {pos: [0, 11, 9], state: "minecraft:tuff_bricks"},
        {pos: [0, 11, 10], state: "minecraft:tuff_bricks"},
        {pos: [0, 11, 11], state: "minecraft:tuff_bricks"},
        {pos: [0, 11, 12], state: "minecraft:tuff_bricks"},
        {pos: [0, 11, 13], state: "minecraft:tuff_bricks"},
        {pos: [0, 11, 14], state: "minecraft:tuff_bricks"},
        {pos: [1, 11, 0], state: "minecraft:air"},
        {pos: [1, 11, 1], state: "minecraft:air"},
        {pos: [1, 11, 2], state: "minecraft:air"},
        {pos: [1, 11, 3], state: "minecraft:air"},
        {pos: [1, 11, 4], state: "minecraft:air"},
        {pos: [1, 11, 5], state: "minecraft:waxed_copper_block"},
        {pos: [1, 11, 6], state: "minecraft:tuff_bricks"},
        {pos: [1, 11, 7], state: "minecraft:tuff_bricks"},
        {pos: [1, 11, 8], state: "minecraft:tuff_bricks"},
        {pos: [1, 11, 9], state: "minecraft:tuff_bricks"},
        {pos: [1, 11, 10], state: "minecraft:tuff_bricks"},
        {pos: [1, 11, 11], state: "minecraft:tuff_bricks"},
        {pos: [1, 11, 12], state: "minecraft:tuff_bricks"},
        {pos: [1, 11, 13], state: "minecraft:tuff_bricks"},
        {pos: [1, 11, 14], state: "minecraft:tuff_bricks"},
        {pos: [2, 11, 0], state: "minecraft:air"},
        {pos: [2, 11, 1], state: "minecraft:air"},
        {pos: [2, 11, 2], state: "minecraft:air"},
        {pos: [2, 11, 3], state: "minecraft:air"},
        {pos: [2, 11, 4], state: "minecraft:air"},
        {pos: [2, 11, 5], state: "minecraft:waxed_copper_block"},
        {pos: [2, 11, 6], state: "minecraft:tuff_bricks"},
        {pos: [2, 11, 7], state: "minecraft:tuff_bricks"},
        {pos: [2, 11, 8], state: "minecraft:tuff_bricks"},
        {pos: [2, 11, 9], state: "minecraft:tuff_bricks"},
        {pos: [2, 11, 10], state: "minecraft:tuff_bricks"},
        {pos: [2, 11, 11], state: "minecraft:tuff_bricks"},
        {pos: [2, 11, 12], state: "minecraft:tuff_bricks"},
        {pos: [2, 11, 13], state: "minecraft:tuff_bricks"},
        {pos: [2, 11, 14], state: "minecraft:tuff_bricks"},
        {pos: [3, 11, 0], state: "minecraft:air"},
        {pos: [3, 11, 1], state: "minecraft:air"},
        {pos: [3, 11, 2], state: "minecraft:air"},
        {pos: [3, 11, 3], state: "minecraft:air"},
        {pos: [3, 11, 4], state: "minecraft:air"},
        {pos: [3, 11, 5], state: "minecraft:waxed_copper_block"},
        {pos: [3, 11, 6], state: "minecraft:tuff_bricks"},
        {pos: [3, 11, 7], state: "minecraft:tuff_bricks"},
        {pos: [3, 11, 8], state: "minecraft:tuff_bricks"},
        {pos: [3, 11, 9], state: "minecraft:tuff_bricks"},
        {pos: [3, 11, 10], state: "minecraft:tuff_bricks"},
        {pos: [3, 11, 11], state: "minecraft:tuff_bricks"},
        {pos: [3, 11, 12], state: "minecraft:tuff_bricks"},
        {pos: [3, 11, 13], state: "minecraft:tuff_bricks"},
        {pos: [3, 11, 14], state: "minecraft:tuff_bricks"},
        {pos: [4, 11, 0], state: "minecraft:air"},
        {pos: [4, 11, 1], state: "minecraft:air"},
        {pos: [4, 11, 2], state: "minecraft:air"},
        {pos: [4, 11, 3], state: "minecraft:air"},
        {pos: [4, 11, 4], state: "minecraft:waxed_copper_block"},
        {pos: [4, 11, 5], state: "minecraft:waxed_copper_block"},
        {pos: [4, 11, 6], state: "minecraft:waxed_copper_block"},
        {pos: [4, 11, 7], state: "minecraft:waxed_copper_block"},
        {pos: [4, 11, 8], state: "minecraft:waxed_copper_block"},
        {pos: [4, 11, 9], state: "minecraft:waxed_copper_block"},
        {pos: [4, 11, 10], state: "minecraft:waxed_copper_block"},
        {pos: [4, 11, 11], state: "minecraft:waxed_copper_block"},
        {pos: [4, 11, 12], state: "minecraft:waxed_copper_block"},
        {pos: [4, 11, 13], state: "minecraft:waxed_copper_block"},
        {pos: [4, 11, 14], state: "minecraft:waxed_copper_block"},
        {pos: [0, 12, 0], state: "minecraft:tuff_bricks"},
        {pos: [0, 12, 1], state: "minecraft:air"},
        {pos: [0, 12, 2], state: "minecraft:jigsaw{orientation:west_up}", nbt: {final_state: "minecraft:air", id: "minecraft:jigsaw", joint: "rollable", name: "minecraft:upper_start", placement_priority: 0, pool: "minecraft:empty", selection_priority: 0, target: "minecraft:empty"}},
        {pos: [0, 12, 3], state: "minecraft:air"},
        {pos: [0, 12, 4], state: "minecraft:tuff_bricks"},
        {pos: [0, 12, 5], state: "minecraft:tuff_bricks"},
        {pos: [0, 12, 6], state: "minecraft:tuff_bricks"},
        {pos: [0, 12, 7], state: "minecraft:tuff_bricks"},
        {pos: [0, 12, 8], state: "minecraft:tuff_bricks"},
        {pos: [0, 12, 9], state: "minecraft:tuff_bricks"},
        {pos: [0, 12, 10], state: "minecraft:tuff_bricks"},
        {pos: [0, 12, 11], state: "minecraft:tuff_bricks"},
        {pos: [0, 12, 12], state: "minecraft:tuff_bricks"},
        {pos: [0, 12, 13], state: "minecraft:tuff_bricks"},
        {pos: [0, 12, 14], state: "minecraft:tuff_bricks"},
        {pos: [1, 12, 0], state: "minecraft:air"},
        {pos: [1, 12, 1], state: "minecraft:air"},
        {pos: [1, 12, 2], state: "minecraft:air"},
        {pos: [1, 12, 3], state: "minecraft:air"},
        {pos: [1, 12, 4], state: "minecraft:air"},
        {pos: [1, 12, 5], state: "minecraft:tuff_bricks"},
        {pos: [1, 12, 6], state: "minecraft:tuff_bricks"},
        {pos: [1, 12, 7], state: "minecraft:tuff_bricks"},
        {pos: [1, 12, 8], state: "minecraft:tuff_bricks"},
        {pos: [1, 12, 9], state: "minecraft:tuff_bricks"},
        {pos: [1, 12, 10], state: "minecraft:tuff_bricks"},
        {pos: [1, 12, 11], state: "minecraft:tuff_bricks"},
        {pos: [1, 12, 12], state: "minecraft:tuff_bricks"},
        {pos: [1, 12, 13], state: "minecraft:tuff_bricks"},
        {pos: [1, 12, 14], state: "minecraft:tuff_bricks"},
        {pos: [2, 12, 0], state: "minecraft:jigsaw{orientation:north_up}", nbt: {final_state: "minecraft:air", id: "minecraft:jigsaw", joint: "rollable", name: "minecraft:empty", placement_priority: 0, pool: "minecraft:trial_chambers/chamber/addon", selection_priority: 0, target: "minecraft:upper_addon_extension"}},
        {pos: [2, 12, 1], state: "minecraft:air"},
        {pos: [2, 12, 2], state: "minecraft:air"},
        {pos: [2, 12, 3], state: "minecraft:air"},
        {pos: [2, 12, 4], state: "minecraft:air"},
        {pos: [2, 12, 5], state: "minecraft:waxed_copper_bulb{lit:true,powered:false}"},
        {pos: [2, 12, 6], state: "minecraft:tuff_bricks"},
        {pos: [2, 12, 7], state: "minecraft:tuff_bricks"},
        {pos: [2, 12, 8], state: "minecraft:tuff_bricks"},
        {pos: [2, 12, 9], state: "minecraft:tuff_bricks"},
        {pos: [2, 12, 10], state: "minecraft:tuff_bricks"},
        {pos: [2, 12, 11], state: "minecraft:tuff_bricks"},
        {pos: [2, 12, 12], state: "minecraft:tuff_bricks"},
        {pos: [2, 12, 13], state: "minecraft:tuff_bricks"},
        {pos: [2, 12, 14], state: "minecraft:tuff_bricks"},
        {pos: [3, 12, 0], state: "minecraft:air"},
        {pos: [3, 12, 1], state: "minecraft:air"},
        {pos: [3, 12, 2], state: "minecraft:air"},
        {pos: [3, 12, 3], state: "minecraft:air"},
        {pos: [3, 12, 4], state: "minecraft:air"},
        {pos: [3, 12, 5], state: "minecraft:tuff_bricks"},
        {pos: [3, 12, 6], state: "minecraft:tuff_bricks"},
        {pos: [3, 12, 7], state: "minecraft:tuff_bricks"},
        {pos: [3, 12, 8], state: "minecraft:tuff_bricks"},
        {pos: [3, 12, 9], state: "minecraft:tuff_bricks"},
        {pos: [3, 12, 10], state: "minecraft:tuff_bricks"},
        {pos: [3, 12, 11], state: "minecraft:tuff_bricks"},
        {pos: [3, 12, 12], state: "minecraft:tuff_bricks"},
        {pos: [3, 12, 13], state: "minecraft:tuff_bricks"},
        {pos: [3, 12, 14], state: "minecraft:tuff_bricks"},
        {pos: [4, 12, 0], state: "minecraft:air"},
        {pos: [4, 12, 1], state: "minecraft:air"},
        {pos: [4, 12, 2], state: "minecraft:jigsaw{orientation:east_up}", nbt: {final_state: "minecraft:air", id: "minecraft:jigsaw", joint: "rollable", name: "minecraft:empty", placement_priority: 0, pool: "minecraft:trial_chambers/chamber/addon", selection_priority: 0, target: "minecraft:upper_addon_extension"}},
        {pos: [4, 12, 3], state: "minecraft:air"},
        {pos: [4, 12, 4], state: "minecraft:tuff_bricks"},
        {pos: [4, 12, 5], state: "minecraft:tuff_bricks"},
        {pos: [4, 12, 6], state: "minecraft:tuff_bricks"},
        {pos: [4, 12, 7], state: "minecraft:waxed_copper_bulb{lit:true,powered:false}"},
        {pos: [4, 12, 8], state: "minecraft:tuff_bricks"},
        {pos: [4, 12, 9], state: "minecraft:tuff_bricks"},
        {pos: [4, 12, 10], state: "minecraft:tuff_bricks"},
        {pos: [4, 12, 11], state: "minecraft:tuff_bricks"},
        {pos: [4, 12, 12], state: "minecraft:waxed_copper_bulb{lit:true,powered:false}"},
        {pos: [4, 12, 13], state: "minecraft:tuff_bricks"},
        {pos: [4, 12, 14], state: "minecraft:tuff_bricks"},
        {pos: [0, 13, 0], state: "minecraft:chiseled_tuff_bricks"},
        {pos: [0, 13, 1], state: "minecraft:air"},
        {pos: [0, 13, 2], state: "minecraft:air"},
        {pos: [0, 13, 3], state: "minecraft:air"},
        {pos: [0, 13, 4], state: "minecraft:chiseled_tuff_bricks"},
        {pos: [0, 13, 5], state: "minecraft:chiseled_tuff_bricks"},
        {pos: [0, 13, 6], state: "minecraft:tuff_bricks"},
        {pos: [0, 13, 7], state: "minecraft:tuff_bricks"},
        {pos: [0, 13, 8], state: "minecraft:tuff_bricks"},
        {pos: [0, 13, 9], state: "minecraft:tuff_bricks"},
        {pos: [0, 13, 10], state: "minecraft:tuff_bricks"},
        {pos: [0, 13, 11], state: "minecraft:tuff_bricks"},
        {pos: [0, 13, 12], state: "minecraft:tuff_bricks"},
        {pos: [0, 13, 13], state: "minecraft:tuff_bricks"},
        {pos: [0, 13, 14], state: "minecraft:tuff_bricks"},
        {pos: [1, 13, 0], state: "minecraft:air"},
        {pos: [1, 13, 1], state: "minecraft:air"},
        {pos: [1, 13, 2], state: "minecraft:air"},
        {pos: [1, 13, 3], state: "minecraft:air"},
        {pos: [1, 13, 4], state: "minecraft:air"},
        {pos: [1, 13, 5], state: "minecraft:chiseled_tuff_bricks"},
        {pos: [1, 13, 6], state: "minecraft:tuff_bricks"},
        {pos: [1, 13, 7], state: "minecraft:tuff_bricks"},
        {pos: [1, 13, 8], state: "minecraft:tuff_bricks"},
        {pos: [1, 13, 9], state: "minecraft:tuff_bricks"},
        {pos: [1, 13, 10], state: "minecraft:tuff_bricks"},
        {pos: [1, 13, 11], state: "minecraft:tuff_bricks"},
        {pos: [1, 13, 12], state: "minecraft:tuff_bricks"},
        {pos: [1, 13, 13], state: "minecraft:tuff_bricks"},
        {pos: [1, 13, 14], state: "minecraft:tuff_bricks"},
        {pos: [2, 13, 0], state: "minecraft:air"},
        {pos: [2, 13, 1], state: "minecraft:air"},
        {pos: [2, 13, 2], state: "minecraft:air"},
        {pos: [2, 13, 3], state: "minecraft:air"},
        {pos: [2, 13, 4], state: "minecraft:air"},
        {pos: [2, 13, 5], state: "minecraft:chiseled_tuff_bricks"},
        {pos: [2, 13, 6], state: "minecraft:tuff_bricks"},
        {pos: [2, 13, 7], state: "minecraft:tuff_bricks"},
        {pos: [2, 13, 8], state: "minecraft:tuff_bricks"},
        {pos: [2, 13, 9], state: "minecraft:tuff_bricks"},
        {pos: [2, 13, 10], state: "minecraft:tuff_bricks"},
        {pos: [2, 13, 11], state: "minecraft:tuff_bricks"},
        {pos: [2, 13, 12], state: "minecraft:tuff_bricks"},
        {pos: [2, 13, 13], state: "minecraft:tuff_bricks"},
        {pos: [2, 13, 14], state: "minecraft:tuff_bricks"},
        {pos: [3, 13, 0], state: "minecraft:air"},
        {pos: [3, 13, 1], state: "minecraft:air"},
        {pos: [3, 13, 2], state: "minecraft:air"},
        {pos: [3, 13, 3], state: "minecraft:air"},
        {pos: [3, 13, 4], state: "minecraft:air"},
        {pos: [3, 13, 5], state: "minecraft:chiseled_tuff_bricks"},
        {pos: [3, 13, 6], state: "minecraft:tuff_bricks"},
        {pos: [3, 13, 7], state: "minecraft:tuff_bricks"},
        {pos: [3, 13, 8], state: "minecraft:tuff_bricks"},
        {pos: [3, 13, 9], state: "minecraft:tuff_bricks"},
        {pos: [3, 13, 10], state: "minecraft:tuff_bricks"},
        {pos: [3, 13, 11], state: "minecraft:tuff_bricks"},
        {pos: [3, 13, 12], state: "minecraft:tuff_bricks"},
        {pos: [3, 13, 13], state: "minecraft:tuff_bricks"},
        {pos: [3, 13, 14], state: "minecraft:tuff_bricks"},
        {pos: [4, 13, 0], state: "minecraft:air"},
        {pos: [4, 13, 1], state: "minecraft:air"},
        {pos: [4, 13, 2], state: "minecraft:air"},
        {pos: [4, 13, 3], state: "minecraft:air"},
        {pos: [4, 13, 4], state: "minecraft:chiseled_tuff_bricks"},
        {pos: [4, 13, 5], state: "minecraft:chiseled_tuff_bricks"},
        {pos: [4, 13, 6], state: "minecraft:chiseled_tuff_bricks"},
        {pos: [4, 13, 7], state: "minecraft:chiseled_tuff_bricks"},
        {pos: [4, 13, 8], state: "minecraft:chiseled_tuff_bricks"},
        {pos: [4, 13, 9], state: "minecraft:chiseled_tuff_bricks"},
        {pos: [4, 13, 10], state: "minecraft:chiseled_tuff_bricks"},
        {pos: [4, 13, 11], state: "minecraft:chiseled_tuff_bricks"},
        {pos: [4, 13, 12], state: "minecraft:chiseled_tuff_bricks"},
        {pos: [4, 13, 13], state: "minecraft:chiseled_tuff_bricks"},
        {pos: [4, 13, 14], state: "minecraft:chiseled_tuff_bricks"},
        {pos: [0, 14, 0], state: "minecraft:tuff_bricks"},
        {pos: [0, 14, 1], state: "minecraft:air"},
        {pos: [0, 14, 2], state: "minecraft:air"},
        {pos: [0, 14, 3], state: "minecraft:air"},
        {pos: [0, 14, 4], state: "minecraft:tuff_bricks"},
        {pos: [0, 14, 5], state: "minecraft:tuff_bricks"},
        {pos: [0, 14, 6], state: "minecraft:tuff_bricks"},
        {pos: [0, 14, 7], state: "minecraft:tuff_bricks"},
        {pos: [0, 14, 8], state: "minecraft:tuff_bricks"},
        {pos: [0, 14, 9], state: "minecraft:tuff_bricks"},
        {pos: [0, 14, 10], state: "minecraft:tuff_bricks"},
        {pos: [0, 14, 11], state: "minecraft:tuff_bricks"},
        {pos: [0, 14, 12], state: "minecraft:tuff_bricks"},
        {pos: [0, 14, 13], state: "minecraft:tuff_bricks"},
        {pos: [0, 14, 14], state: "minecraft:tuff_bricks"},
        {pos: [1, 14, 0], state: "minecraft:air"},
        {pos: [1, 14, 1], state: "minecraft:air"},
        {pos: [1, 14, 2], state: "minecraft:air"},
        {pos: [1, 14, 3], state: "minecraft:air"},
        {pos: [1, 14, 4], state: "minecraft:air"},
        {pos: [1, 14, 5], state: "minecraft:tuff_bricks"},
        {pos: [1, 14, 6], state: "minecraft:tuff_bricks"},
        {pos: [1, 14, 7], state: "minecraft:tuff_bricks"},
        {pos: [1, 14, 8], state: "minecraft:tuff_bricks"},
        {pos: [1, 14, 9], state: "minecraft:tuff_bricks"},
        {pos: [1, 14, 10], state: "minecraft:tuff_bricks"},
        {pos: [1, 14, 11], state: "minecraft:tuff_bricks"},
        {pos: [1, 14, 12], state: "minecraft:tuff_bricks"},
        {pos: [1, 14, 13], state: "minecraft:tuff_bricks"},
        {pos: [1, 14, 14], state: "minecraft:tuff_bricks"},
        {pos: [2, 14, 0], state: "minecraft:air"},
        {pos: [2, 14, 1], state: "minecraft:air"},
        {pos: [2, 14, 2], state: "minecraft:air"},
        {pos: [2, 14, 3], state: "minecraft:air"},
        {pos: [2, 14, 4], state: "minecraft:air"},
        {pos: [2, 14, 5], state: "minecraft:tuff_bricks"},
        {pos: [2, 14, 6], state: "minecraft:tuff_bricks"},
        {pos: [2, 14, 7], state: "minecraft:tuff_bricks"},
        {pos: [2, 14, 8], state: "minecraft:tuff_bricks"},
        {pos: [2, 14, 9], state: "minecraft:tuff_bricks"},
        {pos: [2, 14, 10], state: "minecraft:tuff_bricks"},
        {pos: [2, 14, 11], state: "minecraft:tuff_bricks"},
        {pos: [2, 14, 12], state: "minecraft:tuff_bricks"},
        {pos: [2, 14, 13], state: "minecraft:tuff_bricks"},
        {pos: [2, 14, 14], state: "minecraft:tuff_bricks"},
        {pos: [3, 14, 0], state: "minecraft:air"},
        {pos: [3, 14, 1], state: "minecraft:air"},
        {pos: [3, 14, 2], state: "minecraft:air"},
        {pos: [3, 14, 3], state: "minecraft:air"},
        {pos: [3, 14, 4], state: "minecraft:air"},
        {pos: [3, 14, 5], state: "minecraft:tuff_bricks"},
        {pos: [3, 14, 6], state: "minecraft:tuff_bricks"},
        {pos: [3, 14, 7], state: "minecraft:tuff_bricks"},
        {pos: [3, 14, 8], state: "minecraft:tuff_bricks"},
        {pos: [3, 14, 9], state: "minecraft:tuff_bricks"},
        {pos: [3, 14, 10], state: "minecraft:tuff_bricks"},
        {pos: [3, 14, 11], state: "minecraft:tuff_bricks"},
        {pos: [3, 14, 12], state: "minecraft:tuff_bricks"},
        {pos: [3, 14, 13], state: "minecraft:tuff_bricks"},
        {pos: [3, 14, 14], state: "minecraft:tuff_bricks"},
        {pos: [4, 14, 0], state: "minecraft:air"},
        {pos: [4, 14, 1], state: "minecraft:air"},
        {pos: [4, 14, 2], state: "minecraft:air"},
        {pos: [4, 14, 3], state: "minecraft:air"},
        {pos: [4, 14, 4], state: "minecraft:tuff_bricks"},
        {pos: [4, 14, 5], state: "minecraft:tuff_bricks"},
        {pos: [4, 14, 6], state: "minecraft:tuff_bricks"},
        {pos: [4, 14, 7], state: "minecraft:tuff_bricks"},
        {pos: [4, 14, 8], state: "minecraft:tuff_bricks"},
        {pos: [4, 14, 9], state: "minecraft:tuff_bricks"},
        {pos: [4, 14, 10], state: "minecraft:tuff_bricks"},
        {pos: [4, 14, 11], state: "minecraft:tuff_bricks"},
        {pos: [4, 14, 12], state: "minecraft:tuff_bricks"},
        {pos: [4, 14, 13], state: "minecraft:tuff_bricks"},
        {pos: [4, 14, 14], state: "minecraft:tuff_bricks"},
        {pos: [0, 15, 0], state: "minecraft:waxed_copper_block"},
        {pos: [0, 15, 1], state: "minecraft:air"},
        {pos: [0, 15, 2], state: "minecraft:air"},
        {pos: [0, 15, 3], state: "minecraft:air"},
        {pos: [0, 15, 4], state: "minecraft:waxed_copper_block"},
        {pos: [0, 15, 5], state: "minecraft:waxed_copper_block"},
        {pos: [0, 15, 6], state: "minecraft:tuff_bricks"},
        {pos: [0, 15, 7], state: "minecraft:tuff_bricks"},
        {pos: [0, 15, 8], state: "minecraft:tuff_bricks"},
        {pos: [0, 15, 9], state: "minecraft:tuff_bricks"},
        {pos: [0, 15, 10], state: "minecraft:tuff_bricks"},
        {pos: [0, 15, 11], state: "minecraft:tuff_bricks"},
        {pos: [0, 15, 12], state: "minecraft:tuff_bricks"},
        {pos: [0, 15, 13], state: "minecraft:tuff_bricks"},
        {pos: [0, 15, 14], state: "minecraft:tuff_bricks"},
        {pos: [1, 15, 0], state: "minecraft:air"},
        {pos: [1, 15, 1], state: "minecraft:air"},
        {pos: [1, 15, 2], state: "minecraft:air"},
        {pos: [1, 15, 3], state: "minecraft:air"},
        {pos: [1, 15, 4], state: "minecraft:air"},
        {pos: [1, 15, 5], state: "minecraft:waxed_copper_block"},
        {pos: [1, 15, 6], state: "minecraft:tuff_bricks"},
        {pos: [1, 15, 7], state: "minecraft:tuff_bricks"},
        {pos: [1, 15, 8], state: "minecraft:tuff_bricks"},
        {pos: [1, 15, 9], state: "minecraft:tuff_bricks"},
        {pos: [1, 15, 10], state: "minecraft:tuff_bricks"},
        {pos: [1, 15, 11], state: "minecraft:tuff_bricks"},
        {pos: [1, 15, 12], state: "minecraft:tuff_bricks"},
        {pos: [1, 15, 13], state: "minecraft:tuff_bricks"},
        {pos: [1, 15, 14], state: "minecraft:tuff_bricks"},
        {pos: [2, 15, 0], state: "minecraft:air"},
        {pos: [2, 15, 1], state: "minecraft:air"},
        {pos: [2, 15, 2], state: "minecraft:air"},
        {pos: [2, 15, 3], state: "minecraft:air"},
        {pos: [2, 15, 4], state: "minecraft:air"},
        {pos: [2, 15, 5], state: "minecraft:waxed_copper_block"},
        {pos: [2, 15, 6], state: "minecraft:tuff_bricks"},
        {pos: [2, 15, 7], state: "minecraft:tuff_bricks"},
        {pos: [2, 15, 8], state: "minecraft:tuff_bricks"},
        {pos: [2, 15, 9], state: "minecraft:tuff_bricks"},
        {pos: [2, 15, 10], state: "minecraft:tuff_bricks"},
        {pos: [2, 15, 11], state: "minecraft:tuff_bricks"},
        {pos: [2, 15, 12], state: "minecraft:tuff_bricks"},
        {pos: [2, 15, 13], state: "minecraft:tuff_bricks"},
        {pos: [2, 15, 14], state: "minecraft:tuff_bricks"},
        {pos: [3, 15, 0], state: "minecraft:air"},
        {pos: [3, 15, 1], state: "minecraft:air"},
        {pos: [3, 15, 2], state: "minecraft:air"},
        {pos: [3, 15, 3], state: "minecraft:air"},
        {pos: [3, 15, 4], state: "minecraft:air"},
        {pos: [3, 15, 5], state: "minecraft:waxed_copper_block"},
        {pos: [3, 15, 6], state: "minecraft:tuff_bricks"},
        {pos: [3, 15, 7], state: "minecraft:tuff_bricks"},
        {pos: [3, 15, 8], state: "minecraft:tuff_bricks"},
        {pos: [3, 15, 9], state: "minecraft:tuff_bricks"},
        {pos: [3, 15, 10], state: "minecraft:tuff_bricks"},
        {pos: [3, 15, 11], state: "minecraft:tuff_bricks"},
        {pos: [3, 15, 12], state: "minecraft:tuff_bricks"},
        {pos: [3, 15, 13], state: "minecraft:tuff_bricks"},
        {pos: [3, 15, 14], state: "minecraft:tuff_bricks"},
        {pos: [4, 15, 0], state: "minecraft:air"},
        {pos: [4, 15, 1], state: "minecraft:air"},
        {pos: [4, 15, 2], state: "minecraft:air"},
        {pos: [4, 15, 3], state: "minecraft:air"},
        {pos: [4, 15, 4], state: "minecraft:waxed_copper_block"},
        {pos: [4, 15, 5], state: "minecraft:waxed_copper_block"},
        {pos: [4, 15, 6], state: "minecraft:waxed_copper_block"},
        {pos: [4, 15, 7], state: "minecraft:waxed_copper_block"},
        {pos: [4, 15, 8], state: "minecraft:waxed_copper_block"},
        {pos: [4, 15, 9], state: "minecraft:waxed_copper_block"},
        {pos: [4, 15, 10], state: "minecraft:waxed_copper_block"},
        {pos: [4, 15, 11], state: "minecraft:waxed_copper_block"},
        {pos: [4, 15, 12], state: "minecraft:waxed_copper_block"},
        {pos: [4, 15, 13], state: "minecraft:waxed_copper_block"},
        {pos: [4, 15, 14], state: "minecraft:waxed_copper_block"},
        {pos: [0, 16, 0], state: "minecraft:tuff_bricks"},
        {pos: [0, 16, 1], state: "minecraft:polished_tuff"},
        {pos: [0, 16, 2], state: "minecraft:polished_tuff"},
        {pos: [0, 16, 3], state: "minecraft:polished_tuff"},
        {pos: [0, 16, 4], state: "minecraft:tuff_bricks"},
        {pos: [0, 16, 5], state: "minecraft:tuff_bricks"},
        {pos: [0, 16, 6], state: "minecraft:tuff_bricks"},
        {pos: [0, 16, 7], state: "minecraft:tuff_bricks"},
        {pos: [0, 16, 8], state: "minecraft:tuff_bricks"},
        {pos: [0, 16, 9], state: "minecraft:tuff_bricks"},
        {pos: [0, 16, 10], state: "minecraft:tuff_bricks"},
        {pos: [0, 16, 11], state: "minecraft:tuff_bricks"},
        {pos: [0, 16, 12], state: "minecraft:tuff_bricks"},
        {pos: [0, 16, 13], state: "minecraft:tuff_bricks"},
        {pos: [0, 16, 14], state: "minecraft:tuff_bricks"},
        {pos: [1, 16, 0], state: "minecraft:polished_tuff"},
        {pos: [1, 16, 1], state: "minecraft:polished_tuff"},
        {pos: [1, 16, 2], state: "minecraft:polished_tuff"},
        {pos: [1, 16, 3], state: "minecraft:polished_tuff"},
        {pos: [1, 16, 4], state: "minecraft:polished_tuff"},
        {pos: [1, 16, 5], state: "minecraft:tuff_bricks"},
        {pos: [1, 16, 6], state: "minecraft:tuff_bricks"},
        {pos: [1, 16, 7], state: "minecraft:tuff_bricks"},
        {pos: [1, 16, 8], state: "minecraft:tuff_bricks"},
        {pos: [1, 16, 9], state: "minecraft:tuff_bricks"},
        {pos: [1, 16, 10], state: "minecraft:tuff_bricks"},
        {pos: [1, 16, 11], state: "minecraft:tuff_bricks"},
        {pos: [1, 16, 12], state: "minecraft:tuff_bricks"},
        {pos: [1, 16, 13], state: "minecraft:tuff_bricks"},
        {pos: [1, 16, 14], state: "minecraft:tuff_bricks"},
        {pos: [2, 16, 0], state: "minecraft:polished_tuff"},
        {pos: [2, 16, 1], state: "minecraft:polished_tuff"},
        {pos: [2, 16, 2], state: "minecraft:polished_tuff"},
        {pos: [2, 16, 3], state: "minecraft:polished_tuff"},
        {pos: [2, 16, 4], state: "minecraft:polished_tuff"},
        {pos: [2, 16, 5], state: "minecraft:tuff_bricks"},
        {pos: [2, 16, 6], state: "minecraft:tuff_bricks"},
        {pos: [2, 16, 7], state: "minecraft:tuff_bricks"},
        {pos: [2, 16, 8], state: "minecraft:tuff_bricks"},
        {pos: [2, 16, 9], state: "minecraft:tuff_bricks"},
        {pos: [2, 16, 10], state: "minecraft:tuff_bricks"},
        {pos: [2, 16, 11], state: "minecraft:tuff_bricks"},
        {pos: [2, 16, 12], state: "minecraft:tuff_bricks"},
        {pos: [2, 16, 13], state: "minecraft:tuff_bricks"},
        {pos: [2, 16, 14], state: "minecraft:tuff_bricks"},
        {pos: [3, 16, 0], state: "minecraft:polished_tuff"},
        {pos: [3, 16, 1], state: "minecraft:polished_tuff"},
        {pos: [3, 16, 2], state: "minecraft:polished_tuff"},
        {pos: [3, 16, 3], state: "minecraft:polished_tuff"},
        {pos: [3, 16, 4], state: "minecraft:polished_tuff"},
        {pos: [3, 16, 5], state: "minecraft:tuff_bricks"},
        {pos: [3, 16, 6], state: "minecraft:tuff_bricks"},
        {pos: [3, 16, 7], state: "minecraft:tuff_bricks"},
        {pos: [3, 16, 8], state: "minecraft:tuff_bricks"},
        {pos: [3, 16, 9], state: "minecraft:tuff_bricks"},
        {pos: [3, 16, 10], state: "minecraft:tuff_bricks"},
        {pos: [3, 16, 11], state: "minecraft:tuff_bricks"},
        {pos: [3, 16, 12], state: "minecraft:tuff_bricks"},
        {pos: [3, 16, 13], state: "minecraft:tuff_bricks"},
        {pos: [3, 16, 14], state: "minecraft:tuff_bricks"},
        {pos: [4, 16, 0], state: "minecraft:polished_tuff"},
        {pos: [4, 16, 1], state: "minecraft:polished_tuff"},
        {pos: [4, 16, 2], state: "minecraft:polished_tuff"},
        {pos: [4, 16, 3], state: "minecraft:polished_tuff"},
        {pos: [4, 16, 4], state: "minecraft:tuff_bricks"},
        {pos: [4, 16, 5], state: "minecraft:tuff_bricks"},
        {pos: [4, 16, 6], state: "minecraft:tuff_bricks"},
        {pos: [4, 16, 7], state: "minecraft:tuff_bricks"},
        {pos: [4, 16, 8], state: "minecraft:tuff_bricks"},
        {pos: [4, 16, 9], state: "minecraft:tuff_bricks"},
        {pos: [4, 16, 10], state: "minecraft:tuff_bricks"},
        {pos: [4, 16, 11], state: "minecraft:tuff_bricks"},
        {pos: [4, 16, 12], state: "minecraft:tuff_bricks"},
        {pos: [4, 16, 13], state: "minecraft:tuff_bricks"},
        {pos: [4, 16, 14], state: "minecraft:tuff_bricks"}
    ],
    entities: [],
    palette: [
        "minecraft:tuff_bricks",
        "minecraft:waxed_oxidized_copper",
        "minecraft:waxed_copper_block",
        "minecraft:waxed_copper_bulb{lit:true,powered:false}",
        "minecraft:chiseled_tuff_bricks",
        "minecraft:polished_tuff",
        "minecraft:air",
        "minecraft:jigsaw{orientation:down_east}",
        "minecraft:jigsaw{orientation:west_up}",
        "minecraft:jigsaw{orientation:north_up}",
        "minecraft:jigsaw{orientation:east_up}"
    ]
}
