{
    size: [13, 10, 9],
    data: [
        {pos: [0, 0, 0], state: "minecraft:grass_block{snowy:false}"},
        {pos: [0, 0, 1], state: "minecraft:grass_block{snowy:false}"},
        {pos: [0, 0, 2], state: "minecraft:grass_block{snowy:false}"},
        {pos: [0, 0, 3], state: "minecraft:dirt"},
        {pos: [0, 0, 4], state: "minecraft:dirt"},
        {pos: [0, 0, 5], state: "minecraft:dirt"},
        {pos: [0, 0, 6], state: "minecraft:grass_block{snowy:false}"},
        {pos: [0, 0, 7], state: "minecraft:short_grass"},
        {pos: [0, 0, 8], state: "minecraft:air"},
        {pos: [1, 0, 0], state: "minecraft:grass_block{snowy:false}"},
        {pos: [1, 0, 1], state: "minecraft:grass_block{snowy:false}"},
        {pos: [1, 0, 2], state: "minecraft:grass_block{snowy:false}"},
        {pos: [1, 0, 3], state: "minecraft:dirt"},
        {pos: [1, 0, 4], state: "minecraft:dirt"},
        {pos: [1, 0, 5], state: "minecraft:dirt"},
        {pos: [1, 0, 6], state: "minecraft:grass_block{snowy:false}"},
        {pos: [1, 0, 7], state: "minecraft:air"},
        {pos: [1, 0, 8], state: "minecraft:short_grass"},
        {pos: [2, 0, 0], state: "minecraft:grass_block{snowy:false}"},
        {pos: [2, 0, 1], state: "minecraft:grass_block{snowy:false}"},
        {pos: [2, 0, 2], state: "minecraft:grass_block{snowy:false}"},
        {pos: [2, 0, 3], state: "minecraft:grass_block{snowy:false}"},
        {pos: [2, 0, 4], state: "minecraft:grass_block{snowy:false}"},
        {pos: [2, 0, 5], state: "minecraft:grass_block{snowy:false}"},
        {pos: [2, 0, 6], state: "minecraft:grass_block{snowy:false}"},
        {pos: [2, 0, 7], state: "minecraft:air"},
        {pos: [2, 0, 8], state: "minecraft:short_grass"},
        {pos: [3, 0, 0], state: "minecraft:grass_block{snowy:false}"},
        {pos: [3, 0, 1], state: "minecraft:grass_block{snowy:false}"},
        {pos: [3, 0, 2], state: "minecraft:grass_block{snowy:false}"},
        {pos: [3, 0, 3], state: "minecraft:grass_block{snowy:false}"},
        {pos: [3, 0, 4], state: "minecraft:grass_block{snowy:false}"},
        {pos: [3, 0, 5], state: "minecraft:grass_block{snowy:false}"},
        {pos: [3, 0, 6], state: "minecraft:grass_block{snowy:false}"},
        {pos: [3, 0, 7], state: "minecraft:air"},
        {pos: [3, 0, 8], state: "minecraft:grass_block{snowy:false}"},
        {pos: [4, 0, 0], state: "minecraft:grass_block{snowy:false}"},
        {pos: [4, 0, 1], state: "minecraft:grass_block{snowy:false}"},
        {pos: [4, 0, 2], state: "minecraft:grass_block{snowy:false}"},
        {pos: [4, 0, 3], state: "minecraft:grass_block{snowy:false}"},
        {pos: [4, 0, 4], state: "minecraft:grass_block{snowy:false}"},
        {pos: [4, 0, 5], state: "minecraft:grass_block{snowy:false}"},
        {pos: [4, 0, 6], state: "minecraft:grass_block{snowy:false}"},
        {pos: [4, 0, 7], state: "minecraft:grass_block{snowy:false}"},
        {pos: [4, 0, 8], state: "minecraft:grass_block{snowy:false}"},
        {pos: [5, 0, 0], state: "minecraft:grass_block{snowy:false}"},
        {pos: [5, 0, 1], state: "minecraft:grass_block{snowy:false}"},
        {pos: [5, 0, 2], state: "minecraft:grass_block{snowy:false}"},
        {pos: [5, 0, 3], state: "minecraft:grass_block{snowy:false}"},
        {pos: [5, 0, 4], state: "minecraft:grass_block{snowy:false}"},
        {pos: [5, 0, 5], state: "minecraft:grass_block{snowy:false}"},
        {pos: [5, 0, 6], state: "minecraft:grass_block{snowy:false}"},
        {pos: [5, 0, 7], state: "minecraft:grass_block{snowy:false}"},
        {pos: [5, 0, 8], state: "minecraft:grass_block{snowy:false}"},
        {pos: [6, 0, 0], state: "minecraft:grass_block{snowy:false}"},
        {pos: [6, 0, 1], state: "minecraft:grass_block{snowy:false}"},
        {pos: [6, 0, 2], state: "minecraft:grass_block{snowy:false}"},
        {pos: [6, 0, 3], state: "minecraft:grass_block{snowy:false}"},
        {pos: [6, 0, 4], state: "minecraft:grass_block{snowy:false}"},
        {pos: [6, 0, 5], state: "minecraft:grass_block{snowy:false}"},
        {pos: [6, 0, 6], state: "minecraft:grass_block{snowy:false}"},
        {pos: [6, 0, 7], state: "minecraft:grass_block{snowy:false}"},
        {pos: [6, 0, 8], state: "minecraft:grass_block{snowy:false}"},
        {pos: [7, 0, 0], state: "minecraft:grass_block{snowy:false}"},
        {pos: [7, 0, 1], state: "minecraft:grass_block{snowy:false}"},
        {pos: [7, 0, 2], state: "minecraft:grass_block{snowy:false}"},
        {pos: [7, 0, 3], state: "minecraft:grass_block{snowy:false}"},
        {pos: [7, 0, 4], state: "minecraft:grass_block{snowy:false}"},
        {pos: [7, 0, 5], state: "minecraft:grass_block{snowy:false}"},
        {pos: [7, 0, 6], state: "minecraft:grass_block{snowy:false}"},
        {pos: [7, 0, 7], state: "minecraft:grass_block{snowy:false}"},
        {pos: [7, 0, 8], state: "minecraft:grass_block{snowy:false}"},
        {pos: [8, 0, 0], state: "minecraft:grass_block{snowy:false}"},
        {pos: [8, 0, 1], state: "minecraft:grass_block{snowy:false}"},
        {pos: [8, 0, 2], state: "minecraft:grass_block{snowy:false}"},
        {pos: [8, 0, 3], state: "minecraft:grass_block{snowy:false}"},
        {pos: [8, 0, 4], state: "minecraft:grass_block{snowy:false}"},
        {pos: [8, 0, 5], state: "minecraft:grass_block{snowy:false}"},
        {pos: [8, 0, 6], state: "minecraft:grass_block{snowy:false}"},
        {pos: [8, 0, 7], state: "minecraft:grass_block{snowy:false}"},
        {pos: [8, 0, 8], state: "minecraft:grass_block{snowy:false}"},
        {pos: [9, 0, 0], state: "minecraft:grass_block{snowy:false}"},
        {pos: [9, 0, 1], state: "minecraft:grass_block{snowy:false}"},
        {pos: [9, 0, 2], state: "minecraft:grass_block{snowy:false}"},
        {pos: [9, 0, 3], state: "minecraft:grass_block{snowy:false}"},
        {pos: [9, 0, 4], state: "minecraft:grass_block{snowy:false}"},
        {pos: [9, 0, 5], state: "minecraft:grass_block{snowy:false}"},
        {pos: [9, 0, 6], state: "minecraft:grass_block{snowy:false}"},
        {pos: [9, 0, 7], state: "minecraft:grass_block{snowy:false}"},
        {pos: [9, 0, 8], state: "minecraft:grass_block{snowy:false}"},
        {pos: [10, 0, 0], state: "minecraft:grass_block{snowy:false}"},
        {pos: [10, 0, 1], state: "minecraft:grass_block{snowy:false}"},
        {pos: [10, 0, 2], state: "minecraft:jigsaw{orientation:up_north}", nbt: {final_state: "minecraft:grass_block", id: "minecraft:jigsaw", joint: "rollable", name: "minecraft:bottom", pool: "minecraft:village/common/butcher_animals", target: "minecraft:bottom"}},
        {pos: [10, 0, 3], state: "minecraft:grass_block{snowy:false}"},
        {pos: [10, 0, 4], state: "minecraft:grass_block{snowy:false}"},
        {pos: [10, 0, 5], state: "minecraft:grass_block{snowy:false}"},
        {pos: [10, 0, 6], state: "minecraft:dirt"},
        {pos: [10, 0, 7], state: "minecraft:grass_block{snowy:false}"},
        {pos: [10, 0, 8], state: "minecraft:grass_block{snowy:false}"},
        {pos: [11, 0, 0], state: "minecraft:grass_block{snowy:false}"},
        {pos: [11, 0, 1], state: "minecraft:grass_block{snowy:false}"},
        {pos: [11, 0, 2], state: "minecraft:grass_block{snowy:false}"},
        {pos: [11, 0, 3], state: "minecraft:grass_block{snowy:false}"},
        {pos: [11, 0, 4], state: "minecraft:grass_block{snowy:false}"},
        {pos: [11, 0, 5], state: "minecraft:grass_block{snowy:false}"},
        {pos: [11, 0, 6], state: "minecraft:grass_block{snowy:false}"},
        {pos: [11, 0, 7], state: "minecraft:grass_block{snowy:false}"},
        {pos: [11, 0, 8], state: "minecraft:grass_block{snowy:false}"},
        {pos: [12, 0, 0], state: "minecraft:grass_block{snowy:false}"},
        {pos: [12, 0, 1], state: "minecraft:grass_block{snowy:false}"},
        {pos: [12, 0, 2], state: "minecraft:grass_block{snowy:false}"},
        {pos: [12, 0, 3], state: "minecraft:grass_block{snowy:false}"},
        {pos: [12, 0, 4], state: "minecraft:grass_block{snowy:false}"},
        {pos: [12, 0, 5], state: "minecraft:grass_block{snowy:false}"},
        {pos: [12, 0, 6], state: "minecraft:grass_block{snowy:false}"},
        {pos: [12, 0, 7], state: "minecraft:grass_block{snowy:false}"},
        {pos: [12, 0, 8], state: "minecraft:grass_block{snowy:false}"},
        {pos: [0, 1, 1], state: "minecraft:short_grass"},
        {pos: [0, 1, 2], state: "minecraft:short_grass"},
        {pos: [0, 1, 3], state: "minecraft:acacia_stairs{facing:east,half:bottom,shape:straight,waterlogged:false}"},
        {pos: [0, 1, 4], state: "minecraft:jigsaw{orientation:west_up}", nbt: {final_state: "minecraft:acacia_stairs[facing=east]", id: "minecraft:jigsaw", joint: "aligned", name: "minecraft:building_entrance", pool: "minecraft:empty", target: "minecraft:building_entrance"}},
        {pos: [0, 1, 5], state: "minecraft:acacia_stairs{facing:east,half:bottom,shape:straight,waterlogged:false}"},
        {pos: [0, 1, 6], state: "minecraft:short_grass"},
        {pos: [1, 1, 0], state: "minecraft:short_grass"},
        {pos: [1, 1, 2], state: "minecraft:acacia_fence{east:true,north:false,south:true,waterlogged:false,west:false}"},
        {pos: [1, 1, 3], state: "minecraft:acacia_planks"},
        {pos: [1, 1, 4], state: "minecraft:acacia_planks"},
        {pos: [1, 1, 5], state: "minecraft:acacia_planks"},
        {pos: [1, 1, 6], state: "minecraft:acacia_fence{east:true,north:true,south:false,waterlogged:false,west:false}"},
        {pos: [1, 1, 7], state: "minecraft:air"},
        {pos: [2, 1, 1], state: "minecraft:short_grass"},
        {pos: [2, 1, 2], state: "minecraft:acacia_fence{east:true,north:false,south:false,waterlogged:false,west:true}"},
        {pos: [2, 1, 6], state: "minecraft:acacia_fence{east:true,north:false,south:false,waterlogged:false,west:true}"},
        {pos: [2, 1, 7], state: "minecraft:air"},
        {pos: [3, 1, 1], state: "minecraft:short_grass"},
        {pos: [3, 1, 2], state: "minecraft:acacia_fence{east:true,north:false,south:false,waterlogged:false,west:true}"},
        {pos: [3, 1, 6], state: "minecraft:acacia_fence{east:true,north:false,south:false,waterlogged:false,west:true}"},
        {pos: [3, 1, 7], state: "minecraft:air"},
        {pos: [4, 1, 0], state: "minecraft:acacia_fence{east:true,north:false,south:true,waterlogged:false,west:false}"},
        {pos: [4, 1, 1], state: "minecraft:acacia_fence{east:false,north:true,south:true,waterlogged:false,west:false}"},
        {pos: [4, 1, 2], state: "minecraft:acacia_fence{east:false,north:true,south:false,waterlogged:false,west:true}"},
        {pos: [4, 1, 4], state: "minecraft:acacia_fence{east:false,north:false,south:false,waterlogged:false,west:false}"},
        {pos: [4, 1, 6], state: "minecraft:acacia_fence{east:false,north:false,south:true,waterlogged:false,west:true}"},
        {pos: [4, 1, 7], state: "minecraft:acacia_fence{east:false,north:true,south:true,waterlogged:false,west:false}"},
        {pos: [4, 1, 8], state: "minecraft:acacia_fence{east:true,north:true,south:false,waterlogged:false,west:false}"},
        {pos: [5, 1, 0], state: "minecraft:acacia_fence{east:true,north:false,south:false,waterlogged:false,west:true}"},
        {pos: [5, 1, 1], state: "minecraft:short_grass"},
        {pos: [5, 1, 3], state: "minecraft:short_grass"},
        {pos: [5, 1, 4], state: "minecraft:torch"},
        {pos: [5, 1, 6], state: "minecraft:short_grass"},
        {pos: [5, 1, 7], state: "minecraft:short_grass"},
        {pos: [5, 1, 8], state: "minecraft:acacia_fence{east:true,north:false,south:false,waterlogged:false,west:true}"},
        {pos: [6, 1, 0], state: "minecraft:acacia_fence{east:true,north:false,south:false,waterlogged:false,west:true}"},
        {pos: [6, 1, 5], state: "minecraft:short_grass"},
        {pos: [6, 1, 6], state: "minecraft:short_grass"},
        {pos: [6, 1, 7], state: "minecraft:short_grass"},
        {pos: [6, 1, 8], state: "minecraft:acacia_fence{east:true,north:false,south:false,waterlogged:false,west:true}"},
        {pos: [7, 1, 0], state: "minecraft:acacia_fence{east:true,north:false,south:false,waterlogged:false,west:true}"},
        {pos: [7, 1, 1], state: "minecraft:short_grass"},
        {pos: [7, 1, 2], state: "minecraft:acacia_fence{east:false,north:false,south:false,waterlogged:false,west:false}"},
        {pos: [7, 1, 4], state: "minecraft:acacia_fence{east:false,north:false,south:false,waterlogged:false,west:false}"},
        {pos: [7, 1, 6], state: "minecraft:acacia_fence{east:false,north:false,south:false,waterlogged:false,west:false}"},
        {pos: [7, 1, 8], state: "minecraft:acacia_fence{east:true,north:false,south:false,waterlogged:false,west:true}"},
        {pos: [8, 1, 0], state: "minecraft:acacia_fence{east:true,north:false,south:false,waterlogged:false,west:true}"},
        {pos: [8, 1, 1], state: "minecraft:short_grass"},
        {pos: [8, 1, 4], state: "minecraft:short_grass"},
        {pos: [8, 1, 5], state: "minecraft:acacia_fence{east:false,north:false,south:false,waterlogged:false,west:false}"},
        {pos: [8, 1, 7], state: "minecraft:short_grass"},
        {pos: [8, 1, 8], state: "minecraft:acacia_fence{east:true,north:false,south:false,waterlogged:false,west:true}"},
        {pos: [9, 1, 0], state: "minecraft:acacia_fence{east:true,north:false,south:false,waterlogged:false,west:true}"},
        {pos: [9, 1, 1], state: "minecraft:short_grass"},
        {pos: [9, 1, 3], state: "minecraft:short_grass"},
        {pos: [9, 1, 5], state: "minecraft:short_grass"},
        {pos: [9, 1, 6], state: "minecraft:acacia_slab{type:top,waterlogged:false}"},
        {pos: [9, 1, 7], state: "minecraft:short_grass"},
        {pos: [9, 1, 8], state: "minecraft:acacia_fence{east:true,north:false,south:false,waterlogged:false,west:true}"},
        {pos: [10, 1, 0], state: "minecraft:acacia_fence{east:true,north:false,south:false,waterlogged:false,west:true}"},
        {pos: [10, 1, 1], state: "minecraft:short_grass"},
        {pos: [10, 1, 3], state: "minecraft:short_grass"},
        {pos: [10, 1, 4], state: "minecraft:short_grass"},
        {pos: [10, 1, 5], state: "minecraft:short_grass"},
        {pos: [10, 1, 6], state: "minecraft:acacia_stairs{facing:west,half:bottom,shape:straight,waterlogged:false}"},
        {pos: [10, 1, 7], state: "minecraft:short_grass"},
        {pos: [10, 1, 8], state: "minecraft:acacia_fence{east:true,north:false,south:false,waterlogged:false,west:true}"},
        {pos: [11, 1, 0], state: "minecraft:acacia_fence{east:true,north:false,south:false,waterlogged:false,west:true}"},
        {pos: [11, 1, 2], state: "minecraft:short_grass"},
        {pos: [11, 1, 3], state: "minecraft:short_grass"},
        {pos: [11, 1, 5], state: "minecraft:short_grass"},
        {pos: [11, 1, 6], state: "minecraft:short_grass"},
        {pos: [11, 1, 8], state: "minecraft:acacia_fence{east:true,north:false,south:false,waterlogged:false,west:true}"},
        {pos: [12, 1, 0], state: "minecraft:acacia_fence{east:false,north:false,south:true,waterlogged:false,west:true}"},
        {pos: [12, 1, 1], state: "minecraft:acacia_fence{east:false,north:true,south:true,waterlogged:false,west:false}"},
        {pos: [12, 1, 2], state: "minecraft:acacia_fence{east:false,north:true,south:true,waterlogged:false,west:false}"},
        {pos: [12, 1, 3], state: "minecraft:acacia_fence{east:false,north:true,south:true,waterlogged:false,west:false}"},
        {pos: [12, 1, 4], state: "minecraft:acacia_fence{east:false,north:true,south:true,waterlogged:false,west:false}"},
        {pos: [12, 1, 5], state: "minecraft:acacia_fence{east:false,north:true,south:true,waterlogged:false,west:false}"},
        {pos: [12, 1, 6], state: "minecraft:acacia_fence{east:false,north:true,south:true,waterlogged:false,west:false}"},
        {pos: [12, 1, 7], state: "minecraft:acacia_fence{east:false,north:true,south:true,waterlogged:false,west:false}"},
        {pos: [12, 1, 8], state: "minecraft:acacia_fence{east:false,north:true,south:false,waterlogged:false,west:true}"},
        {pos: [1, 2, 3], state: "minecraft:acacia_stairs{facing:east,half:bottom,shape:straight,waterlogged:false}"},
        {pos: [1, 2, 4], state: "minecraft:acacia_stairs{facing:east,half:bottom,shape:straight,waterlogged:false}"},
        {pos: [1, 2, 5], state: "minecraft:acacia_stairs{facing:east,half:bottom,shape:straight,waterlogged:false}"},
        {pos: [2, 2, 3], state: "minecraft:acacia_slab{type:top,waterlogged:false}"},
        {pos: [2, 2, 4], state: "minecraft:acacia_slab{type:top,waterlogged:false}"},
        {pos: [2, 2, 5], state: "minecraft:acacia_slab{type:top,waterlogged:false}"},
        {pos: [4, 2, 2], state: "minecraft:acacia_fence{east:false,north:false,south:false,waterlogged:false,west:false}"},
        {pos: [4, 2, 4], state: "minecraft:acacia_fence{east:false,north:false,south:false,waterlogged:false,west:false}"},
        {pos: [4, 2, 6], state: "minecraft:acacia_fence{east:false,north:false,south:false,waterlogged:false,west:false}"},
        {pos: [4, 2, 8], state: "minecraft:torch"},
        {pos: [7, 2, 2], state: "minecraft:acacia_fence{east:false,north:false,south:false,waterlogged:false,west:false}"},
        {pos: [7, 2, 4], state: "minecraft:acacia_fence{east:false,north:false,south:false,waterlogged:false,west:false}"},
        {pos: [7, 2, 6], state: "minecraft:acacia_fence{east:false,north:false,south:false,waterlogged:false,west:false}"},
        {pos: [8, 2, 5], state: "minecraft:acacia_fence{east:false,north:false,south:false,waterlogged:false,west:false}"},
        {pos: [8, 2, 6], state: "minecraft:acacia_slab{type:top,waterlogged:false}"},
        {pos: [9, 2, 6], state: "minecraft:acacia_stairs{facing:west,half:bottom,shape:straight,waterlogged:false}"},
        {pos: [12, 2, 0], state: "minecraft:torch"},
        {pos: [12, 2, 8], state: "minecraft:torch"},
        {pos: [2, 3, 3], state: "minecraft:acacia_stairs{facing:east,half:bottom,shape:straight,waterlogged:false}"},
        {pos: [2, 3, 4], state: "minecraft:acacia_stairs{facing:east,half:bottom,shape:straight,waterlogged:false}"},
        {pos: [2, 3, 5], state: "minecraft:acacia_stairs{facing:east,half:bottom,shape:straight,waterlogged:false}"},
        {pos: [3, 3, 3], state: "minecraft:acacia_planks"},
        {pos: [3, 3, 4], state: "minecraft:acacia_planks"},
        {pos: [3, 3, 5], state: "minecraft:acacia_planks"},
        {pos: [4, 3, 2], state: "minecraft:acacia_planks"},
        {pos: [4, 3, 3], state: "minecraft:acacia_planks"},
        {pos: [4, 3, 4], state: "minecraft:acacia_wood{axis:x}"},
        {pos: [4, 3, 5], state: "minecraft:acacia_planks"},
        {pos: [4, 3, 6], state: "minecraft:acacia_planks"},
        {pos: [5, 3, 2], state: "minecraft:acacia_planks"},
        {pos: [5, 3, 3], state: "minecraft:acacia_planks"},
        {pos: [5, 3, 4], state: "minecraft:acacia_planks"},
        {pos: [5, 3, 5], state: "minecraft:acacia_planks"},
        {pos: [5, 3, 6], state: "minecraft:acacia_planks"},
        {pos: [6, 3, 2], state: "minecraft:acacia_planks"},
        {pos: [6, 3, 3], state: "minecraft:acacia_planks"},
        {pos: [6, 3, 4], state: "minecraft:acacia_planks"},
        {pos: [6, 3, 5], state: "minecraft:acacia_planks"},
        {pos: [6, 3, 6], state: "minecraft:acacia_planks"},
        {pos: [7, 3, 2], state: "minecraft:acacia_planks"},
        {pos: [7, 3, 3], state: "minecraft:acacia_planks"},
        {pos: [7, 3, 4], state: "minecraft:acacia_wood{axis:x}"},
        {pos: [7, 3, 5], state: "minecraft:acacia_planks"},
        {pos: [7, 3, 6], state: "minecraft:acacia_planks"},
        {pos: [8, 3, 3], state: "minecraft:acacia_slab{type:top,waterlogged:false}"},
        {pos: [8, 3, 4], state: "minecraft:acacia_slab{type:top,waterlogged:false}"},
        {pos: [8, 3, 5], state: "minecraft:acacia_stairs{facing:north,half:bottom,shape:straight,waterlogged:false}"},
        {pos: [4, 4, 2], state: "minecraft:acacia_wood{axis:y}"},
        {pos: [4, 4, 3], state: "minecraft:acacia_wood{axis:y}"},
        {pos: [4, 4, 4], state: "minecraft:acacia_door{facing:west,half:lower,hinge:left,open:false,powered:false}"},
        {pos: [4, 4, 5], state: "minecraft:acacia_wood{axis:y}"},
        {pos: [4, 4, 6], state: "minecraft:acacia_wood{axis:y}"},
        {pos: [5, 4, 2], state: "minecraft:acacia_wood{axis:x}"},
        {pos: [5, 4, 3], state: "minecraft:acacia_stairs{facing:north,half:bottom,shape:straight,waterlogged:false}"},
        {pos: [5, 4, 6], state: "minecraft:acacia_wood{axis:x}"},
        {pos: [6, 4, 2], state: "minecraft:acacia_wood{axis:x}"},
        {pos: [6, 4, 3], state: "minecraft:acacia_stairs{facing:north,half:bottom,shape:straight,waterlogged:false}"},
        {pos: [6, 4, 5], state: "minecraft:chest{facing:north,type:single,waterlogged:false}", nbt: {LootTable: "minecraft:chests/village/village_butcher", id: "minecraft:chest"}},
        {pos: [6, 4, 6], state: "minecraft:acacia_wood{axis:x}"},
        {pos: [7, 4, 2], state: "minecraft:acacia_wood{axis:y}"},
        {pos: [7, 4, 3], state: "minecraft:acacia_wood{axis:y}"},
        {pos: [7, 4, 4], state: "minecraft:acacia_door{facing:east,half:lower,hinge:right,open:false,powered:false}"},
        {pos: [7, 4, 5], state: "minecraft:acacia_wood{axis:y}"},
        {pos: [7, 4, 6], state: "minecraft:acacia_wood{axis:y}"},
        {pos: [8, 4, 3], state: "minecraft:smoker{facing:east,lit:false}", nbt: {Items: [], RecipesUsed: {}, cooking_time_spent: 0s, cooking_total_time: 0s, id: "minecraft:smoker", lit_time_remaining: 0s, lit_total_time: 0s}},
        {pos: [3, 5, 3], state: "minecraft:wall_torch{facing:west}"},
        {pos: [3, 5, 5], state: "minecraft:wall_torch{facing:west}"},
        {pos: [4, 5, 2], state: "minecraft:acacia_wood{axis:y}"},
        {pos: [4, 5, 3], state: "minecraft:acacia_wood{axis:y}"},
        {pos: [4, 5, 4], state: "minecraft:acacia_door{facing:west,half:upper,hinge:left,open:false,powered:false}"},
        {pos: [4, 5, 5], state: "minecraft:acacia_wood{axis:y}"},
        {pos: [4, 5, 6], state: "minecraft:acacia_wood{axis:y}"},
        {pos: [5, 5, 2], state: "minecraft:glass_pane{east:true,north:false,south:false,waterlogged:false,west:true}"},
        {pos: [5, 5, 6], state: "minecraft:glass_pane{east:true,north:false,south:false,waterlogged:false,west:true}"},
        {pos: [6, 5, 2], state: "minecraft:glass_pane{east:true,north:false,south:false,waterlogged:false,west:true}"},
        {pos: [6, 5, 6], state: "minecraft:glass_pane{east:true,north:false,south:false,waterlogged:false,west:true}"},
        {pos: [7, 5, 2], state: "minecraft:acacia_wood{axis:y}"},
        {pos: [7, 5, 3], state: "minecraft:acacia_wood{axis:y}"},
        {pos: [7, 5, 4], state: "minecraft:acacia_door{facing:east,half:upper,hinge:right,open:false,powered:false}"},
        {pos: [7, 5, 5], state: "minecraft:acacia_wood{axis:y}"},
        {pos: [7, 5, 6], state: "minecraft:acacia_wood{axis:y}"},
        {pos: [4, 6, 2], state: "minecraft:acacia_wood{axis:y}"},
        {pos: [4, 6, 3], state: "minecraft:acacia_wood{axis:y}"},
        {pos: [4, 6, 4], state: "minecraft:acacia_wood{axis:z}"},
        {pos: [4, 6, 5], state: "minecraft:acacia_wood{axis:y}"},
        {pos: [4, 6, 6], state: "minecraft:acacia_wood{axis:y}"},
        {pos: [5, 6, 2], state: "minecraft:acacia_wood{axis:x}"},
        {pos: [5, 6, 6], state: "minecraft:acacia_wood{axis:x}"},
        {pos: [6, 6, 2], state: "minecraft:acacia_wood{axis:x}"},
        {pos: [6, 6, 4], state: "minecraft:wall_torch{facing:west}"},
        {pos: [6, 6, 6], state: "minecraft:acacia_wood{axis:x}"},
        {pos: [7, 6, 2], state: "minecraft:acacia_wood{axis:y}"},
        {pos: [7, 6, 3], state: "minecraft:acacia_wood{axis:y}"},
        {pos: [7, 6, 4], state: "minecraft:acacia_wood{axis:z}"},
        {pos: [7, 6, 5], state: "minecraft:acacia_wood{axis:y}"},
        {pos: [7, 6, 6], state: "minecraft:acacia_wood{axis:y}"},
        {pos: [8, 6, 4], state: "minecraft:wall_torch{facing:east}"},
        {pos: [3, 7, 2], state: "minecraft:acacia_stairs{facing:east,half:bottom,shape:straight,waterlogged:false}"},
        {pos: [3, 7, 3], state: "minecraft:acacia_stairs{facing:east,half:bottom,shape:straight,waterlogged:false}"},
        {pos: [3, 7, 4], state: "minecraft:acacia_stairs{facing:east,half:bottom,shape:straight,waterlogged:false}"},
        {pos: [3, 7, 5], state: "minecraft:acacia_stairs{facing:east,half:bottom,shape:straight,waterlogged:false}"},
        {pos: [3, 7, 6], state: "minecraft:acacia_stairs{facing:east,half:bottom,shape:straight,waterlogged:false}"},
        {pos: [4, 7, 1], state: "minecraft:acacia_stairs{facing:south,half:bottom,shape:straight,waterlogged:false}"},
        {pos: [4, 7, 2], state: "minecraft:acacia_planks"},
        {pos: [4, 7, 3], state: "minecraft:acacia_planks"},
        {pos: [4, 7, 4], state: "minecraft:acacia_planks"},
        {pos: [4, 7, 5], state: "minecraft:acacia_planks"},
        {pos: [4, 7, 6], state: "minecraft:acacia_planks"},
        {pos: [4, 7, 7], state: "minecraft:acacia_stairs{facing:north,half:bottom,shape:straight,waterlogged:false}"},
        {pos: [5, 7, 1], state: "minecraft:acacia_stairs{facing:south,half:bottom,shape:straight,waterlogged:false}"},
        {pos: [5, 7, 2], state: "minecraft:acacia_planks"},
        {pos: [5, 7, 6], state: "minecraft:acacia_planks"},
        {pos: [5, 7, 7], state: "minecraft:acacia_stairs{facing:north,half:bottom,shape:straight,waterlogged:false}"},
        {pos: [6, 7, 1], state: "minecraft:acacia_stairs{facing:south,half:bottom,shape:straight,waterlogged:false}"},
        {pos: [6, 7, 2], state: "minecraft:acacia_planks"},
        {pos: [6, 7, 6], state: "minecraft:acacia_planks"},
        {pos: [6, 7, 7], state: "minecraft:acacia_stairs{facing:north,half:bottom,shape:straight,waterlogged:false}"},
        {pos: [7, 7, 1], state: "minecraft:acacia_stairs{facing:south,half:bottom,shape:straight,waterlogged:false}"},
        {pos: [7, 7, 2], state: "minecraft:acacia_planks"},
        {pos: [7, 7, 3], state: "minecraft:acacia_planks"},
        {pos: [7, 7, 4], state: "minecraft:acacia_planks"},
        {pos: [7, 7, 5], state: "minecraft:acacia_planks"},
        {pos: [7, 7, 6], state: "minecraft:acacia_planks"},
        {pos: [7, 7, 7], state: "minecraft:acacia_stairs{facing:north,half:bottom,shape:straight,waterlogged:false}"},
        {pos: [8, 7, 2], state: "minecraft:acacia_stairs{facing:west,half:bottom,shape:straight,waterlogged:false}"},
        {pos: [8, 7, 3], state: "minecraft:acacia_stairs{facing:west,half:bottom,shape:straight,waterlogged:false}"},
        {pos: [8, 7, 4], state: "minecraft:acacia_stairs{facing:west,half:bottom,shape:straight,waterlogged:false}"},
        {pos: [8, 7, 5], state: "minecraft:acacia_stairs{facing:west,half:bottom,shape:straight,waterlogged:false}"},
        {pos: [8, 7, 6], state: "minecraft:acacia_stairs{facing:west,half:bottom,shape:straight,waterlogged:false}"},
        {pos: [4, 8, 2], state: "minecraft:acacia_stairs{facing:east,half:bottom,shape:outer_right,waterlogged:false}"},
        {pos: [4, 8, 3], state: "minecraft:acacia_stairs{facing:east,half:bottom,shape:straight,waterlogged:false}"},
        {pos: [4, 8, 4], state: "minecraft:acacia_stairs{facing:east,half:bottom,shape:straight,waterlogged:false}"},
        {pos: [4, 8, 5], state: "minecraft:acacia_stairs{facing:east,half:bottom,shape:straight,waterlogged:false}"},
        {pos: [4, 8, 6], state: "minecraft:acacia_stairs{facing:north,half:bottom,shape:outer_right,waterlogged:false}"},
        {pos: [5, 8, 2], state: "minecraft:acacia_stairs{facing:south,half:bottom,shape:straight,waterlogged:false}"},
        {pos: [5, 8, 3], state: "minecraft:acacia_planks"},
        {pos: [5, 8, 4], state: "minecraft:acacia_planks"},
        {pos: [5, 8, 5], state: "minecraft:acacia_planks"},
        {pos: [5, 8, 6], state: "minecraft:acacia_stairs{facing:north,half:bottom,shape:straight,waterlogged:false}"},
        {pos: [6, 8, 2], state: "minecraft:acacia_stairs{facing:south,half:bottom,shape:straight,waterlogged:false}"},
        {pos: [6, 8, 3], state: "minecraft:acacia_planks"},
        {pos: [6, 8, 4], state: "minecraft:acacia_planks"},
        {pos: [6, 8, 5], state: "minecraft:acacia_planks"},
        {pos: [6, 8, 6], state: "minecraft:acacia_stairs{facing:north,half:bottom,shape:straight,waterlogged:false}"},
        {pos: [7, 8, 2], state: "minecraft:acacia_stairs{facing:west,half:bottom,shape:outer_left,waterlogged:false}"},
        {pos: [7, 8, 3], state: "minecraft:acacia_stairs{facing:west,half:bottom,shape:straight,waterlogged:false}"},
        {pos: [7, 8, 4], state: "minecraft:acacia_stairs{facing:west,half:bottom,shape:straight,waterlogged:false}"},
        {pos: [7, 8, 5], state: "minecraft:acacia_stairs{facing:west,half:bottom,shape:straight,waterlogged:false}"},
        {pos: [7, 8, 6], state: "minecraft:acacia_stairs{facing:north,half:bottom,shape:outer_left,waterlogged:false}"}
    ],
    entities: [],
    palette: [
        "minecraft:grass_block{snowy:false}",
        "minecraft:dirt",
        "minecraft:acacia_planks",
        "minecraft:acacia_wood{axis:x}",
        "minecraft:acacia_wood{axis:y}",
        "minecraft:acacia_wood{axis:z}",
        "minecraft:short_grass",
        "minecraft:air",
        "minecraft:acacia_stairs{facing:east,half:bottom,shape:straight,waterlogged:false}",
        "minecraft:acacia_fence{east:true,north:false,south:true,waterlogged:false,west:false}",
        "minecraft:acacia_fence{east:true,north:true,south:false,waterlogged:false,west:false}",
        "minecraft:acacia_fence{east:true,north:false,south:false,waterlogged:false,west:true}",
        "minecraft:acacia_fence{east:false,north:true,south:true,waterlogged:false,west:false}",
        "minecraft:acacia_fence{east:false,north:true,south:false,waterlogged:false,west:true}",
        "minecraft:acacia_fence{east:false,north:false,south:false,waterlogged:false,west:false}",
        "minecraft:acacia_fence{east:false,north:false,south:true,waterlogged:false,west:true}",
        "minecraft:torch",
        "minecraft:acacia_slab{type:top,waterlogged:false}",
        "minecraft:acacia_stairs{facing:west,half:bottom,shape:straight,waterlogged:false}",
        "minecraft:acacia_stairs{facing:north,half:bottom,shape:straight,waterlogged:false}",
        "minecraft:acacia_door{facing:west,half:lower,hinge:left,open:false,powered:false}",
        "minecraft:acacia_door{facing:east,half:lower,hinge:right,open:false,powered:false}",
        "minecraft:wall_torch{facing:west}",
        "minecraft:acacia_door{facing:west,half:upper,hinge:left,open:false,powered:false}",
        "minecraft:glass_pane{east:true,north:false,south:false,waterlogged:false,west:true}",
        "minecraft:acacia_door{facing:east,half:upper,hinge:right,open:false,powered:false}",
        "minecraft:wall_torch{facing:east}",
        "minecraft:acacia_stairs{facing:south,half:bottom,shape:straight,waterlogged:false}",
        "minecraft:acacia_stairs{facing:east,half:bottom,shape:outer_right,waterlogged:false}",
        "minecraft:acacia_stairs{facing:north,half:bottom,shape:outer_right,waterlogged:false}",
        "minecraft:acacia_stairs{facing:west,half:bottom,shape:outer_left,waterlogged:false}",
        "minecraft:acacia_stairs{facing:north,half:bottom,shape:outer_left,waterlogged:false}",
        "minecraft:jigsaw{orientation:up_north}",
        "minecraft:jigsaw{orientation:west_up}",
        "minecraft:chest{facing:north,type:single,waterlogged:false}",
        "minecraft:smoker{facing:east,lit:false}"
    ]
}
