{
    DataVersion: 2856,
    size: [6, 7, 9],
    data: [
        {pos: [0, 0, 0], state: "minecraft:dirt"},
        {pos: [0, 0, 3], state: "minecraft:grass_block{snowy:false}"},
        {pos: [0, 0, 4], state: "minecraft:grass_block{snowy:false}"},
        {pos: [0, 0, 5], state: "minecraft:grass_block{snowy:false}"},
        {pos: [0, 0, 6], state: "minecraft:dirt"},
        {pos: [0, 0, 7], state: "minecraft:grass_block{snowy:false}"},
        {pos: [0, 0, 8], state: "minecraft:grass_block{snowy:false}"},
        {pos: [1, 0, 0], state: "minecraft:dirt"},
        {pos: [1, 0, 1], state: "minecraft:dirt"},
        {pos: [1, 0, 2], state: "minecraft:grass_block{snowy:false}"},
        {pos: [1, 0, 3], state: "minecraft:grass_block{snowy:false}"},
        {pos: [1, 0, 4], state: "minecraft:grass_block{snowy:false}"},
        {pos: [1, 0, 5], state: "minecraft:grass_block{snowy:false}"},
        {pos: [1, 0, 6], state: "minecraft:grass_block{snowy:false}"},
        {pos: [1, 0, 7], state: "minecraft:grass_block{snowy:false}"},
        {pos: [1, 0, 8], state: "minecraft:dirt"},
        {pos: [2, 0, 0], state: "minecraft:grass_block{snowy:false}"},
        {pos: [2, 0, 1], state: "minecraft:grass_block{snowy:false}"},
        {pos: [2, 0, 2], state: "minecraft:grass_block{snowy:false}"},
        {pos: [2, 0, 3], state: "minecraft:grass_block{snowy:false}"},
        {pos: [2, 0, 4], state: "minecraft:dirt"},
        {pos: [2, 0, 5], state: "minecraft:grass_block{snowy:false}"},
        {pos: [2, 0, 6], state: "minecraft:grass_block{snowy:false}"},
        {pos: [2, 0, 7], state: "minecraft:grass_block{snowy:false}"},
        {pos: [2, 0, 8], state: "minecraft:grass_block{snowy:false}"},
        {pos: [3, 0, 0], state: "minecraft:grass_block{snowy:false}"},
        {pos: [3, 0, 1], state: "minecraft:grass_block{snowy:false}"},
        {pos: [3, 0, 2], state: "minecraft:grass_block{snowy:false}"},
        {pos: [3, 0, 3], state: "minecraft:grass_block{snowy:false}"},
        {pos: [3, 0, 4], state: "minecraft:grass_block{snowy:false}"},
        {pos: [3, 0, 5], state: "minecraft:grass_block{snowy:false}"},
        {pos: [3, 0, 6], state: "minecraft:grass_block{snowy:false}"},
        {pos: [3, 0, 7], state: "minecraft:grass_block{snowy:false}"},
        {pos: [3, 0, 8], state: "minecraft:grass_block{snowy:false}"},
        {pos: [4, 0, 0], state: "minecraft:grass_block{snowy:false}"},
        {pos: [4, 0, 1], state: "minecraft:grass_block{snowy:false}"},
        {pos: [4, 0, 2], state: "minecraft:grass_block{snowy:false}"},
        {pos: [4, 0, 3], state: "minecraft:grass_block{snowy:false}"},
        {pos: [4, 0, 4], state: "minecraft:grass_block{snowy:false}"},
        {pos: [4, 0, 5], state: "minecraft:dirt"},
        {pos: [4, 0, 6], state: "minecraft:grass_block{snowy:false}"},
        {pos: [4, 0, 7], state: "minecraft:dirt"},
        {pos: [4, 0, 8], state: "minecraft:dirt"},
        {pos: [5, 0, 0], state: "minecraft:grass_block{snowy:false}"},
        {pos: [5, 0, 1], state: "minecraft:grass_block{snowy:false}"},
        {pos: [5, 0, 2], state: "minecraft:dirt"},
        {pos: [5, 0, 3], state: "minecraft:grass_block{snowy:false}"},
        {pos: [5, 0, 4], state: "minecraft:grass_block{snowy:false}"},
        {pos: [5, 0, 5], state: "minecraft:dirt"},
        {pos: [5, 0, 7], state: "minecraft:dirt"},
        {pos: [0, 1, 0], state: "minecraft:grass_block{snowy:false}"},
        {pos: [0, 1, 3], state: "minecraft:farmland{moisture:7}"},
        {pos: [0, 1, 4], state: "minecraft:farmland{moisture:7}"},
        {pos: [0, 1, 5], state: "minecraft:farmland{moisture:7}"},
        {pos: [0, 1, 6], state: "minecraft:grass_block{snowy:false}"},
        {pos: [0, 1, 7], state: "minecraft:farmland{moisture:7}"},
        {pos: [0, 1, 8], state: "minecraft:farmland{moisture:7}"},
        {pos: [1, 1, 0], state: "minecraft:dirt"},
        {pos: [1, 1, 1], state: "minecraft:grass_block{snowy:false}"},
        {pos: [1, 1, 2], state: "minecraft:farmland{moisture:7}"},
        {pos: [1, 1, 3], state: "minecraft:farmland{moisture:7}"},
        {pos: [1, 1, 4], state: "minecraft:farmland{moisture:7}"},
        {pos: [1, 1, 5], state: "minecraft:farmland{moisture:7}"},
        {pos: [1, 1, 6], state: "minecraft:farmland{moisture:7}"},
        {pos: [1, 1, 7], state: "minecraft:farmland{moisture:7}"},
        {pos: [1, 1, 8], state: "minecraft:grass_block{snowy:false}"},
        {pos: [2, 1, 0], state: "minecraft:farmland{moisture:7}"},
        {pos: [2, 1, 1], state: "minecraft:farmland{moisture:7}"},
        {pos: [2, 1, 2], state: "minecraft:water{level:0}"},
        {pos: [2, 1, 3], state: "minecraft:farmland{moisture:7}"},
        {pos: [2, 1, 4], state: "minecraft:grass_block{snowy:false}"},
        {pos: [2, 1, 5], state: "minecraft:water{level:0}"},
        {pos: [2, 1, 6], state: "minecraft:farmland{moisture:7}"},
        {pos: [2, 1, 7], state: "minecraft:farmland{moisture:7}"},
        {pos: [2, 1, 8], state: "minecraft:farmland{moisture:7}"},
        {pos: [3, 1, 0], state: "minecraft:farmland{moisture:7}"},
        {pos: [3, 1, 1], state: "minecraft:farmland{moisture:7}"},
        {pos: [3, 1, 2], state: "minecraft:farmland{moisture:7}"},
        {pos: [3, 1, 3], state: "minecraft:farmland{moisture:7}"},
        {pos: [3, 1, 4], state: "minecraft:farmland{moisture:7}"},
        {pos: [3, 1, 5], state: "minecraft:farmland{moisture:7}"},
        {pos: [3, 1, 6], state: "minecraft:farmland{moisture:7}"},
        {pos: [3, 1, 7], state: "minecraft:farmland{moisture:7}"},
        {pos: [3, 1, 8], state: "minecraft:farmland{moisture:7}"},
        {pos: [4, 1, 0], state: "minecraft:farmland{moisture:0}"},
        {pos: [4, 1, 1], state: "minecraft:water{level:0}"},
        {pos: [4, 1, 2], state: "minecraft:farmland{moisture:7}"},
        {pos: [4, 1, 3], state: "minecraft:farmland{moisture:7}"},
        {pos: [4, 1, 4], state: "minecraft:farmland{moisture:7}"},
        {pos: [4, 1, 5], state: "minecraft:grass_block{snowy:false}"},
        {pos: [4, 1, 6], state: "minecraft:farmland{moisture:7}"},
        {pos: [4, 1, 7], state: "minecraft:grass_block{snowy:false}"},
        {pos: [4, 1, 8], state: "minecraft:dirt"},
        {pos: [5, 1, 0], state: "minecraft:farmland{moisture:7}"},
        {pos: [5, 1, 1], state: "minecraft:farmland{moisture:7}"},
        {pos: [5, 1, 2], state: "minecraft:grass_block{snowy:false}"},
        {pos: [5, 1, 3], state: "minecraft:farmland{moisture:7}"},
        {pos: [5, 1, 4], state: "minecraft:farmland{moisture:7}"},
        {pos: [5, 1, 5], state: "minecraft:grass_block{snowy:false}"},
        {pos: [5, 1, 7], state: "minecraft:grass_block{snowy:false}"},
        {pos: [0, 2, 0], state: "minecraft:tall_grass{half:lower}"},
        {pos: [0, 2, 1], state: "minecraft:air"},
        {pos: [0, 2, 2], state: "minecraft:air"},
        {pos: [0, 2, 3], state: "minecraft:wheat{age:7}"},
        {pos: [0, 2, 4], state: "minecraft:wheat{age:7}"},
        {pos: [0, 2, 5], state: "minecraft:wheat{age:6}"},
        {pos: [0, 2, 6], state: "minecraft:tall_grass{half:lower}"},
        {pos: [0, 2, 7], state: "minecraft:wheat{age:5}"},
        {pos: [0, 2, 8], state: "minecraft:wheat{age:6}"},
        {pos: [1, 2, 0], state: "minecraft:jigsaw{orientation:north_up}", nbt: {final_state: "minecraft:structure_void", id: "minecraft:jigsaw", joint: "aligned", name: "minecraft:building_entrance", pool: "minecraft:empty", target: "minecraft:building_entrance"}},
        {pos: [1, 2, 1], state: "minecraft:tall_grass{half:lower}"},
        {pos: [1, 2, 2], state: "minecraft:wheat{age:7}"},
        {pos: [1, 2, 3], state: "minecraft:wheat{age:7}"},
        {pos: [1, 2, 4], state: "minecraft:wheat{age:7}"},
        {pos: [1, 2, 5], state: "minecraft:wheat{age:5}"},
        {pos: [1, 2, 6], state: "minecraft:wheat{age:7}"},
        {pos: [1, 2, 7], state: "minecraft:wheat{age:7}"},
        {pos: [1, 2, 8], state: "minecraft:grass"},
        {pos: [2, 2, 0], state: "minecraft:wheat{age:0}"},
        {pos: [2, 2, 1], state: "minecraft:wheat{age:1}"},
        {pos: [2, 2, 2], state: "minecraft:air"},
        {pos: [2, 2, 3], state: "minecraft:wheat{age:7}"},
        {pos: [2, 2, 4], state: "minecraft:tall_grass{half:lower}"},
        {pos: [2, 2, 5], state: "minecraft:air"},
        {pos: [2, 2, 6], state: "minecraft:wheat{age:0}"},
        {pos: [2, 2, 7], state: "minecraft:wheat{age:0}"},
        {pos: [2, 2, 8], state: "minecraft:wheat{age:0}"},
        {pos: [3, 2, 0], state: "minecraft:wheat{age:1}"},
        {pos: [3, 2, 1], state: "minecraft:wheat{age:7}"},
        {pos: [3, 2, 2], state: "minecraft:wheat{age:7}"},
        {pos: [3, 2, 3], state: "minecraft:wheat{age:0}"},
        {pos: [3, 2, 4], state: "minecraft:wheat{age:1}"},
        {pos: [3, 2, 5], state: "minecraft:wheat{age:7}"},
        {pos: [3, 2, 6], state: "minecraft:wheat{age:7}"},
        {pos: [3, 2, 7], state: "minecraft:wheat{age:0}"},
        {pos: [3, 2, 8], state: "minecraft:wheat{age:0}"},
        {pos: [4, 2, 0], state: "minecraft:wheat{age:0}"},
        {pos: [4, 2, 1], state: "minecraft:air"},
        {pos: [4, 2, 2], state: "minecraft:wheat{age:0}"},
        {pos: [4, 2, 3], state: "minecraft:wheat{age:7}"},
        {pos: [4, 2, 4], state: "minecraft:wheat{age:7}"},
        {pos: [4, 2, 5], state: "minecraft:composter{level:0}"},
        {pos: [4, 2, 6], state: "minecraft:wheat{age:7}"},
        {pos: [4, 2, 7], state: "minecraft:tall_grass{half:lower}"},
        {pos: [4, 2, 8], state: "minecraft:melon"},
        {pos: [5, 2, 0], state: "minecraft:wheat{age:7}"},
        {pos: [5, 2, 1], state: "minecraft:wheat{age:7}"},
        {pos: [5, 2, 2], state: "minecraft:tall_grass{half:lower}"},
        {pos: [5, 2, 3], state: "minecraft:wheat{age:7}"},
        {pos: [5, 2, 4], state: "minecraft:wheat{age:7}"},
        {pos: [5, 2, 5], state: "minecraft:tall_grass{half:lower}"},
        {pos: [5, 2, 6], state: "minecraft:air"},
        {pos: [5, 2, 7], state: "minecraft:grass"},
        {pos: [5, 2, 8], state: "minecraft:air"},
        {pos: [0, 3, 0], state: "minecraft:tall_grass{half:upper}"},
        {pos: [0, 3, 1], state: "minecraft:air"},
        {pos: [0, 3, 2], state: "minecraft:air"},
        {pos: [0, 3, 3], state: "minecraft:air"},
        {pos: [0, 3, 4], state: "minecraft:air"},
        {pos: [0, 3, 5], state: "minecraft:air"},
        {pos: [0, 3, 6], state: "minecraft:tall_grass{half:upper}"},
        {pos: [0, 3, 7], state: "minecraft:air"},
        {pos: [0, 3, 8], state: "minecraft:air"},
        {pos: [1, 3, 0], state: "minecraft:air"},
        {pos: [1, 3, 1], state: "minecraft:tall_grass{half:upper}"},
        {pos: [1, 3, 2], state: "minecraft:air"},
        {pos: [1, 3, 3], state: "minecraft:air"},
        {pos: [1, 3, 4], state: "minecraft:air"},
        {pos: [1, 3, 5], state: "minecraft:air"},
        {pos: [1, 3, 6], state: "minecraft:air"},
        {pos: [1, 3, 7], state: "minecraft:air"},
        {pos: [1, 3, 8], state: "minecraft:air"},
        {pos: [2, 3, 0], state: "minecraft:air"},
        {pos: [2, 3, 1], state: "minecraft:air"},
        {pos: [2, 3, 2], state: "minecraft:air"},
        {pos: [2, 3, 3], state: "minecraft:air"},
        {pos: [2, 3, 4], state: "minecraft:tall_grass{half:upper}"},
        {pos: [2, 3, 5], state: "minecraft:air"},
        {pos: [2, 3, 6], state: "minecraft:air"},
        {pos: [2, 3, 7], state: "minecraft:air"},
        {pos: [2, 3, 8], state: "minecraft:air"},
        {pos: [3, 3, 0], state: "minecraft:air"},
        {pos: [3, 3, 1], state: "minecraft:air"},
        {pos: [3, 3, 2], state: "minecraft:air"},
        {pos: [3, 3, 3], state: "minecraft:air"},
        {pos: [3, 3, 4], state: "minecraft:air"},
        {pos: [3, 3, 5], state: "minecraft:air"},
        {pos: [3, 3, 6], state: "minecraft:air"},
        {pos: [3, 3, 7], state: "minecraft:air"},
        {pos: [3, 3, 8], state: "minecraft:air"},
        {pos: [4, 3, 0], state: "minecraft:air"},
        {pos: [4, 3, 1], state: "minecraft:air"},
        {pos: [4, 3, 2], state: "minecraft:air"},
        {pos: [4, 3, 3], state: "minecraft:air"},
        {pos: [4, 3, 4], state: "minecraft:air"},
        {pos: [4, 3, 5], state: "minecraft:air"},
        {pos: [4, 3, 6], state: "minecraft:air"},
        {pos: [4, 3, 7], state: "minecraft:tall_grass{half:upper}"},
        {pos: [4, 3, 8], state: "minecraft:air"},
        {pos: [5, 3, 0], state: "minecraft:air"},
        {pos: [5, 3, 1], state: "minecraft:air"},
        {pos: [5, 3, 2], state: "minecraft:tall_grass{half:upper}"},
        {pos: [5, 3, 3], state: "minecraft:air"},
        {pos: [5, 3, 4], state: "minecraft:air"},
        {pos: [5, 3, 5], state: "minecraft:tall_grass{half:upper}"},
        {pos: [5, 3, 6], state: "minecraft:air"},
        {pos: [5, 3, 7], state: "minecraft:air"},
        {pos: [5, 3, 8], state: "minecraft:air"}
    ],
    entities: [],
    palette: [
        "minecraft:dirt",
        "minecraft:grass_block{snowy:false}",
        "minecraft:melon",
        "minecraft:farmland{moisture:7}",
        "minecraft:water{level:0}",
        "minecraft:farmland{moisture:0}",
        "minecraft:tall_grass{half:lower}",
        "minecraft:air",
        "minecraft:wheat{age:7}",
        "minecraft:wheat{age:6}",
        "minecraft:wheat{age:5}",
        "minecraft:grass",
        "minecraft:wheat{age:0}",
        "minecraft:wheat{age:1}",
        "minecraft:composter{level:0}",
        "minecraft:tall_grass{half:upper}",
        "minecraft:jigsaw{orientation:north_up}"
    ]
}
