{
    size: [9, 6, 9],
    data: [
        {pos: [0, 0, 0], state: "minecraft:grass_block{snowy:false}"},
        {pos: [0, 0, 1], state: "minecraft:dirt"},
        {pos: [0, 0, 2], state: "minecraft:dirt"},
        {pos: [0, 0, 3], state: "minecraft:dirt"},
        {pos: [0, 0, 4], state: "minecraft:grass_block{snowy:false}"},
        {pos: [0, 0, 5], state: "minecraft:dirt"},
        {pos: [0, 0, 6], state: "minecraft:dirt"},
        {pos: [0, 0, 7], state: "minecraft:dirt"},
        {pos: [0, 0, 8], state: "minecraft:grass_block{snowy:false}"},
        {pos: [1, 0, 0], state: "minecraft:dirt"},
        {pos: [1, 0, 1], state: "minecraft:grass_block{snowy:false}"},
        {pos: [1, 0, 2], state: "minecraft:grass_block{snowy:false}"},
        {pos: [1, 0, 3], state: "minecraft:grass_block{snowy:false}"},
        {pos: [1, 0, 4], state: "minecraft:dirt"},
        {pos: [1, 0, 5], state: "minecraft:grass_block{snowy:false}"},
        {pos: [1, 0, 6], state: "minecraft:grass_block{snowy:false}"},
        {pos: [1, 0, 7], state: "minecraft:grass_block{snowy:false}"},
        {pos: [1, 0, 8], state: "minecraft:dirt"},
        {pos: [2, 0, 0], state: "minecraft:dirt"},
        {pos: [2, 0, 1], state: "minecraft:grass_block{snowy:false}"},
        {pos: [2, 0, 2], state: "minecraft:grass_block{snowy:false}"},
        {pos: [2, 0, 3], state: "minecraft:grass_block{snowy:false}"},
        {pos: [2, 0, 4], state: "minecraft:dirt"},
        {pos: [2, 0, 5], state: "minecraft:grass_block{snowy:false}"},
        {pos: [2, 0, 6], state: "minecraft:grass_block{snowy:false}"},
        {pos: [2, 0, 7], state: "minecraft:grass_block{snowy:false}"},
        {pos: [2, 0, 8], state: "minecraft:dirt"},
        {pos: [3, 0, 0], state: "minecraft:dirt"},
        {pos: [3, 0, 1], state: "minecraft:grass_block{snowy:false}"},
        {pos: [3, 0, 2], state: "minecraft:grass_block{snowy:false}"},
        {pos: [3, 0, 3], state: "minecraft:grass_block{snowy:false}"},
        {pos: [3, 0, 4], state: "minecraft:dirt"},
        {pos: [3, 0, 5], state: "minecraft:grass_block{snowy:false}"},
        {pos: [3, 0, 6], state: "minecraft:grass_block{snowy:false}"},
        {pos: [3, 0, 7], state: "minecraft:grass_block{snowy:false}"},
        {pos: [3, 0, 8], state: "minecraft:dirt"},
        {pos: [4, 0, 0], state: "minecraft:grass_block{snowy:false}"},
        {pos: [4, 0, 1], state: "minecraft:dirt"},
        {pos: [4, 0, 2], state: "minecraft:dirt"},
        {pos: [4, 0, 3], state: "minecraft:dirt"},
        {pos: [4, 0, 4], state: "minecraft:dirt"},
        {pos: [4, 0, 5], state: "minecraft:dirt"},
        {pos: [4, 0, 6], state: "minecraft:dirt"},
        {pos: [4, 0, 7], state: "minecraft:dirt"},
        {pos: [4, 0, 8], state: "minecraft:grass_block{snowy:false}"},
        {pos: [5, 0, 0], state: "minecraft:dirt"},
        {pos: [5, 0, 1], state: "minecraft:grass_block{snowy:false}"},
        {pos: [5, 0, 2], state: "minecraft:grass_block{snowy:false}"},
        {pos: [5, 0, 3], state: "minecraft:grass_block{snowy:false}"},
        {pos: [5, 0, 4], state: "minecraft:dirt"},
        {pos: [5, 0, 5], state: "minecraft:grass_block{snowy:false}"},
        {pos: [5, 0, 6], state: "minecraft:grass_block{snowy:false}"},
        {pos: [5, 0, 7], state: "minecraft:grass_block{snowy:false}"},
        {pos: [5, 0, 8], state: "minecraft:dirt"},
        {pos: [6, 0, 0], state: "minecraft:dirt"},
        {pos: [6, 0, 1], state: "minecraft:grass_block{snowy:false}"},
        {pos: [6, 0, 2], state: "minecraft:grass_block{snowy:false}"},
        {pos: [6, 0, 3], state: "minecraft:grass_block{snowy:false}"},
        {pos: [6, 0, 4], state: "minecraft:dirt"},
        {pos: [6, 0, 5], state: "minecraft:grass_block{snowy:false}"},
        {pos: [6, 0, 6], state: "minecraft:grass_block{snowy:false}"},
        {pos: [6, 0, 7], state: "minecraft:grass_block{snowy:false}"},
        {pos: [6, 0, 8], state: "minecraft:dirt"},
        {pos: [7, 0, 0], state: "minecraft:dirt"},
        {pos: [7, 0, 1], state: "minecraft:grass_block{snowy:false}"},
        {pos: [7, 0, 2], state: "minecraft:grass_block{snowy:false}"},
        {pos: [7, 0, 3], state: "minecraft:grass_block{snowy:false}"},
        {pos: [7, 0, 4], state: "minecraft:dirt"},
        {pos: [7, 0, 5], state: "minecraft:grass_block{snowy:false}"},
        {pos: [7, 0, 6], state: "minecraft:grass_block{snowy:false}"},
        {pos: [7, 0, 7], state: "minecraft:grass_block{snowy:false}"},
        {pos: [7, 0, 8], state: "minecraft:dirt"},
        {pos: [8, 0, 0], state: "minecraft:grass_block{snowy:false}"},
        {pos: [8, 0, 1], state: "minecraft:dirt"},
        {pos: [8, 0, 2], state: "minecraft:dirt"},
        {pos: [8, 0, 3], state: "minecraft:dirt"},
        {pos: [8, 0, 4], state: "minecraft:grass_block{snowy:false}"},
        {pos: [8, 0, 5], state: "minecraft:dirt"},
        {pos: [8, 0, 6], state: "minecraft:dirt"},
        {pos: [8, 0, 7], state: "minecraft:dirt"},
        {pos: [8, 0, 8], state: "minecraft:grass_block{snowy:false}"},
        {pos: [0, 1, 0], state: "minecraft:composter{level:0}"},
        {pos: [0, 1, 1], state: "minecraft:acacia_log{axis:y}"},
        {pos: [0, 1, 2], state: "minecraft:acacia_log{axis:y}"},
        {pos: [0, 1, 3], state: "minecraft:acacia_log{axis:y}"},
        {pos: [0, 1, 4], state: "minecraft:acacia_stairs{facing:east,half:bottom,shape:straight,waterlogged:false}"},
        {pos: [0, 1, 5], state: "minecraft:acacia_log{axis:y}"},
        {pos: [0, 1, 6], state: "minecraft:acacia_log{axis:y}"},
        {pos: [0, 1, 7], state: "minecraft:acacia_log{axis:y}"},
        {pos: [0, 1, 8], state: "minecraft:short_grass"},
        {pos: [1, 1, 0], state: "minecraft:acacia_log{axis:y}"},
        {pos: [1, 1, 1], state: "minecraft:farmland{moisture:7}"},
        {pos: [1, 1, 2], state: "minecraft:farmland{moisture:7}"},
        {pos: [1, 1, 3], state: "minecraft:farmland{moisture:7}"},
        {pos: [1, 1, 4], state: "minecraft:acacia_planks"},
        {pos: [1, 1, 5], state: "minecraft:farmland{moisture:7}"},
        {pos: [1, 1, 6], state: "minecraft:farmland{moisture:7}"},
        {pos: [1, 1, 7], state: "minecraft:farmland{moisture:7}"},
        {pos: [1, 1, 8], state: "minecraft:acacia_log{axis:y}"},
        {pos: [2, 1, 0], state: "minecraft:acacia_log{axis:y}"},
        {pos: [2, 1, 1], state: "minecraft:farmland{moisture:7}"},
        {pos: [2, 1, 2], state: "minecraft:farmland{moisture:7}"},
        {pos: [2, 1, 3], state: "minecraft:farmland{moisture:7}"},
        {pos: [2, 1, 4], state: "minecraft:acacia_planks"},
        {pos: [2, 1, 5], state: "minecraft:farmland{moisture:7}"},
        {pos: [2, 1, 6], state: "minecraft:farmland{moisture:7}"},
        {pos: [2, 1, 7], state: "minecraft:farmland{moisture:7}"},
        {pos: [2, 1, 8], state: "minecraft:acacia_log{axis:y}"},
        {pos: [3, 1, 0], state: "minecraft:acacia_log{axis:y}"},
        {pos: [3, 1, 1], state: "minecraft:farmland{moisture:7}"},
        {pos: [3, 1, 2], state: "minecraft:farmland{moisture:7}"},
        {pos: [3, 1, 3], state: "minecraft:water{level:0}"},
        {pos: [3, 1, 4], state: "minecraft:acacia_planks"},
        {pos: [3, 1, 5], state: "minecraft:water{level:0}"},
        {pos: [3, 1, 6], state: "minecraft:farmland{moisture:7}"},
        {pos: [3, 1, 7], state: "minecraft:farmland{moisture:7}"},
        {pos: [3, 1, 8], state: "minecraft:jigsaw{orientation:south_up}", nbt: {final_state: "minecraft:acacia_log", id: "minecraft:jigsaw", joint: "aligned", name: "minecraft:building_entrance", pool: "minecraft:empty", target: "minecraft:building_entrance"}},
        {pos: [4, 1, 0], state: "minecraft:acacia_stairs{facing:south,half:bottom,shape:straight,waterlogged:false}"},
        {pos: [4, 1, 1], state: "minecraft:acacia_planks"},
        {pos: [4, 1, 2], state: "minecraft:acacia_planks"},
        {pos: [4, 1, 3], state: "minecraft:acacia_planks"},
        {pos: [4, 1, 4], state: "minecraft:acacia_planks"},
        {pos: [4, 1, 5], state: "minecraft:acacia_planks"},
        {pos: [4, 1, 6], state: "minecraft:acacia_planks"},
        {pos: [4, 1, 7], state: "minecraft:acacia_planks"},
        {pos: [4, 1, 8], state: "minecraft:acacia_stairs{facing:north,half:bottom,shape:straight,waterlogged:false}"},
        {pos: [5, 1, 0], state: "minecraft:acacia_log{axis:y}"},
        {pos: [5, 1, 1], state: "minecraft:farmland{moisture:7}"},
        {pos: [5, 1, 2], state: "minecraft:farmland{moisture:7}"},
        {pos: [5, 1, 3], state: "minecraft:water{level:0}"},
        {pos: [5, 1, 4], state: "minecraft:acacia_planks"},
        {pos: [5, 1, 5], state: "minecraft:water{level:0}"},
        {pos: [5, 1, 6], state: "minecraft:farmland{moisture:7}"},
        {pos: [5, 1, 7], state: "minecraft:farmland{moisture:7}"},
        {pos: [5, 1, 8], state: "minecraft:acacia_log{axis:y}"},
        {pos: [6, 1, 0], state: "minecraft:acacia_log{axis:y}"},
        {pos: [6, 1, 1], state: "minecraft:farmland{moisture:7}"},
        {pos: [6, 1, 2], state: "minecraft:farmland{moisture:7}"},
        {pos: [6, 1, 3], state: "minecraft:farmland{moisture:7}"},
        {pos: [6, 1, 4], state: "minecraft:acacia_planks"},
        {pos: [6, 1, 5], state: "minecraft:farmland{moisture:7}"},
        {pos: [6, 1, 6], state: "minecraft:farmland{moisture:7}"},
        {pos: [6, 1, 7], state: "minecraft:farmland{moisture:7}"},
        {pos: [6, 1, 8], state: "minecraft:acacia_log{axis:y}"},
        {pos: [7, 1, 0], state: "minecraft:acacia_log{axis:y}"},
        {pos: [7, 1, 1], state: "minecraft:farmland{moisture:7}"},
        {pos: [7, 1, 2], state: "minecraft:farmland{moisture:7}"},
        {pos: [7, 1, 3], state: "minecraft:farmland{moisture:7}"},
        {pos: [7, 1, 4], state: "minecraft:acacia_planks"},
        {pos: [7, 1, 5], state: "minecraft:farmland{moisture:7}"},
        {pos: [7, 1, 6], state: "minecraft:farmland{moisture:7}"},
        {pos: [7, 1, 7], state: "minecraft:farmland{moisture:7}"},
        {pos: [7, 1, 8], state: "minecraft:acacia_log{axis:y}"},
        {pos: [8, 1, 0], state: "minecraft:air"},
        {pos: [8, 1, 1], state: "minecraft:acacia_log{axis:y}"},
        {pos: [8, 1, 2], state: "minecraft:acacia_log{axis:y}"},
        {pos: [8, 1, 3], state: "minecraft:acacia_log{axis:y}"},
        {pos: [8, 1, 4], state: "minecraft:acacia_stairs{facing:west,half:bottom,shape:straight,waterlogged:false}"},
        {pos: [8, 1, 5], state: "minecraft:acacia_log{axis:y}"},
        {pos: [8, 1, 6], state: "minecraft:acacia_log{axis:y}"},
        {pos: [8, 1, 7], state: "minecraft:acacia_log{axis:y}"},
        {pos: [8, 1, 8], state: "minecraft:composter{level:0}"},
        {pos: [0, 2, 0], state: "minecraft:air"},
        {pos: [0, 2, 1], state: "minecraft:air"},
        {pos: [0, 2, 2], state: "minecraft:air"},
        {pos: [0, 2, 3], state: "minecraft:air"},
        {pos: [0, 2, 4], state: "minecraft:air"},
        {pos: [0, 2, 5], state: "minecraft:air"},
        {pos: [0, 2, 6], state: "minecraft:air"},
        {pos: [0, 2, 7], state: "minecraft:air"},
        {pos: [0, 2, 8], state: "minecraft:air"},
        {pos: [1, 2, 0], state: "minecraft:air"},
        {pos: [1, 2, 1], state: "minecraft:wheat{age:7}"},
        {pos: [1, 2, 2], state: "minecraft:wheat{age:7}"},
        {pos: [1, 2, 3], state: "minecraft:wheat{age:7}"},
        {pos: [1, 2, 4], state: "minecraft:air"},
        {pos: [1, 2, 5], state: "minecraft:wheat{age:7}"},
        {pos: [1, 2, 6], state: "minecraft:wheat{age:7}"},
        {pos: [1, 2, 7], state: "minecraft:wheat{age:7}"},
        {pos: [1, 2, 8], state: "minecraft:air"},
        {pos: [2, 2, 0], state: "minecraft:air"},
        {pos: [2, 2, 1], state: "minecraft:wheat{age:7}"},
        {pos: [2, 2, 2], state: "minecraft:wheat{age:7}"},
        {pos: [2, 2, 3], state: "minecraft:wheat{age:7}"},
        {pos: [2, 2, 4], state: "minecraft:air"},
        {pos: [2, 2, 5], state: "minecraft:wheat{age:7}"},
        {pos: [2, 2, 6], state: "minecraft:wheat{age:7}"},
        {pos: [2, 2, 7], state: "minecraft:wheat{age:7}"},
        {pos: [2, 2, 8], state: "minecraft:air"},
        {pos: [3, 2, 0], state: "minecraft:air"},
        {pos: [3, 2, 1], state: "minecraft:wheat{age:7}"},
        {pos: [3, 2, 2], state: "minecraft:wheat{age:7}"},
        {pos: [3, 2, 3], state: "minecraft:air"},
        {pos: [3, 2, 4], state: "minecraft:air"},
        {pos: [3, 2, 5], state: "minecraft:air"},
        {pos: [3, 2, 6], state: "minecraft:wheat{age:7}"},
        {pos: [3, 2, 7], state: "minecraft:wheat{age:7}"},
        {pos: [3, 2, 8], state: "minecraft:air"},
        {pos: [4, 2, 0], state: "minecraft:air"},
        {pos: [4, 2, 1], state: "minecraft:air"},
        {pos: [4, 2, 2], state: "minecraft:air"},
        {pos: [4, 2, 3], state: "minecraft:air"},
        {pos: [4, 2, 4], state: "minecraft:air"},
        {pos: [4, 2, 5], state: "minecraft:air"},
        {pos: [4, 2, 6], state: "minecraft:air"},
        {pos: [4, 2, 7], state: "minecraft:air"},
        {pos: [4, 2, 8], state: "minecraft:air"},
        {pos: [5, 2, 0], state: "minecraft:air"},
        {pos: [5, 2, 1], state: "minecraft:wheat{age:7}"},
        {pos: [5, 2, 2], state: "minecraft:wheat{age:7}"},
        {pos: [5, 2, 3], state: "minecraft:air"},
        {pos: [5, 2, 4], state: "minecraft:air"},
        {pos: [5, 2, 5], state: "minecraft:air"},
        {pos: [5, 2, 6], state: "minecraft:wheat{age:7}"},
        {pos: [5, 2, 7], state: "minecraft:wheat{age:7}"},
        {pos: [5, 2, 8], state: "minecraft:air"},
        {pos: [6, 2, 0], state: "minecraft:air"},
        {pos: [6, 2, 1], state: "minecraft:wheat{age:7}"},
        {pos: [6, 2, 2], state: "minecraft:wheat{age:7}"},
        {pos: [6, 2, 3], state: "minecraft:wheat{age:7}"},
        {pos: [6, 2, 4], state: "minecraft:air"},
        {pos: [6, 2, 5], state: "minecraft:wheat{age:7}"},
        {pos: [6, 2, 6], state: "minecraft:wheat{age:7}"},
        {pos: [6, 2, 7], state: "minecraft:wheat{age:7}"},
        {pos: [6, 2, 8], state: "minecraft:air"},
        {pos: [7, 2, 0], state: "minecraft:air"},
        {pos: [7, 2, 1], state: "minecraft:wheat{age:7}"},
        {pos: [7, 2, 2], state: "minecraft:wheat{age:7}"},
        {pos: [7, 2, 3], state: "minecraft:wheat{age:7}"},
        {pos: [7, 2, 4], state: "minecraft:air"},
        {pos: [7, 2, 5], state: "minecraft:wheat{age:7}"},
        {pos: [7, 2, 6], state: "minecraft:wheat{age:7}"},
        {pos: [7, 2, 7], state: "minecraft:wheat{age:7}"},
        {pos: [7, 2, 8], state: "minecraft:air"},
        {pos: [8, 2, 0], state: "minecraft:air"},
        {pos: [8, 2, 1], state: "minecraft:air"},
        {pos: [8, 2, 2], state: "minecraft:air"},
        {pos: [8, 2, 3], state: "minecraft:air"},
        {pos: [8, 2, 4], state: "minecraft:air"},
        {pos: [8, 2, 5], state: "minecraft:air"},
        {pos: [8, 2, 6], state: "minecraft:air"},
        {pos: [8, 2, 7], state: "minecraft:air"},
        {pos: [8, 2, 8], state: "minecraft:air"}
    ],
    entities: [],
    palette: [
        "minecraft:grass_block{snowy:false}",
        "minecraft:dirt",
        "minecraft:acacia_log{axis:y}",
        "minecraft:acacia_planks",
        "minecraft:composter{level:0}",
        "minecraft:acacia_stairs{facing:east,half:bottom,shape:straight,waterlogged:false}",
        "minecraft:short_grass",
        "minecraft:farmland{moisture:7}",
        "minecraft:water{level:0}",
        "minecraft:acacia_stairs{facing:south,half:bottom,shape:straight,waterlogged:false}",
        "minecraft:acacia_stairs{facing:north,half:bottom,shape:straight,waterlogged:false}",
        "minecraft:air",
        "minecraft:acacia_stairs{facing:west,half:bottom,shape:straight,waterlogged:false}",
        "minecraft:wheat{age:7}",
        "minecraft:jigsaw{orientation:south_up}"
    ]
}
