{
    size: [9, 7, 13],
    data: [
        {pos: [0, 0, 4], state: "minecraft:grass_block{snowy:false}"},
        {pos: [0, 0, 5], state: "minecraft:grass_block{snowy:false}"},
        {pos: [0, 0, 6], state: "minecraft:dirt"},
        {pos: [0, 0, 7], state: "minecraft:grass_block{snowy:false}"},
        {pos: [0, 0, 8], state: "minecraft:grass_block{snowy:false}"},
        {pos: [1, 0, 4], state: "minecraft:grass_block{snowy:false}"},
        {pos: [1, 0, 5], state: "minecraft:dirt"},
        {pos: [1, 0, 6], state: "minecraft:dirt"},
        {pos: [1, 0, 7], state: "minecraft:dirt"},
        {pos: [1, 0, 8], state: "minecraft:grass_block{snowy:false}"},
        {pos: [1, 0, 9], state: "minecraft:dirt"},
        {pos: [1, 0, 10], state: "minecraft:dirt"},
        {pos: [2, 0, 2], state: "minecraft:dirt"},
        {pos: [2, 0, 3], state: "minecraft:dirt"},
        {pos: [2, 0, 4], state: "minecraft:dirt"},
        {pos: [2, 0, 5], state: "minecraft:dirt"},
        {pos: [2, 0, 6], state: "minecraft:dirt"},
        {pos: [2, 0, 7], state: "minecraft:dirt"},
        {pos: [2, 0, 8], state: "minecraft:dirt"},
        {pos: [2, 0, 9], state: "minecraft:dirt"},
        {pos: [2, 0, 10], state: "minecraft:dirt"},
        {pos: [2, 0, 11], state: "minecraft:dirt"},
        {pos: [3, 0, 2], state: "minecraft:dirt"},
        {pos: [3, 0, 3], state: "minecraft:dirt"},
        {pos: [3, 0, 4], state: "minecraft:dirt"},
        {pos: [3, 0, 5], state: "minecraft:dirt"},
        {pos: [3, 0, 6], state: "minecraft:dirt"},
        {pos: [3, 0, 7], state: "minecraft:dirt"},
        {pos: [3, 0, 8], state: "minecraft:dirt"},
        {pos: [3, 0, 9], state: "minecraft:dirt"},
        {pos: [3, 0, 10], state: "minecraft:dirt"},
        {pos: [3, 0, 11], state: "minecraft:dirt"},
        {pos: [4, 0, 2], state: "minecraft:dirt"},
        {pos: [4, 0, 3], state: "minecraft:dirt"},
        {pos: [4, 0, 4], state: "minecraft:dirt"},
        {pos: [4, 0, 5], state: "minecraft:dirt"},
        {pos: [4, 0, 6], state: "minecraft:dirt"},
        {pos: [4, 0, 7], state: "minecraft:dirt"},
        {pos: [4, 0, 8], state: "minecraft:dirt"},
        {pos: [4, 0, 9], state: "minecraft:dirt"},
        {pos: [4, 0, 10], state: "minecraft:dirt"},
        {pos: [4, 0, 11], state: "minecraft:dirt"},
        {pos: [5, 0, 1], state: "minecraft:dirt"},
        {pos: [5, 0, 2], state: "minecraft:dirt"},
        {pos: [5, 0, 3], state: "minecraft:dirt"},
        {pos: [5, 0, 4], state: "minecraft:dirt"},
        {pos: [5, 0, 5], state: "minecraft:dirt"},
        {pos: [5, 0, 6], state: "minecraft:dirt"},
        {pos: [5, 0, 7], state: "minecraft:dirt"},
        {pos: [5, 0, 8], state: "minecraft:dirt"},
        {pos: [5, 0, 9], state: "minecraft:dirt"},
        {pos: [5, 0, 10], state: "minecraft:dirt"},
        {pos: [5, 0, 11], state: "minecraft:dirt"},
        {pos: [6, 0, 1], state: "minecraft:dirt"},
        {pos: [6, 0, 2], state: "minecraft:dirt"},
        {pos: [6, 0, 3], state: "minecraft:dirt"},
        {pos: [6, 0, 4], state: "minecraft:dirt"},
        {pos: [6, 0, 5], state: "minecraft:dirt"},
        {pos: [6, 0, 6], state: "minecraft:dirt"},
        {pos: [6, 0, 7], state: "minecraft:dirt"},
        {pos: [6, 0, 8], state: "minecraft:dirt"},
        {pos: [6, 0, 9], state: "minecraft:dirt"},
        {pos: [6, 0, 10], state: "minecraft:dirt"},
        {pos: [6, 0, 11], state: "minecraft:dirt"},
        {pos: [7, 0, 2], state: "minecraft:dirt"},
        {pos: [7, 0, 3], state: "minecraft:dirt"},
        {pos: [7, 0, 4], state: "minecraft:dirt"},
        {pos: [7, 0, 5], state: "minecraft:dirt"},
        {pos: [7, 0, 6], state: "minecraft:dirt"},
        {pos: [7, 0, 7], state: "minecraft:dirt"},
        {pos: [7, 0, 8], state: "minecraft:dirt"},
        {pos: [7, 0, 9], state: "minecraft:dirt"},
        {pos: [7, 0, 10], state: "minecraft:dirt"},
        {pos: [8, 0, 0], state: "minecraft:short_grass"},
        {pos: [8, 0, 1], state: "minecraft:short_grass"},
        {pos: [8, 0, 2], state: "minecraft:short_grass"},
        {pos: [8, 0, 3], state: "minecraft:short_grass"},
        {pos: [8, 0, 4], state: "minecraft:cave_air"},
        {pos: [0, 1, 0], state: "minecraft:cave_air"},
        {pos: [0, 1, 4], state: "minecraft:smooth_stone_slab{type:bottom,waterlogged:false}"},
        {pos: [0, 1, 5], state: "minecraft:smooth_stone_slab{type:bottom,waterlogged:false}"},
        {pos: [0, 1, 6], state: "minecraft:jigsaw{orientation:west_up}", nbt: {final_state: "minecraft:smooth_stone_slab[type=bottom]", id: "minecraft:jigsaw", joint: "aligned", name: "minecraft:building_entrance", pool: "minecraft:empty", target: "minecraft:building_entrance"}},
        {pos: [0, 1, 7], state: "minecraft:smooth_stone_slab{type:bottom,waterlogged:false}"},
        {pos: [0, 1, 8], state: "minecraft:smooth_stone_slab{type:bottom,waterlogged:false}"},
        {pos: [1, 1, 0], state: "minecraft:cave_air"},
        {pos: [1, 1, 4], state: "minecraft:smooth_stone_slab{type:bottom,waterlogged:false}"},
        {pos: [1, 1, 5], state: "minecraft:smooth_stone"},
        {pos: [1, 1, 6], state: "minecraft:smooth_stone"},
        {pos: [1, 1, 7], state: "minecraft:smooth_stone"},
        {pos: [1, 1, 8], state: "minecraft:smooth_stone_slab{type:bottom,waterlogged:false}"},
        {pos: [1, 1, 9], state: "minecraft:acacia_wood{axis:y}"},
        {pos: [1, 1, 10], state: "minecraft:acacia_wood{axis:y}"},
        {pos: [2, 1, 0], state: "minecraft:cave_air"},
        {pos: [2, 1, 2], state: "minecraft:smooth_stone"},
        {pos: [2, 1, 3], state: "minecraft:smooth_stone"},
        {pos: [2, 1, 4], state: "minecraft:smooth_stone"},
        {pos: [2, 1, 5], state: "minecraft:smooth_stone"},
        {pos: [2, 1, 6], state: "minecraft:smooth_stone"},
        {pos: [2, 1, 7], state: "minecraft:smooth_stone"},
        {pos: [2, 1, 8], state: "minecraft:acacia_wood{axis:y}"},
        {pos: [2, 1, 9], state: "minecraft:acacia_planks"},
        {pos: [2, 1, 10], state: "minecraft:acacia_planks"},
        {pos: [2, 1, 11], state: "minecraft:acacia_wood{axis:y}"},
        {pos: [3, 1, 2], state: "minecraft:smooth_stone"},
        {pos: [3, 1, 3], state: "minecraft:smooth_stone"},
        {pos: [3, 1, 4], state: "minecraft:smooth_stone"},
        {pos: [3, 1, 5], state: "minecraft:smooth_stone"},
        {pos: [3, 1, 6], state: "minecraft:smooth_stone"},
        {pos: [3, 1, 7], state: "minecraft:smooth_stone"},
        {pos: [3, 1, 8], state: "minecraft:acacia_wood{axis:x}"},
        {pos: [3, 1, 9], state: "minecraft:acacia_planks"},
        {pos: [3, 1, 10], state: "minecraft:acacia_planks"},
        {pos: [3, 1, 11], state: "minecraft:acacia_wood{axis:y}"},
        {pos: [4, 1, 2], state: "minecraft:smooth_stone"},
        {pos: [4, 1, 3], state: "minecraft:smooth_stone"},
        {pos: [4, 1, 4], state: "minecraft:smooth_stone"},
        {pos: [4, 1, 5], state: "minecraft:acacia_wood{axis:y}"},
        {pos: [4, 1, 6], state: "minecraft:acacia_wood{axis:y}"},
        {pos: [4, 1, 7], state: "minecraft:acacia_wood{axis:z}"},
        {pos: [4, 1, 8], state: "minecraft:acacia_planks"},
        {pos: [4, 1, 9], state: "minecraft:acacia_planks"},
        {pos: [4, 1, 10], state: "minecraft:acacia_planks"},
        {pos: [4, 1, 11], state: "minecraft:acacia_wood{axis:y}"},
        {pos: [5, 1, 1], state: "minecraft:acacia_wood{axis:y}"},
        {pos: [5, 1, 2], state: "minecraft:smooth_stone"},
        {pos: [5, 1, 3], state: "minecraft:smooth_stone"},
        {pos: [5, 1, 4], state: "minecraft:smooth_stone"},
        {pos: [5, 1, 5], state: "minecraft:acacia_planks"},
        {pos: [5, 1, 6], state: "minecraft:acacia_planks"},
        {pos: [5, 1, 7], state: "minecraft:acacia_planks"},
        {pos: [5, 1, 8], state: "minecraft:acacia_planks"},
        {pos: [5, 1, 9], state: "minecraft:acacia_planks"},
        {pos: [5, 1, 10], state: "minecraft:acacia_planks"},
        {pos: [5, 1, 11], state: "minecraft:acacia_wood{axis:y}"},
        {pos: [6, 1, 1], state: "minecraft:acacia_wood{axis:y}"},
        {pos: [6, 1, 2], state: "minecraft:smooth_stone"},
        {pos: [6, 1, 3], state: "minecraft:smooth_stone"},
        {pos: [6, 1, 4], state: "minecraft:smooth_stone"},
        {pos: [6, 1, 5], state: "minecraft:acacia_planks"},
        {pos: [6, 1, 6], state: "minecraft:acacia_planks"},
        {pos: [6, 1, 7], state: "minecraft:acacia_planks"},
        {pos: [6, 1, 8], state: "minecraft:acacia_planks"},
        {pos: [6, 1, 9], state: "minecraft:acacia_planks"},
        {pos: [6, 1, 10], state: "minecraft:acacia_planks"},
        {pos: [6, 1, 11], state: "minecraft:acacia_wood{axis:y}"},
        {pos: [7, 1, 2], state: "minecraft:acacia_wood{axis:y}"},
        {pos: [7, 1, 3], state: "minecraft:acacia_wood{axis:y}"},
        {pos: [7, 1, 4], state: "minecraft:acacia_wood{axis:y}"},
        {pos: [7, 1, 5], state: "minecraft:acacia_wood{axis:y}"},
        {pos: [7, 1, 6], state: "minecraft:acacia_wood{axis:y}"},
        {pos: [7, 1, 7], state: "minecraft:acacia_wood{axis:y}"},
        {pos: [7, 1, 8], state: "minecraft:acacia_wood{axis:x}"},
        {pos: [7, 1, 9], state: "minecraft:acacia_wood{axis:x}"},
        {pos: [7, 1, 10], state: "minecraft:acacia_wood{axis:y}"},
        {pos: [1, 2, 9], state: "minecraft:acacia_wood{axis:y}"},
        {pos: [1, 2, 10], state: "minecraft:acacia_wood{axis:y}"},
        {pos: [2, 2, 2], state: "minecraft:smooth_stone"},
        {pos: [2, 2, 3], state: "minecraft:smooth_stone"},
        {pos: [2, 2, 4], state: "minecraft:smooth_stone"},
        {pos: [2, 2, 6], state: "minecraft:grindstone{face:floor,facing:east}"},
        {pos: [2, 2, 8], state: "minecraft:acacia_wood{axis:y}"},
        {pos: [2, 2, 9], state: "minecraft:chest{facing:east,type:single,waterlogged:false}", nbt: {LootTable: "minecraft:chests/village/village_weaponsmith", id: "minecraft:chest"}},
        {pos: [2, 2, 11], state: "minecraft:acacia_wood{axis:y}"},
        {pos: [3, 2, 2], state: "minecraft:smooth_stone"},
        {pos: [3, 2, 3], state: "minecraft:lava{level:0}"},
        {pos: [3, 2, 4], state: "minecraft:smooth_stone"},
        {pos: [3, 2, 8], state: "minecraft:acacia_wood{axis:y}"},
        {pos: [3, 2, 11], state: "minecraft:acacia_wood{axis:y}"},
        {pos: [4, 2, 2], state: "minecraft:smooth_stone"},
        {pos: [4, 2, 3], state: "minecraft:smooth_stone"},
        {pos: [4, 2, 4], state: "minecraft:smooth_stone"},
        {pos: [4, 2, 5], state: "minecraft:acacia_wood{axis:y}"},
        {pos: [4, 2, 6], state: "minecraft:acacia_door{facing:west,half:lower,hinge:left,open:false,powered:false}"},
        {pos: [4, 2, 7], state: "minecraft:acacia_wood{axis:y}"},
        {pos: [4, 2, 11], state: "minecraft:acacia_wood{axis:y}"},
        {pos: [5, 2, 1], state: "minecraft:acacia_wood{axis:y}"},
        {pos: [5, 2, 3], state: "minecraft:grindstone{face:wall,facing:east}"},
        {pos: [5, 2, 11], state: "minecraft:acacia_wood{axis:y}"},
        {pos: [6, 2, 1], state: "minecraft:acacia_wood{axis:y}"},
        {pos: [6, 2, 8], state: "minecraft:acacia_stairs{facing:north,half:bottom,shape:straight,waterlogged:false}"},
        {pos: [6, 2, 9], state: "minecraft:acacia_fence{east:true,north:false,south:false,waterlogged:false,west:false}"},
        {pos: [6, 2, 10], state: "minecraft:acacia_stairs{facing:south,half:bottom,shape:straight,waterlogged:false}"},
        {pos: [6, 2, 11], state: "minecraft:acacia_wood{axis:y}"},
        {pos: [7, 2, 2], state: "minecraft:acacia_wood{axis:y}"},
        {pos: [7, 2, 3], state: "minecraft:acacia_wood{axis:x}"},
        {pos: [7, 2, 4], state: "minecraft:acacia_wood{axis:y}"},
        {pos: [7, 2, 5], state: "minecraft:acacia_wood{axis:y}"},
        {pos: [7, 2, 6], state: "minecraft:acacia_wood{axis:y}"},
        {pos: [7, 2, 7], state: "minecraft:acacia_wood{axis:y}"},
        {pos: [7, 2, 8], state: "minecraft:acacia_wood{axis:y}"},
        {pos: [7, 2, 9], state: "minecraft:acacia_wood{axis:y}"},
        {pos: [7, 2, 10], state: "minecraft:acacia_wood{axis:y}"},
        {pos: [1, 3, 8], state: "minecraft:air"},
        {pos: [1, 3, 9], state: "minecraft:acacia_wood{axis:y}"},
        {pos: [1, 3, 10], state: "minecraft:acacia_wood{axis:y}"},
        {pos: [1, 3, 11], state: "minecraft:wall_torch{facing:west}"},
        {pos: [2, 3, 2], state: "minecraft:iron_bars{east:true,north:false,south:true,waterlogged:false,west:false}"},
        {pos: [2, 3, 3], state: "minecraft:iron_bars{east:false,north:true,south:true,waterlogged:false,west:false}"},
        {pos: [2, 3, 4], state: "minecraft:iron_bars{east:false,north:true,south:false,waterlogged:false,west:false}"},
        {pos: [2, 3, 8], state: "minecraft:acacia_wood{axis:y}"},
        {pos: [2, 3, 11], state: "minecraft:acacia_wood{axis:y}"},
        {pos: [3, 3, 2], state: "minecraft:iron_bars{east:true,north:false,south:false,waterlogged:false,west:true}"},
        {pos: [3, 3, 5], state: "minecraft:air"},
        {pos: [3, 3, 8], state: "minecraft:acacia_wood{axis:y}"},
        {pos: [3, 3, 11], state: "minecraft:acacia_wood{axis:x}"},
        {pos: [4, 3, 2], state: "minecraft:smooth_stone"},
        {pos: [4, 3, 3], state: "minecraft:smooth_stone"},
        {pos: [4, 3, 4], state: "minecraft:smooth_stone"},
        {pos: [4, 3, 5], state: "minecraft:smooth_stone"},
        {pos: [4, 3, 6], state: "minecraft:acacia_door{facing:west,half:upper,hinge:left,open:false,powered:false}"},
        {pos: [4, 3, 7], state: "minecraft:acacia_log{axis:y}"},
        {pos: [4, 3, 11], state: "minecraft:glass_pane{east:true,north:false,south:false,waterlogged:false,west:true}"},
        {pos: [5, 3, 1], state: "minecraft:smooth_stone"},
        {pos: [5, 3, 11], state: "minecraft:acacia_wood{axis:x}"},
        {pos: [6, 3, 1], state: "minecraft:acacia_wood{axis:y}"},
        {pos: [6, 3, 9], state: "minecraft:acacia_pressure_plate{powered:false}"},
        {pos: [6, 3, 11], state: "minecraft:acacia_wood{axis:x}"},
        {pos: [7, 3, 2], state: "minecraft:acacia_wood{axis:y}"},
        {pos: [7, 3, 3], state: "minecraft:acacia_wood{axis:z}"},
        {pos: [7, 3, 4], state: "minecraft:glass_pane{east:false,north:true,south:true,waterlogged:false,west:false}"},
        {pos: [7, 3, 5], state: "minecraft:acacia_wood{axis:z}"},
        {pos: [7, 3, 6], state: "minecraft:acacia_wood{axis:z}"},
        {pos: [7, 3, 7], state: "minecraft:acacia_wood{axis:z}"},
        {pos: [7, 3, 8], state: "minecraft:glass_pane{east:false,north:true,south:true,waterlogged:false,west:false}"},
        {pos: [7, 3, 9], state: "minecraft:acacia_wood{axis:z}"},
        {pos: [7, 3, 10], state: "minecraft:acacia_wood{axis:y}"},
        {pos: [1, 4, 9], state: "minecraft:acacia_wood{axis:y}"},
        {pos: [1, 4, 10], state: "minecraft:acacia_wood{axis:y}"},
        {pos: [2, 4, 2], state: "minecraft:iron_bars{east:true,north:false,south:true,waterlogged:false,west:false}"},
        {pos: [2, 4, 3], state: "minecraft:iron_bars{east:false,north:true,south:true,waterlogged:false,west:false}"},
        {pos: [2, 4, 4], state: "minecraft:iron_bars{east:false,north:true,south:false,waterlogged:false,west:false}"},
        {pos: [2, 4, 8], state: "minecraft:acacia_wood{axis:y}"},
        {pos: [2, 4, 9], state: "minecraft:wall_torch{facing:east}"},
        {pos: [2, 4, 11], state: "minecraft:acacia_wood{axis:y}"},
        {pos: [3, 4, 2], state: "minecraft:iron_bars{east:true,north:false,south:false,waterlogged:false,west:true}"},
        {pos: [3, 4, 6], state: "minecraft:wall_torch{facing:west}"},
        {pos: [3, 4, 8], state: "minecraft:acacia_wood{axis:y}"},
        {pos: [3, 4, 11], state: "minecraft:acacia_wood{axis:y}"},
        {pos: [4, 4, 2], state: "minecraft:smooth_stone"},
        {pos: [4, 4, 3], state: "minecraft:smooth_stone"},
        {pos: [4, 4, 4], state: "minecraft:smooth_stone"},
        {pos: [4, 4, 5], state: "minecraft:smooth_stone"},
        {pos: [4, 4, 6], state: "minecraft:acacia_log{axis:z}"},
        {pos: [4, 4, 7], state: "minecraft:acacia_log{axis:y}"},
        {pos: [4, 4, 11], state: "minecraft:acacia_wood{axis:y}"},
        {pos: [5, 4, 1], state: "minecraft:smooth_stone"},
        {pos: [5, 4, 11], state: "minecraft:acacia_wood{axis:y}"},
        {pos: [6, 4, 1], state: "minecraft:acacia_wood{axis:y}"},
        {pos: [6, 4, 4], state: "minecraft:wall_torch{facing:west}"},
        {pos: [6, 4, 8], state: "minecraft:wall_torch{facing:west}"},
        {pos: [6, 4, 11], state: "minecraft:acacia_wood{axis:y}"},
        {pos: [7, 4, 2], state: "minecraft:acacia_wood{axis:y}"},
        {pos: [7, 4, 3], state: "minecraft:acacia_wood{axis:y}"},
        {pos: [7, 4, 4], state: "minecraft:acacia_wood{axis:y}"},
        {pos: [7, 4, 5], state: "minecraft:acacia_wood{axis:y}"},
        {pos: [7, 4, 6], state: "minecraft:acacia_wood{axis:y}"},
        {pos: [7, 4, 7], state: "minecraft:acacia_wood{axis:y}"},
        {pos: [7, 4, 8], state: "minecraft:acacia_wood{axis:y}"},
        {pos: [7, 4, 9], state: "minecraft:acacia_wood{axis:y}"},
        {pos: [7, 4, 10], state: "minecraft:acacia_wood{axis:y}"},
        {pos: [0, 5, 8], state: "minecraft:acacia_stairs{facing:east,half:bottom,shape:straight,waterlogged:false}"},
        {pos: [0, 5, 9], state: "minecraft:acacia_stairs{facing:east,half:bottom,shape:straight,waterlogged:false}"},
        {pos: [0, 5, 10], state: "minecraft:acacia_stairs{facing:east,half:bottom,shape:straight,waterlogged:false}"},
        {pos: [0, 5, 11], state: "minecraft:acacia_stairs{facing:east,half:bottom,shape:straight,waterlogged:false}"},
        {pos: [1, 5, 7], state: "minecraft:acacia_stairs{facing:south,half:bottom,shape:straight,waterlogged:false}"},
        {pos: [1, 5, 8], state: "minecraft:acacia_planks"},
        {pos: [1, 5, 9], state: "minecraft:acacia_planks"},
        {pos: [1, 5, 10], state: "minecraft:acacia_planks"},
        {pos: [1, 5, 11], state: "minecraft:acacia_planks"},
        {pos: [1, 5, 12], state: "minecraft:acacia_stairs{facing:north,half:bottom,shape:straight,waterlogged:false}"},
        {pos: [2, 5, 2], state: "minecraft:smooth_stone_slab{type:bottom,waterlogged:false}"},
        {pos: [2, 5, 3], state: "minecraft:smooth_stone_slab{type:bottom,waterlogged:false}"},
        {pos: [2, 5, 4], state: "minecraft:smooth_stone_slab{type:bottom,waterlogged:false}"},
        {pos: [2, 5, 5], state: "minecraft:air"},
        {pos: [2, 5, 7], state: "minecraft:acacia_stairs{facing:south,half:bottom,shape:straight,waterlogged:false}"},
        {pos: [2, 5, 8], state: "minecraft:acacia_planks"},
        {pos: [2, 5, 11], state: "minecraft:acacia_planks"},
        {pos: [2, 5, 12], state: "minecraft:acacia_stairs{facing:north,half:bottom,shape:straight,waterlogged:false}"},
        {pos: [3, 5, 1], state: "minecraft:smooth_stone_slab{type:bottom,waterlogged:false}"},
        {pos: [3, 5, 2], state: "minecraft:smooth_stone_slab{type:bottom,waterlogged:false}"},
        {pos: [3, 5, 3], state: "minecraft:smooth_stone_slab{type:bottom,waterlogged:false}"},
        {pos: [3, 5, 4], state: "minecraft:smooth_stone_slab{type:bottom,waterlogged:false}"},
        {pos: [3, 5, 5], state: "minecraft:smooth_stone_slab{type:bottom,waterlogged:false}"},
        {pos: [3, 5, 6], state: "minecraft:acacia_stairs{facing:east,half:bottom,shape:straight,waterlogged:false}"},
        {pos: [3, 5, 7], state: "minecraft:acacia_stairs{facing:east,half:bottom,shape:inner_right,waterlogged:false}"},
        {pos: [3, 5, 8], state: "minecraft:acacia_planks"},
        {pos: [3, 5, 11], state: "minecraft:acacia_planks"},
        {pos: [3, 5, 12], state: "minecraft:acacia_stairs{facing:north,half:bottom,shape:straight,waterlogged:false}"},
        {pos: [4, 5, 0], state: "minecraft:smooth_stone_slab{type:bottom,waterlogged:false}"},
        {pos: [4, 5, 1], state: "minecraft:smooth_stone"},
        {pos: [4, 5, 2], state: "minecraft:smooth_stone"},
        {pos: [4, 5, 3], state: "minecraft:smooth_stone"},
        {pos: [4, 5, 4], state: "minecraft:smooth_stone"},
        {pos: [4, 5, 5], state: "minecraft:smooth_stone"},
        {pos: [4, 5, 6], state: "minecraft:acacia_planks"},
        {pos: [4, 5, 7], state: "minecraft:acacia_planks"},
        {pos: [4, 5, 8], state: "minecraft:acacia_planks"},
        {pos: [4, 5, 11], state: "minecraft:acacia_planks"},
        {pos: [4, 5, 12], state: "minecraft:acacia_stairs{facing:north,half:bottom,shape:straight,waterlogged:false}"},
        {pos: [5, 5, 0], state: "minecraft:smooth_stone_slab{type:bottom,waterlogged:false}"},
        {pos: [5, 5, 1], state: "minecraft:smooth_stone"},
        {pos: [5, 5, 3], state: "minecraft:air"},
        {pos: [5, 5, 5], state: "minecraft:air"},
        {pos: [5, 5, 11], state: "minecraft:acacia_planks"},
        {pos: [5, 5, 12], state: "minecraft:acacia_stairs{facing:north,half:bottom,shape:straight,waterlogged:false}"},
        {pos: [6, 5, 0], state: "minecraft:acacia_stairs{facing:south,half:bottom,shape:straight,waterlogged:false}"},
        {pos: [6, 5, 1], state: "minecraft:acacia_planks"},
        {pos: [6, 5, 11], state: "minecraft:acacia_planks"},
        {pos: [6, 5, 12], state: "minecraft:acacia_stairs{facing:north,half:bottom,shape:straight,waterlogged:false}"},
        {pos: [7, 5, 0], state: "minecraft:acacia_stairs{facing:south,half:bottom,shape:straight,waterlogged:false}"},
        {pos: [7, 5, 1], state: "minecraft:acacia_planks"},
        {pos: [7, 5, 2], state: "minecraft:acacia_planks"},
        {pos: [7, 5, 3], state: "minecraft:acacia_planks"},
        {pos: [7, 5, 4], state: "minecraft:acacia_planks"},
        {pos: [7, 5, 5], state: "minecraft:acacia_planks"},
        {pos: [7, 5, 6], state: "minecraft:acacia_planks"},
        {pos: [7, 5, 7], state: "minecraft:acacia_planks"},
        {pos: [7, 5, 8], state: "minecraft:acacia_planks"},
        {pos: [7, 5, 9], state: "minecraft:acacia_planks"},
        {pos: [7, 5, 10], state: "minecraft:acacia_planks"},
        {pos: [7, 5, 11], state: "minecraft:acacia_planks"},
        {pos: [7, 5, 12], state: "minecraft:acacia_stairs{facing:north,half:bottom,shape:straight,waterlogged:false}"},
        {pos: [8, 5, 1], state: "minecraft:acacia_stairs{facing:west,half:bottom,shape:straight,waterlogged:false}"},
        {pos: [8, 5, 2], state: "minecraft:acacia_stairs{facing:west,half:bottom,shape:straight,waterlogged:false}"},
        {pos: [8, 5, 3], state: "minecraft:acacia_stairs{facing:west,half:bottom,shape:straight,waterlogged:false}"},
        {pos: [8, 5, 4], state: "minecraft:acacia_stairs{facing:west,half:bottom,shape:straight,waterlogged:false}"},
        {pos: [8, 5, 5], state: "minecraft:acacia_stairs{facing:west,half:bottom,shape:straight,waterlogged:false}"},
        {pos: [8, 5, 6], state: "minecraft:acacia_stairs{facing:west,half:bottom,shape:straight,waterlogged:false}"},
        {pos: [8, 5, 7], state: "minecraft:acacia_stairs{facing:west,half:bottom,shape:straight,waterlogged:false}"},
        {pos: [8, 5, 8], state: "minecraft:acacia_stairs{facing:west,half:bottom,shape:straight,waterlogged:false}"},
        {pos: [8, 5, 9], state: "minecraft:acacia_stairs{facing:west,half:bottom,shape:straight,waterlogged:false}"},
        {pos: [8, 5, 10], state: "minecraft:acacia_stairs{facing:west,half:bottom,shape:straight,waterlogged:false}"},
        {pos: [8, 5, 11], state: "minecraft:acacia_stairs{facing:west,half:bottom,shape:straight,waterlogged:false}"},
        {pos: [1, 6, 8], state: "minecraft:acacia_stairs{facing:south,half:bottom,shape:outer_left,waterlogged:false}"},
        {pos: [1, 6, 9], state: "minecraft:acacia_stairs{facing:east,half:bottom,shape:straight,waterlogged:false}"},
        {pos: [1, 6, 10], state: "minecraft:acacia_stairs{facing:east,half:bottom,shape:straight,waterlogged:false}"},
        {pos: [1, 6, 11], state: "minecraft:acacia_stairs{facing:north,half:bottom,shape:outer_right,waterlogged:false}"},
        {pos: [2, 6, 8], state: "minecraft:acacia_stairs{facing:south,half:bottom,shape:straight,waterlogged:false}"},
        {pos: [2, 6, 9], state: "minecraft:acacia_planks"},
        {pos: [2, 6, 10], state: "minecraft:acacia_planks"},
        {pos: [2, 6, 11], state: "minecraft:acacia_stairs{facing:north,half:bottom,shape:straight,waterlogged:false}"},
        {pos: [3, 6, 8], state: "minecraft:acacia_stairs{facing:south,half:bottom,shape:straight,waterlogged:false}"},
        {pos: [3, 6, 9], state: "minecraft:acacia_planks"},
        {pos: [3, 6, 10], state: "minecraft:acacia_planks"},
        {pos: [3, 6, 11], state: "minecraft:acacia_stairs{facing:north,half:bottom,shape:straight,waterlogged:false}"},
        {pos: [4, 6, 1], state: "minecraft:acacia_stairs{facing:south,half:bottom,shape:outer_left,waterlogged:false}"},
        {pos: [4, 6, 2], state: "minecraft:acacia_stairs{facing:east,half:bottom,shape:straight,waterlogged:false}"},
        {pos: [4, 6, 3], state: "minecraft:acacia_stairs{facing:east,half:bottom,shape:straight,waterlogged:false}"},
        {pos: [4, 6, 4], state: "minecraft:acacia_stairs{facing:east,half:bottom,shape:straight,waterlogged:false}"},
        {pos: [4, 6, 5], state: "minecraft:acacia_stairs{facing:east,half:bottom,shape:straight,waterlogged:false}"},
        {pos: [4, 6, 6], state: "minecraft:acacia_stairs{facing:east,half:bottom,shape:straight,waterlogged:false}"},
        {pos: [4, 6, 7], state: "minecraft:acacia_stairs{facing:east,half:bottom,shape:straight,waterlogged:false}"},
        {pos: [4, 6, 8], state: "minecraft:acacia_stairs{facing:east,half:bottom,shape:inner_right,waterlogged:false}"},
        {pos: [4, 6, 9], state: "minecraft:acacia_planks"},
        {pos: [4, 6, 10], state: "minecraft:acacia_planks"},
        {pos: [4, 6, 11], state: "minecraft:acacia_stairs{facing:north,half:bottom,shape:straight,waterlogged:false}"},
        {pos: [5, 6, 1], state: "minecraft:acacia_stairs{facing:south,half:bottom,shape:straight,waterlogged:false}"},
        {pos: [5, 6, 2], state: "minecraft:acacia_planks"},
        {pos: [5, 6, 3], state: "minecraft:acacia_planks"},
        {pos: [5, 6, 4], state: "minecraft:acacia_planks"},
        {pos: [5, 6, 5], state: "minecraft:acacia_planks"},
        {pos: [5, 6, 6], state: "minecraft:acacia_planks"},
        {pos: [5, 6, 7], state: "minecraft:acacia_planks"},
        {pos: [5, 6, 8], state: "minecraft:acacia_planks"},
        {pos: [5, 6, 9], state: "minecraft:acacia_planks"},
        {pos: [5, 6, 10], state: "minecraft:acacia_planks"},
        {pos: [5, 6, 11], state: "minecraft:acacia_stairs{facing:north,half:bottom,shape:straight,waterlogged:false}"},
        {pos: [6, 6, 1], state: "minecraft:acacia_stairs{facing:south,half:bottom,shape:straight,waterlogged:false}"},
        {pos: [6, 6, 2], state: "minecraft:acacia_planks"},
        {pos: [6, 6, 3], state: "minecraft:acacia_planks"},
        {pos: [6, 6, 4], state: "minecraft:acacia_planks"},
        {pos: [6, 6, 5], state: "minecraft:acacia_planks"},
        {pos: [6, 6, 6], state: "minecraft:acacia_planks"},
        {pos: [6, 6, 7], state: "minecraft:acacia_planks"},
        {pos: [6, 6, 8], state: "minecraft:acacia_planks"},
        {pos: [6, 6, 9], state: "minecraft:acacia_planks"},
        {pos: [6, 6, 10], state: "minecraft:acacia_planks"},
        {pos: [6, 6, 11], state: "minecraft:acacia_stairs{facing:north,half:bottom,shape:straight,waterlogged:false}"},
        {pos: [7, 6, 1], state: "minecraft:acacia_stairs{facing:south,half:bottom,shape:outer_right,waterlogged:false}"},
        {pos: [7, 6, 2], state: "minecraft:acacia_stairs{facing:west,half:bottom,shape:straight,waterlogged:false}"},
        {pos: [7, 6, 3], state: "minecraft:acacia_stairs{facing:west,half:bottom,shape:straight,waterlogged:false}"},
        {pos: [7, 6, 4], state: "minecraft:acacia_stairs{facing:west,half:bottom,shape:straight,waterlogged:false}"},
        {pos: [7, 6, 5], state: "minecraft:acacia_stairs{facing:west,half:bottom,shape:straight,waterlogged:false}"},
        {pos: [7, 6, 6], state: "minecraft:acacia_stairs{facing:west,half:bottom,shape:straight,waterlogged:false}"},
        {pos: [7, 6, 7], state: "minecraft:acacia_stairs{facing:west,half:bottom,shape:straight,waterlogged:false}"},
        {pos: [7, 6, 8], state: "minecraft:acacia_stairs{facing:west,half:bottom,shape:straight,waterlogged:false}"},
        {pos: [7, 6, 9], state: "minecraft:acacia_stairs{facing:west,half:bottom,shape:straight,waterlogged:false}"},
        {pos: [7, 6, 10], state: "minecraft:acacia_stairs{facing:west,half:bottom,shape:straight,waterlogged:false}"},
        {pos: [7, 6, 11], state: "minecraft:acacia_stairs{facing:north,half:bottom,shape:outer_left,waterlogged:false}"}
    ],
    entities: [],
    palette: [
        "minecraft:grass_block{snowy:false}",
        "minecraft:dirt",
        "minecraft:smooth_stone",
        "minecraft:acacia_wood{axis:y}",
        "minecraft:acacia_planks",
        "minecraft:acacia_wood{axis:x}",
        "minecraft:acacia_wood{axis:z}",
        "minecraft:acacia_log{axis:y}",
        "minecraft:acacia_log{axis:z}",
        "minecraft:short_grass",
        "minecraft:cave_air",
        "minecraft:smooth_stone_slab{type:bottom,waterlogged:false}",
        "minecraft:grindstone{face:floor,facing:east}",
        "minecraft:lava{level:0}",
        "minecraft:acacia_door{facing:west,half:lower,hinge:left,open:false,powered:false}",
        "minecraft:grindstone{face:wall,facing:east}",
        "minecraft:acacia_stairs{facing:north,half:bottom,shape:straight,waterlogged:false}",
        "minecraft:acacia_fence{east:true,north:false,south:false,waterlogged:false,west:false}",
        "minecraft:acacia_stairs{facing:south,half:bottom,shape:straight,waterlogged:false}",
        "minecraft:air",
        "minecraft:wall_torch{facing:west}",
        "minecraft:iron_bars{east:true,north:false,south:true,waterlogged:false,west:false}",
        "minecraft:iron_bars{east:false,north:true,south:true,waterlogged:false,west:false}",
        "minecraft:iron_bars{east:false,north:true,south:false,waterlogged:false,west:false}",
        "minecraft:iron_bars{east:true,north:false,south:false,waterlogged:false,west:true}",
        "minecraft:acacia_door{facing:west,half:upper,hinge:left,open:false,powered:false}",
        "minecraft:glass_pane{east:true,north:false,south:false,waterlogged:false,west:true}",
        "minecraft:acacia_pressure_plate{powered:false}",
        "minecraft:glass_pane{east:false,north:true,south:true,waterlogged:false,west:false}",
        "minecraft:wall_torch{facing:east}",
        "minecraft:acacia_stairs{facing:east,half:bottom,shape:straight,waterlogged:false}",
        "minecraft:acacia_stairs{facing:east,half:bottom,shape:inner_right,waterlogged:false}",
        "minecraft:acacia_stairs{facing:west,half:bottom,shape:straight,waterlogged:false}",
        "minecraft:acacia_stairs{facing:south,half:bottom,shape:outer_left,waterlogged:false}",
        "minecraft:acacia_stairs{facing:north,half:bottom,shape:outer_right,waterlogged:false}",
        "minecraft:acacia_stairs{facing:south,half:bottom,shape:outer_right,waterlogged:false}",
        "minecraft:acacia_stairs{facing:north,half:bottom,shape:outer_left,waterlogged:false}",
        "minecraft:jigsaw{orientation:west_up}",
        "minecraft:chest{facing:east,type:single,waterlogged:false}"
    ]
}
