{
    size: [10, 13, 11],
    data: [
        {pos: [1, 0, 3], state: "minecraft:dirt"},
        {pos: [2, 0, 1], state: "minecraft:dirt"},
        {pos: [2, 0, 2], state: "minecraft:dirt"},
        {pos: [2, 0, 3], state: "minecraft:dirt"},
        {pos: [2, 0, 4], state: "minecraft:dirt"},
        {pos: [2, 0, 5], state: "minecraft:dirt_path"},
        {pos: [2, 0, 6], state: "minecraft:dirt_path"},
        {pos: [2, 0, 8], state: "minecraft:dirt"},
        {pos: [3, 0, 2], state: "minecraft:dirt"},
        {pos: [3, 0, 3], state: "minecraft:dirt"},
        {pos: [3, 0, 5], state: "minecraft:dirt_path"},
        {pos: [3, 0, 6], state: "minecraft:dirt_path"},
        {pos: [3, 0, 7], state: "minecraft:dirt_path"},
        {pos: [4, 0, 4], state: "minecraft:dirt_path"},
        {pos: [4, 0, 5], state: "minecraft:dirt_path"},
        {pos: [4, 0, 6], state: "minecraft:dirt_path"},
        {pos: [4, 0, 8], state: "minecraft:dirt_path"},
        {pos: [5, 0, 3], state: "minecraft:grass_block{snowy:false}"},
        {pos: [5, 0, 4], state: "minecraft:dirt_path"},
        {pos: [5, 0, 5], state: "minecraft:dirt_path"},
        {pos: [5, 0, 6], state: "minecraft:grass_block{snowy:false}"},
        {pos: [5, 0, 7], state: "minecraft:dirt_path"},
        {pos: [5, 0, 8], state: "minecraft:dirt_path"},
        {pos: [6, 0, 4], state: "minecraft:dirt_path"},
        {pos: [6, 0, 5], state: "minecraft:dirt_path"},
        {pos: [6, 0, 6], state: "minecraft:dirt_path"},
        {pos: [6, 0, 7], state: "minecraft:dirt_path"},
        {pos: [7, 0, 2], state: "minecraft:dirt"},
        {pos: [7, 0, 5], state: "minecraft:dirt_path"},
        {pos: [7, 0, 6], state: "minecraft:dirt_path"},
        {pos: [7, 0, 8], state: "minecraft:grass_block{snowy:false}"},
        {pos: [8, 0, 5], state: "minecraft:dirt_path"},
        {pos: [8, 0, 6], state: "minecraft:dirt_path"},
        {pos: [9, 0, 5], state: "minecraft:jigsaw{orientation:east_up}", nbt: {components: {}, final_state: "minecraft:dirt_path", id: "minecraft:jigsaw", joint: "rollable", name: "minecraft:end_connector", placement_priority: 0, pool: "minecraft:empty", selection_priority: 0, target: "minecraft:connector"}},
        {pos: [9, 0, 6], state: "minecraft:dirt_path"},
        {pos: [1, 1, 3], state: "minecraft:stone"},
        {pos: [2, 1, 1], state: "minecraft:stone"},
        {pos: [2, 1, 2], state: "minecraft:stone"},
        {pos: [2, 1, 3], state: "minecraft:stone"},
        {pos: [2, 1, 4], state: "minecraft:stone"},
        {pos: [2, 1, 7], state: "minecraft:cobweb"},
        {pos: [2, 1, 8], state: "minecraft:jungle_log{axis:y}"},
        {pos: [3, 1, 2], state: "minecraft:stone"},
        {pos: [3, 1, 3], state: "minecraft:stone"},
        {pos: [3, 1, 4], state: "minecraft:cobweb"},
        {pos: [3, 1, 8], state: "minecraft:cobweb"},
        {pos: [4, 1, 2], state: "minecraft:cobweb"},
        {pos: [4, 1, 3], state: "minecraft:cobweb"},
        {pos: [5, 1, 3], state: "minecraft:chest{facing:south,type:single,waterlogged:false}", nbt: {Items: [], LootTable: "minecraft:chests/abandoned_camp_common_chest", components: {}, id: "minecraft:chest"}},
        {pos: [5, 1, 6], state: "minecraft:campfire{facing:east,lit:false,signal_fire:false,waterlogged:false}", nbt: {CookingTimes: [I; 0, 0, 0, 0], CookingTotalTimes: [I; 0, 0, 0, 0], Items: [], components: {}, id: "minecraft:campfire"}},
        {pos: [7, 1, 2], state: "minecraft:jungle_log{axis:y}"},
        {pos: [7, 1, 3], state: "minecraft:cobweb"},
        {pos: [7, 1, 8], state: "minecraft:jungle_fence{east:false,north:false,south:false,waterlogged:false,west:false}"},
        {pos: [8, 1, 3], state: "minecraft:cobweb"},
        {pos: [2, 2, 2], state: "minecraft:stone"},
        {pos: [2, 2, 3], state: "minecraft:stone"},
        {pos: [2, 2, 7], state: "minecraft:cocoa{age:2,facing:south}"},
        {pos: [2, 2, 8], state: "minecraft:jungle_log{axis:y}"},
        {pos: [3, 2, 2], state: "minecraft:cobweb"},
        {pos: [3, 2, 3], state: "minecraft:stone"},
        {pos: [3, 2, 8], state: "minecraft:cobweb"},
        {pos: [7, 2, 2], state: "minecraft:jungle_log{axis:y}"},
        {pos: [2, 3, 3], state: "minecraft:stone"},
        {pos: [2, 3, 8], state: "minecraft:jungle_log{axis:y}"},
        {pos: [2, 3, 9], state: "minecraft:cocoa{age:2,facing:north}"},
        {pos: [3, 3, 3], state: "minecraft:cobweb"},
        {pos: [3, 3, 8], state: "minecraft:cocoa{age:2,facing:west}"},
        {pos: [7, 3, 2], state: "minecraft:jungle_log{axis:y}"},
        {pos: [7, 3, 3], state: "minecraft:cocoa{age:2,facing:north}"},
        {pos: [2, 4, 8], state: "minecraft:jungle_log{axis:y}"},
        {pos: [7, 4, 2], state: "minecraft:jungle_log{axis:y}"},
        {pos: [7, 4, 3], state: "minecraft:cocoa{age:2,facing:north}"},
        {pos: [0, 5, 6], state: "minecraft:jungle_leaves{distance:4,persistent:false,waterlogged:false}"},
        {pos: [0, 5, 7], state: "minecraft:jungle_leaves{distance:3,persistent:false,waterlogged:false}"},
        {pos: [0, 5, 8], state: "minecraft:jungle_leaves{distance:2,persistent:false,waterlogged:false}"},
        {pos: [0, 5, 9], state: "minecraft:jungle_leaves{distance:3,persistent:false,waterlogged:false}"},
        {pos: [0, 5, 10], state: "minecraft:jungle_leaves{distance:4,persistent:false,waterlogged:false}"},
        {pos: [1, 5, 6], state: "minecraft:jungle_leaves{distance:3,persistent:false,waterlogged:false}"},
        {pos: [1, 5, 7], state: "minecraft:jungle_leaves{distance:2,persistent:false,waterlogged:false}"},
        {pos: [1, 5, 8], state: "minecraft:jungle_leaves{distance:1,persistent:false,waterlogged:false}"},
        {pos: [1, 5, 9], state: "minecraft:jungle_leaves{distance:2,persistent:false,waterlogged:false}"},
        {pos: [1, 5, 10], state: "minecraft:jungle_leaves{distance:3,persistent:false,waterlogged:false}"},
        {pos: [2, 5, 6], state: "minecraft:jungle_leaves{distance:2,persistent:false,waterlogged:false}"},
        {pos: [2, 5, 7], state: "minecraft:jungle_leaves{distance:1,persistent:false,waterlogged:false}"},
        {pos: [2, 5, 8], state: "minecraft:jungle_log{axis:y}"},
        {pos: [2, 5, 9], state: "minecraft:jungle_leaves{distance:1,persistent:false,waterlogged:false}"},
        {pos: [2, 5, 10], state: "minecraft:jungle_leaves{distance:2,persistent:false,waterlogged:false}"},
        {pos: [3, 5, 6], state: "minecraft:jungle_leaves{distance:3,persistent:false,waterlogged:false}"},
        {pos: [3, 5, 7], state: "minecraft:jungle_leaves{distance:2,persistent:false,waterlogged:false}"},
        {pos: [3, 5, 8], state: "minecraft:jungle_leaves{distance:1,persistent:false,waterlogged:false}"},
        {pos: [3, 5, 9], state: "minecraft:jungle_leaves{distance:2,persistent:false,waterlogged:false}"},
        {pos: [3, 5, 10], state: "minecraft:jungle_leaves{distance:3,persistent:false,waterlogged:false}"},
        {pos: [4, 5, 6], state: "minecraft:jungle_leaves{distance:4,persistent:false,waterlogged:false}"},
        {pos: [4, 5, 7], state: "minecraft:jungle_leaves{distance:3,persistent:false,waterlogged:false}"},
        {pos: [4, 5, 8], state: "minecraft:jungle_leaves{distance:2,persistent:false,waterlogged:false}"},
        {pos: [4, 5, 9], state: "minecraft:jungle_leaves{distance:3,persistent:false,waterlogged:false}"},
        {pos: [7, 5, 2], state: "minecraft:jungle_log{axis:y}"},
        {pos: [0, 6, 6], state: "minecraft:jungle_leaves{distance:4,persistent:false,waterlogged:false}"},
        {pos: [0, 6, 7], state: "minecraft:jungle_leaves{distance:3,persistent:false,waterlogged:false}"},
        {pos: [0, 6, 8], state: "minecraft:jungle_leaves{distance:2,persistent:false,waterlogged:false}"},
        {pos: [0, 6, 9], state: "minecraft:jungle_leaves{distance:3,persistent:false,waterlogged:false}"},
        {pos: [0, 6, 10], state: "minecraft:jungle_leaves{distance:4,persistent:false,waterlogged:false}"},
        {pos: [1, 6, 6], state: "minecraft:jungle_leaves{distance:3,persistent:false,waterlogged:false}"},
        {pos: [1, 6, 7], state: "minecraft:jungle_leaves{distance:2,persistent:false,waterlogged:false}"},
        {pos: [1, 6, 8], state: "minecraft:jungle_leaves{distance:1,persistent:false,waterlogged:false}"},
        {pos: [1, 6, 9], state: "minecraft:jungle_leaves{distance:2,persistent:false,waterlogged:false}"},
        {pos: [1, 6, 10], state: "minecraft:jungle_leaves{distance:3,persistent:false,waterlogged:false}"},
        {pos: [2, 6, 6], state: "minecraft:jungle_leaves{distance:2,persistent:false,waterlogged:false}"},
        {pos: [2, 6, 7], state: "minecraft:jungle_leaves{distance:1,persistent:false,waterlogged:false}"},
        {pos: [2, 6, 8], state: "minecraft:jungle_log{axis:y}"},
        {pos: [2, 6, 9], state: "minecraft:jungle_leaves{distance:1,persistent:false,waterlogged:false}"},
        {pos: [2, 6, 10], state: "minecraft:jungle_leaves{distance:2,persistent:false,waterlogged:false}"},
        {pos: [3, 6, 6], state: "minecraft:jungle_leaves{distance:3,persistent:false,waterlogged:false}"},
        {pos: [3, 6, 7], state: "minecraft:jungle_leaves{distance:2,persistent:false,waterlogged:false}"},
        {pos: [3, 6, 8], state: "minecraft:jungle_leaves{distance:1,persistent:false,waterlogged:false}"},
        {pos: [3, 6, 9], state: "minecraft:jungle_leaves{distance:2,persistent:false,waterlogged:false}"},
        {pos: [3, 6, 10], state: "minecraft:jungle_leaves{distance:3,persistent:false,waterlogged:false}"},
        {pos: [4, 6, 6], state: "minecraft:jungle_leaves{distance:4,persistent:false,waterlogged:false}"},
        {pos: [4, 6, 7], state: "minecraft:jungle_leaves{distance:3,persistent:false,waterlogged:false}"},
        {pos: [4, 6, 8], state: "minecraft:jungle_leaves{distance:2,persistent:false,waterlogged:false}"},
        {pos: [4, 6, 9], state: "minecraft:jungle_leaves{distance:3,persistent:false,waterlogged:false}"},
        {pos: [4, 6, 10], state: "minecraft:jungle_leaves{distance:4,persistent:false,waterlogged:false}"},
        {pos: [7, 6, 2], state: "minecraft:jungle_log{axis:y}"},
        {pos: [1, 7, 7], state: "minecraft:jungle_leaves{distance:2,persistent:false,waterlogged:false}"},
        {pos: [1, 7, 8], state: "minecraft:jungle_leaves{distance:1,persistent:false,waterlogged:false}"},
        {pos: [2, 7, 7], state: "minecraft:jungle_leaves{distance:1,persistent:false,waterlogged:false}"},
        {pos: [2, 7, 8], state: "minecraft:jungle_log{axis:y}"},
        {pos: [2, 7, 9], state: "minecraft:jungle_leaves{distance:1,persistent:false,waterlogged:false}"},
        {pos: [3, 7, 7], state: "minecraft:jungle_leaves{distance:2,persistent:false,waterlogged:false}"},
        {pos: [3, 7, 8], state: "minecraft:jungle_leaves{distance:1,persistent:false,waterlogged:false}"},
        {pos: [3, 7, 9], state: "minecraft:jungle_leaves{distance:2,persistent:false,waterlogged:false}"},
        {pos: [7, 7, 2], state: "minecraft:jungle_log{axis:y}"},
        {pos: [1, 8, 8], state: "minecraft:jungle_leaves{distance:2,persistent:false,waterlogged:false}"},
        {pos: [2, 8, 7], state: "minecraft:jungle_leaves{distance:2,persistent:false,waterlogged:false}"},
        {pos: [2, 8, 8], state: "minecraft:jungle_leaves{distance:1,persistent:false,waterlogged:false}"},
        {pos: [2, 8, 9], state: "minecraft:jungle_leaves{distance:2,persistent:false,waterlogged:false}"},
        {pos: [3, 8, 8], state: "minecraft:jungle_leaves{distance:2,persistent:false,waterlogged:false}"},
        {pos: [7, 8, 2], state: "minecraft:jungle_log{axis:y}"},
        {pos: [5, 9, 0], state: "minecraft:jungle_leaves{distance:4,persistent:false,waterlogged:false}"},
        {pos: [5, 9, 1], state: "minecraft:jungle_leaves{distance:3,persistent:false,waterlogged:false}"},
        {pos: [5, 9, 2], state: "minecraft:jungle_leaves{distance:2,persistent:false,waterlogged:false}"},
        {pos: [5, 9, 3], state: "minecraft:jungle_leaves{distance:3,persistent:false,waterlogged:false}"},
        {pos: [5, 9, 4], state: "minecraft:jungle_leaves{distance:4,persistent:false,waterlogged:false}"},
        {pos: [6, 9, 0], state: "minecraft:jungle_leaves{distance:3,persistent:false,waterlogged:false}"},
        {pos: [6, 9, 1], state: "minecraft:jungle_leaves{distance:2,persistent:false,waterlogged:false}"},
        {pos: [6, 9, 2], state: "minecraft:jungle_leaves{distance:1,persistent:false,waterlogged:false}"},
        {pos: [6, 9, 3], state: "minecraft:jungle_leaves{distance:2,persistent:false,waterlogged:false}"},
        {pos: [6, 9, 4], state: "minecraft:jungle_leaves{distance:3,persistent:false,waterlogged:false}"},
        {pos: [7, 9, 0], state: "minecraft:jungle_leaves{distance:2,persistent:false,waterlogged:false}"},
        {pos: [7, 9, 1], state: "minecraft:jungle_leaves{distance:1,persistent:false,waterlogged:false}"},
        {pos: [7, 9, 2], state: "minecraft:jungle_log{axis:y}"},
        {pos: [7, 9, 3], state: "minecraft:jungle_leaves{distance:1,persistent:false,waterlogged:false}"},
        {pos: [7, 9, 4], state: "minecraft:jungle_leaves{distance:2,persistent:false,waterlogged:false}"},
        {pos: [8, 9, 0], state: "minecraft:jungle_leaves{distance:3,persistent:false,waterlogged:false}"},
        {pos: [8, 9, 1], state: "minecraft:jungle_leaves{distance:2,persistent:false,waterlogged:false}"},
        {pos: [8, 9, 2], state: "minecraft:jungle_leaves{distance:1,persistent:false,waterlogged:false}"},
        {pos: [8, 9, 3], state: "minecraft:jungle_leaves{distance:2,persistent:false,waterlogged:false}"},
        {pos: [8, 9, 4], state: "minecraft:jungle_leaves{distance:3,persistent:false,waterlogged:false}"},
        {pos: [9, 9, 1], state: "minecraft:jungle_leaves{distance:3,persistent:false,waterlogged:false}"},
        {pos: [9, 9, 2], state: "minecraft:jungle_leaves{distance:2,persistent:false,waterlogged:false}"},
        {pos: [9, 9, 3], state: "minecraft:jungle_leaves{distance:3,persistent:false,waterlogged:false}"},
        {pos: [5, 10, 0], state: "minecraft:jungle_leaves{distance:4,persistent:false,waterlogged:false}"},
        {pos: [5, 10, 1], state: "minecraft:jungle_leaves{distance:3,persistent:false,waterlogged:false}"},
        {pos: [5, 10, 2], state: "minecraft:jungle_leaves{distance:2,persistent:false,waterlogged:false}"},
        {pos: [5, 10, 3], state: "minecraft:jungle_leaves{distance:3,persistent:false,waterlogged:false}"},
        {pos: [6, 10, 0], state: "minecraft:jungle_leaves{distance:3,persistent:false,waterlogged:false}"},
        {pos: [6, 10, 1], state: "minecraft:jungle_leaves{distance:2,persistent:false,waterlogged:false}"},
        {pos: [6, 10, 2], state: "minecraft:jungle_leaves{distance:1,persistent:false,waterlogged:false}"},
        {pos: [6, 10, 3], state: "minecraft:jungle_leaves{distance:2,persistent:false,waterlogged:false}"},
        {pos: [6, 10, 4], state: "minecraft:jungle_leaves{distance:3,persistent:false,waterlogged:false}"},
        {pos: [7, 10, 0], state: "minecraft:jungle_leaves{distance:2,persistent:false,waterlogged:false}"},
        {pos: [7, 10, 1], state: "minecraft:jungle_leaves{distance:1,persistent:false,waterlogged:false}"},
        {pos: [7, 10, 2], state: "minecraft:jungle_log{axis:y}"},
        {pos: [7, 10, 3], state: "minecraft:jungle_leaves{distance:1,persistent:false,waterlogged:false}"},
        {pos: [7, 10, 4], state: "minecraft:jungle_leaves{distance:2,persistent:false,waterlogged:false}"},
        {pos: [8, 10, 0], state: "minecraft:jungle_leaves{distance:3,persistent:false,waterlogged:false}"},
        {pos: [8, 10, 1], state: "minecraft:jungle_leaves{distance:2,persistent:false,waterlogged:false}"},
        {pos: [8, 10, 2], state: "minecraft:jungle_leaves{distance:1,persistent:false,waterlogged:false}"},
        {pos: [8, 10, 3], state: "minecraft:jungle_leaves{distance:2,persistent:false,waterlogged:false}"},
        {pos: [8, 10, 4], state: "minecraft:jungle_leaves{distance:3,persistent:false,waterlogged:false}"},
        {pos: [9, 10, 0], state: "minecraft:jungle_leaves{distance:4,persistent:false,waterlogged:false}"},
        {pos: [9, 10, 1], state: "minecraft:jungle_leaves{distance:3,persistent:false,waterlogged:false}"},
        {pos: [9, 10, 2], state: "minecraft:jungle_leaves{distance:2,persistent:false,waterlogged:false}"},
        {pos: [9, 10, 3], state: "minecraft:jungle_leaves{distance:3,persistent:false,waterlogged:false}"},
        {pos: [9, 10, 4], state: "minecraft:jungle_leaves{distance:4,persistent:false,waterlogged:false}"},
        {pos: [6, 11, 1], state: "minecraft:jungle_leaves{distance:2,persistent:false,waterlogged:false}"},
        {pos: [6, 11, 2], state: "minecraft:jungle_leaves{distance:1,persistent:false,waterlogged:false}"},
        {pos: [7, 11, 1], state: "minecraft:jungle_leaves{distance:1,persistent:false,waterlogged:false}"},
        {pos: [7, 11, 2], state: "minecraft:jungle_log{axis:y}"},
        {pos: [7, 11, 3], state: "minecraft:jungle_leaves{distance:1,persistent:false,waterlogged:false}"},
        {pos: [8, 11, 1], state: "minecraft:jungle_leaves{distance:2,persistent:false,waterlogged:false}"},
        {pos: [8, 11, 2], state: "minecraft:jungle_leaves{distance:1,persistent:false,waterlogged:false}"},
        {pos: [6, 12, 2], state: "minecraft:jungle_leaves{distance:2,persistent:false,waterlogged:false}"},
        {pos: [7, 12, 1], state: "minecraft:jungle_leaves{distance:2,persistent:false,waterlogged:false}"},
        {pos: [7, 12, 2], state: "minecraft:jungle_leaves{distance:1,persistent:false,waterlogged:false}"},
        {pos: [7, 12, 3], state: "minecraft:jungle_leaves{distance:2,persistent:false,waterlogged:false}"},
        {pos: [8, 12, 2], state: "minecraft:jungle_leaves{distance:2,persistent:false,waterlogged:false}"}
    ],
    entities: [
        {blockPos: [5, 0, 5], pos: [5.5d, 0.9375d, 5.5d], nbt: {Air: 300s, Fire: 0s, Invulnerable: 0b, Motion: [0.0d, 0.0d, 0.0d], OnGround: 0b, PortalCooldown: 0, Pos: [-88.5d, -60.0625d, -58.5d], Rotation: [0.0f, 0.0f], UUID: [I; 1841232916, 1388396858, -1783601615, -904863149], block_pos: [I; -89, -61, -59], color: "brown", fall_distance: 0.0d, id: "minecraft:cushion"}},
        {blockPos: [5, 0, 8], pos: [5.5d, 0.9375d, 8.5d], nbt: {Air: 300s, Fire: 0s, Invulnerable: 0b, Motion: [0.0d, 0.0d, 0.0d], OnGround: 0b, PortalCooldown: 0, Pos: [-88.5d, -60.0625d, -55.5d], Rotation: [0.0f, 0.0f], UUID: [I; 2142662268, 845236202, -1489293317, 1974651819], block_pos: [I; -89, -61, -56], color: "black", fall_distance: 0.0d, id: "minecraft:cushion"}},
        {blockPos: [6, 0, 6], pos: [6.5d, 0.9375d, 6.5d], nbt: {Air: 300s, Fire: 0s, Invulnerable: 0b, Motion: [0.0d, 0.0d, 0.0d], OnGround: 0b, PortalCooldown: 0, Pos: [-87.5d, -60.0625d, -57.5d], Rotation: [90.0f, 0.0f], UUID: [I; 1840005642, -1376696390, -1714094112, 1850842638], block_pos: [I; -88, -61, -58], color: "light_gray", fall_distance: 0.0d, id: "minecraft:cushion"}}
    ],
    palette: [
        "minecraft:dirt",
        "minecraft:grass_block{snowy:false}",
        "minecraft:stone",
        "minecraft:jungle_log{axis:y}",
        "minecraft:jungle_leaves{distance:4,persistent:false,waterlogged:false}",
        "minecraft:jungle_leaves{distance:3,persistent:false,waterlogged:false}",
        "minecraft:jungle_leaves{distance:2,persistent:false,waterlogged:false}",
        "minecraft:jungle_leaves{distance:1,persistent:false,waterlogged:false}",
        "minecraft:dirt_path",
        "minecraft:cobweb",
        "minecraft:jungle_fence{east:false,north:false,south:false,waterlogged:false,west:false}",
        "minecraft:cocoa{age:2,facing:south}",
        "minecraft:cocoa{age:2,facing:north}",
        "minecraft:cocoa{age:2,facing:west}",
        "minecraft:jigsaw{orientation:east_up}",
        "minecraft:chest{facing:south,type:single,waterlogged:false}",
        "minecraft:campfire{facing:east,lit:false,signal_fire:false,waterlogged:false}"
    ]
}
