{
    size: [10, 12, 10],
    data: [
        {pos: [1, 0, 2], state: "minecraft:grass_block{snowy:false}"},
        {pos: [1, 0, 7], state: "minecraft:vine{east:true,north:false,south:false,up:false,west:false}"},
        {pos: [2, 0, 1], state: "minecraft:grass_block{snowy:false}"},
        {pos: [2, 0, 2], state: "minecraft:grass_block{snowy:false}"},
        {pos: [2, 0, 4], state: "minecraft:dirt_path"},
        {pos: [2, 0, 5], state: "minecraft:dirt_path"},
        {pos: [2, 0, 6], state: "minecraft:vine{east:false,north:false,south:true,up:false,west:false}"},
        {pos: [2, 0, 7], state: "minecraft:dirt"},
        {pos: [2, 0, 8], state: "minecraft:vine{east:false,north:true,south:false,up:false,west:false}"},
        {pos: [3, 0, 1], state: "minecraft:grass_block{snowy:false}"},
        {pos: [3, 0, 2], state: "minecraft:dirt"},
        {pos: [3, 0, 3], state: "minecraft:grass_block{snowy:false}"},
        {pos: [3, 0, 4], state: "minecraft:grass_block{snowy:false}"},
        {pos: [3, 0, 5], state: "minecraft:dirt_path"},
        {pos: [3, 0, 7], state: "minecraft:vine{east:false,north:false,south:false,up:false,west:true}"},
        {pos: [4, 0, 0], state: "minecraft:grass_block{snowy:false}"},
        {pos: [4, 0, 1], state: "minecraft:grass_block{snowy:false}"},
        {pos: [4, 0, 2], state: "minecraft:oxidized_copper_chest{facing:south,type:single,waterlogged:false}", nbt: {Items: [], LootTable: "minecraft:chests/abandoned_camp_secret_chest", components: {}, id: "minecraft:chest"}},
        {pos: [4, 0, 3], state: "minecraft:grass_block{snowy:false}"},
        {pos: [4, 0, 4], state: "minecraft:dirt_path"},
        {pos: [4, 0, 6], state: "minecraft:vine{east:false,north:false,south:true,up:false,west:false}"},
        {pos: [4, 0, 7], state: "minecraft:dirt"},
        {pos: [5, 0, 0], state: "minecraft:grass_block{snowy:false}"},
        {pos: [5, 0, 1], state: "minecraft:grass_block{snowy:false}"},
        {pos: [5, 0, 2], state: "minecraft:dirt_path"},
        {pos: [5, 0, 5], state: "minecraft:grass_block{snowy:false}"},
        {pos: [5, 0, 6], state: "minecraft:grass_block{snowy:false}"},
        {pos: [5, 0, 7], state: "minecraft:dirt"},
        {pos: [6, 0, 0], state: "minecraft:grass_block{snowy:false}"},
        {pos: [6, 0, 1], state: "minecraft:grass_block{snowy:false}"},
        {pos: [6, 0, 2], state: "minecraft:grass_block{snowy:false}"},
        {pos: [6, 0, 4], state: "minecraft:dirt_path"},
        {pos: [6, 0, 7], state: "minecraft:dirt"},
        {pos: [7, 0, 1], state: "minecraft:grass_block{snowy:false}"},
        {pos: [7, 0, 2], state: "minecraft:grass_block{snowy:false}"},
        {pos: [7, 0, 3], state: "minecraft:grass_block{snowy:false}"},
        {pos: [7, 0, 4], state: "minecraft:dirt_path"},
        {pos: [7, 0, 6], state: "minecraft:dirt"},
        {pos: [8, 0, 2], state: "minecraft:grass_block{snowy:false}"},
        {pos: [8, 0, 4], state: "minecraft:dirt_path"},
        {pos: [8, 0, 5], state: "minecraft:dirt_path"},
        {pos: [9, 0, 4], state: "minecraft:jigsaw{orientation:east_up}", nbt: {components: {}, final_state: "minecraft:dirt_path", id: "minecraft:jigsaw", joint: "rollable", name: "minecraft:end_connector", placement_priority: 0, pool: "minecraft:empty", selection_priority: 0, target: "minecraft:connector"}},
        {pos: [9, 0, 5], state: "minecraft:dirt_path"},
        {pos: [1, 1, 7], state: "minecraft:vine{east:true,north:false,south:false,up:false,west:false}"},
        {pos: [2, 1, 6], state: "minecraft:vine{east:false,north:false,south:true,up:false,west:false}"},
        {pos: [2, 1, 7], state: "minecraft:jungle_log{axis:y}"},
        {pos: [2, 1, 8], state: "minecraft:vine{east:false,north:true,south:false,up:false,west:false}"},
        {pos: [3, 1, 2], state: "minecraft:jungle_log{axis:y}"},
        {pos: [3, 1, 7], state: "minecraft:vine{east:false,north:false,south:false,up:false,west:true}"},
        {pos: [4, 1, 2], state: "minecraft:barrel{facing:east,open:false}", nbt: {Items: [], LootTable: "minecraft:barrels/abandoned_camp_barrel", components: {}, id: "minecraft:barrel"}},
        {pos: [4, 1, 5], state: "minecraft:cobweb"},
        {pos: [4, 1, 6], state: "minecraft:vine{east:false,north:false,south:true,up:false,west:false}"},
        {pos: [4, 1, 7], state: "minecraft:jungle_log{axis:x}"},
        {pos: [5, 1, 4], state: "minecraft:cobweb"},
        {pos: [5, 1, 5], state: "minecraft:campfire{facing:west,lit:false,signal_fire:false,waterlogged:false}", nbt: {CookingTimes: [I; 0, 0, 0, 0], CookingTotalTimes: [I; 0, 0, 0, 0], Items: [], components: {}, id: "minecraft:campfire"}},
        {pos: [5, 1, 6], state: "minecraft:vine{east:false,north:false,south:true,up:false,west:false}"},
        {pos: [5, 1, 7], state: "minecraft:jungle_log{axis:x}"},
        {pos: [6, 1, 2], state: "minecraft:jungle_fence{east:false,north:false,south:false,waterlogged:false,west:false}"},
        {pos: [6, 1, 5], state: "minecraft:cobweb"},
        {pos: [6, 1, 7], state: "minecraft:jungle_log{axis:x}"},
        {pos: [7, 1, 6], state: "minecraft:barrel{facing:up,open:false}", nbt: {Items: [], LootTable: "minecraft:barrels/abandoned_camp_barrel", components: {}, id: "minecraft:barrel"}},
        {pos: [1, 2, 7], state: "minecraft:vine{east:true,north:false,south:false,up:false,west:false}"},
        {pos: [2, 2, 6], state: "minecraft:cocoa{age:2,facing:south}"},
        {pos: [2, 2, 7], state: "minecraft:jungle_log{axis:y}"},
        {pos: [2, 2, 8], state: "minecraft:vine{east:false,north:true,south:false,up:false,west:false}"},
        {pos: [3, 2, 2], state: "minecraft:jungle_log{axis:y}"},
        {pos: [3, 2, 7], state: "minecraft:vine{east:false,north:false,south:false,up:false,west:true}"},
        {pos: [1, 3, 7], state: "minecraft:vine{east:true,north:false,south:false,up:false,west:false}"},
        {pos: [2, 3, 6], state: "minecraft:vine{east:false,north:false,south:true,up:false,west:false}"},
        {pos: [2, 3, 7], state: "minecraft:jungle_log{axis:y}"},
        {pos: [2, 3, 8], state: "minecraft:vine{east:false,north:true,south:false,up:false,west:false}"},
        {pos: [3, 3, 2], state: "minecraft:jungle_log{axis:y}"},
        {pos: [3, 3, 3], state: "minecraft:cocoa{age:2,facing:north}"},
        {pos: [3, 3, 7], state: "minecraft:vine{east:false,north:false,south:false,up:false,west:true}"},
        {pos: [1, 4, 7], state: "minecraft:vine{east:true,north:false,south:false,up:false,west:false}"},
        {pos: [2, 4, 6], state: "minecraft:vine{east:false,north:false,south:true,up:false,west:false}"},
        {pos: [2, 4, 7], state: "minecraft:jungle_log{axis:y}"},
        {pos: [2, 4, 8], state: "minecraft:vine{east:false,north:true,south:false,up:false,west:false}"},
        {pos: [3, 4, 2], state: "minecraft:jungle_log{axis:y}"},
        {pos: [3, 4, 7], state: "minecraft:vine{east:false,north:false,south:false,up:false,west:true}"},
        {pos: [1, 5, 7], state: "minecraft:vine{east:true,north:false,south:false,up:false,west:false}"},
        {pos: [2, 5, 7], state: "minecraft:jungle_log{axis:y}"},
        {pos: [2, 5, 8], state: "minecraft:vine{east:false,north:true,south:false,up:false,west:false}"},
        {pos: [3, 5, 2], state: "minecraft:jungle_log{axis:y}"},
        {pos: [3, 5, 7], state: "minecraft:vine{east:false,north:false,south:false,up:false,west:true}"},
        {pos: [1, 6, 7], state: "minecraft:vine{east:true,north:false,south:false,up:true,west:false}"},
        {pos: [2, 6, 7], state: "minecraft:jungle_log{axis:y}"},
        {pos: [2, 6, 8], state: "minecraft:vine{east:false,north:true,south:false,up:true,west:false}"},
        {pos: [3, 6, 2], state: "minecraft:jungle_log{axis:y}"},
        {pos: [3, 6, 7], state: "minecraft:vine{east:false,north:false,south:false,up:true,west:true}"},
        {pos: [0, 7, 5], state: "minecraft:jungle_leaves{distance:4,persistent:false,waterlogged:false}"},
        {pos: [0, 7, 6], state: "minecraft:jungle_leaves{distance:3,persistent:false,waterlogged:false}"},
        {pos: [0, 7, 7], state: "minecraft:jungle_leaves{distance:2,persistent:false,waterlogged:false}"},
        {pos: [0, 7, 8], state: "minecraft:jungle_leaves{distance:3,persistent:false,waterlogged:false}"},
        {pos: [1, 7, 0], state: "minecraft:jungle_leaves{distance:4,persistent:false,waterlogged:false}"},
        {pos: [1, 7, 1], state: "minecraft:jungle_leaves{distance:3,persistent:false,waterlogged:false}"},
        {pos: [1, 7, 2], state: "minecraft:jungle_leaves{distance:2,persistent:false,waterlogged:false}"},
        {pos: [1, 7, 3], state: "minecraft:jungle_leaves{distance:3,persistent:false,waterlogged:false}"},
        {pos: [1, 7, 5], state: "minecraft:jungle_leaves{distance:3,persistent:false,waterlogged:false}"},
        {pos: [1, 7, 6], state: "minecraft:jungle_leaves{distance:2,persistent:false,waterlogged:false}"},
        {pos: [1, 7, 7], state: "minecraft:jungle_leaves{distance:1,persistent:false,waterlogged:false}"},
        {pos: [1, 7, 8], state: "minecraft:jungle_leaves{distance:2,persistent:false,waterlogged:false}"},
        {pos: [1, 7, 9], state: "minecraft:jungle_leaves{distance:3,persistent:false,waterlogged:false}"},
        {pos: [2, 7, 0], state: "minecraft:jungle_leaves{distance:3,persistent:false,waterlogged:false}"},
        {pos: [2, 7, 1], state: "minecraft:jungle_leaves{distance:2,persistent:false,waterlogged:false}"},
        {pos: [2, 7, 2], state: "minecraft:jungle_leaves{distance:1,persistent:false,waterlogged:false}"},
        {pos: [2, 7, 3], state: "minecraft:jungle_leaves{distance:2,persistent:false,waterlogged:false}"},
        {pos: [2, 7, 4], state: "minecraft:jungle_leaves{distance:3,persistent:false,waterlogged:false}"},
        {pos: [2, 7, 5], state: "minecraft:jungle_leaves{distance:2,persistent:false,waterlogged:false}"},
        {pos: [2, 7, 6], state: "minecraft:jungle_leaves{distance:1,persistent:false,waterlogged:false}"},
        {pos: [2, 7, 7], state: "minecraft:jungle_log{axis:y}"},
        {pos: [2, 7, 8], state: "minecraft:jungle_leaves{distance:1,persistent:false,waterlogged:false}"},
        {pos: [2, 7, 9], state: "minecraft:jungle_leaves{distance:2,persistent:false,waterlogged:false}"},
        {pos: [3, 7, 0], state: "minecraft:jungle_leaves{distance:2,persistent:false,waterlogged:false}"},
        {pos: [3, 7, 1], state: "minecraft:jungle_leaves{distance:1,persistent:false,waterlogged:false}"},
        {pos: [3, 7, 2], state: "minecraft:jungle_log{axis:y}"},
        {pos: [3, 7, 3], state: "minecraft:jungle_leaves{distance:1,persistent:false,waterlogged:false}"},
        {pos: [3, 7, 4], state: "minecraft:jungle_leaves{distance:2,persistent:false,waterlogged:false}"},
        {pos: [3, 7, 5], state: "minecraft:jungle_leaves{distance:3,persistent:false,waterlogged:false}"},
        {pos: [3, 7, 6], state: "minecraft:jungle_leaves{distance:2,persistent:false,waterlogged:false}"},
        {pos: [3, 7, 7], state: "minecraft:jungle_leaves{distance:1,persistent:false,waterlogged:false}"},
        {pos: [3, 7, 8], state: "minecraft:jungle_leaves{distance:2,persistent:false,waterlogged:false}"},
        {pos: [3, 7, 9], state: "minecraft:jungle_leaves{distance:3,persistent:false,waterlogged:false}"},
        {pos: [4, 7, 0], state: "minecraft:jungle_leaves{distance:3,persistent:false,waterlogged:false}"},
        {pos: [4, 7, 1], state: "minecraft:jungle_leaves{distance:2,persistent:false,waterlogged:false}"},
        {pos: [4, 7, 2], state: "minecraft:jungle_leaves{distance:1,persistent:false,waterlogged:false}"},
        {pos: [4, 7, 3], state: "minecraft:jungle_leaves{distance:2,persistent:false,waterlogged:false}"},
        {pos: [4, 7, 4], state: "minecraft:jungle_leaves{distance:3,persistent:false,waterlogged:false}"},
        {pos: [4, 7, 6], state: "minecraft:jungle_leaves{distance:3,persistent:false,waterlogged:false}"},
        {pos: [4, 7, 7], state: "minecraft:jungle_leaves{distance:2,persistent:false,waterlogged:false}"},
        {pos: [4, 7, 8], state: "minecraft:jungle_leaves{distance:3,persistent:false,waterlogged:false}"},
        {pos: [4, 7, 9], state: "minecraft:jungle_leaves{distance:4,persistent:false,waterlogged:false}"},
        {pos: [5, 7, 1], state: "minecraft:jungle_leaves{distance:3,persistent:false,waterlogged:false}"},
        {pos: [5, 7, 2], state: "minecraft:jungle_leaves{distance:2,persistent:false,waterlogged:false}"},
        {pos: [5, 7, 3], state: "minecraft:jungle_leaves{distance:3,persistent:false,waterlogged:false}"},
        {pos: [0, 8, 6], state: "minecraft:jungle_leaves{distance:3,persistent:false,waterlogged:false}"},
        {pos: [0, 8, 7], state: "minecraft:jungle_leaves{distance:2,persistent:false,waterlogged:false}"},
        {pos: [0, 8, 8], state: "minecraft:jungle_leaves{distance:3,persistent:false,waterlogged:false}"},
        {pos: [1, 8, 0], state: "minecraft:jungle_leaves{distance:4,persistent:false,waterlogged:false}"},
        {pos: [1, 8, 1], state: "minecraft:jungle_leaves{distance:3,persistent:false,waterlogged:false}"},
        {pos: [1, 8, 2], state: "minecraft:jungle_leaves{distance:2,persistent:false,waterlogged:false}"},
        {pos: [1, 8, 3], state: "minecraft:jungle_leaves{distance:3,persistent:false,waterlogged:false}"},
        {pos: [1, 8, 4], state: "minecraft:jungle_leaves{distance:4,persistent:false,waterlogged:false}"},
        {pos: [1, 8, 5], state: "minecraft:jungle_leaves{distance:3,persistent:false,waterlogged:false}"},
        {pos: [1, 8, 6], state: "minecraft:jungle_leaves{distance:2,persistent:false,waterlogged:false}"},
        {pos: [1, 8, 7], state: "minecraft:jungle_leaves{distance:1,persistent:false,waterlogged:false}"},
        {pos: [1, 8, 8], state: "minecraft:jungle_leaves{distance:2,persistent:false,waterlogged:false}"},
        {pos: [1, 8, 9], state: "minecraft:jungle_leaves{distance:3,persistent:false,waterlogged:false}"},
        {pos: [2, 8, 0], state: "minecraft:jungle_leaves{distance:3,persistent:false,waterlogged:false}"},
        {pos: [2, 8, 1], state: "minecraft:jungle_leaves{distance:2,persistent:false,waterlogged:false}"},
        {pos: [2, 8, 2], state: "minecraft:jungle_leaves{distance:1,persistent:false,waterlogged:false}"},
        {pos: [2, 8, 3], state: "minecraft:jungle_leaves{distance:2,persistent:false,waterlogged:false}"},
        {pos: [2, 8, 4], state: "minecraft:jungle_leaves{distance:3,persistent:false,waterlogged:false}"},
        {pos: [2, 8, 5], state: "minecraft:jungle_leaves{distance:2,persistent:false,waterlogged:false}"},
        {pos: [2, 8, 6], state: "minecraft:jungle_leaves{distance:1,persistent:false,waterlogged:false}"},
        {pos: [2, 8, 7], state: "minecraft:jungle_log{axis:y}"},
        {pos: [2, 8, 8], state: "minecraft:jungle_leaves{distance:1,persistent:false,waterlogged:false}"},
        {pos: [2, 8, 9], state: "minecraft:jungle_leaves{distance:2,persistent:false,waterlogged:false}"},
        {pos: [3, 8, 0], state: "minecraft:jungle_leaves{distance:2,persistent:false,waterlogged:false}"},
        {pos: [3, 8, 1], state: "minecraft:jungle_leaves{distance:1,persistent:false,waterlogged:false}"},
        {pos: [3, 8, 2], state: "minecraft:jungle_log{axis:y}"},
        {pos: [3, 8, 3], state: "minecraft:jungle_leaves{distance:1,persistent:false,waterlogged:false}"},
        {pos: [3, 8, 4], state: "minecraft:jungle_leaves{distance:2,persistent:false,waterlogged:false}"},
        {pos: [3, 8, 5], state: "minecraft:jungle_leaves{distance:3,persistent:false,waterlogged:false}"},
        {pos: [3, 8, 6], state: "minecraft:jungle_leaves{distance:2,persistent:true,waterlogged:false}"},
        {pos: [3, 8, 7], state: "minecraft:jungle_leaves{distance:1,persistent:false,waterlogged:false}"},
        {pos: [3, 8, 8], state: "minecraft:jungle_leaves{distance:2,persistent:false,waterlogged:false}"},
        {pos: [3, 8, 9], state: "minecraft:jungle_leaves{distance:3,persistent:false,waterlogged:false}"},
        {pos: [4, 8, 0], state: "minecraft:jungle_leaves{distance:3,persistent:false,waterlogged:false}"},
        {pos: [4, 8, 1], state: "minecraft:jungle_leaves{distance:2,persistent:false,waterlogged:false}"},
        {pos: [4, 8, 2], state: "minecraft:jungle_leaves{distance:1,persistent:false,waterlogged:false}"},
        {pos: [4, 8, 3], state: "minecraft:jungle_leaves{distance:2,persistent:false,waterlogged:false}"},
        {pos: [4, 8, 4], state: "minecraft:jungle_leaves{distance:3,persistent:false,waterlogged:false}"},
        {pos: [4, 8, 5], state: "minecraft:jungle_leaves{distance:4,persistent:false,waterlogged:false}"},
        {pos: [4, 8, 6], state: "minecraft:jungle_leaves{distance:3,persistent:false,waterlogged:false}"},
        {pos: [4, 8, 7], state: "minecraft:jungle_leaves{distance:2,persistent:false,waterlogged:false}"},
        {pos: [4, 8, 8], state: "minecraft:jungle_leaves{distance:3,persistent:false,waterlogged:false}"},
        {pos: [5, 8, 1], state: "minecraft:jungle_leaves{distance:3,persistent:false,waterlogged:false}"},
        {pos: [5, 8, 2], state: "minecraft:jungle_leaves{distance:2,persistent:false,waterlogged:false}"},
        {pos: [5, 8, 3], state: "minecraft:jungle_leaves{distance:3,persistent:false,waterlogged:false}"},
        {pos: [5, 8, 4], state: "minecraft:jungle_leaves{distance:4,persistent:false,waterlogged:false}"},
        {pos: [1, 9, 7], state: "minecraft:jungle_leaves{distance:1,persistent:false,waterlogged:false}"},
        {pos: [2, 9, 1], state: "minecraft:jungle_leaves{distance:2,persistent:false,waterlogged:false}"},
        {pos: [2, 9, 2], state: "minecraft:jungle_leaves{distance:1,persistent:false,waterlogged:false}"},
        {pos: [2, 9, 6], state: "minecraft:jungle_leaves{distance:1,persistent:true,waterlogged:false}"},
        {pos: [2, 9, 7], state: "minecraft:jungle_log{axis:y}"},
        {pos: [2, 9, 8], state: "minecraft:jungle_leaves{distance:1,persistent:false,waterlogged:false}"},
        {pos: [3, 9, 1], state: "minecraft:jungle_leaves{distance:1,persistent:false,waterlogged:false}"},
        {pos: [3, 9, 2], state: "minecraft:jungle_log{axis:y}"},
        {pos: [3, 9, 3], state: "minecraft:jungle_leaves{distance:1,persistent:false,waterlogged:false}"},
        {pos: [3, 9, 7], state: "minecraft:jungle_leaves{distance:1,persistent:true,waterlogged:false}"},
        {pos: [3, 9, 8], state: "minecraft:jungle_leaves{distance:2,persistent:true,waterlogged:false}"},
        {pos: [4, 9, 2], state: "minecraft:jungle_leaves{distance:1,persistent:false,waterlogged:false}"},
        {pos: [4, 9, 3], state: "minecraft:jungle_leaves{distance:2,persistent:false,waterlogged:false}"},
        {pos: [1, 10, 7], state: "minecraft:jungle_leaves{distance:2,persistent:false,waterlogged:false}"},
        {pos: [2, 10, 2], state: "minecraft:jungle_leaves{distance:2,persistent:false,waterlogged:false}"},
        {pos: [2, 10, 6], state: "minecraft:jungle_leaves{distance:2,persistent:false,waterlogged:false}"},
        {pos: [2, 10, 7], state: "minecraft:jungle_leaves{distance:1,persistent:false,waterlogged:false}"},
        {pos: [2, 10, 8], state: "minecraft:jungle_leaves{distance:2,persistent:false,waterlogged:false}"},
        {pos: [3, 10, 1], state: "minecraft:jungle_leaves{distance:2,persistent:false,waterlogged:false}"},
        {pos: [3, 10, 2], state: "minecraft:jungle_leaves{distance:1,persistent:false,waterlogged:false}"},
        {pos: [3, 10, 3], state: "minecraft:jungle_leaves{distance:2,persistent:false,waterlogged:false}"},
        {pos: [3, 10, 7], state: "minecraft:jungle_leaves{distance:2,persistent:false,waterlogged:false}"},
        {pos: [4, 10, 2], state: "minecraft:jungle_leaves{distance:2,persistent:false,waterlogged:false}"}
    ],
    entities: [
        {blockPos: [4, 0, 4], pos: [4.5d, 0.9375d, 4.5d], nbt: {Air: 300s, Fire: 0s, Invulnerable: 0b, Motion: [0.0d, 0.0d, 0.0d], OnGround: 0b, PortalCooldown: 0, Pos: [-89.5d, -60.0625d, -73.5d], Rotation: [90.0f, 0.0f], UUID: [I; 1769704749, 67715306, -1324283751, -1284985202], block_pos: [I; -90, -61, -74], color: "red", fall_distance: 0.0d, id: "minecraft:cushion"}}
    ],
    palette: [
        "minecraft:grass_block{snowy:false}",
        "minecraft:dirt",
        "minecraft:jungle_log{axis:y}",
        "minecraft:jungle_log{axis:x}",
        "minecraft:jungle_leaves{distance:4,persistent:false,waterlogged:false}",
        "minecraft:jungle_leaves{distance:3,persistent:false,waterlogged:false}",
        "minecraft:jungle_leaves{distance:2,persistent:false,waterlogged:false}",
        "minecraft:jungle_leaves{distance:1,persistent:false,waterlogged:false}",
        "minecraft:jungle_leaves{distance:2,persistent:true,waterlogged:false}",
        "minecraft:jungle_leaves{distance:1,persistent:true,waterlogged:false}",
        "minecraft:vine{east:true,north:false,south:false,up:false,west:false}",
        "minecraft:dirt_path",
        "minecraft:vine{east:false,north:false,south:true,up:false,west:false}",
        "minecraft:vine{east:false,north:true,south:false,up:false,west:false}",
        "minecraft:vine{east:false,north:false,south:false,up:false,west:true}",
        "minecraft:cobweb",
        "minecraft:jungle_fence{east:false,north:false,south:false,waterlogged:false,west:false}",
        "minecraft:cocoa{age:2,facing:south}",
        "minecraft:cocoa{age:2,facing:north}",
        "minecraft:vine{east:true,north:false,south:false,up:true,west:false}",
        "minecraft:vine{east:false,north:true,south:false,up:true,west:false}",
        "minecraft:vine{east:false,north:false,south:false,up:true,west:true}",
        "minecraft:oxidized_copper_chest{facing:south,type:single,waterlogged:false}",
        "minecraft:jigsaw{orientation:east_up}",
        "minecraft:barrel{facing:east,open:false}",
        "minecraft:campfire{facing:west,lit:false,signal_fire:false,waterlogged:false}",
        "minecraft:barrel{facing:up,open:false}"
    ]
}
