{
    size: [10, 10, 10],
    data: [
        {pos: [0, 0, 4], state: "minecraft:dirt"},
        {pos: [0, 0, 5], state: "minecraft:dirt"},
        {pos: [0, 0, 6], state: "minecraft:dirt"},
        {pos: [0, 0, 7], state: "minecraft:dirt"},
        {pos: [1, 0, 3], state: "minecraft:vine{east:false,north:false,south:true,up:false,west:false}"},
        {pos: [1, 0, 4], state: "minecraft:dirt"},
        {pos: [1, 0, 5], state: "minecraft:gravel"},
        {pos: [1, 0, 6], state: "minecraft:dirt"},
        {pos: [1, 0, 7], state: "minecraft:dirt"},
        {pos: [1, 0, 8], state: "minecraft:dirt"},
        {pos: [1, 0, 9], state: "minecraft:dirt"},
        {pos: [2, 0, 4], state: "minecraft:vine{east:false,north:false,south:true,up:false,west:false}"},
        {pos: [2, 0, 5], state: "minecraft:gravel"},
        {pos: [2, 0, 6], state: "minecraft:gravel"},
        {pos: [2, 0, 7], state: "minecraft:gravel"},
        {pos: [2, 0, 8], state: "minecraft:dirt"},
        {pos: [2, 0, 9], state: "minecraft:dirt"},
        {pos: [3, 0, 1], state: "minecraft:jigsaw{orientation:up_north}", nbt: {components: {}, final_state: "minecraft:dirt", id: "minecraft:jigsaw", joint: "rollable", name: "minecraft:bottom", placement_priority: 0, pool: "minecraft:abandoned_camp/trees/jungle", selection_priority: 0, target: "minecraft:bottom"}},
        {pos: [3, 0, 3], state: "minecraft:dirt_path"},
        {pos: [3, 0, 4], state: "minecraft:dirt_path"},
        {pos: [3, 0, 5], state: "minecraft:vine{east:false,north:false,south:true,up:false,west:true}"},
        {pos: [3, 0, 6], state: "minecraft:gravel"},
        {pos: [3, 0, 7], state: "minecraft:oxidized_copper_chest{facing:north,type:single,waterlogged:false}", nbt: {Items: [], LootTable: "minecraft:chests/abandoned_camp_secret_chest", components: {}, id: "minecraft:chest"}},
        {pos: [3, 0, 8], state: "minecraft:dirt"},
        {pos: [3, 0, 9], state: "minecraft:dirt"},
        {pos: [4, 0, 2], state: "minecraft:dirt_path"},
        {pos: [4, 0, 3], state: "minecraft:dirt_path"},
        {pos: [4, 0, 4], state: "minecraft:dirt_path"},
        {pos: [4, 0, 5], state: "minecraft:dirt_path"},
        {pos: [4, 0, 6], state: "minecraft:gravel"},
        {pos: [4, 0, 7], state: "minecraft:dirt"},
        {pos: [4, 0, 8], state: "minecraft:dirt"},
        {pos: [4, 0, 9], state: "minecraft:dirt"},
        {pos: [5, 0, 1], state: "minecraft:dirt_path"},
        {pos: [5, 0, 2], state: "minecraft:dirt_path"},
        {pos: [5, 0, 3], state: "minecraft:dirt"},
        {pos: [5, 0, 4], state: "minecraft:dirt_path"},
        {pos: [5, 0, 5], state: "minecraft:dirt_path"},
        {pos: [5, 0, 7], state: "minecraft:dirt"},
        {pos: [5, 0, 8], state: "minecraft:dirt"},
        {pos: [6, 0, 2], state: "minecraft:dirt_path"},
        {pos: [6, 0, 3], state: "minecraft:dirt_path"},
        {pos: [6, 0, 4], state: "minecraft:dirt_path"},
        {pos: [7, 0, 3], state: "minecraft:dirt_path"},
        {pos: [7, 0, 4], state: "minecraft:dirt_path"},
        {pos: [7, 0, 5], state: "minecraft:vine{east:true,north:false,south:false,up:false,west:false}"},
        {pos: [7, 0, 7], state: "minecraft:jigsaw{orientation:up_east}", nbt: {components: {}, final_state: "minecraft:dirt", id: "minecraft:jigsaw", joint: "rollable", name: "minecraft:bottom", placement_priority: 0, pool: "minecraft:abandoned_camp/trees/jungle", selection_priority: 0, target: "minecraft:bottom"}},
        {pos: [8, 0, 1], state: "minecraft:jigsaw{orientation:up_east}", nbt: {components: {}, final_state: "minecraft:dirt", id: "minecraft:jigsaw", joint: "rollable", name: "minecraft:bottom", placement_priority: 0, pool: "minecraft:abandoned_camp/trees/jungle", selection_priority: 0, target: "minecraft:bottom"}},
        {pos: [8, 0, 3], state: "minecraft:dirt_path"},
        {pos: [8, 0, 4], state: "minecraft:dirt_path"},
        {pos: [8, 0, 5], state: "minecraft:dirt"},
        {pos: [9, 0, 3], state: "minecraft:dirt_path"},
        {pos: [9, 0, 4], state: "minecraft:jigsaw{orientation:east_up}", nbt: {components: {}, final_state: "minecraft:dirt_path", id: "minecraft:jigsaw", joint: "rollable", name: "minecraft:end_connector", placement_priority: 0, pool: "minecraft:empty", selection_priority: 0, target: "minecraft:connector"}},
        {pos: [9, 0, 5], state: "minecraft:vine{east:true,north:false,south:false,up:false,west:true}"},
        {pos: [0, 1, 4], state: "minecraft:grass_block{snowy:false}"},
        {pos: [0, 1, 5], state: "minecraft:stone"},
        {pos: [0, 1, 6], state: "minecraft:dirt"},
        {pos: [0, 1, 7], state: "minecraft:grass_block{snowy:false}"},
        {pos: [1, 1, 3], state: "minecraft:vine{east:false,north:false,south:true,up:false,west:false}"},
        {pos: [1, 1, 4], state: "minecraft:stone"},
        {pos: [1, 1, 5], state: "minecraft:barrel{facing:east,open:false}", nbt: {Items: [], LootTable: "minecraft:barrels/abandoned_camp_barrel", components: {}, id: "minecraft:barrel"}},
        {pos: [1, 1, 6], state: "minecraft:stone"},
        {pos: [1, 1, 7], state: "minecraft:stone"},
        {pos: [1, 1, 8], state: "minecraft:grass_block{snowy:false}"},
        {pos: [1, 1, 9], state: "minecraft:grass_block{snowy:false}"},
        {pos: [2, 1, 5], state: "minecraft:vine{east:false,north:false,south:true,up:false,west:true}"},
        {pos: [2, 1, 7], state: "minecraft:barrel{facing:north,open:false}", nbt: {Items: [], LootTable: "minecraft:barrels/abandoned_camp_barrel", components: {}, id: "minecraft:barrel"}},
        {pos: [2, 1, 8], state: "minecraft:stone"},
        {pos: [2, 1, 9], state: "minecraft:dirt"},
        {pos: [3, 1, 7], state: "minecraft:barrel{facing:north,open:false}", nbt: {Items: [], LootTable: "minecraft:barrels/abandoned_camp_barrel", components: {}, id: "minecraft:barrel"}},
        {pos: [3, 1, 8], state: "minecraft:stone"},
        {pos: [3, 1, 9], state: "minecraft:grass_block{snowy:false}"},
        {pos: [4, 1, 6], state: "minecraft:vine{east:false,north:false,south:true,up:false,west:false}"},
        {pos: [4, 1, 7], state: "minecraft:stone"},
        {pos: [4, 1, 8], state: "minecraft:grass_block{snowy:false}"},
        {pos: [4, 1, 9], state: "minecraft:grass_block{snowy:false}"},
        {pos: [5, 1, 3], state: "minecraft:campfire{facing:west,lit:false,signal_fire:false,waterlogged:false}", nbt: {CookingTimes: [I; 0, 0, 0, 0], CookingTotalTimes: [I; 0, 0, 0, 0], Items: [], components: {}, id: "minecraft:campfire"}},
        {pos: [5, 1, 7], state: "minecraft:grass_block{snowy:false}"},
        {pos: [5, 1, 8], state: "minecraft:grass_block{snowy:false}"},
        {pos: [7, 1, 5], state: "minecraft:vine{east:true,north:false,south:false,up:false,west:false}"},
        {pos: [8, 1, 4], state: "minecraft:vine{east:false,north:false,south:true,up:false,west:false}"},
        {pos: [8, 1, 5], state: "minecraft:stone"},
        {pos: [9, 1, 5], state: "minecraft:vine{east:false,north:false,south:false,up:false,west:true}"},
        {pos: [0, 2, 5], state: "minecraft:stone"},
        {pos: [0, 2, 6], state: "minecraft:grass_block{snowy:false}"},
        {pos: [1, 2, 4], state: "minecraft:grass_block{snowy:false}"},
        {pos: [1, 2, 5], state: "minecraft:stone"},
        {pos: [1, 2, 6], state: "minecraft:stone"},
        {pos: [1, 2, 7], state: "minecraft:grass_block{snowy:false}"},
        {pos: [2, 2, 5], state: "minecraft:vine{east:false,north:false,south:true,up:true,west:true}"},
        {pos: [2, 2, 6], state: "minecraft:stone"},
        {pos: [2, 2, 7], state: "minecraft:stone"},
        {pos: [2, 2, 8], state: "minecraft:stone"},
        {pos: [2, 2, 9], state: "minecraft:grass_block{snowy:false}"},
        {pos: [3, 2, 6], state: "minecraft:vine{east:false,north:false,south:true,up:true,west:true}"},
        {pos: [3, 2, 7], state: "minecraft:stone"},
        {pos: [3, 2, 8], state: "minecraft:stone"},
        {pos: [4, 2, 6], state: "minecraft:vine{east:false,north:false,south:true,up:false,west:false}"},
        {pos: [4, 2, 7], state: "minecraft:grass_block{snowy:false}"},
        {pos: [1, 3, 4], state: "minecraft:vine{east:false,north:false,south:true,up:false,west:false}"},
        {pos: [1, 3, 5], state: "minecraft:grass_block{snowy:false}"},
        {pos: [1, 3, 6], state: "minecraft:grass_block{snowy:false}"},
        {pos: [2, 3, 4], state: "minecraft:vine{east:false,north:false,south:true,up:false,west:false}"},
        {pos: [2, 3, 5], state: "minecraft:stone"},
        {pos: [2, 3, 6], state: "minecraft:jigsaw{orientation:up_north}", nbt: {components: {}, final_state: "minecraft:dirt", id: "minecraft:jigsaw", joint: "rollable", name: "minecraft:bottom", placement_priority: 0, pool: "minecraft:abandoned_camp/trees/jungle", selection_priority: 0, target: "minecraft:bottom"}},
        {pos: [2, 3, 7], state: "minecraft:grass_block{snowy:false}"},
        {pos: [2, 3, 8], state: "minecraft:grass_block{snowy:false}"},
        {pos: [3, 3, 5], state: "minecraft:vine{east:false,north:false,south:true,up:false,west:true}"},
        {pos: [3, 3, 6], state: "minecraft:stone"},
        {pos: [3, 3, 7], state: "minecraft:grass_block{snowy:false}"}
    ],
    entities: [
        {blockPos: [5, 0, 4], pos: [5.5d, 0.9375d, 4.5d], nbt: {Air: 300s, Fire: 0s, Invulnerable: 0b, Motion: [0.0d, 0.0d, 0.0d], OnGround: 0b, PortalCooldown: 0, Pos: [-105.5d, -60.0625d, -88.5d], Rotation: [90.0f, 0.0f], UUID: [I; 201309792, -810007865, -1701133855, 1998736454], block_pos: [I; -106, -61, -89], color: "red", fall_distance: 0.0d, id: "minecraft:cushion"}}
    ],
    palette: [
        "minecraft:dirt",
        "minecraft:gravel",
        "minecraft:grass_block{snowy:false}",
        "minecraft:stone",
        "minecraft:vine{east:false,north:false,south:true,up:false,west:false}",
        "minecraft:dirt_path",
        "minecraft:vine{east:false,north:false,south:true,up:false,west:true}",
        "minecraft:vine{east:true,north:false,south:false,up:false,west:false}",
        "minecraft:vine{east:true,north:false,south:false,up:false,west:true}",
        "minecraft:vine{east:false,north:false,south:false,up:false,west:true}",
        "minecraft:vine{east:false,north:false,south:true,up:true,west:true}",
        "minecraft:jigsaw{orientation:up_north}",
        "minecraft:oxidized_copper_chest{facing:north,type:single,waterlogged:false}",
        "minecraft:jigsaw{orientation:up_east}",
        "minecraft:jigsaw{orientation:east_up}",
        "minecraft:barrel{facing:east,open:false}",
        "minecraft:barrel{facing:north,open:false}",
        "minecraft:campfire{facing:west,lit:false,signal_fire:false,waterlogged:false}"
    ]
}
