{
    size: [10, 14, 11],
    data: [
        {pos: [3, 0, 4], state: "minecraft:dirt_path"},
        {pos: [3, 0, 5], state: "minecraft:dirt_path"},
        {pos: [3, 0, 6], state: "minecraft:dirt_path"},
        {pos: [4, 0, 3], state: "minecraft:dirt_path"},
        {pos: [4, 0, 4], state: "minecraft:dirt_path"},
        {pos: [4, 0, 5], state: "minecraft:dirt_path"},
        {pos: [4, 0, 7], state: "minecraft:dirt_path"},
        {pos: [5, 0, 3], state: "minecraft:dirt_path"},
        {pos: [5, 0, 4], state: "minecraft:grass_block{snowy:false}"},
        {pos: [5, 0, 7], state: "minecraft:dirt_path"},
        {pos: [6, 0, 3], state: "minecraft:dirt_path"},
        {pos: [6, 0, 4], state: "minecraft:dirt_path"},
        {pos: [6, 0, 5], state: "minecraft:dirt_path"},
        {pos: [7, 0, 4], state: "minecraft:dirt_path"},
        {pos: [7, 0, 5], state: "minecraft:dirt_path"},
        {pos: [8, 0, 5], state: "minecraft:dirt_path"},
        {pos: [8, 0, 6], state: "minecraft:dirt_path"},
        {pos: [9, 0, 4], state: "minecraft:jigsaw{orientation:east_up}", nbt: {components: {}, final_state: "minecraft:dirt_path", id: "minecraft:jigsaw", joint: "rollable", name: "minecraft:end_connector", placement_priority: 0, pool: "minecraft:empty", selection_priority: 0, target: "minecraft:connector"}},
        {pos: [9, 0, 5], state: "minecraft:dirt_path"},
        {pos: [9, 0, 6], state: "minecraft:dirt_path"},
        {pos: [9, 0, 7], state: "minecraft:dirt_path"},
        {pos: [1, 1, 3], state: "minecraft:vine{east:true,north:false,south:false,up:false,west:false}"},
        {pos: [2, 1, 2], state: "minecraft:vine{east:false,north:false,south:true,up:false,west:false}"},
        {pos: [2, 1, 3], state: "minecraft:jungle_log{axis:y}"},
        {pos: [2, 1, 7], state: "minecraft:jungle_log{axis:y}"},
        {pos: [4, 1, 2], state: "minecraft:jungle_log{axis:x}"},
        {pos: [4, 1, 3], state: "minecraft:vine{east:false,north:true,south:false,up:false,west:false}"},
        {pos: [5, 1, 2], state: "minecraft:jungle_log{axis:x}"},
        {pos: [5, 1, 4], state: "minecraft:campfire{facing:west,lit:false,signal_fire:false,waterlogged:false}", nbt: {CookingTimes: [I; 0, 0, 0, 0], CookingTotalTimes: [I; 0, 0, 0, 0], Items: [], components: {}, id: "minecraft:campfire"}},
        {pos: [5, 1, 6], state: "minecraft:jungle_log{axis:x}"},
        {pos: [5, 1, 8], state: "minecraft:vine{east:true,north:false,south:false,up:false,west:false}"},
        {pos: [6, 1, 2], state: "minecraft:chest{facing:south,type:single,waterlogged:false}", nbt: {LootTable: "minecraft:chests/abandoned_camp_common_chest", components: {}, id: "minecraft:chest"}},
        {pos: [6, 1, 5], state: "minecraft:vine{east:false,north:false,south:true,up:false,west:false}"},
        {pos: [6, 1, 6], state: "minecraft:jungle_log{axis:x}"},
        {pos: [6, 1, 7], state: "minecraft:vine{east:false,north:true,south:false,up:false,west:false}"},
        {pos: [6, 1, 8], state: "minecraft:jungle_log{axis:y}"},
        {pos: [6, 1, 9], state: "minecraft:vine{east:false,north:true,south:false,up:false,west:false}"},
        {pos: [7, 1, 2], state: "minecraft:jungle_fence{east:false,north:false,south:false,waterlogged:false,west:false}"},
        {pos: [7, 1, 5], state: "minecraft:vine{east:false,north:false,south:true,up:false,west:false}"},
        {pos: [7, 1, 6], state: "minecraft:jungle_log{axis:x}"},
        {pos: [7, 1, 7], state: "minecraft:vine{east:false,north:true,south:false,up:false,west:false}"},
        {pos: [7, 1, 8], state: "minecraft:vine{east:false,north:false,south:false,up:false,west:true}"},
        {pos: [8, 1, 6], state: "minecraft:vine{east:false,north:false,south:false,up:false,west:true}"},
        {pos: [1, 2, 3], state: "minecraft:vine{east:true,north:false,south:false,up:false,west:false}"},
        {pos: [2, 2, 2], state: "minecraft:vine{east:false,north:false,south:true,up:false,west:false}"},
        {pos: [2, 2, 3], state: "minecraft:jungle_log{axis:y}"},
        {pos: [2, 2, 4], state: "minecraft:cocoa{age:2,facing:north}"},
        {pos: [2, 2, 7], state: "minecraft:jungle_log{axis:y}"},
        {pos: [3, 2, 7], state: "minecraft:jungle_leaves{distance:1,persistent:true,waterlogged:false}"},
        {pos: [3, 2, 8], state: "minecraft:jungle_leaves{distance:2,persistent:true,waterlogged:false}"},
        {pos: [5, 2, 8], state: "minecraft:vine{east:true,north:false,south:false,up:false,west:false}"},
        {pos: [6, 2, 8], state: "minecraft:jungle_log{axis:y}"},
        {pos: [6, 2, 9], state: "minecraft:vine{east:false,north:true,south:false,up:false,west:false}"},
        {pos: [7, 2, 8], state: "minecraft:vine{east:false,north:false,south:false,up:false,west:true}"},
        {pos: [0, 3, 5], state: "minecraft:jungle_leaves{distance:4,persistent:false,waterlogged:false}"},
        {pos: [0, 3, 6], state: "minecraft:jungle_leaves{distance:3,persistent:false,waterlogged:false}"},
        {pos: [0, 3, 7], state: "minecraft:jungle_leaves{distance:2,persistent:false,waterlogged:false}"},
        {pos: [0, 3, 8], state: "minecraft:jungle_leaves{distance:3,persistent:false,waterlogged:false}"},
        {pos: [0, 3, 9], state: "minecraft:jungle_leaves{distance:4,persistent:false,waterlogged:false}"},
        {pos: [1, 3, 3], state: "minecraft:vine{east:true,north:false,south:false,up:false,west:false}"},
        {pos: [1, 3, 5], state: "minecraft:jungle_leaves{distance:3,persistent:false,waterlogged:false}"},
        {pos: [1, 3, 6], state: "minecraft:jungle_leaves{distance:2,persistent:false,waterlogged:false}"},
        {pos: [1, 3, 7], state: "minecraft:jungle_leaves{distance:1,persistent:false,waterlogged:false}"},
        {pos: [1, 3, 8], state: "minecraft:jungle_leaves{distance:2,persistent:false,waterlogged:false}"},
        {pos: [1, 3, 9], state: "minecraft:jungle_leaves{distance:3,persistent:false,waterlogged:false}"},
        {pos: [2, 3, 2], state: "minecraft:vine{east:false,north:false,south:true,up:false,west:false}"},
        {pos: [2, 3, 3], state: "minecraft:jungle_log{axis:y}"},
        {pos: [2, 3, 4], state: "minecraft:vine{east:false,north:true,south:false,up:false,west:false}"},
        {pos: [2, 3, 5], state: "minecraft:jungle_leaves{distance:2,persistent:false,waterlogged:false}"},
        {pos: [2, 3, 6], state: "minecraft:jungle_leaves{distance:1,persistent:false,waterlogged:false}"},
        {pos: [2, 3, 7], state: "minecraft:jungle_log{axis:y}"},
        {pos: [2, 3, 8], state: "minecraft:jungle_leaves{distance:1,persistent:false,waterlogged:false}"},
        {pos: [2, 3, 9], state: "minecraft:jungle_leaves{distance:2,persistent:false,waterlogged:false}"},
        {pos: [3, 3, 3], state: "minecraft:cocoa{age:2,facing:west}"},
        {pos: [3, 3, 5], state: "minecraft:jungle_leaves{distance:3,persistent:false,waterlogged:false}"},
        {pos: [3, 3, 6], state: "minecraft:jungle_leaves{distance:2,persistent:false,waterlogged:false}"},
        {pos: [3, 3, 7], state: "minecraft:jungle_leaves{distance:1,persistent:false,waterlogged:false}"},
        {pos: [3, 3, 8], state: "minecraft:jungle_leaves{distance:2,persistent:false,waterlogged:false}"},
        {pos: [3, 3, 9], state: "minecraft:jungle_leaves{distance:3,persistent:false,waterlogged:false}"},
        {pos: [4, 3, 5], state: "minecraft:jungle_leaves{distance:4,persistent:false,waterlogged:false}"},
        {pos: [4, 3, 6], state: "minecraft:jungle_leaves{distance:3,persistent:false,waterlogged:false}"},
        {pos: [4, 3, 7], state: "minecraft:jungle_leaves{distance:2,persistent:false,waterlogged:false}"},
        {pos: [4, 3, 8], state: "minecraft:jungle_leaves{distance:3,persistent:false,waterlogged:false}"},
        {pos: [5, 3, 8], state: "minecraft:vine{east:true,north:false,south:false,up:false,west:false}"},
        {pos: [6, 3, 7], state: "minecraft:cocoa{age:2,facing:south}"},
        {pos: [6, 3, 8], state: "minecraft:jungle_log{axis:y}"},
        {pos: [6, 3, 9], state: "minecraft:vine{east:false,north:true,south:false,up:false,west:false}"},
        {pos: [7, 3, 8], state: "minecraft:vine{east:false,north:false,south:false,up:false,west:true}"},
        {pos: [0, 4, 5], state: "minecraft:jungle_leaves{distance:4,persistent:false,waterlogged:false}"},
        {pos: [0, 4, 6], state: "minecraft:jungle_leaves{distance:3,persistent:false,waterlogged:false}"},
        {pos: [0, 4, 7], state: "minecraft:jungle_leaves{distance:2,persistent:false,waterlogged:false}"},
        {pos: [0, 4, 8], state: "minecraft:jungle_leaves{distance:3,persistent:false,waterlogged:false}"},
        {pos: [0, 4, 9], state: "minecraft:jungle_leaves{distance:4,persistent:false,waterlogged:false}"},
        {pos: [1, 4, 3], state: "minecraft:vine{east:true,north:false,south:false,up:false,west:false}"},
        {pos: [1, 4, 5], state: "minecraft:jungle_leaves{distance:3,persistent:false,waterlogged:false}"},
        {pos: [1, 4, 6], state: "minecraft:jungle_leaves{distance:2,persistent:false,waterlogged:false}"},
        {pos: [1, 4, 7], state: "minecraft:jungle_leaves{distance:1,persistent:false,waterlogged:false}"},
        {pos: [1, 4, 8], state: "minecraft:jungle_leaves{distance:2,persistent:false,waterlogged:false}"},
        {pos: [1, 4, 9], state: "minecraft:jungle_leaves{distance:3,persistent:false,waterlogged:false}"},
        {pos: [2, 4, 2], state: "minecraft:vine{east:false,north:false,south:true,up:false,west:false}"},
        {pos: [2, 4, 3], state: "minecraft:jungle_log{axis:y}"},
        {pos: [2, 4, 4], state: "minecraft:vine{east:false,north:true,south:false,up:false,west:false}"},
        {pos: [2, 4, 5], state: "minecraft:jungle_leaves{distance:2,persistent:false,waterlogged:false}"},
        {pos: [2, 4, 6], state: "minecraft:jungle_leaves{distance:1,persistent:false,waterlogged:false}"},
        {pos: [2, 4, 7], state: "minecraft:jungle_log{axis:y}"},
        {pos: [2, 4, 8], state: "minecraft:jungle_leaves{distance:1,persistent:false,waterlogged:false}"},
        {pos: [2, 4, 9], state: "minecraft:jungle_leaves{distance:2,persistent:false,waterlogged:false}"},
        {pos: [3, 4, 3], state: "minecraft:vine{east:false,north:false,south:false,up:false,west:true}"},
        {pos: [3, 4, 5], state: "minecraft:jungle_leaves{distance:3,persistent:false,waterlogged:false}"},
        {pos: [3, 4, 6], state: "minecraft:jungle_leaves{distance:2,persistent:false,waterlogged:false}"},
        {pos: [3, 4, 7], state: "minecraft:jungle_leaves{distance:1,persistent:false,waterlogged:false}"},
        {pos: [3, 4, 8], state: "minecraft:jungle_leaves{distance:2,persistent:false,waterlogged:false}"},
        {pos: [3, 4, 9], state: "minecraft:jungle_leaves{distance:3,persistent:false,waterlogged:false}"},
        {pos: [4, 4, 5], state: "minecraft:jungle_leaves{distance:4,persistent:false,waterlogged:false}"},
        {pos: [4, 4, 6], state: "minecraft:jungle_leaves{distance:3,persistent:false,waterlogged:false}"},
        {pos: [4, 4, 7], state: "minecraft:jungle_leaves{distance:2,persistent:false,waterlogged:false}"},
        {pos: [4, 4, 8], state: "minecraft:jungle_leaves{distance:3,persistent:false,waterlogged:false}"},
        {pos: [4, 4, 9], state: "minecraft:jungle_leaves{distance:4,persistent:false,waterlogged:false}"},
        {pos: [5, 4, 8], state: "minecraft:vine{east:true,north:false,south:false,up:false,west:false}"},
        {pos: [6, 4, 7], state: "minecraft:vine{east:false,north:false,south:true,up:false,west:false}"},
        {pos: [6, 4, 8], state: "minecraft:jungle_log{axis:y}"},
        {pos: [6, 4, 9], state: "minecraft:vine{east:false,north:true,south:false,up:false,west:false}"},
        {pos: [7, 4, 8], state: "minecraft:vine{east:false,north:false,south:false,up:false,west:true}"},
        {pos: [1, 5, 3], state: "minecraft:vine{east:true,north:false,south:false,up:false,west:false}"},
        {pos: [1, 5, 7], state: "minecraft:jungle_leaves{distance:1,persistent:false,waterlogged:false}"},
        {pos: [2, 5, 2], state: "minecraft:vine{east:false,north:false,south:true,up:false,west:false}"},
        {pos: [2, 5, 3], state: "minecraft:jungle_log{axis:y}"},
        {pos: [2, 5, 4], state: "minecraft:vine{east:false,north:true,south:false,up:false,west:false}"},
        {pos: [2, 5, 6], state: "minecraft:jungle_leaves{distance:1,persistent:false,waterlogged:false}"},
        {pos: [2, 5, 7], state: "minecraft:jungle_log{axis:y}"},
        {pos: [2, 5, 8], state: "minecraft:jungle_leaves{distance:1,persistent:false,waterlogged:false}"},
        {pos: [3, 5, 7], state: "minecraft:jungle_leaves{distance:1,persistent:false,waterlogged:false}"},
        {pos: [3, 5, 8], state: "minecraft:jungle_leaves{distance:2,persistent:false,waterlogged:false}"},
        {pos: [6, 5, 8], state: "minecraft:jungle_log{axis:y}"},
        {pos: [1, 6, 3], state: "minecraft:vine{east:true,north:false,south:false,up:false,west:false}"},
        {pos: [1, 6, 7], state: "minecraft:jungle_leaves{distance:2,persistent:false,waterlogged:false}"},
        {pos: [2, 6, 2], state: "minecraft:vine{east:false,north:false,south:true,up:false,west:false}"},
        {pos: [2, 6, 3], state: "minecraft:jungle_log{axis:y}"},
        {pos: [2, 6, 4], state: "minecraft:vine{east:false,north:true,south:false,up:false,west:false}"},
        {pos: [2, 6, 6], state: "minecraft:jungle_leaves{distance:2,persistent:false,waterlogged:false}"},
        {pos: [2, 6, 7], state: "minecraft:jungle_leaves{distance:1,persistent:false,waterlogged:false}"},
        {pos: [2, 6, 8], state: "minecraft:jungle_leaves{distance:2,persistent:false,waterlogged:false}"},
        {pos: [3, 6, 7], state: "minecraft:jungle_leaves{distance:2,persistent:false,waterlogged:false}"},
        {pos: [6, 6, 8], state: "minecraft:jungle_log{axis:y}"},
        {pos: [2, 7, 3], state: "minecraft:jungle_log{axis:y}"},
        {pos: [6, 7, 8], state: "minecraft:jungle_log{axis:y}"},
        {pos: [2, 8, 3], state: "minecraft:jungle_log{axis:y}"},
        {pos: [6, 8, 8], state: "minecraft:jungle_log{axis:y}"},
        {pos: [2, 9, 3], state: "minecraft:jungle_log{axis:y}"},
        {pos: [4, 9, 7], state: "minecraft:jungle_leaves{distance:3,persistent:false,waterlogged:false}"},
        {pos: [4, 9, 8], state: "minecraft:jungle_leaves{distance:2,persistent:false,waterlogged:false}"},
        {pos: [4, 9, 9], state: "minecraft:jungle_leaves{distance:3,persistent:false,waterlogged:false}"},
        {pos: [4, 9, 10], state: "minecraft:jungle_leaves{distance:4,persistent:false,waterlogged:false}"},
        {pos: [5, 9, 6], state: "minecraft:jungle_leaves{distance:3,persistent:false,waterlogged:false}"},
        {pos: [5, 9, 7], state: "minecraft:jungle_leaves{distance:2,persistent:false,waterlogged:false}"},
        {pos: [5, 9, 8], state: "minecraft:jungle_leaves{distance:1,persistent:false,waterlogged:false}"},
        {pos: [5, 9, 9], state: "minecraft:jungle_leaves{distance:2,persistent:false,waterlogged:false}"},
        {pos: [5, 9, 10], state: "minecraft:jungle_leaves{distance:3,persistent:false,waterlogged:false}"},
        {pos: [6, 9, 6], state: "minecraft:jungle_leaves{distance:2,persistent:false,waterlogged:false}"},
        {pos: [6, 9, 7], state: "minecraft:jungle_leaves{distance:1,persistent:false,waterlogged:false}"},
        {pos: [6, 9, 8], state: "minecraft:jungle_log{axis:y}"},
        {pos: [6, 9, 9], state: "minecraft:jungle_leaves{distance:1,persistent:false,waterlogged:false}"},
        {pos: [6, 9, 10], state: "minecraft:jungle_leaves{distance:2,persistent:false,waterlogged:false}"},
        {pos: [7, 9, 6], state: "minecraft:jungle_leaves{distance:3,persistent:false,waterlogged:false}"},
        {pos: [7, 9, 7], state: "minecraft:jungle_leaves{distance:2,persistent:false,waterlogged:false}"},
        {pos: [7, 9, 8], state: "minecraft:jungle_leaves{distance:1,persistent:false,waterlogged:false}"},
        {pos: [7, 9, 9], state: "minecraft:jungle_leaves{distance:2,persistent:false,waterlogged:false}"},
        {pos: [7, 9, 10], state: "minecraft:jungle_leaves{distance:3,persistent:false,waterlogged:false}"},
        {pos: [8, 9, 6], state: "minecraft:jungle_leaves{distance:4,persistent:false,waterlogged:false}"},
        {pos: [8, 9, 7], state: "minecraft:jungle_leaves{distance:3,persistent:false,waterlogged:false}"},
        {pos: [8, 9, 8], state: "minecraft:jungle_leaves{distance:2,persistent:false,waterlogged:false}"},
        {pos: [8, 9, 9], state: "minecraft:jungle_leaves{distance:3,persistent:false,waterlogged:false}"},
        {pos: [8, 9, 10], state: "minecraft:jungle_leaves{distance:4,persistent:false,waterlogged:false}"},
        {pos: [0, 10, 2], state: "minecraft:jungle_leaves{distance:3,persistent:false,waterlogged:false}"},
        {pos: [0, 10, 3], state: "minecraft:jungle_leaves{distance:2,persistent:false,waterlogged:false}"},
        {pos: [0, 10, 4], state: "minecraft:jungle_leaves{distance:3,persistent:false,waterlogged:false}"},
        {pos: [1, 10, 1], state: "minecraft:jungle_leaves{distance:3,persistent:false,waterlogged:false}"},
        {pos: [1, 10, 2], state: "minecraft:jungle_leaves{distance:2,persistent:false,waterlogged:false}"},
        {pos: [1, 10, 3], state: "minecraft:jungle_leaves{distance:1,persistent:false,waterlogged:false}"},
        {pos: [1, 10, 4], state: "minecraft:jungle_leaves{distance:2,persistent:false,waterlogged:false}"},
        {pos: [1, 10, 5], state: "minecraft:jungle_leaves{distance:3,persistent:false,waterlogged:false}"},
        {pos: [2, 10, 1], state: "minecraft:jungle_leaves{distance:2,persistent:false,waterlogged:false}"},
        {pos: [2, 10, 2], state: "minecraft:jungle_leaves{distance:1,persistent:false,waterlogged:false}"},
        {pos: [2, 10, 3], state: "minecraft:jungle_log{axis:y}"},
        {pos: [2, 10, 4], state: "minecraft:jungle_leaves{distance:1,persistent:false,waterlogged:false}"},
        {pos: [2, 10, 5], state: "minecraft:jungle_leaves{distance:2,persistent:false,waterlogged:false}"},
        {pos: [3, 10, 1], state: "minecraft:jungle_leaves{distance:3,persistent:false,waterlogged:false}"},
        {pos: [3, 10, 2], state: "minecraft:jungle_leaves{distance:2,persistent:false,waterlogged:false}"},
        {pos: [3, 10, 3], state: "minecraft:jungle_leaves{distance:1,persistent:false,waterlogged:false}"},
        {pos: [3, 10, 4], state: "minecraft:jungle_leaves{distance:2,persistent:false,waterlogged:false}"},
        {pos: [3, 10, 5], state: "minecraft:jungle_leaves{distance:3,persistent:false,waterlogged:false}"},
        {pos: [4, 10, 1], state: "minecraft:jungle_leaves{distance:4,persistent:false,waterlogged:false}"},
        {pos: [4, 10, 2], state: "minecraft:jungle_leaves{distance:3,persistent:false,waterlogged:false}"},
        {pos: [4, 10, 3], state: "minecraft:jungle_leaves{distance:2,persistent:false,waterlogged:false}"},
        {pos: [4, 10, 4], state: "minecraft:jungle_leaves{distance:3,persistent:false,waterlogged:false}"},
        {pos: [4, 10, 5], state: "minecraft:jungle_leaves{distance:4,persistent:false,waterlogged:false}"},
        {pos: [4, 10, 7], state: "minecraft:jungle_leaves{distance:3,persistent:false,waterlogged:false}"},
        {pos: [4, 10, 8], state: "minecraft:jungle_leaves{distance:2,persistent:false,waterlogged:false}"},
        {pos: [4, 10, 9], state: "minecraft:jungle_leaves{distance:3,persistent:false,waterlogged:false}"},
        {pos: [5, 10, 6], state: "minecraft:jungle_leaves{distance:3,persistent:false,waterlogged:false}"},
        {pos: [5, 10, 7], state: "minecraft:jungle_leaves{distance:2,persistent:false,waterlogged:false}"},
        {pos: [5, 10, 8], state: "minecraft:jungle_leaves{distance:1,persistent:false,waterlogged:false}"},
        {pos: [5, 10, 9], state: "minecraft:jungle_leaves{distance:2,persistent:false,waterlogged:false}"},
        {pos: [5, 10, 10], state: "minecraft:jungle_leaves{distance:3,persistent:false,waterlogged:false}"},
        {pos: [6, 10, 6], state: "minecraft:jungle_leaves{distance:2,persistent:false,waterlogged:false}"},
        {pos: [6, 10, 7], state: "minecraft:jungle_leaves{distance:1,persistent:false,waterlogged:false}"},
        {pos: [6, 10, 8], state: "minecraft:jungle_log{axis:y}"},
        {pos: [6, 10, 9], state: "minecraft:jungle_leaves{distance:1,persistent:false,waterlogged:false}"},
        {pos: [6, 10, 10], state: "minecraft:jungle_leaves{distance:2,persistent:false,waterlogged:false}"},
        {pos: [7, 10, 6], state: "minecraft:jungle_leaves{distance:3,persistent:false,waterlogged:false}"},
        {pos: [7, 10, 7], state: "minecraft:jungle_leaves{distance:2,persistent:false,waterlogged:false}"},
        {pos: [7, 10, 8], state: "minecraft:jungle_leaves{distance:1,persistent:false,waterlogged:false}"},
        {pos: [7, 10, 9], state: "minecraft:jungle_leaves{distance:2,persistent:false,waterlogged:false}"},
        {pos: [7, 10, 10], state: "minecraft:jungle_leaves{distance:3,persistent:false,waterlogged:false}"},
        {pos: [8, 10, 6], state: "minecraft:jungle_leaves{distance:4,persistent:false,waterlogged:false}"},
        {pos: [8, 10, 7], state: "minecraft:jungle_leaves{distance:3,persistent:false,waterlogged:false}"},
        {pos: [8, 10, 8], state: "minecraft:jungle_leaves{distance:2,persistent:false,waterlogged:false}"},
        {pos: [8, 10, 9], state: "minecraft:jungle_leaves{distance:3,persistent:false,waterlogged:false}"},
        {pos: [0, 11, 2], state: "minecraft:jungle_leaves{distance:3,persistent:false,waterlogged:false}"},
        {pos: [0, 11, 3], state: "minecraft:jungle_leaves{distance:2,persistent:false,waterlogged:false}"},
        {pos: [0, 11, 4], state: "minecraft:jungle_leaves{distance:3,persistent:false,waterlogged:false}"},
        {pos: [0, 11, 5], state: "minecraft:jungle_leaves{distance:4,persistent:false,waterlogged:false}"},
        {pos: [1, 11, 1], state: "minecraft:jungle_leaves{distance:3,persistent:false,waterlogged:false}"},
        {pos: [1, 11, 2], state: "minecraft:jungle_leaves{distance:2,persistent:false,waterlogged:false}"},
        {pos: [1, 11, 3], state: "minecraft:jungle_leaves{distance:1,persistent:false,waterlogged:false}"},
        {pos: [1, 11, 4], state: "minecraft:jungle_leaves{distance:2,persistent:false,waterlogged:false}"},
        {pos: [1, 11, 5], state: "minecraft:jungle_leaves{distance:3,persistent:false,waterlogged:false}"},
        {pos: [2, 11, 1], state: "minecraft:jungle_leaves{distance:2,persistent:false,waterlogged:false}"},
        {pos: [2, 11, 2], state: "minecraft:jungle_leaves{distance:1,persistent:false,waterlogged:false}"},
        {pos: [2, 11, 3], state: "minecraft:jungle_log{axis:y}"},
        {pos: [2, 11, 4], state: "minecraft:jungle_leaves{distance:1,persistent:false,waterlogged:false}"},
        {pos: [2, 11, 5], state: "minecraft:jungle_leaves{distance:2,persistent:false,waterlogged:false}"},
        {pos: [3, 11, 1], state: "minecraft:jungle_leaves{distance:3,persistent:false,waterlogged:false}"},
        {pos: [3, 11, 2], state: "minecraft:jungle_leaves{distance:2,persistent:false,waterlogged:false}"},
        {pos: [3, 11, 3], state: "minecraft:jungle_leaves{distance:1,persistent:false,waterlogged:false}"},
        {pos: [3, 11, 4], state: "minecraft:jungle_leaves{distance:2,persistent:false,waterlogged:false}"},
        {pos: [3, 11, 5], state: "minecraft:jungle_leaves{distance:3,persistent:false,waterlogged:false}"},
        {pos: [4, 11, 2], state: "minecraft:jungle_leaves{distance:3,persistent:false,waterlogged:false}"},
        {pos: [4, 11, 3], state: "minecraft:jungle_leaves{distance:2,persistent:false,waterlogged:false}"},
        {pos: [4, 11, 4], state: "minecraft:jungle_leaves{distance:3,persistent:false,waterlogged:false}"},
        {pos: [4, 11, 5], state: "minecraft:jungle_leaves{distance:4,persistent:false,waterlogged:false}"},
        {pos: [5, 11, 7], state: "minecraft:jungle_leaves{distance:2,persistent:false,waterlogged:false}"},
        {pos: [5, 11, 8], state: "minecraft:jungle_leaves{distance:1,persistent:false,waterlogged:false}"},
        {pos: [5, 11, 9], state: "minecraft:jungle_leaves{distance:2,persistent:false,waterlogged:false}"},
        {pos: [6, 11, 7], state: "minecraft:jungle_leaves{distance:1,persistent:false,waterlogged:false}"},
        {pos: [6, 11, 8], state: "minecraft:jungle_log{axis:y}"},
        {pos: [6, 11, 9], state: "minecraft:jungle_leaves{distance:1,persistent:false,waterlogged:false}"},
        {pos: [7, 11, 8], state: "minecraft:jungle_leaves{distance:1,persistent:false,waterlogged:false}"},
        {pos: [1, 12, 2], state: "minecraft:jungle_leaves{distance:2,persistent:false,waterlogged:false}"},
        {pos: [1, 12, 3], state: "minecraft:jungle_leaves{distance:1,persistent:false,waterlogged:false}"},
        {pos: [2, 12, 2], state: "minecraft:jungle_leaves{distance:1,persistent:false,waterlogged:false}"},
        {pos: [2, 12, 3], state: "minecraft:jungle_log{axis:y}"},
        {pos: [2, 12, 4], state: "minecraft:jungle_leaves{distance:1,persistent:false,waterlogged:false}"},
        {pos: [3, 12, 3], state: "minecraft:jungle_leaves{distance:1,persistent:false,waterlogged:false}"},
        {pos: [5, 12, 8], state: "minecraft:jungle_leaves{distance:2,persistent:false,waterlogged:false}"},
        {pos: [6, 12, 7], state: "minecraft:jungle_leaves{distance:2,persistent:false,waterlogged:false}"},
        {pos: [6, 12, 8], state: "minecraft:jungle_leaves{distance:1,persistent:false,waterlogged:false}"},
        {pos: [6, 12, 9], state: "minecraft:jungle_leaves{distance:2,persistent:false,waterlogged:false}"},
        {pos: [7, 12, 8], state: "minecraft:jungle_leaves{distance:2,persistent:false,waterlogged:false}"},
        {pos: [1, 13, 3], state: "minecraft:jungle_leaves{distance:2,persistent:false,waterlogged:false}"},
        {pos: [2, 13, 2], state: "minecraft:jungle_leaves{distance:2,persistent:false,waterlogged:false}"},
        {pos: [2, 13, 3], state: "minecraft:jungle_leaves{distance:1,persistent:false,waterlogged:false}"},
        {pos: [2, 13, 4], state: "minecraft:jungle_leaves{distance:2,persistent:false,waterlogged:false}"},
        {pos: [3, 13, 3], state: "minecraft:jungle_leaves{distance:2,persistent:false,waterlogged:false}"}
    ],
    entities: [
        {blockPos: [4, 0, 4], pos: [4.5d, 0.9375d, 4.5d], nbt: {Air: 300s, Fire: 0s, Invulnerable: 0b, Motion: [0.0d, 0.0d, 0.0d], OnGround: 0b, PortalCooldown: 0, Pos: [-89.5d, -60.0625d, -88.5d], Rotation: [0.0f, 0.0f], UUID: [I; 896961967, -1383775627, -1422356559, 1794368294], block_pos: [I; -90, -61, -89], color: "gray", fall_distance: 0.0d, id: "minecraft:cushion"}},
        {blockPos: [5, 2, 2], pos: [5.5d, 2.0d, 2.5d], nbt: {Air: 300s, Fire: 0s, Invulnerable: 0b, Motion: [0.0d, 0.0d, 0.0d], OnGround: 0b, PortalCooldown: 0, Pos: [-88.5d, -59.0d, -90.5d], Rotation: [90.0f, 0.0f], UUID: [I; -1451871467, -938262222, -1591486214, -2014523993], block_pos: [I; -89, -59, -91], color: "light_gray", fall_distance: 0.0d, id: "minecraft:cushion"}}
    ],
    palette: [
        "minecraft:grass_block{snowy:false}",
        "minecraft:jungle_log{axis:y}",
        "minecraft:jungle_log{axis:x}",
        "minecraft:jungle_leaves{distance:1,persistent:true,waterlogged:false}",
        "minecraft:jungle_leaves{distance:2,persistent:true,waterlogged:false}",
        "minecraft:jungle_leaves{distance:4,persistent:false,waterlogged:false}",
        "minecraft:jungle_leaves{distance:3,persistent:false,waterlogged:false}",
        "minecraft:jungle_leaves{distance:2,persistent:false,waterlogged:false}",
        "minecraft:jungle_leaves{distance:1,persistent:false,waterlogged:false}",
        "minecraft:dirt_path",
        "minecraft:vine{east:true,north:false,south:false,up:false,west:false}",
        "minecraft:vine{east:false,north:false,south:true,up:false,west:false}",
        "minecraft:vine{east:false,north:true,south:false,up:false,west:false}",
        "minecraft:jungle_fence{east:false,north:false,south:false,waterlogged:false,west:false}",
        "minecraft:vine{east:false,north:false,south:false,up:false,west:true}",
        "minecraft:cocoa{age:2,facing:north}",
        "minecraft:cocoa{age:2,facing:west}",
        "minecraft:cocoa{age:2,facing:south}",
        "minecraft:jigsaw{orientation:east_up}",
        "minecraft:campfire{facing:west,lit:false,signal_fire:false,waterlogged:false}",
        "minecraft:chest{facing:south,type:single,waterlogged:false}"
    ]
}
