{
    DataVersion: 2856,
    size: [7, 6, 8],
    data: [
        {pos: [0, 0, 0], state: "minecraft:blackstone"},
        {pos: [0, 0, 1], state: "minecraft:polished_blackstone_bricks"},
        {pos: [0, 0, 2], state: "minecraft:polished_blackstone_bricks"},
        {pos: [0, 0, 5], state: "minecraft:polished_blackstone_bricks"},
        {pos: [0, 0, 6], state: "minecraft:polished_blackstone_bricks"},
        {pos: [0, 0, 7], state: "minecraft:polished_blackstone_bricks"},
        {pos: [1, 0, 0], state: "minecraft:polished_blackstone_bricks"},
        {pos: [1, 0, 1], state: "minecraft:polished_blackstone_bricks"},
        {pos: [1, 0, 2], state: "minecraft:polished_blackstone_bricks"},
        {pos: [1, 0, 5], state: "minecraft:polished_blackstone_bricks"},
        {pos: [1, 0, 6], state: "minecraft:polished_blackstone_bricks"},
        {pos: [1, 0, 7], state: "minecraft:polished_blackstone_bricks"},
        {pos: [2, 0, 0], state: "minecraft:polished_blackstone_bricks"},
        {pos: [2, 0, 1], state: "minecraft:polished_blackstone_bricks"},
        {pos: [2, 0, 2], state: "minecraft:polished_blackstone_bricks"},
        {pos: [2, 0, 5], state: "minecraft:polished_blackstone_bricks"},
        {pos: [2, 0, 6], state: "minecraft:polished_blackstone_bricks"},
        {pos: [2, 0, 7], state: "minecraft:polished_blackstone_bricks"},
        {pos: [5, 0, 0], state: "minecraft:polished_blackstone_bricks"},
        {pos: [5, 0, 1], state: "minecraft:polished_blackstone_bricks"},
        {pos: [5, 0, 2], state: "minecraft:polished_blackstone_bricks"},
        {pos: [5, 0, 3], state: "minecraft:polished_blackstone_bricks"},
        {pos: [5, 0, 4], state: "minecraft:polished_blackstone_bricks"},
        {pos: [5, 0, 5], state: "minecraft:polished_blackstone_bricks"},
        {pos: [5, 0, 6], state: "minecraft:polished_blackstone_bricks"},
        {pos: [5, 0, 7], state: "minecraft:polished_blackstone_bricks"},
        {pos: [6, 0, 0], state: "minecraft:polished_blackstone_bricks"},
        {pos: [6, 0, 1], state: "minecraft:polished_blackstone_bricks"},
        {pos: [6, 0, 2], state: "minecraft:polished_blackstone_bricks"},
        {pos: [6, 0, 3], state: "minecraft:polished_blackstone_bricks"},
        {pos: [6, 0, 4], state: "minecraft:polished_blackstone_bricks"},
        {pos: [6, 0, 5], state: "minecraft:polished_blackstone_bricks"},
        {pos: [6, 0, 6], state: "minecraft:polished_blackstone_bricks"},
        {pos: [6, 0, 7], state: "minecraft:polished_blackstone_bricks"},
        {pos: [0, 1, 1], state: "minecraft:polished_blackstone_bricks"},
        {pos: [0, 1, 2], state: "minecraft:polished_blackstone_bricks"},
        {pos: [0, 1, 5], state: "minecraft:blackstone"},
        {pos: [0, 1, 6], state: "minecraft:polished_blackstone_bricks"},
        {pos: [0, 1, 7], state: "minecraft:polished_blackstone_bricks"},
        {pos: [1, 1, 0], state: "minecraft:polished_blackstone_bricks"},
        {pos: [1, 1, 1], state: "minecraft:polished_blackstone_bricks"},
        {pos: [1, 1, 2], state: "minecraft:polished_blackstone_bricks"},
        {pos: [1, 1, 5], state: "minecraft:polished_blackstone_bricks"},
        {pos: [1, 1, 6], state: "minecraft:polished_blackstone_bricks"},
        {pos: [1, 1, 7], state: "minecraft:polished_blackstone_bricks"},
        {pos: [2, 1, 0], state: "minecraft:polished_blackstone_bricks"},
        {pos: [2, 1, 1], state: "minecraft:polished_blackstone_bricks"},
        {pos: [2, 1, 2], state: "minecraft:polished_blackstone_bricks"},
        {pos: [2, 1, 5], state: "minecraft:polished_blackstone_bricks"},
        {pos: [2, 1, 6], state: "minecraft:polished_blackstone_bricks"},
        {pos: [2, 1, 7], state: "minecraft:polished_blackstone_bricks"},
        {pos: [5, 1, 0], state: "minecraft:polished_blackstone_bricks"},
        {pos: [5, 1, 1], state: "minecraft:polished_blackstone_bricks"},
        {pos: [5, 1, 2], state: "minecraft:polished_blackstone_bricks"},
        {pos: [5, 1, 3], state: "minecraft:polished_blackstone_bricks"},
        {pos: [5, 1, 4], state: "minecraft:polished_blackstone_bricks"},
        {pos: [5, 1, 5], state: "minecraft:polished_blackstone_bricks"},
        {pos: [5, 1, 6], state: "minecraft:polished_blackstone_bricks"},
        {pos: [5, 1, 7], state: "minecraft:polished_blackstone_bricks"},
        {pos: [6, 1, 0], state: "minecraft:polished_blackstone_bricks"},
        {pos: [6, 1, 1], state: "minecraft:polished_blackstone_bricks"},
        {pos: [6, 1, 2], state: "minecraft:polished_blackstone_bricks"},
        {pos: [6, 1, 3], state: "minecraft:polished_blackstone_bricks"},
        {pos: [6, 1, 4], state: "minecraft:polished_blackstone_bricks"},
        {pos: [6, 1, 5], state: "minecraft:polished_blackstone_bricks"},
        {pos: [6, 1, 6], state: "minecraft:polished_blackstone_bricks"},
        {pos: [6, 1, 7], state: "minecraft:polished_blackstone_bricks"},
        {pos: [0, 2, 0], state: "minecraft:blackstone"},
        {pos: [0, 2, 2], state: "minecraft:polished_blackstone_bricks"},
        {pos: [0, 2, 3], state: "minecraft:blackstone"},
        {pos: [0, 2, 4], state: "minecraft:polished_blackstone_bricks"},
        {pos: [0, 2, 5], state: "minecraft:polished_blackstone_bricks"},
        {pos: [0, 2, 6], state: "minecraft:polished_blackstone_bricks"},
        {pos: [0, 2, 7], state: "minecraft:polished_blackstone_bricks"},
        {pos: [1, 2, 0], state: "minecraft:polished_blackstone_bricks"},
        {pos: [1, 2, 1], state: "minecraft:polished_blackstone_bricks"},
        {pos: [1, 2, 2], state: "minecraft:polished_blackstone_bricks"},
        {pos: [1, 2, 3], state: "minecraft:polished_blackstone_bricks"},
        {pos: [1, 2, 4], state: "minecraft:polished_blackstone_bricks"},
        {pos: [1, 2, 5], state: "minecraft:jigsaw{orientation:up_north}", nbt: {final_state: "minecraft:blackstone", id: "minecraft:jigsaw", joint: "rollable", name: "minecraft:empty", pool: "minecraft:bastion/mobs/piglin_melee", target: "minecraft:melee_connector"}},
        {pos: [1, 2, 6], state: "minecraft:polished_blackstone_bricks"},
        {pos: [1, 2, 7], state: "minecraft:polished_blackstone_bricks"},
        {pos: [2, 2, 0], state: "minecraft:polished_blackstone_bricks"},
        {pos: [2, 2, 1], state: "minecraft:polished_blackstone_bricks"},
        {pos: [2, 2, 2], state: "minecraft:polished_blackstone_bricks"},
        {pos: [2, 2, 3], state: "minecraft:polished_blackstone_bricks"},
        {pos: [2, 2, 4], state: "minecraft:polished_blackstone_bricks"},
        {pos: [2, 2, 5], state: "minecraft:polished_blackstone_bricks"},
        {pos: [2, 2, 6], state: "minecraft:polished_blackstone_bricks"},
        {pos: [2, 2, 7], state: "minecraft:polished_blackstone_bricks"},
        {pos: [3, 2, 0], state: "minecraft:polished_blackstone_bricks"},
        {pos: [3, 2, 1], state: "minecraft:polished_blackstone_bricks"},
        {pos: [3, 2, 2], state: "minecraft:polished_blackstone_bricks"},
        {pos: [3, 2, 3], state: "minecraft:blackstone_wall{east:low,north:low,south:low,up:false,waterlogged:false,west:low}"},
        {pos: [3, 2, 4], state: "minecraft:blackstone_wall{east:low,north:low,south:low,up:false,waterlogged:false,west:low}"},
        {pos: [3, 2, 5], state: "minecraft:polished_blackstone_bricks"},
        {pos: [3, 2, 6], state: "minecraft:polished_blackstone_bricks"},
        {pos: [3, 2, 7], state: "minecraft:polished_blackstone_bricks"},
        {pos: [4, 2, 0], state: "minecraft:polished_blackstone_bricks"},
        {pos: [4, 2, 1], state: "minecraft:polished_blackstone_bricks"},
        {pos: [4, 2, 2], state: "minecraft:polished_blackstone_bricks"},
        {pos: [4, 2, 3], state: "minecraft:blackstone_wall{east:low,north:low,south:low,up:false,waterlogged:false,west:low}"},
        {pos: [4, 2, 4], state: "minecraft:blackstone_wall{east:low,north:low,south:low,up:false,waterlogged:false,west:low}"},
        {pos: [4, 2, 5], state: "minecraft:polished_blackstone_bricks"},
        {pos: [4, 2, 6], state: "minecraft:gilded_blackstone"},
        {pos: [4, 2, 7], state: "minecraft:polished_blackstone_bricks"},
        {pos: [5, 2, 0], state: "minecraft:polished_blackstone_bricks"},
        {pos: [5, 2, 1], state: "minecraft:polished_blackstone_bricks"},
        {pos: [5, 2, 2], state: "minecraft:polished_blackstone_bricks"},
        {pos: [5, 2, 3], state: "minecraft:polished_blackstone_bricks"},
        {pos: [5, 2, 4], state: "minecraft:polished_blackstone_bricks"},
        {pos: [5, 2, 5], state: "minecraft:polished_blackstone_bricks"},
        {pos: [5, 2, 6], state: "minecraft:polished_blackstone_bricks"},
        {pos: [5, 2, 7], state: "minecraft:polished_blackstone_bricks"},
        {pos: [6, 2, 0], state: "minecraft:blackstone"},
        {pos: [6, 2, 1], state: "minecraft:blackstone"},
        {pos: [6, 2, 2], state: "minecraft:jigsaw{orientation:east_up}", nbt: {final_state: "minecraft:polished_blackstone_bricks", id: "minecraft:jigsaw", joint: "rollable", name: "minecraft:treasure", pool: "minecraft:empty", target: "minecraft:empty"}},
        {pos: [6, 2, 3], state: "minecraft:polished_blackstone_bricks"},
        {pos: [6, 2, 5], state: "minecraft:polished_blackstone_bricks"},
        {pos: [6, 2, 6], state: "minecraft:polished_blackstone_bricks"},
        {pos: [6, 2, 7], state: "minecraft:polished_blackstone_bricks"},
        {pos: [0, 3, 7], state: "minecraft:blackstone"},
        {pos: [1, 3, 1], state: "minecraft:polished_blackstone_bricks"},
        {pos: [1, 3, 5], state: "minecraft:air"},
        {pos: [1, 3, 6], state: "minecraft:blackstone"},
        {pos: [1, 3, 7], state: "minecraft:polished_blackstone_bricks"},
        {pos: [2, 3, 0], state: "minecraft:polished_blackstone_bricks"},
        {pos: [2, 3, 1], state: "minecraft:air"},
        {pos: [2, 3, 2], state: "minecraft:gold_block"},
        {pos: [2, 3, 3], state: "minecraft:gold_block"},
        {pos: [2, 3, 4], state: "minecraft:gold_block"},
        {pos: [2, 3, 5], state: "minecraft:gold_block"},
        {pos: [2, 3, 6], state: "minecraft:gold_block"},
        {pos: [2, 3, 7], state: "minecraft:polished_blackstone_bricks"},
        {pos: [3, 3, 0], state: "minecraft:polished_blackstone_bricks"},
        {pos: [3, 3, 2], state: "minecraft:gold_block"},
        {pos: [3, 3, 5], state: "minecraft:gold_block"},
        {pos: [3, 3, 6], state: "minecraft:gold_block"},
        {pos: [3, 3, 7], state: "minecraft:polished_blackstone_bricks"},
        {pos: [4, 3, 0], state: "minecraft:polished_blackstone_bricks"},
        {pos: [4, 3, 1], state: "minecraft:gold_block"},
        {pos: [4, 3, 5], state: "minecraft:gold_block"},
        {pos: [4, 3, 6], state: "minecraft:chest{facing:north,type:single,waterlogged:false}", nbt: {LootTable: "minecraft:chests/bastion_treasure", id: "minecraft:chest"}},
        {pos: [4, 3, 7], state: "minecraft:polished_blackstone_bricks"},
        {pos: [5, 3, 0], state: "minecraft:polished_blackstone_bricks"},
        {pos: [5, 3, 1], state: "minecraft:blackstone"},
        {pos: [5, 3, 2], state: "minecraft:gold_block"},
        {pos: [5, 3, 3], state: "minecraft:gold_block"},
        {pos: [5, 3, 4], state: "minecraft:gold_block"},
        {pos: [5, 3, 6], state: "minecraft:polished_blackstone_bricks"},
        {pos: [5, 3, 7], state: "minecraft:polished_blackstone_bricks"},
        {pos: [6, 3, 6], state: "minecraft:blackstone"},
        {pos: [1, 4, 1], state: "minecraft:air"},
        {pos: [1, 4, 5], state: "minecraft:air"},
        {pos: [1, 4, 6], state: "minecraft:air"},
        {pos: [1, 4, 7], state: "minecraft:blackstone"},
        {pos: [2, 4, 4], state: "minecraft:air"},
        {pos: [2, 4, 6], state: "minecraft:gold_block"},
        {pos: [2, 4, 7], state: "minecraft:blackstone"},
        {pos: [3, 4, 0], state: "minecraft:blackstone"},
        {pos: [3, 4, 2], state: "minecraft:air"},
        {pos: [3, 4, 5], state: "minecraft:gold_block"},
        {pos: [3, 4, 6], state: "minecraft:gold_block"},
        {pos: [3, 4, 7], state: "minecraft:air"},
        {pos: [4, 4, 7], state: "minecraft:air"},
        {pos: [5, 4, 1], state: "minecraft:gold_block"},
        {pos: [5, 4, 6], state: "minecraft:air"},
        {pos: [2, 5, 6], state: "minecraft:gold_block"},
        {pos: [3, 5, 5], state: "minecraft:gold_block"},
        {pos: [5, 5, 6], state: "minecraft:air"}
    ],
    entities: [],
    palette: [
        "minecraft:blackstone",
        "minecraft:polished_blackstone_bricks",
        "minecraft:gilded_blackstone",
        "minecraft:gold_block",
        "minecraft:blackstone_wall{east:low,north:low,south:low,up:false,waterlogged:false,west:low}",
        "minecraft:air",
        "minecraft:jigsaw{orientation:up_north}",
        "minecraft:jigsaw{orientation:east_up}",
        "minecraft:chest{facing:north,type:single,waterlogged:false}"
    ]
}
