{
    size: [10, 10, 10],
    data: [
        {pos: [1, 0, 3], state: "minecraft:jigsaw{orientation:up_south}", nbt: {components: {}, final_state: "minecraft:dirt", id: "minecraft:jigsaw", joint: "rollable", name: "minecraft:bottom", placement_priority: 0, pool: "minecraft:abandoned_camp/trees/spruce", selection_priority: 0, target: "minecraft:bottom"}},
        {pos: [1, 0, 4], state: "minecraft:dirt"},
        {pos: [1, 0, 5], state: "minecraft:dirt"},
        {pos: [1, 0, 6], state: "minecraft:dirt"},
        {pos: [1, 0, 7], state: "minecraft:dirt"},
        {pos: [1, 0, 8], state: "minecraft:dirt"},
        {pos: [2, 0, 3], state: "minecraft:mossy_cobblestone"},
        {pos: [2, 0, 4], state: "minecraft:grass_block{snowy:false}"},
        {pos: [2, 0, 5], state: "minecraft:mossy_cobblestone"},
        {pos: [2, 0, 6], state: "minecraft:stone"},
        {pos: [2, 0, 7], state: "minecraft:dirt"},
        {pos: [2, 0, 8], state: "minecraft:stone"},
        {pos: [3, 0, 2], state: "minecraft:mossy_cobblestone"},
        {pos: [3, 0, 3], state: "minecraft:water{level:0}"},
        {pos: [3, 0, 4], state: "minecraft:mossy_cobblestone"},
        {pos: [3, 0, 5], state: "minecraft:water{level:8}"},
        {pos: [3, 0, 6], state: "minecraft:oxidized_copper_chest{facing:east,type:single,waterlogged:true}", nbt: {Items: [], LootTable: "minecraft:chests/abandoned_camp_secret_chest", components: {}, id: "minecraft:chest"}},
        {pos: [3, 0, 7], state: "minecraft:stone"},
        {pos: [3, 0, 8], state: "minecraft:dirt"},
        {pos: [3, 0, 9], state: "minecraft:dirt"},
        {pos: [4, 0, 1], state: "minecraft:cobblestone"},
        {pos: [4, 0, 2], state: "minecraft:water{level:0}"},
        {pos: [4, 0, 3], state: "minecraft:water{level:0}"},
        {pos: [4, 0, 4], state: "minecraft:water{level:0}"},
        {pos: [4, 0, 5], state: "minecraft:water{level:0}"},
        {pos: [4, 0, 6], state: "minecraft:water{level:8}"},
        {pos: [4, 0, 7], state: "minecraft:cobblestone"},
        {pos: [4, 0, 8], state: "minecraft:dirt"},
        {pos: [5, 0, 1], state: "minecraft:jigsaw{orientation:up_south}", nbt: {components: {}, final_state: "minecraft:dirt", id: "minecraft:jigsaw", joint: "rollable", name: "minecraft:bottom", placement_priority: 0, pool: "minecraft:abandoned_camp/trees/spruce", selection_priority: 0, target: "minecraft:bottom"}},
        {pos: [5, 0, 2], state: "minecraft:mossy_cobblestone"},
        {pos: [5, 0, 3], state: "minecraft:water{level:0}"},
        {pos: [5, 0, 4], state: "minecraft:water{level:0}"},
        {pos: [5, 0, 5], state: "minecraft:water{level:0}"},
        {pos: [5, 0, 6], state: "minecraft:mossy_cobblestone"},
        {pos: [5, 0, 7], state: "minecraft:dirt"},
        {pos: [5, 0, 8], state: "minecraft:dirt"},
        {pos: [6, 0, 2], state: "minecraft:dirt"},
        {pos: [6, 0, 3], state: "minecraft:mossy_cobblestone"},
        {pos: [6, 0, 4], state: "minecraft:water{level:0}"},
        {pos: [6, 0, 5], state: "minecraft:mossy_cobblestone"},
        {pos: [7, 0, 1], state: "minecraft:dirt_path"},
        {pos: [7, 0, 2], state: "minecraft:dirt_path"},
        {pos: [7, 0, 3], state: "minecraft:dirt_path"},
        {pos: [7, 0, 4], state: "minecraft:mossy_cobblestone"},
        {pos: [8, 0, 1], state: "minecraft:dirt_path"},
        {pos: [8, 0, 2], state: "minecraft:dirt_path"},
        {pos: [8, 0, 3], state: "minecraft:dirt"},
        {pos: [8, 0, 4], state: "minecraft:dirt_path"},
        {pos: [8, 0, 8], state: "minecraft:jigsaw{orientation:up_north}", nbt: {components: {}, final_state: "minecraft:dirt", id: "minecraft:jigsaw", joint: "rollable", name: "minecraft:bottom", placement_priority: 0, pool: "minecraft:abandoned_camp/trees/spruce", selection_priority: 0, target: "minecraft:bottom"}},
        {pos: [9, 0, 2], state: "minecraft:dirt_path"},
        {pos: [9, 0, 3], state: "minecraft:dirt_path"},
        {pos: [9, 0, 4], state: "minecraft:jigsaw{orientation:east_up}", nbt: {components: {}, final_state: "minecraft:dirt_path", id: "minecraft:jigsaw", joint: "rollable", name: "minecraft:end_connector", placement_priority: 0, pool: "minecraft:empty", selection_priority: 0, target: "minecraft:connector"}},
        {pos: [1, 1, 4], state: "minecraft:stone"},
        {pos: [1, 1, 5], state: "minecraft:stone"},
        {pos: [1, 1, 6], state: "minecraft:stone"},
        {pos: [1, 1, 7], state: "minecraft:stone"},
        {pos: [1, 1, 8], state: "minecraft:stone"},
        {pos: [2, 1, 5], state: "minecraft:stone"},
        {pos: [2, 1, 6], state: "minecraft:stone"},
        {pos: [2, 1, 7], state: "minecraft:stone"},
        {pos: [2, 1, 8], state: "minecraft:stone"},
        {pos: [3, 1, 5], state: "minecraft:water{level:1}"},
        {pos: [3, 1, 6], state: "minecraft:water{level:8}"},
        {pos: [3, 1, 7], state: "minecraft:stone"},
        {pos: [3, 1, 8], state: "minecraft:stone"},
        {pos: [3, 1, 9], state: "minecraft:stone"},
        {pos: [4, 1, 6], state: "minecraft:water{level:1}"},
        {pos: [4, 1, 7], state: "minecraft:stone"},
        {pos: [4, 1, 8], state: "minecraft:stone"},
        {pos: [5, 1, 7], state: "minecraft:stone"},
        {pos: [5, 1, 8], state: "minecraft:stone"},
        {pos: [6, 1, 2], state: "minecraft:chest{facing:east,type:single,waterlogged:false}", nbt: {Items: [], LootTable: "minecraft:chests/abandoned_camp_common_chest", components: {}, id: "minecraft:chest"}},
        {pos: [8, 1, 3], state: "minecraft:campfire{facing:west,lit:false,signal_fire:false,waterlogged:false}", nbt: {CookingTimes: [I; 0, 0, 0, 0], CookingTotalTimes: [I; 0, 0, 0, 0], Items: [], components: {}, id: "minecraft:campfire"}},
        {pos: [1, 2, 6], state: "minecraft:stone"},
        {pos: [1, 2, 7], state: "minecraft:stone"},
        {pos: [1, 2, 8], state: "minecraft:stone"},
        {pos: [2, 2, 5], state: "minecraft:stone"},
        {pos: [2, 2, 6], state: "minecraft:stone"},
        {pos: [2, 2, 7], state: "minecraft:stone"},
        {pos: [2, 2, 8], state: "minecraft:stone"},
        {pos: [3, 2, 6], state: "minecraft:water{level:1}"},
        {pos: [3, 2, 7], state: "minecraft:water{level:0}"},
        {pos: [3, 2, 8], state: "minecraft:stone"},
        {pos: [4, 2, 7], state: "minecraft:stone"},
        {pos: [1, 3, 6], state: "minecraft:stone"},
        {pos: [2, 3, 6], state: "minecraft:stone"},
        {pos: [2, 3, 7], state: "minecraft:stone"},
        {pos: [2, 3, 8], state: "minecraft:stone"},
        {pos: [3, 3, 6], state: "minecraft:stone"},
        {pos: [3, 3, 7], state: "minecraft:stone"},
        {pos: [3, 3, 8], state: "minecraft:stone"},
        {pos: [4, 3, 7], state: "minecraft:stone"},
        {pos: [3, 4, 7], state: "minecraft:stone"},
        {pos: [4, 4, 7], state: "minecraft:stone"},
        {pos: [3, 5, 7], state: "minecraft:stone"}
    ],
    entities: [
        {blockPos: [8, 0, 2], pos: [8.5d, 0.9375d, 2.5d], nbt: {Air: 300s, Fire: 0s, Invulnerable: 0b, Motion: [0.0d, 0.0d, 0.0d], OnGround: 0b, PortalCooldown: 0, Pos: [-102.5d, -60.0625d, 179.5d], Rotation: [180.0f, 0.0f], UUID: [I; -1348163573, -1099152982, -1730158890, -521995845], block_pos: [I; -103, -61, 179], color: "brown", fall_distance: 0.0d, id: "minecraft:cushion"}},
        {blockPos: [8, 0, 4], pos: [8.5d, 0.9375d, 4.5d], nbt: {Air: 300s, Fire: 0s, Invulnerable: 0b, Motion: [0.0d, 0.0d, 0.0d], OnGround: 0b, PortalCooldown: 0, Pos: [-102.5d, -60.0625d, 181.5d], Rotation: [90.0f, 0.0f], UUID: [I; -252472853, 1815890697, -1628724336, 1886674250], block_pos: [I; -103, -61, 181], color: "green", fall_distance: 0.0d, id: "minecraft:cushion"}}
    ],
    palette: [
        "minecraft:dirt",
        "minecraft:mossy_cobblestone",
        "minecraft:grass_block{snowy:false}",
        "minecraft:stone",
        "minecraft:cobblestone",
        "minecraft:water{level:0}",
        "minecraft:water{level:8}",
        "minecraft:dirt_path",
        "minecraft:water{level:1}",
        "minecraft:jigsaw{orientation:up_south}",
        "minecraft:oxidized_copper_chest{facing:east,type:single,waterlogged:true}",
        "minecraft:jigsaw{orientation:up_north}",
        "minecraft:jigsaw{orientation:east_up}",
        "minecraft:chest{facing:east,type:single,waterlogged:false}",
        "minecraft:campfire{facing:west,lit:false,signal_fire:false,waterlogged:false}"
    ]
}
