{
    size: [10, 10, 10],
    data: [
        {pos: [0, 0, 6], state: "minecraft:grass_block{snowy:false}"},
        {pos: [1, 0, 2], state: "minecraft:dirt"},
        {pos: [1, 0, 3], state: "minecraft:dirt"},
        {pos: [1, 0, 4], state: "minecraft:dirt"},
        {pos: [2, 0, 2], state: "minecraft:dirt"},
        {pos: [2, 0, 3], state: "minecraft:dirt"},
        {pos: [2, 0, 4], state: "minecraft:dirt"},
        {pos: [3, 0, 1], state: "minecraft:dirt"},
        {pos: [3, 0, 2], state: "minecraft:dirt"},
        {pos: [3, 0, 3], state: "minecraft:dirt"},
        {pos: [4, 0, 1], state: "minecraft:dirt"},
        {pos: [4, 0, 2], state: "minecraft:dirt"},
        {pos: [4, 0, 3], state: "minecraft:grass_block{snowy:false}"},
        {pos: [5, 0, 3], state: "minecraft:dirt_path"},
        {pos: [5, 0, 4], state: "minecraft:dirt_path"},
        {pos: [5, 0, 6], state: "minecraft:grass_block{snowy:false}"},
        {pos: [6, 0, 2], state: "minecraft:grass_block{snowy:false}"},
        {pos: [6, 0, 3], state: "minecraft:dirt_path"},
        {pos: [6, 0, 4], state: "minecraft:dirt_path"},
        {pos: [6, 0, 5], state: "minecraft:dirt_path"},
        {pos: [7, 0, 1], state: "minecraft:grass_block{snowy:false}"},
        {pos: [7, 0, 3], state: "minecraft:dirt_path"},
        {pos: [7, 0, 4], state: "minecraft:grass_block{snowy:false}"},
        {pos: [7, 0, 5], state: "minecraft:dirt_path"},
        {pos: [7, 0, 6], state: "minecraft:dirt_path"},
        {pos: [7, 0, 7], state: "minecraft:jigsaw{orientation:up_west}", nbt: {components: {}, final_state: "minecraft:dirt", id: "minecraft:jigsaw", joint: "rollable", name: "minecraft:bottom", placement_priority: 0, pool: "minecraft:abandoned_camp/trees/spruce", selection_priority: 0, target: "minecraft:bottom"}},
        {pos: [8, 0, 1], state: "minecraft:grass_block{snowy:false}"},
        {pos: [8, 0, 4], state: "minecraft:dirt_path"},
        {pos: [8, 0, 5], state: "minecraft:dirt_path"},
        {pos: [8, 0, 6], state: "minecraft:dirt_path"},
        {pos: [9, 0, 2], state: "minecraft:dirt_path"},
        {pos: [9, 0, 3], state: "minecraft:dirt_path"},
        {pos: [9, 0, 4], state: "minecraft:jigsaw{orientation:east_up}", nbt: {components: {}, final_state: "minecraft:dirt_path", id: "minecraft:jigsaw", joint: "rollable", name: "minecraft:end_connector", placement_priority: 0, pool: "minecraft:empty", selection_priority: 0, target: "minecraft:connector"}},
        {pos: [9, 0, 5], state: "minecraft:dirt_path"},
        {pos: [0, 1, 6], state: "minecraft:large_fern{half:lower}"},
        {pos: [1, 1, 2], state: "minecraft:grass_block{snowy:false}"},
        {pos: [1, 1, 3], state: "minecraft:grass_block{snowy:false}"},
        {pos: [1, 1, 4], state: "minecraft:grass_block{snowy:false}"},
        {pos: [2, 1, 2], state: "minecraft:grass_block{snowy:false}"},
        {pos: [2, 1, 3], state: "minecraft:jigsaw{orientation:up_east}", nbt: {components: {}, final_state: "minecraft:dirt", id: "minecraft:jigsaw", joint: "rollable", name: "minecraft:bottom", placement_priority: 0, pool: "minecraft:abandoned_camp/trees/spruce", selection_priority: 0, target: "minecraft:bottom"}},
        {pos: [2, 1, 4], state: "minecraft:grass_block{snowy:false}"},
        {pos: [3, 1, 1], state: "minecraft:grass_block{snowy:false}"},
        {pos: [3, 1, 2], state: "minecraft:grass_block{snowy:false}"},
        {pos: [3, 1, 3], state: "minecraft:grass_block{snowy:false}"},
        {pos: [4, 1, 1], state: "minecraft:grass_block{snowy:false}"},
        {pos: [4, 1, 2], state: "minecraft:grass_block{snowy:false}"},
        {pos: [4, 1, 3], state: "minecraft:chest{facing:east,type:single,waterlogged:false}", nbt: {LootTable: "minecraft:chests/abandoned_camp_common_chest", components: {}, id: "minecraft:chest"}},
        {pos: [5, 1, 6], state: "minecraft:large_fern{half:lower}"},
        {pos: [6, 1, 2], state: "minecraft:large_fern{half:lower}"},
        {pos: [7, 1, 1], state: "minecraft:fern"},
        {pos: [7, 1, 4], state: "minecraft:campfire{facing:west,lit:false,signal_fire:false,waterlogged:false}", nbt: {CookingTimes: [I; 0, 0, 0, 0], CookingTotalTimes: [I; 0, 0, 0, 0], Items: [], components: {}, id: "minecraft:campfire"}},
        {pos: [8, 1, 1], state: "minecraft:large_fern{half:lower}"},
        {pos: [0, 2, 6], state: "minecraft:large_fern{half:upper}"},
        {pos: [1, 2, 2], state: "minecraft:large_fern{half:lower}"},
        {pos: [2, 2, 4], state: "minecraft:fern"},
        {pos: [4, 2, 2], state: "minecraft:fern"},
        {pos: [5, 2, 6], state: "minecraft:large_fern{half:upper}"},
        {pos: [6, 2, 2], state: "minecraft:large_fern{half:upper}"},
        {pos: [8, 2, 1], state: "minecraft:large_fern{half:upper}"},
        {pos: [1, 3, 2], state: "minecraft:large_fern{half:upper}"}
    ],
    entities: [
        {blockPos: [7, 0, 3], pos: [7.5d, 0.9375d, 3.5d], nbt: {Air: 300s, Fire: 0s, Invulnerable: 0b, Motion: [0.0d, 0.0d, 0.0d], OnGround: 0b, PortalCooldown: 0, Pos: [-86.5d, -60.0625d, 180.5d], Rotation: [90.0f, 0.0f], UUID: [I; 2057171199, -1918156393, -1814690647, 1298301316], block_pos: [I; -87, -61, 180], color: "green", fall_distance: 0.0d, id: "minecraft:cushion"}},
        {blockPos: [7, 0, 5], pos: [7.5d, 0.9375d, 5.5d], nbt: {Air: 300s, Fire: 0s, Invulnerable: 0b, Motion: [0.0d, 0.0d, 0.0d], OnGround: 0b, PortalCooldown: 0, Pos: [-86.5d, -60.0625d, 182.5d], Rotation: [90.0f, 0.0f], UUID: [I; -135735487, -1031257474, -1637920971, -1604207666], block_pos: [I; -87, -61, 182], color: "gray", fall_distance: 0.0d, id: "minecraft:cushion"}}
    ],
    palette: [
        "minecraft:grass_block{snowy:false}",
        "minecraft:dirt",
        "minecraft:dirt_path",
        "minecraft:large_fern{half:lower}",
        "minecraft:fern",
        "minecraft:large_fern{half:upper}",
        "minecraft:jigsaw{orientation:up_west}",
        "minecraft:jigsaw{orientation:east_up}",
        "minecraft:jigsaw{orientation:up_east}",
        "minecraft:chest{facing:east,type:single,waterlogged:false}",
        "minecraft:campfire{facing:west,lit:false,signal_fire:false,waterlogged:false}"
    ]
}
