{
    size: [10, 10, 10],
    data: [
        {pos: [1, 0, 4], state: "minecraft:red_sandstone"},
        {pos: [1, 0, 5], state: "minecraft:red_sandstone"},
        {pos: [2, 0, 3], state: "minecraft:red_sandstone"},
        {pos: [2, 0, 4], state: "minecraft:red_sandstone"},
        {pos: [2, 0, 5], state: "minecraft:red_sandstone"},
        {pos: [2, 0, 6], state: "minecraft:red_sandstone"},
        {pos: [3, 0, 2], state: "minecraft:red_sand"},
        {pos: [3, 0, 3], state: "minecraft:red_sand"},
        {pos: [3, 0, 4], state: "minecraft:red_sand"},
        {pos: [3, 0, 5], state: "minecraft:red_sand"},
        {pos: [3, 0, 6], state: "minecraft:red_sandstone"},
        {pos: [3, 0, 7], state: "minecraft:red_sandstone"},
        {pos: [4, 0, 2], state: "minecraft:red_sand"},
        {pos: [4, 0, 3], state: "minecraft:red_sand"},
        {pos: [4, 0, 4], state: "minecraft:dirt"},
        {pos: [4, 0, 5], state: "minecraft:dirt"},
        {pos: [4, 0, 6], state: "minecraft:red_sand"},
        {pos: [4, 0, 7], state: "minecraft:red_sandstone"},
        {pos: [4, 0, 8], state: "minecraft:red_sandstone"},
        {pos: [5, 0, 1], state: "minecraft:red_sandstone"},
        {pos: [5, 0, 2], state: "minecraft:red_sand"},
        {pos: [5, 0, 3], state: "minecraft:dirt"},
        {pos: [5, 0, 4], state: "minecraft:dirt"},
        {pos: [5, 0, 5], state: "minecraft:dirt"},
        {pos: [5, 0, 6], state: "minecraft:dirt"},
        {pos: [5, 0, 7], state: "minecraft:red_sandstone"},
        {pos: [5, 0, 8], state: "minecraft:red_sandstone"},
        {pos: [5, 0, 9], state: "minecraft:red_sand"},
        {pos: [6, 0, 1], state: "minecraft:red_sand"},
        {pos: [6, 0, 2], state: "minecraft:red_sand"},
        {pos: [6, 0, 3], state: "minecraft:red_sand"},
        {pos: [6, 0, 4], state: "minecraft:dirt"},
        {pos: [6, 0, 5], state: "minecraft:dirt"},
        {pos: [6, 0, 6], state: "minecraft:red_sand"},
        {pos: [6, 0, 7], state: "minecraft:red_sandstone"},
        {pos: [6, 0, 8], state: "minecraft:red_sandstone"},
        {pos: [6, 0, 9], state: "minecraft:red_sand"},
        {pos: [7, 0, 2], state: "minecraft:red_sand"},
        {pos: [7, 0, 3], state: "minecraft:dirt_path"},
        {pos: [7, 0, 4], state: "minecraft:dirt_path"},
        {pos: [7, 0, 5], state: "minecraft:red_sand"},
        {pos: [7, 0, 6], state: "minecraft:red_sand"},
        {pos: [7, 0, 7], state: "minecraft:red_sand"},
        {pos: [7, 0, 8], state: "minecraft:red_sandstone"},
        {pos: [7, 0, 9], state: "minecraft:red_sand"},
        {pos: [8, 0, 2], state: "minecraft:dirt_path"},
        {pos: [8, 0, 3], state: "minecraft:dirt_path"},
        {pos: [8, 0, 4], state: "minecraft:dirt_path"},
        {pos: [8, 0, 5], state: "minecraft:red_sand"},
        {pos: [8, 0, 6], state: "minecraft:red_sand"},
        {pos: [8, 0, 7], state: "minecraft:red_sandstone"},
        {pos: [9, 0, 2], state: "minecraft:dirt_path"},
        {pos: [9, 0, 3], state: "minecraft:dirt_path"},
        {pos: [9, 0, 4], state: "minecraft:jigsaw{orientation:east_up}", nbt: {components: {}, final_state: "minecraft:dirt_path", id: "minecraft:jigsaw", joint: "rollable", name: "minecraft:end_connector", placement_priority: 0, pool: "minecraft:empty", selection_priority: 0, target: "minecraft:connector"}},
        {pos: [1, 1, 4], state: "minecraft:red_sand"},
        {pos: [1, 1, 5], state: "minecraft:red_sand"},
        {pos: [2, 1, 3], state: "minecraft:red_sand"},
        {pos: [2, 1, 4], state: "minecraft:red_sandstone"},
        {pos: [2, 1, 5], state: "minecraft:red_sandstone"},
        {pos: [2, 1, 6], state: "minecraft:red_sand"},
        {pos: [3, 1, 2], state: "minecraft:red_sand"},
        {pos: [3, 1, 3], state: "minecraft:red_sandstone"},
        {pos: [3, 1, 4], state: "minecraft:red_sandstone"},
        {pos: [3, 1, 5], state: "minecraft:red_sandstone"},
        {pos: [3, 1, 6], state: "minecraft:red_sandstone"},
        {pos: [3, 1, 7], state: "minecraft:red_sand"},
        {pos: [4, 1, 2], state: "minecraft:red_sandstone"},
        {pos: [4, 1, 3], state: "minecraft:red_sandstone"},
        {pos: [4, 1, 4], state: "minecraft:red_sand"},
        {pos: [4, 1, 5], state: "minecraft:red_sand"},
        {pos: [4, 1, 6], state: "minecraft:red_sandstone"},
        {pos: [4, 1, 7], state: "minecraft:red_sandstone"},
        {pos: [4, 1, 8], state: "minecraft:red_sand"},
        {pos: [5, 1, 2], state: "minecraft:red_sandstone"},
        {pos: [5, 1, 3], state: "minecraft:red_sand"},
        {pos: [5, 1, 4], state: "minecraft:red_sand"},
        {pos: [5, 1, 5], state: "minecraft:oxidized_copper_chest{facing:east,type:single,waterlogged:false}", nbt: {LootTable: "minecraft:chests/abandoned_camp_secret_chest", components: {}, id: "minecraft:chest"}},
        {pos: [5, 1, 6], state: "minecraft:red_sand"},
        {pos: [5, 1, 7], state: "minecraft:red_sand"},
        {pos: [5, 1, 8], state: "minecraft:red_sandstone"},
        {pos: [5, 1, 9], state: "minecraft:red_sand"},
        {pos: [6, 1, 2], state: "minecraft:red_sandstone"},
        {pos: [6, 1, 4], state: "minecraft:campfire{facing:west,lit:false,signal_fire:false,waterlogged:false}", nbt: {CookingTimes: [I; 0, 0, 0, 0], CookingTotalTimes: [I; 0, 0, 0, 0], Items: [], components: {}, id: "minecraft:campfire"}},
        {pos: [6, 1, 5], state: "minecraft:red_sand"},
        {pos: [6, 1, 6], state: "minecraft:red_sand"},
        {pos: [6, 1, 7], state: "minecraft:red_sand"},
        {pos: [6, 1, 8], state: "minecraft:red_sandstone"},
        {pos: [6, 1, 9], state: "minecraft:red_sandstone"},
        {pos: [7, 1, 6], state: "minecraft:barrel{facing:north,open:false}", nbt: {LootTable: "minecraft:barrels/abandoned_camp_barrel", components: {}, id: "minecraft:barrel"}},
        {pos: [7, 1, 7], state: "minecraft:red_sandstone"},
        {pos: [7, 1, 8], state: "minecraft:red_sandstone"},
        {pos: [7, 1, 9], state: "minecraft:red_sandstone"},
        {pos: [8, 1, 6], state: "minecraft:red_sand"},
        {pos: [8, 1, 7], state: "minecraft:red_sand"},
        {pos: [1, 2, 5], state: "minecraft:tall_dry_grass"},
        {pos: [2, 2, 4], state: "minecraft:red_sand"},
        {pos: [2, 2, 5], state: "minecraft:red_sand"},
        {pos: [3, 2, 2], state: "minecraft:tall_dry_grass"},
        {pos: [3, 2, 3], state: "minecraft:red_sand"},
        {pos: [3, 2, 4], state: "minecraft:red_sandstone"},
        {pos: [3, 2, 5], state: "minecraft:red_sandstone"},
        {pos: [3, 2, 6], state: "minecraft:red_sand"},
        {pos: [4, 2, 3], state: "minecraft:red_sand"},
        {pos: [4, 2, 4], state: "minecraft:red_sand"},
        {pos: [4, 2, 5], state: "minecraft:red_sand"},
        {pos: [4, 2, 6], state: "minecraft:red_sand"},
        {pos: [4, 2, 7], state: "minecraft:red_sand"},
        {pos: [4, 2, 8], state: "minecraft:tall_dry_grass"},
        {pos: [5, 2, 2], state: "minecraft:red_sand"},
        {pos: [5, 2, 5], state: "minecraft:red_sand"},
        {pos: [5, 2, 6], state: "minecraft:red_sand"},
        {pos: [5, 2, 7], state: "minecraft:red_sand"},
        {pos: [5, 2, 8], state: "minecraft:red_sand"},
        {pos: [5, 2, 9], state: "minecraft:tall_dry_grass"},
        {pos: [6, 2, 5], state: "minecraft:red_sand"},
        {pos: [6, 2, 6], state: "minecraft:red_sand"},
        {pos: [6, 2, 7], state: "minecraft:red_sand"},
        {pos: [6, 2, 8], state: "minecraft:red_sandstone"},
        {pos: [7, 2, 6], state: "minecraft:red_sand"},
        {pos: [7, 2, 7], state: "minecraft:red_sandstone"},
        {pos: [7, 2, 8], state: "minecraft:red_sandstone"},
        {pos: [8, 2, 7], state: "minecraft:red_sand"},
        {pos: [3, 3, 4], state: "minecraft:red_sand"},
        {pos: [3, 3, 6], state: "minecraft:red_sand"},
        {pos: [4, 3, 3], state: "minecraft:tall_dry_grass"},
        {pos: [4, 3, 5], state: "minecraft:red_sand"},
        {pos: [4, 3, 6], state: "minecraft:red_sand"},
        {pos: [5, 3, 2], state: "minecraft:tall_dry_grass"},
        {pos: [5, 3, 5], state: "minecraft:red_sand"},
        {pos: [5, 3, 6], state: "minecraft:tall_dry_grass"},
        {pos: [5, 3, 7], state: "minecraft:red_sand"},
        {pos: [6, 3, 5], state: "minecraft:tall_dry_grass"},
        {pos: [8, 3, 7], state: "minecraft:tall_dry_grass"},
        {pos: [3, 4, 4], state: "minecraft:tall_dry_grass"},
        {pos: [3, 4, 6], state: "minecraft:tall_dry_grass"}
    ],
    entities: [
        {blockPos: [7, 0, 3], pos: [7.5d, 0.9375d, 3.5d], nbt: {Air: 300s, Fire: 0s, Invulnerable: 0b, Motion: [0.0d, 0.0d, 0.0d], OnGround: 0b, PortalCooldown: 0, Pos: [-103.5d, -60.0625d, 540.5d], Rotation: [90.0f, 0.0f], UUID: [I; 73405058, -342080708, -1455080041, 531891575], block_pos: [I; -104, -61, 540], color: "orange", fall_distance: 0.0d, id: "minecraft:cushion"}}
    ],
    palette: [
        "minecraft:red_sandstone",
        "minecraft:red_sand",
        "minecraft:dirt",
        "minecraft:dirt_path",
        "minecraft:tall_dry_grass",
        "minecraft:jigsaw{orientation:east_up}",
        "minecraft:oxidized_copper_chest{facing:east,type:single,waterlogged:false}",
        "minecraft:campfire{facing:west,lit:false,signal_fire:false,waterlogged:false}",
        "minecraft:barrel{facing:north,open:false}"
    ]
}
