{
    size: [10, 10, 10],
    data: [
        {pos: [0, 0, 6], state: "minecraft:dirt"},
        {pos: [0, 0, 7], state: "minecraft:dirt"},
        {pos: [1, 0, 5], state: "minecraft:dirt"},
        {pos: [1, 0, 6], state: "minecraft:dirt"},
        {pos: [1, 0, 7], state: "minecraft:dirt"},
        {pos: [1, 0, 8], state: "minecraft:dirt"},
        {pos: [2, 0, 5], state: "minecraft:dirt"},
        {pos: [2, 0, 6], state: "minecraft:dirt"},
        {pos: [2, 0, 7], state: "minecraft:dirt"},
        {pos: [2, 0, 8], state: "minecraft:dirt"},
        {pos: [3, 0, 4], state: "minecraft:dirt"},
        {pos: [3, 0, 5], state: "minecraft:dirt"},
        {pos: [3, 0, 6], state: "minecraft:dirt"},
        {pos: [3, 0, 7], state: "minecraft:dirt"},
        {pos: [3, 0, 8], state: "minecraft:dirt"},
        {pos: [3, 0, 9], state: "minecraft:dirt"},
        {pos: [4, 0, 2], state: "minecraft:red_sand"},
        {pos: [4, 0, 3], state: "minecraft:gold_ore"},
        {pos: [4, 0, 4], state: "minecraft:red_sandstone"},
        {pos: [4, 0, 5], state: "minecraft:dirt"},
        {pos: [4, 0, 6], state: "minecraft:dirt"},
        {pos: [4, 0, 7], state: "minecraft:dirt"},
        {pos: [4, 0, 8], state: "minecraft:dirt"},
        {pos: [5, 0, 2], state: "minecraft:oxidized_copper_chest{facing:south,type:single,waterlogged:false}", nbt: {LootTable: "minecraft:chests/abandoned_camp_secret_chest", components: {}, id: "minecraft:chest"}},
        {pos: [5, 0, 3], state: "minecraft:red_sand"},
        {pos: [5, 0, 4], state: "minecraft:red_sand"},
        {pos: [5, 0, 5], state: "minecraft:red_sandstone"},
        {pos: [5, 0, 6], state: "minecraft:dirt"},
        {pos: [5, 0, 7], state: "minecraft:dirt"},
        {pos: [5, 0, 8], state: "minecraft:dirt"},
        {pos: [6, 0, 2], state: "minecraft:red_sand"},
        {pos: [6, 0, 3], state: "minecraft:gold_ore"},
        {pos: [6, 0, 5], state: "minecraft:dirt"},
        {pos: [6, 0, 6], state: "minecraft:dirt"},
        {pos: [6, 0, 7], state: "minecraft:dirt"},
        {pos: [7, 0, 3], state: "minecraft:dirt"},
        {pos: [7, 0, 5], state: "minecraft:dirt"},
        {pos: [7, 0, 6], state: "minecraft:dirt"},
        {pos: [7, 0, 7], state: "minecraft:dirt"},
        {pos: [8, 0, 5], state: "minecraft:dirt"},
        {pos: [8, 0, 6], state: "minecraft:dirt"},
        {pos: [8, 0, 7], state: "minecraft:dirt"},
        {pos: [9, 0, 4], state: "minecraft:dirt"},
        {pos: [9, 0, 5], state: "minecraft:dirt"},
        {pos: [9, 0, 6], state: "minecraft:dirt"},
        {pos: [9, 0, 7], state: "minecraft:dirt"},
        {pos: [0, 1, 6], state: "minecraft:red_sand"},
        {pos: [0, 1, 7], state: "minecraft:red_sand"},
        {pos: [1, 1, 5], state: "minecraft:terracotta"},
        {pos: [1, 1, 6], state: "minecraft:terracotta"},
        {pos: [1, 1, 7], state: "minecraft:red_sand"},
        {pos: [1, 1, 8], state: "minecraft:red_sand"},
        {pos: [2, 1, 5], state: "minecraft:red_sandstone"},
        {pos: [2, 1, 6], state: "minecraft:terracotta"},
        {pos: [2, 1, 7], state: "minecraft:terracotta"},
        {pos: [2, 1, 8], state: "minecraft:terracotta"},
        {pos: [3, 1, 4], state: "minecraft:red_sandstone"},
        {pos: [3, 1, 5], state: "minecraft:red_sandstone"},
        {pos: [3, 1, 6], state: "minecraft:red_sandstone"},
        {pos: [3, 1, 7], state: "minecraft:terracotta"},
        {pos: [3, 1, 8], state: "minecraft:red_sandstone"},
        {pos: [3, 1, 9], state: "minecraft:terracotta"},
        {pos: [4, 1, 2], state: "minecraft:short_dry_grass"},
        {pos: [4, 1, 3], state: "minecraft:cobweb"},
        {pos: [4, 1, 4], state: "minecraft:red_sandstone"},
        {pos: [4, 1, 5], state: "minecraft:red_sand"},
        {pos: [4, 1, 6], state: "minecraft:red_sandstone"},
        {pos: [4, 1, 7], state: "minecraft:red_sandstone"},
        {pos: [4, 1, 8], state: "minecraft:red_sandstone"},
        {pos: [5, 1, 2], state: "minecraft:red_sand"},
        {pos: [5, 1, 3], state: "minecraft:tall_dry_grass"},
        {pos: [5, 1, 4], state: "minecraft:dead_bush"},
        {pos: [5, 1, 5], state: "minecraft:red_sandstone"},
        {pos: [5, 1, 6], state: "minecraft:red_sandstone"},
        {pos: [5, 1, 7], state: "minecraft:red_sandstone"},
        {pos: [5, 1, 8], state: "minecraft:red_sandstone"},
        {pos: [6, 1, 2], state: "minecraft:short_dry_grass"},
        {pos: [6, 1, 3], state: "minecraft:cobweb"},
        {pos: [6, 1, 5], state: "minecraft:red_sand"},
        {pos: [6, 1, 6], state: "minecraft:dirt_path"},
        {pos: [6, 1, 7], state: "minecraft:dirt_path"},
        {pos: [7, 1, 3], state: "minecraft:red_sand"},
        {pos: [7, 1, 5], state: "minecraft:dirt_path"},
        {pos: [7, 1, 6], state: "minecraft:dirt_path"},
        {pos: [7, 1, 7], state: "minecraft:dirt_path"},
        {pos: [8, 1, 5], state: "minecraft:dirt_path"},
        {pos: [8, 1, 6], state: "minecraft:red_sand"},
        {pos: [8, 1, 7], state: "minecraft:dirt_path"},
        {pos: [9, 1, 4], state: "minecraft:jigsaw{orientation:east_up}", nbt: {components: {}, final_state: "minecraft:dirt_path", id: "minecraft:jigsaw", joint: "rollable", name: "minecraft:end_connector", placement_priority: 0, pool: "minecraft:empty", selection_priority: 0, target: "minecraft:connector"}},
        {pos: [9, 1, 5], state: "minecraft:dirt_path"},
        {pos: [9, 1, 6], state: "minecraft:dirt_path"},
        {pos: [9, 1, 7], state: "minecraft:dirt_path"},
        {pos: [0, 2, 6], state: "minecraft:red_sand"},
        {pos: [0, 2, 7], state: "minecraft:red_sand"},
        {pos: [1, 2, 5], state: "minecraft:red_sand"},
        {pos: [1, 2, 6], state: "minecraft:red_sand"},
        {pos: [1, 2, 7], state: "minecraft:red_sand"},
        {pos: [1, 2, 8], state: "minecraft:red_sand"},
        {pos: [2, 2, 5], state: "minecraft:red_sandstone"},
        {pos: [2, 2, 6], state: "minecraft:red_sandstone"},
        {pos: [2, 2, 7], state: "minecraft:red_sandstone"},
        {pos: [2, 2, 8], state: "minecraft:red_sandstone"},
        {pos: [3, 2, 4], state: "minecraft:red_sandstone"},
        {pos: [3, 2, 5], state: "minecraft:red_sandstone"},
        {pos: [3, 2, 6], state: "minecraft:red_sandstone"},
        {pos: [3, 2, 7], state: "minecraft:red_sandstone"},
        {pos: [3, 2, 8], state: "minecraft:red_sandstone"},
        {pos: [3, 2, 9], state: "minecraft:red_sandstone"},
        {pos: [4, 2, 5], state: "minecraft:red_sandstone"},
        {pos: [4, 2, 6], state: "minecraft:red_sandstone"},
        {pos: [4, 2, 7], state: "minecraft:red_sandstone"},
        {pos: [4, 2, 8], state: "minecraft:red_sandstone"},
        {pos: [5, 2, 6], state: "minecraft:barrel{facing:up,open:false}", nbt: {LootTable: "minecraft:barrels/abandoned_camp_barrel", components: {}, id: "minecraft:barrel"}},
        {pos: [5, 2, 7], state: "minecraft:red_sandstone"},
        {pos: [5, 2, 8], state: "minecraft:red_sandstone"},
        {pos: [6, 2, 5], state: "minecraft:dead_bush"},
        {pos: [7, 2, 3], state: "minecraft:cactus{age:0}"},
        {pos: [8, 2, 6], state: "minecraft:campfire{facing:west,lit:false,signal_fire:false,waterlogged:false}", nbt: {CookingTimes: [I; 0, 0, 0, 0], CookingTotalTimes: [I; 0, 0, 0, 0], Items: [], components: {}, id: "minecraft:campfire"}},
        {pos: [1, 3, 6], state: "minecraft:red_sand"},
        {pos: [2, 3, 5], state: "minecraft:red_sandstone"},
        {pos: [2, 3, 6], state: "minecraft:red_sandstone"},
        {pos: [2, 3, 7], state: "minecraft:red_sandstone"},
        {pos: [2, 3, 8], state: "minecraft:red_sand"},
        {pos: [3, 3, 5], state: "minecraft:red_sandstone"},
        {pos: [3, 3, 6], state: "minecraft:red_sandstone"},
        {pos: [3, 3, 7], state: "minecraft:red_sandstone"},
        {pos: [3, 3, 8], state: "minecraft:red_sandstone"},
        {pos: [4, 3, 5], state: "minecraft:red_sand"},
        {pos: [4, 3, 6], state: "minecraft:red_sandstone"},
        {pos: [4, 3, 7], state: "minecraft:red_sandstone"},
        {pos: [4, 3, 8], state: "minecraft:red_sandstone"},
        {pos: [5, 3, 7], state: "minecraft:red_sand"},
        {pos: [7, 3, 3], state: "minecraft:cactus{age:0}"},
        {pos: [2, 4, 5], state: "minecraft:red_sand"},
        {pos: [3, 4, 5], state: "minecraft:red_sandstone"},
        {pos: [3, 4, 6], state: "minecraft:red_sandstone"},
        {pos: [3, 4, 7], state: "minecraft:red_sand"},
        {pos: [4, 4, 6], state: "minecraft:red_sandstone"},
        {pos: [4, 4, 7], state: "minecraft:red_sand"},
        {pos: [4, 4, 8], state: "minecraft:red_sand"},
        {pos: [5, 4, 7], state: "minecraft:short_dry_grass"},
        {pos: [7, 4, 3], state: "minecraft:cactus_flower"},
        {pos: [2, 5, 5], state: "minecraft:dead_bush"},
        {pos: [3, 5, 6], state: "minecraft:red_sand"},
        {pos: [4, 5, 8], state: "minecraft:short_dry_grass"}
    ],
    entities: [
        {blockPos: [7, 1, 6], pos: [7.5d, 1.9375d, 6.5d], nbt: {Air: 300s, Fire: 0s, Invulnerable: 0b, Motion: [0.0d, 0.0d, 0.0d], OnGround: 0b, PortalCooldown: 0, Pos: [-86.5d, -60.0625d, 573.5d], Rotation: [90.0f, 0.0f], UUID: [I; -666513699, -1008120614, -1859728418, 881265628], block_pos: [I; -87, -61, 573], color: "orange", fall_distance: 0.0d, id: "minecraft:cushion"}},
        {blockPos: [8, 1, 5], pos: [8.5d, 1.9375d, 5.5d], nbt: {Air: 300s, Fire: 0s, Invulnerable: 0b, Motion: [0.0d, 0.0d, 0.0d], OnGround: 0b, PortalCooldown: 0, Pos: [-85.5d, -60.0625d, 572.5d], Rotation: [90.0f, 0.0f], UUID: [I; -318289738, -913423183, -1483932134, -957965281], block_pos: [I; -86, -61, 572], color: "brown", fall_distance: 0.0d, id: "minecraft:cushion"}},
        {blockPos: [8, 1, 7], pos: [8.5d, 1.9375d, 7.5d], nbt: {Air: 300s, Fire: 0s, Invulnerable: 0b, Motion: [0.0d, 0.0d, 0.0d], OnGround: 0b, PortalCooldown: 0, Pos: [-85.5d, -60.0625d, 574.5d], Rotation: [90.0f, 0.0f], UUID: [I; -1249844376, -14728289, -1417532871, -377730366], block_pos: [I; -86, -61, 574], color: "orange", fall_distance: 0.0d, id: "minecraft:cushion"}},
        {blockPos: [9, 1, 6], pos: [9.5d, 1.9375d, 6.5d], nbt: {Air: 300s, Fire: 0s, Invulnerable: 0b, Motion: [0.0d, 0.0d, 0.0d], OnGround: 0b, PortalCooldown: 0, Pos: [-84.5d, -60.0625d, 573.5d], Rotation: [90.0f, 0.0f], UUID: [I; -2120878039, 354436239, -1633327993, -773021765], block_pos: [I; -85, -61, 573], color: "brown", fall_distance: 0.0d, id: "minecraft:cushion"}}
    ],
    palette: [
        "minecraft:dirt",
        "minecraft:red_sand",
        "minecraft:gold_ore",
        "minecraft:red_sandstone",
        "minecraft:terracotta",
        "minecraft:short_dry_grass",
        "minecraft:cobweb",
        "minecraft:tall_dry_grass",
        "minecraft:dead_bush",
        "minecraft:dirt_path",
        "minecraft:cactus{age:0}",
        "minecraft:cactus_flower",
        "minecraft:oxidized_copper_chest{facing:south,type:single,waterlogged:false}",
        "minecraft:jigsaw{orientation:east_up}",
        "minecraft:barrel{facing:up,open:false}",
        "minecraft:campfire{facing:west,lit:false,signal_fire:false,waterlogged:false}"
    ]
}
