{
    size: [10, 10, 10],
    data: [
        {pos: [1, 0, 5], state: "minecraft:terracotta"},
        {pos: [1, 0, 6], state: "minecraft:terracotta"},
        {pos: [2, 0, 2], state: "minecraft:dirt"},
        {pos: [2, 0, 3], state: "minecraft:red_sand"},
        {pos: [2, 0, 4], state: "minecraft:terracotta"},
        {pos: [2, 0, 5], state: "minecraft:terracotta"},
        {pos: [2, 0, 6], state: "minecraft:terracotta"},
        {pos: [2, 0, 7], state: "minecraft:terracotta"},
        {pos: [3, 0, 1], state: "minecraft:dirt"},
        {pos: [3, 0, 2], state: "minecraft:terracotta"},
        {pos: [3, 0, 3], state: "minecraft:terracotta"},
        {pos: [3, 0, 4], state: "minecraft:terracotta"},
        {pos: [3, 0, 5], state: "minecraft:terracotta"},
        {pos: [3, 0, 6], state: "minecraft:terracotta"},
        {pos: [3, 0, 7], state: "minecraft:terracotta"},
        {pos: [3, 0, 8], state: "minecraft:terracotta"},
        {pos: [4, 0, 1], state: "minecraft:dirt"},
        {pos: [4, 0, 2], state: "minecraft:terracotta"},
        {pos: [4, 0, 3], state: "minecraft:terracotta"},
        {pos: [4, 0, 4], state: "minecraft:terracotta"},
        {pos: [4, 0, 5], state: "minecraft:terracotta"},
        {pos: [4, 0, 6], state: "minecraft:terracotta"},
        {pos: [4, 0, 7], state: "minecraft:terracotta"},
        {pos: [4, 0, 8], state: "minecraft:terracotta"},
        {pos: [5, 0, 1], state: "minecraft:dirt"},
        {pos: [5, 0, 2], state: "minecraft:dirt"},
        {pos: [5, 0, 3], state: "minecraft:dirt"},
        {pos: [5, 0, 4], state: "minecraft:dirt"},
        {pos: [5, 0, 5], state: "minecraft:dirt_path"},
        {pos: [5, 0, 6], state: "minecraft:dirt_path"},
        {pos: [5, 0, 7], state: "minecraft:dirt"},
        {pos: [6, 0, 5], state: "minecraft:dirt_path"},
        {pos: [6, 0, 6], state: "minecraft:dirt_path"},
        {pos: [6, 0, 7], state: "minecraft:dirt_path"},
        {pos: [7, 0, 2], state: "minecraft:red_sand"},
        {pos: [7, 0, 4], state: "minecraft:dirt_path"},
        {pos: [7, 0, 5], state: "minecraft:dirt"},
        {pos: [7, 0, 6], state: "minecraft:dirt_path"},
        {pos: [8, 0, 4], state: "minecraft:dirt_path"},
        {pos: [8, 0, 5], state: "minecraft:dirt_path"},
        {pos: [8, 0, 6], state: "minecraft:dirt_path"},
        {pos: [8, 0, 8], state: "minecraft:red_sand"},
        {pos: [9, 0, 2], state: "minecraft:dirt_path"},
        {pos: [9, 0, 3], state: "minecraft:dirt_path"},
        {pos: [9, 0, 4], state: "minecraft:jigsaw{orientation:east_up}", nbt: {components: {}, final_state: "minecraft:dirt_path", id: "minecraft:jigsaw", joint: "rollable", name: "minecraft:end_connector", placement_priority: 0, pool: "minecraft:empty", selection_priority: 0, target: "minecraft:connector"}},
        {pos: [9, 0, 5], state: "minecraft:dirt_path"},
        {pos: [9, 0, 6], state: "minecraft:dirt_path"},
        {pos: [1, 1, 5], state: "minecraft:terracotta"},
        {pos: [1, 1, 6], state: "minecraft:terracotta"},
        {pos: [2, 1, 2], state: "minecraft:red_sand"},
        {pos: [2, 1, 3], state: "minecraft:red_sand"},
        {pos: [2, 1, 4], state: "minecraft:terracotta"},
        {pos: [2, 1, 5], state: "minecraft:terracotta"},
        {pos: [2, 1, 6], state: "minecraft:terracotta"},
        {pos: [2, 1, 7], state: "minecraft:terracotta"},
        {pos: [3, 1, 1], state: "minecraft:red_sand"},
        {pos: [3, 1, 2], state: "minecraft:terracotta"},
        {pos: [3, 1, 3], state: "minecraft:terracotta"},
        {pos: [3, 1, 4], state: "minecraft:terracotta"},
        {pos: [3, 1, 5], state: "minecraft:terracotta"},
        {pos: [3, 1, 6], state: "minecraft:terracotta"},
        {pos: [3, 1, 7], state: "minecraft:terracotta"},
        {pos: [3, 1, 8], state: "minecraft:terracotta"},
        {pos: [4, 1, 1], state: "minecraft:terracotta"},
        {pos: [4, 1, 2], state: "minecraft:terracotta"},
        {pos: [4, 1, 3], state: "minecraft:terracotta"},
        {pos: [4, 1, 4], state: "minecraft:terracotta"},
        {pos: [4, 1, 5], state: "minecraft:barrel{facing:east,open:false}", nbt: {Items: [], LootTable: "minecraft:barrels/abandoned_camp_barrel", components: {}, id: "minecraft:barrel"}},
        {pos: [4, 1, 6], state: "minecraft:terracotta"},
        {pos: [4, 1, 7], state: "minecraft:terracotta"},
        {pos: [4, 1, 8], state: "minecraft:terracotta"},
        {pos: [5, 1, 1], state: "minecraft:terracotta"},
        {pos: [5, 1, 2], state: "minecraft:terracotta"},
        {pos: [5, 1, 3], state: "minecraft:terracotta"},
        {pos: [5, 1, 4], state: "minecraft:barrel{facing:up,open:false}", nbt: {Items: [], LootTable: "minecraft:barrels/abandoned_camp_barrel", components: {}, id: "minecraft:barrel"}},
        {pos: [5, 1, 7], state: "minecraft:terracotta"},
        {pos: [7, 1, 2], state: "minecraft:cactus{age:0}"},
        {pos: [7, 1, 5], state: "minecraft:campfire{facing:west,lit:false,signal_fire:false,waterlogged:false}", nbt: {CookingTimes: [I; 0, 0, 0, 0], CookingTotalTimes: [I; 0, 0, 0, 0], Items: [], components: {}, id: "minecraft:campfire"}},
        {pos: [8, 1, 8], state: "minecraft:cactus{age:0}"},
        {pos: [1, 2, 5], state: "minecraft:white_terracotta"},
        {pos: [1, 2, 6], state: "minecraft:white_terracotta"},
        {pos: [2, 2, 2], state: "minecraft:short_dry_grass"},
        {pos: [2, 2, 4], state: "minecraft:red_sandstone"},
        {pos: [2, 2, 5], state: "minecraft:red_sandstone"},
        {pos: [2, 2, 6], state: "minecraft:red_sandstone"},
        {pos: [2, 2, 7], state: "minecraft:white_terracotta"},
        {pos: [3, 2, 1], state: "minecraft:red_sand"},
        {pos: [3, 2, 2], state: "minecraft:red_sandstone"},
        {pos: [3, 2, 3], state: "minecraft:red_sandstone"},
        {pos: [3, 2, 4], state: "minecraft:red_sandstone"},
        {pos: [3, 2, 5], state: "minecraft:white_terracotta"},
        {pos: [3, 2, 6], state: "minecraft:white_terracotta"},
        {pos: [3, 2, 7], state: "minecraft:white_terracotta"},
        {pos: [3, 2, 8], state: "minecraft:white_terracotta"},
        {pos: [4, 2, 1], state: "minecraft:red_sandstone"},
        {pos: [4, 2, 2], state: "minecraft:red_sandstone"},
        {pos: [4, 2, 3], state: "minecraft:red_sandstone"},
        {pos: [4, 2, 4], state: "minecraft:white_terracotta"},
        {pos: [4, 2, 6], state: "minecraft:white_terracotta"},
        {pos: [4, 2, 7], state: "minecraft:red_sandstone"},
        {pos: [4, 2, 8], state: "minecraft:white_terracotta"},
        {pos: [5, 2, 2], state: "minecraft:red_sandstone"},
        {pos: [5, 2, 7], state: "minecraft:white_terracotta"},
        {pos: [7, 2, 2], state: "minecraft:cactus{age:0}"},
        {pos: [8, 2, 8], state: "minecraft:cactus{age:0}"},
        {pos: [1, 3, 5], state: "minecraft:red_sandstone"},
        {pos: [1, 3, 6], state: "minecraft:red_sandstone"},
        {pos: [2, 3, 4], state: "minecraft:red_sandstone"},
        {pos: [2, 3, 5], state: "minecraft:red_sandstone"},
        {pos: [2, 3, 6], state: "minecraft:red_sandstone"},
        {pos: [2, 3, 7], state: "minecraft:red_sandstone"},
        {pos: [3, 3, 1], state: "minecraft:tall_dry_grass"},
        {pos: [3, 3, 2], state: "minecraft:red_sand"},
        {pos: [3, 3, 3], state: "minecraft:red_sandstone"},
        {pos: [3, 3, 4], state: "minecraft:red_sandstone"},
        {pos: [3, 3, 5], state: "minecraft:red_sandstone"},
        {pos: [3, 3, 6], state: "minecraft:red_sandstone"},
        {pos: [3, 3, 7], state: "minecraft:red_sandstone"},
        {pos: [3, 3, 8], state: "minecraft:red_sand"},
        {pos: [4, 3, 3], state: "minecraft:red_sand"},
        {pos: [4, 3, 4], state: "minecraft:red_sand"},
        {pos: [4, 3, 6], state: "minecraft:red_sandstone"},
        {pos: [4, 3, 7], state: "minecraft:red_sandstone"},
        {pos: [7, 3, 2], state: "minecraft:cactus_flower"},
        {pos: [8, 3, 8], state: "minecraft:cactus{age:0}"},
        {pos: [2, 4, 5], state: "minecraft:red_sand"},
        {pos: [2, 4, 6], state: "minecraft:red_sand"},
        {pos: [3, 4, 3], state: "minecraft:red_sand"},
        {pos: [3, 4, 4], state: "minecraft:red_sand"},
        {pos: [3, 4, 5], state: "minecraft:red_sand"},
        {pos: [3, 4, 6], state: "minecraft:red_sand"},
        {pos: [3, 4, 7], state: "minecraft:red_sand"},
        {pos: [4, 4, 4], state: "minecraft:red_sand"},
        {pos: [4, 4, 6], state: "minecraft:red_sand"},
        {pos: [8, 4, 8], state: "minecraft:cactus_flower"},
        {pos: [3, 5, 4], state: "minecraft:short_dry_grass"},
        {pos: [3, 5, 6], state: "minecraft:red_sand"}
    ],
    entities: [
        {blockPos: [6, 0, 6], pos: [6.5d, 0.9375d, 6.5d], nbt: {Air: 300s, Fire: 0s, Invulnerable: 0b, Motion: [0.0d, 0.0d, 0.0d], OnGround: 0b, PortalCooldown: 0, Pos: [-87.5d, -60.0625d, 543.5d], Rotation: [90.0f, 0.0f], UUID: [I; -449585359, 52973325, -1789102181, -1591479520], block_pos: [I; -88, -61, 543], color: "orange", fall_distance: 0.0d, id: "minecraft:cushion"}},
        {blockPos: [7, 0, 4], pos: [7.5d, 0.9375d, 4.5d], nbt: {Air: 300s, Fire: 0s, Invulnerable: 0b, Motion: [0.0d, 0.0d, 0.0d], OnGround: 0b, PortalCooldown: 0, Pos: [-86.5d, -60.0625d, 541.5d], Rotation: [90.0f, 0.0f], UUID: [I; 808443117, -31308560, -1183325817, 2063755967], block_pos: [I; -87, -61, 541], color: "orange", fall_distance: 0.0d, id: "minecraft:cushion"}},
        {blockPos: [5, 2, 3], pos: [5.5d, 2.0d, 3.5d], nbt: {Air: 300s, Fire: 0s, Invulnerable: 0b, Motion: [0.0d, 0.0d, 0.0d], OnGround: 0b, PortalCooldown: 0, Pos: [-88.5d, -59.0d, 540.5d], Rotation: [90.0f, 0.0f], UUID: [I; -1755094763, 1166034435, -1319752515, -749768546], block_pos: [I; -89, -59, 540], color: "orange", fall_distance: 0.0d, id: "minecraft:cushion"}}
    ],
    palette: [
        "minecraft:terracotta",
        "minecraft:dirt",
        "minecraft:red_sand",
        "minecraft:white_terracotta",
        "minecraft:red_sandstone",
        "minecraft:dirt_path",
        "minecraft:cactus{age:0}",
        "minecraft:short_dry_grass",
        "minecraft:tall_dry_grass",
        "minecraft:cactus_flower",
        "minecraft:jigsaw{orientation:east_up}",
        "minecraft:barrel{facing:east,open:false}",
        "minecraft:barrel{facing:up,open:false}",
        "minecraft:campfire{facing:west,lit:false,signal_fire:false,waterlogged:false}"
    ]
}
