{
    size: [10, 10, 10],
    data: [
        {pos: [1, 0, 4], state: "minecraft:red_sandstone"},
        {pos: [1, 0, 5], state: "minecraft:red_sandstone"},
        {pos: [1, 0, 7], state: "minecraft:red_sand"},
        {pos: [2, 0, 3], state: "minecraft:red_sandstone"},
        {pos: [2, 0, 4], state: "minecraft:red_sandstone"},
        {pos: [2, 0, 5], state: "minecraft:red_sandstone"},
        {pos: [2, 0, 6], state: "minecraft:red_sandstone"},
        {pos: [3, 0, 2], state: "minecraft:red_sand"},
        {pos: [3, 0, 3], state: "minecraft:red_sand"},
        {pos: [3, 0, 4], state: "minecraft:red_sand"},
        {pos: [3, 0, 5], state: "minecraft:red_sand"},
        {pos: [3, 0, 6], state: "minecraft:red_sandstone"},
        {pos: [3, 0, 7], state: "minecraft:red_sandstone"},
        {pos: [4, 0, 2], state: "minecraft:red_sand"},
        {pos: [4, 0, 3], state: "minecraft:red_sand"},
        {pos: [4, 0, 4], state: "minecraft:dirt_path"},
        {pos: [4, 0, 5], state: "minecraft:dirt"},
        {pos: [4, 0, 6], state: "minecraft:red_sand"},
        {pos: [4, 0, 7], state: "minecraft:red_sandstone"},
        {pos: [4, 0, 8], state: "minecraft:red_sandstone"},
        {pos: [5, 0, 1], state: "minecraft:red_sandstone"},
        {pos: [5, 0, 2], state: "minecraft:red_sand"},
        {pos: [5, 0, 3], state: "minecraft:dirt_path"},
        {pos: [5, 0, 4], state: "minecraft:dirt_path"},
        {pos: [5, 0, 5], state: "minecraft:dirt_path"},
        {pos: [5, 0, 6], state: "minecraft:dirt_path"},
        {pos: [5, 0, 7], state: "minecraft:red_sandstone"},
        {pos: [5, 0, 8], state: "minecraft:red_sandstone"},
        {pos: [5, 0, 9], state: "minecraft:red_sand"},
        {pos: [6, 0, 2], state: "minecraft:red_sand"},
        {pos: [6, 0, 3], state: "minecraft:red_sand"},
        {pos: [6, 0, 4], state: "minecraft:dirt"},
        {pos: [6, 0, 5], state: "minecraft:dirt_path"},
        {pos: [6, 0, 6], state: "minecraft:red_sand"},
        {pos: [6, 0, 7], state: "minecraft:red_sandstone"},
        {pos: [6, 0, 8], state: "minecraft:red_sandstone"},
        {pos: [6, 0, 9], state: "minecraft:red_sand"},
        {pos: [7, 0, 3], state: "minecraft:dirt_path"},
        {pos: [7, 0, 4], state: "minecraft:dirt_path"},
        {pos: [7, 0, 5], state: "minecraft:dirt_path"},
        {pos: [7, 0, 7], state: "minecraft:red_sand"},
        {pos: [7, 0, 8], state: "minecraft:red_sandstone"},
        {pos: [7, 0, 9], state: "minecraft:red_sand"},
        {pos: [8, 0, 2], state: "minecraft:dirt_path"},
        {pos: [8, 0, 3], state: "minecraft:dirt_path"},
        {pos: [8, 0, 4], state: "minecraft:dirt_path"},
        {pos: [8, 0, 7], state: "minecraft:red_sandstone"},
        {pos: [9, 0, 2], state: "minecraft:dirt_path"},
        {pos: [9, 0, 3], state: "minecraft:dirt_path"},
        {pos: [9, 0, 4], state: "minecraft:jigsaw{orientation:east_up}", nbt: {components: {}, final_state: "minecraft:dirt_path", id: "minecraft:jigsaw", joint: "rollable", name: "minecraft:end_connector", placement_priority: 0, pool: "minecraft:empty", selection_priority: 0, target: "minecraft:connector"}},
        {pos: [9, 0, 6], state: "minecraft:red_sand"},
        {pos: [1, 1, 4], state: "minecraft:red_sand"},
        {pos: [1, 1, 5], state: "minecraft:red_sand"},
        {pos: [1, 1, 7], state: "minecraft:cactus{age:0}"},
        {pos: [2, 1, 3], state: "minecraft:red_sand"},
        {pos: [2, 1, 4], state: "minecraft:red_sandstone"},
        {pos: [2, 1, 5], state: "minecraft:red_sandstone"},
        {pos: [2, 1, 6], state: "minecraft:red_sand"},
        {pos: [3, 1, 2], state: "minecraft:red_sand"},
        {pos: [3, 1, 3], state: "minecraft:red_sandstone"},
        {pos: [3, 1, 4], state: "minecraft:red_sandstone"},
        {pos: [3, 1, 5], state: "minecraft:red_sandstone"},
        {pos: [3, 1, 6], state: "minecraft:red_sandstone"},
        {pos: [3, 1, 7], state: "minecraft:red_sand"},
        {pos: [4, 1, 2], state: "minecraft:red_sandstone"},
        {pos: [4, 1, 3], state: "minecraft:red_sandstone"},
        {pos: [4, 1, 5], state: "minecraft:chest{facing:east,type:single,waterlogged:false}", nbt: {Items: [], LootTable: "minecraft:chests/abandoned_camp_common_chest", components: {}, id: "minecraft:chest"}},
        {pos: [4, 1, 6], state: "minecraft:red_sandstone"},
        {pos: [4, 1, 7], state: "minecraft:red_sandstone"},
        {pos: [4, 1, 8], state: "minecraft:red_sand"},
        {pos: [5, 1, 1], state: "minecraft:red_sandstone"},
        {pos: [5, 1, 2], state: "minecraft:red_sandstone"},
        {pos: [5, 1, 7], state: "minecraft:red_sandstone"},
        {pos: [5, 1, 8], state: "minecraft:red_sandstone"},
        {pos: [5, 1, 9], state: "minecraft:red_sand"},
        {pos: [6, 1, 2], state: "minecraft:red_sandstone"},
        {pos: [6, 1, 3], state: "minecraft:oak_fence{east:false,north:true,south:false,waterlogged:false,west:false}"},
        {pos: [6, 1, 4], state: "minecraft:campfire{facing:west,lit:false,signal_fire:false,waterlogged:false}", nbt: {CookingTimes: [I; 0, 0, 0, 0], CookingTotalTimes: [I; 0, 0, 0, 0], Items: [], components: {}, id: "minecraft:campfire"}},
        {pos: [6, 1, 6], state: "minecraft:oak_fence{east:false,north:false,south:true,waterlogged:false,west:false}"},
        {pos: [6, 1, 7], state: "minecraft:red_sandstone"},
        {pos: [6, 1, 8], state: "minecraft:red_sandstone"},
        {pos: [6, 1, 9], state: "minecraft:red_sandstone"},
        {pos: [7, 1, 7], state: "minecraft:red_sandstone"},
        {pos: [7, 1, 8], state: "minecraft:red_sandstone"},
        {pos: [7, 1, 9], state: "minecraft:red_sandstone"},
        {pos: [8, 1, 7], state: "minecraft:red_sand"},
        {pos: [9, 1, 6], state: "minecraft:cactus{age:0}"},
        {pos: [1, 2, 7], state: "minecraft:cactus{age:0}"},
        {pos: [2, 2, 3], state: "minecraft:tall_dry_grass"},
        {pos: [2, 2, 4], state: "minecraft:red_sand"},
        {pos: [2, 2, 5], state: "minecraft:red_sand"},
        {pos: [3, 2, 3], state: "minecraft:red_sand"},
        {pos: [3, 2, 4], state: "minecraft:red_sandstone"},
        {pos: [3, 2, 5], state: "minecraft:red_sandstone"},
        {pos: [3, 2, 6], state: "minecraft:red_sand"},
        {pos: [4, 2, 2], state: "minecraft:red_sandstone"},
        {pos: [4, 2, 3], state: "minecraft:red_sandstone"},
        {pos: [4, 2, 6], state: "minecraft:red_sandstone"},
        {pos: [4, 2, 7], state: "minecraft:red_sand"},
        {pos: [5, 2, 1], state: "minecraft:red_sand"},
        {pos: [5, 2, 2], state: "minecraft:red_sandstone"},
        {pos: [5, 2, 7], state: "minecraft:red_sandstone"},
        {pos: [5, 2, 8], state: "minecraft:red_sand"},
        {pos: [6, 2, 2], state: "minecraft:red_sand"},
        {pos: [6, 2, 3], state: "minecraft:oak_fence{east:false,north:true,south:false,waterlogged:false,west:false}"},
        {pos: [6, 2, 6], state: "minecraft:oak_fence{east:false,north:false,south:true,waterlogged:false,west:false}"},
        {pos: [6, 2, 7], state: "minecraft:red_sandstone"},
        {pos: [6, 2, 8], state: "minecraft:red_sandstone"},
        {pos: [7, 2, 7], state: "minecraft:red_sandstone"},
        {pos: [7, 2, 8], state: "minecraft:red_sandstone"},
        {pos: [8, 2, 7], state: "minecraft:red_sand"},
        {pos: [9, 2, 6], state: "minecraft:cactus{age:0}"},
        {pos: [1, 3, 7], state: "minecraft:cactus{age:0}"},
        {pos: [3, 3, 4], state: "minecraft:red_sand"},
        {pos: [3, 3, 5], state: "minecraft:red_sand"},
        {pos: [4, 3, 3], state: "minecraft:red_sand"},
        {pos: [4, 3, 4], state: "minecraft:red_sandstone"},
        {pos: [4, 3, 5], state: "minecraft:red_sandstone"},
        {pos: [4, 3, 6], state: "minecraft:red_sand"},
        {pos: [5, 3, 3], state: "minecraft:red_sandstone"},
        {pos: [5, 3, 4], state: "minecraft:red_sandstone"},
        {pos: [5, 3, 5], state: "minecraft:red_sandstone"},
        {pos: [5, 3, 6], state: "minecraft:red_sandstone"},
        {pos: [5, 3, 8], state: "minecraft:short_dry_grass"},
        {pos: [6, 3, 2], state: "minecraft:tall_dry_grass"},
        {pos: [6, 3, 4], state: "minecraft:red_sandstone"},
        {pos: [6, 3, 5], state: "minecraft:red_sandstone"},
        {pos: [6, 3, 6], state: "minecraft:red_sandstone"},
        {pos: [7, 3, 6], state: "minecraft:red_sandstone"},
        {pos: [9, 3, 6], state: "minecraft:cactus{age:0}"},
        {pos: [1, 4, 7], state: "minecraft:cactus_flower"},
        {pos: [3, 4, 5], state: "minecraft:cactus{age:0}"},
        {pos: [4, 4, 6], state: "minecraft:short_dry_grass"},
        {pos: [5, 4, 4], state: "minecraft:red_sand"},
        {pos: [5, 4, 5], state: "minecraft:red_sand"},
        {pos: [6, 4, 5], state: "minecraft:red_sand"},
        {pos: [9, 4, 6], state: "minecraft:cactus_flower"},
        {pos: [3, 5, 5], state: "minecraft:cactus{age:0}"},
        {pos: [5, 5, 4], state: "minecraft:tall_dry_grass"},
        {pos: [6, 5, 5], state: "minecraft:short_dry_grass"},
        {pos: [3, 6, 5], state: "minecraft:cactus_flower"}
    ],
    entities: [
        {blockPos: [5, 0, 5], pos: [5.5d, 0.9375d, 5.5d], nbt: {Air: 300s, Fire: 0s, Invulnerable: 0b, Motion: [0.0d, 0.0d, 0.0d], OnGround: 0b, PortalCooldown: 0, Pos: [-88.5d, -60.0625d, 557.5d], Rotation: [90.0f, 0.0f], UUID: [I; -1931171657, 1383156794, -1463765142, -1486771460], block_pos: [I; -89, -61, 557], color: "brown", fall_distance: 0.0d, id: "minecraft:cushion"}}
    ],
    palette: [
        "minecraft:red_sandstone",
        "minecraft:red_sand",
        "minecraft:dirt",
        "minecraft:dirt_path",
        "minecraft:cactus{age:0}",
        "minecraft:oak_fence{east:false,north:true,south:false,waterlogged:false,west:false}",
        "minecraft:oak_fence{east:false,north:false,south:true,waterlogged:false,west:false}",
        "minecraft:tall_dry_grass",
        "minecraft:short_dry_grass",
        "minecraft:cactus_flower",
        "minecraft:jigsaw{orientation:east_up}",
        "minecraft:chest{facing:east,type:single,waterlogged:false}",
        "minecraft:campfire{facing:west,lit:false,signal_fire:false,waterlogged:false}"
    ]
}
