{
    size: [7, 11, 7],
    data: [
        {pos: [0, 0, 0], state: "minecraft:waxed_oxidized_cut_copper"},
        {pos: [0, 0, 1], state: "minecraft:waxed_oxidized_cut_copper"},
        {pos: [0, 0, 2], state: "minecraft:waxed_oxidized_cut_copper"},
        {pos: [0, 0, 3], state: "minecraft:waxed_oxidized_cut_copper"},
        {pos: [0, 0, 4], state: "minecraft:waxed_oxidized_cut_copper"},
        {pos: [0, 0, 5], state: "minecraft:waxed_oxidized_cut_copper"},
        {pos: [0, 0, 6], state: "minecraft:waxed_oxidized_cut_copper"},
        {pos: [1, 0, 0], state: "minecraft:waxed_oxidized_cut_copper"},
        {pos: [1, 0, 1], state: "minecraft:tuff_bricks"},
        {pos: [1, 0, 2], state: "minecraft:tuff_bricks"},
        {pos: [1, 0, 3], state: "minecraft:tuff_bricks"},
        {pos: [1, 0, 4], state: "minecraft:tuff_bricks"},
        {pos: [1, 0, 5], state: "minecraft:tuff_bricks"},
        {pos: [1, 0, 6], state: "minecraft:waxed_oxidized_cut_copper"},
        {pos: [2, 0, 0], state: "minecraft:waxed_oxidized_cut_copper"},
        {pos: [2, 0, 1], state: "minecraft:tuff_bricks"},
        {pos: [2, 0, 2], state: "minecraft:tuff_bricks"},
        {pos: [2, 0, 3], state: "minecraft:tuff_bricks"},
        {pos: [2, 0, 4], state: "minecraft:tuff_bricks"},
        {pos: [2, 0, 5], state: "minecraft:tuff_bricks"},
        {pos: [2, 0, 6], state: "minecraft:waxed_oxidized_cut_copper"},
        {pos: [3, 0, 0], state: "minecraft:waxed_oxidized_cut_copper"},
        {pos: [3, 0, 1], state: "minecraft:tuff_bricks"},
        {pos: [3, 0, 2], state: "minecraft:tuff_bricks"},
        {pos: [3, 0, 3], state: "minecraft:jigsaw{orientation:down_west}", nbt: {final_state: "minecraft:tuff_bricks", id: "minecraft:jigsaw", joint: "rollable", name: "minecraft:c6_addon", placement_priority: 0, pool: "minecraft:empty", selection_priority: 0, target: "minecraft:empty"}},
        {pos: [3, 0, 4], state: "minecraft:tuff_bricks"},
        {pos: [3, 0, 5], state: "minecraft:tuff_bricks"},
        {pos: [3, 0, 6], state: "minecraft:waxed_oxidized_cut_copper"},
        {pos: [4, 0, 0], state: "minecraft:waxed_oxidized_cut_copper"},
        {pos: [4, 0, 1], state: "minecraft:tuff_bricks"},
        {pos: [4, 0, 2], state: "minecraft:tuff_bricks"},
        {pos: [4, 0, 3], state: "minecraft:tuff_bricks"},
        {pos: [4, 0, 4], state: "minecraft:tuff_bricks"},
        {pos: [4, 0, 5], state: "minecraft:tuff_bricks"},
        {pos: [4, 0, 6], state: "minecraft:waxed_oxidized_cut_copper"},
        {pos: [5, 0, 0], state: "minecraft:waxed_oxidized_cut_copper"},
        {pos: [5, 0, 1], state: "minecraft:tuff_bricks"},
        {pos: [5, 0, 2], state: "minecraft:tuff_bricks"},
        {pos: [5, 0, 3], state: "minecraft:tuff_bricks"},
        {pos: [5, 0, 4], state: "minecraft:tuff_bricks"},
        {pos: [5, 0, 5], state: "minecraft:tuff_bricks"},
        {pos: [5, 0, 6], state: "minecraft:waxed_oxidized_cut_copper"},
        {pos: [6, 0, 0], state: "minecraft:waxed_oxidized_cut_copper"},
        {pos: [6, 0, 1], state: "minecraft:waxed_oxidized_cut_copper"},
        {pos: [6, 0, 2], state: "minecraft:waxed_oxidized_cut_copper"},
        {pos: [6, 0, 3], state: "minecraft:waxed_oxidized_cut_copper"},
        {pos: [6, 0, 4], state: "minecraft:waxed_oxidized_cut_copper"},
        {pos: [6, 0, 5], state: "minecraft:waxed_oxidized_cut_copper"},
        {pos: [6, 0, 6], state: "minecraft:waxed_oxidized_cut_copper"},
        {pos: [1, 1, 1], state: "minecraft:waxed_copper_block"},
        {pos: [1, 1, 2], state: "minecraft:waxed_copper_block"},
        {pos: [1, 1, 3], state: "minecraft:waxed_copper_block"},
        {pos: [1, 1, 4], state: "minecraft:waxed_copper_block"},
        {pos: [1, 1, 5], state: "minecraft:waxed_copper_block"},
        {pos: [2, 1, 1], state: "minecraft:waxed_copper_block"},
        {pos: [2, 1, 2], state: "minecraft:tuff_bricks"},
        {pos: [2, 1, 3], state: "minecraft:tuff_bricks"},
        {pos: [2, 1, 4], state: "minecraft:tuff_bricks"},
        {pos: [2, 1, 5], state: "minecraft:waxed_copper_block"},
        {pos: [3, 1, 1], state: "minecraft:waxed_copper_block"},
        {pos: [3, 1, 2], state: "minecraft:tuff_bricks"},
        {pos: [3, 1, 3], state: "minecraft:tuff_bricks"},
        {pos: [3, 1, 4], state: "minecraft:tuff_bricks"},
        {pos: [3, 1, 5], state: "minecraft:waxed_copper_block"},
        {pos: [4, 1, 1], state: "minecraft:waxed_copper_block"},
        {pos: [4, 1, 2], state: "minecraft:tuff_bricks"},
        {pos: [4, 1, 3], state: "minecraft:tuff_bricks"},
        {pos: [4, 1, 4], state: "minecraft:tuff_bricks"},
        {pos: [4, 1, 5], state: "minecraft:waxed_copper_block"},
        {pos: [5, 1, 1], state: "minecraft:waxed_copper_block"},
        {pos: [5, 1, 2], state: "minecraft:waxed_copper_block"},
        {pos: [5, 1, 3], state: "minecraft:waxed_copper_block"},
        {pos: [5, 1, 4], state: "minecraft:waxed_copper_block"},
        {pos: [5, 1, 5], state: "minecraft:waxed_copper_block"},
        {pos: [1, 2, 1], state: "minecraft:tuff_bricks"},
        {pos: [1, 2, 2], state: "minecraft:tuff_bricks"},
        {pos: [1, 2, 3], state: "minecraft:waxed_copper_bulb{lit:true,powered:false}"},
        {pos: [1, 2, 4], state: "minecraft:tuff_bricks"},
        {pos: [1, 2, 5], state: "minecraft:tuff_bricks"},
        {pos: [2, 2, 1], state: "minecraft:tuff_bricks"},
        {pos: [2, 2, 2], state: "minecraft:tuff_bricks"},
        {pos: [2, 2, 3], state: "minecraft:tuff_bricks"},
        {pos: [2, 2, 4], state: "minecraft:tuff_bricks"},
        {pos: [2, 2, 5], state: "minecraft:tuff_bricks"},
        {pos: [3, 2, 1], state: "minecraft:waxed_copper_bulb{lit:true,powered:false}"},
        {pos: [3, 2, 2], state: "minecraft:tuff_bricks"},
        {pos: [3, 2, 3], state: "minecraft:tuff_bricks"},
        {pos: [3, 2, 4], state: "minecraft:tuff_bricks"},
        {pos: [3, 2, 5], state: "minecraft:waxed_copper_bulb{lit:true,powered:false}"},
        {pos: [4, 2, 1], state: "minecraft:tuff_bricks"},
        {pos: [4, 2, 2], state: "minecraft:tuff_bricks"},
        {pos: [4, 2, 3], state: "minecraft:tuff_bricks"},
        {pos: [4, 2, 4], state: "minecraft:tuff_bricks"},
        {pos: [4, 2, 5], state: "minecraft:tuff_bricks"},
        {pos: [5, 2, 1], state: "minecraft:tuff_bricks"},
        {pos: [5, 2, 2], state: "minecraft:tuff_bricks"},
        {pos: [5, 2, 3], state: "minecraft:waxed_copper_bulb{lit:true,powered:false}"},
        {pos: [5, 2, 4], state: "minecraft:tuff_bricks"},
        {pos: [5, 2, 5], state: "minecraft:tuff_bricks"},
        {pos: [1, 3, 1], state: "minecraft:chiseled_tuff_bricks"},
        {pos: [1, 3, 2], state: "minecraft:chiseled_tuff_bricks"},
        {pos: [1, 3, 3], state: "minecraft:chiseled_tuff_bricks"},
        {pos: [1, 3, 4], state: "minecraft:chiseled_tuff_bricks"},
        {pos: [1, 3, 5], state: "minecraft:chiseled_tuff_bricks"},
        {pos: [2, 3, 1], state: "minecraft:chiseled_tuff_bricks"},
        {pos: [2, 3, 2], state: "minecraft:tuff_bricks"},
        {pos: [2, 3, 3], state: "minecraft:tuff_bricks"},
        {pos: [2, 3, 4], state: "minecraft:tuff_bricks"},
        {pos: [2, 3, 5], state: "minecraft:chiseled_tuff_bricks"},
        {pos: [3, 3, 1], state: "minecraft:chiseled_tuff_bricks"},
        {pos: [3, 3, 2], state: "minecraft:tuff_bricks"},
        {pos: [3, 3, 3], state: "minecraft:tuff_bricks"},
        {pos: [3, 3, 4], state: "minecraft:tuff_bricks"},
        {pos: [3, 3, 5], state: "minecraft:chiseled_tuff_bricks"},
        {pos: [4, 3, 1], state: "minecraft:chiseled_tuff_bricks"},
        {pos: [4, 3, 2], state: "minecraft:tuff_bricks"},
        {pos: [4, 3, 3], state: "minecraft:tuff_bricks"},
        {pos: [4, 3, 4], state: "minecraft:tuff_bricks"},
        {pos: [4, 3, 5], state: "minecraft:chiseled_tuff_bricks"},
        {pos: [5, 3, 1], state: "minecraft:chiseled_tuff_bricks"},
        {pos: [5, 3, 2], state: "minecraft:chiseled_tuff_bricks"},
        {pos: [5, 3, 3], state: "minecraft:chiseled_tuff_bricks"},
        {pos: [5, 3, 4], state: "minecraft:chiseled_tuff_bricks"},
        {pos: [5, 3, 5], state: "minecraft:chiseled_tuff_bricks"},
        {pos: [1, 4, 1], state: "minecraft:tuff_bricks"},
        {pos: [1, 4, 2], state: "minecraft:jigsaw{orientation:down_west}", nbt: {final_state: "minecraft:tuff_bricks", id: "minecraft:jigsaw", joint: "aligned", name: "minecraft:empty", placement_priority: 0, pool: "minecraft:trial_chambers/dispensers/chamber", selection_priority: 0, target: "minecraft:dispenser"}},
        {pos: [1, 4, 3], state: "minecraft:tuff_bricks"},
        {pos: [1, 4, 4], state: "minecraft:tuff_bricks"},
        {pos: [1, 4, 5], state: "minecraft:tuff_bricks"},
        {pos: [2, 4, 1], state: "minecraft:tuff_bricks"},
        {pos: [2, 4, 2], state: "minecraft:tuff_bricks"},
        {pos: [2, 4, 3], state: "minecraft:tuff_bricks"},
        {pos: [2, 4, 4], state: "minecraft:tuff_bricks"},
        {pos: [2, 4, 5], state: "minecraft:jigsaw{orientation:down_south}", nbt: {final_state: "minecraft:tuff_bricks", id: "minecraft:jigsaw", joint: "aligned", name: "minecraft:empty", placement_priority: 0, pool: "minecraft:trial_chambers/dispensers/chamber", selection_priority: 0, target: "minecraft:dispenser"}},
        {pos: [3, 4, 1], state: "minecraft:tuff_bricks"},
        {pos: [3, 4, 2], state: "minecraft:tuff_bricks"},
        {pos: [3, 4, 3], state: "minecraft:tuff_bricks"},
        {pos: [3, 4, 4], state: "minecraft:tuff_bricks"},
        {pos: [3, 4, 5], state: "minecraft:tuff_bricks"},
        {pos: [4, 4, 1], state: "minecraft:jigsaw{orientation:down_north}", nbt: {final_state: "minecraft:tuff_bricks", id: "minecraft:jigsaw", joint: "aligned", name: "minecraft:empty", placement_priority: 0, pool: "minecraft:trial_chambers/dispensers/chamber", selection_priority: 0, target: "minecraft:dispenser"}},
        {pos: [4, 4, 2], state: "minecraft:tuff_bricks"},
        {pos: [4, 4, 3], state: "minecraft:tuff_bricks"},
        {pos: [4, 4, 4], state: "minecraft:tuff_bricks"},
        {pos: [4, 4, 5], state: "minecraft:tuff_bricks"},
        {pos: [5, 4, 1], state: "minecraft:tuff_bricks"},
        {pos: [5, 4, 2], state: "minecraft:tuff_bricks"},
        {pos: [5, 4, 3], state: "minecraft:tuff_bricks"},
        {pos: [5, 4, 4], state: "minecraft:jigsaw{orientation:down_east}", nbt: {final_state: "minecraft:tuff_bricks", id: "minecraft:jigsaw", joint: "aligned", name: "minecraft:empty", placement_priority: 0, pool: "minecraft:trial_chambers/dispensers/chamber", selection_priority: 0, target: "minecraft:dispenser"}},
        {pos: [5, 4, 5], state: "minecraft:tuff_bricks"},
        {pos: [1, 5, 1], state: "minecraft:tuff_bricks"},
        {pos: [1, 5, 2], state: "minecraft:tuff_bricks"},
        {pos: [1, 5, 3], state: "minecraft:tuff_bricks"},
        {pos: [1, 5, 4], state: "minecraft:tuff_bricks"},
        {pos: [1, 5, 5], state: "minecraft:tuff_bricks"},
        {pos: [2, 5, 1], state: "minecraft:tuff_bricks"},
        {pos: [2, 5, 2], state: "minecraft:tuff_bricks"},
        {pos: [2, 5, 3], state: "minecraft:tuff_bricks"},
        {pos: [2, 5, 4], state: "minecraft:tuff_bricks"},
        {pos: [2, 5, 5], state: "minecraft:tuff_bricks"},
        {pos: [3, 5, 1], state: "minecraft:tuff_bricks"},
        {pos: [3, 5, 2], state: "minecraft:tuff_bricks"},
        {pos: [3, 5, 3], state: "minecraft:tuff_bricks"},
        {pos: [3, 5, 4], state: "minecraft:tuff_bricks"},
        {pos: [3, 5, 5], state: "minecraft:tuff_bricks"},
        {pos: [4, 5, 1], state: "minecraft:tuff_bricks"},
        {pos: [4, 5, 2], state: "minecraft:tuff_bricks"},
        {pos: [4, 5, 3], state: "minecraft:tuff_bricks"},
        {pos: [4, 5, 4], state: "minecraft:tuff_bricks"},
        {pos: [4, 5, 5], state: "minecraft:tuff_bricks"},
        {pos: [5, 5, 1], state: "minecraft:tuff_bricks"},
        {pos: [5, 5, 2], state: "minecraft:tuff_bricks"},
        {pos: [5, 5, 3], state: "minecraft:tuff_bricks"},
        {pos: [5, 5, 4], state: "minecraft:tuff_bricks"},
        {pos: [5, 5, 5], state: "minecraft:tuff_bricks"},
        {pos: [1, 6, 1], state: "minecraft:waxed_copper_block"},
        {pos: [1, 6, 2], state: "minecraft:waxed_copper_block"},
        {pos: [1, 6, 3], state: "minecraft:waxed_copper_block"},
        {pos: [1, 6, 4], state: "minecraft:waxed_copper_block"},
        {pos: [1, 6, 5], state: "minecraft:waxed_copper_block"},
        {pos: [2, 6, 1], state: "minecraft:waxed_copper_block"},
        {pos: [2, 6, 2], state: "minecraft:tuff_bricks"},
        {pos: [2, 6, 3], state: "minecraft:tuff_bricks"},
        {pos: [2, 6, 4], state: "minecraft:tuff_bricks"},
        {pos: [2, 6, 5], state: "minecraft:waxed_copper_block"},
        {pos: [3, 6, 1], state: "minecraft:waxed_copper_block"},
        {pos: [3, 6, 2], state: "minecraft:tuff_bricks"},
        {pos: [3, 6, 3], state: "minecraft:tuff_bricks"},
        {pos: [3, 6, 4], state: "minecraft:tuff_bricks"},
        {pos: [3, 6, 5], state: "minecraft:waxed_copper_block"},
        {pos: [4, 6, 1], state: "minecraft:waxed_copper_block"},
        {pos: [4, 6, 2], state: "minecraft:tuff_bricks"},
        {pos: [4, 6, 3], state: "minecraft:tuff_bricks"},
        {pos: [4, 6, 4], state: "minecraft:tuff_bricks"},
        {pos: [4, 6, 5], state: "minecraft:waxed_copper_block"},
        {pos: [5, 6, 1], state: "minecraft:waxed_copper_block"},
        {pos: [5, 6, 2], state: "minecraft:waxed_copper_block"},
        {pos: [5, 6, 3], state: "minecraft:waxed_copper_block"},
        {pos: [5, 6, 4], state: "minecraft:waxed_copper_block"},
        {pos: [5, 6, 5], state: "minecraft:waxed_copper_block"},
        {pos: [1, 7, 1], state: "minecraft:tuff_bricks"},
        {pos: [1, 7, 2], state: "minecraft:tuff_bricks"},
        {pos: [1, 7, 3], state: "minecraft:tuff_bricks"},
        {pos: [1, 7, 4], state: "minecraft:tuff_bricks"},
        {pos: [1, 7, 5], state: "minecraft:tuff_bricks"},
        {pos: [2, 7, 1], state: "minecraft:tuff_bricks"},
        {pos: [2, 7, 2], state: "minecraft:tuff_bricks"},
        {pos: [2, 7, 3], state: "minecraft:tuff_bricks"},
        {pos: [2, 7, 4], state: "minecraft:tuff_bricks"},
        {pos: [2, 7, 5], state: "minecraft:tuff_bricks"},
        {pos: [3, 7, 1], state: "minecraft:tuff_bricks"},
        {pos: [3, 7, 2], state: "minecraft:tuff_bricks"},
        {pos: [3, 7, 3], state: "minecraft:tuff_bricks"},
        {pos: [3, 7, 4], state: "minecraft:tuff_bricks"},
        {pos: [3, 7, 5], state: "minecraft:tuff_bricks"},
        {pos: [4, 7, 1], state: "minecraft:tuff_bricks"},
        {pos: [4, 7, 2], state: "minecraft:tuff_bricks"},
        {pos: [4, 7, 3], state: "minecraft:tuff_bricks"},
        {pos: [4, 7, 4], state: "minecraft:tuff_bricks"},
        {pos: [4, 7, 5], state: "minecraft:tuff_bricks"},
        {pos: [5, 7, 1], state: "minecraft:tuff_bricks"},
        {pos: [5, 7, 2], state: "minecraft:tuff_bricks"},
        {pos: [5, 7, 3], state: "minecraft:tuff_bricks"},
        {pos: [5, 7, 4], state: "minecraft:tuff_bricks"},
        {pos: [5, 7, 5], state: "minecraft:tuff_bricks"},
        {pos: [1, 8, 1], state: "minecraft:chiseled_tuff_bricks"},
        {pos: [1, 8, 2], state: "minecraft:chiseled_tuff_bricks"},
        {pos: [1, 8, 3], state: "minecraft:chiseled_tuff_bricks"},
        {pos: [1, 8, 4], state: "minecraft:chiseled_tuff_bricks"},
        {pos: [1, 8, 5], state: "minecraft:chiseled_tuff_bricks"},
        {pos: [2, 8, 1], state: "minecraft:chiseled_tuff_bricks"},
        {pos: [2, 8, 2], state: "minecraft:tuff_bricks"},
        {pos: [2, 8, 3], state: "minecraft:tuff_bricks"},
        {pos: [2, 8, 4], state: "minecraft:tuff_bricks"},
        {pos: [2, 8, 5], state: "minecraft:chiseled_tuff_bricks"},
        {pos: [3, 8, 1], state: "minecraft:chiseled_tuff_bricks"},
        {pos: [3, 8, 2], state: "minecraft:tuff_bricks"},
        {pos: [3, 8, 3], state: "minecraft:tuff_bricks"},
        {pos: [3, 8, 4], state: "minecraft:tuff_bricks"},
        {pos: [3, 8, 5], state: "minecraft:chiseled_tuff_bricks"},
        {pos: [4, 8, 1], state: "minecraft:chiseled_tuff_bricks"},
        {pos: [4, 8, 2], state: "minecraft:tuff_bricks"},
        {pos: [4, 8, 3], state: "minecraft:tuff_bricks"},
        {pos: [4, 8, 4], state: "minecraft:tuff_bricks"},
        {pos: [4, 8, 5], state: "minecraft:chiseled_tuff_bricks"},
        {pos: [5, 8, 1], state: "minecraft:chiseled_tuff_bricks"},
        {pos: [5, 8, 2], state: "minecraft:chiseled_tuff_bricks"},
        {pos: [5, 8, 3], state: "minecraft:chiseled_tuff_bricks"},
        {pos: [5, 8, 4], state: "minecraft:chiseled_tuff_bricks"},
        {pos: [5, 8, 5], state: "minecraft:chiseled_tuff_bricks"},
        {pos: [1, 9, 1], state: "minecraft:tuff_bricks"},
        {pos: [1, 9, 2], state: "minecraft:tuff_bricks"},
        {pos: [1, 9, 3], state: "minecraft:tuff_bricks"},
        {pos: [1, 9, 4], state: "minecraft:tuff_bricks"},
        {pos: [1, 9, 5], state: "minecraft:tuff_bricks"},
        {pos: [2, 9, 1], state: "minecraft:tuff_bricks"},
        {pos: [2, 9, 2], state: "minecraft:tuff_bricks"},
        {pos: [2, 9, 3], state: "minecraft:tuff_bricks"},
        {pos: [2, 9, 4], state: "minecraft:tuff_bricks"},
        {pos: [2, 9, 5], state: "minecraft:tuff_bricks"},
        {pos: [3, 9, 1], state: "minecraft:tuff_bricks"},
        {pos: [3, 9, 2], state: "minecraft:tuff_bricks"},
        {pos: [3, 9, 3], state: "minecraft:tuff_bricks"},
        {pos: [3, 9, 4], state: "minecraft:tuff_bricks"},
        {pos: [3, 9, 5], state: "minecraft:tuff_bricks"},
        {pos: [4, 9, 1], state: "minecraft:tuff_bricks"},
        {pos: [4, 9, 2], state: "minecraft:tuff_bricks"},
        {pos: [4, 9, 3], state: "minecraft:tuff_bricks"},
        {pos: [4, 9, 4], state: "minecraft:tuff_bricks"},
        {pos: [4, 9, 5], state: "minecraft:tuff_bricks"},
        {pos: [5, 9, 1], state: "minecraft:tuff_bricks"},
        {pos: [5, 9, 2], state: "minecraft:tuff_bricks"},
        {pos: [5, 9, 3], state: "minecraft:tuff_bricks"},
        {pos: [5, 9, 4], state: "minecraft:tuff_bricks"},
        {pos: [5, 9, 5], state: "minecraft:tuff_bricks"},
        {pos: [1, 10, 1], state: "minecraft:waxed_copper_block"},
        {pos: [1, 10, 2], state: "minecraft:waxed_copper_block"},
        {pos: [1, 10, 3], state: "minecraft:waxed_copper_block"},
        {pos: [1, 10, 4], state: "minecraft:waxed_copper_block"},
        {pos: [1, 10, 5], state: "minecraft:waxed_copper_block"},
        {pos: [2, 10, 1], state: "minecraft:waxed_copper_block"},
        {pos: [2, 10, 2], state: "minecraft:waxed_oxidized_copper"},
        {pos: [2, 10, 3], state: "minecraft:waxed_oxidized_copper"},
        {pos: [2, 10, 4], state: "minecraft:waxed_oxidized_copper"},
        {pos: [2, 10, 5], state: "minecraft:waxed_copper_block"},
        {pos: [3, 10, 1], state: "minecraft:waxed_copper_block"},
        {pos: [3, 10, 2], state: "minecraft:waxed_oxidized_copper"},
        {pos: [3, 10, 3], state: "minecraft:waxed_oxidized_copper"},
        {pos: [3, 10, 4], state: "minecraft:waxed_oxidized_copper"},
        {pos: [3, 10, 5], state: "minecraft:waxed_copper_block"},
        {pos: [4, 10, 1], state: "minecraft:waxed_copper_block"},
        {pos: [4, 10, 2], state: "minecraft:waxed_oxidized_copper"},
        {pos: [4, 10, 3], state: "minecraft:waxed_oxidized_copper"},
        {pos: [4, 10, 4], state: "minecraft:waxed_oxidized_copper"},
        {pos: [4, 10, 5], state: "minecraft:waxed_copper_block"},
        {pos: [5, 10, 1], state: "minecraft:waxed_copper_block"},
        {pos: [5, 10, 2], state: "minecraft:waxed_copper_block"},
        {pos: [5, 10, 3], state: "minecraft:waxed_copper_block"},
        {pos: [5, 10, 4], state: "minecraft:waxed_copper_block"},
        {pos: [5, 10, 5], state: "minecraft:waxed_copper_block"}
    ],
    entities: [],
    palette: [
        "minecraft:waxed_oxidized_cut_copper",
        "minecraft:tuff_bricks",
        "minecraft:waxed_copper_block",
        "minecraft:waxed_copper_bulb{lit:true,powered:false}",
        "minecraft:chiseled_tuff_bricks",
        "minecraft:waxed_oxidized_copper",
        "minecraft:jigsaw{orientation:down_west}",
        "minecraft:jigsaw{orientation:down_south}",
        "minecraft:jigsaw{orientation:down_north}",
        "minecraft:jigsaw{orientation:down_east}"
    ]
}
