{
    size: [6, 6, 26],
    data: [
        {pos: [0, 0, 1], state: "minecraft:tuff_bricks"},
        {pos: [0, 0, 2], state: "minecraft:tuff_bricks"},
        {pos: [0, 0, 3], state: "minecraft:tuff_bricks"},
        {pos: [0, 0, 6], state: "minecraft:tuff_bricks"},
        {pos: [0, 0, 7], state: "minecraft:tuff_bricks"},
        {pos: [0, 0, 8], state: "minecraft:tuff_bricks"},
        {pos: [0, 0, 11], state: "minecraft:tuff_bricks"},
        {pos: [0, 0, 12], state: "minecraft:tuff_bricks"},
        {pos: [0, 0, 13], state: "minecraft:tuff_bricks"},
        {pos: [0, 0, 16], state: "minecraft:tuff_bricks"},
        {pos: [0, 0, 17], state: "minecraft:tuff_bricks"},
        {pos: [0, 0, 18], state: "minecraft:tuff_bricks"},
        {pos: [0, 0, 21], state: "minecraft:tuff_bricks"},
        {pos: [0, 0, 22], state: "minecraft:tuff_bricks"},
        {pos: [0, 0, 23], state: "minecraft:tuff_bricks"},
        {pos: [0, 0, 25], state: "minecraft:waxed_oxidized_cut_copper"},
        {pos: [1, 0, 0], state: "minecraft:tuff_bricks"},
        {pos: [1, 0, 1], state: "minecraft:tuff_bricks"},
        {pos: [1, 0, 2], state: "minecraft:tuff_bricks"},
        {pos: [1, 0, 3], state: "minecraft:tuff_bricks"},
        {pos: [1, 0, 4], state: "minecraft:tuff_bricks"},
        {pos: [1, 0, 5], state: "minecraft:tuff_bricks"},
        {pos: [1, 0, 6], state: "minecraft:tuff_bricks"},
        {pos: [1, 0, 7], state: "minecraft:tuff_bricks"},
        {pos: [1, 0, 8], state: "minecraft:tuff_bricks"},
        {pos: [1, 0, 9], state: "minecraft:tuff_bricks"},
        {pos: [1, 0, 10], state: "minecraft:tuff_bricks"},
        {pos: [1, 0, 11], state: "minecraft:tuff_bricks"},
        {pos: [1, 0, 12], state: "minecraft:tuff_bricks"},
        {pos: [1, 0, 13], state: "minecraft:tuff_bricks"},
        {pos: [1, 0, 14], state: "minecraft:tuff_bricks"},
        {pos: [1, 0, 15], state: "minecraft:tuff_bricks"},
        {pos: [1, 0, 16], state: "minecraft:tuff_bricks"},
        {pos: [1, 0, 17], state: "minecraft:tuff_bricks"},
        {pos: [1, 0, 18], state: "minecraft:tuff_bricks"},
        {pos: [1, 0, 19], state: "minecraft:tuff_bricks"},
        {pos: [1, 0, 20], state: "minecraft:tuff_bricks"},
        {pos: [1, 0, 21], state: "minecraft:tuff_bricks"},
        {pos: [1, 0, 22], state: "minecraft:tuff_bricks"},
        {pos: [1, 0, 23], state: "minecraft:tuff_bricks"},
        {pos: [1, 0, 24], state: "minecraft:tuff_bricks"},
        {pos: [1, 0, 25], state: "minecraft:waxed_oxidized_cut_copper"},
        {pos: [2, 0, 0], state: "minecraft:tuff_bricks"},
        {pos: [2, 0, 1], state: "minecraft:tuff_bricks"},
        {pos: [2, 0, 2], state: "minecraft:tuff_bricks"},
        {pos: [2, 0, 3], state: "minecraft:tuff_bricks"},
        {pos: [2, 0, 4], state: "minecraft:tuff_bricks"},
        {pos: [2, 0, 5], state: "minecraft:tuff_bricks"},
        {pos: [2, 0, 6], state: "minecraft:tuff_bricks"},
        {pos: [2, 0, 7], state: "minecraft:tuff_bricks"},
        {pos: [2, 0, 8], state: "minecraft:tuff_bricks"},
        {pos: [2, 0, 9], state: "minecraft:tuff_bricks"},
        {pos: [2, 0, 10], state: "minecraft:tuff_bricks"},
        {pos: [2, 0, 11], state: "minecraft:tuff_bricks"},
        {pos: [2, 0, 12], state: "minecraft:tuff_bricks"},
        {pos: [2, 0, 13], state: "minecraft:tuff_bricks"},
        {pos: [2, 0, 14], state: "minecraft:tuff_bricks"},
        {pos: [2, 0, 15], state: "minecraft:tuff_bricks"},
        {pos: [2, 0, 16], state: "minecraft:tuff_bricks"},
        {pos: [2, 0, 17], state: "minecraft:tuff_bricks"},
        {pos: [2, 0, 18], state: "minecraft:tuff_bricks"},
        {pos: [2, 0, 19], state: "minecraft:tuff_bricks"},
        {pos: [2, 0, 20], state: "minecraft:tuff_bricks"},
        {pos: [2, 0, 21], state: "minecraft:tuff_bricks"},
        {pos: [2, 0, 22], state: "minecraft:jigsaw{orientation:down_east}", nbt: {final_state: "minecraft:tuff_bricks", id: "minecraft:jigsaw", joint: "aligned", name: "minecraft:wide_platform", placement_priority: 0, pool: "minecraft:empty", selection_priority: 0, target: "minecraft:empty"}},
        {pos: [2, 0, 23], state: "minecraft:tuff_bricks"},
        {pos: [2, 0, 24], state: "minecraft:tuff_bricks"},
        {pos: [2, 0, 25], state: "minecraft:waxed_oxidized_cut_copper"},
        {pos: [3, 0, 0], state: "minecraft:tuff_bricks"},
        {pos: [3, 0, 1], state: "minecraft:tuff_bricks"},
        {pos: [3, 0, 2], state: "minecraft:tuff_bricks"},
        {pos: [3, 0, 3], state: "minecraft:tuff_bricks"},
        {pos: [3, 0, 4], state: "minecraft:tuff_bricks"},
        {pos: [3, 0, 5], state: "minecraft:tuff_bricks"},
        {pos: [3, 0, 6], state: "minecraft:tuff_bricks"},
        {pos: [3, 0, 7], state: "minecraft:tuff_bricks"},
        {pos: [3, 0, 8], state: "minecraft:tuff_bricks"},
        {pos: [3, 0, 9], state: "minecraft:tuff_bricks"},
        {pos: [3, 0, 10], state: "minecraft:tuff_bricks"},
        {pos: [3, 0, 11], state: "minecraft:tuff_bricks"},
        {pos: [3, 0, 12], state: "minecraft:tuff_bricks"},
        {pos: [3, 0, 13], state: "minecraft:tuff_bricks"},
        {pos: [3, 0, 14], state: "minecraft:tuff_bricks"},
        {pos: [3, 0, 15], state: "minecraft:tuff_bricks"},
        {pos: [3, 0, 16], state: "minecraft:tuff_bricks"},
        {pos: [3, 0, 17], state: "minecraft:tuff_bricks"},
        {pos: [3, 0, 18], state: "minecraft:tuff_bricks"},
        {pos: [3, 0, 19], state: "minecraft:tuff_bricks"},
        {pos: [3, 0, 20], state: "minecraft:tuff_bricks"},
        {pos: [3, 0, 21], state: "minecraft:tuff_bricks"},
        {pos: [3, 0, 22], state: "minecraft:tuff_bricks"},
        {pos: [3, 0, 23], state: "minecraft:tuff_bricks"},
        {pos: [3, 0, 24], state: "minecraft:tuff_bricks"},
        {pos: [3, 0, 25], state: "minecraft:waxed_oxidized_cut_copper"},
        {pos: [4, 0, 1], state: "minecraft:tuff_bricks"},
        {pos: [4, 0, 2], state: "minecraft:tuff_bricks"},
        {pos: [4, 0, 3], state: "minecraft:tuff_bricks"},
        {pos: [4, 0, 4], state: "minecraft:tuff_bricks"},
        {pos: [4, 0, 5], state: "minecraft:tuff_bricks"},
        {pos: [4, 0, 6], state: "minecraft:tuff_bricks"},
        {pos: [4, 0, 7], state: "minecraft:tuff_bricks"},
        {pos: [4, 0, 8], state: "minecraft:tuff_bricks"},
        {pos: [4, 0, 9], state: "minecraft:tuff_bricks"},
        {pos: [4, 0, 10], state: "minecraft:tuff_bricks"},
        {pos: [4, 0, 11], state: "minecraft:tuff_bricks"},
        {pos: [4, 0, 12], state: "minecraft:tuff_bricks"},
        {pos: [4, 0, 13], state: "minecraft:tuff_bricks"},
        {pos: [4, 0, 14], state: "minecraft:tuff_bricks"},
        {pos: [4, 0, 15], state: "minecraft:tuff_bricks"},
        {pos: [4, 0, 16], state: "minecraft:tuff_bricks"},
        {pos: [4, 0, 17], state: "minecraft:tuff_bricks"},
        {pos: [4, 0, 18], state: "minecraft:tuff_bricks"},
        {pos: [4, 0, 19], state: "minecraft:tuff_bricks"},
        {pos: [4, 0, 20], state: "minecraft:tuff_bricks"},
        {pos: [4, 0, 21], state: "minecraft:tuff_bricks"},
        {pos: [4, 0, 22], state: "minecraft:tuff_bricks"},
        {pos: [4, 0, 23], state: "minecraft:tuff_bricks"},
        {pos: [4, 0, 24], state: "minecraft:tuff_bricks"},
        {pos: [4, 0, 25], state: "minecraft:waxed_oxidized_cut_copper"},
        {pos: [5, 0, 0], state: "minecraft:waxed_oxidized_cut_copper"},
        {pos: [5, 0, 1], state: "minecraft:waxed_oxidized_cut_copper"},
        {pos: [5, 0, 2], state: "minecraft:waxed_oxidized_cut_copper"},
        {pos: [5, 0, 3], state: "minecraft:waxed_oxidized_cut_copper"},
        {pos: [5, 0, 4], state: "minecraft:waxed_oxidized_cut_copper"},
        {pos: [5, 0, 5], state: "minecraft:waxed_oxidized_cut_copper"},
        {pos: [5, 0, 6], state: "minecraft:waxed_oxidized_cut_copper"},
        {pos: [5, 0, 7], state: "minecraft:waxed_oxidized_cut_copper"},
        {pos: [5, 0, 8], state: "minecraft:waxed_oxidized_cut_copper"},
        {pos: [5, 0, 9], state: "minecraft:waxed_oxidized_cut_copper"},
        {pos: [5, 0, 10], state: "minecraft:waxed_oxidized_cut_copper"},
        {pos: [5, 0, 11], state: "minecraft:waxed_oxidized_cut_copper"},
        {pos: [5, 0, 12], state: "minecraft:waxed_oxidized_cut_copper"},
        {pos: [5, 0, 13], state: "minecraft:waxed_oxidized_cut_copper"},
        {pos: [5, 0, 14], state: "minecraft:waxed_oxidized_cut_copper"},
        {pos: [5, 0, 15], state: "minecraft:waxed_oxidized_cut_copper"},
        {pos: [5, 0, 16], state: "minecraft:waxed_oxidized_cut_copper"},
        {pos: [5, 0, 17], state: "minecraft:waxed_oxidized_cut_copper"},
        {pos: [5, 0, 18], state: "minecraft:waxed_oxidized_cut_copper"},
        {pos: [5, 0, 19], state: "minecraft:waxed_oxidized_cut_copper"},
        {pos: [5, 0, 20], state: "minecraft:waxed_oxidized_cut_copper"},
        {pos: [5, 0, 21], state: "minecraft:waxed_oxidized_cut_copper"},
        {pos: [5, 0, 22], state: "minecraft:waxed_oxidized_cut_copper"},
        {pos: [5, 0, 23], state: "minecraft:waxed_oxidized_cut_copper"},
        {pos: [5, 0, 24], state: "minecraft:waxed_oxidized_cut_copper"},
        {pos: [5, 0, 25], state: "minecraft:waxed_oxidized_cut_copper"},
        {pos: [0, 1, 1], state: "minecraft:tuff_bricks"},
        {pos: [0, 1, 2], state: "minecraft:tuff_bricks"},
        {pos: [0, 1, 3], state: "minecraft:tuff_bricks"},
        {pos: [0, 1, 6], state: "minecraft:tuff_bricks"},
        {pos: [0, 1, 7], state: "minecraft:tuff_bricks"},
        {pos: [0, 1, 8], state: "minecraft:tuff_bricks"},
        {pos: [0, 1, 11], state: "minecraft:tuff_bricks"},
        {pos: [0, 1, 12], state: "minecraft:tuff_bricks"},
        {pos: [0, 1, 13], state: "minecraft:tuff_bricks"},
        {pos: [0, 1, 16], state: "minecraft:tuff_bricks"},
        {pos: [0, 1, 17], state: "minecraft:tuff_bricks"},
        {pos: [0, 1, 18], state: "minecraft:tuff_bricks"},
        {pos: [0, 1, 21], state: "minecraft:tuff_bricks"},
        {pos: [0, 1, 22], state: "minecraft:tuff_bricks"},
        {pos: [0, 1, 23], state: "minecraft:tuff_bricks"},
        {pos: [1, 1, 0], state: "minecraft:tuff_bricks"},
        {pos: [1, 1, 1], state: "minecraft:tuff_bricks"},
        {pos: [1, 1, 2], state: "minecraft:tuff_bricks"},
        {pos: [1, 1, 3], state: "minecraft:tuff_bricks"},
        {pos: [1, 1, 4], state: "minecraft:tuff_bricks"},
        {pos: [1, 1, 5], state: "minecraft:tuff_bricks"},
        {pos: [1, 1, 6], state: "minecraft:tuff_bricks"},
        {pos: [1, 1, 7], state: "minecraft:tuff_bricks"},
        {pos: [1, 1, 8], state: "minecraft:tuff_bricks"},
        {pos: [1, 1, 9], state: "minecraft:tuff_bricks"},
        {pos: [1, 1, 10], state: "minecraft:tuff_bricks"},
        {pos: [1, 1, 11], state: "minecraft:tuff_bricks"},
        {pos: [1, 1, 12], state: "minecraft:tuff_bricks"},
        {pos: [1, 1, 13], state: "minecraft:tuff_bricks"},
        {pos: [1, 1, 14], state: "minecraft:tuff_bricks"},
        {pos: [1, 1, 15], state: "minecraft:tuff_bricks"},
        {pos: [1, 1, 16], state: "minecraft:tuff_bricks"},
        {pos: [1, 1, 17], state: "minecraft:tuff_bricks"},
        {pos: [1, 1, 18], state: "minecraft:tuff_bricks"},
        {pos: [1, 1, 19], state: "minecraft:tuff_bricks"},
        {pos: [1, 1, 20], state: "minecraft:tuff_bricks"},
        {pos: [1, 1, 21], state: "minecraft:tuff_bricks"},
        {pos: [1, 1, 22], state: "minecraft:tuff_bricks"},
        {pos: [1, 1, 23], state: "minecraft:tuff_bricks"},
        {pos: [1, 1, 24], state: "minecraft:tuff_bricks"},
        {pos: [2, 1, 0], state: "minecraft:tuff_bricks"},
        {pos: [2, 1, 1], state: "minecraft:tuff_bricks"},
        {pos: [2, 1, 2], state: "minecraft:tuff_bricks"},
        {pos: [2, 1, 3], state: "minecraft:tuff_bricks"},
        {pos: [2, 1, 4], state: "minecraft:tuff_bricks"},
        {pos: [2, 1, 5], state: "minecraft:tuff_bricks"},
        {pos: [2, 1, 6], state: "minecraft:tuff_bricks"},
        {pos: [2, 1, 7], state: "minecraft:tuff_bricks"},
        {pos: [2, 1, 8], state: "minecraft:tuff_bricks"},
        {pos: [2, 1, 9], state: "minecraft:tuff_bricks"},
        {pos: [2, 1, 10], state: "minecraft:tuff_bricks"},
        {pos: [2, 1, 11], state: "minecraft:tuff_bricks"},
        {pos: [2, 1, 12], state: "minecraft:tuff_bricks"},
        {pos: [2, 1, 13], state: "minecraft:tuff_bricks"},
        {pos: [2, 1, 14], state: "minecraft:tuff_bricks"},
        {pos: [2, 1, 15], state: "minecraft:tuff_bricks"},
        {pos: [2, 1, 16], state: "minecraft:tuff_bricks"},
        {pos: [2, 1, 17], state: "minecraft:tuff_bricks"},
        {pos: [2, 1, 18], state: "minecraft:tuff_bricks"},
        {pos: [2, 1, 19], state: "minecraft:tuff_bricks"},
        {pos: [2, 1, 20], state: "minecraft:tuff_bricks"},
        {pos: [2, 1, 21], state: "minecraft:tuff_bricks"},
        {pos: [2, 1, 22], state: "minecraft:tuff_bricks"},
        {pos: [2, 1, 23], state: "minecraft:tuff_bricks"},
        {pos: [2, 1, 24], state: "minecraft:tuff_bricks"},
        {pos: [3, 1, 0], state: "minecraft:tuff_bricks"},
        {pos: [3, 1, 1], state: "minecraft:tuff_bricks"},
        {pos: [3, 1, 2], state: "minecraft:tuff_bricks"},
        {pos: [3, 1, 3], state: "minecraft:tuff_bricks"},
        {pos: [3, 1, 4], state: "minecraft:tuff_bricks"},
        {pos: [3, 1, 5], state: "minecraft:tuff_bricks"},
        {pos: [3, 1, 6], state: "minecraft:tuff_bricks"},
        {pos: [3, 1, 7], state: "minecraft:tuff_bricks"},
        {pos: [3, 1, 8], state: "minecraft:tuff_bricks"},
        {pos: [3, 1, 9], state: "minecraft:tuff_bricks"},
        {pos: [3, 1, 10], state: "minecraft:tuff_bricks"},
        {pos: [3, 1, 11], state: "minecraft:tuff_bricks"},
        {pos: [3, 1, 12], state: "minecraft:tuff_bricks"},
        {pos: [3, 1, 13], state: "minecraft:tuff_bricks"},
        {pos: [3, 1, 14], state: "minecraft:tuff_bricks"},
        {pos: [3, 1, 15], state: "minecraft:tuff_bricks"},
        {pos: [3, 1, 16], state: "minecraft:tuff_bricks"},
        {pos: [3, 1, 17], state: "minecraft:tuff_bricks"},
        {pos: [3, 1, 18], state: "minecraft:tuff_bricks"},
        {pos: [3, 1, 19], state: "minecraft:tuff_bricks"},
        {pos: [3, 1, 20], state: "minecraft:tuff_bricks"},
        {pos: [3, 1, 21], state: "minecraft:tuff_bricks"},
        {pos: [3, 1, 22], state: "minecraft:tuff_bricks"},
        {pos: [3, 1, 23], state: "minecraft:tuff_bricks"},
        {pos: [3, 1, 24], state: "minecraft:tuff_bricks"},
        {pos: [4, 1, 1], state: "minecraft:tuff_bricks"},
        {pos: [4, 1, 2], state: "minecraft:tuff_bricks"},
        {pos: [4, 1, 3], state: "minecraft:tuff_bricks"},
        {pos: [4, 1, 4], state: "minecraft:tuff_bricks"},
        {pos: [4, 1, 5], state: "minecraft:tuff_bricks"},
        {pos: [4, 1, 6], state: "minecraft:tuff_bricks"},
        {pos: [4, 1, 7], state: "minecraft:tuff_bricks"},
        {pos: [4, 1, 8], state: "minecraft:tuff_bricks"},
        {pos: [4, 1, 9], state: "minecraft:tuff_bricks"},
        {pos: [4, 1, 10], state: "minecraft:tuff_bricks"},
        {pos: [4, 1, 11], state: "minecraft:tuff_bricks"},
        {pos: [4, 1, 12], state: "minecraft:tuff_bricks"},
        {pos: [4, 1, 13], state: "minecraft:tuff_bricks"},
        {pos: [4, 1, 14], state: "minecraft:tuff_bricks"},
        {pos: [4, 1, 15], state: "minecraft:tuff_bricks"},
        {pos: [4, 1, 16], state: "minecraft:tuff_bricks"},
        {pos: [4, 1, 17], state: "minecraft:tuff_bricks"},
        {pos: [4, 1, 18], state: "minecraft:tuff_bricks"},
        {pos: [4, 1, 19], state: "minecraft:tuff_bricks"},
        {pos: [4, 1, 20], state: "minecraft:tuff_bricks"},
        {pos: [4, 1, 21], state: "minecraft:tuff_bricks"},
        {pos: [4, 1, 22], state: "minecraft:tuff_bricks"},
        {pos: [4, 1, 23], state: "minecraft:tuff_bricks"},
        {pos: [4, 1, 24], state: "minecraft:tuff_bricks"},
        {pos: [0, 2, 1], state: "minecraft:waxed_oxidized_cut_copper"},
        {pos: [0, 2, 2], state: "minecraft:waxed_oxidized_cut_copper"},
        {pos: [0, 2, 3], state: "minecraft:waxed_oxidized_cut_copper"},
        {pos: [0, 2, 6], state: "minecraft:waxed_oxidized_cut_copper"},
        {pos: [0, 2, 7], state: "minecraft:waxed_oxidized_cut_copper"},
        {pos: [0, 2, 8], state: "minecraft:waxed_oxidized_cut_copper"},
        {pos: [0, 2, 11], state: "minecraft:waxed_oxidized_cut_copper"},
        {pos: [0, 2, 12], state: "minecraft:waxed_oxidized_cut_copper"},
        {pos: [0, 2, 13], state: "minecraft:waxed_oxidized_cut_copper"},
        {pos: [0, 2, 16], state: "minecraft:waxed_oxidized_cut_copper"},
        {pos: [0, 2, 17], state: "minecraft:waxed_oxidized_cut_copper"},
        {pos: [0, 2, 18], state: "minecraft:waxed_oxidized_cut_copper"},
        {pos: [0, 2, 21], state: "minecraft:waxed_oxidized_cut_copper"},
        {pos: [0, 2, 22], state: "minecraft:waxed_oxidized_cut_copper"},
        {pos: [0, 2, 23], state: "minecraft:waxed_oxidized_cut_copper"},
        {pos: [1, 2, 0], state: "minecraft:waxed_oxidized_cut_copper"},
        {pos: [1, 2, 1], state: "minecraft:waxed_oxidized_copper"},
        {pos: [1, 2, 2], state: "minecraft:waxed_oxidized_copper"},
        {pos: [1, 2, 3], state: "minecraft:waxed_oxidized_copper"},
        {pos: [1, 2, 4], state: "minecraft:waxed_oxidized_copper"},
        {pos: [1, 2, 5], state: "minecraft:waxed_oxidized_copper"},
        {pos: [1, 2, 6], state: "minecraft:waxed_oxidized_copper"},
        {pos: [1, 2, 7], state: "minecraft:waxed_oxidized_copper"},
        {pos: [1, 2, 8], state: "minecraft:waxed_oxidized_copper"},
        {pos: [1, 2, 9], state: "minecraft:waxed_oxidized_copper"},
        {pos: [1, 2, 10], state: "minecraft:waxed_oxidized_copper"},
        {pos: [1, 2, 11], state: "minecraft:waxed_oxidized_copper"},
        {pos: [1, 2, 12], state: "minecraft:waxed_oxidized_copper"},
        {pos: [1, 2, 13], state: "minecraft:waxed_oxidized_copper"},
        {pos: [1, 2, 14], state: "minecraft:waxed_oxidized_copper"},
        {pos: [1, 2, 15], state: "minecraft:waxed_oxidized_copper"},
        {pos: [1, 2, 16], state: "minecraft:waxed_oxidized_copper"},
        {pos: [1, 2, 17], state: "minecraft:waxed_oxidized_copper"},
        {pos: [1, 2, 18], state: "minecraft:waxed_oxidized_copper"},
        {pos: [1, 2, 19], state: "minecraft:waxed_oxidized_copper"},
        {pos: [1, 2, 20], state: "minecraft:waxed_oxidized_copper"},
        {pos: [1, 2, 21], state: "minecraft:waxed_oxidized_copper"},
        {pos: [1, 2, 22], state: "minecraft:waxed_oxidized_copper"},
        {pos: [1, 2, 23], state: "minecraft:waxed_oxidized_copper"},
        {pos: [1, 2, 24], state: "minecraft:waxed_copper_block"},
        {pos: [2, 2, 0], state: "minecraft:waxed_oxidized_cut_copper"},
        {pos: [2, 2, 1], state: "minecraft:waxed_oxidized_copper"},
        {pos: [2, 2, 2], state: "minecraft:waxed_oxidized_copper"},
        {pos: [2, 2, 3], state: "minecraft:waxed_oxidized_copper"},
        {pos: [2, 2, 4], state: "minecraft:waxed_oxidized_copper"},
        {pos: [2, 2, 5], state: "minecraft:waxed_oxidized_copper"},
        {pos: [2, 2, 6], state: "minecraft:waxed_oxidized_copper"},
        {pos: [2, 2, 7], state: "minecraft:waxed_oxidized_copper"},
        {pos: [2, 2, 8], state: "minecraft:waxed_oxidized_copper"},
        {pos: [2, 2, 9], state: "minecraft:waxed_oxidized_copper"},
        {pos: [2, 2, 10], state: "minecraft:waxed_oxidized_copper"},
        {pos: [2, 2, 11], state: "minecraft:waxed_oxidized_copper"},
        {pos: [2, 2, 12], state: "minecraft:waxed_oxidized_copper"},
        {pos: [2, 2, 13], state: "minecraft:waxed_oxidized_copper"},
        {pos: [2, 2, 14], state: "minecraft:waxed_oxidized_copper"},
        {pos: [2, 2, 15], state: "minecraft:waxed_oxidized_copper"},
        {pos: [2, 2, 16], state: "minecraft:waxed_oxidized_copper"},
        {pos: [2, 2, 17], state: "minecraft:waxed_oxidized_copper"},
        {pos: [2, 2, 18], state: "minecraft:waxed_oxidized_copper"},
        {pos: [2, 2, 19], state: "minecraft:waxed_oxidized_copper"},
        {pos: [2, 2, 20], state: "minecraft:waxed_oxidized_copper"},
        {pos: [2, 2, 21], state: "minecraft:waxed_oxidized_copper"},
        {pos: [2, 2, 22], state: "minecraft:waxed_oxidized_copper"},
        {pos: [2, 2, 23], state: "minecraft:waxed_oxidized_copper"},
        {pos: [2, 2, 24], state: "minecraft:waxed_copper_block"},
        {pos: [3, 2, 0], state: "minecraft:waxed_oxidized_cut_copper"},
        {pos: [3, 2, 1], state: "minecraft:waxed_oxidized_copper"},
        {pos: [3, 2, 2], state: "minecraft:waxed_oxidized_copper"},
        {pos: [3, 2, 3], state: "minecraft:waxed_oxidized_copper"},
        {pos: [3, 2, 4], state: "minecraft:waxed_oxidized_copper"},
        {pos: [3, 2, 5], state: "minecraft:waxed_oxidized_copper"},
        {pos: [3, 2, 6], state: "minecraft:waxed_oxidized_copper"},
        {pos: [3, 2, 7], state: "minecraft:waxed_oxidized_copper"},
        {pos: [3, 2, 8], state: "minecraft:waxed_oxidized_copper"},
        {pos: [3, 2, 9], state: "minecraft:waxed_oxidized_copper"},
        {pos: [3, 2, 10], state: "minecraft:waxed_oxidized_copper"},
        {pos: [3, 2, 11], state: "minecraft:waxed_oxidized_copper"},
        {pos: [3, 2, 12], state: "minecraft:waxed_oxidized_copper"},
        {pos: [3, 2, 13], state: "minecraft:waxed_oxidized_copper"},
        {pos: [3, 2, 14], state: "minecraft:waxed_oxidized_copper"},
        {pos: [3, 2, 15], state: "minecraft:waxed_oxidized_copper"},
        {pos: [3, 2, 16], state: "minecraft:waxed_oxidized_copper"},
        {pos: [3, 2, 17], state: "minecraft:waxed_oxidized_copper"},
        {pos: [3, 2, 18], state: "minecraft:waxed_oxidized_copper"},
        {pos: [3, 2, 19], state: "minecraft:waxed_oxidized_copper"},
        {pos: [3, 2, 20], state: "minecraft:waxed_oxidized_copper"},
        {pos: [3, 2, 21], state: "minecraft:waxed_oxidized_copper"},
        {pos: [3, 2, 22], state: "minecraft:waxed_oxidized_copper"},
        {pos: [3, 2, 23], state: "minecraft:waxed_oxidized_copper"},
        {pos: [3, 2, 24], state: "minecraft:waxed_copper_block"},
        {pos: [4, 2, 1], state: "minecraft:waxed_copper_block"},
        {pos: [4, 2, 2], state: "minecraft:waxed_copper_block"},
        {pos: [4, 2, 3], state: "minecraft:waxed_copper_block"},
        {pos: [4, 2, 4], state: "minecraft:waxed_copper_block"},
        {pos: [4, 2, 5], state: "minecraft:waxed_copper_block"},
        {pos: [4, 2, 6], state: "minecraft:waxed_copper_block"},
        {pos: [4, 2, 7], state: "minecraft:waxed_copper_block"},
        {pos: [4, 2, 8], state: "minecraft:waxed_copper_block"},
        {pos: [4, 2, 9], state: "minecraft:waxed_copper_block"},
        {pos: [4, 2, 10], state: "minecraft:waxed_copper_block"},
        {pos: [4, 2, 11], state: "minecraft:waxed_copper_block"},
        {pos: [4, 2, 12], state: "minecraft:waxed_copper_block"},
        {pos: [4, 2, 13], state: "minecraft:waxed_copper_block"},
        {pos: [4, 2, 14], state: "minecraft:waxed_copper_block"},
        {pos: [4, 2, 15], state: "minecraft:waxed_copper_block"},
        {pos: [4, 2, 16], state: "minecraft:waxed_copper_block"},
        {pos: [4, 2, 17], state: "minecraft:waxed_copper_block"},
        {pos: [4, 2, 18], state: "minecraft:waxed_copper_block"},
        {pos: [4, 2, 19], state: "minecraft:waxed_copper_block"},
        {pos: [4, 2, 20], state: "minecraft:waxed_copper_block"},
        {pos: [4, 2, 21], state: "minecraft:waxed_copper_block"},
        {pos: [4, 2, 22], state: "minecraft:waxed_copper_block"},
        {pos: [4, 2, 23], state: "minecraft:waxed_copper_block"},
        {pos: [4, 2, 24], state: "minecraft:waxed_copper_block"},
        {pos: [3, 3, 2], state: "minecraft:air"},
        {pos: [2, 4, 2], state: "minecraft:jigsaw{orientation:west_up}", nbt: {final_state: "minecraft:air", id: "minecraft:jigsaw", joint: "aligned", name: "minecraft:empty", placement_priority: 0, pool: "minecraft:trial_chambers/reward/all", selection_priority: 0, target: "minecraft:reward_connector"}},
        {pos: [2, 4, 7], state: "minecraft:jigsaw{orientation:east_up}", nbt: {final_state: "minecraft:air", id: "minecraft:jigsaw", joint: "aligned", name: "minecraft:empty", placement_priority: 1, pool: "minecraft:trial_chambers/spawner/ranged", selection_priority: 1, target: "minecraft:spawner_connector"}},
        {pos: [2, 4, 17], state: "minecraft:jigsaw{orientation:west_up}", nbt: {final_state: "minecraft:air", id: "minecraft:jigsaw", joint: "aligned", name: "minecraft:empty", placement_priority: 1, pool: "minecraft:trial_chambers/spawner/breeze", selection_priority: 1, target: "minecraft:spawner_connector"}},
        {pos: [3, 4, 2], state: "minecraft:air"}
    ],
    entities: [],
    palette: [
        "minecraft:tuff_bricks",
        "minecraft:waxed_oxidized_cut_copper",
        "minecraft:waxed_oxidized_copper",
        "minecraft:waxed_copper_block",
        "minecraft:air",
        "minecraft:jigsaw{orientation:down_east}",
        "minecraft:jigsaw{orientation:west_up}",
        "minecraft:jigsaw{orientation:east_up}"
    ]
}
