{
    size: [5, 8, 5],
    data: [
        {pos: [1, 1, 1], state: "minecraft:waxed_copper_grate{waterlogged:false}"},
        {pos: [1, 1, 2], state: "minecraft:waxed_copper_grate{waterlogged:false}"},
        {pos: [1, 1, 3], state: "minecraft:waxed_copper_grate{waterlogged:false}"},
        {pos: [2, 1, 1], state: "minecraft:waxed_copper_grate{waterlogged:false}"},
        {pos: [2, 1, 2], state: "minecraft:waxed_chiseled_copper"},
        {pos: [2, 1, 3], state: "minecraft:waxed_copper_grate{waterlogged:false}"},
        {pos: [3, 1, 1], state: "minecraft:waxed_copper_grate{waterlogged:false}"},
        {pos: [3, 1, 2], state: "minecraft:waxed_copper_grate{waterlogged:false}"},
        {pos: [3, 1, 3], state: "minecraft:waxed_copper_grate{waterlogged:false}"},
        {pos: [2, 2, 2], state: "minecraft:chain{axis:y,waterlogged:false}"},
        {pos: [2, 3, 0], state: "minecraft:jigsaw{orientation:north_up}", nbt: {final_state: "minecraft:air", id: "minecraft:jigsaw", joint: "rollable", name: "minecraft:upper_addon_extension", placement_priority: 0, pool: "minecraft:empty", selection_priority: 0, target: "minecraft:empty"}},
        {pos: [2, 3, 2], state: "minecraft:chain{axis:y,waterlogged:false}"},
        {pos: [2, 4, 2], state: "minecraft:chain{axis:y,waterlogged:false}"},
        {pos: [2, 5, 2], state: "minecraft:chain{axis:y,waterlogged:false}"},
        {pos: [2, 6, 2], state: "minecraft:chain{axis:y,waterlogged:false}"},
        {pos: [0, 7, 0], state: "minecraft:polished_tuff"},
        {pos: [0, 7, 1], state: "minecraft:polished_tuff"},
        {pos: [0, 7, 2], state: "minecraft:polished_tuff"},
        {pos: [0, 7, 3], state: "minecraft:polished_tuff"},
        {pos: [0, 7, 4], state: "minecraft:polished_tuff"},
        {pos: [1, 7, 0], state: "minecraft:polished_tuff"},
        {pos: [1, 7, 1], state: "minecraft:waxed_copper_block"},
        {pos: [1, 7, 2], state: "minecraft:waxed_copper_block"},
        {pos: [1, 7, 3], state: "minecraft:waxed_copper_block"},
        {pos: [1, 7, 4], state: "minecraft:polished_tuff"},
        {pos: [2, 7, 0], state: "minecraft:polished_tuff"},
        {pos: [2, 7, 1], state: "minecraft:waxed_copper_block"},
        {pos: [2, 7, 2], state: "minecraft:waxed_chiseled_copper"},
        {pos: [2, 7, 3], state: "minecraft:waxed_copper_block"},
        {pos: [2, 7, 4], state: "minecraft:polished_tuff"},
        {pos: [3, 7, 0], state: "minecraft:polished_tuff"},
        {pos: [3, 7, 1], state: "minecraft:waxed_copper_block"},
        {pos: [3, 7, 2], state: "minecraft:waxed_copper_block"},
        {pos: [3, 7, 3], state: "minecraft:waxed_copper_block"},
        {pos: [3, 7, 4], state: "minecraft:polished_tuff"},
        {pos: [4, 7, 0], state: "minecraft:polished_tuff"},
        {pos: [4, 7, 1], state: "minecraft:polished_tuff"},
        {pos: [4, 7, 2], state: "minecraft:polished_tuff"},
        {pos: [4, 7, 3], state: "minecraft:polished_tuff"},
        {pos: [4, 7, 4], state: "minecraft:polished_tuff"}
    ],
    entities: [],
    palette: [
        "minecraft:waxed_copper_grate{waterlogged:false}",
        "minecraft:waxed_chiseled_copper",
        "minecraft:polished_tuff",
        "minecraft:waxed_copper_block",
        "minecraft:chain{axis:y,waterlogged:false}",
        "minecraft:jigsaw{orientation:north_up}"
    ]
}
