{
    size: [11, 6, 5],
    data: [
        {pos: [0, 0, 0], state: "minecraft:tuff_bricks"},
        {pos: [0, 0, 1], state: "minecraft:tuff_bricks"},
        {pos: [0, 0, 2], state: "minecraft:tuff_bricks"},
        {pos: [0, 0, 3], state: "minecraft:tuff_bricks"},
        {pos: [0, 0, 4], state: "minecraft:tuff_bricks"},
        {pos: [1, 0, 0], state: "minecraft:tuff_bricks"},
        {pos: [1, 0, 1], state: "minecraft:tuff_bricks"},
        {pos: [1, 0, 2], state: "minecraft:tuff_bricks"},
        {pos: [1, 0, 3], state: "minecraft:tuff_bricks"},
        {pos: [1, 0, 4], state: "minecraft:tuff_bricks"},
        {pos: [2, 0, 0], state: "minecraft:tuff_bricks"},
        {pos: [2, 0, 1], state: "minecraft:tuff_bricks"},
        {pos: [2, 0, 2], state: "minecraft:tuff_bricks"},
        {pos: [2, 0, 3], state: "minecraft:tuff_bricks"},
        {pos: [2, 0, 4], state: "minecraft:tuff_bricks"},
        {pos: [3, 0, 0], state: "minecraft:tuff_bricks"},
        {pos: [3, 0, 1], state: "minecraft:tuff_bricks"},
        {pos: [3, 0, 2], state: "minecraft:tuff_bricks"},
        {pos: [3, 0, 3], state: "minecraft:tuff_bricks"},
        {pos: [3, 0, 4], state: "minecraft:tuff_bricks"},
        {pos: [4, 0, 0], state: "minecraft:tuff_bricks"},
        {pos: [4, 0, 1], state: "minecraft:tuff_bricks"},
        {pos: [4, 0, 2], state: "minecraft:tuff_bricks"},
        {pos: [4, 0, 3], state: "minecraft:tuff_bricks"},
        {pos: [4, 0, 4], state: "minecraft:tuff_bricks"},
        {pos: [5, 0, 0], state: "minecraft:tuff_bricks"},
        {pos: [5, 0, 1], state: "minecraft:tuff_bricks"},
        {pos: [5, 0, 2], state: "minecraft:tuff_bricks"},
        {pos: [5, 0, 3], state: "minecraft:tuff_bricks"},
        {pos: [5, 0, 4], state: "minecraft:tuff_bricks"},
        {pos: [6, 0, 0], state: "minecraft:waxed_oxidized_copper"},
        {pos: [6, 0, 1], state: "minecraft:waxed_oxidized_copper"},
        {pos: [6, 0, 2], state: "minecraft:waxed_oxidized_copper"},
        {pos: [6, 0, 3], state: "minecraft:waxed_oxidized_copper"},
        {pos: [6, 0, 4], state: "minecraft:waxed_oxidized_copper"},
        {pos: [7, 0, 0], state: "minecraft:waxed_oxidized_copper"},
        {pos: [7, 0, 1], state: "minecraft:waxed_oxidized_copper"},
        {pos: [7, 0, 2], state: "minecraft:waxed_oxidized_copper"},
        {pos: [7, 0, 3], state: "minecraft:waxed_oxidized_copper"},
        {pos: [7, 0, 4], state: "minecraft:waxed_oxidized_copper"},
        {pos: [8, 0, 0], state: "minecraft:waxed_oxidized_copper"},
        {pos: [8, 0, 1], state: "minecraft:waxed_oxidized_copper"},
        {pos: [8, 0, 2], state: "minecraft:waxed_oxidized_copper"},
        {pos: [8, 0, 3], state: "minecraft:waxed_oxidized_copper"},
        {pos: [8, 0, 4], state: "minecraft:waxed_oxidized_copper"},
        {pos: [9, 0, 0], state: "minecraft:tuff_bricks"},
        {pos: [9, 0, 1], state: "minecraft:tuff_bricks"},
        {pos: [9, 0, 2], state: "minecraft:tuff_bricks"},
        {pos: [9, 0, 3], state: "minecraft:tuff_bricks"},
        {pos: [9, 0, 4], state: "minecraft:tuff_bricks"},
        {pos: [10, 0, 0], state: "minecraft:waxed_oxidized_copper"},
        {pos: [10, 0, 1], state: "minecraft:waxed_oxidized_copper"},
        {pos: [10, 0, 2], state: "minecraft:waxed_oxidized_copper"},
        {pos: [10, 0, 3], state: "minecraft:waxed_oxidized_copper"},
        {pos: [10, 0, 4], state: "minecraft:waxed_oxidized_copper"},
        {pos: [0, 1, 0], state: "minecraft:waxed_copper_block"},
        {pos: [0, 1, 1], state: "minecraft:waxed_copper_block"},
        {pos: [0, 1, 2], state: "minecraft:waxed_copper_block"},
        {pos: [0, 1, 3], state: "minecraft:waxed_copper_block"},
        {pos: [0, 1, 4], state: "minecraft:waxed_copper_block"},
        {pos: [1, 1, 0], state: "minecraft:tuff_bricks"},
        {pos: [1, 1, 1], state: "minecraft:tuff_bricks"},
        {pos: [1, 1, 2], state: "minecraft:tuff_bricks"},
        {pos: [1, 1, 3], state: "minecraft:tuff_bricks"},
        {pos: [1, 1, 4], state: "minecraft:waxed_copper_block"},
        {pos: [2, 1, 0], state: "minecraft:tuff_bricks"},
        {pos: [2, 1, 1], state: "minecraft:tuff_bricks"},
        {pos: [2, 1, 2], state: "minecraft:tuff_bricks"},
        {pos: [2, 1, 3], state: "minecraft:tuff_bricks"},
        {pos: [2, 1, 4], state: "minecraft:waxed_copper_block"},
        {pos: [3, 1, 0], state: "minecraft:tuff_bricks"},
        {pos: [3, 1, 1], state: "minecraft:tuff_bricks"},
        {pos: [3, 1, 2], state: "minecraft:tuff_bricks"},
        {pos: [3, 1, 3], state: "minecraft:tuff_bricks"},
        {pos: [3, 1, 4], state: "minecraft:waxed_copper_block"},
        {pos: [4, 1, 0], state: "minecraft:tuff_bricks"},
        {pos: [4, 1, 1], state: "minecraft:tuff_bricks"},
        {pos: [4, 1, 2], state: "minecraft:tuff_bricks"},
        {pos: [4, 1, 3], state: "minecraft:tuff_bricks"},
        {pos: [4, 1, 4], state: "minecraft:waxed_copper_block"},
        {pos: [5, 1, 0], state: "minecraft:waxed_copper_block"},
        {pos: [5, 1, 1], state: "minecraft:waxed_copper_block"},
        {pos: [5, 1, 2], state: "minecraft:waxed_copper_block"},
        {pos: [5, 1, 3], state: "minecraft:waxed_copper_block"},
        {pos: [5, 1, 4], state: "minecraft:waxed_copper_block"},
        {pos: [6, 1, 0], state: "minecraft:air"},
        {pos: [6, 1, 1], state: "minecraft:air"},
        {pos: [6, 1, 2], state: "minecraft:air"},
        {pos: [6, 1, 3], state: "minecraft:air"},
        {pos: [6, 1, 4], state: "minecraft:air"},
        {pos: [7, 1, 0], state: "minecraft:air"},
        {pos: [7, 1, 1], state: "minecraft:air"},
        {pos: [7, 1, 2], state: "minecraft:air"},
        {pos: [7, 1, 3], state: "minecraft:air"},
        {pos: [7, 1, 4], state: "minecraft:air"},
        {pos: [8, 1, 0], state: "minecraft:air"},
        {pos: [8, 1, 1], state: "minecraft:air"},
        {pos: [8, 1, 2], state: "minecraft:air"},
        {pos: [8, 1, 3], state: "minecraft:air"},
        {pos: [8, 1, 4], state: "minecraft:air"},
        {pos: [9, 1, 0], state: "minecraft:waxed_copper_block"},
        {pos: [9, 1, 1], state: "minecraft:waxed_copper_block"},
        {pos: [9, 1, 2], state: "minecraft:waxed_copper_block"},
        {pos: [9, 1, 3], state: "minecraft:waxed_copper_block"},
        {pos: [9, 1, 4], state: "minecraft:waxed_copper_block"},
        {pos: [10, 1, 0], state: "minecraft:air"},
        {pos: [10, 1, 1], state: "minecraft:air"},
        {pos: [10, 1, 2], state: "minecraft:air"},
        {pos: [10, 1, 3], state: "minecraft:air"},
        {pos: [10, 1, 4], state: "minecraft:air"},
        {pos: [0, 2, 0], state: "minecraft:tuff_bricks"},
        {pos: [0, 2, 1], state: "minecraft:tuff_bricks"},
        {pos: [0, 2, 2], state: "minecraft:tuff_bricks"},
        {pos: [0, 2, 3], state: "minecraft:tuff_bricks"},
        {pos: [0, 2, 4], state: "minecraft:tuff_bricks"},
        {pos: [1, 2, 0], state: "minecraft:tuff_bricks"},
        {pos: [1, 2, 1], state: "minecraft:tuff_bricks"},
        {pos: [1, 2, 2], state: "minecraft:tuff_bricks"},
        {pos: [1, 2, 3], state: "minecraft:tuff_bricks"},
        {pos: [1, 2, 4], state: "minecraft:tuff_bricks"},
        {pos: [2, 2, 0], state: "minecraft:tuff_bricks"},
        {pos: [2, 2, 1], state: "minecraft:tuff_bricks"},
        {pos: [2, 2, 2], state: "minecraft:tuff_bricks"},
        {pos: [2, 2, 3], state: "minecraft:tuff_bricks"},
        {pos: [2, 2, 4], state: "minecraft:tuff_bricks"},
        {pos: [3, 2, 0], state: "minecraft:tuff_bricks"},
        {pos: [3, 2, 1], state: "minecraft:tuff_bricks"},
        {pos: [3, 2, 2], state: "minecraft:tuff_bricks"},
        {pos: [3, 2, 3], state: "minecraft:tuff_bricks"},
        {pos: [3, 2, 4], state: "minecraft:tuff_bricks"},
        {pos: [4, 2, 0], state: "minecraft:tuff_bricks"},
        {pos: [4, 2, 1], state: "minecraft:tuff_bricks"},
        {pos: [4, 2, 2], state: "minecraft:tuff_bricks"},
        {pos: [4, 2, 3], state: "minecraft:tuff_bricks"},
        {pos: [4, 2, 4], state: "minecraft:tuff_bricks"},
        {pos: [5, 2, 0], state: "minecraft:tuff_bricks"},
        {pos: [5, 2, 1], state: "minecraft:tuff_bricks"},
        {pos: [5, 2, 2], state: "minecraft:tuff_bricks"},
        {pos: [5, 2, 3], state: "minecraft:tuff_bricks"},
        {pos: [5, 2, 4], state: "minecraft:waxed_copper_block"},
        {pos: [6, 2, 0], state: "minecraft:air"},
        {pos: [6, 2, 1], state: "minecraft:air"},
        {pos: [6, 2, 2], state: "minecraft:air"},
        {pos: [6, 2, 3], state: "minecraft:air"},
        {pos: [6, 2, 4], state: "minecraft:air"},
        {pos: [7, 2, 0], state: "minecraft:jigsaw{orientation:north_up}", nbt: {final_state: "minecraft:air", id: "minecraft:jigsaw", joint: "rollable", name: "minecraft:lower_start", placement_priority: 0, pool: "minecraft:empty", selection_priority: 0, target: "minecraft:empty"}},
        {pos: [7, 2, 1], state: "minecraft:air"},
        {pos: [7, 2, 2], state: "minecraft:air"},
        {pos: [7, 2, 3], state: "minecraft:air"},
        {pos: [7, 2, 4], state: "minecraft:jigsaw{orientation:south_up}", nbt: {final_state: "minecraft:air", id: "minecraft:jigsaw", joint: "rollable", name: "minecraft:lower_walkable_extension", placement_priority: 0, pool: "minecraft:trial_chamber/chamber/addon", selection_priority: 0, target: "minecraft:empty"}},
        {pos: [8, 2, 0], state: "minecraft:air"},
        {pos: [8, 2, 1], state: "minecraft:air"},
        {pos: [8, 2, 2], state: "minecraft:air"},
        {pos: [8, 2, 3], state: "minecraft:air"},
        {pos: [8, 2, 4], state: "minecraft:air"},
        {pos: [9, 2, 0], state: "minecraft:tuff_bricks"},
        {pos: [9, 2, 1], state: "minecraft:air"},
        {pos: [9, 2, 2], state: "minecraft:tuff_bricks"},
        {pos: [9, 2, 3], state: "minecraft:tuff_bricks"},
        {pos: [9, 2, 4], state: "minecraft:waxed_copper_block"},
        {pos: [10, 2, 0], state: "minecraft:air"},
        {pos: [10, 2, 1], state: "minecraft:air"},
        {pos: [10, 2, 2], state: "minecraft:air"},
        {pos: [10, 2, 3], state: "minecraft:air"},
        {pos: [10, 2, 4], state: "minecraft:air"},
        {pos: [0, 3, 0], state: "minecraft:tuff_bricks"},
        {pos: [0, 3, 1], state: "minecraft:tuff_bricks"},
        {pos: [0, 3, 2], state: "minecraft:tuff_bricks"},
        {pos: [0, 3, 3], state: "minecraft:tuff_bricks"},
        {pos: [0, 3, 4], state: "minecraft:tuff_bricks"},
        {pos: [1, 3, 0], state: "minecraft:tuff_bricks"},
        {pos: [1, 3, 1], state: "minecraft:tuff_bricks"},
        {pos: [1, 3, 2], state: "minecraft:tuff_bricks"},
        {pos: [1, 3, 3], state: "minecraft:tuff_bricks"},
        {pos: [1, 3, 4], state: "minecraft:tuff_bricks"},
        {pos: [2, 3, 0], state: "minecraft:tuff_bricks"},
        {pos: [2, 3, 1], state: "minecraft:tuff_bricks"},
        {pos: [2, 3, 2], state: "minecraft:tuff_bricks"},
        {pos: [2, 3, 3], state: "minecraft:tuff_bricks"},
        {pos: [2, 3, 4], state: "minecraft:tuff_bricks"},
        {pos: [3, 3, 0], state: "minecraft:tuff_bricks"},
        {pos: [3, 3, 1], state: "minecraft:tuff_bricks"},
        {pos: [3, 3, 2], state: "minecraft:tuff_bricks"},
        {pos: [3, 3, 3], state: "minecraft:tuff_bricks"},
        {pos: [3, 3, 4], state: "minecraft:tuff_bricks"},
        {pos: [4, 3, 0], state: "minecraft:tuff_bricks"},
        {pos: [4, 3, 1], state: "minecraft:tuff_bricks"},
        {pos: [4, 3, 2], state: "minecraft:tuff_bricks"},
        {pos: [4, 3, 3], state: "minecraft:tuff_bricks"},
        {pos: [4, 3, 4], state: "minecraft:tuff_bricks"},
        {pos: [5, 3, 0], state: "minecraft:tuff_bricks"},
        {pos: [5, 3, 1], state: "minecraft:tuff_bricks"},
        {pos: [5, 3, 2], state: "minecraft:tuff_bricks"},
        {pos: [5, 3, 3], state: "minecraft:tuff_bricks"},
        {pos: [5, 3, 4], state: "minecraft:waxed_copper_block"},
        {pos: [6, 3, 0], state: "minecraft:air"},
        {pos: [6, 3, 1], state: "minecraft:air"},
        {pos: [6, 3, 2], state: "minecraft:air"},
        {pos: [6, 3, 3], state: "minecraft:air"},
        {pos: [6, 3, 4], state: "minecraft:air"},
        {pos: [7, 3, 0], state: "minecraft:air"},
        {pos: [7, 3, 1], state: "minecraft:air"},
        {pos: [7, 3, 2], state: "minecraft:air"},
        {pos: [7, 3, 3], state: "minecraft:air"},
        {pos: [7, 3, 4], state: "minecraft:air"},
        {pos: [8, 3, 0], state: "minecraft:air"},
        {pos: [8, 3, 1], state: "minecraft:air"},
        {pos: [8, 3, 2], state: "minecraft:air"},
        {pos: [8, 3, 3], state: "minecraft:air"},
        {pos: [8, 3, 4], state: "minecraft:air"},
        {pos: [9, 3, 0], state: "minecraft:tuff_bricks"},
        {pos: [9, 3, 1], state: "minecraft:lantern{hanging:true,waterlogged:false}"},
        {pos: [9, 3, 2], state: "minecraft:tuff_bricks"},
        {pos: [9, 3, 3], state: "minecraft:tuff_bricks"},
        {pos: [9, 3, 4], state: "minecraft:waxed_copper_block"},
        {pos: [10, 3, 0], state: "minecraft:air"},
        {pos: [10, 3, 1], state: "minecraft:air"},
        {pos: [10, 3, 2], state: "minecraft:air"},
        {pos: [10, 3, 3], state: "minecraft:air"},
        {pos: [10, 3, 4], state: "minecraft:air"},
        {pos: [0, 4, 0], state: "minecraft:tuff_bricks"},
        {pos: [0, 4, 1], state: "minecraft:tuff_bricks"},
        {pos: [0, 4, 2], state: "minecraft:tuff_bricks"},
        {pos: [0, 4, 3], state: "minecraft:tuff_bricks"},
        {pos: [0, 4, 4], state: "minecraft:tuff_bricks"},
        {pos: [1, 4, 0], state: "minecraft:tuff_bricks"},
        {pos: [1, 4, 1], state: "minecraft:tuff_bricks"},
        {pos: [1, 4, 2], state: "minecraft:tuff_bricks"},
        {pos: [1, 4, 3], state: "minecraft:tuff_bricks"},
        {pos: [1, 4, 4], state: "minecraft:tuff_bricks"},
        {pos: [2, 4, 0], state: "minecraft:tuff_bricks"},
        {pos: [2, 4, 1], state: "minecraft:tuff_bricks"},
        {pos: [2, 4, 2], state: "minecraft:tuff_bricks"},
        {pos: [2, 4, 3], state: "minecraft:tuff_bricks"},
        {pos: [2, 4, 4], state: "minecraft:tuff_bricks"},
        {pos: [3, 4, 0], state: "minecraft:tuff_bricks"},
        {pos: [3, 4, 1], state: "minecraft:tuff_bricks"},
        {pos: [3, 4, 2], state: "minecraft:tuff_bricks"},
        {pos: [3, 4, 3], state: "minecraft:tuff_bricks"},
        {pos: [3, 4, 4], state: "minecraft:tuff_bricks"},
        {pos: [4, 4, 0], state: "minecraft:tuff_bricks"},
        {pos: [4, 4, 1], state: "minecraft:tuff_bricks"},
        {pos: [4, 4, 2], state: "minecraft:tuff_bricks"},
        {pos: [4, 4, 3], state: "minecraft:tuff_bricks"},
        {pos: [4, 4, 4], state: "minecraft:tuff_bricks"},
        {pos: [5, 4, 0], state: "minecraft:tuff_bricks"},
        {pos: [5, 4, 1], state: "minecraft:tuff_bricks"},
        {pos: [5, 4, 2], state: "minecraft:tuff_bricks"},
        {pos: [5, 4, 3], state: "minecraft:tuff_bricks"},
        {pos: [5, 4, 4], state: "minecraft:waxed_copper_block"},
        {pos: [6, 4, 0], state: "minecraft:polished_tuff"},
        {pos: [6, 4, 1], state: "minecraft:polished_tuff"},
        {pos: [6, 4, 2], state: "minecraft:polished_tuff"},
        {pos: [6, 4, 3], state: "minecraft:polished_tuff"},
        {pos: [6, 4, 4], state: "minecraft:polished_tuff"},
        {pos: [7, 4, 0], state: "minecraft:polished_tuff"},
        {pos: [7, 4, 1], state: "minecraft:polished_tuff"},
        {pos: [7, 4, 2], state: "minecraft:polished_tuff"},
        {pos: [7, 4, 3], state: "minecraft:polished_tuff"},
        {pos: [7, 4, 4], state: "minecraft:polished_tuff"},
        {pos: [8, 4, 0], state: "minecraft:polished_tuff"},
        {pos: [8, 4, 1], state: "minecraft:polished_tuff"},
        {pos: [8, 4, 2], state: "minecraft:polished_tuff"},
        {pos: [8, 4, 3], state: "minecraft:polished_tuff"},
        {pos: [8, 4, 4], state: "minecraft:polished_tuff"},
        {pos: [9, 4, 0], state: "minecraft:tuff_bricks"},
        {pos: [9, 4, 1], state: "minecraft:tuff_bricks"},
        {pos: [9, 4, 2], state: "minecraft:tuff_bricks"},
        {pos: [9, 4, 3], state: "minecraft:tuff_bricks"},
        {pos: [9, 4, 4], state: "minecraft:waxed_copper_block"},
        {pos: [10, 4, 0], state: "minecraft:air"},
        {pos: [10, 4, 1], state: "minecraft:air"},
        {pos: [10, 4, 2], state: "minecraft:air"},
        {pos: [10, 4, 3], state: "minecraft:air"},
        {pos: [10, 4, 4], state: "minecraft:air"},
        {pos: [0, 5, 0], state: "minecraft:waxed_copper_block"},
        {pos: [0, 5, 1], state: "minecraft:waxed_copper_block"},
        {pos: [0, 5, 2], state: "minecraft:waxed_copper_block"},
        {pos: [0, 5, 3], state: "minecraft:waxed_copper_block"},
        {pos: [0, 5, 4], state: "minecraft:waxed_copper_block"},
        {pos: [1, 5, 0], state: "minecraft:waxed_oxidized_cut_copper"},
        {pos: [1, 5, 1], state: "minecraft:waxed_oxidized_copper"},
        {pos: [1, 5, 2], state: "minecraft:waxed_oxidized_copper"},
        {pos: [1, 5, 3], state: "minecraft:waxed_oxidized_cut_copper"},
        {pos: [1, 5, 4], state: "minecraft:waxed_copper_block"},
        {pos: [2, 5, 0], state: "minecraft:waxed_oxidized_cut_copper"},
        {pos: [2, 5, 1], state: "minecraft:waxed_oxidized_copper"},
        {pos: [2, 5, 2], state: "minecraft:waxed_oxidized_copper"},
        {pos: [2, 5, 3], state: "minecraft:waxed_oxidized_cut_copper"},
        {pos: [2, 5, 4], state: "minecraft:waxed_copper_block"},
        {pos: [3, 5, 0], state: "minecraft:waxed_oxidized_cut_copper"},
        {pos: [3, 5, 1], state: "minecraft:waxed_oxidized_copper"},
        {pos: [3, 5, 2], state: "minecraft:waxed_oxidized_copper"},
        {pos: [3, 5, 3], state: "minecraft:waxed_oxidized_cut_copper"},
        {pos: [3, 5, 4], state: "minecraft:waxed_copper_block"},
        {pos: [4, 5, 0], state: "minecraft:waxed_oxidized_cut_copper"},
        {pos: [4, 5, 1], state: "minecraft:waxed_oxidized_copper"},
        {pos: [4, 5, 2], state: "minecraft:waxed_oxidized_copper"},
        {pos: [4, 5, 3], state: "minecraft:waxed_oxidized_cut_copper"},
        {pos: [4, 5, 4], state: "minecraft:waxed_copper_block"},
        {pos: [5, 5, 0], state: "minecraft:waxed_oxidized_cut_copper"},
        {pos: [5, 5, 1], state: "minecraft:waxed_oxidized_copper"},
        {pos: [5, 5, 2], state: "minecraft:waxed_oxidized_copper"},
        {pos: [5, 5, 3], state: "minecraft:waxed_oxidized_cut_copper"},
        {pos: [5, 5, 4], state: "minecraft:waxed_copper_block"},
        {pos: [6, 5, 0], state: "minecraft:waxed_oxidized_cut_copper"},
        {pos: [6, 5, 1], state: "minecraft:waxed_oxidized_copper"},
        {pos: [6, 5, 2], state: "minecraft:waxed_oxidized_copper"},
        {pos: [6, 5, 3], state: "minecraft:waxed_oxidized_cut_copper"},
        {pos: [6, 5, 4], state: "minecraft:waxed_oxidized_cut_copper"},
        {pos: [7, 5, 0], state: "minecraft:waxed_oxidized_cut_copper"},
        {pos: [7, 5, 1], state: "minecraft:waxed_oxidized_copper"},
        {pos: [7, 5, 2], state: "minecraft:waxed_oxidized_copper"},
        {pos: [7, 5, 3], state: "minecraft:waxed_oxidized_copper"},
        {pos: [7, 5, 4], state: "minecraft:waxed_oxidized_copper"},
        {pos: [8, 5, 0], state: "minecraft:waxed_oxidized_cut_copper"},
        {pos: [8, 5, 1], state: "minecraft:waxed_oxidized_cut_copper"},
        {pos: [8, 5, 2], state: "minecraft:waxed_oxidized_cut_copper"},
        {pos: [8, 5, 3], state: "minecraft:waxed_oxidized_cut_copper"},
        {pos: [8, 5, 4], state: "minecraft:waxed_oxidized_cut_copper"},
        {pos: [9, 5, 0], state: "minecraft:waxed_copper_block"},
        {pos: [9, 5, 1], state: "minecraft:waxed_copper_block"},
        {pos: [9, 5, 2], state: "minecraft:waxed_copper_block"},
        {pos: [9, 5, 3], state: "minecraft:waxed_copper_block"},
        {pos: [9, 5, 4], state: "minecraft:waxed_copper_block"},
        {pos: [10, 5, 0], state: "minecraft:air"},
        {pos: [10, 5, 1], state: "minecraft:air"},
        {pos: [10, 5, 2], state: "minecraft:air"},
        {pos: [10, 5, 3], state: "minecraft:air"},
        {pos: [10, 5, 4], state: "minecraft:air"}
    ],
    entities: [],
    palette: [
        "minecraft:tuff_bricks",
        "minecraft:waxed_oxidized_copper",
        "minecraft:waxed_copper_block",
        "minecraft:polished_tuff",
        "minecraft:waxed_oxidized_cut_copper",
        "minecraft:air",
        "minecraft:lantern{hanging:true,waterlogged:false}",
        "minecraft:jigsaw{orientation:north_up}",
        "minecraft:jigsaw{orientation:south_up}"
    ]
}
