{
    size: [6, 12, 32],
    data: [
        {pos: [0, 0, 1], state: "minecraft:tuff_bricks"},
        {pos: [0, 0, 2], state: "minecraft:tuff_bricks"},
        {pos: [0, 0, 3], state: "minecraft:tuff_bricks"},
        {pos: [0, 0, 4], state: "minecraft:tuff_bricks"},
        {pos: [0, 0, 5], state: "minecraft:tuff_bricks"},
        {pos: [0, 0, 6], state: "minecraft:tuff_bricks"},
        {pos: [0, 0, 7], state: "minecraft:tuff_bricks"},
        {pos: [0, 0, 8], state: "minecraft:tuff_bricks"},
        {pos: [0, 0, 9], state: "minecraft:tuff_bricks"},
        {pos: [0, 0, 10], state: "minecraft:tuff_bricks"},
        {pos: [0, 0, 11], state: "minecraft:tuff_bricks"},
        {pos: [0, 0, 12], state: "minecraft:tuff_bricks"},
        {pos: [0, 0, 13], state: "minecraft:tuff_bricks"},
        {pos: [0, 0, 14], state: "minecraft:tuff_bricks"},
        {pos: [0, 0, 15], state: "minecraft:tuff_bricks"},
        {pos: [0, 0, 16], state: "minecraft:tuff_bricks"},
        {pos: [0, 0, 17], state: "minecraft:tuff_bricks"},
        {pos: [0, 0, 18], state: "minecraft:tuff_bricks"},
        {pos: [0, 0, 19], state: "minecraft:tuff_bricks"},
        {pos: [0, 0, 20], state: "minecraft:tuff_bricks"},
        {pos: [0, 0, 21], state: "minecraft:tuff_bricks"},
        {pos: [0, 0, 22], state: "minecraft:tuff_bricks"},
        {pos: [0, 0, 23], state: "minecraft:tuff_bricks"},
        {pos: [0, 0, 24], state: "minecraft:tuff_bricks"},
        {pos: [0, 0, 25], state: "minecraft:tuff_bricks"},
        {pos: [0, 0, 26], state: "minecraft:tuff_bricks"},
        {pos: [0, 0, 27], state: "minecraft:tuff_bricks"},
        {pos: [0, 0, 28], state: "minecraft:tuff_bricks"},
        {pos: [0, 0, 29], state: "minecraft:tuff_bricks"},
        {pos: [0, 0, 30], state: "minecraft:tuff_bricks"},
        {pos: [1, 0, 1], state: "minecraft:tuff_bricks"},
        {pos: [1, 0, 2], state: "minecraft:tuff_bricks"},
        {pos: [1, 0, 3], state: "minecraft:tuff_bricks"},
        {pos: [1, 0, 4], state: "minecraft:tuff_bricks"},
        {pos: [1, 0, 5], state: "minecraft:tuff_bricks"},
        {pos: [1, 0, 6], state: "minecraft:tuff_bricks"},
        {pos: [1, 0, 7], state: "minecraft:tuff_bricks"},
        {pos: [1, 0, 8], state: "minecraft:tuff_bricks"},
        {pos: [1, 0, 9], state: "minecraft:tuff_bricks"},
        {pos: [1, 0, 10], state: "minecraft:tuff_bricks"},
        {pos: [1, 0, 11], state: "minecraft:tuff_bricks"},
        {pos: [1, 0, 12], state: "minecraft:tuff_bricks"},
        {pos: [1, 0, 13], state: "minecraft:tuff_bricks"},
        {pos: [1, 0, 14], state: "minecraft:tuff_bricks"},
        {pos: [1, 0, 15], state: "minecraft:tuff_bricks"},
        {pos: [1, 0, 16], state: "minecraft:tuff_bricks"},
        {pos: [1, 0, 17], state: "minecraft:tuff_bricks"},
        {pos: [1, 0, 18], state: "minecraft:tuff_bricks"},
        {pos: [1, 0, 19], state: "minecraft:tuff_bricks"},
        {pos: [1, 0, 20], state: "minecraft:tuff_bricks"},
        {pos: [1, 0, 21], state: "minecraft:tuff_bricks"},
        {pos: [1, 0, 22], state: "minecraft:tuff_bricks"},
        {pos: [1, 0, 23], state: "minecraft:tuff_bricks"},
        {pos: [1, 0, 24], state: "minecraft:tuff_bricks"},
        {pos: [1, 0, 25], state: "minecraft:tuff_bricks"},
        {pos: [1, 0, 26], state: "minecraft:tuff_bricks"},
        {pos: [1, 0, 27], state: "minecraft:tuff_bricks"},
        {pos: [1, 0, 28], state: "minecraft:tuff_bricks"},
        {pos: [1, 0, 29], state: "minecraft:tuff_bricks"},
        {pos: [1, 0, 30], state: "minecraft:tuff_bricks"},
        {pos: [2, 0, 1], state: "minecraft:tuff_bricks"},
        {pos: [2, 0, 2], state: "minecraft:tuff_bricks"},
        {pos: [2, 0, 3], state: "minecraft:tuff_bricks"},
        {pos: [2, 0, 4], state: "minecraft:tuff_bricks"},
        {pos: [2, 0, 5], state: "minecraft:tuff_bricks"},
        {pos: [2, 0, 6], state: "minecraft:tuff_bricks"},
        {pos: [2, 0, 7], state: "minecraft:tuff_bricks"},
        {pos: [2, 0, 8], state: "minecraft:tuff_bricks"},
        {pos: [2, 0, 9], state: "minecraft:tuff_bricks"},
        {pos: [2, 0, 10], state: "minecraft:tuff_bricks"},
        {pos: [2, 0, 11], state: "minecraft:tuff_bricks"},
        {pos: [2, 0, 12], state: "minecraft:tuff_bricks"},
        {pos: [2, 0, 13], state: "minecraft:tuff_bricks"},
        {pos: [2, 0, 14], state: "minecraft:tuff_bricks"},
        {pos: [2, 0, 15], state: "minecraft:tuff_bricks"},
        {pos: [2, 0, 16], state: "minecraft:tuff_bricks"},
        {pos: [2, 0, 17], state: "minecraft:tuff_bricks"},
        {pos: [2, 0, 18], state: "minecraft:tuff_bricks"},
        {pos: [2, 0, 19], state: "minecraft:tuff_bricks"},
        {pos: [2, 0, 20], state: "minecraft:tuff_bricks"},
        {pos: [2, 0, 21], state: "minecraft:tuff_bricks"},
        {pos: [2, 0, 22], state: "minecraft:tuff_bricks"},
        {pos: [2, 0, 23], state: "minecraft:tuff_bricks"},
        {pos: [2, 0, 24], state: "minecraft:tuff_bricks"},
        {pos: [2, 0, 25], state: "minecraft:tuff_bricks"},
        {pos: [2, 0, 26], state: "minecraft:tuff_bricks"},
        {pos: [2, 0, 27], state: "minecraft:tuff_bricks"},
        {pos: [2, 0, 28], state: "minecraft:tuff_bricks"},
        {pos: [2, 0, 29], state: "minecraft:tuff_bricks"},
        {pos: [2, 0, 30], state: "minecraft:tuff_bricks"},
        {pos: [3, 0, 1], state: "minecraft:tuff_bricks"},
        {pos: [3, 0, 2], state: "minecraft:tuff_bricks"},
        {pos: [3, 0, 3], state: "minecraft:tuff_bricks"},
        {pos: [3, 0, 4], state: "minecraft:tuff_bricks"},
        {pos: [3, 0, 5], state: "minecraft:tuff_bricks"},
        {pos: [3, 0, 6], state: "minecraft:tuff_bricks"},
        {pos: [3, 0, 7], state: "minecraft:tuff_bricks"},
        {pos: [3, 0, 8], state: "minecraft:tuff_bricks"},
        {pos: [3, 0, 9], state: "minecraft:tuff_bricks"},
        {pos: [3, 0, 10], state: "minecraft:tuff_bricks"},
        {pos: [3, 0, 11], state: "minecraft:tuff_bricks"},
        {pos: [3, 0, 12], state: "minecraft:tuff_bricks"},
        {pos: [3, 0, 13], state: "minecraft:tuff_bricks"},
        {pos: [3, 0, 14], state: "minecraft:tuff_bricks"},
        {pos: [3, 0, 15], state: "minecraft:tuff_bricks"},
        {pos: [3, 0, 16], state: "minecraft:tuff_bricks"},
        {pos: [3, 0, 17], state: "minecraft:tuff_bricks"},
        {pos: [3, 0, 18], state: "minecraft:tuff_bricks"},
        {pos: [3, 0, 19], state: "minecraft:tuff_bricks"},
        {pos: [3, 0, 20], state: "minecraft:tuff_bricks"},
        {pos: [3, 0, 21], state: "minecraft:tuff_bricks"},
        {pos: [3, 0, 22], state: "minecraft:tuff_bricks"},
        {pos: [3, 0, 23], state: "minecraft:tuff_bricks"},
        {pos: [3, 0, 24], state: "minecraft:tuff_bricks"},
        {pos: [3, 0, 25], state: "minecraft:tuff_bricks"},
        {pos: [3, 0, 26], state: "minecraft:tuff_bricks"},
        {pos: [3, 0, 27], state: "minecraft:tuff_bricks"},
        {pos: [3, 0, 28], state: "minecraft:tuff_bricks"},
        {pos: [3, 0, 29], state: "minecraft:tuff_bricks"},
        {pos: [3, 0, 30], state: "minecraft:tuff_bricks"},
        {pos: [4, 0, 1], state: "minecraft:tuff_bricks"},
        {pos: [4, 0, 2], state: "minecraft:tuff_bricks"},
        {pos: [4, 0, 3], state: "minecraft:tuff_bricks"},
        {pos: [4, 0, 4], state: "minecraft:tuff_bricks"},
        {pos: [4, 0, 5], state: "minecraft:tuff_bricks"},
        {pos: [4, 0, 6], state: "minecraft:tuff_bricks"},
        {pos: [4, 0, 7], state: "minecraft:tuff_bricks"},
        {pos: [4, 0, 8], state: "minecraft:tuff_bricks"},
        {pos: [4, 0, 9], state: "minecraft:tuff_bricks"},
        {pos: [4, 0, 10], state: "minecraft:tuff_bricks"},
        {pos: [4, 0, 11], state: "minecraft:tuff_bricks"},
        {pos: [4, 0, 12], state: "minecraft:tuff_bricks"},
        {pos: [4, 0, 13], state: "minecraft:tuff_bricks"},
        {pos: [4, 0, 14], state: "minecraft:tuff_bricks"},
        {pos: [4, 0, 15], state: "minecraft:tuff_bricks"},
        {pos: [4, 0, 16], state: "minecraft:tuff_bricks"},
        {pos: [4, 0, 17], state: "minecraft:tuff_bricks"},
        {pos: [4, 0, 18], state: "minecraft:tuff_bricks"},
        {pos: [4, 0, 19], state: "minecraft:tuff_bricks"},
        {pos: [4, 0, 20], state: "minecraft:tuff_bricks"},
        {pos: [4, 0, 21], state: "minecraft:tuff_bricks"},
        {pos: [4, 0, 22], state: "minecraft:tuff_bricks"},
        {pos: [4, 0, 23], state: "minecraft:tuff_bricks"},
        {pos: [4, 0, 24], state: "minecraft:tuff_bricks"},
        {pos: [4, 0, 25], state: "minecraft:tuff_bricks"},
        {pos: [4, 0, 26], state: "minecraft:tuff_bricks"},
        {pos: [4, 0, 27], state: "minecraft:tuff_bricks"},
        {pos: [4, 0, 28], state: "minecraft:tuff_bricks"},
        {pos: [4, 0, 29], state: "minecraft:tuff_bricks"},
        {pos: [4, 0, 30], state: "minecraft:tuff_bricks"},
        {pos: [0, 1, 1], state: "minecraft:waxed_copper_block"},
        {pos: [0, 1, 2], state: "minecraft:waxed_oxidized_cut_copper_stairs{facing:east,half:bottom,shape:straight,waterlogged:false}"},
        {pos: [0, 1, 3], state: "minecraft:waxed_oxidized_cut_copper_stairs{facing:east,half:bottom,shape:straight,waterlogged:false}"},
        {pos: [0, 1, 4], state: "minecraft:waxed_oxidized_cut_copper_stairs{facing:east,half:bottom,shape:straight,waterlogged:false}"},
        {pos: [0, 1, 5], state: "minecraft:waxed_copper_block"},
        {pos: [0, 1, 6], state: "minecraft:waxed_copper_block"},
        {pos: [0, 1, 7], state: "minecraft:waxed_copper_block"},
        {pos: [0, 1, 8], state: "minecraft:waxed_copper_block"},
        {pos: [0, 1, 9], state: "minecraft:waxed_copper_block"},
        {pos: [0, 1, 10], state: "minecraft:waxed_copper_block"},
        {pos: [0, 1, 11], state: "minecraft:waxed_copper_block"},
        {pos: [0, 1, 12], state: "minecraft:waxed_copper_block"},
        {pos: [0, 1, 13], state: "minecraft:waxed_copper_block"},
        {pos: [0, 1, 14], state: "minecraft:waxed_copper_block"},
        {pos: [0, 1, 15], state: "minecraft:waxed_copper_block"},
        {pos: [0, 1, 16], state: "minecraft:waxed_copper_block"},
        {pos: [0, 1, 17], state: "minecraft:waxed_copper_block"},
        {pos: [0, 1, 18], state: "minecraft:waxed_copper_block"},
        {pos: [0, 1, 19], state: "minecraft:waxed_copper_block"},
        {pos: [0, 1, 20], state: "minecraft:waxed_copper_block"},
        {pos: [0, 1, 21], state: "minecraft:waxed_copper_block"},
        {pos: [0, 1, 22], state: "minecraft:waxed_copper_block"},
        {pos: [0, 1, 23], state: "minecraft:waxed_copper_block"},
        {pos: [0, 1, 24], state: "minecraft:waxed_copper_block"},
        {pos: [0, 1, 25], state: "minecraft:waxed_copper_block"},
        {pos: [0, 1, 26], state: "minecraft:waxed_copper_block"},
        {pos: [0, 1, 27], state: "minecraft:waxed_oxidized_cut_copper_stairs{facing:east,half:bottom,shape:straight,waterlogged:false}"},
        {pos: [0, 1, 28], state: "minecraft:waxed_oxidized_cut_copper_stairs{facing:east,half:bottom,shape:straight,waterlogged:false}"},
        {pos: [0, 1, 29], state: "minecraft:waxed_oxidized_cut_copper_stairs{facing:east,half:bottom,shape:straight,waterlogged:false}"},
        {pos: [0, 1, 30], state: "minecraft:tuff_bricks"},
        {pos: [1, 1, 1], state: "minecraft:tuff_bricks"},
        {pos: [1, 1, 2], state: "minecraft:tuff_bricks"},
        {pos: [1, 1, 3], state: "minecraft:tuff_bricks"},
        {pos: [1, 1, 4], state: "minecraft:tuff_bricks"},
        {pos: [1, 1, 5], state: "minecraft:tuff_bricks"},
        {pos: [1, 1, 6], state: "minecraft:tuff_bricks"},
        {pos: [1, 1, 7], state: "minecraft:tuff_bricks"},
        {pos: [1, 1, 8], state: "minecraft:tuff_bricks"},
        {pos: [1, 1, 9], state: "minecraft:tuff_bricks"},
        {pos: [1, 1, 10], state: "minecraft:tuff_bricks"},
        {pos: [1, 1, 11], state: "minecraft:tuff_bricks"},
        {pos: [1, 1, 12], state: "minecraft:tuff_bricks"},
        {pos: [1, 1, 13], state: "minecraft:tuff_bricks"},
        {pos: [1, 1, 14], state: "minecraft:tuff_bricks"},
        {pos: [1, 1, 15], state: "minecraft:tuff_bricks"},
        {pos: [1, 1, 16], state: "minecraft:tuff_bricks"},
        {pos: [1, 1, 17], state: "minecraft:tuff_bricks"},
        {pos: [1, 1, 18], state: "minecraft:tuff_bricks"},
        {pos: [1, 1, 19], state: "minecraft:tuff_bricks"},
        {pos: [1, 1, 20], state: "minecraft:tuff_bricks"},
        {pos: [1, 1, 21], state: "minecraft:tuff_bricks"},
        {pos: [1, 1, 22], state: "minecraft:tuff_bricks"},
        {pos: [1, 1, 23], state: "minecraft:tuff_bricks"},
        {pos: [1, 1, 24], state: "minecraft:tuff_bricks"},
        {pos: [1, 1, 25], state: "minecraft:tuff_bricks"},
        {pos: [1, 1, 26], state: "minecraft:tuff_bricks"},
        {pos: [1, 1, 27], state: "minecraft:tuff_bricks"},
        {pos: [1, 1, 28], state: "minecraft:tuff_bricks"},
        {pos: [1, 1, 29], state: "minecraft:tuff_bricks"},
        {pos: [1, 1, 30], state: "minecraft:tuff_bricks"},
        {pos: [2, 1, 1], state: "minecraft:tuff_bricks"},
        {pos: [2, 1, 2], state: "minecraft:tuff_bricks"},
        {pos: [2, 1, 3], state: "minecraft:tuff_bricks"},
        {pos: [2, 1, 4], state: "minecraft:tuff_bricks"},
        {pos: [2, 1, 5], state: "minecraft:tuff_bricks"},
        {pos: [2, 1, 6], state: "minecraft:tuff_bricks"},
        {pos: [2, 1, 7], state: "minecraft:tuff_bricks"},
        {pos: [2, 1, 8], state: "minecraft:tuff_bricks"},
        {pos: [2, 1, 9], state: "minecraft:tuff_bricks"},
        {pos: [2, 1, 10], state: "minecraft:tuff_bricks"},
        {pos: [2, 1, 11], state: "minecraft:tuff_bricks"},
        {pos: [2, 1, 12], state: "minecraft:tuff_bricks"},
        {pos: [2, 1, 13], state: "minecraft:tuff_bricks"},
        {pos: [2, 1, 14], state: "minecraft:tuff_bricks"},
        {pos: [2, 1, 15], state: "minecraft:tuff_bricks"},
        {pos: [2, 1, 16], state: "minecraft:tuff_bricks"},
        {pos: [2, 1, 17], state: "minecraft:tuff_bricks"},
        {pos: [2, 1, 18], state: "minecraft:tuff_bricks"},
        {pos: [2, 1, 19], state: "minecraft:tuff_bricks"},
        {pos: [2, 1, 20], state: "minecraft:tuff_bricks"},
        {pos: [2, 1, 21], state: "minecraft:tuff_bricks"},
        {pos: [2, 1, 22], state: "minecraft:tuff_bricks"},
        {pos: [2, 1, 23], state: "minecraft:tuff_bricks"},
        {pos: [2, 1, 24], state: "minecraft:tuff_bricks"},
        {pos: [2, 1, 25], state: "minecraft:tuff_bricks"},
        {pos: [2, 1, 26], state: "minecraft:tuff_bricks"},
        {pos: [2, 1, 27], state: "minecraft:tuff_bricks"},
        {pos: [2, 1, 28], state: "minecraft:tuff_bricks"},
        {pos: [2, 1, 29], state: "minecraft:tuff_bricks"},
        {pos: [2, 1, 30], state: "minecraft:tuff_bricks"},
        {pos: [3, 1, 1], state: "minecraft:tuff_bricks"},
        {pos: [3, 1, 2], state: "minecraft:tuff_bricks"},
        {pos: [3, 1, 3], state: "minecraft:tuff_bricks"},
        {pos: [3, 1, 4], state: "minecraft:tuff_bricks"},
        {pos: [3, 1, 5], state: "minecraft:tuff_bricks"},
        {pos: [3, 1, 6], state: "minecraft:tuff_bricks"},
        {pos: [3, 1, 7], state: "minecraft:tuff_bricks"},
        {pos: [3, 1, 8], state: "minecraft:tuff_bricks"},
        {pos: [3, 1, 9], state: "minecraft:tuff_bricks"},
        {pos: [3, 1, 10], state: "minecraft:tuff_bricks"},
        {pos: [3, 1, 11], state: "minecraft:tuff_bricks"},
        {pos: [3, 1, 12], state: "minecraft:tuff_bricks"},
        {pos: [3, 1, 13], state: "minecraft:tuff_bricks"},
        {pos: [3, 1, 14], state: "minecraft:tuff_bricks"},
        {pos: [3, 1, 15], state: "minecraft:tuff_bricks"},
        {pos: [3, 1, 16], state: "minecraft:tuff_bricks"},
        {pos: [3, 1, 17], state: "minecraft:tuff_bricks"},
        {pos: [3, 1, 18], state: "minecraft:tuff_bricks"},
        {pos: [3, 1, 19], state: "minecraft:tuff_bricks"},
        {pos: [3, 1, 20], state: "minecraft:tuff_bricks"},
        {pos: [3, 1, 21], state: "minecraft:tuff_bricks"},
        {pos: [3, 1, 22], state: "minecraft:tuff_bricks"},
        {pos: [3, 1, 23], state: "minecraft:tuff_bricks"},
        {pos: [3, 1, 24], state: "minecraft:tuff_bricks"},
        {pos: [3, 1, 25], state: "minecraft:tuff_bricks"},
        {pos: [3, 1, 26], state: "minecraft:tuff_bricks"},
        {pos: [3, 1, 27], state: "minecraft:tuff_bricks"},
        {pos: [3, 1, 28], state: "minecraft:tuff_bricks"},
        {pos: [3, 1, 29], state: "minecraft:tuff_bricks"},
        {pos: [3, 1, 30], state: "minecraft:tuff_bricks"},
        {pos: [4, 1, 1], state: "minecraft:tuff_bricks"},
        {pos: [4, 1, 2], state: "minecraft:tuff_bricks"},
        {pos: [4, 1, 3], state: "minecraft:tuff_bricks"},
        {pos: [4, 1, 4], state: "minecraft:tuff_bricks"},
        {pos: [4, 1, 5], state: "minecraft:tuff_bricks"},
        {pos: [4, 1, 6], state: "minecraft:tuff_bricks"},
        {pos: [4, 1, 7], state: "minecraft:tuff_bricks"},
        {pos: [4, 1, 8], state: "minecraft:tuff_bricks"},
        {pos: [4, 1, 9], state: "minecraft:tuff_bricks"},
        {pos: [4, 1, 10], state: "minecraft:tuff_bricks"},
        {pos: [4, 1, 11], state: "minecraft:tuff_bricks"},
        {pos: [4, 1, 12], state: "minecraft:tuff_bricks"},
        {pos: [4, 1, 13], state: "minecraft:tuff_bricks"},
        {pos: [4, 1, 14], state: "minecraft:tuff_bricks"},
        {pos: [4, 1, 15], state: "minecraft:tuff_bricks"},
        {pos: [4, 1, 16], state: "minecraft:tuff_bricks"},
        {pos: [4, 1, 17], state: "minecraft:tuff_bricks"},
        {pos: [4, 1, 18], state: "minecraft:tuff_bricks"},
        {pos: [4, 1, 19], state: "minecraft:tuff_bricks"},
        {pos: [4, 1, 20], state: "minecraft:tuff_bricks"},
        {pos: [4, 1, 21], state: "minecraft:tuff_bricks"},
        {pos: [4, 1, 22], state: "minecraft:tuff_bricks"},
        {pos: [4, 1, 23], state: "minecraft:tuff_bricks"},
        {pos: [4, 1, 24], state: "minecraft:tuff_bricks"},
        {pos: [4, 1, 25], state: "minecraft:tuff_bricks"},
        {pos: [4, 1, 26], state: "minecraft:tuff_bricks"},
        {pos: [4, 1, 27], state: "minecraft:tuff_bricks"},
        {pos: [4, 1, 28], state: "minecraft:tuff_bricks"},
        {pos: [4, 1, 29], state: "minecraft:tuff_bricks"},
        {pos: [4, 1, 30], state: "minecraft:tuff_bricks"},
        {pos: [0, 2, 1], state: "minecraft:tuff_bricks"},
        {pos: [0, 2, 2], state: "minecraft:air"},
        {pos: [0, 2, 3], state: "minecraft:air"},
        {pos: [0, 2, 4], state: "minecraft:air"},
        {pos: [0, 2, 5], state: "minecraft:waxed_copper_block"},
        {pos: [0, 2, 6], state: "minecraft:waxed_copper_block"},
        {pos: [0, 2, 7], state: "minecraft:waxed_copper_block"},
        {pos: [0, 2, 8], state: "minecraft:waxed_copper_block"},
        {pos: [0, 2, 9], state: "minecraft:waxed_copper_block"},
        {pos: [0, 2, 10], state: "minecraft:waxed_copper_block"},
        {pos: [0, 2, 11], state: "minecraft:waxed_copper_block"},
        {pos: [0, 2, 12], state: "minecraft:waxed_copper_block"},
        {pos: [0, 2, 13], state: "minecraft:waxed_copper_block"},
        {pos: [0, 2, 14], state: "minecraft:tuff_bricks"},
        {pos: [0, 2, 15], state: "minecraft:tuff_bricks"},
        {pos: [0, 2, 16], state: "minecraft:tuff_bricks"},
        {pos: [0, 2, 17], state: "minecraft:tuff_bricks"},
        {pos: [0, 2, 18], state: "minecraft:waxed_copper_bulb{lit:true,powered:false}"},
        {pos: [0, 2, 19], state: "minecraft:tuff_bricks"},
        {pos: [0, 2, 20], state: "minecraft:tuff_bricks"},
        {pos: [0, 2, 21], state: "minecraft:tuff_bricks"},
        {pos: [0, 2, 22], state: "minecraft:tuff_bricks"},
        {pos: [0, 2, 23], state: "minecraft:waxed_copper_block"},
        {pos: [0, 2, 24], state: "minecraft:waxed_copper_block"},
        {pos: [0, 2, 25], state: "minecraft:waxed_copper_block"},
        {pos: [0, 2, 26], state: "minecraft:waxed_copper_block"},
        {pos: [0, 2, 27], state: "minecraft:air"},
        {pos: [0, 2, 28], state: "minecraft:air"},
        {pos: [0, 2, 29], state: "minecraft:air"},
        {pos: [0, 2, 30], state: "minecraft:tuff_bricks"},
        {pos: [1, 2, 1], state: "minecraft:waxed_oxidized_cut_copper"},
        {pos: [1, 2, 2], state: "minecraft:waxed_oxidized_cut_copper_stairs{facing:east,half:bottom,shape:straight,waterlogged:false}"},
        {pos: [1, 2, 3], state: "minecraft:waxed_oxidized_cut_copper_stairs{facing:east,half:bottom,shape:straight,waterlogged:false}"},
        {pos: [1, 2, 4], state: "minecraft:waxed_oxidized_cut_copper_stairs{facing:east,half:bottom,shape:straight,waterlogged:false}"},
        {pos: [1, 2, 5], state: "minecraft:waxed_oxidized_copper"},
        {pos: [1, 2, 6], state: "minecraft:waxed_oxidized_copper"},
        {pos: [1, 2, 7], state: "minecraft:waxed_oxidized_copper"},
        {pos: [1, 2, 8], state: "minecraft:waxed_oxidized_copper"},
        {pos: [1, 2, 9], state: "minecraft:waxed_oxidized_copper"},
        {pos: [1, 2, 10], state: "minecraft:waxed_oxidized_copper"},
        {pos: [1, 2, 11], state: "minecraft:waxed_oxidized_copper"},
        {pos: [1, 2, 12], state: "minecraft:waxed_oxidized_copper"},
        {pos: [1, 2, 13], state: "minecraft:tuff_bricks"},
        {pos: [1, 2, 14], state: "minecraft:tuff_bricks"},
        {pos: [1, 2, 15], state: "minecraft:tuff_bricks"},
        {pos: [1, 2, 16], state: "minecraft:tuff_bricks"},
        {pos: [1, 2, 17], state: "minecraft:tuff_bricks"},
        {pos: [1, 2, 18], state: "minecraft:tuff_bricks"},
        {pos: [1, 2, 19], state: "minecraft:tuff_bricks"},
        {pos: [1, 2, 20], state: "minecraft:tuff_bricks"},
        {pos: [1, 2, 21], state: "minecraft:tuff_bricks"},
        {pos: [1, 2, 22], state: "minecraft:tuff_bricks"},
        {pos: [1, 2, 23], state: "minecraft:tuff_bricks"},
        {pos: [1, 2, 24], state: "minecraft:waxed_oxidized_copper"},
        {pos: [1, 2, 25], state: "minecraft:waxed_oxidized_copper"},
        {pos: [1, 2, 26], state: "minecraft:waxed_oxidized_copper"},
        {pos: [1, 2, 27], state: "minecraft:waxed_oxidized_cut_copper_stairs{facing:east,half:bottom,shape:straight,waterlogged:false}"},
        {pos: [1, 2, 28], state: "minecraft:waxed_oxidized_cut_copper_stairs{facing:east,half:bottom,shape:straight,waterlogged:false}"},
        {pos: [1, 2, 29], state: "minecraft:waxed_oxidized_cut_copper_stairs{facing:east,half:bottom,shape:straight,waterlogged:false}"},
        {pos: [1, 2, 30], state: "minecraft:waxed_oxidized_cut_copper"},
        {pos: [2, 2, 1], state: "minecraft:waxed_oxidized_cut_copper"},
        {pos: [2, 2, 2], state: "minecraft:waxed_oxidized_copper"},
        {pos: [2, 2, 3], state: "minecraft:waxed_oxidized_copper"},
        {pos: [2, 2, 4], state: "minecraft:waxed_oxidized_copper"},
        {pos: [2, 2, 5], state: "minecraft:waxed_oxidized_copper"},
        {pos: [2, 2, 6], state: "minecraft:waxed_oxidized_copper"},
        {pos: [2, 2, 7], state: "minecraft:waxed_oxidized_copper"},
        {pos: [2, 2, 8], state: "minecraft:waxed_oxidized_copper"},
        {pos: [2, 2, 9], state: "minecraft:waxed_oxidized_copper"},
        {pos: [2, 2, 10], state: "minecraft:waxed_oxidized_copper"},
        {pos: [2, 2, 11], state: "minecraft:waxed_oxidized_copper"},
        {pos: [2, 2, 12], state: "minecraft:waxed_oxidized_copper"},
        {pos: [2, 2, 13], state: "minecraft:tuff_bricks"},
        {pos: [2, 2, 14], state: "minecraft:tuff_bricks"},
        {pos: [2, 2, 15], state: "minecraft:tuff_bricks"},
        {pos: [2, 2, 16], state: "minecraft:tuff_bricks"},
        {pos: [2, 2, 17], state: "minecraft:tuff_bricks"},
        {pos: [2, 2, 18], state: "minecraft:tuff_bricks"},
        {pos: [2, 2, 19], state: "minecraft:tuff_bricks"},
        {pos: [2, 2, 20], state: "minecraft:tuff_bricks"},
        {pos: [2, 2, 21], state: "minecraft:tuff_bricks"},
        {pos: [2, 2, 22], state: "minecraft:tuff_bricks"},
        {pos: [2, 2, 23], state: "minecraft:tuff_bricks"},
        {pos: [2, 2, 24], state: "minecraft:waxed_oxidized_copper"},
        {pos: [2, 2, 25], state: "minecraft:waxed_oxidized_copper"},
        {pos: [2, 2, 26], state: "minecraft:waxed_oxidized_copper"},
        {pos: [2, 2, 27], state: "minecraft:waxed_oxidized_copper"},
        {pos: [2, 2, 28], state: "minecraft:waxed_oxidized_copper"},
        {pos: [2, 2, 29], state: "minecraft:waxed_oxidized_copper"},
        {pos: [2, 2, 30], state: "minecraft:waxed_oxidized_cut_copper"},
        {pos: [3, 2, 1], state: "minecraft:waxed_oxidized_cut_copper"},
        {pos: [3, 2, 2], state: "minecraft:waxed_oxidized_copper"},
        {pos: [3, 2, 3], state: "minecraft:waxed_oxidized_copper"},
        {pos: [3, 2, 4], state: "minecraft:waxed_oxidized_copper"},
        {pos: [3, 2, 5], state: "minecraft:waxed_oxidized_copper"},
        {pos: [3, 2, 6], state: "minecraft:waxed_oxidized_copper"},
        {pos: [3, 2, 7], state: "minecraft:waxed_oxidized_copper"},
        {pos: [3, 2, 8], state: "minecraft:waxed_oxidized_copper"},
        {pos: [3, 2, 9], state: "minecraft:waxed_oxidized_copper"},
        {pos: [3, 2, 10], state: "minecraft:waxed_oxidized_copper"},
        {pos: [3, 2, 11], state: "minecraft:waxed_oxidized_copper"},
        {pos: [3, 2, 12], state: "minecraft:waxed_oxidized_copper"},
        {pos: [3, 2, 13], state: "minecraft:tuff_bricks"},
        {pos: [3, 2, 14], state: "minecraft:tuff_bricks"},
        {pos: [3, 2, 15], state: "minecraft:tuff_bricks"},
        {pos: [3, 2, 16], state: "minecraft:tuff_bricks"},
        {pos: [3, 2, 17], state: "minecraft:tuff_bricks"},
        {pos: [3, 2, 18], state: "minecraft:tuff_bricks"},
        {pos: [3, 2, 19], state: "minecraft:tuff_bricks"},
        {pos: [3, 2, 20], state: "minecraft:tuff_bricks"},
        {pos: [3, 2, 21], state: "minecraft:tuff_bricks"},
        {pos: [3, 2, 22], state: "minecraft:tuff_bricks"},
        {pos: [3, 2, 23], state: "minecraft:tuff_bricks"},
        {pos: [3, 2, 24], state: "minecraft:waxed_oxidized_copper"},
        {pos: [3, 2, 25], state: "minecraft:waxed_oxidized_copper"},
        {pos: [3, 2, 26], state: "minecraft:waxed_oxidized_copper"},
        {pos: [3, 2, 27], state: "minecraft:waxed_oxidized_copper"},
        {pos: [3, 2, 28], state: "minecraft:waxed_oxidized_copper"},
        {pos: [3, 2, 29], state: "minecraft:waxed_oxidized_copper"},
        {pos: [3, 2, 30], state: "minecraft:waxed_oxidized_cut_copper"},
        {pos: [4, 2, 1], state: "minecraft:tuff_bricks"},
        {pos: [4, 2, 2], state: "minecraft:waxed_oxidized_cut_copper"},
        {pos: [4, 2, 3], state: "minecraft:waxed_oxidized_cut_copper"},
        {pos: [4, 2, 4], state: "minecraft:waxed_oxidized_cut_copper"},
        {pos: [4, 2, 5], state: "minecraft:tuff_bricks"},
        {pos: [4, 2, 6], state: "minecraft:tuff_bricks"},
        {pos: [4, 2, 7], state: "minecraft:waxed_oxidized_cut_copper"},
        {pos: [4, 2, 8], state: "minecraft:waxed_oxidized_cut_copper"},
        {pos: [4, 2, 9], state: "minecraft:waxed_oxidized_cut_copper"},
        {pos: [4, 2, 10], state: "minecraft:tuff_bricks"},
        {pos: [4, 2, 11], state: "minecraft:tuff_bricks"},
        {pos: [4, 2, 12], state: "minecraft:waxed_oxidized_cut_copper"},
        {pos: [4, 2, 13], state: "minecraft:waxed_oxidized_cut_copper"},
        {pos: [4, 2, 14], state: "minecraft:waxed_oxidized_cut_copper"},
        {pos: [4, 2, 15], state: "minecraft:tuff_bricks"},
        {pos: [4, 2, 16], state: "minecraft:tuff_bricks"},
        {pos: [4, 2, 17], state: "minecraft:tuff_bricks"},
        {pos: [4, 2, 18], state: "minecraft:tuff_bricks"},
        {pos: [4, 2, 19], state: "minecraft:tuff_bricks"},
        {pos: [4, 2, 20], state: "minecraft:tuff_bricks"},
        {pos: [4, 2, 21], state: "minecraft:tuff_bricks"},
        {pos: [4, 2, 22], state: "minecraft:waxed_oxidized_cut_copper"},
        {pos: [4, 2, 23], state: "minecraft:waxed_oxidized_cut_copper"},
        {pos: [4, 2, 24], state: "minecraft:waxed_oxidized_cut_copper"},
        {pos: [4, 2, 25], state: "minecraft:tuff_bricks"},
        {pos: [4, 2, 26], state: "minecraft:tuff_bricks"},
        {pos: [4, 2, 27], state: "minecraft:waxed_oxidized_cut_copper"},
        {pos: [4, 2, 28], state: "minecraft:waxed_oxidized_cut_copper"},
        {pos: [4, 2, 29], state: "minecraft:waxed_oxidized_cut_copper"},
        {pos: [4, 2, 30], state: "minecraft:tuff_bricks"},
        {pos: [0, 3, 1], state: "minecraft:chiseled_tuff_bricks"},
        {pos: [0, 3, 2], state: "minecraft:air"},
        {pos: [0, 3, 3], state: "minecraft:air"},
        {pos: [0, 3, 4], state: "minecraft:air"},
        {pos: [0, 3, 5], state: "minecraft:air"},
        {pos: [0, 3, 6], state: "minecraft:air"},
        {pos: [0, 3, 7], state: "minecraft:air"},
        {pos: [0, 3, 8], state: "minecraft:air"},
        {pos: [0, 3, 9], state: "minecraft:air"},
        {pos: [0, 3, 10], state: "minecraft:air"},
        {pos: [0, 3, 11], state: "minecraft:air"},
        {pos: [0, 3, 12], state: "minecraft:air"},
        {pos: [0, 3, 13], state: "minecraft:waxed_copper_block"},
        {pos: [0, 3, 14], state: "minecraft:waxed_copper_block"},
        {pos: [0, 3, 15], state: "minecraft:chiseled_tuff_bricks"},
        {pos: [0, 3, 16], state: "minecraft:chiseled_tuff_bricks"},
        {pos: [0, 3, 17], state: "minecraft:chiseled_tuff_bricks"},
        {pos: [0, 3, 18], state: "minecraft:chiseled_tuff_bricks"},
        {pos: [0, 3, 19], state: "minecraft:chiseled_tuff_bricks"},
        {pos: [0, 3, 20], state: "minecraft:chiseled_tuff_bricks"},
        {pos: [0, 3, 21], state: "minecraft:chiseled_tuff_bricks"},
        {pos: [0, 3, 22], state: "minecraft:waxed_copper_block"},
        {pos: [0, 3, 23], state: "minecraft:waxed_copper_block"},
        {pos: [0, 3, 24], state: "minecraft:air"},
        {pos: [0, 3, 25], state: "minecraft:air"},
        {pos: [0, 3, 26], state: "minecraft:air"},
        {pos: [0, 3, 27], state: "minecraft:air"},
        {pos: [0, 3, 28], state: "minecraft:air"},
        {pos: [0, 3, 29], state: "minecraft:air"},
        {pos: [0, 3, 30], state: "minecraft:chiseled_tuff_bricks"},
        {pos: [1, 3, 1], state: "minecraft:air"},
        {pos: [1, 3, 2], state: "minecraft:air"},
        {pos: [1, 3, 3], state: "minecraft:air"},
        {pos: [1, 3, 4], state: "minecraft:air"},
        {pos: [1, 3, 5], state: "minecraft:air"},
        {pos: [1, 3, 6], state: "minecraft:air"},
        {pos: [1, 3, 7], state: "minecraft:air"},
        {pos: [1, 3, 8], state: "minecraft:air"},
        {pos: [1, 3, 9], state: "minecraft:air"},
        {pos: [1, 3, 10], state: "minecraft:air"},
        {pos: [1, 3, 11], state: "minecraft:air"},
        {pos: [1, 3, 12], state: "minecraft:air"},
        {pos: [1, 3, 13], state: "minecraft:waxed_oxidized_cut_copper_stairs{facing:south,half:bottom,shape:straight,waterlogged:false}"},
        {pos: [1, 3, 14], state: "minecraft:tuff_bricks"},
        {pos: [1, 3, 15], state: "minecraft:tuff_bricks"},
        {pos: [1, 3, 16], state: "minecraft:tuff_bricks"},
        {pos: [1, 3, 17], state: "minecraft:tuff_bricks"},
        {pos: [1, 3, 18], state: "minecraft:tuff_bricks"},
        {pos: [1, 3, 19], state: "minecraft:tuff_bricks"},
        {pos: [1, 3, 20], state: "minecraft:tuff_bricks"},
        {pos: [1, 3, 21], state: "minecraft:tuff_bricks"},
        {pos: [1, 3, 22], state: "minecraft:tuff_bricks"},
        {pos: [1, 3, 23], state: "minecraft:waxed_oxidized_cut_copper_stairs{facing:north,half:bottom,shape:straight,waterlogged:false}"},
        {pos: [1, 3, 24], state: "minecraft:air"},
        {pos: [1, 3, 25], state: "minecraft:air"},
        {pos: [1, 3, 26], state: "minecraft:air"},
        {pos: [1, 3, 27], state: "minecraft:air"},
        {pos: [1, 3, 28], state: "minecraft:air"},
        {pos: [1, 3, 29], state: "minecraft:air"},
        {pos: [1, 3, 30], state: "minecraft:air"},
        {pos: [2, 3, 1], state: "minecraft:air"},
        {pos: [2, 3, 2], state: "minecraft:air"},
        {pos: [2, 3, 3], state: "minecraft:air"},
        {pos: [2, 3, 4], state: "minecraft:air"},
        {pos: [2, 3, 5], state: "minecraft:air"},
        {pos: [2, 3, 6], state: "minecraft:air"},
        {pos: [2, 3, 7], state: "minecraft:air"},
        {pos: [2, 3, 8], state: "minecraft:air"},
        {pos: [2, 3, 9], state: "minecraft:air"},
        {pos: [2, 3, 10], state: "minecraft:air"},
        {pos: [2, 3, 11], state: "minecraft:air"},
        {pos: [2, 3, 12], state: "minecraft:air"},
        {pos: [2, 3, 13], state: "minecraft:waxed_oxidized_cut_copper_stairs{facing:south,half:bottom,shape:straight,waterlogged:false}"},
        {pos: [2, 3, 14], state: "minecraft:tuff_bricks"},
        {pos: [2, 3, 15], state: "minecraft:tuff_bricks"},
        {pos: [2, 3, 16], state: "minecraft:tuff_bricks"},
        {pos: [2, 3, 17], state: "minecraft:tuff_bricks"},
        {pos: [2, 3, 18], state: "minecraft:tuff_bricks"},
        {pos: [2, 3, 19], state: "minecraft:tuff_bricks"},
        {pos: [2, 3, 20], state: "minecraft:tuff_bricks"},
        {pos: [2, 3, 21], state: "minecraft:tuff_bricks"},
        {pos: [2, 3, 22], state: "minecraft:tuff_bricks"},
        {pos: [2, 3, 23], state: "minecraft:waxed_oxidized_cut_copper_stairs{facing:north,half:bottom,shape:straight,waterlogged:false}"},
        {pos: [2, 3, 24], state: "minecraft:air"},
        {pos: [2, 3, 25], state: "minecraft:air"},
        {pos: [2, 3, 26], state: "minecraft:air"},
        {pos: [2, 3, 27], state: "minecraft:air"},
        {pos: [2, 3, 28], state: "minecraft:air"},
        {pos: [2, 3, 29], state: "minecraft:air"},
        {pos: [2, 3, 30], state: "minecraft:air"},
        {pos: [3, 3, 1], state: "minecraft:air"},
        {pos: [3, 3, 2], state: "minecraft:air"},
        {pos: [3, 3, 3], state: "minecraft:air"},
        {pos: [3, 3, 4], state: "minecraft:air"},
        {pos: [3, 3, 5], state: "minecraft:air"},
        {pos: [3, 3, 6], state: "minecraft:air"},
        {pos: [3, 3, 7], state: "minecraft:air"},
        {pos: [3, 3, 8], state: "minecraft:air"},
        {pos: [3, 3, 9], state: "minecraft:air"},
        {pos: [3, 3, 10], state: "minecraft:air"},
        {pos: [3, 3, 11], state: "minecraft:air"},
        {pos: [3, 3, 12], state: "minecraft:air"},
        {pos: [3, 3, 13], state: "minecraft:waxed_oxidized_cut_copper_stairs{facing:south,half:bottom,shape:straight,waterlogged:false}"},
        {pos: [3, 3, 14], state: "minecraft:tuff_bricks"},
        {pos: [3, 3, 15], state: "minecraft:tuff_bricks"},
        {pos: [3, 3, 16], state: "minecraft:tuff_bricks"},
        {pos: [3, 3, 17], state: "minecraft:tuff_bricks"},
        {pos: [3, 3, 18], state: "minecraft:tuff_bricks"},
        {pos: [3, 3, 19], state: "minecraft:tuff_bricks"},
        {pos: [3, 3, 20], state: "minecraft:tuff_bricks"},
        {pos: [3, 3, 21], state: "minecraft:tuff_bricks"},
        {pos: [3, 3, 22], state: "minecraft:tuff_bricks"},
        {pos: [3, 3, 23], state: "minecraft:waxed_oxidized_cut_copper_stairs{facing:north,half:bottom,shape:straight,waterlogged:false}"},
        {pos: [3, 3, 24], state: "minecraft:air"},
        {pos: [3, 3, 25], state: "minecraft:air"},
        {pos: [3, 3, 26], state: "minecraft:air"},
        {pos: [3, 3, 27], state: "minecraft:air"},
        {pos: [3, 3, 28], state: "minecraft:air"},
        {pos: [3, 3, 29], state: "minecraft:air"},
        {pos: [3, 3, 30], state: "minecraft:air"},
        {pos: [4, 3, 1], state: "minecraft:chiseled_tuff_bricks"},
        {pos: [4, 3, 2], state: "minecraft:air"},
        {pos: [4, 3, 3], state: "minecraft:air"},
        {pos: [4, 3, 4], state: "minecraft:air"},
        {pos: [4, 3, 5], state: "minecraft:chiseled_tuff_bricks"},
        {pos: [4, 3, 6], state: "minecraft:chiseled_tuff_bricks"},
        {pos: [4, 3, 7], state: "minecraft:air"},
        {pos: [4, 3, 8], state: "minecraft:air"},
        {pos: [4, 3, 9], state: "minecraft:air"},
        {pos: [4, 3, 10], state: "minecraft:chiseled_tuff_bricks"},
        {pos: [4, 3, 11], state: "minecraft:chiseled_tuff_bricks"},
        {pos: [4, 3, 12], state: "minecraft:air"},
        {pos: [4, 3, 13], state: "minecraft:air"},
        {pos: [4, 3, 14], state: "minecraft:air"},
        {pos: [4, 3, 15], state: "minecraft:chiseled_tuff_bricks"},
        {pos: [4, 3, 16], state: "minecraft:tuff_bricks"},
        {pos: [4, 3, 17], state: "minecraft:tuff_bricks"},
        {pos: [4, 3, 18], state: "minecraft:tuff_bricks"},
        {pos: [4, 3, 19], state: "minecraft:tuff_bricks"},
        {pos: [4, 3, 20], state: "minecraft:tuff_bricks"},
        {pos: [4, 3, 21], state: "minecraft:tuff_bricks"},
        {pos: [4, 3, 22], state: "minecraft:air"},
        {pos: [4, 3, 23], state: "minecraft:air"},
        {pos: [4, 3, 24], state: "minecraft:air"},
        {pos: [4, 3, 25], state: "minecraft:chiseled_tuff_bricks"},
        {pos: [4, 3, 26], state: "minecraft:chiseled_tuff_bricks"},
        {pos: [4, 3, 27], state: "minecraft:air"},
        {pos: [4, 3, 28], state: "minecraft:air"},
        {pos: [4, 3, 29], state: "minecraft:air"},
        {pos: [4, 3, 30], state: "minecraft:chiseled_tuff_bricks"},
        {pos: [0, 4, 1], state: "minecraft:tuff_bricks"},
        {pos: [0, 4, 2], state: "minecraft:air"},
        {pos: [0, 4, 3], state: "minecraft:air"},
        {pos: [0, 4, 4], state: "minecraft:air"},
        {pos: [0, 4, 5], state: "minecraft:air"},
        {pos: [0, 4, 6], state: "minecraft:air"},
        {pos: [0, 4, 7], state: "minecraft:air"},
        {pos: [0, 4, 8], state: "minecraft:air"},
        {pos: [0, 4, 9], state: "minecraft:air"},
        {pos: [0, 4, 10], state: "minecraft:air"},
        {pos: [0, 4, 11], state: "minecraft:air"},
        {pos: [0, 4, 12], state: "minecraft:air"},
        {pos: [0, 4, 13], state: "minecraft:air"},
        {pos: [0, 4, 14], state: "minecraft:waxed_copper_block"},
        {pos: [0, 4, 15], state: "minecraft:waxed_copper_block"},
        {pos: [0, 4, 16], state: "minecraft:tuff_bricks"},
        {pos: [0, 4, 17], state: "minecraft:jigsaw{orientation:down_west}", nbt: {final_state: "minecraft:tuff_bricks", id: "minecraft:jigsaw", joint: "aligned", name: "minecraft:empty", placement_priority: 0, pool: "minecraft:trial_chambers/dispensers/chamber", selection_priority: 0, target: "minecraft:dispenser"}},
        {pos: [0, 4, 18], state: "minecraft:tuff_bricks"},
        {pos: [0, 4, 19], state: "minecraft:tuff_bricks"},
        {pos: [0, 4, 20], state: "minecraft:tuff_bricks"},
        {pos: [0, 4, 21], state: "minecraft:waxed_copper_block"},
        {pos: [0, 4, 22], state: "minecraft:waxed_copper_block"},
        {pos: [0, 4, 23], state: "minecraft:air"},
        {pos: [0, 4, 24], state: "minecraft:air"},
        {pos: [0, 4, 25], state: "minecraft:air"},
        {pos: [0, 4, 26], state: "minecraft:air"},
        {pos: [0, 4, 27], state: "minecraft:air"},
        {pos: [0, 4, 28], state: "minecraft:air"},
        {pos: [0, 4, 29], state: "minecraft:air"},
        {pos: [0, 4, 30], state: "minecraft:tuff_bricks"},
        {pos: [1, 4, 1], state: "minecraft:air"},
        {pos: [1, 4, 2], state: "minecraft:air"},
        {pos: [1, 4, 3], state: "minecraft:air"},
        {pos: [1, 4, 4], state: "minecraft:air"},
        {pos: [1, 4, 5], state: "minecraft:air"},
        {pos: [1, 4, 6], state: "minecraft:air"},
        {pos: [1, 4, 7], state: "minecraft:air"},
        {pos: [1, 4, 8], state: "minecraft:air"},
        {pos: [1, 4, 9], state: "minecraft:air"},
        {pos: [1, 4, 10], state: "minecraft:air"},
        {pos: [1, 4, 11], state: "minecraft:air"},
        {pos: [1, 4, 12], state: "minecraft:air"},
        {pos: [1, 4, 13], state: "minecraft:air"},
        {pos: [1, 4, 14], state: "minecraft:waxed_oxidized_cut_copper_stairs{facing:south,half:bottom,shape:straight,waterlogged:false}"},
        {pos: [1, 4, 15], state: "minecraft:tuff_bricks"},
        {pos: [1, 4, 16], state: "minecraft:tuff_bricks"},
        {pos: [1, 4, 17], state: "minecraft:tuff_bricks"},
        {pos: [1, 4, 18], state: "minecraft:tuff_bricks"},
        {pos: [1, 4, 19], state: "minecraft:tuff_bricks"},
        {pos: [1, 4, 20], state: "minecraft:tuff_bricks"},
        {pos: [1, 4, 21], state: "minecraft:tuff_bricks"},
        {pos: [1, 4, 22], state: "minecraft:waxed_oxidized_cut_copper_stairs{facing:north,half:bottom,shape:straight,waterlogged:false}"},
        {pos: [1, 4, 23], state: "minecraft:air"},
        {pos: [1, 4, 24], state: "minecraft:air"},
        {pos: [1, 4, 25], state: "minecraft:air"},
        {pos: [1, 4, 26], state: "minecraft:air"},
        {pos: [1, 4, 27], state: "minecraft:air"},
        {pos: [1, 4, 28], state: "minecraft:air"},
        {pos: [1, 4, 29], state: "minecraft:air"},
        {pos: [1, 4, 30], state: "minecraft:air"},
        {pos: [2, 4, 1], state: "minecraft:air"},
        {pos: [2, 4, 2], state: "minecraft:air"},
        {pos: [2, 4, 3], state: "minecraft:air"},
        {pos: [2, 4, 4], state: "minecraft:air"},
        {pos: [2, 4, 5], state: "minecraft:air"},
        {pos: [2, 4, 6], state: "minecraft:air"},
        {pos: [2, 4, 7], state: "minecraft:air"},
        {pos: [2, 4, 8], state: "minecraft:air"},
        {pos: [2, 4, 9], state: "minecraft:air"},
        {pos: [2, 4, 10], state: "minecraft:air"},
        {pos: [2, 4, 11], state: "minecraft:air"},
        {pos: [2, 4, 12], state: "minecraft:air"},
        {pos: [2, 4, 13], state: "minecraft:air"},
        {pos: [2, 4, 14], state: "minecraft:waxed_oxidized_cut_copper_stairs{facing:south,half:bottom,shape:straight,waterlogged:false}"},
        {pos: [2, 4, 15], state: "minecraft:tuff_bricks"},
        {pos: [2, 4, 16], state: "minecraft:tuff_bricks"},
        {pos: [2, 4, 17], state: "minecraft:tuff_bricks"},
        {pos: [2, 4, 18], state: "minecraft:tuff_bricks"},
        {pos: [2, 4, 19], state: "minecraft:tuff_bricks"},
        {pos: [2, 4, 20], state: "minecraft:tuff_bricks"},
        {pos: [2, 4, 21], state: "minecraft:tuff_bricks"},
        {pos: [2, 4, 22], state: "minecraft:waxed_oxidized_cut_copper_stairs{facing:north,half:bottom,shape:straight,waterlogged:false}"},
        {pos: [2, 4, 23], state: "minecraft:air"},
        {pos: [2, 4, 24], state: "minecraft:air"},
        {pos: [2, 4, 25], state: "minecraft:air"},
        {pos: [2, 4, 26], state: "minecraft:air"},
        {pos: [2, 4, 27], state: "minecraft:air"},
        {pos: [2, 4, 28], state: "minecraft:air"},
        {pos: [2, 4, 29], state: "minecraft:air"},
        {pos: [2, 4, 30], state: "minecraft:air"},
        {pos: [3, 4, 1], state: "minecraft:air"},
        {pos: [3, 4, 2], state: "minecraft:air"},
        {pos: [3, 4, 3], state: "minecraft:air"},
        {pos: [3, 4, 4], state: "minecraft:air"},
        {pos: [3, 4, 5], state: "minecraft:air"},
        {pos: [3, 4, 6], state: "minecraft:air"},
        {pos: [3, 4, 7], state: "minecraft:air"},
        {pos: [3, 4, 8], state: "minecraft:air"},
        {pos: [3, 4, 9], state: "minecraft:air"},
        {pos: [3, 4, 10], state: "minecraft:air"},
        {pos: [3, 4, 11], state: "minecraft:air"},
        {pos: [3, 4, 12], state: "minecraft:air"},
        {pos: [3, 4, 13], state: "minecraft:air"},
        {pos: [3, 4, 14], state: "minecraft:waxed_oxidized_cut_copper_stairs{facing:south,half:bottom,shape:straight,waterlogged:false}"},
        {pos: [3, 4, 15], state: "minecraft:tuff_bricks"},
        {pos: [3, 4, 16], state: "minecraft:tuff_bricks"},
        {pos: [3, 4, 17], state: "minecraft:tuff_bricks"},
        {pos: [3, 4, 18], state: "minecraft:tuff_bricks"},
        {pos: [3, 4, 19], state: "minecraft:tuff_bricks"},
        {pos: [3, 4, 20], state: "minecraft:tuff_bricks"},
        {pos: [3, 4, 21], state: "minecraft:tuff_bricks"},
        {pos: [3, 4, 22], state: "minecraft:waxed_oxidized_cut_copper_stairs{facing:north,half:bottom,shape:straight,waterlogged:false}"},
        {pos: [3, 4, 23], state: "minecraft:air"},
        {pos: [3, 4, 24], state: "minecraft:air"},
        {pos: [3, 4, 25], state: "minecraft:air"},
        {pos: [3, 4, 26], state: "minecraft:air"},
        {pos: [3, 4, 27], state: "minecraft:air"},
        {pos: [3, 4, 28], state: "minecraft:air"},
        {pos: [3, 4, 29], state: "minecraft:air"},
        {pos: [3, 4, 30], state: "minecraft:air"},
        {pos: [4, 4, 1], state: "minecraft:tuff_bricks"},
        {pos: [4, 4, 2], state: "minecraft:air"},
        {pos: [4, 4, 3], state: "minecraft:air"},
        {pos: [4, 4, 4], state: "minecraft:air"},
        {pos: [4, 4, 5], state: "minecraft:tuff_bricks"},
        {pos: [4, 4, 6], state: "minecraft:tuff_bricks"},
        {pos: [4, 4, 7], state: "minecraft:air"},
        {pos: [4, 4, 8], state: "minecraft:air"},
        {pos: [4, 4, 9], state: "minecraft:air"},
        {pos: [4, 4, 10], state: "minecraft:tuff_bricks"},
        {pos: [4, 4, 11], state: "minecraft:tuff_bricks"},
        {pos: [4, 4, 12], state: "minecraft:air"},
        {pos: [4, 4, 13], state: "minecraft:air"},
        {pos: [4, 4, 14], state: "minecraft:air"},
        {pos: [4, 4, 15], state: "minecraft:tuff_bricks"},
        {pos: [4, 4, 16], state: "minecraft:tuff_bricks"},
        {pos: [4, 4, 17], state: "minecraft:tuff_bricks"},
        {pos: [4, 4, 18], state: "minecraft:tuff_bricks"},
        {pos: [4, 4, 19], state: "minecraft:tuff_bricks"},
        {pos: [4, 4, 20], state: "minecraft:tuff_bricks"},
        {pos: [4, 4, 21], state: "minecraft:tuff_bricks"},
        {pos: [4, 4, 22], state: "minecraft:air"},
        {pos: [4, 4, 23], state: "minecraft:air"},
        {pos: [4, 4, 24], state: "minecraft:air"},
        {pos: [4, 4, 25], state: "minecraft:tuff_bricks"},
        {pos: [4, 4, 26], state: "minecraft:tuff_bricks"},
        {pos: [4, 4, 27], state: "minecraft:air"},
        {pos: [4, 4, 28], state: "minecraft:air"},
        {pos: [4, 4, 29], state: "minecraft:air"},
        {pos: [4, 4, 30], state: "minecraft:tuff_bricks"},
        {pos: [0, 5, 1], state: "minecraft:tuff_bricks"},
        {pos: [0, 5, 2], state: "minecraft:air"},
        {pos: [0, 5, 3], state: "minecraft:air"},
        {pos: [0, 5, 4], state: "minecraft:air"},
        {pos: [0, 5, 5], state: "minecraft:air"},
        {pos: [0, 5, 6], state: "minecraft:air"},
        {pos: [0, 5, 7], state: "minecraft:air"},
        {pos: [0, 5, 8], state: "minecraft:air"},
        {pos: [0, 5, 9], state: "minecraft:air"},
        {pos: [0, 5, 10], state: "minecraft:air"},
        {pos: [0, 5, 11], state: "minecraft:air"},
        {pos: [0, 5, 12], state: "minecraft:air"},
        {pos: [0, 5, 13], state: "minecraft:air"},
        {pos: [0, 5, 14], state: "minecraft:air"},
        {pos: [0, 5, 15], state: "minecraft:waxed_copper_block"},
        {pos: [0, 5, 16], state: "minecraft:waxed_copper_block"},
        {pos: [0, 5, 17], state: "minecraft:waxed_copper_block"},
        {pos: [0, 5, 18], state: "minecraft:waxed_copper_block"},
        {pos: [0, 5, 19], state: "minecraft:waxed_copper_block"},
        {pos: [0, 5, 20], state: "minecraft:waxed_copper_block"},
        {pos: [0, 5, 21], state: "minecraft:waxed_copper_block"},
        {pos: [0, 5, 22], state: "minecraft:air"},
        {pos: [0, 5, 23], state: "minecraft:air"},
        {pos: [0, 5, 24], state: "minecraft:air"},
        {pos: [0, 5, 25], state: "minecraft:air"},
        {pos: [0, 5, 26], state: "minecraft:air"},
        {pos: [0, 5, 27], state: "minecraft:air"},
        {pos: [0, 5, 28], state: "minecraft:air"},
        {pos: [0, 5, 29], state: "minecraft:air"},
        {pos: [0, 5, 30], state: "minecraft:tuff_bricks"},
        {pos: [1, 5, 1], state: "minecraft:air"},
        {pos: [1, 5, 2], state: "minecraft:air"},
        {pos: [1, 5, 3], state: "minecraft:air"},
        {pos: [1, 5, 4], state: "minecraft:air"},
        {pos: [1, 5, 5], state: "minecraft:air"},
        {pos: [1, 5, 6], state: "minecraft:air"},
        {pos: [1, 5, 7], state: "minecraft:air"},
        {pos: [1, 5, 8], state: "minecraft:air"},
        {pos: [1, 5, 9], state: "minecraft:air"},
        {pos: [1, 5, 10], state: "minecraft:air"},
        {pos: [1, 5, 11], state: "minecraft:air"},
        {pos: [1, 5, 12], state: "minecraft:air"},
        {pos: [1, 5, 13], state: "minecraft:air"},
        {pos: [1, 5, 14], state: "minecraft:air"},
        {pos: [1, 5, 15], state: "minecraft:waxed_oxidized_cut_copper_stairs{facing:south,half:bottom,shape:straight,waterlogged:false}"},
        {pos: [1, 5, 16], state: "minecraft:waxed_oxidized_copper"},
        {pos: [1, 5, 17], state: "minecraft:waxed_oxidized_copper"},
        {pos: [1, 5, 18], state: "minecraft:waxed_oxidized_copper"},
        {pos: [1, 5, 19], state: "minecraft:waxed_oxidized_copper"},
        {pos: [1, 5, 20], state: "minecraft:waxed_oxidized_copper"},
        {pos: [1, 5, 21], state: "minecraft:waxed_oxidized_cut_copper_stairs{facing:north,half:bottom,shape:straight,waterlogged:false}"},
        {pos: [1, 5, 22], state: "minecraft:air"},
        {pos: [1, 5, 23], state: "minecraft:air"},
        {pos: [1, 5, 24], state: "minecraft:air"},
        {pos: [1, 5, 25], state: "minecraft:air"},
        {pos: [1, 5, 26], state: "minecraft:air"},
        {pos: [1, 5, 27], state: "minecraft:air"},
        {pos: [1, 5, 28], state: "minecraft:air"},
        {pos: [1, 5, 29], state: "minecraft:air"},
        {pos: [1, 5, 30], state: "minecraft:air"},
        {pos: [2, 5, 1], state: "minecraft:air"},
        {pos: [2, 5, 2], state: "minecraft:air"},
        {pos: [2, 5, 3], state: "minecraft:air"},
        {pos: [2, 5, 4], state: "minecraft:air"},
        {pos: [2, 5, 5], state: "minecraft:air"},
        {pos: [2, 5, 6], state: "minecraft:air"},
        {pos: [2, 5, 7], state: "minecraft:air"},
        {pos: [2, 5, 8], state: "minecraft:air"},
        {pos: [2, 5, 9], state: "minecraft:air"},
        {pos: [2, 5, 10], state: "minecraft:air"},
        {pos: [2, 5, 11], state: "minecraft:air"},
        {pos: [2, 5, 12], state: "minecraft:air"},
        {pos: [2, 5, 13], state: "minecraft:air"},
        {pos: [2, 5, 14], state: "minecraft:air"},
        {pos: [2, 5, 15], state: "minecraft:waxed_oxidized_cut_copper_stairs{facing:south,half:bottom,shape:straight,waterlogged:false}"},
        {pos: [2, 5, 16], state: "minecraft:waxed_oxidized_copper"},
        {pos: [2, 5, 17], state: "minecraft:waxed_oxidized_copper"},
        {pos: [2, 5, 18], state: "minecraft:waxed_oxidized_copper"},
        {pos: [2, 5, 19], state: "minecraft:waxed_oxidized_copper"},
        {pos: [2, 5, 20], state: "minecraft:waxed_oxidized_copper"},
        {pos: [2, 5, 21], state: "minecraft:waxed_oxidized_cut_copper_stairs{facing:north,half:bottom,shape:straight,waterlogged:false}"},
        {pos: [2, 5, 22], state: "minecraft:air"},
        {pos: [2, 5, 23], state: "minecraft:air"},
        {pos: [2, 5, 24], state: "minecraft:air"},
        {pos: [2, 5, 25], state: "minecraft:air"},
        {pos: [2, 5, 26], state: "minecraft:air"},
        {pos: [2, 5, 27], state: "minecraft:air"},
        {pos: [2, 5, 28], state: "minecraft:air"},
        {pos: [2, 5, 29], state: "minecraft:air"},
        {pos: [2, 5, 30], state: "minecraft:air"},
        {pos: [3, 5, 1], state: "minecraft:air"},
        {pos: [3, 5, 2], state: "minecraft:air"},
        {pos: [3, 5, 3], state: "minecraft:air"},
        {pos: [3, 5, 4], state: "minecraft:air"},
        {pos: [3, 5, 5], state: "minecraft:air"},
        {pos: [3, 5, 6], state: "minecraft:air"},
        {pos: [3, 5, 7], state: "minecraft:air"},
        {pos: [3, 5, 8], state: "minecraft:air"},
        {pos: [3, 5, 9], state: "minecraft:air"},
        {pos: [3, 5, 10], state: "minecraft:air"},
        {pos: [3, 5, 11], state: "minecraft:air"},
        {pos: [3, 5, 12], state: "minecraft:air"},
        {pos: [3, 5, 13], state: "minecraft:air"},
        {pos: [3, 5, 14], state: "minecraft:air"},
        {pos: [3, 5, 15], state: "minecraft:waxed_oxidized_cut_copper_stairs{facing:south,half:bottom,shape:straight,waterlogged:false}"},
        {pos: [3, 5, 16], state: "minecraft:waxed_oxidized_copper"},
        {pos: [3, 5, 17], state: "minecraft:waxed_oxidized_copper"},
        {pos: [3, 5, 18], state: "minecraft:waxed_oxidized_copper"},
        {pos: [3, 5, 19], state: "minecraft:waxed_oxidized_copper"},
        {pos: [3, 5, 20], state: "minecraft:waxed_oxidized_copper"},
        {pos: [3, 5, 21], state: "minecraft:waxed_oxidized_cut_copper_stairs{facing:north,half:bottom,shape:straight,waterlogged:false}"},
        {pos: [3, 5, 22], state: "minecraft:air"},
        {pos: [3, 5, 23], state: "minecraft:air"},
        {pos: [3, 5, 24], state: "minecraft:air"},
        {pos: [3, 5, 25], state: "minecraft:air"},
        {pos: [3, 5, 26], state: "minecraft:air"},
        {pos: [3, 5, 27], state: "minecraft:air"},
        {pos: [3, 5, 28], state: "minecraft:air"},
        {pos: [3, 5, 29], state: "minecraft:air"},
        {pos: [3, 5, 30], state: "minecraft:air"},
        {pos: [4, 5, 1], state: "minecraft:tuff_bricks"},
        {pos: [4, 5, 2], state: "minecraft:air"},
        {pos: [4, 5, 3], state: "minecraft:air"},
        {pos: [4, 5, 4], state: "minecraft:air"},
        {pos: [4, 5, 5], state: "minecraft:tuff_bricks"},
        {pos: [4, 5, 6], state: "minecraft:tuff_bricks"},
        {pos: [4, 5, 7], state: "minecraft:air"},
        {pos: [4, 5, 8], state: "minecraft:air"},
        {pos: [4, 5, 9], state: "minecraft:air"},
        {pos: [4, 5, 10], state: "minecraft:tuff_bricks"},
        {pos: [4, 5, 11], state: "minecraft:tuff_bricks"},
        {pos: [4, 5, 12], state: "minecraft:air"},
        {pos: [4, 5, 13], state: "minecraft:air"},
        {pos: [4, 5, 14], state: "minecraft:air"},
        {pos: [4, 5, 15], state: "minecraft:tuff_bricks"},
        {pos: [4, 5, 16], state: "minecraft:tuff_bricks"},
        {pos: [4, 5, 17], state: "minecraft:waxed_oxidized_copper"},
        {pos: [4, 5, 18], state: "minecraft:waxed_oxidized_copper"},
        {pos: [4, 5, 19], state: "minecraft:waxed_oxidized_copper"},
        {pos: [4, 5, 20], state: "minecraft:tuff_bricks"},
        {pos: [4, 5, 21], state: "minecraft:tuff_bricks"},
        {pos: [4, 5, 22], state: "minecraft:air"},
        {pos: [4, 5, 23], state: "minecraft:air"},
        {pos: [4, 5, 24], state: "minecraft:air"},
        {pos: [4, 5, 25], state: "minecraft:tuff_bricks"},
        {pos: [4, 5, 26], state: "minecraft:tuff_bricks"},
        {pos: [4, 5, 27], state: "minecraft:air"},
        {pos: [4, 5, 28], state: "minecraft:air"},
        {pos: [4, 5, 29], state: "minecraft:air"},
        {pos: [4, 5, 30], state: "minecraft:tuff_bricks"},
        {pos: [0, 6, 1], state: "minecraft:waxed_copper_block"},
        {pos: [0, 6, 2], state: "minecraft:air"},
        {pos: [0, 6, 3], state: "minecraft:air"},
        {pos: [0, 6, 4], state: "minecraft:air"},
        {pos: [0, 6, 5], state: "minecraft:air"},
        {pos: [0, 6, 6], state: "minecraft:air"},
        {pos: [0, 6, 7], state: "minecraft:air"},
        {pos: [0, 6, 8], state: "minecraft:air"},
        {pos: [0, 6, 9], state: "minecraft:air"},
        {pos: [0, 6, 10], state: "minecraft:air"},
        {pos: [0, 6, 11], state: "minecraft:air"},
        {pos: [0, 6, 12], state: "minecraft:air"},
        {pos: [0, 6, 13], state: "minecraft:air"},
        {pos: [0, 6, 14], state: "minecraft:air"},
        {pos: [0, 6, 15], state: "minecraft:air"},
        {pos: [0, 6, 16], state: "minecraft:waxed_copper_block"},
        {pos: [0, 6, 17], state: "minecraft:waxed_copper_grate"},
        {pos: [0, 6, 18], state: "minecraft:waxed_copper_grate"},
        {pos: [0, 6, 19], state: "minecraft:waxed_copper_grate"},
        {pos: [0, 6, 20], state: "minecraft:waxed_copper_block"},
        {pos: [0, 6, 21], state: "minecraft:air"},
        {pos: [0, 6, 22], state: "minecraft:air"},
        {pos: [0, 6, 23], state: "minecraft:air"},
        {pos: [0, 6, 24], state: "minecraft:air"},
        {pos: [0, 6, 25], state: "minecraft:air"},
        {pos: [0, 6, 26], state: "minecraft:air"},
        {pos: [0, 6, 27], state: "minecraft:air"},
        {pos: [0, 6, 28], state: "minecraft:air"},
        {pos: [0, 6, 29], state: "minecraft:air"},
        {pos: [0, 6, 30], state: "minecraft:waxed_copper_block"},
        {pos: [1, 6, 1], state: "minecraft:air"},
        {pos: [1, 6, 2], state: "minecraft:air"},
        {pos: [1, 6, 3], state: "minecraft:air"},
        {pos: [1, 6, 4], state: "minecraft:air"},
        {pos: [1, 6, 5], state: "minecraft:air"},
        {pos: [1, 6, 6], state: "minecraft:air"},
        {pos: [1, 6, 7], state: "minecraft:air"},
        {pos: [1, 6, 8], state: "minecraft:air"},
        {pos: [1, 6, 9], state: "minecraft:air"},
        {pos: [1, 6, 10], state: "minecraft:air"},
        {pos: [1, 6, 11], state: "minecraft:air"},
        {pos: [1, 6, 12], state: "minecraft:air"},
        {pos: [1, 6, 13], state: "minecraft:air"},
        {pos: [1, 6, 14], state: "minecraft:air"},
        {pos: [1, 6, 15], state: "minecraft:air"},
        {pos: [1, 6, 16], state: "minecraft:air"},
        {pos: [1, 6, 17], state: "minecraft:air"},
        {pos: [1, 6, 18], state: "minecraft:air"},
        {pos: [1, 6, 19], state: "minecraft:air"},
        {pos: [1, 6, 20], state: "minecraft:air"},
        {pos: [1, 6, 21], state: "minecraft:air"},
        {pos: [1, 6, 22], state: "minecraft:air"},
        {pos: [1, 6, 23], state: "minecraft:air"},
        {pos: [1, 6, 24], state: "minecraft:air"},
        {pos: [1, 6, 25], state: "minecraft:air"},
        {pos: [1, 6, 26], state: "minecraft:air"},
        {pos: [1, 6, 27], state: "minecraft:air"},
        {pos: [1, 6, 28], state: "minecraft:air"},
        {pos: [1, 6, 29], state: "minecraft:air"},
        {pos: [1, 6, 30], state: "minecraft:air"},
        {pos: [2, 6, 1], state: "minecraft:air"},
        {pos: [2, 6, 2], state: "minecraft:air"},
        {pos: [2, 6, 3], state: "minecraft:air"},
        {pos: [2, 6, 4], state: "minecraft:air"},
        {pos: [2, 6, 5], state: "minecraft:air"},
        {pos: [2, 6, 6], state: "minecraft:air"},
        {pos: [2, 6, 7], state: "minecraft:air"},
        {pos: [2, 6, 8], state: "minecraft:air"},
        {pos: [2, 6, 9], state: "minecraft:air"},
        {pos: [2, 6, 10], state: "minecraft:air"},
        {pos: [2, 6, 11], state: "minecraft:air"},
        {pos: [2, 6, 12], state: "minecraft:air"},
        {pos: [2, 6, 13], state: "minecraft:air"},
        {pos: [2, 6, 14], state: "minecraft:air"},
        {pos: [2, 6, 15], state: "minecraft:air"},
        {pos: [2, 6, 16], state: "minecraft:air"},
        {pos: [2, 6, 17], state: "minecraft:air"},
        {pos: [2, 6, 18], state: "minecraft:air"},
        {pos: [2, 6, 19], state: "minecraft:air"},
        {pos: [2, 6, 20], state: "minecraft:air"},
        {pos: [2, 6, 21], state: "minecraft:air"},
        {pos: [2, 6, 22], state: "minecraft:air"},
        {pos: [2, 6, 23], state: "minecraft:air"},
        {pos: [2, 6, 24], state: "minecraft:air"},
        {pos: [2, 6, 25], state: "minecraft:air"},
        {pos: [2, 6, 26], state: "minecraft:air"},
        {pos: [2, 6, 27], state: "minecraft:air"},
        {pos: [2, 6, 28], state: "minecraft:air"},
        {pos: [2, 6, 29], state: "minecraft:air"},
        {pos: [2, 6, 30], state: "minecraft:air"},
        {pos: [3, 6, 1], state: "minecraft:air"},
        {pos: [3, 6, 2], state: "minecraft:air"},
        {pos: [3, 6, 3], state: "minecraft:air"},
        {pos: [3, 6, 4], state: "minecraft:air"},
        {pos: [3, 6, 5], state: "minecraft:air"},
        {pos: [3, 6, 6], state: "minecraft:air"},
        {pos: [3, 6, 7], state: "minecraft:air"},
        {pos: [3, 6, 8], state: "minecraft:air"},
        {pos: [3, 6, 9], state: "minecraft:air"},
        {pos: [3, 6, 10], state: "minecraft:air"},
        {pos: [3, 6, 11], state: "minecraft:air"},
        {pos: [3, 6, 12], state: "minecraft:air"},
        {pos: [3, 6, 13], state: "minecraft:air"},
        {pos: [3, 6, 14], state: "minecraft:air"},
        {pos: [3, 6, 15], state: "minecraft:air"},
        {pos: [3, 6, 16], state: "minecraft:air"},
        {pos: [3, 6, 17], state: "minecraft:air"},
        {pos: [3, 6, 18], state: "minecraft:air"},
        {pos: [3, 6, 19], state: "minecraft:air"},
        {pos: [3, 6, 20], state: "minecraft:air"},
        {pos: [3, 6, 21], state: "minecraft:air"},
        {pos: [3, 6, 22], state: "minecraft:air"},
        {pos: [3, 6, 23], state: "minecraft:air"},
        {pos: [3, 6, 24], state: "minecraft:air"},
        {pos: [3, 6, 25], state: "minecraft:air"},
        {pos: [3, 6, 26], state: "minecraft:air"},
        {pos: [3, 6, 27], state: "minecraft:air"},
        {pos: [3, 6, 28], state: "minecraft:air"},
        {pos: [3, 6, 29], state: "minecraft:air"},
        {pos: [3, 6, 30], state: "minecraft:air"},
        {pos: [4, 6, 1], state: "minecraft:waxed_copper_block"},
        {pos: [4, 6, 2], state: "minecraft:air"},
        {pos: [4, 6, 3], state: "minecraft:air"},
        {pos: [4, 6, 4], state: "minecraft:air"},
        {pos: [4, 6, 5], state: "minecraft:waxed_copper_block"},
        {pos: [4, 6, 6], state: "minecraft:waxed_copper_block"},
        {pos: [4, 6, 7], state: "minecraft:air"},
        {pos: [4, 6, 8], state: "minecraft:air"},
        {pos: [4, 6, 9], state: "minecraft:air"},
        {pos: [4, 6, 10], state: "minecraft:waxed_copper_block"},
        {pos: [4, 6, 11], state: "minecraft:waxed_copper_block"},
        {pos: [4, 6, 12], state: "minecraft:air"},
        {pos: [4, 6, 13], state: "minecraft:air"},
        {pos: [4, 6, 14], state: "minecraft:air"},
        {pos: [4, 6, 15], state: "minecraft:waxed_copper_block"},
        {pos: [4, 6, 16], state: "minecraft:waxed_copper_block"},
        {pos: [4, 6, 17], state: "minecraft:air"},
        {pos: [4, 6, 18], state: "minecraft:air"},
        {pos: [4, 6, 19], state: "minecraft:air"},
        {pos: [4, 6, 20], state: "minecraft:waxed_copper_block"},
        {pos: [4, 6, 21], state: "minecraft:waxed_copper_block"},
        {pos: [4, 6, 22], state: "minecraft:air"},
        {pos: [4, 6, 23], state: "minecraft:air"},
        {pos: [4, 6, 24], state: "minecraft:air"},
        {pos: [4, 6, 25], state: "minecraft:waxed_copper_block"},
        {pos: [4, 6, 26], state: "minecraft:waxed_copper_block"},
        {pos: [4, 6, 27], state: "minecraft:air"},
        {pos: [4, 6, 28], state: "minecraft:air"},
        {pos: [4, 6, 29], state: "minecraft:air"},
        {pos: [4, 6, 30], state: "minecraft:waxed_copper_block"},
        {pos: [0, 7, 1], state: "minecraft:tuff_bricks"},
        {pos: [0, 7, 2], state: "minecraft:air"},
        {pos: [0, 7, 3], state: "minecraft:air"},
        {pos: [0, 7, 4], state: "minecraft:air"},
        {pos: [0, 7, 5], state: "minecraft:air"},
        {pos: [0, 7, 6], state: "minecraft:air"},
        {pos: [0, 7, 7], state: "minecraft:air"},
        {pos: [0, 7, 8], state: "minecraft:air"},
        {pos: [0, 7, 9], state: "minecraft:air"},
        {pos: [0, 7, 10], state: "minecraft:air"},
        {pos: [0, 7, 11], state: "minecraft:air"},
        {pos: [0, 7, 12], state: "minecraft:air"},
        {pos: [0, 7, 13], state: "minecraft:air"},
        {pos: [0, 7, 14], state: "minecraft:air"},
        {pos: [0, 7, 15], state: "minecraft:air"},
        {pos: [0, 7, 16], state: "minecraft:waxed_copper_block"},
        {pos: [0, 7, 17], state: "minecraft:waxed_copper_block"},
        {pos: [0, 7, 18], state: "minecraft:waxed_copper_block"},
        {pos: [0, 7, 19], state: "minecraft:waxed_copper_block"},
        {pos: [0, 7, 20], state: "minecraft:waxed_copper_block"},
        {pos: [0, 7, 21], state: "minecraft:air"},
        {pos: [0, 7, 22], state: "minecraft:air"},
        {pos: [0, 7, 23], state: "minecraft:air"},
        {pos: [0, 7, 24], state: "minecraft:air"},
        {pos: [0, 7, 25], state: "minecraft:air"},
        {pos: [0, 7, 26], state: "minecraft:air"},
        {pos: [0, 7, 27], state: "minecraft:air"},
        {pos: [0, 7, 28], state: "minecraft:air"},
        {pos: [0, 7, 29], state: "minecraft:air"},
        {pos: [0, 7, 30], state: "minecraft:tuff_bricks"},
        {pos: [1, 7, 1], state: "minecraft:air"},
        {pos: [1, 7, 2], state: "minecraft:air"},
        {pos: [1, 7, 3], state: "minecraft:air"},
        {pos: [1, 7, 4], state: "minecraft:air"},
        {pos: [1, 7, 5], state: "minecraft:air"},
        {pos: [1, 7, 6], state: "minecraft:air"},
        {pos: [1, 7, 7], state: "minecraft:air"},
        {pos: [1, 7, 8], state: "minecraft:air"},
        {pos: [1, 7, 9], state: "minecraft:air"},
        {pos: [1, 7, 10], state: "minecraft:air"},
        {pos: [1, 7, 11], state: "minecraft:air"},
        {pos: [1, 7, 12], state: "minecraft:air"},
        {pos: [1, 7, 13], state: "minecraft:air"},
        {pos: [1, 7, 14], state: "minecraft:air"},
        {pos: [1, 7, 15], state: "minecraft:air"},
        {pos: [1, 7, 16], state: "minecraft:air"},
        {pos: [1, 7, 17], state: "minecraft:air"},
        {pos: [1, 7, 18], state: "minecraft:air"},
        {pos: [1, 7, 19], state: "minecraft:air"},
        {pos: [1, 7, 20], state: "minecraft:air"},
        {pos: [1, 7, 21], state: "minecraft:air"},
        {pos: [1, 7, 22], state: "minecraft:air"},
        {pos: [1, 7, 23], state: "minecraft:air"},
        {pos: [1, 7, 24], state: "minecraft:air"},
        {pos: [1, 7, 25], state: "minecraft:air"},
        {pos: [1, 7, 26], state: "minecraft:air"},
        {pos: [1, 7, 27], state: "minecraft:air"},
        {pos: [1, 7, 28], state: "minecraft:air"},
        {pos: [1, 7, 29], state: "minecraft:air"},
        {pos: [1, 7, 30], state: "minecraft:air"},
        {pos: [2, 7, 1], state: "minecraft:air"},
        {pos: [2, 7, 2], state: "minecraft:air"},
        {pos: [2, 7, 3], state: "minecraft:air"},
        {pos: [2, 7, 4], state: "minecraft:air"},
        {pos: [2, 7, 5], state: "minecraft:air"},
        {pos: [2, 7, 6], state: "minecraft:air"},
        {pos: [2, 7, 7], state: "minecraft:air"},
        {pos: [2, 7, 8], state: "minecraft:air"},
        {pos: [2, 7, 9], state: "minecraft:air"},
        {pos: [2, 7, 10], state: "minecraft:air"},
        {pos: [2, 7, 11], state: "minecraft:air"},
        {pos: [2, 7, 12], state: "minecraft:air"},
        {pos: [2, 7, 13], state: "minecraft:air"},
        {pos: [2, 7, 14], state: "minecraft:air"},
        {pos: [2, 7, 15], state: "minecraft:air"},
        {pos: [2, 7, 16], state: "minecraft:air"},
        {pos: [2, 7, 17], state: "minecraft:air"},
        {pos: [2, 7, 18], state: "minecraft:air"},
        {pos: [2, 7, 19], state: "minecraft:air"},
        {pos: [2, 7, 20], state: "minecraft:air"},
        {pos: [2, 7, 21], state: "minecraft:air"},
        {pos: [2, 7, 22], state: "minecraft:air"},
        {pos: [2, 7, 23], state: "minecraft:air"},
        {pos: [2, 7, 24], state: "minecraft:air"},
        {pos: [2, 7, 25], state: "minecraft:air"},
        {pos: [2, 7, 26], state: "minecraft:air"},
        {pos: [2, 7, 27], state: "minecraft:air"},
        {pos: [2, 7, 28], state: "minecraft:air"},
        {pos: [2, 7, 29], state: "minecraft:air"},
        {pos: [2, 7, 30], state: "minecraft:air"},
        {pos: [3, 7, 1], state: "minecraft:air"},
        {pos: [3, 7, 2], state: "minecraft:air"},
        {pos: [3, 7, 3], state: "minecraft:air"},
        {pos: [3, 7, 4], state: "minecraft:air"},
        {pos: [3, 7, 5], state: "minecraft:air"},
        {pos: [3, 7, 6], state: "minecraft:air"},
        {pos: [3, 7, 7], state: "minecraft:air"},
        {pos: [3, 7, 8], state: "minecraft:air"},
        {pos: [3, 7, 9], state: "minecraft:air"},
        {pos: [3, 7, 10], state: "minecraft:air"},
        {pos: [3, 7, 11], state: "minecraft:air"},
        {pos: [3, 7, 12], state: "minecraft:air"},
        {pos: [3, 7, 13], state: "minecraft:air"},
        {pos: [3, 7, 14], state: "minecraft:air"},
        {pos: [3, 7, 15], state: "minecraft:air"},
        {pos: [3, 7, 16], state: "minecraft:air"},
        {pos: [3, 7, 17], state: "minecraft:air"},
        {pos: [3, 7, 18], state: "minecraft:air"},
        {pos: [3, 7, 19], state: "minecraft:air"},
        {pos: [3, 7, 20], state: "minecraft:air"},
        {pos: [3, 7, 21], state: "minecraft:air"},
        {pos: [3, 7, 22], state: "minecraft:air"},
        {pos: [3, 7, 23], state: "minecraft:air"},
        {pos: [3, 7, 24], state: "minecraft:air"},
        {pos: [3, 7, 25], state: "minecraft:air"},
        {pos: [3, 7, 26], state: "minecraft:air"},
        {pos: [3, 7, 27], state: "minecraft:air"},
        {pos: [3, 7, 28], state: "minecraft:air"},
        {pos: [3, 7, 29], state: "minecraft:air"},
        {pos: [3, 7, 30], state: "minecraft:air"},
        {pos: [4, 7, 1], state: "minecraft:tuff_bricks"},
        {pos: [4, 7, 2], state: "minecraft:air"},
        {pos: [4, 7, 3], state: "minecraft:air"},
        {pos: [4, 7, 4], state: "minecraft:air"},
        {pos: [4, 7, 5], state: "minecraft:tuff_bricks"},
        {pos: [4, 7, 6], state: "minecraft:tuff_bricks"},
        {pos: [4, 7, 7], state: "minecraft:air"},
        {pos: [4, 7, 8], state: "minecraft:air"},
        {pos: [4, 7, 9], state: "minecraft:air"},
        {pos: [4, 7, 10], state: "minecraft:tuff_bricks"},
        {pos: [4, 7, 11], state: "minecraft:tuff_bricks"},
        {pos: [4, 7, 12], state: "minecraft:air"},
        {pos: [4, 7, 13], state: "minecraft:air"},
        {pos: [4, 7, 14], state: "minecraft:air"},
        {pos: [4, 7, 15], state: "minecraft:tuff_bricks"},
        {pos: [4, 7, 16], state: "minecraft:tuff_bricks"},
        {pos: [4, 7, 17], state: "minecraft:air"},
        {pos: [4, 7, 18], state: "minecraft:air"},
        {pos: [4, 7, 19], state: "minecraft:air"},
        {pos: [4, 7, 20], state: "minecraft:tuff_bricks"},
        {pos: [4, 7, 21], state: "minecraft:tuff_bricks"},
        {pos: [4, 7, 22], state: "minecraft:air"},
        {pos: [4, 7, 23], state: "minecraft:air"},
        {pos: [4, 7, 24], state: "minecraft:air"},
        {pos: [4, 7, 25], state: "minecraft:tuff_bricks"},
        {pos: [4, 7, 26], state: "minecraft:tuff_bricks"},
        {pos: [4, 7, 27], state: "minecraft:air"},
        {pos: [4, 7, 28], state: "minecraft:air"},
        {pos: [4, 7, 29], state: "minecraft:air"},
        {pos: [4, 7, 30], state: "minecraft:tuff_bricks"},
        {pos: [0, 8, 1], state: "minecraft:tuff_bricks"},
        {pos: [0, 8, 2], state: "minecraft:air"},
        {pos: [0, 8, 3], state: "minecraft:air"},
        {pos: [0, 8, 4], state: "minecraft:air"},
        {pos: [0, 8, 5], state: "minecraft:air"},
        {pos: [0, 8, 6], state: "minecraft:air"},
        {pos: [0, 8, 7], state: "minecraft:air"},
        {pos: [0, 8, 8], state: "minecraft:air"},
        {pos: [0, 8, 9], state: "minecraft:air"},
        {pos: [0, 8, 10], state: "minecraft:air"},
        {pos: [0, 8, 11], state: "minecraft:air"},
        {pos: [0, 8, 12], state: "minecraft:air"},
        {pos: [0, 8, 13], state: "minecraft:air"},
        {pos: [0, 8, 14], state: "minecraft:air"},
        {pos: [0, 8, 15], state: "minecraft:air"},
        {pos: [0, 8, 16], state: "minecraft:waxed_copper_block"},
        {pos: [0, 8, 17], state: "minecraft:waxed_copper_block"},
        {pos: [0, 8, 18], state: "minecraft:waxed_copper_block"},
        {pos: [0, 8, 19], state: "minecraft:waxed_copper_block"},
        {pos: [0, 8, 20], state: "minecraft:waxed_copper_block"},
        {pos: [0, 8, 21], state: "minecraft:air"},
        {pos: [0, 8, 22], state: "minecraft:air"},
        {pos: [0, 8, 23], state: "minecraft:air"},
        {pos: [0, 8, 24], state: "minecraft:air"},
        {pos: [0, 8, 25], state: "minecraft:air"},
        {pos: [0, 8, 26], state: "minecraft:air"},
        {pos: [0, 8, 27], state: "minecraft:air"},
        {pos: [0, 8, 28], state: "minecraft:air"},
        {pos: [0, 8, 29], state: "minecraft:air"},
        {pos: [0, 8, 30], state: "minecraft:tuff_bricks"},
        {pos: [1, 8, 1], state: "minecraft:air"},
        {pos: [1, 8, 2], state: "minecraft:air"},
        {pos: [1, 8, 3], state: "minecraft:air"},
        {pos: [1, 8, 4], state: "minecraft:air"},
        {pos: [1, 8, 5], state: "minecraft:air"},
        {pos: [1, 8, 6], state: "minecraft:air"},
        {pos: [1, 8, 7], state: "minecraft:air"},
        {pos: [1, 8, 8], state: "minecraft:air"},
        {pos: [1, 8, 9], state: "minecraft:air"},
        {pos: [1, 8, 10], state: "minecraft:air"},
        {pos: [1, 8, 11], state: "minecraft:air"},
        {pos: [1, 8, 12], state: "minecraft:air"},
        {pos: [1, 8, 13], state: "minecraft:air"},
        {pos: [1, 8, 14], state: "minecraft:air"},
        {pos: [1, 8, 15], state: "minecraft:air"},
        {pos: [1, 8, 16], state: "minecraft:air"},
        {pos: [1, 8, 17], state: "minecraft:air"},
        {pos: [1, 8, 18], state: "minecraft:air"},
        {pos: [1, 8, 19], state: "minecraft:air"},
        {pos: [1, 8, 20], state: "minecraft:air"},
        {pos: [1, 8, 21], state: "minecraft:air"},
        {pos: [1, 8, 22], state: "minecraft:air"},
        {pos: [1, 8, 23], state: "minecraft:air"},
        {pos: [1, 8, 24], state: "minecraft:air"},
        {pos: [1, 8, 25], state: "minecraft:air"},
        {pos: [1, 8, 26], state: "minecraft:air"},
        {pos: [1, 8, 27], state: "minecraft:air"},
        {pos: [1, 8, 28], state: "minecraft:air"},
        {pos: [1, 8, 29], state: "minecraft:air"},
        {pos: [1, 8, 30], state: "minecraft:air"},
        {pos: [2, 8, 1], state: "minecraft:air"},
        {pos: [2, 8, 2], state: "minecraft:air"},
        {pos: [2, 8, 3], state: "minecraft:air"},
        {pos: [2, 8, 4], state: "minecraft:air"},
        {pos: [2, 8, 5], state: "minecraft:air"},
        {pos: [2, 8, 6], state: "minecraft:air"},
        {pos: [2, 8, 7], state: "minecraft:air"},
        {pos: [2, 8, 8], state: "minecraft:air"},
        {pos: [2, 8, 9], state: "minecraft:air"},
        {pos: [2, 8, 10], state: "minecraft:air"},
        {pos: [2, 8, 11], state: "minecraft:air"},
        {pos: [2, 8, 12], state: "minecraft:air"},
        {pos: [2, 8, 13], state: "minecraft:air"},
        {pos: [2, 8, 14], state: "minecraft:air"},
        {pos: [2, 8, 15], state: "minecraft:air"},
        {pos: [2, 8, 16], state: "minecraft:air"},
        {pos: [2, 8, 17], state: "minecraft:air"},
        {pos: [2, 8, 18], state: "minecraft:air"},
        {pos: [2, 8, 19], state: "minecraft:air"},
        {pos: [2, 8, 20], state: "minecraft:air"},
        {pos: [2, 8, 21], state: "minecraft:air"},
        {pos: [2, 8, 22], state: "minecraft:air"},
        {pos: [2, 8, 23], state: "minecraft:air"},
        {pos: [2, 8, 24], state: "minecraft:air"},
        {pos: [2, 8, 25], state: "minecraft:air"},
        {pos: [2, 8, 26], state: "minecraft:air"},
        {pos: [2, 8, 27], state: "minecraft:air"},
        {pos: [2, 8, 28], state: "minecraft:air"},
        {pos: [2, 8, 29], state: "minecraft:air"},
        {pos: [2, 8, 30], state: "minecraft:air"},
        {pos: [3, 8, 1], state: "minecraft:air"},
        {pos: [3, 8, 2], state: "minecraft:air"},
        {pos: [3, 8, 3], state: "minecraft:air"},
        {pos: [3, 8, 4], state: "minecraft:air"},
        {pos: [3, 8, 5], state: "minecraft:air"},
        {pos: [3, 8, 6], state: "minecraft:air"},
        {pos: [3, 8, 7], state: "minecraft:air"},
        {pos: [3, 8, 8], state: "minecraft:air"},
        {pos: [3, 8, 9], state: "minecraft:air"},
        {pos: [3, 8, 10], state: "minecraft:air"},
        {pos: [3, 8, 11], state: "minecraft:air"},
        {pos: [3, 8, 12], state: "minecraft:air"},
        {pos: [3, 8, 13], state: "minecraft:air"},
        {pos: [3, 8, 14], state: "minecraft:air"},
        {pos: [3, 8, 15], state: "minecraft:air"},
        {pos: [3, 8, 16], state: "minecraft:air"},
        {pos: [3, 8, 17], state: "minecraft:air"},
        {pos: [3, 8, 18], state: "minecraft:air"},
        {pos: [3, 8, 19], state: "minecraft:air"},
        {pos: [3, 8, 20], state: "minecraft:air"},
        {pos: [3, 8, 21], state: "minecraft:air"},
        {pos: [3, 8, 22], state: "minecraft:air"},
        {pos: [3, 8, 23], state: "minecraft:air"},
        {pos: [3, 8, 24], state: "minecraft:air"},
        {pos: [3, 8, 25], state: "minecraft:air"},
        {pos: [3, 8, 26], state: "minecraft:air"},
        {pos: [3, 8, 27], state: "minecraft:air"},
        {pos: [3, 8, 28], state: "minecraft:air"},
        {pos: [3, 8, 29], state: "minecraft:air"},
        {pos: [3, 8, 30], state: "minecraft:air"},
        {pos: [4, 8, 1], state: "minecraft:tuff_bricks"},
        {pos: [4, 8, 2], state: "minecraft:air"},
        {pos: [4, 8, 3], state: "minecraft:air"},
        {pos: [4, 8, 4], state: "minecraft:air"},
        {pos: [4, 8, 5], state: "minecraft:tuff_bricks"},
        {pos: [4, 8, 6], state: "minecraft:tuff_bricks"},
        {pos: [4, 8, 7], state: "minecraft:air"},
        {pos: [4, 8, 8], state: "minecraft:air"},
        {pos: [4, 8, 9], state: "minecraft:air"},
        {pos: [4, 8, 10], state: "minecraft:tuff_bricks"},
        {pos: [4, 8, 11], state: "minecraft:tuff_bricks"},
        {pos: [4, 8, 12], state: "minecraft:air"},
        {pos: [4, 8, 13], state: "minecraft:air"},
        {pos: [4, 8, 14], state: "minecraft:air"},
        {pos: [4, 8, 15], state: "minecraft:tuff_bricks"},
        {pos: [4, 8, 16], state: "minecraft:tuff_bricks"},
        {pos: [4, 8, 17], state: "minecraft:air"},
        {pos: [4, 8, 18], state: "minecraft:air"},
        {pos: [4, 8, 19], state: "minecraft:air"},
        {pos: [4, 8, 20], state: "minecraft:tuff_bricks"},
        {pos: [4, 8, 21], state: "minecraft:tuff_bricks"},
        {pos: [4, 8, 22], state: "minecraft:air"},
        {pos: [4, 8, 23], state: "minecraft:air"},
        {pos: [4, 8, 24], state: "minecraft:air"},
        {pos: [4, 8, 25], state: "minecraft:tuff_bricks"},
        {pos: [4, 8, 26], state: "minecraft:tuff_bricks"},
        {pos: [4, 8, 27], state: "minecraft:air"},
        {pos: [4, 8, 28], state: "minecraft:air"},
        {pos: [4, 8, 29], state: "minecraft:air"},
        {pos: [4, 8, 30], state: "minecraft:tuff_bricks"},
        {pos: [5, 8, 18], state: "minecraft:jigsaw{orientation:east_up}", nbt: {final_state: "minecraft:air", id: "minecraft:jigsaw", joint: "rollable", name: "minecraft:full_room_side_platform", placement_priority: 0, pool: "minecraft:empty", selection_priority: 0, target: "minecraft:empty"}},
        {pos: [0, 9, 1], state: "minecraft:tuff_bricks"},
        {pos: [0, 9, 2], state: "minecraft:polished_tuff"},
        {pos: [0, 9, 3], state: "minecraft:polished_tuff"},
        {pos: [0, 9, 4], state: "minecraft:polished_tuff"},
        {pos: [0, 9, 5], state: "minecraft:polished_tuff"},
        {pos: [0, 9, 6], state: "minecraft:polished_tuff"},
        {pos: [0, 9, 7], state: "minecraft:polished_tuff"},
        {pos: [0, 9, 8], state: "minecraft:polished_tuff"},
        {pos: [0, 9, 9], state: "minecraft:polished_tuff"},
        {pos: [0, 9, 10], state: "minecraft:polished_tuff"},
        {pos: [0, 9, 11], state: "minecraft:polished_tuff"},
        {pos: [0, 9, 12], state: "minecraft:polished_tuff"},
        {pos: [0, 9, 13], state: "minecraft:polished_tuff"},
        {pos: [0, 9, 14], state: "minecraft:polished_tuff"},
        {pos: [0, 9, 15], state: "minecraft:polished_tuff"},
        {pos: [0, 9, 16], state: "minecraft:polished_tuff"},
        {pos: [0, 9, 17], state: "minecraft:polished_tuff"},
        {pos: [0, 9, 18], state: "minecraft:polished_tuff"},
        {pos: [0, 9, 19], state: "minecraft:polished_tuff"},
        {pos: [0, 9, 20], state: "minecraft:polished_tuff"},
        {pos: [0, 9, 21], state: "minecraft:polished_tuff"},
        {pos: [0, 9, 22], state: "minecraft:polished_tuff"},
        {pos: [0, 9, 23], state: "minecraft:polished_tuff"},
        {pos: [0, 9, 24], state: "minecraft:polished_tuff"},
        {pos: [0, 9, 25], state: "minecraft:polished_tuff"},
        {pos: [0, 9, 26], state: "minecraft:polished_tuff"},
        {pos: [0, 9, 27], state: "minecraft:polished_tuff"},
        {pos: [0, 9, 28], state: "minecraft:polished_tuff"},
        {pos: [0, 9, 29], state: "minecraft:polished_tuff"},
        {pos: [0, 9, 30], state: "minecraft:tuff_bricks"},
        {pos: [1, 9, 1], state: "minecraft:polished_tuff"},
        {pos: [1, 9, 2], state: "minecraft:polished_tuff"},
        {pos: [1, 9, 3], state: "minecraft:polished_tuff"},
        {pos: [1, 9, 4], state: "minecraft:polished_tuff"},
        {pos: [1, 9, 5], state: "minecraft:polished_tuff"},
        {pos: [1, 9, 6], state: "minecraft:polished_tuff"},
        {pos: [1, 9, 7], state: "minecraft:polished_tuff"},
        {pos: [1, 9, 8], state: "minecraft:polished_tuff"},
        {pos: [1, 9, 9], state: "minecraft:polished_tuff"},
        {pos: [1, 9, 10], state: "minecraft:polished_tuff"},
        {pos: [1, 9, 11], state: "minecraft:polished_tuff"},
        {pos: [1, 9, 12], state: "minecraft:polished_tuff"},
        {pos: [1, 9, 13], state: "minecraft:polished_tuff"},
        {pos: [1, 9, 14], state: "minecraft:polished_tuff"},
        {pos: [1, 9, 15], state: "minecraft:polished_tuff"},
        {pos: [1, 9, 16], state: "minecraft:polished_tuff"},
        {pos: [1, 9, 17], state: "minecraft:polished_tuff"},
        {pos: [1, 9, 18], state: "minecraft:polished_tuff"},
        {pos: [1, 9, 19], state: "minecraft:polished_tuff"},
        {pos: [1, 9, 20], state: "minecraft:polished_tuff"},
        {pos: [1, 9, 21], state: "minecraft:polished_tuff"},
        {pos: [1, 9, 22], state: "minecraft:polished_tuff"},
        {pos: [1, 9, 23], state: "minecraft:polished_tuff"},
        {pos: [1, 9, 24], state: "minecraft:polished_tuff"},
        {pos: [1, 9, 25], state: "minecraft:polished_tuff"},
        {pos: [1, 9, 26], state: "minecraft:polished_tuff"},
        {pos: [1, 9, 27], state: "minecraft:polished_tuff"},
        {pos: [1, 9, 28], state: "minecraft:polished_tuff"},
        {pos: [1, 9, 29], state: "minecraft:polished_tuff"},
        {pos: [1, 9, 30], state: "minecraft:polished_tuff"},
        {pos: [2, 9, 1], state: "minecraft:polished_tuff"},
        {pos: [2, 9, 2], state: "minecraft:polished_tuff"},
        {pos: [2, 9, 3], state: "minecraft:polished_tuff"},
        {pos: [2, 9, 4], state: "minecraft:polished_tuff"},
        {pos: [2, 9, 5], state: "minecraft:polished_tuff"},
        {pos: [2, 9, 6], state: "minecraft:polished_tuff"},
        {pos: [2, 9, 7], state: "minecraft:polished_tuff"},
        {pos: [2, 9, 8], state: "minecraft:polished_tuff"},
        {pos: [2, 9, 9], state: "minecraft:polished_tuff"},
        {pos: [2, 9, 10], state: "minecraft:polished_tuff"},
        {pos: [2, 9, 11], state: "minecraft:polished_tuff"},
        {pos: [2, 9, 12], state: "minecraft:polished_tuff"},
        {pos: [2, 9, 13], state: "minecraft:polished_tuff"},
        {pos: [2, 9, 14], state: "minecraft:polished_tuff"},
        {pos: [2, 9, 15], state: "minecraft:polished_tuff"},
        {pos: [2, 9, 16], state: "minecraft:polished_tuff"},
        {pos: [2, 9, 17], state: "minecraft:polished_tuff"},
        {pos: [2, 9, 18], state: "minecraft:polished_tuff"},
        {pos: [2, 9, 19], state: "minecraft:polished_tuff"},
        {pos: [2, 9, 20], state: "minecraft:polished_tuff"},
        {pos: [2, 9, 21], state: "minecraft:polished_tuff"},
        {pos: [2, 9, 22], state: "minecraft:polished_tuff"},
        {pos: [2, 9, 23], state: "minecraft:polished_tuff"},
        {pos: [2, 9, 24], state: "minecraft:polished_tuff"},
        {pos: [2, 9, 25], state: "minecraft:polished_tuff"},
        {pos: [2, 9, 26], state: "minecraft:polished_tuff"},
        {pos: [2, 9, 27], state: "minecraft:polished_tuff"},
        {pos: [2, 9, 28], state: "minecraft:polished_tuff"},
        {pos: [2, 9, 29], state: "minecraft:polished_tuff"},
        {pos: [2, 9, 30], state: "minecraft:polished_tuff"},
        {pos: [3, 9, 1], state: "minecraft:polished_tuff"},
        {pos: [3, 9, 2], state: "minecraft:polished_tuff"},
        {pos: [3, 9, 3], state: "minecraft:polished_tuff"},
        {pos: [3, 9, 4], state: "minecraft:polished_tuff"},
        {pos: [3, 9, 5], state: "minecraft:polished_tuff"},
        {pos: [3, 9, 6], state: "minecraft:polished_tuff"},
        {pos: [3, 9, 7], state: "minecraft:polished_tuff"},
        {pos: [3, 9, 8], state: "minecraft:polished_tuff"},
        {pos: [3, 9, 9], state: "minecraft:polished_tuff"},
        {pos: [3, 9, 10], state: "minecraft:polished_tuff"},
        {pos: [3, 9, 11], state: "minecraft:polished_tuff"},
        {pos: [3, 9, 12], state: "minecraft:polished_tuff"},
        {pos: [3, 9, 13], state: "minecraft:polished_tuff"},
        {pos: [3, 9, 14], state: "minecraft:polished_tuff"},
        {pos: [3, 9, 15], state: "minecraft:polished_tuff"},
        {pos: [3, 9, 16], state: "minecraft:polished_tuff"},
        {pos: [3, 9, 17], state: "minecraft:polished_tuff"},
        {pos: [3, 9, 18], state: "minecraft:polished_tuff"},
        {pos: [3, 9, 19], state: "minecraft:polished_tuff"},
        {pos: [3, 9, 20], state: "minecraft:polished_tuff"},
        {pos: [3, 9, 21], state: "minecraft:polished_tuff"},
        {pos: [3, 9, 22], state: "minecraft:polished_tuff"},
        {pos: [3, 9, 23], state: "minecraft:polished_tuff"},
        {pos: [3, 9, 24], state: "minecraft:polished_tuff"},
        {pos: [3, 9, 25], state: "minecraft:polished_tuff"},
        {pos: [3, 9, 26], state: "minecraft:polished_tuff"},
        {pos: [3, 9, 27], state: "minecraft:polished_tuff"},
        {pos: [3, 9, 28], state: "minecraft:polished_tuff"},
        {pos: [3, 9, 29], state: "minecraft:polished_tuff"},
        {pos: [3, 9, 30], state: "minecraft:polished_tuff"},
        {pos: [4, 9, 1], state: "minecraft:tuff_bricks"},
        {pos: [4, 9, 2], state: "minecraft:polished_tuff"},
        {pos: [4, 9, 3], state: "minecraft:polished_tuff"},
        {pos: [4, 9, 4], state: "minecraft:polished_tuff"},
        {pos: [4, 9, 5], state: "minecraft:tuff_bricks"},
        {pos: [4, 9, 6], state: "minecraft:tuff_bricks"},
        {pos: [4, 9, 7], state: "minecraft:polished_tuff"},
        {pos: [4, 9, 8], state: "minecraft:polished_tuff"},
        {pos: [4, 9, 9], state: "minecraft:polished_tuff"},
        {pos: [4, 9, 10], state: "minecraft:tuff_bricks"},
        {pos: [4, 9, 11], state: "minecraft:tuff_bricks"},
        {pos: [4, 9, 12], state: "minecraft:polished_tuff"},
        {pos: [4, 9, 13], state: "minecraft:polished_tuff"},
        {pos: [4, 9, 14], state: "minecraft:polished_tuff"},
        {pos: [4, 9, 15], state: "minecraft:tuff_bricks"},
        {pos: [4, 9, 16], state: "minecraft:tuff_bricks"},
        {pos: [4, 9, 17], state: "minecraft:tuff_bricks"},
        {pos: [4, 9, 18], state: "minecraft:tuff_bricks"},
        {pos: [4, 9, 19], state: "minecraft:tuff_bricks"},
        {pos: [4, 9, 20], state: "minecraft:tuff_bricks"},
        {pos: [4, 9, 21], state: "minecraft:tuff_bricks"},
        {pos: [4, 9, 22], state: "minecraft:polished_tuff"},
        {pos: [4, 9, 23], state: "minecraft:polished_tuff"},
        {pos: [4, 9, 24], state: "minecraft:polished_tuff"},
        {pos: [4, 9, 25], state: "minecraft:tuff_bricks"},
        {pos: [4, 9, 26], state: "minecraft:tuff_bricks"},
        {pos: [4, 9, 27], state: "minecraft:polished_tuff"},
        {pos: [4, 9, 28], state: "minecraft:polished_tuff"},
        {pos: [4, 9, 29], state: "minecraft:polished_tuff"},
        {pos: [4, 9, 30], state: "minecraft:tuff_bricks"},
        {pos: [0, 10, 1], state: "minecraft:tuff_bricks"},
        {pos: [0, 10, 2], state: "minecraft:tuff_bricks"},
        {pos: [0, 10, 3], state: "minecraft:tuff_bricks"},
        {pos: [0, 10, 4], state: "minecraft:tuff_bricks"},
        {pos: [0, 10, 5], state: "minecraft:tuff_bricks"},
        {pos: [0, 10, 6], state: "minecraft:tuff_bricks"},
        {pos: [0, 10, 7], state: "minecraft:tuff_bricks"},
        {pos: [0, 10, 8], state: "minecraft:tuff_bricks"},
        {pos: [0, 10, 9], state: "minecraft:tuff_bricks"},
        {pos: [0, 10, 10], state: "minecraft:tuff_bricks"},
        {pos: [0, 10, 11], state: "minecraft:tuff_bricks"},
        {pos: [0, 10, 12], state: "minecraft:tuff_bricks"},
        {pos: [0, 10, 13], state: "minecraft:tuff_bricks"},
        {pos: [0, 10, 14], state: "minecraft:tuff_bricks"},
        {pos: [0, 10, 15], state: "minecraft:tuff_bricks"},
        {pos: [0, 10, 16], state: "minecraft:tuff_bricks"},
        {pos: [0, 10, 17], state: "minecraft:tuff_bricks"},
        {pos: [0, 10, 18], state: "minecraft:tuff_bricks"},
        {pos: [0, 10, 19], state: "minecraft:tuff_bricks"},
        {pos: [0, 10, 20], state: "minecraft:tuff_bricks"},
        {pos: [0, 10, 21], state: "minecraft:tuff_bricks"},
        {pos: [0, 10, 22], state: "minecraft:tuff_bricks"},
        {pos: [0, 10, 23], state: "minecraft:tuff_bricks"},
        {pos: [0, 10, 24], state: "minecraft:tuff_bricks"},
        {pos: [0, 10, 25], state: "minecraft:tuff_bricks"},
        {pos: [0, 10, 26], state: "minecraft:tuff_bricks"},
        {pos: [0, 10, 27], state: "minecraft:tuff_bricks"},
        {pos: [0, 10, 28], state: "minecraft:tuff_bricks"},
        {pos: [0, 10, 29], state: "minecraft:tuff_bricks"},
        {pos: [0, 10, 30], state: "minecraft:tuff_bricks"},
        {pos: [1, 10, 1], state: "minecraft:tuff_bricks"},
        {pos: [1, 10, 2], state: "minecraft:tuff_bricks"},
        {pos: [1, 10, 3], state: "minecraft:tuff_bricks"},
        {pos: [1, 10, 4], state: "minecraft:tuff_bricks"},
        {pos: [1, 10, 5], state: "minecraft:tuff_bricks"},
        {pos: [1, 10, 6], state: "minecraft:tuff_bricks"},
        {pos: [1, 10, 7], state: "minecraft:tuff_bricks"},
        {pos: [1, 10, 8], state: "minecraft:tuff_bricks"},
        {pos: [1, 10, 9], state: "minecraft:tuff_bricks"},
        {pos: [1, 10, 10], state: "minecraft:tuff_bricks"},
        {pos: [1, 10, 11], state: "minecraft:tuff_bricks"},
        {pos: [1, 10, 12], state: "minecraft:tuff_bricks"},
        {pos: [1, 10, 13], state: "minecraft:tuff_bricks"},
        {pos: [1, 10, 14], state: "minecraft:tuff_bricks"},
        {pos: [1, 10, 15], state: "minecraft:tuff_bricks"},
        {pos: [1, 10, 16], state: "minecraft:tuff_bricks"},
        {pos: [1, 10, 17], state: "minecraft:tuff_bricks"},
        {pos: [1, 10, 18], state: "minecraft:tuff_bricks"},
        {pos: [1, 10, 19], state: "minecraft:tuff_bricks"},
        {pos: [1, 10, 20], state: "minecraft:tuff_bricks"},
        {pos: [1, 10, 21], state: "minecraft:tuff_bricks"},
        {pos: [1, 10, 22], state: "minecraft:tuff_bricks"},
        {pos: [1, 10, 23], state: "minecraft:tuff_bricks"},
        {pos: [1, 10, 24], state: "minecraft:tuff_bricks"},
        {pos: [1, 10, 25], state: "minecraft:tuff_bricks"},
        {pos: [1, 10, 26], state: "minecraft:tuff_bricks"},
        {pos: [1, 10, 27], state: "minecraft:tuff_bricks"},
        {pos: [1, 10, 28], state: "minecraft:tuff_bricks"},
        {pos: [1, 10, 29], state: "minecraft:tuff_bricks"},
        {pos: [1, 10, 30], state: "minecraft:tuff_bricks"},
        {pos: [2, 10, 1], state: "minecraft:tuff_bricks"},
        {pos: [2, 10, 2], state: "minecraft:tuff_bricks"},
        {pos: [2, 10, 3], state: "minecraft:tuff_bricks"},
        {pos: [2, 10, 4], state: "minecraft:tuff_bricks"},
        {pos: [2, 10, 5], state: "minecraft:tuff_bricks"},
        {pos: [2, 10, 6], state: "minecraft:tuff_bricks"},
        {pos: [2, 10, 7], state: "minecraft:tuff_bricks"},
        {pos: [2, 10, 8], state: "minecraft:tuff_bricks"},
        {pos: [2, 10, 9], state: "minecraft:tuff_bricks"},
        {pos: [2, 10, 10], state: "minecraft:tuff_bricks"},
        {pos: [2, 10, 11], state: "minecraft:tuff_bricks"},
        {pos: [2, 10, 12], state: "minecraft:tuff_bricks"},
        {pos: [2, 10, 13], state: "minecraft:tuff_bricks"},
        {pos: [2, 10, 14], state: "minecraft:tuff_bricks"},
        {pos: [2, 10, 15], state: "minecraft:tuff_bricks"},
        {pos: [2, 10, 16], state: "minecraft:tuff_bricks"},
        {pos: [2, 10, 17], state: "minecraft:tuff_bricks"},
        {pos: [2, 10, 18], state: "minecraft:tuff_bricks"},
        {pos: [2, 10, 19], state: "minecraft:tuff_bricks"},
        {pos: [2, 10, 20], state: "minecraft:tuff_bricks"},
        {pos: [2, 10, 21], state: "minecraft:tuff_bricks"},
        {pos: [2, 10, 22], state: "minecraft:tuff_bricks"},
        {pos: [2, 10, 23], state: "minecraft:tuff_bricks"},
        {pos: [2, 10, 24], state: "minecraft:tuff_bricks"},
        {pos: [2, 10, 25], state: "minecraft:tuff_bricks"},
        {pos: [2, 10, 26], state: "minecraft:tuff_bricks"},
        {pos: [2, 10, 27], state: "minecraft:tuff_bricks"},
        {pos: [2, 10, 28], state: "minecraft:tuff_bricks"},
        {pos: [2, 10, 29], state: "minecraft:tuff_bricks"},
        {pos: [2, 10, 30], state: "minecraft:tuff_bricks"},
        {pos: [3, 10, 1], state: "minecraft:tuff_bricks"},
        {pos: [3, 10, 2], state: "minecraft:tuff_bricks"},
        {pos: [3, 10, 3], state: "minecraft:tuff_bricks"},
        {pos: [3, 10, 4], state: "minecraft:tuff_bricks"},
        {pos: [3, 10, 5], state: "minecraft:tuff_bricks"},
        {pos: [3, 10, 6], state: "minecraft:tuff_bricks"},
        {pos: [3, 10, 7], state: "minecraft:tuff_bricks"},
        {pos: [3, 10, 8], state: "minecraft:tuff_bricks"},
        {pos: [3, 10, 9], state: "minecraft:tuff_bricks"},
        {pos: [3, 10, 10], state: "minecraft:tuff_bricks"},
        {pos: [3, 10, 11], state: "minecraft:tuff_bricks"},
        {pos: [3, 10, 12], state: "minecraft:tuff_bricks"},
        {pos: [3, 10, 13], state: "minecraft:tuff_bricks"},
        {pos: [3, 10, 14], state: "minecraft:tuff_bricks"},
        {pos: [3, 10, 15], state: "minecraft:tuff_bricks"},
        {pos: [3, 10, 16], state: "minecraft:tuff_bricks"},
        {pos: [3, 10, 17], state: "minecraft:tuff_bricks"},
        {pos: [3, 10, 18], state: "minecraft:tuff_bricks"},
        {pos: [3, 10, 19], state: "minecraft:tuff_bricks"},
        {pos: [3, 10, 20], state: "minecraft:tuff_bricks"},
        {pos: [3, 10, 21], state: "minecraft:tuff_bricks"},
        {pos: [3, 10, 22], state: "minecraft:tuff_bricks"},
        {pos: [3, 10, 23], state: "minecraft:tuff_bricks"},
        {pos: [3, 10, 24], state: "minecraft:tuff_bricks"},
        {pos: [3, 10, 25], state: "minecraft:tuff_bricks"},
        {pos: [3, 10, 26], state: "minecraft:tuff_bricks"},
        {pos: [3, 10, 27], state: "minecraft:tuff_bricks"},
        {pos: [3, 10, 28], state: "minecraft:tuff_bricks"},
        {pos: [3, 10, 29], state: "minecraft:tuff_bricks"},
        {pos: [3, 10, 30], state: "minecraft:tuff_bricks"},
        {pos: [4, 10, 1], state: "minecraft:tuff_bricks"},
        {pos: [4, 10, 2], state: "minecraft:tuff_bricks"},
        {pos: [4, 10, 3], state: "minecraft:tuff_bricks"},
        {pos: [4, 10, 4], state: "minecraft:tuff_bricks"},
        {pos: [4, 10, 5], state: "minecraft:tuff_bricks"},
        {pos: [4, 10, 6], state: "minecraft:tuff_bricks"},
        {pos: [4, 10, 7], state: "minecraft:tuff_bricks"},
        {pos: [4, 10, 8], state: "minecraft:tuff_bricks"},
        {pos: [4, 10, 9], state: "minecraft:tuff_bricks"},
        {pos: [4, 10, 10], state: "minecraft:tuff_bricks"},
        {pos: [4, 10, 11], state: "minecraft:tuff_bricks"},
        {pos: [4, 10, 12], state: "minecraft:tuff_bricks"},
        {pos: [4, 10, 13], state: "minecraft:tuff_bricks"},
        {pos: [4, 10, 14], state: "minecraft:tuff_bricks"},
        {pos: [4, 10, 15], state: "minecraft:tuff_bricks"},
        {pos: [4, 10, 16], state: "minecraft:tuff_bricks"},
        {pos: [4, 10, 17], state: "minecraft:tuff_bricks"},
        {pos: [4, 10, 18], state: "minecraft:tuff_bricks"},
        {pos: [4, 10, 19], state: "minecraft:tuff_bricks"},
        {pos: [4, 10, 20], state: "minecraft:tuff_bricks"},
        {pos: [4, 10, 21], state: "minecraft:tuff_bricks"},
        {pos: [4, 10, 22], state: "minecraft:tuff_bricks"},
        {pos: [4, 10, 23], state: "minecraft:tuff_bricks"},
        {pos: [4, 10, 24], state: "minecraft:tuff_bricks"},
        {pos: [4, 10, 25], state: "minecraft:tuff_bricks"},
        {pos: [4, 10, 26], state: "minecraft:tuff_bricks"},
        {pos: [4, 10, 27], state: "minecraft:tuff_bricks"},
        {pos: [4, 10, 28], state: "minecraft:tuff_bricks"},
        {pos: [4, 10, 29], state: "minecraft:tuff_bricks"},
        {pos: [4, 10, 30], state: "minecraft:tuff_bricks"},
        {pos: [0, 11, 1], state: "minecraft:tuff_bricks"},
        {pos: [0, 11, 2], state: "minecraft:tuff_bricks"},
        {pos: [0, 11, 3], state: "minecraft:tuff_bricks"},
        {pos: [0, 11, 4], state: "minecraft:tuff_bricks"},
        {pos: [0, 11, 5], state: "minecraft:tuff_bricks"},
        {pos: [0, 11, 6], state: "minecraft:tuff_bricks"},
        {pos: [0, 11, 7], state: "minecraft:tuff_bricks"},
        {pos: [0, 11, 8], state: "minecraft:tuff_bricks"},
        {pos: [0, 11, 9], state: "minecraft:tuff_bricks"},
        {pos: [0, 11, 10], state: "minecraft:tuff_bricks"},
        {pos: [0, 11, 11], state: "minecraft:tuff_bricks"},
        {pos: [0, 11, 12], state: "minecraft:tuff_bricks"},
        {pos: [0, 11, 13], state: "minecraft:tuff_bricks"},
        {pos: [0, 11, 14], state: "minecraft:tuff_bricks"},
        {pos: [0, 11, 15], state: "minecraft:tuff_bricks"},
        {pos: [0, 11, 16], state: "minecraft:tuff_bricks"},
        {pos: [0, 11, 17], state: "minecraft:tuff_bricks"},
        {pos: [0, 11, 18], state: "minecraft:tuff_bricks"},
        {pos: [0, 11, 19], state: "minecraft:tuff_bricks"},
        {pos: [0, 11, 20], state: "minecraft:tuff_bricks"},
        {pos: [0, 11, 21], state: "minecraft:tuff_bricks"},
        {pos: [0, 11, 22], state: "minecraft:tuff_bricks"},
        {pos: [0, 11, 23], state: "minecraft:tuff_bricks"},
        {pos: [0, 11, 24], state: "minecraft:tuff_bricks"},
        {pos: [0, 11, 25], state: "minecraft:tuff_bricks"},
        {pos: [0, 11, 26], state: "minecraft:tuff_bricks"},
        {pos: [0, 11, 27], state: "minecraft:tuff_bricks"},
        {pos: [0, 11, 28], state: "minecraft:tuff_bricks"},
        {pos: [0, 11, 29], state: "minecraft:tuff_bricks"},
        {pos: [0, 11, 30], state: "minecraft:tuff_bricks"},
        {pos: [1, 11, 1], state: "minecraft:tuff_bricks"},
        {pos: [1, 11, 2], state: "minecraft:tuff_bricks"},
        {pos: [1, 11, 3], state: "minecraft:tuff_bricks"},
        {pos: [1, 11, 4], state: "minecraft:tuff_bricks"},
        {pos: [1, 11, 5], state: "minecraft:tuff_bricks"},
        {pos: [1, 11, 6], state: "minecraft:tuff_bricks"},
        {pos: [1, 11, 7], state: "minecraft:tuff_bricks"},
        {pos: [1, 11, 8], state: "minecraft:tuff_bricks"},
        {pos: [1, 11, 9], state: "minecraft:tuff_bricks"},
        {pos: [1, 11, 10], state: "minecraft:tuff_bricks"},
        {pos: [1, 11, 11], state: "minecraft:tuff_bricks"},
        {pos: [1, 11, 12], state: "minecraft:tuff_bricks"},
        {pos: [1, 11, 13], state: "minecraft:tuff_bricks"},
        {pos: [1, 11, 14], state: "minecraft:tuff_bricks"},
        {pos: [1, 11, 15], state: "minecraft:tuff_bricks"},
        {pos: [1, 11, 16], state: "minecraft:tuff_bricks"},
        {pos: [1, 11, 17], state: "minecraft:tuff_bricks"},
        {pos: [1, 11, 18], state: "minecraft:tuff_bricks"},
        {pos: [1, 11, 19], state: "minecraft:tuff_bricks"},
        {pos: [1, 11, 20], state: "minecraft:tuff_bricks"},
        {pos: [1, 11, 21], state: "minecraft:tuff_bricks"},
        {pos: [1, 11, 22], state: "minecraft:tuff_bricks"},
        {pos: [1, 11, 23], state: "minecraft:tuff_bricks"},
        {pos: [1, 11, 24], state: "minecraft:tuff_bricks"},
        {pos: [1, 11, 25], state: "minecraft:tuff_bricks"},
        {pos: [1, 11, 26], state: "minecraft:tuff_bricks"},
        {pos: [1, 11, 27], state: "minecraft:tuff_bricks"},
        {pos: [1, 11, 28], state: "minecraft:tuff_bricks"},
        {pos: [1, 11, 29], state: "minecraft:tuff_bricks"},
        {pos: [1, 11, 30], state: "minecraft:tuff_bricks"},
