{
    size: [29, 20, 21],
    data: [
        {pos: [5, 0, 0], state: "minecraft:tuff_bricks"},
        {pos: [5, 0, 1], state: "minecraft:tuff_bricks"},
        {pos: [5, 0, 2], state: "minecraft:tuff_bricks"},
        {pos: [5, 0, 3], state: "minecraft:tuff_bricks"},
        {pos: [5, 0, 4], state: "minecraft:tuff_bricks"},
        {pos: [5, 0, 5], state: "minecraft:tuff_bricks"},
        {pos: [5, 0, 6], state: "minecraft:tuff_bricks"},
        {pos: [5, 0, 7], state: "minecraft:tuff_bricks"},
        {pos: [5, 0, 8], state: "minecraft:tuff_bricks"},
        {pos: [5, 0, 9], state: "minecraft:tuff_bricks"},
        {pos: [5, 0, 10], state: "minecraft:tuff_bricks"},
        {pos: [5, 0, 11], state: "minecraft:tuff_bricks"},
        {pos: [5, 0, 12], state: "minecraft:tuff_bricks"},
        {pos: [5, 0, 13], state: "minecraft:tuff_bricks"},
        {pos: [5, 0, 14], state: "minecraft:tuff_bricks"},
        {pos: [5, 0, 15], state: "minecraft:tuff_bricks"},
        {pos: [5, 0, 16], state: "minecraft:tuff_bricks"},
        {pos: [5, 0, 17], state: "minecraft:tuff_bricks"},
        {pos: [5, 0, 18], state: "minecraft:tuff_bricks"},
        {pos: [5, 0, 19], state: "minecraft:tuff_bricks"},
        {pos: [5, 0, 20], state: "minecraft:tuff_bricks"},
        {pos: [6, 0, 0], state: "minecraft:tuff_bricks"},
        {pos: [6, 0, 1], state: "minecraft:tuff_bricks"},
        {pos: [6, 0, 2], state: "minecraft:tuff_bricks"},
        {pos: [6, 0, 3], state: "minecraft:tuff_bricks"},
        {pos: [6, 0, 4], state: "minecraft:tuff_bricks"},
        {pos: [6, 0, 5], state: "minecraft:tuff_bricks"},
        {pos: [6, 0, 6], state: "minecraft:tuff_bricks"},
        {pos: [6, 0, 7], state: "minecraft:tuff_bricks"},
        {pos: [6, 0, 8], state: "minecraft:tuff_bricks"},
        {pos: [6, 0, 9], state: "minecraft:tuff_bricks"},
        {pos: [6, 0, 10], state: "minecraft:tuff_bricks"},
        {pos: [6, 0, 11], state: "minecraft:tuff_bricks"},
        {pos: [6, 0, 12], state: "minecraft:tuff_bricks"},
        {pos: [6, 0, 13], state: "minecraft:tuff_bricks"},
        {pos: [6, 0, 14], state: "minecraft:tuff_bricks"},
        {pos: [6, 0, 15], state: "minecraft:tuff_bricks"},
        {pos: [6, 0, 16], state: "minecraft:tuff_bricks"},
        {pos: [6, 0, 17], state: "minecraft:tuff_bricks"},
        {pos: [6, 0, 18], state: "minecraft:tuff_bricks"},
        {pos: [6, 0, 19], state: "minecraft:tuff_bricks"},
        {pos: [6, 0, 20], state: "minecraft:tuff_bricks"},
        {pos: [7, 0, 0], state: "minecraft:tuff_bricks"},
        {pos: [7, 0, 1], state: "minecraft:tuff_bricks"},
        {pos: [7, 0, 2], state: "minecraft:tuff_bricks"},
        {pos: [7, 0, 3], state: "minecraft:tuff_bricks"},
        {pos: [7, 0, 4], state: "minecraft:tuff_bricks"},
        {pos: [7, 0, 5], state: "minecraft:tuff_bricks"},
        {pos: [7, 0, 6], state: "minecraft:tuff_bricks"},
        {pos: [7, 0, 7], state: "minecraft:tuff_bricks"},
        {pos: [7, 0, 8], state: "minecraft:tuff_bricks"},
        {pos: [7, 0, 9], state: "minecraft:tuff_bricks"},
        {pos: [7, 0, 10], state: "minecraft:tuff_bricks"},
        {pos: [7, 0, 11], state: "minecraft:tuff_bricks"},
        {pos: [7, 0, 12], state: "minecraft:tuff_bricks"},
        {pos: [7, 0, 13], state: "minecraft:tuff_bricks"},
        {pos: [7, 0, 14], state: "minecraft:tuff_bricks"},
        {pos: [7, 0, 15], state: "minecraft:tuff_bricks"},
        {pos: [7, 0, 16], state: "minecraft:tuff_bricks"},
        {pos: [7, 0, 17], state: "minecraft:tuff_bricks"},
        {pos: [7, 0, 18], state: "minecraft:tuff_bricks"},
        {pos: [7, 0, 19], state: "minecraft:tuff_bricks"},
        {pos: [7, 0, 20], state: "minecraft:tuff_bricks"},
        {pos: [8, 0, 0], state: "minecraft:tuff_bricks"},
        {pos: [8, 0, 1], state: "minecraft:tuff_bricks"},
        {pos: [8, 0, 2], state: "minecraft:tuff_bricks"},
        {pos: [8, 0, 3], state: "minecraft:tuff_bricks"},
        {pos: [8, 0, 4], state: "minecraft:tuff_bricks"},
        {pos: [8, 0, 5], state: "minecraft:tuff_bricks"},
        {pos: [8, 0, 6], state: "minecraft:tuff_bricks"},
        {pos: [8, 0, 7], state: "minecraft:tuff_bricks"},
        {pos: [8, 0, 8], state: "minecraft:tuff_bricks"},
        {pos: [8, 0, 9], state: "minecraft:tuff_bricks"},
        {pos: [8, 0, 10], state: "minecraft:tuff_bricks"},
        {pos: [8, 0, 11], state: "minecraft:tuff_bricks"},
        {pos: [8, 0, 12], state: "minecraft:tuff_bricks"},
        {pos: [8, 0, 13], state: "minecraft:tuff_bricks"},
        {pos: [8, 0, 14], state: "minecraft:tuff_bricks"},
        {pos: [8, 0, 15], state: "minecraft:tuff_bricks"},
        {pos: [8, 0, 16], state: "minecraft:tuff_bricks"},
        {pos: [8, 0, 17], state: "minecraft:tuff_bricks"},
        {pos: [8, 0, 18], state: "minecraft:tuff_bricks"},
        {pos: [8, 0, 19], state: "minecraft:tuff_bricks"},
        {pos: [8, 0, 20], state: "minecraft:tuff_bricks"},
        {pos: [9, 0, 0], state: "minecraft:tuff_bricks"},
        {pos: [9, 0, 1], state: "minecraft:tuff_bricks"},
        {pos: [9, 0, 2], state: "minecraft:tuff_bricks"},
        {pos: [9, 0, 3], state: "minecraft:tuff_bricks"},
        {pos: [9, 0, 4], state: "minecraft:tuff_bricks"},
        {pos: [9, 0, 5], state: "minecraft:tuff_bricks"},
        {pos: [9, 0, 6], state: "minecraft:tuff_bricks"},
        {pos: [9, 0, 7], state: "minecraft:tuff_bricks"},
        {pos: [9, 0, 8], state: "minecraft:tuff_bricks"},
        {pos: [9, 0, 9], state: "minecraft:tuff_bricks"},
        {pos: [9, 0, 10], state: "minecraft:tuff_bricks"},
        {pos: [9, 0, 11], state: "minecraft:tuff_bricks"},
        {pos: [9, 0, 12], state: "minecraft:tuff_bricks"},
        {pos: [9, 0, 13], state: "minecraft:tuff_bricks"},
        {pos: [9, 0, 14], state: "minecraft:tuff_bricks"},
        {pos: [9, 0, 15], state: "minecraft:tuff_bricks"},
        {pos: [9, 0, 16], state: "minecraft:tuff_bricks"},
        {pos: [9, 0, 17], state: "minecraft:tuff_bricks"},
        {pos: [9, 0, 18], state: "minecraft:tuff_bricks"},
        {pos: [9, 0, 19], state: "minecraft:tuff_bricks"},
        {pos: [9, 0, 20], state: "minecraft:tuff_bricks"},
        {pos: [10, 0, 0], state: "minecraft:tuff_bricks"},
        {pos: [10, 0, 1], state: "minecraft:tuff_bricks"},
        {pos: [10, 0, 2], state: "minecraft:tuff_bricks"},
        {pos: [10, 0, 3], state: "minecraft:tuff_bricks"},
        {pos: [10, 0, 4], state: "minecraft:tuff_bricks"},
        {pos: [10, 0, 5], state: "minecraft:tuff_bricks"},
        {pos: [10, 0, 6], state: "minecraft:tuff_bricks"},
        {pos: [10, 0, 7], state: "minecraft:tuff_bricks"},
        {pos: [10, 0, 8], state: "minecraft:tuff_bricks"},
        {pos: [10, 0, 9], state: "minecraft:tuff_bricks"},
        {pos: [10, 0, 10], state: "minecraft:tuff_bricks"},
        {pos: [10, 0, 11], state: "minecraft:tuff_bricks"},
        {pos: [10, 0, 12], state: "minecraft:tuff_bricks"},
        {pos: [10, 0, 13], state: "minecraft:tuff_bricks"},
        {pos: [10, 0, 14], state: "minecraft:tuff_bricks"},
        {pos: [10, 0, 15], state: "minecraft:tuff_bricks"},
        {pos: [10, 0, 16], state: "minecraft:tuff_bricks"},
        {pos: [10, 0, 17], state: "minecraft:tuff_bricks"},
        {pos: [10, 0, 18], state: "minecraft:tuff_bricks"},
        {pos: [10, 0, 19], state: "minecraft:tuff_bricks"},
        {pos: [10, 0, 20], state: "minecraft:tuff_bricks"},
        {pos: [11, 0, 0], state: "minecraft:tuff_bricks"},
        {pos: [11, 0, 1], state: "minecraft:tuff_bricks"},
        {pos: [11, 0, 2], state: "minecraft:tuff_bricks"},
        {pos: [11, 0, 3], state: "minecraft:tuff_bricks"},
        {pos: [11, 0, 4], state: "minecraft:tuff_bricks"},
        {pos: [11, 0, 5], state: "minecraft:tuff_bricks"},
        {pos: [11, 0, 6], state: "minecraft:tuff_bricks"},
        {pos: [11, 0, 7], state: "minecraft:tuff_bricks"},
        {pos: [11, 0, 8], state: "minecraft:tuff_bricks"},
        {pos: [11, 0, 9], state: "minecraft:tuff_bricks"},
        {pos: [11, 0, 10], state: "minecraft:tuff_bricks"},
        {pos: [11, 0, 11], state: "minecraft:tuff_bricks"},
        {pos: [11, 0, 12], state: "minecraft:tuff_bricks"},
        {pos: [11, 0, 13], state: "minecraft:tuff_bricks"},
        {pos: [11, 0, 14], state: "minecraft:tuff_bricks"},
        {pos: [11, 0, 15], state: "minecraft:tuff_bricks"},
        {pos: [11, 0, 16], state: "minecraft:tuff_bricks"},
        {pos: [11, 0, 17], state: "minecraft:tuff_bricks"},
        {pos: [11, 0, 18], state: "minecraft:tuff_bricks"},
        {pos: [11, 0, 19], state: "minecraft:tuff_bricks"},
        {pos: [11, 0, 20], state: "minecraft:tuff_bricks"},
        {pos: [12, 0, 0], state: "minecraft:tuff_bricks"},
        {pos: [12, 0, 1], state: "minecraft:tuff_bricks"},
        {pos: [12, 0, 2], state: "minecraft:tuff_bricks"},
        {pos: [12, 0, 3], state: "minecraft:tuff_bricks"},
        {pos: [12, 0, 4], state: "minecraft:tuff_bricks"},
        {pos: [12, 0, 5], state: "minecraft:tuff_bricks"},
        {pos: [12, 0, 6], state: "minecraft:tuff_bricks"},
        {pos: [12, 0, 7], state: "minecraft:tuff_bricks"},
        {pos: [12, 0, 8], state: "minecraft:tuff_bricks"},
        {pos: [12, 0, 9], state: "minecraft:tuff_bricks"},
        {pos: [12, 0, 10], state: "minecraft:tuff_bricks"},
        {pos: [12, 0, 11], state: "minecraft:tuff_bricks"},
        {pos: [12, 0, 12], state: "minecraft:tuff_bricks"},
        {pos: [12, 0, 13], state: "minecraft:tuff_bricks"},
        {pos: [12, 0, 14], state: "minecraft:tuff_bricks"},
        {pos: [12, 0, 15], state: "minecraft:tuff_bricks"},
        {pos: [12, 0, 16], state: "minecraft:tuff_bricks"},
        {pos: [12, 0, 17], state: "minecraft:tuff_bricks"},
        {pos: [12, 0, 18], state: "minecraft:tuff_bricks"},
        {pos: [12, 0, 19], state: "minecraft:tuff_bricks"},
        {pos: [12, 0, 20], state: "minecraft:tuff_bricks"},
        {pos: [13, 0, 0], state: "minecraft:tuff_bricks"},
        {pos: [13, 0, 1], state: "minecraft:tuff_bricks"},
        {pos: [13, 0, 2], state: "minecraft:tuff_bricks"},
        {pos: [13, 0, 3], state: "minecraft:tuff_bricks"},
        {pos: [13, 0, 4], state: "minecraft:tuff_bricks"},
        {pos: [13, 0, 5], state: "minecraft:tuff_bricks"},
        {pos: [13, 0, 6], state: "minecraft:tuff_bricks"},
        {pos: [13, 0, 7], state: "minecraft:tuff_bricks"},
        {pos: [13, 0, 8], state: "minecraft:tuff_bricks"},
        {pos: [13, 0, 9], state: "minecraft:tuff_bricks"},
        {pos: [13, 0, 10], state: "minecraft:tuff_bricks"},
        {pos: [13, 0, 11], state: "minecraft:tuff_bricks"},
        {pos: [13, 0, 12], state: "minecraft:tuff_bricks"},
        {pos: [13, 0, 13], state: "minecraft:tuff_bricks"},
        {pos: [13, 0, 14], state: "minecraft:tuff_bricks"},
        {pos: [13, 0, 15], state: "minecraft:tuff_bricks"},
        {pos: [13, 0, 16], state: "minecraft:tuff_bricks"},
        {pos: [13, 0, 17], state: "minecraft:tuff_bricks"},
        {pos: [13, 0, 18], state: "minecraft:tuff_bricks"},
        {pos: [13, 0, 19], state: "minecraft:tuff_bricks"},
        {pos: [13, 0, 20], state: "minecraft:tuff_bricks"},
        {pos: [14, 0, 0], state: "minecraft:jigsaw{orientation:north_up}", nbt: {final_state: "minecraft:tuff_bricks", id: "minecraft:jigsaw", joint: "rollable", name: "minecraft:atrium", placement_priority: 1, pool: "minecraft:empty", selection_priority: 1, target: "minecraft:empty"}},
        {pos: [14, 0, 1], state: "minecraft:tuff_bricks"},
        {pos: [14, 0, 2], state: "minecraft:tuff_bricks"},
        {pos: [14, 0, 3], state: "minecraft:tuff_bricks"},
        {pos: [14, 0, 4], state: "minecraft:tuff_bricks"},
        {pos: [14, 0, 5], state: "minecraft:tuff_bricks"},
        {pos: [14, 0, 6], state: "minecraft:tuff_bricks"},
        {pos: [14, 0, 7], state: "minecraft:tuff_bricks"},
        {pos: [14, 0, 8], state: "minecraft:tuff_bricks"},
        {pos: [14, 0, 9], state: "minecraft:tuff_bricks"},
        {pos: [14, 0, 10], state: "minecraft:tuff_bricks"},
        {pos: [14, 0, 11], state: "minecraft:tuff_bricks"},
        {pos: [14, 0, 12], state: "minecraft:tuff_bricks"},
        {pos: [14, 0, 13], state: "minecraft:tuff_bricks"},
        {pos: [14, 0, 14], state: "minecraft:tuff_bricks"},
        {pos: [14, 0, 15], state: "minecraft:tuff_bricks"},
        {pos: [14, 0, 16], state: "minecraft:tuff_bricks"},
        {pos: [14, 0, 17], state: "minecraft:tuff_bricks"},
        {pos: [14, 0, 18], state: "minecraft:tuff_bricks"},
        {pos: [14, 0, 19], state: "minecraft:tuff_bricks"},
        {pos: [14, 0, 20], state: "minecraft:tuff_bricks"},
        {pos: [15, 0, 0], state: "minecraft:tuff_bricks"},
        {pos: [15, 0, 1], state: "minecraft:tuff_bricks"},
        {pos: [15, 0, 2], state: "minecraft:tuff_bricks"},
        {pos: [15, 0, 3], state: "minecraft:tuff_bricks"},
        {pos: [15, 0, 4], state: "minecraft:tuff_bricks"},
        {pos: [15, 0, 5], state: "minecraft:tuff_bricks"},
        {pos: [15, 0, 6], state: "minecraft:tuff_bricks"},
        {pos: [15, 0, 7], state: "minecraft:tuff_bricks"},
        {pos: [15, 0, 8], state: "minecraft:tuff_bricks"},
        {pos: [15, 0, 9], state: "minecraft:tuff_bricks"},
        {pos: [15, 0, 10], state: "minecraft:tuff_bricks"},
        {pos: [15, 0, 11], state: "minecraft:tuff_bricks"},
        {pos: [15, 0, 12], state: "minecraft:tuff_bricks"},
        {pos: [15, 0, 13], state: "minecraft:tuff_bricks"},
        {pos: [15, 0, 14], state: "minecraft:tuff_bricks"},
        {pos: [15, 0, 15], state: "minecraft:tuff_bricks"},
        {pos: [15, 0, 16], state: "minecraft:tuff_bricks"},
        {pos: [15, 0, 17], state: "minecraft:tuff_bricks"},
        {pos: [15, 0, 18], state: "minecraft:tuff_bricks"},
        {pos: [15, 0, 19], state: "minecraft:tuff_bricks"},
        {pos: [15, 0, 20], state: "minecraft:tuff_bricks"},
        {pos: [16, 0, 0], state: "minecraft:tuff_bricks"},
        {pos: [16, 0, 1], state: "minecraft:tuff_bricks"},
        {pos: [16, 0, 2], state: "minecraft:tuff_bricks"},
        {pos: [16, 0, 3], state: "minecraft:tuff_bricks"},
        {pos: [16, 0, 4], state: "minecraft:tuff_bricks"},
        {pos: [16, 0, 5], state: "minecraft:tuff_bricks"},
        {pos: [16, 0, 6], state: "minecraft:tuff_bricks"},
        {pos: [16, 0, 7], state: "minecraft:tuff_bricks"},
        {pos: [16, 0, 8], state: "minecraft:tuff_bricks"},
        {pos: [16, 0, 9], state: "minecraft:tuff_bricks"},
        {pos: [16, 0, 10], state: "minecraft:tuff_bricks"},
        {pos: [16, 0, 11], state: "minecraft:tuff_bricks"},
        {pos: [16, 0, 12], state: "minecraft:tuff_bricks"},
        {pos: [16, 0, 13], state: "minecraft:tuff_bricks"},
        {pos: [16, 0, 14], state: "minecraft:tuff_bricks"},
        {pos: [16, 0, 15], state: "minecraft:tuff_bricks"},
        {pos: [16, 0, 16], state: "minecraft:tuff_bricks"},
        {pos: [16, 0, 17], state: "minecraft:tuff_bricks"},
        {pos: [16, 0, 18], state: "minecraft:tuff_bricks"},
        {pos: [16, 0, 19], state: "minecraft:tuff_bricks"},
        {pos: [16, 0, 20], state: "minecraft:tuff_bricks"},
        {pos: [17, 0, 0], state: "minecraft:tuff_bricks"},
        {pos: [17, 0, 1], state: "minecraft:tuff_bricks"},
        {pos: [17, 0, 2], state: "minecraft:tuff_bricks"},
        {pos: [17, 0, 3], state: "minecraft:tuff_bricks"},
        {pos: [17, 0, 4], state: "minecraft:tuff_bricks"},
        {pos: [17, 0, 5], state: "minecraft:tuff_bricks"},
        {pos: [17, 0, 6], state: "minecraft:tuff_bricks"},
        {pos: [17, 0, 7], state: "minecraft:tuff_bricks"},
        {pos: [17, 0, 8], state: "minecraft:tuff_bricks"},
        {pos: [17, 0, 9], state: "minecraft:tuff_bricks"},
        {pos: [17, 0, 10], state: "minecraft:tuff_bricks"},
        {pos: [17, 0, 11], state: "minecraft:tuff_bricks"},
        {pos: [17, 0, 12], state: "minecraft:tuff_bricks"},
        {pos: [17, 0, 13], state: "minecraft:tuff_bricks"},
        {pos: [17, 0, 14], state: "minecraft:tuff_bricks"},
        {pos: [17, 0, 15], state: "minecraft:tuff_bricks"},
        {pos: [17, 0, 16], state: "minecraft:tuff_bricks"},
        {pos: [17, 0, 17], state: "minecraft:tuff_bricks"},
        {pos: [17, 0, 18], state: "minecraft:tuff_bricks"},
        {pos: [17, 0, 19], state: "minecraft:tuff_bricks"},
        {pos: [17, 0, 20], state: "minecraft:tuff_bricks"},
        {pos: [18, 0, 0], state: "minecraft:tuff_bricks"},
        {pos: [18, 0, 1], state: "minecraft:tuff_bricks"},
        {pos: [18, 0, 2], state: "minecraft:tuff_bricks"},
        {pos: [18, 0, 3], state: "minecraft:tuff_bricks"},
        {pos: [18, 0, 4], state: "minecraft:tuff_bricks"},
        {pos: [18, 0, 5], state: "minecraft:tuff_bricks"},
        {pos: [18, 0, 6], state: "minecraft:tuff_bricks"},
        {pos: [18, 0, 7], state: "minecraft:tuff_bricks"},
        {pos: [18, 0, 8], state: "minecraft:tuff_bricks"},
        {pos: [18, 0, 9], state: "minecraft:tuff_bricks"},
        {pos: [18, 0, 10], state: "minecraft:tuff_bricks"},
        {pos: [18, 0, 11], state: "minecraft:tuff_bricks"},
        {pos: [18, 0, 12], state: "minecraft:tuff_bricks"},
        {pos: [18, 0, 13], state: "minecraft:tuff_bricks"},
        {pos: [18, 0, 14], state: "minecraft:tuff_bricks"},
        {pos: [18, 0, 15], state: "minecraft:tuff_bricks"},
        {pos: [18, 0, 16], state: "minecraft:tuff_bricks"},
        {pos: [18, 0, 17], state: "minecraft:tuff_bricks"},
        {pos: [18, 0, 18], state: "minecraft:tuff_bricks"},
        {pos: [18, 0, 19], state: "minecraft:tuff_bricks"},
        {pos: [18, 0, 20], state: "minecraft:tuff_bricks"},
        {pos: [19, 0, 0], state: "minecraft:tuff_bricks"},
        {pos: [19, 0, 1], state: "minecraft:tuff_bricks"},
        {pos: [19, 0, 2], state: "minecraft:tuff_bricks"},
        {pos: [19, 0, 3], state: "minecraft:tuff_bricks"},
        {pos: [19, 0, 4], state: "minecraft:tuff_bricks"},
        {pos: [19, 0, 5], state: "minecraft:tuff_bricks"},
        {pos: [19, 0, 6], state: "minecraft:tuff_bricks"},
        {pos: [19, 0, 7], state: "minecraft:tuff_bricks"},
        {pos: [19, 0, 8], state: "minecraft:tuff_bricks"},
        {pos: [19, 0, 9], state: "minecraft:tuff_bricks"},
        {pos: [19, 0, 10], state: "minecraft:tuff_bricks"},
        {pos: [19, 0, 11], state: "minecraft:tuff_bricks"},
        {pos: [19, 0, 12], state: "minecraft:tuff_bricks"},
        {pos: [19, 0, 13], state: "minecraft:tuff_bricks"},
        {pos: [19, 0, 14], state: "minecraft:tuff_bricks"},
        {pos: [19, 0, 15], state: "minecraft:tuff_bricks"},
        {pos: [19, 0, 16], state: "minecraft:tuff_bricks"},
        {pos: [19, 0, 17], state: "minecraft:tuff_bricks"},
        {pos: [19, 0, 18], state: "minecraft:tuff_bricks"},
        {pos: [19, 0, 19], state: "minecraft:tuff_bricks"},
        {pos: [19, 0, 20], state: "minecraft:tuff_bricks"},
        {pos: [20, 0, 0], state: "minecraft:tuff_bricks"},
        {pos: [20, 0, 1], state: "minecraft:tuff_bricks"},
        {pos: [20, 0, 2], state: "minecraft:tuff_bricks"},
        {pos: [20, 0, 3], state: "minecraft:tuff_bricks"},
        {pos: [20, 0, 4], state: "minecraft:tuff_bricks"},
        {pos: [20, 0, 5], state: "minecraft:tuff_bricks"},
        {pos: [20, 0, 6], state: "minecraft:tuff_bricks"},
        {pos: [20, 0, 7], state: "minecraft:tuff_bricks"},
        {pos: [20, 0, 8], state: "minecraft:tuff_bricks"},
        {pos: [20, 0, 9], state: "minecraft:tuff_bricks"},
        {pos: [20, 0, 10], state: "minecraft:tuff_bricks"},
        {pos: [20, 0, 11], state: "minecraft:tuff_bricks"},
        {pos: [20, 0, 12], state: "minecraft:tuff_bricks"},
        {pos: [20, 0, 13], state: "minecraft:tuff_bricks"},
        {pos: [20, 0, 14], state: "minecraft:tuff_bricks"},
        {pos: [20, 0, 15], state: "minecraft:tuff_bricks"},
        {pos: [20, 0, 16], state: "minecraft:tuff_bricks"},
        {pos: [20, 0, 17], state: "minecraft:tuff_bricks"},
        {pos: [20, 0, 18], state: "minecraft:tuff_bricks"},
        {pos: [20, 0, 19], state: "minecraft:tuff_bricks"},
        {pos: [20, 0, 20], state: "minecraft:tuff_bricks"},
        {pos: [21, 0, 0], state: "minecraft:tuff_bricks"},
        {pos: [21, 0, 1], state: "minecraft:tuff_bricks"},
        {pos: [21, 0, 2], state: "minecraft:tuff_bricks"},
        {pos: [21, 0, 3], state: "minecraft:tuff_bricks"},
        {pos: [21, 0, 4], state: "minecraft:tuff_bricks"},
        {pos: [21, 0, 5], state: "minecraft:tuff_bricks"},
        {pos: [21, 0, 6], state: "minecraft:tuff_bricks"},
        {pos: [21, 0, 7], state: "minecraft:tuff_bricks"},
        {pos: [21, 0, 8], state: "minecraft:tuff_bricks"},
        {pos: [21, 0, 9], state: "minecraft:tuff_bricks"},
        {pos: [21, 0, 10], state: "minecraft:tuff_bricks"},
        {pos: [21, 0, 11], state: "minecraft:tuff_bricks"},
        {pos: [21, 0, 12], state: "minecraft:tuff_bricks"},
        {pos: [21, 0, 13], state: "minecraft:tuff_bricks"},
        {pos: [21, 0, 14], state: "minecraft:tuff_bricks"},
        {pos: [21, 0, 15], state: "minecraft:tuff_bricks"},
        {pos: [21, 0, 16], state: "minecraft:tuff_bricks"},
        {pos: [21, 0, 17], state: "minecraft:tuff_bricks"},
        {pos: [21, 0, 18], state: "minecraft:tuff_bricks"},
        {pos: [21, 0, 19], state: "minecraft:tuff_bricks"},
        {pos: [21, 0, 20], state: "minecraft:tuff_bricks"},
        {pos: [22, 0, 0], state: "minecraft:tuff_bricks"},
        {pos: [22, 0, 1], state: "minecraft:tuff_bricks"},
        {pos: [22, 0, 2], state: "minecraft:tuff_bricks"},
        {pos: [22, 0, 3], state: "minecraft:tuff_bricks"},
        {pos: [22, 0, 4], state: "minecraft:tuff_bricks"},
        {pos: [22, 0, 5], state: "minecraft:tuff_bricks"},
        {pos: [22, 0, 6], state: "minecraft:tuff_bricks"},
        {pos: [22, 0, 7], state: "minecraft:tuff_bricks"},
        {pos: [22, 0, 8], state: "minecraft:tuff_bricks"},
        {pos: [22, 0, 9], state: "minecraft:tuff_bricks"},
        {pos: [22, 0, 10], state: "minecraft:tuff_bricks"},
        {pos: [22, 0, 11], state: "minecraft:tuff_bricks"},
        {pos: [22, 0, 12], state: "minecraft:tuff_bricks"},
        {pos: [22, 0, 13], state: "minecraft:tuff_bricks"},
        {pos: [22, 0, 14], state: "minecraft:tuff_bricks"},
        {pos: [22, 0, 15], state: "minecraft:tuff_bricks"},
        {pos: [22, 0, 16], state: "minecraft:tuff_bricks"},
        {pos: [22, 0, 17], state: "minecraft:tuff_bricks"},
        {pos: [22, 0, 18], state: "minecraft:tuff_bricks"},
        {pos: [22, 0, 19], state: "minecraft:tuff_bricks"},
        {pos: [22, 0, 20], state: "minecraft:tuff_bricks"},
        {pos: [23, 0, 0], state: "minecraft:tuff_bricks"},
        {pos: [23, 0, 1], state: "minecraft:tuff_bricks"},
        {pos: [23, 0, 2], state: "minecraft:tuff_bricks"},
        {pos: [23, 0, 3], state: "minecraft:tuff_bricks"},
        {pos: [23, 0, 4], state: "minecraft:tuff_bricks"},
        {pos: [23, 0, 5], state: "minecraft:tuff_bricks"},
        {pos: [23, 0, 6], state: "minecraft:tuff_bricks"},
        {pos: [23, 0, 7], state: "minecraft:tuff_bricks"},
        {pos: [23, 0, 8], state: "minecraft:tuff_bricks"},
        {pos: [23, 0, 9], state: "minecraft:tuff_bricks"},
        {pos: [23, 0, 10], state: "minecraft:tuff_bricks"},
        {pos: [23, 0, 11], state: "minecraft:tuff_bricks"},
        {pos: [23, 0, 12], state: "minecraft:tuff_bricks"},
        {pos: [23, 0, 13], state: "minecraft:tuff_bricks"},
        {pos: [23, 0, 14], state: "minecraft:tuff_bricks"},
        {pos: [23, 0, 15], state: "minecraft:tuff_bricks"},
        {pos: [23, 0, 16], state: "minecraft:tuff_bricks"},
        {pos: [23, 0, 17], state: "minecraft:tuff_bricks"},
        {pos: [23, 0, 18], state: "minecraft:tuff_bricks"},
        {pos: [23, 0, 19], state: "minecraft:tuff_bricks"},
        {pos: [23, 0, 20], state: "minecraft:tuff_bricks"},
        {pos: [5, 1, 0], state: "minecraft:tuff_bricks"},
        {pos: [5, 1, 1], state: "minecraft:tuff_bricks"},
        {pos: [5, 1, 2], state: "minecraft:tuff_bricks"},
        {pos: [5, 1, 3], state: "minecraft:tuff_bricks"},
        {pos: [5, 1, 4], state: "minecraft:tuff_bricks"},
        {pos: [5, 1, 5], state: "minecraft:tuff_bricks"},
        {pos: [5, 1, 6], state: "minecraft:tuff_bricks"},
        {pos: [5, 1, 7], state: "minecraft:tuff_bricks"},
        {pos: [5, 1, 8], state: "minecraft:tuff_bricks"},
        {pos: [5, 1, 9], state: "minecraft:tuff_bricks"},
        {pos: [5, 1, 10], state: "minecraft:tuff_bricks"},
        {pos: [5, 1, 11], state: "minecraft:tuff_bricks"},
        {pos: [5, 1, 12], state: "minecraft:tuff_bricks"},
        {pos: [5, 1, 13], state: "minecraft:tuff_bricks"},
        {pos: [5, 1, 14], state: "minecraft:tuff_bricks"},
        {pos: [5, 1, 15], state: "minecraft:tuff_bricks"},
        {pos: [5, 1, 16], state: "minecraft:tuff_bricks"},
        {pos: [5, 1, 17], state: "minecraft:tuff_bricks"},
        {pos: [5, 1, 18], state: "minecraft:tuff_bricks"},
        {pos: [5, 1, 19], state: "minecraft:tuff_bricks"},
        {pos: [5, 1, 20], state: "minecraft:tuff_bricks"},
        {pos: [6, 1, 0], state: "minecraft:tuff_bricks"},
        {pos: [6, 1, 1], state: "minecraft:tuff_bricks"},
        {pos: [6, 1, 2], state: "minecraft:tuff_bricks"},
        {pos: [6, 1, 3], state: "minecraft:tuff_bricks"},
        {pos: [6, 1, 4], state: "minecraft:tuff_bricks"},
        {pos: [6, 1, 5], state: "minecraft:tuff_bricks"},
        {pos: [6, 1, 6], state: "minecraft:tuff_bricks"},
        {pos: [6, 1, 7], state: "minecraft:tuff_bricks"},
        {pos: [6, 1, 8], state: "minecraft:tuff_bricks"},
        {pos: [6, 1, 9], state: "minecraft:tuff_bricks"},
        {pos: [6, 1, 10], state: "minecraft:tuff_bricks"},
        {pos: [6, 1, 11], state: "minecraft:tuff_bricks"},
        {pos: [6, 1, 12], state: "minecraft:tuff_bricks"},
        {pos: [6, 1, 13], state: "minecraft:tuff_bricks"},
        {pos: [6, 1, 14], state: "minecraft:tuff_bricks"},
        {pos: [6, 1, 15], state: "minecraft:tuff_bricks"},
        {pos: [6, 1, 16], state: "minecraft:tuff_bricks"},
        {pos: [6, 1, 17], state: "minecraft:tuff_bricks"},
        {pos: [6, 1, 18], state: "minecraft:tuff_bricks"},
        {pos: [6, 1, 19], state: "minecraft:tuff_bricks"},
        {pos: [6, 1, 20], state: "minecraft:tuff_bricks"},
        {pos: [7, 1, 0], state: "minecraft:tuff_bricks"},
        {pos: [7, 1, 1], state: "minecraft:tuff_bricks"},
        {pos: [7, 1, 2], state: "minecraft:tuff_bricks"},
        {pos: [7, 1, 3], state: "minecraft:tuff_bricks"},
        {pos: [7, 1, 4], state: "minecraft:tuff_bricks"},
        {pos: [7, 1, 5], state: "minecraft:tuff_bricks"},
        {pos: [7, 1, 6], state: "minecraft:tuff_bricks"},
        {pos: [7, 1, 7], state: "minecraft:tuff_bricks"},
        {pos: [7, 1, 8], state: "minecraft:tuff_bricks"},
        {pos: [7, 1, 9], state: "minecraft:tuff_bricks"},
        {pos: [7, 1, 10], state: "minecraft:tuff_bricks"},
        {pos: [7, 1, 11], state: "minecraft:tuff_bricks"},
        {pos: [7, 1, 12], state: "minecraft:tuff_bricks"},
        {pos: [7, 1, 13], state: "minecraft:tuff_bricks"},
        {pos: [7, 1, 14], state: "minecraft:tuff_bricks"},
        {pos: [7, 1, 15], state: "minecraft:tuff_bricks"},
        {pos: [7, 1, 16], state: "minecraft:tuff_bricks"},
        {pos: [7, 1, 17], state: "minecraft:tuff_bricks"},
        {pos: [7, 1, 18], state: "minecraft:tuff_bricks"},
        {pos: [7, 1, 19], state: "minecraft:tuff_bricks"},
        {pos: [7, 1, 20], state: "minecraft:tuff_bricks"},
        {pos: [8, 1, 0], state: "minecraft:tuff_bricks"},
        {pos: [8, 1, 1], state: "minecraft:tuff_bricks"},
        {pos: [8, 1, 2], state: "minecraft:tuff_bricks"},
        {pos: [8, 1, 3], state: "minecraft:tuff_bricks"},
        {pos: [8, 1, 4], state: "minecraft:tuff_bricks"},
        {pos: [8, 1, 5], state: "minecraft:tuff_bricks"},
        {pos: [8, 1, 6], state: "minecraft:tuff_bricks"},
        {pos: [8, 1, 7], state: "minecraft:tuff_bricks"},
        {pos: [8, 1, 8], state: "minecraft:tuff_bricks"},
        {pos: [8, 1, 9], state: "minecraft:tuff_bricks"},
        {pos: [8, 1, 10], state: "minecraft:tuff_bricks"},
        {pos: [8, 1, 11], state: "minecraft:tuff_bricks"},
        {pos: [8, 1, 12], state: "minecraft:tuff_bricks"},
        {pos: [8, 1, 13], state: "minecraft:tuff_bricks"},
        {pos: [8, 1, 14], state: "minecraft:tuff_bricks"},
        {pos: [8, 1, 15], state: "minecraft:tuff_bricks"},
        {pos: [8, 1, 16], state: "minecraft:tuff_bricks"},
        {pos: [8, 1, 17], state: "minecraft:tuff_bricks"},
        {pos: [8, 1, 18], state: "minecraft:tuff_bricks"},
        {pos: [8, 1, 19], state: "minecraft:tuff_bricks"},
        {pos: [8, 1, 20], state: "minecraft:tuff_bricks"},
        {pos: [9, 1, 0], state: "minecraft:tuff_bricks"},
        {pos: [9, 1, 1], state: "minecraft:tuff_bricks"},
        {pos: [9, 1, 2], state: "minecraft:tuff_bricks"},
        {pos: [9, 1, 3], state: "minecraft:tuff_bricks"},
        {pos: [9, 1, 4], state: "minecraft:tuff_bricks"},
        {pos: [9, 1, 5], state: "minecraft:tuff_bricks"},
        {pos: [9, 1, 6], state: "minecraft:tuff_bricks"},
        {pos: [9, 1, 7], state: "minecraft:tuff_bricks"},
        {pos: [9, 1, 8], state: "minecraft:tuff_bricks"},
        {pos: [9, 1, 9], state: "minecraft:tuff_bricks"},
        {pos: [9, 1, 10], state: "minecraft:tuff_bricks"},
        {pos: [9, 1, 11], state: "minecraft:tuff_bricks"},
        {pos: [9, 1, 12], state: "minecraft:tuff_bricks"},
        {pos: [9, 1, 13], state: "minecraft:tuff_bricks"},
        {pos: [9, 1, 14], state: "minecraft:tuff_bricks"},
        {pos: [9, 1, 15], state: "minecraft:tuff_bricks"},
        {pos: [9, 1, 16], state: "minecraft:tuff_bricks"},
        {pos: [9, 1, 17], state: "minecraft:tuff_bricks"},
        {pos: [9, 1, 18], state: "minecraft:tuff_bricks"},
        {pos: [9, 1, 19], state: "minecraft:tuff_bricks"},
        {pos: [9, 1, 20], state: "minecraft:tuff_bricks"},
        {pos: [10, 1, 0], state: "minecraft:tuff_bricks"},
        {pos: [10, 1, 1], state: "minecraft:tuff_bricks"},
        {pos: [10, 1, 2], state: "minecraft:tuff_bricks"},
        {pos: [10, 1, 3], state: "minecraft:tuff_bricks"},
        {pos: [10, 1, 4], state: "minecraft:tuff_bricks"},
        {pos: [10, 1, 5], state: "minecraft:tuff_bricks"},
        {pos: [10, 1, 6], state: "minecraft:tuff_bricks"},
        {pos: [10, 1, 7], state: "minecraft:tuff_bricks"},
        {pos: [10, 1, 8], state: "minecraft:tuff_bricks"},
        {pos: [10, 1, 9], state: "minecraft:tuff_bricks"},
        {pos: [10, 1, 10], state: "minecraft:tuff_bricks"},
        {pos: [10, 1, 11], state: "minecraft:tuff_bricks"},
        {pos: [10, 1, 12], state: "minecraft:tuff_bricks"},
        {pos: [10, 1, 13], state: "minecraft:tuff_bricks"},
        {pos: [10, 1, 14], state: "minecraft:tuff_bricks"},
        {pos: [10, 1, 15], state: "minecraft:tuff_bricks"},
        {pos: [10, 1, 16], state: "minecraft:tuff_bricks"},
        {pos: [10, 1, 17], state: "minecraft:tuff_bricks"},
        {pos: [10, 1, 18], state: "minecraft:tuff_bricks"},
        {pos: [10, 1, 19], state: "minecraft:tuff_bricks"},
        {pos: [10, 1, 20], state: "minecraft:tuff_bricks"},
        {pos: [11, 1, 0], state: "minecraft:tuff_bricks"},
        {pos: [11, 1, 1], state: "minecraft:tuff_bricks"},
        {pos: [11, 1, 2], state: "minecraft:tuff_bricks"},
        {pos: [11, 1, 3], state: "minecraft:tuff_bricks"},
        {pos: [11, 1, 4], state: "minecraft:tuff_bricks"},
        {pos: [11, 1, 5], state: "minecraft:tuff_bricks"},
        {pos: [11, 1, 6], state: "minecraft:tuff_bricks"},
        {pos: [11, 1, 7], state: "minecraft:tuff_bricks"},
        {pos: [11, 1, 8], state: "minecraft:tuff_bricks"},
        {pos: [11, 1, 9], state: "minecraft:tuff_bricks"},
        {pos: [11, 1, 10], state: "minecraft:tuff_bricks"},
        {pos: [11, 1, 11], state: "minecraft:tuff_bricks"},
        {pos: [11, 1, 12], state: "minecraft:tuff_bricks"},
        {pos: [11, 1, 13], state: "minecraft:tuff_bricks"},
        {pos: [11, 1, 14], state: "minecraft:tuff_bricks"},
        {pos: [11, 1, 15], state: "minecraft:tuff_bricks"},
        {pos: [11, 1, 16], state: "minecraft:tuff_bricks"},
        {pos: [11, 1, 17], state: "minecraft:tuff_bricks"},
        {pos: [11, 1, 18], state: "minecraft:tuff_bricks"},
        {pos: [11, 1, 19], state: "minecraft:tuff_bricks"},
        {pos: [11, 1, 20], state: "minecraft:tuff_bricks"},
        {pos: [12, 1, 0], state: "minecraft:tuff_bricks"},
        {pos: [12, 1, 1], state: "minecraft:tuff_bricks"},
        {pos: [12, 1, 2], state: "minecraft:tuff_bricks"},
        {pos: [12, 1, 3], state: "minecraft:tuff_bricks"},
        {pos: [12, 1, 4], state: "minecraft:tuff_bricks"},
        {pos: [12, 1, 5], state: "minecraft:tuff_bricks"},
        {pos: [12, 1, 6], state: "minecraft:tuff_bricks"},
        {pos: [12, 1, 7], state: "minecraft:tuff_bricks"},
        {pos: [12, 1, 8], state: "minecraft:tuff_bricks"},
        {pos: [12, 1, 9], state: "minecraft:tuff_bricks"},
        {pos: [12, 1, 10], state: "minecraft:tuff_bricks"},
        {pos: [12, 1, 11], state: "minecraft:tuff_bricks"},
        {pos: [12, 1, 12], state: "minecraft:tuff_bricks"},
        {pos: [12, 1, 13], state: "minecraft:tuff_bricks"},
        {pos: [12, 1, 14], state: "minecraft:tuff_bricks"},
        {pos: [12, 1, 15], state: "minecraft:tuff_bricks"},
        {pos: [12, 1, 16], state: "minecraft:tuff_bricks"},
        {pos: [12, 1, 17], state: "minecraft:tuff_bricks"},
        {pos: [12, 1, 18], state: "minecraft:tuff_bricks"},
        {pos: [12, 1, 19], state: "minecraft:tuff_bricks"},
        {pos: [12, 1, 20], state: "minecraft:tuff_bricks"},
        {pos: [13, 1, 0], state: "minecraft:tuff_bricks"},
        {pos: [13, 1, 1], state: "minecraft:tuff_bricks"},
        {pos: [13, 1, 2], state: "minecraft:tuff_bricks"},
        {pos: [13, 1, 3], state: "minecraft:tuff_bricks"},
        {pos: [13, 1, 4], state: "minecraft:tuff_bricks"},
        {pos: [13, 1, 5], state: "minecraft:tuff_bricks"},
        {pos: [13, 1, 6], state: "minecraft:tuff_bricks"},
        {pos: [13, 1, 7], state: "minecraft:tuff_bricks"},
        {pos: [13, 1, 8], state: "minecraft:tuff_bricks"},
        {pos: [13, 1, 9], state: "minecraft:tuff_bricks"},
        {pos: [13, 1, 10], state: "minecraft:tuff_bricks"},
        {pos: [13, 1, 11], state: "minecraft:tuff_bricks"},
        {pos: [13, 1, 12], state: "minecraft:tuff_bricks"},
        {pos: [13, 1, 13], state: "minecraft:tuff_bricks"},
        {pos: [13, 1, 14], state: "minecraft:tuff_bricks"},
        {pos: [13, 1, 15], state: "minecraft:tuff_bricks"},
        {pos: [13, 1, 16], state: "minecraft:tuff_bricks"},
        {pos: [13, 1, 17], state: "minecraft:tuff_bricks"},
        {pos: [13, 1, 18], state: "minecraft:tuff_bricks"},
        {pos: [13, 1, 19], state: "minecraft:tuff_bricks"},
        {pos: [13, 1, 20], state: "minecraft:tuff_bricks"},
        {pos: [14, 1, 0], state: "minecraft:tuff_bricks"},
        {pos: [14, 1, 1], state: "minecraft:tuff_bricks"},
        {pos: [14, 1, 2], state: "minecraft:jigsaw{orientation:down_north}", nbt: {final_state: "minecraft:tuff_bricks", id: "minecraft:jigsaw", joint: "aligned", name: "minecraft:slice", placement_priority: 0, pool: "minecraft:empty", selection_priority: 0, target: "minecraft:plate"}},
        {pos: [14, 1, 3], state: "minecraft:tuff_bricks"},
        {pos: [14, 1, 4], state: "minecraft:tuff_bricks"},
        {pos: [14, 1, 5], state: "minecraft:tuff_bricks"},
        {pos: [14, 1, 6], state: "minecraft:tuff_bricks"},
        {pos: [14, 1, 7], state: "minecraft:tuff_bricks"},
        {pos: [14, 1, 8], state: "minecraft:tuff_bricks"},
        {pos: [14, 1, 9], state: "minecraft:tuff_bricks"},
        {pos: [14, 1, 10], state: "minecraft:tuff_bricks"},
        {pos: [14, 1, 11], state: "minecraft:tuff_bricks"},
        {pos: [14, 1, 12], state: "minecraft:tuff_bricks"},
        {pos: [14, 1, 13], state: "minecraft:tuff_bricks"},
        {pos: [14, 1, 14], state: "minecraft:tuff_bricks"},
        {pos: [14, 1, 15], state: "minecraft:tuff_bricks"},
        {pos: [14, 1, 16], state: "minecraft:tuff_bricks"},
        {pos: [14, 1, 17], state: "minecraft:tuff_bricks"},
        {pos: [14, 1, 18], state: "minecraft:tuff_bricks"},
        {pos: [14, 1, 19], state: "minecraft:tuff_bricks"},
        {pos: [14, 1, 20], state: "minecraft:tuff_bricks"},
        {pos: [15, 1, 0], state: "minecraft:tuff_bricks"},
        {pos: [15, 1, 1], state: "minecraft:tuff_bricks"},
        {pos: [15, 1, 2], state: "minecraft:tuff_bricks"},
        {pos: [15, 1, 3], state: "minecraft:tuff_bricks"},
        {pos: [15, 1, 4], state: "minecraft:tuff_bricks"},
        {pos: [15, 1, 5], state: "minecraft:tuff_bricks"},
        {pos: [15, 1, 6], state: "minecraft:tuff_bricks"},
        {pos: [15, 1, 7], state: "minecraft:tuff_bricks"},
        {pos: [15, 1, 8], state: "minecraft:tuff_bricks"},
        {pos: [15, 1, 9], state: "minecraft:tuff_bricks"},
        {pos: [15, 1, 10], state: "minecraft:tuff_bricks"},
        {pos: [15, 1, 11], state: "minecraft:tuff_bricks"},
        {pos: [15, 1, 12], state: "minecraft:tuff_bricks"},
        {pos: [15, 1, 13], state: "minecraft:tuff_bricks"},
        {pos: [15, 1, 14], state: "minecraft:tuff_bricks"},
        {pos: [15, 1, 15], state: "minecraft:tuff_bricks"},
        {pos: [15, 1, 16], state: "minecraft:tuff_bricks"},
        {pos: [15, 1, 17], state: "minecraft:tuff_bricks"},
        {pos: [15, 1, 18], state: "minecraft:tuff_bricks"},
        {pos: [15, 1, 19], state: "minecraft:tuff_bricks"},
        {pos: [15, 1, 20], state: "minecraft:tuff_bricks"},
        {pos: [16, 1, 0], state: "minecraft:tuff_bricks"},
        {pos: [16, 1, 1], state: "minecraft:tuff_bricks"},
        {pos: [16, 1, 2], state: "minecraft:tuff_bricks"},
        {pos: [16, 1, 3], state: "minecraft:tuff_bricks"},
        {pos: [16, 1, 4], state: "minecraft:tuff_bricks"},
        {pos: [16, 1, 5], state: "minecraft:tuff_bricks"},
        {pos: [16, 1, 6], state: "minecraft:tuff_bricks"},
        {pos: [16, 1, 7], state: "minecraft:tuff_bricks"},
        {pos: [16, 1, 8], state: "minecraft:tuff_bricks"},
        {pos: [16, 1, 9], state: "minecraft:tuff_bricks"},
        {pos: [16, 1, 10], state: "minecraft:tuff_bricks"},
        {pos: [16, 1, 11], state: "minecraft:tuff_bricks"},
        {pos: [16, 1, 12], state: "minecraft:tuff_bricks"},
        {pos: [16, 1, 13], state: "minecraft:tuff_bricks"},
        {pos: [16, 1, 14], state: "minecraft:tuff_bricks"},
        {pos: [16, 1, 15], state: "minecraft:tuff_bricks"},
        {pos: [16, 1, 16], state: "minecraft:tuff_bricks"},
        {pos: [16, 1, 17], state: "minecraft:tuff_bricks"},
        {pos: [16, 1, 18], state: "minecraft:tuff_bricks"},
        {pos: [16, 1, 19], state: "minecraft:tuff_bricks"},
        {pos: [16, 1, 20], state: "minecraft:tuff_bricks"},
        {pos: [17, 1, 0], state: "minecraft:tuff_bricks"},
        {pos: [17, 1, 1], state: "minecraft:tuff_bricks"},
        {pos: [17, 1, 2], state: "minecraft:tuff_bricks"},
        {pos: [17, 1, 3], state: "minecraft:tuff_bricks"},
        {pos: [17, 1, 4], state: "minecraft:tuff_bricks"},
        {pos: [17, 1, 5], state: "minecraft:tuff_bricks"},
        {pos: [17, 1, 6], state: "minecraft:tuff_bricks"},
        {pos: [17, 1, 7], state: "minecraft:tuff_bricks"},
        {pos: [17, 1, 8], state: "minecraft:tuff_bricks"},
        {pos: [17, 1, 9], state: "minecraft:tuff_bricks"},
        {pos: [17, 1, 10], state: "minecraft:tuff_bricks"},
        {pos: [17, 1, 11], state: "minecraft:tuff_bricks"},
        {pos: [17, 1, 12], state: "minecraft:tuff_bricks"},
        {pos: [17, 1, 13], state: "minecraft:tuff_bricks"},
        {pos: [17, 1, 14], state: "minecraft:tuff_bricks"},
        {pos: [17, 1, 15], state: "minecraft:tuff_bricks"},
        {pos: [17, 1, 16], state: "minecraft:tuff_bricks"},
        {pos: [17, 1, 17], state: "minecraft:tuff_bricks"},
        {pos: [17, 1, 18], state: "minecraft:tuff_bricks"},
        {pos: [17, 1, 19], state: "minecraft:tuff_bricks"},
        {pos: [17, 1, 20], state: "minecraft:tuff_bricks"},
        {pos: [18, 1, 0], state: "minecraft:tuff_bricks"},
        {pos: [18, 1, 1], state: "minecraft:tuff_bricks"},
        {pos: [18, 1, 2], state: "minecraft:tuff_bricks"},
        {pos: [18, 1, 3], state: "minecraft:tuff_bricks"},
        {pos: [18, 1, 4], state: "minecraft:tuff_bricks"},
        {pos: [18, 1, 5], state: "minecraft:tuff_bricks"},
        {pos: [18, 1, 6], state: "minecraft:tuff_bricks"},
        {pos: [18, 1, 7], state: "minecraft:tuff_bricks"},
        {pos: [18, 1, 8], state: "minecraft:tuff_bricks"},
        {pos: [18, 1, 9], state: "minecraft:tuff_bricks"},
        {pos: [18, 1, 10], state: "minecraft:tuff_bricks"},
        {pos: [18, 1, 11], state: "minecraft:tuff_bricks"},
        {pos: [18, 1, 12], state: "minecraft:tuff_bricks"},
        {pos: [18, 1, 13], state: "minecraft:tuff_bricks"},
        {pos: [18, 1, 14], state: "minecraft:tuff_bricks"},
        {pos: [18, 1, 15], state: "minecraft:tuff_bricks"},
        {pos: [18, 1, 16], state: "minecraft:tuff_bricks"},
        {pos: [18, 1, 17], state: "minecraft:tuff_bricks"},
        {pos: [18, 1, 18], state: "minecraft:tuff_bricks"},
        {pos: [18, 1, 19], state: "minecraft:tuff_bricks"},
        {pos: [18, 1, 20], state: "minecraft:tuff_bricks"},
        {pos: [19, 1, 0], state: "minecraft:tuff_bricks"},
        {pos: [19, 1, 1], state: "minecraft:tuff_bricks"},
        {pos: [19, 1, 2], state: "minecraft:tuff_bricks"},
        {pos: [19, 1, 3], state: "minecraft:tuff_bricks"},
        {pos: [19, 1, 4], state: "minecraft:tuff_bricks"},
        {pos: [19, 1, 5], state: "minecraft:tuff_bricks"},
        {pos: [19, 1, 6], state: "minecraft:tuff_bricks"},
        {pos: [19, 1, 7], state: "minecraft:tuff_bricks"},
        {pos: [19, 1, 8], state: "minecraft:tuff_bricks"},
        {pos: [19, 1, 9], state: "minecraft:tuff_bricks"},
        {pos: [19, 1, 10], state: "minecraft:tuff_bricks"},
        {pos: [19, 1, 11], state: "minecraft:tuff_bricks"},
        {pos: [19, 1, 12], state: "minecraft:tuff_bricks"},
        {pos: [19, 1, 13], state: "minecraft:tuff_bricks"},
        {pos: [19, 1, 14], state: "minecraft:tuff_bricks"},
        {pos: [19, 1, 15], state: "minecraft:tuff_bricks"},
        {pos: [19, 1, 16], state: "minecraft:tuff_bricks"},
        {pos: [19, 1, 17], state: "minecraft:tuff_bricks"},
        {pos: [19, 1, 18], state: "minecraft:tuff_bricks"},
        {pos: [19, 1, 19], state: "minecraft:tuff_bricks"},
        {pos: [19, 1, 20], state: "minecraft:tuff_bricks"},
        {pos: [20, 1, 0], state: "minecraft:tuff_bricks"},
        {pos: [20, 1, 1], state: "minecraft:tuff_bricks"},
        {pos: [20, 1, 2], state: "minecraft:tuff_bricks"},
        {pos: [20, 1, 3], state: "minecraft:tuff_bricks"},
        {pos: [20, 1, 4], state: "minecraft:tuff_bricks"},
        {pos: [20, 1, 5], state: "minecraft:tuff_bricks"},
        {pos: [20, 1, 6], state: "minecraft:tuff_bricks"},
        {pos: [20, 1, 7], state: "minecraft:tuff_bricks"},
        {pos: [20, 1, 8], state: "minecraft:tuff_bricks"},
        {pos: [20, 1, 9], state: "minecraft:tuff_bricks"},
        {pos: [20, 1, 10], state: "minecraft:tuff_bricks"},
        {pos: [20, 1, 11], state: "minecraft:tuff_bricks"},
        {pos: [20, 1, 12], state: "minecraft:tuff_bricks"},
        {pos: [20, 1, 13], state: "minecraft:tuff_bricks"},
        {pos: [20, 1, 14], state: "minecraft:tuff_bricks"},
        {pos: [20, 1, 15], state: "minecraft:tuff_bricks"},
        {pos: [20, 1, 16], state: "minecraft:tuff_bricks"},
        {pos: [20, 1, 17], state: "minecraft:tuff_bricks"},
        {pos: [20, 1, 18], state: "minecraft:tuff_bricks"},
        {pos: [20, 1, 19], state: "minecraft:tuff_bricks"},
        {pos: [20, 1, 20], state: "minecraft:tuff_bricks"},
        {pos: [21, 1, 0], state: "minecraft:tuff_bricks"},
        {pos: [21, 1, 1], state: "minecraft:tuff_bricks"},
        {pos: [21, 1, 2], state: "minecraft:tuff_bricks"},
        {pos: [21, 1, 3], state: "minecraft:tuff_bricks"},
        {pos: [21, 1, 4], state: "minecraft:tuff_bricks"},
        {pos: [21, 1, 5], state: "minecraft:tuff_bricks"},
        {pos: [21, 1, 6], state: "minecraft:tuff_bricks"},
        {pos: [21, 1, 7], state: "minecraft:tuff_bricks"},
        {pos: [21, 1, 8], state: "minecraft:tuff_bricks"},
        {pos: [21, 1, 9], state: "minecraft:tuff_bricks"},
        {pos: [21, 1, 10], state: "minecraft:tuff_bricks"},
        {pos: [21, 1, 11], state: "minecraft:tuff_bricks"},
        {pos: [21, 1, 12], state: "minecraft:tuff_bricks"},
        {pos: [21, 1, 13], state: "minecraft:tuff_bricks"},
        {pos: [21, 1, 14], state: "minecraft:tuff_bricks"},
        {pos: [21, 1, 15], state: "minecraft:tuff_bricks"},
        {pos: [21, 1, 16], state: "minecraft:tuff_bricks"},
        {pos: [21, 1, 17], state: "minecraft:tuff_bricks"},
        {pos: [21, 1, 18], state: "minecraft:tuff_bricks"},
        {pos: [21, 1, 19], state: "minecraft:tuff_bricks"},
        {pos: [21, 1, 20], state: "minecraft:tuff_bricks"},
        {pos: [22, 1, 0], state: "minecraft:tuff_bricks"},
        {pos: [22, 1, 1], state: "minecraft:tuff_bricks"},
        {pos: [22, 1, 2], state: "minecraft:tuff_bricks"},
        {pos: [22, 1, 3], state: "minecraft:tuff_bricks"},
        {pos: [22, 1, 4], state: "minecraft:tuff_bricks"},
        {pos: [22, 1, 5], state: "minecraft:tuff_bricks"},
        {pos: [22, 1, 6], state: "minecraft:tuff_bricks"},
        {pos: [22, 1, 7], state: "minecraft:tuff_bricks"},
        {pos: [22, 1, 8], state: "minecraft:tuff_bricks"},
        {pos: [22, 1, 9], state: "minecraft:tuff_bricks"},
        {pos: [22, 1, 10], state: "minecraft:tuff_bricks"},
        {pos: [22, 1, 11], state: "minecraft:tuff_bricks"},
        {pos: [22, 1, 12], state: "minecraft:tuff_bricks"},
        {pos: [22, 1, 13], state: "minecraft:tuff_bricks"},
        {pos: [22, 1, 14], state: "minecraft:tuff_bricks"},
        {pos: [22, 1, 15], state: "minecraft:tuff_bricks"},
        {pos: [22, 1, 16], state: "minecraft:tuff_bricks"},
        {pos: [22, 1, 17], state: "minecraft:tuff_bricks"},
        {pos: [22, 1, 18], state: "minecraft:tuff_bricks"},
        {pos: [22, 1, 19], state: "minecraft:tuff_bricks"},
        {pos: [22, 1, 20], state: "minecraft:tuff_bricks"},
        {pos: [23, 1, 0], state: "minecraft:tuff_bricks"},
        {pos: [23, 1, 1], state: "minecraft:tuff_bricks"},
        {pos: [23, 1, 2], state: "minecraft:tuff_bricks"},
        {pos: [23, 1, 3], state: "minecraft:tuff_bricks"},
        {pos: [23, 1, 4], state: "minecraft:tuff_bricks"},
        {pos: [23, 1, 5], state: "minecraft:tuff_bricks"},
        {pos: [23, 1, 6], state: "minecraft:tuff_bricks"},
        {pos: [23, 1, 7], state: "minecraft:tuff_bricks"},
        {pos: [23, 1, 8], state: "minecraft:tuff_bricks"},
        {pos: [23, 1, 9], state: "minecraft:tuff_bricks"},
        {pos: [23, 1, 10], state: "minecraft:tuff_bricks"},
        {pos: [23, 1, 11], state: "minecraft:tuff_bricks"},
        {pos: [23, 1, 12], state: "minecraft:tuff_bricks"},
        {pos: [23, 1, 13], state: "minecraft:tuff_bricks"},
        {pos: [23, 1, 14], state: "minecraft:tuff_bricks"},
        {pos: [23, 1, 15], state: "minecraft:tuff_bricks"},
        {pos: [23, 1, 16], state: "minecraft:tuff_bricks"},
        {pos: [23, 1, 17], state: "minecraft:tuff_bricks"},
        {pos: [23, 1, 18], state: "minecraft:tuff_bricks"},
        {pos: [23, 1, 19], state: "minecraft:tuff_bricks"},
        {pos: [23, 1, 20], state: "minecraft:tuff_bricks"},
        {pos: [5, 2, 0], state: "minecraft:tuff_bricks"},
        {pos: [5, 2, 1], state: "minecraft:tuff_bricks"},
        {pos: [5, 2, 2], state: "minecraft:tuff_bricks"},
        {pos: [5, 2, 3], state: "minecraft:tuff_bricks"},
        {pos: [5, 2, 4], state: "minecraft:tuff_bricks"},
        {pos: [5, 2, 5], state: "minecraft:tuff_bricks"},
        {pos: [5, 2, 6], state: "minecraft:tuff_bricks"},
        {pos: [5, 2, 7], state: "minecraft:tuff_bricks"},
        {pos: [5, 2, 8], state: "minecraft:tuff_bricks"},
        {pos: [5, 2, 9], state: "minecraft:tuff_bricks"},
        {pos: [5, 2, 10], state: "minecraft:tuff_bricks"},
        {pos: [5, 2, 11], state: "minecraft:tuff_bricks"},
        {pos: [5, 2, 12], state: "minecraft:tuff_bricks"},
        {pos: [5, 2, 13], state: "minecraft:tuff_bricks"},
        {pos: [5, 2, 14], state: "minecraft:tuff_bricks"},
        {pos: [5, 2, 15], state: "minecraft:tuff_bricks"},
        {pos: [5, 2, 16], state: "minecraft:tuff_bricks"},
        {pos: [5, 2, 17], state: "minecraft:tuff_bricks"},
        {pos: [5, 2, 18], state: "minecraft:tuff_bricks"},
        {pos: [5, 2, 19], state: "minecraft:tuff_bricks"},
        {pos: [5, 2, 20], state: "minecraft:tuff_bricks"},
        {pos: [6, 2, 0], state: "minecraft:tuff_bricks"},
        {pos: [6, 2, 1], state: "minecraft:tuff_bricks"},
        {pos: [6, 2, 2], state: "minecraft:tuff_bricks"},
        {pos: [6, 2, 3], state: "minecraft:tuff_bricks"},
        {pos: [6, 2, 4], state: "minecraft:tuff_bricks"},
        {pos: [6, 2, 5], state: "minecraft:tuff_bricks"},
        {pos: [6, 2, 6], state: "minecraft:tuff_bricks"},
        {pos: [6, 2, 7], state: "minecraft:tuff_bricks"},
        {pos: [6, 2, 8], state: "minecraft:tuff_bricks"},
        {pos: [6, 2, 9], state: "minecraft:tuff_bricks"},
        {pos: [6, 2, 10], state: "minecraft:tuff_bricks"},
        {pos: [6, 2, 11], state: "minecraft:tuff_bricks"},
        {pos: [6, 2, 12], state: "minecraft:tuff_bricks"},
        {pos: [6, 2, 13], state: "minecraft:tuff_bricks"},
        {pos: [6, 2, 14], state: "minecraft:tuff_bricks"},
        {pos: [6, 2, 15], state: "minecraft:tuff_bricks"},
        {pos: [6, 2, 16], state: "minecraft:tuff_bricks"},
        {pos: [6, 2, 17], state: "minecraft:tuff_bricks"},
        {pos: [6, 2, 18], state: "minecraft:tuff_bricks"},
        {pos: [6, 2, 19], state: "minecraft:tuff_bricks"},
        {pos: [6, 2, 20], state: "minecraft:tuff_bricks"},
        {pos: [7, 2, 0], state: "minecraft:tuff_bricks"},
        {pos: [7, 2, 1], state: "minecraft:waxed_oxidized_copper"},
        {pos: [7, 2, 2], state: "minecraft:waxed_oxidized_copper"},
        {pos: [7, 2, 3], state: "minecraft:waxed_oxidized_copper"},
        {pos: [7, 2, 4], state: "minecraft:tuff_bricks"},
        {pos: [7, 2, 5], state: "minecraft:tuff_bricks"},
        {pos: [7, 2, 6], state: "minecraft:waxed_oxidized_copper"},
        {pos: [7, 2, 7], state: "minecraft:waxed_oxidized_copper"},
        {pos: [7, 2, 8], state: "minecraft:waxed_oxidized_copper"},
        {pos: [7, 2, 9], state: "minecraft:waxed_oxidized_copper"},
        {pos: [7, 2, 10], state: "minecraft:waxed_oxidized_copper"},
        {pos: [7, 2, 11], state: "minecraft:waxed_oxidized_copper"},
        {pos: [7, 2, 12], state: "minecraft:waxed_oxidized_copper"},
        {pos: [7, 2, 13], state: "minecraft:waxed_oxidized_copper"},
        {pos: [7, 2, 14], state: "minecraft:tuff_bricks"},
        {pos: [7, 2, 15], state: "minecraft:tuff_bricks"},
        {pos: [7, 2, 16], state: "minecraft:tuff_bricks"},
        {pos: [7, 2, 17], state: "minecraft:tuff_bricks"},
        {pos: [7, 2, 18], state: "minecraft:tuff_bricks"},
        {pos: [7, 2, 19], state: "minecraft:tuff_bricks"},
        {pos: [7, 2, 20], state: "minecraft:tuff_bricks"},
        {pos: [8, 2, 0], state: "minecraft:tuff_bricks"},
        {pos: [8, 2, 1], state: "minecraft:waxed_oxidized_copper"},
        {pos: [8, 2, 2], state: "minecraft:waxed_oxidized_copper"},
        {pos: [8, 2, 3], state: "minecraft:waxed_oxidized_copper"},
        {pos: [8, 2, 4], state: "minecraft:waxed_oxidized_copper"},
        {pos: [8, 2, 5], state: "minecraft:waxed_oxidized_copper"},
        {pos: [8, 2, 6], state: "minecraft:waxed_oxidized_copper"},
        {pos: [8, 2, 7], state: "minecraft:waxed_oxidized_copper"},
        {pos: [8, 2, 8], state: "minecraft:waxed_oxidized_copper"},
        {pos: [8, 2, 9], state: "minecraft:waxed_oxidized_copper"},
        {pos: [8, 2, 10], state: "minecraft:waxed_oxidized_copper"},
        {pos: [8, 2, 11], state: "minecraft:air"},
        {pos: [8, 2, 12], state: "minecraft:air"},
        {pos: [8, 2, 13], state: "minecraft:air"},
        {pos: [8, 2, 14], state: "minecraft:air"},
        {pos: [8, 2, 15], state: "minecraft:air"},
        {pos: [8, 2, 16], state: "minecraft:air"},
        {pos: [8, 2, 17], state: "minecraft:air"},
        {pos: [8, 2, 18], state: "minecraft:air"},
        {pos: [8, 2, 19], state: "minecraft:tuff_bricks"},
        {pos: [8, 2, 20], state: "minecraft:tuff_bricks"},
        {pos: [9, 2, 0], state: "minecraft:tuff_bricks"},
        {pos: [9, 2, 1], state: "minecraft:waxed_oxidized_copper"},
        {pos: [9, 2, 2], state: "minecraft:waxed_oxidized_copper"},
        {pos: [9, 2, 3], state: "minecraft:waxed_oxidized_copper"},
        {pos: [9, 2, 4], state: "minecraft:waxed_oxidized_copper"},
        {pos: [9, 2, 5], state: "minecraft:waxed_oxidized_copper"},
        {pos: [9, 2, 6], state: "minecraft:waxed_oxidized_copper"},
        {pos: [9, 2, 7], state: "minecraft:waxed_oxidized_copper"},
        {pos: [9, 2, 8], state: "minecraft:waxed_oxidized_copper"},
        {pos: [9, 2, 9], state: "minecraft:waxed_oxidized_copper"},
        {pos: [9, 2, 10], state: "minecraft:waxed_oxidized_copper"},
        {pos: [9, 2, 11], state: "minecraft:air"},
        {pos: [9, 2, 12], state: "minecraft:air"},
        {pos: [9, 2, 13], state: "minecraft:air"},
        {pos: [9, 2, 14], state: "minecraft:air"},
        {pos: [9, 2, 15], state: "minecraft:air"},
        {pos: [9, 2, 16], state: "minecraft:air"},
        {pos: [9, 2, 17], state: "minecraft:air"},
        {pos: [9, 2, 18], state: "minecraft:air"},
        {pos: [9, 2, 19], state: "minecraft:tuff_bricks"},
        {pos: [9, 2, 20], state: "minecraft:tuff_bricks"},
        {pos: [10, 2, 0], state: "minecraft:tuff_bricks"},
        {pos: [10, 2, 1], state: "minecraft:waxed_oxidized_copper"},
        {pos: [10, 2, 2], state: "minecraft:waxed_oxidized_copper"},
        {pos: [10, 2, 3], state: "minecraft:waxed_oxidized_copper"},
        {pos: [10, 2, 4], state: "minecraft:waxed_oxidized_copper"},
        {pos: [10, 2, 5], state: "minecraft:waxed_oxidized_copper"},
        {pos: [10, 2, 6], state: "minecraft:waxed_oxidized_copper"},
        {pos: [10, 2, 7], state: "minecraft:waxed_oxidized_copper"},
        {pos: [10, 2, 8], state: "minecraft:waxed_oxidized_copper"},
        {pos: [10, 2, 9], state: "minecraft:waxed_oxidized_copper"},
        {pos: [10, 2, 10], state: "minecraft:waxed_oxidized_copper"},
        {pos: [10, 2, 11], state: "minecraft:air"},
        {pos: [10, 2, 12], state: "minecraft:air"},
        {pos: [10, 2, 13], state: "minecraft:air"},
        {pos: [10, 2, 14], state: "minecraft:air"},
        {pos: [10, 2, 15], state: "minecraft:air"},
        {pos: [10, 2, 16], state: "minecraft:air"},
        {pos: [10, 2, 17], state: "minecraft:air"},
        {pos: [10, 2, 18], state: "minecraft:air"},
        {pos: [10, 2, 19], state: "minecraft:tuff_bricks"},
        {pos: [10, 2, 20], state: "minecraft:tuff_bricks"},
        {pos: [11, 2, 0], state: "minecraft:tuff_bricks"},
        {pos: [11, 2, 1], state: "minecraft:waxed_oxidized_copper"},
        {pos: [11, 2, 2], state: "minecraft:waxed_oxidized_copper"},
        {pos: [11, 2, 3], state: "minecraft:waxed_oxidized_copper"},
        {pos: [11, 2, 4], state: "minecraft:waxed_oxidized_copper"},
        {pos: [11, 2, 5], state: "minecraft:waxed_oxidized_copper"},
        {pos: [11, 2, 6], state: "minecraft:waxed_oxidized_copper"},
        {pos: [11, 2, 7], state: "minecraft:waxed_oxidized_copper"},
        {pos: [11, 2, 8], state: "minecraft:waxed_oxidized_copper"},
        {pos: [11, 2, 9], state: "minecraft:waxed_oxidized_copper"},
        {pos: [11, 2, 10], state: "minecraft:waxed_oxidized_copper"},
        {pos: [11, 2, 11], state: "minecraft:air"},
        {pos: [11, 2, 12], state: "minecraft:air"},
        {pos: [11, 2, 13], state: "minecraft:air"},
        {pos: [11, 2, 14], state: "minecraft:air"},
        {pos: [11, 2, 15], state: "minecraft:air"},
        {pos: [11, 2, 16], state: "minecraft:air"},
        {pos: [11, 2, 17], state: "minecraft:air"},
        {pos: [11, 2, 18], state: "minecraft:air"},
        {pos: [11, 2, 19], state: "minecraft:tuff_bricks"},
        {pos: [11, 2, 20], state: "minecraft:tuff_bricks"},
        {pos: [12, 2, 0], state: "minecraft:tuff_bricks"},
        {pos: [12, 2, 1], state: "minecraft:waxed_oxidized_copper"},
        {pos: [12, 2, 2], state: "minecraft:waxed_oxidized_copper"},
        {pos: [12, 2, 3], state: "minecraft:waxed_oxidized_copper"},
        {pos: [12, 2, 4], state: "minecraft:waxed_oxidized_copper"},
        {pos: [12, 2, 5], state: "minecraft:waxed_oxidized_copper"},
        {pos: [12, 2, 6], state: "minecraft:tuff_bricks"},
        {pos: [12, 2, 7], state: "minecraft:tuff_bricks"},
        {pos: [12, 2, 8], state: "minecraft:tuff_bricks"},
        {pos: [12, 2, 9], state: "minecraft:waxed_oxidized_copper"},
        {pos: [12, 2, 10], state: "minecraft:waxed_oxidized_copper"},
        {pos: [12, 2, 11], state: "minecraft:air"},
        {pos: [12, 2, 12], state: "minecraft:air"},
        {pos: [12, 2, 13], state: "minecraft:air"},
        {pos: [12, 2, 14], state: "minecraft:air"},
        {pos: [12, 2, 15], state: "minecraft:air"},
        {pos: [12, 2, 16], state: "minecraft:air"},
        {pos: [12, 2, 17], state: "minecraft:air"},
        {pos: [12, 2, 18], state: "minecraft:air"},
        {pos: [12, 2, 19], state: "minecraft:tuff_bricks"},
        {pos: [12, 2, 20], state: "minecraft:tuff_bricks"},
        {pos: [13, 2, 0], state: "minecraft:waxed_oxidized_copper"},
        {pos: [13, 2, 1], state: "minecraft:waxed_oxidized_copper"},
        {pos: [13, 2, 2], state: "minecraft:waxed_oxidized_copper"},
        {pos: [13, 2, 3], state: "minecraft:waxed_oxidized_copper"},
        {pos: [13, 2, 4], state: "minecraft:waxed_oxidized_copper"},
        {pos: [13, 2, 5], state: "minecraft:tuff_bricks"},
        {pos: [13, 2, 6], state: "minecraft:waxed_oxidized_cut_copper"},
        {pos: [13, 2, 7], state: "minecraft:waxed_oxidized_cut_copper"},
        {pos: [13, 2, 8], state: "minecraft:waxed_oxidized_cut_copper"},
        {pos: [13, 2, 9], state: "minecraft:tuff_bricks"},
        {pos: [13, 2, 10], state: "minecraft:waxed_oxidized_copper"},
        {pos: [13, 2, 11], state: "minecraft:air"},
        {pos: [13, 2, 12], state: "minecraft:air"},
        {pos: [13, 2, 13], state: "minecraft:air"},
        {pos: [13, 2, 14], state: "minecraft:air"},
        {pos: [13, 2, 15], state: "minecraft:air"},
        {pos: [13, 2, 16], state: "minecraft:air"},
        {pos: [13, 2, 17], state: "minecraft:air"},
        {pos: [13, 2, 18], state: "minecraft:air"},
        {pos: [13, 2, 19], state: "minecraft:tuff_bricks"},
        {pos: [13, 2, 20], state: "minecraft:tuff_bricks"},
        {pos: [14, 2, 0], state: "minecraft:waxed_oxidized_copper"},
        {pos: [14, 2, 1], state: "minecraft:waxed_oxidized_copper"},
        {pos: [14, 2, 2], state: "minecraft:waxed_oxidized_copper"},
        {pos: [14, 2, 3], state: "minecraft:waxed_oxidized_copper"},
        {pos: [14, 2, 4], state: "minecraft:waxed_oxidized_copper"},
        {pos: [14, 2, 5], state: "minecraft:tuff_bricks"},
        {pos: [14, 2, 6], state: "minecraft:waxed_oxidized_cut_copper"},
        {pos: [14, 2, 7], state: "minecraft:waxed_oxidized_cut_copper"},
        {pos: [14, 2, 8], state: "minecraft:waxed_oxidized_cut_copper"},
        {pos: [14, 2, 9], state: "minecraft:tuff_bricks"},
        {pos: [14, 2, 10], state: "minecraft:waxed_oxidized_copper"},
        {pos: [14, 2, 11], state: "minecraft:air"},
        {pos: [14, 2, 12], state: "minecraft:air"},
        {pos: [14, 2, 13], state: "minecraft:air"},
        {pos: [14, 2, 14], state: "minecraft:air"},
        {pos: [14, 2, 15], state: "minecraft:air"},
        {pos: [14, 2, 16], state: "minecraft:air"},
        {pos: [14, 2, 17], state: "minecraft:air"},
        {pos: [14, 2, 18], state: "minecraft:air"},
        {pos: [14, 2, 19], state: "minecraft:tuff_bricks"},
        {pos: [14, 2, 20], state: "minecraft:tuff_bricks"},
        {pos: [15, 2, 0], state: "minecraft:waxed_oxidized_copper"},
        {pos: [15, 2, 1], state: "minecraft:waxed_oxidized_copper"},
        {pos: [15, 2, 2], state: "minecraft:waxed_oxidized_copper"},
        {pos: [15, 2, 3], state: "minecraft:waxed_oxidized_copper"},
        {pos: [15, 2, 4], state: "minecraft:waxed_oxidized_copper"},
        {pos: [15, 2, 5], state: "minecraft:tuff_bricks"},
        {pos: [15, 2, 6], state: "minecraft:waxed_oxidized_cut_copper"},
        {pos: [15, 2, 7], state: "minecraft:waxed_oxidized_cut_copper"},
        {pos: [15, 2, 8], state: "minecraft:waxed_oxidized_cut_copper"},
        {pos: [15, 2, 9], state: "minecraft:tuff_bricks"},
        {pos: [15, 2, 10], state: "minecraft:waxed_oxidized_copper"},
        {pos: [15, 2, 11], state: "minecraft:air"},
        {pos: [15, 2, 12], state: "minecraft:air"},
        {pos: [15, 2, 13], state: "minecraft:air"},
        {pos: [15, 2, 14], state: "minecraft:air"},
        {pos: [15, 2, 15], state: "minecraft:air"},
        {pos: [15, 2, 16], state: "minecraft:air"},
        {pos: [15, 2, 17], state: "minecraft:air"},
        {pos: [15, 2, 18], state: "minecraft:air"},
        {pos: [15, 2, 19], state: "minecraft:tuff_bricks"},
        {pos: [15, 2, 20], state: "minecraft:tuff_bricks"},
        {pos: [16, 2, 0], state: "minecraft:tuff_bricks"},
        {pos: [16, 2, 1], state: "minecraft:waxed_oxidized_copper"},
        {pos: [16, 2, 2], state: "minecraft:waxed_oxidized_copper"},
        {pos: [16, 2, 3], state: "minecraft:waxed_oxidized_copper"},
        {pos: [16, 2, 4], state: "minecraft:waxed_oxidized_copper"},
        {pos: [16, 2, 5], state: "minecraft:waxed_oxidized_copper"},
        {pos: [16, 2, 6], state: "minecraft:tuff_bricks"},
        {pos: [16, 2, 7], state: "minecraft:waxed_oxidized_cut_copper"},
        {pos: [16, 2, 8], state: "minecraft:waxed_oxidized_cut_copper"},
        {pos: [16, 2, 9], state: "minecraft:waxed_oxidized_copper"},
        {pos: [16, 2, 10], state: "minecraft:waxed_oxidized_copper"},
        {pos: [16, 2, 11], state: "minecraft:air"},
        {pos: [16, 2, 12], state: "minecraft:air"},
        {pos: [16, 2, 13], state: "minecraft:air"},
        {pos: [16, 2, 14], state: "minecraft:air"},
        {pos: [16, 2, 15], state: "minecraft:air"},
        {pos: [16, 2, 16], state: "minecraft:air"},
        {pos: [16, 2, 17], state: "minecraft:air"},
        {pos: [16, 2, 18], state: "minecraft:air"},
        {pos: [16, 2, 19], state: "minecraft:tuff_bricks"},
        {pos: [16, 2, 20], state: "minecraft:tuff_bricks"},
        {pos: [17, 2, 0], state: "minecraft:tuff_bricks"},
        {pos: [17, 2, 1], state: "minecraft:waxed_oxidized_copper"},
        {pos: [17, 2, 2], state: "minecraft:waxed_oxidized_copper"},
        {pos: [17, 2, 3], state: "minecraft:waxed_oxidized_copper"},
        {pos: [17, 2, 4], state: "minecraft:waxed_oxidized_copper"},
        {pos: [17, 2, 5], state: "minecraft:waxed_oxidized_copper"},
        {pos: [17, 2, 6], state: "minecraft:waxed_oxidized_copper"},
        {pos: [17, 2, 7], state: "minecraft:waxed_oxidized_copper"},
        {pos: [17, 2, 8], state: "minecraft:waxed_oxidized_copper"},
        {pos: [17, 2, 9], state: "minecraft:waxed_oxidized_copper"},
        {pos: [17, 2, 10], state: "minecraft:waxed_oxidized_copper"},
        {pos: [17, 2, 11], state: "minecraft:air"},
        {pos: [17, 2, 12], state: "minecraft:air"},
        {pos: [17, 2, 13], state: "minecraft:air"},
        {pos: [17, 2, 14], state: "minecraft:air"},
        {pos: [17, 2, 15], state: "minecraft:air"},
        {pos: [17, 2, 16], state: "minecraft:air"},
        {pos: [17, 2, 17], state: "minecraft:air"},
        {pos: [17, 2, 18], state: "minecraft:air"},
        {pos: [17, 2, 19], state: "minecraft:tuff_bricks"},
        {pos: [17, 2, 20], state: "minecraft:tuff_bricks"},
        {pos: [18, 2, 0], state: "minecraft:tuff_bricks"},
        {pos: [18, 2, 1], state: "minecraft:waxed_oxidized_copper"},
        {pos: [18, 2, 2], state: "minecraft:waxed_oxidized_copper"},
        {pos: [18, 2, 3], state: "minecraft:waxed_oxidized_copper"},
        {pos: [18, 2, 4], state: "minecraft:waxed_oxidized_copper"},
        {pos: [18, 2, 5], state: "minecraft:waxed_oxidized_copper"},
        {pos: [18, 2, 6], state: "minecraft:waxed_oxidized_copper"},
        {pos: [18, 2, 7], state: "minecraft:waxed_oxidized_copper"},
        {pos: [18, 2, 8], state: "minecraft:waxed_oxidized_copper"},
        {pos: [18, 2, 9], state: "minecraft:waxed_oxidized_copper"},
        {pos: [18, 2, 10], state: "minecraft:waxed_oxidized_copper"},
        {pos: [18, 2, 11], state: "minecraft:air"},
        {pos: [18, 2, 12], state: "minecraft:air"},
        {pos: [18, 2, 13], state: "minecraft:air"},
        {pos: [18, 2, 14], state: "minecraft:air"},
        {pos: [18, 2, 15], state: "minecraft:air"},
        {pos: [18, 2, 16], state: "minecraft:air"},
        {pos: [18, 2, 17], state: "minecraft:air"},
        {pos: [18, 2, 18], state: "minecraft:air"},
        {pos: [18, 2, 19], state: "minecraft:tuff_bricks"},
        {pos: [18, 2, 20], state: "minecraft:tuff_bricks"},
        {pos: [19, 2, 0], state: "minecraft:tuff_bricks"},
        {pos: [19, 2, 1], state: "minecraft:waxed_oxidized_copper"},
        {pos: [19, 2, 2], state: "minecraft:waxed_oxidized_copper"},
        {pos: [19, 2, 3], state: "minecraft:waxed_oxidized_copper"},
        {pos: [19, 2, 4], state: "minecraft:waxed_oxidized_copper"},
        {pos: [19, 2, 5], state: "minecraft:waxed_oxidized_copper"},
        {pos: [19, 2, 6], state: "minecraft:waxed_oxidized_copper"},
        {pos: [19, 2, 7], state: "minecraft:waxed_oxidized_copper"},
        {pos: [19, 2, 8], state: "minecraft:waxed_oxidized_copper"},
        {pos: [19, 2, 9], state: "minecraft:waxed_oxidized_copper"},
        {pos: [19, 2, 10], state: "minecraft:waxed_oxidized_copper"},
        {pos: [19, 2, 11], state: "minecraft:air"},
        {pos: [19, 2, 12], state: "minecraft:air"},
        {pos: [19, 2, 13], state: "minecraft:air"},
        {pos: [19, 2, 14], state: "minecraft:air"},
        {pos: [19, 2, 15], state: "minecraft:air"},
        {pos: [19, 2, 16], state: "minecraft:air"},
        {pos: [19, 2, 17], state: "minecraft:air"},
        {pos: [19, 2, 18], state: "minecraft:air"},
        {pos: [19, 2, 19], state: "minecraft:tuff_bricks"},
        {pos: [19, 2, 20], state: "minecraft:tuff_bricks"},
        {pos: [20, 2, 0], state: "minecraft:tuff_bricks"},
        {pos: [20, 2, 1], state: "minecraft:waxed_oxidized_copper"},
        {pos: [20, 2, 2], state: "minecraft:waxed_oxidized_copper"},
        {pos: [20, 2, 3], state: "minecraft:waxed_oxidized_copper"},
        {pos: [20, 2, 4], state: "minecraft:waxed_oxidized_copper"},
        {pos: [20, 2, 5], state: "minecraft:waxed_oxidized_copper"},
        {pos: [20, 2, 6], state: "minecraft:waxed_oxidized_copper"},
        {pos: [20, 2, 7], state: "minecraft:waxed_oxidized_copper"},
        {pos: [20, 2, 8], state: "minecraft:waxed_oxidized_copper"},
        {pos: [20, 2, 9], state: "minecraft:waxed_oxidized_copper"},
        {pos: [20, 2, 10], state: "minecraft:waxed_oxidized_copper"},
        {pos: [20, 2, 11], state: "minecraft:air"},
        {pos: [20, 2, 12], state: "minecraft:air"},
        {pos: [20, 2, 13], state: "minecraft:air"},
        {pos: [20, 2, 14], state: "minecraft:air"},
        {pos: [20, 2, 15], state: "minecraft:air"},
        {pos: [20, 2, 16], state: "minecraft:air"},
        {pos: [20, 2, 17], state: "minecraft:air"},
        {pos: [20, 2, 18], state: "minecraft:air"},
        {pos: [20, 2, 19], state: "minecraft:tuff_bricks"},
        {pos: [20, 2, 20], state: "minecraft:tuff_bricks"},
        {pos: [21, 2, 0], state: "minecraft:tuff_bricks"},
        {pos: [21, 2, 1], state: "minecraft:waxed_oxidized_copper"},
        {pos: [21, 2, 2], state: "minecraft:waxed_oxidized_copper"},
        {pos: [21, 2, 3], state: "minecraft:waxed_oxidized_copper"},
        {pos: [21, 2, 4], state: "minecraft:tuff_bricks"},
        {pos: [21, 2, 5], state: "minecraft:tuff_bricks"},
        {pos: [21, 2, 6], state: "minecraft:waxed_oxidized_copper"},
        {pos: [21, 2, 7], state: "minecraft:waxed_oxidized_copper"},
        {pos: [21, 2, 8], state: "minecraft:waxed_oxidized_copper"},
        {pos: [21, 2, 9], state: "minecraft:waxed_oxidized_copper"},
        {pos: [21, 2, 10], state: "minecraft:waxed_oxidized_copper"},
        {pos: [21, 2, 11], state: "minecraft:waxed_oxidized_copper"},
        {pos: [21, 2, 12], state: "minecraft:waxed_oxidized_copper"},
        {pos: [21, 2, 13], state: "minecraft:waxed_oxidized_copper"},
        {pos: [21, 2, 14], state: "minecraft:tuff_bricks"},
        {pos: [21, 2, 15], state: "minecraft:tuff_bricks"},
        {pos: [21, 2, 16], state: "minecraft:tuff_bricks"},
        {pos: [21, 2, 17], state: "minecraft:tuff_bricks"},
        {pos: [21, 2, 18], state: "minecraft:tuff_bricks"},
        {pos: [21, 2, 19], state: "minecraft:tuff_bricks"},
        {pos: [21, 2, 20], state: "minecraft:tuff_bricks"},
        {pos: [22, 2, 0], state: "minecraft:tuff_bricks"},
        {pos: [22, 2, 1], state: "minecraft:tuff_bricks"},
        {pos: [22, 2, 2], state: "minecraft:tuff_bricks"},
        {pos: [22, 2, 3], state: "minecraft:tuff_bricks"},
        {pos: [22, 2, 4], state: "minecraft:tuff_bricks"},
        {pos: [22, 2, 5], state: "minecraft:tuff_bricks"},
        {pos: [22, 2, 6], state: "minecraft:tuff_bricks"},
        {pos: [22, 2, 7], state: "minecraft:tuff_bricks"},
        {pos: [22, 2, 8], state: "minecraft:tuff_bricks"},
        {pos: [22, 2, 9], state: "minecraft:tuff_bricks"},
        {pos: [22, 2, 10], state: "minecraft:tuff_bricks"},
        {pos: [22, 2, 11], state: "minecraft:waxed_oxidized_copper"},
        {pos: [22, 2, 12], state: "minecraft:waxed_oxidized_copper"},
        {pos: [22, 2, 13], state: "minecraft:waxed_oxidized_copper"},
        {pos: [22, 2, 14], state: "minecraft:tuff_bricks"},
        {pos: [22, 2, 15], state: "minecraft:tuff_bricks"},
        {pos: [22, 2, 16], state: "minecraft:tuff_bricks"},
        {pos: [22, 2, 17], state: "minecraft:tuff_bricks"},
        {pos: [22, 2, 18], state: "minecraft:tuff_bricks"},
        {pos: [22, 2, 19], state: "minecraft:tuff_bricks"},
        {pos: [22, 2, 20], state: "minecraft:tuff_bricks"},
        {pos: [23, 2, 0], state: "minecraft:tuff_bricks"},
        {pos: [23, 2, 1], state: "minecraft:tuff_bricks"},
        {pos: [23, 2, 2], state: "minecraft:tuff_bricks"},
        {pos: [23, 2, 3], state: "minecraft:tuff_bricks"},
        {pos: [23, 2, 4], state: "minecraft:tuff_bricks"},
        {pos: [23, 2, 5], state: "minecraft:tuff_bricks"},
        {pos: [23, 2, 6], state: "minecraft:tuff_bricks"},
        {pos: [23, 2, 7], state: "minecraft:tuff_bricks"},
        {pos: [23, 2, 8], state: "minecraft:tuff_bricks"},
        {pos: [23, 2, 9], state: "minecraft:tuff_bricks"},
        {pos: [23, 2, 10], state: "minecraft:tuff_bricks"},
        {pos: [23, 2, 11], state: "minecraft:tuff_bricks"},
        {pos: [23, 2, 12], state: "minecraft:tuff_bricks"},
        {pos: [23, 2, 13], state: "minecraft:tuff_bricks"},
        {pos: [23, 2, 14], state: "minecraft:tuff_bricks"},
        {pos: [23, 2, 15], state: "minecraft:tuff_bricks"},
        {pos: [23, 2, 16], state: "minecraft:tuff_bricks"},
        {pos: [23, 2, 17], state: "minecraft:tuff_bricks"},
        {pos: [23, 2, 18], state: "minecraft:tuff_bricks"},
        {pos: [23, 2, 19], state: "minecraft:tuff_bricks"},
        {pos: [23, 2, 20], state: "minecraft:tuff_bricks"},
        {pos: [5, 3, 0], state: "minecraft:tuff_bricks"},
        {pos: [5, 3, 1], state: "minecraft:tuff_bricks"},
        {pos: [5, 3, 2], state: "minecraft:tuff_bricks"},
        {pos: [5, 3, 3], state: "minecraft:tuff_bricks"},
        {pos: [5, 3, 4], state: "minecraft:tuff_bricks"},
        {pos: [5, 3, 5], state: "minecraft:tuff_bricks"},
        {pos: [5, 3, 6], state: "minecraft:tuff_bricks"},
        {pos: [5, 3, 7], state: "minecraft:tuff_bricks"},
        {pos: [5, 3, 8], state: "minecraft:tuff_bricks"},
        {pos: [5, 3, 9], state: "minecraft:tuff_bricks"},
        {pos: [5, 3, 10], state: "minecraft:tuff_bricks"},
        {pos: [5, 3, 11], state: "minecraft:tuff_bricks"},
        {pos: [5, 3, 12], state: "minecraft:tuff_bricks"},
        {pos: [5, 3, 13], state: "minecraft:tuff_bricks"},
        {pos: [5, 3, 14], state: "minecraft:tuff_bricks"},
        {pos: [5, 3, 15], state: "minecraft:tuff_bricks"},
        {pos: [5, 3, 16], state: "minecraft:tuff_bricks"},
        {pos: [5, 3, 17], state: "minecraft:tuff_bricks"},
        {pos: [5, 3, 18], state: "minecraft:tuff_bricks"},
        {pos: [5, 3, 19], state: "minecraft:tuff_bricks"},
        {pos: [5, 3, 20], state: "minecraft:tuff_bricks"},
        {pos: [6, 3, 0], state: "minecraft:waxed_oxidized_cut_copper"},
        {pos: [6, 3, 1], state: "minecraft:waxed_oxidized_cut_copper"},
        {pos: [6, 3, 2], state: "minecraft:waxed_oxidized_cut_copper"},
        {pos: [6, 3, 3], state: "minecraft:waxed_oxidized_cut_copper"},
        {pos: [6, 3, 4], state: "minecraft:waxed_oxidized_cut_copper"},
        {pos: [6, 3, 5], state: "minecraft:waxed_oxidized_cut_copper"},
        {pos: [6, 3, 6], state: "minecraft:waxed_oxidized_cut_copper"},
        {pos: [6, 3, 7], state: "minecraft:waxed_oxidized_cut_copper"},
        {pos: [6, 3, 8], state: "minecraft:waxed_oxidized_cut_copper"},
        {pos: [6, 3, 9], state: "minecraft:waxed_oxidized_cut_copper"},
        {pos: [6, 3, 10], state: "minecraft:waxed_oxidized_cut_copper"},
        {pos: [6, 3, 11], state: "minecraft:waxed_oxidized_cut_copper"},
        {pos: [6, 3, 12], state: "minecraft:waxed_oxidized_cut_copper"},
        {pos: [6, 3, 13], state: "minecraft:waxed_oxidized_cut_copper"},
        {pos: [6, 3, 14], state: "minecraft:waxed_oxidized_cut_copper"},
        {pos: [6, 3, 15], state: "minecraft:waxed_oxidized_cut_copper"},
        {pos: [6, 3, 16], state: "minecraft:tuff_bricks"},
        {pos: [6, 3, 17], state: "minecraft:tuff_bricks"},
        {pos: [6, 3, 18], state: "minecraft:tuff_bricks"},
        {pos: [6, 3, 19], state: "minecraft:tuff_bricks"},
        {pos: [6, 3, 20], state: "minecraft:tuff_bricks"},
        {pos: [7, 3, 0], state: "minecraft:waxed_oxidized_cut_copper"},
        {pos: [7, 3, 1], state: "minecraft:air"},
        {pos: [7, 3, 2], state: "minecraft:air"},
        {pos: [7, 3, 3], state: "minecraft:air"},
        {pos: [7, 3, 4], state: "minecraft:waxed_oxidized_cut_copper"},
        {pos: [7, 3, 5], state: "minecraft:waxed_oxidized_cut_copper"},
        {pos: [7, 3, 6], state: "minecraft:air"},
        {pos: [7, 3, 7], state: "minecraft:air"},
        {pos: [7, 3, 8], state: "minecraft:air"},
        {pos: [7, 3, 9], state: "minecraft:air"},
        {pos: [7, 3, 10], state: "minecraft:air"},
        {pos: [7, 3, 11], state: "minecraft:air"},
        {pos: [7, 3, 12], state: "minecraft:air"},
        {pos: [7, 3, 13], state: "minecraft:jigsaw{orientation:west_up}", nbt: {final_state: "minecraft:air", id: "minecraft:jigsaw", joint: "rollable", name: "minecraft:empty", placement_priority: 0, pool: "minecraft:trial_chambers/atrium", selection_priority: 0, target: "minecraft:relief"}},
        {pos: [7, 3, 14], state: "minecraft:waxed_oxidized_cut_copper"},
        {pos: [7, 3, 15], state: "minecraft:waxed_oxidized_cut_copper"},
        {pos: [7, 3, 16], state: "minecraft:waxed_oxidized_cut_copper"},
        {pos: [7, 3, 17], state: "minecraft:waxed_oxidized_cut_copper"},
        {pos: [7, 3, 18], state: "minecraft:waxed_oxidized_cut_copper"},
        {pos: [7, 3, 19], state: "minecraft:waxed_oxidized_cut_copper"},
        {pos: [7, 3, 20], state: "minecraft:tuff_bricks"},
        {pos: [8, 3, 0], state: "minecraft:tuff_bricks"},
        {pos: [8, 3, 1], state: "minecraft:waxed_oxidized_cut_copper_stairs{facing:north,half:bottom,shape:straight,waterlogged:false}"},
        {pos: [8, 3, 2], state: "minecraft:air"},
        {pos: [8, 3, 3], state: "minecraft:air"},
        {pos: [8, 3, 4], state: "minecraft:air"},
        {pos: [8, 3, 5], state: "minecraft:air"},
        {pos: [8, 3, 6], state: "minecraft:air"},
        {pos: [8, 3, 7], state: "minecraft:air"},
        {pos: [8, 3, 8], state: "minecraft:air"},
        {pos: [8, 3, 9], state: "minecraft:air"},
        {pos: [8, 3, 10], state: "minecraft:air"},
        {pos: [8, 3, 11], state: "minecraft:air"},
        {pos: [8, 3, 12], state: "minecraft:air"},
        {pos: [8, 3, 13], state: "minecraft:air"},
        {pos: [8, 3, 14], state: "minecraft:air"},
        {pos: [8, 3, 15], state: "minecraft:air"},
        {pos: [8, 3, 16], state: "minecraft:air"},
        {pos: [8, 3, 17], state: "minecraft:air"},
        {pos: [8, 3, 18], state: "minecraft:air"},
        {pos: [8, 3, 19], state: "minecraft:waxed_oxidized_cut_copper"},
        {pos: [8, 3, 20], state: "minecraft:tuff_bricks"},
        {pos: [9, 3, 0], state: "minecraft:tuff_bricks"},
        {pos: [9, 3, 1], state: "minecraft:waxed_oxidized_cut_copper_stairs{facing:north,half:bottom,shape:straight,waterlogged:false}"},
        {pos: [9, 3, 2], state: "minecraft:air"},
        {pos: [9, 3, 3], state: "minecraft:air"},
        {pos: [9, 3, 4], state: "minecraft:air"},
        {pos: [9, 3, 5], state: "minecraft:air"},
        {pos: [9, 3, 6], state: "minecraft:air"},
        {pos: [9, 3, 7], state: "minecraft:air"},
        {pos: [9, 3, 8], state: "minecraft:air"},
        {pos: [9, 3, 9], state: "minecraft:air"},
        {pos: [9, 3, 10], state: "minecraft:air"},
        {pos: [9, 3, 11], state: "minecraft:air"},
        {pos: [9, 3, 12], state: "minecraft:air"},
        {pos: [9, 3, 13], state: "minecraft:air"},
        {pos: [9, 3, 14], state: "minecraft:air"},
        {pos: [9, 3, 15], state: "minecraft:air"},
        {pos: [9, 3, 16], state: "minecraft:air"},
        {pos: [9, 3, 17], state: "minecraft:air"},
        {pos: [9, 3, 18], state: "minecraft:air"},
        {pos: [9, 3, 19], state: "minecraft:waxed_oxidized_cut_copper"},
        {pos: [9, 3, 20], state: "minecraft:tuff_bricks"},
        {pos: [10, 3, 0], state: "minecraft:tuff_bricks"},
        {pos: [10, 3, 1], state: "minecraft:waxed_oxidized_cut_copper_stairs{facing:north,half:bottom,shape:straight,waterlogged:false}"},
        {pos: [10, 3, 2], state: "minecraft:air"},
        {pos: [10, 3, 3], state: "minecraft:air"},
        {pos: [10, 3, 4], state: "minecraft:air"},
        {pos: [10, 3, 5], state: "minecraft:air"},
        {pos: [10, 3, 6], state: "minecraft:air"},
        {pos: [10, 3, 7], state: "minecraft:air"},
        {pos: [10, 3, 8], state: "minecraft:air"},
        {pos: [10, 3, 9], state: "minecraft:air"},
        {pos: [10, 3, 10], state: "minecraft:air"},
        {pos: [10, 3, 11], state: "minecraft:air"},
        {pos: [10, 3, 12], state: "minecraft:air"},
        {pos: [10, 3, 13], state: "minecraft:air"},
        {pos: [10, 3, 14], state: "minecraft:air"},
        {pos: [10, 3, 15], state: "minecraft:air"},
        {pos: [10, 3, 16], state: "minecraft:air"},
        {pos: [10, 3, 17], state: "minecraft:air"},
        {pos: [10, 3, 18], state: "minecraft:air"},
        {pos: [10, 3, 19], state: "minecraft:waxed_oxidized_cut_copper"},
        {pos: [10, 3, 20], state: "minecraft:tuff_bricks"},
        {pos: [11, 3, 0], state: "minecraft:waxed_oxidized_cut_copper"},
        {pos: [11, 3, 1], state: "minecraft:air"},
        {pos: [11, 3, 2], state: "minecraft:air"},
        {pos: [11, 3, 3], state: "minecraft:air"},
        {pos: [11, 3, 4], state: "minecraft:air"},
        {pos: [11, 3, 5], state: "minecraft:air"},
        {pos: [11, 3, 6], state: "minecraft:air"},
        {pos: [11, 3, 7], state: "minecraft:air"},
        {pos: [11, 3, 8], state: "minecraft:air"},
        {pos: [11, 3, 9], state: "minecraft:air"},
        {pos: [11, 3, 10], state: "minecraft:air"},
        {pos: [11, 3, 11], state: "minecraft:air"},
        {pos: [11, 3, 12], state: "minecraft:air"},
        {pos: [11, 3, 13], state: "minecraft:air"},
        {pos: [11, 3, 14], state: "minecraft:air"},
        {pos: [11, 3, 15], state: "minecraft:air"},
        {pos: [11, 3, 16], state: "minecraft:air"},
        {pos: [11, 3, 17], state: "minecraft:air"},
        {pos: [11, 3, 18], state: "minecraft:air"},
        {pos: [11, 3, 19], state: "minecraft:waxed_oxidized_cut_copper"},
        {pos: [11, 3, 20], state: "minecraft:tuff_bricks"},
        {pos: [12, 3, 0], state: "minecraft:waxed_oxidized_cut_copper"},
        {pos: [12, 3, 1], state: "minecraft:air"},
        {pos: [12, 3, 2], state: "minecraft:air"},
        {pos: [12, 3, 3], state: "minecraft:air"},
        {pos: [12, 3, 4], state: "minecraft:air"},
        {pos: [12, 3, 5], state: "minecraft:air"},
        {pos: [12, 3, 6], state: "minecraft:waxed_copper_block"},
        {pos: [12, 3, 7], state: "minecraft:waxed_copper_block"},
        {pos: [12, 3, 8], state: "minecraft:waxed_copper_block"},
        {pos: [12, 3, 9], state: "minecraft:air"},
        {pos: [12, 3, 10], state: "minecraft:air"},
        {pos: [12, 3, 11], state: "minecraft:air"},
        {pos: [12, 3, 12], state: "minecraft:air"},
        {pos: [12, 3, 13], state: "minecraft:air"},
        {pos: [12, 3, 14], state: "minecraft:air"},
        {pos: [12, 3, 15], state: "minecraft:air"},
        {pos: [12, 3, 16], state: "minecraft:air"},
        {pos: [12, 3, 17], state: "minecraft:air"},
        {pos: [12, 3, 18], state: "minecraft:air"},
        {pos: [12, 3, 19], state: "minecraft:waxed_oxidized_cut_copper"},
        {pos: [12, 3, 20], state: "minecraft:tuff_bricks"},
        {pos: [13, 3, 0], state: "minecraft:air"},
        {pos: [13, 3, 1], state: "minecraft:air"},
        {pos: [13, 3, 2], state: "minecraft:air"},
        {pos: [13, 3, 3], state: "minecraft:air"},
        {pos: [13, 3, 4], state: "minecraft:air"},
        {pos: [13, 3, 5], state: "minecraft:waxed_copper_block"},
        {pos: [13, 3, 6], state: "minecraft:water{level:0}"},
        {pos: [13, 3, 7], state: "minecraft:water{level:0}"},
        {pos: [13, 3, 8], state: "minecraft:water{level:0}"},
        {pos: [13, 3, 9], state: "minecraft:waxed_copper_block"},
        {pos: [13, 3, 10], state: "minecraft:air"},
        {pos: [13, 3, 11], state: "minecraft:air"},
        {pos: [13, 3, 12], state: "minecraft:air"},
        {pos: [13, 3, 13], state: "minecraft:air"},
        {pos: [13, 3, 14], state: "minecraft:air"},
        {pos: [13, 3, 15], state: "minecraft:air"},
        {pos: [13, 3, 16], state: "minecraft:air"},
        {pos: [13, 3, 17], state: "minecraft:air"},
        {pos: [13, 3, 18], state: "minecraft:air"},
        {pos: [13, 3, 19], state: "minecraft:waxed_oxidized_cut_copper"},
        {pos: [13, 3, 20], state: "minecraft:tuff_bricks"},
        {pos: [14, 3, 0], state: "minecraft:air"},
        {pos: [14, 3, 1], state: "minecraft:air"},
        {pos: [14, 3, 2], state: "minecraft:air"},
        {pos: [14, 3, 3], state: "minecraft:air"},
        {pos: [14, 3, 4], state: "minecraft:air"},
        {pos: [14, 3, 5], state: "minecraft:waxed_copper_block"},
        {pos: [14, 3, 6], state: "minecraft:water{level:0}"},
        {pos: [14, 3, 7], state: "minecraft:waxed_copper_bulb{lit:true,powered:false}"},
        {pos: [14, 3, 8], state: "minecraft:water{level:0}"},
        {pos: [14, 3, 9], state: "minecraft:waxed_copper_block"},
        {pos: [14, 3, 10], state: "minecraft:air"},
        {pos: [14, 3, 11], state: "minecraft:air"},
        {pos: [14, 3, 12], state: "minecraft:air"},
        {pos: [14, 3, 13], state: "minecraft:air"},
        {pos: [14, 3, 14], state: "minecraft:air"},
        {pos: [14, 3, 15], state: "minecraft:air"},
        {pos: [14, 3, 16], state: "minecraft:air"},
        {pos: [14, 3, 17], state: "minecraft:air"},
        {pos: [14, 3, 18], state: "minecraft:air"},
        {pos: [14, 3, 19], state: "minecraft:waxed_oxidized_cut_copper"},
        {pos: [14, 3, 20], state: "minecraft:tuff_bricks"},
        {pos: [15, 3, 0], state: "minecraft:air"},
        {pos: [15, 3, 1], state: "minecraft:air"},
        {pos: [15, 3, 2], state: "minecraft:air"},
        {pos: [15, 3, 3], state: "minecraft:air"},
        {pos: [15, 3, 4], state: "minecraft:air"},
        {pos: [15, 3, 5], state: "minecraft:waxed_copper_block"},
        {pos: [15, 3, 6], state: "minecraft:water{level:0}"},
        {pos: [15, 3, 7], state: "minecraft:water{level:0}"},
        {pos: [15, 3, 8], state: "minecraft:water{level:0}"},
        {pos: [15, 3, 9], state: "minecraft:waxed_copper_block"},
        {pos: [15, 3, 10], state: "minecraft:air"},
        {pos: [15, 3, 11], state: "minecraft:air"},
        {pos: [15, 3, 12], state: "minecraft:air"},
        {pos: [15, 3, 13], state: "minecraft:air"},
        {pos: [15, 3, 14], state: "minecraft:air"},
        {pos: [15, 3, 15], state: "minecraft:air"},
        {pos: [15, 3, 16], state: "minecraft:air"},
        {pos: [15, 3, 17], state: "minecraft:air"},
        {pos: [15, 3, 18], state: "minecraft:air"},
        {pos: [15, 3, 19], state: "minecraft:waxed_oxidized_cut_copper"},
        {pos: [15, 3, 20], state: "minecraft:tuff_bricks"},
        {pos: [16, 3, 0], state: "minecraft:waxed_oxidized_cut_copper"},
        {pos: [16, 3, 1], state: "minecraft:air"},
        {pos: [16, 3, 2], state: "minecraft:air"},
        {pos: [16, 3, 3], state: "minecraft:air"},
        {pos: [16, 3, 4], state: "minecraft:air"},
        {pos: [16, 3, 5], state: "minecraft:air"},
        {pos: [16, 3, 6], state: "minecraft:waxed_copper_block"},
        {pos: [16, 3, 7], state: "minecraft:waxed_copper_block"},
        {pos: [16, 3, 8], state: "minecraft:waxed_copper_block"},
        {pos: [16, 3, 9], state: "minecraft:air"},
        {pos: [16, 3, 10], state: "minecraft:air"},
        {pos: [16, 3, 11], state: "minecraft:air"},
        {pos: [16, 3, 12], state: "minecraft:air"},
        {pos: [16, 3, 13], state: "minecraft:air"},
        {pos: [16, 3, 14], state: "minecraft:air"},
        {pos: [16, 3, 15], state: "minecraft:air"},
        {pos: [16, 3, 16], state: "minecraft:air"},
        {pos: [16, 3, 17], state: "minecraft:air"},
        {pos: [16, 3, 18], state: "minecraft:air"},
        {pos: [16, 3, 19], state: "minecraft:waxed_oxidized_cut_copper"},
        {pos: [16, 3, 20], state: "minecraft:tuff_bricks"},
        {pos: [17, 3, 0], state: "minecraft:waxed_oxidized_cut_copper"},
        {pos: [17, 3, 1], state: "minecraft:air"},
        {pos: [17, 3, 2], state: "minecraft:air"},
        {pos: [17, 3, 3], state: "minecraft:air"},
        {pos: [17, 3, 4], state: "minecraft:air"},
        {pos: [17, 3, 5], state: "minecraft:air"},
        {pos: [17, 3, 6], state: "minecraft:air"},
        {pos: [17, 3, 7], state: "minecraft:air"},
        {pos: [17, 3, 8], state: "minecraft:air"},
        {pos: [17, 3, 9], state: "minecraft:air"},
        {pos: [17, 3, 10], state: "minecraft:air"},
        {pos: [17, 3, 11], state: "minecraft:air"},
        {pos: [17, 3, 12], state: "minecraft:air"},
        {pos: [17, 3, 13], state: "minecraft:air"},
        {pos: [17, 3, 14], state: "minecraft:air"},
        {pos: [17, 3, 15], state: "minecraft:air"},
        {pos: [17, 3, 16], state: "minecraft:air"},
        {pos: [17, 3, 17], state: "minecraft:air"},
        {pos: [17, 3, 18], state: "minecraft:air"},
        {pos: [17, 3, 19], state: "minecraft:waxed_oxidized_cut_copper"},
        {pos: [17, 3, 20], state: "minecraft:tuff_bricks"},
        {pos: [18, 3, 0], state: "minecraft:tuff_bricks"},
        {pos: [18, 3, 1], state: "minecraft:waxed_oxidized_cut_copper_stairs{facing:north,half:bottom,shape:straight,waterlogged:false}"},
        {pos: [18, 3, 2], state: "minecraft:air"},
        {pos: [18, 3, 3], state: "minecraft:air"},
        {pos: [18, 3, 4], state: "minecraft:air"},
        {pos: [18, 3, 5], state: "minecraft:air"},
        {pos: [18, 3, 6], state: "minecraft:air"},
        {pos: [18, 3, 7], state: "minecraft:air"},
        {pos: [18, 3, 8], state: "minecraft:air"},
        {pos: [18, 3, 9], state: "minecraft:air"},
        {pos: [18, 3, 10], state: "minecraft:air"},
        {pos: [18, 3, 11], state: "minecraft:air"},
        {pos: [18, 3, 12], state: "minecraft:air"},
        {pos: [18, 3, 13], state: "minecraft:air"},
        {pos: [18, 3, 14], state: "minecraft:air"},
        {pos: [18, 3, 15], state: "minecraft:air"},
        {pos: [18, 3, 16], state: "minecraft:air"},
        {pos: [18, 3, 17], state: "minecraft:air"},
        {pos: [18, 3, 18], state: "minecraft:air"},
        {pos: [18, 3, 19], state: "minecraft:waxed_oxidized_cut_copper"},
        {pos: [18, 3, 20], state: "minecraft:tuff_bricks"},
        {pos: [19, 3, 0], state: "minecraft:tuff_bricks"},
        {pos: [19, 3, 1], state: "minecraft:waxed_oxidized_cut_copper_stairs{facing:north,half:bottom,shape:straight,waterlogged:false}"},
        {pos: [19, 3, 2], state: "minecraft:air"},
        {pos: [19, 3, 3], state: "minecraft:air"},
        {pos: [19, 3, 4], state: "minecraft:air"},
        {pos: [19, 3, 5], state: "minecraft:air"},
        {pos: [19, 3, 6], state: "minecraft:air"},
        {pos: [19, 3, 7], state: "minecraft:air"},
        {pos: [19, 3, 8], state: "minecraft:air"},
        {pos: [19, 3, 9], state: "minecraft:air"},
        {pos: [19, 3, 10], state: "minecraft:air"},
        {pos: [19, 3, 11], state: "minecraft:air"},
        {pos: [19, 3, 12], state: "minecraft:air"},
        {pos: [19, 3, 13], state: "minecraft:air"},
        {pos: [19, 3, 14], state: "minecraft:air"},
        {pos: [19, 3, 15], state: "minecraft:air"},
        {pos: [19, 3, 16], state: "minecraft:air"},
        {pos: [19, 3, 17], state: "minecraft:air"},
        {pos: [19, 3, 18], state: "minecraft:air"},
        {pos: [19, 3, 19], state: "minecraft:waxed_oxidized_cut_copper"},
        {pos: [19, 3, 20], state: "minecraft:tuff_bricks"},
        {pos: [20, 3, 0], state: "minecraft:tuff_bricks"},
        {pos: [20, 3, 1], state: "minecraft:waxed_oxidized_cut_copper_stairs{facing:north,half:bottom,shape:straight,waterlogged:false}"},
        {pos: [20, 3, 2], state: "minecraft:air"},
        {pos: [20, 3, 3], state: "minecraft:air"},
        {pos: [20, 3, 4], state: "minecraft:air"},
        {pos: [20, 3, 5], state: "minecraft:air"},
        {pos: [20, 3, 6], state: "minecraft:air"},
        {pos: [20, 3, 7], state: "minecraft:air"},
        {pos: [20, 3, 8], state: "minecraft:air"},
        {pos: [20, 3, 9], state: "minecraft:air"},
        {pos: [20, 3, 10], state: "minecraft:air"},
        {pos: [20, 3, 11], state: "minecraft:air"},
        {pos: [20, 3, 12], state: "minecraft:air"},
        {pos: [20, 3, 13], state: "minecraft:air"},
        {pos: [20, 3, 14], state: "minecraft:air"},
        {pos: [20, 3, 15], state: "minecraft:air"},
        {pos: [20, 3, 16], state: "minecraft:air"},
        {pos: [20, 3, 17], state: "minecraft:air"},
        {pos: [20, 3, 18], state: "minecraft:air"},
        {pos: [20, 3, 19], state: "minecraft:waxed_oxidized_cut_copper"},
        {pos: [20, 3, 20], state: "minecraft:tuff_bricks"},
        {pos: [21, 3, 0], state: "minecraft:waxed_oxidized_cut_copper"},
        {pos: [21, 3, 1], state: "minecraft:ladder{facing:south,waterlogged:false}"},
        {pos: [21, 3, 2], state: "minecraft:air"},
        {pos: [21, 3, 3], state: "minecraft:air"},
        {pos: [21, 3, 4], state: "minecraft:waxed_oxidized_cut_copper"},
        {pos: [21, 3, 5], state: "minecraft:waxed_oxidized_cut_copper"},
        {pos: [21, 3, 6], state: "minecraft:jigsaw{orientation:east_up}", nbt: {final_state: "minecraft:air", id: "minecraft:jigsaw", joint: "rollable", name: "minecraft:empty", placement_priority: 0, pool: "minecraft:trial_chambers/atrium", selection_priority: 0, target: "minecraft:relief"}},
        {pos: [21, 3, 7], state: "minecraft:air"},
        {pos: [21, 3, 8], state: "minecraft:air"},
        {pos: [21, 3, 9], state: "minecraft:air"},
        {pos: [21, 3, 10], state: "minecraft:air"},
        {pos: [21, 3, 11], state: "minecraft:air"},
        {pos: [21, 3, 12], state: "minecraft:air"},
        {pos: [21, 3, 13], state: "minecraft:air"},
        {pos: [21, 3, 14], state: "minecraft:waxed_oxidized_cut_copper"},
        {pos: [21, 3, 15], state: "minecraft:waxed_oxidized_cut_copper"},
        {pos: [21, 3, 16], state: "minecraft:waxed_oxidized_cut_copper"},
        {pos: [21, 3, 17], state: "minecraft:waxed_oxidized_cut_copper"},
        {pos: [21, 3, 18], state: "minecraft:waxed_oxidized_cut_copper"},
        {pos: [21, 3, 19], state: "minecraft:waxed_oxidized_cut_copper"},
        {pos: [21, 3, 20], state: "minecraft:tuff_bricks"},
        {pos: [22, 3, 0], state: "minecraft:waxed_oxidized_cut_copper"},
        {pos: [22, 3, 1], state: "minecraft:waxed_oxidized_cut_copper"},
        {pos: [22, 3, 2], state: "minecraft:waxed_oxidized_cut_copper"},
        {pos: [22, 3, 3], state: "minecraft:waxed_oxidized_cut_copper"},
        {pos: [22, 3, 4], state: "minecraft:tuff_bricks"},
        {pos: [22, 3, 5], state: "minecraft:waxed_oxidized_cut_copper"},
        {pos: [22, 3, 6], state: "minecraft:waxed_oxidized_cut_copper"},
        {pos: [22, 3, 7], state: "minecraft:waxed_oxidized_cut_copper"},
        {pos: [22, 3, 8], state: "minecraft:waxed_oxidized_cut_copper"},
        {pos: [22, 3, 9], state: "minecraft:waxed_oxidized_cut_copper"},
        {pos: [22, 3, 10], state: "minecraft:waxed_oxidized_cut_copper"},
        {pos: [22, 3, 11], state: "minecraft:waxed_oxidized_cut_copper"},
        {pos: [22, 3, 12], state: "minecraft:waxed_oxidized_cut_copper"},
        {pos: [22, 3, 13], state: "minecraft:waxed_oxidized_cut_copper"},
        {pos: [22, 3, 14], state: "minecraft:waxed_oxidized_cut_copper"},
        {pos: [22, 3, 15], state: "minecraft:tuff_bricks"},
        {pos: [22, 3, 16], state: "minecraft:tuff_bricks"},
        {pos: [22, 3, 17], state: "minecraft:tuff_bricks"},
        {pos: [22, 3, 18], state: "minecraft:tuff_bricks"},
        {pos: [22, 3, 19], state: "minecraft:tuff_bricks"},
        {pos: [22, 3, 20], state: "minecraft:tuff_bricks"},
        {pos: [23, 3, 0], state: "minecraft:tuff_bricks"},
        {pos: [23, 3, 1], state: "minecraft:tuff_bricks"},
        {pos: [23, 3, 2], state: "minecraft:tuff_bricks"},
        {pos: [23, 3, 3], state: "minecraft:tuff_bricks"},
        {pos: [23, 3, 4], state: "minecraft:tuff_bricks"},
        {pos: [23, 3, 5], state: "minecraft:tuff_bricks"},
        {pos: [23, 3, 6], state: "minecraft:tuff_bricks"},
        {pos: [23, 3, 7], state: "minecraft:tuff_bricks"},
        {pos: [23, 3, 8], state: "minecraft:tuff_bricks"},
        {pos: [23, 3, 9], state: "minecraft:tuff_bricks"},
        {pos: [23, 3, 10], state: "minecraft:tuff_bricks"},
        {pos: [23, 3, 11], state: "minecraft:tuff_bricks"},
        {pos: [23, 3, 12], state: "minecraft:tuff_bricks"},
        {pos: [23, 3, 13], state: "minecraft:tuff_bricks"},
        {pos: [23, 3, 14], state: "minecraft:tuff_bricks"},
        {pos: [23, 3, 15], state: "minecraft:tuff_bricks"},
        {pos: [23, 3, 16], state: "minecraft:tuff_bricks"},
        {pos: [23, 3, 17], state: "minecraft:tuff_bricks"},
        {pos: [23, 3, 18], state: "minecraft:tuff_bricks"},
        {pos: [23, 3, 19], state: "minecraft:tuff_bricks"},
        {pos: [23, 3, 20], state: "minecraft:tuff_bricks"},
        {pos: [5, 4, 0], state: "minecraft:tuff_bricks"},
        {pos: [5, 4, 1], state: "minecraft:tuff_bricks"},
        {pos: [5, 4, 2], state: "minecraft:tuff_bricks"},
        {pos: [5, 4, 3], state: "minecraft:tuff_bricks"},
        {pos: [5, 4, 4], state: "minecraft:tuff_bricks"},
        {pos: [5, 4, 5], state: "minecraft:tuff_bricks"},
        {pos: [5, 4, 6], state: "minecraft:tuff_bricks"},
        {pos: [5, 4, 7], state: "minecraft:tuff_bricks"},
        {pos: [5, 4, 8], state: "minecraft:tuff_bricks"},
        {pos: [5, 4, 9], state: "minecraft:tuff_bricks"},
        {pos: [5, 4, 10], state: "minecraft:tuff_bricks"},
        {pos: [5, 4, 11], state: "minecraft:tuff_bricks"},
        {pos: [5, 4, 12], state: "minecraft:tuff_bricks"},
        {pos: [5, 4, 13], state: "minecraft:tuff_bricks"},
        {pos: [5, 4, 14], state: "minecraft:tuff_bricks"},
        {pos: [5, 4, 15], state: "minecraft:tuff_bricks"},
        {pos: [5, 4, 16], state: "minecraft:tuff_bricks"},
        {pos: [5, 4, 17], state: "minecraft:tuff_bricks"},
        {pos: [5, 4, 18], state: "minecraft:tuff_bricks"},
        {pos: [5, 4, 19], state: "minecraft:tuff_bricks"},
        {pos: [5, 4, 20], state: "minecraft:tuff_bricks"},
        {pos: [6, 4, 0], state: "minecraft:tuff_bricks"},
        {pos: [6, 4, 1], state: "minecraft:tuff_bricks"},
        {pos: [6, 4, 2], state: "minecraft:tuff_bricks"},
        {pos: [6, 4, 3], state: "minecraft:tuff_bricks"},
        {pos: [6, 4, 4], state: "minecraft:tuff_bricks"},
        {pos: [6, 4, 5], state: "minecraft:tuff_bricks"},
        {pos: [6, 4, 6], state: "minecraft:tuff_bricks"},
        {pos: [6, 4, 7], state: "minecraft:tuff_bricks"},
        {pos: [6, 4, 8], state: "minecraft:tuff_bricks"},
        {pos: [6, 4, 9], state: "minecraft:tuff_bricks"},
        {pos: [6, 4, 10], state: "minecraft:tuff_bricks"},
        {pos: [6, 4, 11], state: "minecraft:tuff_bricks"},
        {pos: [6, 4, 12], state: "minecraft:tuff_bricks"},
        {pos: [6, 4, 13], state: "minecraft:tuff_bricks"},
        {pos: [6, 4, 14], state: "minecraft:tuff_bricks"},
        {pos: [6, 4, 15], state: "minecraft:tuff_bricks"},
        {pos: [6, 4, 16], state: "minecraft:tuff_bricks"},
        {pos: [6, 4, 17], state: "minecraft:tuff_bricks"},
        {pos: [6, 4, 18], state: "minecraft:tuff_bricks"},
        {pos: [6, 4, 19], state: "minecraft:tuff_bricks"},
        {pos: [6, 4, 20], state: "minecraft:tuff_bricks"},
        {pos: [7, 4, 0], state: "minecraft:tuff_bricks"},
        {pos: [7, 4, 1], state: "minecraft:ladder{facing:south,waterlogged:false}"},
        {pos: [7, 4, 2], state: "minecraft:air"},
        {pos: [7, 4, 3], state: "minecraft:air"},
        {pos: [7, 4, 4], state: "minecraft:tuff_bricks"},
        {pos: [7, 4, 5], state: "minecraft:tuff_bricks"},
        {pos: [7, 4, 6], state: "minecraft:air"},
        {pos: [7, 4, 7], state: "minecraft:air"},
        {pos: [7, 4, 8], state: "minecraft:air"},
        {pos: [7, 4, 9], state: "minecraft:air"},
        {pos: [7, 4, 10], state: "minecraft:air"},
        {pos: [7, 4, 11], state: "minecraft:air"},
        {pos: [7, 4, 12], state: "minecraft:air"},
        {pos: [7, 4, 13], state: "minecraft:air"},
        {pos: [7, 4, 14], state: "minecraft:tuff_bricks"},
        {pos: [7, 4, 15], state: "minecraft:tuff_bricks"},
        {pos: [7, 4, 16], state: "minecraft:tuff_bricks"},
        {pos: [7, 4, 17], state: "minecraft:tuff_bricks"},
        {pos: [7, 4, 18], state: "minecraft:tuff_bricks"},
        {pos: [7, 4, 19], state: "minecraft:tuff_bricks"},
        {pos: [7, 4, 20], state: "minecraft:tuff_bricks"},
        {pos: [8, 4, 0], state: "minecraft:waxed_oxidized_cut_copper_stairs{facing:north,half:bottom,shape:straight,waterlogged:false}"},
        {pos: [8, 4, 1], state: "minecraft:air"},
        {pos: [8, 4, 2], state: "minecraft:air"},
        {pos: [8, 4, 3], state: "minecraft:air"},
        {pos: [8, 4, 4], state: "minecraft:air"},
        {pos: [8, 4, 5], state: "minecraft:air"},
