{
    size: [9, 7, 6],
    data: [
        {pos: [0, 0, 0], state: "minecraft:cobblestone"},
        {pos: [0, 0, 1], state: "minecraft:mud_bricks"},
        {pos: [0, 0, 2], state: "minecraft:mud_bricks"},
        {pos: [0, 0, 3], state: "minecraft:mud_bricks"},
        {pos: [0, 0, 4], state: "minecraft:mud_bricks"},
        {pos: [0, 0, 5], state: "minecraft:mud_bricks"},
        {pos: [1, 0, 0], state: "minecraft:stone"},
        {pos: [1, 0, 1], state: "minecraft:mud_bricks"},
        {pos: [1, 0, 2], state: "minecraft:mud_bricks"},
        {pos: [1, 0, 3], state: "minecraft:mud_bricks"},
        {pos: [1, 0, 4], state: "minecraft:mud_bricks"},
        {pos: [1, 0, 5], state: "minecraft:mud_bricks"},
        {pos: [2, 0, 0], state: "minecraft:cobblestone"},
        {pos: [2, 0, 1], state: "minecraft:mud_bricks"},
        {pos: [2, 0, 2], state: "minecraft:mud_bricks"},
        {pos: [2, 0, 3], state: "minecraft:mud_bricks"},
        {pos: [2, 0, 4], state: "minecraft:mud_bricks"},
        {pos: [2, 0, 5], state: "minecraft:mud_bricks"},
        {pos: [3, 0, 0], state: "minecraft:stone"},
        {pos: [3, 0, 1], state: "minecraft:mud_bricks"},
        {pos: [3, 0, 2], state: "minecraft:mud_bricks"},
        {pos: [3, 0, 3], state: "minecraft:mud_bricks"},
        {pos: [3, 0, 4], state: "minecraft:mud_bricks"},
        {pos: [3, 0, 5], state: "minecraft:mud_bricks"},
        {pos: [4, 0, 0], state: "minecraft:mud_bricks"},
        {pos: [4, 0, 1], state: "minecraft:mud_bricks"},
        {pos: [4, 0, 2], state: "minecraft:mud_bricks"},
        {pos: [4, 0, 3], state: "minecraft:mud_bricks"},
        {pos: [4, 0, 4], state: "minecraft:mud_bricks"},
        {pos: [4, 0, 5], state: "minecraft:mud_bricks"},
        {pos: [5, 0, 0], state: "minecraft:mud_bricks"},
        {pos: [5, 0, 1], state: "minecraft:mud_bricks"},
        {pos: [5, 0, 2], state: "minecraft:mud_bricks"},
        {pos: [5, 0, 3], state: "minecraft:mud_bricks"},
        {pos: [5, 0, 4], state: "minecraft:mud_bricks"},
        {pos: [5, 0, 5], state: "minecraft:mud_bricks"},
        {pos: [6, 0, 0], state: "minecraft:mud_bricks"},
        {pos: [6, 0, 1], state: "minecraft:mud_bricks"},
        {pos: [6, 0, 2], state: "minecraft:mud_bricks"},
        {pos: [6, 0, 3], state: "minecraft:mud_bricks"},
        {pos: [6, 0, 4], state: "minecraft:mud_bricks"},
        {pos: [6, 0, 5], state: "minecraft:mud_bricks"},
        {pos: [7, 0, 0], state: "minecraft:mud_bricks"},
        {pos: [7, 0, 1], state: "minecraft:mud_bricks"},
        {pos: [7, 0, 2], state: "minecraft:mud_bricks"},
        {pos: [7, 0, 3], state: "minecraft:mud_bricks"},
        {pos: [7, 0, 4], state: "minecraft:mud_bricks"},
        {pos: [7, 0, 5], state: "minecraft:mud_bricks"},
        {pos: [8, 0, 0], state: "minecraft:mud_bricks"},
        {pos: [8, 0, 1], state: "minecraft:mud_bricks"},
        {pos: [8, 0, 2], state: "minecraft:mud_bricks"},
        {pos: [8, 0, 3], state: "minecraft:mud_bricks"},
        {pos: [8, 0, 4], state: "minecraft:mud_bricks"},
        {pos: [8, 0, 5], state: "minecraft:mud_bricks"},
        {pos: [0, 1, 0], state: "minecraft:stone"},
        {pos: [0, 1, 1], state: "minecraft:mud_bricks"},
        {pos: [0, 1, 2], state: "minecraft:brown_glazed_terracotta{facing:north}"},
        {pos: [0, 1, 3], state: "minecraft:mud_bricks"},
        {pos: [0, 1, 4], state: "minecraft:brown_glazed_terracotta{facing:west}"},
        {pos: [0, 1, 5], state: "minecraft:mud_bricks"},
        {pos: [1, 1, 0], state: "minecraft:sand"},
        {pos: [1, 1, 1], state: "minecraft:cyan_concrete"},
        {pos: [1, 1, 2], state: "minecraft:brown_glazed_terracotta{facing:east}"},
        {pos: [1, 1, 3], state: "minecraft:mud_bricks"},
        {pos: [1, 1, 4], state: "minecraft:brown_glazed_terracotta{facing:south}"},
        {pos: [1, 1, 5], state: "minecraft:cyan_concrete"},
        {pos: [2, 1, 0], state: "minecraft:sand"},
        {pos: [2, 1, 1], state: "minecraft:cyan_concrete"},
        {pos: [2, 1, 2], state: "minecraft:brown_glazed_terracotta{facing:north}"},
        {pos: [2, 1, 3], state: "minecraft:mud_bricks"},
        {pos: [2, 1, 4], state: "minecraft:brown_glazed_terracotta{facing:west}"},
        {pos: [2, 1, 5], state: "minecraft:cyan_concrete"},
        {pos: [3, 1, 0], state: "minecraft:stone"},
        {pos: [3, 1, 1], state: "minecraft:cyan_concrete"},
        {pos: [3, 1, 2], state: "minecraft:brown_glazed_terracotta{facing:east}"},
        {pos: [3, 1, 3], state: "minecraft:mud_bricks"},
        {pos: [3, 1, 4], state: "minecraft:brown_glazed_terracotta{facing:south}"},
        {pos: [3, 1, 5], state: "minecraft:cyan_concrete"},
        {pos: [4, 1, 0], state: "minecraft:mud_bricks"},
        {pos: [4, 1, 1], state: "minecraft:cyan_concrete"},
        {pos: [4, 1, 2], state: "minecraft:brown_glazed_terracotta{facing:north}"},
        {pos: [4, 1, 3], state: "minecraft:mud_bricks"},
        {pos: [4, 1, 4], state: "minecraft:brown_glazed_terracotta{facing:west}"},
        {pos: [4, 1, 5], state: "minecraft:mud_bricks"},
        {pos: [5, 1, 0], state: "minecraft:mud_bricks"},
        {pos: [5, 1, 1], state: "minecraft:cyan_concrete"},
        {pos: [5, 1, 2], state: "minecraft:brown_glazed_terracotta{facing:east}"},
        {pos: [5, 1, 3], state: "minecraft:mud_bricks"},
        {pos: [5, 1, 4], state: "minecraft:brown_glazed_terracotta{facing:south}"},
        {pos: [5, 1, 5], state: "minecraft:cyan_concrete"},
        {pos: [6, 1, 0], state: "minecraft:jigsaw{orientation:north_up}", nbt: {final_state: "minecraft:cyan_concrete", id: "minecraft:jigsaw", joint: "rollable", name: "minecraft:road_hall_anchor", pool: "minecraft:trail_ruins/tower", target: "minecraft:road_anchor"}},
        {pos: [6, 1, 1], state: "minecraft:cyan_concrete"},
        {pos: [6, 1, 2], state: "minecraft:cyan_concrete"},
        {pos: [6, 1, 3], state: "minecraft:cyan_concrete"},
        {pos: [6, 1, 4], state: "minecraft:cyan_concrete"},
        {pos: [6, 1, 5], state: "minecraft:cyan_concrete"},
        {pos: [7, 1, 0], state: "minecraft:mud_bricks"},
        {pos: [7, 1, 1], state: "minecraft:cyan_concrete"},
        {pos: [7, 1, 2], state: "minecraft:cyan_concrete"},
        {pos: [7, 1, 3], state: "minecraft:cyan_concrete"},
        {pos: [7, 1, 4], state: "minecraft:cyan_concrete"},
        {pos: [7, 1, 5], state: "minecraft:cyan_concrete"},
        {pos: [8, 1, 0], state: "minecraft:mud_bricks"},
        {pos: [8, 1, 1], state: "minecraft:mud_bricks"},
        {pos: [8, 1, 2], state: "minecraft:jigsaw{orientation:east_up}", nbt: {final_state: "minecraft:cyan_concrete", id: "minecraft:jigsaw", joint: "rollable", name: "minecraft:hall_room_anchor", pool: "minecraft:trail_ruins/tower/additions", target: "minecraft:room_anchor"}},
        {pos: [8, 1, 3], state: "minecraft:cyan_concrete"},
        {pos: [8, 1, 4], state: "minecraft:cyan_concrete"},
        {pos: [8, 1, 5], state: "minecraft:mud_bricks"},
        {pos: [0, 2, 0], state: "minecraft:sand"},
        {pos: [0, 2, 1], state: "minecraft:mud_bricks"},
        {pos: [0, 2, 2], state: "minecraft:sand"},
        {pos: [0, 2, 3], state: "minecraft:sand"},
        {pos: [0, 2, 4], state: "minecraft:red_terracotta"},
        {pos: [0, 2, 5], state: "minecraft:mud_bricks"},
        {pos: [1, 2, 0], state: "minecraft:sand"},
        {pos: [1, 2, 1], state: "minecraft:sand"},
        {pos: [1, 2, 2], state: "minecraft:sand"},
        {pos: [1, 2, 3], state: "minecraft:mud_bricks"},
        {pos: [1, 2, 4], state: "minecraft:mud_bricks"},
        {pos: [1, 2, 5], state: "minecraft:sand"},
        {pos: [2, 2, 0], state: "minecraft:sand"},
        {pos: [2, 2, 1], state: "minecraft:sand"},
        {pos: [2, 2, 2], state: "minecraft:sand"},
        {pos: [2, 2, 3], state: "minecraft:sand"},
        {pos: [2, 2, 4], state: "minecraft:sand"},
        {pos: [2, 2, 5], state: "minecraft:sand"},
        {pos: [3, 2, 0], state: "minecraft:sand"},
        {pos: [3, 2, 1], state: "minecraft:mud_bricks"},
        {pos: [3, 2, 2], state: "minecraft:sand"},
        {pos: [3, 2, 3], state: "minecraft:sand"},
        {pos: [3, 2, 4], state: "minecraft:sand"},
        {pos: [3, 2, 5], state: "minecraft:sand"},
        {pos: [4, 2, 0], state: "minecraft:mud_bricks"},
        {pos: [4, 2, 1], state: "minecraft:mud_bricks"},
        {pos: [4, 2, 2], state: "minecraft:sand"},
        {pos: [4, 2, 3], state: "minecraft:sand"},
        {pos: [4, 2, 4], state: "minecraft:sand"},
        {pos: [4, 2, 5], state: "minecraft:mud_bricks"},
        {pos: [5, 2, 0], state: "minecraft:mud_bricks"},
        {pos: [5, 2, 1], state: "minecraft:sand"},
        {pos: [5, 2, 2], state: "minecraft:sand"},
        {pos: [5, 2, 3], state: "minecraft:sand"},
        {pos: [5, 2, 4], state: "minecraft:sand"},
        {pos: [5, 2, 5], state: "minecraft:sand"},
        {pos: [6, 2, 0], state: "minecraft:sand"},
        {pos: [6, 2, 1], state: "minecraft:sand"},
        {pos: [6, 2, 2], state: "minecraft:sand"},
        {pos: [6, 2, 3], state: "minecraft:cyan_concrete"},
        {pos: [6, 2, 4], state: "minecraft:cyan_concrete"},
        {pos: [6, 2, 5], state: "minecraft:jigsaw{orientation:south_up}", nbt: {final_state: "minecraft:air", id: "minecraft:jigsaw", joint: "rollable", name: "minecraft:hall_room_anchor", pool: "minecraft:trail_ruins/tower/additions", target: "minecraft:room_anchor"}},
        {pos: [7, 2, 0], state: "minecraft:mud_bricks"},
        {pos: [7, 2, 1], state: "minecraft:ladder{facing:south,waterlogged:false}"},
        {pos: [7, 2, 2], state: "minecraft:sand"},
        {pos: [7, 2, 3], state: "minecraft:cyan_concrete"},
        {pos: [7, 2, 4], state: "minecraft:sand"},
        {pos: [7, 2, 5], state: "minecraft:sand"},
        {pos: [8, 2, 0], state: "minecraft:mud_bricks"},
        {pos: [8, 2, 1], state: "minecraft:mud_bricks"},
        {pos: [8, 2, 2], state: "minecraft:sand"},
        {pos: [8, 2, 3], state: "minecraft:mud_bricks"},
        {pos: [8, 2, 4], state: "minecraft:mud_bricks"},
        {pos: [8, 2, 5], state: "minecraft:mud_bricks"},
        {pos: [0, 3, 1], state: "minecraft:red_terracotta"},
        {pos: [0, 3, 2], state: "minecraft:sand"},
        {pos: [0, 3, 3], state: "minecraft:sand"},
        {pos: [0, 3, 4], state: "minecraft:sand"},
        {pos: [0, 3, 5], state: "minecraft:sand"},
        {pos: [1, 3, 0], state: "minecraft:sand"},
        {pos: [1, 3, 1], state: "minecraft:sand"},
        {pos: [1, 3, 2], state: "minecraft:sand"},
        {pos: [1, 3, 3], state: "minecraft:sand"},
        {pos: [1, 3, 4], state: "minecraft:sand"},
        {pos: [1, 3, 5], state: "minecraft:sand"},
        {pos: [2, 3, 0], state: "minecraft:sand"},
        {pos: [2, 3, 1], state: "minecraft:sand"},
        {pos: [2, 3, 2], state: "minecraft:sand"},
        {pos: [2, 3, 3], state: "minecraft:sand"},
        {pos: [2, 3, 4], state: "minecraft:sand"},
        {pos: [2, 3, 5], state: "minecraft:sand"},
        {pos: [3, 3, 1], state: "minecraft:red_terracotta"},
        {pos: [3, 3, 2], state: "minecraft:sand"},
        {pos: [3, 3, 3], state: "minecraft:sand"},
        {pos: [3, 3, 4], state: "minecraft:sand"},
        {pos: [3, 3, 5], state: "minecraft:sand"},
        {pos: [4, 3, 0], state: "minecraft:red_terracotta"},
        {pos: [4, 3, 1], state: "minecraft:red_terracotta"},
        {pos: [4, 3, 2], state: "minecraft:sand"},
        {pos: [4, 3, 3], state: "minecraft:sand"},
        {pos: [4, 3, 4], state: "minecraft:sand"},
        {pos: [4, 3, 5], state: "minecraft:red_terracotta"},
        {pos: [5, 3, 0], state: "minecraft:red_terracotta"},
        {pos: [5, 3, 1], state: "minecraft:sand"},
        {pos: [5, 3, 2], state: "minecraft:sand"},
        {pos: [5, 3, 3], state: "minecraft:sand"},
        {pos: [5, 3, 4], state: "minecraft:sand"},
        {pos: [5, 3, 5], state: "minecraft:sand"},
        {pos: [6, 3, 0], state: "minecraft:sand"},
        {pos: [6, 3, 1], state: "minecraft:sand"},
        {pos: [6, 3, 2], state: "minecraft:sand"},
        {pos: [6, 3, 3], state: "minecraft:sand"},
        {pos: [6, 3, 4], state: "minecraft:sand"},
        {pos: [6, 3, 5], state: "minecraft:sand"},
        {pos: [7, 3, 0], state: "minecraft:red_terracotta"},
        {pos: [7, 3, 1], state: "minecraft:sand"},
        {pos: [7, 3, 2], state: "minecraft:sand"},
        {pos: [7, 3, 3], state: "minecraft:sand"},
        {pos: [7, 3, 4], state: "minecraft:sand"},
        {pos: [7, 3, 5], state: "minecraft:sand"},
        {pos: [8, 3, 0], state: "minecraft:red_terracotta"},
        {pos: [8, 3, 1], state: "minecraft:red_terracotta"},
        {pos: [8, 3, 2], state: "minecraft:sand"},
        {pos: [8, 3, 3], state: "minecraft:red_terracotta"},
        {pos: [8, 3, 4], state: "minecraft:red_terracotta"},
        {pos: [8, 3, 5], state: "minecraft:red_terracotta"},
        {pos: [0, 4, 1], state: "minecraft:brown_terracotta"},
        {pos: [0, 4, 2], state: "minecraft:sand"},
        {pos: [0, 4, 3], state: "minecraft:sand"},
        {pos: [0, 4, 4], state: "minecraft:sand"},
        {pos: [0, 4, 5], state: "minecraft:sand"},
        {pos: [1, 4, 1], state: "minecraft:sand"},
        {pos: [1, 4, 2], state: "minecraft:sand"},
        {pos: [1, 4, 3], state: "minecraft:sand"},
        {pos: [1, 4, 4], state: "minecraft:sand"},
        {pos: [1, 4, 5], state: "minecraft:sand"},
        {pos: [2, 4, 1], state: "minecraft:sand"},
        {pos: [2, 4, 2], state: "minecraft:sand"},
        {pos: [2, 4, 3], state: "minecraft:sand"},
        {pos: [2, 4, 4], state: "minecraft:sand"},
        {pos: [2, 4, 5], state: "minecraft:sand"},
        {pos: [3, 4, 1], state: "minecraft:brown_terracotta"},
        {pos: [3, 4, 3], state: "minecraft:sand"},
        {pos: [3, 4, 4], state: "minecraft:sand"},
        {pos: [3, 4, 5], state: "minecraft:sand"},
        {pos: [4, 4, 0], state: "minecraft:brown_terracotta"},
        {pos: [4, 4, 1], state: "minecraft:brown_terracotta"},
        {pos: [4, 4, 2], state: "minecraft:sand"},
        {pos: [4, 4, 3], state: "minecraft:sand"},
        {pos: [4, 4, 4], state: "minecraft:sand"},
        {pos: [4, 4, 5], state: "minecraft:brown_terracotta"},
        {pos: [5, 4, 0], state: "minecraft:brown_terracotta"},
        {pos: [5, 4, 1], state: "minecraft:sand"},
        {pos: [5, 4, 2], state: "minecraft:sand"},
        {pos: [5, 4, 3], state: "minecraft:sand"},
        {pos: [5, 4, 4], state: "minecraft:sand"},
        {pos: [5, 4, 5], state: "minecraft:sand"},
        {pos: [6, 4, 0], state: "minecraft:brown_terracotta"},
        {pos: [6, 4, 1], state: "minecraft:sand"},
        {pos: [6, 4, 2], state: "minecraft:sand"},
        {pos: [6, 4, 3], state: "minecraft:brown_terracotta"},
        {pos: [6, 4, 4], state: "minecraft:sand"},
        {pos: [6, 4, 5], state: "minecraft:sand"},
        {pos: [7, 4, 0], state: "minecraft:brown_terracotta"},
        {pos: [7, 4, 1], state: "minecraft:sand"},
        {pos: [7, 4, 2], state: "minecraft:sand"},
        {pos: [7, 4, 3], state: "minecraft:sand"},
        {pos: [7, 4, 4], state: "minecraft:sand"},
        {pos: [7, 4, 5], state: "minecraft:sand"},
        {pos: [8, 4, 0], state: "minecraft:brown_terracotta"},
        {pos: [8, 4, 1], state: "minecraft:brown_terracotta"},
        {pos: [8, 4, 2], state: "minecraft:brown_terracotta"},
        {pos: [8, 4, 3], state: "minecraft:brown_terracotta"},
        {pos: [8, 4, 4], state: "minecraft:brown_terracotta"},
        {pos: [8, 4, 5], state: "minecraft:brown_terracotta"},
        {pos: [0, 5, 2], state: "minecraft:brown_terracotta"},
        {pos: [1, 5, 1], state: "minecraft:brown_terracotta"},
        {pos: [1, 5, 2], state: "minecraft:sand"},
        {pos: [1, 5, 3], state: "minecraft:sand"},
        {pos: [1, 5, 4], state: "minecraft:sand"},
        {pos: [2, 5, 1], state: "minecraft:brown_terracotta"},
        {pos: [2, 5, 2], state: "minecraft:sand"},
        {pos: [2, 5, 3], state: "minecraft:air"},
        {pos: [2, 5, 4], state: "minecraft:sand"},
        {pos: [2, 5, 5], state: "minecraft:brown_terracotta"},
        {pos: [3, 5, 1], state: "minecraft:brown_terracotta"},
        {pos: [3, 5, 3], state: "minecraft:sand"},
        {pos: [3, 5, 4], state: "minecraft:sand"},
        {pos: [3, 5, 5], state: "minecraft:brown_terracotta"},
        {pos: [4, 5, 0], state: "minecraft:brown_terracotta"},
        {pos: [4, 5, 1], state: "minecraft:brown_terracotta"},
        {pos: [4, 5, 2], state: "minecraft:sand"},
        {pos: [4, 5, 3], state: "minecraft:sand"},
        {pos: [4, 5, 4], state: "minecraft:sand"},
        {pos: [4, 5, 5], state: "minecraft:brown_terracotta"},
        {pos: [5, 5, 0], state: "minecraft:brown_terracotta"},
        {pos: [5, 5, 1], state: "minecraft:brown_terracotta"},
        {pos: [5, 5, 2], state: "minecraft:air"},
        {pos: [5, 5, 3], state: "minecraft:sand"},
        {pos: [5, 5, 4], state: "minecraft:sand"},
        {pos: [5, 5, 5], state: "minecraft:brown_terracotta"},
        {pos: [6, 5, 0], state: "minecraft:brown_terracotta"},
        {pos: [6, 5, 1], state: "minecraft:sand"},
        {pos: [6, 5, 2], state: "minecraft:sand"},
        {pos: [6, 5, 3], state: "minecraft:sand"},
        {pos: [6, 5, 4], state: "minecraft:air"},
        {pos: [6, 5, 5], state: "minecraft:brown_terracotta"},
        {pos: [7, 5, 0], state: "minecraft:brown_terracotta"},
        {pos: [7, 5, 1], state: "minecraft:ladder{facing:south,waterlogged:false}"},
        {pos: [7, 5, 2], state: "minecraft:sand"},
        {pos: [7, 5, 3], state: "minecraft:brown_terracotta"},
        {pos: [7, 5, 4], state: "minecraft:air"},
        {pos: [7, 5, 5], state: "minecraft:brown_terracotta"},
        {pos: [8, 5, 0], state: "minecraft:brown_terracotta"},
        {pos: [8, 5, 1], state: "minecraft:brown_terracotta"},
        {pos: [8, 5, 2], state: "minecraft:brown_terracotta"},
        {pos: [8, 5, 3], state: "minecraft:brown_terracotta"},
        {pos: [8, 5, 4], state: "minecraft:brown_terracotta"},
        {pos: [8, 5, 5], state: "minecraft:brown_terracotta"},
        {pos: [1, 6, 2], state: "minecraft:brown_terracotta"},
        {pos: [2, 6, 2], state: "minecraft:brown_terracotta"},
        {pos: [2, 6, 3], state: "minecraft:brown_terracotta"},
        {pos: [2, 6, 4], state: "minecraft:brown_terracotta"},
        {pos: [3, 6, 2], state: "minecraft:brown_terracotta"},
        {pos: [3, 6, 3], state: "minecraft:brown_terracotta"},
        {pos: [3, 6, 4], state: "minecraft:brown_terracotta"},
        {pos: [4, 6, 2], state: "minecraft:brown_terracotta"},
        {pos: [4, 6, 3], state: "minecraft:brown_terracotta"},
        {pos: [4, 6, 4], state: "minecraft:brown_terracotta"},
        {pos: [5, 6, 0], state: "minecraft:brown_terracotta"},
        {pos: [5, 6, 1], state: "minecraft:brown_terracotta"},
        {pos: [5, 6, 2], state: "minecraft:brown_terracotta"},
        {pos: [5, 6, 3], state: "minecraft:brown_terracotta"},
        {pos: [5, 6, 4], state: "minecraft:brown_terracotta"},
        {pos: [6, 6, 0], state: "minecraft:brown_terracotta"},
        {pos: [6, 6, 1], state: "minecraft:brown_terracotta"},
        {pos: [6, 6, 2], state: "minecraft:brown_terracotta"},
        {pos: [6, 6, 4], state: "minecraft:brown_terracotta"},
        {pos: [7, 6, 0], state: "minecraft:brown_terracotta"},
        {pos: [7, 6, 1], state: "minecraft:sand"},
        {pos: [7, 6, 2], state: "minecraft:brown_terracotta"},
        {pos: [7, 6, 4], state: "minecraft:brown_terracotta"},
        {pos: [8, 6, 0], state: "minecraft:brown_terracotta"},
        {pos: [8, 6, 1], state: "minecraft:brown_terracotta"},
        {pos: [8, 6, 2], state: "minecraft:brown_terracotta"},
        {pos: [8, 6, 3], state: "minecraft:brown_terracotta"},
        {pos: [8, 6, 4], state: "minecraft:brown_terracotta"},
        {pos: [8, 6, 5], state: "minecraft:brown_terracotta"}
    ],
    entities: [],
    palette: [
        "minecraft:cobblestone",
        "minecraft:mud_bricks",
        "minecraft:stone",
        "minecraft:brown_glazed_terracotta{facing:north}",
        "minecraft:brown_glazed_terracotta{facing:west}",
        "minecraft:sand",
        "minecraft:cyan_concrete",
        "minecraft:brown_glazed_terracotta{facing:east}",
        "minecraft:brown_glazed_terracotta{facing:south}",
        "minecraft:red_terracotta",
        "minecraft:brown_terracotta",
        "minecraft:ladder{facing:south,waterlogged:false}",
        "minecraft:air",
        "minecraft:jigsaw{orientation:north_up}",
        "minecraft:jigsaw{orientation:east_up}",
        "minecraft:jigsaw{orientation:south_up}"
    ]
}
