{
    size: [7, 7, 7],
    data: [
        {pos: [0, 0, 0], state: "minecraft:bricks"},
        {pos: [0, 0, 1], state: "minecraft:bricks"},
        {pos: [0, 0, 2], state: "minecraft:bricks"},
        {pos: [0, 0, 3], state: "minecraft:bricks"},
        {pos: [0, 0, 4], state: "minecraft:bricks"},
        {pos: [0, 0, 5], state: "minecraft:bricks"},
        {pos: [0, 0, 6], state: "minecraft:gravel"},
        {pos: [1, 0, 0], state: "minecraft:bricks"},
        {pos: [1, 0, 1], state: "minecraft:bricks"},
        {pos: [1, 0, 2], state: "minecraft:gravel"},
        {pos: [1, 0, 3], state: "minecraft:gravel"},
        {pos: [1, 0, 4], state: "minecraft:gravel"},
        {pos: [1, 0, 5], state: "minecraft:bricks"},
        {pos: [1, 0, 6], state: "minecraft:bricks"},
        {pos: [2, 0, 0], state: "minecraft:bricks"},
        {pos: [2, 0, 1], state: "minecraft:bricks"},
        {pos: [2, 0, 2], state: "minecraft:gravel"},
        {pos: [2, 0, 3], state: "minecraft:gravel"},
        {pos: [2, 0, 4], state: "minecraft:gravel"},
        {pos: [2, 0, 5], state: "minecraft:bricks"},
        {pos: [2, 0, 6], state: "minecraft:bricks"},
        {pos: [3, 0, 0], state: "minecraft:bricks"},
        {pos: [3, 0, 1], state: "minecraft:bricks"},
        {pos: [3, 0, 2], state: "minecraft:gravel"},
        {pos: [3, 0, 3], state: "minecraft:gravel"},
        {pos: [3, 0, 4], state: "minecraft:gravel"},
        {pos: [3, 0, 5], state: "minecraft:gravel"},
        {pos: [3, 0, 6], state: "minecraft:bricks"},
        {pos: [4, 0, 0], state: "minecraft:bricks"},
        {pos: [4, 0, 1], state: "minecraft:bricks"},
        {pos: [4, 0, 2], state: "minecraft:bricks"},
        {pos: [4, 0, 3], state: "minecraft:bricks"},
        {pos: [4, 0, 4], state: "minecraft:gravel"},
        {pos: [4, 0, 5], state: "minecraft:bricks"},
        {pos: [4, 0, 6], state: "minecraft:bricks"},
        {pos: [5, 0, 0], state: "minecraft:bricks"},
        {pos: [5, 0, 1], state: "minecraft:bricks"},
        {pos: [5, 0, 2], state: "minecraft:bricks"},
        {pos: [5, 0, 3], state: "minecraft:bricks"},
        {pos: [5, 0, 4], state: "minecraft:bricks"},
        {pos: [5, 0, 5], state: "minecraft:bricks"},
        {pos: [5, 0, 6], state: "minecraft:bricks"},
        {pos: [6, 0, 0], state: "minecraft:gravel"},
        {pos: [6, 0, 1], state: "minecraft:bricks"},
        {pos: [6, 0, 2], state: "minecraft:bricks"},
        {pos: [6, 0, 3], state: "minecraft:bricks"},
        {pos: [6, 0, 4], state: "minecraft:bricks"},
        {pos: [6, 0, 5], state: "minecraft:bricks"},
        {pos: [6, 0, 6], state: "minecraft:gravel"},
        {pos: [0, 1, 0], state: "minecraft:bricks"},
        {pos: [0, 1, 1], state: "minecraft:bricks"},
        {pos: [0, 1, 2], state: "minecraft:jigsaw{orientation:west_up}", nbt: {final_state: "minecraft:dirt", id: "minecraft:jigsaw", joint: "rollable", name: "minecraft:room_anchor", pool: "minecraft:trail_ruins/tower/additions", target: "minecraft:hall_room_anchor"}},
        {pos: [0, 1, 3], state: "minecraft:bricks"},
        {pos: [0, 1, 4], state: "minecraft:bricks"},
        {pos: [0, 1, 5], state: "minecraft:bricks"},
        {pos: [0, 1, 6], state: "minecraft:gravel"},
        {pos: [1, 1, 0], state: "minecraft:bricks"},
        {pos: [1, 1, 1], state: "minecraft:gravel"},
        {pos: [1, 1, 2], state: "minecraft:gravel"},
        {pos: [1, 1, 3], state: "minecraft:gravel"},
        {pos: [1, 1, 4], state: "minecraft:gravel"},
        {pos: [1, 1, 5], state: "minecraft:gravel"},
        {pos: [1, 1, 6], state: "minecraft:gravel"},
        {pos: [2, 1, 0], state: "minecraft:bricks"},
        {pos: [2, 1, 1], state: "minecraft:gravel"},
        {pos: [2, 1, 2], state: "minecraft:gravel"},
        {pos: [2, 1, 3], state: "minecraft:gravel"},
        {pos: [2, 1, 4], state: "minecraft:gravel"},
        {pos: [2, 1, 5], state: "minecraft:gravel"},
        {pos: [2, 1, 6], state: "minecraft:gravel"},
        {pos: [3, 1, 0], state: "minecraft:bricks"},
        {pos: [3, 1, 1], state: "minecraft:gravel"},
        {pos: [3, 1, 2], state: "minecraft:gravel"},
        {pos: [3, 1, 3], state: "minecraft:gravel"},
        {pos: [3, 1, 4], state: "minecraft:gravel"},
        {pos: [3, 1, 5], state: "minecraft:gravel"},
        {pos: [3, 1, 6], state: "minecraft:bricks"},
        {pos: [4, 1, 0], state: "minecraft:bricks"},
        {pos: [4, 1, 1], state: "minecraft:gravel"},
        {pos: [4, 1, 2], state: "minecraft:gravel"},
        {pos: [4, 1, 3], state: "minecraft:gravel"},
        {pos: [4, 1, 4], state: "minecraft:gravel"},
        {pos: [4, 1, 5], state: "minecraft:gravel"},
        {pos: [4, 1, 6], state: "minecraft:bricks"},
        {pos: [5, 1, 0], state: "minecraft:bricks"},
        {pos: [5, 1, 1], state: "minecraft:gravel"},
        {pos: [5, 1, 2], state: "minecraft:gravel"},
        {pos: [5, 1, 3], state: "minecraft:gravel"},
        {pos: [5, 1, 4], state: "minecraft:gravel"},
        {pos: [5, 1, 5], state: "minecraft:gravel"},
        {pos: [5, 1, 6], state: "minecraft:bricks"},
        {pos: [6, 1, 0], state: "minecraft:gravel"},
        {pos: [6, 1, 1], state: "minecraft:bricks"},
        {pos: [6, 1, 2], state: "minecraft:bricks"},
        {pos: [6, 1, 3], state: "minecraft:bricks"},
        {pos: [6, 1, 4], state: "minecraft:bricks"},
        {pos: [6, 1, 5], state: "minecraft:bricks"},
        {pos: [0, 2, 0], state: "minecraft:bricks"},
        {pos: [0, 2, 1], state: "minecraft:gravel"},
        {pos: [0, 2, 2], state: "minecraft:gravel"},
        {pos: [0, 2, 3], state: "minecraft:bricks"},
        {pos: [0, 2, 4], state: "minecraft:gravel"},
        {pos: [0, 2, 5], state: "minecraft:gravel"},
        {pos: [1, 2, 0], state: "minecraft:gravel"},
        {pos: [1, 2, 1], state: "minecraft:gravel"},
        {pos: [1, 2, 2], state: "minecraft:gravel"},
        {pos: [1, 2, 3], state: "minecraft:gravel"},
        {pos: [1, 2, 4], state: "minecraft:gravel"},
        {pos: [1, 2, 5], state: "minecraft:gravel"},
        {pos: [1, 2, 6], state: "minecraft:gravel"},
        {pos: [2, 2, 0], state: "minecraft:gravel"},
        {pos: [2, 2, 1], state: "minecraft:gravel"},
        {pos: [2, 2, 2], state: "minecraft:gravel"},
        {pos: [2, 2, 3], state: "minecraft:gravel"},
        {pos: [2, 2, 4], state: "minecraft:gravel"},
        {pos: [2, 2, 5], state: "minecraft:gravel"},
        {pos: [2, 2, 6], state: "minecraft:gravel"},
        {pos: [3, 2, 0], state: "minecraft:gravel"},
        {pos: [3, 2, 1], state: "minecraft:gravel"},
        {pos: [3, 2, 2], state: "minecraft:gravel"},
        {pos: [3, 2, 3], state: "minecraft:gravel"},
        {pos: [3, 2, 4], state: "minecraft:gravel"},
        {pos: [3, 2, 5], state: "minecraft:gravel"},
        {pos: [3, 2, 6], state: "minecraft:gravel"},
        {pos: [4, 2, 0], state: "minecraft:gravel"},
        {pos: [4, 2, 1], state: "minecraft:gravel"},
        {pos: [4, 2, 2], state: "minecraft:gravel"},
        {pos: [4, 2, 3], state: "minecraft:gravel"},
        {pos: [4, 2, 4], state: "minecraft:gravel"},
        {pos: [4, 2, 5], state: "minecraft:gravel"},
        {pos: [4, 2, 6], state: "minecraft:gravel"},
        {pos: [5, 2, 0], state: "minecraft:gravel"},
        {pos: [5, 2, 1], state: "minecraft:gravel"},
        {pos: [5, 2, 2], state: "minecraft:gravel"},
        {pos: [5, 2, 3], state: "minecraft:gravel"},
        {pos: [5, 2, 4], state: "minecraft:gravel"},
        {pos: [5, 2, 5], state: "minecraft:gravel"},
        {pos: [5, 2, 6], state: "minecraft:gravel"},
        {pos: [6, 2, 1], state: "minecraft:bricks"},
        {pos: [6, 2, 2], state: "minecraft:bricks"},
        {pos: [6, 2, 3], state: "minecraft:bricks"},
        {pos: [6, 2, 4], state: "minecraft:gravel"},
        {pos: [6, 2, 5], state: "minecraft:bricks"},
        {pos: [0, 3, 0], state: "minecraft:gravel"},
        {pos: [0, 3, 1], state: "minecraft:gravel"},
        {pos: [0, 3, 2], state: "minecraft:gravel"},
        {pos: [0, 3, 3], state: "minecraft:gravel"},
        {pos: [0, 3, 4], state: "minecraft:gravel"},
        {pos: [0, 3, 5], state: "minecraft:gravel"},
        {pos: [1, 3, 0], state: "minecraft:gravel"},
        {pos: [1, 3, 1], state: "minecraft:gravel"},
        {pos: [1, 3, 2], state: "minecraft:gravel"},
        {pos: [1, 3, 3], state: "minecraft:gravel"},
        {pos: [1, 3, 4], state: "minecraft:gravel"},
        {pos: [1, 3, 5], state: "minecraft:gravel"},
        {pos: [1, 3, 6], state: "minecraft:gravel"},
        {pos: [2, 3, 0], state: "minecraft:gravel"},
        {pos: [2, 3, 1], state: "minecraft:gravel"},
        {pos: [2, 3, 2], state: "minecraft:gravel"},
        {pos: [2, 3, 3], state: "minecraft:gravel"},
        {pos: [2, 3, 4], state: "minecraft:gravel"},
        {pos: [2, 3, 5], state: "minecraft:gravel"},
        {pos: [2, 3, 6], state: "minecraft:gravel"},
        {pos: [3, 3, 0], state: "minecraft:gravel"},
        {pos: [3, 3, 1], state: "minecraft:gravel"},
        {pos: [3, 3, 2], state: "minecraft:gravel"},
        {pos: [3, 3, 3], state: "minecraft:gravel"},
        {pos: [3, 3, 4], state: "minecraft:gravel"},
        {pos: [3, 3, 5], state: "minecraft:gravel"},
        {pos: [3, 3, 6], state: "minecraft:gravel"},
        {pos: [4, 3, 0], state: "minecraft:gravel"},
        {pos: [4, 3, 1], state: "minecraft:gravel"},
        {pos: [4, 3, 2], state: "minecraft:gravel"},
        {pos: [4, 3, 3], state: "minecraft:gravel"},
        {pos: [4, 3, 4], state: "minecraft:gravel"},
        {pos: [4, 3, 5], state: "minecraft:gravel"},
        {pos: [4, 3, 6], state: "minecraft:gravel"},
        {pos: [5, 3, 0], state: "minecraft:gravel"},
        {pos: [5, 3, 1], state: "minecraft:gravel"},
        {pos: [5, 3, 2], state: "minecraft:gravel"},
        {pos: [5, 3, 3], state: "minecraft:gravel"},
        {pos: [5, 3, 4], state: "minecraft:gravel"},
        {pos: [5, 3, 5], state: "minecraft:gravel"},
        {pos: [5, 3, 6], state: "minecraft:gravel"},
        {pos: [6, 3, 1], state: "minecraft:gravel"},
        {pos: [6, 3, 2], state: "minecraft:gravel"},
        {pos: [6, 3, 3], state: "minecraft:gravel"},
        {pos: [6, 3, 4], state: "minecraft:gravel"},
        {pos: [6, 3, 5], state: "minecraft:gravel"},
        {pos: [0, 4, 0], state: "minecraft:gravel"},
        {pos: [0, 4, 1], state: "minecraft:gravel"},
        {pos: [0, 4, 2], state: "minecraft:gravel"},
        {pos: [0, 4, 3], state: "minecraft:gravel"},
        {pos: [0, 4, 4], state: "minecraft:gravel"},
        {pos: [0, 4, 5], state: "minecraft:gravel"},
        {pos: [1, 4, 0], state: "minecraft:gravel"},
        {pos: [1, 4, 1], state: "minecraft:gravel"},
        {pos: [1, 4, 4], state: "minecraft:gravel"},
        {pos: [1, 4, 5], state: "minecraft:gravel"},
        {pos: [1, 4, 6], state: "minecraft:gravel"},
        {pos: [2, 4, 0], state: "minecraft:gravel"},
        {pos: [2, 4, 1], state: "minecraft:gravel"},
        {pos: [2, 4, 2], state: "minecraft:gravel"},
        {pos: [2, 4, 3], state: "minecraft:gravel"},
        {pos: [2, 4, 4], state: "minecraft:gravel"},
        {pos: [2, 4, 5], state: "minecraft:gravel"},
        {pos: [2, 4, 6], state: "minecraft:gravel"},
        {pos: [3, 4, 0], state: "minecraft:gravel"},
        {pos: [3, 4, 1], state: "minecraft:gravel"},
        {pos: [3, 4, 6], state: "minecraft:gravel"},
        {pos: [4, 4, 0], state: "minecraft:gravel"},
        {pos: [4, 4, 1], state: "minecraft:gravel"},
        {pos: [4, 4, 2], state: "minecraft:gravel"},
        {pos: [4, 4, 3], state: "minecraft:gravel"},
        {pos: [4, 4, 5], state: "minecraft:gravel"},
        {pos: [4, 4, 6], state: "minecraft:gravel"},
        {pos: [5, 4, 0], state: "minecraft:gravel"},
        {pos: [5, 4, 1], state: "minecraft:gravel"},
        {pos: [5, 4, 2], state: "minecraft:gravel"},
        {pos: [5, 4, 3], state: "minecraft:gravel"},
        {pos: [5, 4, 4], state: "minecraft:gravel"},
        {pos: [5, 4, 5], state: "minecraft:gravel"},
        {pos: [5, 4, 6], state: "minecraft:gravel"},
        {pos: [6, 4, 1], state: "minecraft:gravel"},
        {pos: [6, 4, 3], state: "minecraft:gravel"},
        {pos: [6, 4, 4], state: "minecraft:gravel"},
        {pos: [6, 4, 5], state: "minecraft:gravel"},
        {pos: [0, 5, 0], state: "minecraft:gravel"},
        {pos: [0, 5, 1], state: "minecraft:gravel"},
        {pos: [0, 5, 2], state: "minecraft:light_gray_terracotta"},
        {pos: [0, 5, 3], state: "minecraft:gravel"},
        {pos: [0, 5, 4], state: "minecraft:gravel"},
        {pos: [0, 5, 5], state: "minecraft:gravel"},
        {pos: [1, 5, 0], state: "minecraft:gravel"},
        {pos: [1, 5, 1], state: "minecraft:gravel"},
        {pos: [1, 5, 4], state: "minecraft:gravel"},
        {pos: [1, 5, 5], state: "minecraft:gravel"},
        {pos: [2, 5, 0], state: "minecraft:light_gray_terracotta"},
        {pos: [2, 5, 3], state: "minecraft:gravel"},
        {pos: [4, 5, 2], state: "minecraft:gravel"},
        {pos: [4, 5, 3], state: "minecraft:gravel"},
        {pos: [5, 5, 3], state: "minecraft:gravel"},
        {pos: [5, 5, 4], state: "minecraft:gravel"},
        {pos: [6, 5, 3], state: "minecraft:gravel"},
        {pos: [6, 5, 4], state: "minecraft:gravel"},
        {pos: [0, 6, 1], state: "minecraft:light_gray_terracotta"},
        {pos: [0, 6, 2], state: "minecraft:gravel"},
        {pos: [0, 6, 3], state: "minecraft:light_gray_terracotta"},
        {pos: [0, 6, 4], state: "minecraft:light_gray_terracotta"},
        {pos: [0, 6, 5], state: "minecraft:gravel"},
        {pos: [1, 6, 5], state: "minecraft:light_gray_terracotta"}
    ],
    entities: [],
    palette: [
        "minecraft:bricks",
        "minecraft:gravel",
        "minecraft:light_gray_terracotta",
        "minecraft:jigsaw{orientation:west_up}"
    ]
}
