{
    size: [5, 4, 5],
    data: [
        {pos: [0, 0, 0], state: "minecraft:blue_terracotta"},
        {pos: [0, 0, 1], state: "minecraft:blue_terracotta"},
        {pos: [1, 0, 1], state: "minecraft:gravel"},
        {pos: [1, 0, 2], state: "minecraft:gravel"},
        {pos: [1, 0, 3], state: "minecraft:mud_bricks"},
        {pos: [1, 0, 4], state: "minecraft:blue_terracotta"},
        {pos: [2, 0, 1], state: "minecraft:gravel"},
        {pos: [2, 0, 2], state: "minecraft:gravel"},
        {pos: [2, 0, 3], state: "minecraft:mud_bricks"},
        {pos: [2, 0, 4], state: "minecraft:gravel"},
        {pos: [3, 0, 1], state: "minecraft:gravel"},
        {pos: [3, 0, 2], state: "minecraft:gravel"},
        {pos: [3, 0, 3], state: "minecraft:gravel"},
        {pos: [3, 0, 4], state: "minecraft:blue_terracotta"},
        {pos: [4, 0, 0], state: "minecraft:jigsaw{orientation:down_north}", nbt: {final_state: "minecraft:dirt", id: "minecraft:jigsaw", joint: "aligned", name: "minecraft:tower_top_1", pool: "minecraft:trail_ruins/tower", target: "minecraft:tower_bottom_1"}},
        {pos: [4, 0, 3], state: "minecraft:blue_terracotta"},
        {pos: [4, 0, 4], state: "minecraft:blue_terracotta"},
        {pos: [0, 1, 0], state: "minecraft:red_terracotta"},
        {pos: [0, 1, 1], state: "minecraft:red_terracotta"},
        {pos: [0, 1, 2], state: "minecraft:red_terracotta"},
        {pos: [0, 1, 3], state: "minecraft:red_terracotta"},
        {pos: [0, 1, 4], state: "minecraft:red_terracotta"},
        {pos: [1, 1, 2], state: "minecraft:gravel"},
        {pos: [1, 1, 3], state: "minecraft:gravel"},
        {pos: [1, 1, 4], state: "minecraft:red_terracotta"},
        {pos: [2, 1, 1], state: "minecraft:gravel"},
        {pos: [2, 1, 2], state: "minecraft:gravel"},
        {pos: [2, 1, 3], state: "minecraft:gravel"},
        {pos: [2, 1, 4], state: "minecraft:red_terracotta"},
        {pos: [3, 1, 3], state: "minecraft:mud_bricks"},
        {pos: [3, 1, 4], state: "minecraft:red_terracotta"},
        {pos: [4, 1, 4], state: "minecraft:red_terracotta"},
        {pos: [0, 2, 1], state: "minecraft:blue_terracotta"},
        {pos: [0, 2, 2], state: "minecraft:red_terracotta"},
        {pos: [0, 2, 3], state: "minecraft:blue_terracotta"},
        {pos: [0, 2, 4], state: "minecraft:blue_terracotta"},
        {pos: [1, 2, 2], state: "minecraft:gravel"},
        {pos: [1, 2, 3], state: "minecraft:gravel"},
        {pos: [1, 2, 4], state: "minecraft:blue_terracotta"},
        {pos: [2, 2, 3], state: "minecraft:gravel"},
        {pos: [2, 2, 4], state: "minecraft:red_terracotta"},
        {pos: [0, 3, 2], state: "minecraft:mud_brick_slab{type:bottom,waterlogged:false}"},
        {pos: [0, 3, 3], state: "minecraft:blue_terracotta"},
        {pos: [0, 3, 4], state: "minecraft:blue_terracotta"},
        {pos: [1, 3, 3], state: "minecraft:gravel"},
        {pos: [1, 3, 4], state: "minecraft:blue_terracotta"}
    ],
    entities: [],
    palette: [
        "minecraft:blue_terracotta",
        "minecraft:gravel",
        "minecraft:mud_bricks",
        "minecraft:red_terracotta",
        "minecraft:mud_brick_slab{type:bottom,waterlogged:false}",
        "minecraft:jigsaw{orientation:down_north}"
    ]
}
