{
    size: [5, 4, 5],
    data: [
        {pos: [0, 0, 1], state: "minecraft:gravel"},
        {pos: [0, 0, 2], state: "minecraft:gravel"},
        {pos: [0, 0, 3], state: "minecraft:light_gray_terracotta"},
        {pos: [0, 0, 4], state: "minecraft:light_gray_terracotta"},
        {pos: [1, 0, 0], state: "minecraft:gravel"},
        {pos: [1, 0, 1], state: "minecraft:gravel"},
        {pos: [1, 0, 2], state: "minecraft:gravel"},
        {pos: [1, 0, 3], state: "minecraft:gravel"},
        {pos: [1, 0, 4], state: "minecraft:light_gray_terracotta"},
        {pos: [2, 0, 0], state: "minecraft:gravel"},
        {pos: [2, 0, 1], state: "minecraft:gravel"},
        {pos: [2, 0, 2], state: "minecraft:gravel"},
        {pos: [2, 0, 3], state: "minecraft:gravel"},
        {pos: [2, 0, 4], state: "minecraft:gravel"},
        {pos: [3, 0, 0], state: "minecraft:light_gray_terracotta"},
        {pos: [3, 0, 1], state: "minecraft:gravel"},
        {pos: [3, 0, 2], state: "minecraft:gravel"},
        {pos: [3, 0, 3], state: "minecraft:gravel"},
        {pos: [3, 0, 4], state: "minecraft:light_gray_terracotta"},
        {pos: [4, 0, 0], state: "minecraft:jigsaw{orientation:down_east}", nbt: {final_state: "minecraft:dirt", id: "minecraft:jigsaw", joint: "aligned", name: "minecraft:tower_top_2", pool: "minecraft:trail_ruins/tower", target: "minecraft:tower_bottom_2"}},
        {pos: [4, 0, 1], state: "minecraft:light_gray_terracotta"},
        {pos: [4, 0, 3], state: "minecraft:light_gray_terracotta"},
        {pos: [4, 0, 4], state: "minecraft:light_gray_terracotta"},
        {pos: [0, 1, 3], state: "minecraft:gravel"},
        {pos: [0, 1, 4], state: "minecraft:cyan_terracotta"},
        {pos: [1, 1, 1], state: "minecraft:gravel"},
        {pos: [1, 1, 2], state: "minecraft:gravel"},
        {pos: [1, 1, 3], state: "minecraft:white_terracotta"},
        {pos: [1, 1, 4], state: "minecraft:cyan_terracotta"},
        {pos: [2, 1, 0], state: "minecraft:gravel"},
        {pos: [2, 1, 1], state: "minecraft:gravel"},
        {pos: [2, 1, 2], state: "minecraft:gravel"},
        {pos: [2, 1, 3], state: "minecraft:gravel"},
        {pos: [2, 1, 4], state: "minecraft:gravel"},
        {pos: [3, 1, 0], state: "minecraft:cyan_terracotta"},
        {pos: [3, 1, 1], state: "minecraft:gravel"},
        {pos: [3, 1, 2], state: "minecraft:gravel"},
        {pos: [3, 1, 3], state: "minecraft:gravel"},
        {pos: [3, 1, 4], state: "minecraft:cyan_terracotta"},
        {pos: [4, 1, 1], state: "minecraft:cyan_terracotta"},
        {pos: [4, 1, 2], state: "minecraft:cyan_terracotta"},
        {pos: [4, 1, 3], state: "minecraft:cyan_terracotta"},
        {pos: [4, 1, 4], state: "minecraft:cyan_terracotta"},
        {pos: [2, 2, 2], state: "minecraft:gravel"},
        {pos: [2, 2, 3], state: "minecraft:gravel"},
        {pos: [2, 2, 4], state: "minecraft:gravel"},
        {pos: [3, 2, 0], state: "minecraft:gravel"},
        {pos: [3, 2, 1], state: "minecraft:gravel"},
        {pos: [3, 2, 2], state: "minecraft:white_terracotta"},
        {pos: [3, 2, 3], state: "minecraft:gravel"},
        {pos: [3, 2, 4], state: "minecraft:white_terracotta"},
        {pos: [4, 2, 1], state: "minecraft:white_terracotta"},
        {pos: [4, 2, 2], state: "minecraft:cyan_terracotta"},
        {pos: [4, 2, 3], state: "minecraft:white_terracotta"},
        {pos: [4, 2, 4], state: "minecraft:white_terracotta"},
        {pos: [3, 3, 4], state: "minecraft:gravel"},
        {pos: [4, 3, 1], state: "minecraft:white_terracotta"},
        {pos: [4, 3, 2], state: "minecraft:gravel"},
        {pos: [4, 3, 3], state: "minecraft:white_terracotta"},
        {pos: [4, 3, 4], state: "minecraft:gravel"}
    ],
    entities: [],
    palette: [
        "minecraft:gravel",
        "minecraft:light_gray_terracotta",
        "minecraft:cyan_terracotta",
        "minecraft:white_terracotta",
        "minecraft:jigsaw{orientation:down_east}"
    ]
}
