{
    size: [7, 17, 7],
    data: [
        {pos: [0, 0, 1], state: "minecraft:mud_bricks"},
        {pos: [0, 0, 2], state: "minecraft:stone_bricks"},
        {pos: [0, 0, 3], state: "minecraft:stone_bricks"},
        {pos: [0, 0, 4], state: "minecraft:cracked_stone_bricks"},
        {pos: [0, 0, 5], state: "minecraft:mud_bricks"},
        {pos: [1, 0, 0], state: "minecraft:mud_bricks"},
        {pos: [1, 0, 1], state: "minecraft:mud_bricks"},
        {pos: [1, 0, 2], state: "minecraft:mud_bricks"},
        {pos: [1, 0, 3], state: "minecraft:mud_bricks"},
        {pos: [1, 0, 4], state: "minecraft:mud_bricks"},
        {pos: [1, 0, 5], state: "minecraft:mud_bricks"},
        {pos: [1, 0, 6], state: "minecraft:mud_bricks"},
        {pos: [2, 0, 0], state: "minecraft:stone_bricks"},
        {pos: [2, 0, 1], state: "minecraft:mud_bricks"},
        {pos: [2, 0, 2], state: "minecraft:mud_bricks"},
        {pos: [2, 0, 3], state: "minecraft:mud_bricks"},
        {pos: [2, 0, 4], state: "minecraft:mud_bricks"},
        {pos: [2, 0, 5], state: "minecraft:mud_bricks"},
        {pos: [2, 0, 6], state: "minecraft:cracked_stone_bricks"},
        {pos: [3, 0, 0], state: "minecraft:cracked_stone_bricks"},
        {pos: [3, 0, 1], state: "minecraft:mud_bricks"},
        {pos: [3, 0, 2], state: "minecraft:mud_bricks"},
        {pos: [3, 0, 3], state: "minecraft:mud_bricks"},
        {pos: [3, 0, 4], state: "minecraft:mud_bricks"},
        {pos: [3, 0, 5], state: "minecraft:mud_bricks"},
        {pos: [3, 0, 6], state: "minecraft:stone_bricks"},
        {pos: [4, 0, 0], state: "minecraft:cracked_stone_bricks"},
        {pos: [4, 0, 1], state: "minecraft:mud_bricks"},
        {pos: [4, 0, 2], state: "minecraft:mud_bricks"},
        {pos: [4, 0, 3], state: "minecraft:mud_bricks"},
        {pos: [4, 0, 4], state: "minecraft:mud_bricks"},
        {pos: [4, 0, 5], state: "minecraft:mud_bricks"},
        {pos: [4, 0, 6], state: "minecraft:stone_bricks"},
        {pos: [5, 0, 0], state: "minecraft:mud_bricks"},
        {pos: [5, 0, 1], state: "minecraft:mud_bricks"},
        {pos: [5, 0, 2], state: "minecraft:mud_bricks"},
        {pos: [5, 0, 3], state: "minecraft:mud_bricks"},
        {pos: [5, 0, 4], state: "minecraft:mud_bricks"},
        {pos: [5, 0, 5], state: "minecraft:mud_bricks"},
        {pos: [5, 0, 6], state: "minecraft:mud_bricks"},
        {pos: [6, 0, 1], state: "minecraft:mud_bricks"},
        {pos: [6, 0, 2], state: "minecraft:cracked_stone_bricks"},
        {pos: [6, 0, 3], state: "minecraft:stone_bricks"},
        {pos: [6, 0, 4], state: "minecraft:stone_bricks"},
        {pos: [6, 0, 5], state: "minecraft:mud_bricks"},
        {pos: [0, 1, 1], state: "minecraft:mud_bricks"},
        {pos: [0, 1, 2], state: "minecraft:stone_bricks"},
        {pos: [0, 1, 3], state: "minecraft:jigsaw{orientation:west_up}", nbt: {final_state: "minecraft:mud_bricks", id: "minecraft:jigsaw", joint: "rollable", name: "minecraft:road_connector", pool: "minecraft:trail_ruins/roads", target: "minecraft:long_road_end"}},
        {pos: [0, 1, 4], state: "minecraft:stone_bricks"},
        {pos: [0, 1, 5], state: "minecraft:mud_bricks"},
        {pos: [1, 1, 0], state: "minecraft:mud_bricks"},
        {pos: [1, 1, 1], state: "minecraft:mud_bricks"},
        {pos: [1, 1, 2], state: "minecraft:mud_bricks"},
        {pos: [1, 1, 3], state: "minecraft:stone_bricks"},
        {pos: [1, 1, 4], state: "minecraft:mud_bricks"},
        {pos: [1, 1, 5], state: "minecraft:mud_bricks"},
        {pos: [1, 1, 6], state: "minecraft:mud_bricks"},
        {pos: [2, 1, 0], state: "minecraft:stone_bricks"},
        {pos: [2, 1, 1], state: "minecraft:stone_bricks"},
        {pos: [2, 1, 2], state: "minecraft:sand"},
        {pos: [2, 1, 3], state: "minecraft:sand"},
        {pos: [2, 1, 4], state: "minecraft:stone_bricks"},
        {pos: [2, 1, 5], state: "minecraft:stone_bricks"},
        {pos: [2, 1, 6], state: "minecraft:stone_bricks"},
        {pos: [3, 1, 0], state: "minecraft:jigsaw{orientation:north_up}", nbt: {final_state: "minecraft:cobblestone", id: "minecraft:jigsaw", joint: "rollable", name: "minecraft:road_anchor", pool: "minecraft:trail_ruins/tower/additions", target: "minecraft:large_hall_connector"}},
        {pos: [3, 1, 1], state: "minecraft:cracked_stone_bricks"},
        {pos: [3, 1, 2], state: "minecraft:cracked_stone_bricks"},
        {pos: [3, 1, 3], state: "minecraft:sand"},
        {pos: [3, 1, 4], state: "minecraft:mud_bricks"},
        {pos: [3, 1, 5], state: "minecraft:cracked_stone_bricks"},
        {pos: [3, 1, 6], state: "minecraft:jigsaw{orientation:south_up}", nbt: {final_state: "minecraft:cobblestone", id: "minecraft:jigsaw", joint: "rollable", name: "minecraft:road_anchor", pool: "minecraft:trail_ruins/tower/additions", target: "minecraft:road_hall_anchor"}},
        {pos: [4, 1, 0], state: "minecraft:stone_bricks"},
        {pos: [4, 1, 1], state: "minecraft:cracked_stone_bricks"},
        {pos: [4, 1, 2], state: "minecraft:mud_bricks"},
        {pos: [4, 1, 3], state: "minecraft:sand"},
        {pos: [4, 1, 4], state: "minecraft:mud_bricks"},
        {pos: [4, 1, 5], state: "minecraft:cracked_stone_bricks"},
        {pos: [4, 1, 6], state: "minecraft:stone_bricks"},
        {pos: [5, 1, 0], state: "minecraft:mud_bricks"},
        {pos: [5, 1, 1], state: "minecraft:mud_bricks"},
        {pos: [5, 1, 2], state: "minecraft:cracked_stone_bricks"},
        {pos: [5, 1, 3], state: "minecraft:stone_bricks"},
        {pos: [5, 1, 4], state: "minecraft:cracked_stone_bricks"},
        {pos: [5, 1, 5], state: "minecraft:mud_bricks"},
        {pos: [5, 1, 6], state: "minecraft:mud_bricks"},
        {pos: [6, 1, 1], state: "minecraft:mud_bricks"},
        {pos: [6, 1, 2], state: "minecraft:stone_bricks"},
        {pos: [6, 1, 3], state: "minecraft:jigsaw{orientation:east_up}", nbt: {final_state: "minecraft:cobblestone", id: "minecraft:jigsaw", joint: "rollable", name: "minecraft:road_connector", pool: "minecraft:trail_ruins/roads", target: "minecraft:road_spacer"}},
        {pos: [6, 1, 4], state: "minecraft:stone_bricks"},
        {pos: [6, 1, 5], state: "minecraft:mud_bricks"},
        {pos: [0, 2, 1], state: "minecraft:mud_bricks"},
        {pos: [0, 2, 2], state: "minecraft:sand"},
        {pos: [0, 2, 3], state: "minecraft:sand"},
        {pos: [0, 2, 4], state: "minecraft:sand"},
        {pos: [0, 2, 5], state: "minecraft:mud_bricks"},
        {pos: [1, 2, 0], state: "minecraft:mud_bricks"},
        {pos: [1, 2, 1], state: "minecraft:sand"},
        {pos: [1, 2, 3], state: "minecraft:sand"},
        {pos: [1, 2, 4], state: "minecraft:sand"},
        {pos: [1, 2, 5], state: "minecraft:cyan_terracotta"},
        {pos: [1, 2, 6], state: "minecraft:cyan_terracotta"},
        {pos: [2, 2, 0], state: "minecraft:mud_brick_stairs{facing:north,half:bottom,shape:straight,waterlogged:false}"},
        {pos: [2, 2, 1], state: "minecraft:sand"},
        {pos: [2, 2, 2], state: "minecraft:sand"},
        {pos: [2, 2, 3], state: "minecraft:sand"},
        {pos: [2, 2, 4], state: "minecraft:sand"},
        {pos: [2, 2, 5], state: "minecraft:sand"},
        {pos: [2, 2, 6], state: "minecraft:sand"},
        {pos: [3, 2, 0], state: "minecraft:sand"},
        {pos: [3, 2, 1], state: "minecraft:cyan_terracotta"},
        {pos: [3, 2, 2], state: "minecraft:sand"},
        {pos: [3, 2, 3], state: "minecraft:sand"},
        {pos: [3, 2, 4], state: "minecraft:sand"},
        {pos: [3, 2, 5], state: "minecraft:sand"},
        {pos: [3, 2, 6], state: "minecraft:sand"},
        {pos: [4, 2, 0], state: "minecraft:sand"},
        {pos: [4, 2, 1], state: "minecraft:sand"},
        {pos: [4, 2, 2], state: "minecraft:sand"},
        {pos: [4, 2, 3], state: "minecraft:sand"},
        {pos: [4, 2, 4], state: "minecraft:sand"},
        {pos: [4, 2, 6], state: "minecraft:sand"},
        {pos: [5, 2, 0], state: "minecraft:sand"},
        {pos: [5, 2, 1], state: "minecraft:sand"},
        {pos: [5, 2, 3], state: "minecraft:sand"},
        {pos: [5, 2, 4], state: "minecraft:sand"},
        {pos: [5, 2, 5], state: "minecraft:sand"},
        {pos: [5, 2, 6], state: "minecraft:mud_bricks"},
        {pos: [6, 2, 1], state: "minecraft:mud_bricks"},
        {pos: [6, 2, 2], state: "minecraft:mud_brick_stairs{facing:west,half:bottom,shape:straight,waterlogged:false}"},
        {pos: [6, 2, 3], state: "minecraft:sand"},
        {pos: [6, 2, 4], state: "minecraft:sand"},
        {pos: [6, 2, 5], state: "minecraft:mud_bricks"},
        {pos: [0, 3, 1], state: "minecraft:mud_bricks"},
        {pos: [0, 3, 2], state: "minecraft:sand"},
        {pos: [0, 3, 3], state: "minecraft:sand"},
        {pos: [0, 3, 4], state: "minecraft:sand"},
        {pos: [0, 3, 5], state: "minecraft:mud_bricks"},
        {pos: [1, 3, 0], state: "minecraft:mud_bricks"},
        {pos: [1, 3, 1], state: "minecraft:sand"},
        {pos: [1, 3, 3], state: "minecraft:sand"},
        {pos: [1, 3, 4], state: "minecraft:sand"},
        {pos: [1, 3, 5], state: "minecraft:white_terracotta"},
        {pos: [1, 3, 6], state: "minecraft:cyan_terracotta"},
        {pos: [2, 3, 0], state: "minecraft:sand"},
        {pos: [2, 3, 1], state: "minecraft:sand"},
        {pos: [2, 3, 2], state: "minecraft:sand"},
        {pos: [2, 3, 3], state: "minecraft:sand"},
        {pos: [2, 3, 4], state: "minecraft:sand"},
        {pos: [2, 3, 5], state: "minecraft:sand"},
        {pos: [2, 3, 6], state: "minecraft:sand"},
        {pos: [3, 3, 0], state: "minecraft:sand"},
        {pos: [3, 3, 1], state: "minecraft:sand"},
        {pos: [3, 3, 2], state: "minecraft:sand"},
        {pos: [3, 3, 3], state: "minecraft:sand"},
        {pos: [3, 3, 4], state: "minecraft:sand"},
        {pos: [3, 3, 5], state: "minecraft:sand"},
        {pos: [3, 3, 6], state: "minecraft:sand"},
        {pos: [4, 3, 0], state: "minecraft:sand"},
        {pos: [4, 3, 6], state: "minecraft:sand"},
        {pos: [5, 3, 0], state: "minecraft:sand"},
        {pos: [5, 3, 3], state: "minecraft:sand"},
        {pos: [5, 3, 4], state: "minecraft:sand"},
        {pos: [5, 3, 6], state: "minecraft:mud_bricks"},
        {pos: [6, 3, 1], state: "minecraft:mud_bricks"},
        {pos: [6, 3, 2], state: "minecraft:sand"},
        {pos: [6, 3, 3], state: "minecraft:sand"},
        {pos: [6, 3, 4], state: "minecraft:sand"},
        {pos: [6, 3, 5], state: "minecraft:mud_bricks"},
        {pos: [0, 4, 1], state: "minecraft:mud_bricks"},
        {pos: [0, 4, 2], state: "minecraft:mud_brick_stairs{facing:north,half:top,shape:straight,waterlogged:false}"},
        {pos: [0, 4, 4], state: "minecraft:mud_brick_stairs{facing:south,half:top,shape:straight,waterlogged:false}"},
        {pos: [0, 4, 5], state: "minecraft:orange_terracotta"},
        {pos: [1, 4, 0], state: "minecraft:mud_bricks"},
        {pos: [1, 4, 4], state: "minecraft:sand"},
        {pos: [1, 4, 5], state: "minecraft:sand"},
        {pos: [1, 4, 6], state: "minecraft:white_terracotta"},
        {pos: [2, 4, 0], state: "minecraft:sand"},
        {pos: [2, 4, 1], state: "minecraft:sand"},
        {pos: [2, 4, 2], state: "minecraft:cyan_terracotta"},
        {pos: [2, 4, 3], state: "minecraft:sand"},
        {pos: [2, 4, 4], state: "minecraft:sand"},
        {pos: [2, 4, 5], state: "minecraft:sand"},
        {pos: [2, 4, 6], state: "minecraft:mud_brick_stairs{facing:west,half:top,shape:straight,waterlogged:false}"},
        {pos: [3, 4, 0], state: "minecraft:sand"},
        {pos: [3, 4, 1], state: "minecraft:sand"},
        {pos: [3, 4, 4], state: "minecraft:sand"},
        {pos: [3, 4, 6], state: "minecraft:sand"},
        {pos: [4, 4, 0], state: "minecraft:sand"},
        {pos: [4, 4, 6], state: "minecraft:mud_brick_stairs{facing:east,half:top,shape:straight,waterlogged:false}"},
        {pos: [5, 4, 0], state: "minecraft:mud_bricks"},
        {pos: [5, 4, 3], state: "minecraft:sand"},
        {pos: [5, 4, 4], state: "minecraft:sand"},
        {pos: [5, 4, 6], state: "minecraft:mud_bricks"},
        {pos: [6, 4, 1], state: "minecraft:mud_bricks"},
        {pos: [6, 4, 2], state: "minecraft:mud_brick_stairs{facing:north,half:top,shape:straight,waterlogged:false}"},
        {pos: [6, 4, 3], state: "minecraft:sand"},
        {pos: [6, 4, 4], state: "minecraft:sand"},
        {pos: [6, 4, 5], state: "minecraft:mud_bricks"},
        {pos: [0, 5, 1], state: "minecraft:cyan_terracotta"},
        {pos: [0, 5, 2], state: "minecraft:mud_bricks"},
        {pos: [0, 5, 3], state: "minecraft:mud_bricks"},
        {pos: [0, 5, 4], state: "minecraft:mud_bricks"},
        {pos: [0, 5, 5], state: "minecraft:sand"},
        {pos: [1, 5, 0], state: "minecraft:cyan_terracotta"},
        {pos: [1, 5, 3], state: "minecraft:mud_brick_stairs{facing:west,half:top,shape:straight,waterlogged:false}"},
        {pos: [1, 5, 4], state: "minecraft:mud_brick_stairs{facing:west,half:top,shape:straight,waterlogged:false}"},
        {pos: [1, 5, 5], state: "minecraft:sand"},
        {pos: [1, 5, 6], state: "minecraft:sand"},
        {pos: [2, 5, 1], state: "minecraft:sand"},
        {pos: [2, 5, 2], state: "minecraft:sand"},
        {pos: [2, 5, 5], state: "minecraft:mud_brick_stairs{facing:south,half:top,shape:straight,waterlogged:false}"},
        {pos: [2, 5, 6], state: "minecraft:mud_bricks"},
        {pos: [3, 5, 0], state: "minecraft:sand"},
        {pos: [3, 5, 1], state: "minecraft:sand"},
        {pos: [3, 5, 4], state: "minecraft:sand"},
        {pos: [3, 5, 5], state: "minecraft:mud_brick_stairs{facing:south,half:top,shape:straight,waterlogged:false}"},
        {pos: [3, 5, 6], state: "minecraft:mud_bricks"},
        {pos: [4, 5, 0], state: "minecraft:mud_brick_stairs{facing:east,half:top,shape:straight,waterlogged:false}"},
        {pos: [4, 5, 1], state: "minecraft:mud_brick_stairs{facing:north,half:top,shape:outer_right,waterlogged:false}"},
        {pos: [4, 5, 5], state: "minecraft:mud_brick_stairs{facing:south,half:top,shape:straight,waterlogged:false}"},
        {pos: [4, 5, 6], state: "minecraft:mud_bricks"},
        {pos: [5, 5, 0], state: "minecraft:cyan_terracotta"},
        {pos: [5, 5, 1], state: "minecraft:mud_brick_stairs{facing:north,half:top,shape:inner_right,waterlogged:false}"},
        {pos: [5, 5, 2], state: "minecraft:mud_brick_stairs{facing:east,half:top,shape:straight,waterlogged:false}"},
        {pos: [5, 5, 3], state: "minecraft:mud_brick_stairs{facing:east,half:top,shape:straight,waterlogged:false}"},
        {pos: [5, 5, 4], state: "minecraft:mud_brick_stairs{facing:east,half:top,shape:straight,waterlogged:false}"},
        {pos: [5, 5, 5], state: "minecraft:mud_brick_stairs{facing:east,half:top,shape:inner_right,waterlogged:false}"},
        {pos: [5, 5, 6], state: "minecraft:cyan_terracotta"},
        {pos: [6, 5, 1], state: "minecraft:cyan_terracotta"},
        {pos: [6, 5, 2], state: "minecraft:mud_bricks"},
        {pos: [6, 5, 3], state: "minecraft:mud_bricks"},
        {pos: [6, 5, 4], state: "minecraft:mud_bricks"},
        {pos: [6, 5, 5], state: "minecraft:cyan_terracotta"},
        {pos: [0, 6, 1], state: "minecraft:cyan_terracotta"},
        {pos: [0, 6, 2], state: "minecraft:cyan_terracotta"},
        {pos: [0, 6, 3], state: "minecraft:cyan_terracotta"},
        {pos: [0, 6, 5], state: "minecraft:sand"},
        {pos: [1, 6, 0], state: "minecraft:cyan_terracotta"},
        {pos: [1, 6, 1], state: "minecraft:cyan_terracotta"},
        {pos: [1, 6, 2], state: "minecraft:cyan_terracotta"},
        {pos: [1, 6, 3], state: "minecraft:cyan_terracotta"},
        {pos: [1, 6, 4], state: "minecraft:cyan_terracotta"},
        {pos: [1, 6, 5], state: "minecraft:sand"},
        {pos: [1, 6, 6], state: "minecraft:sand"},
        {pos: [2, 6, 0], state: "minecraft:cyan_terracotta"},
        {pos: [2, 6, 1], state: "minecraft:cyan_terracotta"},
        {pos: [2, 6, 2], state: "minecraft:sand"},
        {pos: [2, 6, 3], state: "minecraft:orange_glazed_terracotta{facing:north}"},
        {pos: [2, 6, 4], state: "minecraft:orange_glazed_terracotta{facing:north}"},
        {pos: [2, 6, 5], state: "minecraft:cyan_terracotta"},
        {pos: [2, 6, 6], state: "minecraft:sand"},
        {pos: [3, 6, 0], state: "minecraft:cyan_terracotta"},
        {pos: [3, 6, 1], state: "minecraft:cyan_terracotta"},
        {pos: [3, 6, 3], state: "minecraft:mud_bricks"},
        {pos: [3, 6, 4], state: "minecraft:orange_glazed_terracotta{facing:west}"},
        {pos: [3, 6, 5], state: "minecraft:cyan_terracotta"},
        {pos: [3, 6, 6], state: "minecraft:cyan_terracotta"},
        {pos: [4, 6, 0], state: "minecraft:cyan_terracotta"},
        {pos: [4, 6, 1], state: "minecraft:cyan_terracotta"},
        {pos: [4, 6, 2], state: "minecraft:orange_glazed_terracotta{facing:south}"},
        {pos: [4, 6, 3], state: "minecraft:orange_glazed_terracotta{facing:south}"},
        {pos: [4, 6, 4], state: "minecraft:orange_glazed_terracotta{facing:west}"},
        {pos: [4, 6, 5], state: "minecraft:cyan_terracotta"},
        {pos: [4, 6, 6], state: "minecraft:cyan_terracotta"},
        {pos: [5, 6, 0], state: "minecraft:cyan_terracotta"},
        {pos: [5, 6, 1], state: "minecraft:cyan_terracotta"},
        {pos: [5, 6, 2], state: "minecraft:cyan_terracotta"},
        {pos: [5, 6, 3], state: "minecraft:cyan_terracotta"},
        {pos: [5, 6, 4], state: "minecraft:cyan_terracotta"},
        {pos: [5, 6, 5], state: "minecraft:cyan_terracotta"},
        {pos: [5, 6, 6], state: "minecraft:cyan_terracotta"},
        {pos: [6, 6, 1], state: "minecraft:cyan_terracotta"},
        {pos: [6, 6, 2], state: "minecraft:cyan_terracotta"},
        {pos: [6, 6, 3], state: "minecraft:cyan_terracotta"},
        {pos: [6, 6, 4], state: "minecraft:cyan_terracotta"},
        {pos: [6, 6, 5], state: "minecraft:cyan_terracotta"},
        {pos: [0, 7, 1], state: "minecraft:sand"},
        {pos: [0, 7, 2], state: "minecraft:orange_glazed_terracotta{facing:west}"},
        {pos: [0, 7, 3], state: "minecraft:yellow_terracotta"},
        {pos: [0, 7, 4], state: "minecraft:orange_glazed_terracotta{facing:north}"},
        {pos: [0, 7, 5], state: "minecraft:sand"},
        {pos: [1, 7, 0], state: "minecraft:sand"},
        {pos: [1, 7, 1], state: "minecraft:cyan_terracotta"},
        {pos: [1, 7, 2], state: "minecraft:cyan_terracotta"},
        {pos: [1, 7, 3], state: "minecraft:cyan_terracotta"},
        {pos: [1, 7, 4], state: "minecraft:cyan_terracotta"},
        {pos: [1, 7, 5], state: "minecraft:sand"},
        {pos: [1, 7, 6], state: "minecraft:sand"},
        {pos: [2, 7, 0], state: "minecraft:orange_glazed_terracotta{facing:east}"},
        {pos: [2, 7, 1], state: "minecraft:cyan_terracotta"},
        {pos: [2, 7, 2], state: "minecraft:sand"},
        {pos: [2, 7, 3], state: "minecraft:mud_brick_slab{type:top,waterlogged:false}"},
        {pos: [2, 7, 4], state: "minecraft:sand"},
        {pos: [2, 7, 5], state: "minecraft:cyan_terracotta"},
        {pos: [2, 7, 6], state: "minecraft:sand"},
        {pos: [3, 7, 0], state: "minecraft:orange_terracotta"},
        {pos: [3, 7, 1], state: "minecraft:cyan_terracotta"},
        {pos: [3, 7, 3], state: "minecraft:sand"},
        {pos: [3, 7, 4], state: "minecraft:sand"},
        {pos: [3, 7, 5], state: "minecraft:sand"},
        {pos: [3, 7, 6], state: "minecraft:sand"},
        {pos: [4, 7, 0], state: "minecraft:orange_glazed_terracotta{facing:north}"},
        {pos: [4, 7, 1], state: "minecraft:cyan_terracotta"},
        {pos: [4, 7, 2], state: "minecraft:sand"},
        {pos: [4, 7, 4], state: "minecraft:sand"},
        {pos: [4, 7, 5], state: "minecraft:cyan_terracotta"},
        {pos: [4, 7, 6], state: "minecraft:orange_glazed_terracotta{facing:west}"},
        {pos: [5, 7, 0], state: "minecraft:orange_glazed_terracotta{facing:east}"},
        {pos: [5, 7, 1], state: "minecraft:cyan_terracotta"},
        {pos: [5, 7, 2], state: "minecraft:cyan_terracotta"},
        {pos: [5, 7, 3], state: "minecraft:cyan_terracotta"},
        {pos: [5, 7, 4], state: "minecraft:cyan_terracotta"},
        {pos: [5, 7, 5], state: "minecraft:cyan_terracotta"},
        {pos: [5, 7, 6], state: "minecraft:orange_glazed_terracotta{facing:south}"},
        {pos: [6, 7, 1], state: "minecraft:orange_glazed_terracotta{facing:east}"},
        {pos: [6, 7, 2], state: "minecraft:orange_glazed_terracotta{facing:south}"},
        {pos: [6, 7, 3], state: "minecraft:orange_terracotta"},
        {pos: [6, 7, 4], state: "minecraft:orange_glazed_terracotta{facing:east}"},
        {pos: [6, 7, 5], state: "minecraft:orange_glazed_terracotta{facing:south}"},
        {pos: [0, 8, 1], state: "minecraft:sand"},
        {pos: [0, 8, 2], state: "minecraft:sand"},
        {pos: [0, 8, 3], state: "minecraft:sand"},
        {pos: [0, 8, 4], state: "minecraft:sand"},
        {pos: [0, 8, 5], state: "minecraft:sand"},
        {pos: [1, 8, 0], state: "minecraft:sand"},
        {pos: [1, 8, 1], state: "minecraft:sand"},
        {pos: [1, 8, 2], state: "minecraft:sand"},
        {pos: [1, 8, 3], state: "minecraft:sand"},
        {pos: [1, 8, 4], state: "minecraft:sand"},
        {pos: [1, 8, 5], state: "minecraft:sand"},
        {pos: [1, 8, 6], state: "minecraft:sand"},
        {pos: [2, 8, 0], state: "minecraft:sand"},
        {pos: [2, 8, 2], state: "minecraft:sand"},
        {pos: [2, 8, 3], state: "minecraft:sand"},
        {pos: [2, 8, 4], state: "minecraft:sand"},
        {pos: [2, 8, 5], state: "minecraft:yellow_terracotta"},
        {pos: [2, 8, 6], state: "minecraft:sand"},
        {pos: [3, 8, 0], state: "minecraft:orange_terracotta"},
        {pos: [3, 8, 2], state: "minecraft:mud_brick_slab{type:top,waterlogged:false}"},
        {pos: [3, 8, 3], state: "minecraft:sand"},
        {pos: [3, 8, 4], state: "minecraft:sand"},
        {pos: [3, 8, 5], state: "minecraft:sand"},
        {pos: [3, 8, 6], state: "minecraft:sand"},
        {pos: [4, 8, 0], state: "minecraft:mud_brick_slab{type:bottom,waterlogged:false}"},
        {pos: [4, 8, 1], state: "minecraft:yellow_terracotta"},
        {pos: [4, 8, 2], state: "minecraft:sand"},
        {pos: [4, 8, 4], state: "minecraft:sand"},
        {pos: [4, 8, 5], state: "minecraft:yellow_terracotta"},
        {pos: [4, 8, 6], state: "minecraft:mud_brick_slab{type:bottom,waterlogged:false}"},
        {pos: [5, 8, 0], state: "minecraft:mud_brick_slab{type:bottom,waterlogged:false}"},
        {pos: [5, 8, 1], state: "minecraft:yellow_terracotta"},
        {pos: [5, 8, 2], state: "minecraft:yellow_terracotta"},
        {pos: [5, 8, 3], state: "minecraft:yellow_terracotta"},
        {pos: [5, 8, 4], state: "minecraft:yellow_terracotta"},
        {pos: [5, 8, 5], state: "minecraft:yellow_terracotta"},
        {pos: [5, 8, 6], state: "minecraft:mud_brick_slab{type:bottom,waterlogged:false}"},
        {pos: [6, 8, 1], state: "minecraft:mud_brick_slab{type:bottom,waterlogged:false}"},
        {pos: [6, 8, 2], state: "minecraft:mud_brick_slab{type:bottom,waterlogged:false}"},
        {pos: [6, 8, 3], state: "minecraft:orange_terracotta"},
        {pos: [6, 8, 4], state: "minecraft:mud_brick_slab{type:bottom,waterlogged:false}"},
        {pos: [6, 8, 5], state: "minecraft:mud_brick_slab{type:bottom,waterlogged:false}"},
        {pos: [0, 9, 1], state: "minecraft:sand"},
        {pos: [0, 9, 2], state: "minecraft:sand"},
        {pos: [0, 9, 3], state: "minecraft:sand"},
        {pos: [0, 9, 4], state: "minecraft:sand"},
        {pos: [0, 9, 5], state: "minecraft:sand"},
        {pos: [1, 9, 0], state: "minecraft:sand"},
        {pos: [1, 9, 1], state: "minecraft:sand"},
        {pos: [1, 9, 2], state: "minecraft:sand"},
        {pos: [1, 9, 3], state: "minecraft:sand"},
        {pos: [1, 9, 4], state: "minecraft:sand"},
        {pos: [1, 9, 5], state: "minecraft:cyan_terracotta"},
        {pos: [1, 9, 6], state: "minecraft:sand"},
        {pos: [2, 9, 0], state: "minecraft:sand"},
        {pos: [2, 9, 1], state: "minecraft:cyan_terracotta"},
        {pos: [2, 9, 3], state: "minecraft:sand"},
        {pos: [2, 9, 4], state: "minecraft:sand"},
        {pos: [2, 9, 5], state: "minecraft:cyan_terracotta"},
        {pos: [2, 9, 6], state: "minecraft:sand"},
        {pos: [3, 9, 0], state: "minecraft:mud_brick_slab{type:bottom,waterlogged:false}"},
        {pos: [3, 9, 1], state: "minecraft:yellow_terracotta"},
        {pos: [3, 9, 2], state: "minecraft:sand"},
        {pos: [3, 9, 3], state: "minecraft:sand"},
        {pos: [3, 9, 5], state: "minecraft:yellow_terracotta"},
        {pos: [3, 9, 6], state: "minecraft:sand"},
        {pos: [4, 9, 0], state: "minecraft:sand"},
        {pos: [4, 9, 1], state: "minecraft:sand"},
        {pos: [4, 9, 2], state: "minecraft:sand"},
        {pos: [4, 9, 3], state: "minecraft:mud_brick_slab{type:top,waterlogged:false}"},
        {pos: [4, 9, 4], state: "minecraft:sand"},
        {pos: [4, 9, 5], state: "minecraft:cyan_terracotta"},
        {pos: [4, 9, 6], state: "minecraft:sand"},
        {pos: [5, 9, 0], state: "minecraft:sand"},
        {pos: [5, 9, 1], state: "minecraft:cyan_terracotta"},
        {pos: [5, 9, 2], state: "minecraft:cyan_terracotta"},
        {pos: [5, 9, 3], state: "minecraft:yellow_terracotta"},
        {pos: [5, 9, 4], state: "minecraft:cyan_terracotta"},
        {pos: [5, 9, 5], state: "minecraft:cyan_terracotta"},
        {pos: [5, 9, 6], state: "minecraft:sand"},
        {pos: [6, 9, 1], state: "minecraft:sand"},
        {pos: [6, 9, 2], state: "minecraft:sand"},
        {pos: [6, 9, 3], state: "minecraft:mud_brick_slab{type:bottom,waterlogged:false}"},
        {pos: [6, 9, 4], state: "minecraft:sand"},
        {pos: [6, 9, 5], state: "minecraft:sand"},
        {pos: [0, 10, 1], state: "minecraft:sand"},
        {pos: [0, 10, 2], state: "minecraft:sand"},
        {pos: [0, 10, 3], state: "minecraft:sand"},
        {pos: [0, 10, 4], state: "minecraft:sand"},
        {pos: [0, 10, 5], state: "minecraft:sand"},
        {pos: [1, 10, 1], state: "minecraft:sand"},
        {pos: [1, 10, 2], state: "minecraft:sand"},
        {pos: [1, 10, 3], state: "minecraft:sand"},
        {pos: [1, 10, 4], state: "minecraft:sand"},
        {pos: [1, 10, 5], state: "minecraft:sand"},
        {pos: [1, 10, 6], state: "minecraft:sand"},
        {pos: [2, 10, 1], state: "minecraft:sand"},
        {pos: [2, 10, 3], state: "minecraft:sand"},
        {pos: [2, 10, 4], state: "minecraft:sand"},
        {pos: [2, 10, 5], state: "minecraft:cyan_terracotta"},
        {pos: [2, 10, 6], state: "minecraft:sand"},
        {pos: [3, 10, 0], state: "minecraft:sand"},
        {pos: [3, 10, 1], state: "minecraft:sand"},
        {pos: [3, 10, 2], state: "minecraft:sand"},
        {pos: [3, 10, 3], state: "minecraft:sand"},
        {pos: [3, 10, 4], state: "minecraft:mud_brick_slab{type:top,waterlogged:false}"},
        {pos: [3, 10, 5], state: "minecraft:yellow_terracotta"},
        {pos: [3, 10, 6], state: "minecraft:sand"},
        {pos: [4, 10, 0], state: "minecraft:sand"},
        {pos: [4, 10, 1], state: "minecraft:cyan_terracotta"},
        {pos: [4, 10, 2], state: "minecraft:sand"},
        {pos: [4, 10, 3], state: "minecraft:sand"},
        {pos: [4, 10, 4], state: "minecraft:sand"},
        {pos: [4, 10, 5], state: "minecraft:cyan_terracotta"},
        {pos: [4, 10, 6], state: "minecraft:sand"},
        {pos: [5, 10, 2], state: "minecraft:cyan_terracotta"},
        {pos: [5, 10, 3], state: "minecraft:yellow_terracotta"},
        {pos: [5, 10, 4], state: "minecraft:cyan_terracotta"},
        {pos: [5, 10, 5], state: "minecraft:orange_terracotta"},
        {pos: [5, 10, 6], state: "minecraft:sand"},
        {pos: [6, 10, 4], state: "minecraft:sand"},
        {pos: [6, 10, 5], state: "minecraft:sand"},
        {pos: [0, 11, 2], state: "minecraft:sand"},
        {pos: [0, 11, 3], state: "minecraft:sand"},
        {pos: [0, 11, 4], state: "minecraft:sand"},
        {pos: [1, 11, 1], state: "minecraft:sand"},
        {pos: [1, 11, 2], state: "minecraft:sand"},
        {pos: [1, 11, 3], state: "minecraft:sand"},
        {pos: [1, 11, 4], state: "minecraft:sand"},
        {pos: [1, 11, 5], state: "minecraft:white_terracotta"},
        {pos: [1, 11, 6], state: "minecraft:sand"},
        {pos: [2, 11, 1], state: "minecraft:cyan_terracotta"},
        {pos: [2, 11, 3], state: "minecraft:sand"},
        {pos: [2, 11, 4], state: "minecraft:sand"},
        {pos: [2, 11, 5], state: "minecraft:white_terracotta"},
        {pos: [2, 11, 6], state: "minecraft:sand"},
        {pos: [3, 11, 0], state: "minecraft:sand"},
        {pos: [3, 11, 1], state: "minecraft:mud_brick_slab{type:bottom,waterlogged:false}"},
        {pos: [3, 11, 2], state: "minecraft:sand"},
        {pos: [3, 11, 3], state: "minecraft:sand"},
        {pos: [3, 11, 4], state: "minecraft:sand"},
        {pos: [3, 11, 5], state: "minecraft:mud_brick_slab{type:bottom,waterlogged:false}"},
        {pos: [3, 11, 6], state: "minecraft:sand"},
        {pos: [4, 11, 0], state: "minecraft:sand"},
        {pos: [4, 11, 2], state: "minecraft:sand"},
        {pos: [4, 11, 3], state: "minecraft:sand"},
        {pos: [4, 11, 4], state: "minecraft:sand"},
        {pos: [4, 11, 5], state: "minecraft:cyan_terracotta"},
        {pos: [5, 11, 2], state: "minecraft:cyan_terracotta"},
        {pos: [5, 11, 3], state: "minecraft:sand"},
        {pos: [5, 11, 4], state: "minecraft:cyan_terracotta"},
        {pos: [5, 11, 5], state: "minecraft:cyan_terracotta"},
        {pos: [5, 11, 6], state: "minecraft:sand"},
        {pos: [0, 12, 3], state: "minecraft:sand"},
        {pos: [0, 12, 4], state: "minecraft:sand"},
        {pos: [1, 12, 1], state: "minecraft:sand"},
        {pos: [1, 12, 4], state: "minecraft:sand"},
        {pos: [1, 12, 5], state: "minecraft:sand"},
        {pos: [2, 12, 1], state: "minecraft:white_glazed_terracotta{facing:east}"},
        {pos: [2, 12, 2], state: "minecraft:mud_brick_slab{type:top,waterlogged:false}"},
        {pos: [2, 12, 3], state: "minecraft:sand"},
        {pos: [2, 12, 4], state: "minecraft:sand"},
        {pos: [2, 12, 6], state: "minecraft:sand"},
        {pos: [3, 12, 2], state: "minecraft:sand"},
        {pos: [3, 12, 3], state: "minecraft:sand"},
        {pos: [3, 12, 6], state: "minecraft:sand"},
        {pos: [4, 12, 0], state: "minecraft:sand"},
        {pos: [4, 12, 1], state: "minecraft:white_glazed_terracotta{facing:north}"},
        {pos: [4, 12, 2], state: "minecraft:sand"},
        {pos: [4, 12, 3], state: "minecraft:sand"},
        {pos: [4, 12, 4], state: "minecraft:sand"},
        {pos: [4, 12, 5], state: "minecraft:white_glazed_terracotta{facing:west}"},
        {pos: [5, 12, 1], state: "minecraft:white_glazed_terracotta{facing:east}"},
        {pos: [5, 12, 2], state: "minecraft:white_glazed_terracotta{facing:south}"},
        {pos: [5, 12, 3], state: "minecraft:sand"},
        {pos: [5, 12, 4], state: "minecraft:white_glazed_terracotta{facing:east}"},
        {pos: [5, 12, 5], state: "minecraft:white_glazed_terracotta{facing:south}"},
        {pos: [0, 13, 3], state: "minecraft:sand"},
        {pos: [0, 13, 4], state: "minecraft:sand"},
        {pos: [1, 13, 1], state: "minecraft:light_blue_terracotta"},
        {pos: [1, 13, 2], state: "minecraft:white_terracotta"},
        {pos: [1, 13, 3], state: "minecraft:mud_brick_slab{type:top,waterlogged:false}"},
        {pos: [1, 13, 4], state: "minecraft:sand"},
        {pos: [2, 13, 1], state: "minecraft:white_terracotta"},
        {pos: [2, 13, 3], state: "minecraft:sand"},
        {pos: [2, 13, 4], state: "minecraft:sand"},
        {pos: [3, 13, 1], state: "minecraft:mud_brick_slab{type:top,waterlogged:false}"},
        {pos: [3, 13, 2], state: "minecraft:sand"},
        {pos: [3, 13, 5], state: "minecraft:mud_brick_slab{type:top,waterlogged:false}"},
        {pos: [4, 13, 1], state: "minecraft:white_terracotta"},
        {pos: [4, 13, 2], state: "minecraft:mud_brick_slab{type:top,waterlogged:false}"},
        {pos: [4, 13, 3], state: "minecraft:sand"},
        {pos: [4, 13, 4], state: "minecraft:sand"},
        {pos: [4, 13, 5], state: "minecraft:white_terracotta"},
        {pos: [5, 13, 1], state: "minecraft:light_blue_terracotta"},
        {pos: [5, 13, 2], state: "minecraft:white_terracotta"},
        {pos: [5, 13, 3], state: "minecraft:mud_brick_slab{type:top,waterlogged:false}"},
        {pos: [5, 13, 4], state: "minecraft:white_terracotta"},
        {pos: [5, 13, 5], state: "minecraft:light_blue_terracotta"},
        {pos: [1, 14, 1], state: "minecraft:sand"},
        {pos: [1, 14, 3], state: "minecraft:yellow_terracotta"},
        {pos: [2, 14, 1], state: "minecraft:white_terracotta"},
        {pos: [2, 14, 4], state: "minecraft:sand"},
        {pos: [3, 14, 1], state: "minecraft:yellow_terracotta"},
        {pos: [3, 14, 2], state: "minecraft:sand"},
        {pos: [3, 14, 3], state: "minecraft:mud_brick_slab{type:top,waterlogged:false}"},
        {pos: [3, 14, 4], state: "minecraft:mud_brick_slab{type:top,waterlogged:false}"},
        {pos: [3, 14, 5], state: "minecraft:sand"},
        {pos: [4, 14, 1], state: "minecraft:white_terracotta"},
        {pos: [4, 14, 2], state: "minecraft:sand"},
        {pos: [4, 14, 3], state: "minecraft:mud_brick_slab{type:top,waterlogged:false}"},
        {pos: [4, 14, 4], state: "minecraft:mud_brick_slab{type:top,waterlogged:false}"},
        {pos: [4, 14, 5], state: "minecraft:white_terracotta"},
        {pos: [5, 14, 1], state: "minecraft:light_blue_terracotta"},
        {pos: [5, 14, 2], state: "minecraft:white_terracotta"},
        {pos: [5, 14, 3], state: "minecraft:yellow_terracotta"},
        {pos: [5, 14, 4], state: "minecraft:white_terracotta"},
        {pos: [5, 14, 5], state: "minecraft:light_blue_terracotta"},
        {pos: [3, 15, 2], state: "minecraft:sand"},
        {pos: [3, 15, 3], state: "minecraft:sand"},
        {pos: [4, 15, 1], state: "minecraft:yellow_terracotta"},
        {pos: [4, 15, 2], state: "minecraft:sand"},
        {pos: [4, 15, 3], state: "minecraft:sand"},
        {pos: [4, 15, 5], state: "minecraft:yellow_terracotta"},
        {pos: [5, 15, 1], state: "minecraft:white_terracotta"},
        {pos: [5, 15, 2], state: "minecraft:yellow_terracotta"},
        {pos: [5, 15, 4], state: "minecraft:yellow_terracotta"},
        {pos: [5, 15, 5], state: "minecraft:white_terracotta"},
        {pos: [4, 16, 1], state: "minecraft:sand"},
        {pos: [5, 16, 0], state: "minecraft:air"},
        {pos: [5, 16, 1], state: "minecraft:yellow_terracotta"},
        {pos: [5, 16, 2], state: "minecraft:sand"},
        {pos: [5, 16, 5], state: "minecraft:yellow_terracotta"},
        {pos: [6, 16, 0], state: "minecraft:air"},
        {pos: [6, 16, 1], state: "minecraft:air"},
        {pos: [6, 16, 2], state: "minecraft:air"}
    ],
    entities: [],
    palette: [
        "minecraft:mud_bricks",
        "minecraft:stone_bricks",
        "minecraft:cracked_stone_bricks",
        "minecraft:sand",
        "minecraft:cyan_terracotta",
        "minecraft:white_terracotta",
        "minecraft:orange_terracotta",
        "minecraft:orange_glazed_terracotta{facing:north}",
        "minecraft:orange_glazed_terracotta{facing:west}",
        "minecraft:orange_glazed_terracotta{facing:south}",
        "minecraft:yellow_terracotta",
        "minecraft:orange_glazed_terracotta{facing:east}",
        "minecraft:white_glazed_terracotta{facing:east}",
        "minecraft:white_glazed_terracotta{facing:north}",
        "minecraft:white_glazed_terracotta{facing:west}",
        "minecraft:white_glazed_terracotta{facing:south}",
        "minecraft:light_blue_terracotta",
        "minecraft:mud_brick_stairs{facing:north,half:bottom,shape:straight,waterlogged:false}",
        "minecraft:mud_brick_stairs{facing:west,half:bottom,shape:straight,waterlogged:false}",
        "minecraft:mud_brick_stairs{facing:north,half:top,shape:straight,waterlogged:false}",
        "minecraft:mud_brick_stairs{facing:south,half:top,shape:straight,waterlogged:false}",
        "minecraft:mud_brick_stairs{facing:west,half:top,shape:straight,waterlogged:false}",
        "minecraft:mud_brick_stairs{facing:east,half:top,shape:straight,waterlogged:false}",
        "minecraft:mud_brick_stairs{facing:north,half:top,shape:outer_right,waterlogged:false}",
        "minecraft:mud_brick_stairs{facing:north,half:top,shape:inner_right,waterlogged:false}",
        "minecraft:mud_brick_stairs{facing:east,half:top,shape:inner_right,waterlogged:false}",
        "minecraft:mud_brick_slab{type:top,waterlogged:false}",
        "minecraft:mud_brick_slab{type:bottom,waterlogged:false}",
        "minecraft:air",
        "minecraft:jigsaw{orientation:west_up}",
        "minecraft:jigsaw{orientation:north_up}",
        "minecraft:jigsaw{orientation:south_up}",
        "minecraft:jigsaw{orientation:east_up}"
    ]
}
