{
    size: [5, 17, 5],
    data: [
        {pos: [0, 0, 0], state: "minecraft:cobblestone"},
        {pos: [0, 0, 1], state: "minecraft:cobblestone"},
        {pos: [0, 0, 2], state: "minecraft:cobblestone"},
        {pos: [0, 0, 3], state: "minecraft:cobblestone"},
        {pos: [0, 0, 4], state: "minecraft:cobblestone"},
        {pos: [1, 0, 0], state: "minecraft:cobblestone"},
        {pos: [1, 0, 1], state: "minecraft:cobblestone"},
        {pos: [1, 0, 2], state: "minecraft:cobblestone"},
        {pos: [1, 0, 3], state: "minecraft:cobblestone"},
        {pos: [1, 0, 4], state: "minecraft:cobblestone"},
        {pos: [2, 0, 0], state: "minecraft:cobblestone"},
        {pos: [2, 0, 1], state: "minecraft:cobblestone"},
        {pos: [2, 0, 2], state: "minecraft:cobblestone"},
        {pos: [2, 0, 3], state: "minecraft:cobblestone"},
        {pos: [2, 0, 4], state: "minecraft:cobblestone"},
        {pos: [3, 0, 0], state: "minecraft:cobblestone"},
        {pos: [3, 0, 1], state: "minecraft:cobblestone"},
        {pos: [3, 0, 2], state: "minecraft:cobblestone"},
        {pos: [3, 0, 3], state: "minecraft:cobblestone"},
        {pos: [3, 0, 4], state: "minecraft:cobblestone"},
        {pos: [4, 0, 0], state: "minecraft:cobblestone"},
        {pos: [4, 0, 1], state: "minecraft:cobblestone"},
        {pos: [4, 0, 2], state: "minecraft:cobblestone"},
        {pos: [4, 0, 3], state: "minecraft:cobblestone"},
        {pos: [4, 0, 4], state: "minecraft:cobblestone"},
        {pos: [0, 1, 0], state: "minecraft:cobblestone"},
        {pos: [0, 1, 1], state: "minecraft:cobblestone"},
        {pos: [0, 1, 2], state: "minecraft:jigsaw{orientation:west_up}", nbt: {final_state: "minecraft:cobblestone", id: "minecraft:jigsaw", joint: "rollable", name: "minecraft:road_connector", pool: "minecraft:trail_ruins/roads", target: "minecraft:long_road_end"}},
        {pos: [0, 1, 3], state: "minecraft:cobblestone"},
        {pos: [0, 1, 4], state: "minecraft:cobblestone"},
        {pos: [1, 1, 0], state: "minecraft:stone"},
        {pos: [1, 1, 1], state: "minecraft:stone"},
        {pos: [1, 1, 2], state: "minecraft:stone"},
        {pos: [1, 1, 3], state: "minecraft:cobblestone"},
        {pos: [1, 1, 4], state: "minecraft:stone"},
        {pos: [2, 1, 0], state: "minecraft:jigsaw{orientation:north_up}", nbt: {final_state: "minecraft:cobblestone", id: "minecraft:jigsaw", joint: "rollable", name: "minecraft:road_anchor", pool: "minecraft:trail_ruins/tower/additions", target: "minecraft:large_hall_connector"}},
        {pos: [2, 1, 1], state: "minecraft:cobblestone"},
        {pos: [2, 1, 2], state: "minecraft:stone"},
        {pos: [2, 1, 3], state: "minecraft:stone"},
        {pos: [2, 1, 4], state: "minecraft:jigsaw{orientation:south_up}", nbt: {final_state: "minecraft:cobblestone", id: "minecraft:jigsaw", joint: "rollable", name: "minecraft:road_anchor", pool: "minecraft:trail_ruins/tower/additions", target: "minecraft:road_hall_anchor"}},
        {pos: [3, 1, 0], state: "minecraft:stone"},
        {pos: [3, 1, 1], state: "minecraft:stone"},
        {pos: [3, 1, 2], state: "minecraft:stone"},
        {pos: [3, 1, 3], state: "minecraft:stone"},
        {pos: [3, 1, 4], state: "minecraft:stone"},
        {pos: [4, 1, 0], state: "minecraft:cobblestone"},
        {pos: [4, 1, 1], state: "minecraft:cobblestone"},
        {pos: [4, 1, 2], state: "minecraft:jigsaw{orientation:east_up}", nbt: {final_state: "minecraft:cobblestone", id: "minecraft:jigsaw", joint: "rollable", name: "minecraft:road_connector", pool: "minecraft:trail_ruins/roads", target: "minecraft:road_spacer"}},
        {pos: [4, 1, 3], state: "minecraft:cobblestone"},
        {pos: [4, 1, 4], state: "minecraft:cobblestone"},
        {pos: [0, 2, 0], state: "minecraft:mud_bricks"},
        {pos: [0, 2, 1], state: "minecraft:sand"},
        {pos: [0, 2, 2], state: "minecraft:sand"},
        {pos: [0, 2, 3], state: "minecraft:sand"},
        {pos: [0, 2, 4], state: "minecraft:mud_bricks"},
        {pos: [1, 2, 0], state: "minecraft:sand"},
        {pos: [1, 2, 1], state: "minecraft:sand"},
        {pos: [1, 2, 2], state: "minecraft:sand"},
        {pos: [1, 2, 3], state: "minecraft:sand"},
        {pos: [1, 2, 4], state: "minecraft:sand"},
        {pos: [2, 2, 0], state: "minecraft:sand"},
        {pos: [2, 2, 1], state: "minecraft:sand"},
        {pos: [2, 2, 2], state: "minecraft:sand"},
        {pos: [2, 2, 3], state: "minecraft:sand"},
        {pos: [2, 2, 4], state: "minecraft:sand"},
        {pos: [3, 2, 0], state: "minecraft:sand"},
        {pos: [3, 2, 1], state: "minecraft:sand"},
        {pos: [3, 2, 2], state: "minecraft:sand"},
        {pos: [3, 2, 3], state: "minecraft:sand"},
        {pos: [3, 2, 4], state: "minecraft:sand"},
        {pos: [4, 2, 0], state: "minecraft:mud_bricks"},
        {pos: [4, 2, 1], state: "minecraft:sand"},
        {pos: [4, 2, 2], state: "minecraft:sand"},
        {pos: [4, 2, 3], state: "minecraft:sand"},
        {pos: [4, 2, 4], state: "minecraft:mud_bricks"},
        {pos: [0, 3, 0], state: "minecraft:red_terracotta"},
        {pos: [0, 3, 1], state: "minecraft:sand"},
        {pos: [0, 3, 2], state: "minecraft:sand"},
        {pos: [0, 3, 3], state: "minecraft:sand"},
        {pos: [0, 3, 4], state: "minecraft:red_terracotta"},
        {pos: [1, 3, 0], state: "minecraft:sand"},
        {pos: [1, 3, 1], state: "minecraft:sand"},
        {pos: [1, 3, 2], state: "minecraft:sand"},
        {pos: [1, 3, 3], state: "minecraft:red_glazed_terracotta{facing:west}"},
        {pos: [1, 3, 4], state: "minecraft:sand"},
        {pos: [2, 3, 0], state: "minecraft:sand"},
        {pos: [2, 3, 1], state: "minecraft:sand"},
        {pos: [2, 3, 2], state: "minecraft:sand"},
        {pos: [2, 3, 3], state: "minecraft:sand"},
        {pos: [2, 3, 4], state: "minecraft:sand"},
        {pos: [3, 3, 0], state: "minecraft:sand"},
        {pos: [3, 3, 1], state: "minecraft:sand"},
        {pos: [3, 3, 2], state: "minecraft:sand"},
        {pos: [3, 3, 3], state: "minecraft:sand"},
        {pos: [3, 3, 4], state: "minecraft:sand"},
        {pos: [4, 3, 0], state: "minecraft:red_terracotta"},
        {pos: [4, 3, 1], state: "minecraft:sand"},
        {pos: [4, 3, 2], state: "minecraft:sand"},
        {pos: [4, 3, 3], state: "minecraft:sand"},
        {pos: [4, 3, 4], state: "minecraft:red_terracotta"},
        {pos: [0, 4, 0], state: "minecraft:mud_bricks"},
        {pos: [0, 4, 1], state: "minecraft:sand"},
        {pos: [0, 4, 2], state: "minecraft:sand"},
        {pos: [0, 4, 3], state: "minecraft:sand"},
        {pos: [0, 4, 4], state: "minecraft:mud_bricks"},
        {pos: [1, 4, 0], state: "minecraft:sand"},
        {pos: [1, 4, 1], state: "minecraft:sand"},
        {pos: [1, 4, 2], state: "minecraft:air"},
        {pos: [1, 4, 3], state: "minecraft:sand"},
        {pos: [1, 4, 4], state: "minecraft:sand"},
        {pos: [2, 4, 0], state: "minecraft:sand"},
        {pos: [2, 4, 1], state: "minecraft:air"},
        {pos: [2, 4, 2], state: "minecraft:air"},
        {pos: [2, 4, 3], state: "minecraft:sand"},
        {pos: [2, 4, 4], state: "minecraft:sand"},
        {pos: [3, 4, 0], state: "minecraft:sand"},
        {pos: [3, 4, 1], state: "minecraft:sand"},
        {pos: [3, 4, 2], state: "minecraft:sand"},
        {pos: [3, 4, 3], state: "minecraft:sand"},
        {pos: [3, 4, 4], state: "minecraft:sand"},
        {pos: [4, 4, 0], state: "minecraft:mud_bricks"},
        {pos: [4, 4, 1], state: "minecraft:sand"},
        {pos: [4, 4, 2], state: "minecraft:sand"},
        {pos: [4, 4, 3], state: "minecraft:sand"},
        {pos: [4, 4, 4], state: "minecraft:mud_bricks"},
        {pos: [0, 5, 0], state: "minecraft:mud_bricks"},
        {pos: [0, 5, 1], state: "minecraft:mud_bricks"},
        {pos: [0, 5, 2], state: "minecraft:mud_bricks"},
        {pos: [0, 5, 3], state: "minecraft:mud_bricks"},
        {pos: [0, 5, 4], state: "minecraft:mud_bricks"},
        {pos: [1, 5, 0], state: "minecraft:mud_bricks"},
        {pos: [1, 5, 1], state: "minecraft:air"},
        {pos: [1, 5, 2], state: "minecraft:air"},
        {pos: [1, 5, 3], state: "minecraft:air"},
        {pos: [1, 5, 4], state: "minecraft:mud_bricks"},
        {pos: [2, 5, 0], state: "minecraft:mud_bricks"},
        {pos: [2, 5, 1], state: "minecraft:air"},
        {pos: [2, 5, 2], state: "minecraft:air"},
        {pos: [2, 5, 3], state: "minecraft:air"},
        {pos: [2, 5, 4], state: "minecraft:mud_bricks"},
        {pos: [3, 5, 0], state: "minecraft:mud_bricks"},
        {pos: [3, 5, 1], state: "minecraft:air"},
        {pos: [3, 5, 2], state: "minecraft:sand"},
        {pos: [3, 5, 3], state: "minecraft:air"},
        {pos: [3, 5, 4], state: "minecraft:mud_bricks"},
        {pos: [4, 5, 0], state: "minecraft:mud_bricks"},
        {pos: [4, 5, 1], state: "minecraft:mud_bricks"},
        {pos: [4, 5, 2], state: "minecraft:mud_bricks"},
        {pos: [4, 5, 3], state: "minecraft:mud_bricks"},
        {pos: [4, 5, 4], state: "minecraft:mud_bricks"},
        {pos: [0, 6, 0], state: "minecraft:sand"},
        {pos: [0, 6, 1], state: "minecraft:mud_bricks"},
        {pos: [0, 6, 2], state: "minecraft:mud_bricks"},
        {pos: [0, 6, 3], state: "minecraft:sand"},
        {pos: [0, 6, 4], state: "minecraft:mud_bricks"},
        {pos: [1, 6, 0], state: "minecraft:mud_bricks"},
        {pos: [1, 6, 1], state: "minecraft:red_glazed_terracotta{facing:south}"},
        {pos: [1, 6, 2], state: "minecraft:red_glazed_terracotta{facing:west}"},
        {pos: [1, 6, 3], state: "minecraft:red_glazed_terracotta{facing:north}"},
        {pos: [1, 6, 4], state: "minecraft:red_terracotta"},
        {pos: [2, 6, 0], state: "minecraft:mud_bricks"},
        {pos: [2, 6, 1], state: "minecraft:red_glazed_terracotta{facing:north}"},
        {pos: [2, 6, 2], state: "minecraft:red_concrete"},
        {pos: [2, 6, 3], state: "minecraft:red_glazed_terracotta{facing:south}"},
        {pos: [2, 6, 4], state: "minecraft:red_terracotta"},
        {pos: [3, 6, 0], state: "minecraft:mud_bricks"},
        {pos: [3, 6, 1], state: "minecraft:red_glazed_terracotta{facing:south}"},
        {pos: [3, 6, 2], state: "minecraft:sand"},
        {pos: [3, 6, 3], state: "minecraft:red_glazed_terracotta{facing:north}"},
        {pos: [3, 6, 4], state: "minecraft:red_terracotta"},
        {pos: [4, 6, 0], state: "minecraft:mud_bricks"},
        {pos: [4, 6, 1], state: "minecraft:mud_bricks"},
        {pos: [4, 6, 2], state: "minecraft:mud_bricks"},
        {pos: [4, 6, 3], state: "minecraft:mud_bricks"},
        {pos: [4, 6, 4], state: "minecraft:mud_bricks"},
        {pos: [0, 7, 0], state: "minecraft:sand"},
        {pos: [0, 7, 1], state: "minecraft:blue_terracotta"},
        {pos: [0, 7, 2], state: "minecraft:blue_terracotta"},
        {pos: [0, 7, 3], state: "minecraft:sand"},
        {pos: [1, 7, 0], state: "minecraft:blue_terracotta"},
        {pos: [1, 7, 1], state: "minecraft:air"},
        {pos: [1, 7, 2], state: "minecraft:sand"},
        {pos: [1, 7, 3], state: "minecraft:sand"},
        {pos: [1, 7, 4], state: "minecraft:blue_terracotta"},
        {pos: [2, 7, 0], state: "minecraft:blue_terracotta"},
        {pos: [2, 7, 1], state: "minecraft:terracotta"},
        {pos: [2, 7, 2], state: "minecraft:sand"},
        {pos: [2, 7, 3], state: "minecraft:sand"},
        {pos: [2, 7, 4], state: "minecraft:sand"},
        {pos: [3, 7, 0], state: "minecraft:blue_terracotta"},
        {pos: [3, 7, 1], state: "minecraft:terracotta"},
        {pos: [3, 7, 2], state: "minecraft:sand"},
        {pos: [3, 7, 3], state: "minecraft:sand"},
        {pos: [3, 7, 4], state: "minecraft:blue_terracotta"},
        {pos: [4, 7, 0], state: "minecraft:red_terracotta"},
        {pos: [4, 7, 1], state: "minecraft:blue_terracotta"},
        {pos: [4, 7, 2], state: "minecraft:blue_terracotta"},
        {pos: [4, 7, 3], state: "minecraft:blue_terracotta"},
        {pos: [4, 7, 4], state: "minecraft:red_terracotta"},
        {pos: [0, 8, 0], state: "minecraft:sand"},
        {pos: [0, 8, 1], state: "minecraft:sand"},
        {pos: [0, 8, 2], state: "minecraft:blue_glazed_terracotta{facing:south}"},
        {pos: [0, 8, 3], state: "minecraft:blue_terracotta"},
        {pos: [0, 8, 4], state: "minecraft:red_terracotta"},
        {pos: [1, 8, 0], state: "minecraft:sand"},
        {pos: [1, 8, 1], state: "minecraft:terracotta"},
        {pos: [1, 8, 2], state: "minecraft:terracotta"},
        {pos: [1, 8, 3], state: "minecraft:air"},
        {pos: [1, 8, 4], state: "minecraft:blue_terracotta"},
        {pos: [2, 8, 0], state: "minecraft:blue_glazed_terracotta{facing:west}"},
        {pos: [2, 8, 1], state: "minecraft:sand"},
        {pos: [2, 8, 2], state: "minecraft:sand"},
        {pos: [2, 8, 3], state: "minecraft:sand"},
        {pos: [2, 8, 4], state: "minecraft:sand"},
        {pos: [3, 8, 0], state: "minecraft:blue_terracotta"},
        {pos: [3, 8, 1], state: "minecraft:sand"},
        {pos: [3, 8, 2], state: "minecraft:sand"},
        {pos: [3, 8, 3], state: "minecraft:sand"},
        {pos: [3, 8, 4], state: "minecraft:blue_terracotta"},
        {pos: [4, 8, 0], state: "minecraft:red_terracotta"},
        {pos: [4, 8, 1], state: "minecraft:blue_terracotta"},
        {pos: [4, 8, 2], state: "minecraft:blue_glazed_terracotta{facing:north}"},
        {pos: [4, 8, 3], state: "minecraft:blue_terracotta"},
        {pos: [4, 8, 4], state: "minecraft:red_terracotta"},
        {pos: [0, 9, 0], state: "minecraft:sand"},
        {pos: [0, 9, 1], state: "minecraft:sand"},
        {pos: [0, 9, 2], state: "minecraft:blue_terracotta"},
        {pos: [0, 9, 3], state: "minecraft:blue_terracotta"},
        {pos: [0, 9, 4], state: "minecraft:sand"},
        {pos: [1, 9, 0], state: "minecraft:sand"},
        {pos: [1, 9, 1], state: "minecraft:sand"},
        {pos: [1, 9, 2], state: "minecraft:sand"},
        {pos: [1, 9, 3], state: "minecraft:terracotta"},
        {pos: [1, 9, 4], state: "minecraft:sand"},
        {pos: [2, 9, 0], state: "minecraft:blue_terracotta"},
        {pos: [2, 9, 1], state: "minecraft:sand"},
        {pos: [2, 9, 2], state: "minecraft:sand"},
        {pos: [2, 9, 3], state: "minecraft:sand"},
        {pos: [2, 9, 4], state: "minecraft:blue_terracotta"},
        {pos: [3, 9, 0], state: "minecraft:blue_terracotta"},
        {pos: [3, 9, 1], state: "minecraft:sand"},
        {pos: [3, 9, 2], state: "minecraft:sand"},
        {pos: [3, 9, 3], state: "minecraft:air"},
        {pos: [3, 9, 4], state: "minecraft:blue_terracotta"},
        {pos: [4, 9, 0], state: "minecraft:red_terracotta"},
        {pos: [4, 9, 1], state: "minecraft:blue_terracotta"},
        {pos: [4, 9, 2], state: "minecraft:blue_terracotta"},
        {pos: [4, 9, 3], state: "minecraft:blue_terracotta"},
        {pos: [4, 9, 4], state: "minecraft:red_terracotta"},
        {pos: [0, 10, 1], state: "minecraft:sand"},
        {pos: [0, 10, 2], state: "minecraft:yellow_terracotta"},
        {pos: [0, 10, 3], state: "minecraft:yellow_terracotta"},
        {pos: [0, 10, 4], state: "minecraft:sand"},
        {pos: [1, 10, 0], state: "minecraft:yellow_terracotta"},
        {pos: [1, 10, 1], state: "minecraft:sand"},
        {pos: [1, 10, 2], state: "minecraft:sand"},
        {pos: [1, 10, 3], state: "minecraft:sand"},
        {pos: [1, 10, 4], state: "minecraft:sand"},
        {pos: [2, 10, 0], state: "minecraft:yellow_terracotta"},
        {pos: [2, 10, 1], state: "minecraft:sand"},
        {pos: [2, 10, 2], state: "minecraft:sand"},
        {pos: [2, 10, 3], state: "minecraft:sand"},
        {pos: [2, 10, 4], state: "minecraft:yellow_terracotta"},
        {pos: [3, 10, 0], state: "minecraft:yellow_terracotta"},
        {pos: [3, 10, 1], state: "minecraft:sand"},
        {pos: [3, 10, 2], state: "minecraft:sand"},
        {pos: [3, 10, 3], state: "minecraft:terracotta"},
        {pos: [3, 10, 4], state: "minecraft:yellow_terracotta"},
        {pos: [4, 10, 0], state: "minecraft:red_terracotta"},
        {pos: [4, 10, 1], state: "minecraft:yellow_terracotta"},
        {pos: [4, 10, 2], state: "minecraft:yellow_terracotta"},
        {pos: [4, 10, 3], state: "minecraft:yellow_terracotta"},
        {pos: [4, 10, 4], state: "minecraft:red_terracotta"},
        {pos: [0, 11, 0], state: "minecraft:red_terracotta"},
        {pos: [0, 11, 1], state: "minecraft:red_terracotta"},
        {pos: [0, 11, 2], state: "minecraft:red_terracotta"},
        {pos: [0, 11, 3], state: "minecraft:red_terracotta"},
        {pos: [0, 11, 4], state: "minecraft:sand"},
        {pos: [1, 11, 0], state: "minecraft:red_terracotta"},
        {pos: [1, 11, 1], state: "minecraft:air"},
        {pos: [1, 11, 2], state: "minecraft:air"},
        {pos: [1, 11, 3], state: "minecraft:sand"},
        {pos: [1, 11, 4], state: "minecraft:sand"},
        {pos: [2, 11, 0], state: "minecraft:red_terracotta"},
        {pos: [2, 11, 1], state: "minecraft:terracotta"},
        {pos: [2, 11, 2], state: "minecraft:sand"},
        {pos: [2, 11, 3], state: "minecraft:sand"},
        {pos: [2, 11, 4], state: "minecraft:red_terracotta"},
        {pos: [3, 11, 0], state: "minecraft:red_terracotta"},
        {pos: [3, 11, 1], state: "minecraft:terracotta"},
        {pos: [3, 11, 2], state: "minecraft:sand"},
        {pos: [3, 11, 3], state: "minecraft:sand"},
        {pos: [3, 11, 4], state: "minecraft:red_terracotta"},
        {pos: [4, 11, 0], state: "minecraft:red_terracotta"},
        {pos: [4, 11, 1], state: "minecraft:red_terracotta"},
        {pos: [4, 11, 2], state: "minecraft:red_terracotta"},
        {pos: [4, 11, 3], state: "minecraft:red_terracotta"},
        {pos: [4, 11, 4], state: "minecraft:red_terracotta"},
        {pos: [0, 12, 0], state: "minecraft:blue_terracotta"},
        {pos: [0, 12, 1], state: "minecraft:blue_terracotta"},
        {pos: [0, 12, 2], state: "minecraft:sand"},
        {pos: [0, 12, 3], state: "minecraft:blue_terracotta"},
        {pos: [0, 12, 4], state: "minecraft:sand"},
        {pos: [1, 12, 0], state: "minecraft:blue_terracotta"},
        {pos: [1, 12, 1], state: "minecraft:terracotta"},
        {pos: [1, 12, 2], state: "minecraft:terracotta"},
        {pos: [1, 12, 3], state: "minecraft:air"},
        {pos: [1, 12, 4], state: "minecraft:blue_terracotta"},
        {pos: [2, 12, 0], state: "minecraft:air"},
        {pos: [2, 12, 1], state: "minecraft:sand"},
        {pos: [2, 12, 2], state: "minecraft:sand"},
        {pos: [2, 12, 3], state: "minecraft:air"},
        {pos: [2, 12, 4], state: "minecraft:sand"},
        {pos: [3, 12, 0], state: "minecraft:blue_terracotta"},
        {pos: [3, 12, 1], state: "minecraft:sand"},
        {pos: [3, 12, 2], state: "minecraft:sand"},
        {pos: [3, 12, 3], state: "minecraft:sand"},
        {pos: [3, 12, 4], state: "minecraft:blue_terracotta"},
        {pos: [4, 12, 0], state: "minecraft:blue_terracotta"},
        {pos: [4, 12, 1], state: "minecraft:blue_terracotta"},
        {pos: [4, 12, 2], state: "minecraft:sand"},
        {pos: [4, 12, 3], state: "minecraft:blue_terracotta"},
        {pos: [4, 12, 4], state: "minecraft:blue_terracotta"},
        {pos: [0, 13, 1], state: "minecraft:blue_terracotta"},
        {pos: [0, 13, 2], state: "minecraft:sand"},
        {pos: [0, 13, 3], state: "minecraft:blue_terracotta"},
        {pos: [0, 13, 4], state: "minecraft:blue_terracotta"},
        {pos: [1, 13, 1], state: "minecraft:sand"},
        {pos: [1, 13, 2], state: "minecraft:sand"},
        {pos: [1, 13, 3], state: "minecraft:terracotta"},
        {pos: [1, 13, 4], state: "minecraft:blue_terracotta"},
        {pos: [2, 13, 1], state: "minecraft:sand"},
        {pos: [2, 13, 2], state: "minecraft:sand"},
        {pos: [2, 13, 3], state: "minecraft:terracotta"},
        {pos: [2, 13, 4], state: "minecraft:sand"},
        {pos: [3, 13, 1], state: "minecraft:sand"},
        {pos: [3, 13, 2], state: "minecraft:sand"},
        {pos: [3, 13, 4], state: "minecraft:blue_terracotta"},
        {pos: [4, 13, 3], state: "minecraft:blue_terracotta"},
        {pos: [4, 13, 4], state: "minecraft:blue_terracotta"},
        {pos: [0, 14, 2], state: "minecraft:red_terracotta"},
        {pos: [0, 14, 3], state: "minecraft:red_terracotta"},
        {pos: [0, 14, 4], state: "minecraft:red_terracotta"},
        {pos: [1, 14, 2], state: "minecraft:sand"},
        {pos: [1, 14, 3], state: "minecraft:sand"},
        {pos: [1, 14, 4], state: "minecraft:red_terracotta"},
        {pos: [2, 14, 2], state: "minecraft:sand"},
        {pos: [2, 14, 3], state: "minecraft:sand"},
        {pos: [2, 14, 4], state: "minecraft:red_terracotta"},
        {pos: [3, 14, 3], state: "minecraft:terracotta"},
        {pos: [3, 14, 4], state: "minecraft:red_terracotta"},
        {pos: [4, 14, 4], state: "minecraft:red_terracotta"},
        {pos: [0, 15, 2], state: "minecraft:red_terracotta"},
        {pos: [0, 15, 3], state: "minecraft:yellow_terracotta"},
        {pos: [0, 15, 4], state: "minecraft:yellow_terracotta"},
        {pos: [1, 15, 2], state: "minecraft:sand"},
        {pos: [1, 15, 3], state: "minecraft:sand"},
        {pos: [1, 15, 4], state: "minecraft:yellow_terracotta"},
        {pos: [2, 15, 2], state: "minecraft:sand"},
        {pos: [2, 15, 3], state: "minecraft:sand"},
        {pos: [2, 15, 4], state: "minecraft:red_terracotta"},
        {pos: [3, 15, 3], state: "minecraft:sand"},
        {pos: [3, 15, 4], state: "minecraft:yellow_terracotta"},
        {pos: [4, 15, 4], state: "minecraft:yellow_terracotta"},
        {pos: [0, 16, 3], state: "minecraft:yellow_terracotta"},
        {pos: [1, 16, 3], state: "minecraft:sand"},
        {pos: [1, 16, 4], state: "minecraft:yellow_terracotta"},
        {pos: [2, 16, 4], state: "minecraft:yellow_terracotta"},
        {pos: [3, 16, 4], state: "minecraft:yellow_terracotta"}
    ],
    entities: [],
    palette: [
        "minecraft:cobblestone",
        "minecraft:stone",
        "minecraft:mud_bricks",
        "minecraft:sand",
        "minecraft:red_terracotta",
        "minecraft:red_glazed_terracotta{facing:west}",
        "minecraft:red_glazed_terracotta{facing:south}",
        "minecraft:red_glazed_terracotta{facing:north}",
        "minecraft:red_concrete",
        "minecraft:blue_terracotta",
        "minecraft:terracotta",
        "minecraft:blue_glazed_terracotta{facing:south}",
        "minecraft:blue_glazed_terracotta{facing:west}",
        "minecraft:blue_glazed_terracotta{facing:north}",
        "minecraft:yellow_terracotta",
        "minecraft:air",
        "minecraft:jigsaw{orientation:west_up}",
        "minecraft:jigsaw{orientation:north_up}",
        "minecraft:jigsaw{orientation:south_up}",
        "minecraft:jigsaw{orientation:east_up}"
    ]
}
