{
    size: [7, 4, 7],
    data: [
        {pos: [1, 0, 4], state: "minecraft:red_terracotta"},
        {pos: [2, 0, 2], state: "minecraft:gravel"},
        {pos: [2, 0, 3], state: "minecraft:gravel"},
        {pos: [2, 0, 4], state: "minecraft:gravel"},
        {pos: [2, 0, 5], state: "minecraft:light_gray_terracotta"},
        {pos: [3, 0, 2], state: "minecraft:gravel"},
        {pos: [3, 0, 3], state: "minecraft:gravel"},
        {pos: [3, 0, 4], state: "minecraft:gravel"},
        {pos: [3, 0, 5], state: "minecraft:red_terracotta"},
        {pos: [4, 0, 2], state: "minecraft:gravel"},
        {pos: [4, 0, 3], state: "minecraft:gravel"},
        {pos: [4, 0, 4], state: "minecraft:gravel"},
        {pos: [4, 0, 5], state: "minecraft:gravel"},
        {pos: [5, 0, 1], state: "minecraft:jigsaw{orientation:down_east}", nbt: {final_state: "minecraft:dirt", id: "minecraft:jigsaw", joint: "aligned", name: "minecraft:tower_top_5", pool: "minecraft:trail_ruins/tower", target: "minecraft:tower_bottom_5"}},
        {pos: [5, 0, 2], state: "minecraft:red_terracotta"},
        {pos: [5, 0, 3], state: "minecraft:gravel"},
        {pos: [5, 0, 4], state: "minecraft:gravel"},
        {pos: [5, 0, 5], state: "minecraft:gravel"},
        {pos: [2, 1, 4], state: "minecraft:gravel"},
        {pos: [3, 1, 3], state: "minecraft:gravel"},
        {pos: [3, 1, 4], state: "minecraft:gravel"},
        {pos: [3, 1, 5], state: "minecraft:red_terracotta"},
        {pos: [4, 1, 2], state: "minecraft:gravel"},
        {pos: [4, 1, 3], state: "minecraft:gravel"},
        {pos: [4, 1, 4], state: "minecraft:gravel"},
        {pos: [3, 2, 4], state: "minecraft:gravel"},
        {pos: [3, 2, 5], state: "minecraft:red_terracotta"},
        {pos: [4, 2, 3], state: "minecraft:gravel"},
        {pos: [4, 2, 4], state: "minecraft:gravel"},
        {pos: [3, 3, 5], state: "minecraft:red_terracotta"},
        {pos: [4, 3, 4], state: "minecraft:gravel"}
    ],
    entities: [],
    palette: [
        "minecraft:red_terracotta",
        "minecraft:gravel",
        "minecraft:light_gray_terracotta",
        "minecraft:jigsaw{orientation:down_east}"
    ]
}
