{
    size: [5, 15, 5],
    data: [
        {pos: [0, 0, 1], state: "minecraft:mud_bricks"},
        {pos: [0, 0, 2], state: "minecraft:mud_bricks"},
        {pos: [0, 0, 3], state: "minecraft:mud_bricks"},
        {pos: [0, 0, 4], state: "minecraft:mud_bricks"},
        {pos: [1, 0, 0], state: "minecraft:gravel"},
        {pos: [1, 0, 1], state: "minecraft:mud_bricks"},
        {pos: [1, 0, 2], state: "minecraft:mud_bricks"},
        {pos: [1, 0, 3], state: "minecraft:mud_bricks"},
        {pos: [1, 0, 4], state: "minecraft:mud_bricks"},
        {pos: [2, 0, 0], state: "minecraft:mud_bricks"},
        {pos: [2, 0, 1], state: "minecraft:mud_bricks"},
        {pos: [2, 0, 2], state: "minecraft:mud_bricks"},
        {pos: [2, 0, 3], state: "minecraft:mud_bricks"},
        {pos: [2, 0, 4], state: "minecraft:mud_bricks"},
        {pos: [3, 0, 0], state: "minecraft:mud_bricks"},
        {pos: [3, 0, 2], state: "minecraft:mud_bricks"},
        {pos: [3, 0, 3], state: "minecraft:mud_bricks"},
        {pos: [3, 0, 4], state: "minecraft:mud_bricks"},
        {pos: [4, 0, 0], state: "minecraft:mud_bricks"},
        {pos: [4, 0, 1], state: "minecraft:mud_bricks"},
        {pos: [4, 0, 2], state: "minecraft:mud_bricks"},
        {pos: [4, 0, 3], state: "minecraft:mud_bricks"},
        {pos: [4, 0, 4], state: "minecraft:mud_bricks"},
        {pos: [0, 1, 1], state: "minecraft:gravel"},
        {pos: [0, 1, 2], state: "minecraft:gravel"},
        {pos: [0, 1, 3], state: "minecraft:gravel"},
        {pos: [0, 1, 4], state: "minecraft:gravel"},
        {pos: [1, 1, 0], state: "minecraft:gravel"},
        {pos: [1, 1, 1], state: "minecraft:gravel"},
        {pos: [1, 1, 2], state: "minecraft:gravel"},
        {pos: [1, 1, 3], state: "minecraft:mud_brick_stairs{facing:east,half:bottom,shape:straight,waterlogged:false}"},
        {pos: [1, 1, 4], state: "minecraft:mud_bricks"},
        {pos: [2, 1, 1], state: "minecraft:gravel"},
        {pos: [2, 1, 2], state: "minecraft:gravel"},
        {pos: [2, 1, 3], state: "minecraft:mud_bricks"},
        {pos: [2, 1, 4], state: "minecraft:mud_bricks"},
        {pos: [3, 1, 2], state: "minecraft:gravel"},
        {pos: [3, 1, 3], state: "minecraft:gravel"},
        {pos: [3, 1, 4], state: "minecraft:mud_bricks"},
        {pos: [4, 1, 0], state: "minecraft:mud_bricks"},
        {pos: [4, 1, 1], state: "minecraft:mud_bricks"},
        {pos: [4, 1, 2], state: "minecraft:mud_bricks"},
        {pos: [4, 1, 3], state: "minecraft:mud_bricks"},
        {pos: [4, 1, 4], state: "minecraft:mud_bricks"},
        {pos: [0, 2, 1], state: "minecraft:gravel"},
        {pos: [0, 2, 2], state: "minecraft:gravel"},
        {pos: [0, 2, 3], state: "minecraft:gravel"},
        {pos: [0, 2, 4], state: "minecraft:mud_bricks"},
        {pos: [1, 2, 0], state: "minecraft:gravel"},
        {pos: [1, 2, 1], state: "minecraft:gravel"},
        {pos: [1, 2, 2], state: "minecraft:gravel"},
        {pos: [1, 2, 3], state: "minecraft:gravel"},
        {pos: [1, 2, 4], state: "minecraft:mud_bricks"},
        {pos: [2, 2, 1], state: "minecraft:gravel"},
        {pos: [2, 2, 2], state: "minecraft:gravel"},
        {pos: [2, 2, 3], state: "minecraft:mud_brick_stairs{facing:east,half:bottom,shape:straight,waterlogged:false}"},
        {pos: [2, 2, 4], state: "minecraft:mud_bricks"},
        {pos: [3, 2, 0], state: "minecraft:mud_bricks"},
        {pos: [3, 2, 2], state: "minecraft:gravel"},
        {pos: [3, 2, 3], state: "minecraft:mud_bricks"},
        {pos: [3, 2, 4], state: "minecraft:mud_bricks"},
        {pos: [4, 2, 0], state: "minecraft:mud_bricks"},
        {pos: [4, 2, 1], state: "minecraft:mud_bricks"},
        {pos: [4, 2, 2], state: "minecraft:mud_bricks"},
        {pos: [4, 2, 3], state: "minecraft:mud_bricks"},
        {pos: [4, 2, 4], state: "minecraft:mud_bricks"},
        {pos: [0, 3, 0], state: "minecraft:mud_bricks"},
        {pos: [0, 3, 2], state: "minecraft:gravel"},
        {pos: [0, 3, 3], state: "minecraft:gravel"},
        {pos: [1, 3, 0], state: "minecraft:gravel"},
        {pos: [1, 3, 1], state: "minecraft:gravel"},
        {pos: [1, 3, 2], state: "minecraft:gravel"},
        {pos: [1, 3, 3], state: "minecraft:gravel"},
        {pos: [2, 3, 0], state: "minecraft:mud_bricks"},
        {pos: [2, 3, 1], state: "minecraft:gravel"},
        {pos: [2, 3, 2], state: "minecraft:gravel"},
        {pos: [2, 3, 3], state: "minecraft:gravel"},
        {pos: [2, 3, 4], state: "minecraft:mud_bricks"},
        {pos: [3, 3, 0], state: "minecraft:gravel"},
        {pos: [3, 3, 1], state: "minecraft:mud_bricks"},
        {pos: [3, 3, 2], state: "minecraft:mud_brick_stairs{facing:north,half:bottom,shape:straight,waterlogged:false}"},
        {pos: [3, 3, 3], state: "minecraft:gravel"},
        {pos: [3, 3, 4], state: "minecraft:mud_bricks"},
        {pos: [4, 3, 0], state: "minecraft:mud_bricks"},
        {pos: [4, 3, 1], state: "minecraft:mud_bricks"},
        {pos: [4, 3, 2], state: "minecraft:mud_bricks"},
        {pos: [4, 3, 3], state: "minecraft:mud_bricks"},
        {pos: [4, 3, 4], state: "minecraft:mud_bricks"},
        {pos: [0, 4, 0], state: "minecraft:gravel"},
        {pos: [0, 4, 1], state: "minecraft:mud_bricks"},
        {pos: [0, 4, 3], state: "minecraft:mud_bricks"},
        {pos: [0, 4, 4], state: "minecraft:mud_bricks"},
        {pos: [1, 4, 0], state: "minecraft:gravel"},
        {pos: [1, 4, 1], state: "minecraft:mud_bricks"},
        {pos: [1, 4, 2], state: "minecraft:mud_bricks"},
        {pos: [1, 4, 3], state: "minecraft:gravel"},
        {pos: [1, 4, 4], state: "minecraft:mud_bricks"},
        {pos: [2, 4, 0], state: "minecraft:gravel"},
        {pos: [2, 4, 1], state: "minecraft:gravel"},
        {pos: [2, 4, 2], state: "minecraft:gravel"},
        {pos: [2, 4, 3], state: "minecraft:gravel"},
        {pos: [2, 4, 4], state: "minecraft:mud_bricks"},
        {pos: [3, 4, 0], state: "minecraft:gravel"},
        {pos: [3, 4, 1], state: "minecraft:gravel"},
        {pos: [3, 4, 2], state: "minecraft:gravel"},
        {pos: [3, 4, 3], state: "minecraft:gravel"},
        {pos: [3, 4, 4], state: "minecraft:mud_bricks"},
        {pos: [4, 4, 0], state: "minecraft:mud_bricks"},
        {pos: [4, 4, 1], state: "minecraft:mud_bricks"},
        {pos: [4, 4, 2], state: "minecraft:mud_bricks"},
        {pos: [4, 4, 3], state: "minecraft:mud_bricks"},
        {pos: [4, 4, 4], state: "minecraft:mud_bricks"},
        {pos: [0, 5, 0], state: "minecraft:gravel"},
        {pos: [0, 5, 1], state: "minecraft:gravel"},
        {pos: [0, 5, 2], state: "minecraft:jigsaw{orientation:west_up}", nbt: {final_state: "minecraft:dirt", id: "minecraft:jigsaw", joint: "rollable", name: "minecraft:room", pool: "minecraft:trail_ruins/buildings/grouped", target: "minecraft:hall"}},
        {pos: [0, 5, 3], state: "minecraft:gravel"},
        {pos: [0, 5, 4], state: "minecraft:mud_bricks"},
        {pos: [1, 5, 0], state: "minecraft:gravel"},
        {pos: [1, 5, 1], state: "minecraft:gravel"},
        {pos: [1, 5, 2], state: "minecraft:gravel"},
        {pos: [1, 5, 3], state: "minecraft:gravel"},
        {pos: [1, 5, 4], state: "minecraft:mud_bricks"},
        {pos: [2, 5, 0], state: "minecraft:gravel"},
        {pos: [2, 5, 1], state: "minecraft:gravel"},
        {pos: [2, 5, 2], state: "minecraft:gravel"},
        {pos: [2, 5, 3], state: "minecraft:gravel"},
        {pos: [2, 5, 4], state: "minecraft:mud_bricks"},
        {pos: [3, 5, 0], state: "minecraft:gravel"},
        {pos: [3, 5, 1], state: "minecraft:gravel"},
        {pos: [3, 5, 2], state: "minecraft:gravel"},
        {pos: [3, 5, 3], state: "minecraft:gravel"},
        {pos: [3, 5, 4], state: "minecraft:mud_bricks"},
        {pos: [4, 5, 0], state: "minecraft:mud_bricks"},
        {pos: [4, 5, 1], state: "minecraft:mud_bricks"},
        {pos: [4, 5, 2], state: "minecraft:mud_bricks"},
        {pos: [4, 5, 4], state: "minecraft:mud_bricks"},
        {pos: [0, 6, 0], state: "minecraft:gravel"},
        {pos: [0, 6, 1], state: "minecraft:gravel"},
        {pos: [0, 6, 2], state: "minecraft:gravel"},
        {pos: [0, 6, 3], state: "minecraft:gravel"},
        {pos: [0, 6, 4], state: "minecraft:mud_bricks"},
        {pos: [1, 6, 0], state: "minecraft:gravel"},
        {pos: [1, 6, 1], state: "minecraft:gravel"},
        {pos: [1, 6, 2], state: "minecraft:gravel"},
        {pos: [1, 6, 3], state: "minecraft:gravel"},
        {pos: [1, 6, 4], state: "minecraft:gravel"},
        {pos: [2, 6, 0], state: "minecraft:gravel"},
        {pos: [2, 6, 1], state: "minecraft:gravel"},
        {pos: [2, 6, 2], state: "minecraft:gravel"},
        {pos: [2, 6, 3], state: "minecraft:gravel"},
        {pos: [2, 6, 4], state: "minecraft:gravel"},
        {pos: [3, 6, 0], state: "minecraft:gravel"},
        {pos: [3, 6, 1], state: "minecraft:gravel"},
        {pos: [3, 6, 2], state: "minecraft:gravel"},
        {pos: [3, 6, 3], state: "minecraft:gravel"},
        {pos: [3, 6, 4], state: "minecraft:gravel"},
        {pos: [4, 6, 1], state: "minecraft:gravel"},
        {pos: [4, 6, 2], state: "minecraft:gravel"},
        {pos: [0, 7, 0], state: "minecraft:gravel"},
        {pos: [0, 7, 1], state: "minecraft:gravel"},
        {pos: [0, 7, 2], state: "minecraft:gravel"},
        {pos: [0, 7, 3], state: "minecraft:gravel"},
        {pos: [0, 7, 4], state: "minecraft:mud_bricks"},
        {pos: [1, 7, 0], state: "minecraft:gravel"},
        {pos: [1, 7, 1], state: "minecraft:gravel"},
        {pos: [1, 7, 2], state: "minecraft:gravel"},
        {pos: [1, 7, 3], state: "minecraft:gravel"},
        {pos: [1, 7, 4], state: "minecraft:mud_bricks"},
        {pos: [2, 7, 0], state: "minecraft:gravel"},
        {pos: [2, 7, 1], state: "minecraft:gravel"},
        {pos: [2, 7, 2], state: "minecraft:gravel"},
        {pos: [2, 7, 3], state: "minecraft:gravel"},
        {pos: [2, 7, 4], state: "minecraft:mud_bricks"},
        {pos: [3, 7, 0], state: "minecraft:gravel"},
        {pos: [3, 7, 1], state: "minecraft:gravel"},
        {pos: [3, 7, 2], state: "minecraft:gravel"},
        {pos: [3, 7, 3], state: "minecraft:gravel"},
        {pos: [3, 7, 4], state: "minecraft:mud_bricks"},
        {pos: [4, 7, 4], state: "minecraft:mud_bricks"},
        {pos: [0, 8, 0], state: "minecraft:gravel"},
        {pos: [0, 8, 1], state: "minecraft:mud_bricks"},
        {pos: [0, 8, 2], state: "minecraft:mud_bricks"},
        {pos: [0, 8, 3], state: "minecraft:mud_bricks"},
        {pos: [0, 8, 4], state: "minecraft:mud_bricks"},
        {pos: [1, 8, 0], state: "minecraft:gravel"},
        {pos: [1, 8, 1], state: "minecraft:mud_bricks"},
        {pos: [1, 8, 2], state: "minecraft:gravel"},
        {pos: [1, 8, 3], state: "minecraft:mud_bricks"},
        {pos: [1, 8, 4], state: "minecraft:mud_bricks"},
        {pos: [2, 8, 0], state: "minecraft:gravel"},
        {pos: [2, 8, 1], state: "minecraft:gravel"},
        {pos: [2, 8, 2], state: "minecraft:gravel"},
        {pos: [2, 8, 3], state: "minecraft:mud_bricks"},
        {pos: [2, 8, 4], state: "minecraft:gravel"},
        {pos: [3, 8, 1], state: "minecraft:gravel"},
        {pos: [3, 8, 2], state: "minecraft:gravel"},
        {pos: [3, 8, 3], state: "minecraft:gravel"},
        {pos: [3, 8, 4], state: "minecraft:gravel"},
        {pos: [0, 9, 0], state: "minecraft:gravel"},
        {pos: [0, 9, 1], state: "minecraft:orange_terracotta"},
        {pos: [0, 9, 2], state: "minecraft:orange_terracotta"},
        {pos: [0, 9, 3], state: "minecraft:orange_terracotta"},
        {pos: [0, 9, 4], state: "minecraft:mud_bricks"},
        {pos: [1, 9, 0], state: "minecraft:gravel"},
        {pos: [1, 9, 1], state: "minecraft:mud_brick_stairs{facing:west,half:bottom,shape:straight,waterlogged:false}"},
        {pos: [1, 9, 2], state: "minecraft:mud_brick_stairs{facing:west,half:bottom,shape:straight,waterlogged:false}"},
        {pos: [1, 9, 3], state: "minecraft:mud_brick_stairs{facing:west,half:bottom,shape:straight,waterlogged:false}"},
        {pos: [1, 9, 4], state: "minecraft:orange_terracotta"},
        {pos: [2, 9, 0], state: "minecraft:orange_terracotta"},
        {pos: [2, 9, 1], state: "minecraft:gravel"},
        {pos: [2, 9, 2], state: "minecraft:gravel"},
        {pos: [2, 9, 3], state: "minecraft:gravel"},
        {pos: [2, 9, 4], state: "minecraft:orange_terracotta"},
        {pos: [3, 9, 1], state: "minecraft:gravel"},
        {pos: [3, 9, 2], state: "minecraft:gravel"},
        {pos: [3, 9, 3], state: "minecraft:gravel"},
        {pos: [3, 9, 4], state: "minecraft:gravel"},
        {pos: [4, 9, 1], state: "minecraft:orange_terracotta"},
        {pos: [4, 9, 3], state: "minecraft:orange_terracotta"},
        {pos: [0, 10, 0], state: "minecraft:gravel"},
        {pos: [0, 10, 1], state: "minecraft:gravel"},
        {pos: [0, 10, 2], state: "minecraft:gravel"},
        {pos: [0, 10, 3], state: "minecraft:gravel"},
        {pos: [0, 10, 4], state: "minecraft:mud_bricks"},
        {pos: [1, 10, 0], state: "minecraft:orange_terracotta"},
        {pos: [1, 10, 1], state: "minecraft:gravel"},
        {pos: [1, 10, 2], state: "minecraft:gravel"},
        {pos: [1, 10, 3], state: "minecraft:gravel"},
        {pos: [1, 10, 4], state: "minecraft:orange_terracotta"},
        {pos: [2, 10, 0], state: "minecraft:orange_terracotta"},
        {pos: [2, 10, 1], state: "minecraft:gravel"},
        {pos: [2, 10, 2], state: "minecraft:gravel"},
        {pos: [2, 10, 3], state: "minecraft:gravel"},
        {pos: [2, 10, 4], state: "minecraft:orange_terracotta"},
        {pos: [3, 10, 0], state: "minecraft:orange_terracotta"},
        {pos: [3, 10, 1], state: "minecraft:gravel"},
        {pos: [3, 10, 2], state: "minecraft:gravel"},
        {pos: [3, 10, 3], state: "minecraft:gravel"},
        {pos: [4, 10, 0], state: "minecraft:mud_bricks"},
        {pos: [4, 10, 1], state: "minecraft:orange_terracotta"},
        {pos: [4, 10, 2], state: "minecraft:orange_terracotta"},
        {pos: [4, 10, 3], state: "minecraft:orange_terracotta"},
        {pos: [0, 11, 0], state: "minecraft:gravel"},
        {pos: [0, 11, 1], state: "minecraft:gravel"},
        {pos: [0, 11, 2], state: "minecraft:gravel"},
        {pos: [0, 11, 3], state: "minecraft:gravel"},
        {pos: [0, 11, 4], state: "minecraft:mud_bricks"},
        {pos: [1, 11, 1], state: "minecraft:gravel"},
        {pos: [1, 11, 2], state: "minecraft:gravel"},
        {pos: [1, 11, 3], state: "minecraft:gravel"},
        {pos: [2, 11, 0], state: "minecraft:gravel"},
        {pos: [2, 11, 1], state: "minecraft:gravel"},
        {pos: [2, 11, 2], state: "minecraft:gravel"},
        {pos: [2, 11, 3], state: "minecraft:gravel"},
        {pos: [3, 11, 1], state: "minecraft:gravel"},
        {pos: [3, 11, 2], state: "minecraft:gravel"},
        {pos: [4, 11, 0], state: "minecraft:mud_bricks"},
        {pos: [4, 11, 3], state: "minecraft:gravel"},
        {pos: [0, 12, 0], state: "minecraft:orange_terracotta"},
        {pos: [0, 12, 1], state: "minecraft:gravel"},
        {pos: [0, 12, 2], state: "minecraft:gravel"},
        {pos: [0, 12, 3], state: "minecraft:gravel"},
        {pos: [0, 12, 4], state: "minecraft:orange_terracotta"},
        {pos: [1, 12, 1], state: "minecraft:gravel"},
        {pos: [1, 12, 2], state: "minecraft:gravel"},
        {pos: [1, 12, 3], state: "minecraft:gravel"},
        {pos: [2, 12, 0], state: "minecraft:gravel"},
        {pos: [2, 12, 1], state: "minecraft:gravel"},
        {pos: [2, 12, 2], state: "minecraft:gravel"},
        {pos: [3, 12, 1], state: "minecraft:gravel"},
        {pos: [3, 12, 2], state: "minecraft:gravel"},
        {pos: [4, 12, 0], state: "minecraft:orange_terracotta"},
        {pos: [0, 13, 0], state: "minecraft:mud_bricks"},
        {pos: [0, 13, 1], state: "minecraft:mud_brick_stairs{facing:north,half:top,shape:straight,waterlogged:false}"},
        {pos: [0, 13, 3], state: "minecraft:mud_brick_stairs{facing:south,half:top,shape:straight,waterlogged:false}"},
        {pos: [1, 13, 0], state: "minecraft:mud_brick_stairs{facing:west,half:top,shape:straight,waterlogged:false}"},
        {pos: [1, 13, 1], state: "minecraft:gravel"},
        {pos: [1, 13, 2], state: "minecraft:gravel"},
        {pos: [1, 13, 4], state: "minecraft:mud_brick_stairs{facing:west,half:top,shape:straight,waterlogged:false}"},
        {pos: [2, 13, 0], state: "minecraft:mud_brick_slab{type:top,waterlogged:false}"},
        {pos: [2, 13, 2], state: "minecraft:gravel"},
        {pos: [2, 13, 4], state: "minecraft:mud_brick_slab{type:top,waterlogged:false}"},
        {pos: [1, 14, 1], state: "minecraft:orange_terracotta"},
        {pos: [1, 14, 2], state: "minecraft:orange_terracotta"},
        {pos: [1, 14, 3], state: "minecraft:orange_terracotta"},
        {pos: [2, 14, 1], state: "minecraft:orange_terracotta"},
        {pos: [2, 14, 2], state: "minecraft:orange_terracotta"},
        {pos: [2, 14, 3], state: "minecraft:orange_terracotta"}
    ],
    entities: [],
    palette: [
        "minecraft:mud_bricks",
        "minecraft:gravel",
        "minecraft:orange_terracotta",
        "minecraft:mud_brick_stairs{facing:east,half:bottom,shape:straight,waterlogged:false}",
        "minecraft:mud_brick_stairs{facing:north,half:bottom,shape:straight,waterlogged:false}",
        "minecraft:mud_brick_stairs{facing:west,half:bottom,shape:straight,waterlogged:false}",
        "minecraft:mud_brick_stairs{facing:north,half:top,shape:straight,waterlogged:false}",
        "minecraft:mud_brick_stairs{facing:south,half:top,shape:straight,waterlogged:false}",
        "minecraft:mud_brick_stairs{facing:west,half:top,shape:straight,waterlogged:false}",
        "minecraft:mud_brick_slab{type:top,waterlogged:false}",
        "minecraft:jigsaw{orientation:west_up}"
    ]
}
