{
    size: [9, 6, 11],
    data: [
        {pos: [0, 0, 3], state: "minecraft:mud_bricks"},
        {pos: [0, 0, 4], state: "minecraft:mud_bricks"},
        {pos: [0, 0, 5], state: "minecraft:mud_bricks"},
        {pos: [0, 0, 6], state: "minecraft:mud_bricks"},
        {pos: [0, 0, 7], state: "minecraft:mud_bricks"},
        {pos: [0, 0, 8], state: "minecraft:mud_bricks"},
        {pos: [1, 0, 1], state: "minecraft:mud_bricks"},
        {pos: [1, 0, 2], state: "minecraft:mud_bricks"},
        {pos: [1, 0, 3], state: "minecraft:mud_bricks"},
        {pos: [1, 0, 4], state: "minecraft:mud_bricks"},
        {pos: [1, 0, 5], state: "minecraft:mud_bricks"},
        {pos: [1, 0, 6], state: "minecraft:mud_bricks"},
        {pos: [1, 0, 7], state: "minecraft:mud_bricks"},
        {pos: [1, 0, 8], state: "minecraft:mud_bricks"},
        {pos: [1, 0, 9], state: "minecraft:mud_bricks"},
        {pos: [2, 0, 0], state: "minecraft:mud_bricks"},
        {pos: [2, 0, 1], state: "minecraft:mud_bricks"},
        {pos: [2, 0, 2], state: "minecraft:mud_bricks"},
        {pos: [2, 0, 3], state: "minecraft:mud_bricks"},
        {pos: [2, 0, 4], state: "minecraft:mud_bricks"},
        {pos: [2, 0, 5], state: "minecraft:mud_bricks"},
        {pos: [2, 0, 6], state: "minecraft:mud_bricks"},
        {pos: [2, 0, 7], state: "minecraft:mud_bricks"},
        {pos: [2, 0, 8], state: "minecraft:mud_bricks"},
        {pos: [2, 0, 9], state: "minecraft:mud_bricks"},
        {pos: [3, 0, 0], state: "minecraft:mud_bricks"},
        {pos: [3, 0, 1], state: "minecraft:mud_bricks"},
        {pos: [3, 0, 2], state: "minecraft:mud_bricks"},
        {pos: [3, 0, 3], state: "minecraft:mud_bricks"},
        {pos: [3, 0, 4], state: "minecraft:yellow_glazed_terracotta{facing:west}"},
        {pos: [3, 0, 5], state: "minecraft:yellow_glazed_terracotta{facing:south}"},
        {pos: [3, 0, 6], state: "minecraft:yellow_glazed_terracotta{facing:east}"},
        {pos: [3, 0, 7], state: "minecraft:mud_bricks"},
        {pos: [3, 0, 8], state: "minecraft:mud_bricks"},
        {pos: [3, 0, 9], state: "minecraft:mud_bricks"},
        {pos: [4, 0, 0], state: "minecraft:mud_bricks"},
        {pos: [4, 0, 1], state: "minecraft:mud_bricks"},
        {pos: [4, 0, 2], state: "minecraft:mud_bricks"},
        {pos: [4, 0, 3], state: "minecraft:mud_bricks"},
        {pos: [4, 0, 4], state: "minecraft:yellow_glazed_terracotta{facing:south}"},
        {pos: [4, 0, 5], state: "minecraft:yellow_glazed_terracotta{facing:west}"},
        {pos: [4, 0, 6], state: "minecraft:yellow_glazed_terracotta{facing:north}"},
        {pos: [4, 0, 7], state: "minecraft:mud_bricks"},
        {pos: [4, 0, 8], state: "minecraft:mud_bricks"},
        {pos: [4, 0, 9], state: "minecraft:mud_bricks"},
        {pos: [4, 0, 10], state: "minecraft:mud_bricks"},
        {pos: [5, 0, 0], state: "minecraft:mud_bricks"},
        {pos: [5, 0, 1], state: "minecraft:mud_bricks"},
        {pos: [5, 0, 2], state: "minecraft:mud_bricks"},
        {pos: [5, 0, 3], state: "minecraft:mud_bricks"},
        {pos: [5, 0, 4], state: "minecraft:mud_bricks"},
        {pos: [5, 0, 5], state: "minecraft:mud_bricks"},
        {pos: [5, 0, 6], state: "minecraft:mud_bricks"},
        {pos: [5, 0, 7], state: "minecraft:mud_bricks"},
        {pos: [5, 0, 8], state: "minecraft:mud_bricks"},
        {pos: [5, 0, 9], state: "minecraft:mud_bricks"},
        {pos: [5, 0, 10], state: "minecraft:mud_bricks"},
        {pos: [6, 0, 1], state: "minecraft:mud_bricks"},
        {pos: [6, 0, 2], state: "minecraft:mud_bricks"},
        {pos: [6, 0, 3], state: "minecraft:mud_bricks"},
        {pos: [6, 0, 4], state: "minecraft:mud_bricks"},
        {pos: [6, 0, 5], state: "minecraft:mud_bricks"},
        {pos: [6, 0, 6], state: "minecraft:mud_bricks"},
        {pos: [6, 0, 7], state: "minecraft:mud_bricks"},
        {pos: [6, 0, 8], state: "minecraft:mud_bricks"},
        {pos: [6, 0, 9], state: "minecraft:mud_bricks"},
        {pos: [6, 0, 10], state: "minecraft:mud_bricks"},
        {pos: [7, 0, 4], state: "minecraft:mud_bricks"},
        {pos: [7, 0, 5], state: "minecraft:mud_bricks"},
        {pos: [7, 0, 6], state: "minecraft:mud_bricks"},
        {pos: [7, 0, 7], state: "minecraft:mud_bricks"},
        {pos: [7, 0, 8], state: "minecraft:mud_bricks"},
        {pos: [7, 0, 9], state: "minecraft:mud_bricks"},
        {pos: [7, 0, 10], state: "minecraft:mud_bricks"},
        {pos: [8, 0, 5], state: "minecraft:mud_bricks"},
        {pos: [8, 0, 6], state: "minecraft:mud_bricks"},
        {pos: [8, 0, 7], state: "minecraft:mud_bricks"},
        {pos: [8, 0, 8], state: "minecraft:mud_bricks"},
        {pos: [8, 0, 9], state: "minecraft:mud_bricks"},
        {pos: [8, 0, 10], state: "minecraft:mud_bricks"},
        {pos: [0, 1, 3], state: "minecraft:mud_bricks"},
        {pos: [0, 1, 4], state: "minecraft:mud_bricks"},
        {pos: [0, 1, 5], state: "minecraft:mud_bricks"},
        {pos: [0, 1, 6], state: "minecraft:mud_bricks"},
        {pos: [0, 1, 7], state: "minecraft:mud_bricks"},
        {pos: [0, 1, 8], state: "minecraft:mud_bricks"},
        {pos: [1, 1, 1], state: "minecraft:mud_bricks"},
        {pos: [1, 1, 2], state: "minecraft:mud_bricks"},
        {pos: [1, 1, 3], state: "minecraft:gravel"},
        {pos: [1, 1, 4], state: "minecraft:mud_bricks"},
        {pos: [1, 1, 5], state: "minecraft:red_terracotta"},
        {pos: [1, 1, 6], state: "minecraft:gravel"},
        {pos: [1, 1, 7], state: "minecraft:blue_terracotta"},
        {pos: [1, 1, 8], state: "minecraft:blue_terracotta"},
        {pos: [1, 1, 9], state: "minecraft:mud_bricks"},
        {pos: [2, 1, 0], state: "minecraft:mud_bricks"},
        {pos: [2, 1, 1], state: "minecraft:mud_bricks"},
        {pos: [2, 1, 2], state: "minecraft:mud_bricks"},
        {pos: [2, 1, 3], state: "minecraft:gravel"},
        {pos: [2, 1, 4], state: "minecraft:gravel"},
        {pos: [2, 1, 5], state: "minecraft:gravel"},
        {pos: [2, 1, 6], state: "minecraft:gravel"},
        {pos: [2, 1, 7], state: "minecraft:smooth_stone_slab{type:double,waterlogged:false}"},
        {pos: [2, 1, 8], state: "minecraft:blue_terracotta"},
        {pos: [2, 1, 9], state: "minecraft:mud_bricks"},
        {pos: [3, 1, 0], state: "minecraft:mud_bricks"},
        {pos: [3, 1, 1], state: "minecraft:mud_bricks"},
        {pos: [3, 1, 2], state: "minecraft:mud_brick_stairs{facing:north,half:bottom,shape:straight,waterlogged:false}"},
        {pos: [3, 1, 3], state: "minecraft:gravel"},
        {pos: [3, 1, 4], state: "minecraft:gravel"},
        {pos: [3, 1, 5], state: "minecraft:gravel"},
        {pos: [3, 1, 6], state: "minecraft:gravel"},
        {pos: [3, 1, 7], state: "minecraft:gravel"},
        {pos: [3, 1, 8], state: "minecraft:blue_terracotta"},
        {pos: [3, 1, 9], state: "minecraft:mud_bricks"},
        {pos: [4, 1, 0], state: "minecraft:mud_bricks"},
        {pos: [4, 1, 1], state: "minecraft:mud_bricks"},
        {pos: [4, 1, 2], state: "minecraft:mud_brick_stairs{facing:north,half:bottom,shape:straight,waterlogged:false}"},
        {pos: [4, 1, 3], state: "minecraft:gravel"},
        {pos: [4, 1, 4], state: "minecraft:gravel"},
        {pos: [4, 1, 5], state: "minecraft:gravel"},
        {pos: [4, 1, 6], state: "minecraft:gravel"},
        {pos: [4, 1, 7], state: "minecraft:gravel"},
        {pos: [4, 1, 8], state: "minecraft:gravel"},
        {pos: [4, 1, 9], state: "minecraft:gravel"},
        {pos: [4, 1, 10], state: "minecraft:mud_bricks"},
        {pos: [5, 1, 0], state: "minecraft:mud_bricks"},
        {pos: [5, 1, 1], state: "minecraft:mud_bricks"},
        {pos: [5, 1, 2], state: "minecraft:mud_bricks"},
        {pos: [5, 1, 3], state: "minecraft:gravel"},
        {pos: [5, 1, 4], state: "minecraft:gravel"},
        {pos: [5, 1, 5], state: "minecraft:gravel"},
        {pos: [5, 1, 6], state: "minecraft:gravel"},
        {pos: [5, 1, 7], state: "minecraft:gravel"},
        {pos: [5, 1, 8], state: "minecraft:gravel"},
        {pos: [5, 1, 9], state: "minecraft:gravel"},
        {pos: [5, 1, 10], state: "minecraft:mud_bricks"},
        {pos: [6, 1, 1], state: "minecraft:mud_bricks"},
        {pos: [6, 1, 2], state: "minecraft:mud_bricks"},
        {pos: [6, 1, 3], state: "minecraft:mud_bricks"},
        {pos: [6, 1, 4], state: "minecraft:mud_bricks"},
        {pos: [6, 1, 5], state: "minecraft:gravel"},
        {pos: [6, 1, 6], state: "minecraft:smithing_table"},
        {pos: [6, 1, 7], state: "minecraft:gravel"},
        {pos: [6, 1, 8], state: "minecraft:mud_bricks"},
        {pos: [6, 1, 9], state: "minecraft:blast_furnace{facing:west,lit:false}", nbt: {BurnTime: 0s, CookTime: 0s, CookTimeTotal: 0s, Items: [], RecipesUsed: {}, id: "minecraft:blast_furnace"}},
        {pos: [6, 1, 10], state: "minecraft:mud_bricks"},
        {pos: [7, 1, 4], state: "minecraft:mud_bricks"},
        {pos: [7, 1, 5], state: "minecraft:gravel"},
        {pos: [7, 1, 6], state: "minecraft:gravel"},
        {pos: [7, 1, 7], state: "minecraft:gravel"},
        {pos: [7, 1, 8], state: "minecraft:mud_bricks"},
        {pos: [7, 1, 9], state: "minecraft:gravel"},
        {pos: [7, 1, 10], state: "minecraft:mud_bricks"},
        {pos: [8, 1, 5], state: "minecraft:mud_bricks"},
        {pos: [8, 1, 6], state: "minecraft:mud_bricks"},
        {pos: [8, 1, 7], state: "minecraft:mud_bricks"},
        {pos: [8, 1, 8], state: "minecraft:mud_bricks"},
        {pos: [8, 1, 9], state: "minecraft:mud_bricks"},
        {pos: [8, 1, 10], state: "minecraft:mud_bricks"},
        {pos: [0, 2, 3], state: "minecraft:mud_bricks"},
        {pos: [0, 2, 4], state: "minecraft:mud_bricks"},
        {pos: [0, 2, 5], state: "minecraft:mud_bricks"},
        {pos: [0, 2, 6], state: "minecraft:mud_bricks"},
        {pos: [0, 2, 7], state: "minecraft:mud_bricks"},
        {pos: [0, 2, 8], state: "minecraft:mud_bricks"},
        {pos: [1, 2, 1], state: "minecraft:mud_bricks"},
        {pos: [1, 2, 2], state: "minecraft:mud_bricks"},
        {pos: [1, 2, 3], state: "minecraft:gravel"},
        {pos: [1, 2, 4], state: "minecraft:mud_bricks"},
        {pos: [1, 2, 5], state: "minecraft:gravel"},
        {pos: [1, 2, 6], state: "minecraft:gravel"},
        {pos: [1, 2, 7], state: "minecraft:gravel"},
        {pos: [1, 2, 8], state: "minecraft:blue_terracotta"},
        {pos: [1, 2, 9], state: "minecraft:mud_bricks"},
        {pos: [2, 2, 0], state: "minecraft:mud_bricks"},
        {pos: [2, 2, 1], state: "minecraft:gravel"},
        {pos: [2, 2, 2], state: "minecraft:gravel"},
        {pos: [2, 2, 3], state: "minecraft:gravel"},
        {pos: [2, 2, 4], state: "minecraft:gravel"},
        {pos: [2, 2, 5], state: "minecraft:gravel"},
        {pos: [2, 2, 6], state: "minecraft:gravel"},
        {pos: [2, 2, 7], state: "minecraft:gravel"},
        {pos: [2, 2, 8], state: "minecraft:gravel"},
        {pos: [2, 2, 9], state: "minecraft:mud_bricks"},
        {pos: [3, 2, 0], state: "minecraft:jigsaw{orientation:north_up}", nbt: {final_state: "minecraft:dirt", id: "minecraft:jigsaw", joint: "rollable", name: "minecraft:building_anchor", pool: "minecraft:trail_ruins/roads", target: "minecraft:road_anchor"}},
        {pos: [3, 2, 1], state: "minecraft:gravel"},
        {pos: [3, 2, 2], state: "minecraft:gravel"},
        {pos: [3, 2, 3], state: "minecraft:gravel"},
        {pos: [3, 2, 4], state: "minecraft:gravel"},
        {pos: [3, 2, 5], state: "minecraft:gravel"},
        {pos: [3, 2, 6], state: "minecraft:gravel"},
        {pos: [3, 2, 7], state: "minecraft:gravel"},
        {pos: [3, 2, 8], state: "minecraft:gravel"},
        {pos: [3, 2, 9], state: "minecraft:mud_bricks"},
        {pos: [4, 2, 0], state: "minecraft:gravel"},
        {pos: [4, 2, 1], state: "minecraft:gravel"},
        {pos: [4, 2, 2], state: "minecraft:gravel"},
        {pos: [4, 2, 3], state: "minecraft:gravel"},
        {pos: [4, 2, 4], state: "minecraft:gravel"},
        {pos: [4, 2, 5], state: "minecraft:gravel"},
        {pos: [4, 2, 6], state: "minecraft:gravel"},
        {pos: [4, 2, 7], state: "minecraft:gravel"},
        {pos: [4, 2, 8], state: "minecraft:gravel"},
        {pos: [4, 2, 9], state: "minecraft:gravel"},
        {pos: [4, 2, 10], state: "minecraft:gravel"},
        {pos: [5, 2, 0], state: "minecraft:mud_bricks"},
        {pos: [5, 2, 1], state: "minecraft:blue_terracotta"},
        {pos: [5, 2, 2], state: "minecraft:gravel"},
        {pos: [5, 2, 3], state: "minecraft:gravel"},
        {pos: [5, 2, 4], state: "minecraft:gravel"},
        {pos: [5, 2, 5], state: "minecraft:gravel"},
        {pos: [5, 2, 6], state: "minecraft:gravel"},
        {pos: [5, 2, 7], state: "minecraft:gravel"},
        {pos: [5, 2, 8], state: "minecraft:gravel"},
        {pos: [5, 2, 9], state: "minecraft:gravel"},
        {pos: [5, 2, 10], state: "minecraft:mud_bricks"},
        {pos: [6, 2, 1], state: "minecraft:mud_bricks"},
        {pos: [6, 2, 2], state: "minecraft:mud_bricks"},
        {pos: [6, 2, 3], state: "minecraft:mud_bricks"},
        {pos: [6, 2, 4], state: "minecraft:mud_bricks"},
        {pos: [6, 2, 5], state: "minecraft:gravel"},
        {pos: [6, 2, 6], state: "minecraft:gravel"},
        {pos: [6, 2, 7], state: "minecraft:gravel"},
        {pos: [6, 2, 8], state: "minecraft:gravel"},
        {pos: [6, 2, 9], state: "minecraft:furnace{facing:north,lit:false}", nbt: {BurnTime: 0s, CookTime: 0s, CookTimeTotal: 0s, Items: [], RecipesUsed: {}, id: "minecraft:furnace"}},
        {pos: [6, 2, 10], state: "minecraft:mud_bricks"},
        {pos: [7, 2, 4], state: "minecraft:mud_bricks"},
        {pos: [7, 2, 5], state: "minecraft:gravel"},
        {pos: [7, 2, 6], state: "minecraft:gravel"},
        {pos: [7, 2, 7], state: "minecraft:gravel"},
        {pos: [7, 2, 8], state: "minecraft:gravel"},
        {pos: [7, 2, 9], state: "minecraft:gravel"},
        {pos: [7, 2, 10], state: "minecraft:iron_bars{east:true,north:true,south:false,waterlogged:false,west:true}"},
        {pos: [8, 2, 5], state: "minecraft:mud_bricks"},
        {pos: [8, 2, 6], state: "minecraft:gravel"},
        {pos: [8, 2, 7], state: "minecraft:mud_bricks"},
        {pos: [8, 2, 8], state: "minecraft:mud_bricks"},
        {pos: [8, 2, 9], state: "minecraft:mud_bricks"},
        {pos: [8, 2, 10], state: "minecraft:mud_bricks"},
        {pos: [0, 3, 3], state: "minecraft:red_terracotta"},
        {pos: [0, 3, 4], state: "minecraft:red_terracotta"},
        {pos: [0, 3, 5], state: "minecraft:gravel"},
        {pos: [0, 3, 6], state: "minecraft:red_terracotta"},
        {pos: [0, 3, 7], state: "minecraft:gravel"},
        {pos: [0, 3, 8], state: "minecraft:gravel"},
        {pos: [1, 3, 1], state: "minecraft:red_terracotta"},
        {pos: [1, 3, 2], state: "minecraft:red_terracotta"},
        {pos: [1, 3, 3], state: "minecraft:gravel"},
        {pos: [1, 3, 4], state: "minecraft:mud_bricks"},
        {pos: [1, 3, 5], state: "minecraft:gravel"},
        {pos: [1, 3, 6], state: "minecraft:gravel"},
        {pos: [1, 3, 7], state: "minecraft:gravel"},
        {pos: [1, 3, 8], state: "minecraft:gravel"},
        {pos: [1, 3, 9], state: "minecraft:red_terracotta"},
        {pos: [2, 3, 0], state: "minecraft:red_terracotta"},
        {pos: [2, 3, 1], state: "minecraft:gravel"},
        {pos: [2, 3, 2], state: "minecraft:gravel"},
        {pos: [2, 3, 3], state: "minecraft:gravel"},
        {pos: [2, 3, 4], state: "minecraft:gravel"},
        {pos: [2, 3, 5], state: "minecraft:gravel"},
        {pos: [2, 3, 6], state: "minecraft:gravel"},
        {pos: [2, 3, 7], state: "minecraft:gravel"},
        {pos: [2, 3, 8], state: "minecraft:gravel"},
        {pos: [2, 3, 9], state: "minecraft:red_terracotta"},
        {pos: [3, 3, 0], state: "minecraft:gravel"},
        {pos: [3, 3, 1], state: "minecraft:gravel"},
        {pos: [3, 3, 2], state: "minecraft:gravel"},
        {pos: [3, 3, 3], state: "minecraft:gravel"},
        {pos: [3, 3, 4], state: "minecraft:gravel"},
        {pos: [3, 3, 5], state: "minecraft:gravel"},
        {pos: [3, 3, 6], state: "minecraft:gravel"},
        {pos: [3, 3, 7], state: "minecraft:gravel"},
        {pos: [3, 3, 8], state: "minecraft:gravel"},
        {pos: [3, 3, 9], state: "minecraft:red_terracotta"},
        {pos: [4, 3, 0], state: "minecraft:gravel"},
        {pos: [4, 3, 1], state: "minecraft:gravel"},
        {pos: [4, 3, 2], state: "minecraft:gravel"},
        {pos: [4, 3, 3], state: "minecraft:gravel"},
        {pos: [4, 3, 4], state: "minecraft:gravel"},
        {pos: [4, 3, 5], state: "minecraft:gravel"},
        {pos: [4, 3, 6], state: "minecraft:gravel"},
        {pos: [4, 3, 7], state: "minecraft:gravel"},
        {pos: [4, 3, 8], state: "minecraft:gravel"},
        {pos: [4, 3, 9], state: "minecraft:gravel"},
        {pos: [4, 3, 10], state: "minecraft:gravel"},
        {pos: [5, 3, 0], state: "minecraft:blue_terracotta"},
        {pos: [5, 3, 1], state: "minecraft:gravel"},
        {pos: [5, 3, 2], state: "minecraft:gravel"},
        {pos: [5, 3, 3], state: "minecraft:gravel"},
        {pos: [5, 3, 4], state: "minecraft:gravel"},
        {pos: [5, 3, 5], state: "minecraft:gravel"},
        {pos: [5, 3, 6], state: "minecraft:gravel"},
        {pos: [5, 3, 7], state: "minecraft:gravel"},
        {pos: [5, 3, 8], state: "minecraft:gravel"},
        {pos: [5, 3, 9], state: "minecraft:gravel"},
        {pos: [5, 3, 10], state: "minecraft:red_terracotta"},
        {pos: [6, 3, 1], state: "minecraft:red_terracotta"},
        {pos: [6, 3, 2], state: "minecraft:red_terracotta"},
        {pos: [6, 3, 3], state: "minecraft:red_terracotta"},
        {pos: [6, 3, 4], state: "minecraft:mud_bricks"},
        {pos: [6, 3, 5], state: "minecraft:gravel"},
        {pos: [6, 3, 6], state: "minecraft:gravel"},
        {pos: [6, 3, 7], state: "minecraft:gravel"},
        {pos: [6, 3, 8], state: "minecraft:gravel"},
        {pos: [6, 3, 9], state: "minecraft:mud_bricks"},
        {pos: [6, 3, 10], state: "minecraft:red_terracotta"},
        {pos: [7, 3, 4], state: "minecraft:red_terracotta"},
        {pos: [7, 3, 5], state: "minecraft:gravel"},
        {pos: [7, 3, 6], state: "minecraft:gravel"},
        {pos: [7, 3, 7], state: "minecraft:gravel"},
        {pos: [7, 3, 8], state: "minecraft:gravel"},
        {pos: [7, 3, 9], state: "minecraft:gravel"},
        {pos: [7, 3, 10], state: "minecraft:iron_bars{east:true,north:true,south:false,waterlogged:false,west:true}"},
        {pos: [8, 3, 5], state: "minecraft:red_terracotta"},
        {pos: [8, 3, 6], state: "minecraft:gravel"},
        {pos: [8, 3, 7], state: "minecraft:red_terracotta"},
        {pos: [8, 3, 8], state: "minecraft:red_terracotta"},
        {pos: [8, 3, 9], state: "minecraft:red_terracotta"},
        {pos: [8, 3, 10], state: "minecraft:red_terracotta"},
        {pos: [0, 4, 4], state: "minecraft:blue_terracotta"},
        {pos: [0, 4, 6], state: "minecraft:blue_terracotta"},
        {pos: [1, 4, 1], state: "minecraft:gravel"},
        {pos: [1, 4, 2], state: "minecraft:gravel"},
        {pos: [1, 4, 3], state: "minecraft:gravel"},
        {pos: [1, 4, 4], state: "minecraft:blue_terracotta"},
        {pos: [1, 4, 5], state: "minecraft:gravel"},
        {pos: [1, 4, 6], state: "minecraft:gravel"},
        {pos: [1, 4, 7], state: "minecraft:gravel"},
        {pos: [1, 4, 8], state: "minecraft:gravel"},
        {pos: [1, 4, 9], state: "minecraft:air"},
        {pos: [2, 4, 0], state: "minecraft:gravel"},
        {pos: [2, 4, 1], state: "minecraft:gravel"},
        {pos: [2, 4, 2], state: "minecraft:gravel"},
        {pos: [2, 4, 3], state: "minecraft:gravel"},
        {pos: [2, 4, 4], state: "minecraft:mud_bricks"},
        {pos: [2, 4, 5], state: "minecraft:gravel"},
        {pos: [2, 4, 6], state: "minecraft:gravel"},
        {pos: [2, 4, 7], state: "minecraft:gravel"},
        {pos: [2, 4, 8], state: "minecraft:gravel"},
        {pos: [2, 4, 9], state: "minecraft:air"},
        {pos: [3, 4, 0], state: "minecraft:gravel"},
        {pos: [3, 4, 1], state: "minecraft:gravel"},
        {pos: [3, 4, 2], state: "minecraft:gravel"},
        {pos: [3, 4, 3], state: "minecraft:gravel"},
        {pos: [3, 4, 4], state: "minecraft:mud_bricks"},
        {pos: [3, 4, 5], state: "minecraft:gravel"},
        {pos: [3, 4, 6], state: "minecraft:gravel"},
        {pos: [3, 4, 7], state: "minecraft:gravel"},
        {pos: [3, 4, 8], state: "minecraft:gravel"},
        {pos: [3, 4, 9], state: "minecraft:air"},
        {pos: [4, 4, 0], state: "minecraft:gravel"},
        {pos: [4, 4, 1], state: "minecraft:gravel"},
        {pos: [4, 4, 2], state: "minecraft:gravel"},
        {pos: [4, 4, 3], state: "minecraft:gravel"},
        {pos: [4, 4, 4], state: "minecraft:mud_bricks"},
        {pos: [4, 4, 5], state: "minecraft:gravel"},
        {pos: [4, 4, 6], state: "minecraft:gravel"},
        {pos: [4, 4, 7], state: "minecraft:gravel"},
        {pos: [4, 4, 8], state: "minecraft:gravel"},
        {pos: [4, 4, 9], state: "minecraft:air"},
        {pos: [4, 4, 10], state: "minecraft:air"},
        {pos: [5, 4, 1], state: "minecraft:gravel"},
        {pos: [5, 4, 2], state: "minecraft:gravel"},
        {pos: [5, 4, 3], state: "minecraft:gravel"},
        {pos: [5, 4, 4], state: "minecraft:mud_bricks"},
        {pos: [5, 4, 5], state: "minecraft:gravel"},
        {pos: [5, 4, 6], state: "minecraft:gravel"},
        {pos: [5, 4, 7], state: "minecraft:gravel"},
        {pos: [5, 4, 8], state: "minecraft:gravel"},
        {pos: [5, 4, 9], state: "minecraft:air"},
        {pos: [5, 4, 10], state: "minecraft:air"},
        {pos: [6, 4, 1], state: "minecraft:gravel"},
        {pos: [6, 4, 2], state: "minecraft:blue_terracotta"},
        {pos: [6, 4, 3], state: "minecraft:gravel"},
        {pos: [6, 4, 4], state: "minecraft:blue_terracotta"},
        {pos: [6, 4, 5], state: "minecraft:mud_bricks"},
        {pos: [6, 4, 6], state: "minecraft:mud_bricks"},
        {pos: [6, 4, 7], state: "minecraft:mud_bricks"},
        {pos: [6, 4, 8], state: "minecraft:mud_bricks"},
        {pos: [6, 4, 9], state: "minecraft:blue_terracotta"},
        {pos: [6, 4, 10], state: "minecraft:blue_terracotta"},
        {pos: [7, 4, 4], state: "minecraft:gravel"},
        {pos: [7, 4, 5], state: "minecraft:gravel"},
        {pos: [7, 4, 6], state: "minecraft:gravel"},
        {pos: [7, 4, 7], state: "minecraft:gravel"},
        {pos: [7, 4, 8], state: "minecraft:gravel"},
        {pos: [7, 4, 9], state: "minecraft:air"},
        {pos: [7, 4, 10], state: "minecraft:air"},
        {pos: [8, 4, 6], state: "minecraft:gravel"},
        {pos: [8, 4, 7], state: "minecraft:gravel"},
        {pos: [8, 4, 8], state: "minecraft:blue_terracotta"},
        {pos: [8, 4, 9], state: "minecraft:blue_terracotta"},
        {pos: [8, 4, 10], state: "minecraft:air"},
        {pos: [1, 5, 4], state: "minecraft:blue_terracotta"},
        {pos: [2, 5, 3], state: "minecraft:blue_terracotta"},
        {pos: [2, 5, 4], state: "minecraft:blue_terracotta"},
        {pos: [2, 5, 5], state: "minecraft:blue_terracotta"},
        {pos: [3, 5, 2], state: "minecraft:blue_terracotta"},
        {pos: [3, 5, 3], state: "minecraft:blue_terracotta"},
        {pos: [3, 5, 4], state: "minecraft:blue_terracotta"},
        {pos: [3, 5, 5], state: "minecraft:blue_terracotta"},
        {pos: [3, 5, 6], state: "minecraft:blue_terracotta"},
        {pos: [4, 5, 2], state: "minecraft:blue_terracotta"},
        {pos: [4, 5, 3], state: "minecraft:blue_terracotta"},
        {pos: [4, 5, 4], state: "minecraft:blue_terracotta"},
        {pos: [4, 5, 5], state: "minecraft:blue_terracotta"},
        {pos: [4, 5, 6], state: "minecraft:blue_terracotta"},
        {pos: [4, 5, 7], state: "minecraft:blue_terracotta"},
        {pos: [5, 5, 3], state: "minecraft:blue_terracotta"},
        {pos: [5, 5, 4], state: "minecraft:blue_terracotta"},
        {pos: [5, 5, 5], state: "minecraft:blue_terracotta"},
        {pos: [5, 5, 6], state: "minecraft:blue_terracotta"},
        {pos: [5, 5, 7], state: "minecraft:blue_terracotta"},
        {pos: [6, 5, 6], state: "minecraft:blue_terracotta"},
        {pos: [6, 5, 7], state: "minecraft:blue_terracotta"},
        {pos: [7, 5, 7], state: "minecraft:blue_terracotta"}
    ],
    entities: [],
    palette: [
        "minecraft:mud_bricks",
        "minecraft:yellow_glazed_terracotta{facing:west}",
        "minecraft:yellow_glazed_terracotta{facing:south}",
        "minecraft:yellow_glazed_terracotta{facing:east}",
        "minecraft:yellow_glazed_terracotta{facing:north}",
        "minecraft:gravel",
        "minecraft:red_terracotta",
        "minecraft:blue_terracotta",
        "minecraft:smooth_stone_slab{type:double,waterlogged:false}",
        "minecraft:smithing_table",
        "minecraft:mud_brick_stairs{facing:north,half:bottom,shape:straight,waterlogged:false}",
        "minecraft:iron_bars{east:true,north:true,south:false,waterlogged:false,west:true}",
        "minecraft:air",
        "minecraft:blast_furnace{facing:west,lit:false}",
        "minecraft:jigsaw{orientation:north_up}",
        "minecraft:furnace{facing:north,lit:false}"
    ]
}
