{
    size: [13, 15, 9],
    data: [
        {pos: [3, 2, 4], state: "minecraft:mud_bricks"},
        {pos: [4, 2, 3], state: "minecraft:mud_bricks"},
        {pos: [4, 2, 4], state: "minecraft:mud_bricks"},
        {pos: [4, 2, 5], state: "minecraft:mud_bricks"},
        {pos: [5, 2, 3], state: "minecraft:mud_bricks"},
        {pos: [5, 2, 4], state: "minecraft:mud_bricks"},
        {pos: [5, 2, 5], state: "minecraft:mud_bricks"},
        {pos: [6, 2, 3], state: "minecraft:mud_bricks"},
        {pos: [6, 2, 4], state: "minecraft:mud_bricks"},
        {pos: [6, 2, 5], state: "minecraft:mud_bricks"},
        {pos: [7, 2, 3], state: "minecraft:mud_bricks"},
        {pos: [7, 2, 4], state: "minecraft:mud_bricks"},
        {pos: [7, 2, 5], state: "minecraft:mud_bricks"},
        {pos: [8, 2, 3], state: "minecraft:mud_bricks"},
        {pos: [8, 2, 4], state: "minecraft:mud_bricks"},
        {pos: [8, 2, 5], state: "minecraft:mud_bricks"},
        {pos: [9, 2, 4], state: "minecraft:mud_bricks"},
        {pos: [2, 3, 3], state: "minecraft:mud_bricks"},
        {pos: [2, 3, 4], state: "minecraft:mud_bricks"},
        {pos: [2, 3, 5], state: "minecraft:mud_bricks"},
        {pos: [3, 3, 3], state: "minecraft:mud_bricks"},
        {pos: [3, 3, 4], state: "minecraft:gravel"},
        {pos: [3, 3, 5], state: "minecraft:mud_bricks"},
        {pos: [4, 3, 2], state: "minecraft:mud_bricks"},
        {pos: [4, 3, 3], state: "minecraft:gravel"},
        {pos: [4, 3, 4], state: "minecraft:mud_bricks"},
        {pos: [4, 3, 5], state: "minecraft:mud_bricks"},
        {pos: [4, 3, 6], state: "minecraft:mud_bricks"},
        {pos: [5, 3, 2], state: "minecraft:mud_bricks"},
        {pos: [5, 3, 3], state: "minecraft:gravel"},
        {pos: [5, 3, 4], state: "minecraft:gravel"},
        {pos: [5, 3, 5], state: "minecraft:gravel"},
        {pos: [5, 3, 6], state: "minecraft:mud_bricks"},
        {pos: [6, 3, 2], state: "minecraft:mud_bricks"},
        {pos: [6, 3, 3], state: "minecraft:gravel"},
        {pos: [6, 3, 4], state: "minecraft:gravel"},
        {pos: [6, 3, 5], state: "minecraft:gravel"},
        {pos: [6, 3, 6], state: "minecraft:mud_bricks"},
        {pos: [7, 3, 2], state: "minecraft:mud_bricks"},
        {pos: [7, 3, 3], state: "minecraft:gravel"},
        {pos: [7, 3, 4], state: "minecraft:cauldron"},
        {pos: [7, 3, 5], state: "minecraft:gravel"},
        {pos: [7, 3, 6], state: "minecraft:mud_bricks"},
        {pos: [8, 3, 2], state: "minecraft:mud_bricks"},
        {pos: [8, 3, 3], state: "minecraft:gravel"},
        {pos: [8, 3, 4], state: "minecraft:gravel"},
        {pos: [8, 3, 5], state: "minecraft:gravel"},
        {pos: [8, 3, 6], state: "minecraft:mud_bricks"},
        {pos: [9, 3, 3], state: "minecraft:mud_bricks"},
        {pos: [9, 3, 4], state: "minecraft:gravel"},
        {pos: [9, 3, 5], state: "minecraft:mud_bricks"},
        {pos: [10, 3, 3], state: "minecraft:mud_bricks"},
        {pos: [10, 3, 4], state: "minecraft:mud_bricks"},
        {pos: [2, 4, 3], state: "minecraft:mud_bricks"},
        {pos: [2, 4, 4], state: "minecraft:mud_bricks"},
        {pos: [2, 4, 5], state: "minecraft:mud_bricks"},
        {pos: [3, 4, 3], state: "minecraft:mud_bricks"},
        {pos: [3, 4, 4], state: "minecraft:mud_bricks"},
        {pos: [3, 4, 5], state: "minecraft:mud_bricks"},
        {pos: [4, 4, 2], state: "minecraft:mud_bricks"},
        {pos: [4, 4, 3], state: "minecraft:gravel"},
        {pos: [4, 4, 4], state: "minecraft:gravel"},
        {pos: [4, 4, 5], state: "minecraft:mud_bricks"},
        {pos: [4, 4, 6], state: "minecraft:mud_bricks"},
        {pos: [5, 4, 2], state: "minecraft:mud_bricks"},
        {pos: [5, 4, 3], state: "minecraft:gravel"},
        {pos: [5, 4, 4], state: "minecraft:gravel"},
        {pos: [5, 4, 5], state: "minecraft:gravel"},
        {pos: [5, 4, 6], state: "minecraft:mud_bricks"},
        {pos: [6, 4, 2], state: "minecraft:mud_bricks"},
        {pos: [6, 4, 3], state: "minecraft:gravel"},
        {pos: [6, 4, 4], state: "minecraft:gravel"},
        {pos: [6, 4, 5], state: "minecraft:gravel"},
        {pos: [6, 4, 6], state: "minecraft:mud_bricks"},
        {pos: [7, 4, 2], state: "minecraft:mud_bricks"},
        {pos: [7, 4, 3], state: "minecraft:gravel"},
        {pos: [7, 4, 4], state: "minecraft:gravel"},
        {pos: [7, 4, 5], state: "minecraft:gravel"},
        {pos: [7, 4, 6], state: "minecraft:mud_bricks"},
        {pos: [8, 4, 2], state: "minecraft:mud_bricks"},
        {pos: [8, 4, 3], state: "minecraft:gravel"},
        {pos: [8, 4, 4], state: "minecraft:gravel"},
        {pos: [8, 4, 5], state: "minecraft:gravel"},
        {pos: [8, 4, 6], state: "minecraft:mud_bricks"},
        {pos: [9, 4, 3], state: "minecraft:mud_bricks"},
        {pos: [9, 4, 4], state: "minecraft:gravel"},
        {pos: [9, 4, 5], state: "minecraft:mud_bricks"},
        {pos: [10, 4, 3], state: "minecraft:mud_bricks"},
        {pos: [10, 4, 4], state: "minecraft:mud_bricks"},
        {pos: [2, 5, 3], state: "minecraft:mud_bricks"},
        {pos: [2, 5, 4], state: "minecraft:mud_bricks"},
        {pos: [2, 5, 5], state: "minecraft:mud_bricks"},
        {pos: [3, 5, 3], state: "minecraft:mud_bricks"},
        {pos: [3, 5, 4], state: "minecraft:white_terracotta"},
        {pos: [3, 5, 5], state: "minecraft:mud_bricks"},
        {pos: [4, 5, 2], state: "minecraft:mud_bricks"},
        {pos: [4, 5, 3], state: "minecraft:gravel"},
        {pos: [4, 5, 4], state: "minecraft:gravel"},
        {pos: [4, 5, 5], state: "minecraft:mud_bricks"},
        {pos: [4, 5, 6], state: "minecraft:mud_bricks"},
        {pos: [5, 5, 2], state: "minecraft:mud_bricks"},
        {pos: [5, 5, 3], state: "minecraft:gravel"},
        {pos: [5, 5, 4], state: "minecraft:gravel"},
        {pos: [5, 5, 5], state: "minecraft:gravel"},
        {pos: [5, 5, 6], state: "minecraft:mud_bricks"},
        {pos: [6, 5, 2], state: "minecraft:mud_bricks"},
        {pos: [6, 5, 3], state: "minecraft:gravel"},
        {pos: [6, 5, 4], state: "minecraft:gravel"},
        {pos: [6, 5, 5], state: "minecraft:gravel"},
        {pos: [6, 5, 6], state: "minecraft:mud_bricks"},
        {pos: [7, 5, 2], state: "minecraft:gravel"},
        {pos: [7, 5, 3], state: "minecraft:gravel"},
        {pos: [7, 5, 4], state: "minecraft:gravel"},
        {pos: [7, 5, 5], state: "minecraft:mud_bricks"},
        {pos: [7, 5, 6], state: "minecraft:mud_bricks"},
        {pos: [8, 5, 2], state: "minecraft:mud_bricks"},
        {pos: [8, 5, 3], state: "minecraft:gravel"},
        {pos: [8, 5, 4], state: "minecraft:gravel"},
        {pos: [8, 5, 5], state: "minecraft:gravel"},
        {pos: [8, 5, 6], state: "minecraft:mud_bricks"},
        {pos: [9, 5, 3], state: "minecraft:gravel"},
        {pos: [9, 5, 4], state: "minecraft:gravel"},
        {pos: [9, 5, 5], state: "minecraft:gravel"},
        {pos: [10, 5, 3], state: "minecraft:mud_bricks"},
        {pos: [10, 5, 4], state: "minecraft:mud_bricks"},
        {pos: [1, 6, 3], state: "minecraft:mud_bricks"},
        {pos: [1, 6, 4], state: "minecraft:mud_bricks"},
        {pos: [1, 6, 5], state: "minecraft:mud_bricks"},
        {pos: [2, 6, 2], state: "minecraft:mud_bricks"},
        {pos: [2, 6, 3], state: "minecraft:mud_bricks"},
        {pos: [2, 6, 4], state: "minecraft:gravel"},
        {pos: [2, 6, 5], state: "minecraft:gravel"},
        {pos: [2, 6, 6], state: "minecraft:mud_bricks"},
        {pos: [3, 6, 2], state: "minecraft:mud_bricks"},
        {pos: [3, 6, 3], state: "minecraft:gravel"},
        {pos: [3, 6, 4], state: "minecraft:gravel"},
        {pos: [3, 6, 5], state: "minecraft:white_terracotta"},
        {pos: [3, 6, 6], state: "minecraft:mud_bricks"},
        {pos: [4, 6, 1], state: "minecraft:mud_bricks"},
        {pos: [4, 6, 2], state: "minecraft:gravel"},
        {pos: [4, 6, 3], state: "minecraft:gravel"},
        {pos: [4, 6, 4], state: "minecraft:gravel"},
        {pos: [4, 6, 5], state: "minecraft:gravel"},
        {pos: [4, 6, 6], state: "minecraft:gravel"},
        {pos: [4, 6, 7], state: "minecraft:mud_bricks"},
        {pos: [5, 6, 1], state: "minecraft:mud_bricks"},
        {pos: [5, 6, 2], state: "minecraft:gravel"},
        {pos: [5, 6, 3], state: "minecraft:gravel"},
        {pos: [5, 6, 4], state: "minecraft:gravel"},
        {pos: [5, 6, 5], state: "minecraft:gravel"},
        {pos: [5, 6, 6], state: "minecraft:gravel"},
        {pos: [5, 6, 7], state: "minecraft:mud_bricks"},
        {pos: [6, 6, 1], state: "minecraft:mud_bricks"},
        {pos: [6, 6, 2], state: "minecraft:gravel"},
        {pos: [6, 6, 3], state: "minecraft:gravel"},
        {pos: [6, 6, 4], state: "minecraft:gravel"},
        {pos: [6, 6, 5], state: "minecraft:gravel"},
        {pos: [6, 6, 6], state: "minecraft:gravel"},
        {pos: [6, 6, 7], state: "minecraft:mud_bricks"},
        {pos: [7, 6, 1], state: "minecraft:mud_bricks"},
        {pos: [7, 6, 2], state: "minecraft:gravel"},
        {pos: [7, 6, 3], state: "minecraft:gravel"},
        {pos: [7, 6, 4], state: "minecraft:gravel"},
        {pos: [7, 6, 5], state: "minecraft:gravel"},
        {pos: [7, 6, 6], state: "minecraft:gravel"},
        {pos: [7, 6, 7], state: "minecraft:mud_bricks"},
        {pos: [8, 6, 1], state: "minecraft:mud_bricks"},
        {pos: [8, 6, 2], state: "minecraft:gravel"},
        {pos: [8, 6, 3], state: "minecraft:gravel"},
        {pos: [8, 6, 4], state: "minecraft:gravel"},
        {pos: [8, 6, 5], state: "minecraft:gravel"},
        {pos: [8, 6, 6], state: "minecraft:gravel"},
        {pos: [8, 6, 7], state: "minecraft:mud_bricks"},
        {pos: [9, 6, 3], state: "minecraft:gravel"},
        {pos: [9, 6, 4], state: "minecraft:gravel"},
        {pos: [9, 6, 5], state: "minecraft:gravel"},
        {pos: [9, 6, 6], state: "minecraft:mud_bricks"},
        {pos: [10, 6, 3], state: "minecraft:gravel"},
        {pos: [10, 6, 4], state: "minecraft:gravel"},
        {pos: [10, 6, 6], state: "minecraft:mud_bricks"},
        {pos: [11, 6, 4], state: "minecraft:mud_bricks"},
        {pos: [11, 6, 5], state: "minecraft:mud_bricks"},
        {pos: [1, 7, 3], state: "minecraft:mud_bricks"},
        {pos: [1, 7, 4], state: "minecraft:mud_bricks"},
        {pos: [1, 7, 5], state: "minecraft:mud_bricks"},
        {pos: [2, 7, 2], state: "minecraft:mud_bricks"},
        {pos: [2, 7, 3], state: "minecraft:gravel"},
        {pos: [2, 7, 4], state: "minecraft:gravel"},
        {pos: [2, 7, 5], state: "minecraft:gravel"},
        {pos: [2, 7, 6], state: "minecraft:mud_bricks"},
        {pos: [3, 7, 2], state: "minecraft:mud_bricks"},
        {pos: [3, 7, 3], state: "minecraft:gravel"},
        {pos: [3, 7, 4], state: "minecraft:gravel"},
        {pos: [3, 7, 5], state: "minecraft:gravel"},
        {pos: [3, 7, 6], state: "minecraft:mud_bricks"},
        {pos: [4, 7, 1], state: "minecraft:mud_bricks"},
        {pos: [4, 7, 2], state: "minecraft:mud_bricks"},
        {pos: [4, 7, 3], state: "minecraft:gravel"},
        {pos: [4, 7, 4], state: "minecraft:gravel"},
        {pos: [4, 7, 5], state: "minecraft:gravel"},
        {pos: [4, 7, 6], state: "minecraft:gravel"},
        {pos: [4, 7, 7], state: "minecraft:mud_bricks"},
        {pos: [5, 7, 1], state: "minecraft:mud_bricks"},
        {pos: [5, 7, 2], state: "minecraft:gravel"},
        {pos: [5, 7, 3], state: "minecraft:gravel"},
        {pos: [5, 7, 4], state: "minecraft:gravel"},
        {pos: [5, 7, 5], state: "minecraft:gravel"},
        {pos: [5, 7, 6], state: "minecraft:gravel"},
        {pos: [5, 7, 7], state: "minecraft:mud_bricks"},
        {pos: [6, 7, 1], state: "minecraft:mud_bricks"},
        {pos: [6, 7, 2], state: "minecraft:gravel"},
        {pos: [6, 7, 3], state: "minecraft:gravel"},
        {pos: [6, 7, 4], state: "minecraft:gravel"},
        {pos: [6, 7, 5], state: "minecraft:gravel"},
        {pos: [6, 7, 6], state: "minecraft:gravel"},
        {pos: [6, 7, 7], state: "minecraft:mud_bricks"},
        {pos: [7, 7, 1], state: "minecraft:mud_bricks"},
        {pos: [7, 7, 2], state: "minecraft:gravel"},
        {pos: [7, 7, 3], state: "minecraft:gravel"},
        {pos: [7, 7, 4], state: "minecraft:gravel"},
        {pos: [7, 7, 5], state: "minecraft:gravel"},
        {pos: [7, 7, 6], state: "minecraft:gravel"},
        {pos: [7, 7, 7], state: "minecraft:mud_bricks"},
        {pos: [8, 7, 1], state: "minecraft:mud_bricks"},
        {pos: [8, 7, 2], state: "minecraft:gravel"},
        {pos: [8, 7, 3], state: "minecraft:gravel"},
        {pos: [8, 7, 4], state: "minecraft:gravel"},
        {pos: [8, 7, 5], state: "minecraft:gravel"},
        {pos: [8, 7, 6], state: "minecraft:gravel"},
        {pos: [8, 7, 7], state: "minecraft:mud_bricks"},
        {pos: [9, 7, 2], state: "minecraft:mud_bricks"},
        {pos: [9, 7, 3], state: "minecraft:gravel"},
        {pos: [9, 7, 4], state: "minecraft:gravel"},
        {pos: [9, 7, 5], state: "minecraft:gravel"},
        {pos: [9, 7, 6], state: "minecraft:mud_bricks"},
        {pos: [10, 7, 2], state: "minecraft:mud_bricks"},
        {pos: [10, 7, 4], state: "minecraft:gravel"},
        {pos: [10, 7, 6], state: "minecraft:mud_bricks"},
        {pos: [11, 7, 3], state: "minecraft:mud_bricks"},
        {pos: [11, 7, 4], state: "minecraft:mud_bricks"},
        {pos: [11, 7, 5], state: "minecraft:mud_bricks"},
        {pos: [0, 8, 4], state: "minecraft:mud_bricks"},
        {pos: [0, 8, 5], state: "minecraft:mud_bricks"},
        {pos: [1, 8, 3], state: "minecraft:gravel"},
        {pos: [1, 8, 4], state: "minecraft:gravel"},
        {pos: [1, 8, 5], state: "minecraft:gravel"},
        {pos: [1, 8, 6], state: "minecraft:mud_bricks"},
        {pos: [2, 8, 1], state: "minecraft:mud_bricks"},
        {pos: [2, 8, 2], state: "minecraft:gravel"},
        {pos: [2, 8, 3], state: "minecraft:gravel"},
        {pos: [2, 8, 4], state: "minecraft:gravel"},
        {pos: [2, 8, 5], state: "minecraft:gravel"},
        {pos: [2, 8, 6], state: "minecraft:mud_bricks"},
        {pos: [2, 8, 7], state: "minecraft:mud_bricks"},
        {pos: [3, 8, 1], state: "minecraft:mud_bricks"},
        {pos: [3, 8, 2], state: "minecraft:gravel"},
        {pos: [3, 8, 3], state: "minecraft:gravel"},
        {pos: [3, 8, 4], state: "minecraft:gravel"},
        {pos: [3, 8, 5], state: "minecraft:mud_bricks"},
        {pos: [3, 8, 6], state: "minecraft:mud_bricks"},
        {pos: [3, 8, 7], state: "minecraft:mud_bricks"},
        {pos: [4, 8, 0], state: "minecraft:mud_bricks"},
        {pos: [4, 8, 1], state: "minecraft:mud_bricks"},
        {pos: [4, 8, 2], state: "minecraft:gravel"},
        {pos: [4, 8, 3], state: "minecraft:gravel"},
        {pos: [4, 8, 4], state: "minecraft:yellow_terracotta"},
        {pos: [4, 8, 5], state: "minecraft:mud_bricks"},
        {pos: [4, 8, 6], state: "minecraft:mud_bricks"},
        {pos: [4, 8, 7], state: "minecraft:mud_bricks"},
        {pos: [4, 8, 8], state: "minecraft:mud_bricks"},
        {pos: [5, 8, 0], state: "minecraft:mud_bricks"},
        {pos: [5, 8, 1], state: "minecraft:mud_bricks"},
        {pos: [5, 8, 2], state: "minecraft:mud_bricks"},
        {pos: [5, 8, 3], state: "minecraft:yellow_terracotta"},
        {pos: [5, 8, 4], state: "minecraft:orange_terracotta"},
        {pos: [5, 8, 5], state: "minecraft:yellow_terracotta"},
        {pos: [5, 8, 6], state: "minecraft:mud_bricks"},
        {pos: [5, 8, 7], state: "minecraft:mud_bricks"},
        {pos: [5, 8, 8], state: "minecraft:mud_bricks"},
        {pos: [6, 8, 0], state: "minecraft:mud_bricks"},
        {pos: [6, 8, 1], state: "minecraft:mud_bricks"},
        {pos: [6, 8, 2], state: "minecraft:yellow_terracotta"},
        {pos: [6, 8, 3], state: "minecraft:orange_terracotta"},
        {pos: [6, 8, 4], state: "minecraft:white_terracotta"},
        {pos: [6, 8, 5], state: "minecraft:orange_terracotta"},
        {pos: [6, 8, 6], state: "minecraft:yellow_terracotta"},
        {pos: [6, 8, 7], state: "minecraft:mud_bricks"},
        {pos: [6, 8, 8], state: "minecraft:mud_bricks"},
        {pos: [7, 8, 0], state: "minecraft:mud_bricks"},
        {pos: [7, 8, 1], state: "minecraft:yellow_terracotta"},
        {pos: [7, 8, 2], state: "minecraft:orange_terracotta"},
        {pos: [7, 8, 3], state: "minecraft:white_terracotta"},
        {pos: [7, 8, 4], state: "minecraft:white_terracotta"},
        {pos: [7, 8, 5], state: "minecraft:white_terracotta"},
        {pos: [7, 8, 6], state: "minecraft:orange_terracotta"},
        {pos: [7, 8, 7], state: "minecraft:yellow_terracotta"},
        {pos: [7, 8, 8], state: "minecraft:mud_bricks"},
        {pos: [8, 8, 0], state: "minecraft:mud_bricks"},
        {pos: [8, 8, 1], state: "minecraft:mud_bricks"},
        {pos: [8, 8, 2], state: "minecraft:yellow_terracotta"},
        {pos: [8, 8, 3], state: "minecraft:orange_terracotta"},
        {pos: [8, 8, 4], state: "minecraft:white_terracotta"},
        {pos: [8, 8, 5], state: "minecraft:orange_terracotta"},
        {pos: [8, 8, 6], state: "minecraft:yellow_terracotta"},
        {pos: [8, 8, 7], state: "minecraft:mud_bricks"},
        {pos: [8, 8, 8], state: "minecraft:mud_bricks"},
        {pos: [9, 8, 1], state: "minecraft:mud_bricks"},
        {pos: [9, 8, 2], state: "minecraft:mud_bricks"},
        {pos: [9, 8, 3], state: "minecraft:yellow_terracotta"},
        {pos: [9, 8, 4], state: "minecraft:orange_terracotta"},
        {pos: [9, 8, 5], state: "minecraft:yellow_terracotta"},
        {pos: [9, 8, 6], state: "minecraft:mud_bricks"},
        {pos: [9, 8, 7], state: "minecraft:mud_bricks"},
        {pos: [10, 8, 1], state: "minecraft:mud_bricks"},
        {pos: [10, 8, 2], state: "minecraft:mud_bricks"},
        {pos: [10, 8, 3], state: "minecraft:mud_bricks"},
        {pos: [10, 8, 4], state: "minecraft:yellow_terracotta"},
        {pos: [10, 8, 5], state: "minecraft:mud_bricks"},
        {pos: [10, 8, 6], state: "minecraft:mud_bricks"},
        {pos: [10, 8, 7], state: "minecraft:mud_bricks"},
        {pos: [11, 8, 2], state: "minecraft:mud_bricks"},
        {pos: [11, 8, 3], state: "minecraft:mud_bricks"},
        {pos: [11, 8, 4], state: "minecraft:mud_bricks"},
        {pos: [11, 8, 5], state: "minecraft:mud_bricks"},
        {pos: [11, 8, 6], state: "minecraft:mud_bricks"},
        {pos: [12, 8, 3], state: "minecraft:mud_bricks"},
        {pos: [12, 8, 4], state: "minecraft:mud_bricks"},
        {pos: [12, 8, 5], state: "minecraft:mud_bricks"},
        {pos: [0, 9, 4], state: "minecraft:mud_bricks"},
        {pos: [0, 9, 5], state: "minecraft:mud_bricks"},
        {pos: [1, 9, 3], state: "minecraft:gravel"},
        {pos: [1, 9, 5], state: "minecraft:gravel"},
        {pos: [1, 9, 6], state: "minecraft:mud_bricks"},
        {pos: [2, 9, 1], state: "minecraft:mud_bricks"},
        {pos: [2, 9, 2], state: "minecraft:gravel"},
        {pos: [2, 9, 3], state: "minecraft:gravel"},
        {pos: [2, 9, 4], state: "minecraft:gravel"},
        {pos: [2, 9, 5], state: "minecraft:gravel"},
        {pos: [2, 9, 6], state: "minecraft:gravel"},
        {pos: [2, 9, 7], state: "minecraft:mud_bricks"},
        {pos: [3, 9, 1], state: "minecraft:mud_bricks"},
        {pos: [3, 9, 2], state: "minecraft:gravel"},
        {pos: [3, 9, 3], state: "minecraft:gravel"},
        {pos: [3, 9, 4], state: "minecraft:gravel"},
        {pos: [3, 9, 5], state: "minecraft:gravel"},
        {pos: [3, 9, 6], state: "minecraft:gravel"},
        {pos: [3, 9, 7], state: "minecraft:mud_bricks"},
        {pos: [4, 9, 0], state: "minecraft:mud_bricks"},
        {pos: [4, 9, 1], state: "minecraft:gravel"},
        {pos: [4, 9, 2], state: "minecraft:gravel"},
        {pos: [4, 9, 3], state: "minecraft:gravel"},
        {pos: [4, 9, 4], state: "minecraft:gravel"},
        {pos: [4, 9, 5], state: "minecraft:gravel"},
        {pos: [4, 9, 6], state: "minecraft:gravel"},
        {pos: [4, 9, 7], state: "minecraft:gravel"},
        {pos: [4, 9, 8], state: "minecraft:mud_bricks"},
        {pos: [5, 9, 0], state: "minecraft:mud_bricks"},
        {pos: [5, 9, 1], state: "minecraft:gravel"},
        {pos: [5, 9, 2], state: "minecraft:gravel"},
        {pos: [5, 9, 3], state: "minecraft:gravel"},
        {pos: [5, 9, 4], state: "minecraft:gravel"},
        {pos: [5, 9, 5], state: "minecraft:gravel"},
        {pos: [5, 9, 6], state: "minecraft:gravel"},
        {pos: [5, 9, 7], state: "minecraft:gravel"},
        {pos: [5, 9, 8], state: "minecraft:mud_bricks"},
        {pos: [6, 9, 0], state: "minecraft:jigsaw{orientation:north_up}", nbt: {final_state: "minecraft:dirt", id: "minecraft:jigsaw", joint: "rollable", name: "minecraft:building_anchor", pool: "minecraft:trail_ruins/roads", target: "minecraft:road_anchor"}},
        {pos: [6, 9, 1], state: "minecraft:gravel"},
        {pos: [6, 9, 2], state: "minecraft:gravel"},
        {pos: [6, 9, 3], state: "minecraft:gravel"},
        {pos: [6, 9, 4], state: "minecraft:gravel"},
        {pos: [6, 9, 5], state: "minecraft:gravel"},
        {pos: [6, 9, 6], state: "minecraft:gravel"},
        {pos: [6, 9, 7], state: "minecraft:gravel"},
        {pos: [6, 9, 8], state: "minecraft:mud_bricks"},
        {pos: [7, 9, 0], state: "minecraft:mud_bricks"},
        {pos: [7, 9, 1], state: "minecraft:gravel"},
        {pos: [7, 9, 2], state: "minecraft:gravel"},
        {pos: [7, 9, 3], state: "minecraft:gravel"},
        {pos: [7, 9, 4], state: "minecraft:loom{facing:west}"},
        {pos: [7, 9, 5], state: "minecraft:gravel"},
        {pos: [7, 9, 6], state: "minecraft:gravel"},
        {pos: [7, 9, 7], state: "minecraft:gravel"},
        {pos: [7, 9, 8], state: "minecraft:mud_bricks"},
        {pos: [8, 9, 0], state: "minecraft:mud_bricks"},
        {pos: [8, 9, 1], state: "minecraft:gravel"},
        {pos: [8, 9, 2], state: "minecraft:gravel"},
        {pos: [8, 9, 3], state: "minecraft:white_terracotta"},
        {pos: [8, 9, 4], state: "minecraft:gravel"},
        {pos: [8, 9, 5], state: "minecraft:gravel"},
        {pos: [8, 9, 6], state: "minecraft:gravel"},
        {pos: [8, 9, 7], state: "minecraft:gravel"},
        {pos: [8, 9, 8], state: "minecraft:mud_bricks"},
        {pos: [9, 9, 1], state: "minecraft:mud_bricks"},
        {pos: [9, 9, 2], state: "minecraft:gravel"},
        {pos: [9, 9, 3], state: "minecraft:gravel"},
        {pos: [9, 9, 4], state: "minecraft:gravel"},
        {pos: [9, 9, 5], state: "minecraft:gravel"},
        {pos: [9, 9, 6], state: "minecraft:gravel"},
        {pos: [9, 9, 7], state: "minecraft:mud_bricks"},
        {pos: [10, 9, 1], state: "minecraft:mud_bricks"},
        {pos: [10, 9, 2], state: "minecraft:mud_bricks"},
        {pos: [10, 9, 3], state: "minecraft:mud_bricks"},
        {pos: [10, 9, 4], state: "minecraft:gravel"},
        {pos: [10, 9, 5], state: "minecraft:gravel"},
        {pos: [10, 9, 6], state: "minecraft:gravel"},
        {pos: [10, 9, 7], state: "minecraft:mud_bricks"},
        {pos: [11, 9, 2], state: "minecraft:mud_bricks"},
        {pos: [11, 9, 3], state: "minecraft:gravel"},
        {pos: [11, 9, 4], state: "minecraft:gravel"},
        {pos: [11, 9, 5], state: "minecraft:gravel"},
        {pos: [11, 9, 6], state: "minecraft:mud_bricks"},
        {pos: [12, 9, 3], state: "minecraft:mud_bricks"},
        {pos: [12, 9, 4], state: "minecraft:mud_bricks"},
        {pos: [12, 9, 5], state: "minecraft:mud_bricks"},
        {pos: [0, 10, 5], state: "minecraft:white_terracotta"},
        {pos: [1, 10, 3], state: "minecraft:gravel"},
        {pos: [1, 10, 4], state: "minecraft:white_terracotta"},
        {pos: [1, 10, 5], state: "minecraft:white_terracotta"},
        {pos: [1, 10, 6], state: "minecraft:white_terracotta"},
        {pos: [2, 10, 1], state: "minecraft:white_terracotta"},
        {pos: [2, 10, 2], state: "minecraft:white_terracotta"},
        {pos: [2, 10, 3], state: "minecraft:gravel"},
        {pos: [2, 10, 4], state: "minecraft:gravel"},
        {pos: [2, 10, 5], state: "minecraft:gravel"},
        {pos: [2, 10, 6], state: "minecraft:white_terracotta"},
        {pos: [2, 10, 7], state: "minecraft:white_terracotta"},
        {pos: [3, 10, 1], state: "minecraft:white_terracotta"},
        {pos: [3, 10, 2], state: "minecraft:gravel"},
        {pos: [3, 10, 3], state: "minecraft:gravel"},
        {pos: [3, 10, 4], state: "minecraft:gravel"},
        {pos: [3, 10, 5], state: "minecraft:gravel"},
        {pos: [3, 10, 6], state: "minecraft:white_terracotta"},
        {pos: [3, 10, 7], state: "minecraft:white_terracotta"},
        {pos: [4, 10, 0], state: "minecraft:white_terracotta"},
        {pos: [4, 10, 2], state: "minecraft:gravel"},
        {pos: [4, 10, 3], state: "minecraft:gravel"},
        {pos: [4, 10, 4], state: "minecraft:gravel"},
        {pos: [4, 10, 5], state: "minecraft:gravel"},
        {pos: [4, 10, 6], state: "minecraft:gravel"},
        {pos: [4, 10, 7], state: "minecraft:white_terracotta"},
        {pos: [4, 10, 8], state: "minecraft:white_terracotta"},
        {pos: [5, 10, 0], state: "minecraft:gravel"},
        {pos: [5, 10, 1], state: "minecraft:gravel"},
        {pos: [5, 10, 2], state: "minecraft:gravel"},
        {pos: [5, 10, 3], state: "minecraft:gravel"},
        {pos: [5, 10, 4], state: "minecraft:gravel"},
        {pos: [5, 10, 5], state: "minecraft:gravel"},
        {pos: [5, 10, 6], state: "minecraft:gravel"},
        {pos: [5, 10, 7], state: "minecraft:cyan_terracotta"},
        {pos: [5, 10, 8], state: "minecraft:white_terracotta"},
        {pos: [6, 10, 0], state: "minecraft:gravel"},
        {pos: [6, 10, 1], state: "minecraft:gravel"},
        {pos: [6, 10, 2], state: "minecraft:gravel"},
        {pos: [6, 10, 3], state: "minecraft:gravel"},
        {pos: [6, 10, 4], state: "minecraft:gravel"},
        {pos: [6, 10, 5], state: "minecraft:gravel"},
        {pos: [6, 10, 6], state: "minecraft:gravel"},
        {pos: [6, 10, 7], state: "minecraft:gravel"},
        {pos: [6, 10, 8], state: "minecraft:cyan_terracotta"},
        {pos: [7, 10, 0], state: "minecraft:cyan_terracotta"},
        {pos: [7, 10, 1], state: "minecraft:gravel"},
        {pos: [7, 10, 2], state: "minecraft:gravel"},
        {pos: [7, 10, 3], state: "minecraft:gravel"},
        {pos: [7, 10, 4], state: "minecraft:gravel"},
        {pos: [7, 10, 5], state: "minecraft:gravel"},
        {pos: [7, 10, 6], state: "minecraft:gravel"},
        {pos: [7, 10, 7], state: "minecraft:gravel"},
        {pos: [7, 10, 8], state: "minecraft:cyan_terracotta"},
        {pos: [8, 10, 0], state: "minecraft:cyan_terracotta"},
        {pos: [8, 10, 1], state: "minecraft:gravel"},
        {pos: [8, 10, 2], state: "minecraft:gravel"},
        {pos: [8, 10, 3], state: "minecraft:white_terracotta"},
        {pos: [8, 10, 4], state: "minecraft:gravel"},
        {pos: [8, 10, 5], state: "minecraft:gravel"},
        {pos: [8, 10, 6], state: "minecraft:gravel"},
        {pos: [8, 10, 8], state: "minecraft:cyan_terracotta"},
        {pos: [9, 10, 1], state: "minecraft:cyan_terracotta"},
        {pos: [9, 10, 2], state: "minecraft:gravel"},
        {pos: [9, 10, 3], state: "minecraft:gravel"},
        {pos: [9, 10, 4], state: "minecraft:gravel"},
        {pos: [9, 10, 5], state: "minecraft:gravel"},
        {pos: [9, 10, 6], state: "minecraft:gravel"},
        {pos: [9, 10, 7], state: "minecraft:cyan_terracotta"},
        {pos: [10, 10, 1], state: "minecraft:cyan_terracotta"},
        {pos: [10, 10, 2], state: "minecraft:gravel"},
        {pos: [10, 10, 3], state: "minecraft:gravel"},
        {pos: [10, 10, 4], state: "minecraft:gravel"},
        {pos: [10, 10, 5], state: "minecraft:gravel"},
        {pos: [10, 10, 6], state: "minecraft:gravel"},
        {pos: [10, 10, 7], state: "minecraft:cyan_terracotta"},
        {pos: [11, 10, 2], state: "minecraft:mud_bricks"},
        {pos: [11, 10, 3], state: "minecraft:gravel"},
        {pos: [11, 10, 4], state: "minecraft:gravel"},
        {pos: [11, 10, 5], state: "minecraft:gravel"},
        {pos: [11, 10, 6], state: "minecraft:mud_bricks"},
        {pos: [12, 10, 3], state: "minecraft:cyan_terracotta"},
        {pos: [12, 10, 4], state: "minecraft:cyan_terracotta"},
        {pos: [12, 10, 5], state: "minecraft:cyan_terracotta"},
        {pos: [0, 11, 5], state: "minecraft:gravel"},
        {pos: [1, 11, 3], state: "minecraft:gravel"},
        {pos: [1, 11, 5], state: "minecraft:white_terracotta"},
        {pos: [1, 11, 6], state: "minecraft:white_terracotta"},
        {pos: [2, 11, 1], state: "minecraft:white_terracotta"},
        {pos: [2, 11, 3], state: "minecraft:white_terracotta"},
        {pos: [2, 11, 4], state: "minecraft:white_terracotta"},
        {pos: [2, 11, 5], state: "minecraft:white_terracotta"},
        {pos: [2, 11, 6], state: "minecraft:white_terracotta"},
        {pos: [2, 11, 7], state: "minecraft:white_terracotta"},
        {pos: [3, 11, 1], state: "minecraft:white_terracotta"},
        {pos: [3, 11, 2], state: "minecraft:white_terracotta"},
        {pos: [3, 11, 3], state: "minecraft:white_terracotta"},
        {pos: [3, 11, 4], state: "minecraft:gravel"},
        {pos: [3, 11, 5], state: "minecraft:gravel"},
        {pos: [3, 11, 6], state: "minecraft:white_terracotta"},
        {pos: [3, 11, 7], state: "minecraft:white_terracotta"},
        {pos: [4, 11, 0], state: "minecraft:white_terracotta"},
        {pos: [4, 11, 1], state: "minecraft:white_terracotta"},
        {pos: [4, 11, 2], state: "minecraft:white_terracotta"},
        {pos: [4, 11, 3], state: "minecraft:white_terracotta"},
        {pos: [4, 11, 4], state: "minecraft:gravel"},
        {pos: [4, 11, 5], state: "minecraft:white_terracotta"},
        {pos: [4, 11, 6], state: "minecraft:white_terracotta"},
        {pos: [4, 11, 7], state: "minecraft:white_terracotta"},
        {pos: [4, 11, 8], state: "minecraft:white_terracotta"},
        {pos: [5, 11, 0], state: "minecraft:gravel"},
        {pos: [5, 11, 1], state: "minecraft:cyan_terracotta"},
        {pos: [5, 11, 2], state: "minecraft:cyan_terracotta"},
        {pos: [5, 11, 3], state: "minecraft:cyan_terracotta"},
        {pos: [5, 11, 4], state: "minecraft:cyan_terracotta"},
        {pos: [5, 11, 5], state: "minecraft:cyan_terracotta"},
        {pos: [5, 11, 6], state: "minecraft:cyan_terracotta"},
        {pos: [5, 11, 7], state: "minecraft:cyan_terracotta"},
        {pos: [5, 11, 8], state: "minecraft:white_terracotta"},
        {pos: [6, 11, 0], state: "minecraft:gravel"},
        {pos: [6, 11, 1], state: "minecraft:gravel"},
        {pos: [6, 11, 2], state: "minecraft:gravel"},
        {pos: [6, 11, 3], state: "minecraft:gravel"},
        {pos: [6, 11, 4], state: "minecraft:gravel"},
        {pos: [6, 11, 5], state: "minecraft:gravel"},
        {pos: [6, 11, 6], state: "minecraft:cyan_terracotta"},
        {pos: [6, 11, 7], state: "minecraft:cyan_terracotta"},
        {pos: [6, 11, 8], state: "minecraft:cyan_terracotta"},
        {pos: [7, 11, 0], state: "minecraft:cyan_terracotta"},
        {pos: [7, 11, 1], state: "minecraft:gravel"},
        {pos: [7, 11, 2], state: "minecraft:gravel"},
        {pos: [7, 11, 3], state: "minecraft:gravel"},
        {pos: [7, 11, 4], state: "minecraft:gravel"},
        {pos: [7, 11, 5], state: "minecraft:gravel"},
        {pos: [7, 11, 6], state: "minecraft:cyan_terracotta"},
        {pos: [7, 11, 7], state: "minecraft:cyan_terracotta"},
        {pos: [7, 11, 8], state: "minecraft:cyan_terracotta"},
        {pos: [8, 11, 0], state: "minecraft:gravel"},
        {pos: [8, 11, 1], state: "minecraft:gravel"},
        {pos: [8, 11, 2], state: "minecraft:gravel"},
        {pos: [8, 11, 3], state: "minecraft:white_terracotta"},
        {pos: [8, 11, 4], state: "minecraft:gravel"},
        {pos: [8, 11, 5], state: "minecraft:gravel"},
        {pos: [8, 11, 6], state: "minecraft:gravel"},
        {pos: [8, 11, 7], state: "minecraft:cyan_terracotta"},
        {pos: [8, 11, 8], state: "minecraft:cyan_terracotta"},
        {pos: [9, 11, 1], state: "minecraft:cyan_terracotta"},
        {pos: [9, 11, 2], state: "minecraft:gravel"},
        {pos: [9, 11, 3], state: "minecraft:gravel"},
        {pos: [9, 11, 4], state: "minecraft:gravel"},
        {pos: [9, 11, 5], state: "minecraft:gravel"},
        {pos: [9, 11, 6], state: "minecraft:gravel"},
        {pos: [9, 11, 7], state: "minecraft:cyan_terracotta"},
        {pos: [10, 11, 1], state: "minecraft:orange_glazed_terracotta{facing:south}"},
        {pos: [10, 11, 2], state: "minecraft:gravel"},
        {pos: [10, 11, 3], state: "minecraft:gravel"},
        {pos: [10, 11, 4], state: "minecraft:gravel"},
        {pos: [10, 11, 5], state: "minecraft:cyan_terracotta"},
        {pos: [10, 11, 6], state: "minecraft:cyan_terracotta"},
        {pos: [10, 11, 7], state: "minecraft:cyan_terracotta"},
        {pos: [11, 11, 2], state: "minecraft:gravel"},
        {pos: [11, 11, 3], state: "minecraft:gravel"},
        {pos: [11, 11, 4], state: "minecraft:gravel"},
        {pos: [11, 11, 5], state: "minecraft:cyan_terracotta"},
        {pos: [11, 11, 6], state: "minecraft:mud_bricks"},
        {pos: [12, 11, 5], state: "minecraft:cyan_terracotta"},
        {pos: [2, 12, 3], state: "minecraft:gravel"},
        {pos: [2, 12, 4], state: "minecraft:gravel"},
        {pos: [2, 12, 5], state: "minecraft:gravel"},
        {pos: [3, 12, 2], state: "minecraft:gravel"},
        {pos: [3, 12, 3], state: "minecraft:gravel"},
        {pos: [3, 12, 4], state: "minecraft:gravel"},
        {pos: [3, 12, 5], state: "minecraft:gravel"},
        {pos: [3, 12, 6], state: "minecraft:gravel"},
        {pos: [3, 12, 7], state: "minecraft:gravel"},
        {pos: [4, 12, 2], state: "minecraft:gravel"},
        {pos: [4, 12, 3], state: "minecraft:gravel"},
        {pos: [4, 12, 4], state: "minecraft:gravel"},
        {pos: [4, 12, 5], state: "minecraft:gravel"},
        {pos: [4, 12, 6], state: "minecraft:gravel"},
        {pos: [4, 12, 7], state: "minecraft:gravel"},
        {pos: [4, 12, 8], state: "minecraft:gravel"},
        {pos: [5, 12, 0], state: "minecraft:orange_glazed_terracotta{facing:west}"},
        {pos: [5, 12, 1], state: "minecraft:orange_glazed_terracotta{facing:south}"},
        {pos: [5, 12, 2], state: "minecraft:gravel"},
        {pos: [5, 12, 3], state: "minecraft:gravel"},
        {pos: [5, 12, 4], state: "minecraft:orange_glazed_terracotta{facing:west}"},
        {pos: [5, 12, 5], state: "minecraft:gravel"},
        {pos: [5, 12, 6], state: "minecraft:orange_glazed_terracotta{facing:west}"},
        {pos: [5, 12, 7], state: "minecraft:orange_glazed_terracotta{facing:north}"},
        {pos: [5, 12, 8], state: "minecraft:gravel"},
        {pos: [6, 12, 0], state: "minecraft:gravel"},
        {pos: [6, 12, 1], state: "minecraft:gravel"},
        {pos: [6, 12, 2], state: "minecraft:gravel"},
        {pos: [6, 12, 3], state: "minecraft:gravel"},
        {pos: [6, 12, 4], state: "minecraft:gravel"},
        {pos: [6, 12, 5], state: "minecraft:gravel"},
        {pos: [6, 12, 6], state: "minecraft:gravel"},
        {pos: [6, 12, 7], state: "minecraft:gravel"},
        {pos: [6, 12, 8], state: "minecraft:orange_glazed_terracotta{facing:north}"},
        {pos: [7, 12, 0], state: "minecraft:gravel"},
        {pos: [7, 12, 1], state: "minecraft:gravel"},
        {pos: [7, 12, 2], state: "minecraft:gravel"},
        {pos: [7, 12, 3], state: "minecraft:gravel"},
        {pos: [7, 12, 4], state: "minecraft:gravel"},
        {pos: [7, 12, 5], state: "minecraft:gravel"},
        {pos: [7, 12, 6], state: "minecraft:gravel"},
        {pos: [7, 12, 7], state: "minecraft:gravel"},
        {pos: [7, 12, 8], state: "minecraft:orange_glazed_terracotta{facing:east}"},
        {pos: [8, 12, 1], state: "minecraft:gravel"},
        {pos: [8, 12, 2], state: "minecraft:gravel"},
        {pos: [8, 12, 3], state: "minecraft:white_terracotta"},
        {pos: [8, 12, 4], state: "minecraft:gravel"},
        {pos: [8, 12, 5], state: "minecraft:gravel"},
        {pos: [8, 12, 6], state: "minecraft:gravel"},
        {pos: [8, 12, 7], state: "minecraft:gravel"},
        {pos: [8, 12, 8], state: "minecraft:orange_glazed_terracotta{facing:north}"},
        {pos: [9, 12, 1], state: "minecraft:gravel"},
        {pos: [9, 12, 2], state: "minecraft:gravel"},
        {pos: [9, 12, 3], state: "minecraft:gravel"},
        {pos: [9, 12, 4], state: "minecraft:gravel"},
        {pos: [9, 12, 5], state: "minecraft:gravel"},
        {pos: [9, 12, 6], state: "minecraft:gravel"},
        {pos: [9, 12, 7], state: "minecraft:gravel"},
        {pos: [10, 12, 1], state: "minecraft:gravel"},
        {pos: [10, 12, 2], state: "minecraft:gravel"},
        {pos: [10, 12, 3], state: "minecraft:gravel"},
        {pos: [10, 12, 4], state: "minecraft:gravel"},
        {pos: [10, 12, 5], state: "minecraft:gravel"},
        {pos: [10, 12, 6], state: "minecraft:gravel"},
        {pos: [10, 12, 7], state: "minecraft:orange_glazed_terracotta{facing:west}"},
        {pos: [11, 12, 2], state: "minecraft:gravel"},
        {pos: [11, 12, 3], state: "minecraft:gravel"},
        {pos: [11, 12, 4], state: "minecraft:gravel"},
        {pos: [11, 12, 5], state: "minecraft:gravel"},
        {pos: [11, 12, 6], state: "minecraft:mud_bricks"},
        {pos: [12, 12, 5], state: "minecraft:orange_glazed_terracotta{facing:west}"},
        {pos: [3, 13, 4], state: "minecraft:gravel"},
        {pos: [5, 13, 0], state: "minecraft:orange_terracotta"},
        {pos: [5, 13, 1], state: "minecraft:orange_terracotta"},
        {pos: [5, 13, 2], state: "minecraft:orange_terracotta"},
        {pos: [5, 13, 3], state: "minecraft:orange_terracotta"},
        {pos: [5, 13, 4], state: "minecraft:orange_terracotta"},
        {pos: [5, 13, 6], state: "minecraft:orange_terracotta"},
        {pos: [5, 13, 7], state: "minecraft:orange_terracotta"},
        {pos: [5, 13, 8], state: "minecraft:gravel"},
        {pos: [6, 13, 0], state: "minecraft:orange_terracotta"},
        {pos: [6, 13, 2], state: "minecraft:gravel"},
        {pos: [6, 13, 3], state: "minecraft:gravel"},
        {pos: [6, 13, 4], state: "minecraft:gravel"},
        {pos: [6, 13, 5], state: "minecraft:gravel"},
        {pos: [6, 13, 6], state: "minecraft:gravel"},
        {pos: [6, 13, 7], state: "minecraft:gravel"},
        {pos: [6, 13, 8], state: "minecraft:orange_terracotta"},
        {pos: [7, 13, 0], state: "minecraft:gravel"},
        {pos: [7, 13, 1], state: "minecraft:gravel"},
        {pos: [7, 13, 2], state: "minecraft:gravel"},
        {pos: [7, 13, 3], state: "minecraft:gravel"},
        {pos: [7, 13, 4], state: "minecraft:gravel"},
        {pos: [7, 13, 5], state: "minecraft:gravel"},
        {pos: [7, 13, 6], state: "minecraft:gravel"},
        {pos: [7, 13, 7], state: "minecraft:gravel"},
        {pos: [7, 13, 8], state: "minecraft:orange_terracotta"},
        {pos: [8, 13, 1], state: "minecraft:gravel"},
        {pos: [8, 13, 2], state: "minecraft:gravel"},
        {pos: [8, 13, 3], state: "minecraft:white_terracotta"},
        {pos: [8, 13, 4], state: "minecraft:gravel"},
        {pos: [8, 13, 5], state: "minecraft:gravel"},
        {pos: [8, 13, 6], state: "minecraft:gravel"},
        {pos: [8, 13, 8], state: "minecraft:orange_terracotta"},
        {pos: [9, 13, 1], state: "minecraft:gravel"},
        {pos: [9, 13, 2], state: "minecraft:gravel"},
        {pos: [9, 13, 3], state: "minecraft:ladder{facing:east,waterlogged:false}"},
        {pos: [9, 13, 4], state: "minecraft:gravel"},
        {pos: [9, 13, 5], state: "minecraft:gravel"},
        {pos: [9, 13, 6], state: "minecraft:gravel"},
        {pos: [9, 13, 7], state: "minecraft:orange_terracotta"},
        {pos: [10, 13, 1], state: "minecraft:gravel"},
        {pos: [10, 13, 2], state: "minecraft:gravel"},
        {pos: [10, 13, 3], state: "minecraft:gravel"},
        {pos: [10, 13, 4], state: "minecraft:gravel"},
        {pos: [10, 13, 5], state: "minecraft:gravel"},
        {pos: [10, 13, 6], state: "minecraft:gravel"},
        {pos: [10, 13, 7], state: "minecraft:orange_terracotta"},
        {pos: [11, 13, 3], state: "minecraft:gravel"},
        {pos: [11, 13, 4], state: "minecraft:gravel"},
        {pos: [11, 13, 5], state: "minecraft:gravel"},
        {pos: [11, 13, 6], state: "minecraft:orange_terracotta"},
        {pos: [12, 13, 5], state: "minecraft:orange_terracotta"},
        {pos: [6, 14, 1], state: "minecraft:white_terracotta"},
        {pos: [6, 14, 2], state: "minecraft:white_terracotta"},
        {pos: [6, 14, 3], state: "minecraft:gravel"},
        {pos: [6, 14, 4], state: "minecraft:white_terracotta"},
        {pos: [6, 14, 5], state: "minecraft:white_terracotta"},
        {pos: [6, 14, 6], state: "minecraft:white_terracotta"},
        {pos: [6, 14, 7], state: "minecraft:white_terracotta"},
        {pos: [7, 14, 1], state: "minecraft:white_terracotta"},
        {pos: [7, 14, 2], state: "minecraft:gravel"},
        {pos: [7, 14, 3], state: "minecraft:gravel"},
        {pos: [7, 14, 4], state: "minecraft:white_terracotta"},
        {pos: [7, 14, 5], state: "minecraft:white_terracotta"},
        {pos: [7, 14, 6], state: "minecraft:white_terracotta"},
        {pos: [7, 14, 7], state: "minecraft:white_terracotta"},
        {pos: [8, 14, 2], state: "minecraft:white_terracotta"},
        {pos: [8, 14, 3], state: "minecraft:gravel"},
        {pos: [8, 14, 4], state: "minecraft:white_terracotta"},
        {pos: [8, 14, 5], state: "minecraft:white_terracotta"},
        {pos: [8, 14, 6], state: "minecraft:white_terracotta"},
        {pos: [8, 14, 7], state: "minecraft:white_terracotta"},
        {pos: [9, 14, 1], state: "minecraft:gravel"},
        {pos: [9, 14, 2], state: "minecraft:white_terracotta"},
        {pos: [9, 14, 3], state: "minecraft:gravel"},
        {pos: [9, 14, 4], state: "minecraft:white_terracotta"},
        {pos: [9, 14, 5], state: "minecraft:white_terracotta"},
        {pos: [9, 14, 6], state: "minecraft:white_terracotta"},
        {pos: [10, 14, 2], state: "minecraft:gravel"},
        {pos: [10, 14, 3], state: "minecraft:white_terracotta"},
        {pos: [10, 14, 4], state: "minecraft:white_terracotta"},
        {pos: [10, 14, 5], state: "minecraft:white_terracotta"},
        {pos: [10, 14, 6], state: "minecraft:white_terracotta"},
        {pos: [11, 14, 4], state: "minecraft:white_terracotta"},
        {pos: [11, 14, 5], state: "minecraft:white_terracotta"}
    ],
    entities: [],
    palette: [
        "minecraft:mud_bricks",
        "minecraft:gravel",
        "minecraft:white_terracotta",
        "minecraft:yellow_terracotta",
        "minecraft:orange_terracotta",
        "minecraft:loom{facing:west}",
        "minecraft:cyan_terracotta",
        "minecraft:orange_glazed_terracotta{facing:south}",
        "minecraft:orange_glazed_terracotta{facing:west}",
        "minecraft:orange_glazed_terracotta{facing:north}",
        "minecraft:orange_glazed_terracotta{facing:east}",
        "minecraft:cauldron",
        "minecraft:ladder{facing:east,waterlogged:false}",
        "minecraft:jigsaw{orientation:north_up}"
    ]
}
