{
    size: [9, 15, 13],
    data: [
        {pos: [0, 0, 2], state: "minecraft:bricks"},
        {pos: [0, 0, 3], state: "minecraft:brown_terracotta"},
        {pos: [0, 0, 4], state: "minecraft:brown_terracotta"},
        {pos: [0, 0, 5], state: "minecraft:brown_terracotta"},
        {pos: [0, 0, 6], state: "minecraft:brown_terracotta"},
        {pos: [0, 0, 7], state: "minecraft:brown_terracotta"},
        {pos: [0, 0, 8], state: "minecraft:brown_terracotta"},
        {pos: [0, 0, 9], state: "minecraft:brown_terracotta"},
        {pos: [1, 0, 2], state: "minecraft:bricks"},
        {pos: [1, 0, 3], state: "minecraft:brown_terracotta"},
        {pos: [1, 0, 4], state: "minecraft:brown_terracotta"},
        {pos: [1, 0, 5], state: "minecraft:brown_terracotta"},
        {pos: [1, 0, 6], state: "minecraft:brown_terracotta"},
        {pos: [1, 0, 7], state: "minecraft:brown_terracotta"},
        {pos: [1, 0, 8], state: "minecraft:brown_terracotta"},
        {pos: [1, 0, 9], state: "minecraft:brown_terracotta"},
        {pos: [2, 0, 2], state: "minecraft:bricks"},
        {pos: [2, 0, 3], state: "minecraft:brown_terracotta"},
        {pos: [2, 0, 4], state: "minecraft:brown_terracotta"},
        {pos: [2, 0, 5], state: "minecraft:brown_terracotta"},
        {pos: [2, 0, 6], state: "minecraft:brown_terracotta"},
        {pos: [2, 0, 7], state: "minecraft:brown_terracotta"},
        {pos: [2, 0, 8], state: "minecraft:brown_terracotta"},
        {pos: [2, 0, 9], state: "minecraft:brown_terracotta"},
        {pos: [3, 0, 4], state: "minecraft:brown_terracotta"},
        {pos: [3, 0, 5], state: "minecraft:brown_terracotta"},
        {pos: [3, 0, 6], state: "minecraft:brown_terracotta"},
        {pos: [3, 0, 7], state: "minecraft:brown_terracotta"},
        {pos: [3, 0, 8], state: "minecraft:brown_terracotta"},
        {pos: [3, 0, 9], state: "minecraft:brown_terracotta"},
        {pos: [4, 0, 4], state: "minecraft:brown_terracotta"},
        {pos: [4, 0, 5], state: "minecraft:brown_terracotta"},
        {pos: [4, 0, 6], state: "minecraft:brown_terracotta"},
        {pos: [4, 0, 7], state: "minecraft:brown_terracotta"},
        {pos: [4, 0, 8], state: "minecraft:brown_terracotta"},
        {pos: [5, 0, 4], state: "minecraft:brown_terracotta"},
        {pos: [5, 0, 5], state: "minecraft:brown_terracotta"},
        {pos: [5, 0, 6], state: "minecraft:brown_terracotta"},
        {pos: [5, 0, 7], state: "minecraft:brown_terracotta"},
        {pos: [5, 0, 8], state: "minecraft:brown_terracotta"},
        {pos: [6, 0, 8], state: "minecraft:brown_terracotta"},
        {pos: [0, 1, 3], state: "minecraft:gravel"},
        {pos: [0, 1, 4], state: "minecraft:bricks"},
        {pos: [0, 1, 5], state: "minecraft:bricks"},
        {pos: [0, 1, 6], state: "minecraft:brown_terracotta"},
        {pos: [0, 1, 7], state: "minecraft:brown_terracotta"},
        {pos: [0, 1, 8], state: "minecraft:brown_terracotta"},
        {pos: [0, 1, 9], state: "minecraft:brown_terracotta"},
        {pos: [1, 1, 3], state: "minecraft:gravel"},
        {pos: [1, 1, 4], state: "minecraft:gravel"},
        {pos: [1, 1, 5], state: "minecraft:gravel"},
        {pos: [1, 1, 6], state: "minecraft:gravel"},
        {pos: [1, 1, 7], state: "minecraft:gravel"},
        {pos: [1, 1, 8], state: "minecraft:gravel"},
        {pos: [1, 1, 9], state: "minecraft:brown_terracotta"},
        {pos: [2, 1, 2], state: "minecraft:bricks"},
        {pos: [2, 1, 3], state: "minecraft:gravel"},
        {pos: [2, 1, 4], state: "minecraft:gravel"},
        {pos: [2, 1, 5], state: "minecraft:gravel"},
        {pos: [2, 1, 6], state: "minecraft:gravel"},
        {pos: [2, 1, 7], state: "minecraft:gravel"},
        {pos: [2, 1, 8], state: "minecraft:gravel"},
        {pos: [2, 1, 9], state: "minecraft:brown_terracotta"},
        {pos: [3, 1, 3], state: "minecraft:brown_terracotta"},
        {pos: [3, 1, 4], state: "minecraft:gravel"},
        {pos: [3, 1, 5], state: "minecraft:gravel"},
        {pos: [3, 1, 6], state: "minecraft:gravel"},
        {pos: [3, 1, 7], state: "minecraft:gravel"},
        {pos: [3, 1, 8], state: "minecraft:gravel"},
        {pos: [3, 1, 9], state: "minecraft:brown_terracotta"},
        {pos: [4, 1, 4], state: "minecraft:gravel"},
        {pos: [4, 1, 5], state: "minecraft:gravel"},
        {pos: [4, 1, 6], state: "minecraft:gravel"},
        {pos: [4, 1, 7], state: "minecraft:gravel"},
        {pos: [4, 1, 8], state: "minecraft:gravel"},
        {pos: [4, 1, 9], state: "minecraft:brown_terracotta"},
        {pos: [5, 1, 4], state: "minecraft:brown_terracotta"},
        {pos: [5, 1, 5], state: "minecraft:brown_terracotta"},
        {pos: [5, 1, 6], state: "minecraft:brown_terracotta"},
        {pos: [5, 1, 7], state: "minecraft:gravel"},
        {pos: [5, 1, 8], state: "minecraft:gravel"},
        {pos: [5, 1, 9], state: "minecraft:brown_terracotta"},
        {pos: [6, 1, 4], state: "minecraft:brown_terracotta"},
        {pos: [6, 1, 5], state: "minecraft:brown_terracotta"},
        {pos: [6, 1, 6], state: "minecraft:brown_terracotta"},
        {pos: [6, 1, 7], state: "minecraft:brown_terracotta"},
        {pos: [6, 1, 8], state: "minecraft:gravel"},
        {pos: [6, 1, 9], state: "minecraft:brown_terracotta"},
        {pos: [7, 1, 4], state: "minecraft:brown_terracotta"},
        {pos: [7, 1, 5], state: "minecraft:brown_terracotta"},
        {pos: [7, 1, 6], state: "minecraft:brown_terracotta"},
        {pos: [7, 1, 7], state: "minecraft:brown_terracotta"},
        {pos: [7, 1, 8], state: "minecraft:brown_terracotta"},
        {pos: [7, 1, 9], state: "minecraft:brown_terracotta"},
        {pos: [8, 1, 4], state: "minecraft:brown_terracotta"},
        {pos: [8, 1, 5], state: "minecraft:brown_terracotta"},
        {pos: [8, 1, 6], state: "minecraft:brown_terracotta"},
        {pos: [8, 1, 7], state: "minecraft:brown_terracotta"},
        {pos: [8, 1, 8], state: "minecraft:brown_terracotta"},
        {pos: [0, 2, 3], state: "minecraft:gravel"},
        {pos: [0, 2, 4], state: "minecraft:gravel"},
        {pos: [0, 2, 5], state: "minecraft:bricks"},
        {pos: [0, 2, 6], state: "minecraft:bricks"},
        {pos: [0, 2, 7], state: "minecraft:brown_terracotta"},
        {pos: [0, 2, 8], state: "minecraft:brown_terracotta"},
        {pos: [0, 2, 9], state: "minecraft:brown_terracotta"},
        {pos: [1, 2, 2], state: "minecraft:ladder{facing:west,waterlogged:false}"},
        {pos: [1, 2, 3], state: "minecraft:gravel"},
        {pos: [1, 2, 5], state: "minecraft:gravel"},
        {pos: [1, 2, 6], state: "minecraft:gravel"},
        {pos: [1, 2, 7], state: "minecraft:gravel"},
        {pos: [1, 2, 8], state: "minecraft:gravel"},
        {pos: [1, 2, 9], state: "minecraft:brown_terracotta"},
        {pos: [2, 2, 2], state: "minecraft:bricks"},
        {pos: [2, 2, 3], state: "minecraft:brown_terracotta"},
        {pos: [2, 2, 4], state: "minecraft:gravel"},
        {pos: [2, 2, 5], state: "minecraft:gravel"},
        {pos: [2, 2, 6], state: "minecraft:gravel"},
        {pos: [2, 2, 7], state: "minecraft:gravel"},
        {pos: [2, 2, 8], state: "minecraft:gravel"},
        {pos: [2, 2, 9], state: "minecraft:brown_terracotta"},
        {pos: [3, 2, 3], state: "minecraft:brown_terracotta"},
        {pos: [3, 2, 4], state: "minecraft:gravel"},
        {pos: [3, 2, 5], state: "minecraft:gravel"},
        {pos: [3, 2, 6], state: "minecraft:gravel"},
        {pos: [3, 2, 7], state: "minecraft:gravel"},
        {pos: [3, 2, 8], state: "minecraft:gravel"},
        {pos: [3, 2, 9], state: "minecraft:brown_terracotta"},
        {pos: [4, 2, 3], state: "minecraft:brown_terracotta"},
        {pos: [4, 2, 4], state: "minecraft:gravel"},
        {pos: [4, 2, 5], state: "minecraft:gravel"},
        {pos: [4, 2, 6], state: "minecraft:gravel"},
        {pos: [4, 2, 7], state: "minecraft:gravel"},
        {pos: [4, 2, 8], state: "minecraft:gravel"},
        {pos: [4, 2, 9], state: "minecraft:brown_terracotta"},
        {pos: [5, 2, 3], state: "minecraft:brown_terracotta"},
        {pos: [5, 2, 4], state: "minecraft:gravel"},
        {pos: [5, 2, 5], state: "minecraft:gravel"},
        {pos: [5, 2, 6], state: "minecraft:gravel"},
        {pos: [5, 2, 7], state: "minecraft:gravel"},
        {pos: [5, 2, 8], state: "minecraft:gravel"},
        {pos: [5, 2, 9], state: "minecraft:brown_terracotta"},
        {pos: [6, 2, 3], state: "minecraft:brown_terracotta"},
        {pos: [6, 2, 4], state: "minecraft:gravel"},
        {pos: [6, 2, 5], state: "minecraft:gravel"},
        {pos: [6, 2, 6], state: "minecraft:gravel"},
        {pos: [6, 2, 7], state: "minecraft:gravel"},
        {pos: [6, 2, 8], state: "minecraft:gravel"},
        {pos: [6, 2, 9], state: "minecraft:brown_terracotta"},
        {pos: [7, 2, 3], state: "minecraft:brown_terracotta"},
        {pos: [7, 2, 4], state: "minecraft:gravel"},
        {pos: [7, 2, 5], state: "minecraft:gravel"},
        {pos: [7, 2, 6], state: "minecraft:gravel"},
        {pos: [7, 2, 7], state: "minecraft:gravel"},
        {pos: [7, 2, 8], state: "minecraft:gravel"},
        {pos: [7, 2, 9], state: "minecraft:brown_terracotta"},
        {pos: [8, 2, 4], state: "minecraft:brown_terracotta"},
        {pos: [8, 2, 5], state: "minecraft:brown_terracotta"},
        {pos: [8, 2, 6], state: "minecraft:brown_terracotta"},
        {pos: [8, 2, 7], state: "minecraft:brown_terracotta"},
        {pos: [8, 2, 8], state: "minecraft:brown_terracotta"},
        {pos: [0, 3, 3], state: "minecraft:gravel"},
        {pos: [0, 3, 4], state: "minecraft:gravel"},
        {pos: [0, 3, 5], state: "minecraft:gravel"},
        {pos: [0, 3, 6], state: "minecraft:gravel"},
        {pos: [0, 3, 7], state: "minecraft:gravel"},
        {pos: [0, 3, 9], state: "minecraft:gravel"},
        {pos: [1, 3, 3], state: "minecraft:brown_terracotta"},
        {pos: [1, 3, 4], state: "minecraft:brown_terracotta"},
        {pos: [1, 3, 5], state: "minecraft:gravel"},
        {pos: [1, 3, 6], state: "minecraft:gravel"},
        {pos: [1, 3, 7], state: "minecraft:brown_terracotta"},
        {pos: [1, 3, 8], state: "minecraft:brown_terracotta"},
        {pos: [1, 3, 9], state: "minecraft:gravel"},
        {pos: [2, 3, 2], state: "minecraft:bricks"},
        {pos: [2, 3, 3], state: "minecraft:brown_terracotta"},
        {pos: [2, 3, 4], state: "minecraft:brown_terracotta"},
        {pos: [2, 3, 5], state: "minecraft:brown_terracotta"},
        {pos: [2, 3, 6], state: "minecraft:brown_terracotta"},
        {pos: [2, 3, 7], state: "minecraft:brown_terracotta"},
        {pos: [2, 3, 8], state: "minecraft:brown_terracotta"},
        {pos: [2, 3, 9], state: "minecraft:gravel"},
        {pos: [3, 3, 3], state: "minecraft:brown_terracotta"},
        {pos: [3, 3, 4], state: "minecraft:bricks"},
        {pos: [3, 3, 5], state: "minecraft:bricks"},
        {pos: [3, 3, 6], state: "minecraft:bricks"},
        {pos: [3, 3, 7], state: "minecraft:bricks"},
        {pos: [3, 3, 8], state: "minecraft:bricks"},
        {pos: [3, 3, 9], state: "minecraft:brown_terracotta"},
        {pos: [4, 3, 3], state: "minecraft:brown_terracotta"},
        {pos: [4, 3, 4], state: "minecraft:gravel"},
        {pos: [4, 3, 5], state: "minecraft:gravel"},
        {pos: [4, 3, 6], state: "minecraft:gravel"},
        {pos: [4, 3, 7], state: "minecraft:gravel"},
        {pos: [4, 3, 8], state: "minecraft:gravel"},
        {pos: [4, 3, 9], state: "minecraft:brown_terracotta"},
        {pos: [5, 3, 3], state: "minecraft:brown_terracotta"},
        {pos: [5, 3, 4], state: "minecraft:bricks"},
        {pos: [5, 3, 5], state: "minecraft:bricks"},
        {pos: [5, 3, 6], state: "minecraft:gravel"},
        {pos: [5, 3, 7], state: "minecraft:bricks"},
        {pos: [5, 3, 8], state: "minecraft:bricks"},
        {pos: [5, 3, 9], state: "minecraft:brown_terracotta"},
        {pos: [6, 3, 3], state: "minecraft:brown_terracotta"},
        {pos: [6, 3, 4], state: "minecraft:gravel"},
        {pos: [6, 3, 5], state: "minecraft:gravel"},
        {pos: [6, 3, 6], state: "minecraft:gravel"},
        {pos: [6, 3, 7], state: "minecraft:gravel"},
        {pos: [6, 3, 8], state: "minecraft:gravel"},
        {pos: [6, 3, 9], state: "minecraft:brown_terracotta"},
        {pos: [7, 3, 3], state: "minecraft:brown_terracotta"},
        {pos: [7, 3, 4], state: "minecraft:bricks"},
        {pos: [7, 3, 5], state: "minecraft:bricks"},
        {pos: [7, 3, 6], state: "minecraft:bricks"},
        {pos: [7, 3, 7], state: "minecraft:bricks"},
        {pos: [7, 3, 8], state: "minecraft:bricks"},
        {pos: [7, 3, 9], state: "minecraft:brown_terracotta"},
        {pos: [8, 3, 4], state: "minecraft:brown_terracotta"},
        {pos: [8, 3, 5], state: "minecraft:brown_terracotta"},
        {pos: [8, 3, 6], state: "minecraft:brown_terracotta"},
        {pos: [8, 3, 7], state: "minecraft:brown_terracotta"},
        {pos: [8, 3, 8], state: "minecraft:brown_terracotta"},
        {pos: [0, 4, 3], state: "minecraft:gravel"},
        {pos: [0, 4, 4], state: "minecraft:gravel"},
        {pos: [0, 4, 5], state: "minecraft:gravel"},
        {pos: [0, 4, 6], state: "minecraft:gravel"},
        {pos: [0, 4, 7], state: "minecraft:gravel"},
        {pos: [0, 4, 9], state: "minecraft:gravel"},
        {pos: [1, 4, 2], state: "minecraft:ladder{facing:west,waterlogged:false}"},
        {pos: [1, 4, 3], state: "minecraft:gravel"},
        {pos: [1, 4, 4], state: "minecraft:gravel"},
        {pos: [1, 4, 5], state: "minecraft:gravel"},
        {pos: [1, 4, 6], state: "minecraft:gravel"},
        {pos: [1, 4, 7], state: "minecraft:gravel"},
        {pos: [1, 4, 8], state: "minecraft:gravel"},
        {pos: [1, 4, 9], state: "minecraft:gravel"},
        {pos: [2, 4, 2], state: "minecraft:bricks"},
        {pos: [2, 4, 3], state: "minecraft:brown_terracotta"},
        {pos: [2, 4, 4], state: "minecraft:blast_furnace{facing:south,lit:false}", nbt: {Items: [], RecipesUsed: {}, cooking_time_spent: 0s, cooking_total_time: 0s, id: "minecraft:blast_furnace", lit_time_remaining: 0s, lit_total_time: 0s}},
        {pos: [2, 4, 5], state: "minecraft:gravel"},
        {pos: [2, 4, 6], state: "minecraft:gravel"},
        {pos: [2, 4, 7], state: "minecraft:blast_furnace{facing:north,lit:false}", nbt: {Items: [], RecipesUsed: {}, cooking_time_spent: 0s, cooking_total_time: 0s, id: "minecraft:blast_furnace", lit_time_remaining: 0s, lit_total_time: 0s}},
        {pos: [2, 4, 8], state: "minecraft:brown_terracotta"},
        {pos: [2, 4, 9], state: "minecraft:gravel"},
        {pos: [3, 4, 3], state: "minecraft:brown_terracotta"},
        {pos: [3, 4, 4], state: "minecraft:gravel"},
        {pos: [3, 4, 5], state: "minecraft:gravel"},
        {pos: [3, 4, 6], state: "minecraft:gravel"},
        {pos: [3, 4, 7], state: "minecraft:gravel"},
        {pos: [3, 4, 8], state: "minecraft:gravel"},
        {pos: [3, 4, 9], state: "minecraft:brown_terracotta"},
        {pos: [4, 4, 3], state: "minecraft:brown_terracotta"},
        {pos: [4, 4, 4], state: "minecraft:gravel"},
        {pos: [4, 4, 5], state: "minecraft:gravel"},
        {pos: [4, 4, 6], state: "minecraft:gravel"},
        {pos: [4, 4, 7], state: "minecraft:gravel"},
        {pos: [4, 4, 8], state: "minecraft:gravel"},
        {pos: [4, 4, 9], state: "minecraft:brown_terracotta"},
        {pos: [5, 4, 3], state: "minecraft:brown_terracotta"},
        {pos: [5, 4, 4], state: "minecraft:gravel"},
        {pos: [5, 4, 5], state: "minecraft:gravel"},
        {pos: [5, 4, 6], state: "minecraft:gravel"},
        {pos: [5, 4, 7], state: "minecraft:gravel"},
        {pos: [5, 4, 8], state: "minecraft:gravel"},
        {pos: [5, 4, 9], state: "minecraft:brown_terracotta"},
        {pos: [6, 4, 3], state: "minecraft:brown_terracotta"},
        {pos: [6, 4, 4], state: "minecraft:gravel"},
        {pos: [6, 4, 5], state: "minecraft:gravel"},
        {pos: [6, 4, 6], state: "minecraft:gravel"},
        {pos: [6, 4, 7], state: "minecraft:gravel"},
        {pos: [6, 4, 8], state: "minecraft:gravel"},
        {pos: [6, 4, 9], state: "minecraft:brown_terracotta"},
        {pos: [7, 4, 3], state: "minecraft:brown_terracotta"},
        {pos: [7, 4, 4], state: "minecraft:gravel"},
        {pos: [7, 4, 5], state: "minecraft:gravel"},
        {pos: [7, 4, 6], state: "minecraft:gravel"},
        {pos: [7, 4, 7], state: "minecraft:gravel"},
        {pos: [7, 4, 8], state: "minecraft:gravel"},
        {pos: [7, 4, 9], state: "minecraft:brown_terracotta"},
        {pos: [8, 4, 4], state: "minecraft:brown_terracotta"},
        {pos: [8, 4, 5], state: "minecraft:brown_terracotta"},
        {pos: [8, 4, 6], state: "minecraft:brown_terracotta"},
        {pos: [8, 4, 7], state: "minecraft:brown_terracotta"},
        {pos: [8, 4, 8], state: "minecraft:brown_terracotta"},
        {pos: [0, 5, 3], state: "minecraft:gravel"},
        {pos: [0, 5, 4], state: "minecraft:gravel"},
        {pos: [0, 5, 5], state: "minecraft:gravel"},
        {pos: [0, 5, 6], state: "minecraft:gravel"},
        {pos: [0, 5, 7], state: "minecraft:gravel"},
        {pos: [0, 5, 9], state: "minecraft:gravel"},
        {pos: [1, 5, 2], state: "minecraft:gravel"},
        {pos: [1, 5, 3], state: "minecraft:gravel"},
        {pos: [1, 5, 4], state: "minecraft:gravel"},
        {pos: [1, 5, 5], state: "minecraft:gravel"},
        {pos: [1, 5, 6], state: "minecraft:gravel"},
        {pos: [1, 5, 7], state: "minecraft:gravel"},
        {pos: [1, 5, 8], state: "minecraft:gravel"},
        {pos: [1, 5, 9], state: "minecraft:gravel"},
        {pos: [2, 5, 2], state: "minecraft:bricks"},
        {pos: [2, 5, 3], state: "minecraft:brown_terracotta"},
        {pos: [2, 5, 4], state: "minecraft:brown_terracotta"},
        {pos: [2, 5, 5], state: "minecraft:brown_terracotta"},
        {pos: [2, 5, 6], state: "minecraft:brown_terracotta"},
        {pos: [2, 5, 7], state: "minecraft:brown_terracotta"},
        {pos: [2, 5, 8], state: "minecraft:brown_terracotta"},
        {pos: [2, 5, 9], state: "minecraft:gravel"},
        {pos: [3, 5, 3], state: "minecraft:brown_terracotta"},
        {pos: [3, 5, 4], state: "minecraft:bricks"},
        {pos: [3, 5, 5], state: "minecraft:gravel"},
        {pos: [3, 5, 6], state: "minecraft:bricks"},
        {pos: [3, 5, 7], state: "minecraft:gravel"},
        {pos: [3, 5, 8], state: "minecraft:bricks"},
        {pos: [3, 5, 9], state: "minecraft:brown_terracotta"},
        {pos: [4, 5, 3], state: "minecraft:brown_terracotta"},
        {pos: [4, 5, 4], state: "minecraft:bricks"},
        {pos: [4, 5, 5], state: "minecraft:gravel"},
        {pos: [4, 5, 6], state: "minecraft:bricks"},
        {pos: [4, 5, 7], state: "minecraft:gravel"},
        {pos: [4, 5, 8], state: "minecraft:bricks"},
        {pos: [4, 5, 9], state: "minecraft:brown_terracotta"},
        {pos: [5, 5, 3], state: "minecraft:brown_terracotta"},
        {pos: [5, 5, 4], state: "minecraft:bricks"},
        {pos: [5, 5, 5], state: "minecraft:gravel"},
        {pos: [5, 5, 6], state: "minecraft:gravel"},
        {pos: [5, 5, 7], state: "minecraft:gravel"},
        {pos: [5, 5, 8], state: "minecraft:bricks"},
        {pos: [5, 5, 9], state: "minecraft:brown_terracotta"},
        {pos: [6, 5, 3], state: "minecraft:brown_terracotta"},
        {pos: [6, 5, 4], state: "minecraft:bricks"},
        {pos: [6, 5, 5], state: "minecraft:gravel"},
        {pos: [6, 5, 6], state: "minecraft:gravel"},
        {pos: [6, 5, 7], state: "minecraft:gravel"},
        {pos: [6, 5, 8], state: "minecraft:bricks"},
        {pos: [6, 5, 9], state: "minecraft:brown_terracotta"},
        {pos: [7, 5, 3], state: "minecraft:brown_terracotta"},
        {pos: [7, 5, 4], state: "minecraft:bricks"},
        {pos: [7, 5, 5], state: "minecraft:gravel"},
        {pos: [7, 5, 6], state: "minecraft:bricks"},
        {pos: [7, 5, 7], state: "minecraft:gravel"},
        {pos: [7, 5, 8], state: "minecraft:bricks"},
        {pos: [7, 5, 9], state: "minecraft:brown_terracotta"},
        {pos: [8, 5, 4], state: "minecraft:brown_terracotta"},
        {pos: [8, 5, 5], state: "minecraft:brown_terracotta"},
        {pos: [8, 5, 6], state: "minecraft:brown_terracotta"},
        {pos: [8, 5, 7], state: "minecraft:brown_terracotta"},
        {pos: [8, 5, 8], state: "minecraft:brown_terracotta"},
        {pos: [0, 6, 3], state: "minecraft:gravel"},
        {pos: [0, 6, 4], state: "minecraft:gravel"},
        {pos: [0, 6, 5], state: "minecraft:gravel"},
        {pos: [0, 6, 6], state: "minecraft:gravel"},
        {pos: [0, 6, 7], state: "minecraft:gravel"},
        {pos: [1, 6, 2], state: "minecraft:gravel"},
        {pos: [1, 6, 3], state: "minecraft:gravel"},
        {pos: [1, 6, 4], state: "minecraft:gravel"},
        {pos: [1, 6, 5], state: "minecraft:gravel"},
        {pos: [1, 6, 6], state: "minecraft:gravel"},
        {pos: [1, 6, 7], state: "minecraft:gravel"},
        {pos: [1, 6, 8], state: "minecraft:gravel"},
        {pos: [1, 6, 9], state: "minecraft:gravel"},
        {pos: [2, 6, 2], state: "minecraft:bricks"},
        {pos: [2, 6, 3], state: "minecraft:brown_terracotta"},
        {pos: [2, 6, 4], state: "minecraft:brown_terracotta"},
        {pos: [2, 6, 5], state: "minecraft:brown_terracotta"},
        {pos: [2, 6, 6], state: "minecraft:brown_terracotta"},
        {pos: [2, 6, 7], state: "minecraft:brown_terracotta"},
        {pos: [2, 6, 8], state: "minecraft:brown_terracotta"},
        {pos: [2, 6, 9], state: "minecraft:gravel"},
        {pos: [3, 6, 3], state: "minecraft:brown_terracotta"},
        {pos: [3, 6, 4], state: "minecraft:gravel"},
        {pos: [3, 6, 5], state: "minecraft:gravel"},
        {pos: [3, 6, 6], state: "minecraft:gravel"},
        {pos: [3, 6, 7], state: "minecraft:gravel"},
        {pos: [3, 6, 8], state: "minecraft:gravel"},
        {pos: [3, 6, 9], state: "minecraft:brown_terracotta"},
        {pos: [4, 6, 3], state: "minecraft:brown_terracotta"},
        {pos: [4, 6, 4], state: "minecraft:gravel"},
        {pos: [4, 6, 5], state: "minecraft:gravel"},
        {pos: [4, 6, 6], state: "minecraft:gravel"},
        {pos: [4, 6, 7], state: "minecraft:gravel"},
        {pos: [4, 6, 8], state: "minecraft:gravel"},
        {pos: [4, 6, 9], state: "minecraft:brown_terracotta"},
        {pos: [5, 6, 3], state: "minecraft:brown_terracotta"},
        {pos: [5, 6, 4], state: "minecraft:gravel"},
        {pos: [5, 6, 5], state: "minecraft:gravel"},
        {pos: [5, 6, 6], state: "minecraft:gravel"},
        {pos: [5, 6, 7], state: "minecraft:gravel"},
        {pos: [5, 6, 8], state: "minecraft:gravel"},
        {pos: [5, 6, 9], state: "minecraft:brown_terracotta"},
        {pos: [6, 6, 3], state: "minecraft:brown_terracotta"},
        {pos: [6, 6, 4], state: "minecraft:gravel"},
        {pos: [6, 6, 5], state: "minecraft:gravel"},
        {pos: [6, 6, 6], state: "minecraft:gravel"},
        {pos: [6, 6, 7], state: "minecraft:gravel"},
        {pos: [6, 6, 8], state: "minecraft:gravel"},
        {pos: [6, 6, 9], state: "minecraft:brown_terracotta"},
        {pos: [7, 6, 3], state: "minecraft:brown_terracotta"},
        {pos: [7, 6, 4], state: "minecraft:gravel"},
        {pos: [7, 6, 5], state: "minecraft:gravel"},
        {pos: [7, 6, 6], state: "minecraft:gravel"},
        {pos: [7, 6, 7], state: "minecraft:gravel"},
        {pos: [7, 6, 8], state: "minecraft:gravel"},
        {pos: [7, 6, 9], state: "minecraft:brown_terracotta"},
        {pos: [8, 6, 4], state: "minecraft:brown_terracotta"},
        {pos: [8, 6, 5], state: "minecraft:brown_terracotta"},
        {pos: [8, 6, 6], state: "minecraft:brown_terracotta"},
        {pos: [8, 6, 7], state: "minecraft:brown_terracotta"},
        {pos: [8, 6, 8], state: "minecraft:brown_terracotta"},
        {pos: [0, 7, 4], state: "minecraft:gravel"},
        {pos: [0, 7, 5], state: "minecraft:gravel"},
        {pos: [0, 7, 6], state: "minecraft:gravel"},
        {pos: [1, 7, 2], state: "minecraft:gravel"},
        {pos: [1, 7, 3], state: "minecraft:gravel"},
        {pos: [1, 7, 4], state: "minecraft:gravel"},
        {pos: [1, 7, 5], state: "minecraft:gravel"},
        {pos: [1, 7, 6], state: "minecraft:gravel"},
        {pos: [1, 7, 7], state: "minecraft:gravel"},
        {pos: [1, 7, 8], state: "minecraft:gravel"},
        {pos: [1, 7, 9], state: "minecraft:gravel"},
        {pos: [2, 7, 2], state: "minecraft:bricks"},
        {pos: [2, 7, 3], state: "minecraft:bricks"},
        {pos: [2, 7, 4], state: "minecraft:bricks"},
        {pos: [2, 7, 5], state: "minecraft:bricks"},
        {pos: [2, 7, 6], state: "minecraft:bricks"},
        {pos: [2, 7, 7], state: "minecraft:bricks"},
        {pos: [2, 7, 8], state: "minecraft:bricks"},
        {pos: [2, 7, 9], state: "minecraft:gravel"},
        {pos: [3, 7, 3], state: "minecraft:bricks"},
        {pos: [3, 7, 4], state: "minecraft:bricks"},
        {pos: [3, 7, 5], state: "minecraft:bricks"},
        {pos: [3, 7, 6], state: "minecraft:bricks"},
        {pos: [3, 7, 7], state: "minecraft:bricks"},
        {pos: [3, 7, 8], state: "minecraft:gravel"},
        {pos: [3, 7, 9], state: "minecraft:bricks"},
        {pos: [3, 7, 10], state: "minecraft:bricks"},
        {pos: [4, 7, 3], state: "minecraft:bricks"},
        {pos: [4, 7, 4], state: "minecraft:gravel"},
        {pos: [4, 7, 5], state: "minecraft:gravel"},
        {pos: [4, 7, 6], state: "minecraft:gravel"},
        {pos: [4, 7, 7], state: "minecraft:gravel"},
        {pos: [4, 7, 8], state: "minecraft:gravel"},
        {pos: [4, 7, 9], state: "minecraft:bricks"},
        {pos: [5, 7, 3], state: "minecraft:bricks"},
        {pos: [5, 7, 4], state: "minecraft:bricks"},
        {pos: [5, 7, 5], state: "minecraft:bricks"},
        {pos: [5, 7, 6], state: "minecraft:bricks"},
        {pos: [5, 7, 7], state: "minecraft:gravel"},
        {pos: [5, 7, 8], state: "minecraft:gravel"},
        {pos: [5, 7, 9], state: "minecraft:bricks"},
        {pos: [6, 7, 3], state: "minecraft:bricks"},
        {pos: [6, 7, 4], state: "minecraft:gravel"},
        {pos: [6, 7, 5], state: "minecraft:gravel"},
        {pos: [6, 7, 6], state: "minecraft:gravel"},
        {pos: [6, 7, 7], state: "minecraft:gravel"},
        {pos: [6, 7, 8], state: "minecraft:gravel"},
        {pos: [6, 7, 9], state: "minecraft:bricks"},
        {pos: [7, 7, 3], state: "minecraft:bricks"},
        {pos: [7, 7, 4], state: "minecraft:bricks"},
        {pos: [7, 7, 5], state: "minecraft:bricks"},
        {pos: [7, 7, 6], state: "minecraft:bricks"},
        {pos: [7, 7, 7], state: "minecraft:bricks"},
        {pos: [7, 7, 8], state: "minecraft:bricks"},
        {pos: [7, 7, 9], state: "minecraft:bricks"},
        {pos: [8, 7, 4], state: "minecraft:bricks"},
        {pos: [8, 7, 5], state: "minecraft:bricks"},
        {pos: [8, 7, 6], state: "minecraft:bricks"},
        {pos: [8, 7, 7], state: "minecraft:bricks"},
        {pos: [8, 7, 8], state: "minecraft:gravel"},
        {pos: [0, 8, 4], state: "minecraft:gravel"},
        {pos: [0, 8, 5], state: "minecraft:gravel"},
        {pos: [1, 8, 2], state: "minecraft:gravel"},
        {pos: [1, 8, 4], state: "minecraft:gravel"},
        {pos: [1, 8, 5], state: "minecraft:gravel"},
        {pos: [1, 8, 6], state: "minecraft:gravel"},
        {pos: [1, 8, 7], state: "minecraft:gravel"},
        {pos: [1, 8, 8], state: "minecraft:gravel"},
        {pos: [2, 8, 2], state: "minecraft:bricks"},
        {pos: [2, 8, 3], state: "minecraft:bricks"},
        {pos: [2, 8, 4], state: "minecraft:bricks"},
        {pos: [2, 8, 5], state: "minecraft:bricks"},
        {pos: [2, 8, 6], state: "minecraft:bricks"},
        {pos: [2, 8, 7], state: "minecraft:bricks"},
        {pos: [2, 8, 8], state: "minecraft:bricks"},
        {pos: [2, 8, 9], state: "minecraft:gravel"},
        {pos: [3, 8, 3], state: "minecraft:bricks"},
        {pos: [3, 8, 4], state: "minecraft:gravel"},
        {pos: [3, 8, 5], state: "minecraft:gravel"},
        {pos: [3, 8, 6], state: "minecraft:gravel"},
        {pos: [3, 8, 7], state: "minecraft:gravel"},
        {pos: [3, 8, 8], state: "minecraft:gravel"},
        {pos: [3, 8, 9], state: "minecraft:bricks"},
        {pos: [3, 8, 10], state: "minecraft:gravel"},
        {pos: [4, 8, 3], state: "minecraft:bricks"},
        {pos: [4, 8, 4], state: "minecraft:gravel"},
        {pos: [4, 8, 5], state: "minecraft:gravel"},
        {pos: [4, 8, 6], state: "minecraft:gravel"},
        {pos: [4, 8, 7], state: "minecraft:gravel"},
        {pos: [4, 8, 8], state: "minecraft:gravel"},
        {pos: [4, 8, 9], state: "minecraft:bricks"},
        {pos: [4, 8, 10], state: "minecraft:bricks"},
        {pos: [5, 8, 3], state: "minecraft:bricks"},
        {pos: [5, 8, 4], state: "minecraft:gravel"},
        {pos: [5, 8, 5], state: "minecraft:gravel"},
        {pos: [5, 8, 6], state: "minecraft:gravel"},
        {pos: [5, 8, 7], state: "minecraft:gravel"},
        {pos: [5, 8, 8], state: "minecraft:gravel"},
        {pos: [5, 8, 9], state: "minecraft:bricks"},
        {pos: [5, 8, 10], state: "minecraft:bricks"},
        {pos: [6, 8, 3], state: "minecraft:bricks"},
        {pos: [6, 8, 4], state: "minecraft:gravel"},
        {pos: [6, 8, 5], state: "minecraft:gravel"},
        {pos: [6, 8, 6], state: "minecraft:gravel"},
        {pos: [6, 8, 7], state: "minecraft:gravel"},
        {pos: [6, 8, 8], state: "minecraft:gravel"},
        {pos: [6, 8, 9], state: "minecraft:bricks"},
        {pos: [7, 8, 3], state: "minecraft:bricks"},
        {pos: [7, 8, 4], state: "minecraft:gravel"},
        {pos: [7, 8, 5], state: "minecraft:gravel"},
        {pos: [7, 8, 6], state: "minecraft:gravel"},
        {pos: [7, 8, 7], state: "minecraft:gravel"},
        {pos: [7, 8, 8], state: "minecraft:gravel"},
        {pos: [7, 8, 9], state: "minecraft:bricks"},
        {pos: [8, 8, 4], state: "minecraft:bricks"},
        {pos: [8, 8, 5], state: "minecraft:bricks"},
        {pos: [8, 8, 6], state: "minecraft:bricks"},
        {pos: [8, 8, 7], state: "minecraft:gravel"},
        {pos: [8, 8, 8], state: "minecraft:bricks"},
        {pos: [0, 9, 4], state: "minecraft:gravel"},
        {pos: [0, 9, 5], state: "minecraft:black_glazed_terracotta{facing:east}"},
        {pos: [0, 9, 6], state: "minecraft:black_glazed_terracotta{facing:south}"},
        {pos: [0, 9, 7], state: "minecraft:black_glazed_terracotta{facing:east}"},
        {pos: [0, 9, 8], state: "minecraft:black_glazed_terracotta{facing:north}"},
        {pos: [1, 9, 2], state: "minecraft:ladder{facing:west,waterlogged:false}"},
        {pos: [1, 9, 3], state: "minecraft:bricks"},
        {pos: [1, 9, 4], state: "minecraft:gravel"},
        {pos: [1, 9, 5], state: "minecraft:gravel"},
        {pos: [1, 9, 6], state: "minecraft:gravel"},
        {pos: [1, 9, 7], state: "minecraft:black_glazed_terracotta{facing:north}"},
        {pos: [1, 9, 8], state: "minecraft:black_glazed_terracotta{facing:west}"},
        {pos: [1, 9, 9], state: "minecraft:bricks"},
        {pos: [2, 9, 1], state: "minecraft:bricks"},
        {pos: [2, 9, 2], state: "minecraft:bricks"},
        {pos: [2, 9, 3], state: "minecraft:bricks"},
        {pos: [2, 9, 4], state: "minecraft:bricks"},
        {pos: [2, 9, 5], state: "minecraft:bricks"},
        {pos: [2, 9, 6], state: "minecraft:bricks"},
        {pos: [2, 9, 7], state: "minecraft:bricks"},
        {pos: [2, 9, 8], state: "minecraft:bricks"},
        {pos: [2, 9, 9], state: "minecraft:bricks"},
        {pos: [2, 9, 10], state: "minecraft:bricks"},
        {pos: [3, 9, 0], state: "minecraft:bricks"},
        {pos: [3, 9, 3], state: "minecraft:bricks"},
        {pos: [3, 9, 4], state: "minecraft:gravel"},
        {pos: [3, 9, 5], state: "minecraft:bricks"},
        {pos: [3, 9, 6], state: "minecraft:gravel"},
        {pos: [3, 9, 7], state: "minecraft:bricks"},
        {pos: [3, 9, 8], state: "minecraft:gravel"},
        {pos: [3, 9, 9], state: "minecraft:bricks"},
        {pos: [3, 9, 10], state: "minecraft:black_glazed_terracotta{facing:north}"},
        {pos: [3, 9, 12], state: "minecraft:bricks"},
        {pos: [4, 9, 0], state: "minecraft:bricks"},
        {pos: [4, 9, 1], state: "minecraft:black_glazed_terracotta{facing:east}"},
        {pos: [4, 9, 3], state: "minecraft:bricks"},
        {pos: [4, 9, 4], state: "minecraft:gravel"},
        {pos: [4, 9, 5], state: "minecraft:bricks"},
        {pos: [4, 9, 6], state: "minecraft:gravel"},
        {pos: [4, 9, 7], state: "minecraft:bricks"},
        {pos: [4, 9, 8], state: "minecraft:gravel"},
        {pos: [4, 9, 9], state: "minecraft:gravel"},
        {pos: [4, 9, 10], state: "minecraft:gravel"},
        {pos: [4, 9, 11], state: "minecraft:black_glazed_terracotta{facing:south}"},
        {pos: [4, 9, 12], state: "minecraft:bricks"},
        {pos: [5, 9, 0], state: "minecraft:bricks"},
        {pos: [5, 9, 1], state: "minecraft:black_glazed_terracotta{facing:north}"},
        {pos: [5, 9, 2], state: "minecraft:black_glazed_terracotta{facing:west}"},
        {pos: [5, 9, 3], state: "minecraft:bricks"},
        {pos: [5, 9, 4], state: "minecraft:gravel"},
        {pos: [5, 9, 5], state: "minecraft:bricks"},
        {pos: [5, 9, 6], state: "minecraft:gravel"},
        {pos: [5, 9, 7], state: "minecraft:bricks"},
        {pos: [5, 9, 8], state: "minecraft:gravel"},
        {pos: [5, 9, 9], state: "minecraft:gravel"},
        {pos: [5, 9, 10], state: "minecraft:gravel"},
        {pos: [5, 9, 11], state: "minecraft:black_glazed_terracotta{facing:west}"},
        {pos: [5, 9, 12], state: "minecraft:bricks"},
        {pos: [6, 9, 0], state: "minecraft:bricks"},
        {pos: [6, 9, 1], state: "minecraft:black_glazed_terracotta{facing:east}"},
        {pos: [6, 9, 2], state: "minecraft:black_glazed_terracotta{facing:south}"},
        {pos: [6, 9, 3], state: "minecraft:bricks"},
        {pos: [6, 9, 4], state: "minecraft:gravel"},
        {pos: [6, 9, 5], state: "minecraft:gravel"},
        {pos: [6, 9, 6], state: "minecraft:gravel"},
        {pos: [6, 9, 7], state: "minecraft:bricks"},
        {pos: [6, 9, 8], state: "minecraft:gravel"},
        {pos: [6, 9, 9], state: "minecraft:gravel"},
        {pos: [6, 9, 10], state: "minecraft:black_glazed_terracotta{facing:east}"},
        {pos: [6, 9, 11], state: "minecraft:black_glazed_terracotta{facing:south}"},
        {pos: [6, 9, 12], state: "minecraft:bricks"},
        {pos: [7, 9, 0], state: "minecraft:bricks"},
        {pos: [7, 9, 1], state: "minecraft:black_glazed_terracotta{facing:north}"},
        {pos: [7, 9, 2], state: "minecraft:black_glazed_terracotta{facing:west}"},
        {pos: [7, 9, 3], state: "minecraft:gravel"},
        {pos: [7, 9, 4], state: "minecraft:gravel"},
        {pos: [7, 9, 5], state: "minecraft:bricks"},
        {pos: [7, 9, 6], state: "minecraft:gravel"},
        {pos: [7, 9, 7], state: "minecraft:gravel"},
        {pos: [7, 9, 8], state: "minecraft:gravel"},
        {pos: [7, 9, 9], state: "minecraft:gravel"},
        {pos: [7, 9, 10], state: "minecraft:black_glazed_terracotta{facing:north}"},
        {pos: [7, 9, 11], state: "minecraft:black_glazed_terracotta{facing:west}"},
        {pos: [7, 9, 12], state: "minecraft:bricks"},
        {pos: [8, 9, 0], state: "minecraft:bricks"},
        {pos: [8, 9, 1], state: "minecraft:bricks"},
        {pos: [8, 9, 2], state: "minecraft:bricks"},
        {pos: [8, 9, 4], state: "minecraft:bricks"},
        {pos: [8, 9, 5], state: "minecraft:gravel"},
        {pos: [8, 9, 6], state: "minecraft:bricks"},
        {pos: [8, 9, 7], state: "minecraft:gravel"},
        {pos: [8, 9, 8], state: "minecraft:bricks"},
        {pos: [8, 9, 10], state: "minecraft:bricks"},
        {pos: [8, 9, 11], state: "minecraft:bricks"},
        {pos: [0, 10, 4], state: "minecraft:gravel"},
        {pos: [0, 10, 5], state: "minecraft:gravel"},
        {pos: [0, 10, 6], state: "minecraft:gravel"},
        {pos: [0, 10, 7], state: "minecraft:gravel"},
        {pos: [0, 10, 8], state: "minecraft:gravel"},
        {pos: [1, 10, 2], state: "minecraft:gravel"},
        {pos: [1, 10, 3], state: "minecraft:gravel"},
        {pos: [1, 10, 4], state: "minecraft:gravel"},
        {pos: [1, 10, 5], state: "minecraft:gravel"},
        {pos: [1, 10, 6], state: "minecraft:gravel"},
        {pos: [1, 10, 7], state: "minecraft:gravel"},
        {pos: [1, 10, 8], state: "minecraft:gravel"},
        {pos: [1, 10, 9], state: "minecraft:gravel"},
        {pos: [2, 10, 1], state: "minecraft:gravel"},
        {pos: [2, 10, 2], state: "minecraft:gravel"},
        {pos: [2, 10, 3], state: "minecraft:bricks"},
        {pos: [2, 10, 4], state: "minecraft:gravel"},
        {pos: [2, 10, 5], state: "minecraft:gravel"},
        {pos: [2, 10, 6], state: "minecraft:gravel"},
        {pos: [2, 10, 7], state: "minecraft:gravel"},
        {pos: [2, 10, 8], state: "minecraft:gravel"},
        {pos: [2, 10, 9], state: "minecraft:bricks"},
        {pos: [2, 10, 10], state: "minecraft:gravel"},
        {pos: [3, 10, 3], state: "minecraft:gravel"},
        {pos: [3, 10, 4], state: "minecraft:gravel"},
        {pos: [3, 10, 5], state: "minecraft:gravel"},
        {pos: [3, 10, 6], state: "minecraft:gravel"},
        {pos: [3, 10, 7], state: "minecraft:gravel"},
        {pos: [3, 10, 8], state: "minecraft:gravel"},
        {pos: [3, 10, 9], state: "minecraft:gravel"},
        {pos: [3, 10, 10], state: "minecraft:gravel"},
        {pos: [3, 10, 12], state: "minecraft:gravel"},
        {pos: [4, 10, 1], state: "minecraft:gravel"},
        {pos: [4, 10, 3], state: "minecraft:gravel"},
        {pos: [4, 10, 4], state: "minecraft:gravel"},
        {pos: [4, 10, 5], state: "minecraft:gravel"},
        {pos: [4, 10, 6], state: "minecraft:gravel"},
        {pos: [4, 10, 7], state: "minecraft:gravel"},
        {pos: [4, 10, 8], state: "minecraft:gravel"},
        {pos: [4, 10, 9], state: "minecraft:gravel"},
        {pos: [4, 10, 10], state: "minecraft:gravel"},
        {pos: [4, 10, 11], state: "minecraft:gravel"},
        {pos: [4, 10, 12], state: "minecraft:gravel"},
        {pos: [5, 10, 0], state: "minecraft:jigsaw{orientation:north_up}", nbt: {final_state: "minecraft:dirt", id: "minecraft:jigsaw", joint: "rollable", name: "minecraft:building_anchor", pool: "minecraft:trail_ruins/roads", target: "minecraft:road_anchor"}},
        {pos: [5, 10, 1], state: "minecraft:gravel"},
        {pos: [5, 10, 2], state: "minecraft:gravel"},
        {pos: [5, 10, 3], state: "minecraft:gravel"},
        {pos: [5, 10, 4], state: "minecraft:gravel"},
        {pos: [5, 10, 5], state: "minecraft:gravel"},
        {pos: [5, 10, 6], state: "minecraft:gravel"},
        {pos: [5, 10, 7], state: "minecraft:gravel"},
        {pos: [5, 10, 8], state: "minecraft:gravel"},
        {pos: [5, 10, 9], state: "minecraft:gravel"},
        {pos: [5, 10, 10], state: "minecraft:gravel"},
        {pos: [5, 10, 11], state: "minecraft:gravel"},
        {pos: [6, 10, 1], state: "minecraft:gravel"},
        {pos: [6, 10, 2], state: "minecraft:gravel"},
        {pos: [6, 10, 3], state: "minecraft:gravel"},
        {pos: [6, 10, 4], state: "minecraft:gravel"},
        {pos: [6, 10, 5], state: "minecraft:gravel"},
        {pos: [6, 10, 6], state: "minecraft:gravel"},
        {pos: [6, 10, 7], state: "minecraft:gravel"},
        {pos: [6, 10, 8], state: "minecraft:gravel"},
        {pos: [6, 10, 9], state: "minecraft:gravel"},
        {pos: [6, 10, 10], state: "minecraft:gravel"},
        {pos: [6, 10, 11], state: "minecraft:gravel"},
        {pos: [6, 10, 12], state: "minecraft:gravel"},
        {pos: [7, 10, 1], state: "minecraft:gravel"},
        {pos: [7, 10, 2], state: "minecraft:gravel"},
        {pos: [7, 10, 3], state: "minecraft:gravel"},
        {pos: [7, 10, 4], state: "minecraft:gravel"},
        {pos: [7, 10, 5], state: "minecraft:gravel"},
        {pos: [7, 10, 6], state: "minecraft:gravel"},
        {pos: [7, 10, 7], state: "minecraft:gravel"},
        {pos: [7, 10, 8], state: "minecraft:gravel"},
        {pos: [7, 10, 9], state: "minecraft:gravel"},
        {pos: [7, 10, 10], state: "minecraft:gravel"},
        {pos: [7, 10, 11], state: "minecraft:gravel"},
        {pos: [8, 10, 2], state: "minecraft:gravel"},
        {pos: [8, 10, 4], state: "minecraft:gravel"},
        {pos: [8, 10, 5], state: "minecraft:gravel"},
        {pos: [8, 10, 6], state: "minecraft:gravel"},
        {pos: [8, 10, 7], state: "minecraft:gravel"},
        {pos: [8, 10, 8], state: "minecraft:gravel"},
        {pos: [8, 10, 9], state: "minecraft:bricks"},
        {pos: [8, 10, 10], state: "minecraft:gravel"},
        {pos: [0, 11, 4], state: "minecraft:gravel"},
        {pos: [0, 11, 5], state: "minecraft:gravel"},
        {pos: [0, 11, 6], state: "minecraft:gravel"},
        {pos: [0, 11, 7], state: "minecraft:gravel"},
        {pos: [0, 11, 8], state: "minecraft:gravel"},
        {pos: [1, 11, 2], state: "minecraft:gravel"},
        {pos: [1, 11, 3], state: "minecraft:gravel"},
        {pos: [1, 11, 4], state: "minecraft:gravel"},
        {pos: [1, 11, 5], state: "minecraft:gravel"},
        {pos: [1, 11, 6], state: "minecraft:gravel"},
        {pos: [1, 11, 7], state: "minecraft:gravel"},
        {pos: [1, 11, 8], state: "minecraft:gravel"},
        {pos: [1, 11, 9], state: "minecraft:gravel"},
        {pos: [2, 11, 2], state: "minecraft:gravel"},
        {pos: [2, 11, 3], state: "minecraft:bricks"},
        {pos: [2, 11, 4], state: "minecraft:gravel"},
        {pos: [2, 11, 5], state: "minecraft:gravel"},
        {pos: [2, 11, 6], state: "minecraft:gravel"},
        {pos: [2, 11, 7], state: "minecraft:gravel"},
        {pos: [2, 11, 8], state: "minecraft:gravel"},
        {pos: [2, 11, 9], state: "minecraft:bricks"},
        {pos: [2, 11, 10], state: "minecraft:gravel"},
        {pos: [3, 11, 3], state: "minecraft:gravel"},
        {pos: [3, 11, 4], state: "minecraft:gravel"},
        {pos: [3, 11, 5], state: "minecraft:gravel"},
        {pos: [3, 11, 6], state: "minecraft:gravel"},
        {pos: [3, 11, 7], state: "minecraft:gravel"},
        {pos: [3, 11, 8], state: "minecraft:gravel"},
        {pos: [3, 11, 9], state: "minecraft:gravel"},
        {pos: [3, 11, 10], state: "minecraft:gravel"},
        {pos: [4, 11, 3], state: "minecraft:gravel"},
        {pos: [4, 11, 4], state: "minecraft:gravel"},
        {pos: [4, 11, 5], state: "minecraft:gravel"},
        {pos: [4, 11, 6], state: "minecraft:gravel"},
        {pos: [4, 11, 7], state: "minecraft:gravel"},
        {pos: [4, 11, 8], state: "minecraft:gravel"},
        {pos: [4, 11, 9], state: "minecraft:gravel"},
        {pos: [4, 11, 10], state: "minecraft:gravel"},
        {pos: [4, 11, 11], state: "minecraft:gravel"},
        {pos: [5, 11, 2], state: "minecraft:gravel"},
        {pos: [5, 11, 3], state: "minecraft:gravel"},
        {pos: [5, 11, 4], state: "minecraft:gravel"},
        {pos: [5, 11, 5], state: "minecraft:gravel"},
        {pos: [5, 11, 6], state: "minecraft:gravel"},
        {pos: [5, 11, 7], state: "minecraft:gravel"},
        {pos: [5, 11, 8], state: "minecraft:gravel"},
        {pos: [5, 11, 9], state: "minecraft:gravel"},
        {pos: [5, 11, 10], state: "minecraft:gravel"},
        {pos: [5, 11, 11], state: "minecraft:gravel"},
        {pos: [6, 11, 2], state: "minecraft:gravel"},
        {pos: [6, 11, 3], state: "minecraft:gravel"},
        {pos: [6, 11, 4], state: "minecraft:gravel"},
        {pos: [6, 11, 5], state: "minecraft:gravel"},
        {pos: [6, 11, 6], state: "minecraft:gravel"},
        {pos: [6, 11, 7], state: "minecraft:gravel"},
        {pos: [6, 11, 8], state: "minecraft:gravel"},
        {pos: [6, 11, 9], state: "minecraft:gravel"},
        {pos: [6, 11, 10], state: "minecraft:gravel"},
        {pos: [6, 11, 11], state: "minecraft:gravel"},
        {pos: [7, 11, 2], state: "minecraft:gravel"},
        {pos: [7, 11, 3], state: "minecraft:gravel"},
        {pos: [7, 11, 4], state: "minecraft:gravel"},
        {pos: [7, 11, 5], state: "minecraft:gravel"},
        {pos: [7, 11, 6], state: "minecraft:gravel"},
        {pos: [7, 11, 7], state: "minecraft:gravel"},
        {pos: [7, 11, 8], state: "minecraft:gravel"},
        {pos: [7, 11, 9], state: "minecraft:gravel"},
        {pos: [7, 11, 10], state: "minecraft:gravel"},
        {pos: [7, 11, 11], state: "minecraft:gravel"},
        {pos: [8, 11, 3], state: "minecraft:bricks"},
        {pos: [8, 11, 4], state: "minecraft:gravel"},
        {pos: [8, 11, 5], state: "minecraft:gravel"},
        {pos: [8, 11, 6], state: "minecraft:gravel"},
        {pos: [8, 11, 7], state: "minecraft:gravel"},
        {pos: [8, 11, 8], state: "minecraft:gravel"},
        {pos: [8, 11, 9], state: "minecraft:bricks"},
        {pos: [8, 11, 10], state: "minecraft:gravel"},
        {pos: [0, 12, 6], state: "minecraft:gravel"},
        {pos: [2, 12, 3], state: "minecraft:bricks"},
        {pos: [2, 12, 4], state: "minecraft:gravel"},
        {pos: [2, 12, 5], state: "minecraft:gravel"},
        {pos: [2, 12, 6], state: "minecraft:gravel"},
        {pos: [2, 12, 7], state: "minecraft:gravel"},
        {pos: [2, 12, 8], state: "minecraft:gravel"},
        {pos: [2, 12, 9], state: "minecraft:bricks"},
        {pos: [3, 12, 3], state: "minecraft:gravel"},
        {pos: [3, 12, 4], state: "minecraft:gravel"},
        {pos: [3, 12, 5], state: "minecraft:gravel"},
        {pos: [3, 12, 6], state: "minecraft:gravel"},
        {pos: [3, 12, 7], state: "minecraft:gravel"},
        {pos: [3, 12, 8], state: "minecraft:gravel"},
        {pos: [4, 12, 3], state: "minecraft:gravel"},
        {pos: [4, 12, 4], state: "minecraft:gravel"},
        {pos: [4, 12, 5], state: "minecraft:gravel"},
        {pos: [4, 12, 6], state: "minecraft:gravel"},
        {pos: [4, 12, 7], state: "minecraft:gravel"},
        {pos: [4, 12, 8], state: "minecraft:gravel"},
        {pos: [5, 12, 2], state: "minecraft:gravel"},
        {pos: [5, 12, 3], state: "minecraft:gravel"},
        {pos: [5, 12, 4], state: "minecraft:gravel"},
        {pos: [5, 12, 5], state: "minecraft:gravel"},
        {pos: [5, 12, 6], state: "minecraft:gravel"},
        {pos: [5, 12, 7], state: "minecraft:gravel"},
        {pos: [5, 12, 8], state: "minecraft:gravel"},
        {pos: [6, 12, 3], state: "minecraft:gravel"},
        {pos: [6, 12, 4], state: "minecraft:gravel"},
        {pos: [6, 12, 5], state: "minecraft:gravel"},
        {pos: [6, 12, 6], state: "minecraft:gravel"},
        {pos: [6, 12, 7], state: "minecraft:gravel"},
        {pos: [6, 12, 8], state: "minecraft:gravel"},
        {pos: [7, 12, 3], state: "minecraft:gravel"},
        {pos: [7, 12, 4], state: "minecraft:gravel"},
        {pos: [7, 12, 5], state: "minecraft:gravel"},
        {pos: [7, 12, 6], state: "minecraft:gravel"},
        {pos: [7, 12, 7], state: "minecraft:gravel"},
        {pos: [7, 12, 8], state: "minecraft:gravel"},
        {pos: [8, 12, 3], state: "minecraft:bricks"},
        {pos: [8, 12, 4], state: "minecraft:gravel"},
        {pos: [8, 12, 5], state: "minecraft:gravel"},
        {pos: [8, 12, 6], state: "minecraft:gravel"},
        {pos: [8, 12, 8], state: "minecraft:gravel"},
        {pos: [8, 12, 9], state: "minecraft:bricks"},
        {pos: [2, 13, 3], state: "minecraft:gravel"},
        {pos: [2, 13, 4], state: "minecraft:gravel"},
        {pos: [2, 13, 5], state: "minecraft:gravel"},
        {pos: [2, 13, 6], state: "minecraft:gravel"},
        {pos: [2, 13, 7], state: "minecraft:gravel"},
        {pos: [2, 13, 8], state: "minecraft:bricks"},
        {pos: [3, 13, 3], state: "minecraft:gravel"},
        {pos: [3, 13, 4], state: "minecraft:gravel"},
        {pos: [3, 13, 5], state: "minecraft:gravel"},
        {pos: [3, 13, 6], state: "minecraft:gravel"},
        {pos: [3, 13, 7], state: "minecraft:gravel"},
        {pos: [3, 13, 8], state: "minecraft:gravel"},
        {pos: [3, 13, 9], state: "minecraft:bricks"},
        {pos: [4, 13, 3], state: "minecraft:gravel"},
        {pos: [4, 13, 4], state: "minecraft:gravel"},
        {pos: [4, 13, 5], state: "minecraft:gravel"},
        {pos: [4, 13, 6], state: "minecraft:gravel"},
        {pos: [4, 13, 7], state: "minecraft:gravel"},
        {pos: [4, 13, 8], state: "minecraft:gravel"},
        {pos: [5, 13, 3], state: "minecraft:gravel"},
        {pos: [5, 13, 4], state: "minecraft:gravel"},
        {pos: [5, 13, 5], state: "minecraft:gravel"},
        {pos: [5, 13, 6], state: "minecraft:gravel"},
        {pos: [5, 13, 7], state: "minecraft:gravel"},
        {pos: [5, 13, 8], state: "minecraft:gravel"},
        {pos: [6, 13, 3], state: "minecraft:gravel"},
        {pos: [6, 13, 4], state: "minecraft:gravel"},
        {pos: [6, 13, 5], state: "minecraft:gravel"},
        {pos: [6, 13, 6], state: "minecraft:gravel"},
        {pos: [6, 13, 7], state: "minecraft:gravel"},
        {pos: [6, 13, 8], state: "minecraft:gravel"},
        {pos: [7, 13, 3], state: "minecraft:bricks"},
        {pos: [7, 13, 4], state: "minecraft:gravel"},
        {pos: [7, 13, 5], state: "minecraft:gravel"},
        {pos: [7, 13, 6], state: "minecraft:gravel"},
        {pos: [7, 13, 7], state: "minecraft:gravel"},
        {pos: [7, 13, 8], state: "minecraft:gravel"},
        {pos: [7, 13, 9], state: "minecraft:bricks"},
        {pos: [8, 13, 3], state: "minecraft:gravel"},
        {pos: [8, 13, 4], state: "minecraft:bricks"},
        {pos: [8, 13, 5], state: "minecraft:gravel"},
        {pos: [8, 13, 6], state: "minecraft:gravel"},
        {pos: [8, 13, 8], state: "minecraft:bricks"},
        {pos: [2, 14, 3], state: "minecraft:gravel"},
        {pos: [2, 14, 4], state: "minecraft:gravel"},
        {pos: [2, 14, 5], state: "minecraft:bricks"},
        {pos: [2, 14, 6], state: "minecraft:bricks"},
        {pos: [2, 14, 7], state: "minecraft:bricks"},
        {pos: [2, 14, 8], state: "minecraft:gravel"},
        {pos: [3, 14, 3], state: "minecraft:gravel"},
        {pos: [3, 14, 4], state: "minecraft:gravel"},
        {pos: [3, 14, 5], state: "minecraft:bricks"},
        {pos: [3, 14, 6], state: "minecraft:bricks"},
        {pos: [3, 14, 7], state: "minecraft:bricks"},
        {pos: [3, 14, 8], state: "minecraft:bricks"},
        {pos: [4, 14, 3], state: "minecraft:gravel"},
        {pos: [4, 14, 4], state: "minecraft:gravel"},
        {pos: [4, 14, 5], state: "minecraft:gravel"},
        {pos: [4, 14, 6], state: "minecraft:gravel"},
        {pos: [4, 14, 7], state: "minecraft:gravel"},
        {pos: [4, 14, 8], state: "minecraft:bricks"},
        {pos: [4, 14, 9], state: "minecraft:bricks"},
        {pos: [5, 14, 3], state: "minecraft:bricks"},
        {pos: [5, 14, 4], state: "minecraft:bricks"},
        {pos: [5, 14, 5], state: "minecraft:bricks"},
        {pos: [5, 14, 6], state: "minecraft:gravel"},
        {pos: [5, 14, 7], state: "minecraft:bricks"},
        {pos: [5, 14, 8], state: "minecraft:bricks"},
        {pos: [5, 14, 9], state: "minecraft:bricks"},
        {pos: [6, 14, 3], state: "minecraft:bricks"},
        {pos: [6, 14, 4], state: "minecraft:bricks"},
        {pos: [6, 14, 5], state: "minecraft:bricks"},
        {pos: [6, 14, 6], state: "minecraft:bricks"},
        {pos: [6, 14, 7], state: "minecraft:bricks"},
        {pos: [6, 14, 8], state: "minecraft:bricks"},
        {pos: [6, 14, 9], state: "minecraft:bricks"},
        {pos: [7, 14, 3], state: "minecraft:gravel"},
        {pos: [7, 14, 4], state: "minecraft:bricks"},
        {pos: [7, 14, 5], state: "minecraft:bricks"},
        {pos: [7, 14, 6], state: "minecraft:bricks"},
        {pos: [7, 14, 7], state: "minecraft:bricks"},
        {pos: [7, 14, 8], state: "minecraft:bricks"},
        {pos: [8, 14, 3], state: "minecraft:gravel"},
        {pos: [8, 14, 4], state: "minecraft:gravel"},
        {pos: [8, 14, 5], state: "minecraft:bricks"},
        {pos: [8, 14, 6], state: "minecraft:bricks"},
        {pos: [8, 14, 7], state: "minecraft:bricks"},
        {pos: [8, 14, 8], state: "minecraft:gravel"}
    ],
    entities: [],
    palette: [
        "minecraft:bricks",
        "minecraft:brown_terracotta",
        "minecraft:gravel",
        "minecraft:black_glazed_terracotta{facing:east}",
        "minecraft:black_glazed_terracotta{facing:south}",
        "minecraft:black_glazed_terracotta{facing:north}",
        "minecraft:black_glazed_terracotta{facing:west}",
        "minecraft:ladder{facing:west,waterlogged:false}",
        "minecraft:blast_furnace{facing:south,lit:false}",
        "minecraft:blast_furnace{facing:north,lit:false}",
        "minecraft:jigsaw{orientation:north_up}"
    ]
}
