{
    size: [10, 10, 10],
    data: [
        {pos: [2, 0, 1], state: "minecraft:grass_block{snowy:false}"},
        {pos: [2, 0, 3], state: "minecraft:dirt"},
        {pos: [2, 0, 4], state: "minecraft:dirt"},
        {pos: [2, 0, 5], state: "minecraft:dirt"},
        {pos: [2, 0, 7], state: "minecraft:grass_block{snowy:false}"},
        {pos: [3, 0, 1], state: "minecraft:grass_block{snowy:false}"},
        {pos: [3, 0, 2], state: "minecraft:dirt"},
        {pos: [3, 0, 3], state: "minecraft:dirt"},
        {pos: [3, 0, 4], state: "minecraft:dirt"},
        {pos: [3, 0, 5], state: "minecraft:dirt"},
        {pos: [3, 0, 6], state: "minecraft:dirt"},
        {pos: [3, 0, 7], state: "minecraft:dirt"},
        {pos: [4, 0, 1], state: "minecraft:dirt"},
        {pos: [4, 0, 2], state: "minecraft:dirt"},
        {pos: [4, 0, 3], state: "minecraft:dirt"},
        {pos: [4, 0, 4], state: "minecraft:dirt"},
        {pos: [4, 0, 5], state: "minecraft:dirt"},
        {pos: [4, 0, 6], state: "minecraft:dirt"},
        {pos: [4, 0, 7], state: "minecraft:dirt"},
        {pos: [4, 0, 8], state: "minecraft:dirt"},
        {pos: [5, 0, 2], state: "minecraft:dirt"},
        {pos: [5, 0, 3], state: "minecraft:dirt"},
        {pos: [5, 0, 4], state: "minecraft:grass_block{snowy:false}"},
        {pos: [5, 0, 5], state: "minecraft:dirt"},
        {pos: [5, 0, 6], state: "minecraft:dirt"},
        {pos: [5, 0, 7], state: "minecraft:dirt"},
        {pos: [5, 0, 8], state: "minecraft:dirt"},
        {pos: [5, 0, 9], state: "minecraft:grass_block{snowy:false}"},
        {pos: [6, 0, 0], state: "minecraft:grass_block{snowy:false}"},
        {pos: [6, 0, 2], state: "minecraft:dirt"},
        {pos: [6, 0, 3], state: "minecraft:dirt"},
        {pos: [6, 0, 4], state: "minecraft:dirt"},
        {pos: [6, 0, 5], state: "minecraft:dirt"},
        {pos: [6, 0, 6], state: "minecraft:dirt"},
        {pos: [6, 0, 7], state: "minecraft:dirt"},
        {pos: [6, 0, 8], state: "minecraft:dirt"},
        {pos: [7, 0, 3], state: "minecraft:dirt"},
        {pos: [7, 0, 4], state: "minecraft:dirt"},
        {pos: [7, 0, 5], state: "minecraft:dirt"},
        {pos: [7, 0, 6], state: "minecraft:dirt"},
        {pos: [7, 0, 7], state: "minecraft:dirt"},
        {pos: [8, 0, 1], state: "minecraft:grass_block{snowy:false}"},
        {pos: [8, 0, 4], state: "minecraft:dirt_path"},
        {pos: [8, 0, 5], state: "minecraft:dirt"},
        {pos: [8, 0, 6], state: "minecraft:dirt"},
        {pos: [8, 0, 7], state: "minecraft:dirt"},
        {pos: [8, 0, 8], state: "minecraft:grass_block{snowy:false}"},
        {pos: [9, 0, 4], state: "minecraft:jigsaw{orientation:east_up}", nbt: {components: {}, final_state: "minecraft:dirt_path", id: "minecraft:jigsaw", joint: "rollable", name: "minecraft:end_connector", placement_priority: 0, pool: "minecraft:empty", selection_priority: 0, target: "minecraft:connector"}},
        {pos: [2, 1, 1], state: "minecraft:rose_bush{half:lower}"},
        {pos: [2, 1, 3], state: "minecraft:grass_block{snowy:false}"},
        {pos: [2, 1, 4], state: "minecraft:grass_block{snowy:false}"},
        {pos: [2, 1, 5], state: "minecraft:grass_block{snowy:false}"},
        {pos: [2, 1, 7], state: "minecraft:rose_bush{half:lower}"},
        {pos: [3, 1, 2], state: "minecraft:grass_block{snowy:false}"},
        {pos: [3, 1, 3], state: "minecraft:dirt"},
        {pos: [3, 1, 4], state: "minecraft:dirt"},
        {pos: [3, 1, 5], state: "minecraft:dirt"},
        {pos: [3, 1, 6], state: "minecraft:grass_block{snowy:false}"},
        {pos: [3, 1, 7], state: "minecraft:grass_block{snowy:false}"},
        {pos: [4, 1, 1], state: "minecraft:grass_block{snowy:false}"},
        {pos: [4, 1, 2], state: "minecraft:dirt"},
        {pos: [4, 1, 3], state: "minecraft:dirt"},
        {pos: [4, 1, 4], state: "minecraft:dirt"},
        {pos: [4, 1, 5], state: "minecraft:dirt"},
        {pos: [4, 1, 6], state: "minecraft:dirt"},
        {pos: [4, 1, 7], state: "minecraft:grass_block{snowy:false}"},
        {pos: [4, 1, 8], state: "minecraft:grass_block{snowy:false}"},
        {pos: [5, 1, 2], state: "minecraft:dirt"},
        {pos: [5, 1, 3], state: "minecraft:dirt"},
        {pos: [5, 1, 4], state: "minecraft:oxidized_copper_chest{facing:east,type:single,waterlogged:false}", nbt: {Items: [], LootTable: "minecraft:chests/abandoned_camp_secret_chest", components: {}, id: "minecraft:chest"}},
        {pos: [5, 1, 5], state: "minecraft:dirt"},
        {pos: [5, 1, 6], state: "minecraft:dirt"},
        {pos: [5, 1, 7], state: "minecraft:dirt"},
        {pos: [5, 1, 8], state: "minecraft:grass_block{snowy:false}"},
        {pos: [5, 1, 9], state: "minecraft:rose_bush{half:lower}"},
        {pos: [6, 1, 0], state: "minecraft:rose_bush{half:lower}"},
        {pos: [6, 1, 2], state: "minecraft:grass_block{snowy:false}"},
        {pos: [6, 1, 3], state: "minecraft:dirt"},
        {pos: [6, 1, 4], state: "minecraft:dirt"},
        {pos: [6, 1, 5], state: "minecraft:dirt"},
        {pos: [6, 1, 6], state: "minecraft:dirt"},
        {pos: [6, 1, 7], state: "minecraft:grass_block{snowy:false}"},
        {pos: [6, 1, 8], state: "minecraft:grass_block{snowy:false}"},
        {pos: [7, 1, 3], state: "minecraft:grass_block{snowy:false}"},
        {pos: [7, 1, 4], state: "minecraft:dirt_path"},
        {pos: [7, 1, 5], state: "minecraft:dirt"},
        {pos: [7, 1, 6], state: "minecraft:grass_block{snowy:false}"},
        {pos: [7, 1, 7], state: "minecraft:grass_block{snowy:false}"},
        {pos: [8, 1, 1], state: "minecraft:rose_bush{half:lower}"},
        {pos: [8, 1, 5], state: "minecraft:grass_block{snowy:false}"},
        {pos: [8, 1, 6], state: "minecraft:grass_block{snowy:false}"},
        {pos: [8, 1, 7], state: "minecraft:grass_block{snowy:false}"},
        {pos: [8, 1, 8], state: "minecraft:rose_bush{half:lower}"},
        {pos: [2, 2, 1], state: "minecraft:rose_bush{half:upper}"},
        {pos: [2, 2, 3], state: "minecraft:rose_bush{half:lower}"},
        {pos: [2, 2, 5], state: "minecraft:rose_bush{half:lower}"},
        {pos: [2, 2, 7], state: "minecraft:rose_bush{half:upper}"},
        {pos: [3, 2, 3], state: "minecraft:grass_block{snowy:false}"},
        {pos: [3, 2, 4], state: "minecraft:grass_block{snowy:false}"},
        {pos: [3, 2, 5], state: "minecraft:grass_block{snowy:false}"},
        {pos: [4, 2, 1], state: "minecraft:rose_bush{half:lower}"},
        {pos: [4, 2, 2], state: "minecraft:grass_block{snowy:false}"},
        {pos: [4, 2, 3], state: "minecraft:dirt_path"},
        {pos: [4, 2, 4], state: "minecraft:dirt_path"},
        {pos: [4, 2, 5], state: "minecraft:dirt_path"},
        {pos: [4, 2, 6], state: "minecraft:grass_block{snowy:false}"},
        {pos: [4, 2, 7], state: "minecraft:rose_bush{half:lower}"},
        {pos: [5, 2, 2], state: "minecraft:grass_block{snowy:false}"},
        {pos: [5, 2, 3], state: "minecraft:dirt_path"},
        {pos: [5, 2, 4], state: "minecraft:gravel"},
        {pos: [5, 2, 5], state: "minecraft:dirt_path"},
        {pos: [5, 2, 6], state: "minecraft:dirt"},
        {pos: [5, 2, 7], state: "minecraft:grass_block{snowy:false}"},
        {pos: [5, 2, 9], state: "minecraft:rose_bush{half:upper}"},
        {pos: [6, 2, 0], state: "minecraft:rose_bush{half:upper}"},
        {pos: [6, 2, 2], state: "minecraft:rose_bush{half:lower}"},
        {pos: [6, 2, 3], state: "minecraft:grass_block{snowy:false}"},
        {pos: [6, 2, 4], state: "minecraft:dirt_path"},
        {pos: [6, 2, 5], state: "minecraft:dirt_path"},
        {pos: [6, 2, 6], state: "minecraft:grass_block{snowy:false}"},
        {pos: [6, 2, 7], state: "minecraft:rose_bush{half:lower}"},
        {pos: [7, 2, 5], state: "minecraft:grass_block{snowy:false}"},
        {pos: [8, 2, 1], state: "minecraft:rose_bush{half:upper}"},
        {pos: [8, 2, 6], state: "minecraft:rose_bush{half:lower}"},
        {pos: [8, 2, 8], state: "minecraft:rose_bush{half:upper}"},
        {pos: [2, 3, 3], state: "minecraft:rose_bush{half:upper}"},
        {pos: [2, 3, 5], state: "minecraft:rose_bush{half:upper}"},
        {pos: [3, 3, 5], state: "minecraft:rose_bush{half:lower}"},
        {pos: [4, 3, 1], state: "minecraft:rose_bush{half:upper}"},
        {pos: [4, 3, 7], state: "minecraft:rose_bush{half:upper}"},
        {pos: [5, 3, 2], state: "minecraft:rose_bush{half:lower}"},
        {pos: [5, 3, 4], state: "minecraft:campfire{facing:north,lit:false,signal_fire:false,waterlogged:false}", nbt: {CookingTimes: [I; 0, 0, 0, 0], CookingTotalTimes: [I; 0, 0, 0, 0], Items: [], components: {}, id: "minecraft:campfire"}},
        {pos: [5, 3, 6], state: "minecraft:barrel{facing:up,open:false}", nbt: {Items: [], LootTable: "minecraft:barrels/abandoned_camp_barrel", components: {}, id: "minecraft:barrel"}},
        {pos: [6, 3, 2], state: "minecraft:rose_bush{half:upper}"},
        {pos: [6, 3, 7], state: "minecraft:rose_bush{half:upper}"},
        {pos: [7, 3, 5], state: "minecraft:rose_bush{half:lower}"},
        {pos: [8, 3, 6], state: "minecraft:rose_bush{half:upper}"},
        {pos: [3, 4, 5], state: "minecraft:rose_bush{half:upper}"},
        {pos: [5, 4, 2], state: "minecraft:rose_bush{half:upper}"},
        {pos: [7, 4, 5], state: "minecraft:rose_bush{half:upper}"}
    ],
    entities: [
        {blockPos: [4, 2, 3], pos: [4.5d, 2.9375d, 3.5d], nbt: {Air: 300s, Fire: 0s, Invulnerable: 0b, Motion: [0.0d, 0.0d, 0.0d], OnGround: 0b, PortalCooldown: 0, Pos: [-106.5d, -58.0625d, 135.5d], Rotation: [90.0f, 0.0f], UUID: [I; 352678158, -600160457, -1402876533, -419871179], block_pos: [I; -107, -59, 135], color: "red", fall_distance: 0.0d, id: "minecraft:cushion"}},
        {blockPos: [4, 2, 5], pos: [4.5d, 2.9375d, 5.5d], nbt: {Air: 300s, Fire: 0s, Invulnerable: 0b, Motion: [0.0d, 0.0d, 0.0d], OnGround: 0b, PortalCooldown: 0, Pos: [-106.5d, -58.0625d, 137.5d], Rotation: [0.0f, 0.0f], UUID: [I; 928319803, 1364413348, -1273071326, -320951314], block_pos: [I; -107, -59, 137], color: "red", fall_distance: 0.0d, id: "minecraft:cushion"}},
        {blockPos: [6, 2, 5], pos: [6.5d, 2.9375d, 5.5d], nbt: {Air: 300s, Fire: 0s, Invulnerable: 0b, Motion: [0.0d, 0.0d, 0.0d], OnGround: 0b, PortalCooldown: 0, Pos: [-104.5d, -58.0625d, 137.5d], Rotation: [0.0f, 0.0f], UUID: [I; 194549991, 324420993, -1820880092, 2116820271], block_pos: [I; -105, -59, 137], color: "red", fall_distance: 0.0d, id: "minecraft:cushion"}}
    ],
    palette: [
        "minecraft:grass_block{snowy:false}",
        "minecraft:dirt",
        "minecraft:gravel",
        "minecraft:dirt_path",
        "minecraft:rose_bush{half:lower}",
        "minecraft:rose_bush{half:upper}",
        "minecraft:jigsaw{orientation:east_up}",
        "minecraft:oxidized_copper_chest{facing:east,type:single,waterlogged:false}",
        "minecraft:campfire{facing:north,lit:false,signal_fire:false,waterlogged:false}",
        "minecraft:barrel{facing:up,open:false}"
    ]
}
