{
    size: [10, 10, 10],
    data: [
        {pos: [0, 0, 2], state: "minecraft:dirt"},
        {pos: [0, 0, 3], state: "minecraft:dirt"},
        {pos: [0, 0, 4], state: "minecraft:dirt"},
        {pos: [1, 0, 1], state: "minecraft:dirt"},
        {pos: [1, 0, 2], state: "minecraft:dirt"},
        {pos: [1, 0, 3], state: "minecraft:dirt"},
        {pos: [1, 0, 4], state: "minecraft:dirt"},
        {pos: [1, 0, 5], state: "minecraft:dirt"},
        {pos: [2, 0, 2], state: "minecraft:dirt"},
        {pos: [2, 0, 3], state: "minecraft:dirt"},
        {pos: [2, 0, 4], state: "minecraft:dirt"},
        {pos: [2, 0, 7], state: "minecraft:dirt"},
        {pos: [3, 0, 3], state: "minecraft:dirt"},
        {pos: [3, 0, 4], state: "minecraft:grass_block{snowy:false}"},
        {pos: [3, 0, 5], state: "minecraft:dirt"},
        {pos: [4, 0, 4], state: "minecraft:dirt"},
        {pos: [4, 0, 5], state: "minecraft:dirt"},
        {pos: [4, 0, 6], state: "minecraft:dirt"},
        {pos: [4, 0, 7], state: "minecraft:dirt"},
        {pos: [4, 0, 8], state: "minecraft:dirt"},
        {pos: [5, 0, 5], state: "minecraft:oxidized_copper_chest{facing:south,type:single,waterlogged:false}", nbt: {LootTable: "minecraft:chests/abandoned_camp_secret_chest", components: {}, id: "minecraft:chest"}},
        {pos: [5, 0, 6], state: "minecraft:dirt"},
        {pos: [5, 0, 7], state: "minecraft:dirt"},
        {pos: [6, 0, 2], state: "minecraft:dirt"},
        {pos: [6, 0, 3], state: "minecraft:dirt"},
        {pos: [6, 0, 4], state: "minecraft:dirt"},
        {pos: [6, 0, 5], state: "minecraft:dirt"},
        {pos: [6, 0, 6], state: "minecraft:dirt"},
        {pos: [6, 0, 8], state: "minecraft:dirt"},
        {pos: [7, 0, 2], state: "minecraft:dirt"},
        {pos: [7, 0, 3], state: "minecraft:dirt"},
        {pos: [7, 0, 4], state: "minecraft:dirt"},
        {pos: [7, 0, 5], state: "minecraft:dirt"},
        {pos: [7, 0, 6], state: "minecraft:dirt"},
        {pos: [7, 0, 7], state: "minecraft:dirt"},
        {pos: [8, 0, 2], state: "minecraft:dirt"},
        {pos: [8, 0, 3], state: "minecraft:dirt"},
        {pos: [8, 0, 4], state: "minecraft:dirt"},
        {pos: [8, 0, 7], state: "minecraft:dirt"},
        {pos: [8, 0, 8], state: "minecraft:dirt"},
        {pos: [9, 0, 2], state: "minecraft:dirt"},
        {pos: [9, 0, 3], state: "minecraft:dirt"},
        {pos: [9, 0, 4], state: "minecraft:dirt"},
        {pos: [0, 1, 2], state: "minecraft:grass_block{snowy:false}"},
        {pos: [0, 1, 3], state: "minecraft:grass_block{snowy:false}"},
        {pos: [0, 1, 4], state: "minecraft:grass_block{snowy:false}"},
        {pos: [1, 1, 1], state: "minecraft:grass_block{snowy:false}"},
        {pos: [1, 1, 2], state: "minecraft:grass_block{snowy:false}"},
        {pos: [1, 1, 3], state: "minecraft:grass_block{snowy:false}"},
        {pos: [1, 1, 4], state: "minecraft:grass_block{snowy:false}"},
        {pos: [1, 1, 5], state: "minecraft:grass_block{snowy:false}"},
        {pos: [2, 1, 2], state: "minecraft:grass_block{snowy:false}"},
        {pos: [2, 1, 3], state: "minecraft:grass_block{snowy:false}"},
        {pos: [2, 1, 4], state: "minecraft:grass_block{snowy:false}"},
        {pos: [2, 1, 7], state: "minecraft:jigsaw{orientation:up_east}", nbt: {components: {}, final_state: "minecraft:dirt", id: "minecraft:jigsaw", joint: "rollable", name: "minecraft:bottom", placement_priority: 0, pool: "minecraft:abandoned_camp/trees/oak", selection_priority: 0, target: "minecraft:bottom"}},
        {pos: [3, 1, 3], state: "minecraft:grass_block{snowy:false}"},
        {pos: [3, 1, 5], state: "minecraft:grass_block{snowy:false}"},
        {pos: [4, 1, 4], state: "minecraft:grass_block{snowy:false}"},
        {pos: [4, 1, 5], state: "minecraft:dirt_path"},
        {pos: [4, 1, 6], state: "minecraft:dirt_path"},
        {pos: [4, 1, 7], state: "minecraft:grass_block{snowy:false}"},
        {pos: [4, 1, 8], state: "minecraft:grass_block{snowy:false}"},
        {pos: [5, 1, 5], state: "minecraft:gravel"},
        {pos: [5, 1, 6], state: "minecraft:dirt_path"},
        {pos: [5, 1, 7], state: "minecraft:grass_block{snowy:false}"},
        {pos: [6, 1, 2], state: "minecraft:jigsaw{orientation:up_east}", nbt: {components: {}, final_state: "minecraft:dirt", id: "minecraft:jigsaw", joint: "rollable", name: "minecraft:bottom", placement_priority: 0, pool: "minecraft:abandoned_camp/trees/oak", selection_priority: 0, target: "minecraft:bottom"}},
        {pos: [6, 1, 3], state: "minecraft:dirt_path"},
        {pos: [6, 1, 4], state: "minecraft:dirt_path"},
        {pos: [6, 1, 5], state: "minecraft:dirt_path"},
        {pos: [6, 1, 6], state: "minecraft:grass_block{snowy:false}"},
        {pos: [6, 1, 8], state: "minecraft:grass_block{snowy:false}"},
        {pos: [7, 1, 2], state: "minecraft:dirt_path"},
        {pos: [7, 1, 3], state: "minecraft:dirt_path"},
        {pos: [7, 1, 4], state: "minecraft:dirt_path"},
        {pos: [7, 1, 5], state: "minecraft:grass_block{snowy:false}"},
        {pos: [7, 1, 6], state: "minecraft:grass_block{snowy:false}"},
        {pos: [7, 1, 7], state: "minecraft:jigsaw{orientation:up_west}", nbt: {components: {}, final_state: "minecraft:dirt", id: "minecraft:jigsaw", joint: "rollable", name: "minecraft:bottom", placement_priority: 0, pool: "minecraft:abandoned_camp/trees/oak", selection_priority: 0, target: "minecraft:bottom"}},
        {pos: [8, 1, 2], state: "minecraft:dirt_path"},
        {pos: [8, 1, 3], state: "minecraft:dirt_path"},
        {pos: [8, 1, 4], state: "minecraft:grass_block{snowy:false}"},
        {pos: [8, 1, 7], state: "minecraft:grass_block{snowy:false}"},
        {pos: [8, 1, 8], state: "minecraft:grass_block{snowy:false}"},
        {pos: [9, 1, 2], state: "minecraft:dirt_path"},
        {pos: [9, 1, 3], state: "minecraft:dirt_path"},
        {pos: [9, 1, 4], state: "minecraft:jigsaw{orientation:east_up}", nbt: {components: {}, final_state: "minecraft:dirt_path", id: "minecraft:jigsaw", joint: "rollable", name: "minecraft:end_connector", placement_priority: 0, pool: "minecraft:empty", selection_priority: 0, target: "minecraft:connector"}},
        {pos: [0, 2, 2], state: "minecraft:azure_bluet"},
        {pos: [0, 2, 4], state: "minecraft:azure_bluet"},
        {pos: [1, 2, 1], state: "minecraft:cornflower"},
        {pos: [1, 2, 2], state: "minecraft:allium"},
        {pos: [1, 2, 3], state: "minecraft:azure_bluet"},
        {pos: [1, 2, 4], state: "minecraft:allium"},
        {pos: [1, 2, 5], state: "minecraft:azure_bluet"},
        {pos: [2, 2, 2], state: "minecraft:allium"},
        {pos: [2, 2, 3], state: "minecraft:cornflower"},
        {pos: [2, 2, 4], state: "minecraft:allium"},
        {pos: [3, 2, 3], state: "minecraft:allium"},
        {pos: [3, 2, 5], state: "minecraft:chest{facing:east,type:single,waterlogged:false}", nbt: {LootTable: "minecraft:chests/abandoned_camp_common_chest", components: {}, id: "minecraft:chest"}},
        {pos: [4, 2, 4], state: "minecraft:cobweb"},
        {pos: [4, 2, 7], state: "minecraft:azure_bluet"},
        {pos: [4, 2, 8], state: "minecraft:azure_bluet"},
        {pos: [5, 2, 5], state: "minecraft:campfire{facing:west,lit:false,signal_fire:false,waterlogged:false}", nbt: {CookingTimes: [I; 0, 0, 0, 0], CookingTotalTimes: [I; 0, 0, 0, 0], Items: [], components: {}, id: "minecraft:campfire"}},
        {pos: [5, 2, 7], state: "minecraft:cobweb"},
        {pos: [6, 2, 6], state: "minecraft:cobweb"},
        {pos: [6, 2, 8], state: "minecraft:azure_bluet"},
        {pos: [7, 2, 5], state: "minecraft:cobweb"},
        {pos: [7, 2, 6], state: "minecraft:cornflower"},
        {pos: [8, 2, 4], state: "minecraft:cobweb"},
        {pos: [8, 2, 7], state: "minecraft:cornflower"},
        {pos: [8, 2, 8], state: "minecraft:allium"},
        {pos: [3, 3, 5], state: "minecraft:cobweb"}
    ],
    entities: [
        {blockPos: [5, 1, 6], pos: [5.5d, 1.9375d, 6.5d], nbt: {Air: 300s, Fire: 0s, Invulnerable: 0b, Motion: [0.0d, 0.0d, 0.0d], OnGround: 0b, PortalCooldown: 0, Pos: [-88.5d, -60.0625d, 153.5d], Rotation: [90.0f, 0.0f], UUID: [I; 1435476212, 1819755894, -1556620720, 383559033], block_pos: [I; -89, -61, 153], color: "purple", fall_distance: 0.0d, id: "minecraft:cushion"}},
        {blockPos: [6, 1, 4], pos: [6.5d, 1.9375d, 4.5d], nbt: {Air: 300s, Fire: 0s, Invulnerable: 0b, Motion: [0.0d, 0.0d, 0.0d], OnGround: 0b, PortalCooldown: 0, Pos: [-87.5d, -60.0625d, 151.5d], Rotation: [90.0f, 0.0f], UUID: [I; -1306149724, 445401312, -1463617250, 1250240476], block_pos: [I; -88, -61, 151], color: "blue", fall_distance: 0.0d, id: "minecraft:cushion"}}
    ],
    palette: [
        "minecraft:dirt",
        "minecraft:grass_block{snowy:false}",
        "minecraft:gravel",
        "minecraft:dirt_path",
        "minecraft:azure_bluet",
        "minecraft:cornflower",
        "minecraft:allium",
        "minecraft:cobweb",
        "minecraft:oxidized_copper_chest{facing:south,type:single,waterlogged:false}",
        "minecraft:jigsaw{orientation:up_east}",
        "minecraft:jigsaw{orientation:up_west}",
        "minecraft:jigsaw{orientation:east_up}",
        "minecraft:chest{facing:east,type:single,waterlogged:false}",
        "minecraft:campfire{facing:west,lit:false,signal_fire:false,waterlogged:false}"
    ]
}
