{
    size: [5, 3, 3],
    data: [
        {pos: [0, 0, 0], state: "minecraft:cobblestone"},
        {pos: [0, 0, 1], state: "minecraft:cobblestone"},
        {pos: [0, 0, 2], state: "minecraft:cobblestone"},
        {pos: [1, 0, 0], state: "minecraft:cobblestone"},
        {pos: [1, 0, 1], state: "minecraft:cobblestone"},
        {pos: [1, 0, 2], state: "minecraft:cobblestone"},
        {pos: [2, 0, 0], state: "minecraft:cobblestone"},
        {pos: [2, 0, 1], state: "minecraft:cobblestone"},
        {pos: [2, 0, 2], state: "minecraft:cobblestone"},
        {pos: [3, 0, 0], state: "minecraft:cobblestone"},
        {pos: [3, 0, 1], state: "minecraft:cobblestone"},
        {pos: [3, 0, 2], state: "minecraft:cobblestone"},
        {pos: [4, 0, 0], state: "minecraft:cobblestone"},
        {pos: [4, 0, 1], state: "minecraft:cobblestone"},
        {pos: [4, 0, 2], state: "minecraft:cobblestone"},
        {pos: [0, 1, 0], state: "minecraft:cobblestone"},
        {pos: [0, 1, 1], state: "minecraft:cobblestone"},
        {pos: [0, 1, 2], state: "minecraft:cobblestone"},
        {pos: [1, 1, 0], state: "minecraft:cobblestone"},
        {pos: [1, 1, 1], state: "minecraft:cobblestone"},
        {pos: [1, 1, 2], state: "minecraft:cobblestone"},
        {pos: [2, 1, 0], state: "minecraft:cobblestone"},
        {pos: [2, 1, 1], state: "minecraft:cobblestone"},
        {pos: [2, 1, 2], state: "minecraft:cobblestone"},
        {pos: [3, 1, 0], state: "minecraft:cobblestone"},
        {pos: [3, 1, 1], state: "minecraft:cobblestone"},
        {pos: [3, 1, 2], state: "minecraft:cobblestone"},
        {pos: [4, 1, 0], state: "minecraft:cobblestone"},
        {pos: [4, 1, 1], state: "minecraft:cobblestone"},
        {pos: [4, 1, 2], state: "minecraft:cobblestone"},
        {pos: [0, 2, 0], state: "minecraft:red_terracotta"},
        {pos: [0, 2, 1], state: "minecraft:red_terracotta"},
        {pos: [0, 2, 2], state: "minecraft:red_terracotta"},
        {pos: [1, 2, 0], state: "minecraft:red_terracotta"},
        {pos: [1, 2, 1], state: "minecraft:coarse_dirt"},
        {pos: [1, 2, 2], state: "minecraft:red_terracotta"},
        {pos: [2, 2, 0], state: "minecraft:red_terracotta"},
        {pos: [2, 2, 1], state: "minecraft:coarse_dirt"},
        {pos: [2, 2, 2], state: "minecraft:jigsaw{orientation:south_up}", nbt: {final_state: "minecraft:red_terracotta", id: "minecraft:jigsaw", joint: "rollable", name: "minecraft:decor_anchor", pool: "minecraft:trail_ruins/roads", target: "minecraft:road_anchor"}},
        {pos: [3, 2, 0], state: "minecraft:red_terracotta"},
        {pos: [3, 2, 1], state: "minecraft:coarse_dirt"},
        {pos: [3, 2, 2], state: "minecraft:red_terracotta"},
        {pos: [4, 2, 0], state: "minecraft:red_terracotta"},
        {pos: [4, 2, 1], state: "minecraft:red_terracotta"},
        {pos: [4, 2, 2], state: "minecraft:red_terracotta"}
    ],
    entities: [],
    palette: [
        "minecraft:cobblestone",
        "minecraft:red_terracotta",
        "minecraft:coarse_dirt",
        "minecraft:jigsaw{orientation:south_up}"
    ]
}
