{
    size: [10, 10, 10],
    data: [
        {pos: [2, 0, 5], state: "minecraft:dirt"},
        {pos: [2, 0, 6], state: "minecraft:dirt"},
        {pos: [3, 0, 1], state: "minecraft:dirt"},
        {pos: [3, 0, 4], state: "minecraft:dirt_path"},
        {pos: [3, 0, 5], state: "minecraft:dirt_path"},
        {pos: [3, 0, 6], state: "minecraft:dirt"},
        {pos: [3, 0, 7], state: "minecraft:dirt"},
        {pos: [4, 0, 4], state: "minecraft:dirt_path"},
        {pos: [4, 0, 5], state: "minecraft:dirt_path"},
        {pos: [4, 0, 6], state: "minecraft:jigsaw{orientation:up_east}", nbt: {components: {}, final_state: "minecraft:dirt", id: "minecraft:jigsaw", joint: "rollable", name: "minecraft:bottom", placement_priority: 0, pool: "minecraft:abandoned_camp/trees/orange_poplar", selection_priority: 0, target: "minecraft:bottom"}},
        {pos: [4, 0, 7], state: "minecraft:dirt"},
        {pos: [4, 0, 8], state: "minecraft:dirt"},
        {pos: [5, 0, 1], state: "minecraft:dirt"},
        {pos: [5, 0, 4], state: "minecraft:dirt_path"},
        {pos: [5, 0, 5], state: "minecraft:dirt_path"},
        {pos: [5, 0, 6], state: "minecraft:dirt_path"},
        {pos: [5, 0, 7], state: "minecraft:dirt"},
        {pos: [5, 0, 8], state: "minecraft:dirt"},
        {pos: [6, 0, 1], state: "minecraft:dirt"},
        {pos: [6, 0, 4], state: "minecraft:dirt"},
        {pos: [6, 0, 5], state: "minecraft:dirt"},
        {pos: [6, 0, 6], state: "minecraft:dirt_path"},
        {pos: [6, 0, 7], state: "minecraft:dirt_path"},
        {pos: [6, 0, 8], state: "minecraft:dirt"},
        {pos: [7, 0, 1], state: "minecraft:dirt"},
        {pos: [7, 0, 4], state: "minecraft:dirt_path"},
        {pos: [7, 0, 5], state: "minecraft:dirt_path"},
        {pos: [7, 0, 6], state: "minecraft:dirt_path"},
        {pos: [7, 0, 7], state: "minecraft:dirt"},
        {pos: [7, 0, 8], state: "minecraft:dirt"},
        {pos: [8, 0, 3], state: "minecraft:dirt_path"},
        {pos: [8, 0, 4], state: "minecraft:dirt_path"},
        {pos: [8, 0, 5], state: "minecraft:dirt_path"},
        {pos: [8, 0, 6], state: "minecraft:dirt_path"},
        {pos: [8, 0, 7], state: "minecraft:dirt"},
        {pos: [9, 0, 2], state: "minecraft:dirt_path"},
        {pos: [9, 0, 3], state: "minecraft:dirt_path"},
        {pos: [9, 0, 4], state: "minecraft:jigsaw{orientation:east_up}", nbt: {components: {}, final_state: "minecraft:dirt_path", id: "minecraft:jigsaw", joint: "rollable", name: "minecraft:end_connector", placement_priority: 0, pool: "minecraft:empty", selection_priority: 0, target: "minecraft:connector"}},
        {pos: [9, 0, 5], state: "minecraft:dirt_path"},
        {pos: [2, 1, 5], state: "minecraft:grass_block{snowy:false}"},
        {pos: [2, 1, 6], state: "minecraft:grass_block{snowy:false}"},
        {pos: [3, 1, 1], state: "minecraft:poplar_log{axis:y}"},
        {pos: [3, 1, 6], state: "minecraft:grass_block{snowy:false}"},
        {pos: [3, 1, 7], state: "minecraft:grass_block{snowy:false}"},
        {pos: [4, 1, 7], state: "minecraft:grass_block{snowy:false}"},
        {pos: [4, 1, 8], state: "minecraft:grass_block{snowy:false}"},
        {pos: [5, 1, 1], state: "minecraft:poplar_log{axis:x}"},
        {pos: [5, 1, 7], state: "minecraft:grass_block{snowy:false}"},
        {pos: [5, 1, 8], state: "minecraft:grass_block{snowy:false}"},
        {pos: [6, 1, 1], state: "minecraft:poplar_log{axis:x}"},
        {pos: [6, 1, 4], state: "minecraft:barrel{facing:up,open:false}", nbt: {Items: [], LootTable: "minecraft:barrels/abandoned_camp_barrel", components: {}, id: "minecraft:barrel"}},
        {pos: [6, 1, 5], state: "minecraft:campfire{facing:south,lit:false,signal_fire:false,waterlogged:false}", nbt: {CookingTimes: [I; 0, 0, 0, 0], CookingTotalTimes: [I; 0, 0, 0, 0], Items: [], components: {}, id: "minecraft:campfire"}},
        {pos: [6, 1, 8], state: "minecraft:grass_block{snowy:false}"},
        {pos: [7, 1, 1], state: "minecraft:poplar_log{axis:x}"},
        {pos: [7, 1, 7], state: "minecraft:grass_block{snowy:false}"},
        {pos: [7, 1, 8], state: "minecraft:grass_block{snowy:false}"},
        {pos: [8, 1, 7], state: "minecraft:grass_block{snowy:false}"},
        {pos: [3, 2, 1], state: "minecraft:leaf_litter{facing:south,segment_amount:3}"},
        {pos: [3, 2, 7], state: "minecraft:leaf_litter{facing:west,segment_amount:3}"},
        {pos: [4, 2, 8], state: "minecraft:leaf_litter{facing:west,segment_amount:1}"},
        {pos: [5, 2, 1], state: "minecraft:leaf_litter{facing:south,segment_amount:1}"},
        {pos: [5, 2, 8], state: "minecraft:leaf_litter{facing:west,segment_amount:1}"},
        {pos: [6, 2, 1], state: "minecraft:leaf_litter{facing:south,segment_amount:1}"},
        {pos: [7, 2, 1], state: "minecraft:leaf_litter{facing:south,segment_amount:4}"},
        {pos: [7, 2, 7], state: "minecraft:leaf_litter{facing:west,segment_amount:1}"},
        {pos: [7, 2, 8], state: "minecraft:leaf_litter{facing:west,segment_amount:3}"},
        {pos: [8, 2, 7], state: "minecraft:leaf_litter{facing:west,segment_amount:3}"}
    ],
    entities: [
        {blockPos: [5, 0, 5], pos: [5.5d, 0.9375d, 5.5d], nbt: {Air: 300s, Fire: 0s, Invulnerable: 0b, Motion: [0.0d, 0.0d, 0.0d], OnGround: 0b, PortalCooldown: 0, Pos: [-88.5d, -60.0625d, 602.5d], Rotation: [90.0f, 0.0f], UUID: [I; -8786577, 1610105131, -2103488802, 1610522376], block_pos: [I; -89, -61, 602], color: "red", fall_distance: 0.0d, id: "minecraft:cushion"}},
        {blockPos: [7, 0, 5], pos: [7.5d, 0.9375d, 5.5d], nbt: {Air: 300s, Fire: 0s, Invulnerable: 0b, Motion: [0.0d, 0.0d, 0.0d], OnGround: 0b, PortalCooldown: 0, Pos: [-86.5d, -60.0625d, 602.5d], Rotation: [270.0f, 0.0f], UUID: [I; -1950776613, -1996208194, -2016384358, -1300232553], block_pos: [I; -87, -61, 602], color: "yellow", fall_distance: 0.0d, id: "minecraft:cushion"}}
    ],
    palette: [
        "minecraft:dirt",
        "minecraft:grass_block{snowy:false}",
        "minecraft:poplar_log{axis:y}",
        "minecraft:poplar_log{axis:x}",
        "minecraft:dirt_path",
        "minecraft:leaf_litter{facing:south,segment_amount:3}",
        "minecraft:leaf_litter{facing:west,segment_amount:3}",
        "minecraft:leaf_litter{facing:west,segment_amount:1}",
        "minecraft:leaf_litter{facing:south,segment_amount:1}",
        "minecraft:leaf_litter{facing:south,segment_amount:4}",
        "minecraft:jigsaw{orientation:up_east}",
        "minecraft:jigsaw{orientation:east_up}",
        "minecraft:barrel{facing:up,open:false}",
        "minecraft:campfire{facing:south,lit:false,signal_fire:false,waterlogged:false}"
    ]
}
