{
    size: [7, 6, 9],
    data: [
        {pos: [1, 0, 0], state: "minecraft:stone"},
        {pos: [1, 0, 1], state: "minecraft:stone"},
        {pos: [1, 0, 2], state: "minecraft:stone"},
        {pos: [1, 0, 3], state: "minecraft:polished_andesite"},
        {pos: [1, 0, 4], state: "minecraft:stone_bricks"},
        {pos: [1, 0, 5], state: "minecraft:chiseled_stone_bricks"},
        {pos: [1, 0, 6], state: "minecraft:stone_bricks"},
        {pos: [1, 0, 7], state: "minecraft:chiseled_stone_bricks"},
        {pos: [2, 0, 0], state: "minecraft:stone"},
        {pos: [2, 0, 1], state: "minecraft:cracked_stone_bricks"},
        {pos: [2, 0, 2], state: "minecraft:stone_bricks"},
        {pos: [2, 0, 3], state: "minecraft:stone_bricks"},
        {pos: [2, 0, 4], state: "minecraft:infested_stone_bricks"},
        {pos: [2, 0, 5], state: "minecraft:stone_bricks"},
        {pos: [2, 0, 6], state: "minecraft:stone_bricks"},
        {pos: [2, 0, 7], state: "minecraft:stone_bricks"},
        {pos: [3, 0, 0], state: "minecraft:stone"},
        {pos: [3, 0, 1], state: "minecraft:stone"},
        {pos: [3, 0, 2], state: "minecraft:stone"},
        {pos: [3, 0, 3], state: "minecraft:chiseled_stone_bricks"},
        {pos: [3, 0, 4], state: "minecraft:stone_bricks"},
        {pos: [3, 0, 5], state: "minecraft:chiseled_stone_bricks"},
        {pos: [3, 0, 6], state: "minecraft:stone_bricks"},
        {pos: [3, 0, 7], state: "minecraft:chiseled_stone_bricks"},
        {pos: [4, 0, 0], state: "minecraft:stone"},
        {pos: [4, 0, 1], state: "minecraft:cracked_stone_bricks"},
        {pos: [4, 0, 2], state: "minecraft:stone_bricks"},
        {pos: [4, 0, 3], state: "minecraft:stone_bricks"},
        {pos: [4, 0, 4], state: "minecraft:stone_bricks"},
        {pos: [4, 0, 5], state: "minecraft:stone_bricks"},
        {pos: [4, 0, 6], state: "minecraft:stone_bricks"},
        {pos: [4, 0, 7], state: "minecraft:stone_bricks"},
        {pos: [5, 0, 0], state: "minecraft:stone"},
        {pos: [5, 0, 1], state: "minecraft:stone"},
        {pos: [5, 0, 2], state: "minecraft:stone"},
        {pos: [5, 0, 3], state: "minecraft:infested_chiseled_stone_bricks"},
        {pos: [5, 0, 4], state: "minecraft:stone_bricks"},
        {pos: [5, 0, 5], state: "minecraft:chiseled_stone_bricks"},
        {pos: [5, 0, 6], state: "minecraft:infested_stone_bricks"},
        {pos: [5, 0, 7], state: "minecraft:chiseled_stone_bricks"},
        {pos: [0, 1, 3], state: "minecraft:mossy_stone_bricks"},
        {pos: [0, 1, 4], state: "minecraft:mossy_stone_bricks"},
        {pos: [0, 1, 5], state: "minecraft:mossy_stone_bricks"},
        {pos: [0, 1, 6], state: "minecraft:mossy_stone_bricks"},
        {pos: [0, 1, 7], state: "minecraft:mossy_stone_bricks"},
        {pos: [1, 1, 0], state: "minecraft:stone_bricks"},
        {pos: [1, 1, 1], state: "minecraft:stone_bricks"},
        {pos: [1, 1, 2], state: "minecraft:mossy_stone_bricks"},
        {pos: [1, 1, 3], state: "minecraft:red_carpet"},
        {pos: [1, 1, 4], state: "minecraft:red_carpet"},
        {pos: [1, 1, 5], state: "minecraft:air"},
        {pos: [1, 1, 6], state: "minecraft:chest{facing:east,type:single,waterlogged:false}", nbt: {Items: [], id: "minecraft:chest"}},
        {pos: [1, 1, 7], state: "minecraft:air"},
        {pos: [1, 1, 8], state: "minecraft:mossy_stone_bricks"},
        {pos: [2, 1, 0], state: "minecraft:stone_bricks"},
        {pos: [2, 1, 1], state: "minecraft:air"},
        {pos: [2, 1, 2], state: "minecraft:iron_bars{east:true,north:false,south:false,waterlogged:false,west:true}"},
        {pos: [2, 1, 3], state: "minecraft:air"},
        {pos: [2, 1, 4], state: "minecraft:air"},
        {pos: [2, 1, 5], state: "minecraft:air"},
        {pos: [2, 1, 6], state: "minecraft:air"},
        {pos: [2, 1, 7], state: "minecraft:air"},
        {pos: [2, 1, 8], state: "minecraft:infested_mossy_stone_bricks"},
        {pos: [3, 1, 0], state: "minecraft:stone_bricks"},
        {pos: [3, 1, 1], state: "minecraft:stone_bricks"},
        {pos: [3, 1, 2], state: "minecraft:mossy_stone_bricks"},
        {pos: [3, 1, 3], state: "minecraft:air"},
        {pos: [3, 1, 4], state: "minecraft:air"},
        {pos: [3, 1, 5], state: "minecraft:air"},
        {pos: [3, 1, 6], state: "minecraft:air"},
        {pos: [3, 1, 7], state: "minecraft:air"},
        {pos: [3, 1, 8], state: "minecraft:mossy_stone_bricks"},
        {pos: [4, 1, 0], state: "minecraft:stone_bricks"},
        {pos: [4, 1, 1], state: "minecraft:air"},
        {pos: [4, 1, 2], state: "minecraft:iron_bars{east:true,north:false,south:false,waterlogged:false,west:true}"},
        {pos: [4, 1, 3], state: "minecraft:air"},
        {pos: [4, 1, 4], state: "minecraft:air"},
        {pos: [4, 1, 5], state: "minecraft:air"},
        {pos: [4, 1, 6], state: "minecraft:air"},
        {pos: [4, 1, 7], state: "minecraft:air"},
        {pos: [4, 1, 8], state: "minecraft:mossy_stone_bricks"},
        {pos: [5, 1, 0], state: "minecraft:stone_bricks"},
        {pos: [5, 1, 1], state: "minecraft:stone_bricks"},
        {pos: [5, 1, 2], state: "minecraft:mossy_stone_bricks"},
        {pos: [5, 1, 3], state: "minecraft:air"},
        {pos: [5, 1, 4], state: "minecraft:water_cauldron{level:2}"},
        {pos: [5, 1, 5], state: "minecraft:spruce_stairs{facing:north,half:top,shape:straight,waterlogged:false}"},
        {pos: [5, 1, 6], state: "minecraft:spruce_slab{type:top,waterlogged:false}"},
        {pos: [5, 1, 7], state: "minecraft:spruce_stairs{facing:south,half:top,shape:straight,waterlogged:false}"},
        {pos: [5, 1, 8], state: "minecraft:mossy_stone_bricks"},
        {pos: [6, 1, 3], state: "minecraft:mossy_stone_bricks"},
        {pos: [6, 1, 4], state: "minecraft:mossy_stone_bricks"},
        {pos: [6, 1, 5], state: "minecraft:mossy_stone_bricks"},
        {pos: [6, 1, 6], state: "minecraft:mossy_stone_bricks"},
        {pos: [6, 1, 7], state: "minecraft:mossy_stone_bricks"},
        {pos: [0, 2, 3], state: "minecraft:cracked_stone_bricks"},
        {pos: [0, 2, 4], state: "minecraft:stone_bricks"},
        {pos: [0, 2, 5], state: "minecraft:stone_bricks"},
        {pos: [0, 2, 6], state: "minecraft:cracked_stone_bricks"},
        {pos: [0, 2, 7], state: "minecraft:stone_bricks"},
        {pos: [1, 2, 0], state: "minecraft:stone_bricks"},
        {pos: [1, 2, 1], state: "minecraft:stone_bricks"},
        {pos: [1, 2, 2], state: "minecraft:stone_bricks"},
        {pos: [1, 2, 3], state: "minecraft:air"},
        {pos: [1, 2, 4], state: "minecraft:air"},
        {pos: [1, 2, 5], state: "minecraft:air"},
        {pos: [1, 2, 6], state: "minecraft:structure_block{mode:data}", nbt: {author: "Searge", id: "minecraft:structure_block", ignoreEntities: 0b, integrity: 1.0f, metadata: "chest", mirror: "NONE", mode: "DATA", name: "", posX: 1, posY: 1, posZ: 1, powered: 0b, rotation: "NONE", seed: 0L, showair: 0b, showboundingbox: 0b, sizeX: 0, sizeY: 0, sizeZ: 0}},
        {pos: [1, 2, 7], state: "minecraft:air"},
        {pos: [1, 2, 8], state: "minecraft:infested_stone_bricks"},
        {pos: [2, 2, 0], state: "minecraft:stone_bricks"},
        {pos: [2, 2, 1], state: "minecraft:air"},
        {pos: [2, 2, 2], state: "minecraft:iron_bars{east:true,north:false,south:false,waterlogged:false,west:true}"},
        {pos: [2, 2, 3], state: "minecraft:air"},
        {pos: [2, 2, 4], state: "minecraft:air"},
        {pos: [2, 2, 5], state: "minecraft:air"},
        {pos: [2, 2, 6], state: "minecraft:air"},
        {pos: [2, 2, 7], state: "minecraft:air"},
        {pos: [2, 2, 8], state: "minecraft:stone_bricks"},
        {pos: [3, 2, 0], state: "minecraft:stone_bricks"},
        {pos: [3, 2, 1], state: "minecraft:stone_bricks"},
        {pos: [3, 2, 2], state: "minecraft:cracked_stone_bricks"},
        {pos: [3, 2, 3], state: "minecraft:oak_wall_sign{facing:south,waterlogged:false}", nbt: {back_text: {color: "black", has_glowing_text: 0b, messages: [{text: ""}, {text: ""}, {text: ""}, {text: ""}]}, front_text: {color: "black", filtered_messages: [{text: ""}, {text: "<----"}, {text: "---->"}, {text: ""}], has_glowing_text: 0b, messages: [{text: ""}, {text: "<----"}, {text: "---->"}, {text: ""}]}, id: "minecraft:sign"}},
        {pos: [3, 2, 4], state: "minecraft:air"},
        {pos: [3, 2, 5], state: "minecraft:air"},
        {pos: [3, 2, 6], state: "minecraft:air"},
        {pos: [3, 2, 7], state: "minecraft:ladder{facing:north,waterlogged:false}"},
        {pos: [3, 2, 8], state: "minecraft:cracked_stone_bricks"},
        {pos: [4, 2, 0], state: "minecraft:stone_bricks"},
        {pos: [4, 2, 1], state: "minecraft:air"},
        {pos: [4, 2, 2], state: "minecraft:iron_bars{east:true,north:false,south:false,waterlogged:false,west:true}"},
        {pos: [4, 2, 3], state: "minecraft:air"},
        {pos: [4, 2, 4], state: "minecraft:air"},
        {pos: [4, 2, 5], state: "minecraft:air"},
        {pos: [4, 2, 6], state: "minecraft:air"},
        {pos: [4, 2, 7], state: "minecraft:air"},
        {pos: [4, 2, 8], state: "minecraft:stone_bricks"},
        {pos: [5, 2, 0], state: "minecraft:stone_bricks"},
        {pos: [5, 2, 1], state: "minecraft:stone_bricks"},
        {pos: [5, 2, 2], state: "minecraft:stone_bricks"},
        {pos: [5, 2, 3], state: "minecraft:air"},
        {pos: [5, 2, 4], state: "minecraft:air"},
        {pos: [5, 2, 5], state: "minecraft:air"},
        {pos: [5, 2, 6], state: "minecraft:brewing_stand{has_bottle_0:false,has_bottle_1:true,has_bottle_2:false}", nbt: {BrewTime: 0s, Fuel: 0b, Items: [{Slot: 1b, components: {"minecraft:potion_contents": {potion: "minecraft:weakness"}}, count: 1, id: "minecraft:splash_potion"}], id: "minecraft:brewing_stand"}},
        {pos: [5, 2, 7], state: "minecraft:potted_cactus"},
        {pos: [5, 2, 8], state: "minecraft:cracked_stone_bricks"},
        {pos: [6, 2, 3], state: "minecraft:stone_bricks"},
        {pos: [6, 2, 4], state: "minecraft:stone_bricks"},
        {pos: [6, 2, 5], state: "minecraft:cracked_stone_bricks"},
        {pos: [6, 2, 6], state: "minecraft:infested_stone_bricks"},
        {pos: [6, 2, 7], state: "minecraft:stone_bricks"},
        {pos: [0, 3, 3], state: "minecraft:stone_bricks"},
        {pos: [0, 3, 4], state: "minecraft:infested_stone_bricks"},
        {pos: [0, 3, 5], state: "minecraft:stone_bricks"},
        {pos: [0, 3, 6], state: "minecraft:stone_bricks"},
        {pos: [0, 3, 7], state: "minecraft:stone_bricks"},
        {pos: [1, 3, 0], state: "minecraft:stone_bricks"},
        {pos: [1, 3, 1], state: "minecraft:stone_bricks"},
        {pos: [1, 3, 2], state: "minecraft:stone_bricks"},
        {pos: [1, 3, 3], state: "minecraft:cobweb"},
        {pos: [1, 3, 4], state: "minecraft:air"},
        {pos: [1, 3, 5], state: "minecraft:air"},
        {pos: [1, 3, 6], state: "minecraft:air"},
        {pos: [1, 3, 7], state: "minecraft:air"},
        {pos: [1, 3, 8], state: "minecraft:stone_bricks"},
        {pos: [2, 3, 0], state: "minecraft:stone_bricks"},
        {pos: [2, 3, 1], state: "minecraft:air"},
        {pos: [2, 3, 2], state: "minecraft:stone_bricks"},
        {pos: [2, 3, 3], state: "minecraft:air"},
        {pos: [2, 3, 4], state: "minecraft:air"},
        {pos: [2, 3, 5], state: "minecraft:air"},
        {pos: [2, 3, 6], state: "minecraft:air"},
        {pos: [2, 3, 7], state: "minecraft:wall_torch{facing:north}"},
        {pos: [2, 3, 8], state: "minecraft:stone_bricks"},
        {pos: [3, 3, 0], state: "minecraft:stone_bricks"},
        {pos: [3, 3, 1], state: "minecraft:stone_bricks"},
        {pos: [3, 3, 2], state: "minecraft:stone_bricks"},
        {pos: [3, 3, 3], state: "minecraft:wall_torch{facing:south}"},
        {pos: [3, 3, 4], state: "minecraft:air"},
        {pos: [3, 3, 5], state: "minecraft:air"},
        {pos: [3, 3, 6], state: "minecraft:air"},
        {pos: [3, 3, 7], state: "minecraft:ladder{facing:north,waterlogged:false}"},
        {pos: [3, 3, 8], state: "minecraft:stone_bricks"},
        {pos: [4, 3, 0], state: "minecraft:stone_bricks"},
        {pos: [4, 3, 1], state: "minecraft:air"},
        {pos: [4, 3, 2], state: "minecraft:stone_bricks"},
        {pos: [4, 3, 3], state: "minecraft:air"},
        {pos: [4, 3, 4], state: "minecraft:air"},
        {pos: [4, 3, 5], state: "minecraft:air"},
        {pos: [4, 3, 6], state: "minecraft:air"},
        {pos: [4, 3, 7], state: "minecraft:wall_torch{facing:north}"},
        {pos: [4, 3, 8], state: "minecraft:stone_bricks"},
        {pos: [5, 3, 0], state: "minecraft:stone_bricks"},
        {pos: [5, 3, 1], state: "minecraft:stone_bricks"},
        {pos: [5, 3, 2], state: "minecraft:stone_bricks"},
        {pos: [5, 3, 3], state: "minecraft:air"},
        {pos: [5, 3, 4], state: "minecraft:air"},
        {pos: [5, 3, 5], state: "minecraft:air"},
        {pos: [5, 3, 6], state: "minecraft:air"},
        {pos: [5, 3, 7], state: "minecraft:air"},
        {pos: [5, 3, 8], state: "minecraft:stone_bricks"},
        {pos: [6, 3, 3], state: "minecraft:stone_bricks"},
        {pos: [6, 3, 4], state: "minecraft:stone_bricks"},
        {pos: [6, 3, 5], state: "minecraft:stone_bricks"},
        {pos: [6, 3, 6], state: "minecraft:stone_bricks"},
        {pos: [6, 3, 7], state: "minecraft:stone_bricks"},
        {pos: [1, 4, 3], state: "minecraft:stone_bricks"},
        {pos: [1, 4, 4], state: "minecraft:stone_bricks"},
        {pos: [1, 4, 5], state: "minecraft:stone_bricks"},
        {pos: [1, 4, 6], state: "minecraft:stone_bricks"},
        {pos: [1, 4, 7], state: "minecraft:stone_bricks"},
        {pos: [2, 4, 1], state: "minecraft:stone_bricks"},
        {pos: [2, 4, 2], state: "minecraft:stone_bricks"},
        {pos: [2, 4, 3], state: "minecraft:stone_bricks"},
        {pos: [2, 4, 4], state: "minecraft:stone_bricks"},
        {pos: [2, 4, 5], state: "minecraft:stone_bricks"},
        {pos: [2, 4, 6], state: "minecraft:infested_stone_bricks"},
        {pos: [2, 4, 7], state: "minecraft:stone_bricks"},
        {pos: [2, 4, 8], state: "minecraft:stone_bricks"},
        {pos: [3, 4, 1], state: "minecraft:stone_bricks"},
        {pos: [3, 4, 2], state: "minecraft:stone_bricks"},
        {pos: [3, 4, 3], state: "minecraft:stone_bricks"},
        {pos: [3, 4, 4], state: "minecraft:stone_bricks"},
        {pos: [3, 4, 5], state: "minecraft:infested_chiseled_stone_bricks"},
        {pos: [3, 4, 6], state: "minecraft:stone_bricks"},
        {pos: [3, 4, 7], state: "minecraft:ladder{facing:north,waterlogged:false}"},
        {pos: [3, 4, 8], state: "minecraft:stone_bricks"},
        {pos: [4, 4, 1], state: "minecraft:stone_bricks"},
        {pos: [4, 4, 2], state: "minecraft:stone_bricks"},
        {pos: [4, 4, 3], state: "minecraft:stone_bricks"},
        {pos: [4, 4, 4], state: "minecraft:stone_bricks"},
        {pos: [4, 4, 5], state: "minecraft:stone_bricks"},
        {pos: [4, 4, 6], state: "minecraft:stone_bricks"},
        {pos: [4, 4, 7], state: "minecraft:stone_bricks"},
        {pos: [4, 4, 8], state: "minecraft:stone_bricks"},
        {pos: [5, 4, 3], state: "minecraft:stone_bricks"},
        {pos: [5, 4, 4], state: "minecraft:stone_bricks"},
        {pos: [5, 4, 5], state: "minecraft:stone_bricks"},
        {pos: [5, 4, 6], state: "minecraft:stone_bricks"},
        {pos: [5, 4, 7], state: "minecraft:stone_bricks"},
        {pos: [2, 5, 7], state: "minecraft:stone_bricks"},
        {pos: [3, 5, 6], state: "minecraft:stone_bricks"},
        {pos: [3, 5, 7], state: "minecraft:ladder{facing:north,waterlogged:false}"},
        {pos: [3, 5, 8], state: "minecraft:stone_bricks"},
        {pos: [4, 5, 7], state: "minecraft:stone_bricks"}
    ],
    entities: [
        {blockPos: [2, 1, 1], pos: [2.5d, 1.0d, 1.5d], nbt: {AbsorptionAmount: 0.0f, Age: 0, Air: 300s, ArmorItems: [{}, {}, {}, {}], CanPickUpLoot: 1b, DeathTime: 0s, Dimension: 0, FallFlying: 0b, Fire: -1s, ForcedAge: 0, HandItems: [{}, {}], Health: 20.0f, HurtByTimestamp: 0, HurtTime: 0s, Inventory: [], Invulnerable: 0b, Leashed: 0b, LeftHanded: 0b, Motion: [0.0d, -0.0784000015258789d, 0.0d], Offers: {Recipes: [{buy: {count: 36, id: "minecraft:rotten_flesh"}, maxUses: 7, rewardExp: 1b, sell: {count: 1, id: "minecraft:emerald"}, uses: 0}, {buy: {count: 9, id: "minecraft:gold_ingot"}, maxUses: 7, rewardExp: 1b, sell: {count: 1, id: "minecraft:emerald"}, uses: 0}]}, OnGround: 1b, PersistenceRequired: 1b, PortalCooldown: 0, Pos: [-986.5d, 8.0d, -1060.5d], Riches: 15, Rotation: [-4.3276978f, -3.41655f], UUID: [I; -1630920815, 245714788, -1593885403, 1511953888], VillagerData: {level: 1, profession: "minecraft:cleric", type: "minecraft:plains"}, Willing: 0b, Xp: 0, attributes: [{base: 20.0d, id: "minecraft:max_health"}, {base: 0.0d, id: "minecraft:knockback_resistance"}, {base: 0.5d, id: "minecraft:movement_speed"}, {base: 0.0d, id: "minecraft:armor"}, {base: 0.0d, id: "minecraft:armor_toughness"}, {base: 16.0d, id: "minecraft:follow_range", modifiers: [{amount: -0.07807250298271795d, id: "minecraft:random_spawn_bonus", operation: "add_multiplied_base"}]}], fall_distance: 0.0d, id: "minecraft:villager"}},
        {blockPos: [4, 1, 1], pos: [4.5d, 1.0d, 1.300000011920929d], nbt: {AbsorptionAmount: 0.0f, Air: 300s, ArmorItems: [{}, {}, {}, {}], CanBreakDoors: 0b, CanPickUpLoot: 0b, ConversionTime: -1, DeathTime: 0s, Dimension: 0, FallFlying: 0b, Fire: -1s, HandItems: [{}, {}], Health: 19.05f, HurtByTimestamp: 125, HurtTime: 0s, Invulnerable: 0b, Leashed: 0b, LeftHanded: 0b, Motion: [0.0d, -0.0784000015258789d, 0.0d], OnGround: 1b, PersistenceRequired: 1b, PortalCooldown: 0, Pos: [-984.5d, 8.0d, -1060.699999988079d], Rotation: [-95.78888f, 0.0f], UUID: [I; 669208369, 1839481473, -1764747872, -1340605115], VillagerData: {level: 1, profession: "minecraft:cleric", type: "minecraft:plains"}, Xp: 0, attributes: [{base: 20.0d, id: "minecraft:max_health"}, {base: 0.0d, id: "minecraft:knockback_resistance", modifiers: [{amount: 0.033586338385064834d, id: "minecraft:random_spawn_bonus", operation: "add_value"}]}, {base: 0.23000000417232513d, id: "minecraft:movement_speed"}, {base: 2.0d, id: "minecraft:armor"}, {base: 0.0d, id: "minecraft:armor_toughness"}, {base: 35.0d, id: "minecraft:follow_range", modifiers: [{amount: -0.013882809459502736d, id: "minecraft:random_spawn_bonus", operation: "add_multiplied_base"}]}, {base: 3.0d, id: "minecraft:attack_damage"}, {base: 0.08507647017248195d, id: "minecraft:spawn_reinforcements"}], fall_distance: 0.0d, id: "minecraft:zombie_villager"}}
    ],
    palette: [
        "minecraft:stone",
        "minecraft:polished_andesite",
        "minecraft:stone_bricks",
        "minecraft:chiseled_stone_bricks",
        "minecraft:cracked_stone_bricks",
        "minecraft:infested_stone_bricks",
        "minecraft:infested_chiseled_stone_bricks",
        "minecraft:mossy_stone_bricks",
        "minecraft:infested_mossy_stone_bricks",
        "minecraft:red_carpet",
        "minecraft:air",
        "minecraft:iron_bars{east:true,north:false,south:false,waterlogged:false,west:true}",
        "minecraft:water_cauldron{level:2}",
        "minecraft:spruce_stairs{facing:north,half:top,shape:straight,waterlogged:false}",
        "minecraft:spruce_slab{type:top,waterlogged:false}",
        "minecraft:spruce_stairs{facing:south,half:top,shape:straight,waterlogged:false}",
        "minecraft:ladder{facing:north,waterlogged:false}",
        "minecraft:potted_cactus",
        "minecraft:cobweb",
        "minecraft:wall_torch{facing:north}",
        "minecraft:wall_torch{facing:south}",
        "minecraft:chest{facing:east,type:single,waterlogged:false}",
        "minecraft:structure_block{mode:data}",
        "minecraft:oak_wall_sign{facing:south,waterlogged:false}",
        "minecraft:brewing_stand{has_bottle_0:false,has_bottle_1:true,has_bottle_2:false}"
    ]
}
