{
    size: [10, 10, 10],
    data: [
        {pos: [1, 0, 1], state: "minecraft:jigsaw{orientation:up_east}", nbt: {components: {}, final_state: "minecraft:dirt", id: "minecraft:jigsaw", joint: "rollable", name: "minecraft:bottom", placement_priority: 0, pool: "minecraft:abandoned_camp/trees/birch", selection_priority: 0, target: "minecraft:bottom"}},
        {pos: [1, 0, 7], state: "minecraft:dirt"},
        {pos: [1, 0, 8], state: "minecraft:stone"},
        {pos: [2, 0, 3], state: "minecraft:dirt"},
        {pos: [2, 0, 4], state: "minecraft:dirt"},
        {pos: [2, 0, 5], state: "minecraft:dirt"},
        {pos: [2, 0, 6], state: "minecraft:dirt"},
        {pos: [2, 0, 7], state: "minecraft:dirt"},
        {pos: [2, 0, 8], state: "minecraft:dirt"},
        {pos: [2, 0, 9], state: "minecraft:dirt"},
        {pos: [3, 0, 2], state: "minecraft:dirt"},
        {pos: [3, 0, 3], state: "minecraft:dirt"},
        {pos: [3, 0, 4], state: "minecraft:dirt"},
        {pos: [3, 0, 5], state: "minecraft:dirt"},
        {pos: [3, 0, 6], state: "minecraft:dirt"},
        {pos: [3, 0, 7], state: "minecraft:grass_block{snowy:false}"},
        {pos: [3, 0, 8], state: "minecraft:dirt"},
        {pos: [3, 0, 9], state: "minecraft:dirt"},
        {pos: [4, 0, 1], state: "minecraft:dirt"},
        {pos: [4, 0, 2], state: "minecraft:dirt"},
        {pos: [4, 0, 3], state: "minecraft:dirt"},
        {pos: [4, 0, 4], state: "minecraft:dirt"},
        {pos: [4, 0, 5], state: "minecraft:dirt"},
        {pos: [4, 0, 6], state: "minecraft:dirt"},
        {pos: [4, 0, 7], state: "minecraft:dirt"},
        {pos: [4, 0, 8], state: "minecraft:dirt"},
        {pos: [5, 0, 2], state: "minecraft:dirt"},
        {pos: [5, 0, 3], state: "minecraft:dirt"},
        {pos: [5, 0, 4], state: "minecraft:dirt"},
        {pos: [5, 0, 5], state: "minecraft:dirt"},
        {pos: [5, 0, 6], state: "minecraft:dirt"},
        {pos: [5, 0, 7], state: "minecraft:dirt"},
        {pos: [6, 0, 2], state: "minecraft:dirt"},
        {pos: [6, 0, 3], state: "minecraft:dirt"},
        {pos: [6, 0, 4], state: "minecraft:dirt"},
        {pos: [6, 0, 5], state: "minecraft:dirt"},
        {pos: [6, 0, 6], state: "minecraft:dirt"},
        {pos: [6, 0, 7], state: "minecraft:dirt"},
        {pos: [6, 0, 8], state: "minecraft:dirt"},
        {pos: [7, 0, 3], state: "minecraft:dirt"},
        {pos: [7, 0, 4], state: "minecraft:dirt"},
        {pos: [7, 0, 5], state: "minecraft:dirt"},
        {pos: [7, 0, 6], state: "minecraft:dirt"},
        {pos: [7, 0, 7], state: "minecraft:dirt"},
        {pos: [8, 0, 1], state: "minecraft:jigsaw{orientation:up_south}", nbt: {components: {}, final_state: "minecraft:dirt", id: "minecraft:jigsaw", joint: "rollable", name: "minecraft:bottom", placement_priority: 0, pool: "minecraft:abandoned_camp/trees/birch", selection_priority: 0, target: "minecraft:bottom"}},
        {pos: [8, 0, 4], state: "minecraft:dirt_path"},
        {pos: [8, 0, 5], state: "minecraft:dirt"},
        {pos: [8, 0, 6], state: "minecraft:dirt"},
        {pos: [8, 0, 7], state: "minecraft:dirt"},
        {pos: [9, 0, 4], state: "minecraft:jigsaw{orientation:east_up}", nbt: {components: {}, final_state: "minecraft:dirt_path", id: "minecraft:jigsaw", joint: "rollable", name: "minecraft:end_connector", placement_priority: 0, pool: "minecraft:empty", selection_priority: 0, target: "minecraft:connector"}},
        {pos: [1, 1, 7], state: "minecraft:stone"},
        {pos: [1, 1, 8], state: "minecraft:stone"},
        {pos: [2, 1, 3], state: "minecraft:grass_block{snowy:false}"},
        {pos: [2, 1, 4], state: "minecraft:grass_block{snowy:false}"},
        {pos: [2, 1, 5], state: "minecraft:grass_block{snowy:false}"},
        {pos: [2, 1, 6], state: "minecraft:stone"},
        {pos: [2, 1, 7], state: "minecraft:stone"},
        {pos: [2, 1, 8], state: "minecraft:stone"},
        {pos: [2, 1, 9], state: "minecraft:stone"},
        {pos: [3, 1, 2], state: "minecraft:dirt_path"},
        {pos: [3, 1, 3], state: "minecraft:dirt_path"},
        {pos: [3, 1, 4], state: "minecraft:dirt_path"},
        {pos: [3, 1, 5], state: "minecraft:jigsaw{orientation:up_east}", nbt: {components: {}, final_state: "minecraft:dirt", id: "minecraft:jigsaw", joint: "rollable", name: "minecraft:bottom", placement_priority: 0, pool: "minecraft:abandoned_camp/trees/birch", selection_priority: 0, target: "minecraft:bottom"}},
        {pos: [3, 1, 6], state: "minecraft:dirt"},
        {pos: [3, 1, 7], state: "minecraft:oxidized_copper_chest{facing:north,type:single,waterlogged:false}", nbt: {Items: [], LootTable: "minecraft:chests/abandoned_camp_secret_chest", components: {}, id: "minecraft:chest"}},
        {pos: [3, 1, 8], state: "minecraft:stone"},
        {pos: [3, 1, 9], state: "minecraft:stone"},
        {pos: [4, 1, 1], state: "minecraft:grass_block{snowy:false}"},
        {pos: [4, 1, 2], state: "minecraft:dirt_path"},
        {pos: [4, 1, 3], state: "minecraft:dirt_path"},
        {pos: [4, 1, 4], state: "minecraft:dirt_path"},
        {pos: [4, 1, 5], state: "minecraft:dirt_path"},
        {pos: [4, 1, 6], state: "minecraft:dirt_path"},
        {pos: [4, 1, 7], state: "minecraft:dirt_path"},
        {pos: [4, 1, 8], state: "minecraft:grass_block{snowy:false}"},
        {pos: [5, 1, 2], state: "minecraft:dirt_path"},
        {pos: [5, 1, 3], state: "minecraft:dirt_path"},
        {pos: [5, 1, 4], state: "minecraft:dirt"},
        {pos: [5, 1, 5], state: "minecraft:dirt_path"},
        {pos: [5, 1, 6], state: "minecraft:dirt_path"},
        {pos: [5, 1, 7], state: "minecraft:dirt_path"},
        {pos: [6, 1, 2], state: "minecraft:grass_block{snowy:false}"},
        {pos: [6, 1, 3], state: "minecraft:dirt_path"},
        {pos: [6, 1, 4], state: "minecraft:dirt_path"},
        {pos: [6, 1, 5], state: "minecraft:dirt_path"},
        {pos: [6, 1, 6], state: "minecraft:dirt_path"},
        {pos: [6, 1, 7], state: "minecraft:grass_block{snowy:false}"},
        {pos: [6, 1, 8], state: "minecraft:grass_block{snowy:false}"},
        {pos: [7, 1, 3], state: "minecraft:grass_block{snowy:false}"},
        {pos: [7, 1, 4], state: "minecraft:birch_stairs{facing:west,half:bottom,shape:straight,waterlogged:false}"},
        {pos: [7, 1, 5], state: "minecraft:dirt_path"},
        {pos: [7, 1, 6], state: "minecraft:grass_block{snowy:false}"},
        {pos: [7, 1, 7], state: "minecraft:jigsaw{orientation:up_west}", nbt: {components: {}, final_state: "minecraft:dirt", id: "minecraft:jigsaw", joint: "rollable", name: "minecraft:bottom", placement_priority: 0, pool: "minecraft:abandoned_camp/trees/birch", selection_priority: 0, target: "minecraft:bottom"}},
        {pos: [8, 1, 5], state: "minecraft:grass_block{snowy:false}"},
        {pos: [8, 1, 6], state: "minecraft:grass_block{snowy:false}"},
        {pos: [8, 1, 7], state: "minecraft:grass_block{snowy:false}"},
        {pos: [1, 2, 7], state: "minecraft:stone"},
        {pos: [2, 2, 4], state: "minecraft:short_grass"},
        {pos: [2, 2, 5], state: "minecraft:tall_grass{half:lower}"},
        {pos: [2, 2, 6], state: "minecraft:stone"},
        {pos: [2, 2, 7], state: "minecraft:stone"},
        {pos: [2, 2, 8], state: "minecraft:stone"},
        {pos: [3, 2, 6], state: "minecraft:barrel{facing:up,open:false}", nbt: {Items: [], LootTable: "minecraft:barrels/abandoned_camp_barrel", components: {}, id: "minecraft:barrel"}},
        {pos: [3, 2, 7], state: "minecraft:stone"},
        {pos: [3, 2, 8], state: "minecraft:stone"},
        {pos: [3, 2, 9], state: "minecraft:stone"},
        {pos: [4, 2, 1], state: "minecraft:short_grass"},
        {pos: [4, 2, 8], state: "minecraft:tall_grass{half:lower}"},
        {pos: [5, 2, 4], state: "minecraft:campfire{facing:north,lit:false,signal_fire:true,waterlogged:false}", nbt: {CookingTimes: [I; 0, 0, 0, 0], CookingTotalTimes: [I; 0, 0, 0, 0], Items: [], components: {}, id: "minecraft:campfire"}},
        {pos: [6, 2, 2], state: "minecraft:tall_grass{half:lower}"},
        {pos: [6, 2, 7], state: "minecraft:tall_grass{half:lower}"},
        {pos: [6, 2, 8], state: "minecraft:short_grass"},
        {pos: [7, 2, 3], state: "minecraft:tall_grass{half:lower}"},
        {pos: [7, 2, 6], state: "minecraft:short_grass"},
        {pos: [8, 2, 5], state: "minecraft:tall_grass{half:lower}"},
        {pos: [8, 2, 6], state: "minecraft:short_grass"},
        {pos: [8, 2, 7], state: "minecraft:tall_grass{half:lower}"},
        {pos: [2, 3, 5], state: "minecraft:tall_grass{half:upper}"},
        {pos: [2, 3, 7], state: "minecraft:stone"},
        {pos: [2, 3, 8], state: "minecraft:stone"},
        {pos: [3, 3, 8], state: "minecraft:stone"},
        {pos: [4, 3, 8], state: "minecraft:tall_grass{half:upper}"},
        {pos: [6, 3, 2], state: "minecraft:tall_grass{half:upper}"},
        {pos: [6, 3, 7], state: "minecraft:tall_grass{half:upper}"},
        {pos: [7, 3, 3], state: "minecraft:tall_grass{half:upper}"},
        {pos: [8, 3, 5], state: "minecraft:tall_grass{half:upper}"},
        {pos: [8, 3, 7], state: "minecraft:tall_grass{half:upper}"},
        {pos: [2, 4, 8], state: "minecraft:stone"}
    ],
    entities: [
        {blockPos: [5, 1, 5], pos: [5.5d, 1.9375d, 5.5d], nbt: {Air: 300s, Fire: 0s, Invulnerable: 0b, Motion: [0.0d, 0.0d, 0.0d], OnGround: 0b, PortalCooldown: 0, Pos: [-105.5d, -59.0625d, 362.5d], Rotation: [90.0f, 0.0f], UUID: [I; -903845099, 1039024270, -1117178340, 898091040], block_pos: [I; -106, -60, 362], color: "red", fall_distance: 0.0d, id: "minecraft:cushion"}},
        {blockPos: [6, 1, 3], pos: [6.5d, 1.9375d, 3.5d], nbt: {Air: 300s, Fire: 0s, Invulnerable: 0b, Motion: [0.0d, 0.0d, 0.0d], OnGround: 0b, PortalCooldown: 0, Pos: [-104.5d, -59.0625d, 360.5d], Rotation: [90.0f, 0.0f], UUID: [I; -1927765267, 654592504, -1399735271, 789412478], block_pos: [I; -105, -60, 360], color: "red", fall_distance: 0.0d, id: "minecraft:cushion"}}
    ],
    palette: [
        "minecraft:dirt",
        "minecraft:stone",
        "minecraft:grass_block{snowy:false}",
        "minecraft:dirt_path",
        "minecraft:birch_stairs{facing:west,half:bottom,shape:straight,waterlogged:false}",
        "minecraft:short_grass",
        "minecraft:tall_grass{half:lower}",
        "minecraft:tall_grass{half:upper}",
        "minecraft:jigsaw{orientation:up_east}",
        "minecraft:jigsaw{orientation:up_south}",
        "minecraft:jigsaw{orientation:east_up}",
        "minecraft:oxidized_copper_chest{facing:north,type:single,waterlogged:false}",
        "minecraft:jigsaw{orientation:up_west}",
        "minecraft:barrel{facing:up,open:false}",
        "minecraft:campfire{facing:north,lit:false,signal_fire:true,waterlogged:false}"
    ]
}
