{
    DataVersion: 2856,
    size: [15, 6, 15],
    data: [
        {pos: [0, 0, 3], state: "minecraft:sand"},
        {pos: [0, 0, 4], state: "minecraft:sand"},
        {pos: [0, 0, 5], state: "minecraft:sand"},
        {pos: [0, 0, 6], state: "minecraft:smooth_sandstone"},
        {pos: [0, 0, 7], state: "minecraft:sand"},
        {pos: [0, 0, 8], state: "minecraft:smooth_sandstone"},
        {pos: [0, 0, 9], state: "minecraft:sand"},
        {pos: [0, 0, 10], state: "minecraft:sand"},
        {pos: [0, 0, 11], state: "minecraft:sand"},
        {pos: [1, 0, 0], state: "minecraft:jigsaw{orientation:up_north}", nbt: {final_state: "minecraft:sand", id: "minecraft:jigsaw", joint: "rollable", name: "minecraft:bottom", pool: "minecraft:village/desert/decor", target: "minecraft:bottom"}},
        {pos: [1, 0, 1], state: "minecraft:sand"},
        {pos: [1, 0, 2], state: "minecraft:sand"},
        {pos: [1, 0, 3], state: "minecraft:sand"},
        {pos: [1, 0, 4], state: "minecraft:smooth_sandstone"},
        {pos: [1, 0, 5], state: "minecraft:smooth_sandstone"},
        {pos: [1, 0, 6], state: "minecraft:smooth_sandstone"},
        {pos: [1, 0, 7], state: "minecraft:smooth_sandstone"},
        {pos: [1, 0, 8], state: "minecraft:smooth_sandstone"},
        {pos: [1, 0, 9], state: "minecraft:smooth_sandstone"},
        {pos: [1, 0, 10], state: "minecraft:sand"},
        {pos: [1, 0, 11], state: "minecraft:sand"},
        {pos: [1, 0, 12], state: "minecraft:sand"},
        {pos: [2, 0, 1], state: "minecraft:sand"},
        {pos: [2, 0, 2], state: "minecraft:sand"},
        {pos: [2, 0, 3], state: "minecraft:sand"},
        {pos: [2, 0, 4], state: "minecraft:smooth_sandstone"},
        {pos: [2, 0, 5], state: "minecraft:sand"},
        {pos: [2, 0, 6], state: "minecraft:sand"},
        {pos: [2, 0, 7], state: "minecraft:sand"},
        {pos: [2, 0, 8], state: "minecraft:sand"},
        {pos: [2, 0, 9], state: "minecraft:smooth_sandstone"},
        {pos: [2, 0, 10], state: "minecraft:sand"},
        {pos: [2, 0, 11], state: "minecraft:sand"},
        {pos: [2, 0, 12], state: "minecraft:jigsaw{orientation:up_north}", nbt: {final_state: "minecraft:sand", id: "minecraft:jigsaw", joint: "rollable", name: "minecraft:bottom", pool: "minecraft:village/desert/decor", target: "minecraft:bottom"}},
        {pos: [2, 0, 13], state: "minecraft:sand"},
        {pos: [3, 0, 0], state: "minecraft:sand"},
        {pos: [3, 0, 1], state: "minecraft:sand"},
        {pos: [3, 0, 2], state: "minecraft:sand"},
        {pos: [3, 0, 3], state: "minecraft:sand"},
        {pos: [3, 0, 4], state: "minecraft:smooth_sandstone"},
        {pos: [3, 0, 5], state: "minecraft:sand"},
        {pos: [3, 0, 6], state: "minecraft:smooth_sandstone"},
        {pos: [3, 0, 7], state: "minecraft:smooth_sandstone"},
        {pos: [3, 0, 8], state: "minecraft:sand"},
        {pos: [3, 0, 9], state: "minecraft:smooth_sandstone"},
        {pos: [3, 0, 10], state: "minecraft:jigsaw{orientation:up_north}", nbt: {final_state: "minecraft:sand", id: "minecraft:jigsaw", joint: "rollable", name: "minecraft:bottom", pool: "minecraft:village/desert/villagers", target: "minecraft:bottom"}},
        {pos: [3, 0, 11], state: "minecraft:sand"},
        {pos: [3, 0, 12], state: "minecraft:sand"},
        {pos: [3, 0, 13], state: "minecraft:sand"},
        {pos: [4, 0, 0], state: "minecraft:smooth_sandstone"},
        {pos: [4, 0, 1], state: "minecraft:smooth_sandstone"},
        {pos: [4, 0, 2], state: "minecraft:smooth_sandstone"},
        {pos: [4, 0, 3], state: "minecraft:smooth_sandstone"},
        {pos: [4, 0, 4], state: "minecraft:smooth_sandstone"},
        {pos: [4, 0, 5], state: "minecraft:sand"},
        {pos: [4, 0, 6], state: "minecraft:smooth_sandstone"},
        {pos: [4, 0, 7], state: "minecraft:smooth_sandstone"},
        {pos: [4, 0, 8], state: "minecraft:sand"},
        {pos: [4, 0, 9], state: "minecraft:smooth_sandstone"},
        {pos: [4, 0, 10], state: "minecraft:sand"},
        {pos: [4, 0, 11], state: "minecraft:jigsaw{orientation:up_north}", nbt: {final_state: "minecraft:sand", id: "minecraft:jigsaw", joint: "rollable", name: "minecraft:bottom", pool: "minecraft:village/common/iron_golem", target: "minecraft:bottom"}},
        {pos: [4, 0, 12], state: "minecraft:sand"},
        {pos: [4, 0, 13], state: "minecraft:sand"},
        {pos: [5, 0, 0], state: "minecraft:sand"},
        {pos: [5, 0, 1], state: "minecraft:smooth_sandstone"},
        {pos: [5, 0, 2], state: "minecraft:sand"},
        {pos: [5, 0, 3], state: "minecraft:smooth_sandstone"},
        {pos: [5, 0, 4], state: "minecraft:smooth_sandstone"},
        {pos: [5, 0, 5], state: "minecraft:sand"},
        {pos: [5, 0, 6], state: "minecraft:sand"},
        {pos: [5, 0, 7], state: "minecraft:sand"},
        {pos: [5, 0, 8], state: "minecraft:sand"},
        {pos: [5, 0, 9], state: "minecraft:smooth_sandstone"},
        {pos: [5, 0, 10], state: "minecraft:sand"},
        {pos: [5, 0, 11], state: "minecraft:sand"},
        {pos: [5, 0, 12], state: "minecraft:sand"},
        {pos: [5, 0, 13], state: "minecraft:sand"},
        {pos: [5, 0, 14], state: "minecraft:sand"},
        {pos: [6, 0, 0], state: "minecraft:sand"},
        {pos: [6, 0, 1], state: "minecraft:smooth_sandstone"},
        {pos: [6, 0, 2], state: "minecraft:sand"},
        {pos: [6, 0, 3], state: "minecraft:smooth_sandstone"},
        {pos: [6, 0, 4], state: "minecraft:smooth_sandstone"},
        {pos: [6, 0, 5], state: "minecraft:smooth_sandstone"},
        {pos: [6, 0, 6], state: "minecraft:smooth_sandstone"},
        {pos: [6, 0, 7], state: "minecraft:smooth_sandstone"},
        {pos: [6, 0, 8], state: "minecraft:smooth_sandstone"},
        {pos: [6, 0, 9], state: "minecraft:smooth_sandstone"},
        {pos: [6, 0, 10], state: "minecraft:jigsaw{orientation:up_north}", nbt: {final_state: "minecraft:sand", id: "minecraft:jigsaw", joint: "rollable", name: "minecraft:bottom", pool: "minecraft:village/desert/villagers", target: "minecraft:bottom"}},
        {pos: [6, 0, 11], state: "minecraft:sand"},
        {pos: [6, 0, 12], state: "minecraft:sand"},
        {pos: [6, 0, 13], state: "minecraft:sand"},
        {pos: [6, 0, 14], state: "minecraft:sand"},
        {pos: [7, 0, 0], state: "minecraft:smooth_sandstone"},
        {pos: [7, 0, 1], state: "minecraft:smooth_sandstone"},
        {pos: [7, 0, 2], state: "minecraft:smooth_sandstone"},
        {pos: [7, 0, 3], state: "minecraft:smooth_sandstone"},
        {pos: [7, 0, 4], state: "minecraft:smooth_sandstone"},
        {pos: [7, 0, 5], state: "minecraft:sand"},
        {pos: [7, 0, 6], state: "minecraft:sand"},
        {pos: [7, 0, 7], state: "minecraft:sand"},
        {pos: [7, 0, 8], state: "minecraft:sand"},
        {pos: [7, 0, 9], state: "minecraft:sand"},
        {pos: [7, 0, 10], state: "minecraft:sand"},
        {pos: [7, 0, 11], state: "minecraft:sand"},
        {pos: [7, 0, 12], state: "minecraft:sand"},
        {pos: [7, 0, 13], state: "minecraft:sand"},
        {pos: [7, 0, 14], state: "minecraft:sand"},
        {pos: [8, 0, 0], state: "minecraft:sand"},
        {pos: [8, 0, 1], state: "minecraft:sand"},
        {pos: [8, 0, 2], state: "minecraft:sand"},
        {pos: [8, 0, 3], state: "minecraft:sand"},
        {pos: [8, 0, 4], state: "minecraft:sand"},
        {pos: [8, 0, 5], state: "minecraft:jigsaw{orientation:up_north}", nbt: {final_state: "minecraft:sand", id: "minecraft:jigsaw", joint: "rollable", name: "minecraft:bottom", pool: "minecraft:village/desert/villagers", target: "minecraft:bottom"}},
        {pos: [8, 0, 6], state: "minecraft:sand"},
        {pos: [8, 0, 7], state: "minecraft:sand"},
        {pos: [8, 0, 8], state: "minecraft:sand"},
        {pos: [8, 0, 9], state: "minecraft:sand"},
        {pos: [8, 0, 10], state: "minecraft:sand"},
        {pos: [8, 0, 11], state: "minecraft:sand"},
        {pos: [8, 0, 12], state: "minecraft:sand"},
        {pos: [8, 0, 13], state: "minecraft:sand"},
        {pos: [8, 0, 14], state: "minecraft:sand"},
        {pos: [9, 0, 0], state: "minecraft:sand"},
        {pos: [9, 0, 1], state: "minecraft:sand"},
        {pos: [9, 0, 2], state: "minecraft:sand"},
        {pos: [9, 0, 3], state: "minecraft:sand"},
        {pos: [9, 0, 4], state: "minecraft:sand"},
        {pos: [9, 0, 5], state: "minecraft:sand"},
        {pos: [9, 0, 6], state: "minecraft:sand"},
        {pos: [9, 0, 7], state: "minecraft:sand"},
        {pos: [9, 0, 8], state: "minecraft:sand"},
        {pos: [9, 0, 9], state: "minecraft:sand"},
        {pos: [9, 0, 10], state: "minecraft:sand"},
        {pos: [9, 0, 11], state: "minecraft:sand"},
        {pos: [9, 0, 12], state: "minecraft:sand"},
        {pos: [9, 0, 13], state: "minecraft:sand"},
        {pos: [9, 0, 14], state: "minecraft:sand"},
        {pos: [10, 0, 2], state: "minecraft:sand"},
        {pos: [10, 0, 3], state: "minecraft:sand"},
        {pos: [10, 0, 4], state: "minecraft:sand"},
        {pos: [10, 0, 5], state: "minecraft:sand"},
        {pos: [10, 0, 6], state: "minecraft:sand"},
        {pos: [10, 0, 7], state: "minecraft:sand"},
        {pos: [10, 0, 8], state: "minecraft:sand"},
        {pos: [10, 0, 9], state: "minecraft:sand"},
        {pos: [10, 0, 10], state: "minecraft:sand"},
        {pos: [10, 0, 11], state: "minecraft:sand"},
        {pos: [10, 0, 12], state: "minecraft:sand"},
        {pos: [10, 0, 13], state: "minecraft:sand"},
        {pos: [10, 0, 14], state: "minecraft:sand"},
        {pos: [11, 0, 1], state: "minecraft:sand"},
        {pos: [11, 0, 2], state: "minecraft:sand"},
        {pos: [11, 0, 3], state: "minecraft:sand"},
        {pos: [11, 0, 4], state: "minecraft:sand"},
        {pos: [11, 0, 5], state: "minecraft:sand"},
        {pos: [11, 0, 6], state: "minecraft:sand"},
        {pos: [11, 0, 7], state: "minecraft:sand"},
        {pos: [11, 0, 8], state: "minecraft:sand"},
        {pos: [11, 0, 9], state: "minecraft:sand"},
        {pos: [11, 0, 10], state: "minecraft:sand"},
        {pos: [11, 0, 11], state: "minecraft:sand"},
        {pos: [11, 0, 12], state: "minecraft:sand"},
        {pos: [11, 0, 13], state: "minecraft:sand"},
        {pos: [12, 0, 4], state: "minecraft:sand"},
        {pos: [12, 0, 5], state: "minecraft:sand"},
        {pos: [12, 0, 6], state: "minecraft:sand"},
        {pos: [12, 0, 7], state: "minecraft:sand"},
        {pos: [12, 0, 8], state: "minecraft:sand"},
        {pos: [12, 0, 9], state: "minecraft:sand"},
        {pos: [12, 0, 10], state: "minecraft:sand"},
        {pos: [12, 0, 11], state: "minecraft:sand"},
        {pos: [12, 0, 12], state: "minecraft:sand"},
        {pos: [12, 0, 14], state: "minecraft:sand"},
        {pos: [13, 0, 4], state: "minecraft:sand"},
        {pos: [13, 0, 5], state: "minecraft:sand"},
        {pos: [13, 0, 6], state: "minecraft:sand"},
        {pos: [13, 0, 7], state: "minecraft:sand"},
        {pos: [13, 0, 8], state: "minecraft:sand"},
        {pos: [13, 0, 9], state: "minecraft:sand"},
        {pos: [13, 0, 10], state: "minecraft:sand"},
        {pos: [13, 0, 11], state: "minecraft:jigsaw{orientation:up_north}", nbt: {final_state: "minecraft:sand", id: "minecraft:jigsaw", joint: "rollable", name: "minecraft:bottom", pool: "minecraft:village/desert/decor", target: "minecraft:bottom"}},
        {pos: [13, 0, 12], state: "minecraft:sand"},
        {pos: [13, 0, 14], state: "minecraft:sand"},
        {pos: [14, 0, 7], state: "minecraft:sand"},
        {pos: [14, 0, 8], state: "minecraft:sand"},
        {pos: [14, 0, 9], state: "minecraft:sand"},
        {pos: [14, 0, 10], state: "minecraft:sand"},
        {pos: [14, 0, 11], state: "minecraft:sand"},
        {pos: [14, 0, 12], state: "minecraft:sand"},
        {pos: [0, 1, 3], state: "minecraft:cut_sandstone"},
        {pos: [0, 1, 7], state: "minecraft:jigsaw{orientation:west_up}", nbt: {final_state: "minecraft:structure_void", id: "minecraft:jigsaw", joint: "aligned", name: "minecraft:street", pool: "minecraft:village/desert/streets", target: "minecraft:street"}},
        {pos: [2, 1, 5], state: "minecraft:cut_sandstone"},
        {pos: [2, 1, 6], state: "minecraft:smooth_sandstone"},
        {pos: [2, 1, 7], state: "minecraft:smooth_sandstone"},
        {pos: [2, 1, 8], state: "minecraft:cut_sandstone"},
        {pos: [3, 1, 5], state: "minecraft:smooth_sandstone"},
        {pos: [3, 1, 6], state: "minecraft:water{level:0}"},
        {pos: [3, 1, 7], state: "minecraft:water{level:0}"},
        {pos: [3, 1, 8], state: "minecraft:smooth_sandstone"},
        {pos: [4, 1, 0], state: "minecraft:sandstone_wall{east:low,north:none,south:none,up:true,waterlogged:false,west:none}"},
        {pos: [4, 1, 2], state: "minecraft:sandstone_wall{east:low,north:none,south:none,up:true,waterlogged:false,west:none}"},
        {pos: [4, 1, 5], state: "minecraft:smooth_sandstone"},
        {pos: [4, 1, 6], state: "minecraft:water{level:0}"},
        {pos: [4, 1, 7], state: "minecraft:water{level:0}"},
        {pos: [4, 1, 8], state: "minecraft:smooth_sandstone"},
        {pos: [5, 1, 0], state: "minecraft:white_glazed_terracotta{facing:north}"},
        {pos: [5, 1, 2], state: "minecraft:white_glazed_terracotta{facing:west}"},
        {pos: [5, 1, 4], state: "minecraft:air"},
        {pos: [5, 1, 5], state: "minecraft:cut_sandstone"},
        {pos: [5, 1, 6], state: "minecraft:smooth_sandstone"},
        {pos: [5, 1, 7], state: "minecraft:smooth_sandstone"},
        {pos: [5, 1, 8], state: "minecraft:cut_sandstone"},
        {pos: [6, 1, 0], state: "minecraft:white_glazed_terracotta{facing:east}"},
        {pos: [6, 1, 2], state: "minecraft:white_glazed_terracotta{facing:south}"},
        {pos: [6, 1, 4], state: "minecraft:jigsaw{orientation:up_north}", nbt: {final_state: "minecraft:structure_void", id: "minecraft:jigsaw", joint: "rollable", name: "minecraft:bottom", pool: "minecraft:village/common/cats", target: "minecraft:bottom"}},
        {pos: [6, 1, 8], state: "minecraft:air"},
        {pos: [7, 1, 0], state: "minecraft:sandstone_wall{east:none,north:none,south:none,up:true,waterlogged:false,west:low}"},
        {pos: [7, 1, 2], state: "minecraft:sandstone_wall{east:none,north:none,south:none,up:true,waterlogged:false,west:low}"},
        {pos: [7, 1, 11], state: "minecraft:sandstone_wall{east:none,north:none,south:none,up:true,waterlogged:false,west:none}"},
        {pos: [7, 1, 14], state: "minecraft:sandstone_wall{east:none,north:none,south:none,up:true,waterlogged:false,west:none}"},
        {pos: [8, 1, 12], state: "minecraft:white_glazed_terracotta{facing:north}"},
        {pos: [8, 1, 13], state: "minecraft:white_glazed_terracotta{facing:west}"},
        {pos: [9, 1, 0], state: "minecraft:hay_block{axis:y}"},
        {pos: [9, 1, 5], state: "minecraft:sandstone_wall{east:none,north:none,south:none,up:true,waterlogged:false,west:none}"},
        {pos: [9, 1, 6], state: "minecraft:smooth_sandstone_stairs{facing:east,half:bottom,shape:straight,waterlogged:false}"},
        {pos: [9, 1, 7], state: "minecraft:sandstone_wall{east:none,north:none,south:none,up:true,waterlogged:false,west:none}"},
        {pos: [9, 1, 9], state: "minecraft:jigsaw{orientation:up_north}", nbt: {final_state: "minecraft:structure_void", id: "minecraft:jigsaw", joint: "rollable", name: "minecraft:bottom", pool: "minecraft:village/common/cats", target: "minecraft:bottom"}},
        {pos: [9, 1, 12], state: "minecraft:white_glazed_terracotta{facing:east}"},
        {pos: [9, 1, 13], state: "minecraft:white_glazed_terracotta{facing:south}"},
        {pos: [10, 1, 5], state: "minecraft:potted_dead_bush"},
        {pos: [10, 1, 6], state: "minecraft:cut_sandstone"},
        {pos: [10, 1, 11], state: "minecraft:sandstone_wall{east:none,north:none,south:none,up:true,waterlogged:false,west:none}"},
        {pos: [10, 1, 14], state: "minecraft:sandstone_wall{east:none,north:none,south:none,up:true,waterlogged:false,west:none}"},
        {pos: [11, 1, 2], state: "minecraft:hay_block{axis:x}"},
        {pos: [11, 1, 6], state: "minecraft:cut_sandstone"},
        {pos: [11, 1, 7], state: "minecraft:potted_cactus"},
        {pos: [12, 1, 5], state: "minecraft:potted_dead_bush"},
        {pos: [12, 1, 6], state: "minecraft:cut_sandstone"},
        {pos: [12, 1, 7], state: "minecraft:potted_dead_bush"},
        {pos: [12, 1, 14], state: "minecraft:jigsaw{orientation:south_up}", nbt: {final_state: "minecraft:structure_void", id: "minecraft:jigsaw", joint: "aligned", name: "minecraft:street", pool: "minecraft:village/desert/streets", target: "minecraft:street"}},
        {pos: [13, 1, 4], state: "minecraft:potted_dead_bush"},
        {pos: [13, 1, 5], state: "minecraft:sandstone_wall{east:none,north:none,south:none,up:true,waterlogged:false,west:none}"},
        {pos: [13, 1, 6], state: "minecraft:smooth_sandstone_stairs{facing:west,half:bottom,shape:straight,waterlogged:false}"},
        {pos: [13, 1, 7], state: "minecraft:sandstone_wall{east:none,north:none,south:none,up:true,waterlogged:false,west:none}"},
        {pos: [14, 1, 7], state: "minecraft:potted_cactus"},
        {pos: [14, 1, 8], state: "minecraft:jigsaw{orientation:east_up}", nbt: {final_state: "minecraft:structure_void", id: "minecraft:jigsaw", joint: "aligned", name: "minecraft:street", pool: "minecraft:village/desert/streets", target: "minecraft:street"}},
        {pos: [0, 2, 3], state: "minecraft:cut_sandstone"},
        {pos: [1, 2, 7], state: "minecraft:air"},
        {pos: [2, 2, 5], state: "minecraft:sandstone_slab{type:bottom,waterlogged:false}"},
        {pos: [2, 2, 8], state: "minecraft:sandstone_slab{type:bottom,waterlogged:false}"},
        {pos: [3, 2, 11], state: "minecraft:air"},
        {pos: [4, 2, 0], state: "minecraft:sandstone_wall{east:none,north:none,south:none,up:true,waterlogged:false,west:none}"},
        {pos: [4, 2, 2], state: "minecraft:sandstone_wall{east:none,north:none,south:none,up:true,waterlogged:false,west:none}"},
        {pos: [5, 2, 2], state: "minecraft:potted_cactus"},
        {pos: [5, 2, 5], state: "minecraft:sandstone_slab{type:bottom,waterlogged:false}"},
        {pos: [5, 2, 8], state: "minecraft:sandstone_slab{type:bottom,waterlogged:false}"},
        {pos: [6, 2, 9], state: "minecraft:air"},
        {pos: [7, 2, 0], state: "minecraft:sandstone_wall{east:none,north:none,south:none,up:true,waterlogged:false,west:none}"},
        {pos: [7, 2, 2], state: "minecraft:sandstone_wall{east:none,north:none,south:none,up:true,waterlogged:false,west:none}"},
        {pos: [7, 2, 11], state: "minecraft:sandstone_wall{east:none,north:none,south:none,up:true,waterlogged:false,west:none}"},
        {pos: [7, 2, 14], state: "minecraft:sandstone_wall{east:none,north:none,south:none,up:true,waterlogged:false,west:none}"},
        {pos: [9, 2, 5], state: "minecraft:sandstone_wall{east:none,north:none,south:none,up:true,waterlogged:false,west:none}"},
        {pos: [9, 2, 7], state: "minecraft:sandstone_wall{east:none,north:none,south:none,up:true,waterlogged:false,west:none}"},
        {pos: [10, 2, 6], state: "minecraft:potted_cactus"},
        {pos: [10, 2, 11], state: "minecraft:sandstone_wall{east:none,north:none,south:none,up:true,waterlogged:false,west:none}"},
        {pos: [10, 2, 14], state: "minecraft:sandstone_wall{east:none,north:none,south:none,up:true,waterlogged:false,west:none}"},
        {pos: [11, 2, 6], state: "minecraft:potted_dead_bush"},
        {pos: [12, 2, 6], state: "minecraft:potted_cactus"},
        {pos: [13, 2, 5], state: "minecraft:sandstone_wall{east:none,north:none,south:none,up:true,waterlogged:false,west:none}"},
        {pos: [13, 2, 7], state: "minecraft:sandstone_wall{east:none,north:none,south:none,up:true,waterlogged:false,west:none}"},
        {pos: [0, 3, 3], state: "minecraft:terracotta"},
        {pos: [4, 3, 0], state: "minecraft:sandstone_wall{east:none,north:none,south:none,up:true,waterlogged:false,west:none}"},
        {pos: [4, 3, 2], state: "minecraft:sandstone_wall{east:none,north:none,south:none,up:true,waterlogged:false,west:none}"},
        {pos: [6, 3, 2], state: "minecraft:bell{attachment:ceiling,facing:north,powered:false}", nbt: {id: "minecraft:bell"}},
        {pos: [7, 3, 0], state: "minecraft:sandstone_wall{east:none,north:none,south:none,up:true,waterlogged:false,west:none}"},
        {pos: [7, 3, 2], state: "minecraft:sandstone_wall{east:none,north:none,south:none,up:true,waterlogged:false,west:none}"},
        {pos: [7, 3, 11], state: "minecraft:sandstone_wall{east:none,north:none,south:none,up:true,waterlogged:false,west:none}"},
        {pos: [7, 3, 14], state: "minecraft:sandstone_wall{east:none,north:none,south:none,up:true,waterlogged:false,west:none}"},
        {pos: [9, 3, 5], state: "minecraft:sandstone_wall{east:none,north:none,south:none,up:true,waterlogged:false,west:none}"},
        {pos: [9, 3, 7], state: "minecraft:sandstone_wall{east:none,north:none,south:none,up:true,waterlogged:false,west:none}"},
        {pos: [10, 3, 11], state: "minecraft:sandstone_wall{east:none,north:none,south:none,up:true,waterlogged:false,west:none}"},
        {pos: [10, 3, 14], state: "minecraft:sandstone_wall{east:none,north:none,south:none,up:true,waterlogged:false,west:none}"},
        {pos: [13, 3, 5], state: "minecraft:sandstone_wall{east:none,north:none,south:none,up:true,waterlogged:false,west:none}"},
        {pos: [13, 3, 7], state: "minecraft:sandstone_wall{east:none,north:none,south:none,up:true,waterlogged:false,west:none}"},
        {pos: [0, 4, 3], state: "minecraft:torch"},
        {pos: [4, 4, 0], state: "minecraft:smooth_sandstone_slab{type:bottom,waterlogged:false}"},
        {pos: [4, 4, 1], state: "minecraft:smooth_sandstone_slab{type:bottom,waterlogged:false}"},
        {pos: [4, 4, 2], state: "minecraft:smooth_sandstone_slab{type:bottom,waterlogged:false}"},
        {pos: [5, 4, 0], state: "minecraft:smooth_sandstone_slab{type:bottom,waterlogged:false}"},
        {pos: [5, 4, 2], state: "minecraft:smooth_sandstone_slab{type:bottom,waterlogged:false}"},
        {pos: [6, 4, 0], state: "minecraft:smooth_sandstone_slab{type:bottom,waterlogged:false}"},
        {pos: [6, 4, 2], state: "minecraft:smooth_sandstone_slab{type:bottom,waterlogged:false}"},
        {pos: [7, 4, 0], state: "minecraft:smooth_sandstone_slab{type:bottom,waterlogged:false}"},
        {pos: [7, 4, 1], state: "minecraft:smooth_sandstone_slab{type:bottom,waterlogged:false}"},
        {pos: [7, 4, 2], state: "minecraft:smooth_sandstone_slab{type:bottom,waterlogged:false}"},
        {pos: [7, 4, 11], state: "minecraft:smooth_sandstone_slab{type:bottom,waterlogged:false}"},
        {pos: [7, 4, 12], state: "minecraft:smooth_sandstone_slab{type:bottom,waterlogged:false}"},
        {pos: [7, 4, 13], state: "minecraft:smooth_sandstone_slab{type:bottom,waterlogged:false}"},
        {pos: [7, 4, 14], state: "minecraft:smooth_sandstone_slab{type:bottom,waterlogged:false}"},
        {pos: [8, 4, 11], state: "minecraft:smooth_sandstone_slab{type:bottom,waterlogged:false}"},
        {pos: [8, 4, 14], state: "minecraft:smooth_sandstone_slab{type:bottom,waterlogged:false}"},
        {pos: [9, 4, 5], state: "minecraft:sandstone_wall{east:none,north:none,south:none,up:true,waterlogged:false,west:none}"},
        {pos: [9, 4, 7], state: "minecraft:sandstone_wall{east:none,north:none,south:none,up:true,waterlogged:false,west:none}"},
        {pos: [9, 4, 11], state: "minecraft:smooth_sandstone_slab{type:bottom,waterlogged:false}"},
        {pos: [9, 4, 14], state: "minecraft:smooth_sandstone_slab{type:bottom,waterlogged:false}"},
        {pos: [10, 4, 11], state: "minecraft:smooth_sandstone_slab{type:bottom,waterlogged:false}"},
        {pos: [10, 4, 12], state: "minecraft:smooth_sandstone_slab{type:bottom,waterlogged:false}"},
        {pos: [10, 4, 13], state: "minecraft:smooth_sandstone_slab{type:bottom,waterlogged:false}"},
        {pos: [10, 4, 14], state: "minecraft:smooth_sandstone_slab{type:bottom,waterlogged:false}"},
        {pos: [13, 4, 5], state: "minecraft:sandstone_wall{east:none,north:none,south:none,up:true,waterlogged:false,west:none}"},
        {pos: [13, 4, 7], state: "minecraft:sandstone_wall{east:none,north:none,south:none,up:true,waterlogged:false,west:none}"},
        {pos: [9, 5, 5], state: "minecraft:smooth_sandstone_slab{type:bottom,waterlogged:false}"},
        {pos: [9, 5, 6], state: "minecraft:smooth_sandstone_slab{type:bottom,waterlogged:false}"},
        {pos: [9, 5, 7], state: "minecraft:smooth_sandstone_slab{type:bottom,waterlogged:false}"},
        {pos: [10, 5, 5], state: "minecraft:smooth_sandstone_slab{type:bottom,waterlogged:false}"},
        {pos: [10, 5, 7], state: "minecraft:smooth_sandstone_slab{type:bottom,waterlogged:false}"},
        {pos: [11, 5, 5], state: "minecraft:smooth_sandstone_slab{type:bottom,waterlogged:false}"},
        {pos: [11, 5, 7], state: "minecraft:smooth_sandstone_slab{type:bottom,waterlogged:false}"},
        {pos: [12, 5, 5], state: "minecraft:smooth_sandstone_slab{type:bottom,waterlogged:false}"},
        {pos: [12, 5, 7], state: "minecraft:smooth_sandstone_slab{type:bottom,waterlogged:false}"},
        {pos: [13, 5, 5], state: "minecraft:smooth_sandstone_slab{type:bottom,waterlogged:false}"},
        {pos: [13, 5, 6], state: "minecraft:smooth_sandstone_slab{type:bottom,waterlogged:false}"},
        {pos: [13, 5, 7], state: "minecraft:smooth_sandstone_slab{type:bottom,waterlogged:false}"}
    ],
    entities: [],
    palette: [
        "minecraft:sand",
        "minecraft:smooth_sandstone",
        "minecraft:cut_sandstone",
        "minecraft:white_glazed_terracotta{facing:north}",
        "minecraft:white_glazed_terracotta{facing:west}",
        "minecraft:white_glazed_terracotta{facing:east}",
        "minecraft:white_glazed_terracotta{facing:south}",
        "minecraft:hay_block{axis:y}",
        "minecraft:hay_block{axis:x}",
        "minecraft:terracotta",
        "minecraft:water{level:0}",
        "minecraft:sandstone_wall{east:low,north:none,south:none,up:true,waterlogged:false,west:none}",
        "minecraft:air",
        "minecraft:sandstone_wall{east:none,north:none,south:none,up:true,waterlogged:false,west:low}",
        "minecraft:sandstone_wall{east:none,north:none,south:none,up:true,waterlogged:false,west:none}",
        "minecraft:smooth_sandstone_stairs{facing:east,half:bottom,shape:straight,waterlogged:false}",
        "minecraft:potted_dead_bush",
        "minecraft:potted_cactus",
        "minecraft:smooth_sandstone_stairs{facing:west,half:bottom,shape:straight,waterlogged:false}",
        "minecraft:sandstone_slab{type:bottom,waterlogged:false}",
        "minecraft:torch",
        "minecraft:smooth_sandstone_slab{type:bottom,waterlogged:false}",
        "minecraft:jigsaw{orientation:up_north}",
        "minecraft:jigsaw{orientation:west_up}",
        "minecraft:jigsaw{orientation:south_up}",
        "minecraft:jigsaw{orientation:east_up}",
        "minecraft:bell{attachment:ceiling,facing:north,powered:false}"
    ]
}
