{
    size: [5, 6, 3],
    data: [
        {pos: [1, 0, 0], state: "minecraft:cobblestone"},
        {pos: [1, 0, 1], state: "minecraft:cobblestone"},
        {pos: [1, 0, 2], state: "minecraft:cobblestone"},
        {pos: [2, 0, 0], state: "minecraft:cobblestone"},
        {pos: [2, 0, 1], state: "minecraft:cobblestone"},
        {pos: [2, 0, 2], state: "minecraft:cobblestone"},
        {pos: [3, 0, 0], state: "minecraft:cobblestone"},
        {pos: [3, 0, 1], state: "minecraft:cobblestone"},
        {pos: [3, 0, 2], state: "minecraft:cobblestone"},
        {pos: [1, 1, 0], state: "minecraft:cobblestone"},
        {pos: [1, 1, 1], state: "minecraft:cobblestone"},
        {pos: [1, 1, 2], state: "minecraft:cobblestone"},
        {pos: [2, 1, 0], state: "minecraft:cobblestone"},
        {pos: [2, 1, 1], state: "minecraft:cobblestone"},
        {pos: [2, 1, 2], state: "minecraft:cobblestone"},
        {pos: [3, 1, 0], state: "minecraft:cobblestone"},
        {pos: [3, 1, 1], state: "minecraft:cobblestone"},
        {pos: [3, 1, 2], state: "minecraft:cobblestone"},
        {pos: [1, 2, 0], state: "minecraft:white_terracotta"},
        {pos: [1, 2, 1], state: "minecraft:red_terracotta"},
        {pos: [1, 2, 2], state: "minecraft:red_terracotta"},
        {pos: [2, 2, 0], state: "minecraft:red_terracotta"},
        {pos: [2, 2, 1], state: "minecraft:red_terracotta"},
        {pos: [2, 2, 2], state: "minecraft:jigsaw{orientation:south_up}", nbt: {final_state: "minecraft:red_terracotta", id: "minecraft:jigsaw", joint: "rollable", name: "minecraft:decor_anchor", pool: "minecraft:trail_ruins/roads", target: "minecraft:road_anchor"}},
        {pos: [3, 2, 0], state: "minecraft:red_terracotta"},
        {pos: [3, 2, 1], state: "minecraft:white_terracotta"},
        {pos: [3, 2, 2], state: "minecraft:red_terracotta"},
        {pos: [1, 3, 0], state: "minecraft:gravel"},
        {pos: [1, 3, 1], state: "minecraft:gravel"},
        {pos: [1, 3, 2], state: "minecraft:white_terracotta"},
        {pos: [2, 3, 0], state: "minecraft:white_terracotta"},
        {pos: [2, 3, 1], state: "minecraft:gravel"},
        {pos: [2, 3, 2], state: "minecraft:white_terracotta"},
        {pos: [3, 3, 0], state: "minecraft:white_terracotta"},
        {pos: [3, 3, 1], state: "minecraft:white_terracotta"},
        {pos: [3, 3, 2], state: "minecraft:white_terracotta"},
        {pos: [1, 4, 0], state: "minecraft:gravel"},
        {pos: [1, 4, 1], state: "minecraft:gravel"},
        {pos: [1, 4, 2], state: "minecraft:gravel"},
        {pos: [2, 4, 0], state: "minecraft:gravel"},
        {pos: [2, 4, 2], state: "minecraft:gravel"},
        {pos: [3, 4, 0], state: "minecraft:gravel"},
        {pos: [3, 4, 1], state: "minecraft:white_terracotta"},
        {pos: [3, 4, 2], state: "minecraft:gravel"},
        {pos: [1, 5, 2], state: "minecraft:gravel"},
        {pos: [2, 5, 1], state: "minecraft:white_terracotta"},
        {pos: [2, 5, 2], state: "minecraft:gravel"},
        {pos: [3, 5, 0], state: "minecraft:gravel"},
        {pos: [3, 5, 1], state: "minecraft:white_terracotta"},
        {pos: [3, 5, 2], state: "minecraft:gravel"}
    ],
    entities: [],
    palette: [
        "minecraft:cobblestone",
        "minecraft:white_terracotta",
        "minecraft:red_terracotta",
        "minecraft:gravel",
        "minecraft:jigsaw{orientation:south_up}"
    ]
}
