{
    DataVersion: 2856,
    size: [9, 9, 16],
    data: [
        {pos: [4, 0, 0], state: "minecraft:spruce_planks"},
        {pos: [4, 0, 1], state: "minecraft:spruce_planks"},
        {pos: [4, 0, 2], state: "minecraft:spruce_planks"},
        {pos: [4, 0, 3], state: "minecraft:spruce_planks"},
        {pos: [4, 0, 4], state: "minecraft:spruce_planks"},
        {pos: [4, 0, 5], state: "minecraft:spruce_planks"},
        {pos: [4, 0, 6], state: "minecraft:spruce_planks"},
        {pos: [4, 0, 7], state: "minecraft:spruce_planks"},
        {pos: [4, 0, 8], state: "minecraft:spruce_planks"},
        {pos: [4, 0, 9], state: "minecraft:spruce_stairs{facing:north,half:top,shape:outer_right,waterlogged:false}"},
        {pos: [4, 0, 13], state: "minecraft:oak_planks"},
        {pos: [4, 0, 14], state: "minecraft:oak_planks"},
        {pos: [2, 1, 0], state: "minecraft:oak_stairs{facing:east,half:top,shape:outer_right,waterlogged:false}"},
        {pos: [2, 1, 1], state: "minecraft:oak_stairs{facing:east,half:top,shape:outer_right,waterlogged:false}"},
        {pos: [2, 1, 2], state: "minecraft:oak_stairs{facing:east,half:top,shape:outer_right,waterlogged:false}"},
        {pos: [2, 1, 3], state: "minecraft:oak_stairs{facing:east,half:top,shape:outer_right,waterlogged:false}"},
        {pos: [2, 1, 4], state: "minecraft:oak_stairs{facing:east,half:top,shape:outer_right,waterlogged:false}"},
        {pos: [2, 1, 5], state: "minecraft:oak_stairs{facing:east,half:top,shape:outer_right,waterlogged:false}"},
        {pos: [2, 1, 6], state: "minecraft:oak_stairs{facing:east,half:top,shape:outer_right,waterlogged:false}"},
        {pos: [2, 1, 7], state: "minecraft:oak_stairs{facing:east,half:top,shape:outer_right,waterlogged:false}"},
        {pos: [2, 1, 8], state: "minecraft:oak_stairs{facing:east,half:top,shape:outer_right,waterlogged:false}"},
        {pos: [3, 1, 0], state: "minecraft:oak_planks"},
        {pos: [3, 1, 1], state: "minecraft:oak_planks"},
        {pos: [3, 1, 2], state: "minecraft:oak_planks"},
        {pos: [3, 1, 3], state: "minecraft:oak_planks"},
        {pos: [3, 1, 4], state: "minecraft:oak_planks"},
        {pos: [3, 1, 5], state: "minecraft:oak_planks"},
        {pos: [3, 1, 6], state: "minecraft:oak_planks"},
        {pos: [3, 1, 7], state: "minecraft:oak_planks"},
        {pos: [3, 1, 8], state: "minecraft:oak_planks"},
        {pos: [3, 1, 9], state: "minecraft:oak_stairs{facing:east,half:top,shape:outer_right,waterlogged:false}"},
        {pos: [3, 1, 10], state: "minecraft:oak_stairs{facing:east,half:top,shape:outer_right,waterlogged:false}"},
        {pos: [3, 1, 11], state: "minecraft:oak_stairs{facing:east,half:top,shape:outer_right,waterlogged:false}"},
        {pos: [4, 1, 1], state: "minecraft:oak_planks"},
        {pos: [4, 1, 2], state: "minecraft:oak_planks"},
        {pos: [4, 1, 3], state: "minecraft:oak_planks"},
        {pos: [4, 1, 4], state: "minecraft:oak_planks"},
        {pos: [4, 1, 5], state: "minecraft:oak_planks"},
        {pos: [4, 1, 6], state: "minecraft:oak_planks"},
        {pos: [4, 1, 7], state: "minecraft:oak_planks"},
        {pos: [4, 1, 8], state: "minecraft:oak_planks"},
        {pos: [4, 1, 9], state: "minecraft:oak_planks"},
        {pos: [4, 1, 10], state: "minecraft:spruce_planks"},
        {pos: [4, 1, 11], state: "minecraft:spruce_planks"},
        {pos: [4, 1, 12], state: "minecraft:spruce_stairs{facing:north,half:top,shape:outer_right,waterlogged:false}"},
        {pos: [4, 1, 13], state: "minecraft:oak_planks"},
        {pos: [4, 1, 14], state: "minecraft:oak_planks"},
        {pos: [5, 1, 2], state: "minecraft:oak_planks"},
        {pos: [5, 1, 3], state: "minecraft:oak_planks"},
        {pos: [5, 1, 4], state: "minecraft:oak_planks"},
        {pos: [5, 1, 5], state: "minecraft:oak_planks"},
        {pos: [5, 1, 6], state: "minecraft:oak_planks"},
        {pos: [5, 1, 7], state: "minecraft:oak_planks"},
        {pos: [5, 1, 8], state: "minecraft:oak_planks"},
        {pos: [5, 1, 9], state: "minecraft:oak_stairs{facing:west,half:top,shape:outer_right,waterlogged:false}"},
        {pos: [5, 1, 10], state: "minecraft:oak_stairs{facing:west,half:top,shape:outer_right,waterlogged:false}"},
        {pos: [5, 1, 11], state: "minecraft:oak_stairs{facing:west,half:top,shape:outer_right,waterlogged:false}"},
        {pos: [6, 1, 0], state: "minecraft:oak_stairs{facing:west,half:top,shape:outer_right,waterlogged:false}"},
        {pos: [6, 1, 1], state: "minecraft:oak_stairs{facing:west,half:top,shape:outer_right,waterlogged:false}"},
        {pos: [6, 1, 2], state: "minecraft:oak_stairs{facing:west,half:top,shape:outer_right,waterlogged:false}"},
        {pos: [6, 1, 3], state: "minecraft:oak_stairs{facing:west,half:top,shape:outer_right,waterlogged:false}"},
        {pos: [6, 1, 4], state: "minecraft:oak_stairs{facing:west,half:top,shape:outer_right,waterlogged:false}"},
        {pos: [6, 1, 5], state: "minecraft:oak_stairs{facing:west,half:top,shape:outer_right,waterlogged:false}"},
        {pos: [6, 1, 6], state: "minecraft:oak_stairs{facing:west,half:top,shape:outer_right,waterlogged:false}"},
        {pos: [6, 1, 7], state: "minecraft:oak_stairs{facing:west,half:top,shape:outer_right,waterlogged:false}"},
        {pos: [6, 1, 8], state: "minecraft:oak_stairs{facing:west,half:top,shape:outer_right,waterlogged:false}"},
        {pos: [1, 2, 2], state: "minecraft:oak_stairs{facing:east,half:top,shape:outer_right,waterlogged:false}"},
        {pos: [1, 2, 3], state: "minecraft:oak_stairs{facing:east,half:top,shape:outer_right,waterlogged:false}"},
        {pos: [1, 2, 4], state: "minecraft:oak_stairs{facing:east,half:top,shape:outer_right,waterlogged:false}"},
        {pos: [1, 2, 5], state: "minecraft:oak_stairs{facing:east,half:top,shape:outer_right,waterlogged:false}"},
        {pos: [1, 2, 6], state: "minecraft:oak_stairs{facing:east,half:top,shape:outer_right,waterlogged:false}"},
        {pos: [1, 2, 7], state: "minecraft:oak_stairs{facing:east,half:top,shape:outer_right,waterlogged:false}"},
        {pos: [1, 2, 8], state: "minecraft:oak_stairs{facing:east,half:top,shape:outer_right,waterlogged:false}"},
        {pos: [2, 2, 1], state: "minecraft:oak_planks"},
        {pos: [2, 2, 2], state: "minecraft:oak_planks"},
        {pos: [2, 2, 3], state: "minecraft:oak_stairs{facing:west,half:bottom,shape:outer_right,waterlogged:false}"},
        {pos: [2, 2, 4], state: "minecraft:oak_planks"},
        {pos: [2, 2, 5], state: "minecraft:oak_planks"},
        {pos: [2, 2, 6], state: "minecraft:oak_stairs{facing:west,half:bottom,shape:outer_right,waterlogged:false}"},
        {pos: [2, 2, 7], state: "minecraft:oak_planks"},
        {pos: [2, 2, 8], state: "minecraft:oak_planks"},
        {pos: [2, 2, 9], state: "minecraft:oak_stairs{facing:east,half:top,shape:outer_right,waterlogged:false}"},
        {pos: [2, 2, 10], state: "minecraft:oak_stairs{facing:east,half:top,shape:outer_right,waterlogged:false}"},
        {pos: [2, 2, 11], state: "minecraft:oak_stairs{facing:east,half:top,shape:outer_right,waterlogged:false}"},
        {pos: [2, 2, 12], state: "minecraft:oak_stairs{facing:east,half:top,shape:outer_right,waterlogged:false}"},
        {pos: [3, 2, 4], state: "minecraft:oak_door{facing:south,half:lower,hinge:right,open:false,powered:false}"},
        {pos: [3, 2, 8], state: "minecraft:oak_planks"},
        {pos: [3, 2, 9], state: "minecraft:oak_planks"},
        {pos: [3, 2, 10], state: "minecraft:oak_planks"},
        {pos: [3, 2, 11], state: "minecraft:oak_planks"},
        {pos: [3, 2, 12], state: "minecraft:oak_stairs{facing:north,half:top,shape:outer_right,waterlogged:false}"},
        {pos: [4, 2, 4], state: "minecraft:oak_log{axis:y}"},
        {pos: [4, 2, 8], state: "minecraft:oak_planks"},
        {pos: [4, 2, 9], state: "minecraft:oak_planks"},
        {pos: [4, 2, 10], state: "minecraft:oak_planks"},
        {pos: [4, 2, 11], state: "minecraft:oak_planks"},
        {pos: [4, 2, 12], state: "minecraft:spruce_planks"},
        {pos: [4, 2, 13], state: "minecraft:spruce_fence{east:false,north:false,south:false,waterlogged:false,west:false}"},
        {pos: [4, 2, 14], state: "minecraft:oak_planks"},
        {pos: [5, 2, 4], state: "minecraft:oak_planks"},
        {pos: [5, 2, 6], state: "minecraft:chest{facing:west,type:single,waterlogged:false}", nbt: {Items: [], id: "minecraft:chest"}},
        {pos: [5, 2, 8], state: "minecraft:oak_planks"},
        {pos: [5, 2, 9], state: "minecraft:oak_planks"},
        {pos: [5, 2, 10], state: "minecraft:oak_planks"},
        {pos: [5, 2, 11], state: "minecraft:oak_planks"},
        {pos: [5, 2, 12], state: "minecraft:oak_stairs{facing:north,half:top,shape:outer_right,waterlogged:false}"},
        {pos: [6, 2, 1], state: "minecraft:oak_planks"},
        {pos: [6, 2, 2], state: "minecraft:oak_planks"},
        {pos: [6, 2, 3], state: "minecraft:oak_stairs{facing:east,half:bottom,shape:outer_right,waterlogged:false}"},
        {pos: [6, 2, 4], state: "minecraft:oak_planks"},
        {pos: [6, 2, 5], state: "minecraft:oak_planks"},
        {pos: [6, 2, 6], state: "minecraft:oak_stairs{facing:east,half:bottom,shape:outer_right,waterlogged:false}"},
        {pos: [6, 2, 7], state: "minecraft:oak_planks"},
        {pos: [6, 2, 8], state: "minecraft:oak_planks"},
        {pos: [6, 2, 9], state: "minecraft:oak_stairs{facing:west,half:top,shape:outer_right,waterlogged:false}"},
        {pos: [6, 2, 10], state: "minecraft:oak_stairs{facing:west,half:top,shape:outer_right,waterlogged:false}"},
        {pos: [6, 2, 11], state: "minecraft:oak_stairs{facing:west,half:top,shape:outer_right,waterlogged:false}"},
        {pos: [6, 2, 12], state: "minecraft:oak_stairs{facing:west,half:top,shape:outer_right,waterlogged:false}"},
        {pos: [7, 2, 2], state: "minecraft:oak_stairs{facing:west,half:top,shape:outer_right,waterlogged:false}"},
        {pos: [7, 2, 3], state: "minecraft:oak_stairs{facing:west,half:top,shape:outer_right,waterlogged:false}"},
        {pos: [7, 2, 4], state: "minecraft:oak_stairs{facing:west,half:top,shape:outer_right,waterlogged:false}"},
        {pos: [7, 2, 5], state: "minecraft:oak_stairs{facing:west,half:top,shape:outer_right,waterlogged:false}"},
        {pos: [7, 2, 6], state: "minecraft:oak_stairs{facing:west,half:top,shape:outer_right,waterlogged:false}"},
        {pos: [7, 2, 7], state: "minecraft:oak_stairs{facing:west,half:top,shape:outer_right,waterlogged:false}"},
        {pos: [7, 2, 8], state: "minecraft:oak_stairs{facing:west,half:top,shape:outer_right,waterlogged:false}"},
        {pos: [1, 3, 4], state: "minecraft:oak_planks"},
        {pos: [1, 3, 5], state: "minecraft:oak_planks"},
        {pos: [1, 3, 7], state: "minecraft:oak_planks"},
        {pos: [1, 3, 8], state: "minecraft:oak_planks"},
        {pos: [1, 3, 9], state: "minecraft:oak_stairs{facing:east,half:top,shape:outer_right,waterlogged:false}"},
        {pos: [1, 3, 10], state: "minecraft:oak_stairs{facing:east,half:top,shape:outer_right,waterlogged:false}"},
        {pos: [1, 3, 11], state: "minecraft:oak_stairs{facing:east,half:top,shape:outer_right,waterlogged:false}"},
        {pos: [1, 3, 12], state: "minecraft:oak_stairs{facing:east,half:top,shape:outer_right,waterlogged:false}"},
        {pos: [2, 3, 2], state: "minecraft:oak_planks"},
        {pos: [2, 3, 4], state: "minecraft:oak_planks"},
        {pos: [2, 3, 5], state: "minecraft:oak_planks"},
        {pos: [2, 3, 7], state: "minecraft:oak_planks"},
        {pos: [2, 3, 8], state: "minecraft:oak_planks"},
        {pos: [2, 3, 9], state: "minecraft:spruce_planks"},
        {pos: [2, 3, 10], state: "minecraft:spruce_planks"},
        {pos: [2, 3, 11], state: "minecraft:spruce_planks"},
        {pos: [2, 3, 12], state: "minecraft:spruce_planks"},
        {pos: [2, 3, 13], state: "minecraft:oak_stairs{facing:north,half:top,shape:outer_right,waterlogged:false}"},
        {pos: [3, 3, 4], state: "minecraft:oak_door{facing:east,half:upper,hinge:left,open:false,powered:false}"},
        {pos: [3, 3, 7], state: "minecraft:oak_stairs{facing:south,half:top,shape:outer_right,waterlogged:false}"},
        {pos: [3, 3, 8], state: "minecraft:spruce_planks"},
        {pos: [3, 3, 9], state: "minecraft:spruce_planks"},
        {pos: [3, 3, 10], state: "minecraft:spruce_planks"},
        {pos: [3, 3, 11], state: "minecraft:spruce_planks"},
        {pos: [3, 3, 12], state: "minecraft:spruce_planks"},
        {pos: [3, 3, 13], state: "minecraft:oak_stairs{facing:north,half:top,shape:outer_right,waterlogged:false}"},
        {pos: [4, 3, 4], state: "minecraft:oak_log{axis:y}"},
        {pos: [4, 3, 7], state: "minecraft:oak_stairs{facing:south,half:top,shape:outer_right,waterlogged:false}"},
        {pos: [4, 3, 8], state: "minecraft:spruce_planks"},
        {pos: [4, 3, 9], state: "minecraft:spruce_planks"},
        {pos: [4, 3, 10], state: "minecraft:spruce_planks"},
        {pos: [4, 3, 11], state: "minecraft:spruce_planks"},
        {pos: [4, 3, 12], state: "minecraft:spruce_planks"},
        {pos: [4, 3, 13], state: "minecraft:spruce_fence{east:false,north:false,south:false,waterlogged:false,west:false}"},
        {pos: [5, 3, 4], state: "minecraft:oak_planks"},
        {pos: [5, 3, 6], state: "minecraft:structure_block{mode:data}", nbt: {author: "CascadianBacon", id: "minecraft:structure_block", ignoreEntities: 1b, integrity: 1.0f, metadata: "map_chest", mirror: "NONE", mode: "DATA", name: "", posX: 0, posY: 1, posZ: 0, powered: 0b, rotation: "NONE", seed: 0L, showair: 0b, showboundingbox: 1b, sizeX: 0, sizeY: 0, sizeZ: 0}},
        {pos: [5, 3, 7], state: "minecraft:oak_stairs{facing:south,half:top,shape:outer_right,waterlogged:false}"},
        {pos: [5, 3, 8], state: "minecraft:spruce_planks"},
        {pos: [5, 3, 9], state: "minecraft:spruce_planks"},
        {pos: [5, 3, 10], state: "minecraft:spruce_planks"},
        {pos: [5, 3, 11], state: "minecraft:spruce_planks"},
        {pos: [5, 3, 12], state: "minecraft:spruce_planks"},
        {pos: [5, 3, 13], state: "minecraft:oak_stairs{facing:north,half:top,shape:outer_right,waterlogged:false}"},
        {pos: [6, 3, 4], state: "minecraft:oak_planks"},
        {pos: [6, 3, 5], state: "minecraft:oak_planks"},
        {pos: [6, 3, 7], state: "minecraft:oak_planks"},
        {pos: [6, 3, 8], state: "minecraft:oak_planks"},
        {pos: [6, 3, 9], state: "minecraft:spruce_planks"},
        {pos: [6, 3, 10], state: "minecraft:spruce_planks"},
        {pos: [6, 3, 11], state: "minecraft:spruce_planks"},
        {pos: [6, 3, 12], state: "minecraft:spruce_planks"},
        {pos: [6, 3, 13], state: "minecraft:oak_stairs{facing:north,half:top,shape:outer_right,waterlogged:false}"},
        {pos: [7, 3, 4], state: "minecraft:oak_planks"},
        {pos: [7, 3, 5], state: "minecraft:oak_planks"},
        {pos: [7, 3, 7], state: "minecraft:oak_planks"},
        {pos: [7, 3, 8], state: "minecraft:oak_planks"},
        {pos: [7, 3, 9], state: "minecraft:oak_stairs{facing:west,half:top,shape:outer_right,waterlogged:false}"},
        {pos: [7, 3, 10], state: "minecraft:oak_stairs{facing:west,half:top,shape:outer_right,waterlogged:false}"},
        {pos: [7, 3, 11], state: "minecraft:oak_stairs{facing:west,half:top,shape:outer_right,waterlogged:false}"},
        {pos: [7, 3, 12], state: "minecraft:oak_stairs{facing:west,half:top,shape:outer_right,waterlogged:false}"},
        {pos: [0, 4, 4], state: "minecraft:oak_stairs{facing:east,half:top,shape:outer_right,waterlogged:false}"},
        {pos: [0, 4, 5], state: "minecraft:oak_stairs{facing:east,half:top,shape:outer_right,waterlogged:false}"},
        {pos: [0, 4, 6], state: "minecraft:oak_stairs{facing:east,half:top,shape:outer_right,waterlogged:false}"},
        {pos: [0, 4, 7], state: "minecraft:oak_stairs{facing:east,half:top,shape:outer_right,waterlogged:false}"},
        {pos: [0, 4, 8], state: "minecraft:oak_stairs{facing:east,half:top,shape:outer_right,waterlogged:false}"},
        {pos: [1, 4, 3], state: "minecraft:spruce_planks"},
        {pos: [1, 4, 4], state: "minecraft:spruce_planks"},
        {pos: [1, 4, 5], state: "minecraft:spruce_planks"},
        {pos: [1, 4, 6], state: "minecraft:oak_planks"},
        {pos: [1, 4, 7], state: "minecraft:oak_planks"},
        {pos: [1, 4, 8], state: "minecraft:oak_planks"},
        {pos: [1, 4, 9], state: "minecraft:oak_planks"},
        {pos: [1, 4, 10], state: "minecraft:oak_planks"},
        {pos: [1, 4, 11], state: "minecraft:oak_planks"},
        {pos: [1, 4, 12], state: "minecraft:oak_planks"},
        {pos: [2, 4, 2], state: "minecraft:spruce_planks"},
        {pos: [2, 4, 3], state: "minecraft:spruce_stairs{facing:west,half:top,shape:outer_right,waterlogged:false}"},
        {pos: [2, 4, 4], state: "minecraft:spruce_planks"},
        {pos: [2, 4, 5], state: "minecraft:spruce_planks"},
        {pos: [2, 4, 6], state: "minecraft:spruce_planks"},
        {pos: [2, 4, 7], state: "minecraft:oak_planks"},
        {pos: [2, 4, 8], state: "minecraft:oak_stairs{facing:west,half:bottom,shape:outer_right,waterlogged:false}"},
        {pos: [2, 4, 13], state: "minecraft:oak_planks"},
        {pos: [3, 4, 2], state: "minecraft:oak_trapdoor{facing:east,half:top,open:false,powered:false,waterlogged:false}"},
        {pos: [3, 4, 3], state: "minecraft:oak_trapdoor{facing:north,half:top,open:false,powered:false,waterlogged:false}"},
        {pos: [3, 4, 4], state: "minecraft:spruce_planks"},
        {pos: [3, 4, 5], state: "minecraft:spruce_planks"},
        {pos: [3, 4, 6], state: "minecraft:spruce_planks"},
        {pos: [3, 4, 7], state: "minecraft:oak_planks"},
        {pos: [3, 4, 11], state: "minecraft:oak_stairs{facing:west,half:top,shape:outer_right,waterlogged:false}"},
        {pos: [3, 4, 13], state: "minecraft:oak_planks"},
        {pos: [4, 4, 3], state: "minecraft:oak_trapdoor{facing:north,half:top,open:false,powered:false,waterlogged:false}"},
        {pos: [4, 4, 4], state: "minecraft:oak_log{axis:y}"},
        {pos: [4, 4, 5], state: "minecraft:spruce_planks"},
        {pos: [4, 4, 6], state: "minecraft:spruce_stairs{facing:north,half:bottom,shape:outer_right,waterlogged:false}"},
        {pos: [4, 4, 7], state: "minecraft:spruce_slab{type:bottom,waterlogged:false}"},
        {pos: [4, 4, 11], state: "minecraft:oak_slab{type:bottom,waterlogged:false}"},
        {pos: [4, 4, 13], state: "minecraft:oak_planks"},
        {pos: [4, 4, 14], state: "minecraft:oak_stairs{facing:north,half:top,shape:outer_right,waterlogged:false}"},
        {pos: [5, 4, 5], state: "minecraft:spruce_planks"},
        {pos: [5, 4, 6], state: "minecraft:spruce_planks"},
        {pos: [5, 4, 7], state: "minecraft:oak_planks"},
        {pos: [5, 4, 11], state: "minecraft:oak_stairs{facing:east,half:top,shape:outer_right,waterlogged:false}"},
        {pos: [5, 4, 13], state: "minecraft:oak_planks"},
        {pos: [6, 4, 4], state: "minecraft:spruce_planks"},
        {pos: [6, 4, 5], state: "minecraft:spruce_planks"},
        {pos: [6, 4, 6], state: "minecraft:spruce_planks"},
        {pos: [6, 4, 7], state: "minecraft:oak_planks"},
        {pos: [6, 4, 8], state: "minecraft:oak_stairs{facing:east,half:bottom,shape:outer_right,waterlogged:false}"},
        {pos: [6, 4, 12], state: "minecraft:chest{facing:north,type:single,waterlogged:false}", nbt: {Items: [], id: "minecraft:chest"}},
        {pos: [6, 4, 13], state: "minecraft:oak_planks"},
        {pos: [7, 4, 3], state: "minecraft:spruce_planks"},
        {pos: [7, 4, 4], state: "minecraft:spruce_planks"},
        {pos: [7, 4, 5], state: "minecraft:spruce_planks"},
        {pos: [7, 4, 6], state: "minecraft:oak_planks"},
        {pos: [7, 4, 7], state: "minecraft:oak_planks"},
        {pos: [7, 4, 8], state: "minecraft:oak_planks"},
        {pos: [7, 4, 9], state: "minecraft:oak_planks"},
        {pos: [7, 4, 10], state: "minecraft:oak_planks"},
        {pos: [7, 4, 11], state: "minecraft:oak_planks"},
        {pos: [7, 4, 12], state: "minecraft:oak_planks"},
        {pos: [8, 4, 4], state: "minecraft:oak_stairs{facing:west,half:top,shape:outer_right,waterlogged:false}"},
        {pos: [8, 4, 5], state: "minecraft:oak_stairs{facing:west,half:top,shape:outer_right,waterlogged:false}"},
        {pos: [8, 4, 6], state: "minecraft:oak_stairs{facing:west,half:top,shape:outer_right,waterlogged:false}"},
        {pos: [8, 4, 7], state: "minecraft:oak_stairs{facing:west,half:top,shape:outer_right,waterlogged:false}"},
        {pos: [8, 4, 8], state: "minecraft:oak_stairs{facing:west,half:top,shape:outer_right,waterlogged:false}"},
        {pos: [0, 5, 4], state: "minecraft:spruce_fence{east:false,north:false,south:false,waterlogged:false,west:false}"},
        {pos: [0, 5, 5], state: "minecraft:spruce_fence{east:false,north:false,south:false,waterlogged:false,west:false}"},
        {pos: [0, 5, 6], state: "minecraft:oak_planks"},
        {pos: [0, 5, 7], state: "minecraft:oak_planks"},
        {pos: [0, 5, 8], state: "minecraft:oak_planks"},
        {pos: [0, 5, 9], state: "minecraft:oak_stairs{facing:east,half:top,shape:outer_right,waterlogged:false}"},
        {pos: [0, 5, 10], state: "minecraft:oak_stairs{facing:east,half:top,shape:outer_right,waterlogged:false}"},
        {pos: [0, 5, 11], state: "minecraft:oak_stairs{facing:north,half:top,shape:outer_right,waterlogged:false}"},
        {pos: [1, 5, 6], state: "minecraft:spruce_stairs{facing:south,half:bottom,shape:outer_right,waterlogged:false}"},
        {pos: [1, 5, 7], state: "minecraft:oak_planks"},
        {pos: [1, 5, 8], state: "minecraft:oak_planks"},
        {pos: [1, 5, 9], state: "minecraft:oak_planks"},
        {pos: [1, 5, 10], state: "minecraft:oak_stairs{facing:west,half:bottom,shape:outer_right,waterlogged:false}"},
        {pos: [1, 5, 11], state: "minecraft:oak_planks"},
        {pos: [1, 5, 12], state: "minecraft:oak_planks"},
        {pos: [1, 5, 13], state: "minecraft:oak_stairs{facing:north,half:top,shape:outer_right,waterlogged:false}"},
        {pos: [2, 5, 7], state: "minecraft:oak_planks"},
        {pos: [2, 5, 13], state: "minecraft:oak_planks"},
        {pos: [3, 5, 7], state: "minecraft:oak_planks"},
        {pos: [3, 5, 13], state: "minecraft:oak_stairs{facing:south,half:bottom,shape:outer_right,waterlogged:false}"},
        {pos: [3, 5, 14], state: "minecraft:oak_stairs{facing:north,half:top,shape:outer_right,waterlogged:false}"},
        {pos: [4, 5, 4], state: "minecraft:oak_log{axis:y}"},
        {pos: [4, 5, 13], state: "minecraft:oak_stairs{facing:south,half:bottom,shape:outer_right,waterlogged:false}"},
        {pos: [4, 5, 14], state: "minecraft:oak_planks"},
        {pos: [5, 5, 7], state: "minecraft:oak_planks"},
        {pos: [5, 5, 13], state: "minecraft:oak_stairs{facing:south,half:bottom,shape:outer_right,waterlogged:false}"},
        {pos: [5, 5, 14], state: "minecraft:oak_stairs{facing:north,half:top,shape:outer_right,waterlogged:false}"},
        {pos: [6, 5, 7], state: "minecraft:oak_planks"},
        {pos: [6, 5, 12], state: "minecraft:structure_block{mode:data}", nbt: {author: "CascadianBacon", id: "minecraft:structure_block", ignoreEntities: 1b, integrity: 1.0f, metadata: "treasure_chest", mirror: "NONE", mode: "DATA", name: "", posX: 0, posY: 1, posZ: 0, powered: 0b, rotation: "NONE", seed: 0L, showair: 0b, showboundingbox: 1b, sizeX: 0, sizeY: 0, sizeZ: 0}},
        {pos: [6, 5, 13], state: "minecraft:oak_planks"},
        {pos: [7, 5, 6], state: "minecraft:spruce_stairs{facing:south,half:bottom,shape:outer_right,waterlogged:false}"},
        {pos: [7, 5, 7], state: "minecraft:oak_planks"},
        {pos: [7, 5, 8], state: "minecraft:oak_planks"},
        {pos: [7, 5, 9], state: "minecraft:oak_planks"},
        {pos: [7, 5, 10], state: "minecraft:oak_stairs{facing:east,half:bottom,shape:outer_right,waterlogged:false}"},
        {pos: [7, 5, 11], state: "minecraft:oak_planks"},
        {pos: [7, 5, 12], state: "minecraft:oak_planks"},
        {pos: [7, 5, 13], state: "minecraft:oak_stairs{facing:north,half:top,shape:outer_right,waterlogged:false}"},
        {pos: [8, 5, 4], state: "minecraft:spruce_fence{east:false,north:false,south:false,waterlogged:false,west:false}"},
        {pos: [8, 5, 5], state: "minecraft:spruce_fence{east:false,north:false,south:false,waterlogged:false,west:false}"},
        {pos: [8, 5, 6], state: "minecraft:oak_planks"},
        {pos: [8, 5, 7], state: "minecraft:oak_planks"},
        {pos: [8, 5, 8], state: "minecraft:oak_planks"},
        {pos: [8, 5, 9], state: "minecraft:oak_stairs{facing:west,half:top,shape:outer_right,waterlogged:false}"},
        {pos: [8, 5, 10], state: "minecraft:oak_stairs{facing:west,half:top,shape:outer_right,waterlogged:false}"},
        {pos: [8, 5, 11], state: "minecraft:oak_stairs{facing:north,half:top,shape:outer_right,waterlogged:false}"},
        {pos: [0, 6, 6], state: "minecraft:oak_stairs{facing:south,half:bottom,shape:outer_right,waterlogged:false}"},
        {pos: [0, 6, 7], state: "minecraft:oak_planks"},
        {pos: [0, 6, 8], state: "minecraft:oak_planks"},
        {pos: [0, 6, 9], state: "minecraft:oak_planks"},
        {pos: [0, 6, 11], state: "minecraft:oak_planks"},
        {pos: [1, 6, 7], state: "minecraft:spruce_stairs{facing:south,half:bottom,shape:outer_right,waterlogged:false}"},
        {pos: [1, 6, 8], state: "minecraft:spruce_planks"},
        {pos: [1, 6, 9], state: "minecraft:oak_fence{east:false,north:false,south:false,waterlogged:false,west:false}"},
        {pos: [1, 6, 11], state: "minecraft:oak_fence{east:false,north:false,south:false,waterlogged:false,west:false}"},
        {pos: [1, 6, 12], state: "minecraft:oak_planks"},
        {pos: [1, 6, 13], state: "minecraft:oak_planks"},
        {pos: [2, 6, 7], state: "minecraft:oak_planks"},
        {pos: [2, 6, 8], state: "minecraft:spruce_slab{type:bottom,waterlogged:false}"},
        {pos: [2, 6, 13], state: "minecraft:oak_fence{east:false,north:false,south:false,waterlogged:false,west:false}"},
        {pos: [2, 6, 14], state: "minecraft:oak_stairs{facing:north,half:top,shape:outer_right,waterlogged:false}"},
        {pos: [3, 6, 7], state: "minecraft:oak_planks"},
        {pos: [3, 6, 8], state: "minecraft:spruce_slab{type:bottom,waterlogged:false}"},
        {pos: [3, 6, 9], state: "minecraft:spruce_slab{type:bottom,waterlogged:false}"},
        {pos: [3, 6, 14], state: "minecraft:oak_planks"},
        {pos: [4, 6, 8], state: "minecraft:spruce_slab{type:bottom,waterlogged:false}"},
        {pos: [4, 6, 9], state: "minecraft:spruce_slab{type:bottom,waterlogged:false}"},
        {pos: [5, 6, 7], state: "minecraft:oak_planks"},
        {pos: [5, 6, 8], state: "minecraft:spruce_slab{type:bottom,waterlogged:false}"},
        {pos: [5, 6, 9], state: "minecraft:spruce_slab{type:bottom,waterlogged:false}"},
        {pos: [5, 6, 14], state: "minecraft:oak_planks"},
        {pos: [6, 6, 7], state: "minecraft:oak_planks"},
        {pos: [6, 6, 8], state: "minecraft:spruce_slab{type:bottom,waterlogged:false}"},
        {pos: [6, 6, 13], state: "minecraft:oak_fence{east:false,north:false,south:false,waterlogged:false,west:false}"},
        {pos: [6, 6, 14], state: "minecraft:oak_stairs{facing:north,half:top,shape:outer_right,waterlogged:false}"},
        {pos: [7, 6, 7], state: "minecraft:spruce_stairs{facing:south,half:bottom,shape:outer_right,waterlogged:false}"},
        {pos: [7, 6, 8], state: "minecraft:spruce_planks"},
        {pos: [7, 6, 9], state: "minecraft:oak_fence{east:false,north:false,south:false,waterlogged:false,west:false}"},
        {pos: [7, 6, 11], state: "minecraft:oak_fence{east:false,north:false,south:false,waterlogged:false,west:false}"},
        {pos: [7, 6, 12], state: "minecraft:oak_planks"},
        {pos: [7, 6, 13], state: "minecraft:oak_planks"},
        {pos: [8, 6, 6], state: "minecraft:oak_stairs{facing:south,half:bottom,shape:outer_right,waterlogged:false}"},
        {pos: [8, 6, 7], state: "minecraft:oak_planks"},
        {pos: [8, 6, 8], state: "minecraft:oak_planks"},
        {pos: [8, 6, 9], state: "minecraft:oak_planks"},
        {pos: [8, 6, 11], state: "minecraft:oak_planks"},
        {pos: [0, 7, 8], state: "minecraft:oak_stairs{facing:south,half:bottom,shape:outer_right,waterlogged:false}"},
        {pos: [0, 7, 9], state: "minecraft:oak_planks"},
        {pos: [0, 7, 10], state: "minecraft:oak_planks"},
        {pos: [0, 7, 11], state: "minecraft:oak_planks"},
        {pos: [1, 7, 9], state: "minecraft:oak_planks"},
        {pos: [1, 7, 10], state: "minecraft:spruce_planks"},
        {pos: [1, 7, 11], state: "minecraft:spruce_planks"},
        {pos: [1, 7, 12], state: "minecraft:oak_planks"},
        {pos: [1, 7, 13], state: "minecraft:oak_planks"},
        {pos: [2, 7, 9], state: "minecraft:spruce_stairs{facing:south,half:bottom,shape:outer_right,waterlogged:false}"},
        {pos: [2, 7, 10], state: "minecraft:spruce_slab{type:bottom,waterlogged:false}"},
        {pos: [2, 7, 11], state: "minecraft:spruce_slab{type:bottom,waterlogged:false}"},
        {pos: [2, 7, 12], state: "minecraft:spruce_slab{type:bottom,waterlogged:false}"},
        {pos: [2, 7, 13], state: "minecraft:spruce_planks"},
        {pos: [2, 7, 14], state: "minecraft:oak_planks"},
        {pos: [3, 7, 9], state: "minecraft:oak_planks"},
        {pos: [3, 7, 10], state: "minecraft:spruce_planks"},
        {pos: [3, 7, 11], state: "minecraft:spruce_slab{type:bottom,waterlogged:false}"},
        {pos: [3, 7, 12], state: "minecraft:spruce_slab{type:bottom,waterlogged:false}"},
        {pos: [3, 7, 13], state: "minecraft:spruce_stairs{facing:south,half:top,shape:outer_right,waterlogged:false}"},
        {pos: [3, 7, 14], state: "minecraft:oak_planks"},
        {pos: [3, 7, 15], state: "minecraft:oak_stairs{facing:north,half:top,shape:outer_right,waterlogged:false}"},
        {pos: [4, 7, 7], state: "minecraft:oak_slab{type:bottom,waterlogged:false}"},
        {pos: [4, 7, 8], state: "minecraft:oak_stairs{facing:south,half:bottom,shape:outer_right,waterlogged:false}"},
        {pos: [4, 7, 9], state: "minecraft:oak_planks"},
        {pos: [4, 7, 10], state: "minecraft:spruce_planks"},
        {pos: [4, 7, 11], state: "minecraft:spruce_slab{type:bottom,waterlogged:false}"},
        {pos: [4, 7, 12], state: "minecraft:spruce_slab{type:bottom,waterlogged:false}"},
        {pos: [4, 7, 13], state: "minecraft:spruce_stairs{facing:south,half:top,shape:outer_right,waterlogged:false}"},
        {pos: [4, 7, 14], state: "minecraft:spruce_planks"},
        {pos: [4, 7, 15], state: "minecraft:oak_planks"},
        {pos: [5, 7, 9], state: "minecraft:oak_planks"},
        {pos: [5, 7, 10], state: "minecraft:spruce_planks"},
        {pos: [5, 7, 11], state: "minecraft:spruce_slab{type:bottom,waterlogged:false}"},
        {pos: [5, 7, 12], state: "minecraft:spruce_slab{type:bottom,waterlogged:false}"},
        {pos: [5, 7, 13], state: "minecraft:spruce_stairs{facing:south,half:top,shape:outer_right,waterlogged:false}"},
        {pos: [5, 7, 14], state: "minecraft:oak_planks"},
        {pos: [5, 7, 15], state: "minecraft:oak_stairs{facing:north,half:top,shape:outer_right,waterlogged:false}"},
        {pos: [6, 7, 9], state: "minecraft:spruce_stairs{facing:south,half:bottom,shape:outer_right,waterlogged:false}"},
        {pos: [6, 7, 10], state: "minecraft:spruce_planks"},
        {pos: [6, 7, 11], state: "minecraft:spruce_slab{type:bottom,waterlogged:false}"},
        {pos: [6, 7, 12], state: "minecraft:spruce_slab{type:bottom,waterlogged:false}"},
        {pos: [6, 7, 13], state: "minecraft:spruce_planks"},
        {pos: [6, 7, 14], state: "minecraft:oak_planks"},
        {pos: [7, 7, 9], state: "minecraft:oak_planks"},
        {pos: [7, 7, 10], state: "minecraft:spruce_planks"},
        {pos: [7, 7, 11], state: "minecraft:spruce_planks"},
        {pos: [7, 7, 12], state: "minecraft:oak_planks"},
        {pos: [7, 7, 13], state: "minecraft:oak_planks"},
        {pos: [8, 7, 8], state: "minecraft:oak_stairs{facing:south,half:bottom,shape:outer_right,waterlogged:false}"},
        {pos: [8, 7, 9], state: "minecraft:oak_planks"},
        {pos: [8, 7, 10], state: "minecraft:oak_planks"},
        {pos: [8, 7, 11], state: "minecraft:oak_planks"},
        {pos: [0, 8, 9], state: "minecraft:oak_stairs{facing:east,half:bottom,shape:outer_right,waterlogged:false}"},
        {pos: [0, 8, 10], state: "minecraft:oak_stairs{facing:east,half:bottom,shape:outer_right,waterlogged:false}"},
        {pos: [0, 8, 11], state: "minecraft:oak_stairs{facing:east,half:bottom,shape:outer_right,waterlogged:false}"},
        {pos: [1, 8, 9], state: "minecraft:oak_planks"},
        {pos: [1, 8, 11], state: "minecraft:spruce_fence{east:false,north:false,south:false,waterlogged:false,west:false}"},
        {pos: [1, 8, 12], state: "minecraft:spruce_fence{east:false,north:false,south:false,waterlogged:false,west:false}"},
        {pos: [1, 8, 13], state: "minecraft:oak_planks"},
        {pos: [2, 8, 14], state: "minecraft:oak_planks"},
        {pos: [3, 8, 9], state: "minecraft:oak_planks"},
        {pos: [3, 8, 14], state: "minecraft:spruce_fence{east:false,north:false,south:false,waterlogged:false,west:false}"},
        {pos: [3, 8, 15], state: "minecraft:spruce_fence{east:false,north:false,south:false,waterlogged:false,west:false}"},
        {pos: [4, 8, 9], state: "minecraft:oak_planks"},
        {pos: [4, 8, 15], state: "minecraft:spruce_fence{east:false,north:false,south:false,waterlogged:false,west:false}"},
        {pos: [5, 8, 9], state: "minecraft:oak_planks"},
        {pos: [5, 8, 14], state: "minecraft:spruce_fence{east:false,north:false,south:false,waterlogged:false,west:false}"},
        {pos: [5, 8, 15], state: "minecraft:spruce_fence{east:false,north:false,south:false,waterlogged:false,west:false}"},
        {pos: [6, 8, 14], state: "minecraft:oak_planks"},
        {pos: [7, 8, 9], state: "minecraft:oak_planks"},
        {pos: [7, 8, 11], state: "minecraft:spruce_fence{east:false,north:false,south:false,waterlogged:false,west:false}"},
        {pos: [7, 8, 12], state: "minecraft:spruce_fence{east:false,north:false,south:false,waterlogged:false,west:false}"},
        {pos: [7, 8, 13], state: "minecraft:oak_planks"},
        {pos: [8, 8, 9], state: "minecraft:oak_stairs{facing:west,half:bottom,shape:outer_right,waterlogged:false}"},
        {pos: [8, 8, 10], state: "minecraft:oak_stairs{facing:west,half:bottom,shape:outer_right,waterlogged:false}"},
        {pos: [8, 8, 11], state: "minecraft:oak_stairs{facing:west,half:bottom,shape:outer_right,waterlogged:false}"}
    ],
    entities: [],
    palette: [
        "minecraft:spruce_planks",
        "minecraft:oak_planks",
        "minecraft:oak_log{axis:y}",
        "minecraft:spruce_stairs{facing:north,half:top,shape:outer_right,waterlogged:false}",
        "minecraft:oak_stairs{facing:east,half:top,shape:outer_right,waterlogged:false}",
        "minecraft:oak_stairs{facing:west,half:top,shape:outer_right,waterlogged:false}",
        "minecraft:oak_stairs{facing:west,half:bottom,shape:outer_right,waterlogged:false}",
        "minecraft:oak_door{facing:south,half:lower,hinge:right,open:false,powered:false}",
        "minecraft:oak_stairs{facing:north,half:top,shape:outer_right,waterlogged:false}",
        "minecraft:spruce_fence{east:false,north:false,south:false,waterlogged:false,west:false}",
        "minecraft:oak_stairs{facing:east,half:bottom,shape:outer_right,waterlogged:false}",
        "minecraft:oak_door{facing:east,half:upper,hinge:left,open:false,powered:false}",
        "minecraft:oak_stairs{facing:south,half:top,shape:outer_right,waterlogged:false}",
        "minecraft:spruce_stairs{facing:west,half:top,shape:outer_right,waterlogged:false}",
        "minecraft:oak_trapdoor{facing:east,half:top,open:false,powered:false,waterlogged:false}",
        "minecraft:oak_trapdoor{facing:north,half:top,open:false,powered:false,waterlogged:false}",
        "minecraft:spruce_stairs{facing:north,half:bottom,shape:outer_right,waterlogged:false}",
        "minecraft:spruce_slab{type:bottom,waterlogged:false}",
        "minecraft:oak_slab{type:bottom,waterlogged:false}",
        "minecraft:spruce_stairs{facing:south,half:bottom,shape:outer_right,waterlogged:false}",
        "minecraft:oak_stairs{facing:south,half:bottom,shape:outer_right,waterlogged:false}",
        "minecraft:oak_fence{east:false,north:false,south:false,waterlogged:false,west:false}",
        "minecraft:spruce_stairs{facing:south,half:top,shape:outer_right,waterlogged:false}",
        "minecraft:chest{facing:west,type:single,waterlogged:false}",
        "minecraft:structure_block{mode:data}",
        "minecraft:chest{facing:north,type:single,waterlogged:false}"
    ],
    palettes: [
        {
            "minecraft:chest{facing:north,type:single,waterlogged:false}": "minecraft:chest{facing:north,type:single,waterlogged:false}",
            "minecraft:chest{facing:west,type:single,waterlogged:false}": "minecraft:chest{facing:west,type:single,waterlogged:false}",
            "minecraft:oak_door{facing:east,half:upper,hinge:left,open:false,powered:false}": "minecraft:oak_door{facing:east,half:upper,hinge:left,open:false,powered:false}",
            "minecraft:oak_door{facing:south,half:lower,hinge:right,open:false,powered:false}": "minecraft:oak_door{facing:south,half:lower,hinge:right,open:false,powered:false}",
            "minecraft:oak_fence{east:false,north:false,south:false,waterlogged:false,west:false}": "minecraft:oak_fence{east:false,north:false,south:false,waterlogged:false,west:false}",
            "minecraft:oak_log{axis:y}": "minecraft:oak_log{axis:y}",
            "minecraft:oak_planks": "minecraft:oak_planks",
            "minecraft:oak_slab{type:bottom,waterlogged:false}": "minecraft:oak_slab{type:bottom,waterlogged:false}",
            "minecraft:oak_stairs{facing:east,half:bottom,shape:outer_right,waterlogged:false}": "minecraft:oak_stairs{facing:east,half:bottom,shape:outer_right,waterlogged:false}",
            "minecraft:oak_stairs{facing:east,half:top,shape:outer_right,waterlogged:false}": "minecraft:oak_stairs{facing:east,half:top,shape:outer_right,waterlogged:false}",
            "minecraft:oak_stairs{facing:north,half:top,shape:outer_right,waterlogged:false}": "minecraft:oak_stairs{facing:north,half:top,shape:outer_right,waterlogged:false}",
            "minecraft:oak_stairs{facing:south,half:bottom,shape:outer_right,waterlogged:false}": "minecraft:oak_stairs{facing:south,half:bottom,shape:outer_right,waterlogged:false}",
            "minecraft:oak_stairs{facing:south,half:top,shape:outer_right,waterlogged:false}": "minecraft:oak_stairs{facing:south,half:top,shape:outer_right,waterlogged:false}",
            "minecraft:oak_stairs{facing:west,half:bottom,shape:outer_right,waterlogged:false}": "minecraft:oak_stairs{facing:west,half:bottom,shape:outer_right,waterlogged:false}",
            "minecraft:oak_stairs{facing:west,half:top,shape:outer_right,waterlogged:false}": "minecraft:oak_stairs{facing:west,half:top,shape:outer_right,waterlogged:false}",
            "minecraft:oak_trapdoor{facing:east,half:top,open:false,powered:false,waterlogged:false}": "minecraft:oak_trapdoor{facing:east,half:top,open:false,powered:false,waterlogged:false}",
            "minecraft:oak_trapdoor{facing:north,half:top,open:false,powered:false,waterlogged:false}": "minecraft:oak_trapdoor{facing:north,half:top,open:false,powered:false,waterlogged:false}",
            "minecraft:spruce_fence{east:false,north:false,south:false,waterlogged:false,west:false}": "minecraft:spruce_fence{east:false,north:false,south:false,waterlogged:false,west:false}",
            "minecraft:spruce_planks": "minecraft:spruce_planks",
            "minecraft:spruce_slab{type:bottom,waterlogged:false}": "minecraft:spruce_slab{type:bottom,waterlogged:false}",
            "minecraft:spruce_stairs{facing:north,half:bottom,shape:outer_right,waterlogged:false}": "minecraft:spruce_stairs{facing:north,half:bottom,shape:outer_right,waterlogged:false}",
            "minecraft:spruce_stairs{facing:north,half:top,shape:outer_right,waterlogged:false}": "minecraft:spruce_stairs{facing:north,half:top,shape:outer_right,waterlogged:false}",
            "minecraft:spruce_stairs{facing:south,half:bottom,shape:outer_right,waterlogged:false}": "minecraft:spruce_stairs{facing:south,half:bottom,shape:outer_right,waterlogged:false}",
            "minecraft:spruce_stairs{facing:south,half:top,shape:outer_right,waterlogged:false}": "minecraft:spruce_stairs{facing:south,half:top,shape:outer_right,waterlogged:false}",
            "minecraft:spruce_stairs{facing:west,half:top,shape:outer_right,waterlogged:false}": "minecraft:spruce_stairs{facing:west,half:top,shape:outer_right,waterlogged:false}",
            "minecraft:structure_block{mode:data}": "minecraft:structure_block{mode:data}"
        },
        {
            "minecraft:chest{facing:north,type:single,waterlogged:false}": "minecraft:chest{facing:north,type:single,waterlogged:false}",
            "minecraft:chest{facing:west,type:single,waterlogged:false}": "minecraft:chest{facing:west,type:single,waterlogged:false}",
            "minecraft:oak_door{facing:east,half:upper,hinge:left,open:false,powered:false}": "minecraft:jungle_door{facing:east,half:upper,hinge:left,open:false,powered:false}",
            "minecraft:oak_door{facing:south,half:lower,hinge:right,open:false,powered:false}": "minecraft:jungle_door{facing:south,half:lower,hinge:right,open:false,powered:false}",
            "minecraft:oak_fence{east:false,north:false,south:false,waterlogged:false,west:false}": "minecraft:jungle_fence{east:false,north:false,south:false,waterlogged:false,west:false}",
            "minecraft:oak_log{axis:y}": "minecraft:jungle_log{axis:y}",
            "minecraft:oak_planks": "minecraft:jungle_planks",
            "minecraft:oak_slab{type:bottom,waterlogged:false}": "minecraft:jungle_slab{type:bottom,waterlogged:false}",
            "minecraft:oak_stairs{facing:east,half:bottom,shape:outer_right,waterlogged:false}": "minecraft:jungle_stairs{facing:east,half:bottom,shape:outer_right,waterlogged:false}",
            "minecraft:oak_stairs{facing:east,half:top,shape:outer_right,waterlogged:false}": "minecraft:jungle_stairs{facing:east,half:top,shape:outer_right,waterlogged:false}",
            "minecraft:oak_stairs{facing:north,half:top,shape:outer_right,waterlogged:false}": "minecraft:jungle_stairs{facing:north,half:top,shape:outer_right,waterlogged:false}",
            "minecraft:oak_stairs{facing:south,half:bottom,shape:outer_right,waterlogged:false}": "minecraft:jungle_stairs{facing:south,half:bottom,shape:outer_right,waterlogged:false}",
            "minecraft:oak_stairs{facing:south,half:top,shape:outer_right,waterlogged:false}": "minecraft:jungle_stairs{facing:south,half:top,shape:outer_right,waterlogged:false}",
            "minecraft:oak_stairs{facing:west,half:bottom,shape:outer_right,waterlogged:false}": "minecraft:jungle_stairs{facing:west,half:bottom,shape:outer_right,waterlogged:false}",
            "minecraft:oak_stairs{facing:west,half:top,shape:outer_right,waterlogged:false}": "minecraft:jungle_stairs{facing:west,half:top,shape:outer_right,waterlogged:false}",
            "minecraft:oak_trapdoor{facing:east,half:top,open:false,powered:false,waterlogged:false}": "minecraft:jungle_trapdoor{facing:east,half:top,open:false,powered:false,waterlogged:false}",
            "minecraft:oak_trapdoor{facing:north,half:top,open:false,powered:false,waterlogged:false}": "minecraft:jungle_trapdoor{facing:north,half:top,open:false,powered:false,waterlogged:false}",
            "minecraft:spruce_fence{east:false,north:false,south:false,waterlogged:false,west:false}": "minecraft:spruce_fence{east:false,north:false,south:false,waterlogged:false,west:false}",
            "minecraft:spruce_planks": "minecraft:spruce_planks",
            "minecraft:spruce_slab{type:bottom,waterlogged:false}": "minecraft:spruce_slab{type:bottom,waterlogged:false}",
            "minecraft:spruce_stairs{facing:north,half:bottom,shape:outer_right,waterlogged:false}": "minecraft:spruce_stairs{facing:north,half:bottom,shape:outer_right,waterlogged:false}",
            "minecraft:spruce_stairs{facing:north,half:top,shape:outer_right,waterlogged:false}": "minecraft:spruce_stairs{facing:north,half:top,shape:outer_right,waterlogged:false}",
            "minecraft:spruce_stairs{facing:south,half:bottom,shape:outer_right,waterlogged:false}": "minecraft:spruce_stairs{facing:south,half:bottom,shape:outer_right,waterlogged:false}",
            "minecraft:spruce_stairs{facing:south,half:top,shape:outer_right,waterlogged:false}": "minecraft:spruce_stairs{facing:south,half:top,shape:outer_right,waterlogged:false}",
            "minecraft:spruce_stairs{facing:west,half:top,shape:outer_right,waterlogged:false}": "minecraft:spruce_stairs{facing:west,half:top,shape:outer_right,waterlogged:false}",
            "minecraft:structure_block{mode:data}": "minecraft:structure_block{mode:data}"
        },
        {
            "minecraft:chest{facing:north,type:single,waterlogged:false}": "minecraft:chest{facing:north,type:single,waterlogged:false}",
            "minecraft:chest{facing:west,type:single,waterlogged:false}": "minecraft:chest{facing:west,type:single,waterlogged:false}",
            "minecraft:oak_door{facing:east,half:upper,hinge:left,open:false,powered:false}": "minecraft:dark_oak_door{facing:east,half:upper,hinge:left,open:false,powered:false}",
            "minecraft:oak_door{facing:south,half:lower,hinge:right,open:false,powered:false}": "minecraft:dark_oak_door{facing:south,half:lower,hinge:right,open:false,powered:false}",
            "minecraft:oak_fence{east:false,north:false,south:false,waterlogged:false,west:false}": "minecraft:dark_oak_fence{east:false,north:false,south:false,waterlogged:false,west:false}",
            "minecraft:oak_log{axis:y}": "minecraft:dark_oak_log{axis:y}",
            "minecraft:oak_planks": "minecraft:dark_oak_planks",
            "minecraft:oak_slab{type:bottom,waterlogged:false}": "minecraft:dark_oak_slab{type:bottom,waterlogged:false}",
            "minecraft:oak_stairs{facing:east,half:bottom,shape:outer_right,waterlogged:false}": "minecraft:dark_oak_stairs{facing:east,half:bottom,shape:outer_right,waterlogged:false}",
            "minecraft:oak_stairs{facing:east,half:top,shape:outer_right,waterlogged:false}": "minecraft:dark_oak_stairs{facing:east,half:top,shape:outer_right,waterlogged:false}",
            "minecraft:oak_stairs{facing:north,half:top,shape:outer_right,waterlogged:false}": "minecraft:dark_oak_stairs{facing:north,half:top,shape:outer_right,waterlogged:false}",
            "minecraft:oak_stairs{facing:south,half:bottom,shape:outer_right,waterlogged:false}": "minecraft:dark_oak_stairs{facing:south,half:bottom,shape:outer_right,waterlogged:false}",
            "minecraft:oak_stairs{facing:south,half:top,shape:outer_right,waterlogged:false}": "minecraft:dark_oak_stairs{facing:south,half:top,shape:outer_right,waterlogged:false}",
            "minecraft:oak_stairs{facing:west,half:bottom,shape:outer_right,waterlogged:false}": "minecraft:dark_oak_stairs{facing:west,half:bottom,shape:outer_right,waterlogged:false}",
            "minecraft:oak_stairs{facing:west,half:top,shape:outer_right,waterlogged:false}": "minecraft:dark_oak_stairs{facing:west,half:top,shape:outer_right,waterlogged:false}",
            "minecraft:oak_trapdoor{facing:east,half:top,open:false,powered:false,waterlogged:false}": "minecraft:dark_oak_trapdoor{facing:east,half:top,open:false,powered:false,waterlogged:false}",
            "minecraft:oak_trapdoor{facing:north,half:top,open:false,powered:false,waterlogged:false}": "minecraft:dark_oak_trapdoor{facing:north,half:top,open:false,powered:false,waterlogged:false}",
            "minecraft:spruce_fence{east:false,north:false,south:false,waterlogged:false,west:false}": "minecraft:jungle_fence{east:false,north:false,south:false,waterlogged:false,west:false}",
            "minecraft:spruce_planks": "minecraft:jungle_planks",
            "minecraft:spruce_slab{type:bottom,waterlogged:false}": "minecraft:jungle_slab{type:bottom,waterlogged:false}",
            "minecraft:spruce_stairs{facing:north,half:bottom,shape:outer_right,waterlogged:false}": "minecraft:jungle_stairs{facing:north,half:bottom,shape:outer_right,waterlogged:false}",
            "minecraft:spruce_stairs{facing:north,half:top,shape:outer_right,waterlogged:false}": "minecraft:jungle_stairs{facing:north,half:top,shape:outer_right,waterlogged:false}",
            "minecraft:spruce_stairs{facing:south,half:bottom,shape:outer_right,waterlogged:false}": "minecraft:jungle_stairs{facing:south,half:bottom,shape:outer_right,waterlogged:false}",
            "minecraft:spruce_stairs{facing:south,half:top,shape:outer_right,waterlogged:false}": "minecraft:jungle_stairs{facing:south,half:top,shape:outer_right,waterlogged:false}",
            "minecraft:spruce_stairs{facing:west,half:top,shape:outer_right,waterlogged:false}": "minecraft:jungle_stairs{facing:west,half:top,shape:outer_right,waterlogged:false}",
            "minecraft:structure_block{mode:data}": "minecraft:structure_block{mode:data}"
        },
        {
            "minecraft:chest{facing:north,type:single,waterlogged:false}": "minecraft:chest{facing:north,type:single,waterlogged:false}",
            "minecraft:chest{facing:west,type:single,waterlogged:false}": "minecraft:chest{facing:west,type:single,waterlogged:false}",
            "minecraft:oak_door{facing:east,half:upper,hinge:left,open:false,powered:false}": "minecraft:dark_oak_door{facing:east,half:upper,hinge:left,open:false,powered:false}",
            "minecraft:oak_door{facing:south,half:lower,hinge:right,open:false,powered:false}": "minecraft:dark_oak_door{facing:south,half:lower,hinge:right,open:false,powered:false}",
            "minecraft:oak_fence{east:false,north:false,south:false,waterlogged:false,west:false}": "minecraft:dark_oak_fence{east:false,north:false,south:false,waterlogged:false,west:false}",
            "minecraft:oak_log{axis:y}": "minecraft:dark_oak_log{axis:y}",
            "minecraft:oak_planks": "minecraft:dark_oak_planks",
            "minecraft:oak_slab{type:bottom,waterlogged:false}": "minecraft:dark_oak_slab{type:bottom,waterlogged:false}",
            "minecraft:oak_stairs{facing:east,half:bottom,shape:outer_right,waterlogged:false}": "minecraft:dark_oak_stairs{facing:east,half:bottom,shape:outer_right,waterlogged:false}",
            "minecraft:oak_stairs{facing:east,half:top,shape:outer_right,waterlogged:false}": "minecraft:dark_oak_stairs{facing:east,half:top,shape:outer_right,waterlogged:false}",
            "minecraft:oak_stairs{facing:north,half:top,shape:outer_right,waterlogged:false}": "minecraft:dark_oak_stairs{facing:north,half:top,shape:outer_right,waterlogged:false}",
            "minecraft:oak_stairs{facing:south,half:bottom,shape:outer_right,waterlogged:false}": "minecraft:dark_oak_stairs{facing:south,half:bottom,shape:outer_right,waterlogged:false}",
            "minecraft:oak_stairs{facing:south,half:top,shape:outer_right,waterlogged:false}": "minecraft:dark_oak_stairs{facing:south,half:top,shape:outer_right,waterlogged:false}",
            "minecraft:oak_stairs{facing:west,half:bottom,shape:outer_right,waterlogged:false}": "minecraft:dark_oak_stairs{facing:west,half:bottom,shape:outer_right,waterlogged:false}",
            "minecraft:oak_stairs{facing:west,half:top,shape:outer_right,waterlogged:false}": "minecraft:dark_oak_stairs{facing:west,half:top,shape:outer_right,waterlogged:false}",
            "minecraft:oak_trapdoor{facing:east,half:top,open:false,powered:false,waterlogged:false}": "minecraft:dark_oak_trapdoor{facing:east,half:top,open:false,powered:false,waterlogged:false}",
            "minecraft:oak_trapdoor{facing:north,half:top,open:false,powered:false,waterlogged:false}": "minecraft:dark_oak_trapdoor{facing:north,half:top,open:false,powered:false,waterlogged:false}",
            "minecraft:spruce_fence{east:false,north:false,south:false,waterlogged:false,west:false}": "minecraft:spruce_fence{east:false,north:false,south:false,waterlogged:false,west:false}",
            "minecraft:spruce_planks": "minecraft:spruce_planks",
            "minecraft:spruce_slab{type:bottom,waterlogged:false}": "minecraft:spruce_slab{type:bottom,waterlogged:false}",
            "minecraft:spruce_stairs{facing:north,half:bottom,shape:outer_right,waterlogged:false}": "minecraft:spruce_stairs{facing:north,half:bottom,shape:outer_right,waterlogged:false}",
            "minecraft:spruce_stairs{facing:north,half:top,shape:outer_right,waterlogged:false}": "minecraft:spruce_stairs{facing:north,half:top,shape:outer_right,waterlogged:false}",
            "minecraft:spruce_stairs{facing:south,half:bottom,shape:outer_right,waterlogged:false}": "minecraft:spruce_stairs{facing:south,half:bottom,shape:outer_right,waterlogged:false}",
            "minecraft:spruce_stairs{facing:south,half:top,shape:outer_right,waterlogged:false}": "minecraft:spruce_stairs{facing:south,half:top,shape:outer_right,waterlogged:false}",
            "minecraft:spruce_stairs{facing:west,half:top,shape:outer_right,waterlogged:false}": "minecraft:spruce_stairs{facing:west,half:top,shape:outer_right,waterlogged:false}",
            "minecraft:structure_block{mode:data}": "minecraft:structure_block{mode:data}"
        },
        {
            "minecraft:chest{facing:north,type:single,waterlogged:false}": "minecraft:chest{facing:north,type:single,waterlogged:false}",
            "minecraft:chest{facing:west,type:single,waterlogged:false}": "minecraft:chest{facing:west,type:single,waterlogged:false}",
            "minecraft:oak_door{facing:east,half:upper,hinge:left,open:false,powered:false}": "minecraft:spruce_door{facing:east,half:upper,hinge:left,open:false,powered:false}",
            "minecraft:oak_door{facing:south,half:lower,hinge:right,open:false,powered:false}": "minecraft:spruce_door{facing:south,half:lower,hinge:right,open:false,powered:false}",
            "minecraft:oak_fence{east:false,north:false,south:false,waterlogged:false,west:false}": "minecraft:spruce_fence{east:false,north:false,south:false,waterlogged:false,west:false}",
            "minecraft:oak_log{axis:y}": "minecraft:spruce_log{axis:y}",
            "minecraft:oak_planks": "minecraft:spruce_planks",
            "minecraft:oak_slab{type:bottom,waterlogged:false}": "minecraft:spruce_slab{type:bottom,waterlogged:false}",
            "minecraft:oak_stairs{facing:east,half:bottom,shape:outer_right,waterlogged:false}": "minecraft:spruce_stairs{facing:east,half:bottom,shape:outer_right,waterlogged:false}",
            "minecraft:oak_stairs{facing:east,half:top,shape:outer_right,waterlogged:false}": "minecraft:spruce_stairs{facing:east,half:top,shape:outer_right,waterlogged:false}",
            "minecraft:oak_stairs{facing:north,half:top,shape:outer_right,waterlogged:false}": "minecraft:spruce_stairs{facing:north,half:top,shape:outer_right,waterlogged:false}",
            "minecraft:oak_stairs{facing:south,half:bottom,shape:outer_right,waterlogged:false}": "minecraft:spruce_stairs{facing:south,half:bottom,shape:outer_right,waterlogged:false}",
            "minecraft:oak_stairs{facing:south,half:top,shape:outer_right,waterlogged:false}": "minecraft:spruce_stairs{facing:south,half:top,shape:outer_right,waterlogged:false}",
            "minecraft:oak_stairs{facing:west,half:bottom,shape:outer_right,waterlogged:false}": "minecraft:spruce_stairs{facing:west,half:bottom,shape:outer_right,waterlogged:false}",
            "minecraft:oak_stairs{facing:west,half:top,shape:outer_right,waterlogged:false}": "minecraft:spruce_stairs{facing:west,half:top,shape:outer_right,waterlogged:false}",
            "minecraft:oak_trapdoor{facing:east,half:top,open:false,powered:false,waterlogged:false}": "minecraft:spruce_trapdoor{facing:east,half:top,open:false,powered:false,waterlogged:false}",
            "minecraft:oak_trapdoor{facing:north,half:top,open:false,powered:false,waterlogged:false}": "minecraft:spruce_trapdoor{facing:north,half:top,open:false,powered:false,waterlogged:false}",
            "minecraft:spruce_fence{east:false,north:false,south:false,waterlogged:false,west:false}": "minecraft:oak_fence{east:false,north:false,south:false,waterlogged:false,west:false}",
            "minecraft:spruce_planks": "minecraft:oak_planks",
            "minecraft:spruce_slab{type:bottom,waterlogged:false}": "minecraft:oak_slab{type:bottom,waterlogged:false}",
            "minecraft:spruce_stairs{facing:north,half:bottom,shape:outer_right,waterlogged:false}": "minecraft:oak_stairs{facing:north,half:bottom,shape:outer_right,waterlogged:false}",
            "minecraft:spruce_stairs{facing:north,half:top,shape:outer_right,waterlogged:false}": "minecraft:oak_stairs{facing:north,half:top,shape:outer_right,waterlogged:false}",
            "minecraft:spruce_stairs{facing:south,half:bottom,shape:outer_right,waterlogged:false}": "minecraft:oak_stairs{facing:south,half:bottom,shape:outer_right,waterlogged:false}",
            "minecraft:spruce_stairs{facing:south,half:top,shape:outer_right,waterlogged:false}": "minecraft:oak_stairs{facing:south,half:top,shape:outer_right,waterlogged:false}",
            "minecraft:spruce_stairs{facing:west,half:top,shape:outer_right,waterlogged:false}": "minecraft:oak_stairs{facing:west,half:top,shape:outer_right,waterlogged:false}",
            "minecraft:structure_block{mode:data}": "minecraft:structure_block{mode:data}"
        },
        {
            "minecraft:chest{facing:north,type:single,waterlogged:false}": "minecraft:chest{facing:north,type:single,waterlogged:false}",
            "minecraft:chest{facing:west,type:single,waterlogged:false}": "minecraft:chest{facing:west,type:single,waterlogged:false}",
            "minecraft:oak_door{facing:east,half:upper,hinge:left,open:false,powered:false}": "minecraft:spruce_door{facing:east,half:upper,hinge:left,open:false,powered:false}",
            "minecraft:oak_door{facing:south,half:lower,hinge:right,open:false,powered:false}": "minecraft:spruce_door{facing:south,half:lower,hinge:right,open:false,powered:false}",
            "minecraft:oak_fence{east:false,north:false,south:false,waterlogged:false,west:false}": "minecraft:spruce_fence{east:false,north:false,south:false,waterlogged:false,west:false}",
            "minecraft:oak_log{axis:y}": "minecraft:spruce_log{axis:y}",
            "minecraft:oak_planks": "minecraft:spruce_planks",
            "minecraft:oak_slab{type:bottom,waterlogged:false}": "minecraft:spruce_slab{type:bottom,waterlogged:false}",
            "minecraft:oak_stairs{facing:east,half:bottom,shape:outer_right,waterlogged:false}": "minecraft:spruce_stairs{facing:east,half:bottom,shape:outer_right,waterlogged:false}",
            "minecraft:oak_stairs{facing:east,half:top,shape:outer_right,waterlogged:false}": "minecraft:spruce_stairs{facing:east,half:top,shape:outer_right,waterlogged:false}",
            "minecraft:oak_stairs{facing:north,half:top,shape:outer_right,waterlogged:false}": "minecraft:spruce_stairs{facing:north,half:top,shape:outer_right,waterlogged:false}",
            "minecraft:oak_stairs{facing:south,half:bottom,shape:outer_right,waterlogged:false}": "minecraft:spruce_stairs{facing:south,half:bottom,shape:outer_right,waterlogged:false}",
            "minecraft:oak_stairs{facing:south,half:top,shape:outer_right,waterlogged:false}": "minecraft:spruce_stairs{facing:south,half:top,shape:outer_right,waterlogged:false}",
            "minecraft:oak_stairs{facing:west,half:bottom,shape:outer_right,waterlogged:false}": "minecraft:spruce_stairs{facing:west,half:bottom,shape:outer_right,waterlogged:false}",
            "minecraft:oak_stairs{facing:west,half:top,shape:outer_right,waterlogged:false}": "minecraft:spruce_stairs{facing:west,half:top,shape:outer_right,waterlogged:false}",
            "minecraft:oak_trapdoor{facing:east,half:top,open:false,powered:false,waterlogged:false}": "minecraft:spruce_trapdoor{facing:east,half:top,open:false,powered:false,waterlogged:false}",
            "minecraft:oak_trapdoor{facing:north,half:top,open:false,powered:false,waterlogged:false}": "minecraft:spruce_trapdoor{facing:north,half:top,open:false,powered:false,waterlogged:false}",
            "minecraft:spruce_fence{east:false,north:false,south:false,waterlogged:false,west:false}": "minecraft:jungle_fence{east:false,north:false,south:false,waterlogged:false,west:false}",
            "minecraft:spruce_planks": "minecraft:jungle_planks",
            "minecraft:spruce_slab{type:bottom,waterlogged:false}": "minecraft:jungle_slab{type:bottom,waterlogged:false}",
            "minecraft:spruce_stairs{facing:north,half:bottom,shape:outer_right,waterlogged:false}": "minecraft:jungle_stairs{facing:north,half:bottom,shape:outer_right,waterlogged:false}",
            "minecraft:spruce_stairs{facing:north,half:top,shape:outer_right,waterlogged:false}": "minecraft:jungle_stairs{facing:north,half:top,shape:outer_right,waterlogged:false}",
            "minecraft:spruce_stairs{facing:south,half:bottom,shape:outer_right,waterlogged:false}": "minecraft:jungle_stairs{facing:south,half:bottom,shape:outer_right,waterlogged:false}",
            "minecraft:spruce_stairs{facing:south,half:top,shape:outer_right,waterlogged:false}": "minecraft:jungle_stairs{facing:south,half:top,shape:outer_right,waterlogged:false}",
            "minecraft:spruce_stairs{facing:west,half:top,shape:outer_right,waterlogged:false}": "minecraft:jungle_stairs{facing:west,half:top,shape:outer_right,waterlogged:false}",
            "minecraft:structure_block{mode:data}": "minecraft:structure_block{mode:data}"
        },
        {
            "minecraft:chest{facing:north,type:single,waterlogged:false}": "minecraft:chest{facing:north,type:single,waterlogged:false}",
            "minecraft:chest{facing:west,type:single,waterlogged:false}": "minecraft:chest{facing:west,type:single,waterlogged:false}",
            "minecraft:oak_door{facing:east,half:upper,hinge:left,open:false,powered:false}": "minecraft:spruce_door{facing:east,half:upper,hinge:left,open:false,powered:false}",
            "minecraft:oak_door{facing:south,half:lower,hinge:right,open:false,powered:false}": "minecraft:spruce_door{facing:south,half:lower,hinge:right,open:false,powered:false}",
            "minecraft:oak_fence{east:false,north:false,south:false,waterlogged:false,west:false}": "minecraft:spruce_fence{east:false,north:false,south:false,waterlogged:false,west:false}",
            "minecraft:oak_log{axis:y}": "minecraft:spruce_log{axis:y}",
            "minecraft:oak_planks": "minecraft:spruce_planks",
            "minecraft:oak_slab{type:bottom,waterlogged:false}": "minecraft:spruce_slab{type:bottom,waterlogged:false}",
            "minecraft:oak_stairs{facing:east,half:bottom,shape:outer_right,waterlogged:false}": "minecraft:spruce_stairs{facing:east,half:bottom,shape:outer_right,waterlogged:false}",
            "minecraft:oak_stairs{facing:east,half:top,shape:outer_right,waterlogged:false}": "minecraft:spruce_stairs{facing:east,half:top,shape:outer_right,waterlogged:false}",
            "minecraft:oak_stairs{facing:north,half:top,shape:outer_right,waterlogged:false}": "minecraft:spruce_stairs{facing:north,half:top,shape:outer_right,waterlogged:false}",
            "minecraft:oak_stairs{facing:south,half:bottom,shape:outer_right,waterlogged:false}": "minecraft:spruce_stairs{facing:south,half:bottom,shape:outer_right,waterlogged:false}",
            "minecraft:oak_stairs{facing:south,half:top,shape:outer_right,waterlogged:false}": "minecraft:spruce_stairs{facing:south,half:top,shape:outer_right,waterlogged:false}",
            "minecraft:oak_stairs{facing:west,half:bottom,shape:outer_right,waterlogged:false}": "minecraft:spruce_stairs{facing:west,half:bottom,shape:outer_right,waterlogged:false}",
            "minecraft:oak_stairs{facing:west,half:top,shape:outer_right,waterlogged:false}": "minecraft:spruce_stairs{facing:west,half:top,shape:outer_right,waterlogged:false}",
            "minecraft:oak_trapdoor{facing:east,half:top,open:false,powered:false,waterlogged:false}": "minecraft:spruce_trapdoor{facing:east,half:top,open:false,powered:false,waterlogged:false}",
            "minecraft:oak_trapdoor{facing:north,half:top,open:false,powered:false,waterlogged:false}": "minecraft:spruce_trapdoor{facing:north,half:top,open:false,powered:false,waterlogged:false}",
            "minecraft:spruce_fence{east:false,north:false,south:false,waterlogged:false,west:false}": "minecraft:dark_oak_fence{east:false,north:false,south:false,waterlogged:false,west:false}",
            "minecraft:spruce_planks": "minecraft:dark_oak_planks",
            "minecraft:spruce_slab{type:bottom,waterlogged:false}": "minecraft:dark_oak_slab{type:bottom,waterlogged:false}",
            "minecraft:spruce_stairs{facing:north,half:bottom,shape:outer_right,waterlogged:false}": "minecraft:dark_oak_stairs{facing:north,half:bottom,shape:outer_right,waterlogged:false}",
            "minecraft:spruce_stairs{facing:north,half:top,shape:outer_right,waterlogged:false}": "minecraft:dark_oak_stairs{facing:north,half:top,shape:outer_right,waterlogged:false}",
            "minecraft:spruce_stairs{facing:south,half:bottom,shape:outer_right,waterlogged:false}": "minecraft:dark_oak_stairs{facing:south,half:bottom,shape:outer_right,waterlogged:false}",
            "minecraft:spruce_stairs{facing:south,half:top,shape:outer_right,waterlogged:false}": "minecraft:dark_oak_stairs{facing:south,half:top,shape:outer_right,waterlogged:false}",
            "minecraft:spruce_stairs{facing:west,half:top,shape:outer_right,waterlogged:false}": "minecraft:dark_oak_stairs{facing:west,half:top,shape:outer_right,waterlogged:false}",
            "minecraft:structure_block{mode:data}": "minecraft:structure_block{mode:data}"
        },
        {
            "minecraft:chest{facing:north,type:single,waterlogged:false}": "minecraft:chest{facing:north,type:single,waterlogged:false}",
            "minecraft:chest{facing:west,type:single,waterlogged:false}": "minecraft:chest{facing:west,type:single,waterlogged:false}",
            "minecraft:oak_door{facing:east,half:upper,hinge:left,open:false,powered:false}": "minecraft:oak_door{facing:east,half:upper,hinge:left,open:false,powered:false}",
            "minecraft:oak_door{facing:south,half:lower,hinge:right,open:false,powered:false}": "minecraft:oak_door{facing:south,half:lower,hinge:right,open:false,powered:false}",
            "minecraft:oak_fence{east:false,north:false,south:false,waterlogged:false,west:false}": "minecraft:oak_fence{east:false,north:false,south:false,waterlogged:false,west:false}",
            "minecraft:oak_log{axis:y}": "minecraft:oak_log{axis:y}",
            "minecraft:oak_planks": "minecraft:oak_planks",
            "minecraft:oak_slab{type:bottom,waterlogged:false}": "minecraft:oak_slab{type:bottom,waterlogged:false}",
            "minecraft:oak_stairs{facing:east,half:bottom,shape:outer_right,waterlogged:false}": "minecraft:oak_stairs{facing:east,half:bottom,shape:outer_right,waterlogged:false}",
            "minecraft:oak_stairs{facing:east,half:top,shape:outer_right,waterlogged:false}": "minecraft:oak_stairs{facing:east,half:top,shape:outer_right,waterlogged:false}",
            "minecraft:oak_stairs{facing:north,half:top,shape:outer_right,waterlogged:false}": "minecraft:oak_stairs{facing:north,half:top,shape:outer_right,waterlogged:false}",
            "minecraft:oak_stairs{facing:south,half:bottom,shape:outer_right,waterlogged:false}": "minecraft:oak_stairs{facing:south,half:bottom,shape:outer_right,waterlogged:false}",
            "minecraft:oak_stairs{facing:south,half:top,shape:outer_right,waterlogged:false}": "minecraft:oak_stairs{facing:south,half:top,shape:outer_right,waterlogged:false}",
            "minecraft:oak_stairs{facing:west,half:bottom,shape:outer_right,waterlogged:false}": "minecraft:oak_stairs{facing:west,half:bottom,shape:outer_right,waterlogged:false}",
            "minecraft:oak_stairs{facing:west,half:top,shape:outer_right,waterlogged:false}": "minecraft:oak_stairs{facing:west,half:top,shape:outer_right,waterlogged:false}",
            "minecraft:oak_trapdoor{facing:east,half:top,open:false,powered:false,waterlogged:false}": "minecraft:oak_trapdoor{facing:east,half:top,open:false,powered:false,waterlogged:false}",
            "minecraft:oak_trapdoor{facing:north,half:top,open:false,powered:false,waterlogged:false}": "minecraft:oak_trapdoor{facing:north,half:top,open:false,powered:false,waterlogged:false}",
            "minecraft:spruce_fence{east:false,north:false,south:false,waterlogged:false,west:false}": "minecraft:birch_fence{east:false,north:false,south:false,waterlogged:false,west:false}",
            "minecraft:spruce_planks": "minecraft:birch_planks",
            "minecraft:spruce_slab{type:bottom,waterlogged:false}": "minecraft:birch_slab{type:bottom,waterlogged:false}",
            "minecraft:spruce_stairs{facing:north,half:bottom,shape:outer_right,waterlogged:false}": "minecraft:birch_stairs{facing:north,half:bottom,shape:outer_right,waterlogged:false}",
            "minecraft:spruce_stairs{facing:north,half:top,shape:outer_right,waterlogged:false}": "minecraft:birch_stairs{facing:north,half:top,shape:outer_right,waterlogged:false}",
            "minecraft:spruce_stairs{facing:south,half:bottom,shape:outer_right,waterlogged:false}": "minecraft:birch_stairs{facing:south,half:bottom,shape:outer_right,waterlogged:false}",
            "minecraft:spruce_stairs{facing:south,half:top,shape:outer_right,waterlogged:false}": "minecraft:birch_stairs{facing:south,half:top,shape:outer_right,waterlogged:false}",
            "minecraft:spruce_stairs{facing:west,half:top,shape:outer_right,waterlogged:false}": "minecraft:birch_stairs{facing:west,half:top,shape:outer_right,waterlogged:false}",
            "minecraft:structure_block{mode:data}": "minecraft:structure_block{mode:data}"
        }
    ]
}
