{
    DataVersion: 2856,
    size: [9, 9, 24],
    data: [
        {pos: [4, 0, 8], state: "minecraft:spruce_stairs{facing:south,half:top,shape:outer_right,waterlogged:false}"},
        {pos: [4, 0, 9], state: "minecraft:spruce_planks"},
        {pos: [4, 0, 10], state: "minecraft:spruce_planks"},
        {pos: [4, 0, 11], state: "minecraft:spruce_planks"},
        {pos: [4, 0, 12], state: "minecraft:spruce_planks"},
        {pos: [4, 0, 13], state: "minecraft:spruce_planks"},
        {pos: [4, 0, 14], state: "minecraft:spruce_planks"},
        {pos: [4, 0, 15], state: "minecraft:spruce_planks"},
        {pos: [4, 0, 16], state: "minecraft:spruce_planks"},
        {pos: [4, 0, 17], state: "minecraft:spruce_planks"},
        {pos: [4, 0, 18], state: "minecraft:spruce_planks"},
        {pos: [4, 0, 19], state: "minecraft:spruce_planks"},
        {pos: [4, 0, 20], state: "minecraft:spruce_planks"},
        {pos: [4, 0, 21], state: "minecraft:spruce_stairs{facing:north,half:top,shape:outer_right,waterlogged:false}"},
        {pos: [2, 1, 9], state: "minecraft:oak_stairs{facing:east,half:top,shape:outer_right,waterlogged:false}"},
        {pos: [2, 1, 10], state: "minecraft:oak_stairs{facing:east,half:top,shape:outer_right,waterlogged:false}"},
        {pos: [2, 1, 11], state: "minecraft:oak_stairs{facing:east,half:top,shape:outer_right,waterlogged:false}"},
        {pos: [2, 1, 12], state: "minecraft:oak_stairs{facing:east,half:top,shape:outer_right,waterlogged:false}"},
        {pos: [2, 1, 13], state: "minecraft:oak_stairs{facing:east,half:top,shape:outer_right,waterlogged:false}"},
        {pos: [2, 1, 14], state: "minecraft:oak_stairs{facing:east,half:top,shape:outer_right,waterlogged:false}"},
        {pos: [2, 1, 15], state: "minecraft:oak_stairs{facing:east,half:top,shape:outer_right,waterlogged:false}"},
        {pos: [2, 1, 16], state: "minecraft:oak_stairs{facing:east,half:top,shape:outer_right,waterlogged:false}"},
        {pos: [2, 1, 17], state: "minecraft:oak_stairs{facing:east,half:top,shape:outer_right,waterlogged:false}"},
        {pos: [2, 1, 18], state: "minecraft:oak_stairs{facing:east,half:top,shape:outer_right,waterlogged:false}"},
        {pos: [2, 1, 19], state: "minecraft:oak_stairs{facing:east,half:top,shape:outer_right,waterlogged:false}"},
        {pos: [2, 1, 20], state: "minecraft:oak_stairs{facing:east,half:top,shape:outer_right,waterlogged:false}"},
        {pos: [3, 1, 8], state: "minecraft:oak_stairs{facing:east,half:top,shape:outer_right,waterlogged:false}"},
        {pos: [3, 1, 9], state: "minecraft:oak_planks"},
        {pos: [3, 1, 10], state: "minecraft:oak_planks"},
        {pos: [3, 1, 11], state: "minecraft:oak_planks"},
        {pos: [3, 1, 12], state: "minecraft:oak_planks"},
        {pos: [3, 1, 13], state: "minecraft:oak_planks"},
        {pos: [3, 1, 14], state: "minecraft:oak_planks"},
        {pos: [3, 1, 15], state: "minecraft:oak_planks"},
        {pos: [3, 1, 16], state: "minecraft:oak_planks"},
        {pos: [3, 1, 17], state: "minecraft:oak_planks"},
        {pos: [3, 1, 18], state: "minecraft:oak_planks"},
        {pos: [3, 1, 20], state: "minecraft:oak_planks"},
        {pos: [3, 1, 21], state: "minecraft:oak_stairs{facing:east,half:top,shape:outer_right,waterlogged:false}"},
        {pos: [4, 1, 6], state: "minecraft:spruce_stairs{facing:south,half:top,shape:outer_right,waterlogged:false}"},
        {pos: [4, 1, 7], state: "minecraft:spruce_planks"},
        {pos: [4, 1, 8], state: "minecraft:oak_planks"},
        {pos: [4, 1, 9], state: "minecraft:oak_planks"},
        {pos: [4, 1, 10], state: "minecraft:oak_planks"},
        {pos: [4, 1, 11], state: "minecraft:oak_planks"},
        {pos: [4, 1, 12], state: "minecraft:oak_planks"},
        {pos: [4, 1, 13], state: "minecraft:oak_planks"},
        {pos: [4, 1, 14], state: "minecraft:oak_planks"},
        {pos: [4, 1, 15], state: "minecraft:oak_planks"},
        {pos: [4, 1, 16], state: "minecraft:oak_planks"},
        {pos: [4, 1, 17], state: "minecraft:oak_planks"},
        {pos: [4, 1, 19], state: "minecraft:oak_planks"},
        {pos: [4, 1, 22], state: "minecraft:oak_planks"},
        {pos: [5, 1, 8], state: "minecraft:oak_stairs{facing:west,half:top,shape:outer_right,waterlogged:false}"},
        {pos: [5, 1, 9], state: "minecraft:oak_planks"},
        {pos: [5, 1, 10], state: "minecraft:oak_planks"},
        {pos: [5, 1, 11], state: "minecraft:oak_planks"},
        {pos: [5, 1, 12], state: "minecraft:oak_planks"},
        {pos: [5, 1, 13], state: "minecraft:oak_planks"},
        {pos: [5, 1, 14], state: "minecraft:oak_planks"},
        {pos: [5, 1, 15], state: "minecraft:oak_planks"},
        {pos: [5, 1, 16], state: "minecraft:oak_planks"},
        {pos: [5, 1, 17], state: "minecraft:oak_planks"},
        {pos: [5, 1, 18], state: "minecraft:oak_planks"},
        {pos: [5, 1, 19], state: "minecraft:oak_planks"},
        {pos: [5, 1, 20], state: "minecraft:oak_planks"},
        {pos: [5, 1, 21], state: "minecraft:oak_stairs{facing:west,half:top,shape:outer_right,waterlogged:false}"},
        {pos: [5, 1, 22], state: "minecraft:oak_stairs{facing:west,half:top,shape:outer_right,waterlogged:false}"},
        {pos: [5, 1, 23], state: "minecraft:oak_stairs{facing:west,half:top,shape:outer_right,waterlogged:false}"},
        {pos: [6, 1, 9], state: "minecraft:oak_stairs{facing:west,half:top,shape:outer_right,waterlogged:false}"},
        {pos: [6, 1, 10], state: "minecraft:oak_stairs{facing:west,half:top,shape:outer_right,waterlogged:false}"},
        {pos: [6, 1, 11], state: "minecraft:oak_stairs{facing:west,half:top,shape:outer_right,waterlogged:false}"},
        {pos: [6, 1, 12], state: "minecraft:oak_stairs{facing:west,half:top,shape:outer_right,waterlogged:false}"},
        {pos: [6, 1, 13], state: "minecraft:oak_stairs{facing:west,half:top,shape:outer_right,waterlogged:false}"},
        {pos: [6, 1, 14], state: "minecraft:oak_stairs{facing:west,half:top,shape:outer_right,waterlogged:false}"},
        {pos: [6, 1, 15], state: "minecraft:oak_stairs{facing:west,half:top,shape:outer_right,waterlogged:false}"},
        {pos: [6, 1, 16], state: "minecraft:oak_stairs{facing:west,half:top,shape:outer_right,waterlogged:false}"},
        {pos: [6, 1, 17], state: "minecraft:oak_stairs{facing:west,half:top,shape:outer_right,waterlogged:false}"},
        {pos: [6, 1, 18], state: "minecraft:oak_stairs{facing:west,half:top,shape:outer_right,waterlogged:false}"},
        {pos: [6, 1, 19], state: "minecraft:oak_stairs{facing:west,half:top,shape:outer_right,waterlogged:false}"},
        {pos: [6, 1, 20], state: "minecraft:oak_stairs{facing:west,half:top,shape:outer_right,waterlogged:false}"},
        {pos: [1, 2, 9], state: "minecraft:oak_stairs{facing:east,half:top,shape:outer_right,waterlogged:false}"},
        {pos: [1, 2, 10], state: "minecraft:oak_stairs{facing:east,half:top,shape:outer_right,waterlogged:false}"},
        {pos: [1, 2, 11], state: "minecraft:oak_stairs{facing:east,half:top,shape:outer_right,waterlogged:false}"},
        {pos: [1, 2, 12], state: "minecraft:oak_stairs{facing:east,half:top,shape:outer_right,waterlogged:false}"},
        {pos: [1, 2, 13], state: "minecraft:oak_stairs{facing:east,half:top,shape:outer_right,waterlogged:false}"},
        {pos: [1, 2, 14], state: "minecraft:oak_stairs{facing:east,half:top,shape:outer_right,waterlogged:false}"},
        {pos: [1, 2, 15], state: "minecraft:oak_stairs{facing:east,half:top,shape:outer_right,waterlogged:false}"},
        {pos: [1, 2, 16], state: "minecraft:oak_stairs{facing:east,half:top,shape:outer_right,waterlogged:false}"},
        {pos: [1, 2, 17], state: "minecraft:oak_stairs{facing:east,half:top,shape:outer_right,waterlogged:false}"},
        {pos: [1, 2, 18], state: "minecraft:oak_stairs{facing:east,half:top,shape:outer_right,waterlogged:false}"},
        {pos: [2, 2, 8], state: "minecraft:oak_stairs{facing:east,half:top,shape:outer_right,waterlogged:false}"},
        {pos: [2, 2, 9], state: "minecraft:oak_planks"},
        {pos: [2, 2, 10], state: "minecraft:oak_planks"},
        {pos: [2, 2, 11], state: "minecraft:oak_planks"},
        {pos: [2, 2, 12], state: "minecraft:oak_stairs{facing:west,half:bottom,shape:outer_right,waterlogged:false}"},
        {pos: [2, 2, 13], state: "minecraft:oak_planks"},
        {pos: [2, 2, 14], state: "minecraft:oak_planks"},
        {pos: [2, 2, 15], state: "minecraft:oak_stairs{facing:west,half:bottom,shape:outer_right,waterlogged:false}"},
        {pos: [2, 2, 16], state: "minecraft:oak_planks"},
        {pos: [2, 2, 17], state: "minecraft:oak_planks"},
        {pos: [2, 2, 18], state: "minecraft:oak_stairs{facing:west,half:bottom,shape:outer_right,waterlogged:false}"},
        {pos: [2, 2, 19], state: "minecraft:oak_planks"},
        {pos: [3, 2, 7], state: "minecraft:oak_stairs{facing:east,half:top,shape:outer_right,waterlogged:false}"},
        {pos: [3, 2, 8], state: "minecraft:oak_planks"},
        {pos: [3, 2, 16], state: "minecraft:oak_door{facing:south,half:lower,hinge:right,open:false,powered:false}"},
        {pos: [4, 2, 5], state: "minecraft:spruce_stairs{facing:south,half:top,shape:outer_right,waterlogged:false}"},
        {pos: [4, 2, 6], state: "minecraft:spruce_planks"},
        {pos: [4, 2, 7], state: "minecraft:oak_planks"},
        {pos: [4, 2, 8], state: "minecraft:chest{facing:south,type:single,waterlogged:false}", nbt: {Items: [], id: "minecraft:chest"}},
        {pos: [4, 2, 11], state: "minecraft:oak_log{axis:y}"},
        {pos: [4, 2, 16], state: "minecraft:oak_log{axis:y}"},
        {pos: [5, 2, 7], state: "minecraft:oak_stairs{facing:west,half:top,shape:outer_right,waterlogged:false}"},
        {pos: [5, 2, 8], state: "minecraft:oak_planks"},
        {pos: [5, 2, 16], state: "minecraft:oak_planks"},
        {pos: [5, 2, 20], state: "minecraft:oak_planks"},
        {pos: [6, 2, 8], state: "minecraft:oak_stairs{facing:west,half:top,shape:outer_right,waterlogged:false}"},
        {pos: [6, 2, 9], state: "minecraft:oak_planks"},
        {pos: [6, 2, 10], state: "minecraft:oak_planks"},
        {pos: [6, 2, 11], state: "minecraft:oak_planks"},
        {pos: [6, 2, 12], state: "minecraft:oak_stairs{facing:east,half:bottom,shape:outer_right,waterlogged:false}"},
        {pos: [6, 2, 13], state: "minecraft:oak_planks"},
        {pos: [6, 2, 14], state: "minecraft:oak_planks"},
        {pos: [6, 2, 15], state: "minecraft:oak_stairs{facing:east,half:bottom,shape:outer_right,waterlogged:false}"},
        {pos: [6, 2, 16], state: "minecraft:oak_planks"},
        {pos: [6, 2, 17], state: "minecraft:oak_planks"},
        {pos: [6, 2, 18], state: "minecraft:oak_stairs{facing:east,half:bottom,shape:outer_right,waterlogged:false}"},
        {pos: [6, 2, 19], state: "minecraft:oak_planks"},
        {pos: [6, 2, 20], state: "minecraft:oak_planks"},
        {pos: [7, 2, 9], state: "minecraft:oak_stairs{facing:west,half:top,shape:outer_right,waterlogged:false}"},
        {pos: [7, 2, 10], state: "minecraft:oak_stairs{facing:west,half:top,shape:outer_right,waterlogged:false}"},
        {pos: [7, 2, 11], state: "minecraft:oak_stairs{facing:west,half:top,shape:outer_right,waterlogged:false}"},
        {pos: [7, 2, 12], state: "minecraft:oak_stairs{facing:west,half:top,shape:outer_right,waterlogged:false}"},
        {pos: [7, 2, 13], state: "minecraft:oak_stairs{facing:west,half:top,shape:outer_right,waterlogged:false}"},
        {pos: [7, 2, 14], state: "minecraft:oak_stairs{facing:west,half:top,shape:outer_right,waterlogged:false}"},
        {pos: [7, 2, 15], state: "minecraft:oak_stairs{facing:west,half:top,shape:outer_right,waterlogged:false}"},
        {pos: [7, 2, 16], state: "minecraft:oak_stairs{facing:west,half:top,shape:outer_right,waterlogged:false}"},
        {pos: [7, 2, 17], state: "minecraft:oak_stairs{facing:west,half:top,shape:outer_right,waterlogged:false}"},
        {pos: [7, 2, 18], state: "minecraft:oak_stairs{facing:west,half:top,shape:outer_right,waterlogged:false}"},
        {pos: [7, 2, 19], state: "minecraft:oak_stairs{facing:west,half:top,shape:outer_right,waterlogged:false}"},
        {pos: [7, 2, 20], state: "minecraft:oak_stairs{facing:west,half:top,shape:outer_right,waterlogged:false}"},
        {pos: [1, 3, 8], state: "minecraft:oak_stairs{facing:east,half:top,shape:outer_right,waterlogged:false}"},
        {pos: [1, 3, 9], state: "minecraft:oak_planks"},
        {pos: [1, 3, 10], state: "minecraft:oak_planks"},
        {pos: [1, 3, 11], state: "minecraft:oak_planks"},
        {pos: [1, 3, 13], state: "minecraft:oak_planks"},
        {pos: [1, 3, 14], state: "minecraft:oak_planks"},
        {pos: [1, 3, 16], state: "minecraft:oak_planks"},
        {pos: [1, 3, 17], state: "minecraft:oak_planks"},
        {pos: [2, 3, 7], state: "minecraft:oak_stairs{facing:east,half:top,shape:outer_right,waterlogged:false}"},
        {pos: [2, 3, 8], state: "minecraft:oak_planks"},
        {pos: [2, 3, 9], state: "minecraft:oak_planks"},
        {pos: [2, 3, 10], state: "minecraft:oak_planks"},
        {pos: [2, 3, 11], state: "minecraft:oak_planks"},
        {pos: [2, 3, 13], state: "minecraft:oak_planks"},
        {pos: [2, 3, 14], state: "minecraft:oak_planks"},
        {pos: [2, 3, 16], state: "minecraft:oak_planks"},
        {pos: [2, 3, 17], state: "minecraft:oak_planks"},
        {pos: [3, 3, 5], state: "minecraft:oak_stairs{facing:east,half:top,shape:outer_right,waterlogged:false}"},
        {pos: [3, 3, 6], state: "minecraft:oak_stairs{facing:east,half:top,shape:outer_right,waterlogged:false}"},
        {pos: [3, 3, 7], state: "minecraft:oak_planks"},
        {pos: [3, 3, 16], state: "minecraft:oak_door{facing:east,half:upper,hinge:left,open:false,powered:false}"},
        {pos: [4, 3, 4], state: "minecraft:spruce_stairs{facing:south,half:top,shape:outer_right,waterlogged:false}"},
        {pos: [4, 3, 5], state: "minecraft:oak_planks"},
        {pos: [4, 3, 6], state: "minecraft:oak_planks"},
        {pos: [4, 3, 7], state: "minecraft:oak_planks"},
        {pos: [4, 3, 8], state: "minecraft:structure_block{mode:data}", nbt: {author: "CascadianBacon", id: "minecraft:structure_block", ignoreEntities: 1b, integrity: 1.0f, metadata: "supply_chest", mirror: "NONE", mode: "DATA", name: "", posX: 0, posY: 1, posZ: 0, powered: 0b, rotation: "NONE", seed: 0L, showair: 0b, showboundingbox: 1b, sizeX: 0, sizeY: 0, sizeZ: 0}},
        {pos: [4, 3, 11], state: "minecraft:oak_log{axis:y}"},
        {pos: [4, 3, 16], state: "minecraft:oak_log{axis:y}"},
        {pos: [5, 3, 5], state: "minecraft:oak_stairs{facing:west,half:top,shape:outer_right,waterlogged:false}"},
        {pos: [5, 3, 6], state: "minecraft:oak_stairs{facing:west,half:top,shape:outer_right,waterlogged:false}"},
        {pos: [5, 3, 7], state: "minecraft:oak_planks"},
        {pos: [5, 3, 16], state: "minecraft:oak_planks"},
        {pos: [6, 3, 7], state: "minecraft:oak_stairs{facing:west,half:top,shape:outer_right,waterlogged:false}"},
        {pos: [6, 3, 8], state: "minecraft:oak_planks"},
        {pos: [6, 3, 9], state: "minecraft:oak_planks"},
        {pos: [6, 3, 10], state: "minecraft:oak_planks"},
        {pos: [6, 3, 11], state: "minecraft:oak_planks"},
        {pos: [6, 3, 13], state: "minecraft:oak_planks"},
        {pos: [6, 3, 14], state: "minecraft:oak_planks"},
        {pos: [6, 3, 16], state: "minecraft:oak_planks"},
        {pos: [7, 3, 8], state: "minecraft:oak_stairs{facing:west,half:top,shape:outer_right,waterlogged:false}"},
        {pos: [7, 3, 9], state: "minecraft:oak_planks"},
        {pos: [7, 3, 10], state: "minecraft:oak_planks"},
        {pos: [7, 3, 11], state: "minecraft:oak_planks"},
        {pos: [7, 3, 13], state: "minecraft:oak_planks"},
        {pos: [7, 3, 14], state: "minecraft:oak_planks"},
        {pos: [7, 3, 16], state: "minecraft:oak_planks"},
        {pos: [7, 3, 17], state: "minecraft:oak_planks"},
        {pos: [7, 3, 19], state: "minecraft:oak_planks"},
        {pos: [0, 4, 9], state: "minecraft:oak_stairs{facing:east,half:top,shape:outer_right,waterlogged:false}"},
        {pos: [0, 4, 10], state: "minecraft:oak_stairs{facing:east,half:top,shape:outer_right,waterlogged:false}"},
        {pos: [0, 4, 11], state: "minecraft:oak_stairs{facing:east,half:top,shape:outer_right,waterlogged:false}"},
        {pos: [0, 4, 12], state: "minecraft:oak_stairs{facing:east,half:top,shape:outer_right,waterlogged:false}"},
        {pos: [0, 4, 13], state: "minecraft:oak_stairs{facing:east,half:top,shape:outer_right,waterlogged:false}"},
        {pos: [0, 4, 14], state: "minecraft:oak_stairs{facing:east,half:top,shape:outer_right,waterlogged:false}"},
        {pos: [0, 4, 15], state: "minecraft:oak_stairs{facing:east,half:top,shape:outer_right,waterlogged:false}"},
        {pos: [0, 4, 16], state: "minecraft:oak_stairs{facing:east,half:top,shape:outer_right,waterlogged:false}"},
        {pos: [1, 4, 7], state: "minecraft:oak_stairs{facing:east,half:top,shape:outer_right,waterlogged:false}"},
        {pos: [1, 4, 8], state: "minecraft:oak_planks"},
        {pos: [1, 4, 9], state: "minecraft:spruce_planks"},
        {pos: [1, 4, 10], state: "minecraft:spruce_planks"},
        {pos: [1, 4, 11], state: "minecraft:spruce_planks"},
        {pos: [1, 4, 12], state: "minecraft:spruce_planks"},
        {pos: [1, 4, 13], state: "minecraft:spruce_planks"},
        {pos: [1, 4, 14], state: "minecraft:spruce_planks"},
        {pos: [1, 4, 15], state: "minecraft:spruce_planks"},
        {pos: [1, 4, 16], state: "minecraft:spruce_planks"},
        {pos: [2, 4, 5], state: "minecraft:oak_stairs{facing:east,half:top,shape:outer_right,waterlogged:false}"},
        {pos: [2, 4, 6], state: "minecraft:oak_stairs{facing:east,half:top,shape:outer_right,waterlogged:false}"},
        {pos: [2, 4, 7], state: "minecraft:oak_planks"},
        {pos: [2, 4, 8], state: "minecraft:spruce_planks"},
        {pos: [2, 4, 9], state: "minecraft:spruce_planks"},
        {pos: [2, 4, 10], state: "minecraft:spruce_planks"},
        {pos: [2, 4, 11], state: "minecraft:spruce_planks"},
        {pos: [2, 4, 12], state: "minecraft:spruce_stairs{facing:west,half:top,shape:outer_right,waterlogged:false}"},
        {pos: [2, 4, 13], state: "minecraft:spruce_planks"},
        {pos: [3, 4, 4], state: "minecraft:oak_stairs{facing:south,half:top,shape:outer_right,waterlogged:false}"},
        {pos: [3, 4, 5], state: "minecraft:oak_planks"},
        {pos: [3, 4, 6], state: "minecraft:oak_planks"},
        {pos: [3, 4, 7], state: "minecraft:oak_planks"},
        {pos: [3, 4, 8], state: "minecraft:spruce_stairs{facing:north,half:top,shape:outer_right,waterlogged:false}"},
        {pos: [3, 4, 9], state: "minecraft:oak_trapdoor{facing:south,half:top,open:false,powered:false,waterlogged:false}"},
        {pos: [3, 4, 10], state: "minecraft:oak_trapdoor{facing:north,half:top,open:false,powered:false,waterlogged:false}"},
        {pos: [3, 4, 11], state: "minecraft:spruce_planks"},
        {pos: [3, 4, 12], state: "minecraft:oak_trapdoor{facing:south,half:top,open:false,powered:false,waterlogged:false}"},
        {pos: [3, 4, 13], state: "minecraft:oak_trapdoor{facing:east,half:top,open:false,powered:false,waterlogged:false}"},
        {pos: [4, 4, 3], state: "minecraft:spruce_stairs{facing:south,half:top,shape:outer_right,waterlogged:false}"},
        {pos: [4, 4, 4], state: "minecraft:spruce_planks"},
        {pos: [4, 4, 5], state: "minecraft:oak_planks"},
        {pos: [4, 4, 6], state: "minecraft:oak_planks"},
        {pos: [4, 4, 7], state: "minecraft:oak_log{axis:y}"},
        {pos: [4, 4, 8], state: "minecraft:spruce_stairs{facing:north,half:top,shape:outer_right,waterlogged:false}"},
        {pos: [4, 4, 11], state: "minecraft:oak_log{axis:y}"},
        {pos: [4, 4, 12], state: "minecraft:oak_trapdoor{facing:south,half:top,open:false,powered:false,waterlogged:false}"},
        {pos: [5, 4, 4], state: "minecraft:oak_stairs{facing:south,half:top,shape:outer_right,waterlogged:false}"},
        {pos: [5, 4, 5], state: "minecraft:oak_planks"},
        {pos: [5, 4, 6], state: "minecraft:oak_planks"},
        {pos: [5, 4, 7], state: "minecraft:oak_planks"},
        {pos: [5, 4, 8], state: "minecraft:spruce_stairs{facing:north,half:top,shape:outer_right,waterlogged:false}"},
        {pos: [5, 4, 9], state: "minecraft:oak_trapdoor{facing:south,half:top,open:false,powered:false,waterlogged:false}"},
        {pos: [5, 4, 10], state: "minecraft:oak_trapdoor{facing:west,half:top,open:false,powered:false,waterlogged:false}"},
        {pos: [5, 4, 11], state: "minecraft:spruce_planks"},
        {pos: [5, 4, 12], state: "minecraft:oak_trapdoor{facing:south,half:top,open:false,powered:false,waterlogged:false}"},
        {pos: [5, 4, 13], state: "minecraft:oak_trapdoor{facing:west,half:top,open:false,powered:false,waterlogged:false}"},
        {pos: [5, 4, 14], state: "minecraft:oak_trapdoor{facing:west,half:top,open:false,powered:false,waterlogged:false}"},
        {pos: [5, 4, 15], state: "minecraft:oak_trapdoor{facing:north,half:top,open:false,powered:false,waterlogged:false}"},
        {pos: [5, 4, 16], state: "minecraft:spruce_planks"},
        {pos: [6, 4, 5], state: "minecraft:oak_stairs{facing:west,half:top,shape:outer_right,waterlogged:false}"},
        {pos: [6, 4, 6], state: "minecraft:oak_stairs{facing:west,half:top,shape:outer_right,waterlogged:false}"},
        {pos: [6, 4, 7], state: "minecraft:oak_planks"},
        {pos: [6, 4, 8], state: "minecraft:spruce_planks"},
        {pos: [6, 4, 9], state: "minecraft:spruce_planks"},
        {pos: [6, 4, 10], state: "minecraft:spruce_planks"},
        {pos: [6, 4, 11], state: "minecraft:spruce_planks"},
        {pos: [6, 4, 12], state: "minecraft:spruce_stairs{facing:east,half:top,shape:outer_right,waterlogged:false}"},
        {pos: [6, 4, 13], state: "minecraft:spruce_planks"},
        {pos: [6, 4, 14], state: "minecraft:spruce_planks"},
        {pos: [6, 4, 15], state: "minecraft:spruce_stairs{facing:east,half:top,shape:outer_right,waterlogged:false}"},
        {pos: [7, 4, 7], state: "minecraft:oak_stairs{facing:west,half:top,shape:outer_right,waterlogged:false}"},
        {pos: [7, 4, 8], state: "minecraft:oak_planks"},
        {pos: [7, 4, 9], state: "minecraft:spruce_planks"},
        {pos: [7, 4, 10], state: "minecraft:spruce_planks"},
        {pos: [7, 4, 11], state: "minecraft:spruce_planks"},
        {pos: [7, 4, 12], state: "minecraft:spruce_planks"},
        {pos: [7, 4, 13], state: "minecraft:spruce_planks"},
        {pos: [7, 4, 14], state: "minecraft:spruce_planks"},
        {pos: [7, 4, 15], state: "minecraft:spruce_planks"},
        {pos: [7, 4, 16], state: "minecraft:spruce_planks"},
        {pos: [8, 4, 9], state: "minecraft:oak_stairs{facing:west,half:top,shape:outer_right,waterlogged:false}"},
        {pos: [8, 4, 10], state: "minecraft:oak_stairs{facing:west,half:top,shape:outer_right,waterlogged:false}"},
        {pos: [8, 4, 11], state: "minecraft:oak_stairs{facing:west,half:top,shape:outer_right,waterlogged:false}"},
        {pos: [8, 4, 12], state: "minecraft:oak_stairs{facing:west,half:top,shape:outer_right,waterlogged:false}"},
        {pos: [8, 4, 13], state: "minecraft:oak_stairs{facing:west,half:top,shape:outer_right,waterlogged:false}"},
        {pos: [8, 4, 14], state: "minecraft:oak_stairs{facing:west,half:top,shape:outer_right,waterlogged:false}"},
        {pos: [8, 4, 15], state: "minecraft:oak_stairs{facing:west,half:top,shape:outer_right,waterlogged:false}"},
        {pos: [8, 4, 16], state: "minecraft:oak_stairs{facing:west,half:top,shape:outer_right,waterlogged:false}"},
        {pos: [8, 4, 17], state: "minecraft:oak_stairs{facing:west,half:top,shape:outer_right,waterlogged:false}"},
        {pos: [8, 4, 18], state: "minecraft:oak_stairs{facing:west,half:top,shape:outer_right,waterlogged:false}"},
        {pos: [0, 5, 8], state: "minecraft:oak_stairs{facing:south,half:top,shape:outer_right,waterlogged:false}"},
        {pos: [0, 5, 9], state: "minecraft:oak_planks"},
        {pos: [0, 5, 10], state: "minecraft:oak_planks"},
        {pos: [0, 5, 11], state: "minecraft:spruce_fence{east:false,north:false,south:false,waterlogged:false,west:false}"},
        {pos: [0, 5, 12], state: "minecraft:spruce_fence{east:false,north:false,south:false,waterlogged:false,west:false}"},
        {pos: [0, 5, 13], state: "minecraft:spruce_fence{east:false,north:false,south:false,waterlogged:false,west:false}"},
        {pos: [0, 5, 15], state: "minecraft:spruce_fence{east:false,north:false,south:false,waterlogged:false,west:false}"},
        {pos: [1, 5, 6], state: "minecraft:oak_stairs{facing:east,half:top,shape:outer_right,waterlogged:false}"},
        {pos: [1, 5, 7], state: "minecraft:oak_planks"},
        {pos: [1, 5, 8], state: "minecraft:oak_planks"},
        {pos: [2, 5, 5], state: "minecraft:oak_planks"},
        {pos: [2, 5, 6], state: "minecraft:spruce_planks"},
        {pos: [2, 5, 7], state: "minecraft:spruce_planks"},
        {pos: [3, 5, 3], state: "minecraft:oak_stairs{facing:south,half:top,shape:outer_right,waterlogged:false}"},
        {pos: [3, 5, 4], state: "minecraft:oak_planks"},
        {pos: [3, 5, 5], state: "minecraft:spruce_planks"},
        {pos: [3, 5, 6], state: "minecraft:spruce_planks"},
        {pos: [3, 5, 7], state: "minecraft:spruce_stairs{facing:north,half:bottom,shape:outer_right,waterlogged:false}"},
        {pos: [4, 5, 3], state: "minecraft:spruce_planks"},
        {pos: [4, 5, 4], state: "minecraft:oak_planks"},
        {pos: [4, 5, 5], state: "minecraft:spruce_planks"},
        {pos: [4, 5, 6], state: "minecraft:spruce_planks"},
        {pos: [4, 5, 7], state: "minecraft:oak_log{axis:y}"},
        {pos: [4, 5, 11], state: "minecraft:oak_log{axis:y}"},
        {pos: [5, 5, 3], state: "minecraft:oak_stairs{facing:south,half:top,shape:outer_right,waterlogged:false}"},
        {pos: [5, 5, 4], state: "minecraft:oak_planks"},
        {pos: [5, 5, 5], state: "minecraft:spruce_planks"},
        {pos: [5, 5, 6], state: "minecraft:spruce_planks"},
        {pos: [5, 5, 7], state: "minecraft:spruce_stairs{facing:north,half:bottom,shape:outer_right,waterlogged:false}"},
        {pos: [6, 5, 5], state: "minecraft:oak_planks"},
        {pos: [6, 5, 6], state: "minecraft:spruce_planks"},
        {pos: [6, 5, 7], state: "minecraft:spruce_planks"},
        {pos: [7, 5, 6], state: "minecraft:oak_stairs{facing:west,half:top,shape:outer_right,waterlogged:false}"},
        {pos: [7, 5, 7], state: "minecraft:oak_planks"},
        {pos: [7, 5, 8], state: "minecraft:oak_planks"},
        {pos: [8, 5, 8], state: "minecraft:oak_stairs{facing:south,half:top,shape:outer_right,waterlogged:false}"},
        {pos: [8, 5, 9], state: "minecraft:oak_planks"},
        {pos: [8, 5, 10], state: "minecraft:oak_planks"},
        {pos: [8, 5, 11], state: "minecraft:spruce_fence{east:false,north:false,south:false,waterlogged:false,west:false}"},
        {pos: [8, 5, 12], state: "minecraft:spruce_fence{east:false,north:false,south:false,waterlogged:false,west:false}"},
        {pos: [8, 5, 13], state: "minecraft:spruce_fence{east:false,north:false,south:false,waterlogged:false,west:false}"},
        {pos: [8, 5, 15], state: "minecraft:spruce_fence{east:false,north:false,south:false,waterlogged:false,west:false}"},
        {pos: [8, 5, 16], state: "minecraft:spruce_fence{east:false,north:false,south:false,waterlogged:false,west:false}"},
        {pos: [8, 5, 17], state: "minecraft:spruce_fence{east:false,north:false,south:false,waterlogged:false,west:false}"},
        {pos: [0, 6, 8], state: "minecraft:oak_planks"},
        {pos: [0, 6, 9], state: "minecraft:oak_stairs{facing:north,half:bottom,shape:outer_right,waterlogged:false}"},
        {pos: [1, 6, 6], state: "minecraft:oak_planks"},
        {pos: [1, 6, 7], state: "minecraft:oak_planks"},
        {pos: [1, 6, 8], state: "minecraft:oak_stairs{facing:north,half:bottom,shape:outer_right,waterlogged:false}"},
        {pos: [2, 6, 5], state: "minecraft:oak_planks"},
        {pos: [3, 6, 2], state: "minecraft:spruce_fence{east:false,north:false,south:false,waterlogged:false,west:false}"},
        {pos: [3, 6, 3], state: "minecraft:oak_stairs{facing:south,half:bottom,shape:outer_right,waterlogged:false}"},
        {pos: [3, 6, 4], state: "minecraft:oak_planks"},
        {pos: [4, 6, 2], state: "minecraft:spruce_stairs{facing:south,half:top,shape:outer_right,waterlogged:false}"},
        {pos: [4, 6, 3], state: "minecraft:spruce_planks"},
        {pos: [4, 6, 4], state: "minecraft:spruce_stairs{facing:north,half:bottom,shape:outer_right,waterlogged:false}"},
        {pos: [5, 6, 2], state: "minecraft:spruce_fence{east:false,north:false,south:false,waterlogged:false,west:false}"},
        {pos: [5, 6, 3], state: "minecraft:oak_stairs{facing:south,half:bottom,shape:outer_right,waterlogged:false}"},
        {pos: [5, 6, 4], state: "minecraft:oak_planks"},
        {pos: [6, 6, 5], state: "minecraft:oak_planks"},
        {pos: [7, 6, 6], state: "minecraft:oak_planks"},
        {pos: [7, 6, 7], state: "minecraft:oak_planks"},
        {pos: [7, 6, 8], state: "minecraft:oak_stairs{facing:north,half:bottom,shape:outer_right,waterlogged:false}"},
        {pos: [8, 6, 8], state: "minecraft:oak_planks"},
        {pos: [8, 6, 9], state: "minecraft:oak_stairs{facing:north,half:bottom,shape:outer_right,waterlogged:false}"},
        {pos: [3, 7, 2], state: "minecraft:spruce_fence{east:false,north:false,south:false,waterlogged:false,west:false}"},
        {pos: [3, 7, 3], state: "minecraft:spruce_fence{east:false,north:false,south:false,waterlogged:false,west:false}"},
        {pos: [3, 7, 4], state: "minecraft:spruce_fence{east:false,north:false,south:false,waterlogged:false,west:false}"},
        {pos: [4, 7, 1], state: "minecraft:spruce_stairs{facing:south,half:top,shape:outer_right,waterlogged:false}"},
        {pos: [4, 7, 2], state: "minecraft:spruce_planks"},
        {pos: [4, 7, 3], state: "minecraft:spruce_stairs{facing:north,half:bottom,shape:outer_right,waterlogged:false}"},
        {pos: [5, 7, 2], state: "minecraft:spruce_fence{east:false,north:false,south:false,waterlogged:false,west:false}"},
        {pos: [5, 7, 3], state: "minecraft:spruce_fence{east:false,north:false,south:false,waterlogged:false,west:false}"},
        {pos: [5, 7, 4], state: "minecraft:spruce_fence{east:false,north:false,south:false,waterlogged:false,west:false}"},
        {pos: [4, 8, 0], state: "minecraft:spruce_stairs{facing:south,half:top,shape:outer_right,waterlogged:false}"},
        {pos: [4, 8, 1], state: "minecraft:spruce_stairs{facing:north,half:bottom,shape:outer_right,waterlogged:false}"}
    ],
    entities: [],
    palette: [
        "minecraft:spruce_planks",
        "minecraft:oak_planks",
        "minecraft:oak_log{axis:y}",
        "minecraft:spruce_stairs{facing:south,half:top,shape:outer_right,waterlogged:false}",
        "minecraft:spruce_stairs{facing:north,half:top,shape:outer_right,waterlogged:false}",
        "minecraft:oak_stairs{facing:east,half:top,shape:outer_right,waterlogged:false}",
        "minecraft:oak_stairs{facing:west,half:top,shape:outer_right,waterlogged:false}",
        "minecraft:oak_stairs{facing:west,half:bottom,shape:outer_right,waterlogged:false}",
        "minecraft:oak_door{facing:south,half:lower,hinge:right,open:false,powered:false}",
        "minecraft:oak_stairs{facing:east,half:bottom,shape:outer_right,waterlogged:false}",
        "minecraft:oak_door{facing:east,half:upper,hinge:left,open:false,powered:false}",
        "minecraft:spruce_stairs{facing:west,half:top,shape:outer_right,waterlogged:false}",
        "minecraft:oak_stairs{facing:south,half:top,shape:outer_right,waterlogged:false}",
        "minecraft:oak_trapdoor{facing:south,half:top,open:false,powered:false,waterlogged:false}",
        "minecraft:oak_trapdoor{facing:north,half:top,open:false,powered:false,waterlogged:false}",
        "minecraft:oak_trapdoor{facing:east,half:top,open:false,powered:false,waterlogged:false}",
        "minecraft:oak_trapdoor{facing:west,half:top,open:false,powered:false,waterlogged:false}",
        "minecraft:spruce_stairs{facing:east,half:top,shape:outer_right,waterlogged:false}",
        "minecraft:spruce_fence{east:false,north:false,south:false,waterlogged:false,west:false}",
        "minecraft:spruce_stairs{facing:north,half:bottom,shape:outer_right,waterlogged:false}",
        "minecraft:oak_stairs{facing:north,half:bottom,shape:outer_right,waterlogged:false}",
        "minecraft:oak_stairs{facing:south,half:bottom,shape:outer_right,waterlogged:false}",
        "minecraft:chest{facing:south,type:single,waterlogged:false}",
        "minecraft:structure_block{mode:data}"
    ],
    palettes: [
        {
            "minecraft:chest{facing:south,type:single,waterlogged:false}": "minecraft:chest{facing:south,type:single,waterlogged:false}",
            "minecraft:oak_door{facing:east,half:upper,hinge:left,open:false,powered:false}": "minecraft:oak_door{facing:east,half:upper,hinge:left,open:false,powered:false}",
            "minecraft:oak_door{facing:south,half:lower,hinge:right,open:false,powered:false}": "minecraft:oak_door{facing:south,half:lower,hinge:right,open:false,powered:false}",
            "minecraft:oak_log{axis:y}": "minecraft:oak_log{axis:y}",
            "minecraft:oak_planks": "minecraft:oak_planks",
            "minecraft:oak_stairs{facing:east,half:bottom,shape:outer_right,waterlogged:false}": "minecraft:oak_stairs{facing:east,half:bottom,shape:outer_right,waterlogged:false}",
            "minecraft:oak_stairs{facing:east,half:top,shape:outer_right,waterlogged:false}": "minecraft:oak_stairs{facing:east,half:top,shape:outer_right,waterlogged:false}",
            "minecraft:oak_stairs{facing:north,half:bottom,shape:outer_right,waterlogged:false}": "minecraft:oak_stairs{facing:north,half:bottom,shape:outer_right,waterlogged:false}",
            "minecraft:oak_stairs{facing:south,half:bottom,shape:outer_right,waterlogged:false}": "minecraft:oak_stairs{facing:south,half:bottom,shape:outer_right,waterlogged:false}",
            "minecraft:oak_stairs{facing:south,half:top,shape:outer_right,waterlogged:false}": "minecraft:oak_stairs{facing:south,half:top,shape:outer_right,waterlogged:false}",
            "minecraft:oak_stairs{facing:west,half:bottom,shape:outer_right,waterlogged:false}": "minecraft:oak_stairs{facing:west,half:bottom,shape:outer_right,waterlogged:false}",
            "minecraft:oak_stairs{facing:west,half:top,shape:outer_right,waterlogged:false}": "minecraft:oak_stairs{facing:west,half:top,shape:outer_right,waterlogged:false}",
            "minecraft:oak_trapdoor{facing:east,half:top,open:false,powered:false,waterlogged:false}": "minecraft:oak_trapdoor{facing:east,half:top,open:false,powered:false,waterlogged:false}",
            "minecraft:oak_trapdoor{facing:north,half:top,open:false,powered:false,waterlogged:false}": "minecraft:oak_trapdoor{facing:north,half:top,open:false,powered:false,waterlogged:false}",
            "minecraft:oak_trapdoor{facing:south,half:top,open:false,powered:false,waterlogged:false}": "minecraft:oak_trapdoor{facing:south,half:top,open:false,powered:false,waterlogged:false}",
            "minecraft:oak_trapdoor{facing:west,half:top,open:false,powered:false,waterlogged:false}": "minecraft:oak_trapdoor{facing:west,half:top,open:false,powered:false,waterlogged:false}",
            "minecraft:spruce_fence{east:false,north:false,south:false,waterlogged:false,west:false}": "minecraft:spruce_fence{east:false,north:false,south:false,waterlogged:false,west:false}",
            "minecraft:spruce_planks": "minecraft:spruce_planks",
            "minecraft:spruce_stairs{facing:east,half:top,shape:outer_right,waterlogged:false}": "minecraft:spruce_stairs{facing:east,half:top,shape:outer_right,waterlogged:false}",
            "minecraft:spruce_stairs{facing:north,half:bottom,shape:outer_right,waterlogged:false}": "minecraft:spruce_stairs{facing:north,half:bottom,shape:outer_right,waterlogged:false}",
            "minecraft:spruce_stairs{facing:north,half:top,shape:outer_right,waterlogged:false}": "minecraft:spruce_stairs{facing:north,half:top,shape:outer_right,waterlogged:false}",
            "minecraft:spruce_stairs{facing:south,half:top,shape:outer_right,waterlogged:false}": "minecraft:spruce_stairs{facing:south,half:top,shape:outer_right,waterlogged:false}",
            "minecraft:spruce_stairs{facing:west,half:top,shape:outer_right,waterlogged:false}": "minecraft:spruce_stairs{facing:west,half:top,shape:outer_right,waterlogged:false}",
            "minecraft:structure_block{mode:data}": "minecraft:structure_block{mode:data}"
        },
        {
            "minecraft:chest{facing:south,type:single,waterlogged:false}": "minecraft:chest{facing:south,type:single,waterlogged:false}",
            "minecraft:oak_door{facing:east,half:upper,hinge:left,open:false,powered:false}": "minecraft:jungle_door{facing:east,half:upper,hinge:left,open:false,powered:false}",
            "minecraft:oak_door{facing:south,half:lower,hinge:right,open:false,powered:false}": "minecraft:jungle_door{facing:south,half:lower,hinge:right,open:false,powered:false}",
            "minecraft:oak_log{axis:y}": "minecraft:jungle_log{axis:y}",
            "minecraft:oak_planks": "minecraft:jungle_planks",
            "minecraft:oak_stairs{facing:east,half:bottom,shape:outer_right,waterlogged:false}": "minecraft:jungle_stairs{facing:east,half:bottom,shape:outer_right,waterlogged:false}",
            "minecraft:oak_stairs{facing:east,half:top,shape:outer_right,waterlogged:false}": "minecraft:jungle_stairs{facing:east,half:top,shape:outer_right,waterlogged:false}",
            "minecraft:oak_stairs{facing:north,half:bottom,shape:outer_right,waterlogged:false}": "minecraft:jungle_stairs{facing:north,half:bottom,shape:outer_right,waterlogged:false}",
            "minecraft:oak_stairs{facing:south,half:bottom,shape:outer_right,waterlogged:false}": "minecraft:jungle_stairs{facing:south,half:bottom,shape:outer_right,waterlogged:false}",
            "minecraft:oak_stairs{facing:south,half:top,shape:outer_right,waterlogged:false}": "minecraft:jungle_stairs{facing:south,half:top,shape:outer_right,waterlogged:false}",
            "minecraft:oak_stairs{facing:west,half:bottom,shape:outer_right,waterlogged:false}": "minecraft:jungle_stairs{facing:west,half:bottom,shape:outer_right,waterlogged:false}",
            "minecraft:oak_stairs{facing:west,half:top,shape:outer_right,waterlogged:false}": "minecraft:jungle_stairs{facing:west,half:top,shape:outer_right,waterlogged:false}",
            "minecraft:oak_trapdoor{facing:east,half:top,open:false,powered:false,waterlogged:false}": "minecraft:jungle_trapdoor{facing:east,half:top,open:false,powered:false,waterlogged:false}",
            "minecraft:oak_trapdoor{facing:north,half:top,open:false,powered:false,waterlogged:false}": "minecraft:jungle_trapdoor{facing:north,half:top,open:false,powered:false,waterlogged:false}",
            "minecraft:oak_trapdoor{facing:south,half:top,open:false,powered:false,waterlogged:false}": "minecraft:jungle_trapdoor{facing:south,half:top,open:false,powered:false,waterlogged:false}",
            "minecraft:oak_trapdoor{facing:west,half:top,open:false,powered:false,waterlogged:false}": "minecraft:jungle_trapdoor{facing:west,half:top,open:false,powered:false,waterlogged:false}",
            "minecraft:spruce_fence{east:false,north:false,south:false,waterlogged:false,west:false}": "minecraft:spruce_fence{east:false,north:false,south:false,waterlogged:false,west:false}",
            "minecraft:spruce_planks": "minecraft:spruce_planks",
            "minecraft:spruce_stairs{facing:east,half:top,shape:outer_right,waterlogged:false}": "minecraft:spruce_stairs{facing:east,half:top,shape:outer_right,waterlogged:false}",
            "minecraft:spruce_stairs{facing:north,half:bottom,shape:outer_right,waterlogged:false}": "minecraft:spruce_stairs{facing:north,half:bottom,shape:outer_right,waterlogged:false}",
            "minecraft:spruce_stairs{facing:north,half:top,shape:outer_right,waterlogged:false}": "minecraft:spruce_stairs{facing:north,half:top,shape:outer_right,waterlogged:false}",
            "minecraft:spruce_stairs{facing:south,half:top,shape:outer_right,waterlogged:false}": "minecraft:spruce_stairs{facing:south,half:top,shape:outer_right,waterlogged:false}",
            "minecraft:spruce_stairs{facing:west,half:top,shape:outer_right,waterlogged:false}": "minecraft:spruce_stairs{facing:west,half:top,shape:outer_right,waterlogged:false}",
            "minecraft:structure_block{mode:data}": "minecraft:structure_block{mode:data}"
        },
        {
            "minecraft:chest{facing:south,type:single,waterlogged:false}": "minecraft:chest{facing:south,type:single,waterlogged:false}",
            "minecraft:oak_door{facing:east,half:upper,hinge:left,open:false,powered:false}": "minecraft:dark_oak_door{facing:east,half:upper,hinge:left,open:false,powered:false}",
            "minecraft:oak_door{facing:south,half:lower,hinge:right,open:false,powered:false}": "minecraft:dark_oak_door{facing:south,half:lower,hinge:right,open:false,powered:false}",
            "minecraft:oak_log{axis:y}": "minecraft:dark_oak_log{axis:y}",
            "minecraft:oak_planks": "minecraft:dark_oak_planks",
            "minecraft:oak_stairs{facing:east,half:bottom,shape:outer_right,waterlogged:false}": "minecraft:dark_oak_stairs{facing:east,half:bottom,shape:outer_right,waterlogged:false}",
            "minecraft:oak_stairs{facing:east,half:top,shape:outer_right,waterlogged:false}": "minecraft:dark_oak_stairs{facing:east,half:top,shape:outer_right,waterlogged:false}",
            "minecraft:oak_stairs{facing:north,half:bottom,shape:outer_right,waterlogged:false}": "minecraft:dark_oak_stairs{facing:north,half:bottom,shape:outer_right,waterlogged:false}",
            "minecraft:oak_stairs{facing:south,half:bottom,shape:outer_right,waterlogged:false}": "minecraft:dark_oak_stairs{facing:south,half:bottom,shape:outer_right,waterlogged:false}",
            "minecraft:oak_stairs{facing:south,half:top,shape:outer_right,waterlogged:false}": "minecraft:dark_oak_stairs{facing:south,half:top,shape:outer_right,waterlogged:false}",
            "minecraft:oak_stairs{facing:west,half:bottom,shape:outer_right,waterlogged:false}": "minecraft:dark_oak_stairs{facing:west,half:bottom,shape:outer_right,waterlogged:false}",
            "minecraft:oak_stairs{facing:west,half:top,shape:outer_right,waterlogged:false}": "minecraft:dark_oak_stairs{facing:west,half:top,shape:outer_right,waterlogged:false}",
            "minecraft:oak_trapdoor{facing:east,half:top,open:false,powered:false,waterlogged:false}": "minecraft:dark_oak_trapdoor{facing:east,half:top,open:false,powered:false,waterlogged:false}",
            "minecraft:oak_trapdoor{facing:north,half:top,open:false,powered:false,waterlogged:false}": "minecraft:dark_oak_trapdoor{facing:north,half:top,open:false,powered:false,waterlogged:false}",
            "minecraft:oak_trapdoor{facing:south,half:top,open:false,powered:false,waterlogged:false}": "minecraft:dark_oak_trapdoor{facing:south,half:top,open:false,powered:false,waterlogged:false}",
            "minecraft:oak_trapdoor{facing:west,half:top,open:false,powered:false,waterlogged:false}": "minecraft:dark_oak_trapdoor{facing:west,half:top,open:false,powered:false,waterlogged:false}",
            "minecraft:spruce_fence{east:false,north:false,south:false,waterlogged:false,west:false}": "minecraft:jungle_fence{east:false,north:false,south:false,waterlogged:false,west:false}",
            "minecraft:spruce_planks": "minecraft:jungle_planks",
            "minecraft:spruce_stairs{facing:east,half:top,shape:outer_right,waterlogged:false}": "minecraft:jungle_stairs{facing:east,half:top,shape:outer_right,waterlogged:false}",
            "minecraft:spruce_stairs{facing:north,half:bottom,shape:outer_right,waterlogged:false}": "minecraft:jungle_stairs{facing:north,half:bottom,shape:outer_right,waterlogged:false}",
            "minecraft:spruce_stairs{facing:north,half:top,shape:outer_right,waterlogged:false}": "minecraft:jungle_stairs{facing:north,half:top,shape:outer_right,waterlogged:false}",
            "minecraft:spruce_stairs{facing:south,half:top,shape:outer_right,waterlogged:false}": "minecraft:jungle_stairs{facing:south,half:top,shape:outer_right,waterlogged:false}",
            "minecraft:spruce_stairs{facing:west,half:top,shape:outer_right,waterlogged:false}": "minecraft:jungle_stairs{facing:west,half:top,shape:outer_right,waterlogged:false}",
            "minecraft:structure_block{mode:data}": "minecraft:structure_block{mode:data}"
        },
        {
            "minecraft:chest{facing:south,type:single,waterlogged:false}": "minecraft:chest{facing:south,type:single,waterlogged:false}",
            "minecraft:oak_door{facing:east,half:upper,hinge:left,open:false,powered:false}": "minecraft:dark_oak_door{facing:east,half:upper,hinge:left,open:false,powered:false}",
            "minecraft:oak_door{facing:south,half:lower,hinge:right,open:false,powered:false}": "minecraft:dark_oak_door{facing:south,half:lower,hinge:right,open:false,powered:false}",
            "minecraft:oak_log{axis:y}": "minecraft:dark_oak_log{axis:y}",
            "minecraft:oak_planks": "minecraft:dark_oak_planks",
            "minecraft:oak_stairs{facing:east,half:bottom,shape:outer_right,waterlogged:false}": "minecraft:dark_oak_stairs{facing:east,half:bottom,shape:outer_right,waterlogged:false}",
            "minecraft:oak_stairs{facing:east,half:top,shape:outer_right,waterlogged:false}": "minecraft:dark_oak_stairs{facing:east,half:top,shape:outer_right,waterlogged:false}",
            "minecraft:oak_stairs{facing:north,half:bottom,shape:outer_right,waterlogged:false}": "minecraft:dark_oak_stairs{facing:north,half:bottom,shape:outer_right,waterlogged:false}",
            "minecraft:oak_stairs{facing:south,half:bottom,shape:outer_right,waterlogged:false}": "minecraft:dark_oak_stairs{facing:south,half:bottom,shape:outer_right,waterlogged:false}",
            "minecraft:oak_stairs{facing:south,half:top,shape:outer_right,waterlogged:false}": "minecraft:dark_oak_stairs{facing:south,half:top,shape:outer_right,waterlogged:false}",
            "minecraft:oak_stairs{facing:west,half:bottom,shape:outer_right,waterlogged:false}": "minecraft:dark_oak_stairs{facing:west,half:bottom,shape:outer_right,waterlogged:false}",
            "minecraft:oak_stairs{facing:west,half:top,shape:outer_right,waterlogged:false}": "minecraft:dark_oak_stairs{facing:west,half:top,shape:outer_right,waterlogged:false}",
            "minecraft:oak_trapdoor{facing:east,half:top,open:false,powered:false,waterlogged:false}": "minecraft:dark_oak_trapdoor{facing:east,half:top,open:false,powered:false,waterlogged:false}",
            "minecraft:oak_trapdoor{facing:north,half:top,open:false,powered:false,waterlogged:false}": "minecraft:dark_oak_trapdoor{facing:north,half:top,open:false,powered:false,waterlogged:false}",
            "minecraft:oak_trapdoor{facing:south,half:top,open:false,powered:false,waterlogged:false}": "minecraft:dark_oak_trapdoor{facing:south,half:top,open:false,powered:false,waterlogged:false}",
            "minecraft:oak_trapdoor{facing:west,half:top,open:false,powered:false,waterlogged:false}": "minecraft:dark_oak_trapdoor{facing:west,half:top,open:false,powered:false,waterlogged:false}",
            "minecraft:spruce_fence{east:false,north:false,south:false,waterlogged:false,west:false}": "minecraft:spruce_fence{east:false,north:false,south:false,waterlogged:false,west:false}",
            "minecraft:spruce_planks": "minecraft:spruce_planks",
            "minecraft:spruce_stairs{facing:east,half:top,shape:outer_right,waterlogged:false}": "minecraft:spruce_stairs{facing:east,half:top,shape:outer_right,waterlogged:false}",
            "minecraft:spruce_stairs{facing:north,half:bottom,shape:outer_right,waterlogged:false}": "minecraft:spruce_stairs{facing:north,half:bottom,shape:outer_right,waterlogged:false}",
            "minecraft:spruce_stairs{facing:north,half:top,shape:outer_right,waterlogged:false}": "minecraft:spruce_stairs{facing:north,half:top,shape:outer_right,waterlogged:false}",
            "minecraft:spruce_stairs{facing:south,half:top,shape:outer_right,waterlogged:false}": "minecraft:spruce_stairs{facing:south,half:top,shape:outer_right,waterlogged:false}",
            "minecraft:spruce_stairs{facing:west,half:top,shape:outer_right,waterlogged:false}": "minecraft:spruce_stairs{facing:west,half:top,shape:outer_right,waterlogged:false}",
            "minecraft:structure_block{mode:data}": "minecraft:structure_block{mode:data}"
        },
        {
            "minecraft:chest{facing:south,type:single,waterlogged:false}": "minecraft:chest{facing:south,type:single,waterlogged:false}",
            "minecraft:oak_door{facing:east,half:upper,hinge:left,open:false,powered:false}": "minecraft:spruce_door{facing:east,half:upper,hinge:left,open:false,powered:false}",
            "minecraft:oak_door{facing:south,half:lower,hinge:right,open:false,powered:false}": "minecraft:spruce_door{facing:south,half:lower,hinge:right,open:false,powered:false}",
            "minecraft:oak_log{axis:y}": "minecraft:spruce_log{axis:y}",
            "minecraft:oak_planks": "minecraft:spruce_planks",
            "minecraft:oak_stairs{facing:east,half:bottom,shape:outer_right,waterlogged:false}": "minecraft:spruce_stairs{facing:east,half:bottom,shape:outer_right,waterlogged:false}",
            "minecraft:oak_stairs{facing:east,half:top,shape:outer_right,waterlogged:false}": "minecraft:spruce_stairs{facing:east,half:top,shape:outer_right,waterlogged:false}",
            "minecraft:oak_stairs{facing:north,half:bottom,shape:outer_right,waterlogged:false}": "minecraft:spruce_stairs{facing:north,half:bottom,shape:outer_right,waterlogged:false}",
            "minecraft:oak_stairs{facing:south,half:bottom,shape:outer_right,waterlogged:false}": "minecraft:spruce_stairs{facing:south,half:bottom,shape:outer_right,waterlogged:false}",
            "minecraft:oak_stairs{facing:south,half:top,shape:outer_right,waterlogged:false}": "minecraft:spruce_stairs{facing:south,half:top,shape:outer_right,waterlogged:false}",
            "minecraft:oak_stairs{facing:west,half:bottom,shape:outer_right,waterlogged:false}": "minecraft:spruce_stairs{facing:west,half:bottom,shape:outer_right,waterlogged:false}",
            "minecraft:oak_stairs{facing:west,half:top,shape:outer_right,waterlogged:false}": "minecraft:spruce_stairs{facing:west,half:top,shape:outer_right,waterlogged:false}",
            "minecraft:oak_trapdoor{facing:east,half:top,open:false,powered:false,waterlogged:false}": "minecraft:spruce_trapdoor{facing:east,half:top,open:false,powered:false,waterlogged:false}",
            "minecraft:oak_trapdoor{facing:north,half:top,open:false,powered:false,waterlogged:false}": "minecraft:spruce_trapdoor{facing:north,half:top,open:false,powered:false,waterlogged:false}",
            "minecraft:oak_trapdoor{facing:south,half:top,open:false,powered:false,waterlogged:false}": "minecraft:spruce_trapdoor{facing:south,half:top,open:false,powered:false,waterlogged:false}",
            "minecraft:oak_trapdoor{facing:west,half:top,open:false,powered:false,waterlogged:false}": "minecraft:spruce_trapdoor{facing:west,half:top,open:false,powered:false,waterlogged:false}",
            "minecraft:spruce_fence{east:false,north:false,south:false,waterlogged:false,west:false}": "minecraft:oak_fence{east:false,north:false,south:false,waterlogged:false,west:false}",
            "minecraft:spruce_planks": "minecraft:oak_planks",
            "minecraft:spruce_stairs{facing:east,half:top,shape:outer_right,waterlogged:false}": "minecraft:oak_stairs{facing:east,half:top,shape:outer_right,waterlogged:false}",
            "minecraft:spruce_stairs{facing:north,half:bottom,shape:outer_right,waterlogged:false}": "minecraft:oak_stairs{facing:north,half:bottom,shape:outer_right,waterlogged:false}",
            "minecraft:spruce_stairs{facing:north,half:top,shape:outer_right,waterlogged:false}": "minecraft:oak_stairs{facing:north,half:top,shape:outer_right,waterlogged:false}",
            "minecraft:spruce_stairs{facing:south,half:top,shape:outer_right,waterlogged:false}": "minecraft:oak_stairs{facing:south,half:top,shape:outer_right,waterlogged:false}",
            "minecraft:spruce_stairs{facing:west,half:top,shape:outer_right,waterlogged:false}": "minecraft:oak_stairs{facing:west,half:top,shape:outer_right,waterlogged:false}",
            "minecraft:structure_block{mode:data}": "minecraft:structure_block{mode:data}"
        },
        {
            "minecraft:chest{facing:south,type:single,waterlogged:false}": "minecraft:chest{facing:south,type:single,waterlogged:false}",
            "minecraft:oak_door{facing:east,half:upper,hinge:left,open:false,powered:false}": "minecraft:spruce_door{facing:east,half:upper,hinge:left,open:false,powered:false}",
            "minecraft:oak_door{facing:south,half:lower,hinge:right,open:false,powered:false}": "minecraft:spruce_door{facing:south,half:lower,hinge:right,open:false,powered:false}",
            "minecraft:oak_log{axis:y}": "minecraft:spruce_log{axis:y}",
            "minecraft:oak_planks": "minecraft:spruce_planks",
            "minecraft:oak_stairs{facing:east,half:bottom,shape:outer_right,waterlogged:false}": "minecraft:spruce_stairs{facing:east,half:bottom,shape:outer_right,waterlogged:false}",
            "minecraft:oak_stairs{facing:east,half:top,shape:outer_right,waterlogged:false}": "minecraft:spruce_stairs{facing:east,half:top,shape:outer_right,waterlogged:false}",
            "minecraft:oak_stairs{facing:north,half:bottom,shape:outer_right,waterlogged:false}": "minecraft:spruce_stairs{facing:north,half:bottom,shape:outer_right,waterlogged:false}",
            "minecraft:oak_stairs{facing:south,half:bottom,shape:outer_right,waterlogged:false}": "minecraft:spruce_stairs{facing:south,half:bottom,shape:outer_right,waterlogged:false}",
            "minecraft:oak_stairs{facing:south,half:top,shape:outer_right,waterlogged:false}": "minecraft:spruce_stairs{facing:south,half:top,shape:outer_right,waterlogged:false}",
            "minecraft:oak_stairs{facing:west,half:bottom,shape:outer_right,waterlogged:false}": "minecraft:spruce_stairs{facing:west,half:bottom,shape:outer_right,waterlogged:false}",
            "minecraft:oak_stairs{facing:west,half:top,shape:outer_right,waterlogged:false}": "minecraft:spruce_stairs{facing:west,half:top,shape:outer_right,waterlogged:false}",
            "minecraft:oak_trapdoor{facing:east,half:top,open:false,powered:false,waterlogged:false}": "minecraft:spruce_trapdoor{facing:east,half:top,open:false,powered:false,waterlogged:false}",
            "minecraft:oak_trapdoor{facing:north,half:top,open:false,powered:false,waterlogged:false}": "minecraft:spruce_trapdoor{facing:north,half:top,open:false,powered:false,waterlogged:false}",
            "minecraft:oak_trapdoor{facing:south,half:top,open:false,powered:false,waterlogged:false}": "minecraft:spruce_trapdoor{facing:south,half:top,open:false,powered:false,waterlogged:false}",
            "minecraft:oak_trapdoor{facing:west,half:top,open:false,powered:false,waterlogged:false}": "minecraft:spruce_trapdoor{facing:west,half:top,open:false,powered:false,waterlogged:false}",
            "minecraft:spruce_fence{east:false,north:false,south:false,waterlogged:false,west:false}": "minecraft:jungle_fence{east:false,north:false,south:false,waterlogged:false,west:false}",
            "minecraft:spruce_planks": "minecraft:jungle_planks",
            "minecraft:spruce_stairs{facing:east,half:top,shape:outer_right,waterlogged:false}": "minecraft:jungle_stairs{facing:east,half:top,shape:outer_right,waterlogged:false}",
            "minecraft:spruce_stairs{facing:north,half:bottom,shape:outer_right,waterlogged:false}": "minecraft:jungle_stairs{facing:north,half:bottom,shape:outer_right,waterlogged:false}",
            "minecraft:spruce_stairs{facing:north,half:top,shape:outer_right,waterlogged:false}": "minecraft:jungle_stairs{facing:north,half:top,shape:outer_right,waterlogged:false}",
            "minecraft:spruce_stairs{facing:south,half:top,shape:outer_right,waterlogged:false}": "minecraft:jungle_stairs{facing:south,half:top,shape:outer_right,waterlogged:false}",
            "minecraft:spruce_stairs{facing:west,half:top,shape:outer_right,waterlogged:false}": "minecraft:jungle_stairs{facing:west,half:top,shape:outer_right,waterlogged:false}",
            "minecraft:structure_block{mode:data}": "minecraft:structure_block{mode:data}"
        },
        {
            "minecraft:chest{facing:south,type:single,waterlogged:false}": "minecraft:chest{facing:south,type:single,waterlogged:false}",
            "minecraft:oak_door{facing:east,half:upper,hinge:left,open:false,powered:false}": "minecraft:spruce_door{facing:east,half:upper,hinge:left,open:false,powered:false}",
            "minecraft:oak_door{facing:south,half:lower,hinge:right,open:false,powered:false}": "minecraft:spruce_door{facing:south,half:lower,hinge:right,open:false,powered:false}",
            "minecraft:oak_log{axis:y}": "minecraft:spruce_log{axis:y}",
            "minecraft:oak_planks": "minecraft:spruce_planks",
            "minecraft:oak_stairs{facing:east,half:bottom,shape:outer_right,waterlogged:false}": "minecraft:spruce_stairs{facing:east,half:bottom,shape:outer_right,waterlogged:false}",
            "minecraft:oak_stairs{facing:east,half:top,shape:outer_right,waterlogged:false}": "minecraft:spruce_stairs{facing:east,half:top,shape:outer_right,waterlogged:false}",
            "minecraft:oak_stairs{facing:north,half:bottom,shape:outer_right,waterlogged:false}": "minecraft:spruce_stairs{facing:north,half:bottom,shape:outer_right,waterlogged:false}",
            "minecraft:oak_stairs{facing:south,half:bottom,shape:outer_right,waterlogged:false}": "minecraft:spruce_stairs{facing:south,half:bottom,shape:outer_right,waterlogged:false}",
            "minecraft:oak_stairs{facing:south,half:top,shape:outer_right,waterlogged:false}": "minecraft:spruce_stairs{facing:south,half:top,shape:outer_right,waterlogged:false}",
            "minecraft:oak_stairs{facing:west,half:bottom,shape:outer_right,waterlogged:false}": "minecraft:spruce_stairs{facing:west,half:bottom,shape:outer_right,waterlogged:false}",
            "minecraft:oak_stairs{facing:west,half:top,shape:outer_right,waterlogged:false}": "minecraft:spruce_stairs{facing:west,half:top,shape:outer_right,waterlogged:false}",
            "minecraft:oak_trapdoor{facing:east,half:top,open:false,powered:false,waterlogged:false}": "minecraft:spruce_trapdoor{facing:east,half:top,open:false,powered:false,waterlogged:false}",
            "minecraft:oak_trapdoor{facing:north,half:top,open:false,powered:false,waterlogged:false}": "minecraft:spruce_trapdoor{facing:north,half:top,open:false,powered:false,waterlogged:false}",
            "minecraft:oak_trapdoor{facing:south,half:top,open:false,powered:false,waterlogged:false}": "minecraft:spruce_trapdoor{facing:south,half:top,open:false,powered:false,waterlogged:false}",
            "minecraft:oak_trapdoor{facing:west,half:top,open:false,powered:false,waterlogged:false}": "minecraft:spruce_trapdoor{facing:west,half:top,open:false,powered:false,waterlogged:false}",
            "minecraft:spruce_fence{east:false,north:false,south:false,waterlogged:false,west:false}": "minecraft:dark_oak_fence{east:false,north:false,south:false,waterlogged:false,west:false}",
            "minecraft:spruce_planks": "minecraft:dark_oak_planks",
            "minecraft:spruce_stairs{facing:east,half:top,shape:outer_right,waterlogged:false}": "minecraft:dark_oak_stairs{facing:east,half:top,shape:outer_right,waterlogged:false}",
            "minecraft:spruce_stairs{facing:north,half:bottom,shape:outer_right,waterlogged:false}": "minecraft:dark_oak_stairs{facing:north,half:bottom,shape:outer_right,waterlogged:false}",
            "minecraft:spruce_stairs{facing:north,half:top,shape:outer_right,waterlogged:false}": "minecraft:dark_oak_stairs{facing:north,half:top,shape:outer_right,waterlogged:false}",
            "minecraft:spruce_stairs{facing:south,half:top,shape:outer_right,waterlogged:false}": "minecraft:dark_oak_stairs{facing:south,half:top,shape:outer_right,waterlogged:false}",
            "minecraft:spruce_stairs{facing:west,half:top,shape:outer_right,waterlogged:false}": "minecraft:dark_oak_stairs{facing:west,half:top,shape:outer_right,waterlogged:false}",
            "minecraft:structure_block{mode:data}": "minecraft:structure_block{mode:data}"
        },
        {
            "minecraft:chest{facing:south,type:single,waterlogged:false}": "minecraft:chest{facing:south,type:single,waterlogged:false}",
            "minecraft:oak_door{facing:east,half:upper,hinge:left,open:false,powered:false}": "minecraft:oak_door{facing:east,half:upper,hinge:left,open:false,powered:false}",
            "minecraft:oak_door{facing:south,half:lower,hinge:right,open:false,powered:false}": "minecraft:oak_door{facing:south,half:lower,hinge:right,open:false,powered:false}",
            "minecraft:oak_log{axis:y}": "minecraft:oak_log{axis:y}",
            "minecraft:oak_planks": "minecraft:oak_planks",
            "minecraft:oak_stairs{facing:east,half:bottom,shape:outer_right,waterlogged:false}": "minecraft:oak_stairs{facing:east,half:bottom,shape:outer_right,waterlogged:false}",
            "minecraft:oak_stairs{facing:east,half:top,shape:outer_right,waterlogged:false}": "minecraft:oak_stairs{facing:east,half:top,shape:outer_right,waterlogged:false}",
            "minecraft:oak_stairs{facing:north,half:bottom,shape:outer_right,waterlogged:false}": "minecraft:oak_stairs{facing:north,half:bottom,shape:outer_right,waterlogged:false}",
            "minecraft:oak_stairs{facing:south,half:bottom,shape:outer_right,waterlogged:false}": "minecraft:oak_stairs{facing:south,half:bottom,shape:outer_right,waterlogged:false}",
            "minecraft:oak_stairs{facing:south,half:top,shape:outer_right,waterlogged:false}": "minecraft:oak_stairs{facing:south,half:top,shape:outer_right,waterlogged:false}",
            "minecraft:oak_stairs{facing:west,half:bottom,shape:outer_right,waterlogged:false}": "minecraft:oak_stairs{facing:west,half:bottom,shape:outer_right,waterlogged:false}",
            "minecraft:oak_stairs{facing:west,half:top,shape:outer_right,waterlogged:false}": "minecraft:oak_stairs{facing:west,half:top,shape:outer_right,waterlogged:false}",
            "minecraft:oak_trapdoor{facing:east,half:top,open:false,powered:false,waterlogged:false}": "minecraft:oak_trapdoor{facing:east,half:top,open:false,powered:false,waterlogged:false}",
            "minecraft:oak_trapdoor{facing:north,half:top,open:false,powered:false,waterlogged:false}": "minecraft:oak_trapdoor{facing:north,half:top,open:false,powered:false,waterlogged:false}",
            "minecraft:oak_trapdoor{facing:south,half:top,open:false,powered:false,waterlogged:false}": "minecraft:oak_trapdoor{facing:south,half:top,open:false,powered:false,waterlogged:false}",
            "minecraft:oak_trapdoor{facing:west,half:top,open:false,powered:false,waterlogged:false}": "minecraft:oak_trapdoor{facing:west,half:top,open:false,powered:false,waterlogged:false}",
            "minecraft:spruce_fence{east:false,north:false,south:false,waterlogged:false,west:false}": "minecraft:birch_fence{east:false,north:false,south:false,waterlogged:false,west:false}",
            "minecraft:spruce_planks": "minecraft:birch_planks",
            "minecraft:spruce_stairs{facing:east,half:top,shape:outer_right,waterlogged:false}": "minecraft:birch_stairs{facing:east,half:top,shape:outer_right,waterlogged:false}",
            "minecraft:spruce_stairs{facing:north,half:bottom,shape:outer_right,waterlogged:false}": "minecraft:birch_stairs{facing:north,half:bottom,shape:outer_right,waterlogged:false}",
            "minecraft:spruce_stairs{facing:north,half:top,shape:outer_right,waterlogged:false}": "minecraft:birch_stairs{facing:north,half:top,shape:outer_right,waterlogged:false}",
            "minecraft:spruce_stairs{facing:south,half:top,shape:outer_right,waterlogged:false}": "minecraft:birch_stairs{facing:south,half:top,shape:outer_right,waterlogged:false}",
            "minecraft:spruce_stairs{facing:west,half:top,shape:outer_right,waterlogged:false}": "minecraft:birch_stairs{facing:west,half:top,shape:outer_right,waterlogged:false}",
            "minecraft:structure_block{mode:data}": "minecraft:structure_block{mode:data}"
        }
    ]
}
