{
    DataVersion: 2856,
    size: [9, 9, 17],
    data: [
        {pos: [0, 0, 10], state: "minecraft:oak_stairs{facing:east,half:top,shape:outer_right,waterlogged:false}"},
        {pos: [0, 0, 11], state: "minecraft:oak_stairs{facing:east,half:top,shape:outer_right,waterlogged:false}"},
        {pos: [0, 0, 12], state: "minecraft:oak_stairs{facing:east,half:top,shape:outer_right,waterlogged:false}"},
        {pos: [1, 0, 9], state: "minecraft:oak_stairs{facing:south,half:bottom,shape:outer_right,waterlogged:false}"},
        {pos: [1, 0, 10], state: "minecraft:oak_planks"},
        {pos: [1, 0, 11], state: "minecraft:oak_planks"},
        {pos: [1, 0, 12], state: "minecraft:oak_planks"},
        {pos: [2, 0, 7], state: "minecraft:oak_stairs{facing:south,half:bottom,shape:outer_right,waterlogged:false}"},
        {pos: [2, 0, 8], state: "minecraft:oak_planks"},
        {pos: [2, 0, 9], state: "minecraft:oak_planks"},
        {pos: [2, 0, 10], state: "minecraft:oak_planks"},
        {pos: [2, 0, 12], state: "minecraft:oak_planks"},
        {pos: [3, 0, 7], state: "minecraft:oak_planks"},
        {pos: [3, 0, 8], state: "minecraft:oak_planks"},
        {pos: [3, 0, 9], state: "minecraft:oak_planks"},
        {pos: [3, 0, 10], state: "minecraft:oak_stairs{facing:west,half:top,shape:outer_right,waterlogged:false}"},
        {pos: [3, 0, 11], state: "minecraft:oak_stairs{facing:west,half:top,shape:outer_right,waterlogged:false}"},
        {pos: [3, 0, 12], state: "minecraft:oak_stairs{facing:north,half:top,shape:outer_right,waterlogged:false}"},
        {pos: [4, 0, 0], state: "minecraft:oak_stairs{facing:west,half:top,shape:outer_right,waterlogged:false}"},
        {pos: [4, 0, 1], state: "minecraft:oak_stairs{facing:west,half:top,shape:outer_right,waterlogged:false}"},
        {pos: [4, 0, 2], state: "minecraft:oak_stairs{facing:west,half:top,shape:outer_right,waterlogged:false}"},
        {pos: [4, 0, 3], state: "minecraft:oak_stairs{facing:west,half:top,shape:outer_right,waterlogged:false}"},
        {pos: [4, 0, 4], state: "minecraft:oak_stairs{facing:west,half:top,shape:outer_right,waterlogged:false}"},
        {pos: [4, 0, 5], state: "minecraft:oak_stairs{facing:west,half:top,shape:outer_right,waterlogged:false}"},
        {pos: [4, 0, 6], state: "minecraft:oak_stairs{facing:west,half:top,shape:outer_right,waterlogged:false}"},
        {pos: [4, 0, 7], state: "minecraft:oak_stairs{facing:west,half:top,shape:outer_right,waterlogged:false}"},
        {pos: [4, 0, 8], state: "minecraft:oak_stairs{facing:west,half:top,shape:outer_right,waterlogged:false}"},
        {pos: [4, 0, 9], state: "minecraft:oak_stairs{facing:west,half:top,shape:outer_right,waterlogged:false}"},
        {pos: [0, 1, 10], state: "minecraft:oak_planks"},
        {pos: [0, 1, 12], state: "minecraft:spruce_fence{east:false,north:false,south:false,waterlogged:false,west:false}"},
        {pos: [0, 1, 13], state: "minecraft:spruce_fence{east:false,north:false,south:false,waterlogged:false,west:false}"},
        {pos: [0, 1, 14], state: "minecraft:oak_planks"},
        {pos: [1, 1, 10], state: "minecraft:oak_planks"},
        {pos: [1, 1, 11], state: "minecraft:spruce_planks"},
        {pos: [1, 1, 12], state: "minecraft:spruce_planks"},
        {pos: [1, 1, 13], state: "minecraft:oak_planks"},
        {pos: [1, 1, 14], state: "minecraft:oak_planks"},
        {pos: [2, 1, 8], state: "minecraft:spruce_stairs{facing:south,half:bottom,shape:outer_right,waterlogged:false}"},
        {pos: [2, 1, 9], state: "minecraft:spruce_planks"},
        {pos: [2, 1, 10], state: "minecraft:oak_fence{east:false,north:false,south:false,waterlogged:false,west:false}"},
        {pos: [2, 1, 12], state: "minecraft:oak_fence{east:false,north:false,south:false,waterlogged:false,west:false}"},
        {pos: [2, 1, 13], state: "minecraft:oak_planks"},
        {pos: [2, 1, 14], state: "minecraft:oak_planks"},
        {pos: [3, 1, 7], state: "minecraft:spruce_stairs{facing:south,half:bottom,shape:outer_right,waterlogged:false}"},
        {pos: [3, 1, 8], state: "minecraft:spruce_planks"},
        {pos: [3, 1, 9], state: "minecraft:oak_planks"},
        {pos: [3, 1, 10], state: "minecraft:oak_planks"},
        {pos: [3, 1, 11], state: "minecraft:oak_stairs{facing:east,half:bottom,shape:outer_right,waterlogged:false}"},
        {pos: [3, 1, 12], state: "minecraft:oak_planks"},
        {pos: [3, 1, 13], state: "minecraft:oak_planks"},
        {pos: [3, 1, 14], state: "minecraft:oak_stairs{facing:north,half:top,shape:outer_right,waterlogged:false}"},
        {pos: [4, 1, 2], state: "minecraft:spruce_planks"},
        {pos: [4, 1, 3], state: "minecraft:spruce_planks"},
        {pos: [4, 1, 4], state: "minecraft:spruce_planks"},
        {pos: [4, 1, 5], state: "minecraft:spruce_planks"},
        {pos: [4, 1, 6], state: "minecraft:spruce_planks"},
        {pos: [4, 1, 7], state: "minecraft:spruce_planks"},
        {pos: [4, 1, 8], state: "minecraft:oak_planks"},
        {pos: [4, 1, 9], state: "minecraft:oak_planks"},
        {pos: [4, 1, 10], state: "minecraft:oak_planks"},
        {pos: [4, 1, 11], state: "minecraft:oak_planks"},
        {pos: [4, 1, 12], state: "minecraft:oak_planks"},
        {pos: [4, 1, 13], state: "minecraft:oak_planks"},
        {pos: [5, 1, 2], state: "minecraft:oak_planks"},
        {pos: [5, 1, 3], state: "minecraft:oak_planks"},
        {pos: [5, 1, 5], state: "minecraft:oak_planks"},
        {pos: [5, 1, 6], state: "minecraft:oak_planks"},
        {pos: [5, 1, 8], state: "minecraft:oak_planks"},
        {pos: [5, 1, 9], state: "minecraft:oak_planks"},
        {pos: [5, 1, 10], state: "minecraft:oak_stairs{facing:west,half:top,shape:outer_right,waterlogged:false}"},
        {pos: [5, 1, 11], state: "minecraft:oak_stairs{facing:west,half:top,shape:outer_right,waterlogged:false}"},
        {pos: [5, 1, 12], state: "minecraft:oak_stairs{facing:west,half:top,shape:outer_right,waterlogged:false}"},
        {pos: [5, 1, 13], state: "minecraft:oak_stairs{facing:west,half:top,shape:outer_right,waterlogged:false}"},
        {pos: [6, 1, 1], state: "minecraft:oak_stairs{facing:west,half:top,shape:outer_right,waterlogged:false}"},
        {pos: [6, 1, 2], state: "minecraft:oak_stairs{facing:west,half:top,shape:outer_right,waterlogged:false}"},
        {pos: [6, 1, 3], state: "minecraft:oak_stairs{facing:west,half:top,shape:outer_right,waterlogged:false}"},
        {pos: [6, 1, 4], state: "minecraft:oak_stairs{facing:west,half:top,shape:outer_right,waterlogged:false}"},
        {pos: [6, 1, 5], state: "minecraft:oak_stairs{facing:west,half:top,shape:outer_right,waterlogged:false}"},
        {pos: [6, 1, 6], state: "minecraft:oak_stairs{facing:west,half:top,shape:outer_right,waterlogged:false}"},
        {pos: [6, 1, 7], state: "minecraft:oak_stairs{facing:west,half:top,shape:outer_right,waterlogged:false}"},
        {pos: [6, 1, 8], state: "minecraft:oak_stairs{facing:west,half:top,shape:outer_right,waterlogged:false}"},
        {pos: [6, 1, 9], state: "minecraft:oak_stairs{facing:west,half:top,shape:outer_right,waterlogged:false}"},
        {pos: [0, 2, 15], state: "minecraft:oak_planks"},
        {pos: [1, 2, 10], state: "minecraft:spruce_planks"},
        {pos: [1, 2, 11], state: "minecraft:spruce_planks"},
        {pos: [1, 2, 12], state: "minecraft:spruce_planks"},
        {pos: [1, 2, 13], state: "minecraft:spruce_planks"},
        {pos: [1, 2, 14], state: "minecraft:spruce_planks"},
        {pos: [1, 2, 15], state: "minecraft:oak_planks"},
        {pos: [2, 2, 8], state: "minecraft:oak_planks"},
        {pos: [2, 2, 9], state: "minecraft:spruce_planks"},
        {pos: [2, 2, 14], state: "minecraft:oak_fence{east:false,north:false,south:false,waterlogged:false,west:false}"},
        {pos: [2, 2, 15], state: "minecraft:oak_stairs{facing:north,half:top,shape:outer_right,waterlogged:false}"},
        {pos: [3, 2, 8], state: "minecraft:oak_planks"},
        {pos: [3, 2, 13], state: "minecraft:chest{facing:north,type:single,waterlogged:false}", nbt: {Items: [], id: "minecraft:chest"}},
        {pos: [3, 2, 14], state: "minecraft:oak_planks"},
        {pos: [4, 2, 3], state: "minecraft:spruce_planks"},
        {pos: [4, 2, 4], state: "minecraft:spruce_planks"},
        {pos: [4, 2, 5], state: "minecraft:spruce_planks"},
        {pos: [4, 2, 6], state: "minecraft:spruce_planks"},
        {pos: [4, 2, 7], state: "minecraft:spruce_planks"},
        {pos: [4, 2, 8], state: "minecraft:spruce_planks"},
        {pos: [4, 2, 9], state: "minecraft:oak_stairs{facing:east,half:bottom,shape:outer_right,waterlogged:false}"},
        {pos: [4, 2, 13], state: "minecraft:oak_stairs{facing:south,half:bottom,shape:outer_right,waterlogged:false}"},
        {pos: [4, 2, 14], state: "minecraft:oak_stairs{facing:north,half:top,shape:outer_right,waterlogged:false}"},
        {pos: [5, 2, 5], state: "minecraft:oak_planks"},
        {pos: [5, 2, 6], state: "minecraft:oak_planks"},
        {pos: [5, 2, 8], state: "minecraft:oak_planks"},
        {pos: [5, 2, 9], state: "minecraft:oak_planks"},
        {pos: [5, 2, 10], state: "minecraft:spruce_planks"},
        {pos: [5, 2, 11], state: "minecraft:spruce_planks"},
        {pos: [5, 2, 12], state: "minecraft:spruce_planks"},
        {pos: [5, 2, 13], state: "minecraft:spruce_planks"},
        {pos: [5, 2, 14], state: "minecraft:oak_stairs{facing:north,half:top,shape:outer_right,waterlogged:false}"},
        {pos: [6, 2, 1], state: "minecraft:oak_stairs{facing:east,half:bottom,shape:outer_right,waterlogged:false}"},
        {pos: [6, 2, 2], state: "minecraft:oak_planks"},
        {pos: [6, 2, 3], state: "minecraft:oak_planks"},
        {pos: [6, 2, 4], state: "minecraft:oak_stairs{facing:east,half:bottom,shape:outer_right,waterlogged:false}"},
        {pos: [6, 2, 5], state: "minecraft:oak_planks"},
        {pos: [6, 2, 6], state: "minecraft:oak_planks"},
        {pos: [6, 2, 7], state: "minecraft:oak_stairs{facing:east,half:bottom,shape:outer_right,waterlogged:false}"},
        {pos: [6, 2, 8], state: "minecraft:oak_planks"},
        {pos: [6, 2, 9], state: "minecraft:oak_planks"},
        {pos: [6, 2, 10], state: "minecraft:oak_stairs{facing:west,half:top,shape:outer_right,waterlogged:false}"},
        {pos: [6, 2, 11], state: "minecraft:oak_stairs{facing:west,half:top,shape:outer_right,waterlogged:false}"},
        {pos: [6, 2, 12], state: "minecraft:oak_stairs{facing:west,half:top,shape:outer_right,waterlogged:false}"},
        {pos: [6, 2, 13], state: "minecraft:oak_stairs{facing:west,half:top,shape:outer_right,waterlogged:false}"},
        {pos: [7, 2, 0], state: "minecraft:oak_stairs{facing:west,half:top,shape:outer_right,waterlogged:false}"},
        {pos: [7, 2, 1], state: "minecraft:oak_stairs{facing:west,half:top,shape:outer_right,waterlogged:false}"},
        {pos: [7, 2, 2], state: "minecraft:oak_stairs{facing:west,half:top,shape:outer_right,waterlogged:false}"},
        {pos: [7, 2, 3], state: "minecraft:oak_stairs{facing:west,half:top,shape:outer_right,waterlogged:false}"},
        {pos: [7, 2, 4], state: "minecraft:oak_stairs{facing:west,half:top,shape:outer_right,waterlogged:false}"},
        {pos: [7, 2, 5], state: "minecraft:oak_stairs{facing:west,half:top,shape:outer_right,waterlogged:false}"},
        {pos: [7, 2, 6], state: "minecraft:oak_stairs{facing:west,half:top,shape:outer_right,waterlogged:false}"},
        {pos: [7, 2, 7], state: "minecraft:oak_stairs{facing:west,half:top,shape:outer_right,waterlogged:false}"},
        {pos: [7, 2, 8], state: "minecraft:oak_stairs{facing:west,half:top,shape:outer_right,waterlogged:false}"},
        {pos: [7, 2, 9], state: "minecraft:oak_stairs{facing:west,half:top,shape:outer_right,waterlogged:false}"},
        {pos: [0, 3, 10], state: "minecraft:oak_planks"},
        {pos: [0, 3, 15], state: "minecraft:spruce_fence{east:false,north:false,south:false,waterlogged:false,west:false}"},
        {pos: [0, 3, 16], state: "minecraft:spruce_fence{east:false,north:false,south:false,waterlogged:false,west:false}"},
        {pos: [1, 3, 10], state: "minecraft:spruce_planks"},
        {pos: [1, 3, 11], state: "minecraft:spruce_planks"},
        {pos: [1, 3, 12], state: "minecraft:spruce_planks"},
        {pos: [1, 3, 13], state: "minecraft:spruce_planks"},
        {pos: [1, 3, 14], state: "minecraft:spruce_planks"},
        {pos: [1, 3, 15], state: "minecraft:spruce_planks"},
        {pos: [1, 3, 16], state: "minecraft:oak_stairs{facing:north,half:top,shape:outer_right,waterlogged:false}"},
        {pos: [2, 3, 9], state: "minecraft:oak_planks"},
        {pos: [2, 3, 15], state: "minecraft:oak_planks"},
        {pos: [3, 3, 8], state: "minecraft:oak_planks"},
        {pos: [3, 3, 13], state: "minecraft:structure_block{mode:data}", nbt: {author: "CascadianBacon", id: "minecraft:structure_block", ignoreEntities: 1b, integrity: 1.0f, metadata: "treasure_chest", mirror: "NONE", mode: "DATA", name: "", posX: 0, posY: 1, posZ: 0, powered: 0b, rotation: "NONE", seed: 0L, showair: 0b, showboundingbox: 1b, sizeX: 0, sizeY: 0, sizeZ: 0}},
        {pos: [3, 3, 14], state: "minecraft:oak_stairs{facing:south,half:bottom,shape:outer_right,waterlogged:false}"},
        {pos: [3, 3, 15], state: "minecraft:oak_stairs{facing:north,half:top,shape:outer_right,waterlogged:false}"},
        {pos: [4, 3, 3], state: "minecraft:oak_trapdoor{facing:east,half:bottom,open:true,powered:false,waterlogged:false}"},
        {pos: [4, 3, 4], state: "minecraft:oak_trapdoor{facing:east,half:bottom,open:true,powered:false,waterlogged:false}"},
        {pos: [4, 3, 5], state: "minecraft:spruce_planks"},
        {pos: [4, 3, 6], state: "minecraft:spruce_planks"},
        {pos: [4, 3, 7], state: "minecraft:spruce_planks"},
        {pos: [4, 3, 8], state: "minecraft:spruce_planks"},
        {pos: [4, 3, 14], state: "minecraft:oak_planks"},
        {pos: [5, 3, 9], state: "minecraft:spruce_planks"},
        {pos: [5, 3, 10], state: "minecraft:spruce_planks"},
        {pos: [5, 3, 11], state: "minecraft:spruce_planks"},
        {pos: [5, 3, 12], state: "minecraft:spruce_planks"},
        {pos: [5, 3, 13], state: "minecraft:spruce_planks"},
        {pos: [5, 3, 14], state: "minecraft:oak_planks"},
        {pos: [6, 3, 8], state: "minecraft:chest{facing:north,type:single,waterlogged:false}", nbt: {Items: [], id: "minecraft:chest"}},
        {pos: [6, 3, 9], state: "minecraft:oak_planks"},
        {pos: [6, 3, 10], state: "minecraft:oak_planks"},
        {pos: [6, 3, 11], state: "minecraft:oak_planks"},
        {pos: [6, 3, 12], state: "minecraft:oak_planks"},
        {pos: [6, 3, 13], state: "minecraft:oak_planks"},
        {pos: [7, 3, 1], state: "minecraft:oak_planks"},
        {pos: [7, 3, 2], state: "minecraft:oak_planks"},
        {pos: [7, 3, 3], state: "minecraft:oak_planks"},
        {pos: [7, 3, 4], state: "minecraft:oak_planks"},
        {pos: [7, 3, 5], state: "minecraft:oak_planks"},
        {pos: [7, 3, 6], state: "minecraft:oak_planks"},
        {pos: [7, 3, 7], state: "minecraft:oak_planks"},
        {pos: [7, 3, 8], state: "minecraft:oak_planks"},
        {pos: [7, 3, 9], state: "minecraft:oak_planks"},
        {pos: [7, 3, 10], state: "minecraft:oak_stairs{facing:west,half:top,shape:outer_right,waterlogged:false}"},
        {pos: [7, 3, 11], state: "minecraft:oak_stairs{facing:west,half:top,shape:outer_right,waterlogged:false}"},
        {pos: [7, 3, 12], state: "minecraft:oak_stairs{facing:west,half:top,shape:outer_right,waterlogged:false}"},
        {pos: [0, 4, 10], state: "minecraft:oak_planks"},
        {pos: [0, 4, 16], state: "minecraft:spruce_fence{east:false,north:false,south:false,waterlogged:false,west:false}"},
        {pos: [1, 4, 10], state: "minecraft:spruce_planks"},
        {pos: [1, 4, 11], state: "minecraft:spruce_planks"},
        {pos: [1, 4, 12], state: "minecraft:spruce_planks"},
        {pos: [1, 4, 13], state: "minecraft:spruce_planks"},
        {pos: [1, 4, 14], state: "minecraft:spruce_planks"},
        {pos: [1, 4, 15], state: "minecraft:spruce_planks"},
        {pos: [1, 4, 16], state: "minecraft:oak_planks"},
        {pos: [3, 4, 5], state: "minecraft:oak_log{axis:x}"},
        {pos: [3, 4, 15], state: "minecraft:oak_planks"},
        {pos: [4, 4, 4], state: "minecraft:oak_trapdoor{facing:east,half:bottom,open:true,powered:false,waterlogged:false}"},
        {pos: [4, 4, 5], state: "minecraft:oak_log{axis:x}"},
        {pos: [4, 4, 6], state: "minecraft:spruce_planks"},
        {pos: [4, 4, 7], state: "minecraft:spruce_planks"},
        {pos: [4, 4, 8], state: "minecraft:spruce_planks"},
        {pos: [4, 4, 14], state: "minecraft:oak_planks"},
        {pos: [4, 4, 15], state: "minecraft:oak_stairs{facing:north,half:top,shape:outer_right,waterlogged:false}"},
        {pos: [5, 4, 5], state: "minecraft:oak_log{axis:x}"},
        {pos: [5, 4, 9], state: "minecraft:spruce_planks"},
        {pos: [5, 4, 10], state: "minecraft:spruce_planks"},
        {pos: [5, 4, 11], state: "minecraft:spruce_planks"},
        {pos: [5, 4, 12], state: "minecraft:spruce_planks"},
        {pos: [5, 4, 13], state: "minecraft:spruce_planks"},
        {pos: [5, 4, 14], state: "minecraft:spruce_fence{east:false,north:false,south:false,waterlogged:false,west:false}"},
        {pos: [6, 4, 5], state: "minecraft:oak_log{axis:x}"},
        {pos: [6, 4, 8], state: "minecraft:structure_block{mode:data}", nbt: {author: "CascadianBacon", id: "minecraft:structure_block", ignoreEntities: 1b, integrity: 1.0f, metadata: "map_chest", mirror: "NONE", mode: "DATA", name: "", posX: 0, posY: 1, posZ: 0, powered: 0b, rotation: "NONE", seed: 0L, showair: 0b, showboundingbox: 1b, sizeX: 0, sizeY: 0, sizeZ: 0}},
        {pos: [6, 4, 9], state: "minecraft:oak_planks"},
        {pos: [6, 4, 10], state: "minecraft:oak_planks"},
        {pos: [6, 4, 11], state: "minecraft:oak_planks"},
        {pos: [6, 4, 12], state: "minecraft:oak_planks"},
        {pos: [6, 4, 13], state: "minecraft:spruce_planks"},
        {pos: [7, 4, 3], state: "minecraft:oak_planks"},
        {pos: [7, 4, 4], state: "minecraft:oak_planks"},
        {pos: [7, 4, 5], state: "minecraft:oak_planks"},
        {pos: [7, 4, 6], state: "minecraft:oak_planks"},
        {pos: [7, 4, 7], state: "minecraft:oak_planks"},
        {pos: [7, 4, 8], state: "minecraft:oak_planks"},
        {pos: [7, 4, 9], state: "minecraft:oak_planks"},
        {pos: [7, 4, 10], state: "minecraft:spruce_planks"},
        {pos: [7, 4, 11], state: "minecraft:spruce_planks"},
        {pos: [7, 4, 12], state: "minecraft:spruce_planks"},
        {pos: [8, 4, 1], state: "minecraft:spruce_planks"},
        {pos: [8, 4, 2], state: "minecraft:spruce_planks"},
        {pos: [8, 4, 3], state: "minecraft:spruce_planks"},
        {pos: [8, 4, 4], state: "minecraft:spruce_planks"},
        {pos: [8, 4, 5], state: "minecraft:spruce_planks"},
        {pos: [8, 4, 6], state: "minecraft:spruce_planks"},
        {pos: [8, 4, 7], state: "minecraft:spruce_planks"},
        {pos: [8, 4, 8], state: "minecraft:spruce_planks"},
        {pos: [8, 4, 9], state: "minecraft:spruce_planks"},
        {pos: [8, 4, 10], state: "minecraft:spruce_stairs{facing:north,half:top,shape:outer_right,waterlogged:false}"},
        {pos: [0, 5, 10], state: "minecraft:oak_planks"},
        {pos: [0, 5, 15], state: "minecraft:spruce_fence{east:false,north:false,south:false,waterlogged:false,west:false}"},
        {pos: [0, 5, 16], state: "minecraft:spruce_fence{east:false,north:false,south:false,waterlogged:false,west:false}"},
        {pos: [1, 5, 10], state: "minecraft:spruce_planks"},
        {pos: [1, 5, 11], state: "minecraft:spruce_planks"},
        {pos: [1, 5, 12], state: "minecraft:spruce_planks"},
        {pos: [1, 5, 13], state: "minecraft:spruce_planks"},
        {pos: [1, 5, 14], state: "minecraft:spruce_planks"},
        {pos: [1, 5, 15], state: "minecraft:spruce_planks"},
        {pos: [1, 5, 16], state: "minecraft:oak_stairs{facing:north,half:bottom,shape:outer_right,waterlogged:false}"},
        {pos: [2, 5, 9], state: "minecraft:oak_planks"},
        {pos: [2, 5, 15], state: "minecraft:oak_planks"},
        {pos: [3, 5, 8], state: "minecraft:oak_planks"},
        {pos: [3, 5, 14], state: "minecraft:oak_stairs{facing:south,half:top,shape:outer_right,waterlogged:false}"},
        {pos: [3, 5, 15], state: "minecraft:oak_stairs{facing:north,half:bottom,shape:outer_right,waterlogged:false}"},
        {pos: [4, 5, 5], state: "minecraft:spruce_planks"},
        {pos: [4, 5, 6], state: "minecraft:spruce_planks"},
        {pos: [4, 5, 7], state: "minecraft:spruce_planks"},
        {pos: [4, 5, 8], state: "minecraft:spruce_planks"},
        {pos: [4, 5, 14], state: "minecraft:oak_planks"},
        {pos: [5, 5, 5], state: "minecraft:oak_planks"},
        {pos: [5, 5, 9], state: "minecraft:spruce_planks"},
        {pos: [5, 5, 10], state: "minecraft:spruce_planks"},
        {pos: [5, 5, 11], state: "minecraft:spruce_planks"},
        {pos: [5, 5, 12], state: "minecraft:spruce_planks"},
        {pos: [5, 5, 13], state: "minecraft:spruce_planks"},
        {pos: [5, 5, 14], state: "minecraft:oak_planks"},
        {pos: [6, 5, 5], state: "minecraft:oak_planks"},
        {pos: [6, 5, 9], state: "minecraft:oak_planks"},
        {pos: [6, 5, 10], state: "minecraft:oak_planks"},
        {pos: [6, 5, 11], state: "minecraft:oak_planks"},
        {pos: [6, 5, 12], state: "minecraft:oak_planks"},
        {pos: [6, 5, 13], state: "minecraft:oak_planks"},
        {pos: [7, 5, 4], state: "minecraft:oak_planks"},
        {pos: [7, 5, 5], state: "minecraft:oak_planks"},
        {pos: [7, 5, 6], state: "minecraft:oak_planks"},
        {pos: [7, 5, 7], state: "minecraft:oak_planks"},
        {pos: [7, 5, 8], state: "minecraft:oak_planks"},
        {pos: [7, 5, 9], state: "minecraft:oak_planks"},
        {pos: [7, 5, 10], state: "minecraft:oak_stairs{facing:west,half:bottom,shape:outer_right,waterlogged:false}"},
        {pos: [7, 5, 11], state: "minecraft:oak_stairs{facing:west,half:bottom,shape:outer_right,waterlogged:false}"},
        {pos: [7, 5, 12], state: "minecraft:oak_stairs{facing:west,half:bottom,shape:outer_right,waterlogged:false}"},
        {pos: [0, 6, 15], state: "minecraft:oak_planks"},
        {pos: [1, 6, 10], state: "minecraft:spruce_planks"},
        {pos: [1, 6, 11], state: "minecraft:spruce_planks"},
        {pos: [1, 6, 12], state: "minecraft:spruce_planks"},
        {pos: [1, 6, 13], state: "minecraft:spruce_planks"},
        {pos: [1, 6, 14], state: "minecraft:spruce_planks"},
        {pos: [1, 6, 15], state: "minecraft:oak_planks"},
        {pos: [2, 6, 8], state: "minecraft:oak_planks"},
        {pos: [2, 6, 9], state: "minecraft:spruce_planks"},
        {pos: [2, 6, 14], state: "minecraft:oak_fence{east:false,north:false,south:false,waterlogged:false,west:false}"},
        {pos: [2, 6, 15], state: "minecraft:oak_stairs{facing:north,half:bottom,shape:outer_right,waterlogged:false}"},
        {pos: [3, 6, 8], state: "minecraft:oak_planks"},
        {pos: [3, 6, 14], state: "minecraft:oak_planks"},
        {pos: [4, 6, 5], state: "minecraft:spruce_planks"},
        {pos: [4, 6, 6], state: "minecraft:spruce_planks"},
        {pos: [4, 6, 7], state: "minecraft:spruce_planks"},
        {pos: [4, 6, 8], state: "minecraft:spruce_planks"},
        {pos: [4, 6, 9], state: "minecraft:oak_stairs{facing:east,half:top,shape:outer_right,waterlogged:false}"},
        {pos: [4, 6, 13], state: "minecraft:oak_stairs{facing:south,half:top,shape:outer_right,waterlogged:false}"},
        {pos: [4, 6, 14], state: "minecraft:oak_stairs{facing:north,half:bottom,shape:outer_right,waterlogged:false}"},
        {pos: [5, 6, 6], state: "minecraft:oak_planks"},
        {pos: [5, 6, 8], state: "minecraft:oak_planks"},
        {pos: [5, 6, 9], state: "minecraft:oak_planks"},
        {pos: [5, 6, 10], state: "minecraft:spruce_planks"},
        {pos: [5, 6, 11], state: "minecraft:spruce_planks"},
        {pos: [5, 6, 12], state: "minecraft:spruce_planks"},
        {pos: [5, 6, 13], state: "minecraft:spruce_planks"},
        {pos: [5, 6, 14], state: "minecraft:oak_stairs{facing:north,half:bottom,shape:outer_right,waterlogged:false}"},
        {pos: [6, 6, 6], state: "minecraft:oak_planks"},
        {pos: [6, 6, 7], state: "minecraft:oak_stairs{facing:east,half:top,shape:outer_right,waterlogged:false}"},
        {pos: [6, 6, 8], state: "minecraft:oak_planks"},
        {pos: [6, 6, 9], state: "minecraft:oak_planks"},
        {pos: [6, 6, 10], state: "minecraft:oak_stairs{facing:west,half:bottom,shape:outer_right,waterlogged:false}"},
        {pos: [6, 6, 11], state: "minecraft:oak_stairs{facing:west,half:bottom,shape:outer_right,waterlogged:false}"},
        {pos: [6, 6, 12], state: "minecraft:oak_stairs{facing:west,half:bottom,shape:outer_right,waterlogged:false}"},
        {pos: [6, 6, 13], state: "minecraft:oak_stairs{facing:west,half:bottom,shape:outer_right,waterlogged:false}"},
        {pos: [7, 6, 4], state: "minecraft:oak_stairs{facing:west,half:bottom,shape:outer_right,waterlogged:false}"},
        {pos: [7, 6, 5], state: "minecraft:oak_stairs{facing:west,half:bottom,shape:outer_right,waterlogged:false}"},
        {pos: [7, 6, 6], state: "minecraft:oak_stairs{facing:west,half:bottom,shape:outer_right,waterlogged:false}"},
        {pos: [7, 6, 7], state: "minecraft:oak_stairs{facing:west,half:bottom,shape:outer_right,waterlogged:false}"},
        {pos: [7, 6, 8], state: "minecraft:oak_stairs{facing:west,half:bottom,shape:outer_right,waterlogged:false}"},
        {pos: [7, 6, 9], state: "minecraft:oak_stairs{facing:west,half:bottom,shape:outer_right,waterlogged:false}"},
        {pos: [0, 7, 10], state: "minecraft:oak_planks"},
        {pos: [0, 7, 12], state: "minecraft:spruce_fence{east:false,north:false,south:false,waterlogged:false,west:false}"},
        {pos: [0, 7, 13], state: "minecraft:spruce_fence{east:false,north:false,south:false,waterlogged:false,west:false}"},
        {pos: [0, 7, 14], state: "minecraft:oak_planks"},
        {pos: [1, 7, 10], state: "minecraft:oak_planks"},
        {pos: [1, 7, 11], state: "minecraft:spruce_planks"},
        {pos: [1, 7, 12], state: "minecraft:spruce_planks"},
        {pos: [1, 7, 13], state: "minecraft:oak_planks"},
        {pos: [1, 7, 14], state: "minecraft:oak_planks"},
        {pos: [2, 7, 8], state: "minecraft:spruce_stairs{facing:south,half:top,shape:outer_right,waterlogged:false}"},
        {pos: [2, 7, 9], state: "minecraft:spruce_planks"},
        {pos: [2, 7, 10], state: "minecraft:oak_fence{east:false,north:false,south:false,waterlogged:false,west:false}"},
        {pos: [2, 7, 12], state: "minecraft:oak_fence{east:false,north:false,south:false,waterlogged:false,west:false}"},
        {pos: [2, 7, 13], state: "minecraft:oak_planks"},
        {pos: [2, 7, 14], state: "minecraft:oak_planks"},
        {pos: [3, 7, 7], state: "minecraft:spruce_stairs{facing:south,half:top,shape:outer_right,waterlogged:false}"},
        {pos: [3, 7, 8], state: "minecraft:spruce_planks"},
        {pos: [3, 7, 9], state: "minecraft:oak_planks"},
        {pos: [3, 7, 10], state: "minecraft:oak_planks"},
        {pos: [3, 7, 11], state: "minecraft:oak_stairs{facing:east,half:top,shape:outer_right,waterlogged:false}"},
        {pos: [3, 7, 12], state: "minecraft:oak_planks"},
        {pos: [3, 7, 13], state: "minecraft:oak_planks"},
        {pos: [3, 7, 14], state: "minecraft:oak_stairs{facing:north,half:bottom,shape:outer_right,waterlogged:false}"},
        {pos: [4, 7, 6], state: "minecraft:oak_planks"},
        {pos: [4, 7, 7], state: "minecraft:oak_planks"},
        {pos: [4, 7, 8], state: "minecraft:oak_planks"},
        {pos: [4, 7, 9], state: "minecraft:oak_planks"},
        {pos: [4, 7, 10], state: "minecraft:oak_planks"},
        {pos: [4, 7, 11], state: "minecraft:oak_planks"},
        {pos: [4, 7, 12], state: "minecraft:oak_planks"},
        {pos: [4, 7, 13], state: "minecraft:oak_planks"},
        {pos: [5, 7, 8], state: "minecraft:oak_planks"},
        {pos: [5, 7, 9], state: "minecraft:oak_planks"},
        {pos: [5, 7, 10], state: "minecraft:oak_stairs{facing:west,half:bottom,shape:outer_right,waterlogged:false}"},
        {pos: [5, 7, 11], state: "minecraft:oak_stairs{facing:west,half:bottom,shape:outer_right,waterlogged:false}"},
        {pos: [5, 7, 12], state: "minecraft:oak_stairs{facing:west,half:bottom,shape:outer_right,waterlogged:false}"},
        {pos: [5, 7, 13], state: "minecraft:oak_stairs{facing:west,half:bottom,shape:outer_right,waterlogged:false}"},
        {pos: [6, 7, 6], state: "minecraft:oak_stairs{facing:west,half:bottom,shape:outer_right,waterlogged:false}"},
        {pos: [6, 7, 7], state: "minecraft:oak_stairs{facing:west,half:bottom,shape:outer_right,waterlogged:false}"},
        {pos: [6, 7, 8], state: "minecraft:oak_stairs{facing:west,half:bottom,shape:outer_right,waterlogged:false}"},
        {pos: [6, 7, 9], state: "minecraft:oak_stairs{facing:west,half:bottom,shape:outer_right,waterlogged:false}"},
        {pos: [0, 8, 10], state: "minecraft:oak_stairs{facing:east,half:bottom,shape:outer_right,waterlogged:false}"},
        {pos: [0, 8, 11], state: "minecraft:oak_stairs{facing:east,half:bottom,shape:outer_right,waterlogged:false}"},
        {pos: [0, 8, 12], state: "minecraft:oak_stairs{facing:east,half:bottom,shape:outer_right,waterlogged:false}"},
        {pos: [1, 8, 9], state: "minecraft:oak_stairs{facing:south,half:bottom,shape:outer_right,waterlogged:false}"},
        {pos: [1, 8, 10], state: "minecraft:oak_planks"},
        {pos: [1, 8, 11], state: "minecraft:oak_planks"},
        {pos: [1, 8, 12], state: "minecraft:oak_planks"},
        {pos: [2, 8, 7], state: "minecraft:oak_stairs{facing:south,half:top,shape:outer_right,waterlogged:false}"},
        {pos: [2, 8, 8], state: "minecraft:oak_planks"},
        {pos: [2, 8, 9], state: "minecraft:oak_planks"},
        {pos: [2, 8, 10], state: "minecraft:oak_planks"},
        {pos: [2, 8, 12], state: "minecraft:oak_planks"},
        {pos: [3, 8, 8], state: "minecraft:oak_planks"},
        {pos: [3, 8, 9], state: "minecraft:oak_planks"},
        {pos: [3, 8, 10], state: "minecraft:oak_stairs{facing:west,half:bottom,shape:outer_right,waterlogged:false}"},
        {pos: [3, 8, 11], state: "minecraft:oak_stairs{facing:west,half:bottom,shape:outer_right,waterlogged:false}"},
        {pos: [3, 8, 12], state: "minecraft:oak_stairs{facing:west,half:bottom,shape:outer_right,waterlogged:false}"},
        {pos: [4, 8, 7], state: "minecraft:oak_stairs{facing:west,half:bottom,shape:outer_right,waterlogged:false}"},
        {pos: [4, 8, 8], state: "minecraft:oak_stairs{facing:west,half:bottom,shape:outer_right,waterlogged:false}"},
        {pos: [4, 8, 9], state: "minecraft:oak_stairs{facing:west,half:bottom,shape:outer_right,waterlogged:false}"}
    ],
    entities: [],
    palette: [
        "minecraft:oak_planks",
        "minecraft:spruce_planks",
        "minecraft:oak_log{axis:x}",
        "minecraft:oak_stairs{facing:east,half:top,shape:outer_right,waterlogged:false}",
        "minecraft:oak_stairs{facing:south,half:bottom,shape:outer_right,waterlogged:false}",
        "minecraft:oak_stairs{facing:west,half:top,shape:outer_right,waterlogged:false}",
        "minecraft:oak_stairs{facing:north,half:top,shape:outer_right,waterlogged:false}",
        "minecraft:spruce_fence{east:false,north:false,south:false,waterlogged:false,west:false}",
        "minecraft:spruce_stairs{facing:south,half:bottom,shape:outer_right,waterlogged:false}",
        "minecraft:oak_fence{east:false,north:false,south:false,waterlogged:false,west:false}",
        "minecraft:oak_stairs{facing:east,half:bottom,shape:outer_right,waterlogged:false}",
        "minecraft:oak_trapdoor{facing:east,half:bottom,open:true,powered:false,waterlogged:false}",
        "minecraft:spruce_stairs{facing:north,half:top,shape:outer_right,waterlogged:false}",
        "minecraft:oak_stairs{facing:north,half:bottom,shape:outer_right,waterlogged:false}",
        "minecraft:oak_stairs{facing:south,half:top,shape:outer_right,waterlogged:false}",
        "minecraft:oak_stairs{facing:west,half:bottom,shape:outer_right,waterlogged:false}",
        "minecraft:spruce_stairs{facing:south,half:top,shape:outer_right,waterlogged:false}",
        "minecraft:chest{facing:north,type:single,waterlogged:false}",
        "minecraft:structure_block{mode:data}"
    ],
    palettes: [
        {
            "minecraft:chest{facing:north,type:single,waterlogged:false}": "minecraft:chest{facing:north,type:single,waterlogged:false}",
            "minecraft:oak_fence{east:false,north:false,south:false,waterlogged:false,west:false}": "minecraft:oak_fence{east:false,north:false,south:false,waterlogged:false,west:false}",
            "minecraft:oak_log{axis:x}": "minecraft:oak_log{axis:x}",
            "minecraft:oak_planks": "minecraft:oak_planks",
            "minecraft:oak_stairs{facing:east,half:bottom,shape:outer_right,waterlogged:false}": "minecraft:oak_stairs{facing:east,half:bottom,shape:outer_right,waterlogged:false}",
            "minecraft:oak_stairs{facing:east,half:top,shape:outer_right,waterlogged:false}": "minecraft:oak_stairs{facing:east,half:top,shape:outer_right,waterlogged:false}",
            "minecraft:oak_stairs{facing:north,half:bottom,shape:outer_right,waterlogged:false}": "minecraft:oak_stairs{facing:north,half:bottom,shape:outer_right,waterlogged:false}",
            "minecraft:oak_stairs{facing:north,half:top,shape:outer_right,waterlogged:false}": "minecraft:oak_stairs{facing:north,half:top,shape:outer_right,waterlogged:false}",
            "minecraft:oak_stairs{facing:south,half:bottom,shape:outer_right,waterlogged:false}": "minecraft:oak_stairs{facing:south,half:bottom,shape:outer_right,waterlogged:false}",
            "minecraft:oak_stairs{facing:south,half:top,shape:outer_right,waterlogged:false}": "minecraft:oak_stairs{facing:south,half:top,shape:outer_right,waterlogged:false}",
            "minecraft:oak_stairs{facing:west,half:bottom,shape:outer_right,waterlogged:false}": "minecraft:oak_stairs{facing:west,half:bottom,shape:outer_right,waterlogged:false}",
            "minecraft:oak_stairs{facing:west,half:top,shape:outer_right,waterlogged:false}": "minecraft:oak_stairs{facing:west,half:top,shape:outer_right,waterlogged:false}",
            "minecraft:oak_trapdoor{facing:east,half:bottom,open:true,powered:false,waterlogged:false}": "minecraft:oak_trapdoor{facing:east,half:bottom,open:true,powered:false,waterlogged:false}",
            "minecraft:spruce_fence{east:false,north:false,south:false,waterlogged:false,west:false}": "minecraft:spruce_fence{east:false,north:false,south:false,waterlogged:false,west:false}",
            "minecraft:spruce_planks": "minecraft:spruce_planks",
            "minecraft:spruce_stairs{facing:north,half:top,shape:outer_right,waterlogged:false}": "minecraft:spruce_stairs{facing:north,half:top,shape:outer_right,waterlogged:false}",
            "minecraft:spruce_stairs{facing:south,half:bottom,shape:outer_right,waterlogged:false}": "minecraft:spruce_stairs{facing:south,half:bottom,shape:outer_right,waterlogged:false}",
            "minecraft:spruce_stairs{facing:south,half:top,shape:outer_right,waterlogged:false}": "minecraft:spruce_stairs{facing:south,half:top,shape:outer_right,waterlogged:false}",
            "minecraft:structure_block{mode:data}": "minecraft:structure_block{mode:data}"
        },
        {
            "minecraft:chest{facing:north,type:single,waterlogged:false}": "minecraft:chest{facing:north,type:single,waterlogged:false}",
            "minecraft:oak_fence{east:false,north:false,south:false,waterlogged:false,west:false}": "minecraft:jungle_fence{east:false,north:false,south:false,waterlogged:false,west:false}",
            "minecraft:oak_log{axis:x}": "minecraft:jungle_log{axis:x}",
            "minecraft:oak_planks": "minecraft:jungle_planks",
            "minecraft:oak_stairs{facing:east,half:bottom,shape:outer_right,waterlogged:false}": "minecraft:jungle_stairs{facing:east,half:bottom,shape:outer_right,waterlogged:false}",
            "minecraft:oak_stairs{facing:east,half:top,shape:outer_right,waterlogged:false}": "minecraft:jungle_stairs{facing:east,half:top,shape:outer_right,waterlogged:false}",
            "minecraft:oak_stairs{facing:north,half:bottom,shape:outer_right,waterlogged:false}": "minecraft:jungle_stairs{facing:north,half:bottom,shape:outer_right,waterlogged:false}",
            "minecraft:oak_stairs{facing:north,half:top,shape:outer_right,waterlogged:false}": "minecraft:jungle_stairs{facing:north,half:top,shape:outer_right,waterlogged:false}",
            "minecraft:oak_stairs{facing:south,half:bottom,shape:outer_right,waterlogged:false}": "minecraft:jungle_stairs{facing:south,half:bottom,shape:outer_right,waterlogged:false}",
            "minecraft:oak_stairs{facing:south,half:top,shape:outer_right,waterlogged:false}": "minecraft:jungle_stairs{facing:south,half:top,shape:outer_right,waterlogged:false}",
            "minecraft:oak_stairs{facing:west,half:bottom,shape:outer_right,waterlogged:false}": "minecraft:jungle_stairs{facing:west,half:bottom,shape:outer_right,waterlogged:false}",
            "minecraft:oak_stairs{facing:west,half:top,shape:outer_right,waterlogged:false}": "minecraft:jungle_stairs{facing:west,half:top,shape:outer_right,waterlogged:false}",
            "minecraft:oak_trapdoor{facing:east,half:bottom,open:true,powered:false,waterlogged:false}": "minecraft:jungle_trapdoor{facing:east,half:bottom,open:true,powered:false,waterlogged:false}",
            "minecraft:spruce_fence{east:false,north:false,south:false,waterlogged:false,west:false}": "minecraft:spruce_fence{east:false,north:false,south:false,waterlogged:false,west:false}",
            "minecraft:spruce_planks": "minecraft:spruce_planks",
            "minecraft:spruce_stairs{facing:north,half:top,shape:outer_right,waterlogged:false}": "minecraft:spruce_stairs{facing:north,half:top,shape:outer_right,waterlogged:false}",
            "minecraft:spruce_stairs{facing:south,half:bottom,shape:outer_right,waterlogged:false}": "minecraft:spruce_stairs{facing:south,half:bottom,shape:outer_right,waterlogged:false}",
            "minecraft:spruce_stairs{facing:south,half:top,shape:outer_right,waterlogged:false}": "minecraft:spruce_stairs{facing:south,half:top,shape:outer_right,waterlogged:false}",
            "minecraft:structure_block{mode:data}": "minecraft:structure_block{mode:data}"
        },
        {
            "minecraft:chest{facing:north,type:single,waterlogged:false}": "minecraft:chest{facing:north,type:single,waterlogged:false}",
            "minecraft:oak_fence{east:false,north:false,south:false,waterlogged:false,west:false}": "minecraft:dark_oak_fence{east:false,north:false,south:false,waterlogged:false,west:false}",
            "minecraft:oak_log{axis:x}": "minecraft:dark_oak_log{axis:x}",
            "minecraft:oak_planks": "minecraft:dark_oak_planks",
            "minecraft:oak_stairs{facing:east,half:bottom,shape:outer_right,waterlogged:false}": "minecraft:dark_oak_stairs{facing:east,half:bottom,shape:outer_right,waterlogged:false}",
            "minecraft:oak_stairs{facing:east,half:top,shape:outer_right,waterlogged:false}": "minecraft:dark_oak_stairs{facing:east,half:top,shape:outer_right,waterlogged:false}",
            "minecraft:oak_stairs{facing:north,half:bottom,shape:outer_right,waterlogged:false}": "minecraft:dark_oak_stairs{facing:north,half:bottom,shape:outer_right,waterlogged:false}",
            "minecraft:oak_stairs{facing:north,half:top,shape:outer_right,waterlogged:false}": "minecraft:dark_oak_stairs{facing:north,half:top,shape:outer_right,waterlogged:false}",
            "minecraft:oak_stairs{facing:south,half:bottom,shape:outer_right,waterlogged:false}": "minecraft:dark_oak_stairs{facing:south,half:bottom,shape:outer_right,waterlogged:false}",
            "minecraft:oak_stairs{facing:south,half:top,shape:outer_right,waterlogged:false}": "minecraft:dark_oak_stairs{facing:south,half:top,shape:outer_right,waterlogged:false}",
            "minecraft:oak_stairs{facing:west,half:bottom,shape:outer_right,waterlogged:false}": "minecraft:dark_oak_stairs{facing:west,half:bottom,shape:outer_right,waterlogged:false}",
            "minecraft:oak_stairs{facing:west,half:top,shape:outer_right,waterlogged:false}": "minecraft:dark_oak_stairs{facing:west,half:top,shape:outer_right,waterlogged:false}",
            "minecraft:oak_trapdoor{facing:east,half:bottom,open:true,powered:false,waterlogged:false}": "minecraft:dark_oak_trapdoor{facing:east,half:bottom,open:true,powered:false,waterlogged:false}",
            "minecraft:spruce_fence{east:false,north:false,south:false,waterlogged:false,west:false}": "minecraft:jungle_fence{east:false,north:false,south:false,waterlogged:false,west:false}",
            "minecraft:spruce_planks": "minecraft:jungle_planks",
            "minecraft:spruce_stairs{facing:north,half:top,shape:outer_right,waterlogged:false}": "minecraft:jungle_stairs{facing:north,half:top,shape:outer_right,waterlogged:false}",
            "minecraft:spruce_stairs{facing:south,half:bottom,shape:outer_right,waterlogged:false}": "minecraft:jungle_stairs{facing:south,half:bottom,shape:outer_right,waterlogged:false}",
            "minecraft:spruce_stairs{facing:south,half:top,shape:outer_right,waterlogged:false}": "minecraft:jungle_stairs{facing:south,half:top,shape:outer_right,waterlogged:false}",
            "minecraft:structure_block{mode:data}": "minecraft:structure_block{mode:data}"
        },
        {
            "minecraft:chest{facing:north,type:single,waterlogged:false}": "minecraft:chest{facing:north,type:single,waterlogged:false}",
            "minecraft:oak_fence{east:false,north:false,south:false,waterlogged:false,west:false}": "minecraft:dark_oak_fence{east:false,north:false,south:false,waterlogged:false,west:false}",
            "minecraft:oak_log{axis:x}": "minecraft:dark_oak_log{axis:x}",
            "minecraft:oak_planks": "minecraft:dark_oak_planks",
            "minecraft:oak_stairs{facing:east,half:bottom,shape:outer_right,waterlogged:false}": "minecraft:dark_oak_stairs{facing:east,half:bottom,shape:outer_right,waterlogged:false}",
            "minecraft:oak_stairs{facing:east,half:top,shape:outer_right,waterlogged:false}": "minecraft:dark_oak_stairs{facing:east,half:top,shape:outer_right,waterlogged:false}",
            "minecraft:oak_stairs{facing:north,half:bottom,shape:outer_right,waterlogged:false}": "minecraft:dark_oak_stairs{facing:north,half:bottom,shape:outer_right,waterlogged:false}",
            "minecraft:oak_stairs{facing:north,half:top,shape:outer_right,waterlogged:false}": "minecraft:dark_oak_stairs{facing:north,half:top,shape:outer_right,waterlogged:false}",
            "minecraft:oak_stairs{facing:south,half:bottom,shape:outer_right,waterlogged:false}": "minecraft:dark_oak_stairs{facing:south,half:bottom,shape:outer_right,waterlogged:false}",
            "minecraft:oak_stairs{facing:south,half:top,shape:outer_right,waterlogged:false}": "minecraft:dark_oak_stairs{facing:south,half:top,shape:outer_right,waterlogged:false}",
            "minecraft:oak_stairs{facing:west,half:bottom,shape:outer_right,waterlogged:false}": "minecraft:dark_oak_stairs{facing:west,half:bottom,shape:outer_right,waterlogged:false}",
            "minecraft:oak_stairs{facing:west,half:top,shape:outer_right,waterlogged:false}": "minecraft:dark_oak_stairs{facing:west,half:top,shape:outer_right,waterlogged:false}",
            "minecraft:oak_trapdoor{facing:east,half:bottom,open:true,powered:false,waterlogged:false}": "minecraft:dark_oak_trapdoor{facing:east,half:bottom,open:true,powered:false,waterlogged:false}",
            "minecraft:spruce_fence{east:false,north:false,south:false,waterlogged:false,west:false}": "minecraft:spruce_fence{east:false,north:false,south:false,waterlogged:false,west:false}",
            "minecraft:spruce_planks": "minecraft:spruce_planks",
            "minecraft:spruce_stairs{facing:north,half:top,shape:outer_right,waterlogged:false}": "minecraft:spruce_stairs{facing:north,half:top,shape:outer_right,waterlogged:false}",
            "minecraft:spruce_stairs{facing:south,half:bottom,shape:outer_right,waterlogged:false}": "minecraft:spruce_stairs{facing:south,half:bottom,shape:outer_right,waterlogged:false}",
            "minecraft:spruce_stairs{facing:south,half:top,shape:outer_right,waterlogged:false}": "minecraft:spruce_stairs{facing:south,half:top,shape:outer_right,waterlogged:false}",
            "minecraft:structure_block{mode:data}": "minecraft:structure_block{mode:data}"
        },
        {
            "minecraft:chest{facing:north,type:single,waterlogged:false}": "minecraft:chest{facing:north,type:single,waterlogged:false}",
            "minecraft:oak_fence{east:false,north:false,south:false,waterlogged:false,west:false}": "minecraft:spruce_fence{east:false,north:false,south:false,waterlogged:false,west:false}",
            "minecraft:oak_log{axis:x}": "minecraft:spruce_log{axis:x}",
            "minecraft:oak_planks": "minecraft:spruce_planks",
            "minecraft:oak_stairs{facing:east,half:bottom,shape:outer_right,waterlogged:false}": "minecraft:spruce_stairs{facing:east,half:bottom,shape:outer_right,waterlogged:false}",
            "minecraft:oak_stairs{facing:east,half:top,shape:outer_right,waterlogged:false}": "minecraft:spruce_stairs{facing:east,half:top,shape:outer_right,waterlogged:false}",
            "minecraft:oak_stairs{facing:north,half:bottom,shape:outer_right,waterlogged:false}": "minecraft:spruce_stairs{facing:north,half:bottom,shape:outer_right,waterlogged:false}",
            "minecraft:oak_stairs{facing:north,half:top,shape:outer_right,waterlogged:false}": "minecraft:spruce_stairs{facing:north,half:top,shape:outer_right,waterlogged:false}",
            "minecraft:oak_stairs{facing:south,half:bottom,shape:outer_right,waterlogged:false}": "minecraft:spruce_stairs{facing:south,half:bottom,shape:outer_right,waterlogged:false}",
            "minecraft:oak_stairs{facing:south,half:top,shape:outer_right,waterlogged:false}": "minecraft:spruce_stairs{facing:south,half:top,shape:outer_right,waterlogged:false}",
            "minecraft:oak_stairs{facing:west,half:bottom,shape:outer_right,waterlogged:false}": "minecraft:spruce_stairs{facing:west,half:bottom,shape:outer_right,waterlogged:false}",
            "minecraft:oak_stairs{facing:west,half:top,shape:outer_right,waterlogged:false}": "minecraft:spruce_stairs{facing:west,half:top,shape:outer_right,waterlogged:false}",
            "minecraft:oak_trapdoor{facing:east,half:bottom,open:true,powered:false,waterlogged:false}": "minecraft:spruce_trapdoor{facing:east,half:bottom,open:true,powered:false,waterlogged:false}",
            "minecraft:spruce_fence{east:false,north:false,south:false,waterlogged:false,west:false}": "minecraft:oak_fence{east:false,north:false,south:false,waterlogged:false,west:false}",
            "minecraft:spruce_planks": "minecraft:oak_planks",
            "minecraft:spruce_stairs{facing:north,half:top,shape:outer_right,waterlogged:false}": "minecraft:oak_stairs{facing:north,half:top,shape:outer_right,waterlogged:false}",
            "minecraft:spruce_stairs{facing:south,half:bottom,shape:outer_right,waterlogged:false}": "minecraft:oak_stairs{facing:south,half:bottom,shape:outer_right,waterlogged:false}",
            "minecraft:spruce_stairs{facing:south,half:top,shape:outer_right,waterlogged:false}": "minecraft:oak_stairs{facing:south,half:top,shape:outer_right,waterlogged:false}",
            "minecraft:structure_block{mode:data}": "minecraft:structure_block{mode:data}"
        },
        {
            "minecraft:chest{facing:north,type:single,waterlogged:false}": "minecraft:chest{facing:north,type:single,waterlogged:false}",
            "minecraft:oak_fence{east:false,north:false,south:false,waterlogged:false,west:false}": "minecraft:spruce_fence{east:false,north:false,south:false,waterlogged:false,west:false}",
            "minecraft:oak_log{axis:x}": "minecraft:spruce_log{axis:x}",
            "minecraft:oak_planks": "minecraft:spruce_planks",
            "minecraft:oak_stairs{facing:east,half:bottom,shape:outer_right,waterlogged:false}": "minecraft:spruce_stairs{facing:east,half:bottom,shape:outer_right,waterlogged:false}",
            "minecraft:oak_stairs{facing:east,half:top,shape:outer_right,waterlogged:false}": "minecraft:spruce_stairs{facing:east,half:top,shape:outer_right,waterlogged:false}",
            "minecraft:oak_stairs{facing:north,half:bottom,shape:outer_right,waterlogged:false}": "minecraft:spruce_stairs{facing:north,half:bottom,shape:outer_right,waterlogged:false}",
            "minecraft:oak_stairs{facing:north,half:top,shape:outer_right,waterlogged:false}": "minecraft:spruce_stairs{facing:north,half:top,shape:outer_right,waterlogged:false}",
            "minecraft:oak_stairs{facing:south,half:bottom,shape:outer_right,waterlogged:false}": "minecraft:spruce_stairs{facing:south,half:bottom,shape:outer_right,waterlogged:false}",
            "minecraft:oak_stairs{facing:south,half:top,shape:outer_right,waterlogged:false}": "minecraft:spruce_stairs{facing:south,half:top,shape:outer_right,waterlogged:false}",
            "minecraft:oak_stairs{facing:west,half:bottom,shape:outer_right,waterlogged:false}": "minecraft:spruce_stairs{facing:west,half:bottom,shape:outer_right,waterlogged:false}",
            "minecraft:oak_stairs{facing:west,half:top,shape:outer_right,waterlogged:false}": "minecraft:spruce_stairs{facing:west,half:top,shape:outer_right,waterlogged:false}",
            "minecraft:oak_trapdoor{facing:east,half:bottom,open:true,powered:false,waterlogged:false}": "minecraft:spruce_trapdoor{facing:east,half:bottom,open:true,powered:false,waterlogged:false}",
            "minecraft:spruce_fence{east:false,north:false,south:false,waterlogged:false,west:false}": "minecraft:jungle_fence{east:false,north:false,south:false,waterlogged:false,west:false}",
            "minecraft:spruce_planks": "minecraft:jungle_planks",
            "minecraft:spruce_stairs{facing:north,half:top,shape:outer_right,waterlogged:false}": "minecraft:jungle_stairs{facing:north,half:top,shape:outer_right,waterlogged:false}",
            "minecraft:spruce_stairs{facing:south,half:bottom,shape:outer_right,waterlogged:false}": "minecraft:jungle_stairs{facing:south,half:bottom,shape:outer_right,waterlogged:false}",
            "minecraft:spruce_stairs{facing:south,half:top,shape:outer_right,waterlogged:false}": "minecraft:jungle_stairs{facing:south,half:top,shape:outer_right,waterlogged:false}",
            "minecraft:structure_block{mode:data}": "minecraft:structure_block{mode:data}"
        },
        {
            "minecraft:chest{facing:north,type:single,waterlogged:false}": "minecraft:chest{facing:north,type:single,waterlogged:false}",
            "minecraft:oak_fence{east:false,north:false,south:false,waterlogged:false,west:false}": "minecraft:spruce_fence{east:false,north:false,south:false,waterlogged:false,west:false}",
            "minecraft:oak_log{axis:x}": "minecraft:spruce_log{axis:x}",
            "minecraft:oak_planks": "minecraft:spruce_planks",
            "minecraft:oak_stairs{facing:east,half:bottom,shape:outer_right,waterlogged:false}": "minecraft:spruce_stairs{facing:east,half:bottom,shape:outer_right,waterlogged:false}",
            "minecraft:oak_stairs{facing:east,half:top,shape:outer_right,waterlogged:false}": "minecraft:spruce_stairs{facing:east,half:top,shape:outer_right,waterlogged:false}",
            "minecraft:oak_stairs{facing:north,half:bottom,shape:outer_right,waterlogged:false}": "minecraft:spruce_stairs{facing:north,half:bottom,shape:outer_right,waterlogged:false}",
            "minecraft:oak_stairs{facing:north,half:top,shape:outer_right,waterlogged:false}": "minecraft:spruce_stairs{facing:north,half:top,shape:outer_right,waterlogged:false}",
            "minecraft:oak_stairs{facing:south,half:bottom,shape:outer_right,waterlogged:false}": "minecraft:spruce_stairs{facing:south,half:bottom,shape:outer_right,waterlogged:false}",
            "minecraft:oak_stairs{facing:south,half:top,shape:outer_right,waterlogged:false}": "minecraft:spruce_stairs{facing:south,half:top,shape:outer_right,waterlogged:false}",
            "minecraft:oak_stairs{facing:west,half:bottom,shape:outer_right,waterlogged:false}": "minecraft:spruce_stairs{facing:west,half:bottom,shape:outer_right,waterlogged:false}",
            "minecraft:oak_stairs{facing:west,half:top,shape:outer_right,waterlogged:false}": "minecraft:spruce_stairs{facing:west,half:top,shape:outer_right,waterlogged:false}",
            "minecraft:oak_trapdoor{facing:east,half:bottom,open:true,powered:false,waterlogged:false}": "minecraft:spruce_trapdoor{facing:east,half:bottom,open:true,powered:false,waterlogged:false}",
            "minecraft:spruce_fence{east:false,north:false,south:false,waterlogged:false,west:false}": "minecraft:dark_oak_fence{east:false,north:false,south:false,waterlogged:false,west:false}",
            "minecraft:spruce_planks": "minecraft:dark_oak_planks",
            "minecraft:spruce_stairs{facing:north,half:top,shape:outer_right,waterlogged:false}": "minecraft:dark_oak_stairs{facing:north,half:top,shape:outer_right,waterlogged:false}",
            "minecraft:spruce_stairs{facing:south,half:bottom,shape:outer_right,waterlogged:false}": "minecraft:dark_oak_stairs{facing:south,half:bottom,shape:outer_right,waterlogged:false}",
            "minecraft:spruce_stairs{facing:south,half:top,shape:outer_right,waterlogged:false}": "minecraft:dark_oak_stairs{facing:south,half:top,shape:outer_right,waterlogged:false}",
            "minecraft:structure_block{mode:data}": "minecraft:structure_block{mode:data}"
        },
        {
            "minecraft:chest{facing:north,type:single,waterlogged:false}": "minecraft:chest{facing:north,type:single,waterlogged:false}",
            "minecraft:oak_fence{east:false,north:false,south:false,waterlogged:false,west:false}": "minecraft:oak_fence{east:false,north:false,south:false,waterlogged:false,west:false}",
            "minecraft:oak_log{axis:x}": "minecraft:oak_log{axis:x}",
            "minecraft:oak_planks": "minecraft:oak_planks",
            "minecraft:oak_stairs{facing:east,half:bottom,shape:outer_right,waterlogged:false}": "minecraft:oak_stairs{facing:east,half:bottom,shape:outer_right,waterlogged:false}",
            "minecraft:oak_stairs{facing:east,half:top,shape:outer_right,waterlogged:false}": "minecraft:oak_stairs{facing:east,half:top,shape:outer_right,waterlogged:false}",
            "minecraft:oak_stairs{facing:north,half:bottom,shape:outer_right,waterlogged:false}": "minecraft:oak_stairs{facing:north,half:bottom,shape:outer_right,waterlogged:false}",
            "minecraft:oak_stairs{facing:north,half:top,shape:outer_right,waterlogged:false}": "minecraft:oak_stairs{facing:north,half:top,shape:outer_right,waterlogged:false}",
            "minecraft:oak_stairs{facing:south,half:bottom,shape:outer_right,waterlogged:false}": "minecraft:oak_stairs{facing:south,half:bottom,shape:outer_right,waterlogged:false}",
            "minecraft:oak_stairs{facing:south,half:top,shape:outer_right,waterlogged:false}": "minecraft:oak_stairs{facing:south,half:top,shape:outer_right,waterlogged:false}",
            "minecraft:oak_stairs{facing:west,half:bottom,shape:outer_right,waterlogged:false}": "minecraft:oak_stairs{facing:west,half:bottom,shape:outer_right,waterlogged:false}",
            "minecraft:oak_stairs{facing:west,half:top,shape:outer_right,waterlogged:false}": "minecraft:oak_stairs{facing:west,half:top,shape:outer_right,waterlogged:false}",
            "minecraft:oak_trapdoor{facing:east,half:bottom,open:true,powered:false,waterlogged:false}": "minecraft:oak_trapdoor{facing:east,half:bottom,open:true,powered:false,waterlogged:false}",
            "minecraft:spruce_fence{east:false,north:false,south:false,waterlogged:false,west:false}": "minecraft:birch_fence{east:false,north:false,south:false,waterlogged:false,west:false}",
            "minecraft:spruce_planks": "minecraft:birch_planks",
            "minecraft:spruce_stairs{facing:north,half:top,shape:outer_right,waterlogged:false}": "minecraft:birch_stairs{facing:north,half:top,shape:outer_right,waterlogged:false}",
            "minecraft:spruce_stairs{facing:south,half:bottom,shape:outer_right,waterlogged:false}": "minecraft:birch_stairs{facing:south,half:bottom,shape:outer_right,waterlogged:false}",
            "minecraft:spruce_stairs{facing:south,half:top,shape:outer_right,waterlogged:false}": "minecraft:birch_stairs{facing:south,half:top,shape:outer_right,waterlogged:false}",
            "minecraft:structure_block{mode:data}": "minecraft:structure_block{mode:data}"
        }
    ]
}
