{
    size: [9, 9, 28],
    data: [
        {pos: [0, 0, 21], state: "minecraft:oak_stairs{facing:east,half:top,shape:outer_right,waterlogged:false}"},
        {pos: [0, 0, 22], state: "minecraft:oak_stairs{facing:east,half:top,shape:outer_right,waterlogged:false}"},
        {pos: [0, 0, 23], state: "minecraft:oak_stairs{facing:east,half:top,shape:outer_right,waterlogged:false}"},
        {pos: [1, 0, 21], state: "minecraft:oak_planks"},
        {pos: [1, 0, 23], state: "minecraft:spruce_fence{east:false,north:false,south:false,waterlogged:false,west:false}"},
        {pos: [1, 0, 24], state: "minecraft:spruce_fence{east:false,north:false,south:false,waterlogged:false,west:false}"},
        {pos: [1, 0, 25], state: "minecraft:oak_planks"},
        {pos: [2, 0, 26], state: "minecraft:oak_planks"},
        {pos: [3, 0, 21], state: "minecraft:oak_planks"},
        {pos: [3, 0, 26], state: "minecraft:spruce_fence{east:false,north:false,south:false,waterlogged:false,west:false}"},
        {pos: [3, 0, 27], state: "minecraft:spruce_fence{east:false,north:false,south:false,waterlogged:false,west:false}"},
        {pos: [4, 0, 0], state: "minecraft:spruce_stairs{facing:south,half:bottom,shape:outer_right,waterlogged:false}"},
        {pos: [4, 0, 1], state: "minecraft:spruce_stairs{facing:north,half:top,shape:outer_right,waterlogged:false}"},
        {pos: [4, 0, 21], state: "minecraft:oak_planks"},
        {pos: [4, 0, 27], state: "minecraft:spruce_fence{east:false,north:false,south:false,waterlogged:false,west:false}"},
        {pos: [5, 0, 21], state: "minecraft:oak_planks"},
        {pos: [5, 0, 26], state: "minecraft:spruce_fence{east:false,north:false,south:false,waterlogged:false,west:false}"},
        {pos: [5, 0, 27], state: "minecraft:spruce_fence{east:false,north:false,south:false,waterlogged:false,west:false}"},
        {pos: [6, 0, 26], state: "minecraft:oak_planks"},
        {pos: [7, 0, 21], state: "minecraft:oak_planks"},
        {pos: [7, 0, 23], state: "minecraft:spruce_fence{east:false,north:false,south:false,waterlogged:false,west:false}"},
        {pos: [7, 0, 24], state: "minecraft:spruce_fence{east:false,north:false,south:false,waterlogged:false,west:false}"},
        {pos: [7, 0, 25], state: "minecraft:oak_planks"},
        {pos: [8, 0, 21], state: "minecraft:oak_stairs{facing:west,half:top,shape:outer_right,waterlogged:false}"},
        {pos: [8, 0, 22], state: "minecraft:oak_stairs{facing:west,half:top,shape:outer_right,waterlogged:false}"},
        {pos: [8, 0, 23], state: "minecraft:oak_stairs{facing:west,half:top,shape:outer_right,waterlogged:false}"},
        {pos: [0, 1, 20], state: "minecraft:oak_stairs{facing:south,half:top,shape:outer_right,waterlogged:false}"},
        {pos: [0, 1, 21], state: "minecraft:oak_planks"},
        {pos: [0, 1, 22], state: "minecraft:oak_planks"},
        {pos: [0, 1, 23], state: "minecraft:oak_planks"},
        {pos: [1, 1, 21], state: "minecraft:oak_planks"},
        {pos: [1, 1, 22], state: "minecraft:spruce_planks"},
        {pos: [1, 1, 23], state: "minecraft:spruce_planks"},
        {pos: [1, 1, 24], state: "minecraft:oak_planks"},
        {pos: [1, 1, 25], state: "minecraft:oak_planks"},
        {pos: [2, 1, 21], state: "minecraft:spruce_stairs{facing:south,half:top,shape:outer_right,waterlogged:false}"},
        {pos: [2, 1, 22], state: "minecraft:spruce_planks"},
        {pos: [2, 1, 23], state: "minecraft:spruce_planks"},
        {pos: [2, 1, 24], state: "minecraft:spruce_planks"},
        {pos: [2, 1, 25], state: "minecraft:spruce_planks"},
        {pos: [2, 1, 26], state: "minecraft:oak_planks"},
        {pos: [3, 1, 2], state: "minecraft:spruce_fence{east:false,north:false,south:false,waterlogged:false,west:false}"},
        {pos: [3, 1, 3], state: "minecraft:spruce_fence{east:false,north:false,south:false,waterlogged:false,west:false}"},
        {pos: [3, 1, 4], state: "minecraft:spruce_fence{east:false,north:false,south:false,waterlogged:false,west:false}"},
        {pos: [3, 1, 20], state: "minecraft:oak_slab{type:bottom,waterlogged:false}"},
        {pos: [3, 1, 21], state: "minecraft:oak_planks"},
        {pos: [3, 1, 22], state: "minecraft:spruce_planks"},
        {pos: [3, 1, 23], state: "minecraft:spruce_planks"},
        {pos: [3, 1, 24], state: "minecraft:spruce_planks"},
        {pos: [3, 1, 25], state: "minecraft:spruce_planks"},
        {pos: [3, 1, 26], state: "minecraft:oak_planks"},
        {pos: [3, 1, 27], state: "minecraft:oak_stairs{facing:north,half:bottom,shape:outer_right,waterlogged:false}"},
        {pos: [4, 1, 1], state: "minecraft:spruce_stairs{facing:south,half:bottom,shape:outer_right,waterlogged:false}"},
        {pos: [4, 1, 2], state: "minecraft:spruce_planks"},
        {pos: [4, 1, 3], state: "minecraft:spruce_stairs{facing:north,half:top,shape:outer_right,waterlogged:false}"},
        {pos: [4, 1, 20], state: "minecraft:oak_stairs{facing:south,half:bottom,shape:outer_right,waterlogged:false}"},
        {pos: [4, 1, 21], state: "minecraft:oak_planks"},
        {pos: [4, 1, 22], state: "minecraft:spruce_planks"},
        {pos: [4, 1, 23], state: "minecraft:spruce_planks"},
        {pos: [4, 1, 24], state: "minecraft:spruce_planks"},
        {pos: [4, 1, 25], state: "minecraft:spruce_planks"},
        {pos: [4, 1, 26], state: "minecraft:spruce_planks"},
        {pos: [4, 1, 27], state: "minecraft:oak_planks"},
        {pos: [5, 1, 2], state: "minecraft:spruce_fence{east:false,north:false,south:false,waterlogged:false,west:false}"},
        {pos: [5, 1, 3], state: "minecraft:spruce_fence{east:false,north:false,south:false,waterlogged:false,west:false}"},
        {pos: [5, 1, 4], state: "minecraft:spruce_fence{east:false,north:false,south:false,waterlogged:false,west:false}"},
        {pos: [5, 1, 20], state: "minecraft:oak_slab{type:bottom,waterlogged:false}"},
        {pos: [5, 1, 21], state: "minecraft:oak_planks"},
        {pos: [5, 1, 22], state: "minecraft:spruce_planks"},
        {pos: [5, 1, 23], state: "minecraft:spruce_planks"},
        {pos: [5, 1, 24], state: "minecraft:spruce_planks"},
        {pos: [5, 1, 25], state: "minecraft:spruce_planks"},
        {pos: [5, 1, 26], state: "minecraft:oak_planks"},
        {pos: [5, 1, 27], state: "minecraft:oak_stairs{facing:north,half:bottom,shape:outer_right,waterlogged:false}"},
        {pos: [6, 1, 21], state: "minecraft:spruce_stairs{facing:south,half:top,shape:outer_right,waterlogged:false}"},
        {pos: [6, 1, 22], state: "minecraft:spruce_planks"},
        {pos: [6, 1, 23], state: "minecraft:spruce_planks"},
        {pos: [6, 1, 24], state: "minecraft:spruce_planks"},
        {pos: [6, 1, 25], state: "minecraft:spruce_planks"},
        {pos: [6, 1, 26], state: "minecraft:oak_planks"},
        {pos: [7, 1, 21], state: "minecraft:oak_planks"},
        {pos: [7, 1, 22], state: "minecraft:spruce_planks"},
        {pos: [7, 1, 23], state: "minecraft:spruce_planks"},
        {pos: [7, 1, 24], state: "minecraft:oak_planks"},
        {pos: [7, 1, 25], state: "minecraft:oak_planks"},
        {pos: [8, 1, 20], state: "minecraft:oak_stairs{facing:south,half:top,shape:outer_right,waterlogged:false}"},
        {pos: [8, 1, 21], state: "minecraft:oak_planks"},
        {pos: [8, 1, 22], state: "minecraft:oak_planks"},
        {pos: [8, 1, 23], state: "minecraft:oak_planks"},
        {pos: [0, 2, 8], state: "minecraft:oak_planks"},
        {pos: [0, 2, 9], state: "minecraft:oak_stairs{facing:north,half:top,shape:outer_right,waterlogged:false}"},
        {pos: [0, 2, 18], state: "minecraft:oak_stairs{facing:south,half:top,shape:outer_right,waterlogged:false}"},
        {pos: [0, 2, 19], state: "minecraft:oak_planks"},
        {pos: [0, 2, 20], state: "minecraft:oak_planks"},
        {pos: [0, 2, 21], state: "minecraft:oak_planks"},
        {pos: [0, 2, 23], state: "minecraft:oak_planks"},
        {pos: [1, 2, 6], state: "minecraft:oak_planks"},
        {pos: [1, 2, 7], state: "minecraft:oak_planks"},
        {pos: [1, 2, 8], state: "minecraft:oak_stairs{facing:north,half:top,shape:outer_right,waterlogged:false}"},
        {pos: [1, 2, 19], state: "minecraft:spruce_stairs{facing:south,half:top,shape:outer_right,waterlogged:false}"},
        {pos: [1, 2, 20], state: "minecraft:spruce_planks"},
        {pos: [1, 2, 21], state: "minecraft:oak_planks"},
        {pos: [1, 2, 23], state: "minecraft:oak_fence{east:false,north:false,south:false,waterlogged:false,west:false}"},
        {pos: [1, 2, 24], state: "minecraft:oak_planks"},
        {pos: [1, 2, 25], state: "minecraft:oak_planks"},
        {pos: [2, 2, 5], state: "minecraft:oak_planks"},
        {pos: [2, 2, 19], state: "minecraft:oak_planks"},
        {pos: [2, 2, 20], state: "minecraft:spruce_planks"},
        {pos: [2, 2, 21], state: "minecraft:spruce_slab{type:bottom,waterlogged:false}"},
        {pos: [2, 2, 24], state: "minecraft:chest{facing:north,type:single,waterlogged:false}", nbt: {Items: [], id: "minecraft:chest"}},
        {pos: [2, 2, 25], state: "minecraft:oak_fence{east:false,north:false,south:false,waterlogged:false,west:false}"},
        {pos: [2, 2, 26], state: "minecraft:oak_stairs{facing:north,half:bottom,shape:outer_right,waterlogged:false}"},
        {pos: [3, 2, 2], state: "minecraft:spruce_fence{east:false,north:false,south:false,waterlogged:false,west:false}"},
        {pos: [3, 2, 3], state: "minecraft:oak_stairs{facing:south,half:bottom,shape:outer_right,waterlogged:false}"},
        {pos: [3, 2, 4], state: "minecraft:oak_planks"},
        {pos: [3, 2, 19], state: "minecraft:oak_planks"},
        {pos: [3, 2, 20], state: "minecraft:spruce_slab{type:bottom,waterlogged:false}"},
        {pos: [3, 2, 21], state: "minecraft:spruce_slab{type:bottom,waterlogged:false}"},
        {pos: [3, 2, 26], state: "minecraft:oak_planks"},
        {pos: [4, 2, 2], state: "minecraft:spruce_stairs{facing:south,half:bottom,shape:outer_right,waterlogged:false}"},
        {pos: [4, 2, 3], state: "minecraft:spruce_planks"},
        {pos: [4, 2, 4], state: "minecraft:spruce_stairs{facing:north,half:top,shape:outer_right,waterlogged:false}"},
        {pos: [4, 2, 21], state: "minecraft:spruce_slab{type:bottom,waterlogged:false}"},
        {pos: [5, 2, 2], state: "minecraft:spruce_fence{east:false,north:false,south:false,waterlogged:false,west:false}"},
        {pos: [5, 2, 3], state: "minecraft:oak_stairs{facing:south,half:bottom,shape:outer_right,waterlogged:false}"},
        {pos: [5, 2, 4], state: "minecraft:oak_planks"},
        {pos: [5, 2, 19], state: "minecraft:oak_planks"},
        {pos: [5, 2, 20], state: "minecraft:spruce_slab{type:bottom,waterlogged:false}"},
        {pos: [5, 2, 21], state: "minecraft:spruce_slab{type:bottom,waterlogged:false}"},
        {pos: [5, 2, 26], state: "minecraft:oak_planks"},
        {pos: [6, 2, 19], state: "minecraft:oak_planks"},
        {pos: [6, 2, 20], state: "minecraft:spruce_planks"},
        {pos: [6, 2, 21], state: "minecraft:spruce_slab{type:bottom,waterlogged:false}"},
        {pos: [6, 2, 25], state: "minecraft:oak_fence{east:false,north:false,south:false,waterlogged:false,west:false}"},
        {pos: [6, 2, 26], state: "minecraft:oak_stairs{facing:north,half:bottom,shape:outer_right,waterlogged:false}"},
        {pos: [7, 2, 19], state: "minecraft:spruce_stairs{facing:south,half:top,shape:outer_right,waterlogged:false}"},
        {pos: [7, 2, 20], state: "minecraft:spruce_planks"},
        {pos: [7, 2, 21], state: "minecraft:oak_planks"},
        {pos: [7, 2, 23], state: "minecraft:oak_fence{east:false,north:false,south:false,waterlogged:false,west:false}"},
        {pos: [7, 2, 24], state: "minecraft:oak_planks"},
        {pos: [7, 2, 25], state: "minecraft:oak_planks"},
        {pos: [8, 2, 18], state: "minecraft:oak_stairs{facing:south,half:top,shape:outer_right,waterlogged:false}"},
        {pos: [8, 2, 19], state: "minecraft:oak_planks"},
        {pos: [8, 2, 20], state: "minecraft:oak_planks"},
        {pos: [8, 2, 21], state: "minecraft:oak_planks"},
        {pos: [8, 2, 23], state: "minecraft:oak_planks"},
        {pos: [0, 3, 8], state: "minecraft:oak_stairs{facing:south,half:bottom,shape:outer_right,waterlogged:false}"},
        {pos: [0, 3, 9], state: "minecraft:oak_planks"},
        {pos: [0, 3, 10], state: "minecraft:oak_planks"},
        {pos: [0, 3, 11], state: "minecraft:spruce_fence{east:false,north:false,south:false,waterlogged:false,west:false}"},
        {pos: [0, 3, 12], state: "minecraft:spruce_fence{east:false,north:false,south:false,waterlogged:false,west:false}"},
        {pos: [0, 3, 13], state: "minecraft:spruce_fence{east:false,north:false,south:false,waterlogged:false,west:false}"},
        {pos: [0, 3, 15], state: "minecraft:spruce_fence{east:false,north:false,south:false,waterlogged:false,west:false}"},
        {pos: [0, 3, 16], state: "minecraft:spruce_fence{east:false,north:false,south:false,waterlogged:false,west:false}"},
        {pos: [0, 3, 17], state: "minecraft:spruce_fence{east:false,north:false,south:false,waterlogged:false,west:false}"},
        {pos: [0, 3, 18], state: "minecraft:oak_planks"},
        {pos: [0, 3, 19], state: "minecraft:oak_planks"},
        {pos: [0, 3, 20], state: "minecraft:oak_planks"},
        {pos: [0, 3, 21], state: "minecraft:oak_stairs{facing:east,half:bottom,shape:outer_right,waterlogged:false}"},
        {pos: [0, 3, 22], state: "minecraft:oak_stairs{facing:east,half:bottom,shape:outer_right,waterlogged:false}"},
        {pos: [0, 3, 23], state: "minecraft:oak_stairs{facing:north,half:bottom,shape:outer_right,waterlogged:false}"},
        {pos: [1, 3, 6], state: "minecraft:oak_stairs{facing:east,half:bottom,shape:outer_right,waterlogged:false}"},
        {pos: [1, 3, 7], state: "minecraft:oak_planks"},
        {pos: [1, 3, 8], state: "minecraft:oak_planks"},
        {pos: [1, 3, 18], state: "minecraft:spruce_stairs{facing:south,half:top,shape:outer_right,waterlogged:false}"},
        {pos: [1, 3, 19], state: "minecraft:oak_planks"},
        {pos: [1, 3, 20], state: "minecraft:oak_planks"},
        {pos: [1, 3, 21], state: "minecraft:oak_planks"},
        {pos: [1, 3, 22], state: "minecraft:oak_stairs{facing:west,half:top,shape:outer_right,waterlogged:false}"},
        {pos: [1, 3, 23], state: "minecraft:oak_planks"},
        {pos: [1, 3, 24], state: "minecraft:oak_planks"},
        {pos: [1, 3, 25], state: "minecraft:oak_stairs{facing:north,half:bottom,shape:outer_right,waterlogged:false}"},
        {pos: [2, 3, 5], state: "minecraft:oak_planks"},
        {pos: [2, 3, 6], state: "minecraft:spruce_planks"},
        {pos: [2, 3, 7], state: "minecraft:spruce_planks"},
        {pos: [2, 3, 19], state: "minecraft:oak_planks"},
        {pos: [2, 3, 24], state: "minecraft:structure_block{mode:data}", nbt: {author: "CascadianBacon", id: "minecraft:structure_block", ignoreEntities: 1b, integrity: 1.0f, metadata: "treasure_chest", mirror: "NONE", mode: "DATA", name: "", posX: 0, posY: 1, posZ: 0, powered: 0b, rotation: "NONE", seed: 0L, showair: 0b, showboundingbox: 1b, sizeX: 0, sizeY: 0, sizeZ: 0}},
        {pos: [2, 3, 25], state: "minecraft:oak_planks"},
        {pos: [3, 3, 4], state: "minecraft:oak_planks"},
        {pos: [3, 3, 5], state: "minecraft:spruce_planks"},
        {pos: [3, 3, 6], state: "minecraft:spruce_planks"},
        {pos: [3, 3, 7], state: "minecraft:spruce_stairs{facing:north,half:top,shape:outer_right,waterlogged:false}"},
        {pos: [3, 3, 19], state: "minecraft:oak_planks"},
        {pos: [3, 3, 25], state: "minecraft:oak_stairs{facing:south,half:top,shape:outer_right,waterlogged:false}"},
        {pos: [3, 3, 26], state: "minecraft:oak_stairs{facing:north,half:bottom,shape:outer_right,waterlogged:false}"},
        {pos: [4, 3, 3], state: "minecraft:spruce_planks"},
        {pos: [4, 3, 4], state: "minecraft:oak_planks"},
        {pos: [4, 3, 5], state: "minecraft:spruce_planks"},
        {pos: [4, 3, 6], state: "minecraft:spruce_planks"},
        {pos: [4, 3, 7], state: "minecraft:oak_log{axis:y}"},
        {pos: [4, 3, 11], state: "minecraft:oak_log{axis:y}"},
        {pos: [4, 3, 16], state: "minecraft:oak_log{axis:y}"},
        {pos: [4, 3, 25], state: "minecraft:oak_stairs{facing:south,half:top,shape:outer_right,waterlogged:false}"},
        {pos: [4, 3, 26], state: "minecraft:oak_planks"},
        {pos: [5, 3, 4], state: "minecraft:oak_planks"},
        {pos: [5, 3, 5], state: "minecraft:spruce_planks"},
        {pos: [5, 3, 6], state: "minecraft:spruce_planks"},
        {pos: [5, 3, 7], state: "minecraft:spruce_stairs{facing:north,half:top,shape:outer_right,waterlogged:false}"},
        {pos: [5, 3, 19], state: "minecraft:oak_planks"},
        {pos: [5, 3, 25], state: "minecraft:oak_stairs{facing:south,half:top,shape:outer_right,waterlogged:false}"},
        {pos: [5, 3, 26], state: "minecraft:oak_stairs{facing:north,half:bottom,shape:outer_right,waterlogged:false}"},
        {pos: [6, 3, 5], state: "minecraft:oak_planks"},
        {pos: [6, 3, 19], state: "minecraft:oak_planks"},
        {pos: [6, 3, 25], state: "minecraft:oak_planks"},
        {pos: [7, 3, 6], state: "minecraft:oak_stairs{facing:west,half:bottom,shape:outer_right,waterlogged:false}"},
        {pos: [7, 3, 18], state: "minecraft:spruce_stairs{facing:south,half:top,shape:outer_right,waterlogged:false}"},
        {pos: [7, 3, 19], state: "minecraft:oak_planks"},
        {pos: [7, 3, 20], state: "minecraft:oak_planks"},
        {pos: [7, 3, 21], state: "minecraft:oak_planks"},
        {pos: [7, 3, 22], state: "minecraft:oak_stairs{facing:east,half:top,shape:outer_right,waterlogged:false}"},
        {pos: [7, 3, 23], state: "minecraft:oak_planks"},
        {pos: [7, 3, 24], state: "minecraft:oak_planks"},
        {pos: [7, 3, 25], state: "minecraft:oak_stairs{facing:north,half:bottom,shape:outer_right,waterlogged:false}"},
        {pos: [8, 3, 15], state: "minecraft:spruce_fence{east:false,north:false,south:false,waterlogged:false,west:false}"},
        {pos: [8, 3, 16], state: "minecraft:spruce_fence{east:false,north:false,south:false,waterlogged:false,west:false}"},
        {pos: [8, 3, 17], state: "minecraft:spruce_fence{east:false,north:false,south:false,waterlogged:false,west:false}"},
        {pos: [8, 3, 18], state: "minecraft:oak_planks"},
        {pos: [8, 3, 19], state: "minecraft:oak_planks"},
        {pos: [8, 3, 20], state: "minecraft:oak_planks"},
        {pos: [8, 3, 21], state: "minecraft:oak_stairs{facing:west,half:bottom,shape:outer_right,waterlogged:false}"},
        {pos: [8, 3, 22], state: "minecraft:oak_stairs{facing:west,half:bottom,shape:outer_right,waterlogged:false}"},
        {pos: [8, 3, 23], state: "minecraft:oak_stairs{facing:north,half:bottom,shape:outer_right,waterlogged:false}"},
        {pos: [0, 4, 9], state: "minecraft:oak_stairs{facing:east,half:bottom,shape:outer_right,waterlogged:false}"},
        {pos: [0, 4, 10], state: "minecraft:oak_stairs{facing:east,half:bottom,shape:outer_right,waterlogged:false}"},
        {pos: [0, 4, 11], state: "minecraft:oak_stairs{facing:east,half:bottom,shape:outer_right,waterlogged:false}"},
        {pos: [0, 4, 12], state: "minecraft:oak_stairs{facing:east,half:bottom,shape:outer_right,waterlogged:false}"},
        {pos: [0, 4, 13], state: "minecraft:oak_stairs{facing:east,half:bottom,shape:outer_right,waterlogged:false}"},
        {pos: [0, 4, 14], state: "minecraft:oak_stairs{facing:east,half:bottom,shape:outer_right,waterlogged:false}"},
        {pos: [0, 4, 15], state: "minecraft:oak_stairs{facing:east,half:bottom,shape:outer_right,waterlogged:false}"},
        {pos: [0, 4, 16], state: "minecraft:oak_stairs{facing:east,half:bottom,shape:outer_right,waterlogged:false}"},
        {pos: [0, 4, 17], state: "minecraft:oak_stairs{facing:east,half:bottom,shape:outer_right,waterlogged:false}"},
        {pos: [0, 4, 18], state: "minecraft:oak_stairs{facing:east,half:bottom,shape:outer_right,waterlogged:false}"},
        {pos: [0, 4, 19], state: "minecraft:oak_stairs{facing:east,half:bottom,shape:outer_right,waterlogged:false}"},
        {pos: [0, 4, 20], state: "minecraft:oak_stairs{facing:east,half:bottom,shape:outer_right,waterlogged:false}"},
        {pos: [1, 4, 7], state: "minecraft:oak_stairs{facing:east,half:bottom,shape:outer_right,waterlogged:false}"},
        {pos: [1, 4, 8], state: "minecraft:oak_planks"},
        {pos: [1, 4, 9], state: "minecraft:spruce_planks"},
        {pos: [1, 4, 10], state: "minecraft:spruce_planks"},
        {pos: [1, 4, 11], state: "minecraft:spruce_planks"},
        {pos: [1, 4, 12], state: "minecraft:spruce_planks"},
        {pos: [1, 4, 13], state: "minecraft:spruce_planks"},
        {pos: [1, 4, 14], state: "minecraft:spruce_planks"},
        {pos: [1, 4, 15], state: "minecraft:spruce_planks"},
        {pos: [1, 4, 16], state: "minecraft:spruce_planks"},
        {pos: [1, 4, 17], state: "minecraft:spruce_planks"},
        {pos: [1, 4, 18], state: "minecraft:spruce_planks"},
        {pos: [1, 4, 19], state: "minecraft:oak_planks"},
        {pos: [1, 4, 20], state: "minecraft:oak_planks"},
        {pos: [1, 4, 21], state: "minecraft:oak_planks"},
        {pos: [1, 4, 22], state: "minecraft:oak_planks"},
        {pos: [1, 4, 23], state: "minecraft:oak_stairs{facing:east,half:bottom,shape:outer_right,waterlogged:false}"},
        {pos: [1, 4, 24], state: "minecraft:oak_stairs{facing:east,half:bottom,shape:outer_right,waterlogged:false}"},
        {pos: [2, 4, 5], state: "minecraft:oak_stairs{facing:east,half:bottom,shape:outer_right,waterlogged:false}"},
        {pos: [2, 4, 6], state: "minecraft:oak_stairs{facing:east,half:bottom,shape:outer_right,waterlogged:false}"},
        {pos: [2, 4, 7], state: "minecraft:oak_planks"},
        {pos: [2, 4, 8], state: "minecraft:spruce_planks"},
        {pos: [2, 4, 9], state: "minecraft:spruce_planks"},
        {pos: [2, 4, 10], state: "minecraft:spruce_planks"},
        {pos: [2, 4, 11], state: "minecraft:spruce_planks"},
        {pos: [2, 4, 12], state: "minecraft:spruce_stairs{facing:west,half:bottom,shape:outer_right,waterlogged:false}"},
        {pos: [2, 4, 13], state: "minecraft:spruce_planks"},
        {pos: [2, 4, 14], state: "minecraft:spruce_planks"},
        {pos: [2, 4, 15], state: "minecraft:spruce_stairs{facing:west,half:bottom,shape:outer_right,waterlogged:false}"},
        {pos: [2, 4, 16], state: "minecraft:spruce_planks"},
        {pos: [2, 4, 17], state: "minecraft:spruce_planks"},
        {pos: [2, 4, 18], state: "minecraft:spruce_planks"},
        {pos: [2, 4, 19], state: "minecraft:oak_planks"},
        {pos: [2, 4, 20], state: "minecraft:spruce_stairs{facing:west,half:top,shape:outer_right,waterlogged:false}"},
        {pos: [2, 4, 23], state: "minecraft:spruce_slab{type:bottom,waterlogged:false}"},
        {pos: [2, 4, 24], state: "minecraft:spruce_slab{type:bottom,waterlogged:false}"},
        {pos: [2, 4, 25], state: "minecraft:oak_stairs{facing:north,half:bottom,shape:outer_right,waterlogged:false}"},
        {pos: [3, 4, 4], state: "minecraft:oak_stairs{facing:south,half:bottom,shape:outer_right,waterlogged:false}"},
        {pos: [3, 4, 5], state: "minecraft:oak_planks"},
        {pos: [3, 4, 6], state: "minecraft:oak_planks"},
        {pos: [3, 4, 7], state: "minecraft:oak_planks"},
        {pos: [3, 4, 8], state: "minecraft:spruce_planks"},
        {pos: [3, 4, 9], state: "minecraft:oak_trapdoor{facing:east,half:bottom,open:false,powered:false,waterlogged:false}"},
        {pos: [3, 4, 10], state: "minecraft:oak_trapdoor{facing:east,half:bottom,open:false,powered:false,waterlogged:false}"},
        {pos: [3, 4, 11], state: "minecraft:spruce_planks"},
        {pos: [3, 4, 12], state: "minecraft:oak_trapdoor{facing:south,half:bottom,open:false,powered:false,waterlogged:false}"},
        {pos: [3, 4, 13], state: "minecraft:oak_trapdoor{facing:east,half:bottom,open:false,powered:false,waterlogged:false}"},
        {pos: [3, 4, 14], state: "minecraft:oak_trapdoor{facing:east,half:bottom,open:false,powered:false,waterlogged:false}"},
        {pos: [3, 4, 15], state: "minecraft:oak_trapdoor{facing:north,half:bottom,open:false,powered:false,waterlogged:false}"},
        {pos: [3, 4, 16], state: "minecraft:spruce_planks"},
        {pos: [3, 4, 17], state: "minecraft:spruce_planks"},
        {pos: [3, 4, 18], state: "minecraft:spruce_planks"},
        {pos: [3, 4, 19], state: "minecraft:oak_planks"},
        {pos: [3, 4, 20], state: "minecraft:spruce_slab{type:bottom,waterlogged:false}"},
        {pos: [3, 4, 24], state: "minecraft:spruce_slab{type:bottom,waterlogged:false}"},
        {pos: [3, 4, 25], state: "minecraft:oak_planks"},
        {pos: [4, 4, 3], state: "minecraft:spruce_stairs{facing:south,half:bottom,shape:outer_right,waterlogged:false}"},
        {pos: [4, 4, 4], state: "minecraft:spruce_planks"},
        {pos: [4, 4, 5], state: "minecraft:oak_planks"},
        {pos: [4, 4, 6], state: "minecraft:oak_planks"},
        {pos: [4, 4, 7], state: "minecraft:oak_log{axis:y}"},
        {pos: [4, 4, 8], state: "minecraft:spruce_planks"},
        {pos: [4, 4, 11], state: "minecraft:oak_log{axis:y}"},
        {pos: [4, 4, 12], state: "minecraft:oak_trapdoor{facing:south,half:bottom,open:false,powered:false,waterlogged:false}"},
        {pos: [4, 4, 15], state: "minecraft:oak_trapdoor{facing:north,half:bottom,open:false,powered:false,waterlogged:false}"},
        {pos: [4, 4, 16], state: "minecraft:oak_log{axis:y}"},
        {pos: [4, 4, 17], state: "minecraft:spruce_planks"},
        {pos: [4, 4, 18], state: "minecraft:spruce_stairs{facing:north,half:top,shape:outer_right,waterlogged:false}"},
        {pos: [4, 4, 19], state: "minecraft:spruce_slab{type:bottom,waterlogged:false}"},
        {pos: [4, 4, 20], state: "minecraft:spruce_slab{type:bottom,waterlogged:false}"},
        {pos: [4, 4, 25], state: "minecraft:oak_planks"},
        {pos: [4, 4, 26], state: "minecraft:oak_stairs{facing:north,half:bottom,shape:outer_right,waterlogged:false}"},
        {pos: [5, 4, 4], state: "minecraft:oak_stairs{facing:south,half:bottom,shape:outer_right,waterlogged:false}"},
        {pos: [5, 4, 5], state: "minecraft:oak_planks"},
        {pos: [5, 4, 6], state: "minecraft:oak_planks"},
        {pos: [5, 4, 7], state: "minecraft:oak_planks"},
        {pos: [5, 4, 8], state: "minecraft:spruce_planks"},
        {pos: [5, 4, 9], state: "minecraft:oak_trapdoor{facing:west,half:bottom,open:false,powered:false,waterlogged:false}"},
        {pos: [5, 4, 10], state: "minecraft:oak_trapdoor{facing:west,half:bottom,open:false,powered:false,waterlogged:false}"},
        {pos: [5, 4, 11], state: "minecraft:spruce_planks"},
        {pos: [5, 4, 12], state: "minecraft:oak_trapdoor{facing:south,half:bottom,open:false,powered:false,waterlogged:false}"},
        {pos: [5, 4, 13], state: "minecraft:oak_trapdoor{facing:west,half:bottom,open:false,powered:false,waterlogged:false}"},
        {pos: [5, 4, 14], state: "minecraft:oak_trapdoor{facing:west,half:bottom,open:false,powered:false,waterlogged:false}"},
        {pos: [5, 4, 15], state: "minecraft:oak_trapdoor{facing:north,half:bottom,open:false,powered:false,waterlogged:false}"},
        {pos: [5, 4, 16], state: "minecraft:spruce_planks"},
        {pos: [5, 4, 17], state: "minecraft:spruce_planks"},
        {pos: [5, 4, 18], state: "minecraft:spruce_planks"},
        {pos: [5, 4, 19], state: "minecraft:oak_planks"},
        {pos: [5, 4, 20], state: "minecraft:spruce_slab{type:bottom,waterlogged:false}"},
        {pos: [5, 4, 24], state: "minecraft:spruce_slab{type:bottom,waterlogged:false}"},
        {pos: [5, 4, 25], state: "minecraft:oak_planks"},
        {pos: [6, 4, 5], state: "minecraft:oak_stairs{facing:west,half:bottom,shape:outer_right,waterlogged:false}"},
        {pos: [6, 4, 6], state: "minecraft:oak_stairs{facing:west,half:bottom,shape:outer_right,waterlogged:false}"},
        {pos: [6, 4, 7], state: "minecraft:oak_planks"},
        {pos: [6, 4, 8], state: "minecraft:spruce_planks"},
        {pos: [6, 4, 9], state: "minecraft:spruce_planks"},
        {pos: [6, 4, 10], state: "minecraft:spruce_planks"},
        {pos: [6, 4, 11], state: "minecraft:spruce_planks"},
        {pos: [6, 4, 12], state: "minecraft:spruce_stairs{facing:east,half:bottom,shape:outer_right,waterlogged:false}"},
        {pos: [6, 4, 13], state: "minecraft:spruce_planks"},
        {pos: [6, 4, 14], state: "minecraft:spruce_planks"},
        {pos: [6, 4, 15], state: "minecraft:spruce_stairs{facing:east,half:bottom,shape:outer_right,waterlogged:false}"},
        {pos: [6, 4, 16], state: "minecraft:spruce_planks"},
        {pos: [6, 4, 17], state: "minecraft:spruce_planks"},
        {pos: [6, 4, 18], state: "minecraft:spruce_planks"},
        {pos: [6, 4, 19], state: "minecraft:oak_planks"},
        {pos: [6, 4, 20], state: "minecraft:spruce_stairs{facing:east,half:top,shape:outer_right,waterlogged:false}"},
        {pos: [6, 4, 23], state: "minecraft:spruce_slab{type:bottom,waterlogged:false}"},
        {pos: [6, 4, 24], state: "minecraft:spruce_slab{type:bottom,waterlogged:false}"},
        {pos: [6, 4, 25], state: "minecraft:oak_stairs{facing:north,half:bottom,shape:outer_right,waterlogged:false}"},
        {pos: [7, 4, 8], state: "minecraft:oak_planks"},
        {pos: [7, 4, 11], state: "minecraft:spruce_planks"},
        {pos: [7, 4, 12], state: "minecraft:spruce_planks"},
        {pos: [7, 4, 13], state: "minecraft:spruce_planks"},
        {pos: [7, 4, 14], state: "minecraft:spruce_planks"},
        {pos: [7, 4, 15], state: "minecraft:spruce_planks"},
        {pos: [7, 4, 16], state: "minecraft:spruce_planks"},
        {pos: [7, 4, 17], state: "minecraft:spruce_planks"},
        {pos: [7, 4, 18], state: "minecraft:spruce_planks"},
        {pos: [7, 4, 19], state: "minecraft:oak_planks"},
        {pos: [7, 4, 20], state: "minecraft:oak_planks"},
        {pos: [7, 4, 21], state: "minecraft:oak_planks"},
        {pos: [7, 4, 22], state: "minecraft:oak_planks"},
        {pos: [7, 4, 23], state: "minecraft:oak_stairs{facing:west,half:bottom,shape:outer_right,waterlogged:false}"},
        {pos: [7, 4, 24], state: "minecraft:oak_stairs{facing:west,half:bottom,shape:outer_right,waterlogged:false}"},
        {pos: [8, 4, 11], state: "minecraft:oak_stairs{facing:west,half:bottom,shape:outer_right,waterlogged:false}"},
        {pos: [8, 4, 12], state: "minecraft:oak_stairs{facing:west,half:bottom,shape:outer_right,waterlogged:false}"},
        {pos: [8, 4, 13], state: "minecraft:oak_stairs{facing:west,half:bottom,shape:outer_right,waterlogged:false}"},
        {pos: [8, 4, 14], state: "minecraft:oak_stairs{facing:west,half:bottom,shape:outer_right,waterlogged:false}"},
        {pos: [8, 4, 15], state: "minecraft:oak_stairs{facing:west,half:bottom,shape:outer_right,waterlogged:false}"},
        {pos: [8, 4, 16], state: "minecraft:oak_stairs{facing:west,half:bottom,shape:outer_right,waterlogged:false}"},
        {pos: [8, 4, 17], state: "minecraft:oak_stairs{facing:west,half:bottom,shape:outer_right,waterlogged:false}"},
        {pos: [8, 4, 18], state: "minecraft:oak_stairs{facing:west,half:bottom,shape:outer_right,waterlogged:false}"},
        {pos: [8, 4, 19], state: "minecraft:oak_stairs{facing:west,half:bottom,shape:outer_right,waterlogged:false}"},
        {pos: [8, 4, 20], state: "minecraft:oak_stairs{facing:west,half:bottom,shape:outer_right,waterlogged:false}"},
        {pos: [1, 5, 8], state: "minecraft:oak_stairs{facing:east,half:bottom,shape:outer_right,waterlogged:false}"},
        {pos: [1, 5, 9], state: "minecraft:oak_planks"},
        {pos: [1, 5, 10], state: "minecraft:oak_planks"},
        {pos: [1, 5, 11], state: "minecraft:oak_planks"},
        {pos: [1, 5, 13], state: "minecraft:oak_planks"},
        {pos: [1, 5, 14], state: "minecraft:oak_planks"},
        {pos: [1, 5, 17], state: "minecraft:oak_planks"},
        {pos: [1, 5, 19], state: "minecraft:oak_planks"},
        {pos: [1, 5, 20], state: "minecraft:oak_planks"},
        {pos: [1, 5, 21], state: "minecraft:oak_stairs{facing:east,half:bottom,shape:outer_right,waterlogged:false}"},
        {pos: [1, 5, 22], state: "minecraft:oak_stairs{facing:east,half:bottom,shape:outer_right,waterlogged:false}"},
        {pos: [2, 5, 7], state: "minecraft:oak_stairs{facing:east,half:bottom,shape:outer_right,waterlogged:false}"},
        {pos: [2, 5, 8], state: "minecraft:oak_planks"},
        {pos: [2, 5, 9], state: "minecraft:oak_planks"},
        {pos: [2, 5, 10], state: "minecraft:oak_planks"},
        {pos: [2, 5, 11], state: "minecraft:oak_planks"},
        {pos: [2, 5, 13], state: "minecraft:oak_planks"},
        {pos: [2, 5, 16], state: "minecraft:oak_planks"},
        {pos: [2, 5, 17], state: "minecraft:oak_planks"},
        {pos: [2, 5, 19], state: "minecraft:oak_planks"},
        {pos: [2, 5, 20], state: "minecraft:oak_planks"},
        {pos: [2, 5, 21], state: "minecraft:spruce_planks"},
        {pos: [2, 5, 22], state: "minecraft:spruce_planks"},
        {pos: [2, 5, 23], state: "minecraft:oak_planks"},
        {pos: [2, 5, 24], state: "minecraft:oak_stairs{facing:north,half:bottom,shape:outer_right,waterlogged:false}"},
        {pos: [3, 5, 5], state: "minecraft:oak_stairs{facing:east,half:bottom,shape:outer_right,waterlogged:false}"},
        {pos: [3, 5, 6], state: "minecraft:oak_stairs{facing:east,half:bottom,shape:outer_right,waterlogged:false}"},
        {pos: [3, 5, 7], state: "minecraft:oak_planks"},
        {pos: [3, 5, 16], state: "minecraft:oak_planks"},
        {pos: [3, 5, 17], state: "minecraft:chest{facing:east,type:single,waterlogged:false}", nbt: {Items: [], id: "minecraft:chest"}},
        {pos: [3, 5, 19], state: "minecraft:spruce_slab{type:bottom,waterlogged:false}"},
        {pos: [3, 5, 20], state: "minecraft:oak_planks"},
        {pos: [3, 5, 21], state: "minecraft:spruce_planks"},
        {pos: [3, 5, 22], state: "minecraft:spruce_planks"},
        {pos: [3, 5, 23], state: "minecraft:spruce_planks"},
        {pos: [3, 5, 24], state: "minecraft:oak_planks"},
        {pos: [3, 5, 25], state: "minecraft:oak_stairs{facing:north,half:bottom,shape:outer_right,waterlogged:false}"},
        {pos: [4, 5, 4], state: "minecraft:spruce_stairs{facing:south,half:bottom,shape:outer_right,waterlogged:false}"},
        {pos: [4, 5, 5], state: "minecraft:oak_planks"},
        {pos: [4, 5, 6], state: "minecraft:oak_planks"},
        {pos: [4, 5, 7], state: "minecraft:oak_planks"},
        {pos: [4, 5, 8], state: "minecraft:chest{facing:south,type:single,waterlogged:false}", nbt: {Items: [], id: "minecraft:chest"}},
        {pos: [4, 5, 11], state: "minecraft:oak_log{axis:y}"},
        {pos: [4, 5, 16], state: "minecraft:oak_log{axis:y}"},
        {pos: [4, 5, 20], state: "minecraft:oak_planks"},
        {pos: [4, 5, 21], state: "minecraft:spruce_planks"},
        {pos: [4, 5, 22], state: "minecraft:spruce_planks"},
        {pos: [4, 5, 23], state: "minecraft:spruce_planks"},
        {pos: [4, 5, 24], state: "minecraft:spruce_planks"},
        {pos: [4, 5, 25], state: "minecraft:spruce_fence{east:false,north:false,south:false,waterlogged:false,west:false}"},
        {pos: [5, 5, 5], state: "minecraft:oak_stairs{facing:west,half:bottom,shape:outer_right,waterlogged:false}"},
        {pos: [5, 5, 6], state: "minecraft:oak_stairs{facing:west,half:bottom,shape:outer_right,waterlogged:false}"},
        {pos: [5, 5, 7], state: "minecraft:oak_planks"},
        {pos: [5, 5, 19], state: "minecraft:spruce_slab{type:bottom,waterlogged:false}"},
        {pos: [5, 5, 20], state: "minecraft:oak_planks"},
        {pos: [5, 5, 22], state: "minecraft:spruce_planks"},
        {pos: [5, 5, 23], state: "minecraft:spruce_planks"},
        {pos: [5, 5, 24], state: "minecraft:oak_planks"},
        {pos: [5, 5, 25], state: "minecraft:oak_stairs{facing:north,half:bottom,shape:outer_right,waterlogged:false}"},
        {pos: [6, 5, 7], state: "minecraft:oak_stairs{facing:west,half:bottom,shape:outer_right,waterlogged:false}"},
        {pos: [6, 5, 8], state: "minecraft:oak_planks"},
        {pos: [6, 5, 9], state: "minecraft:oak_planks"},
        {pos: [6, 5, 10], state: "minecraft:oak_planks"},
        {pos: [6, 5, 11], state: "minecraft:oak_planks"},
        {pos: [6, 5, 14], state: "minecraft:oak_planks"},
        {pos: [6, 5, 16], state: "minecraft:oak_planks"},
        {pos: [6, 5, 17], state: "minecraft:oak_planks"},
        {pos: [6, 5, 23], state: "minecraft:oak_planks"},
        {pos: [6, 5, 24], state: "minecraft:oak_stairs{facing:north,half:bottom,shape:outer_right,waterlogged:false}"},
        {pos: [7, 5, 10], state: "minecraft:oak_planks"},
        {pos: [7, 5, 11], state: "minecraft:oak_planks"},
        {pos: [7, 5, 14], state: "minecraft:oak_planks"},
        {pos: [7, 5, 16], state: "minecraft:oak_planks"},
        {pos: [7, 5, 17], state: "minecraft:oak_planks"},
        {pos: [7, 5, 19], state: "minecraft:oak_planks"},
        {pos: [7, 5, 22], state: "minecraft:oak_stairs{facing:west,half:bottom,shape:outer_right,waterlogged:false}"},
        {pos: [1, 6, 9], state: "minecraft:oak_stairs{facing:east,half:bottom,shape:outer_right,waterlogged:false}"},
        {pos: [1, 6, 10], state: "minecraft:oak_stairs{facing:east,half:bottom,shape:outer_right,waterlogged:false}"},
        {pos: [1, 6, 11], state: "minecraft:oak_stairs{facing:east,half:bottom,shape:outer_right,waterlogged:false}"},
        {pos: [1, 6, 12], state: "minecraft:oak_stairs{facing:east,half:bottom,shape:outer_right,waterlogged:false}"},
        {pos: [1, 6, 13], state: "minecraft:oak_stairs{facing:east,half:bottom,shape:outer_right,waterlogged:false}"},
        {pos: [1, 6, 17], state: "minecraft:oak_stairs{facing:east,half:bottom,shape:outer_right,waterlogged:false}"},
        {pos: [1, 6, 18], state: "minecraft:oak_stairs{facing:east,half:bottom,shape:outer_right,waterlogged:false}"},
        {pos: [1, 6, 19], state: "minecraft:oak_stairs{facing:east,half:bottom,shape:outer_right,waterlogged:false}"},
        {pos: [1, 6, 20], state: "minecraft:oak_stairs{facing:east,half:bottom,shape:outer_right,waterlogged:false}"},
        {pos: [2, 6, 8], state: "minecraft:oak_stairs{facing:east,half:bottom,shape:outer_right,waterlogged:false}"},
        {pos: [2, 6, 9], state: "minecraft:oak_planks"},
        {pos: [2, 6, 10], state: "minecraft:oak_planks"},
        {pos: [2, 6, 11], state: "minecraft:oak_planks"},
        {pos: [2, 6, 12], state: "minecraft:oak_stairs{facing:west,half:top,shape:outer_right,waterlogged:false}"},
        {pos: [2, 6, 17], state: "minecraft:oak_planks"},
        {pos: [2, 6, 18], state: "minecraft:oak_stairs{facing:west,half:top,shape:outer_right,waterlogged:false}"},
        {pos: [2, 6, 19], state: "minecraft:oak_planks"},
        {pos: [2, 6, 20], state: "minecraft:oak_planks"},
        {pos: [2, 6, 21], state: "minecraft:oak_stairs{facing:east,half:bottom,shape:outer_right,waterlogged:false}"},
        {pos: [2, 6, 22], state: "minecraft:oak_stairs{facing:east,half:bottom,shape:outer_right,waterlogged:false}"},
        {pos: [2, 6, 23], state: "minecraft:oak_stairs{facing:north,half:bottom,shape:outer_right,waterlogged:false}"},
        {pos: [3, 6, 7], state: "minecraft:oak_stairs{facing:east,half:bottom,shape:outer_right,waterlogged:false}"},
        {pos: [3, 6, 8], state: "minecraft:oak_planks"},
        {pos: [3, 6, 17], state: "minecraft:structure_block{mode:data}", nbt: {author: "CascadianBacon", id: "minecraft:structure_block", ignoreEntities: 1b, integrity: 1.0f, metadata: "map_chest", mirror: "NONE", mode: "DATA", name: "", posX: 0, posY: 1, posZ: 0, powered: 0b, rotation: "NONE", seed: 0L, showair: 0b, showboundingbox: 1b, sizeX: 0, sizeY: 0, sizeZ: 0}},
        {pos: [3, 6, 20], state: "minecraft:oak_planks"},
        {pos: [3, 6, 21], state: "minecraft:oak_planks"},
        {pos: [3, 6, 22], state: "minecraft:oak_planks"},
        {pos: [3, 6, 23], state: "minecraft:oak_planks"},
        {pos: [3, 6, 24], state: "minecraft:oak_stairs{facing:north,half:bottom,shape:outer_right,waterlogged:false}"},
        {pos: [4, 6, 5], state: "minecraft:spruce_stairs{facing:south,half:bottom,shape:outer_right,waterlogged:false}"},
        {pos: [4, 6, 6], state: "minecraft:spruce_planks"},
        {pos: [4, 6, 7], state: "minecraft:oak_planks"},
        {pos: [4, 6, 8], state: "minecraft:structure_block{mode:data}", nbt: {author: "CascadianBacon", id: "minecraft:structure_block", ignoreEntities: 1b, integrity: 1.0f, metadata: "supply_chest", mirror: "NONE", mode: "DATA", name: "", posX: 0, posY: 1, posZ: 0, powered: 0b, rotation: "NONE", seed: 0L, showair: 0b, showboundingbox: 1b, sizeX: 0, sizeY: 0, sizeZ: 0}},
        {pos: [4, 6, 11], state: "minecraft:oak_log{axis:y}"},
        {pos: [4, 6, 16], state: "minecraft:oak_log{axis:y}"},
        {pos: [4, 6, 20], state: "minecraft:oak_planks"},
        {pos: [4, 6, 21], state: "minecraft:oak_planks"},
        {pos: [4, 6, 23], state: "minecraft:oak_planks"},
        {pos: [4, 6, 24], state: "minecraft:spruce_planks"},
        {pos: [5, 6, 7], state: "minecraft:oak_stairs{facing:west,half:bottom,shape:outer_right,waterlogged:false}"},
        {pos: [5, 6, 8], state: "minecraft:oak_planks"},
        {pos: [5, 6, 23], state: "minecraft:oak_planks"},
        {pos: [5, 6, 24], state: "minecraft:oak_stairs{facing:north,half:bottom,shape:outer_right,waterlogged:false}"},
        {pos: [6, 6, 8], state: "minecraft:oak_stairs{facing:west,half:bottom,shape:outer_right,waterlogged:false}"},
        {pos: [6, 6, 9], state: "minecraft:oak_planks"},
        {pos: [6, 6, 10], state: "minecraft:oak_planks"},
        {pos: [6, 6, 11], state: "minecraft:oak_planks"},
        {pos: [6, 6, 15], state: "minecraft:oak_stairs{facing:east,half:top,shape:outer_right,waterlogged:false}"},
        {pos: [6, 6, 23], state: "minecraft:oak_stairs{facing:north,half:bottom,shape:outer_right,waterlogged:false}"},
        {pos: [7, 6, 9], state: "minecraft:oak_stairs{facing:west,half:bottom,shape:outer_right,waterlogged:false}"},
        {pos: [7, 6, 10], state: "minecraft:oak_stairs{facing:west,half:bottom,shape:outer_right,waterlogged:false}"},
        {pos: [7, 6, 11], state: "minecraft:oak_stairs{facing:west,half:bottom,shape:outer_right,waterlogged:false}"},
        {pos: [7, 6, 15], state: "minecraft:oak_stairs{facing:west,half:bottom,shape:outer_right,waterlogged:false}"},
        {pos: [7, 6, 16], state: "minecraft:oak_stairs{facing:west,half:bottom,shape:outer_right,waterlogged:false}"},
        {pos: [7, 6, 17], state: "minecraft:oak_stairs{facing:west,half:bottom,shape:outer_right,waterlogged:false}"},
        {pos: [2, 7, 9], state: "minecraft:oak_stairs{facing:east,half:bottom,shape:outer_right,waterlogged:false}"},
        {pos: [2, 7, 10], state: "minecraft:oak_stairs{facing:east,half:bottom,shape:outer_right,waterlogged:false}"},
        {pos: [2, 7, 11], state: "minecraft:oak_stairs{facing:east,half:bottom,shape:outer_right,waterlogged:false}"},
        {pos: [2, 7, 12], state: "minecraft:oak_stairs{facing:east,half:bottom,shape:outer_right,waterlogged:false}"},
        {pos: [2, 7, 18], state: "minecraft:oak_stairs{facing:east,half:bottom,shape:outer_right,waterlogged:false}"},
        {pos: [2, 7, 19], state: "minecraft:oak_stairs{facing:east,half:bottom,shape:outer_right,waterlogged:false}"},
        {pos: [2, 7, 20], state: "minecraft:oak_stairs{facing:east,half:bottom,shape:outer_right,waterlogged:false}"},
        {pos: [3, 7, 8], state: "minecraft:oak_stairs{facing:east,half:bottom,shape:outer_right,waterlogged:false}"},
        {pos: [3, 7, 9], state: "minecraft:oak_planks"},
        {pos: [3, 7, 10], state: "minecraft:oak_planks"},
        {pos: [3, 7, 11], state: "minecraft:oak_planks"},
        {pos: [3, 7, 12], state: "minecraft:oak_planks"},
        {pos: [3, 7, 19], state: "minecraft:oak_planks"},
        {pos: [3, 7, 20], state: "minecraft:oak_planks"},
        {pos: [3, 7, 21], state: "minecraft:oak_stairs{facing:east,half:bottom,shape:outer_right,waterlogged:false}"},
        {pos: [3, 7, 22], state: "minecraft:oak_stairs{facing:east,half:bottom,shape:outer_right,waterlogged:false}"},
        {pos: [3, 7, 23], state: "minecraft:oak_stairs{facing:east,half:bottom,shape:outer_right,waterlogged:false}"},
        {pos: [4, 7, 6], state: "minecraft:spruce_stairs{facing:south,half:bottom,shape:outer_right,waterlogged:false}"},
        {pos: [4, 7, 7], state: "minecraft:spruce_planks"},
        {pos: [4, 7, 8], state: "minecraft:oak_planks"},
        {pos: [4, 7, 9], state: "minecraft:oak_planks"},
        {pos: [4, 7, 10], state: "minecraft:oak_planks"},
        {pos: [4, 7, 11], state: "minecraft:oak_planks"},
        {pos: [4, 7, 19], state: "minecraft:oak_planks"},
        {pos: [4, 7, 20], state: "minecraft:oak_planks"},
        {pos: [4, 7, 21], state: "minecraft:oak_planks"},
        {pos: [4, 7, 22], state: "minecraft:spruce_planks"},
        {pos: [4, 7, 23], state: "minecraft:spruce_planks"},
        {pos: [4, 7, 24], state: "minecraft:spruce_stairs{facing:north,half:bottom,shape:outer_right,waterlogged:false}"},
        {pos: [5, 7, 8], state: "minecraft:oak_stairs{facing:west,half:bottom,shape:outer_right,waterlogged:false}"},
        {pos: [5, 7, 9], state: "minecraft:oak_planks"},
        {pos: [5, 7, 10], state: "minecraft:oak_planks"},
        {pos: [5, 7, 11], state: "minecraft:oak_planks"},
        {pos: [5, 7, 12], state: "minecraft:oak_planks"},
        {pos: [5, 7, 21], state: "minecraft:oak_stairs{facing:west,half:bottom,shape:outer_right,waterlogged:false}"},
        {pos: [5, 7, 23], state: "minecraft:oak_stairs{facing:west,half:bottom,shape:outer_right,waterlogged:false}"},
        {pos: [6, 7, 9], state: "minecraft:oak_stairs{facing:west,half:bottom,shape:outer_right,waterlogged:false}"},
        {pos: [6, 7, 10], state: "minecraft:oak_stairs{facing:west,half:bottom,shape:outer_right,waterlogged:false}"},
        {pos: [6, 7, 11], state: "minecraft:oak_stairs{facing:west,half:bottom,shape:outer_right,waterlogged:false}"},
        {pos: [6, 7, 12], state: "minecraft:oak_stairs{facing:west,half:bottom,shape:outer_right,waterlogged:false}"},
        {pos: [4, 8, 8], state: "minecraft:spruce_stairs{facing:south,half:bottom,shape:outer_right,waterlogged:false}"},
        {pos: [4, 8, 9], state: "minecraft:spruce_planks"},
        {pos: [4, 8, 10], state: "minecraft:spruce_planks"},
        {pos: [4, 8, 11], state: "minecraft:spruce_planks"},
        {pos: [4, 8, 20], state: "minecraft:spruce_planks"},
        {pos: [4, 8, 21], state: "minecraft:spruce_stairs{facing:north,half:bottom,shape:outer_right,waterlogged:false}"}
    ],
    entities: [],
    palette: [
        "minecraft:oak_planks",
        "minecraft:spruce_planks",
        "minecraft:oak_log{axis:y}",
        "minecraft:oak_stairs{facing:east,half:top,shape:outer_right,waterlogged:false}",
        "minecraft:spruce_fence{east:false,north:false,south:false,waterlogged:false,west:false}",
        "minecraft:spruce_stairs{facing:south,half:bottom,shape:outer_right,waterlogged:false}",
        "minecraft:spruce_stairs{facing:north,half:top,shape:outer_right,waterlogged:false}",
        "minecraft:oak_stairs{facing:west,half:top,shape:outer_right,waterlogged:false}",
        "minecraft:oak_stairs{facing:south,half:top,shape:outer_right,waterlogged:false}",
        "minecraft:spruce_stairs{facing:south,half:top,shape:outer_right,waterlogged:false}",
        "minecraft:oak_slab{type:bottom,waterlogged:false}",
        "minecraft:oak_stairs{facing:north,half:bottom,shape:outer_right,waterlogged:false}",
        "minecraft:oak_stairs{facing:south,half:bottom,shape:outer_right,waterlogged:false}",
        "minecraft:oak_stairs{facing:north,half:top,shape:outer_right,waterlogged:false}",
        "minecraft:oak_fence{east:false,north:false,south:false,waterlogged:false,west:false}",
        "minecraft:spruce_slab{type:bottom,waterlogged:false}",
        "minecraft:oak_stairs{facing:east,half:bottom,shape:outer_right,waterlogged:false}",
        "minecraft:oak_stairs{facing:west,half:bottom,shape:outer_right,waterlogged:false}",
        "minecraft:spruce_stairs{facing:west,half:bottom,shape:outer_right,waterlogged:false}",
        "minecraft:spruce_stairs{facing:west,half:top,shape:outer_right,waterlogged:false}",
        "minecraft:oak_trapdoor{facing:east,half:bottom,open:false,powered:false,waterlogged:false}",
        "minecraft:oak_trapdoor{facing:south,half:bottom,open:false,powered:false,waterlogged:false}",
        "minecraft:oak_trapdoor{facing:north,half:bottom,open:false,powered:false,waterlogged:false}",
        "minecraft:oak_trapdoor{facing:west,half:bottom,open:false,powered:false,waterlogged:false}",
        "minecraft:spruce_stairs{facing:east,half:bottom,shape:outer_right,waterlogged:false}",
        "minecraft:spruce_stairs{facing:east,half:top,shape:outer_right,waterlogged:false}",
        "minecraft:spruce_stairs{facing:north,half:bottom,shape:outer_right,waterlogged:false}",
        "minecraft:chest{facing:north,type:single,waterlogged:false}",
        "minecraft:structure_block{mode:data}",
        "minecraft:chest{facing:east,type:single,waterlogged:false}",
        "minecraft:chest{facing:south,type:single,waterlogged:false}"
    ],
    palettes: [
        {
            "minecraft:chest{facing:east,type:single,waterlogged:false}": "minecraft:chest{facing:east,type:single,waterlogged:false}",
            "minecraft:chest{facing:north,type:single,waterlogged:false}": "minecraft:chest{facing:north,type:single,waterlogged:false}",
            "minecraft:chest{facing:south,type:single,waterlogged:false}": "minecraft:chest{facing:south,type:single,waterlogged:false}",
            "minecraft:oak_fence{east:false,north:false,south:false,waterlogged:false,west:false}": "minecraft:oak_fence{east:false,north:false,south:false,waterlogged:false,west:false}",
            "minecraft:oak_log{axis:y}": "minecraft:oak_log{axis:y}",
            "minecraft:oak_planks": "minecraft:oak_planks",
            "minecraft:oak_slab{type:bottom,waterlogged:false}": "minecraft:oak_slab{type:bottom,waterlogged:false}",
            "minecraft:oak_stairs{facing:east,half:bottom,shape:outer_right,waterlogged:false}": "minecraft:oak_stairs{facing:east,half:bottom,shape:outer_right,waterlogged:false}",
            "minecraft:oak_stairs{facing:east,half:top,shape:outer_right,waterlogged:false}": "minecraft:oak_stairs{facing:east,half:top,shape:outer_right,waterlogged:false}",
            "minecraft:oak_stairs{facing:north,half:bottom,shape:outer_right,waterlogged:false}": "minecraft:oak_stairs{facing:north,half:bottom,shape:outer_right,waterlogged:false}",
            "minecraft:oak_stairs{facing:north,half:top,shape:outer_right,waterlogged:false}": "minecraft:oak_stairs{facing:north,half:top,shape:outer_right,waterlogged:false}",
            "minecraft:oak_stairs{facing:south,half:bottom,shape:outer_right,waterlogged:false}": "minecraft:oak_stairs{facing:south,half:bottom,shape:outer_right,waterlogged:false}",
            "minecraft:oak_stairs{facing:south,half:top,shape:outer_right,waterlogged:false}": "minecraft:oak_stairs{facing:south,half:top,shape:outer_right,waterlogged:false}",
            "minecraft:oak_stairs{facing:west,half:bottom,shape:outer_right,waterlogged:false}": "minecraft:oak_stairs{facing:west,half:bottom,shape:outer_right,waterlogged:false}",
            "minecraft:oak_stairs{facing:west,half:top,shape:outer_right,waterlogged:false}": "minecraft:oak_stairs{facing:west,half:top,shape:outer_right,waterlogged:false}",
            "minecraft:oak_trapdoor{facing:east,half:bottom,open:false,powered:false,waterlogged:false}": "minecraft:oak_trapdoor{facing:east,half:bottom,open:false,powered:false,waterlogged:false}",
            "minecraft:oak_trapdoor{facing:north,half:bottom,open:false,powered:false,waterlogged:false}": "minecraft:oak_trapdoor{facing:north,half:bottom,open:false,powered:false,waterlogged:false}",
            "minecraft:oak_trapdoor{facing:south,half:bottom,open:false,powered:false,waterlogged:false}": "minecraft:oak_trapdoor{facing:south,half:bottom,open:false,powered:false,waterlogged:false}",
            "minecraft:oak_trapdoor{facing:west,half:bottom,open:false,powered:false,waterlogged:false}": "minecraft:oak_trapdoor{facing:west,half:bottom,open:false,powered:false,waterlogged:false}",
            "minecraft:spruce_fence{east:false,north:false,south:false,waterlogged:false,west:false}": "minecraft:spruce_fence{east:false,north:false,south:false,waterlogged:false,west:false}",
            "minecraft:spruce_planks": "minecraft:spruce_planks",
            "minecraft:spruce_slab{type:bottom,waterlogged:false}": "minecraft:spruce_slab{type:bottom,waterlogged:false}",
            "minecraft:spruce_stairs{facing:east,half:bottom,shape:outer_right,waterlogged:false}": "minecraft:spruce_stairs{facing:east,half:bottom,shape:outer_right,waterlogged:false}",
            "minecraft:spruce_stairs{facing:east,half:top,shape:outer_right,waterlogged:false}": "minecraft:spruce_stairs{facing:east,half:top,shape:outer_right,waterlogged:false}",
            "minecraft:spruce_stairs{facing:north,half:bottom,shape:outer_right,waterlogged:false}": "minecraft:spruce_stairs{facing:north,half:bottom,shape:outer_right,waterlogged:false}",
            "minecraft:spruce_stairs{facing:north,half:top,shape:outer_right,waterlogged:false}": "minecraft:spruce_stairs{facing:north,half:top,shape:outer_right,waterlogged:false}",
            "minecraft:spruce_stairs{facing:south,half:bottom,shape:outer_right,waterlogged:false}": "minecraft:spruce_stairs{facing:south,half:bottom,shape:outer_right,waterlogged:false}",
            "minecraft:spruce_stairs{facing:south,half:top,shape:outer_right,waterlogged:false}": "minecraft:spruce_stairs{facing:south,half:top,shape:outer_right,waterlogged:false}",
            "minecraft:spruce_stairs{facing:west,half:bottom,shape:outer_right,waterlogged:false}": "minecraft:spruce_stairs{facing:west,half:bottom,shape:outer_right,waterlogged:false}",
            "minecraft:spruce_stairs{facing:west,half:top,shape:outer_right,waterlogged:false}": "minecraft:spruce_stairs{facing:west,half:top,shape:outer_right,waterlogged:false}",
            "minecraft:structure_block{mode:data}": "minecraft:structure_block{mode:data}"
        },
        {
            "minecraft:chest{facing:east,type:single,waterlogged:false}": "minecraft:chest{facing:east,type:single,waterlogged:false}",
            "minecraft:chest{facing:north,type:single,waterlogged:false}": "minecraft:chest{facing:north,type:single,waterlogged:false}",
            "minecraft:chest{facing:south,type:single,waterlogged:false}": "minecraft:chest{facing:south,type:single,waterlogged:false}",
            "minecraft:oak_fence{east:false,north:false,south:false,waterlogged:false,west:false}": "minecraft:jungle_fence{east:false,north:false,south:false,waterlogged:false,west:false}",
            "minecraft:oak_log{axis:y}": "minecraft:jungle_log{axis:y}",
            "minecraft:oak_planks": "minecraft:jungle_planks",
            "minecraft:oak_slab{type:bottom,waterlogged:false}": "minecraft:jungle_slab{type:bottom,waterlogged:false}",
            "minecraft:oak_stairs{facing:east,half:bottom,shape:outer_right,waterlogged:false}": "minecraft:jungle_stairs{facing:east,half:bottom,shape:outer_right,waterlogged:false}",
            "minecraft:oak_stairs{facing:east,half:top,shape:outer_right,waterlogged:false}": "minecraft:jungle_stairs{facing:east,half:top,shape:outer_right,waterlogged:false}",
            "minecraft:oak_stairs{facing:north,half:bottom,shape:outer_right,waterlogged:false}": "minecraft:jungle_stairs{facing:north,half:bottom,shape:outer_right,waterlogged:false}",
            "minecraft:oak_stairs{facing:north,half:top,shape:outer_right,waterlogged:false}": "minecraft:jungle_stairs{facing:north,half:top,shape:outer_right,waterlogged:false}",
            "minecraft:oak_stairs{facing:south,half:bottom,shape:outer_right,waterlogged:false}": "minecraft:jungle_stairs{facing:south,half:bottom,shape:outer_right,waterlogged:false}",
            "minecraft:oak_stairs{facing:south,half:top,shape:outer_right,waterlogged:false}": "minecraft:jungle_stairs{facing:south,half:top,shape:outer_right,waterlogged:false}",
            "minecraft:oak_stairs{facing:west,half:bottom,shape:outer_right,waterlogged:false}": "minecraft:jungle_stairs{facing:west,half:bottom,shape:outer_right,waterlogged:false}",
            "minecraft:oak_stairs{facing:west,half:top,shape:outer_right,waterlogged:false}": "minecraft:jungle_stairs{facing:west,half:top,shape:outer_right,waterlogged:false}",
            "minecraft:oak_trapdoor{facing:east,half:bottom,open:false,powered:false,waterlogged:false}": "minecraft:jungle_trapdoor{facing:east,half:bottom,open:false,powered:false,waterlogged:false}",
            "minecraft:oak_trapdoor{facing:north,half:bottom,open:false,powered:false,waterlogged:false}": "minecraft:jungle_trapdoor{facing:north,half:bottom,open:false,powered:false,waterlogged:false}",
            "minecraft:oak_trapdoor{facing:south,half:bottom,open:false,powered:false,waterlogged:false}": "minecraft:jungle_trapdoor{facing:south,half:bottom,open:false,powered:false,waterlogged:false}",
            "minecraft:oak_trapdoor{facing:west,half:bottom,open:false,powered:false,waterlogged:false}": "minecraft:jungle_trapdoor{facing:west,half:bottom,open:false,powered:false,waterlogged:false}",
            "minecraft:spruce_fence{east:false,north:false,south:false,waterlogged:false,west:false}": "minecraft:spruce_fence{east:false,north:false,south:false,waterlogged:false,west:false}",
            "minecraft:spruce_planks": "minecraft:spruce_planks",
            "minecraft:spruce_slab{type:bottom,waterlogged:false}": "minecraft:spruce_slab{type:bottom,waterlogged:false}",
            "minecraft:spruce_stairs{facing:east,half:bottom,shape:outer_right,waterlogged:false}": "minecraft:spruce_stairs{facing:east,half:bottom,shape:outer_right,waterlogged:false}",
            "minecraft:spruce_stairs{facing:east,half:top,shape:outer_right,waterlogged:false}": "minecraft:spruce_stairs{facing:east,half:top,shape:outer_right,waterlogged:false}",
            "minecraft:spruce_stairs{facing:north,half:bottom,shape:outer_right,waterlogged:false}": "minecraft:spruce_stairs{facing:north,half:bottom,shape:outer_right,waterlogged:false}",
            "minecraft:spruce_stairs{facing:north,half:top,shape:outer_right,waterlogged:false}": "minecraft:spruce_stairs{facing:north,half:top,shape:outer_right,waterlogged:false}",
            "minecraft:spruce_stairs{facing:south,half:bottom,shape:outer_right,waterlogged:false}": "minecraft:spruce_stairs{facing:south,half:bottom,shape:outer_right,waterlogged:false}",
            "minecraft:spruce_stairs{facing:south,half:top,shape:outer_right,waterlogged:false}": "minecraft:spruce_stairs{facing:south,half:top,shape:outer_right,waterlogged:false}",
            "minecraft:spruce_stairs{facing:west,half:bottom,shape:outer_right,waterlogged:false}": "minecraft:spruce_stairs{facing:west,half:bottom,shape:outer_right,waterlogged:false}",
            "minecraft:spruce_stairs{facing:west,half:top,shape:outer_right,waterlogged:false}": "minecraft:spruce_stairs{facing:west,half:top,shape:outer_right,waterlogged:false}",
            "minecraft:structure_block{mode:data}": "minecraft:structure_block{mode:data}"
        },
        {
            "minecraft:chest{facing:east,type:single,waterlogged:false}": "minecraft:chest{facing:east,type:single,waterlogged:false}",
            "minecraft:chest{facing:north,type:single,waterlogged:false}": "minecraft:chest{facing:north,type:single,waterlogged:false}",
            "minecraft:chest{facing:south,type:single,waterlogged:false}": "minecraft:chest{facing:south,type:single,waterlogged:false}",
            "minecraft:oak_fence{east:false,north:false,south:false,waterlogged:false,west:false}": "minecraft:dark_oak_fence{east:false,north:false,south:false,waterlogged:false,west:false}",
            "minecraft:oak_log{axis:y}": "minecraft:dark_oak_log{axis:y}",
            "minecraft:oak_planks": "minecraft:dark_oak_planks",
            "minecraft:oak_slab{type:bottom,waterlogged:false}": "minecraft:dark_oak_slab{type:bottom,waterlogged:false}",
            "minecraft:oak_stairs{facing:east,half:bottom,shape:outer_right,waterlogged:false}": "minecraft:dark_oak_stairs{facing:east,half:bottom,shape:outer_right,waterlogged:false}",
            "minecraft:oak_stairs{facing:east,half:top,shape:outer_right,waterlogged:false}": "minecraft:dark_oak_stairs{facing:east,half:top,shape:outer_right,waterlogged:false}",
            "minecraft:oak_stairs{facing:north,half:bottom,shape:outer_right,waterlogged:false}": "minecraft:dark_oak_stairs{facing:north,half:bottom,shape:outer_right,waterlogged:false}",
            "minecraft:oak_stairs{facing:north,half:top,shape:outer_right,waterlogged:false}": "minecraft:dark_oak_stairs{facing:north,half:top,shape:outer_right,waterlogged:false}",
            "minecraft:oak_stairs{facing:south,half:bottom,shape:outer_right,waterlogged:false}": "minecraft:dark_oak_stairs{facing:south,half:bottom,shape:outer_right,waterlogged:false}",
            "minecraft:oak_stairs{facing:south,half:top,shape:outer_right,waterlogged:false}": "minecraft:dark_oak_stairs{facing:south,half:top,shape:outer_right,waterlogged:false}",
            "minecraft:oak_stairs{facing:west,half:bottom,shape:outer_right,waterlogged:false}": "minecraft:dark_oak_stairs{facing:west,half:bottom,shape:outer_right,waterlogged:false}",
            "minecraft:oak_stairs{facing:west,half:top,shape:outer_right,waterlogged:false}": "minecraft:dark_oak_stairs{facing:west,half:top,shape:outer_right,waterlogged:false}",
            "minecraft:oak_trapdoor{facing:east,half:bottom,open:false,powered:false,waterlogged:false}": "minecraft:dark_oak_trapdoor{facing:east,half:bottom,open:false,powered:false,waterlogged:false}",
            "minecraft:oak_trapdoor{facing:north,half:bottom,open:false,powered:false,waterlogged:false}": "minecraft:dark_oak_trapdoor{facing:north,half:bottom,open:false,powered:false,waterlogged:false}",
            "minecraft:oak_trapdoor{facing:south,half:bottom,open:false,powered:false,waterlogged:false}": "minecraft:dark_oak_trapdoor{facing:south,half:bottom,open:false,powered:false,waterlogged:false}",
            "minecraft:oak_trapdoor{facing:west,half:bottom,open:false,powered:false,waterlogged:false}": "minecraft:dark_oak_trapdoor{facing:west,half:bottom,open:false,powered:false,waterlogged:false}",
            "minecraft:spruce_fence{east:false,north:false,south:false,waterlogged:false,west:false}": "minecraft:jungle_fence{east:false,north:false,south:false,waterlogged:false,west:false}",
            "minecraft:spruce_planks": "minecraft:jungle_planks",
            "minecraft:spruce_slab{type:bottom,waterlogged:false}": "minecraft:jungle_slab{type:bottom,waterlogged:false}",
            "minecraft:spruce_stairs{facing:east,half:bottom,shape:outer_right,waterlogged:false}": "minecraft:jungle_stairs{facing:east,half:bottom,shape:outer_right,waterlogged:false}",
            "minecraft:spruce_stairs{facing:east,half:top,shape:outer_right,waterlogged:false}": "minecraft:jungle_stairs{facing:east,half:top,shape:outer_right,waterlogged:false}",
            "minecraft:spruce_stairs{facing:north,half:bottom,shape:outer_right,waterlogged:false}": "minecraft:jungle_stairs{facing:north,half:bottom,shape:outer_right,waterlogged:false}",
            "minecraft:spruce_stairs{facing:north,half:top,shape:outer_right,waterlogged:false}": "minecraft:jungle_stairs{facing:north,half:top,shape:outer_right,waterlogged:false}",
            "minecraft:spruce_stairs{facing:south,half:bottom,shape:outer_right,waterlogged:false}": "minecraft:jungle_stairs{facing:south,half:bottom,shape:outer_right,waterlogged:false}",
            "minecraft:spruce_stairs{facing:south,half:top,shape:outer_right,waterlogged:false}": "minecraft:jungle_stairs{facing:south,half:top,shape:outer_right,waterlogged:false}",
            "minecraft:spruce_stairs{facing:west,half:bottom,shape:outer_right,waterlogged:false}": "minecraft:jungle_stairs{facing:west,half:bottom,shape:outer_right,waterlogged:false}",
            "minecraft:spruce_stairs{facing:west,half:top,shape:outer_right,waterlogged:false}": "minecraft:jungle_stairs{facing:west,half:top,shape:outer_right,waterlogged:false}",
            "minecraft:structure_block{mode:data}": "minecraft:structure_block{mode:data}"
        },
        {
            "minecraft:chest{facing:east,type:single,waterlogged:false}": "minecraft:chest{facing:east,type:single,waterlogged:false}",
            "minecraft:chest{facing:north,type:single,waterlogged:false}": "minecraft:chest{facing:north,type:single,waterlogged:false}",
            "minecraft:chest{facing:south,type:single,waterlogged:false}": "minecraft:chest{facing:south,type:single,waterlogged:false}",
            "minecraft:oak_fence{east:false,north:false,south:false,waterlogged:false,west:false}": "minecraft:dark_oak_fence{east:false,north:false,south:false,waterlogged:false,west:false}",
            "minecraft:oak_log{axis:y}": "minecraft:dark_oak_log{axis:y}",
            "minecraft:oak_planks": "minecraft:dark_oak_planks",
            "minecraft:oak_slab{type:bottom,waterlogged:false}": "minecraft:dark_oak_slab{type:bottom,waterlogged:false}",
            "minecraft:oak_stairs{facing:east,half:bottom,shape:outer_right,waterlogged:false}": "minecraft:dark_oak_stairs{facing:east,half:bottom,shape:outer_right,waterlogged:false}",
            "minecraft:oak_stairs{facing:east,half:top,shape:outer_right,waterlogged:false}": "minecraft:dark_oak_stairs{facing:east,half:top,shape:outer_right,waterlogged:false}",
            "minecraft:oak_stairs{facing:north,half:bottom,shape:outer_right,waterlogged:false}": "minecraft:dark_oak_stairs{facing:north,half:bottom,shape:outer_right,waterlogged:false}",
            "minecraft:oak_stairs{facing:north,half:top,shape:outer_right,waterlogged:false}": "minecraft:dark_oak_stairs{facing:north,half:top,shape:outer_right,waterlogged:false}",
            "minecraft:oak_stairs{facing:south,half:bottom,shape:outer_right,waterlogged:false}": "minecraft:dark_oak_stairs{facing:south,half:bottom,shape:outer_right,waterlogged:false}",
            "minecraft:oak_stairs{facing:south,half:top,shape:outer_right,waterlogged:false}": "minecraft:dark_oak_stairs{facing:south,half:top,shape:outer_right,waterlogged:false}",
            "minecraft:oak_stairs{facing:west,half:bottom,shape:outer_right,waterlogged:false}": "minecraft:dark_oak_stairs{facing:west,half:bottom,shape:outer_right,waterlogged:false}",
            "minecraft:oak_stairs{facing:west,half:top,shape:outer_right,waterlogged:false}": "minecraft:dark_oak_stairs{facing:west,half:top,shape:outer_right,waterlogged:false}",
            "minecraft:oak_trapdoor{facing:east,half:bottom,open:false,powered:false,waterlogged:false}": "minecraft:dark_oak_trapdoor{facing:east,half:bottom,open:false,powered:false,waterlogged:false}",
            "minecraft:oak_trapdoor{facing:north,half:bottom,open:false,powered:false,waterlogged:false}": "minecraft:dark_oak_trapdoor{facing:north,half:bottom,open:false,powered:false,waterlogged:false}",
            "minecraft:oak_trapdoor{facing:south,half:bottom,open:false,powered:false,waterlogged:false}": "minecraft:dark_oak_trapdoor{facing:south,half:bottom,open:false,powered:false,waterlogged:false}",
            "minecraft:oak_trapdoor{facing:west,half:bottom,open:false,powered:false,waterlogged:false}": "minecraft:dark_oak_trapdoor{facing:west,half:bottom,open:false,powered:false,waterlogged:false}",
            "minecraft:spruce_fence{east:false,north:false,south:false,waterlogged:false,west:false}": "minecraft:spruce_fence{east:false,north:false,south:false,waterlogged:false,west:false}",
            "minecraft:spruce_planks": "minecraft:spruce_planks",
            "minecraft:spruce_slab{type:bottom,waterlogged:false}": "minecraft:spruce_slab{type:bottom,waterlogged:false}",
            "minecraft:spruce_stairs{facing:east,half:bottom,shape:outer_right,waterlogged:false}": "minecraft:spruce_stairs{facing:east,half:bottom,shape:outer_right,waterlogged:false}",
            "minecraft:spruce_stairs{facing:east,half:top,shape:outer_right,waterlogged:false}": "minecraft:spruce_stairs{facing:east,half:top,shape:outer_right,waterlogged:false}",
            "minecraft:spruce_stairs{facing:north,half:bottom,shape:outer_right,waterlogged:false}": "minecraft:spruce_stairs{facing:north,half:bottom,shape:outer_right,waterlogged:false}",
            "minecraft:spruce_stairs{facing:north,half:top,shape:outer_right,waterlogged:false}": "minecraft:spruce_stairs{facing:north,half:top,shape:outer_right,waterlogged:false}",
            "minecraft:spruce_stairs{facing:south,half:bottom,shape:outer_right,waterlogged:false}": "minecraft:spruce_stairs{facing:south,half:bottom,shape:outer_right,waterlogged:false}",
            "minecraft:spruce_stairs{facing:south,half:top,shape:outer_right,waterlogged:false}": "minecraft:spruce_stairs{facing:south,half:top,shape:outer_right,waterlogged:false}",
            "minecraft:spruce_stairs{facing:west,half:bottom,shape:outer_right,waterlogged:false}": "minecraft:spruce_stairs{facing:west,half:bottom,shape:outer_right,waterlogged:false}",
            "minecraft:spruce_stairs{facing:west,half:top,shape:outer_right,waterlogged:false}": "minecraft:spruce_stairs{facing:west,half:top,shape:outer_right,waterlogged:false}",
            "minecraft:structure_block{mode:data}": "minecraft:structure_block{mode:data}"
        },
        {
            "minecraft:chest{facing:east,type:single,waterlogged:false}": "minecraft:chest{facing:east,type:single,waterlogged:false}",
            "minecraft:chest{facing:north,type:single,waterlogged:false}": "minecraft:chest{facing:north,type:single,waterlogged:false}",
            "minecraft:chest{facing:south,type:single,waterlogged:false}": "minecraft:chest{facing:south,type:single,waterlogged:false}",
            "minecraft:oak_fence{east:false,north:false,south:false,waterlogged:false,west:false}": "minecraft:spruce_fence{east:false,north:false,south:false,waterlogged:false,west:false}",
            "minecraft:oak_log{axis:y}": "minecraft:spruce_log{axis:y}",
            "minecraft:oak_planks": "minecraft:spruce_planks",
            "minecraft:oak_slab{type:bottom,waterlogged:false}": "minecraft:spruce_slab{type:bottom,waterlogged:false}",
            "minecraft:oak_stairs{facing:east,half:bottom,shape:outer_right,waterlogged:false}": "minecraft:spruce_stairs{facing:east,half:bottom,shape:outer_right,waterlogged:false}",
            "minecraft:oak_stairs{facing:east,half:top,shape:outer_right,waterlogged:false}": "minecraft:spruce_stairs{facing:east,half:top,shape:outer_right,waterlogged:false}",
            "minecraft:oak_stairs{facing:north,half:bottom,shape:outer_right,waterlogged:false}": "minecraft:spruce_stairs{facing:north,half:bottom,shape:outer_right,waterlogged:false}",
            "minecraft:oak_stairs{facing:north,half:top,shape:outer_right,waterlogged:false}": "minecraft:spruce_stairs{facing:north,half:top,shape:outer_right,waterlogged:false}",
            "minecraft:oak_stairs{facing:south,half:bottom,shape:outer_right,waterlogged:false}": "minecraft:spruce_stairs{facing:south,half:bottom,shape:outer_right,waterlogged:false}",
            "minecraft:oak_stairs{facing:south,half:top,shape:outer_right,waterlogged:false}": "minecraft:spruce_stairs{facing:south,half:top,shape:outer_right,waterlogged:false}",
            "minecraft:oak_stairs{facing:west,half:bottom,shape:outer_right,waterlogged:false}": "minecraft:spruce_stairs{facing:west,half:bottom,shape:outer_right,waterlogged:false}",
            "minecraft:oak_stairs{facing:west,half:top,shape:outer_right,waterlogged:false}": "minecraft:spruce_stairs{facing:west,half:top,shape:outer_right,waterlogged:false}",
            "minecraft:oak_trapdoor{facing:east,half:bottom,open:false,powered:false,waterlogged:false}": "minecraft:spruce_trapdoor{facing:east,half:bottom,open:false,powered:false,waterlogged:false}",
            "minecraft:oak_trapdoor{facing:north,half:bottom,open:false,powered:false,waterlogged:false}": "minecraft:spruce_trapdoor{facing:north,half:bottom,open:false,powered:false,waterlogged:false}",
            "minecraft:oak_trapdoor{facing:south,half:bottom,open:false,powered:false,waterlogged:false}": "minecraft:spruce_trapdoor{facing:south,half:bottom,open:false,powered:false,waterlogged:false}",
            "minecraft:oak_trapdoor{facing:west,half:bottom,open:false,powered:false,waterlogged:false}": "minecraft:spruce_trapdoor{facing:west,half:bottom,open:false,powered:false,waterlogged:false}",
            "minecraft:spruce_fence{east:false,north:false,south:false,waterlogged:false,west:false}": "minecraft:oak_fence{east:false,north:false,south:false,waterlogged:false,west:false}",
            "minecraft:spruce_planks": "minecraft:oak_planks",
            "minecraft:spruce_slab{type:bottom,waterlogged:false}": "minecraft:oak_slab{type:bottom,waterlogged:false}",
            "minecraft:spruce_stairs{facing:east,half:bottom,shape:outer_right,waterlogged:false}": "minecraft:oak_stairs{facing:east,half:bottom,shape:outer_right,waterlogged:false}",
            "minecraft:spruce_stairs{facing:east,half:top,shape:outer_right,waterlogged:false}": "minecraft:oak_stairs{facing:east,half:top,shape:outer_right,waterlogged:false}",
            "minecraft:spruce_stairs{facing:north,half:bottom,shape:outer_right,waterlogged:false}": "minecraft:oak_stairs{facing:north,half:bottom,shape:outer_right,waterlogged:false}",
            "minecraft:spruce_stairs{facing:north,half:top,shape:outer_right,waterlogged:false}": "minecraft:oak_stairs{facing:north,half:top,shape:outer_right,waterlogged:false}",
            "minecraft:spruce_stairs{facing:south,half:bottom,shape:outer_right,waterlogged:false}": "minecraft:oak_stairs{facing:south,half:bottom,shape:outer_right,waterlogged:false}",
            "minecraft:spruce_stairs{facing:south,half:top,shape:outer_right,waterlogged:false}": "minecraft:oak_stairs{facing:south,half:top,shape:outer_right,waterlogged:false}",
            "minecraft:spruce_stairs{facing:west,half:bottom,shape:outer_right,waterlogged:false}": "minecraft:oak_stairs{facing:west,half:bottom,shape:outer_right,waterlogged:false}",
            "minecraft:spruce_stairs{facing:west,half:top,shape:outer_right,waterlogged:false}": "minecraft:oak_stairs{facing:west,half:top,shape:outer_right,waterlogged:false}",
            "minecraft:structure_block{mode:data}": "minecraft:structure_block{mode:data}"
        },
        {
            "minecraft:chest{facing:east,type:single,waterlogged:false}": "minecraft:chest{facing:east,type:single,waterlogged:false}",
            "minecraft:chest{facing:north,type:single,waterlogged:false}": "minecraft:chest{facing:north,type:single,waterlogged:false}",
            "minecraft:chest{facing:south,type:single,waterlogged:false}": "minecraft:chest{facing:south,type:single,waterlogged:false}",
            "minecraft:oak_fence{east:false,north:false,south:false,waterlogged:false,west:false}": "minecraft:spruce_fence{east:false,north:false,south:false,waterlogged:false,west:false}",
            "minecraft:oak_log{axis:y}": "minecraft:spruce_log{axis:y}",
            "minecraft:oak_planks": "minecraft:spruce_planks",
            "minecraft:oak_slab{type:bottom,waterlogged:false}": "minecraft:spruce_slab{type:bottom,waterlogged:false}",
            "minecraft:oak_stairs{facing:east,half:bottom,shape:outer_right,waterlogged:false}": "minecraft:spruce_stairs{facing:east,half:bottom,shape:outer_right,waterlogged:false}",
            "minecraft:oak_stairs{facing:east,half:top,shape:outer_right,waterlogged:false}": "minecraft:spruce_stairs{facing:east,half:top,shape:outer_right,waterlogged:false}",
            "minecraft:oak_stairs{facing:north,half:bottom,shape:outer_right,waterlogged:false}": "minecraft:spruce_stairs{facing:north,half:bottom,shape:outer_right,waterlogged:false}",
            "minecraft:oak_stairs{facing:north,half:top,shape:outer_right,waterlogged:false}": "minecraft:spruce_stairs{facing:north,half:top,shape:outer_right,waterlogged:false}",
            "minecraft:oak_stairs{facing:south,half:bottom,shape:outer_right,waterlogged:false}": "minecraft:spruce_stairs{facing:south,half:bottom,shape:outer_right,waterlogged:false}",
            "minecraft:oak_stairs{facing:south,half:top,shape:outer_right,waterlogged:false}": "minecraft:spruce_stairs{facing:south,half:top,shape:outer_right,waterlogged:false}",
            "minecraft:oak_stairs{facing:west,half:bottom,shape:outer_right,waterlogged:false}": "minecraft:spruce_stairs{facing:west,half:bottom,shape:outer_right,waterlogged:false}",
            "minecraft:oak_stairs{facing:west,half:top,shape:outer_right,waterlogged:false}": "minecraft:spruce_stairs{facing:west,half:top,shape:outer_right,waterlogged:false}",
            "minecraft:oak_trapdoor{facing:east,half:bottom,open:false,powered:false,waterlogged:false}": "minecraft:spruce_trapdoor{facing:east,half:bottom,open:false,powered:false,waterlogged:false}",
            "minecraft:oak_trapdoor{facing:north,half:bottom,open:false,powered:false,waterlogged:false}": "minecraft:spruce_trapdoor{facing:north,half:bottom,open:false,powered:false,waterlogged:false}",
            "minecraft:oak_trapdoor{facing:south,half:bottom,open:false,powered:false,waterlogged:false}": "minecraft:spruce_trapdoor{facing:south,half:bottom,open:false,powered:false,waterlogged:false}",
            "minecraft:oak_trapdoor{facing:west,half:bottom,open:false,powered:false,waterlogged:false}": "minecraft:spruce_trapdoor{facing:west,half:bottom,open:false,powered:false,waterlogged:false}",
            "minecraft:spruce_fence{east:false,north:false,south:false,waterlogged:false,west:false}": "minecraft:jungle_fence{east:false,north:false,south:false,waterlogged:false,west:false}",
            "minecraft:spruce_planks": "minecraft:jungle_planks",
            "minecraft:spruce_slab{type:bottom,waterlogged:false}": "minecraft:jungle_slab{type:bottom,waterlogged:false}",
            "minecraft:spruce_stairs{facing:east,half:bottom,shape:outer_right,waterlogged:false}": "minecraft:jungle_stairs{facing:east,half:bottom,shape:outer_right,waterlogged:false}",
            "minecraft:spruce_stairs{facing:east,half:top,shape:outer_right,waterlogged:false}": "minecraft:jungle_stairs{facing:east,half:top,shape:outer_right,waterlogged:false}",
            "minecraft:spruce_stairs{facing:north,half:bottom,shape:outer_right,waterlogged:false}": "minecraft:jungle_stairs{facing:north,half:bottom,shape:outer_right,waterlogged:false}",
            "minecraft:spruce_stairs{facing:north,half:top,shape:outer_right,waterlogged:false}": "minecraft:jungle_stairs{facing:north,half:top,shape:outer_right,waterlogged:false}",
            "minecraft:spruce_stairs{facing:south,half:bottom,shape:outer_right,waterlogged:false}": "minecraft:jungle_stairs{facing:south,half:bottom,shape:outer_right,waterlogged:false}",
            "minecraft:spruce_stairs{facing:south,half:top,shape:outer_right,waterlogged:false}": "minecraft:jungle_stairs{facing:south,half:top,shape:outer_right,waterlogged:false}",
            "minecraft:spruce_stairs{facing:west,half:bottom,shape:outer_right,waterlogged:false}": "minecraft:jungle_stairs{facing:west,half:bottom,shape:outer_right,waterlogged:false}",
            "minecraft:spruce_stairs{facing:west,half:top,shape:outer_right,waterlogged:false}": "minecraft:jungle_stairs{facing:west,half:top,shape:outer_right,waterlogged:false}",
            "minecraft:structure_block{mode:data}": "minecraft:structure_block{mode:data}"
        },
        {
            "minecraft:chest{facing:east,type:single,waterlogged:false}": "minecraft:chest{facing:east,type:single,waterlogged:false}",
            "minecraft:chest{facing:north,type:single,waterlogged:false}": "minecraft:chest{facing:north,type:single,waterlogged:false}",
            "minecraft:chest{facing:south,type:single,waterlogged:false}": "minecraft:chest{facing:south,type:single,waterlogged:false}",
            "minecraft:oak_fence{east:false,north:false,south:false,waterlogged:false,west:false}": "minecraft:spruce_fence{east:false,north:false,south:false,waterlogged:false,west:false}",
            "minecraft:oak_log{axis:y}": "minecraft:spruce_log{axis:y}",
            "minecraft:oak_planks": "minecraft:spruce_planks",
            "minecraft:oak_slab{type:bottom,waterlogged:false}": "minecraft:spruce_slab{type:bottom,waterlogged:false}",
            "minecraft:oak_stairs{facing:east,half:bottom,shape:outer_right,waterlogged:false}": "minecraft:spruce_stairs{facing:east,half:bottom,shape:outer_right,waterlogged:false}",
            "minecraft:oak_stairs{facing:east,half:top,shape:outer_right,waterlogged:false}": "minecraft:spruce_stairs{facing:east,half:top,shape:outer_right,waterlogged:false}",
            "minecraft:oak_stairs{facing:north,half:bottom,shape:outer_right,waterlogged:false}": "minecraft:spruce_stairs{facing:north,half:bottom,shape:outer_right,waterlogged:false}",
            "minecraft:oak_stairs{facing:north,half:top,shape:outer_right,waterlogged:false}": "minecraft:spruce_stairs{facing:north,half:top,shape:outer_right,waterlogged:false}",
            "minecraft:oak_stairs{facing:south,half:bottom,shape:outer_right,waterlogged:false}": "minecraft:spruce_stairs{facing:south,half:bottom,shape:outer_right,waterlogged:false}",
            "minecraft:oak_stairs{facing:south,half:top,shape:outer_right,waterlogged:false}": "minecraft:spruce_stairs{facing:south,half:top,shape:outer_right,waterlogged:false}",
            "minecraft:oak_stairs{facing:west,half:bottom,shape:outer_right,waterlogged:false}": "minecraft:spruce_stairs{facing:west,half:bottom,shape:outer_right,waterlogged:false}",
            "minecraft:oak_stairs{facing:west,half:top,shape:outer_right,waterlogged:false}": "minecraft:spruce_stairs{facing:west,half:top,shape:outer_right,waterlogged:false}",
            "minecraft:oak_trapdoor{facing:east,half:bottom,open:false,powered:false,waterlogged:false}": "minecraft:spruce_trapdoor{facing:east,half:bottom,open:false,powered:false,waterlogged:false}",
            "minecraft:oak_trapdoor{facing:north,half:bottom,open:false,powered:false,waterlogged:false}": "minecraft:spruce_trapdoor{facing:north,half:bottom,open:false,powered:false,waterlogged:false}",
            "minecraft:oak_trapdoor{facing:south,half:bottom,open:false,powered:false,waterlogged:false}": "minecraft:spruce_trapdoor{facing:south,half:bottom,open:false,powered:false,waterlogged:false}",
            "minecraft:oak_trapdoor{facing:west,half:bottom,open:false,powered:false,waterlogged:false}": "minecraft:spruce_trapdoor{facing:west,half:bottom,open:false,powered:false,waterlogged:false}",
            "minecraft:spruce_fence{east:false,north:false,south:false,waterlogged:false,west:false}": "minecraft:dark_oak_fence{east:false,north:false,south:false,waterlogged:false,west:false}",
            "minecraft:spruce_planks": "minecraft:dark_oak_planks",
            "minecraft:spruce_slab{type:bottom,waterlogged:false}": "minecraft:dark_oak_slab{type:bottom,waterlogged:false}",
            "minecraft:spruce_stairs{facing:east,half:bottom,shape:outer_right,waterlogged:false}": "minecraft:dark_oak_stairs{facing:east,half:bottom,shape:outer_right,waterlogged:false}",
            "minecraft:spruce_stairs{facing:east,half:top,shape:outer_right,waterlogged:false}": "minecraft:dark_oak_stairs{facing:east,half:top,shape:outer_right,waterlogged:false}",
            "minecraft:spruce_stairs{facing:north,half:bottom,shape:outer_right,waterlogged:false}": "minecraft:dark_oak_stairs{facing:north,half:bottom,shape:outer_right,waterlogged:false}",
            "minecraft:spruce_stairs{facing:north,half:top,shape:outer_right,waterlogged:false}": "minecraft:dark_oak_stairs{facing:north,half:top,shape:outer_right,waterlogged:false}",
            "minecraft:spruce_stairs{facing:south,half:bottom,shape:outer_right,waterlogged:false}": "minecraft:dark_oak_stairs{facing:south,half:bottom,shape:outer_right,waterlogged:false}",
            "minecraft:spruce_stairs{facing:south,half:top,shape:outer_right,waterlogged:false}": "minecraft:dark_oak_stairs{facing:south,half:top,shape:outer_right,waterlogged:false}",
            "minecraft:spruce_stairs{facing:west,half:bottom,shape:outer_right,waterlogged:false}": "minecraft:dark_oak_stairs{facing:west,half:bottom,shape:outer_right,waterlogged:false}",
            "minecraft:spruce_stairs{facing:west,half:top,shape:outer_right,waterlogged:false}": "minecraft:dark_oak_stairs{facing:west,half:top,shape:outer_right,waterlogged:false}",
            "minecraft:structure_block{mode:data}": "minecraft:structure_block{mode:data}"
        },
        {
            "minecraft:chest{facing:east,type:single,waterlogged:false}": "minecraft:chest{facing:east,type:single,waterlogged:false}",
            "minecraft:chest{facing:north,type:single,waterlogged:false}": "minecraft:chest{facing:north,type:single,waterlogged:false}",
            "minecraft:chest{facing:south,type:single,waterlogged:false}": "minecraft:chest{facing:south,type:single,waterlogged:false}",
            "minecraft:oak_fence{east:false,north:false,south:false,waterlogged:false,west:false}": "minecraft:oak_fence{east:false,north:false,south:false,waterlogged:false,west:false}",
            "minecraft:oak_log{axis:y}": "minecraft:oak_log{axis:y}",
            "minecraft:oak_planks": "minecraft:oak_planks",
            "minecraft:oak_slab{type:bottom,waterlogged:false}": "minecraft:oak_slab{type:bottom,waterlogged:false}",
            "minecraft:oak_stairs{facing:east,half:bottom,shape:outer_right,waterlogged:false}": "minecraft:oak_stairs{facing:east,half:bottom,shape:outer_right,waterlogged:false}",
            "minecraft:oak_stairs{facing:east,half:top,shape:outer_right,waterlogged:false}": "minecraft:oak_stairs{facing:east,half:top,shape:outer_right,waterlogged:false}",
            "minecraft:oak_stairs{facing:north,half:bottom,shape:outer_right,waterlogged:false}": "minecraft:oak_stairs{facing:north,half:bottom,shape:outer_right,waterlogged:false}",
            "minecraft:oak_stairs{facing:north,half:top,shape:outer_right,waterlogged:false}": "minecraft:oak_stairs{facing:north,half:top,shape:outer_right,waterlogged:false}",
            "minecraft:oak_stairs{facing:south,half:bottom,shape:outer_right,waterlogged:false}": "minecraft:oak_stairs{facing:south,half:bottom,shape:outer_right,waterlogged:false}",
            "minecraft:oak_stairs{facing:south,half:top,shape:outer_right,waterlogged:false}": "minecraft:oak_stairs{facing:south,half:top,shape:outer_right,waterlogged:false}",
            "minecraft:oak_stairs{facing:west,half:bottom,shape:outer_right,waterlogged:false}": "minecraft:oak_stairs{facing:west,half:bottom,shape:outer_right,waterlogged:false}",
            "minecraft:oak_stairs{facing:west,half:top,shape:outer_right,waterlogged:false}": "minecraft:oak_stairs{facing:west,half:top,shape:outer_right,waterlogged:false}",
            "minecraft:oak_trapdoor{facing:east,half:bottom,open:false,powered:false,waterlogged:false}": "minecraft:oak_trapdoor{facing:east,half:bottom,open:false,powered:false,waterlogged:false}",
            "minecraft:oak_trapdoor{facing:north,half:bottom,open:false,powered:false,waterlogged:false}": "minecraft:oak_trapdoor{facing:north,half:bottom,open:false,powered:false,waterlogged:false}",
            "minecraft:oak_trapdoor{facing:south,half:bottom,open:false,powered:false,waterlogged:false}": "minecraft:oak_trapdoor{facing:south,half:bottom,open:false,powered:false,waterlogged:false}",
            "minecraft:oak_trapdoor{facing:west,half:bottom,open:false,powered:false,waterlogged:false}": "minecraft:oak_trapdoor{facing:west,half:bottom,open:false,powered:false,waterlogged:false}",
            "minecraft:spruce_fence{east:false,north:false,south:false,waterlogged:false,west:false}": "minecraft:birch_fence{east:false,north:false,south:false,waterlogged:false,west:false}",
            "minecraft:spruce_planks": "minecraft:birch_planks",
            "minecraft:spruce_slab{type:bottom,waterlogged:false}": "minecraft:birch_slab{type:bottom,waterlogged:false}",
            "minecraft:spruce_stairs{facing:east,half:bottom,shape:outer_right,waterlogged:false}": "minecraft:birch_stairs{facing:east,half:bottom,shape:outer_right,waterlogged:false}",
            "minecraft:spruce_stairs{facing:east,half:top,shape:outer_right,waterlogged:false}": "minecraft:birch_stairs{facing:east,half:top,shape:outer_right,waterlogged:false}",
            "minecraft:spruce_stairs{facing:north,half:bottom,shape:outer_right,waterlogged:false}": "minecraft:birch_stairs{facing:north,half:bottom,shape:outer_right,waterlogged:false}",
            "minecraft:spruce_stairs{facing:north,half:top,shape:outer_right,waterlogged:false}": "minecraft:birch_stairs{facing:north,half:top,shape:outer_right,waterlogged:false}",
            "minecraft:spruce_stairs{facing:south,half:bottom,shape:outer_right,waterlogged:false}": "minecraft:birch_stairs{facing:south,half:bottom,shape:outer_right,waterlogged:false}",
            "minecraft:spruce_stairs{facing:south,half:top,shape:outer_right,waterlogged:false}": "minecraft:birch_stairs{facing:south,half:top,shape:outer_right,waterlogged:false}",
            "minecraft:spruce_stairs{facing:west,half:bottom,shape:outer_right,waterlogged:false}": "minecraft:birch_stairs{facing:west,half:bottom,shape:outer_right,waterlogged:false}",
            "minecraft:spruce_stairs{facing:west,half:top,shape:outer_right,waterlogged:false}": "minecraft:birch_stairs{facing:west,half:top,shape:outer_right,waterlogged:false}",
            "minecraft:structure_block{mode:data}": "minecraft:structure_block{mode:data}"
        }
    ]
}
