{
    DataVersion: 2856,
    size: [9, 21, 28],
    data: [
        {pos: [4, 0, 8], state: "minecraft:spruce_stairs{facing:south,half:top,shape:outer_right,waterlogged:false}"},
        {pos: [4, 0, 9], state: "minecraft:spruce_planks"},
        {pos: [4, 0, 10], state: "minecraft:spruce_planks"},
        {pos: [4, 0, 11], state: "minecraft:spruce_planks"},
        {pos: [4, 0, 12], state: "minecraft:spruce_planks"},
        {pos: [4, 0, 13], state: "minecraft:spruce_planks"},
        {pos: [4, 0, 14], state: "minecraft:spruce_planks"},
        {pos: [4, 0, 15], state: "minecraft:spruce_planks"},
        {pos: [4, 0, 16], state: "minecraft:spruce_planks"},
        {pos: [4, 0, 17], state: "minecraft:spruce_planks"},
        {pos: [4, 0, 18], state: "minecraft:spruce_planks"},
        {pos: [4, 0, 19], state: "minecraft:spruce_planks"},
        {pos: [4, 0, 20], state: "minecraft:spruce_planks"},
        {pos: [4, 0, 21], state: "minecraft:spruce_stairs{facing:north,half:top,shape:outer_right,waterlogged:false}"},
        {pos: [4, 0, 25], state: "minecraft:spruce_planks"},
        {pos: [4, 0, 26], state: "minecraft:spruce_planks"},
        {pos: [2, 1, 9], state: "minecraft:oak_stairs{facing:east,half:top,shape:outer_right,waterlogged:false}"},
        {pos: [2, 1, 10], state: "minecraft:oak_stairs{facing:east,half:top,shape:outer_right,waterlogged:false}"},
        {pos: [2, 1, 11], state: "minecraft:oak_stairs{facing:east,half:top,shape:outer_right,waterlogged:false}"},
        {pos: [2, 1, 12], state: "minecraft:oak_stairs{facing:east,half:top,shape:outer_right,waterlogged:false}"},
        {pos: [2, 1, 13], state: "minecraft:oak_stairs{facing:east,half:top,shape:outer_right,waterlogged:false}"},
        {pos: [2, 1, 14], state: "minecraft:oak_stairs{facing:east,half:top,shape:outer_right,waterlogged:false}"},
        {pos: [2, 1, 15], state: "minecraft:oak_stairs{facing:east,half:top,shape:outer_right,waterlogged:false}"},
        {pos: [2, 1, 16], state: "minecraft:oak_stairs{facing:east,half:top,shape:outer_right,waterlogged:false}"},
        {pos: [2, 1, 17], state: "minecraft:oak_stairs{facing:east,half:top,shape:outer_right,waterlogged:false}"},
        {pos: [2, 1, 18], state: "minecraft:oak_stairs{facing:east,half:top,shape:outer_right,waterlogged:false}"},
        {pos: [2, 1, 19], state: "minecraft:oak_stairs{facing:east,half:top,shape:outer_right,waterlogged:false}"},
        {pos: [2, 1, 20], state: "minecraft:oak_stairs{facing:east,half:top,shape:outer_right,waterlogged:false}"},
        {pos: [3, 1, 8], state: "minecraft:oak_stairs{facing:east,half:top,shape:outer_right,waterlogged:false}"},
        {pos: [3, 1, 9], state: "minecraft:spruce_planks"},
        {pos: [3, 1, 10], state: "minecraft:spruce_planks"},
        {pos: [3, 1, 11], state: "minecraft:spruce_planks"},
        {pos: [3, 1, 12], state: "minecraft:spruce_planks"},
        {pos: [3, 1, 13], state: "minecraft:spruce_planks"},
        {pos: [3, 1, 14], state: "minecraft:spruce_planks"},
        {pos: [3, 1, 15], state: "minecraft:spruce_planks"},
        {pos: [3, 1, 16], state: "minecraft:spruce_planks"},
        {pos: [3, 1, 17], state: "minecraft:spruce_planks"},
        {pos: [3, 1, 18], state: "minecraft:spruce_planks"},
        {pos: [3, 1, 19], state: "minecraft:spruce_planks"},
        {pos: [3, 1, 20], state: "minecraft:spruce_planks"},
        {pos: [3, 1, 21], state: "minecraft:oak_stairs{facing:east,half:top,shape:outer_right,waterlogged:false}"},
        {pos: [3, 1, 22], state: "minecraft:oak_stairs{facing:east,half:top,shape:outer_right,waterlogged:false}"},
        {pos: [3, 1, 23], state: "minecraft:oak_stairs{facing:east,half:top,shape:outer_right,waterlogged:false}"},
        {pos: [4, 1, 6], state: "minecraft:spruce_stairs{facing:south,half:top,shape:outer_right,waterlogged:false}"},
        {pos: [4, 1, 7], state: "minecraft:spruce_planks"},
        {pos: [4, 1, 8], state: "minecraft:oak_planks"},
        {pos: [4, 1, 9], state: "minecraft:spruce_planks"},
        {pos: [4, 1, 10], state: "minecraft:spruce_planks"},
        {pos: [4, 1, 11], state: "minecraft:oak_planks"},
        {pos: [4, 1, 12], state: "minecraft:spruce_planks"},
        {pos: [4, 1, 13], state: "minecraft:spruce_planks"},
        {pos: [4, 1, 14], state: "minecraft:spruce_planks"},
        {pos: [4, 1, 15], state: "minecraft:spruce_planks"},
        {pos: [4, 1, 16], state: "minecraft:oak_planks"},
        {pos: [4, 1, 17], state: "minecraft:spruce_planks"},
        {pos: [4, 1, 18], state: "minecraft:spruce_planks"},
        {pos: [4, 1, 19], state: "minecraft:spruce_planks"},
        {pos: [4, 1, 20], state: "minecraft:oak_planks"},
        {pos: [4, 1, 21], state: "minecraft:oak_planks"},
        {pos: [4, 1, 22], state: "minecraft:spruce_planks"},
        {pos: [4, 1, 23], state: "minecraft:spruce_planks"},
        {pos: [4, 1, 24], state: "minecraft:spruce_stairs{facing:north,half:top,shape:outer_right,waterlogged:false}"},
        {pos: [4, 1, 25], state: "minecraft:spruce_planks"},
        {pos: [4, 1, 26], state: "minecraft:spruce_planks"},
        {pos: [5, 1, 8], state: "minecraft:oak_stairs{facing:west,half:top,shape:outer_right,waterlogged:false}"},
        {pos: [5, 1, 9], state: "minecraft:spruce_planks"},
        {pos: [5, 1, 10], state: "minecraft:spruce_planks"},
        {pos: [5, 1, 11], state: "minecraft:spruce_planks"},
        {pos: [5, 1, 12], state: "minecraft:spruce_planks"},
        {pos: [5, 1, 13], state: "minecraft:spruce_planks"},
        {pos: [5, 1, 14], state: "minecraft:spruce_planks"},
        {pos: [5, 1, 15], state: "minecraft:spruce_planks"},
        {pos: [5, 1, 16], state: "minecraft:spruce_planks"},
        {pos: [5, 1, 17], state: "minecraft:spruce_planks"},
        {pos: [5, 1, 18], state: "minecraft:spruce_planks"},
        {pos: [5, 1, 19], state: "minecraft:spruce_planks"},
        {pos: [5, 1, 20], state: "minecraft:spruce_planks"},
        {pos: [5, 1, 21], state: "minecraft:oak_stairs{facing:west,half:top,shape:outer_right,waterlogged:false}"},
        {pos: [5, 1, 22], state: "minecraft:oak_stairs{facing:west,half:top,shape:outer_right,waterlogged:false}"},
        {pos: [5, 1, 23], state: "minecraft:oak_stairs{facing:west,half:top,shape:outer_right,waterlogged:false}"},
        {pos: [6, 1, 9], state: "minecraft:oak_stairs{facing:west,half:top,shape:outer_right,waterlogged:false}"},
        {pos: [6, 1, 10], state: "minecraft:oak_stairs{facing:west,half:top,shape:outer_right,waterlogged:false}"},
        {pos: [6, 1, 11], state: "minecraft:oak_stairs{facing:west,half:top,shape:outer_right,waterlogged:false}"},
        {pos: [6, 1, 12], state: "minecraft:oak_stairs{facing:west,half:top,shape:outer_right,waterlogged:false}"},
        {pos: [6, 1, 13], state: "minecraft:oak_stairs{facing:west,half:top,shape:outer_right,waterlogged:false}"},
        {pos: [6, 1, 14], state: "minecraft:oak_stairs{facing:west,half:top,shape:outer_right,waterlogged:false}"},
        {pos: [6, 1, 15], state: "minecraft:oak_stairs{facing:west,half:top,shape:outer_right,waterlogged:false}"},
        {pos: [6, 1, 16], state: "minecraft:oak_stairs{facing:west,half:top,shape:outer_right,waterlogged:false}"},
        {pos: [6, 1, 17], state: "minecraft:oak_stairs{facing:west,half:top,shape:outer_right,waterlogged:false}"},
        {pos: [6, 1, 18], state: "minecraft:oak_stairs{facing:west,half:top,shape:outer_right,waterlogged:false}"},
        {pos: [6, 1, 19], state: "minecraft:oak_stairs{facing:west,half:top,shape:outer_right,waterlogged:false}"},
        {pos: [6, 1, 20], state: "minecraft:oak_stairs{facing:west,half:top,shape:outer_right,waterlogged:false}"},
        {pos: [1, 2, 9], state: "minecraft:oak_stairs{facing:east,half:top,shape:outer_right,waterlogged:false}"},
        {pos: [1, 2, 10], state: "minecraft:oak_stairs{facing:east,half:top,shape:outer_right,waterlogged:false}"},
        {pos: [1, 2, 11], state: "minecraft:oak_stairs{facing:east,half:top,shape:outer_right,waterlogged:false}"},
        {pos: [1, 2, 12], state: "minecraft:oak_stairs{facing:east,half:top,shape:outer_right,waterlogged:false}"},
        {pos: [1, 2, 13], state: "minecraft:oak_stairs{facing:east,half:top,shape:outer_right,waterlogged:false}"},
        {pos: [1, 2, 14], state: "minecraft:oak_stairs{facing:east,half:top,shape:outer_right,waterlogged:false}"},
        {pos: [1, 2, 15], state: "minecraft:oak_stairs{facing:east,half:top,shape:outer_right,waterlogged:false}"},
        {pos: [1, 2, 16], state: "minecraft:oak_stairs{facing:east,half:top,shape:outer_right,waterlogged:false}"},
        {pos: [1, 2, 17], state: "minecraft:oak_stairs{facing:east,half:top,shape:outer_right,waterlogged:false}"},
        {pos: [1, 2, 18], state: "minecraft:oak_stairs{facing:east,half:top,shape:outer_right,waterlogged:false}"},
        {pos: [1, 2, 19], state: "minecraft:oak_stairs{facing:east,half:top,shape:outer_right,waterlogged:false}"},
        {pos: [1, 2, 20], state: "minecraft:oak_stairs{facing:east,half:top,shape:outer_right,waterlogged:false}"},
        {pos: [2, 2, 8], state: "minecraft:oak_stairs{facing:east,half:top,shape:outer_right,waterlogged:false}"},
        {pos: [2, 2, 9], state: "minecraft:oak_planks"},
        {pos: [2, 2, 10], state: "minecraft:oak_planks"},
        {pos: [2, 2, 11], state: "minecraft:oak_planks"},
        {pos: [2, 2, 12], state: "minecraft:oak_stairs{facing:west,half:bottom,shape:outer_right,waterlogged:false}"},
        {pos: [2, 2, 13], state: "minecraft:oak_planks"},
        {pos: [2, 2, 14], state: "minecraft:oak_planks"},
        {pos: [2, 2, 15], state: "minecraft:oak_stairs{facing:west,half:bottom,shape:outer_right,waterlogged:false}"},
        {pos: [2, 2, 16], state: "minecraft:oak_planks"},
        {pos: [2, 2, 17], state: "minecraft:oak_planks"},
        {pos: [2, 2, 18], state: "minecraft:oak_stairs{facing:west,half:bottom,shape:outer_right,waterlogged:false}"},
        {pos: [2, 2, 19], state: "minecraft:oak_planks"},
        {pos: [2, 2, 20], state: "minecraft:oak_planks"},
        {pos: [2, 2, 21], state: "minecraft:oak_stairs{facing:east,half:top,shape:outer_right,waterlogged:false}"},
        {pos: [2, 2, 22], state: "minecraft:oak_stairs{facing:east,half:top,shape:outer_right,waterlogged:false}"},
        {pos: [2, 2, 23], state: "minecraft:oak_stairs{facing:north,half:top,shape:outer_right,waterlogged:false}"},
        {pos: [2, 2, 24], state: "minecraft:oak_slab{type:bottom,waterlogged:false}"},
        {pos: [3, 2, 7], state: "minecraft:oak_stairs{facing:east,half:top,shape:outer_right,waterlogged:false}"},
        {pos: [3, 2, 8], state: "minecraft:oak_planks"},
        {pos: [3, 2, 16], state: "minecraft:oak_door{facing:south,half:lower,hinge:right,open:false,powered:false}"},
        {pos: [3, 2, 19], state: "minecraft:oak_stairs{facing:south,half:top,shape:outer_right,waterlogged:false}"},
        {pos: [3, 2, 20], state: "minecraft:oak_planks"},
        {pos: [3, 2, 21], state: "minecraft:oak_planks"},
        {pos: [3, 2, 22], state: "minecraft:oak_planks"},
        {pos: [3, 2, 23], state: "minecraft:oak_planks"},
        {pos: [3, 2, 24], state: "minecraft:oak_stairs{facing:north,half:top,shape:outer_right,waterlogged:false}"},
        {pos: [4, 2, 5], state: "minecraft:spruce_stairs{facing:south,half:top,shape:outer_right,waterlogged:false}"},
        {pos: [4, 2, 6], state: "minecraft:spruce_planks"},
        {pos: [4, 2, 7], state: "minecraft:oak_planks"},
        {pos: [4, 2, 8], state: "minecraft:oak_planks"},
        {pos: [4, 2, 9], state: "minecraft:chest{facing:south,type:single,waterlogged:false}", nbt: {Items: [], id: "minecraft:chest"}},
        {pos: [4, 2, 11], state: "minecraft:oak_log{axis:y}"},
        {pos: [4, 2, 16], state: "minecraft:oak_log{axis:y}"},
        {pos: [4, 2, 19], state: "minecraft:oak_stairs{facing:south,half:top,shape:outer_right,waterlogged:false}"},
        {pos: [4, 2, 20], state: "minecraft:oak_planks"},
        {pos: [4, 2, 21], state: "minecraft:oak_planks"},
        {pos: [4, 2, 22], state: "minecraft:oak_planks"},
        {pos: [4, 2, 23], state: "minecraft:oak_planks"},
        {pos: [4, 2, 24], state: "minecraft:spruce_planks"},
        {pos: [4, 2, 25], state: "minecraft:spruce_fence{east:false,north:false,south:false,waterlogged:false,west:false}"},
        {pos: [4, 2, 26], state: "minecraft:spruce_planks"},
        {pos: [5, 2, 7], state: "minecraft:oak_stairs{facing:west,half:top,shape:outer_right,waterlogged:false}"},
        {pos: [5, 2, 8], state: "minecraft:oak_planks"},
        {pos: [5, 2, 16], state: "minecraft:oak_planks"},
        {pos: [5, 2, 18], state: "minecraft:chest{facing:west,type:single,waterlogged:false}", nbt: {Items: [], id: "minecraft:chest"}},
        {pos: [5, 2, 19], state: "minecraft:oak_stairs{facing:south,half:top,shape:outer_right,waterlogged:false}"},
        {pos: [5, 2, 20], state: "minecraft:oak_planks"},
        {pos: [5, 2, 21], state: "minecraft:oak_planks"},
        {pos: [5, 2, 22], state: "minecraft:oak_planks"},
        {pos: [5, 2, 23], state: "minecraft:oak_planks"},
        {pos: [5, 2, 24], state: "minecraft:oak_stairs{facing:north,half:top,shape:outer_right,waterlogged:false}"},
        {pos: [6, 2, 8], state: "minecraft:oak_stairs{facing:west,half:top,shape:outer_right,waterlogged:false}"},
        {pos: [6, 2, 9], state: "minecraft:oak_planks"},
        {pos: [6, 2, 10], state: "minecraft:oak_planks"},
        {pos: [6, 2, 11], state: "minecraft:oak_planks"},
        {pos: [6, 2, 12], state: "minecraft:oak_stairs{facing:east,half:bottom,shape:outer_right,waterlogged:false}"},
        {pos: [6, 2, 13], state: "minecraft:oak_planks"},
        {pos: [6, 2, 14], state: "minecraft:oak_planks"},
        {pos: [6, 2, 15], state: "minecraft:oak_stairs{facing:east,half:bottom,shape:outer_right,waterlogged:false}"},
        {pos: [6, 2, 16], state: "minecraft:oak_planks"},
        {pos: [6, 2, 17], state: "minecraft:oak_planks"},
        {pos: [6, 2, 18], state: "minecraft:oak_stairs{facing:east,half:bottom,shape:outer_right,waterlogged:false}"},
        {pos: [6, 2, 19], state: "minecraft:oak_planks"},
        {pos: [6, 2, 20], state: "minecraft:oak_planks"},
        {pos: [6, 2, 21], state: "minecraft:oak_stairs{facing:west,half:top,shape:outer_right,waterlogged:false}"},
        {pos: [6, 2, 22], state: "minecraft:oak_stairs{facing:west,half:top,shape:outer_right,waterlogged:false}"},
        {pos: [6, 2, 23], state: "minecraft:oak_stairs{facing:north,half:top,shape:outer_right,waterlogged:false}"},
        {pos: [6, 2, 24], state: "minecraft:oak_slab{type:bottom,waterlogged:false}"},
        {pos: [7, 2, 9], state: "minecraft:oak_stairs{facing:west,half:top,shape:outer_right,waterlogged:false}"},
        {pos: [7, 2, 10], state: "minecraft:oak_stairs{facing:west,half:top,shape:outer_right,waterlogged:false}"},
        {pos: [7, 2, 11], state: "minecraft:oak_stairs{facing:west,half:top,shape:outer_right,waterlogged:false}"},
        {pos: [7, 2, 12], state: "minecraft:oak_stairs{facing:west,half:top,shape:outer_right,waterlogged:false}"},
        {pos: [7, 2, 13], state: "minecraft:oak_stairs{facing:west,half:top,shape:outer_right,waterlogged:false}"},
        {pos: [7, 2, 14], state: "minecraft:oak_stairs{facing:west,half:top,shape:outer_right,waterlogged:false}"},
        {pos: [7, 2, 15], state: "minecraft:oak_stairs{facing:west,half:top,shape:outer_right,waterlogged:false}"},
        {pos: [7, 2, 16], state: "minecraft:oak_stairs{facing:west,half:top,shape:outer_right,waterlogged:false}"},
        {pos: [7, 2, 17], state: "minecraft:oak_stairs{facing:west,half:top,shape:outer_right,waterlogged:false}"},
        {pos: [7, 2, 18], state: "minecraft:oak_stairs{facing:west,half:top,shape:outer_right,waterlogged:false}"},
        {pos: [7, 2, 19], state: "minecraft:oak_stairs{facing:west,half:top,shape:outer_right,waterlogged:false}"},
        {pos: [7, 2, 20], state: "minecraft:oak_stairs{facing:west,half:top,shape:outer_right,waterlogged:false}"},
        {pos: [1, 3, 8], state: "minecraft:oak_stairs{facing:east,half:top,shape:outer_right,waterlogged:false}"},
        {pos: [1, 3, 9], state: "minecraft:oak_planks"},
        {pos: [1, 3, 10], state: "minecraft:oak_planks"},
        {pos: [1, 3, 11], state: "minecraft:oak_planks"},
        {pos: [1, 3, 13], state: "minecraft:oak_planks"},
        {pos: [1, 3, 14], state: "minecraft:oak_planks"},
        {pos: [1, 3, 16], state: "minecraft:oak_planks"},
        {pos: [1, 3, 17], state: "minecraft:oak_planks"},
        {pos: [1, 3, 19], state: "minecraft:oak_planks"},
        {pos: [1, 3, 20], state: "minecraft:oak_planks"},
        {pos: [1, 3, 21], state: "minecraft:oak_stairs{facing:east,half:top,shape:outer_right,waterlogged:false}"},
        {pos: [1, 3, 22], state: "minecraft:oak_stairs{facing:east,half:top,shape:outer_right,waterlogged:false}"},
        {pos: [1, 3, 23], state: "minecraft:oak_stairs{facing:east,half:top,shape:outer_right,waterlogged:false}"},
        {pos: [1, 3, 24], state: "minecraft:oak_stairs{facing:east,half:top,shape:outer_right,waterlogged:false}"},
        {pos: [2, 3, 7], state: "minecraft:oak_stairs{facing:east,half:top,shape:outer_right,waterlogged:false}"},
        {pos: [2, 3, 8], state: "minecraft:oak_planks"},
        {pos: [2, 3, 9], state: "minecraft:oak_planks"},
        {pos: [2, 3, 10], state: "minecraft:oak_planks"},
        {pos: [2, 3, 11], state: "minecraft:oak_planks"},
        {pos: [2, 3, 13], state: "minecraft:oak_planks"},
        {pos: [2, 3, 14], state: "minecraft:oak_planks"},
        {pos: [2, 3, 16], state: "minecraft:oak_planks"},
        {pos: [2, 3, 17], state: "minecraft:oak_planks"},
        {pos: [2, 3, 19], state: "minecraft:oak_planks"},
        {pos: [2, 3, 20], state: "minecraft:oak_planks"},
        {pos: [2, 3, 21], state: "minecraft:spruce_planks"},
        {pos: [2, 3, 22], state: "minecraft:spruce_planks"},
        {pos: [2, 3, 23], state: "minecraft:spruce_planks"},
        {pos: [2, 3, 24], state: "minecraft:spruce_planks"},
        {pos: [2, 3, 25], state: "minecraft:oak_stairs{facing:north,half:top,shape:outer_right,waterlogged:false}"},
        {pos: [3, 3, 5], state: "minecraft:oak_stairs{facing:east,half:top,shape:outer_right,waterlogged:false}"},
        {pos: [3, 3, 6], state: "minecraft:oak_stairs{facing:east,half:top,shape:outer_right,waterlogged:false}"},
        {pos: [3, 3, 7], state: "minecraft:oak_planks"},
        {pos: [3, 3, 8], state: "minecraft:oak_stairs{facing:north,half:top,shape:outer_right,waterlogged:false}"},
        {pos: [3, 3, 16], state: "minecraft:oak_door{facing:east,half:upper,hinge:right,open:false,powered:false}"},
        {pos: [3, 3, 19], state: "minecraft:oak_stairs{facing:south,half:top,shape:outer_right,waterlogged:false}"},
        {pos: [3, 3, 20], state: "minecraft:spruce_planks"},
        {pos: [3, 3, 21], state: "minecraft:spruce_planks"},
        {pos: [3, 3, 22], state: "minecraft:spruce_planks"},
        {pos: [3, 3, 23], state: "minecraft:spruce_planks"},
        {pos: [3, 3, 24], state: "minecraft:spruce_planks"},
        {pos: [3, 3, 25], state: "minecraft:oak_stairs{facing:north,half:top,shape:outer_right,waterlogged:false}"},
        {pos: [4, 3, 4], state: "minecraft:spruce_stairs{facing:south,half:top,shape:outer_right,waterlogged:false}"},
        {pos: [4, 3, 5], state: "minecraft:oak_planks"},
        {pos: [4, 3, 6], state: "minecraft:oak_planks"},
        {pos: [4, 3, 7], state: "minecraft:oak_planks"},
        {pos: [4, 3, 8], state: "minecraft:oak_stairs{facing:north,half:top,shape:outer_right,waterlogged:false}"},
        {pos: [4, 3, 9], state: "minecraft:structure_block{mode:data}", nbt: {author: "CascadianBacon", id: "minecraft:structure_block", ignoreEntities: 1b, integrity: 1.0f, metadata: "supply_chest", mirror: "NONE", mode: "DATA", name: "", posX: 0, posY: 1, posZ: 0, powered: 0b, rotation: "NONE", seed: 0L, showair: 0b, showboundingbox: 1b, sizeX: 0, sizeY: 0, sizeZ: 0}},
        {pos: [4, 3, 11], state: "minecraft:oak_log{axis:y}"},
        {pos: [4, 3, 16], state: "minecraft:oak_log{axis:y}"},
        {pos: [4, 3, 19], state: "minecraft:oak_stairs{facing:south,half:top,shape:outer_right,waterlogged:false}"},
        {pos: [4, 3, 20], state: "minecraft:spruce_planks"},
        {pos: [4, 3, 21], state: "minecraft:spruce_planks"},
        {pos: [4, 3, 22], state: "minecraft:spruce_planks"},
        {pos: [4, 3, 23], state: "minecraft:spruce_planks"},
        {pos: [4, 3, 24], state: "minecraft:spruce_planks"},
        {pos: [4, 3, 25], state: "minecraft:spruce_fence{east:false,north:false,south:false,waterlogged:false,west:false}"},
        {pos: [5, 3, 5], state: "minecraft:oak_stairs{facing:west,half:top,shape:outer_right,waterlogged:false}"},
        {pos: [5, 3, 6], state: "minecraft:oak_stairs{facing:west,half:top,shape:outer_right,waterlogged:false}"},
        {pos: [5, 3, 7], state: "minecraft:oak_planks"},
        {pos: [5, 3, 8], state: "minecraft:oak_stairs{facing:north,half:top,shape:outer_right,waterlogged:false}"},
        {pos: [5, 3, 16], state: "minecraft:oak_planks"},
        {pos: [5, 3, 18], state: "minecraft:structure_block{mode:data}", nbt: {author: "CascadianBacon", id: "minecraft:structure_block", ignoreEntities: 1b, integrity: 1.0f, metadata: "map_chest", mirror: "NONE", mode: "DATA", name: "", posX: 0, posY: 1, posZ: 0, powered: 0b, rotation: "NONE", seed: 0L, showair: 0b, showboundingbox: 1b, sizeX: 0, sizeY: 0, sizeZ: 0}},
        {pos: [5, 3, 19], state: "minecraft:oak_stairs{facing:south,half:top,shape:outer_right,waterlogged:false}"},
        {pos: [5, 3, 20], state: "minecraft:spruce_planks"},
        {pos: [5, 3, 21], state: "minecraft:spruce_planks"},
        {pos: [5, 3, 22], state: "minecraft:spruce_planks"},
        {pos: [5, 3, 23], state: "minecraft:spruce_planks"},
        {pos: [5, 3, 24], state: "minecraft:spruce_planks"},
        {pos: [5, 3, 25], state: "minecraft:oak_stairs{facing:north,half:top,shape:outer_right,waterlogged:false}"},
        {pos: [6, 3, 7], state: "minecraft:oak_stairs{facing:west,half:top,shape:outer_right,waterlogged:false}"},
        {pos: [6, 3, 8], state: "minecraft:oak_planks"},
        {pos: [6, 3, 9], state: "minecraft:oak_planks"},
        {pos: [6, 3, 10], state: "minecraft:oak_planks"},
        {pos: [6, 3, 11], state: "minecraft:oak_planks"},
        {pos: [6, 3, 13], state: "minecraft:oak_planks"},
        {pos: [6, 3, 14], state: "minecraft:oak_planks"},
        {pos: [6, 3, 16], state: "minecraft:oak_planks"},
        {pos: [6, 3, 17], state: "minecraft:oak_planks"},
        {pos: [6, 3, 19], state: "minecraft:oak_planks"},
        {pos: [6, 3, 20], state: "minecraft:oak_planks"},
        {pos: [6, 3, 21], state: "minecraft:spruce_planks"},
        {pos: [6, 3, 22], state: "minecraft:spruce_planks"},
        {pos: [6, 3, 23], state: "minecraft:spruce_planks"},
        {pos: [6, 3, 24], state: "minecraft:spruce_planks"},
        {pos: [6, 3, 25], state: "minecraft:oak_stairs{facing:north,half:top,shape:outer_right,waterlogged:false}"},
        {pos: [7, 3, 8], state: "minecraft:oak_stairs{facing:west,half:top,shape:outer_right,waterlogged:false}"},
        {pos: [7, 3, 9], state: "minecraft:oak_planks"},
        {pos: [7, 3, 10], state: "minecraft:oak_planks"},
        {pos: [7, 3, 11], state: "minecraft:oak_planks"},
        {pos: [7, 3, 13], state: "minecraft:oak_planks"},
        {pos: [7, 3, 14], state: "minecraft:oak_planks"},
        {pos: [7, 3, 16], state: "minecraft:oak_planks"},
        {pos: [7, 3, 17], state: "minecraft:oak_planks"},
        {pos: [7, 3, 19], state: "minecraft:oak_planks"},
        {pos: [7, 3, 20], state: "minecraft:oak_planks"},
        {pos: [7, 3, 21], state: "minecraft:oak_stairs{facing:west,half:top,shape:outer_right,waterlogged:false}"},
        {pos: [7, 3, 22], state: "minecraft:oak_stairs{facing:west,half:top,shape:outer_right,waterlogged:false}"},
        {pos: [7, 3, 23], state: "minecraft:oak_stairs{facing:west,half:top,shape:outer_right,waterlogged:false}"},
        {pos: [7, 3, 24], state: "minecraft:oak_stairs{facing:west,half:top,shape:outer_right,waterlogged:false}"},
        {pos: [0, 4, 9], state: "minecraft:oak_stairs{facing:east,half:top,shape:outer_right,waterlogged:false}"},
        {pos: [0, 4, 10], state: "minecraft:oak_stairs{facing:east,half:top,shape:outer_right,waterlogged:false}"},
        {pos: [0, 4, 11], state: "minecraft:oak_stairs{facing:east,half:top,shape:outer_right,waterlogged:false}"},
        {pos: [0, 4, 12], state: "minecraft:oak_stairs{facing:east,half:top,shape:outer_right,waterlogged:false}"},
        {pos: [0, 4, 13], state: "minecraft:oak_stairs{facing:east,half:top,shape:outer_right,waterlogged:false}"},
        {pos: [0, 4, 14], state: "minecraft:oak_stairs{facing:east,half:top,shape:outer_right,waterlogged:false}"},
        {pos: [0, 4, 15], state: "minecraft:oak_stairs{facing:east,half:top,shape:outer_right,waterlogged:false}"},
        {pos: [0, 4, 16], state: "minecraft:oak_stairs{facing:east,half:top,shape:outer_right,waterlogged:false}"},
        {pos: [0, 4, 17], state: "minecraft:oak_stairs{facing:east,half:top,shape:outer_right,waterlogged:false}"},
        {pos: [0, 4, 18], state: "minecraft:oak_stairs{facing:east,half:top,shape:outer_right,waterlogged:false}"},
        {pos: [0, 4, 19], state: "minecraft:oak_stairs{facing:east,half:top,shape:outer_right,waterlogged:false}"},
        {pos: [0, 4, 20], state: "minecraft:oak_stairs{facing:east,half:top,shape:outer_right,waterlogged:false}"},
        {pos: [1, 4, 7], state: "minecraft:oak_stairs{facing:east,half:top,shape:outer_right,waterlogged:false}"},
        {pos: [1, 4, 8], state: "minecraft:oak_planks"},
        {pos: [1, 4, 9], state: "minecraft:spruce_slab{type:bottom,waterlogged:false}"},
        {pos: [1, 4, 10], state: "minecraft:spruce_slab{type:bottom,waterlogged:false}"},
        {pos: [1, 4, 11], state: "minecraft:spruce_slab{type:bottom,waterlogged:false}"},
        {pos: [1, 4, 12], state: "minecraft:spruce_slab{type:bottom,waterlogged:false}"},
        {pos: [1, 4, 13], state: "minecraft:spruce_slab{type:bottom,waterlogged:false}"},
        {pos: [1, 4, 14], state: "minecraft:spruce_slab{type:bottom,waterlogged:false}"},
        {pos: [1, 4, 15], state: "minecraft:spruce_slab{type:bottom,waterlogged:false}"},
        {pos: [1, 4, 16], state: "minecraft:spruce_slab{type:bottom,waterlogged:false}"},
        {pos: [1, 4, 17], state: "minecraft:spruce_planks"},
        {pos: [1, 4, 18], state: "minecraft:spruce_planks"},
        {pos: [1, 4, 19], state: "minecraft:oak_planks"},
        {pos: [1, 4, 20], state: "minecraft:oak_planks"},
        {pos: [1, 4, 21], state: "minecraft:oak_planks"},
        {pos: [1, 4, 22], state: "minecraft:oak_planks"},
        {pos: [1, 4, 23], state: "minecraft:oak_planks"},
        {pos: [1, 4, 24], state: "minecraft:oak_planks"},
        {pos: [2, 4, 5], state: "minecraft:oak_stairs{facing:east,half:top,shape:outer_right,waterlogged:false}"},
        {pos: [2, 4, 6], state: "minecraft:oak_stairs{facing:east,half:top,shape:outer_right,waterlogged:false}"},
        {pos: [2, 4, 7], state: "minecraft:oak_planks"},
        {pos: [2, 4, 8], state: "minecraft:oak_planks"},
        {pos: [2, 4, 9], state: "minecraft:spruce_slab{type:bottom,waterlogged:false}"},
        {pos: [2, 4, 10], state: "minecraft:spruce_slab{type:bottom,waterlogged:false}"},
        {pos: [2, 4, 11], state: "minecraft:spruce_slab{type:bottom,waterlogged:false}"},
        {pos: [2, 4, 12], state: "minecraft:spruce_slab{type:bottom,waterlogged:false}"},
        {pos: [2, 4, 13], state: "minecraft:spruce_slab{type:bottom,waterlogged:false}"},
        {pos: [2, 4, 14], state: "minecraft:spruce_slab{type:bottom,waterlogged:false}"},
        {pos: [2, 4, 15], state: "minecraft:spruce_slab{type:bottom,waterlogged:false}"},
        {pos: [2, 4, 16], state: "minecraft:spruce_slab{type:bottom,waterlogged:false}"},
        {pos: [2, 4, 17], state: "minecraft:spruce_slab{type:bottom,waterlogged:false}"},
        {pos: [2, 4, 18], state: "minecraft:spruce_slab{type:bottom,waterlogged:false}"},
        {pos: [2, 4, 19], state: "minecraft:oak_planks"},
        {pos: [2, 4, 20], state: "minecraft:oak_stairs{facing:west,half:bottom,shape:outer_right,waterlogged:false}"},
        {pos: [2, 4, 25], state: "minecraft:oak_planks"},
        {pos: [3, 4, 4], state: "minecraft:oak_stairs{facing:south,half:top,shape:outer_right,waterlogged:false}"},
        {pos: [3, 4, 5], state: "minecraft:oak_planks"},
        {pos: [3, 4, 6], state: "minecraft:oak_planks"},
        {pos: [3, 4, 7], state: "minecraft:oak_planks"},
        {pos: [3, 4, 8], state: "minecraft:spruce_planks"},
        {pos: [3, 4, 9], state: "minecraft:oak_trapdoor{facing:east,half:bottom,open:false,powered:false,waterlogged:false}"},
        {pos: [3, 4, 10], state: "minecraft:oak_trapdoor{facing:east,half:bottom,open:false,powered:false,waterlogged:false}"},
        {pos: [3, 4, 11], state: "minecraft:spruce_slab{type:bottom,waterlogged:false}"},
        {pos: [3, 4, 12], state: "minecraft:oak_trapdoor{facing:south,half:bottom,open:false,powered:false,waterlogged:false}"},
        {pos: [3, 4, 13], state: "minecraft:oak_trapdoor{facing:east,half:bottom,open:false,powered:false,waterlogged:false}"},
        {pos: [3, 4, 14], state: "minecraft:oak_trapdoor{facing:east,half:bottom,open:false,powered:false,waterlogged:false}"},
        {pos: [3, 4, 15], state: "minecraft:oak_trapdoor{facing:north,half:bottom,open:false,powered:false,waterlogged:false}"},
        {pos: [3, 4, 16], state: "minecraft:spruce_slab{type:bottom,waterlogged:false}"},
        {pos: [3, 4, 17], state: "minecraft:spruce_slab{type:bottom,waterlogged:false}"},
        {pos: [3, 4, 18], state: "minecraft:spruce_slab{type:bottom,waterlogged:false}"},
        {pos: [3, 4, 19], state: "minecraft:oak_planks"},
        {pos: [3, 4, 23], state: "minecraft:oak_stairs{facing:west,half:top,shape:outer_right,waterlogged:false}"},
        {pos: [3, 4, 25], state: "minecraft:oak_planks"},
        {pos: [4, 4, 3], state: "minecraft:spruce_stairs{facing:south,half:top,shape:outer_right,waterlogged:false}"},
        {pos: [4, 4, 4], state: "minecraft:spruce_planks"},
        {pos: [4, 4, 5], state: "minecraft:oak_planks"},
        {pos: [4, 4, 6], state: "minecraft:oak_planks"},
        {pos: [4, 4, 7], state: "minecraft:oak_log{axis:y}"},
        {pos: [4, 4, 8], state: "minecraft:spruce_planks"},
        {pos: [4, 4, 9], state: "minecraft:oak_trapdoor{facing:south,half:bottom,open:false,powered:false,waterlogged:false}"},
        {pos: [4, 4, 10], state: "minecraft:oak_trapdoor{facing:north,half:bottom,open:false,powered:false,waterlogged:false}"},
        {pos: [4, 4, 11], state: "minecraft:oak_log{axis:y}"},
        {pos: [4, 4, 12], state: "minecraft:oak_trapdoor{facing:south,half:bottom,open:false,powered:false,waterlogged:false}"},
        {pos: [4, 4, 15], state: "minecraft:oak_trapdoor{facing:north,half:bottom,open:false,powered:false,waterlogged:false}"},
        {pos: [4, 4, 16], state: "minecraft:oak_log{axis:y}"},
        {pos: [4, 4, 17], state: "minecraft:spruce_slab{type:bottom,waterlogged:false}"},
        {pos: [4, 4, 18], state: "minecraft:spruce_slab{type:bottom,waterlogged:false}"},
        {pos: [4, 4, 19], state: "minecraft:spruce_slab{type:bottom,waterlogged:false}"},
        {pos: [4, 4, 23], state: "minecraft:oak_slab{type:bottom,waterlogged:false}"},
        {pos: [4, 4, 25], state: "minecraft:oak_planks"},
        {pos: [4, 4, 26], state: "minecraft:oak_stairs{facing:north,half:top,shape:outer_right,waterlogged:false}"},
        {pos: [5, 4, 4], state: "minecraft:oak_stairs{facing:south,half:top,shape:outer_right,waterlogged:false}"},
        {pos: [5, 4, 5], state: "minecraft:oak_planks"},
        {pos: [5, 4, 6], state: "minecraft:oak_planks"},
        {pos: [5, 4, 7], state: "minecraft:oak_planks"},
        {pos: [5, 4, 8], state: "minecraft:spruce_planks"},
        {pos: [5, 4, 9], state: "minecraft:oak_trapdoor{facing:west,half:bottom,open:false,powered:false,waterlogged:false}"},
        {pos: [5, 4, 10], state: "minecraft:oak_trapdoor{facing:west,half:bottom,open:false,powered:false,waterlogged:false}"},
        {pos: [5, 4, 11], state: "minecraft:spruce_slab{type:bottom,waterlogged:false}"},
        {pos: [5, 4, 12], state: "minecraft:oak_trapdoor{facing:south,half:bottom,open:false,powered:false,waterlogged:false}"},
        {pos: [5, 4, 13], state: "minecraft:oak_trapdoor{facing:west,half:bottom,open:false,powered:false,waterlogged:false}"},
        {pos: [5, 4, 14], state: "minecraft:oak_trapdoor{facing:west,half:bottom,open:false,powered:false,waterlogged:false}"},
        {pos: [5, 4, 15], state: "minecraft:oak_trapdoor{facing:north,half:bottom,open:false,powered:false,waterlogged:false}"},
        {pos: [5, 4, 16], state: "minecraft:spruce_slab{type:bottom,waterlogged:false}"},
        {pos: [5, 4, 17], state: "minecraft:spruce_slab{type:bottom,waterlogged:false}"},
        {pos: [5, 4, 18], state: "minecraft:spruce_slab{type:bottom,waterlogged:false}"},
        {pos: [5, 4, 19], state: "minecraft:oak_planks"},
        {pos: [5, 4, 23], state: "minecraft:oak_stairs{facing:east,half:top,shape:outer_right,waterlogged:false}"},
        {pos: [5, 4, 25], state: "minecraft:oak_planks"},
        {pos: [6, 4, 5], state: "minecraft:oak_stairs{facing:west,half:top,shape:outer_right,waterlogged:false}"},
        {pos: [6, 4, 6], state: "minecraft:oak_stairs{facing:west,half:top,shape:outer_right,waterlogged:false}"},
        {pos: [6, 4, 7], state: "minecraft:oak_planks"},
        {pos: [6, 4, 8], state: "minecraft:oak_planks"},
        {pos: [6, 4, 9], state: "minecraft:spruce_slab{type:bottom,waterlogged:false}"},
        {pos: [6, 4, 10], state: "minecraft:spruce_slab{type:bottom,waterlogged:false}"},
        {pos: [6, 4, 11], state: "minecraft:spruce_slab{type:bottom,waterlogged:false}"},
        {pos: [6, 4, 12], state: "minecraft:spruce_slab{type:bottom,waterlogged:false}"},
        {pos: [6, 4, 13], state: "minecraft:spruce_slab{type:bottom,waterlogged:false}"},
        {pos: [6, 4, 14], state: "minecraft:spruce_slab{type:bottom,waterlogged:false}"},
        {pos: [6, 4, 15], state: "minecraft:spruce_slab{type:bottom,waterlogged:false}"},
        {pos: [6, 4, 16], state: "minecraft:spruce_slab{type:bottom,waterlogged:false}"},
        {pos: [6, 4, 17], state: "minecraft:spruce_slab{type:bottom,waterlogged:false}"},
        {pos: [6, 4, 18], state: "minecraft:spruce_slab{type:bottom,waterlogged:false}"},
        {pos: [6, 4, 19], state: "minecraft:oak_planks"},
        {pos: [6, 4, 20], state: "minecraft:oak_stairs{facing:east,half:bottom,shape:outer_right,waterlogged:false}"},
        {pos: [6, 4, 24], state: "minecraft:chest{facing:north,type:single,waterlogged:false}", nbt: {Items: [], id: "minecraft:chest"}},
        {pos: [6, 4, 25], state: "minecraft:oak_planks"},
        {pos: [7, 4, 7], state: "minecraft:oak_stairs{facing:west,half:top,shape:outer_right,waterlogged:false}"},
        {pos: [7, 4, 8], state: "minecraft:oak_planks"},
        {pos: [7, 4, 9], state: "minecraft:spruce_slab{type:bottom,waterlogged:false}"},
        {pos: [7, 4, 10], state: "minecraft:spruce_slab{type:bottom,waterlogged:false}"},
        {pos: [7, 4, 11], state: "minecraft:spruce_slab{type:bottom,waterlogged:false}"},
        {pos: [7, 4, 12], state: "minecraft:spruce_slab{type:bottom,waterlogged:false}"},
        {pos: [7, 4, 13], state: "minecraft:spruce_slab{type:bottom,waterlogged:false}"},
        {pos: [7, 4, 14], state: "minecraft:spruce_slab{type:bottom,waterlogged:false}"},
        {pos: [7, 4, 15], state: "minecraft:spruce_slab{type:bottom,waterlogged:false}"},
        {pos: [7, 4, 16], state: "minecraft:spruce_slab{type:bottom,waterlogged:false}"},
        {pos: [7, 4, 17], state: "minecraft:spruce_planks"},
        {pos: [7, 4, 18], state: "minecraft:spruce_planks"},
        {pos: [7, 4, 19], state: "minecraft:oak_planks"},
        {pos: [7, 4, 20], state: "minecraft:oak_planks"},
        {pos: [7, 4, 21], state: "minecraft:oak_planks"},
        {pos: [7, 4, 22], state: "minecraft:oak_planks"},
        {pos: [7, 4, 23], state: "minecraft:oak_planks"},
        {pos: [7, 4, 24], state: "minecraft:oak_planks"},
        {pos: [8, 4, 9], state: "minecraft:oak_stairs{facing:west,half:top,shape:outer_right,waterlogged:false}"},
        {pos: [8, 4, 10], state: "minecraft:oak_stairs{facing:west,half:top,shape:outer_right,waterlogged:false}"},
        {pos: [8, 4, 11], state: "minecraft:oak_stairs{facing:west,half:top,shape:outer_right,waterlogged:false}"},
        {pos: [8, 4, 12], state: "minecraft:oak_stairs{facing:west,half:top,shape:outer_right,waterlogged:false}"},
        {pos: [8, 4, 13], state: "minecraft:oak_stairs{facing:west,half:top,shape:outer_right,waterlogged:false}"},
        {pos: [8, 4, 14], state: "minecraft:oak_stairs{facing:west,half:top,shape:outer_right,waterlogged:false}"},
        {pos: [8, 4, 15], state: "minecraft:oak_stairs{facing:west,half:top,shape:outer_right,waterlogged:false}"},
        {pos: [8, 4, 16], state: "minecraft:oak_stairs{facing:west,half:top,shape:outer_right,waterlogged:false}"},
        {pos: [8, 4, 17], state: "minecraft:oak_stairs{facing:west,half:top,shape:outer_right,waterlogged:false}"},
        {pos: [8, 4, 18], state: "minecraft:oak_stairs{facing:west,half:top,shape:outer_right,waterlogged:false}"},
        {pos: [8, 4, 19], state: "minecraft:oak_stairs{facing:west,half:top,shape:outer_right,waterlogged:false}"},
        {pos: [8, 4, 20], state: "minecraft:oak_stairs{facing:west,half:top,shape:outer_right,waterlogged:false}"},
        {pos: [0, 5, 8], state: "minecraft:oak_stairs{facing:south,half:top,shape:outer_right,waterlogged:false}"},
        {pos: [0, 5, 9], state: "minecraft:oak_planks"},
        {pos: [0, 5, 10], state: "minecraft:oak_planks"},
        {pos: [0, 5, 11], state: "minecraft:spruce_fence{east:false,north:false,south:false,waterlogged:false,west:false}"},
        {pos: [0, 5, 12], state: "minecraft:spruce_fence{east:false,north:false,south:false,waterlogged:false,west:false}"},
        {pos: [0, 5, 13], state: "minecraft:spruce_fence{east:false,north:false,south:false,waterlogged:false,west:false}"},
        {pos: [0, 5, 15], state: "minecraft:spruce_fence{east:false,north:false,south:false,waterlogged:false,west:false}"},
        {pos: [0, 5, 16], state: "minecraft:spruce_fence{east:false,north:false,south:false,waterlogged:false,west:false}"},
        {pos: [0, 5, 17], state: "minecraft:spruce_fence{east:false,north:false,south:false,waterlogged:false,west:false}"},
        {pos: [0, 5, 18], state: "minecraft:oak_planks"},
        {pos: [0, 5, 19], state: "minecraft:oak_planks"},
        {pos: [0, 5, 20], state: "minecraft:oak_planks"},
        {pos: [0, 5, 21], state: "minecraft:oak_stairs{facing:east,half:top,shape:outer_right,waterlogged:false}"},
        {pos: [0, 5, 22], state: "minecraft:oak_stairs{facing:east,half:top,shape:outer_right,waterlogged:false}"},
        {pos: [0, 5, 23], state: "minecraft:oak_stairs{facing:north,half:top,shape:outer_right,waterlogged:false}"},
        {pos: [1, 5, 6], state: "minecraft:oak_stairs{facing:east,half:top,shape:outer_right,waterlogged:false}"},
        {pos: [1, 5, 7], state: "minecraft:oak_planks"},
        {pos: [1, 5, 8], state: "minecraft:oak_planks"},
        {pos: [1, 5, 18], state: "minecraft:spruce_stairs{facing:south,half:bottom,shape:outer_right,waterlogged:false}"},
        {pos: [1, 5, 19], state: "minecraft:oak_planks"},
        {pos: [1, 5, 20], state: "minecraft:oak_planks"},
        {pos: [1, 5, 21], state: "minecraft:oak_planks"},
        {pos: [1, 5, 22], state: "minecraft:oak_stairs{facing:west,half:bottom,shape:outer_right,waterlogged:false}"},
        {pos: [1, 5, 23], state: "minecraft:oak_planks"},
        {pos: [1, 5, 24], state: "minecraft:oak_planks"},
        {pos: [1, 5, 25], state: "minecraft:oak_stairs{facing:north,half:top,shape:outer_right,waterlogged:false}"},
        {pos: [2, 5, 5], state: "minecraft:oak_planks"},
        {pos: [2, 5, 6], state: "minecraft:spruce_planks"},
        {pos: [2, 5, 7], state: "minecraft:oak_planks"},
        {pos: [2, 5, 19], state: "minecraft:oak_planks"},
        {pos: [2, 5, 25], state: "minecraft:oak_planks"},
        {pos: [3, 5, 3], state: "minecraft:oak_stairs{facing:south,half:top,shape:outer_right,waterlogged:false}"},
        {pos: [3, 5, 4], state: "minecraft:oak_planks"},
        {pos: [3, 5, 5], state: "minecraft:spruce_planks"},
        {pos: [3, 5, 6], state: "minecraft:spruce_planks"},
        {pos: [3, 5, 7], state: "minecraft:spruce_stairs{facing:north,half:bottom,shape:outer_right,waterlogged:false}"},
        {pos: [3, 5, 19], state: "minecraft:oak_planks"},
        {pos: [3, 5, 25], state: "minecraft:oak_stairs{facing:south,half:bottom,shape:outer_right,waterlogged:false}"},
        {pos: [3, 5, 26], state: "minecraft:oak_stairs{facing:north,half:top,shape:outer_right,waterlogged:false}"},
        {pos: [4, 5, 3], state: "minecraft:spruce_planks"},
        {pos: [4, 5, 4], state: "minecraft:oak_planks"},
        {pos: [4, 5, 5], state: "minecraft:spruce_planks"},
        {pos: [4, 5, 6], state: "minecraft:spruce_planks"},
        {pos: [4, 5, 7], state: "minecraft:oak_log{axis:y}"},
        {pos: [4, 5, 11], state: "minecraft:oak_log{axis:y}"},
        {pos: [4, 5, 16], state: "minecraft:oak_log{axis:y}"},
        {pos: [4, 5, 25], state: "minecraft:oak_stairs{facing:south,half:bottom,shape:outer_right,waterlogged:false}"},
        {pos: [4, 5, 26], state: "minecraft:oak_planks"},
        {pos: [5, 5, 3], state: "minecraft:oak_stairs{facing:south,half:top,shape:outer_right,waterlogged:false}"},
        {pos: [5, 5, 4], state: "minecraft:oak_planks"},
        {pos: [5, 5, 5], state: "minecraft:spruce_planks"},
        {pos: [5, 5, 6], state: "minecraft:spruce_planks"},
        {pos: [5, 5, 7], state: "minecraft:spruce_stairs{facing:north,half:bottom,shape:outer_right,waterlogged:false}"},
        {pos: [5, 5, 19], state: "minecraft:oak_planks"},
        {pos: [5, 5, 25], state: "minecraft:oak_stairs{facing:south,half:bottom,shape:outer_right,waterlogged:false}"},
        {pos: [5, 5, 26], state: "minecraft:oak_stairs{facing:north,half:top,shape:outer_right,waterlogged:false}"},
        {pos: [6, 5, 5], state: "minecraft:oak_planks"},
        {pos: [6, 5, 6], state: "minecraft:spruce_planks"},
        {pos: [6, 5, 7], state: "minecraft:oak_planks"},
        {pos: [6, 5, 19], state: "minecraft:oak_planks"},
        {pos: [6, 5, 24], state: "minecraft:structure_block{mode:data}", nbt: {author: "CascadianBacon", id: "minecraft:structure_block", ignoreEntities: 1b, integrity: 1.0f, metadata: "treasure_chest", mirror: "NONE", mode: "DATA", name: "", posX: 0, posY: 1, posZ: 0, powered: 0b, rotation: "NONE", seed: 0L, showair: 0b, showboundingbox: 1b, sizeX: 0, sizeY: 0, sizeZ: 0}},
        {pos: [6, 5, 25], state: "minecraft:oak_planks"},
        {pos: [7, 5, 6], state: "minecraft:oak_stairs{facing:west,half:top,shape:outer_right,waterlogged:false}"},
        {pos: [7, 5, 7], state: "minecraft:oak_planks"},
        {pos: [7, 5, 8], state: "minecraft:oak_planks"},
        {pos: [7, 5, 18], state: "minecraft:spruce_stairs{facing:south,half:bottom,shape:outer_right,waterlogged:false}"},
        {pos: [7, 5, 19], state: "minecraft:oak_planks"},
        {pos: [7, 5, 20], state: "minecraft:oak_planks"},
        {pos: [7, 5, 21], state: "minecraft:oak_planks"},
        {pos: [7, 5, 22], state: "minecraft:oak_stairs{facing:east,half:bottom,shape:outer_right,waterlogged:false}"},
        {pos: [7, 5, 23], state: "minecraft:oak_planks"},
        {pos: [7, 5, 24], state: "minecraft:oak_planks"},
        {pos: [7, 5, 25], state: "minecraft:oak_stairs{facing:north,half:top,shape:outer_right,waterlogged:false}"},
        {pos: [8, 5, 8], state: "minecraft:oak_stairs{facing:south,half:top,shape:outer_right,waterlogged:false}"},
        {pos: [8, 5, 9], state: "minecraft:oak_planks"},
        {pos: [8, 5, 10], state: "minecraft:oak_planks"},
        {pos: [8, 5, 11], state: "minecraft:spruce_fence{east:false,north:false,south:false,waterlogged:false,west:false}"},
        {pos: [8, 5, 12], state: "minecraft:spruce_fence{east:false,north:false,south:false,waterlogged:false,west:false}"},
        {pos: [8, 5, 13], state: "minecraft:spruce_fence{east:false,north:false,south:false,waterlogged:false,west:false}"},
        {pos: [8, 5, 15], state: "minecraft:spruce_fence{east:false,north:false,south:false,waterlogged:false,west:false}"},
        {pos: [8, 5, 16], state: "minecraft:spruce_fence{east:false,north:false,south:false,waterlogged:false,west:false}"},
        {pos: [8, 5, 17], state: "minecraft:spruce_fence{east:false,north:false,south:false,waterlogged:false,west:false}"},
        {pos: [8, 5, 18], state: "minecraft:oak_planks"},
        {pos: [8, 5, 19], state: "minecraft:oak_planks"},
        {pos: [8, 5, 20], state: "minecraft:oak_planks"},
        {pos: [8, 5, 21], state: "minecraft:oak_stairs{facing:west,half:top,shape:outer_right,waterlogged:false}"},
        {pos: [8, 5, 22], state: "minecraft:oak_stairs{facing:west,half:top,shape:outer_right,waterlogged:false}"},
        {pos: [8, 5, 23], state: "minecraft:oak_stairs{facing:north,half:top,shape:outer_right,waterlogged:false}"},
        {pos: [0, 6, 8], state: "minecraft:oak_planks"},
        {pos: [0, 6, 9], state: "minecraft:oak_stairs{facing:north,half:bottom,shape:outer_right,waterlogged:false}"},
        {pos: [0, 6, 18], state: "minecraft:oak_stairs{facing:south,half:bottom,shape:outer_right,waterlogged:false}"},
        {pos: [0, 6, 19], state: "minecraft:oak_planks"},
        {pos: [0, 6, 20], state: "minecraft:oak_planks"},
        {pos: [0, 6, 21], state: "minecraft:oak_planks"},
        {pos: [0, 6, 23], state: "minecraft:oak_planks"},
        {pos: [1, 6, 6], state: "minecraft:oak_planks"},
        {pos: [1, 6, 7], state: "minecraft:oak_planks"},
        {pos: [1, 6, 8], state: "minecraft:oak_stairs{facing:north,half:bottom,shape:outer_right,waterlogged:false}"},
        {pos: [1, 6, 19], state: "minecraft:spruce_stairs{facing:south,half:bottom,shape:outer_right,waterlogged:false}"},
        {pos: [1, 6, 20], state: "minecraft:spruce_planks"},
        {pos: [1, 6, 21], state: "minecraft:oak_fence{east:false,north:false,south:false,waterlogged:false,west:false}"},
        {pos: [1, 6, 23], state: "minecraft:oak_fence{east:false,north:false,south:false,waterlogged:false,west:false}"},
        {pos: [1, 6, 24], state: "minecraft:oak_planks"},
        {pos: [1, 6, 25], state: "minecraft:oak_planks"},
        {pos: [2, 6, 5], state: "minecraft:oak_planks"},
        {pos: [2, 6, 19], state: "minecraft:oak_planks"},
        {pos: [2, 6, 20], state: "minecraft:spruce_slab{type:bottom,waterlogged:false}"},
        {pos: [2, 6, 25], state: "minecraft:oak_fence{east:false,north:false,south:false,waterlogged:false,west:false}"},
        {pos: [2, 6, 26], state: "minecraft:oak_stairs{facing:north,half:top,shape:outer_right,waterlogged:false}"},
        {pos: [3, 6, 2], state: "minecraft:spruce_fence{east:false,north:false,south:false,waterlogged:false,west:false}"},
        {pos: [3, 6, 3], state: "minecraft:oak_stairs{facing:south,half:bottom,shape:outer_right,waterlogged:false}"},
        {pos: [3, 6, 4], state: "minecraft:oak_planks"},
        {pos: [3, 6, 19], state: "minecraft:oak_planks"},
        {pos: [3, 6, 20], state: "minecraft:spruce_slab{type:bottom,waterlogged:false}"},
        {pos: [3, 6, 26], state: "minecraft:oak_planks"},
        {pos: [4, 6, 2], state: "minecraft:spruce_stairs{facing:south,half:top,shape:outer_right,waterlogged:false}"},
        {pos: [4, 6, 3], state: "minecraft:spruce_planks"},
        {pos: [4, 6, 4], state: "minecraft:spruce_stairs{facing:north,half:bottom,shape:outer_right,waterlogged:false}"},
        {pos: [4, 6, 7], state: "minecraft:oak_log{axis:y}"},
        {pos: [4, 6, 11], state: "minecraft:oak_log{axis:y}"},
        {pos: [4, 6, 16], state: "minecraft:oak_log{axis:y}"},
        {pos: [4, 6, 20], state: "minecraft:spruce_slab{type:bottom,waterlogged:false}"},
        {pos: [5, 6, 2], state: "minecraft:spruce_fence{east:false,north:false,south:false,waterlogged:false,west:false}"},
        {pos: [5, 6, 3], state: "minecraft:oak_stairs{facing:south,half:bottom,shape:outer_right,waterlogged:false}"},
        {pos: [5, 6, 4], state: "minecraft:oak_planks"},
        {pos: [5, 6, 19], state: "minecraft:oak_planks"},
        {pos: [5, 6, 20], state: "minecraft:spruce_slab{type:bottom,waterlogged:false}"},
        {pos: [5, 6, 26], state: "minecraft:oak_planks"},
        {pos: [6, 6, 5], state: "minecraft:oak_planks"},
        {pos: [6, 6, 19], state: "minecraft:oak_planks"},
        {pos: [6, 6, 20], state: "minecraft:spruce_slab{type:bottom,waterlogged:false}"},
        {pos: [6, 6, 25], state: "minecraft:oak_fence{east:false,north:false,south:false,waterlogged:false,west:false}"},
        {pos: [6, 6, 26], state: "minecraft:oak_stairs{facing:north,half:top,shape:outer_right,waterlogged:false}"},
        {pos: [7, 6, 6], state: "minecraft:oak_planks"},
        {pos: [7, 6, 7], state: "minecraft:oak_planks"},
        {pos: [7, 6, 8], state: "minecraft:oak_stairs{facing:north,half:bottom,shape:outer_right,waterlogged:false}"},
        {pos: [7, 6, 19], state: "minecraft:spruce_slab{type:bottom,waterlogged:false}"},
        {pos: [7, 6, 20], state: "minecraft:spruce_planks"},
        {pos: [7, 6, 21], state: "minecraft:oak_fence{east:false,north:false,south:false,waterlogged:false,west:false}"},
        {pos: [7, 6, 23], state: "minecraft:oak_fence{east:false,north:false,south:false,waterlogged:false,west:false}"},
        {pos: [7, 6, 24], state: "minecraft:oak_planks"},
        {pos: [7, 6, 25], state: "minecraft:oak_planks"},
        {pos: [8, 6, 8], state: "minecraft:oak_planks"},
        {pos: [8, 6, 9], state: "minecraft:oak_stairs{facing:north,half:bottom,shape:outer_right,waterlogged:false}"},
        {pos: [8, 6, 18], state: "minecraft:oak_stairs{facing:south,half:bottom,shape:outer_right,waterlogged:false}"},
        {pos: [8, 6, 19], state: "minecraft:oak_planks"},
        {pos: [8, 6, 20], state: "minecraft:oak_planks"},
        {pos: [8, 6, 21], state: "minecraft:oak_planks"},
        {pos: [8, 6, 23], state: "minecraft:oak_planks"},
        {pos: [0, 7, 20], state: "minecraft:oak_stairs{facing:south,half:bottom,shape:outer_right,waterlogged:false}"},
        {pos: [0, 7, 21], state: "minecraft:oak_planks"},
        {pos: [0, 7, 22], state: "minecraft:oak_planks"},
        {pos: [0, 7, 23], state: "minecraft:oak_planks"},
        {pos: [1, 7, 21], state: "minecraft:spruce_planks"},
        {pos: [1, 7, 22], state: "minecraft:spruce_stairs{facing:west,half:top,shape:outer_right,waterlogged:false}"},
        {pos: [1, 7, 23], state: "minecraft:spruce_planks"},
        {pos: [1, 7, 24], state: "minecraft:oak_planks"},
        {pos: [1, 7, 25], state: "minecraft:oak_planks"},
        {pos: [2, 7, 19], state: "minecraft:spruce_fence{east:false,north:false,south:false,waterlogged:false,west:false}"},
        {pos: [2, 7, 21], state: "minecraft:spruce_stairs{facing:south,half:bottom,shape:outer_right,waterlogged:false}"},
        {pos: [2, 7, 22], state: "minecraft:spruce_slab{type:bottom,waterlogged:false}"},
        {pos: [2, 7, 23], state: "minecraft:spruce_slab{type:bottom,waterlogged:false}"},
        {pos: [2, 7, 24], state: "minecraft:spruce_slab{type:bottom,waterlogged:false}"},
        {pos: [2, 7, 25], state: "minecraft:spruce_planks"},
        {pos: [2, 7, 26], state: "minecraft:oak_planks"},
        {pos: [3, 7, 2], state: "minecraft:spruce_fence{east:false,north:false,south:false,waterlogged:false,west:false}"},
        {pos: [3, 7, 3], state: "minecraft:spruce_fence{east:false,north:false,south:false,waterlogged:false,west:false}"},
        {pos: [3, 7, 4], state: "minecraft:spruce_fence{east:false,north:false,south:false,waterlogged:false,west:false}"},
        {pos: [3, 7, 19], state: "minecraft:spruce_fence{east:false,north:false,south:false,waterlogged:false,west:false}"},
        {pos: [3, 7, 21], state: "minecraft:spruce_planks"},
        {pos: [3, 7, 22], state: "minecraft:spruce_slab{type:bottom,waterlogged:false}"},
        {pos: [3, 7, 23], state: "minecraft:spruce_slab{type:bottom,waterlogged:false}"},
        {pos: [3, 7, 24], state: "minecraft:spruce_slab{type:bottom,waterlogged:false}"},
        {pos: [3, 7, 25], state: "minecraft:spruce_stairs{facing:south,half:top,shape:outer_right,waterlogged:false}"},
        {pos: [3, 7, 26], state: "minecraft:oak_planks"},
        {pos: [3, 7, 27], state: "minecraft:oak_stairs{facing:north,half:top,shape:outer_right,waterlogged:false}"},
        {pos: [4, 7, 1], state: "minecraft:spruce_stairs{facing:south,half:top,shape:outer_right,waterlogged:false}"},
        {pos: [4, 7, 2], state: "minecraft:spruce_planks"},
        {pos: [4, 7, 3], state: "minecraft:spruce_stairs{facing:north,half:bottom,shape:outer_right,waterlogged:false}"},
        {pos: [4, 7, 7], state: "minecraft:oak_log{axis:y}"},
        {pos: [4, 7, 11], state: "minecraft:oak_log{axis:y}"},
        {pos: [4, 7, 16], state: "minecraft:oak_log{axis:y}"},
        {pos: [4, 7, 19], state: "minecraft:oak_slab{type:bottom,waterlogged:false}"},
        {pos: [4, 7, 20], state: "minecraft:oak_stairs{facing:south,half:bottom,shape:outer_right,waterlogged:false}"},
        {pos: [4, 7, 21], state: "minecraft:spruce_planks"},
        {pos: [4, 7, 22], state: "minecraft:spruce_slab{type:bottom,waterlogged:false}"},
        {pos: [4, 7, 23], state: "minecraft:spruce_slab{type:bottom,waterlogged:false}"},
        {pos: [4, 7, 24], state: "minecraft:spruce_slab{type:bottom,waterlogged:false}"},
        {pos: [4, 7, 25], state: "minecraft:spruce_slab{type:bottom,waterlogged:false}"},
        {pos: [4, 7, 26], state: "minecraft:spruce_slab{type:bottom,waterlogged:false}"},
        {pos: [4, 7, 27], state: "minecraft:oak_planks"},
        {pos: [5, 7, 2], state: "minecraft:spruce_fence{east:false,north:false,south:false,waterlogged:false,west:false}"},
        {pos: [5, 7, 3], state: "minecraft:spruce_fence{east:false,north:false,south:false,waterlogged:false,west:false}"},
        {pos: [5, 7, 4], state: "minecraft:spruce_fence{east:false,north:false,south:false,waterlogged:false,west:false}"},
        {pos: [5, 7, 19], state: "minecraft:spruce_fence{east:false,north:false,south:false,waterlogged:false,west:false}"},
        {pos: [5, 7, 21], state: "minecraft:spruce_planks"},
        {pos: [5, 7, 22], state: "minecraft:spruce_slab{type:bottom,waterlogged:false}"},
        {pos: [5, 7, 23], state: "minecraft:spruce_slab{type:bottom,waterlogged:false}"},
        {pos: [5, 7, 24], state: "minecraft:spruce_slab{type:bottom,waterlogged:false}"},
        {pos: [5, 7, 25], state: "minecraft:spruce_stairs{facing:south,half:top,shape:outer_right,waterlogged:false}"},
        {pos: [5, 7, 26], state: "minecraft:oak_planks"},
        {pos: [5, 7, 27], state: "minecraft:oak_stairs{facing:north,half:top,shape:outer_right,waterlogged:false}"},
        {pos: [6, 7, 19], state: "minecraft:spruce_fence{east:false,north:false,south:false,waterlogged:false,west:false}"},
        {pos: [6, 7, 21], state: "minecraft:spruce_stairs{facing:south,half:bottom,shape:outer_right,waterlogged:false}"},
        {pos: [6, 7, 22], state: "minecraft:spruce_slab{type:bottom,waterlogged:false}"},
        {pos: [6, 7, 23], state: "minecraft:spruce_slab{type:bottom,waterlogged:false}"},
        {pos: [6, 7, 24], state: "minecraft:spruce_slab{type:bottom,waterlogged:false}"},
        {pos: [6, 7, 25], state: "minecraft:spruce_planks"},
        {pos: [6, 7, 26], state: "minecraft:oak_planks"},
        {pos: [7, 7, 21], state: "minecraft:spruce_planks"},
        {pos: [7, 7, 22], state: "minecraft:spruce_stairs{facing:east,half:top,shape:outer_right,waterlogged:false}"},
        {pos: [7, 7, 23], state: "minecraft:spruce_planks"},
        {pos: [7, 7, 24], state: "minecraft:oak_planks"},
        {pos: [7, 7, 25], state: "minecraft:oak_planks"},
        {pos: [8, 7, 20], state: "minecraft:oak_stairs{facing:south,half:bottom,shape:outer_right,waterlogged:false}"},
        {pos: [8, 7, 21], state: "minecraft:oak_planks"},
        {pos: [8, 7, 22], state: "minecraft:oak_planks"},
        {pos: [8, 7, 23], state: "minecraft:oak_planks"},
        {pos: [0, 8, 21], state: "minecraft:oak_stairs{facing:east,half:bottom,shape:outer_right,waterlogged:false}"},
        {pos: [0, 8, 22], state: "minecraft:oak_stairs{facing:east,half:bottom,shape:outer_right,waterlogged:false}"},
        {pos: [0, 8, 23], state: "minecraft:oak_stairs{facing:east,half:bottom,shape:outer_right,waterlogged:false}"},
        {pos: [1, 8, 21], state: "minecraft:oak_planks"},
        {pos: [1, 8, 23], state: "minecraft:spruce_fence{east:false,north:false,south:false,waterlogged:false,west:false}"},
        {pos: [1, 8, 24], state: "minecraft:spruce_fence{east:false,north:false,south:false,waterlogged:false,west:false}"},
        {pos: [1, 8, 25], state: "minecraft:oak_planks"},
        {pos: [2, 8, 26], state: "minecraft:oak_planks"},
        {pos: [3, 8, 21], state: "minecraft:oak_planks"},
        {pos: [3, 8, 26], state: "minecraft:spruce_fence{east:false,north:false,south:false,waterlogged:false,west:false}"},
        {pos: [3, 8, 27], state: "minecraft:spruce_fence{east:false,north:false,south:false,waterlogged:false,west:false}"},
        {pos: [4, 8, 0], state: "minecraft:spruce_stairs{facing:south,half:top,shape:outer_right,waterlogged:false}"},
        {pos: [4, 8, 1], state: "minecraft:spruce_stairs{facing:north,half:bottom,shape:outer_right,waterlogged:false}"},
        {pos: [4, 8, 7], state: "minecraft:oak_log{axis:y}"},
        {pos: [4, 8, 11], state: "minecraft:oak_log{axis:y}"},
        {pos: [4, 8, 16], state: "minecraft:oak_log{axis:y}"},
        {pos: [4, 8, 21], state: "minecraft:oak_planks"},
        {pos: [4, 8, 27], state: "minecraft:spruce_fence{east:false,north:false,south:false,waterlogged:false,west:false}"},
        {pos: [5, 8, 21], state: "minecraft:oak_planks"},
        {pos: [5, 8, 26], state: "minecraft:spruce_fence{east:false,north:false,south:false,waterlogged:false,west:false}"},
        {pos: [5, 8, 27], state: "minecraft:spruce_fence{east:false,north:false,south:false,waterlogged:false,west:false}"},
        {pos: [6, 8, 26], state: "minecraft:oak_planks"},
        {pos: [7, 8, 21], state: "minecraft:oak_planks"},
        {pos: [7, 8, 23], state: "minecraft:spruce_fence{east:false,north:false,south:false,waterlogged:false,west:false}"},
        {pos: [7, 8, 24], state: "minecraft:spruce_fence{east:false,north:false,south:false,waterlogged:false,west:false}"},
        {pos: [7, 8, 25], state: "minecraft:oak_planks"},
        {pos: [8, 8, 21], state: "minecraft:oak_stairs{facing:west,half:bottom,shape:outer_right,waterlogged:false}"},
        {pos: [8, 8, 22], state: "minecraft:oak_stairs{facing:west,half:bottom,shape:outer_right,waterlogged:false}"},
        {pos: [8, 8, 23], state: "minecraft:oak_stairs{facing:west,half:bottom,shape:outer_right,waterlogged:false}"},
        {pos: [4, 9, 7], state: "minecraft:oak_log{axis:y}"},
        {pos: [4, 9, 11], state: "minecraft:oak_log{axis:y}"},
        {pos: [4, 9, 16], state: "minecraft:oak_log{axis:y}"},
        {pos: [1, 10, 6], state: "minecraft:oak_log{axis:x}"},
        {pos: [2, 10, 6], state: "minecraft:oak_log{axis:x}"},
        {pos: [3, 10, 6], state: "minecraft:oak_log{axis:x}"},
        {pos: [4, 10, 6], state: "minecraft:oak_log{axis:x}"},
        {pos: [4, 10, 7], state: "minecraft:oak_log{axis:y}"},
        {pos: [4, 10, 11], state: "minecraft:oak_log{axis:y}"},
        {pos: [4, 10, 16], state: "minecraft:oak_log{axis:y}"},
        {pos: [5, 10, 6], state: "minecraft:oak_log{axis:x}"},
        {pos: [6, 10, 6], state: "minecraft:oak_log{axis:x}"},
        {pos: [4, 11, 7], state: "minecraft:oak_log{axis:y}"},
        {pos: [4, 11, 11], state: "minecraft:oak_log{axis:y}"},
        {pos: [4, 11, 16], state: "minecraft:oak_log{axis:y}"},
        {pos: [4, 12, 7], state: "minecraft:oak_log{axis:y}"},
        {pos: [4, 12, 11], state: "minecraft:oak_log{axis:y}"},
        {pos: [4, 12, 16], state: "minecraft:oak_log{axis:y}"},
        {pos: [4, 13, 7], state: "minecraft:oak_log{axis:y}"},
        {pos: [4, 13, 11], state: "minecraft:oak_log{axis:y}"},
        {pos: [4, 13, 16], state: "minecraft:oak_log{axis:y}"},
        {pos: [1, 14, 15], state: "minecraft:oak_log{axis:x}"},
        {pos: [2, 14, 15], state: "minecraft:oak_log{axis:x}"},
        {pos: [3, 14, 6], state: "minecraft:oak_log{axis:x}"},
        {pos: [3, 14, 15], state: "minecraft:oak_log{axis:x}"},
        {pos: [4, 14, 6], state: "minecraft:oak_log{axis:x}"},
        {pos: [4, 14, 7], state: "minecraft:oak_log{axis:y}"},
        {pos: [4, 14, 11], state: "minecraft:oak_log{axis:y}"},
        {pos: [4, 14, 15], state: "minecraft:oak_log{axis:x}"},
        {pos: [4, 14, 16], state: "minecraft:oak_log{axis:y}"},
        {pos: [5, 14, 6], state: "minecraft:oak_log{axis:x}"},
        {pos: [5, 14, 15], state: "minecraft:oak_log{axis:x}"},
        {pos: [6, 14, 6], state: "minecraft:oak_log{axis:x}"},
        {pos: [6, 14, 15], state: "minecraft:oak_log{axis:x}"},
        {pos: [7, 14, 6], state: "minecraft:oak_log{axis:x}"},
        {pos: [7, 14, 15], state: "minecraft:oak_log{axis:x}"},
        {pos: [4, 15, 7], state: "minecraft:oak_log{axis:y}"},
        {pos: [4, 15, 11], state: "minecraft:oak_log{axis:y}"},
        {pos: [4, 15, 16], state: "minecraft:oak_log{axis:y}"},
        {pos: [4, 16, 7], state: "minecraft:oak_log{axis:y}"},
        {pos: [4, 16, 11], state: "minecraft:oak_log{axis:y}"},
        {pos: [4, 16, 16], state: "minecraft:oak_log{axis:y}"},
        {pos: [4, 17, 7], state: "minecraft:oak_log{axis:y}"},
        {pos: [4, 17, 11], state: "minecraft:oak_log{axis:y}"},
        {pos: [4, 17, 16], state: "minecraft:oak_log{axis:y}"},
        {pos: [4, 18, 11], state: "minecraft:oak_log{axis:y}"},
        {pos: [4, 19, 11], state: "minecraft:oak_log{axis:y}"},
        {pos: [4, 20, 11], state: "minecraft:oak_log{axis:y}"}
    ],
    entities: [],
    palette: [
        "minecraft:spruce_planks",
        "minecraft:oak_planks",
        "minecraft:oak_log{axis:y}",
        "minecraft:oak_log{axis:x}",
        "minecraft:spruce_stairs{facing:south,half:top,shape:outer_right,waterlogged:false}",
        "minecraft:spruce_stairs{facing:north,half:top,shape:outer_right,waterlogged:false}",
        "minecraft:oak_stairs{facing:east,half:top,shape:outer_right,waterlogged:false}",
        "minecraft:oak_stairs{facing:west,half:top,shape:outer_right,waterlogged:false}",
        "minecraft:oak_stairs{facing:west,half:bottom,shape:outer_right,waterlogged:false}",
        "minecraft:oak_stairs{facing:north,half:top,shape:outer_right,waterlogged:false}",
        "minecraft:oak_slab{type:bottom,waterlogged:false}",
        "minecraft:oak_door{facing:south,half:lower,hinge:right,open:false,powered:false}",
        "minecraft:oak_stairs{facing:south,half:top,shape:outer_right,waterlogged:false}",
        "minecraft:spruce_fence{east:false,north:false,south:false,waterlogged:false,west:false}",
        "minecraft:oak_stairs{facing:east,half:bottom,shape:outer_right,waterlogged:false}",
        "minecraft:oak_door{facing:east,half:upper,hinge:right,open:false,powered:false}",
        "minecraft:spruce_slab{type:bottom,waterlogged:false}",
        "minecraft:oak_trapdoor{facing:east,half:bottom,open:false,powered:false,waterlogged:false}",
        "minecraft:oak_trapdoor{facing:south,half:bottom,open:false,powered:false,waterlogged:false}",
        "minecraft:oak_trapdoor{facing:north,half:bottom,open:false,powered:false,waterlogged:false}",
        "minecraft:oak_trapdoor{facing:west,half:bottom,open:false,powered:false,waterlogged:false}",
        "minecraft:spruce_stairs{facing:south,half:bottom,shape:outer_right,waterlogged:false}",
        "minecraft:spruce_stairs{facing:north,half:bottom,shape:outer_right,waterlogged:false}",
        "minecraft:oak_stairs{facing:south,half:bottom,shape:outer_right,waterlogged:false}",
        "minecraft:oak_stairs{facing:north,half:bottom,shape:outer_right,waterlogged:false}",
        "minecraft:oak_fence{east:false,north:false,south:false,waterlogged:false,west:false}",
        "minecraft:spruce_stairs{facing:west,half:top,shape:outer_right,waterlogged:false}",
        "minecraft:spruce_stairs{facing:east,half:top,shape:outer_right,waterlogged:false}",
        "minecraft:chest{facing:south,type:single,waterlogged:false}",
        "minecraft:chest{facing:west,type:single,waterlogged:false}",
        "minecraft:structure_block{mode:data}",
        "minecraft:chest{facing:north,type:single,waterlogged:false}"
    ],
    palettes: [
        {
            "minecraft:chest{facing:north,type:single,waterlogged:false}": "minecraft:chest{facing:north,type:single,waterlogged:false}",
            "minecraft:chest{facing:south,type:single,waterlogged:false}": "minecraft:chest{facing:south,type:single,waterlogged:false}",
            "minecraft:chest{facing:west,type:single,waterlogged:false}": "minecraft:chest{facing:west,type:single,waterlogged:false}",
            "minecraft:oak_door{facing:east,half:upper,hinge:right,open:false,powered:false}": "minecraft:oak_door{facing:east,half:upper,hinge:right,open:false,powered:false}",
            "minecraft:oak_door{facing:south,half:lower,hinge:right,open:false,powered:false}": "minecraft:oak_door{facing:south,half:lower,hinge:right,open:false,powered:false}",
            "minecraft:oak_fence{east:false,north:false,south:false,waterlogged:false,west:false}": "minecraft:oak_fence{east:false,north:false,south:false,waterlogged:false,west:false}",
            "minecraft:oak_log{axis:x}": "minecraft:oak_log{axis:x}",
            "minecraft:oak_log{axis:y}": "minecraft:oak_log{axis:y}",
            "minecraft:oak_planks": "minecraft:oak_planks",
            "minecraft:oak_slab{type:bottom,waterlogged:false}": "minecraft:oak_slab{type:bottom,waterlogged:false}",
            "minecraft:oak_stairs{facing:east,half:bottom,shape:outer_right,waterlogged:false}": "minecraft:oak_stairs{facing:east,half:bottom,shape:outer_right,waterlogged:false}",
            "minecraft:oak_stairs{facing:east,half:top,shape:outer_right,waterlogged:false}": "minecraft:oak_stairs{facing:east,half:top,shape:outer_right,waterlogged:false}",
            "minecraft:oak_stairs{facing:north,half:bottom,shape:outer_right,waterlogged:false}": "minecraft:oak_stairs{facing:north,half:bottom,shape:outer_right,waterlogged:false}",
            "minecraft:oak_stairs{facing:north,half:top,shape:outer_right,waterlogged:false}": "minecraft:oak_stairs{facing:north,half:top,shape:outer_right,waterlogged:false}",
            "minecraft:oak_stairs{facing:south,half:bottom,shape:outer_right,waterlogged:false}": "minecraft:oak_stairs{facing:south,half:bottom,shape:outer_right,waterlogged:false}",
            "minecraft:oak_stairs{facing:south,half:top,shape:outer_right,waterlogged:false}": "minecraft:oak_stairs{facing:south,half:top,shape:outer_right,waterlogged:false}",
            "minecraft:oak_stairs{facing:west,half:bottom,shape:outer_right,waterlogged:false}": "minecraft:oak_stairs{facing:west,half:bottom,shape:outer_right,waterlogged:false}",
            "minecraft:oak_stairs{facing:west,half:top,shape:outer_right,waterlogged:false}": "minecraft:oak_stairs{facing:west,half:top,shape:outer_right,waterlogged:false}",
            "minecraft:oak_trapdoor{facing:east,half:bottom,open:false,powered:false,waterlogged:false}": "minecraft:oak_trapdoor{facing:east,half:bottom,open:false,powered:false,waterlogged:false}",
            "minecraft:oak_trapdoor{facing:north,half:bottom,open:false,powered:false,waterlogged:false}": "minecraft:oak_trapdoor{facing:north,half:bottom,open:false,powered:false,waterlogged:false}",
            "minecraft:oak_trapdoor{facing:south,half:bottom,open:false,powered:false,waterlogged:false}": "minecraft:oak_trapdoor{facing:south,half:bottom,open:false,powered:false,waterlogged:false}",
            "minecraft:oak_trapdoor{facing:west,half:bottom,open:false,powered:false,waterlogged:false}": "minecraft:oak_trapdoor{facing:west,half:bottom,open:false,powered:false,waterlogged:false}",
            "minecraft:spruce_fence{east:false,north:false,south:false,waterlogged:false,west:false}": "minecraft:spruce_fence{east:false,north:false,south:false,waterlogged:false,west:false}",
            "minecraft:spruce_planks": "minecraft:spruce_planks",
            "minecraft:spruce_slab{type:bottom,waterlogged:false}": "minecraft:spruce_slab{type:bottom,waterlogged:false}",
            "minecraft:spruce_stairs{facing:east,half:top,shape:outer_right,waterlogged:false}": "minecraft:spruce_stairs{facing:east,half:top,shape:outer_right,waterlogged:false}",
            "minecraft:spruce_stairs{facing:north,half:bottom,shape:outer_right,waterlogged:false}": "minecraft:spruce_stairs{facing:north,half:bottom,shape:outer_right,waterlogged:false}",
            "minecraft:spruce_stairs{facing:north,half:top,shape:outer_right,waterlogged:false}": "minecraft:spruce_stairs{facing:north,half:top,shape:outer_right,waterlogged:false}",
            "minecraft:spruce_stairs{facing:south,half:bottom,shape:outer_right,waterlogged:false}": "minecraft:spruce_stairs{facing:south,half:bottom,shape:outer_right,waterlogged:false}",
            "minecraft:spruce_stairs{facing:south,half:top,shape:outer_right,waterlogged:false}": "minecraft:spruce_stairs{facing:south,half:top,shape:outer_right,waterlogged:false}",
            "minecraft:spruce_stairs{facing:west,half:top,shape:outer_right,waterlogged:false}": "minecraft:spruce_stairs{facing:west,half:top,shape:outer_right,waterlogged:false}",
            "minecraft:structure_block{mode:data}": "minecraft:structure_block{mode:data}"
        },
        {
            "minecraft:chest{facing:north,type:single,waterlogged:false}": "minecraft:chest{facing:north,type:single,waterlogged:false}",
            "minecraft:chest{facing:south,type:single,waterlogged:false}": "minecraft:chest{facing:south,type:single,waterlogged:false}",
            "minecraft:chest{facing:west,type:single,waterlogged:false}": "minecraft:chest{facing:west,type:single,waterlogged:false}",
            "minecraft:oak_door{facing:east,half:upper,hinge:right,open:false,powered:false}": "minecraft:jungle_door{facing:east,half:upper,hinge:right,open:false,powered:false}",
            "minecraft:oak_door{facing:south,half:lower,hinge:right,open:false,powered:false}": "minecraft:jungle_door{facing:south,half:lower,hinge:right,open:false,powered:false}",
            "minecraft:oak_fence{east:false,north:false,south:false,waterlogged:false,west:false}": "minecraft:jungle_fence{east:false,north:false,south:false,waterlogged:false,west:false}",
            "minecraft:oak_log{axis:x}": "minecraft:jungle_log{axis:x}",
            "minecraft:oak_log{axis:y}": "minecraft:jungle_log{axis:y}",
            "minecraft:oak_planks": "minecraft:jungle_planks",
            "minecraft:oak_slab{type:bottom,waterlogged:false}": "minecraft:jungle_slab{type:bottom,waterlogged:false}",
            "minecraft:oak_stairs{facing:east,half:bottom,shape:outer_right,waterlogged:false}": "minecraft:jungle_stairs{facing:east,half:bottom,shape:outer_right,waterlogged:false}",
            "minecraft:oak_stairs{facing:east,half:top,shape:outer_right,waterlogged:false}": "minecraft:jungle_stairs{facing:east,half:top,shape:outer_right,waterlogged:false}",
            "minecraft:oak_stairs{facing:north,half:bottom,shape:outer_right,waterlogged:false}": "minecraft:jungle_stairs{facing:north,half:bottom,shape:outer_right,waterlogged:false}",
            "minecraft:oak_stairs{facing:north,half:top,shape:outer_right,waterlogged:false}": "minecraft:jungle_stairs{facing:north,half:top,shape:outer_right,waterlogged:false}",
            "minecraft:oak_stairs{facing:south,half:bottom,shape:outer_right,waterlogged:false}": "minecraft:jungle_stairs{facing:south,half:bottom,shape:outer_right,waterlogged:false}",
            "minecraft:oak_stairs{facing:south,half:top,shape:outer_right,waterlogged:false}": "minecraft:jungle_stairs{facing:south,half:top,shape:outer_right,waterlogged:false}",
            "minecraft:oak_stairs{facing:west,half:bottom,shape:outer_right,waterlogged:false}": "minecraft:jungle_stairs{facing:west,half:bottom,shape:outer_right,waterlogged:false}",
            "minecraft:oak_stairs{facing:west,half:top,shape:outer_right,waterlogged:false}": "minecraft:jungle_stairs{facing:west,half:top,shape:outer_right,waterlogged:false}",
            "minecraft:oak_trapdoor{facing:east,half:bottom,open:false,powered:false,waterlogged:false}": "minecraft:jungle_trapdoor{facing:east,half:bottom,open:false,powered:false,waterlogged:false}",
            "minecraft:oak_trapdoor{facing:north,half:bottom,open:false,powered:false,waterlogged:false}": "minecraft:jungle_trapdoor{facing:north,half:bottom,open:false,powered:false,waterlogged:false}",
            "minecraft:oak_trapdoor{facing:south,half:bottom,open:false,powered:false,waterlogged:false}": "minecraft:jungle_trapdoor{facing:south,half:bottom,open:false,powered:false,waterlogged:false}",
            "minecraft:oak_trapdoor{facing:west,half:bottom,open:false,powered:false,waterlogged:false}": "minecraft:jungle_trapdoor{facing:west,half:bottom,open:false,powered:false,waterlogged:false}",
            "minecraft:spruce_fence{east:false,north:false,south:false,waterlogged:false,west:false}": "minecraft:spruce_fence{east:false,north:false,south:false,waterlogged:false,west:false}",
            "minecraft:spruce_planks": "minecraft:spruce_planks",
            "minecraft:spruce_slab{type:bottom,waterlogged:false}": "minecraft:spruce_slab{type:bottom,waterlogged:false}",
            "minecraft:spruce_stairs{facing:east,half:top,shape:outer_right,waterlogged:false}": "minecraft:spruce_stairs{facing:east,half:top,shape:outer_right,waterlogged:false}",
            "minecraft:spruce_stairs{facing:north,half:bottom,shape:outer_right,waterlogged:false}": "minecraft:spruce_stairs{facing:north,half:bottom,shape:outer_right,waterlogged:false}",
            "minecraft:spruce_stairs{facing:north,half:top,shape:outer_right,waterlogged:false}": "minecraft:spruce_stairs{facing:north,half:top,shape:outer_right,waterlogged:false}",
            "minecraft:spruce_stairs{facing:south,half:bottom,shape:outer_right,waterlogged:false}": "minecraft:spruce_stairs{facing:south,half:bottom,shape:outer_right,waterlogged:false}",
            "minecraft:spruce_stairs{facing:south,half:top,shape:outer_right,waterlogged:false}": "minecraft:spruce_stairs{facing:south,half:top,shape:outer_right,waterlogged:false}",
            "minecraft:spruce_stairs{facing:west,half:top,shape:outer_right,waterlogged:false}": "minecraft:spruce_stairs{facing:west,half:top,shape:outer_right,waterlogged:false}",
            "minecraft:structure_block{mode:data}": "minecraft:structure_block{mode:data}"
        },
        {
            "minecraft:chest{facing:north,type:single,waterlogged:false}": "minecraft:chest{facing:north,type:single,waterlogged:false}",
            "minecraft:chest{facing:south,type:single,waterlogged:false}": "minecraft:chest{facing:south,type:single,waterlogged:false}",
            "minecraft:chest{facing:west,type:single,waterlogged:false}": "minecraft:chest{facing:west,type:single,waterlogged:false}",
            "minecraft:oak_door{facing:east,half:upper,hinge:right,open:false,powered:false}": "minecraft:dark_oak_door{facing:east,half:upper,hinge:right,open:false,powered:false}",
            "minecraft:oak_door{facing:south,half:lower,hinge:right,open:false,powered:false}": "minecraft:dark_oak_door{facing:south,half:lower,hinge:right,open:false,powered:false}",
            "minecraft:oak_fence{east:false,north:false,south:false,waterlogged:false,west:false}": "minecraft:dark_oak_fence{east:false,north:false,south:false,waterlogged:false,west:false}",
            "minecraft:oak_log{axis:x}": "minecraft:dark_oak_log{axis:x}",
            "minecraft:oak_log{axis:y}": "minecraft:dark_oak_log{axis:y}",
            "minecraft:oak_planks": "minecraft:dark_oak_planks",
            "minecraft:oak_slab{type:bottom,waterlogged:false}": "minecraft:dark_oak_slab{type:bottom,waterlogged:false}",
            "minecraft:oak_stairs{facing:east,half:bottom,shape:outer_right,waterlogged:false}": "minecraft:dark_oak_stairs{facing:east,half:bottom,shape:outer_right,waterlogged:false}",
            "minecraft:oak_stairs{facing:east,half:top,shape:outer_right,waterlogged:false}": "minecraft:dark_oak_stairs{facing:east,half:top,shape:outer_right,waterlogged:false}",
            "minecraft:oak_stairs{facing:north,half:bottom,shape:outer_right,waterlogged:false}": "minecraft:dark_oak_stairs{facing:north,half:bottom,shape:outer_right,waterlogged:false}",
            "minecraft:oak_stairs{facing:north,half:top,shape:outer_right,waterlogged:false}": "minecraft:dark_oak_stairs{facing:north,half:top,shape:outer_right,waterlogged:false}",
            "minecraft:oak_stairs{facing:south,half:bottom,shape:outer_right,waterlogged:false}": "minecraft:dark_oak_stairs{facing:south,half:bottom,shape:outer_right,waterlogged:false}",
            "minecraft:oak_stairs{facing:south,half:top,shape:outer_right,waterlogged:false}": "minecraft:dark_oak_stairs{facing:south,half:top,shape:outer_right,waterlogged:false}",
            "minecraft:oak_stairs{facing:west,half:bottom,shape:outer_right,waterlogged:false}": "minecraft:dark_oak_stairs{facing:west,half:bottom,shape:outer_right,waterlogged:false}",
            "minecraft:oak_stairs{facing:west,half:top,shape:outer_right,waterlogged:false}": "minecraft:dark_oak_stairs{facing:west,half:top,shape:outer_right,waterlogged:false}",
            "minecraft:oak_trapdoor{facing:east,half:bottom,open:false,powered:false,waterlogged:false}": "minecraft:dark_oak_trapdoor{facing:east,half:bottom,open:false,powered:false,waterlogged:false}",
            "minecraft:oak_trapdoor{facing:north,half:bottom,open:false,powered:false,waterlogged:false}": "minecraft:dark_oak_trapdoor{facing:north,half:bottom,open:false,powered:false,waterlogged:false}",
            "minecraft:oak_trapdoor{facing:south,half:bottom,open:false,powered:false,waterlogged:false}": "minecraft:dark_oak_trapdoor{facing:south,half:bottom,open:false,powered:false,waterlogged:false}",
            "minecraft:oak_trapdoor{facing:west,half:bottom,open:false,powered:false,waterlogged:false}": "minecraft:dark_oak_trapdoor{facing:west,half:bottom,open:false,powered:false,waterlogged:false}",
            "minecraft:spruce_fence{east:false,north:false,south:false,waterlogged:false,west:false}": "minecraft:jungle_fence{east:false,north:false,south:false,waterlogged:false,west:false}",
            "minecraft:spruce_planks": "minecraft:jungle_planks",
            "minecraft:spruce_slab{type:bottom,waterlogged:false}": "minecraft:jungle_slab{type:bottom,waterlogged:false}",
            "minecraft:spruce_stairs{facing:east,half:top,shape:outer_right,waterlogged:false}": "minecraft:jungle_stairs{facing:east,half:top,shape:outer_right,waterlogged:false}",
            "minecraft:spruce_stairs{facing:north,half:bottom,shape:outer_right,waterlogged:false}": "minecraft:jungle_stairs{facing:north,half:bottom,shape:outer_right,waterlogged:false}",
            "minecraft:spruce_stairs{facing:north,half:top,shape:outer_right,waterlogged:false}": "minecraft:jungle_stairs{facing:north,half:top,shape:outer_right,waterlogged:false}",
            "minecraft:spruce_stairs{facing:south,half:bottom,shape:outer_right,waterlogged:false}": "minecraft:jungle_stairs{facing:south,half:bottom,shape:outer_right,waterlogged:false}",
            "minecraft:spruce_stairs{facing:south,half:top,shape:outer_right,waterlogged:false}": "minecraft:jungle_stairs{facing:south,half:top,shape:outer_right,waterlogged:false}",
            "minecraft:spruce_stairs{facing:west,half:top,shape:outer_right,waterlogged:false}": "minecraft:jungle_stairs{facing:west,half:top,shape:outer_right,waterlogged:false}",
            "minecraft:structure_block{mode:data}": "minecraft:structure_block{mode:data}"
        },
        {
            "minecraft:chest{facing:north,type:single,waterlogged:false}": "minecraft:chest{facing:north,type:single,waterlogged:false}",
            "minecraft:chest{facing:south,type:single,waterlogged:false}": "minecraft:chest{facing:south,type:single,waterlogged:false}",
            "minecraft:chest{facing:west,type:single,waterlogged:false}": "minecraft:chest{facing:west,type:single,waterlogged:false}",
            "minecraft:oak_door{facing:east,half:upper,hinge:right,open:false,powered:false}": "minecraft:dark_oak_door{facing:east,half:upper,hinge:right,open:false,powered:false}",
            "minecraft:oak_door{facing:south,half:lower,hinge:right,open:false,powered:false}": "minecraft:dark_oak_door{facing:south,half:lower,hinge:right,open:false,powered:false}",
            "minecraft:oak_fence{east:false,north:false,south:false,waterlogged:false,west:false}": "minecraft:dark_oak_fence{east:false,north:false,south:false,waterlogged:false,west:false}",
            "minecraft:oak_log{axis:x}": "minecraft:dark_oak_log{axis:x}",
            "minecraft:oak_log{axis:y}": "minecraft:dark_oak_log{axis:y}",
            "minecraft:oak_planks": "minecraft:dark_oak_planks",
            "minecraft:oak_slab{type:bottom,waterlogged:false}": "minecraft:dark_oak_slab{type:bottom,waterlogged:false}",
            "minecraft:oak_stairs{facing:east,half:bottom,shape:outer_right,waterlogged:false}": "minecraft:dark_oak_stairs{facing:east,half:bottom,shape:outer_right,waterlogged:false}",
            "minecraft:oak_stairs{facing:east,half:top,shape:outer_right,waterlogged:false}": "minecraft:dark_oak_stairs{facing:east,half:top,shape:outer_right,waterlogged:false}",
            "minecraft:oak_stairs{facing:north,half:bottom,shape:outer_right,waterlogged:false}": "minecraft:dark_oak_stairs{facing:north,half:bottom,shape:outer_right,waterlogged:false}",
            "minecraft:oak_stairs{facing:north,half:top,shape:outer_right,waterlogged:false}": "minecraft:dark_oak_stairs{facing:north,half:top,shape:outer_right,waterlogged:false}",
            "minecraft:oak_stairs{facing:south,half:bottom,shape:outer_right,waterlogged:false}": "minecraft:dark_oak_stairs{facing:south,half:bottom,shape:outer_right,waterlogged:false}",
            "minecraft:oak_stairs{facing:south,half:top,shape:outer_right,waterlogged:false}": "minecraft:dark_oak_stairs{facing:south,half:top,shape:outer_right,waterlogged:false}",
            "minecraft:oak_stairs{facing:west,half:bottom,shape:outer_right,waterlogged:false}": "minecraft:dark_oak_stairs{facing:west,half:bottom,shape:outer_right,waterlogged:false}",
            "minecraft:oak_stairs{facing:west,half:top,shape:outer_right,waterlogged:false}": "minecraft:dark_oak_stairs{facing:west,half:top,shape:outer_right,waterlogged:false}",
            "minecraft:oak_trapdoor{facing:east,half:bottom,open:false,powered:false,waterlogged:false}": "minecraft:dark_oak_trapdoor{facing:east,half:bottom,open:false,powered:false,waterlogged:false}",
            "minecraft:oak_trapdoor{facing:north,half:bottom,open:false,powered:false,waterlogged:false}": "minecraft:dark_oak_trapdoor{facing:north,half:bottom,open:false,powered:false,waterlogged:false}",
            "minecraft:oak_trapdoor{facing:south,half:bottom,open:false,powered:false,waterlogged:false}": "minecraft:dark_oak_trapdoor{facing:south,half:bottom,open:false,powered:false,waterlogged:false}",
            "minecraft:oak_trapdoor{facing:west,half:bottom,open:false,powered:false,waterlogged:false}": "minecraft:dark_oak_trapdoor{facing:west,half:bottom,open:false,powered:false,waterlogged:false}",
            "minecraft:spruce_fence{east:false,north:false,south:false,waterlogged:false,west:false}": "minecraft:spruce_fence{east:false,north:false,south:false,waterlogged:false,west:false}",
            "minecraft:spruce_planks": "minecraft:spruce_planks",
            "minecraft:spruce_slab{type:bottom,waterlogged:false}": "minecraft:spruce_slab{type:bottom,waterlogged:false}",
            "minecraft:spruce_stairs{facing:east,half:top,shape:outer_right,waterlogged:false}": "minecraft:spruce_stairs{facing:east,half:top,shape:outer_right,waterlogged:false}",
            "minecraft:spruce_stairs{facing:north,half:bottom,shape:outer_right,waterlogged:false}": "minecraft:spruce_stairs{facing:north,half:bottom,shape:outer_right,waterlogged:false}",
            "minecraft:spruce_stairs{facing:north,half:top,shape:outer_right,waterlogged:false}": "minecraft:spruce_stairs{facing:north,half:top,shape:outer_right,waterlogged:false}",
            "minecraft:spruce_stairs{facing:south,half:bottom,shape:outer_right,waterlogged:false}": "minecraft:spruce_stairs{facing:south,half:bottom,shape:outer_right,waterlogged:false}",
            "minecraft:spruce_stairs{facing:south,half:top,shape:outer_right,waterlogged:false}": "minecraft:spruce_stairs{facing:south,half:top,shape:outer_right,waterlogged:false}",
            "minecraft:spruce_stairs{facing:west,half:top,shape:outer_right,waterlogged:false}": "minecraft:spruce_stairs{facing:west,half:top,shape:outer_right,waterlogged:false}",
            "minecraft:structure_block{mode:data}": "minecraft:structure_block{mode:data}"
        },
        {
            "minecraft:chest{facing:north,type:single,waterlogged:false}": "minecraft:chest{facing:north,type:single,waterlogged:false}",
            "minecraft:chest{facing:south,type:single,waterlogged:false}": "minecraft:chest{facing:south,type:single,waterlogged:false}",
            "minecraft:chest{facing:west,type:single,waterlogged:false}": "minecraft:chest{facing:west,type:single,waterlogged:false}",
            "minecraft:oak_door{facing:east,half:upper,hinge:right,open:false,powered:false}": "minecraft:spruce_door{facing:east,half:upper,hinge:right,open:false,powered:false}",
            "minecraft:oak_door{facing:south,half:lower,hinge:right,open:false,powered:false}": "minecraft:spruce_door{facing:south,half:lower,hinge:right,open:false,powered:false}",
            "minecraft:oak_fence{east:false,north:false,south:false,waterlogged:false,west:false}": "minecraft:spruce_fence{east:false,north:false,south:false,waterlogged:false,west:false}",
            "minecraft:oak_log{axis:x}": "minecraft:spruce_log{axis:x}",
            "minecraft:oak_log{axis:y}": "minecraft:spruce_log{axis:y}",
            "minecraft:oak_planks": "minecraft:spruce_planks",
            "minecraft:oak_slab{type:bottom,waterlogged:false}": "minecraft:spruce_slab{type:bottom,waterlogged:false}",
            "minecraft:oak_stairs{facing:east,half:bottom,shape:outer_right,waterlogged:false}": "minecraft:spruce_stairs{facing:east,half:bottom,shape:outer_right,waterlogged:false}",
            "minecraft:oak_stairs{facing:east,half:top,shape:outer_right,waterlogged:false}": "minecraft:spruce_stairs{facing:east,half:top,shape:outer_right,waterlogged:false}",
            "minecraft:oak_stairs{facing:north,half:bottom,shape:outer_right,waterlogged:false}": "minecraft:spruce_stairs{facing:north,half:bottom,shape:outer_right,waterlogged:false}",
            "minecraft:oak_stairs{facing:north,half:top,shape:outer_right,waterlogged:false}": "minecraft:spruce_stairs{facing:north,half:top,shape:outer_right,waterlogged:false}",
            "minecraft:oak_stairs{facing:south,half:bottom,shape:outer_right,waterlogged:false}": "minecraft:spruce_stairs{facing:south,half:bottom,shape:outer_right,waterlogged:false}",
            "minecraft:oak_stairs{facing:south,half:top,shape:outer_right,waterlogged:false}": "minecraft:spruce_stairs{facing:south,half:top,shape:outer_right,waterlogged:false}",
            "minecraft:oak_stairs{facing:west,half:bottom,shape:outer_right,waterlogged:false}": "minecraft:spruce_stairs{facing:west,half:bottom,shape:outer_right,waterlogged:false}",
            "minecraft:oak_stairs{facing:west,half:top,shape:outer_right,waterlogged:false}": "minecraft:spruce_stairs{facing:west,half:top,shape:outer_right,waterlogged:false}",
            "minecraft:oak_trapdoor{facing:east,half:bottom,open:false,powered:false,waterlogged:false}": "minecraft:spruce_trapdoor{facing:east,half:bottom,open:false,powered:false,waterlogged:false}",
            "minecraft:oak_trapdoor{facing:north,half:bottom,open:false,powered:false,waterlogged:false}": "minecraft:spruce_trapdoor{facing:north,half:bottom,open:false,powered:false,waterlogged:false}",
            "minecraft:oak_trapdoor{facing:south,half:bottom,open:false,powered:false,waterlogged:false}": "minecraft:spruce_trapdoor{facing:south,half:bottom,open:false,powered:false,waterlogged:false}",
            "minecraft:oak_trapdoor{facing:west,half:bottom,open:false,powered:false,waterlogged:false}": "minecraft:spruce_trapdoor{facing:west,half:bottom,open:false,powered:false,waterlogged:false}",
            "minecraft:spruce_fence{east:false,north:false,south:false,waterlogged:false,west:false}": "minecraft:oak_fence{east:false,north:false,south:false,waterlogged:false,west:false}",
            "minecraft:spruce_planks": "minecraft:oak_planks",
            "minecraft:spruce_slab{type:bottom,waterlogged:false}": "minecraft:oak_slab{type:bottom,waterlogged:false}",
            "minecraft:spruce_stairs{facing:east,half:top,shape:outer_right,waterlogged:false}": "minecraft:oak_stairs{facing:east,half:top,shape:outer_right,waterlogged:false}",
            "minecraft:spruce_stairs{facing:north,half:bottom,shape:outer_right,waterlogged:false}": "minecraft:oak_stairs{facing:north,half:bottom,shape:outer_right,waterlogged:false}",
            "minecraft:spruce_stairs{facing:north,half:top,shape:outer_right,waterlogged:false}": "minecraft:oak_stairs{facing:north,half:top,shape:outer_right,waterlogged:false}",
            "minecraft:spruce_stairs{facing:south,half:bottom,shape:outer_right,waterlogged:false}": "minecraft:oak_stairs{facing:south,half:bottom,shape:outer_right,waterlogged:false}",
            "minecraft:spruce_stairs{facing:south,half:top,shape:outer_right,waterlogged:false}": "minecraft:oak_stairs{facing:south,half:top,shape:outer_right,waterlogged:false}",
            "minecraft:spruce_stairs{facing:west,half:top,shape:outer_right,waterlogged:false}": "minecraft:oak_stairs{facing:west,half:top,shape:outer_right,waterlogged:false}",
            "minecraft:structure_block{mode:data}": "minecraft:structure_block{mode:data}"
        },
        {
            "minecraft:chest{facing:north,type:single,waterlogged:false}": "minecraft:chest{facing:north,type:single,waterlogged:false}",
            "minecraft:chest{facing:south,type:single,waterlogged:false}": "minecraft:chest{facing:south,type:single,waterlogged:false}",
            "minecraft:chest{facing:west,type:single,waterlogged:false}": "minecraft:chest{facing:west,type:single,waterlogged:false}",
            "minecraft:oak_door{facing:east,half:upper,hinge:right,open:false,powered:false}": "minecraft:spruce_door{facing:east,half:upper,hinge:right,open:false,powered:false}",
            "minecraft:oak_door{facing:south,half:lower,hinge:right,open:false,powered:false}": "minecraft:spruce_door{facing:south,half:lower,hinge:right,open:false,powered:false}",
            "minecraft:oak_fence{east:false,north:false,south:false,waterlogged:false,west:false}": "minecraft:spruce_fence{east:false,north:false,south:false,waterlogged:false,west:false}",
            "minecraft:oak_log{axis:x}": "minecraft:spruce_log{axis:x}",
            "minecraft:oak_log{axis:y}": "minecraft:spruce_log{axis:y}",
            "minecraft:oak_planks": "minecraft:spruce_planks",
            "minecraft:oak_slab{type:bottom,waterlogged:false}": "minecraft:spruce_slab{type:bottom,waterlogged:false}",
            "minecraft:oak_stairs{facing:east,half:bottom,shape:outer_right,waterlogged:false}": "minecraft:spruce_stairs{facing:east,half:bottom,shape:outer_right,waterlogged:false}",
            "minecraft:oak_stairs{facing:east,half:top,shape:outer_right,waterlogged:false}": "minecraft:spruce_stairs{facing:east,half:top,shape:outer_right,waterlogged:false}",
            "minecraft:oak_stairs{facing:north,half:bottom,shape:outer_right,waterlogged:false}": "minecraft:spruce_stairs{facing:north,half:bottom,shape:outer_right,waterlogged:false}",
            "minecraft:oak_stairs{facing:north,half:top,shape:outer_right,waterlogged:false}": "minecraft:spruce_stairs{facing:north,half:top,shape:outer_right,waterlogged:false}",
            "minecraft:oak_stairs{facing:south,half:bottom,shape:outer_right,waterlogged:false}": "minecraft:spruce_stairs{facing:south,half:bottom,shape:outer_right,waterlogged:false}",
            "minecraft:oak_stairs{facing:south,half:top,shape:outer_right,waterlogged:false}": "minecraft:spruce_stairs{facing:south,half:top,shape:outer_right,waterlogged:false}",
            "minecraft:oak_stairs{facing:west,half:bottom,shape:outer_right,waterlogged:false}": "minecraft:spruce_stairs{facing:west,half:bottom,shape:outer_right,waterlogged:false}",
            "minecraft:oak_stairs{facing:west,half:top,shape:outer_right,waterlogged:false}": "minecraft:spruce_stairs{facing:west,half:top,shape:outer_right,waterlogged:false}",
            "minecraft:oak_trapdoor{facing:east,half:bottom,open:false,powered:false,waterlogged:false}": "minecraft:spruce_trapdoor{facing:east,half:bottom,open:false,powered:false,waterlogged:false}",
            "minecraft:oak_trapdoor{facing:north,half:bottom,open:false,powered:false,waterlogged:false}": "minecraft:spruce_trapdoor{facing:north,half:bottom,open:false,powered:false,waterlogged:false}",
            "minecraft:oak_trapdoor{facing:south,half:bottom,open:false,powered:false,waterlogged:false}": "minecraft:spruce_trapdoor{facing:south,half:bottom,open:false,powered:false,waterlogged:false}",
            "minecraft:oak_trapdoor{facing:west,half:bottom,open:false,powered:false,waterlogged:false}": "minecraft:spruce_trapdoor{facing:west,half:bottom,open:false,powered:false,waterlogged:false}",
            "minecraft:spruce_fence{east:false,north:false,south:false,waterlogged:false,west:false}": "minecraft:jungle_fence{east:false,north:false,south:false,waterlogged:false,west:false}",
            "minecraft:spruce_planks": "minecraft:jungle_planks",
            "minecraft:spruce_slab{type:bottom,waterlogged:false}": "minecraft:jungle_slab{type:bottom,waterlogged:false}",
            "minecraft:spruce_stairs{facing:east,half:top,shape:outer_right,waterlogged:false}": "minecraft:jungle_stairs{facing:east,half:top,shape:outer_right,waterlogged:false}",
            "minecraft:spruce_stairs{facing:north,half:bottom,shape:outer_right,waterlogged:false}": "minecraft:jungle_stairs{facing:north,half:bottom,shape:outer_right,waterlogged:false}",
            "minecraft:spruce_stairs{facing:north,half:top,shape:outer_right,waterlogged:false}": "minecraft:jungle_stairs{facing:north,half:top,shape:outer_right,waterlogged:false}",
            "minecraft:spruce_stairs{facing:south,half:bottom,shape:outer_right,waterlogged:false}": "minecraft:jungle_stairs{facing:south,half:bottom,shape:outer_right,waterlogged:false}",
            "minecraft:spruce_stairs{facing:south,half:top,shape:outer_right,waterlogged:false}": "minecraft:jungle_stairs{facing:south,half:top,shape:outer_right,waterlogged:false}",
            "minecraft:spruce_stairs{facing:west,half:top,shape:outer_right,waterlogged:false}": "minecraft:jungle_stairs{facing:west,half:top,shape:outer_right,waterlogged:false}",
            "minecraft:structure_block{mode:data}": "minecraft:structure_block{mode:data}"
        },
        {
            "minecraft:chest{facing:north,type:single,waterlogged:false}": "minecraft:chest{facing:north,type:single,waterlogged:false}",
            "minecraft:chest{facing:south,type:single,waterlogged:false}": "minecraft:chest{facing:south,type:single,waterlogged:false}",
            "minecraft:chest{facing:west,type:single,waterlogged:false}": "minecraft:chest{facing:west,type:single,waterlogged:false}",
            "minecraft:oak_door{facing:east,half:upper,hinge:right,open:false,powered:false}": "minecraft:spruce_door{facing:east,half:upper,hinge:right,open:false,powered:false}",
            "minecraft:oak_door{facing:south,half:lower,hinge:right,open:false,powered:false}": "minecraft:spruce_door{facing:south,half:lower,hinge:right,open:false,powered:false}",
            "minecraft:oak_fence{east:false,north:false,south:false,waterlogged:false,west:false}": "minecraft:spruce_fence{east:false,north:false,south:false,waterlogged:false,west:false}",
            "minecraft:oak_log{axis:x}": "minecraft:spruce_log{axis:x}",
            "minecraft:oak_log{axis:y}": "minecraft:spruce_log{axis:y}",
            "minecraft:oak_planks": "minecraft:spruce_planks",
            "minecraft:oak_slab{type:bottom,waterlogged:false}": "minecraft:spruce_slab{type:bottom,waterlogged:false}",
            "minecraft:oak_stairs{facing:east,half:bottom,shape:outer_right,waterlogged:false}": "minecraft:spruce_stairs{facing:east,half:bottom,shape:outer_right,waterlogged:false}",
            "minecraft:oak_stairs{facing:east,half:top,shape:outer_right,waterlogged:false}": "minecraft:spruce_stairs{facing:east,half:top,shape:outer_right,waterlogged:false}",
            "minecraft:oak_stairs{facing:north,half:bottom,shape:outer_right,waterlogged:false}": "minecraft:spruce_stairs{facing:north,half:bottom,shape:outer_right,waterlogged:false}",
            "minecraft:oak_stairs{facing:north,half:top,shape:outer_right,waterlogged:false}": "minecraft:spruce_stairs{facing:north,half:top,shape:outer_right,waterlogged:false}",
            "minecraft:oak_stairs{facing:south,half:bottom,shape:outer_right,waterlogged:false}": "minecraft:spruce_stairs{facing:south,half:bottom,shape:outer_right,waterlogged:false}",
            "minecraft:oak_stairs{facing:south,half:top,shape:outer_right,waterlogged:false}": "minecraft:spruce_stairs{facing:south,half:top,shape:outer_right,waterlogged:false}",
            "minecraft:oak_stairs{facing:west,half:bottom,shape:outer_right,waterlogged:false}": "minecraft:spruce_stairs{facing:west,half:bottom,shape:outer_right,waterlogged:false}",
            "minecraft:oak_stairs{facing:west,half:top,shape:outer_right,waterlogged:false}": "minecraft:spruce_stairs{facing:west,half:top,shape:outer_right,waterlogged:false}",
            "minecraft:oak_trapdoor{facing:east,half:bottom,open:false,powered:false,waterlogged:false}": "minecraft:spruce_trapdoor{facing:east,half:bottom,open:false,powered:false,waterlogged:false}",
            "minecraft:oak_trapdoor{facing:north,half:bottom,open:false,powered:false,waterlogged:false}": "minecraft:spruce_trapdoor{facing:north,half:bottom,open:false,powered:false,waterlogged:false}",
            "minecraft:oak_trapdoor{facing:south,half:bottom,open:false,powered:false,waterlogged:false}": "minecraft:spruce_trapdoor{facing:south,half:bottom,open:false,powered:false,waterlogged:false}",
            "minecraft:oak_trapdoor{facing:west,half:bottom,open:false,powered:false,waterlogged:false}": "minecraft:spruce_trapdoor{facing:west,half:bottom,open:false,powered:false,waterlogged:false}",
