{
    size: [17, 32, 32],
    data: [
        {pos: [0, 0, 0], state: "minecraft:jigsaw{orientation:down_west}", nbt: {final_state: "minecraft:polished_blackstone_bricks", id: "minecraft:jigsaw", joint: "aligned", name: "minecraft:entrance_base_connector", pool: "minecraft:empty", target: "minecraft:empty"}},
        {pos: [0, 0, 1], state: "minecraft:polished_blackstone_bricks"},
        {pos: [0, 0, 2], state: "minecraft:air"},
        {pos: [0, 0, 3], state: "minecraft:air"},
        {pos: [0, 0, 4], state: "minecraft:polished_blackstone_bricks"},
        {pos: [0, 0, 5], state: "minecraft:polished_blackstone_bricks"},
        {pos: [0, 0, 6], state: "minecraft:polished_blackstone_bricks"},
        {pos: [0, 0, 7], state: "minecraft:polished_blackstone_bricks"},
        {pos: [0, 0, 8], state: "minecraft:lava{level:6}"},
        {pos: [0, 0, 9], state: "minecraft:air"},
        {pos: [0, 0, 10], state: "minecraft:air"},
        {pos: [0, 0, 11], state: "minecraft:polished_blackstone_bricks"},
        {pos: [0, 0, 12], state: "minecraft:polished_blackstone_bricks"},
        {pos: [0, 0, 13], state: "minecraft:polished_blackstone_bricks"},
        {pos: [0, 0, 14], state: "minecraft:polished_blackstone_bricks"},
        {pos: [0, 0, 15], state: "minecraft:polished_blackstone_bricks"},
        {pos: [0, 0, 16], state: "minecraft:blackstone"},
        {pos: [0, 0, 17], state: "minecraft:air"},
        {pos: [0, 0, 18], state: "minecraft:air"},
        {pos: [0, 0, 19], state: "minecraft:air"},
        {pos: [0, 0, 20], state: "minecraft:polished_blackstone_bricks"},
        {pos: [0, 0, 21], state: "minecraft:polished_blackstone_bricks"},
        {pos: [0, 0, 22], state: "minecraft:polished_blackstone_bricks"},
        {pos: [0, 0, 23], state: "minecraft:polished_blackstone_bricks"},
        {pos: [0, 0, 24], state: "minecraft:polished_blackstone_bricks"},
        {pos: [0, 0, 25], state: "minecraft:polished_blackstone_bricks"},
        {pos: [0, 0, 26], state: "minecraft:polished_blackstone_bricks"},
        {pos: [0, 0, 27], state: "minecraft:polished_blackstone_bricks"},
        {pos: [0, 0, 28], state: "minecraft:air"},
        {pos: [0, 0, 29], state: "minecraft:air"},
        {pos: [0, 0, 30], state: "minecraft:air"},
        {pos: [0, 0, 31], state: "minecraft:polished_blackstone_bricks"},
        {pos: [1, 0, 0], state: "minecraft:polished_blackstone_bricks"},
        {pos: [1, 0, 1], state: "minecraft:polished_blackstone_bricks"},
        {pos: [1, 0, 2], state: "minecraft:polished_blackstone_bricks"},
        {pos: [1, 0, 3], state: "minecraft:polished_blackstone_bricks"},
        {pos: [1, 0, 4], state: "minecraft:polished_blackstone_bricks"},
        {pos: [1, 0, 5], state: "minecraft:polished_blackstone_bricks"},
        {pos: [1, 0, 6], state: "minecraft:polished_blackstone_bricks"},
        {pos: [1, 0, 7], state: "minecraft:polished_blackstone_bricks"},
        {pos: [1, 0, 8], state: "minecraft:lava{level:4}"},
        {pos: [1, 0, 9], state: "minecraft:lava{level:6}"},
        {pos: [1, 0, 10], state: "minecraft:air"},
        {pos: [1, 0, 11], state: "minecraft:polished_blackstone_bricks"},
        {pos: [1, 0, 12], state: "minecraft:polished_blackstone_bricks"},
        {pos: [1, 0, 13], state: "minecraft:polished_blackstone_bricks"},
        {pos: [1, 0, 14], state: "minecraft:polished_blackstone_bricks"},
        {pos: [1, 0, 15], state: "minecraft:polished_blackstone_bricks"},
        {pos: [1, 0, 16], state: "minecraft:blackstone"},
        {pos: [1, 0, 17], state: "minecraft:blackstone"},
        {pos: [1, 0, 18], state: "minecraft:air"},
        {pos: [1, 0, 19], state: "minecraft:air"},
        {pos: [1, 0, 20], state: "minecraft:blackstone"},
        {pos: [1, 0, 21], state: "minecraft:lava{level:6}"},
        {pos: [1, 0, 22], state: "minecraft:lava{level:4}"},
        {pos: [1, 0, 23], state: "minecraft:lava{level:2}"},
        {pos: [1, 0, 24], state: "minecraft:polished_blackstone_bricks"},
        {pos: [1, 0, 25], state: "minecraft:polished_blackstone_bricks"},
        {pos: [1, 0, 26], state: "minecraft:polished_blackstone_bricks"},
        {pos: [1, 0, 27], state: "minecraft:polished_blackstone_bricks"},
        {pos: [1, 0, 28], state: "minecraft:polished_blackstone_bricks"},
        {pos: [1, 0, 29], state: "minecraft:polished_blackstone_bricks"},
        {pos: [1, 0, 30], state: "minecraft:polished_blackstone_bricks"},
        {pos: [1, 0, 31], state: "minecraft:polished_blackstone_bricks"},
        {pos: [2, 0, 0], state: "minecraft:polished_blackstone_bricks"},
        {pos: [2, 0, 1], state: "minecraft:polished_blackstone_bricks"},
        {pos: [2, 0, 2], state: "minecraft:polished_blackstone_bricks"},
        {pos: [2, 0, 3], state: "minecraft:polished_blackstone_bricks"},
        {pos: [2, 0, 4], state: "minecraft:polished_blackstone_bricks"},
        {pos: [2, 0, 5], state: "minecraft:polished_blackstone_bricks"},
        {pos: [2, 0, 6], state: "minecraft:polished_blackstone_bricks"},
        {pos: [2, 0, 7], state: "minecraft:lava{level:8}"},
        {pos: [2, 0, 8], state: "minecraft:lava{level:2}"},
        {pos: [2, 0, 9], state: "minecraft:lava{level:4}"},
        {pos: [2, 0, 10], state: "minecraft:lava{level:6}"},
        {pos: [2, 0, 11], state: "minecraft:polished_blackstone_bricks"},
        {pos: [2, 0, 12], state: "minecraft:polished_blackstone_bricks"},
        {pos: [2, 0, 13], state: "minecraft:polished_blackstone_bricks"},
        {pos: [2, 0, 14], state: "minecraft:polished_blackstone_bricks"},
        {pos: [2, 0, 15], state: "minecraft:polished_blackstone_bricks"},
        {pos: [2, 0, 16], state: "minecraft:polished_blackstone_bricks"},
        {pos: [2, 0, 17], state: "minecraft:air"},
        {pos: [2, 0, 18], state: "minecraft:air"},
        {pos: [2, 0, 19], state: "minecraft:blackstone"},
        {pos: [2, 0, 20], state: "minecraft:blackstone"},
        {pos: [2, 0, 21], state: "minecraft:lava{level:4}"},
        {pos: [2, 0, 22], state: "minecraft:lava{level:2}"},
        {pos: [2, 0, 23], state: "minecraft:lava{level:8}"},
        {pos: [2, 0, 24], state: "minecraft:lava{level:2}"},
        {pos: [2, 0, 25], state: "minecraft:polished_blackstone_bricks"},
        {pos: [2, 0, 26], state: "minecraft:polished_blackstone_bricks"},
        {pos: [2, 0, 27], state: "minecraft:polished_blackstone_bricks"},
        {pos: [2, 0, 28], state: "minecraft:polished_blackstone_bricks"},
        {pos: [2, 0, 29], state: "minecraft:polished_blackstone_bricks"},
        {pos: [2, 0, 30], state: "minecraft:polished_blackstone_bricks"},
        {pos: [2, 0, 31], state: "minecraft:polished_blackstone_bricks"},
        {pos: [3, 0, 0], state: "minecraft:polished_blackstone_bricks"},
        {pos: [3, 0, 1], state: "minecraft:polished_blackstone_bricks"},
        {pos: [3, 0, 2], state: "minecraft:polished_blackstone_bricks"},
        {pos: [3, 0, 3], state: "minecraft:polished_blackstone_bricks"},
        {pos: [3, 0, 4], state: "minecraft:polished_blackstone_bricks"},
        {pos: [3, 0, 5], state: "minecraft:polished_blackstone_bricks"},
        {pos: [3, 0, 6], state: "minecraft:polished_blackstone_bricks"},
        {pos: [3, 0, 7], state: "minecraft:lava{level:2}"},
        {pos: [3, 0, 8], state: "minecraft:lava{level:8}"},
        {pos: [3, 0, 9], state: "minecraft:lava{level:2}"},
        {pos: [3, 0, 10], state: "minecraft:lava{level:4}"},
        {pos: [3, 0, 11], state: "minecraft:polished_blackstone_bricks"},
        {pos: [3, 0, 12], state: "minecraft:polished_blackstone_bricks"},
        {pos: [3, 0, 13], state: "minecraft:polished_blackstone_bricks"},
        {pos: [3, 0, 14], state: "minecraft:polished_blackstone_bricks"},
        {pos: [3, 0, 15], state: "minecraft:polished_blackstone_bricks"},
        {pos: [3, 0, 16], state: "minecraft:blackstone"},
        {pos: [3, 0, 17], state: "minecraft:blackstone"},
        {pos: [3, 0, 18], state: "minecraft:air"},
        {pos: [3, 0, 19], state: "minecraft:blackstone"},
        {pos: [3, 0, 20], state: "minecraft:polished_blackstone_bricks"},
        {pos: [3, 0, 21], state: "minecraft:lava{level:4}"},
        {pos: [3, 0, 22], state: "minecraft:lava{level:2}"},
        {pos: [3, 0, 23], state: "minecraft:lava{level:8}"},
        {pos: [3, 0, 24], state: "minecraft:lava{level:2}"},
        {pos: [3, 0, 25], state: "minecraft:polished_blackstone_bricks"},
        {pos: [3, 0, 26], state: "minecraft:polished_blackstone_bricks"},
        {pos: [3, 0, 27], state: "minecraft:polished_blackstone_bricks"},
        {pos: [3, 0, 28], state: "minecraft:polished_blackstone_bricks"},
        {pos: [3, 0, 29], state: "minecraft:polished_blackstone_bricks"},
        {pos: [3, 0, 30], state: "minecraft:polished_blackstone_bricks"},
        {pos: [3, 0, 31], state: "minecraft:polished_blackstone_bricks"},
        {pos: [4, 0, 0], state: "minecraft:polished_blackstone_bricks"},
        {pos: [4, 0, 1], state: "minecraft:polished_blackstone_bricks"},
        {pos: [4, 0, 2], state: "minecraft:polished_blackstone_bricks"},
        {pos: [4, 0, 3], state: "minecraft:polished_blackstone_bricks"},
        {pos: [4, 0, 4], state: "minecraft:polished_blackstone_bricks"},
        {pos: [4, 0, 5], state: "minecraft:polished_blackstone_bricks"},
        {pos: [4, 0, 6], state: "minecraft:polished_blackstone_bricks"},
        {pos: [4, 0, 7], state: "minecraft:lava{level:2}"},
        {pos: [4, 0, 8], state: "minecraft:lava{level:2}"},
        {pos: [4, 0, 9], state: "minecraft:lava{level:4}"},
        {pos: [4, 0, 10], state: "minecraft:lava{level:6}"},
        {pos: [4, 0, 11], state: "minecraft:polished_blackstone_bricks"},
        {pos: [4, 0, 12], state: "minecraft:polished_blackstone_bricks"},
        {pos: [4, 0, 13], state: "minecraft:polished_blackstone_bricks"},
        {pos: [4, 0, 14], state: "minecraft:polished_blackstone_bricks"},
        {pos: [4, 0, 15], state: "minecraft:polished_blackstone_bricks"},
        {pos: [4, 0, 16], state: "minecraft:polished_blackstone_bricks"},
        {pos: [4, 0, 17], state: "minecraft:polished_blackstone_bricks"},
        {pos: [4, 0, 18], state: "minecraft:blackstone"},
        {pos: [4, 0, 19], state: "minecraft:polished_blackstone_bricks"},
        {pos: [4, 0, 20], state: "minecraft:polished_blackstone_bricks"},
        {pos: [4, 0, 21], state: "minecraft:lava{level:6}"},
        {pos: [4, 0, 22], state: "minecraft:blackstone"},
        {pos: [4, 0, 23], state: "minecraft:lava{level:2}"},
        {pos: [4, 0, 24], state: "minecraft:polished_blackstone_bricks"},
        {pos: [4, 0, 25], state: "minecraft:polished_blackstone_bricks"},
        {pos: [4, 0, 26], state: "minecraft:polished_blackstone_bricks"},
        {pos: [4, 0, 27], state: "minecraft:polished_blackstone_bricks"},
        {pos: [4, 0, 28], state: "minecraft:polished_blackstone_bricks"},
        {pos: [4, 0, 29], state: "minecraft:polished_blackstone_bricks"},
        {pos: [4, 0, 30], state: "minecraft:polished_blackstone_bricks"},
        {pos: [4, 0, 31], state: "minecraft:polished_blackstone_bricks"},
        {pos: [5, 0, 0], state: "minecraft:polished_blackstone_bricks"},
        {pos: [5, 0, 1], state: "minecraft:polished_blackstone_bricks"},
        {pos: [5, 0, 2], state: "minecraft:polished_blackstone_bricks"},
        {pos: [5, 0, 3], state: "minecraft:polished_blackstone_bricks"},
        {pos: [5, 0, 4], state: "minecraft:polished_blackstone_bricks"},
        {pos: [5, 0, 5], state: "minecraft:polished_blackstone_bricks"},
        {pos: [5, 0, 6], state: "minecraft:polished_blackstone_bricks"},
        {pos: [5, 0, 7], state: "minecraft:lava{level:8}"},
        {pos: [5, 0, 8], state: "minecraft:lava{level:2}"},
        {pos: [5, 0, 9], state: "minecraft:lava{level:4}"},
        {pos: [5, 0, 10], state: "minecraft:lava{level:6}"},
        {pos: [5, 0, 11], state: "minecraft:polished_blackstone_bricks"},
        {pos: [5, 0, 12], state: "minecraft:polished_blackstone_bricks"},
        {pos: [5, 0, 13], state: "minecraft:polished_blackstone_bricks"},
        {pos: [5, 0, 14], state: "minecraft:polished_blackstone_bricks"},
        {pos: [5, 0, 15], state: "minecraft:polished_blackstone_bricks"},
        {pos: [5, 0, 16], state: "minecraft:polished_blackstone_bricks"},
        {pos: [5, 0, 17], state: "minecraft:polished_blackstone_bricks"},
        {pos: [5, 0, 18], state: "minecraft:air"},
        {pos: [5, 0, 19], state: "minecraft:air"},
        {pos: [5, 0, 20], state: "minecraft:air"},
        {pos: [5, 0, 21], state: "minecraft:lava{level:6}"},
        {pos: [5, 0, 22], state: "minecraft:lava{level:4}"},
        {pos: [5, 0, 23], state: "minecraft:lava{level:2}"},
        {pos: [5, 0, 24], state: "minecraft:lava{level:8}"},
        {pos: [5, 0, 25], state: "minecraft:blackstone"},
        {pos: [5, 0, 26], state: "minecraft:polished_blackstone_bricks"},
        {pos: [5, 0, 27], state: "minecraft:polished_blackstone_bricks"},
        {pos: [5, 0, 28], state: "minecraft:polished_blackstone_bricks"},
        {pos: [5, 0, 29], state: "minecraft:polished_blackstone_bricks"},
        {pos: [5, 0, 30], state: "minecraft:polished_blackstone_bricks"},
        {pos: [5, 0, 31], state: "minecraft:polished_blackstone_bricks"},
        {pos: [6, 0, 0], state: "minecraft:polished_blackstone_bricks"},
        {pos: [6, 0, 1], state: "minecraft:polished_blackstone_bricks"},
        {pos: [6, 0, 2], state: "minecraft:polished_blackstone_bricks"},
        {pos: [6, 0, 3], state: "minecraft:polished_blackstone_bricks"},
        {pos: [6, 0, 4], state: "minecraft:polished_blackstone_bricks"},
        {pos: [6, 0, 5], state: "minecraft:polished_blackstone_bricks"},
        {pos: [6, 0, 6], state: "minecraft:polished_blackstone_bricks"},
        {pos: [6, 0, 7], state: "minecraft:lava{level:8}"},
        {pos: [6, 0, 8], state: "minecraft:lava{level:2}"},
        {pos: [6, 0, 9], state: "minecraft:lava{level:4}"},
        {pos: [6, 0, 10], state: "minecraft:lava{level:6}"},
        {pos: [6, 0, 11], state: "minecraft:air"},
        {pos: [6, 0, 12], state: "minecraft:air"},
        {pos: [6, 0, 13], state: "minecraft:polished_blackstone_bricks"},
        {pos: [6, 0, 14], state: "minecraft:polished_blackstone_bricks"},
        {pos: [6, 0, 15], state: "minecraft:polished_blackstone_bricks"},
        {pos: [6, 0, 16], state: "minecraft:polished_blackstone_bricks"},
        {pos: [6, 0, 17], state: "minecraft:polished_blackstone_bricks"},
        {pos: [6, 0, 18], state: "minecraft:air"},
        {pos: [6, 0, 19], state: "minecraft:air"},
        {pos: [6, 0, 20], state: "minecraft:polished_blackstone_bricks"},
        {pos: [6, 0, 21], state: "minecraft:lava{level:4}"},
        {pos: [6, 0, 22], state: "minecraft:lava{level:2}"},
        {pos: [6, 0, 23], state: "minecraft:lava{level:8}"},
        {pos: [6, 0, 24], state: "minecraft:lava{level:2}"},
        {pos: [6, 0, 25], state: "minecraft:lava{level:4}"},
        {pos: [6, 0, 26], state: "minecraft:polished_blackstone_bricks"},
        {pos: [6, 0, 27], state: "minecraft:polished_blackstone_bricks"},
        {pos: [6, 0, 28], state: "minecraft:polished_blackstone_bricks"},
        {pos: [6, 0, 29], state: "minecraft:polished_blackstone_bricks"},
        {pos: [6, 0, 30], state: "minecraft:polished_blackstone_bricks"},
        {pos: [6, 0, 31], state: "minecraft:polished_blackstone_bricks"},
        {pos: [7, 0, 0], state: "minecraft:polished_blackstone_bricks"},
        {pos: [7, 0, 1], state: "minecraft:polished_blackstone_bricks"},
        {pos: [7, 0, 2], state: "minecraft:polished_blackstone_bricks"},
        {pos: [7, 0, 3], state: "minecraft:polished_blackstone_bricks"},
        {pos: [7, 0, 4], state: "minecraft:polished_blackstone_bricks"},
        {pos: [7, 0, 5], state: "minecraft:polished_blackstone_bricks"},
        {pos: [7, 0, 6], state: "minecraft:polished_blackstone_bricks"},
        {pos: [7, 0, 7], state: "minecraft:polished_blackstone_bricks"},
        {pos: [7, 0, 8], state: "minecraft:lava{level:4}"},
        {pos: [7, 0, 9], state: "minecraft:lava{level:6}"},
        {pos: [7, 0, 10], state: "minecraft:air"},
        {pos: [7, 0, 11], state: "minecraft:air"},
        {pos: [7, 0, 12], state: "minecraft:air"},
        {pos: [7, 0, 13], state: "minecraft:air"},
        {pos: [7, 0, 14], state: "minecraft:polished_blackstone_bricks"},
        {pos: [7, 0, 15], state: "minecraft:polished_blackstone_bricks"},
        {pos: [7, 0, 16], state: "minecraft:polished_blackstone_bricks"},
        {pos: [7, 0, 17], state: "minecraft:polished_blackstone_bricks"},
        {pos: [7, 0, 18], state: "minecraft:polished_blackstone_bricks"},
        {pos: [7, 0, 19], state: "minecraft:blackstone"},
        {pos: [7, 0, 20], state: "minecraft:polished_blackstone_bricks"},
        {pos: [7, 0, 21], state: "minecraft:lava{level:4}"},
        {pos: [7, 0, 22], state: "minecraft:lava{level:2}"},
        {pos: [7, 0, 23], state: "minecraft:lava{level:8}"},
        {pos: [7, 0, 24], state: "minecraft:polished_blackstone_bricks"},
        {pos: [7, 0, 25], state: "minecraft:polished_blackstone_bricks"},
        {pos: [7, 0, 26], state: "minecraft:polished_blackstone_bricks"},
        {pos: [7, 0, 27], state: "minecraft:polished_blackstone_bricks"},
        {pos: [7, 0, 28], state: "minecraft:polished_blackstone_bricks"},
        {pos: [7, 0, 29], state: "minecraft:polished_blackstone_bricks"},
        {pos: [7, 0, 30], state: "minecraft:polished_blackstone_bricks"},
        {pos: [7, 0, 31], state: "minecraft:polished_blackstone_bricks"},
        {pos: [8, 0, 0], state: "minecraft:polished_blackstone_bricks"},
        {pos: [8, 0, 1], state: "minecraft:polished_blackstone_bricks"},
        {pos: [8, 0, 2], state: "minecraft:polished_blackstone_bricks"},
        {pos: [8, 0, 3], state: "minecraft:polished_blackstone_bricks"},
        {pos: [8, 0, 4], state: "minecraft:polished_blackstone_bricks"},
        {pos: [8, 0, 5], state: "minecraft:polished_blackstone_bricks"},
        {pos: [8, 0, 6], state: "minecraft:polished_blackstone_bricks"},
        {pos: [8, 0, 7], state: "minecraft:lava{level:8}"},
        {pos: [8, 0, 8], state: "minecraft:lava{level:2}"},
        {pos: [8, 0, 9], state: "minecraft:lava{level:4}"},
        {pos: [8, 0, 10], state: "minecraft:blackstone"},
        {pos: [8, 0, 11], state: "minecraft:air"},
        {pos: [8, 0, 12], state: "minecraft:air"},
        {pos: [8, 0, 13], state: "minecraft:air"},
        {pos: [8, 0, 14], state: "minecraft:air"},
        {pos: [8, 0, 15], state: "minecraft:polished_blackstone_bricks"},
        {pos: [8, 0, 16], state: "minecraft:polished_blackstone_bricks"},
        {pos: [8, 0, 17], state: "minecraft:polished_blackstone_bricks"},
        {pos: [8, 0, 18], state: "minecraft:polished_blackstone_bricks"},
        {pos: [8, 0, 19], state: "minecraft:air"},
        {pos: [8, 0, 20], state: "minecraft:polished_blackstone_bricks"},
        {pos: [8, 0, 21], state: "minecraft:lava{level:6}"},
        {pos: [8, 0, 22], state: "minecraft:blackstone"},
        {pos: [8, 0, 23], state: "minecraft:lava{level:8}"},
        {pos: [8, 0, 24], state: "minecraft:lava{level:2}"},
        {pos: [8, 0, 25], state: "minecraft:polished_blackstone_bricks"},
        {pos: [8, 0, 26], state: "minecraft:polished_blackstone_bricks"},
        {pos: [8, 0, 27], state: "minecraft:polished_blackstone_bricks"},
        {pos: [8, 0, 28], state: "minecraft:polished_blackstone_bricks"},
        {pos: [8, 0, 29], state: "minecraft:polished_blackstone_bricks"},
        {pos: [8, 0, 30], state: "minecraft:polished_blackstone_bricks"},
        {pos: [8, 0, 31], state: "minecraft:polished_blackstone_bricks"},
        {pos: [9, 0, 0], state: "minecraft:polished_blackstone_bricks"},
        {pos: [9, 0, 1], state: "minecraft:polished_blackstone_bricks"},
        {pos: [9, 0, 2], state: "minecraft:polished_blackstone_bricks"},
        {pos: [9, 0, 3], state: "minecraft:polished_blackstone_bricks"},
        {pos: [9, 0, 4], state: "minecraft:polished_blackstone_bricks"},
        {pos: [9, 0, 5], state: "minecraft:polished_blackstone_bricks"},
        {pos: [9, 0, 6], state: "minecraft:polished_blackstone_bricks"},
        {pos: [9, 0, 7], state: "minecraft:lava{level:8}"},
        {pos: [9, 0, 8], state: "minecraft:lava{level:2}"},
        {pos: [9, 0, 9], state: "minecraft:blackstone"},
        {pos: [9, 0, 10], state: "minecraft:air"},
        {pos: [9, 0, 11], state: "minecraft:air"},
        {pos: [9, 0, 12], state: "minecraft:air"},
        {pos: [9, 0, 13], state: "minecraft:polished_blackstone_bricks"},
        {pos: [9, 0, 14], state: "minecraft:polished_blackstone_bricks"},
        {pos: [9, 0, 15], state: "minecraft:polished_blackstone_bricks"},
        {pos: [9, 0, 16], state: "minecraft:polished_blackstone_bricks"},
        {pos: [9, 0, 17], state: "minecraft:polished_blackstone_bricks"},
        {pos: [9, 0, 18], state: "minecraft:polished_blackstone_bricks"},
        {pos: [9, 0, 19], state: "minecraft:air"},
        {pos: [9, 0, 20], state: "minecraft:polished_blackstone_bricks"},
        {pos: [9, 0, 21], state: "minecraft:lava{level:4}"},
        {pos: [9, 0, 22], state: "minecraft:lava{level:2}"},
        {pos: [9, 0, 23], state: "minecraft:lava{level:8}"},
        {pos: [9, 0, 24], state: "minecraft:lava{level:2}"},
        {pos: [9, 0, 25], state: "minecraft:polished_blackstone_bricks"},
        {pos: [9, 0, 26], state: "minecraft:polished_blackstone_bricks"},
        {pos: [9, 0, 27], state: "minecraft:polished_blackstone_bricks"},
        {pos: [9, 0, 28], state: "minecraft:polished_blackstone_bricks"},
        {pos: [9, 0, 29], state: "minecraft:polished_blackstone_bricks"},
        {pos: [9, 0, 30], state: "minecraft:polished_blackstone_bricks"},
        {pos: [9, 0, 31], state: "minecraft:polished_blackstone_bricks"},
        {pos: [10, 0, 0], state: "minecraft:polished_blackstone_bricks"},
        {pos: [10, 0, 1], state: "minecraft:polished_blackstone_bricks"},
        {pos: [10, 0, 2], state: "minecraft:polished_blackstone_bricks"},
        {pos: [10, 0, 3], state: "minecraft:polished_blackstone_bricks"},
        {pos: [10, 0, 4], state: "minecraft:polished_blackstone_bricks"},
        {pos: [10, 0, 5], state: "minecraft:polished_blackstone_bricks"},
        {pos: [10, 0, 6], state: "minecraft:polished_blackstone_bricks"},
        {pos: [10, 0, 7], state: "minecraft:polished_blackstone_bricks"},
        {pos: [10, 0, 8], state: "minecraft:lava{level:4}"},
        {pos: [10, 0, 9], state: "minecraft:blackstone"},
        {pos: [10, 0, 10], state: "minecraft:air"},
        {pos: [10, 0, 11], state: "minecraft:air"},
        {pos: [10, 0, 12], state: "minecraft:air"},
        {pos: [10, 0, 13], state: "minecraft:polished_blackstone_bricks"},
        {pos: [10, 0, 14], state: "minecraft:polished_blackstone_bricks"},
        {pos: [10, 0, 15], state: "minecraft:blackstone"},
        {pos: [10, 0, 16], state: "minecraft:polished_blackstone_bricks"},
        {pos: [10, 0, 17], state: "minecraft:polished_blackstone_bricks"},
        {pos: [10, 0, 18], state: "minecraft:air"},
        {pos: [10, 0, 19], state: "minecraft:air"},
        {pos: [10, 0, 20], state: "minecraft:air"},
        {pos: [10, 0, 21], state: "minecraft:lava{level:6}"},
        {pos: [10, 0, 22], state: "minecraft:lava{level:4}"},
        {pos: [10, 0, 23], state: "minecraft:blackstone"},
        {pos: [10, 0, 24], state: "minecraft:polished_blackstone_bricks"},
        {pos: [10, 0, 25], state: "minecraft:polished_blackstone_bricks"},
        {pos: [10, 0, 26], state: "minecraft:polished_blackstone_bricks"},
        {pos: [10, 0, 27], state: "minecraft:polished_blackstone_bricks"},
        {pos: [10, 0, 28], state: "minecraft:polished_blackstone_bricks"},
        {pos: [10, 0, 29], state: "minecraft:polished_blackstone_bricks"},
        {pos: [10, 0, 30], state: "minecraft:polished_blackstone_bricks"},
        {pos: [10, 0, 31], state: "minecraft:polished_blackstone_bricks"},
        {pos: [11, 0, 0], state: "minecraft:polished_blackstone_bricks"},
        {pos: [11, 0, 1], state: "minecraft:polished_blackstone_bricks"},
        {pos: [11, 0, 2], state: "minecraft:polished_blackstone_bricks"},
        {pos: [11, 0, 3], state: "minecraft:polished_blackstone_bricks"},
        {pos: [11, 0, 4], state: "minecraft:polished_blackstone_bricks"},
        {pos: [11, 0, 5], state: "minecraft:polished_blackstone_bricks"},
        {pos: [11, 0, 6], state: "minecraft:polished_blackstone_bricks"},
        {pos: [11, 0, 7], state: "minecraft:lava{level:8}"},
        {pos: [11, 0, 8], state: "minecraft:lava{level:2}"},
        {pos: [11, 0, 9], state: "minecraft:lava{level:4}"},
        {pos: [11, 0, 10], state: "minecraft:lava{level:6}"},
        {pos: [11, 0, 11], state: "minecraft:polished_blackstone_bricks"},
        {pos: [11, 0, 12], state: "minecraft:polished_blackstone_bricks"},
        {pos: [11, 0, 13], state: "minecraft:polished_blackstone_bricks"},
        {pos: [11, 0, 14], state: "minecraft:polished_blackstone_bricks"},
        {pos: [11, 0, 15], state: "minecraft:polished_blackstone_bricks"},
        {pos: [11, 0, 16], state: "minecraft:polished_blackstone_bricks"},
        {pos: [11, 0, 17], state: "minecraft:polished_blackstone_bricks"},
        {pos: [11, 0, 18], state: "minecraft:blackstone"},
        {pos: [11, 0, 19], state: "minecraft:air"},
        {pos: [11, 0, 20], state: "minecraft:blackstone"},
        {pos: [11, 0, 21], state: "minecraft:lava{level:6}"},
        {pos: [11, 0, 22], state: "minecraft:lava{level:4}"},
        {pos: [11, 0, 23], state: "minecraft:lava{level:2}"},
        {pos: [11, 0, 24], state: "minecraft:lava{level:8}"},
        {pos: [11, 0, 25], state: "minecraft:polished_blackstone_bricks"},
        {pos: [11, 0, 26], state: "minecraft:polished_blackstone_bricks"},
        {pos: [11, 0, 27], state: "minecraft:polished_blackstone_bricks"},
        {pos: [11, 0, 28], state: "minecraft:polished_blackstone_bricks"},
        {pos: [11, 0, 29], state: "minecraft:polished_blackstone_bricks"},
        {pos: [11, 0, 30], state: "minecraft:polished_blackstone_bricks"},
        {pos: [11, 0, 31], state: "minecraft:polished_blackstone_bricks"},
        {pos: [12, 0, 0], state: "minecraft:polished_blackstone_bricks"},
        {pos: [12, 0, 1], state: "minecraft:polished_blackstone_bricks"},
        {pos: [12, 0, 2], state: "minecraft:polished_blackstone_bricks"},
        {pos: [12, 0, 3], state: "minecraft:polished_blackstone_bricks"},
        {pos: [12, 0, 4], state: "minecraft:polished_blackstone_bricks"},
        {pos: [12, 0, 5], state: "minecraft:polished_blackstone_bricks"},
        {pos: [12, 0, 6], state: "minecraft:polished_blackstone_bricks"},
        {pos: [12, 0, 7], state: "minecraft:lava{level:2}"},
        {pos: [12, 0, 8], state: "minecraft:lava{level:8}"},
        {pos: [12, 0, 9], state: "minecraft:lava{level:2}"},
        {pos: [12, 0, 10], state: "minecraft:lava{level:4}"},
        {pos: [12, 0, 11], state: "minecraft:polished_blackstone_bricks"},
        {pos: [12, 0, 12], state: "minecraft:polished_blackstone_bricks"},
        {pos: [12, 0, 13], state: "minecraft:polished_blackstone_bricks"},
        {pos: [12, 0, 14], state: "minecraft:polished_blackstone_bricks"},
        {pos: [12, 0, 15], state: "minecraft:polished_blackstone_bricks"},
        {pos: [12, 0, 16], state: "minecraft:polished_blackstone_bricks"},
        {pos: [12, 0, 17], state: "minecraft:polished_blackstone_bricks"},
        {pos: [12, 0, 18], state: "minecraft:blackstone"},
        {pos: [12, 0, 19], state: "minecraft:blackstone"},
        {pos: [12, 0, 20], state: "minecraft:blackstone"},
        {pos: [12, 0, 21], state: "minecraft:lava{level:6}"},
        {pos: [12, 0, 22], state: "minecraft:lava{level:4}"},
        {pos: [12, 0, 23], state: "minecraft:lava{level:2}"},
        {pos: [12, 0, 24], state: "minecraft:lava{level:8}"},
        {pos: [12, 0, 25], state: "minecraft:polished_blackstone_bricks"},
        {pos: [12, 0, 26], state: "minecraft:polished_blackstone_bricks"},
        {pos: [12, 0, 27], state: "minecraft:polished_blackstone_bricks"},
        {pos: [12, 0, 28], state: "minecraft:polished_blackstone_bricks"},
        {pos: [12, 0, 29], state: "minecraft:polished_blackstone_bricks"},
        {pos: [12, 0, 30], state: "minecraft:polished_blackstone_bricks"},
        {pos: [12, 0, 31], state: "minecraft:polished_blackstone_bricks"},
        {pos: [13, 0, 0], state: "minecraft:polished_blackstone_bricks"},
        {pos: [13, 0, 1], state: "minecraft:polished_blackstone_bricks"},
        {pos: [13, 0, 2], state: "minecraft:polished_blackstone_bricks"},
        {pos: [13, 0, 3], state: "minecraft:polished_blackstone_bricks"},
        {pos: [13, 0, 4], state: "minecraft:polished_blackstone_bricks"},
        {pos: [13, 0, 5], state: "minecraft:polished_blackstone_bricks"},
        {pos: [13, 0, 6], state: "minecraft:polished_blackstone_bricks"},
        {pos: [13, 0, 7], state: "minecraft:polished_blackstone_bricks"},
        {pos: [13, 0, 8], state: "minecraft:lava{level:2}"},
        {pos: [13, 0, 9], state: "minecraft:lava{level:4}"},
        {pos: [13, 0, 10], state: "minecraft:lava{level:6}"},
        {pos: [13, 0, 11], state: "minecraft:polished_blackstone_bricks"},
        {pos: [13, 0, 12], state: "minecraft:polished_blackstone_bricks"},
        {pos: [13, 0, 13], state: "minecraft:polished_blackstone_bricks"},
        {pos: [13, 0, 14], state: "minecraft:polished_blackstone_bricks"},
        {pos: [13, 0, 15], state: "minecraft:polished_blackstone_bricks"},
        {pos: [13, 0, 16], state: "minecraft:polished_blackstone_bricks"},
        {pos: [13, 0, 17], state: "minecraft:polished_blackstone_bricks"},
        {pos: [13, 0, 18], state: "minecraft:blackstone"},
        {pos: [13, 0, 19], state: "minecraft:blackstone"},
        {pos: [13, 0, 20], state: "minecraft:polished_blackstone_bricks"},
        {pos: [13, 0, 21], state: "minecraft:blackstone"},
        {pos: [13, 0, 22], state: "minecraft:blackstone"},
        {pos: [13, 0, 23], state: "minecraft:blackstone"},
        {pos: [13, 0, 24], state: "minecraft:polished_blackstone_bricks"},
        {pos: [13, 0, 25], state: "minecraft:lava{level:2}"},
        {pos: [13, 0, 26], state: "minecraft:blackstone"},
        {pos: [13, 0, 27], state: "minecraft:blackstone"},
        {pos: [13, 0, 28], state: "minecraft:polished_blackstone_bricks"},
        {pos: [13, 0, 29], state: "minecraft:polished_blackstone_bricks"},
        {pos: [13, 0, 30], state: "minecraft:polished_blackstone_bricks"},
        {pos: [13, 0, 31], state: "minecraft:polished_blackstone_bricks"},
        {pos: [14, 0, 0], state: "minecraft:polished_blackstone_bricks"},
        {pos: [14, 0, 1], state: "minecraft:polished_blackstone_bricks"},
        {pos: [14, 0, 2], state: "minecraft:polished_blackstone_bricks"},
        {pos: [14, 0, 3], state: "minecraft:polished_blackstone_bricks"},
        {pos: [14, 0, 4], state: "minecraft:polished_blackstone_bricks"},
        {pos: [14, 0, 5], state: "minecraft:polished_blackstone_bricks"},
        {pos: [14, 0, 6], state: "minecraft:polished_blackstone_bricks"},
        {pos: [14, 0, 7], state: "minecraft:lava{level:2}"},
        {pos: [14, 0, 8], state: "minecraft:lava{level:8}"},
        {pos: [14, 0, 9], state: "minecraft:lava{level:2}"},
        {pos: [14, 0, 10], state: "minecraft:lava{level:4}"},
        {pos: [14, 0, 11], state: "minecraft:polished_blackstone_bricks"},
        {pos: [14, 0, 12], state: "minecraft:polished_blackstone_bricks"},
        {pos: [14, 0, 13], state: "minecraft:polished_blackstone_bricks"},
        {pos: [14, 0, 14], state: "minecraft:polished_blackstone_bricks"},
        {pos: [14, 0, 15], state: "minecraft:polished_blackstone_bricks"},
        {pos: [14, 0, 16], state: "minecraft:polished_blackstone_bricks"},
        {pos: [14, 0, 17], state: "minecraft:polished_blackstone_bricks"},
        {pos: [14, 0, 18], state: "minecraft:polished_blackstone_bricks"},
        {pos: [14, 0, 19], state: "minecraft:polished_blackstone_bricks"},
        {pos: [14, 0, 20], state: "minecraft:polished_blackstone_bricks"},
        {pos: [14, 0, 21], state: "minecraft:air"},
        {pos: [14, 0, 22], state: "minecraft:lava{level:6}"},
        {pos: [14, 0, 23], state: "minecraft:blackstone"},
        {pos: [14, 0, 24], state: "minecraft:lava{level:8}"},
        {pos: [14, 0, 25], state: "minecraft:lava{level:8}"},
        {pos: [14, 0, 26], state: "minecraft:lava{level:2}"},
        {pos: [14, 0, 27], state: "minecraft:gold_block"},
        {pos: [14, 0, 28], state: "minecraft:polished_blackstone_bricks"},
        {pos: [14, 0, 29], state: "minecraft:polished_blackstone_bricks"},
        {pos: [14, 0, 30], state: "minecraft:polished_blackstone_bricks"},
        {pos: [14, 0, 31], state: "minecraft:polished_blackstone_bricks"},
        {pos: [15, 0, 0], state: "minecraft:polished_blackstone_bricks"},
        {pos: [15, 0, 1], state: "minecraft:polished_blackstone_bricks"},
        {pos: [15, 0, 2], state: "minecraft:polished_blackstone_bricks"},
        {pos: [15, 0, 3], state: "minecraft:polished_blackstone_bricks"},
        {pos: [15, 0, 4], state: "minecraft:polished_blackstone_bricks"},
        {pos: [15, 0, 5], state: "minecraft:polished_blackstone_bricks"},
        {pos: [15, 0, 6], state: "minecraft:polished_blackstone_bricks"},
        {pos: [15, 0, 7], state: "minecraft:lava{level:8}"},
        {pos: [15, 0, 8], state: "minecraft:lava{level:2}"},
        {pos: [15, 0, 9], state: "minecraft:lava{level:4}"},
        {pos: [15, 0, 10], state: "minecraft:lava{level:6}"},
        {pos: [15, 0, 11], state: "minecraft:polished_blackstone_bricks"},
        {pos: [15, 0, 12], state: "minecraft:polished_blackstone_bricks"},
        {pos: [15, 0, 13], state: "minecraft:polished_blackstone_bricks"},
        {pos: [15, 0, 14], state: "minecraft:polished_blackstone_bricks"},
        {pos: [15, 0, 15], state: "minecraft:polished_blackstone_bricks"},
        {pos: [15, 0, 16], state: "minecraft:polished_blackstone_bricks"},
        {pos: [15, 0, 17], state: "minecraft:polished_blackstone_bricks"},
        {pos: [15, 0, 18], state: "minecraft:air"},
        {pos: [15, 0, 19], state: "minecraft:polished_blackstone_bricks"},
        {pos: [15, 0, 20], state: "minecraft:polished_blackstone_bricks"},
        {pos: [15, 0, 21], state: "minecraft:lava{level:6}"},
        {pos: [15, 0, 22], state: "minecraft:lava{level:4}"},
        {pos: [15, 0, 23], state: "minecraft:lava{level:2}"},
        {pos: [15, 0, 24], state: "minecraft:lava{level:8}"},
        {pos: [15, 0, 25], state: "minecraft:lava{level:2}"},
        {pos: [15, 0, 26], state: "minecraft:lava{level:4}"},
        {pos: [15, 0, 27], state: "minecraft:cracked_polished_blackstone_bricks"},
        {pos: [15, 0, 28], state: "minecraft:cracked_polished_blackstone_bricks"},
        {pos: [15, 0, 29], state: "minecraft:polished_blackstone_bricks"},
        {pos: [15, 0, 30], state: "minecraft:polished_blackstone_bricks"},
        {pos: [15, 0, 31], state: "minecraft:polished_blackstone_bricks"},
        {pos: [16, 0, 0], state: "minecraft:polished_blackstone_bricks"},
        {pos: [16, 0, 1], state: "minecraft:polished_blackstone_bricks"},
        {pos: [16, 0, 2], state: "minecraft:polished_blackstone_bricks"},
        {pos: [16, 0, 3], state: "minecraft:polished_blackstone_bricks"},
        {pos: [16, 0, 4], state: "minecraft:polished_blackstone_bricks"},
        {pos: [16, 0, 5], state: "minecraft:polished_blackstone_bricks"},
        {pos: [16, 0, 6], state: "minecraft:polished_blackstone_bricks"},
        {pos: [16, 0, 7], state: "minecraft:basalt{axis:y}"},
        {pos: [16, 0, 8], state: "minecraft:basalt{axis:y}"},
        {pos: [16, 0, 9], state: "minecraft:basalt{axis:y}"},
        {pos: [16, 0, 10], state: "minecraft:basalt{axis:y}"},
        {pos: [16, 0, 11], state: "minecraft:jigsaw{orientation:east_up}", nbt: {final_state: "minecraft:polished_blackstone_bricks", id: "minecraft:jigsaw", joint: "rollable", name: "minecraft:empty", pool: "minecraft:bastion/bridge/connectors", target: "minecraft:back_bridge_connector_top"}},
        {pos: [16, 0, 12], state: "minecraft:polished_blackstone_bricks"},
        {pos: [16, 0, 13], state: "minecraft:polished_blackstone_bricks"},
        {pos: [16, 0, 14], state: "minecraft:polished_blackstone_bricks"},
        {pos: [16, 0, 15], state: "minecraft:polished_blackstone_bricks"},
        {pos: [16, 0, 16], state: "minecraft:polished_blackstone_bricks"},
        {pos: [16, 0, 17], state: "minecraft:polished_blackstone_bricks"},
        {pos: [16, 0, 18], state: "minecraft:polished_blackstone_bricks"},
        {pos: [16, 0, 19], state: "minecraft:polished_blackstone_bricks"},
        {pos: [16, 0, 20], state: "minecraft:polished_blackstone_bricks"},
        {pos: [16, 0, 21], state: "minecraft:polished_blackstone_bricks"},
        {pos: [16, 0, 22], state: "minecraft:polished_blackstone_bricks"},
        {pos: [16, 0, 23], state: "minecraft:blackstone"},
        {pos: [16, 0, 24], state: "minecraft:blackstone"},
        {pos: [16, 0, 25], state: "minecraft:cracked_polished_blackstone_bricks"},
        {pos: [16, 0, 26], state: "minecraft:cracked_polished_blackstone_bricks"},
        {pos: [16, 0, 27], state: "minecraft:cracked_polished_blackstone_bricks"},
        {pos: [16, 0, 28], state: "minecraft:cracked_polished_blackstone_bricks"},
        {pos: [16, 0, 29], state: "minecraft:polished_blackstone_bricks"},
        {pos: [16, 0, 30], state: "minecraft:polished_blackstone_bricks"},
        {pos: [16, 0, 31], state: "minecraft:polished_blackstone_bricks"},
        {pos: [0, 1, 0], state: "minecraft:polished_blackstone_bricks"},
        {pos: [0, 1, 1], state: "minecraft:polished_blackstone_bricks"},
        {pos: [0, 1, 2], state: "minecraft:air"},
        {pos: [0, 1, 3], state: "minecraft:air"},
        {pos: [0, 1, 4], state: "minecraft:polished_blackstone_bricks"},
        {pos: [0, 1, 5], state: "minecraft:blackstone"},
        {pos: [0, 1, 6], state: "minecraft:blackstone"},
        {pos: [0, 1, 7], state: "minecraft:polished_blackstone_bricks"},
        {pos: [0, 1, 8], state: "minecraft:air"},
        {pos: [0, 1, 9], state: "minecraft:air"},
        {pos: [0, 1, 10], state: "minecraft:air"},
        {pos: [0, 1, 11], state: "minecraft:polished_blackstone_bricks"},
        {pos: [0, 1, 12], state: "minecraft:polished_blackstone_bricks"},
        {pos: [0, 1, 13], state: "minecraft:air"},
        {pos: [0, 1, 14], state: "minecraft:air"},
        {pos: [0, 1, 15], state: "minecraft:blackstone"},
        {pos: [0, 1, 16], state: "minecraft:air"},
        {pos: [0, 1, 17], state: "minecraft:air"},
        {pos: [0, 1, 18], state: "minecraft:air"},
        {pos: [0, 1, 19], state: "minecraft:air"},
        {pos: [0, 1, 20], state: "minecraft:air"},
        {pos: [0, 1, 21], state: "minecraft:air"},
        {pos: [0, 1, 22], state: "minecraft:air"},
        {pos: [0, 1, 23], state: "minecraft:air"},
        {pos: [0, 1, 24], state: "minecraft:polished_blackstone_bricks"},
        {pos: [0, 1, 25], state: "minecraft:polished_blackstone_bricks"},
        {pos: [0, 1, 26], state: "minecraft:polished_blackstone_bricks"},
        {pos: [0, 1, 27], state: "minecraft:polished_blackstone_bricks"},
        {pos: [0, 1, 28], state: "minecraft:air"},
        {pos: [0, 1, 29], state: "minecraft:air"},
        {pos: [0, 1, 30], state: "minecraft:air"},
        {pos: [0, 1, 31], state: "minecraft:polished_blackstone_bricks"},
        {pos: [1, 1, 0], state: "minecraft:polished_blackstone_bricks"},
        {pos: [1, 1, 1], state: "minecraft:polished_blackstone_bricks"},
        {pos: [1, 1, 2], state: "minecraft:polished_blackstone_bricks"},
        {pos: [1, 1, 3], state: "minecraft:polished_blackstone_bricks"},
        {pos: [1, 1, 4], state: "minecraft:polished_blackstone_bricks"},
        {pos: [1, 1, 5], state: "minecraft:polished_blackstone_bricks"},
        {pos: [1, 1, 6], state: "minecraft:polished_blackstone_bricks"},
        {pos: [1, 1, 7], state: "minecraft:polished_blackstone_bricks"},
        {pos: [1, 1, 8], state: "minecraft:air"},
        {pos: [1, 1, 9], state: "minecraft:air"},
        {pos: [1, 1, 10], state: "minecraft:air"},
        {pos: [1, 1, 11], state: "minecraft:polished_blackstone_bricks"},
        {pos: [1, 1, 12], state: "minecraft:polished_blackstone_bricks"},
        {pos: [1, 1, 13], state: "minecraft:blackstone"},
        {pos: [1, 1, 14], state: "minecraft:blackstone"},
        {pos: [1, 1, 15], state: "minecraft:blackstone"},
        {pos: [1, 1, 16], state: "minecraft:air"},
        {pos: [1, 1, 17], state: "minecraft:blackstone"},
        {pos: [1, 1, 18], state: "minecraft:air"},
        {pos: [1, 1, 19], state: "minecraft:air"},
        {pos: [1, 1, 20], state: "minecraft:air"},
        {pos: [1, 1, 21], state: "minecraft:air"},
        {pos: [1, 1, 22], state: "minecraft:air"},
        {pos: [1, 1, 23], state: "minecraft:air"},
        {pos: [1, 1, 24], state: "minecraft:polished_blackstone_bricks"},
        {pos: [1, 1, 25], state: "minecraft:polished_blackstone_bricks"},
        {pos: [1, 1, 26], state: "minecraft:polished_blackstone_bricks"},
        {pos: [1, 1, 27], state: "minecraft:polished_blackstone_bricks"},
        {pos: [1, 1, 28], state: "minecraft:polished_blackstone_bricks"},
        {pos: [1, 1, 29], state: "minecraft:polished_blackstone_bricks"},
        {pos: [1, 1, 30], state: "minecraft:polished_blackstone_bricks"},
        {pos: [1, 1, 31], state: "minecraft:polished_blackstone_bricks"},
        {pos: [2, 1, 0], state: "minecraft:polished_blackstone_bricks"},
        {pos: [2, 1, 1], state: "minecraft:polished_blackstone_bricks"},
        {pos: [2, 1, 2], state: "minecraft:polished_blackstone_bricks"},
        {pos: [2, 1, 3], state: "minecraft:polished_blackstone_bricks"},
        {pos: [2, 1, 4], state: "minecraft:polished_blackstone_bricks"},
        {pos: [2, 1, 5], state: "minecraft:polished_blackstone_bricks"},
        {pos: [2, 1, 6], state: "minecraft:air"},
        {pos: [2, 1, 7], state: "minecraft:lava{level:8}"},
        {pos: [2, 1, 8], state: "minecraft:air"},
        {pos: [2, 1, 9], state: "minecraft:air"},
        {pos: [2, 1, 10], state: "minecraft:air"},
        {pos: [2, 1, 11], state: "minecraft:polished_blackstone_bricks"},
        {pos: [2, 1, 12], state: "minecraft:polished_blackstone_bricks"},
        {pos: [2, 1, 13], state: "minecraft:polished_blackstone_bricks"},
        {pos: [2, 1, 14], state: "minecraft:blackstone"},
        {pos: [2, 1, 15], state: "minecraft:polished_blackstone_bricks"},
        {pos: [2, 1, 16], state: "minecraft:polished_blackstone_bricks"},
        {pos: [2, 1, 17], state: "minecraft:air"},
        {pos: [2, 1, 18], state: "minecraft:air"},
        {pos: [2, 1, 19], state: "minecraft:air"},
        {pos: [2, 1, 20], state: "minecraft:air"},
        {pos: [2, 1, 21], state: "minecraft:air"},
        {pos: [2, 1, 22], state: "minecraft:air"},
        {pos: [2, 1, 23], state: "minecraft:lava{level:8}"},
        {pos: [2, 1, 24], state: "minecraft:air"},
        {pos: [2, 1, 25], state: "minecraft:polished_blackstone_bricks"},
        {pos: [2, 1, 26], state: "minecraft:polished_blackstone_bricks"},
        {pos: [2, 1, 27], state: "minecraft:polished_blackstone_bricks"},
        {pos: [2, 1, 28], state: "minecraft:polished_blackstone_bricks"},
        {pos: [2, 1, 29], state: "minecraft:polished_blackstone_bricks"},
        {pos: [2, 1, 30], state: "minecraft:polished_blackstone_bricks"},
        {pos: [2, 1, 31], state: "minecraft:polished_blackstone_bricks"},
        {pos: [3, 1, 0], state: "minecraft:polished_blackstone_bricks"},
        {pos: [3, 1, 1], state: "minecraft:polished_blackstone_bricks"},
        {pos: [3, 1, 2], state: "minecraft:polished_blackstone_bricks"},
        {pos: [3, 1, 3], state: "minecraft:polished_blackstone_bricks"},
        {pos: [3, 1, 4], state: "minecraft:polished_blackstone_bricks"},
        {pos: [3, 1, 5], state: "minecraft:polished_blackstone_bricks"},
        {pos: [3, 1, 6], state: "minecraft:polished_blackstone_bricks"},
        {pos: [3, 1, 7], state: "minecraft:polished_blackstone_bricks"},
        {pos: [3, 1, 8], state: "minecraft:lava{level:8}"},
        {pos: [3, 1, 9], state: "minecraft:air"},
        {pos: [3, 1, 10], state: "minecraft:air"},
        {pos: [3, 1, 11], state: "minecraft:polished_blackstone_bricks"},
        {pos: [3, 1, 12], state: "minecraft:polished_blackstone_bricks"},
        {pos: [3, 1, 13], state: "minecraft:polished_blackstone_bricks"},
        {pos: [3, 1, 14], state: "minecraft:air"},
        {pos: [3, 1, 15], state: "minecraft:polished_blackstone_bricks"},
        {pos: [3, 1, 16], state: "minecraft:blackstone"},
        {pos: [3, 1, 17], state: "minecraft:air"},
        {pos: [3, 1, 18], state: "minecraft:air"},
        {pos: [3, 1, 19], state: "minecraft:air"},
        {pos: [3, 1, 20], state: "minecraft:polished_blackstone_bricks"},
        {pos: [3, 1, 21], state: "minecraft:air"},
        {pos: [3, 1, 22], state: "minecraft:air"},
        {pos: [3, 1, 23], state: "minecraft:lava{level:8}"},
        {pos: [3, 1, 24], state: "minecraft:air"},
        {pos: [3, 1, 25], state: "minecraft:polished_blackstone_bricks"},
        {pos: [3, 1, 26], state: "minecraft:polished_blackstone_bricks"},
        {pos: [3, 1, 27], state: "minecraft:polished_blackstone_bricks"},
        {pos: [3, 1, 28], state: "minecraft:polished_blackstone_bricks"},
        {pos: [3, 1, 29], state: "minecraft:polished_blackstone_bricks"},
        {pos: [3, 1, 30], state: "minecraft:polished_blackstone_bricks"},
        {pos: [3, 1, 31], state: "minecraft:polished_blackstone_bricks"},
        {pos: [4, 1, 0], state: "minecraft:polished_blackstone_bricks"},
        {pos: [4, 1, 1], state: "minecraft:polished_blackstone_bricks"},
        {pos: [4, 1, 2], state: "minecraft:polished_blackstone_bricks"},
        {pos: [4, 1, 3], state: "minecraft:polished_blackstone_bricks"},
        {pos: [4, 1, 4], state: "minecraft:polished_blackstone_bricks"},
        {pos: [4, 1, 5], state: "minecraft:polished_blackstone_bricks"},
        {pos: [4, 1, 6], state: "minecraft:polished_blackstone_bricks"},
        {pos: [4, 1, 7], state: "minecraft:polished_blackstone_bricks"},
        {pos: [4, 1, 8], state: "minecraft:air"},
        {pos: [4, 1, 9], state: "minecraft:blackstone"},
        {pos: [4, 1, 10], state: "minecraft:blackstone"},
        {pos: [4, 1, 11], state: "minecraft:polished_blackstone_bricks"},
        {pos: [4, 1, 12], state: "minecraft:polished_blackstone_bricks"},
        {pos: [4, 1, 13], state: "minecraft:polished_blackstone_bricks"},
        {pos: [4, 1, 14], state: "minecraft:blackstone"},
        {pos: [4, 1, 15], state: "minecraft:polished_blackstone_bricks"},
        {pos: [4, 1, 16], state: "minecraft:blackstone"},
        {pos: [4, 1, 17], state: "minecraft:air"},
        {pos: [4, 1, 18], state: "minecraft:air"},
        {pos: [4, 1, 19], state: "minecraft:polished_blackstone_bricks"},
        {pos: [4, 1, 20], state: "minecraft:polished_blackstone_bricks"},
        {pos: [4, 1, 21], state: "minecraft:air"},
        {pos: [4, 1, 22], state: "minecraft:air"},
        {pos: [4, 1, 23], state: "minecraft:air"},
        {pos: [4, 1, 24], state: "minecraft:polished_blackstone_bricks"},
        {pos: [4, 1, 25], state: "minecraft:polished_blackstone_bricks"},
        {pos: [4, 1, 26], state: "minecraft:polished_blackstone_bricks"},
        {pos: [4, 1, 27], state: "minecraft:polished_blackstone_bricks"},
        {pos: [4, 1, 28], state: "minecraft:polished_blackstone_bricks"},
        {pos: [4, 1, 29], state: "minecraft:polished_blackstone_bricks"},
        {pos: [4, 1, 30], state: "minecraft:polished_blackstone_bricks"},
        {pos: [4, 1, 31], state: "minecraft:polished_blackstone_bricks"},
        {pos: [5, 1, 0], state: "minecraft:polished_blackstone_bricks"},
        {pos: [5, 1, 1], state: "minecraft:polished_blackstone_bricks"},
        {pos: [5, 1, 2], state: "minecraft:polished_blackstone_bricks"},
        {pos: [5, 1, 3], state: "minecraft:polished_blackstone_bricks"},
        {pos: [5, 1, 4], state: "minecraft:polished_blackstone_bricks"},
        {pos: [5, 1, 5], state: "minecraft:polished_blackstone_bricks"},
        {pos: [5, 1, 6], state: "minecraft:polished_blackstone_bricks"},
        {pos: [5, 1, 7], state: "minecraft:lava{level:8}"},
        {pos: [5, 1, 8], state: "minecraft:air"},
        {pos: [5, 1, 9], state: "minecraft:air"},
        {pos: [5, 1, 10], state: "minecraft:air"},
        {pos: [5, 1, 11], state: "minecraft:polished_blackstone_bricks"},
        {pos: [5, 1, 12], state: "minecraft:polished_blackstone_bricks"},
        {pos: [5, 1, 13], state: "minecraft:polished_blackstone_bricks"},
        {pos: [5, 1, 14], state: "minecraft:jigsaw{orientation:up_west}", nbt: {final_state: "minecraft:polished_blackstone_bricks", id: "minecraft:jigsaw", joint: "rollable", name: "minecraft:empty", pool: "minecraft:bastion/mobs/hoglin", target: "minecraft:mob_connector"}},
        {pos: [5, 1, 15], state: "minecraft:blackstone"},
        {pos: [5, 1, 16], state: "minecraft:air"},
        {pos: [5, 1, 17], state: "minecraft:air"},
        {pos: [5, 1, 18], state: "minecraft:air"},
        {pos: [5, 1, 19], state: "minecraft:polished_blackstone_bricks"},
        {pos: [5, 1, 20], state: "minecraft:polished_blackstone_bricks"},
        {pos: [5, 1, 21], state: "minecraft:air"},
        {pos: [5, 1, 22], state: "minecraft:air"},
        {pos: [5, 1, 23], state: "minecraft:air"},
        {pos: [5, 1, 24], state: "minecraft:lava{level:8}"},
        {pos: [5, 1, 25], state: "minecraft:air"},
        {pos: [5, 1, 26], state: "minecraft:air"},
        {pos: [5, 1, 27], state: "minecraft:polished_blackstone_bricks"},
        {pos: [5, 1, 28], state: "minecraft:polished_blackstone_bricks"},
        {pos: [5, 1, 29], state: "minecraft:polished_blackstone_bricks"},
        {pos: [5, 1, 30], state: "minecraft:polished_blackstone_bricks"},
        {pos: [5, 1, 31], state: "minecraft:polished_blackstone_bricks"},
        {pos: [6, 1, 0], state: "minecraft:polished_blackstone_bricks"},
        {pos: [6, 1, 1], state: "minecraft:polished_blackstone_bricks"},
        {pos: [6, 1, 2], state: "minecraft:polished_blackstone_bricks"},
        {pos: [6, 1, 3], state: "minecraft:polished_blackstone_bricks"},
        {pos: [6, 1, 4], state: "minecraft:polished_blackstone_bricks"},
        {pos: [6, 1, 5], state: "minecraft:polished_blackstone_bricks"},
        {pos: [6, 1, 6], state: "minecraft:polished_blackstone_bricks"},
        {pos: [6, 1, 7], state: "minecraft:lava{level:8}"},
        {pos: [6, 1, 8], state: "minecraft:air"},
        {pos: [6, 1, 9], state: "minecraft:air"},
        {pos: [6, 1, 10], state: "minecraft:blackstone"},
        {pos: [6, 1, 11], state: "minecraft:air"},
        {pos: [6, 1, 12], state: "minecraft:air"},
        {pos: [6, 1, 13], state: "minecraft:polished_blackstone_bricks"},
        {pos: [6, 1, 14], state: "minecraft:polished_blackstone_bricks"},
        {pos: [6, 1, 15], state: "minecraft:polished_blackstone_bricks"},
        {pos: [6, 1, 16], state: "minecraft:blackstone"},
        {pos: [6, 1, 17], state: "minecraft:blackstone"},
        {pos: [6, 1, 18], state: "minecraft:air"},
        {pos: [6, 1, 19], state: "minecraft:air"},
        {pos: [6, 1, 20], state: "minecraft:polished_blackstone_bricks"},
        {pos: [6, 1, 21], state: "minecraft:air"},
        {pos: [6, 1, 22], state: "minecraft:air"},
        {pos: [6, 1, 23], state: "minecraft:lava{level:8}"},
        {pos: [6, 1, 24], state: "minecraft:air"},
        {pos: [6, 1, 25], state: "minecraft:blackstone"},
        {pos: [6, 1, 26], state: "minecraft:polished_blackstone_bricks"},
        {pos: [6, 1, 27], state: "minecraft:polished_blackstone_bricks"},
        {pos: [6, 1, 28], state: "minecraft:polished_blackstone_bricks"},
        {pos: [6, 1, 29], state: "minecraft:polished_blackstone_bricks"},
        {pos: [6, 1, 30], state: "minecraft:polished_blackstone_bricks"},
        {pos: [6, 1, 31], state: "minecraft:polished_blackstone_bricks"},
        {pos: [7, 1, 0], state: "minecraft:polished_blackstone_bricks"},
        {pos: [7, 1, 1], state: "minecraft:polished_blackstone_bricks"},
        {pos: [7, 1, 2], state: "minecraft:polished_blackstone_bricks"},
        {pos: [7, 1, 3], state: "minecraft:polished_blackstone_bricks"},
        {pos: [7, 1, 4], state: "minecraft:polished_blackstone_bricks"},
        {pos: [7, 1, 5], state: "minecraft:polished_blackstone_bricks"},
        {pos: [7, 1, 6], state: "minecraft:polished_blackstone_bricks"},
        {pos: [7, 1, 7], state: "minecraft:polished_blackstone_bricks"},
        {pos: [7, 1, 8], state: "minecraft:air"},
        {pos: [7, 1, 9], state: "minecraft:air"},
        {pos: [7, 1, 10], state: "minecraft:air"},
        {pos: [7, 1, 11], state: "minecraft:air"},
        {pos: [7, 1, 12], state: "minecraft:air"},
        {pos: [7, 1, 13], state: "minecraft:air"},
        {pos: [7, 1, 14], state: "minecraft:polished_blackstone_bricks"},
        {pos: [7, 1, 15], state: "minecraft:polished_blackstone_bricks"},
        {pos: [7, 1, 16], state: "minecraft:polished_blackstone_bricks"},
        {pos: [7, 1, 17], state: "minecraft:polished_blackstone_bricks"},
        {pos: [7, 1, 18], state: "minecraft:polished_blackstone_bricks"},
        {pos: [7, 1, 19], state: "minecraft:jigsaw{orientation:up_north}", nbt: {final_state: "minecraft:polished_blackstone_bricks", id: "minecraft:jigsaw", joint: "rollable", name: "minecraft:empty", pool: "minecraft:bastion/mobs/piglin", target: "minecraft:mob_connector"}},
        {pos: [7, 1, 20], state: "minecraft:polished_blackstone_bricks"},
        {pos: [7, 1, 21], state: "minecraft:air"},
        {pos: [7, 1, 22], state: "minecraft:air"},
        {pos: [7, 1, 23], state: "minecraft:lava{level:8}"},
        {pos: [7, 1, 24], state: "minecraft:polished_blackstone_bricks"},
        {pos: [7, 1, 25], state: "minecraft:polished_blackstone_bricks"},
        {pos: [7, 1, 26], state: "minecraft:polished_blackstone_bricks"},
        {pos: [7, 1, 27], state: "minecraft:polished_blackstone_bricks"},
        {pos: [7, 1, 28], state: "minecraft:polished_blackstone_bricks"},
        {pos: [7, 1, 29], state: "minecraft:polished_blackstone_bricks"},
        {pos: [7, 1, 30], state: "minecraft:polished_blackstone_bricks"},
        {pos: [7, 1, 31], state: "minecraft:polished_blackstone_bricks"},
        {pos: [8, 1, 0], state: "minecraft:polished_blackstone_bricks"},
        {pos: [8, 1, 1], state: "minecraft:polished_blackstone_bricks"},
        {pos: [8, 1, 2], state: "minecraft:polished_blackstone_bricks"},
        {pos: [8, 1, 3], state: "minecraft:polished_blackstone_bricks"},
        {pos: [8, 1, 4], state: "minecraft:polished_blackstone_bricks"},
        {pos: [8, 1, 5], state: "minecraft:polished_blackstone_bricks"},
        {pos: [8, 1, 6], state: "minecraft:polished_blackstone_bricks"},
        {pos: [8, 1, 7], state: "minecraft:lava{level:8}"},
        {pos: [8, 1, 8], state: "minecraft:air"},
        {pos: [8, 1, 9], state: "minecraft:air"},
        {pos: [8, 1, 10], state: "minecraft:air"},
        {pos: [8, 1, 11], state: "minecraft:air"},
        {pos: [8, 1, 12], state: "minecraft:air"},
        {pos: [8, 1, 13], state: "minecraft:air"},
        {pos: [8, 1, 14], state: "minecraft:polished_blackstone_bricks"},
        {pos: [8, 1, 15], state: "minecraft:polished_blackstone_bricks"},
        {pos: [8, 1, 16], state: "minecraft:jigsaw{orientation:up_west}", nbt: {final_state: "minecraft:polished_blackstone_bricks", id: "minecraft:jigsaw", joint: "rollable", name: "minecraft:empty", pool: "minecraft:bastion/mobs/piglin", target: "minecraft:mob_connector"}},
        {pos: [8, 1, 17], state: "minecraft:polished_blackstone_bricks"},
        {pos: [8, 1, 18], state: "minecraft:polished_blackstone_bricks"},
        {pos: [8, 1, 19], state: "minecraft:polished_blackstone_bricks"},
        {pos: [8, 1, 20], state: "minecraft:polished_blackstone_bricks"},
        {pos: [8, 1, 21], state: "minecraft:air"},
        {pos: [8, 1, 22], state: "minecraft:air"},
        {pos: [8, 1, 23], state: "minecraft:lava{level:8}"},
        {pos: [8, 1, 24], state: "minecraft:air"},
        {pos: [8, 1, 25], state: "minecraft:polished_blackstone_bricks"},
        {pos: [8, 1, 26], state: "minecraft:polished_blackstone_bricks"},
        {pos: [8, 1, 27], state: "minecraft:polished_blackstone_bricks"},
        {pos: [8, 1, 28], state: "minecraft:polished_blackstone_bricks"},
        {pos: [8, 1, 29], state: "minecraft:polished_blackstone_bricks"},
        {pos: [8, 1, 30], state: "minecraft:polished_blackstone_bricks"},
        {pos: [8, 1, 31], state: "minecraft:polished_blackstone_bricks"},
        {pos: [9, 1, 0], state: "minecraft:polished_blackstone_bricks"},
        {pos: [9, 1, 1], state: "minecraft:polished_blackstone_bricks"},
        {pos: [9, 1, 2], state: "minecraft:polished_blackstone_bricks"},
        {pos: [9, 1, 3], state: "minecraft:polished_blackstone_bricks"},
        {pos: [9, 1, 4], state: "minecraft:polished_blackstone_bricks"},
        {pos: [9, 1, 5], state: "minecraft:polished_blackstone_bricks"},
        {pos: [9, 1, 6], state: "minecraft:polished_blackstone_bricks"},
        {pos: [9, 1, 7], state: "minecraft:lava{level:8}"},
        {pos: [9, 1, 8], state: "minecraft:air"},
        {pos: [9, 1, 9], state: "minecraft:air"},
        {pos: [9, 1, 10], state: "minecraft:air"},
        {pos: [9, 1, 11], state: "minecraft:air"},
        {pos: [9, 1, 12], state: "minecraft:air"},
        {pos: [9, 1, 13], state: "minecraft:air"},
        {pos: [9, 1, 14], state: "minecraft:polished_blackstone_bricks"},
        {pos: [9, 1, 15], state: "minecraft:polished_blackstone_bricks"},
        {pos: [9, 1, 16], state: "minecraft:polished_blackstone_bricks"},
        {pos: [9, 1, 17], state: "minecraft:polished_blackstone_bricks"},
        {pos: [9, 1, 18], state: "minecraft:polished_blackstone_bricks"},
        {pos: [9, 1, 19], state: "minecraft:air"},
        {pos: [9, 1, 20], state: "minecraft:blackstone"},
        {pos: [9, 1, 21], state: "minecraft:air"},
        {pos: [9, 1, 22], state: "minecraft:air"},
        {pos: [9, 1, 23], state: "minecraft:lava{level:8}"},
        {pos: [9, 1, 24], state: "minecraft:air"},
        {pos: [9, 1, 25], state: "minecraft:polished_blackstone_bricks"},
        {pos: [9, 1, 26], state: "minecraft:polished_blackstone_bricks"},
        {pos: [9, 1, 27], state: "minecraft:polished_blackstone_bricks"},
        {pos: [9, 1, 28], state: "minecraft:polished_blackstone_bricks"},
        {pos: [9, 1, 29], state: "minecraft:polished_blackstone_bricks"},
        {pos: [9, 1, 30], state: "minecraft:polished_blackstone_bricks"},
        {pos: [9, 1, 31], state: "minecraft:polished_blackstone_bricks"},
        {pos: [10, 1, 0], state: "minecraft:polished_blackstone_bricks"},
        {pos: [10, 1, 1], state: "minecraft:polished_blackstone_bricks"},
        {pos: [10, 1, 2], state: "minecraft:polished_blackstone_bricks"},
        {pos: [10, 1, 3], state: "minecraft:polished_blackstone_bricks"},
        {pos: [10, 1, 4], state: "minecraft:polished_blackstone_bricks"},
        {pos: [10, 1, 5], state: "minecraft:polished_blackstone_bricks"},
        {pos: [10, 1, 6], state: "minecraft:polished_blackstone_bricks"},
        {pos: [10, 1, 7], state: "minecraft:polished_blackstone_bricks"},
        {pos: [10, 1, 8], state: "minecraft:air"},
        {pos: [10, 1, 9], state: "minecraft:air"},
        {pos: [10, 1, 10], state: "minecraft:air"},
        {pos: [10, 1, 11], state: "minecraft:air"},
        {pos: [10, 1, 12], state: "minecraft:air"},
        {pos: [10, 1, 13], state: "minecraft:air"},
        {pos: [10, 1, 14], state: "minecraft:polished_blackstone_bricks"},
        {pos: [10, 1, 15], state: "minecraft:jigsaw{orientation:up_west}", nbt: {final_state: "minecraft:polished_blackstone_bricks", id: "minecraft:jigsaw", joint: "rollable", name: "minecraft:empty", pool: "minecraft:bastion/mobs/piglin", target: "minecraft:mob_connector"}},
        {pos: [10, 1, 16], state: "minecraft:polished_blackstone_bricks"},
        {pos: [10, 1, 17], state: "minecraft:polished_blackstone_bricks"},
        {pos: [10, 1, 18], state: "minecraft:air"},
        {pos: [10, 1, 19], state: "minecraft:air"},
        {pos: [10, 1, 20], state: "minecraft:air"},
        {pos: [10, 1, 21], state: "minecraft:air"},
        {pos: [10, 1, 22], state: "minecraft:air"},
        {pos: [10, 1, 23], state: "minecraft:air"},
        {pos: [10, 1, 24], state: "minecraft:polished_blackstone_bricks"},
        {pos: [10, 1, 25], state: "minecraft:polished_blackstone_bricks"},
        {pos: [10, 1, 26], state: "minecraft:polished_blackstone_bricks"},
        {pos: [10, 1, 27], state: "minecraft:polished_blackstone_bricks"},
        {pos: [10, 1, 28], state: "minecraft:polished_blackstone_bricks"},
        {pos: [10, 1, 29], state: "minecraft:polished_blackstone_bricks"},
        {pos: [10, 1, 30], state: "minecraft:polished_blackstone_bricks"},
        {pos: [10, 1, 31], state: "minecraft:polished_blackstone_bricks"},
        {pos: [11, 1, 0], state: "minecraft:polished_blackstone_bricks"},
        {pos: [11, 1, 1], state: "minecraft:polished_blackstone_bricks"},
        {pos: [11, 1, 2], state: "minecraft:polished_blackstone_bricks"},
        {pos: [11, 1, 3], state: "minecraft:polished_blackstone_bricks"},
        {pos: [11, 1, 4], state: "minecraft:polished_blackstone_bricks"},
        {pos: [11, 1, 5], state: "minecraft:polished_blackstone_bricks"},
        {pos: [11, 1, 6], state: "minecraft:polished_blackstone_bricks"},
        {pos: [11, 1, 7], state: "minecraft:lava{level:8}"},
        {pos: [11, 1, 8], state: "minecraft:air"},
        {pos: [11, 1, 9], state: "minecraft:air"},
        {pos: [11, 1, 10], state: "minecraft:air"},
        {pos: [11, 1, 11], state: "minecraft:air"},
        {pos: [11, 1, 12], state: "minecraft:air"},
        {pos: [11, 1, 13], state: "minecraft:air"},
        {pos: [11, 1, 14], state: "minecraft:polished_blackstone_bricks"},
        {pos: [11, 1, 15], state: "minecraft:polished_blackstone_bricks"},
        {pos: [11, 1, 16], state: "minecraft:polished_blackstone_bricks"},
        {pos: [11, 1, 17], state: "minecraft:air"},
        {pos: [11, 1, 18], state: "minecraft:air"},
        {pos: [11, 1, 19], state: "minecraft:air"},
        {pos: [11, 1, 20], state: "minecraft:blackstone"},
        {pos: [11, 1, 21], state: "minecraft:air"},
        {pos: [11, 1, 22], state: "minecraft:air"},
        {pos: [11, 1, 23], state: "minecraft:air"},
        {pos: [11, 1, 24], state: "minecraft:lava{level:8}"},
        {pos: [11, 1, 25], state: "minecraft:polished_blackstone_bricks"},
        {pos: [11, 1, 26], state: "minecraft:polished_blackstone_bricks"},
        {pos: [11, 1, 27], state: "minecraft:polished_blackstone_bricks"},
        {pos: [11, 1, 28], state: "minecraft:polished_blackstone_bricks"},
        {pos: [11, 1, 29], state: "minecraft:polished_blackstone_bricks"},
        {pos: [11, 1, 30], state: "minecraft:polished_blackstone_bricks"},
        {pos: [11, 1, 31], state: "minecraft:polished_blackstone_bricks"},
        {pos: [12, 1, 0], state: "minecraft:polished_blackstone_bricks"},
        {pos: [12, 1, 1], state: "minecraft:polished_blackstone_bricks"},
        {pos: [12, 1, 2], state: "minecraft:polished_blackstone_bricks"},
        {pos: [12, 1, 3], state: "minecraft:polished_blackstone_bricks"},
        {pos: [12, 1, 4], state: "minecraft:polished_blackstone_bricks"},
        {pos: [12, 1, 5], state: "minecraft:polished_blackstone_bricks"},
        {pos: [12, 1, 6], state: "minecraft:polished_blackstone_bricks"},
        {pos: [12, 1, 7], state: "minecraft:air"},
        {pos: [12, 1, 8], state: "minecraft:lava{level:8}"},
        {pos: [12, 1, 9], state: "minecraft:air"},
        {pos: [12, 1, 10], state: "minecraft:air"},
        {pos: [12, 1, 11], state: "minecraft:air"},
        {pos: [12, 1, 12], state: "minecraft:air"},
        {pos: [12, 1, 13], state: "minecraft:polished_blackstone_bricks"},
        {pos: [12, 1, 14], state: "minecraft:polished_blackstone_bricks"},
        {pos: [12, 1, 15], state: "minecraft:jigsaw{orientation:up_west}", nbt: {final_state: "minecraft:polished_blackstone_bricks", id: "minecraft:jigsaw", joint: "rollable", name: "minecraft:empty", pool: "minecraft:bastion/mobs/piglin", target: "minecraft:mob_connector"}},
        {pos: [12, 1, 16], state: "minecraft:polished_blackstone_bricks"},
        {pos: [12, 1, 17], state: "minecraft:polished_blackstone_bricks"},
        {pos: [12, 1, 18], state: "minecraft:air"},
        {pos: [12, 1, 19], state: "minecraft:air"},
        {pos: [12, 1, 20], state: "minecraft:air"},
        {pos: [12, 1, 21], state: "minecraft:air"},
        {pos: [12, 1, 22], state: "minecraft:air"},
        {pos: [12, 1, 23], state: "minecraft:air"},
        {pos: [12, 1, 24], state: "minecraft:lava{level:8}"},
        {pos: [12, 1, 25], state: "minecraft:polished_blackstone_bricks"},
        {pos: [12, 1, 26], state: "minecraft:polished_blackstone_bricks"},
        {pos: [12, 1, 27], state: "minecraft:polished_blackstone_bricks"},
        {pos: [12, 1, 28], state: "minecraft:polished_blackstone_bricks"},
        {pos: [12, 1, 29], state: "minecraft:polished_blackstone_bricks"},
        {pos: [12, 1, 30], state: "minecraft:polished_blackstone_bricks"},
        {pos: [12, 1, 31], state: "minecraft:polished_blackstone_bricks"},
        {pos: [13, 1, 0], state: "minecraft:polished_blackstone_bricks"},
        {pos: [13, 1, 1], state: "minecraft:polished_blackstone_bricks"},
        {pos: [13, 1, 2], state: "minecraft:polished_blackstone_bricks"},
        {pos: [13, 1, 3], state: "minecraft:polished_blackstone_bricks"},
        {pos: [13, 1, 4], state: "minecraft:polished_blackstone_bricks"},
        {pos: [13, 1, 5], state: "minecraft:polished_blackstone_bricks"},
        {pos: [13, 1, 6], state: "minecraft:polished_blackstone_bricks"},
        {pos: [13, 1, 7], state: "minecraft:polished_blackstone_bricks"},
        {pos: [13, 1, 8], state: "minecraft:air"},
        {pos: [13, 1, 9], state: "minecraft:air"},
        {pos: [13, 1, 10], state: "minecraft:air"},
        {pos: [13, 1, 11], state: "minecraft:polished_blackstone_bricks"},
        {pos: [13, 1, 12], state: "minecraft:polished_blackstone_bricks"},
        {pos: [13, 1, 13], state: "minecraft:polished_blackstone_bricks"},
        {pos: [13, 1, 14], state: "minecraft:polished_blackstone_bricks"},
        {pos: [13, 1, 15], state: "minecraft:polished_blackstone_bricks"},
        {pos: [13, 1, 16], state: "minecraft:polished_blackstone_bricks"},
        {pos: [13, 1, 17], state: "minecraft:polished_blackstone_bricks"},
        {pos: [13, 1, 18], state: "minecraft:air"},
        {pos: [13, 1, 19], state: "minecraft:air"},
        {pos: [13, 1, 20], state: "minecraft:air"},
        {pos: [13, 1, 21], state: "minecraft:air"},
        {pos: [13, 1, 22], state: "minecraft:air"},
        {pos: [13, 1, 23], state: "minecraft:blackstone"},
        {pos: [13, 1, 24], state: "minecraft:polished_blackstone_bricks"},
        {pos: [13, 1, 25], state: "minecraft:polished_blackstone_bricks"},
        {pos: [13, 1, 26], state: "minecraft:polished_blackstone_bricks"},
        {pos: [13, 1, 27], state: "minecraft:polished_blackstone_bricks"},
        {pos: [13, 1, 28], state: "minecraft:polished_blackstone_bricks"},
        {pos: [13, 1, 29], state: "minecraft:polished_blackstone_bricks"},
        {pos: [13, 1, 30], state: "minecraft:polished_blackstone_bricks"},
        {pos: [13, 1, 31], state: "minecraft:polished_blackstone_bricks"},
        {pos: [14, 1, 0], state: "minecraft:polished_blackstone_bricks"},
        {pos: [14, 1, 1], state: "minecraft:polished_blackstone_bricks"},
        {pos: [14, 1, 2], state: "minecraft:polished_blackstone_bricks"},
        {pos: [14, 1, 3], state: "minecraft:polished_blackstone_bricks"},
        {pos: [14, 1, 4], state: "minecraft:polished_blackstone_bricks"},
        {pos: [14, 1, 5], state: "minecraft:polished_blackstone_bricks"},
        {pos: [14, 1, 6], state: "minecraft:polished_blackstone_bricks"},
        {pos: [14, 1, 7], state: "minecraft:air"},
        {pos: [14, 1, 8], state: "minecraft:lava{level:8}"},
        {pos: [14, 1, 9], state: "minecraft:air"},
        {pos: [14, 1, 10], state: "minecraft:air"},
        {pos: [14, 1, 11], state: "minecraft:polished_blackstone_bricks"},
        {pos: [14, 1, 12], state: "minecraft:polished_blackstone_bricks"},
        {pos: [14, 1, 13], state: "minecraft:polished_blackstone_bricks"},
        {pos: [14, 1, 14], state: "minecraft:polished_blackstone_bricks"},
        {pos: [14, 1, 15], state: "minecraft:polished_blackstone_bricks"},
        {pos: [14, 1, 16], state: "minecraft:polished_blackstone_bricks"},
        {pos: [14, 1, 17], state: "minecraft:polished_blackstone_bricks"},
        {pos: [14, 1, 18], state: "minecraft:polished_blackstone_bricks"},
        {pos: [14, 1, 19], state: "minecraft:air"},
        {pos: [14, 1, 20], state: "minecraft:polished_blackstone_bricks"},
        {pos: [14, 1, 21], state: "minecraft:air"},
        {pos: [14, 1, 22], state: "minecraft:air"},
        {pos: [14, 1, 23], state: "minecraft:air"},
        {pos: [14, 1, 24], state: "minecraft:lava{level:8}"},
        {pos: [14, 1, 25], state: "minecraft:lava{level:8}"},
        {pos: [14, 1, 26], state: "minecraft:polished_blackstone_bricks"},
        {pos: [14, 1, 27], state: "minecraft:gold_block"},
        {pos: [14, 1, 28], state: "minecraft:polished_blackstone_bricks"},
        {pos: [14, 1, 29], state: "minecraft:polished_blackstone_bricks"},
        {pos: [14, 1, 30], state: "minecraft:polished_blackstone_bricks"},
        {pos: [14, 1, 31], state: "minecraft:polished_blackstone_bricks"},
        {pos: [15, 1, 0], state: "minecraft:polished_blackstone_bricks"},
        {pos: [15, 1, 1], state: "minecraft:polished_blackstone_bricks"},
        {pos: [15, 1, 2], state: "minecraft:polished_blackstone_bricks"},
        {pos: [15, 1, 3], state: "minecraft:polished_blackstone_bricks"},
        {pos: [15, 1, 4], state: "minecraft:polished_blackstone_bricks"},
        {pos: [15, 1, 5], state: "minecraft:polished_blackstone_bricks"},
        {pos: [15, 1, 6], state: "minecraft:polished_blackstone_bricks"},
        {pos: [15, 1, 7], state: "minecraft:lava{level:8}"},
        {pos: [15, 1, 8], state: "minecraft:air"},
        {pos: [15, 1, 9], state: "minecraft:air"},
        {pos: [15, 1, 10], state: "minecraft:air"},
        {pos: [15, 1, 11], state: "minecraft:polished_blackstone_bricks"},
        {pos: [15, 1, 12], state: "minecraft:polished_blackstone_bricks"},
        {pos: [15, 1, 13], state: "minecraft:polished_blackstone_bricks"},
        {pos: [15, 1, 14], state: "minecraft:polished_blackstone_bricks"},
        {pos: [15, 1, 15], state: "minecraft:polished_blackstone_bricks"},
        {pos: [15, 1, 16], state: "minecraft:polished_blackstone_bricks"},
        {pos: [15, 1, 17], state: "minecraft:polished_blackstone_bricks"},
        {pos: [15, 1, 18], state: "minecraft:polished_blackstone_bricks"},
        {pos: [15, 1, 19], state: "minecraft:polished_blackstone_bricks"},
        {pos: [15, 1, 20], state: "minecraft:blackstone"},
        {pos: [15, 1, 21], state: "minecraft:air"},
        {pos: [15, 1, 22], state: "minecraft:air"},
        {pos: [15, 1, 23], state: "minecraft:air"},
        {pos: [15, 1, 24], state: "minecraft:lava{level:8}"},
        {pos: [15, 1, 25], state: "minecraft:air"},
        {pos: [15, 1, 26], state: "minecraft:chiseled_polished_blackstone"},
        {pos: [15, 1, 27], state: "minecraft:gold_block"},
        {pos: [15, 1, 28], state: "minecraft:air"},
        {pos: [15, 1, 29], state: "minecraft:polished_blackstone_bricks"},
        {pos: [15, 1, 30], state: "minecraft:polished_blackstone_bricks"},
        {pos: [15, 1, 31], state: "minecraft:polished_blackstone_bricks"},
        {pos: [16, 1, 0], state: "minecraft:polished_blackstone_bricks"},
        {pos: [16, 1, 1], state: "minecraft:polished_blackstone_bricks"},
        {pos: [16, 1, 2], state: "minecraft:polished_blackstone_bricks"},
        {pos: [16, 1, 3], state: "minecraft:polished_blackstone_bricks"},
        {pos: [16, 1, 4], state: "minecraft:polished_blackstone_bricks"},
        {pos: [16, 1, 5], state: "minecraft:polished_blackstone_bricks"},
        {pos: [16, 1, 6], state: "minecraft:basalt{axis:y}"},
        {pos: [16, 1, 7], state: "minecraft:basalt{axis:y}"},
        {pos: [16, 1, 8], state: "minecraft:basalt{axis:y}"},
        {pos: [16, 1, 9], state: "minecraft:air"},
        {pos: [16, 1, 10], state: "minecraft:air"},
        {pos: [16, 1, 11], state: "minecraft:polished_blackstone_bricks"},
        {pos: [16, 1, 12], state: "minecraft:polished_blackstone_bricks"},
        {pos: [16, 1, 13], state: "minecraft:polished_blackstone_bricks"},
        {pos: [16, 1, 14], state: "minecraft:polished_blackstone_bricks"},
        {pos: [16, 1, 15], state: "minecraft:polished_blackstone_bricks"},
        {pos: [16, 1, 16], state: "minecraft:polished_blackstone_bricks"},
        {pos: [16, 1, 17], state: "minecraft:polished_blackstone_bricks"},
        {pos: [16, 1, 18], state: "minecraft:polished_blackstone_bricks"},
        {pos: [16, 1, 19], state: "minecraft:polished_blackstone_bricks"},
        {pos: [16, 1, 20], state: "minecraft:polished_blackstone_bricks"},
        {pos: [16, 1, 21], state: "minecraft:air"},
        {pos: [16, 1, 22], state: "minecraft:air"},
        {pos: [16, 1, 23], state: "minecraft:air"},
        {pos: [16, 1, 24], state: "minecraft:polished_blackstone_bricks"},
        {pos: [16, 1, 25], state: "minecraft:air"},
        {pos: [16, 1, 26], state: "minecraft:air"},
        {pos: [16, 1, 27], state: "minecraft:chiseled_polished_blackstone"},
        {pos: [16, 1, 28], state: "minecraft:polished_blackstone_bricks"},
        {pos: [16, 1, 29], state: "minecraft:polished_blackstone_bricks"},
        {pos: [16, 1, 30], state: "minecraft:polished_blackstone_bricks"},
        {pos: [16, 1, 31], state: "minecraft:polished_blackstone_bricks"},
        {pos: [0, 2, 0], state: "minecraft:polished_blackstone_bricks"},
        {pos: [0, 2, 1], state: "minecraft:polished_blackstone_bricks"},
        {pos: [0, 2, 2], state: "minecraft:air"},
        {pos: [0, 2, 3], state: "minecraft:air"},
        {pos: [0, 2, 4], state: "minecraft:blackstone"},
        {pos: [0, 2, 5], state: "minecraft:blackstone"},
        {pos: [0, 2, 6], state: "minecraft:blackstone"},
        {pos: [0, 2, 7], state: "minecraft:polished_blackstone_bricks"},
        {pos: [0, 2, 8], state: "minecraft:air"},
        {pos: [0, 2, 9], state: "minecraft:air"},
        {pos: [0, 2, 10], state: "minecraft:air"},
        {pos: [0, 2, 11], state: "minecraft:jigsaw{orientation:west_up}", nbt: {final_state: "minecraft:polished_blackstone_bricks", id: "minecraft:jigsaw", joint: "rollable", name: "minecraft:empty", pool: "minecraft:bastion/bridge/bridge_pieces", target: "minecraft:bridge_connector"}},
        {pos: [0, 2, 12], state: "minecraft:polished_blackstone_bricks"},
        {pos: [0, 2, 13], state: "minecraft:air"},
        {pos: [0, 2, 14], state: "minecraft:air"},
        {pos: [0, 2, 15], state: "minecraft:blackstone"},
        {pos: [0, 2, 16], state: "minecraft:air"},
        {pos: [0, 2, 17], state: "minecraft:air"},
        {pos: [0, 2, 18], state: "minecraft:air"},
        {pos: [0, 2, 19], state: "minecraft:air"},
        {pos: [0, 2, 20], state: "minecraft:air"},
        {pos: [0, 2, 21], state: "minecraft:air"},
        {pos: [0, 2, 22], state: "minecraft:air"},
        {pos: [0, 2, 23], state: "minecraft:air"},
        {pos: [0, 2, 24], state: "minecraft:polished_blackstone_bricks"},
        {pos: [0, 2, 25], state: "minecraft:polished_blackstone_bricks"},
        {pos: [0, 2, 26], state: "minecraft:blackstone"},
        {pos: [0, 2, 27], state: "minecraft:blackstone"},
        {pos: [0, 2, 28], state: "minecraft:air"},
        {pos: [0, 2, 29], state: "minecraft:air"},
        {pos: [0, 2, 30], state: "minecraft:polished_blackstone_bricks"},
        {pos: [0, 2, 31], state: "minecraft:polished_blackstone_bricks"},
        {pos: [1, 2, 0], state: "minecraft:polished_blackstone_bricks"},
        {pos: [1, 2, 1], state: "minecraft:polished_blackstone_bricks"},
        {pos: [1, 2, 2], state: "minecraft:polished_blackstone_bricks"},
        {pos: [1, 2, 3], state: "minecraft:polished_blackstone_bricks"},
        {pos: [1, 2, 4], state: "minecraft:polished_blackstone_bricks"},
        {pos: [1, 2, 5], state: "minecraft:polished_blackstone_bricks"},
        {pos: [1, 2, 6], state: "minecraft:polished_blackstone_bricks"},
        {pos: [1, 2, 7], state: "minecraft:air"},
        {pos: [1, 2, 8], state: "minecraft:air"},
        {pos: [1, 2, 9], state: "minecraft:air"},
        {pos: [1, 2, 10], state: "minecraft:air"},
        {pos: [1, 2, 11], state: "minecraft:polished_blackstone_bricks"},
        {pos: [1, 2, 12], state: "minecraft:polished_blackstone_bricks"},
        {pos: [1, 2, 13], state: "minecraft:air"},
        {pos: [1, 2, 14], state: "minecraft:air"},
        {pos: [1, 2, 15], state: "minecraft:blackstone"},
        {pos: [1, 2, 16], state: "minecraft:air"},
        {pos: [1, 2, 17], state: "minecraft:air"},
        {pos: [1, 2, 18], state: "minecraft:air"},
        {pos: [1, 2, 19], state: "minecraft:air"},
        {pos: [1, 2, 20], state: "minecraft:air"},
        {pos: [1, 2, 21], state: "minecraft:air"},
        {pos: [1, 2, 22], state: "minecraft:air"},
        {pos: [1, 2, 23], state: "minecraft:air"},
        {pos: [1, 2, 24], state: "minecraft:polished_blackstone_bricks"},
        {pos: [1, 2, 25], state: "minecraft:polished_blackstone_bricks"},
        {pos: [1, 2, 26], state: "minecraft:polished_blackstone_bricks"},
        {pos: [1, 2, 27], state: "minecraft:polished_blackstone_bricks"},
        {pos: [1, 2, 28], state: "minecraft:polished_blackstone_bricks"},
        {pos: [1, 2, 29], state: "minecraft:polished_blackstone_bricks"},
        {pos: [1, 2, 30], state: "minecraft:polished_blackstone_bricks"},
        {pos: [1, 2, 31], state: "minecraft:polished_blackstone_bricks"},
        {pos: [2, 2, 0], state: "minecraft:polished_blackstone_bricks"},
        {pos: [2, 2, 1], state: "minecraft:polished_blackstone_bricks"},
        {pos: [2, 2, 2], state: "minecraft:polished_blackstone_bricks"},
        {pos: [2, 2, 3], state: "minecraft:polished_blackstone_bricks"},
        {pos: [2, 2, 4], state: "minecraft:polished_blackstone_bricks"},
        {pos: [2, 2, 5], state: "minecraft:polished_blackstone_bricks"},
        {pos: [2, 2, 6], state: "minecraft:air"},
        {pos: [2, 2, 7], state: "minecraft:lava{level:8}"},
        {pos: [2, 2, 8], state: "minecraft:air"},
        {pos: [2, 2, 9], state: "minecraft:air"},
        {pos: [2, 2, 10], state: "minecraft:air"},
        {pos: [2, 2, 11], state: "minecraft:polished_blackstone_bricks"},
        {pos: [2, 2, 12], state: "minecraft:polished_blackstone_bricks"},
        {pos: [2, 2, 13], state: "minecraft:air"},
        {pos: [2, 2, 14], state: "minecraft:air"},
        {pos: [2, 2, 15], state: "minecraft:blackstone"},
        {pos: [2, 2, 16], state: "minecraft:polished_blackstone_bricks"},
        {pos: [2, 2, 17], state: "minecraft:air"},
        {pos: [2, 2, 18], state: "minecraft:air"},
        {pos: [2, 2, 19], state: "minecraft:air"},
        {pos: [2, 2, 20], state: "minecraft:air"},
        {pos: [2, 2, 21], state: "minecraft:air"},
        {pos: [2, 2, 22], state: "minecraft:air"},
        {pos: [2, 2, 23], state: "minecraft:lava{level:8}"},
        {pos: [2, 2, 24], state: "minecraft:air"},
        {pos: [2, 2, 25], state: "minecraft:polished_blackstone_bricks"},
        {pos: [2, 2, 26], state: "minecraft:polished_blackstone_bricks"},
        {pos: [2, 2, 27], state: "minecraft:polished_blackstone_bricks"},
        {pos: [2, 2, 28], state: "minecraft:polished_blackstone_bricks"},
        {pos: [2, 2, 29], state: "minecraft:polished_blackstone_bricks"},
        {pos: [2, 2, 30], state: "minecraft:polished_blackstone_bricks"},
        {pos: [2, 2, 31], state: "minecraft:polished_blackstone_bricks"},
        {pos: [3, 2, 0], state: "minecraft:polished_blackstone_bricks"},
        {pos: [3, 2, 1], state: "minecraft:polished_blackstone_bricks"},
        {pos: [3, 2, 2], state: "minecraft:polished_blackstone_bricks"},
        {pos: [3, 2, 3], state: "minecraft:polished_blackstone_bricks"},
        {pos: [3, 2, 4], state: "minecraft:polished_blackstone_bricks"},
        {pos: [3, 2, 5], state: "minecraft:polished_blackstone_bricks"},
        {pos: [3, 2, 6], state: "minecraft:polished_blackstone_bricks"},
        {pos: [3, 2, 7], state: "minecraft:lava{level:8}"},
        {pos: [3, 2, 8], state: "minecraft:lava{level:2}"},
        {pos: [3, 2, 9], state: "minecraft:air"},
        {pos: [3, 2, 10], state: "minecraft:air"},
        {pos: [3, 2, 11], state: "minecraft:polished_blackstone_bricks"},
        {pos: [3, 2, 12], state: "minecraft:polished_blackstone_bricks"},
        {pos: [3, 2, 13], state: "minecraft:blackstone"},
        {pos: [3, 2, 14], state: "minecraft:air"},
        {pos: [3, 2, 15], state: "minecraft:blackstone"},
        {pos: [3, 2, 16], state: "minecraft:air"},
        {pos: [3, 2, 17], state: "minecraft:air"},
        {pos: [3, 2, 18], state: "minecraft:air"},
        {pos: [3, 2, 19], state: "minecraft:air"},
        {pos: [3, 2, 20], state: "minecraft:air"},
        {pos: [3, 2, 21], state: "minecraft:air"},
        {pos: [3, 2, 22], state: "minecraft:air"},
        {pos: [3, 2, 23], state: "minecraft:lava{level:8}"},
        {pos: [3, 2, 24], state: "minecraft:air"},
        {pos: [3, 2, 25], state: "minecraft:polished_blackstone_bricks"},
        {pos: [3, 2, 26], state: "minecraft:polished_blackstone_bricks"},
        {pos: [3, 2, 27], state: "minecraft:polished_blackstone_bricks"},
        {pos: [3, 2, 28], state: "minecraft:polished_blackstone_bricks"},
        {pos: [3, 2, 29], state: "minecraft:polished_blackstone_bricks"},
        {pos: [3, 2, 30], state: "minecraft:polished_blackstone_bricks"},
        {pos: [3, 2, 31], state: "minecraft:polished_blackstone_bricks"},
        {pos: [4, 2, 0], state: "minecraft:polished_blackstone_bricks"},
        {pos: [4, 2, 1], state: "minecraft:polished_blackstone_bricks"},
        {pos: [4, 2, 2], state: "minecraft:polished_blackstone_bricks"},
        {pos: [4, 2, 3], state: "minecraft:polished_blackstone_bricks"},
        {pos: [4, 2, 4], state: "minecraft:polished_blackstone_bricks"},
        {pos: [4, 2, 5], state: "minecraft:polished_blackstone_bricks"},
        {pos: [4, 2, 6], state: "minecraft:polished_blackstone_bricks"},
        {pos: [4, 2, 7], state: "minecraft:polished_blackstone_bricks"},
        {pos: [4, 2, 8], state: "minecraft:air"},
        {pos: [4, 2, 9], state: "minecraft:blackstone"},
        {pos: [4, 2, 10], state: "minecraft:air"},
        {pos: [4, 2, 11], state: "minecraft:air"},
        {pos: [4, 2, 12], state: "minecraft:polished_blackstone_bricks"},
        {pos: [4, 2, 13], state: "minecraft:air"},
        {pos: [4, 2, 14], state: "minecraft:air"},
        {pos: [4, 2, 15], state: "minecraft:air"},
        {pos: [4, 2, 16], state: "minecraft:blackstone"},
        {pos: [4, 2, 17], state: "minecraft:air"},
        {pos: [4, 2, 18], state: "minecraft:blackstone"},
        {pos: [4, 2, 19], state: "minecraft:polished_blackstone_bricks"},
        {pos: [4, 2, 20], state: "minecraft:polished_blackstone_bricks"},
        {pos: [4, 2, 21], state: "minecraft:air"},
        {pos: [4, 2, 22], state: "minecraft:air"},
        {pos: [4, 2, 23], state: "minecraft:air"},
        {pos: [4, 2, 24], state: "minecraft:polished_blackstone_bricks"},
        {pos: [4, 2, 25], state: "minecraft:polished_blackstone_bricks"},
        {pos: [4, 2, 26], state: "minecraft:polished_blackstone_bricks"},
        {pos: [4, 2, 27], state: "minecraft:polished_blackstone_bricks"},
        {pos: [4, 2, 28], state: "minecraft:polished_blackstone_bricks"},
        {pos: [4, 2, 29], state: "minecraft:polished_blackstone_bricks"},
        {pos: [4, 2, 30], state: "minecraft:polished_blackstone_bricks"},
        {pos: [4, 2, 31], state: "minecraft:polished_blackstone_bricks"},
        {pos: [5, 2, 0], state: "minecraft:polished_blackstone_bricks"},
        {pos: [5, 2, 1], state: "minecraft:polished_blackstone_bricks"},
        {pos: [5, 2, 2], state: "minecraft:polished_blackstone_bricks"},
        {pos: [5, 2, 3], state: "minecraft:polished_blackstone_bricks"},
        {pos: [5, 2, 4], state: "minecraft:polished_blackstone_bricks"},
        {pos: [5, 2, 5], state: "minecraft:polished_blackstone_bricks"},
        {pos: [5, 2, 6], state: "minecraft:polished_blackstone_bricks"},
        {pos: [5, 2, 7], state: "minecraft:lava{level:8}"},
        {pos: [5, 2, 8], state: "minecraft:air"},
        {pos: [5, 2, 9], state: "minecraft:air"},
        {pos: [5, 2, 10], state: "minecraft:air"},
        {pos: [5, 2, 11], state: "minecraft:polished_blackstone_bricks"},
        {pos: [5, 2, 12], state: "minecraft:polished_blackstone_bricks"},
        {pos: [5, 2, 13], state: "minecraft:air"},
        {pos: [5, 2, 14], state: "minecraft:air"},
        {pos: [5, 2, 15], state: "minecraft:air"},
        {pos: [5, 2, 16], state: "minecraft:air"},
        {pos: [5, 2, 17], state: "minecraft:air"},
        {pos: [5, 2, 18], state: "minecraft:air"},
        {pos: [5, 2, 19], state: "minecraft:polished_blackstone_bricks"},
        {pos: [5, 2, 20], state: "minecraft:polished_blackstone_bricks"},
        {pos: [5, 2, 21], state: "minecraft:air"},
        {pos: [5, 2, 22], state: "minecraft:air"},
        {pos: [5, 2, 23], state: "minecraft:air"},
        {pos: [5, 2, 24], state: "minecraft:lava{level:8}"},
        {pos: [5, 2, 25], state: "minecraft:polished_blackstone_bricks"},
        {pos: [5, 2, 26], state: "minecraft:polished_blackstone_bricks"},
        {pos: [5, 2, 27], state: "minecraft:polished_blackstone_bricks"},
        {pos: [5, 2, 28], state: "minecraft:polished_blackstone_bricks"},
        {pos: [5, 2, 29], state: "minecraft:polished_blackstone_bricks"},
        {pos: [5, 2, 30], state: "minecraft:polished_blackstone_bricks"},
        {pos: [5, 2, 31], state: "minecraft:polished_blackstone_bricks"},
        {pos: [6, 2, 0], state: "minecraft:polished_blackstone_bricks"},
        {pos: [6, 2, 1], state: "minecraft:polished_blackstone_bricks"},
        {pos: [6, 2, 2], state: "minecraft:polished_blackstone_bricks"},
        {pos: [6, 2, 3], state: "minecraft:polished_blackstone_bricks"},
        {pos: [6, 2, 4], state: "minecraft:polished_blackstone_bricks"},
        {pos: [6, 2, 5], state: "minecraft:polished_blackstone_bricks"},
        {pos: [6, 2, 6], state: "minecraft:polished_blackstone_bricks"},
        {pos: [6, 2, 7], state: "minecraft:lava{level:8}"},
        {pos: [6, 2, 8], state: "minecraft:air"},
        {pos: [6, 2, 9], state: "minecraft:air"},
        {pos: [6, 2, 10], state: "minecraft:air"},
        {pos: [6, 2, 11], state: "minecraft:air"},
        {pos: [6, 2, 12], state: "minecraft:air"},
        {pos: [6, 2, 13], state: "minecraft:air"},
        {pos: [6, 2, 14], state: "minecraft:air"},
        {pos: [6, 2, 15], state: "minecraft:air"},
        {pos: [6, 2, 16], state: "minecraft:air"},
        {pos: [6, 2, 17], state: "minecraft:air"},
        {pos: [6, 2, 18], state: "minecraft:air"},
        {pos: [6, 2, 19], state: "minecraft:polished_blackstone_bricks"},
        {pos: [6, 2, 20], state: "minecraft:polished_blackstone_bricks"},
        {pos: [6, 2, 21], state: "minecraft:air"},
        {pos: [6, 2, 22], state: "minecraft:air"},
        {pos: [6, 2, 23], state: "minecraft:lava{level:8}"},
        {pos: [6, 2, 24], state: "minecraft:blackstone"},
        {pos: [6, 2, 25], state: "minecraft:blackstone"},
        {pos: [6, 2, 26], state: "minecraft:polished_blackstone_bricks"},
        {pos: [6, 2, 27], state: "minecraft:polished_blackstone_bricks"},
        {pos: [6, 2, 28], state: "minecraft:polished_blackstone_bricks"},
        {pos: [6, 2, 29], state: "minecraft:polished_blackstone_bricks"},
        {pos: [6, 2, 30], state: "minecraft:polished_blackstone_bricks"},
        {pos: [6, 2, 31], state: "minecraft:polished_blackstone_bricks"},
        {pos: [7, 2, 0], state: "minecraft:polished_blackstone_bricks"},
        {pos: [7, 2, 1], state: "minecraft:polished_blackstone_bricks"},
        {pos: [7, 2, 2], state: "minecraft:polished_blackstone_bricks"},
        {pos: [7, 2, 3], state: "minecraft:polished_blackstone_bricks"},
        {pos: [7, 2, 4], state: "minecraft:polished_blackstone_bricks"},
        {pos: [7, 2, 5], state: "minecraft:polished_blackstone_bricks"},
        {pos: [7, 2, 6], state: "minecraft:polished_blackstone_bricks"},
        {pos: [7, 2, 7], state: "minecraft:polished_blackstone_bricks"},
        {pos: [7, 2, 8], state: "minecraft:air"},
        {pos: [7, 2, 9], state: "minecraft:air"},
        {pos: [7, 2, 10], state: "minecraft:air"},
        {pos: [7, 2, 11], state: "minecraft:air"},
        {pos: [7, 2, 12], state: "minecraft:air"},
        {pos: [7, 2, 13], state: "minecraft:air"},
        {pos: [7, 2, 14], state: "minecraft:air"},
        {pos: [7, 2, 15], state: "minecraft:blackstone"},
        {pos: [7, 2, 16], state: "minecraft:polished_blackstone_bricks"},
        {pos: [7, 2, 17], state: "minecraft:blackstone"},
        {pos: [7, 2, 18], state: "minecraft:air"},
        {pos: [7, 2, 19], state: "minecraft:air"},
        {pos: [7, 2, 20], state: "minecraft:air"},
        {pos: [7, 2, 21], state: "minecraft:air"},
        {pos: [7, 2, 22], state: "minecraft:air"},
        {pos: [7, 2, 23], state: "minecraft:lava{level:8}"},
        {pos: [7, 2, 24], state: "minecraft:polished_blackstone_bricks"},
        {pos: [7, 2, 25], state: "minecraft:blackstone"},
        {pos: [7, 2, 26], state: "minecraft:polished_blackstone_bricks"},
        {pos: [7, 2, 27], state: "minecraft:polished_blackstone_bricks"},
        {pos: [7, 2, 28], state: "minecraft:polished_blackstone_bricks"},
        {pos: [7, 2, 29], state: "minecraft:polished_blackstone_bricks"},
        {pos: [7, 2, 30], state: "minecraft:polished_blackstone_bricks"},
        {pos: [7, 2, 31], state: "minecraft:polished_blackstone_bricks"},
        {pos: [8, 2, 0], state: "minecraft:polished_blackstone_bricks"},
        {pos: [8, 2, 1], state: "minecraft:polished_blackstone_bricks"},
        {pos: [8, 2, 2], state: "minecraft:polished_blackstone_bricks"},
        {pos: [8, 2, 3], state: "minecraft:polished_blackstone_bricks"},
        {pos: [8, 2, 4], state: "minecraft:polished_blackstone_bricks"},
        {pos: [8, 2, 5], state: "minecraft:polished_blackstone_bricks"},
        {pos: [8, 2, 6], state: "minecraft:polished_blackstone_bricks"},
        {pos: [8, 2, 7], state: "minecraft:lava{level:8}"},
        {pos: [8, 2, 8], state: "minecraft:air"},
        {pos: [8, 2, 9], state: "minecraft:air"},
        {pos: [8, 2, 10], state: "minecraft:air"},
        {pos: [8, 2, 11], state: "minecraft:air"},
        {pos: [8, 2, 12], state: "minecraft:air"},
        {pos: [8, 2, 13], state: "minecraft:air"},
        {pos: [8, 2, 14], state: "minecraft:air"},
        {pos: [8, 2, 15], state: "minecraft:polished_blackstone_bricks"},
        {pos: [8, 2, 16], state: "minecraft:air"},
        {pos: [8, 2, 17], state: "minecraft:air"},
        {pos: [8, 2, 18], state: "minecraft:air"},
        {pos: [8, 2, 19], state: "minecraft:air"},
        {pos: [8, 2, 20], state: "minecraft:air"},
        {pos: [8, 2, 21], state: "minecraft:air"},
        {pos: [8, 2, 22], state: "minecraft:air"},
        {pos: [8, 2, 23], state: "minecraft:lava{level:8}"},
        {pos: [8, 2, 24], state: "minecraft:air"},
        {pos: [8, 2, 25], state: "minecraft:air"},
        {pos: [8, 2, 26], state: "minecraft:polished_blackstone_bricks"},
        {pos: [8, 2, 27], state: "minecraft:polished_blackstone_bricks"},
        {pos: [8, 2, 28], state: "minecraft:polished_blackstone_bricks"},
        {pos: [8, 2, 29], state: "minecraft:polished_blackstone_bricks"},
        {pos: [8, 2, 30], state: "minecraft:polished_blackstone_bricks"},
        {pos: [8, 2, 31], state: "minecraft:polished_blackstone_bricks"},
        {pos: [9, 2, 0], state: "minecraft:polished_blackstone_bricks"},
        {pos: [9, 2, 1], state: "minecraft:polished_blackstone_bricks"},
        {pos: [9, 2, 2], state: "minecraft:polished_blackstone_bricks"},
        {pos: [9, 2, 3], state: "minecraft:polished_blackstone_bricks"},
        {pos: [9, 2, 4], state: "minecraft:polished_blackstone_bricks"},
        {pos: [9, 2, 5], state: "minecraft:polished_blackstone_bricks"},
        {pos: [9, 2, 6], state: "minecraft:polished_blackstone_bricks"},
        {pos: [9, 2, 7], state: "minecraft:lava{level:8}"},
        {pos: [9, 2, 8], state: "minecraft:air"},
        {pos: [9, 2, 9], state: "minecraft:air"},
        {pos: [9, 2, 10], state: "minecraft:air"},
        {pos: [9, 2, 11], state: "minecraft:air"},
        {pos: [9, 2, 12], state: "minecraft:air"},
        {pos: [9, 2, 13], state: "minecraft:air"},
        {pos: [9, 2, 14], state: "minecraft:air"},
        {pos: [9, 2, 15], state: "minecraft:air"},
        {pos: [9, 2, 16], state: "minecraft:polished_blackstone_bricks"},
        {pos: [9, 2, 17], state: "minecraft:blackstone"},
        {pos: [9, 2, 18], state: "minecraft:air"},
        {pos: [9, 2, 19], state: "minecraft:air"},
        {pos: [9, 2, 20], state: "minecraft:blackstone"},
        {pos: [9, 2, 21], state: "minecraft:air"},
        {pos: [9, 2, 22], state: "minecraft:air"},
        {pos: [9, 2, 23], state: "minecraft:lava{level:8}"},
        {pos: [9, 2, 24], state: "minecraft:air"},
        {pos: [9, 2, 25], state: "minecraft:air"},
        {pos: [9, 2, 26], state: "minecraft:polished_blackstone_bricks"},
        {pos: [9, 2, 27], state: "minecraft:polished_blackstone_bricks"},
        {pos: [9, 2, 28], state: "minecraft:polished_blackstone_bricks"},
        {pos: [9, 2, 29], state: "minecraft:polished_blackstone_bricks"},
        {pos: [9, 2, 30], state: "minecraft:polished_blackstone_bricks"},
        {pos: [9, 2, 31], state: "minecraft:polished_blackstone_bricks"},
        {pos: [10, 2, 0], state: "minecraft:polished_blackstone_bricks"},
        {pos: [10, 2, 1], state: "minecraft:polished_blackstone_bricks"},
        {pos: [10, 2, 2], state: "minecraft:polished_blackstone_bricks"},
        {pos: [10, 2, 3], state: "minecraft:polished_blackstone_bricks"},
        {pos: [10, 2, 4], state: "minecraft:polished_blackstone_bricks"},
        {pos: [10, 2, 5], state: "minecraft:polished_blackstone_bricks"},
        {pos: [10, 2, 6], state: "minecraft:polished_blackstone_bricks"},
        {pos: [10, 2, 7], state: "minecraft:polished_blackstone_bricks"},
        {pos: [10, 2, 8], state: "minecraft:air"},
        {pos: [10, 2, 9], state: "minecraft:air"},
        {pos: [10, 2, 10], state: "minecraft:air"},
        {pos: [10, 2, 11], state: "minecraft:air"},
        {pos: [10, 2, 12], state: "minecraft:air"},
        {pos: [10, 2, 13], state: "minecraft:air"},
        {pos: [10, 2, 14], state: "minecraft:air"},
        {pos: [10, 2, 15], state: "minecraft:air"},
        {pos: [10, 2, 16], state: "minecraft:polished_blackstone_bricks"},
        {pos: [10, 2, 17], state: "minecraft:air"},
        {pos: [10, 2, 18], state: "minecraft:air"},
        {pos: [10, 2, 19], state: "minecraft:air"},
        {pos: [10, 2, 20], state: "minecraft:air"},
        {pos: [10, 2, 21], state: "minecraft:air"},
        {pos: [10, 2, 22], state: "minecraft:air"},
        {pos: [10, 2, 23], state: "minecraft:air"},
        {pos: [10, 2, 24], state: "minecraft:polished_blackstone_bricks"},
        {pos: [10, 2, 25], state: "minecraft:polished_blackstone_bricks"},
        {pos: [10, 2, 26], state: "minecraft:polished_blackstone_bricks"},
        {pos: [10, 2, 27], state: "minecraft:polished_blackstone_bricks"},
        {pos: [10, 2, 28], state: "minecraft:polished_blackstone_bricks"},
        {pos: [10, 2, 29], state: "minecraft:polished_blackstone_bricks"},
        {pos: [10, 2, 30], state: "minecraft:polished_blackstone_bricks"},
        {pos: [10, 2, 31], state: "minecraft:polished_blackstone_bricks"},
        {pos: [11, 2, 0], state: "minecraft:polished_blackstone_bricks"},
        {pos: [11, 2, 1], state: "minecraft:polished_blackstone_bricks"},
        {pos: [11, 2, 2], state: "minecraft:polished_blackstone_bricks"},
        {pos: [11, 2, 3], state: "minecraft:polished_blackstone_bricks"},
        {pos: [11, 2, 4], state: "minecraft:polished_blackstone_bricks"},
        {pos: [11, 2, 5], state: "minecraft:polished_blackstone_bricks"},
        {pos: [11, 2, 6], state: "minecraft:polished_blackstone_bricks"},
        {pos: [11, 2, 7], state: "minecraft:lava{level:8}"},
        {pos: [11, 2, 8], state: "minecraft:air"},
        {pos: [11, 2, 9], state: "minecraft:air"},
        {pos: [11, 2, 10], state: "minecraft:air"},
        {pos: [11, 2, 11], state: "minecraft:air"},
        {pos: [11, 2, 12], state: "minecraft:air"},
        {pos: [11, 2, 13], state: "minecraft:air"},
        {pos: [11, 2, 14], state: "minecraft:air"},
        {pos: [11, 2, 15], state: "minecraft:air"},
        {pos: [11, 2, 16], state: "minecraft:blackstone"},
        {pos: [11, 2, 17], state: "minecraft:air"},
        {pos: [11, 2, 18], state: "minecraft:air"},
        {pos: [11, 2, 19], state: "minecraft:air"},
        {pos: [11, 2, 20], state: "minecraft:air"},
        {pos: [11, 2, 21], state: "minecraft:air"},
        {pos: [11, 2, 22], state: "minecraft:air"},
        {pos: [11, 2, 23], state: "minecraft:air"},
        {pos: [11, 2, 24], state: "minecraft:lava{level:8}"},
        {pos: [11, 2, 25], state: "minecraft:polished_blackstone_bricks"},
        {pos: [11, 2, 26], state: "minecraft:polished_blackstone_bricks"},
        {pos: [11, 2, 27], state: "minecraft:polished_blackstone_bricks"},
        {pos: [11, 2, 28], state: "minecraft:polished_blackstone_bricks"},
        {pos: [11, 2, 29], state: "minecraft:polished_blackstone_bricks"},
        {pos: [11, 2, 30], state: "minecraft:polished_blackstone_bricks"},
        {pos: [11, 2, 31], state: "minecraft:polished_blackstone_bricks"},
        {pos: [12, 2, 0], state: "minecraft:polished_blackstone_bricks"},
        {pos: [12, 2, 1], state: "minecraft:polished_blackstone_bricks"},
        {pos: [12, 2, 2], state: "minecraft:polished_blackstone_bricks"},
        {pos: [12, 2, 3], state: "minecraft:polished_blackstone_bricks"},
        {pos: [12, 2, 4], state: "minecraft:polished_blackstone_bricks"},
        {pos: [12, 2, 5], state: "minecraft:polished_blackstone_bricks"},
        {pos: [12, 2, 6], state: "minecraft:polished_blackstone_bricks"},
        {pos: [12, 2, 7], state: "minecraft:air"},
        {pos: [12, 2, 8], state: "minecraft:lava{level:8}"},
        {pos: [12, 2, 9], state: "minecraft:air"},
        {pos: [12, 2, 10], state: "minecraft:air"},
        {pos: [12, 2, 11], state: "minecraft:air"},
        {pos: [12, 2, 12], state: "minecraft:air"},
        {pos: [12, 2, 13], state: "minecraft:air"},
        {pos: [12, 2, 14], state: "minecraft:air"},
        {pos: [12, 2, 15], state: "minecraft:air"},
        {pos: [12, 2, 16], state: "minecraft:air"},
