{
    size: [15, 10, 10],
    data: [
        {pos: [0, 0, 6], state: "minecraft:dirt"},
        {pos: [1, 0, 6], state: "minecraft:dirt"},
        {pos: [2, 0, 1], state: "minecraft:grass_block{snowy:false}"},
        {pos: [2, 0, 2], state: "minecraft:grass_block{snowy:false}"},
        {pos: [2, 0, 3], state: "minecraft:dirt"},
        {pos: [2, 0, 4], state: "minecraft:dirt"},
        {pos: [2, 0, 5], state: "minecraft:dirt"},
        {pos: [2, 0, 6], state: "minecraft:dirt"},
        {pos: [3, 0, 0], state: "minecraft:grass_block{snowy:false}"},
        {pos: [3, 0, 1], state: "minecraft:dirt"},
        {pos: [3, 0, 2], state: "minecraft:dirt"},
        {pos: [3, 0, 3], state: "minecraft:dirt"},
        {pos: [3, 0, 4], state: "minecraft:dirt"},
        {pos: [3, 0, 5], state: "minecraft:dirt"},
        {pos: [3, 0, 6], state: "minecraft:dirt"},
        {pos: [4, 0, 0], state: "minecraft:dirt"},
        {pos: [4, 0, 1], state: "minecraft:dirt"},
        {pos: [4, 0, 2], state: "minecraft:dirt"},
        {pos: [4, 0, 3], state: "minecraft:dirt"},
        {pos: [4, 0, 4], state: "minecraft:dirt"},
        {pos: [4, 0, 5], state: "minecraft:dirt"},
        {pos: [4, 0, 6], state: "minecraft:dirt"},
        {pos: [4, 0, 7], state: "minecraft:dirt"},
        {pos: [5, 0, 0], state: "minecraft:dirt"},
        {pos: [5, 0, 1], state: "minecraft:dirt"},
        {pos: [5, 0, 2], state: "minecraft:dirt"},
        {pos: [5, 0, 3], state: "minecraft:dirt"},
        {pos: [5, 0, 4], state: "minecraft:oxidized_copper_chest{facing:east,type:single,waterlogged:false}", nbt: {Items: [], LootTable: "minecraft:chests/abandoned_camp_secret_chest", components: {}, id: "minecraft:chest"}},
        {pos: [5, 0, 5], state: "minecraft:dirt"},
        {pos: [5, 0, 6], state: "minecraft:dirt"},
        {pos: [5, 0, 7], state: "minecraft:dirt"},
        {pos: [5, 0, 8], state: "minecraft:dirt"},
        {pos: [6, 0, 2], state: "minecraft:dirt_path"},
        {pos: [6, 0, 3], state: "minecraft:dirt"},
        {pos: [6, 0, 4], state: "minecraft:dirt_path"},
        {pos: [6, 0, 5], state: "minecraft:dirt_path"},
        {pos: [6, 0, 6], state: "minecraft:dirt"},
        {pos: [6, 0, 7], state: "minecraft:dirt"},
        {pos: [6, 0, 8], state: "minecraft:dirt"},
        {pos: [7, 0, 3], state: "minecraft:dirt_path"},
        {pos: [7, 0, 4], state: "minecraft:dirt_path"},
        {pos: [7, 0, 5], state: "minecraft:dirt_path"},
        {pos: [7, 0, 6], state: "minecraft:dirt"},
        {pos: [7, 0, 7], state: "minecraft:dirt_path"},
        {pos: [8, 0, 4], state: "minecraft:dirt_path"},
        {pos: [8, 0, 5], state: "minecraft:dirt"},
        {pos: [8, 0, 6], state: "minecraft:dirt_path"},
        {pos: [8, 0, 7], state: "minecraft:dirt_path"},
        {pos: [9, 0, 3], state: "minecraft:dirt_path"},
        {pos: [9, 0, 4], state: "minecraft:dirt_path"},
        {pos: [9, 0, 5], state: "minecraft:dirt_path"},
        {pos: [9, 0, 6], state: "minecraft:dirt_path"},
        {pos: [10, 0, 3], state: "minecraft:dirt_path"},
        {pos: [10, 0, 4], state: "minecraft:grass_block{snowy:false}"},
        {pos: [10, 0, 5], state: "minecraft:dirt_path"},
        {pos: [10, 0, 6], state: "minecraft:dirt_path"},
        {pos: [11, 0, 3], state: "minecraft:dirt_path"},
        {pos: [11, 0, 4], state: "minecraft:dirt_path"},
        {pos: [13, 0, 4], state: "minecraft:dirt_path"},
        {pos: [14, 0, 4], state: "minecraft:jigsaw{orientation:east_up}", nbt: {components: {}, final_state: "minecraft:dirt_path", id: "minecraft:jigsaw", joint: "rollable", name: "minecraft:end_connector", placement_priority: 0, pool: "minecraft:empty", selection_priority: 0, target: "minecraft:connector"}},
        {pos: [0, 1, 6], state: "minecraft:stone"},
        {pos: [1, 1, 5], state: "minecraft:stone"},
        {pos: [1, 1, 6], state: "minecraft:stone"},
        {pos: [2, 1, 3], state: "minecraft:grass_block{snowy:false}"},
        {pos: [2, 1, 4], state: "minecraft:stone"},
        {pos: [2, 1, 5], state: "minecraft:stone"},
        {pos: [2, 1, 6], state: "minecraft:stone"},
        {pos: [3, 1, 1], state: "minecraft:grass_block{snowy:false}"},
        {pos: [3, 1, 2], state: "minecraft:stone"},
        {pos: [3, 1, 3], state: "minecraft:stone"},
        {pos: [3, 1, 4], state: "minecraft:stone"},
        {pos: [3, 1, 5], state: "minecraft:stone"},
        {pos: [3, 1, 6], state: "minecraft:stone"},
        {pos: [4, 1, 0], state: "minecraft:grass_block{snowy:false}"},
        {pos: [4, 1, 1], state: "minecraft:stone"},
        {pos: [4, 1, 2], state: "minecraft:stone"},
        {pos: [4, 1, 3], state: "minecraft:stone"},
        {pos: [4, 1, 4], state: "minecraft:stone"},
        {pos: [4, 1, 5], state: "minecraft:stone"},
        {pos: [4, 1, 6], state: "minecraft:stone"},
        {pos: [4, 1, 7], state: "minecraft:stone"},
        {pos: [5, 1, 0], state: "minecraft:grass_block{snowy:false}"},
        {pos: [5, 1, 1], state: "minecraft:stone"},
        {pos: [5, 1, 2], state: "minecraft:stone"},
        {pos: [5, 1, 3], state: "minecraft:stone"},
        {pos: [5, 1, 5], state: "minecraft:stone"},
        {pos: [5, 1, 6], state: "minecraft:stone"},
        {pos: [5, 1, 7], state: "minecraft:stone"},
        {pos: [5, 1, 8], state: "minecraft:grass_block{snowy:false}"},
        {pos: [6, 1, 3], state: "minecraft:stone"},
        {pos: [6, 1, 6], state: "minecraft:stone"},
        {pos: [6, 1, 7], state: "minecraft:stone"},
        {pos: [6, 1, 8], state: "minecraft:grass_block{snowy:false}"},
        {pos: [7, 1, 6], state: "minecraft:stone"},
        {pos: [8, 1, 5], state: "minecraft:barrel{facing:east,open:false}", nbt: {Items: [], LootTable: "minecraft:barrels/abandoned_camp_barrel", components: {}, id: "minecraft:barrel"}},
        {pos: [10, 1, 4], state: "minecraft:campfire{facing:south,lit:false,signal_fire:false,waterlogged:false}", nbt: {CookingTimes: [I; 0, 0, 0, 0], CookingTotalTimes: [I; 0, 0, 0, 0], Items: [], components: {}, id: "minecraft:campfire"}},
        {pos: [1, 2, 5], state: "minecraft:grass_block{snowy:false}"},
        {pos: [2, 2, 5], state: "minecraft:grass_block{snowy:false}"},
        {pos: [2, 2, 6], state: "minecraft:jigsaw{orientation:up_north}", nbt: {components: {}, final_state: "minecraft:dirt", id: "minecraft:jigsaw", joint: "rollable", name: "minecraft:down", placement_priority: 0, pool: "minecraft:abandoned_camp/trees/acacia", selection_priority: 0, target: "minecraft:down"}},
        {pos: [3, 2, 3], state: "minecraft:stone"},
        {pos: [3, 2, 4], state: "minecraft:stone"},
        {pos: [3, 2, 5], state: "minecraft:stone"},
        {pos: [3, 2, 6], state: "minecraft:grass_block{snowy:false}"},
        {pos: [4, 2, 1], state: "minecraft:grass_block{snowy:false}"},
        {pos: [4, 2, 2], state: "minecraft:grass_block{snowy:false}"},
        {pos: [4, 2, 3], state: "minecraft:stone"},
        {pos: [4, 2, 4], state: "minecraft:stone"},
        {pos: [4, 2, 5], state: "minecraft:stone"},
        {pos: [4, 2, 6], state: "minecraft:grass_block{snowy:false}"},
        {pos: [5, 2, 1], state: "minecraft:grass_block{snowy:false}"},
        {pos: [5, 2, 2], state: "minecraft:stone"},
        {pos: [5, 2, 3], state: "minecraft:stone"},
        {pos: [5, 2, 4], state: "minecraft:stone"},
        {pos: [5, 2, 5], state: "minecraft:stone"},
        {pos: [5, 2, 6], state: "minecraft:stone"},
        {pos: [5, 2, 7], state: "minecraft:grass_block{snowy:false}"},
        {pos: [6, 2, 2], state: "minecraft:stone"},
        {pos: [6, 2, 3], state: "minecraft:stone"},
        {pos: [6, 2, 4], state: "minecraft:stone"},
        {pos: [6, 2, 5], state: "minecraft:stone"},
        {pos: [6, 2, 6], state: "minecraft:stone"},
        {pos: [6, 2, 7], state: "minecraft:grass_block{snowy:false}"},
        {pos: [7, 2, 3], state: "minecraft:stone"},
        {pos: [7, 2, 4], state: "minecraft:stone"},
        {pos: [7, 2, 5], state: "minecraft:stone"},
        {pos: [7, 2, 6], state: "minecraft:stone"},
        {pos: [7, 2, 7], state: "minecraft:stone"},
        {pos: [8, 2, 4], state: "minecraft:stone"},
        {pos: [8, 2, 5], state: "minecraft:stone"},
        {pos: [8, 2, 6], state: "minecraft:stone"},
        {pos: [3, 3, 3], state: "minecraft:grass_block{snowy:false}"},
        {pos: [3, 3, 4], state: "minecraft:grass_block{snowy:false}"},
        {pos: [4, 3, 3], state: "minecraft:grass_block{snowy:false}"},
        {pos: [4, 3, 4], state: "minecraft:grass_block{snowy:false}"},
        {pos: [4, 3, 5], state: "minecraft:grass_block{snowy:false}"},
        {pos: [5, 3, 2], state: "minecraft:grass_block{snowy:false}"},
        {pos: [5, 3, 3], state: "minecraft:grass_block{snowy:false}"},
        {pos: [5, 3, 4], state: "minecraft:dirt"},
        {pos: [5, 3, 5], state: "minecraft:grass_block{snowy:false}"},
        {pos: [5, 3, 6], state: "minecraft:grass_block{snowy:false}"},
        {pos: [6, 3, 2], state: "minecraft:grass_block{snowy:false}"},
        {pos: [6, 3, 3], state: "minecraft:stone"},
        {pos: [6, 3, 4], state: "minecraft:dirt"},
        {pos: [6, 3, 5], state: "minecraft:stone"},
        {pos: [6, 3, 6], state: "minecraft:grass_block{snowy:false}"},
        {pos: [7, 3, 3], state: "minecraft:stone"},
        {pos: [7, 3, 4], state: "minecraft:stone"},
        {pos: [7, 3, 5], state: "minecraft:stone"},
        {pos: [7, 3, 6], state: "minecraft:stone"},
        {pos: [7, 3, 7], state: "minecraft:grass_block{snowy:false}"},
        {pos: [8, 3, 3], state: "minecraft:stone"},
        {pos: [8, 3, 4], state: "minecraft:stone"},
        {pos: [8, 3, 5], state: "minecraft:stone"},
        {pos: [8, 3, 6], state: "minecraft:stone"},
        {pos: [8, 3, 7], state: "minecraft:stone"},
        {pos: [9, 3, 4], state: "minecraft:stone"},
        {pos: [9, 3, 5], state: "minecraft:stone"},
        {pos: [9, 3, 6], state: "minecraft:stone"},
        {pos: [9, 3, 7], state: "minecraft:stone"},
        {pos: [10, 3, 6], state: "minecraft:stone"},
        {pos: [5, 4, 4], state: "minecraft:grass_block{snowy:false}"},
        {pos: [6, 4, 3], state: "minecraft:grass_block{snowy:false}"},
        {pos: [6, 4, 4], state: "minecraft:grass_block{snowy:false}"},
        {pos: [6, 4, 5], state: "minecraft:grass_block{snowy:false}"},
        {pos: [7, 4, 3], state: "minecraft:grass_block{snowy:false}"},
        {pos: [7, 4, 4], state: "minecraft:grass_block{snowy:false}"},
        {pos: [7, 4, 5], state: "minecraft:grass_block{snowy:false}"},
        {pos: [7, 4, 6], state: "minecraft:grass_block{snowy:false}"},
        {pos: [8, 4, 4], state: "minecraft:grass_block{snowy:false}"},
        {pos: [8, 4, 5], state: "minecraft:jigsaw{orientation:up_north}", nbt: {components: {}, final_state: "minecraft:dirt", id: "minecraft:jigsaw", joint: "rollable", name: "minecraft:down", placement_priority: 0, pool: "minecraft:abandoned_camp/trees/acacia", selection_priority: 0, target: "minecraft:down"}},
        {pos: [8, 4, 6], state: "minecraft:grass_block{snowy:false}"},
        {pos: [8, 4, 7], state: "minecraft:grass_block{snowy:false}"},
        {pos: [9, 4, 4], state: "minecraft:grass_block{snowy:false}"},
        {pos: [9, 4, 5], state: "minecraft:grass_block{snowy:false}"},
        {pos: [9, 4, 6], state: "minecraft:grass_block{snowy:false}"},
        {pos: [9, 4, 7], state: "minecraft:grass_block{snowy:false}"},
        {pos: [10, 4, 6], state: "minecraft:grass_block{snowy:false}"}
    ],
    entities: [
        {blockPos: [9, 0, 3], pos: [9.5d, 0.9375d, 3.5d], nbt: {Air: 300s, Fire: 0s, Invulnerable: 0b, Motion: [0.0d, 0.0d, 0.0d], OnGround: 0b, PortalCooldown: 0, Pos: [-103.5d, -60.0625d, 495.5d], Rotation: [90.0f, 0.0f], UUID: [I; 1299686915, 891505817, -1830615770, 1226004916], block_pos: [I; -104, -61, 495], color: "brown", fall_distance: 0.0d, id: "minecraft:cushion"}},
        {blockPos: [10, 0, 5], pos: [10.5d, 0.9375d, 5.5d], nbt: {Air: 300s, Fire: 0s, Invulnerable: 0b, Motion: [0.0d, 0.0d, 0.0d], OnGround: 0b, PortalCooldown: 0, Pos: [-102.5d, -60.0625d, 497.5d], Rotation: [0.0f, 0.0f], UUID: [I; -1528453586, 985088065, -1485856772, 601156445], block_pos: [I; -103, -61, 497], color: "light_gray", fall_distance: 0.0d, id: "minecraft:cushion"}}
    ],
    palette: [
        "minecraft:dirt",
        "minecraft:grass_block{snowy:false}",
        "minecraft:stone",
        "minecraft:dirt_path",
        "minecraft:oxidized_copper_chest{facing:east,type:single,waterlogged:false}",
        "minecraft:jigsaw{orientation:east_up}",
        "minecraft:barrel{facing:east,open:false}",
        "minecraft:campfire{facing:south,lit:false,signal_fire:false,waterlogged:false}",
        "minecraft:jigsaw{orientation:up_north}"
    ]
}
