{
    size: [12, 10, 13],
    data: [
        {pos: [2, 0, 3], state: "minecraft:dirt"},
        {pos: [2, 0, 4], state: "minecraft:dirt"},
        {pos: [3, 0, 1], state: "minecraft:dirt"},
        {pos: [3, 0, 2], state: "minecraft:dirt"},
        {pos: [3, 0, 3], state: "minecraft:dirt"},
        {pos: [3, 0, 4], state: "minecraft:dirt"},
        {pos: [3, 0, 7], state: "minecraft:jigsaw{orientation:up_west}", nbt: {components: {}, final_state: "minecraft:dirt", id: "minecraft:jigsaw", joint: "rollable", name: "minecraft:down", placement_priority: 0, pool: "minecraft:abandoned_camp/trees/acacia", selection_priority: 0, target: "minecraft:down"}},
        {pos: [4, 0, 1], state: "minecraft:grass_block{snowy:false}"},
        {pos: [4, 0, 2], state: "minecraft:dirt"},
        {pos: [4, 0, 3], state: "minecraft:dirt"},
        {pos: [4, 0, 4], state: "minecraft:dirt"},
        {pos: [4, 0, 5], state: "minecraft:dirt"},
        {pos: [5, 0, 1], state: "minecraft:oxidized_copper_chest{facing:east,type:single,waterlogged:false}", nbt: {LootTable: "minecraft:chests/abandoned_camp_secret_chest", components: {}, id: "minecraft:chest"}},
        {pos: [5, 0, 2], state: "minecraft:grass_block{snowy:false}"},
        {pos: [5, 0, 3], state: "minecraft:dirt"},
        {pos: [5, 0, 4], state: "minecraft:dirt"},
        {pos: [5, 0, 5], state: "minecraft:dirt"},
        {pos: [6, 0, 3], state: "minecraft:dirt"},
        {pos: [6, 0, 4], state: "minecraft:dirt"},
        {pos: [6, 0, 5], state: "minecraft:dirt"},
        {pos: [6, 0, 6], state: "minecraft:dirt"},
        {pos: [6, 0, 7], state: "minecraft:dirt"},
        {pos: [6, 0, 8], state: "minecraft:dirt"},
        {pos: [7, 0, 6], state: "minecraft:dirt"},
        {pos: [7, 0, 7], state: "minecraft:dirt"},
        {pos: [7, 0, 8], state: "minecraft:dirt"},
        {pos: [7, 0, 9], state: "minecraft:dirt"},
        {pos: [8, 0, 3], state: "minecraft:dirt_path"},
        {pos: [8, 0, 4], state: "minecraft:dirt_path"},
        {pos: [8, 0, 7], state: "minecraft:dirt"},
        {pos: [8, 0, 8], state: "minecraft:dirt"},
        {pos: [9, 0, 1], state: "minecraft:grass_block{snowy:false}"},
        {pos: [9, 0, 2], state: "minecraft:dirt_path"},
        {pos: [9, 0, 3], state: "minecraft:grass_block{snowy:false}"},
        {pos: [10, 0, 1], state: "minecraft:dirt_path"},
        {pos: [10, 0, 2], state: "minecraft:dirt_path"},
        {pos: [10, 0, 3], state: "minecraft:dirt_path"},
        {pos: [10, 0, 4], state: "minecraft:dirt_path"},
        {pos: [10, 0, 5], state: "minecraft:dirt_path"},
        {pos: [11, 0, 1], state: "minecraft:dirt_path"},
        {pos: [11, 0, 2], state: "minecraft:dirt_path"},
        {pos: [11, 0, 3], state: "minecraft:dirt_path"},
        {pos: [11, 0, 4], state: "minecraft:jigsaw{orientation:east_up}", nbt: {components: {}, final_state: "minecraft:dirt_path", id: "minecraft:jigsaw", joint: "rollable", name: "minecraft:end_connector", placement_priority: 0, pool: "minecraft:empty", selection_priority: 0, target: "minecraft:connector"}},
        {pos: [11, 0, 5], state: "minecraft:dirt_path"},
        {pos: [2, 1, 3], state: "minecraft:grass_block{snowy:false}"},
        {pos: [2, 1, 4], state: "minecraft:grass_block{snowy:false}"},
        {pos: [3, 1, 1], state: "minecraft:grass_block{snowy:false}"},
        {pos: [3, 1, 2], state: "minecraft:grass_block{snowy:false}"},
        {pos: [3, 1, 3], state: "minecraft:grass_block{snowy:false}"},
        {pos: [3, 1, 4], state: "minecraft:grass_block{snowy:false}"},
        {pos: [4, 1, 1], state: "minecraft:acacia_leaves{distance:1,persistent:true,waterlogged:false}"},
        {pos: [4, 1, 2], state: "minecraft:acacia_log{axis:y}"},
        {pos: [4, 1, 3], state: "minecraft:grass_block{snowy:false}"},
        {pos: [4, 1, 4], state: "minecraft:grass_block{snowy:false}"},
        {pos: [4, 1, 5], state: "minecraft:grass_block{snowy:false}"},
        {pos: [5, 1, 1], state: "minecraft:acacia_leaves{distance:2,persistent:true,waterlogged:false}"},
        {pos: [5, 1, 2], state: "minecraft:acacia_leaves{distance:1,persistent:true,waterlogged:false}"},
        {pos: [5, 1, 3], state: "minecraft:grass_block{snowy:false}"},
        {pos: [5, 1, 4], state: "minecraft:grass_block{snowy:false}"},
        {pos: [5, 1, 5], state: "minecraft:stone"},
        {pos: [6, 1, 3], state: "minecraft:barrel{facing:east,open:false}", nbt: {LootTable: "minecraft:barrels/abandoned_camp_barrel", components: {}, id: "minecraft:barrel"}},
        {pos: [6, 1, 4], state: "minecraft:grass_block{snowy:false}"},
        {pos: [6, 1, 5], state: "minecraft:stone"},
        {pos: [6, 1, 6], state: "minecraft:stone"},
        {pos: [6, 1, 7], state: "minecraft:stone"},
        {pos: [6, 1, 8], state: "minecraft:stone"},
        {pos: [7, 1, 6], state: "minecraft:stone"},
        {pos: [7, 1, 7], state: "minecraft:stone"},
        {pos: [7, 1, 8], state: "minecraft:stone"},
        {pos: [7, 1, 9], state: "minecraft:stone"},
        {pos: [8, 1, 7], state: "minecraft:stone"},
        {pos: [8, 1, 8], state: "minecraft:stone"},
        {pos: [9, 1, 1], state: "minecraft:acacia_fence{east:false,north:false,south:false,waterlogged:false,west:false}"},
        {pos: [9, 1, 3], state: "minecraft:campfire{facing:west,lit:false,signal_fire:false,waterlogged:false}", nbt: {CookingTimes: [I; 0, 0, 0, 0], CookingTotalTimes: [I; 0, 0, 0, 0], Items: [], components: {}, id: "minecraft:campfire"}},
        {pos: [3, 2, 2], state: "minecraft:acacia_leaves{distance:2,persistent:true,waterlogged:false}"},
        {pos: [4, 2, 1], state: "minecraft:acacia_leaves{distance:2,persistent:true,waterlogged:false}"},
        {pos: [4, 2, 2], state: "minecraft:acacia_leaves{distance:1,persistent:true,waterlogged:false}"},
        {pos: [4, 2, 3], state: "minecraft:acacia_leaves{distance:2,persistent:true,waterlogged:false}"},
        {pos: [4, 2, 4], state: "minecraft:tall_grass{half:lower}"},
        {pos: [5, 2, 2], state: "minecraft:acacia_leaves{distance:2,persistent:true,waterlogged:false}"},
        {pos: [6, 2, 6], state: "minecraft:stone"},
        {pos: [6, 2, 7], state: "minecraft:stone"},
        {pos: [7, 2, 6], state: "minecraft:stone"},
        {pos: [4, 3, 2], state: "minecraft:acacia_leaves{distance:2,persistent:true,waterlogged:false}"},
        {pos: [4, 3, 4], state: "minecraft:tall_grass{half:upper}"},
        {pos: [6, 3, 6], state: "minecraft:stone"}
    ],
    entities: [
        {blockPos: [8, 0, 4], pos: [8.5d, 0.9375d, 4.5d], nbt: {Air: 300s, Fire: 0s, Invulnerable: 0b, Motion: [0.0d, 0.0d, 0.0d], OnGround: 0b, PortalCooldown: 0, Pos: [-87.5d, -60.0625d, 511.5d], Rotation: [90.0f, 0.0f], UUID: [I; -277684708, -646296411, -1588832068, -1477169776], block_pos: [I; -88, -61, 511], color: "light_gray", fall_distance: 0.0d, id: "minecraft:cushion"}},
        {blockPos: [9, 0, 2], pos: [9.5d, 0.9375d, 2.5d], nbt: {Air: 300s, Fire: 0s, Invulnerable: 0b, Motion: [0.0d, 0.0d, 0.0d], OnGround: 0b, PortalCooldown: 0, Pos: [-86.5d, -60.0625d, 509.5d], Rotation: [180.0f, 0.0f], UUID: [I; 2114459449, 1804421651, -1097508996, 1250781934], block_pos: [I; -87, -61, 509], color: "brown", fall_distance: 0.0d, id: "minecraft:cushion"}}
    ],
    palette: [
        "minecraft:dirt",
        "minecraft:grass_block{snowy:false}",
        "minecraft:acacia_leaves{distance:1,persistent:true,waterlogged:false}",
        "minecraft:acacia_log{axis:y}",
        "minecraft:acacia_leaves{distance:2,persistent:true,waterlogged:false}",
        "minecraft:stone",
        "minecraft:dirt_path",
        "minecraft:acacia_fence{east:false,north:false,south:false,waterlogged:false,west:false}",
        "minecraft:tall_grass{half:lower}",
        "minecraft:tall_grass{half:upper}",
        "minecraft:jigsaw{orientation:up_west}",
        "minecraft:oxidized_copper_chest{facing:east,type:single,waterlogged:false}",
        "minecraft:jigsaw{orientation:east_up}",
        "minecraft:barrel{facing:east,open:false}",
        "minecraft:campfire{facing:west,lit:false,signal_fire:false,waterlogged:false}"
    ]
}
