{
    size: [11, 9, 11],
    data: [
        {pos: [0, 0, 0], state: "minecraft:grass_block{snowy:false}"},
        {pos: [0, 0, 1], state: "minecraft:dirt_path"},
        {pos: [0, 0, 2], state: "minecraft:grass_block{snowy:false}"},
        {pos: [0, 0, 3], state: "minecraft:grass_block{snowy:false}"},
        {pos: [0, 0, 4], state: "minecraft:dirt_path"},
        {pos: [0, 0, 5], state: "minecraft:dirt_path"},
        {pos: [0, 0, 6], state: "minecraft:grass_block{snowy:false}"},
        {pos: [0, 0, 7], state: "minecraft:cobblestone"},
        {pos: [0, 0, 8], state: "minecraft:grass_block{snowy:false}"},
        {pos: [0, 0, 9], state: "minecraft:grass_block{snowy:false}"},
        {pos: [0, 0, 10], state: "minecraft:grass_block{snowy:false}"},
        {pos: [1, 0, 0], state: "minecraft:grass_block{snowy:false}"},
        {pos: [1, 0, 1], state: "minecraft:grass_block{snowy:false}"},
        {pos: [1, 0, 2], state: "minecraft:dirt_path"},
        {pos: [1, 0, 3], state: "minecraft:dirt_path"},
        {pos: [1, 0, 4], state: "minecraft:grass_block{snowy:false}"},
        {pos: [1, 0, 5], state: "minecraft:dirt_path"},
        {pos: [1, 0, 6], state: "minecraft:cobblestone"},
        {pos: [1, 0, 7], state: "minecraft:grass_block{snowy:false}"},
        {pos: [1, 0, 8], state: "minecraft:dirt_path"},
        {pos: [1, 0, 9], state: "minecraft:cobblestone"},
        {pos: [1, 0, 10], state: "minecraft:grass_block{snowy:false}"},
        {pos: [2, 0, 0], state: "minecraft:grass_block{snowy:false}"},
        {pos: [2, 0, 1], state: "minecraft:dirt_path"},
        {pos: [2, 0, 2], state: "minecraft:cobblestone"},
        {pos: [2, 0, 3], state: "minecraft:grass_block{snowy:false}"},
        {pos: [2, 0, 4], state: "minecraft:jigsaw{orientation:up_north}", nbt: {final_state: "minecraft:cobblestone", id: "minecraft:jigsaw", joint: "rollable", name: "minecraft:bottom", pool: "minecraft:village/common/cats", target: "minecraft:bottom"}},
        {pos: [2, 0, 5], state: "minecraft:grass_block{snowy:false}"},
        {pos: [2, 0, 6], state: "minecraft:dirt_path"},
        {pos: [2, 0, 7], state: "minecraft:grass_block{snowy:false}"},
        {pos: [2, 0, 8], state: "minecraft:grass_block{snowy:false}"},
        {pos: [2, 0, 9], state: "minecraft:dirt_path"},
        {pos: [2, 0, 10], state: "minecraft:grass_block{snowy:false}"},
        {pos: [3, 0, 0], state: "minecraft:grass_block{snowy:false}"},
        {pos: [3, 0, 1], state: "minecraft:cobblestone"},
        {pos: [3, 0, 2], state: "minecraft:grass_block{snowy:false}"},
        {pos: [3, 0, 3], state: "minecraft:jigsaw{orientation:up_north}", nbt: {final_state: "minecraft:cobblestone", id: "minecraft:jigsaw", joint: "rollable", name: "minecraft:bottom", pool: "minecraft:village/common/cats", target: "minecraft:bottom"}},
        {pos: [3, 0, 4], state: "minecraft:dirt_path"},
        {pos: [3, 0, 5], state: "minecraft:cobblestone"},
        {pos: [3, 0, 6], state: "minecraft:dirt_path"},
        {pos: [3, 0, 7], state: "minecraft:dirt_path"},
        {pos: [3, 0, 8], state: "minecraft:cobblestone"},
        {pos: [3, 0, 9], state: "minecraft:grass_block{snowy:false}"},
        {pos: [3, 0, 10], state: "minecraft:dirt_path"},
        {pos: [4, 0, 0], state: "minecraft:dirt_path"},
        {pos: [4, 0, 1], state: "minecraft:grass_block{snowy:false}"},
        {pos: [4, 0, 2], state: "minecraft:cobblestone"},
        {pos: [4, 0, 3], state: "minecraft:cobblestone"},
        {pos: [4, 0, 4], state: "minecraft:grass_block{snowy:false}"},
        {pos: [4, 0, 5], state: "minecraft:grass_block{snowy:false}"},
        {pos: [4, 0, 6], state: "minecraft:grass_block{snowy:false}"},
        {pos: [4, 0, 7], state: "minecraft:grass_block{snowy:false}"},
        {pos: [4, 0, 8], state: "minecraft:grass_block{snowy:false}"},
        {pos: [4, 0, 9], state: "minecraft:cobblestone"},
        {pos: [4, 0, 10], state: "minecraft:grass_block{snowy:false}"},
        {pos: [5, 0, 0], state: "minecraft:dirt_path"},
        {pos: [5, 0, 1], state: "minecraft:cobblestone"},
        {pos: [5, 0, 2], state: "minecraft:cobblestone"},
        {pos: [5, 0, 3], state: "minecraft:dirt_path"},
        {pos: [5, 0, 4], state: "minecraft:grass_block{snowy:false}"},
        {pos: [5, 0, 5], state: "minecraft:dirt_path"},
        {pos: [5, 0, 6], state: "minecraft:grass_block{snowy:false}"},
        {pos: [5, 0, 7], state: "minecraft:dirt_path"},
        {pos: [5, 0, 8], state: "minecraft:dirt_path"},
        {pos: [5, 0, 9], state: "minecraft:dirt_path"},
        {pos: [5, 0, 10], state: "minecraft:cobblestone"},
        {pos: [6, 0, 0], state: "minecraft:grass_block{snowy:false}"},
        {pos: [6, 0, 1], state: "minecraft:grass_block{snowy:false}"},
        {pos: [6, 0, 2], state: "minecraft:grass_block{snowy:false}"},
        {pos: [6, 0, 3], state: "minecraft:cobblestone"},
        {pos: [6, 0, 4], state: "minecraft:grass_block{snowy:false}"},
        {pos: [6, 0, 5], state: "minecraft:grass_block{snowy:false}"},
        {pos: [6, 0, 6], state: "minecraft:grass_block{snowy:false}"},
        {pos: [6, 0, 7], state: "minecraft:dirt_path"},
        {pos: [6, 0, 8], state: "minecraft:cobblestone"},
        {pos: [6, 0, 9], state: "minecraft:grass_block{snowy:false}"},
        {pos: [6, 0, 10], state: "minecraft:dirt_path"},
        {pos: [7, 0, 0], state: "minecraft:dirt_path"},
        {pos: [7, 0, 1], state: "minecraft:grass_block{snowy:false}"},
        {pos: [7, 0, 2], state: "minecraft:dirt_path"},
        {pos: [7, 0, 3], state: "minecraft:cobblestone"},
        {pos: [7, 0, 4], state: "minecraft:grass_block{snowy:false}"},
        {pos: [7, 0, 5], state: "minecraft:dirt_path"},
        {pos: [7, 0, 6], state: "minecraft:cobblestone"},
        {pos: [7, 0, 7], state: "minecraft:grass_block{snowy:false}"},
        {pos: [7, 0, 8], state: "minecraft:dirt_path"},
        {pos: [7, 0, 9], state: "minecraft:cobblestone"},
        {pos: [7, 0, 10], state: "minecraft:grass_block{snowy:false}"},
        {pos: [8, 0, 0], state: "minecraft:dirt_path"},
        {pos: [8, 0, 1], state: "minecraft:cobblestone"},
        {pos: [8, 0, 2], state: "minecraft:dirt_path"},
        {pos: [8, 0, 3], state: "minecraft:grass_block{snowy:false}"},
        {pos: [8, 0, 4], state: "minecraft:cobblestone"},
        {pos: [8, 0, 5], state: "minecraft:cobblestone"},
        {pos: [8, 0, 6], state: "minecraft:dirt_path"},
        {pos: [8, 0, 7], state: "minecraft:cobblestone"},
        {pos: [8, 0, 8], state: "minecraft:dirt_path"},
        {pos: [8, 0, 9], state: "minecraft:dirt_path"},
        {pos: [8, 0, 10], state: "minecraft:cobblestone"},
        {pos: [9, 0, 0], state: "minecraft:dirt_path"},
        {pos: [9, 0, 1], state: "minecraft:dirt_path"},
        {pos: [9, 0, 2], state: "minecraft:grass_block{snowy:false}"},
        {pos: [9, 0, 3], state: "minecraft:dirt_path"},
        {pos: [9, 0, 4], state: "minecraft:dirt_path"},
        {pos: [9, 0, 5], state: "minecraft:cobblestone"},
        {pos: [9, 0, 6], state: "minecraft:grass_block{snowy:false}"},
        {pos: [9, 0, 7], state: "minecraft:dirt_path"},
        {pos: [9, 0, 8], state: "minecraft:cobblestone"},
        {pos: [9, 0, 9], state: "minecraft:grass_block{snowy:false}"},
        {pos: [9, 0, 10], state: "minecraft:grass_block{snowy:false}"},
        {pos: [10, 0, 0], state: "minecraft:grass_block{snowy:false}"},
        {pos: [10, 0, 1], state: "minecraft:cobblestone"},
        {pos: [10, 0, 2], state: "minecraft:dirt_path"},
        {pos: [10, 0, 3], state: "minecraft:grass_block{snowy:false}"},
        {pos: [10, 0, 4], state: "minecraft:cobblestone"},
        {pos: [10, 0, 5], state: "minecraft:dirt_path"},
        {pos: [10, 0, 6], state: "minecraft:grass_block{snowy:false}"},
        {pos: [10, 0, 7], state: "minecraft:grass_block{snowy:false}"},
        {pos: [10, 0, 8], state: "minecraft:dirt_path"},
        {pos: [10, 0, 9], state: "minecraft:dirt_path"},
        {pos: [10, 0, 10], state: "minecraft:grass_block{snowy:false}"},
        {pos: [0, 1, 0], state: "minecraft:grass"},
        {pos: [0, 1, 3], state: "minecraft:grass"},
        {pos: [0, 1, 5], state: "minecraft:jigsaw{orientation:west_up}", nbt: {final_state: "minecraft:structure_void", id: "minecraft:jigsaw", joint: "aligned", name: "minecraft:street", pool: "minecraft:village/plains/zombie/streets", target: "minecraft:street"}},
        {pos: [2, 1, 0], state: "minecraft:grass"},
        {pos: [2, 1, 5], state: "minecraft:grass"},
        {pos: [2, 1, 8], state: "minecraft:grass"},
        {pos: [3, 1, 0], state: "minecraft:grass"},
        {pos: [4, 1, 1], state: "minecraft:oak_fence{east:false,north:false,south:false,waterlogged:false,west:false}"},
        {pos: [4, 1, 4], state: "minecraft:cobblestone_stairs{facing:south,half:bottom,shape:outer_left,waterlogged:false}"},
        {pos: [4, 1, 5], state: "minecraft:cobblestone_stairs{facing:east,half:bottom,shape:straight,waterlogged:false}"},
        {pos: [4, 1, 6], state: "minecraft:cobblestone_stairs{facing:north,half:bottom,shape:outer_right,waterlogged:false}"},
        {pos: [4, 1, 7], state: "minecraft:grass"},
        {pos: [4, 1, 8], state: "minecraft:grass"},
        {pos: [4, 1, 9], state: "minecraft:oak_fence{east:false,north:false,south:false,waterlogged:false,west:false}"},
        {pos: [5, 1, 4], state: "minecraft:cobblestone_stairs{facing:south,half:bottom,shape:straight,waterlogged:false}"},
        {pos: [5, 1, 5], state: "minecraft:oak_log{axis:y}"},
        {pos: [5, 1, 6], state: "minecraft:cobblestone_stairs{facing:north,half:bottom,shape:straight,waterlogged:false}"},
        {pos: [5, 1, 10], state: "minecraft:jigsaw{orientation:south_up}", nbt: {final_state: "minecraft:structure_void", id: "minecraft:jigsaw", joint: "aligned", name: "minecraft:street", pool: "minecraft:village/plains/zombie/streets", target: "minecraft:street"}},
        {pos: [6, 1, 1], state: "minecraft:oak_fence{east:false,north:false,south:false,waterlogged:false,west:false}"},
        {pos: [6, 1, 2], state: "minecraft:grass"},
        {pos: [6, 1, 4], state: "minecraft:cobblestone_stairs{facing:south,half:bottom,shape:outer_right,waterlogged:false}"},
        {pos: [6, 1, 5], state: "minecraft:cobblestone_stairs{facing:west,half:bottom,shape:straight,waterlogged:false}"},
        {pos: [6, 1, 6], state: "minecraft:cobblestone_stairs{facing:west,half:bottom,shape:outer_right,waterlogged:false}"},
        {pos: [6, 1, 9], state: "minecraft:oak_fence{east:false,north:false,south:false,waterlogged:false,west:false}"},
        {pos: [7, 1, 1], state: "minecraft:dandelion"},
        {pos: [7, 1, 4], state: "minecraft:grass"},
        {pos: [7, 1, 10], state: "minecraft:grass"},
        {pos: [9, 1, 2], state: "minecraft:grass"},
        {pos: [9, 1, 6], state: "minecraft:grass"},
        {pos: [10, 1, 3], state: "minecraft:grass"},
        {pos: [10, 1, 5], state: "minecraft:jigsaw{orientation:east_up}", nbt: {final_state: "minecraft:structure_void", id: "minecraft:jigsaw", joint: "aligned", name: "minecraft:street", pool: "minecraft:village/plains/zombie/streets", target: "minecraft:street"}},
        {pos: [4, 2, 1], state: "minecraft:oak_fence{east:false,north:false,south:false,waterlogged:false,west:false}"},
        {pos: [4, 2, 9], state: "minecraft:oak_fence{east:false,north:false,south:false,waterlogged:false,west:false}"},
        {pos: [5, 2, 5], state: "minecraft:oak_log{axis:y}"},
        {pos: [6, 2, 1], state: "minecraft:oak_fence{east:false,north:false,south:false,waterlogged:false,west:false}"},
        {pos: [6, 2, 9], state: "minecraft:oak_fence{east:false,north:false,south:false,waterlogged:false,west:false}"},
        {pos: [4, 3, 1], state: "minecraft:oak_fence{east:false,north:false,south:false,waterlogged:false,west:false}"},
        {pos: [4, 3, 5], state: "minecraft:wall_torch{facing:west}"},
        {pos: [4, 3, 9], state: "minecraft:oak_fence{east:false,north:false,south:false,waterlogged:false,west:false}"},
        {pos: [5, 3, 1], state: "minecraft:bell{attachment:ceiling,facing:south,powered:false}", nbt: {id: "minecraft:bell"}},
        {pos: [5, 3, 4], state: "minecraft:wall_torch{facing:north}"},
        {pos: [5, 3, 5], state: "minecraft:oak_log{axis:y}"},
        {pos: [5, 3, 6], state: "minecraft:wall_torch{facing:south}"},
        {pos: [5, 3, 9], state: "minecraft:bell{attachment:ceiling,facing:north,powered:false}", nbt: {id: "minecraft:bell"}},
        {pos: [6, 3, 1], state: "minecraft:oak_fence{east:false,north:false,south:false,waterlogged:false,west:false}"},
        {pos: [6, 3, 5], state: "minecraft:wall_torch{facing:east}"},
        {pos: [6, 3, 9], state: "minecraft:oak_fence{east:false,north:false,south:false,waterlogged:false,west:false}"},
        {pos: [4, 4, 1], state: "minecraft:oak_fence{east:true,north:false,south:false,waterlogged:false,west:false}"},
        {pos: [4, 4, 9], state: "minecraft:oak_fence{east:true,north:false,south:false,waterlogged:false,west:false}"},
        {pos: [5, 4, 1], state: "minecraft:cobblestone"},
        {pos: [5, 4, 5], state: "minecraft:oak_log{axis:y}"},
        {pos: [5, 4, 9], state: "minecraft:cobblestone"},
        {pos: [6, 4, 1], state: "minecraft:oak_fence{east:false,north:false,south:false,waterlogged:false,west:true}"},
        {pos: [6, 4, 9], state: "minecraft:oak_fence{east:false,north:false,south:false,waterlogged:false,west:true}"},
        {pos: [3, 5, 4], state: "minecraft:oak_leaves{distance:3,persistent:false,waterlogged:false}"},
        {pos: [3, 5, 5], state: "minecraft:oak_leaves{distance:2,persistent:false,waterlogged:false}"},
        {pos: [3, 5, 6], state: "minecraft:oak_leaves{distance:3,persistent:false,waterlogged:false}"},
        {pos: [4, 5, 3], state: "minecraft:oak_leaves{distance:3,persistent:false,waterlogged:false}"},
        {pos: [4, 5, 4], state: "minecraft:oak_leaves{distance:2,persistent:false,waterlogged:false}"},
        {pos: [4, 5, 5], state: "minecraft:oak_leaves{distance:1,persistent:false,waterlogged:false}"},
        {pos: [4, 5, 6], state: "minecraft:oak_leaves{distance:2,persistent:false,waterlogged:false}"},
        {pos: [5, 5, 3], state: "minecraft:oak_leaves{distance:2,persistent:false,waterlogged:false}"},
        {pos: [5, 5, 4], state: "minecraft:oak_leaves{distance:1,persistent:false,waterlogged:false}"},
        {pos: [5, 5, 5], state: "minecraft:oak_log{axis:y}"},
        {pos: [5, 5, 6], state: "minecraft:oak_leaves{distance:1,persistent:false,waterlogged:false}"},
        {pos: [5, 5, 7], state: "minecraft:oak_leaves{distance:2,persistent:false,waterlogged:false}"},
        {pos: [6, 5, 4], state: "minecraft:oak_leaves{distance:2,persistent:false,waterlogged:false}"},
        {pos: [6, 5, 5], state: "minecraft:oak_leaves{distance:1,persistent:false,waterlogged:false}"},
        {pos: [6, 5, 6], state: "minecraft:oak_leaves{distance:2,persistent:false,waterlogged:false}"},
        {pos: [7, 5, 4], state: "minecraft:oak_leaves{distance:3,persistent:false,waterlogged:false}"},
        {pos: [7, 5, 5], state: "minecraft:oak_leaves{distance:2,persistent:false,waterlogged:false}"},
        {pos: [7, 5, 6], state: "minecraft:oak_leaves{distance:3,persistent:false,waterlogged:false}"},
        {pos: [3, 6, 4], state: "minecraft:oak_leaves{distance:3,persistent:false,waterlogged:false}"},
        {pos: [3, 6, 5], state: "minecraft:oak_leaves{distance:2,persistent:false,waterlogged:false}"},
        {pos: [3, 6, 6], state: "minecraft:oak_leaves{distance:3,persistent:false,waterlogged:false}"},
        {pos: [4, 6, 3], state: "minecraft:oak_leaves{distance:3,persistent:false,waterlogged:false}"},
        {pos: [4, 6, 4], state: "minecraft:oak_leaves{distance:2,persistent:false,waterlogged:false}"},
        {pos: [4, 6, 5], state: "minecraft:oak_leaves{distance:1,persistent:false,waterlogged:false}"},
        {pos: [4, 6, 6], state: "minecraft:oak_leaves{distance:2,persistent:false,waterlogged:false}"},
        {pos: [4, 6, 7], state: "minecraft:oak_leaves{distance:3,persistent:false,waterlogged:false}"},
        {pos: [5, 6, 3], state: "minecraft:oak_leaves{distance:2,persistent:false,waterlogged:false}"},
        {pos: [5, 6, 4], state: "minecraft:oak_leaves{distance:1,persistent:false,waterlogged:false}"},
        {pos: [5, 6, 5], state: "minecraft:oak_log{axis:y}"},
        {pos: [5, 6, 6], state: "minecraft:oak_leaves{distance:1,persistent:false,waterlogged:false}"},
        {pos: [6, 6, 3], state: "minecraft:oak_leaves{distance:3,persistent:false,waterlogged:false}"},
        {pos: [6, 6, 4], state: "minecraft:oak_leaves{distance:2,persistent:false,waterlogged:false}"},
        {pos: [6, 6, 5], state: "minecraft:oak_leaves{distance:1,persistent:false,waterlogged:false}"},
        {pos: [6, 6, 6], state: "minecraft:oak_leaves{distance:2,persistent:false,waterlogged:false}"},
        {pos: [6, 6, 7], state: "minecraft:oak_leaves{distance:3,persistent:false,waterlogged:false}"},
        {pos: [7, 6, 4], state: "minecraft:oak_leaves{distance:3,persistent:false,waterlogged:false}"},
        {pos: [7, 6, 5], state: "minecraft:oak_leaves{distance:2,persistent:false,waterlogged:false}"},
        {pos: [7, 6, 6], state: "minecraft:oak_leaves{distance:3,persistent:false,waterlogged:false}"},
        {pos: [4, 7, 4], state: "minecraft:oak_leaves{distance:2,persistent:false,waterlogged:false}"},
        {pos: [4, 7, 5], state: "minecraft:oak_leaves{distance:1,persistent:false,waterlogged:false}"},
        {pos: [4, 7, 6], state: "minecraft:oak_leaves{distance:2,persistent:false,waterlogged:false}"},
        {pos: [5, 7, 4], state: "minecraft:oak_leaves{distance:1,persistent:false,waterlogged:false}"},
        {pos: [5, 7, 5], state: "minecraft:oak_log{axis:y}"},
        {pos: [5, 7, 6], state: "minecraft:oak_leaves{distance:1,persistent:false,waterlogged:false}"},
        {pos: [6, 7, 4], state: "minecraft:oak_leaves{distance:2,persistent:false,waterlogged:false}"},
        {pos: [6, 7, 5], state: "minecraft:oak_leaves{distance:1,persistent:false,waterlogged:false}"},
        {pos: [6, 7, 6], state: "minecraft:oak_leaves{distance:2,persistent:false,waterlogged:false}"},
        {pos: [4, 8, 5], state: "minecraft:oak_leaves{distance:2,persistent:false,waterlogged:false}"},
        {pos: [5, 8, 4], state: "minecraft:oak_leaves{distance:2,persistent:false,waterlogged:false}"},
        {pos: [5, 8, 5], state: "minecraft:oak_leaves{distance:1,persistent:false,waterlogged:false}"},
        {pos: [5, 8, 6], state: "minecraft:oak_leaves{distance:2,persistent:false,waterlogged:false}"},
        {pos: [6, 8, 5], state: "minecraft:oak_leaves{distance:2,persistent:false,waterlogged:false}"}
    ],
    entities: [],
    palette: [
        "minecraft:grass_block{snowy:false}",
        "minecraft:cobblestone",
        "minecraft:oak_log{axis:y}",
        "minecraft:oak_leaves{distance:3,persistent:false,waterlogged:false}",
        "minecraft:oak_leaves{distance:2,persistent:false,waterlogged:false}",
        "minecraft:oak_leaves{distance:1,persistent:false,waterlogged:false}",
        "minecraft:dirt_path",
        "minecraft:grass",
        "minecraft:oak_fence{east:false,north:false,south:false,waterlogged:false,west:false}",
        "minecraft:cobblestone_stairs{facing:south,half:bottom,shape:outer_left,waterlogged:false}",
        "minecraft:cobblestone_stairs{facing:east,half:bottom,shape:straight,waterlogged:false}",
        "minecraft:cobblestone_stairs{facing:north,half:bottom,shape:outer_right,waterlogged:false}",
        "minecraft:cobblestone_stairs{facing:south,half:bottom,shape:straight,waterlogged:false}",
        "minecraft:cobblestone_stairs{facing:north,half:bottom,shape:straight,waterlogged:false}",
        "minecraft:cobblestone_stairs{facing:south,half:bottom,shape:outer_right,waterlogged:false}",
        "minecraft:cobblestone_stairs{facing:west,half:bottom,shape:straight,waterlogged:false}",
        "minecraft:cobblestone_stairs{facing:west,half:bottom,shape:outer_right,waterlogged:false}",
        "minecraft:dandelion",
        "minecraft:wall_torch{facing:west}",
        "minecraft:wall_torch{facing:north}",
        "minecraft:wall_torch{facing:south}",
        "minecraft:wall_torch{facing:east}",
        "minecraft:oak_fence{east:true,north:false,south:false,waterlogged:false,west:false}",
        "minecraft:oak_fence{east:false,north:false,south:false,waterlogged:false,west:true}",
        "minecraft:jigsaw{orientation:up_north}",
        "minecraft:jigsaw{orientation:west_up}",
        "minecraft:jigsaw{orientation:south_up}",
        "minecraft:jigsaw{orientation:east_up}",
        "minecraft:bell{attachment:ceiling,facing:south,powered:false}",
        "minecraft:bell{attachment:ceiling,facing:north,powered:false}"
    ]
}
