{
    size: [18, 15, 21],
    data: [
        {pos: [0, 0, 7], state: "minecraft:deepslate_tiles"},
        {pos: [0, 0, 8], state: "minecraft:gray_wool"},
        {pos: [0, 0, 9], state: "minecraft:gray_wool"},
        {pos: [0, 0, 10], state: "minecraft:jigsaw{orientation:west_up}", nbt: {final_state: "minecraft:deepslate_tiles", id: "minecraft:jigsaw", joint: "rollable", name: "minecraft:connect_wall", pool: "minecraft:ancient_city/walls", target: "minecraft:connect_wall"}},
        {pos: [0, 0, 11], state: "minecraft:gray_wool"},
        {pos: [0, 0, 12], state: "minecraft:gray_wool"},
        {pos: [0, 0, 13], state: "minecraft:deepslate_tiles"},
        {pos: [1, 0, 7], state: "minecraft:deepslate_tiles"},
        {pos: [1, 0, 8], state: "minecraft:gray_wool"},
        {pos: [1, 0, 9], state: "minecraft:gray_wool"},
        {pos: [1, 0, 10], state: "minecraft:deepslate_tiles"},
        {pos: [1, 0, 11], state: "minecraft:gray_wool"},
        {pos: [1, 0, 12], state: "minecraft:gray_wool"},
        {pos: [1, 0, 13], state: "minecraft:deepslate_tiles"},
        {pos: [2, 0, 7], state: "minecraft:deepslate_tiles"},
        {pos: [2, 0, 8], state: "minecraft:gray_wool"},
        {pos: [2, 0, 9], state: "minecraft:gray_wool"},
        {pos: [2, 0, 10], state: "minecraft:chiseled_deepslate"},
        {pos: [2, 0, 11], state: "minecraft:gray_wool"},
        {pos: [2, 0, 12], state: "minecraft:gray_wool"},
        {pos: [2, 0, 13], state: "minecraft:deepslate_tiles"},
        {pos: [3, 0, 7], state: "minecraft:deepslate_tiles"},
        {pos: [3, 0, 8], state: "minecraft:gray_wool"},
        {pos: [3, 0, 9], state: "minecraft:gray_wool"},
        {pos: [3, 0, 10], state: "minecraft:deepslate_tiles"},
        {pos: [3, 0, 11], state: "minecraft:gray_wool"},
        {pos: [3, 0, 12], state: "minecraft:gray_wool"},
        {pos: [3, 0, 13], state: "minecraft:deepslate_tiles"},
        {pos: [4, 0, 7], state: "minecraft:deepslate_tiles"},
        {pos: [4, 0, 8], state: "minecraft:gray_wool"},
        {pos: [4, 0, 9], state: "minecraft:gray_wool"},
        {pos: [4, 0, 10], state: "minecraft:deepslate_tiles"},
        {pos: [4, 0, 11], state: "minecraft:gray_wool"},
        {pos: [4, 0, 12], state: "minecraft:gray_wool"},
        {pos: [4, 0, 13], state: "minecraft:deepslate_tiles"},
        {pos: [5, 0, 7], state: "minecraft:deepslate_tiles"},
        {pos: [5, 0, 8], state: "minecraft:gray_wool"},
        {pos: [5, 0, 9], state: "minecraft:gray_wool"},
        {pos: [5, 0, 10], state: "minecraft:deepslate_tiles"},
        {pos: [5, 0, 11], state: "minecraft:gray_wool"},
        {pos: [5, 0, 12], state: "minecraft:gray_wool"},
        {pos: [5, 0, 13], state: "minecraft:deepslate_tiles"},
        {pos: [6, 0, 7], state: "minecraft:deepslate_tiles"},
        {pos: [6, 0, 8], state: "minecraft:gray_wool"},
        {pos: [6, 0, 9], state: "minecraft:gray_wool"},
        {pos: [6, 0, 10], state: "minecraft:chiseled_deepslate"},
        {pos: [6, 0, 11], state: "minecraft:gray_wool"},
        {pos: [6, 0, 12], state: "minecraft:gray_wool"},
        {pos: [6, 0, 13], state: "minecraft:deepslate_tiles"},
        {pos: [7, 0, 7], state: "minecraft:deepslate_tiles"},
        {pos: [7, 0, 8], state: "minecraft:gray_wool"},
        {pos: [7, 0, 9], state: "minecraft:gray_wool"},
        {pos: [7, 0, 10], state: "minecraft:deepslate_tiles"},
        {pos: [7, 0, 11], state: "minecraft:gray_wool"},
        {pos: [7, 0, 12], state: "minecraft:gray_wool"},
        {pos: [7, 0, 13], state: "minecraft:deepslate_tiles"},
        {pos: [8, 0, 7], state: "minecraft:deepslate_tiles"},
        {pos: [8, 0, 8], state: "minecraft:gray_wool"},
        {pos: [8, 0, 9], state: "minecraft:gray_wool"},
        {pos: [8, 0, 10], state: "minecraft:gray_wool"},
        {pos: [8, 0, 11], state: "minecraft:gray_wool"},
        {pos: [8, 0, 12], state: "minecraft:gray_wool"},
        {pos: [8, 0, 13], state: "minecraft:deepslate_tiles"},
        {pos: [9, 0, 0], state: "minecraft:jigsaw{orientation:north_up}", nbt: {final_state: "minecraft:structure_void", id: "minecraft:jigsaw", joint: "rollable", name: "minecraft:empty", pool: "minecraft:ancient_city/structures", target: "minecraft:connect_structure"}},
        {pos: [9, 0, 6], state: "minecraft:deepslate_tile_stairs{facing:south,half:bottom,shape:straight,waterlogged:false}"},
        {pos: [9, 0, 7], state: "minecraft:deepslate_tiles"},
        {pos: [9, 0, 8], state: "minecraft:gray_wool"},
        {pos: [9, 0, 9], state: "minecraft:gray_wool"},
        {pos: [9, 0, 10], state: "minecraft:gray_wool"},
        {pos: [9, 0, 11], state: "minecraft:gray_wool"},
        {pos: [9, 0, 12], state: "minecraft:gray_wool"},
        {pos: [9, 0, 13], state: "minecraft:deepslate_tiles"},
        {pos: [9, 0, 14], state: "minecraft:deepslate_tiles"},
        {pos: [9, 0, 15], state: "minecraft:deepslate_tile_stairs{facing:north,half:bottom,shape:straight,waterlogged:false}"},
        {pos: [9, 0, 16], state: "minecraft:deepslate_tile_slab{type:bottom,waterlogged:false}"},
        {pos: [9, 0, 17], state: "minecraft:deepslate_tile_slab{type:bottom,waterlogged:false}"},
        {pos: [9, 0, 18], state: "minecraft:deepslate_tile_slab{type:bottom,waterlogged:false}"},
        {pos: [9, 0, 20], state: "minecraft:jigsaw{orientation:south_up}", nbt: {final_state: "minecraft:deepslate_tile_slab", id: "minecraft:jigsaw", joint: "rollable", name: "minecraft:empty", pool: "minecraft:ancient_city/structures", target: "minecraft:connect_structure"}},
        {pos: [10, 0, 6], state: "minecraft:deepslate_tile_stairs{facing:south,half:bottom,shape:straight,waterlogged:false}"},
        {pos: [10, 0, 7], state: "minecraft:deepslate_tiles"},
        {pos: [10, 0, 8], state: "minecraft:gray_wool"},
        {pos: [10, 0, 9], state: "minecraft:gray_wool"},
        {pos: [10, 0, 10], state: "minecraft:gray_wool"},
        {pos: [10, 0, 11], state: "minecraft:gray_wool"},
        {pos: [10, 0, 12], state: "minecraft:gray_wool"},
        {pos: [10, 0, 13], state: "minecraft:deepslate_tiles"},
        {pos: [10, 0, 14], state: "minecraft:deepslate_tiles"},
        {pos: [10, 0, 15], state: "minecraft:deepslate_tile_stairs{facing:north,half:bottom,shape:straight,waterlogged:false}"},
        {pos: [10, 0, 16], state: "minecraft:deepslate_tile_slab{type:bottom,waterlogged:false}"},
        {pos: [10, 0, 17], state: "minecraft:deepslate_tile_slab{type:bottom,waterlogged:false}"},
        {pos: [10, 0, 18], state: "minecraft:deepslate_tile_slab{type:bottom,waterlogged:false}"},
        {pos: [11, 0, 6], state: "minecraft:deepslate_tile_stairs{facing:south,half:bottom,shape:straight,waterlogged:false}"},
        {pos: [11, 0, 7], state: "minecraft:deepslate_tiles"},
        {pos: [11, 0, 8], state: "minecraft:gray_wool"},
        {pos: [11, 0, 9], state: "minecraft:gray_wool"},
        {pos: [11, 0, 10], state: "minecraft:gray_wool"},
        {pos: [11, 0, 11], state: "minecraft:gray_wool"},
        {pos: [11, 0, 12], state: "minecraft:gray_wool"},
        {pos: [11, 0, 13], state: "minecraft:deepslate_tiles"},
        {pos: [11, 0, 14], state: "minecraft:deepslate_tiles"},
        {pos: [11, 0, 15], state: "minecraft:deepslate_tile_stairs{facing:north,half:bottom,shape:straight,waterlogged:false}"},
        {pos: [11, 0, 16], state: "minecraft:deepslate_tile_slab{type:bottom,waterlogged:false}"},
        {pos: [11, 0, 17], state: "minecraft:deepslate_tile_slab{type:bottom,waterlogged:false}"},
        {pos: [12, 0, 7], state: "minecraft:deepslate_tiles"},
        {pos: [12, 0, 8], state: "minecraft:gray_wool"},
        {pos: [12, 0, 9], state: "minecraft:gray_wool"},
        {pos: [12, 0, 10], state: "minecraft:gray_wool"},
        {pos: [12, 0, 11], state: "minecraft:gray_wool"},
        {pos: [12, 0, 12], state: "minecraft:gray_wool"},
        {pos: [12, 0, 13], state: "minecraft:deepslate_tiles"},
        {pos: [13, 0, 7], state: "minecraft:deepslate_tiles"},
        {pos: [13, 0, 8], state: "minecraft:gray_wool"},
        {pos: [13, 0, 9], state: "minecraft:gray_wool"},
        {pos: [13, 0, 10], state: "minecraft:deepslate_tiles"},
        {pos: [13, 0, 11], state: "minecraft:gray_wool"},
        {pos: [13, 0, 12], state: "minecraft:gray_wool"},
        {pos: [13, 0, 13], state: "minecraft:deepslate_tiles"},
        {pos: [14, 0, 7], state: "minecraft:deepslate_tiles"},
        {pos: [14, 0, 8], state: "minecraft:gray_wool"},
        {pos: [14, 0, 9], state: "minecraft:gray_wool"},
        {pos: [14, 0, 10], state: "minecraft:deepslate_tiles"},
        {pos: [14, 0, 11], state: "minecraft:gray_wool"},
        {pos: [14, 0, 12], state: "minecraft:gray_wool"},
        {pos: [14, 0, 13], state: "minecraft:deepslate_tiles"},
        {pos: [15, 0, 7], state: "minecraft:deepslate_tiles"},
        {pos: [15, 0, 8], state: "minecraft:gray_wool"},
        {pos: [15, 0, 9], state: "minecraft:gray_wool"},
        {pos: [15, 0, 10], state: "minecraft:deepslate_tiles"},
        {pos: [15, 0, 11], state: "minecraft:gray_wool"},
        {pos: [15, 0, 12], state: "minecraft:gray_wool"},
        {pos: [15, 0, 13], state: "minecraft:deepslate_tiles"},
        {pos: [16, 0, 7], state: "minecraft:deepslate_tiles"},
        {pos: [16, 0, 8], state: "minecraft:gray_wool"},
        {pos: [16, 0, 9], state: "minecraft:gray_wool"},
        {pos: [16, 0, 10], state: "minecraft:deepslate_tiles"},
        {pos: [16, 0, 11], state: "minecraft:gray_wool"},
        {pos: [16, 0, 12], state: "minecraft:gray_wool"},
        {pos: [16, 0, 13], state: "minecraft:deepslate_tiles"},
        {pos: [17, 0, 7], state: "minecraft:deepslate_tiles"},
        {pos: [17, 0, 8], state: "minecraft:gray_wool"},
        {pos: [17, 0, 9], state: "minecraft:gray_wool"},
        {pos: [17, 0, 10], state: "minecraft:jigsaw{orientation:east_up}", nbt: {final_state: "minecraft:deepslate_tiles", id: "minecraft:jigsaw", joint: "rollable", name: "minecraft:connect_wall", pool: "minecraft:ancient_city/walls", target: "minecraft:connect_wall"}},
        {pos: [17, 0, 11], state: "minecraft:gray_wool"},
        {pos: [17, 0, 12], state: "minecraft:gray_wool"},
        {pos: [17, 0, 13], state: "minecraft:deepslate_tiles"},
        {pos: [0, 1, 7], state: "minecraft:deepslate_bricks"},
        {pos: [0, 1, 8], state: "minecraft:gray_wool"},
        {pos: [0, 1, 9], state: "minecraft:gray_wool"},
        {pos: [0, 1, 10], state: "minecraft:deepslate_bricks"},
        {pos: [0, 1, 11], state: "minecraft:gray_wool"},
        {pos: [0, 1, 12], state: "minecraft:gray_wool"},
        {pos: [0, 1, 13], state: "minecraft:deepslate_bricks"},
        {pos: [1, 1, 7], state: "minecraft:deepslate_bricks"},
        {pos: [1, 1, 8], state: "minecraft:gray_wool"},
        {pos: [1, 1, 9], state: "minecraft:gray_wool"},
        {pos: [1, 1, 10], state: "minecraft:deepslate_bricks"},
        {pos: [1, 1, 11], state: "minecraft:gray_wool"},
        {pos: [1, 1, 12], state: "minecraft:gray_wool"},
        {pos: [1, 1, 13], state: "minecraft:deepslate_bricks"},
        {pos: [2, 1, 7], state: "minecraft:deepslate_bricks"},
        {pos: [2, 1, 8], state: "minecraft:gray_wool"},
        {pos: [2, 1, 9], state: "minecraft:gray_wool"},
        {pos: [2, 1, 10], state: "minecraft:deepslate_bricks"},
        {pos: [2, 1, 11], state: "minecraft:gray_wool"},
        {pos: [2, 1, 12], state: "minecraft:gray_wool"},
        {pos: [2, 1, 13], state: "minecraft:deepslate_bricks"},
        {pos: [3, 1, 7], state: "minecraft:deepslate_bricks"},
        {pos: [3, 1, 8], state: "minecraft:gray_wool"},
        {pos: [3, 1, 9], state: "minecraft:gray_wool"},
        {pos: [3, 1, 10], state: "minecraft:deepslate_bricks"},
        {pos: [3, 1, 11], state: "minecraft:gray_wool"},
        {pos: [3, 1, 12], state: "minecraft:gray_wool"},
        {pos: [3, 1, 13], state: "minecraft:deepslate_bricks"},
        {pos: [4, 1, 7], state: "minecraft:deepslate_bricks"},
        {pos: [4, 1, 8], state: "minecraft:gray_wool"},
        {pos: [4, 1, 9], state: "minecraft:gray_wool"},
        {pos: [4, 1, 10], state: "minecraft:deepslate_bricks"},
        {pos: [4, 1, 11], state: "minecraft:gray_wool"},
        {pos: [4, 1, 12], state: "minecraft:gray_wool"},
        {pos: [4, 1, 13], state: "minecraft:deepslate_bricks"},
        {pos: [5, 1, 7], state: "minecraft:deepslate_bricks"},
        {pos: [5, 1, 8], state: "minecraft:gray_wool"},
        {pos: [5, 1, 9], state: "minecraft:gray_wool"},
        {pos: [5, 1, 10], state: "minecraft:deepslate_bricks"},
        {pos: [5, 1, 11], state: "minecraft:gray_wool"},
        {pos: [5, 1, 12], state: "minecraft:gray_wool"},
        {pos: [5, 1, 13], state: "minecraft:deepslate_bricks"},
        {pos: [6, 1, 7], state: "minecraft:deepslate_bricks"},
        {pos: [6, 1, 8], state: "minecraft:gray_wool"},
        {pos: [6, 1, 9], state: "minecraft:gray_wool"},
        {pos: [6, 1, 10], state: "minecraft:deepslate_bricks"},
        {pos: [6, 1, 11], state: "minecraft:gray_wool"},
        {pos: [6, 1, 12], state: "minecraft:gray_wool"},
        {pos: [6, 1, 13], state: "minecraft:deepslate_bricks"},
        {pos: [7, 1, 7], state: "minecraft:deepslate_bricks"},
        {pos: [7, 1, 8], state: "minecraft:gray_wool"},
        {pos: [7, 1, 9], state: "minecraft:gray_wool"},
        {pos: [7, 1, 10], state: "minecraft:deepslate_bricks"},
        {pos: [7, 1, 11], state: "minecraft:gray_wool"},
        {pos: [7, 1, 12], state: "minecraft:gray_wool"},
        {pos: [7, 1, 13], state: "minecraft:deepslate_bricks"},
        {pos: [8, 1, 7], state: "minecraft:deepslate_bricks"},
        {pos: [8, 1, 8], state: "minecraft:gray_wool"},
        {pos: [8, 1, 9], state: "minecraft:gray_wool"},
        {pos: [8, 1, 10], state: "minecraft:gray_wool"},
        {pos: [8, 1, 11], state: "minecraft:gray_wool"},
        {pos: [8, 1, 12], state: "minecraft:gray_wool"},
        {pos: [8, 1, 13], state: "minecraft:deepslate_bricks"},
        {pos: [9, 1, 7], state: "minecraft:deepslate_tile_stairs{facing:south,half:bottom,shape:straight,waterlogged:false}"},
        {pos: [9, 1, 8], state: "minecraft:gray_wool"},
        {pos: [9, 1, 9], state: "minecraft:gray_wool"},
        {pos: [9, 1, 10], state: "minecraft:gray_wool"},
        {pos: [9, 1, 11], state: "minecraft:gray_wool"},
        {pos: [9, 1, 12], state: "minecraft:gray_wool"},
        {pos: [9, 1, 13], state: "minecraft:deepslate_bricks"},
        {pos: [9, 1, 14], state: "minecraft:deepslate_brick_stairs{facing:north,half:bottom,shape:straight,waterlogged:false}"},
        {pos: [10, 1, 7], state: "minecraft:deepslate_tile_stairs{facing:south,half:bottom,shape:straight,waterlogged:false}"},
        {pos: [10, 1, 8], state: "minecraft:gray_wool"},
        {pos: [10, 1, 9], state: "minecraft:gray_wool"},
        {pos: [10, 1, 10], state: "minecraft:gray_wool"},
        {pos: [10, 1, 11], state: "minecraft:gray_wool"},
        {pos: [10, 1, 12], state: "minecraft:gray_wool"},
        {pos: [10, 1, 13], state: "minecraft:deepslate_bricks"},
        {pos: [10, 1, 14], state: "minecraft:deepslate_brick_stairs{facing:north,half:bottom,shape:straight,waterlogged:false}"},
        {pos: [11, 1, 7], state: "minecraft:deepslate_tile_stairs{facing:south,half:bottom,shape:straight,waterlogged:false}"},
        {pos: [11, 1, 8], state: "minecraft:gray_wool"},
        {pos: [11, 1, 9], state: "minecraft:gray_wool"},
        {pos: [11, 1, 10], state: "minecraft:gray_wool"},
        {pos: [11, 1, 11], state: "minecraft:gray_wool"},
        {pos: [11, 1, 12], state: "minecraft:gray_wool"},
        {pos: [11, 1, 13], state: "minecraft:deepslate_bricks"},
        {pos: [11, 1, 14], state: "minecraft:deepslate_brick_stairs{facing:north,half:bottom,shape:straight,waterlogged:false}"},
        {pos: [12, 1, 7], state: "minecraft:deepslate_bricks"},
        {pos: [12, 1, 8], state: "minecraft:gray_wool"},
        {pos: [12, 1, 9], state: "minecraft:gray_wool"},
        {pos: [12, 1, 10], state: "minecraft:gray_wool"},
        {pos: [12, 1, 11], state: "minecraft:gray_wool"},
        {pos: [12, 1, 12], state: "minecraft:gray_wool"},
        {pos: [12, 1, 13], state: "minecraft:deepslate_bricks"},
        {pos: [13, 1, 7], state: "minecraft:deepslate_bricks"},
        {pos: [13, 1, 8], state: "minecraft:gray_wool"},
        {pos: [13, 1, 9], state: "minecraft:gray_wool"},
        {pos: [13, 1, 10], state: "minecraft:deepslate_bricks"},
        {pos: [13, 1, 11], state: "minecraft:gray_wool"},
        {pos: [13, 1, 12], state: "minecraft:gray_wool"},
        {pos: [13, 1, 13], state: "minecraft:deepslate_bricks"},
        {pos: [14, 1, 7], state: "minecraft:deepslate_bricks"},
        {pos: [14, 1, 8], state: "minecraft:gray_wool"},
        {pos: [14, 1, 9], state: "minecraft:gray_wool"},
        {pos: [14, 1, 10], state: "minecraft:deepslate_bricks"},
        {pos: [14, 1, 11], state: "minecraft:gray_wool"},
        {pos: [14, 1, 12], state: "minecraft:gray_wool"},
        {pos: [14, 1, 13], state: "minecraft:deepslate_bricks"},
        {pos: [15, 1, 7], state: "minecraft:deepslate_bricks"},
        {pos: [15, 1, 8], state: "minecraft:gray_wool"},
        {pos: [15, 1, 9], state: "minecraft:gray_wool"},
        {pos: [15, 1, 10], state: "minecraft:deepslate_bricks"},
        {pos: [15, 1, 11], state: "minecraft:gray_wool"},
        {pos: [15, 1, 12], state: "minecraft:gray_wool"},
        {pos: [15, 1, 13], state: "minecraft:deepslate_bricks"},
        {pos: [16, 1, 7], state: "minecraft:deepslate_bricks"},
        {pos: [16, 1, 8], state: "minecraft:gray_wool"},
        {pos: [16, 1, 9], state: "minecraft:gray_wool"},
        {pos: [16, 1, 10], state: "minecraft:deepslate_bricks"},
        {pos: [16, 1, 11], state: "minecraft:gray_wool"},
        {pos: [16, 1, 12], state: "minecraft:gray_wool"},
        {pos: [16, 1, 13], state: "minecraft:deepslate_bricks"},
        {pos: [17, 1, 7], state: "minecraft:deepslate_bricks"},
        {pos: [17, 1, 8], state: "minecraft:gray_wool"},
        {pos: [17, 1, 9], state: "minecraft:gray_wool"},
        {pos: [17, 1, 10], state: "minecraft:deepslate_bricks"},
        {pos: [17, 1, 11], state: "minecraft:gray_wool"},
        {pos: [17, 1, 12], state: "minecraft:gray_wool"},
        {pos: [17, 1, 13], state: "minecraft:deepslate_bricks"},
        {pos: [0, 2, 10], state: "minecraft:deepslate_tiles"},
        {pos: [1, 2, 7], state: "minecraft:polished_deepslate"},
        {pos: [1, 2, 10], state: "minecraft:deepslate_tiles"},
        {pos: [1, 2, 13], state: "minecraft:polished_deepslate"},
        {pos: [2, 2, 10], state: "minecraft:deepslate_tiles"},
        {pos: [3, 2, 7], state: "minecraft:deepslate_bricks"},
        {pos: [3, 2, 10], state: "minecraft:chiseled_deepslate"},
        {pos: [3, 2, 13], state: "minecraft:deepslate_bricks"},
        {pos: [4, 2, 10], state: "minecraft:deepslate_tiles"},
        {pos: [5, 2, 7], state: "minecraft:deepslate_bricks"},
        {pos: [5, 2, 10], state: "minecraft:chiseled_deepslate"},
        {pos: [5, 2, 13], state: "minecraft:deepslate_bricks"},
        {pos: [6, 2, 10], state: "minecraft:deepslate_tiles"},
        {pos: [7, 2, 7], state: "minecraft:polished_deepslate"},
        {pos: [7, 2, 10], state: "minecraft:deepslate_tiles"},
        {pos: [7, 2, 13], state: "minecraft:polished_deepslate"},
        {pos: [8, 2, 9], state: "minecraft:deepslate_tile_stairs{facing:west,half:bottom,shape:straight,waterlogged:false}"},
        {pos: [8, 2, 10], state: "minecraft:deepslate_tile_stairs{facing:west,half:bottom,shape:straight,waterlogged:false}"},
        {pos: [12, 2, 10], state: "minecraft:deepslate_tile_stairs{facing:east,half:bottom,shape:straight,waterlogged:false}"},
        {pos: [12, 2, 11], state: "minecraft:deepslate_tile_stairs{facing:east,half:bottom,shape:straight,waterlogged:false}"},
        {pos: [13, 2, 7], state: "minecraft:polished_deepslate"},
        {pos: [13, 2, 10], state: "minecraft:deepslate_tiles"},
        {pos: [13, 2, 13], state: "minecraft:polished_deepslate"},
        {pos: [14, 2, 10], state: "minecraft:deepslate_tiles"},
        {pos: [15, 2, 7], state: "minecraft:deepslate_bricks"},
        {pos: [15, 2, 10], state: "minecraft:chiseled_deepslate"},
        {pos: [15, 2, 13], state: "minecraft:deepslate_bricks"},
        {pos: [16, 2, 10], state: "minecraft:deepslate_tiles"},
        {pos: [17, 2, 7], state: "minecraft:deepslate_bricks"},
        {pos: [17, 2, 10], state: "minecraft:chiseled_deepslate"},
        {pos: [17, 2, 13], state: "minecraft:deepslate_bricks"},
        {pos: [0, 3, 10], state: "minecraft:deepslate_bricks"},
        {pos: [1, 3, 7], state: "minecraft:polished_deepslate"},
        {pos: [1, 3, 10], state: "minecraft:deepslate_bricks"},
        {pos: [1, 3, 13], state: "minecraft:polished_deepslate"},
        {pos: [2, 3, 10], state: "minecraft:deepslate_bricks"},
        {pos: [3, 3, 10], state: "minecraft:deepslate_tiles"},
        {pos: [4, 3, 10], state: "minecraft:polished_deepslate"},
        {pos: [5, 3, 10], state: "minecraft:deepslate_tiles"},
        {pos: [6, 3, 10], state: "minecraft:deepslate_bricks"},
        {pos: [7, 3, 7], state: "minecraft:polished_deepslate"},
        {pos: [7, 3, 9], state: "minecraft:deepslate_tile_stairs{facing:west,half:bottom,shape:straight,waterlogged:false}"},
        {pos: [7, 3, 10], state: "minecraft:deepslate_tile_stairs{facing:west,half:bottom,shape:straight,waterlogged:false}"},
        {pos: [7, 3, 13], state: "minecraft:polished_deepslate"},
        {pos: [13, 3, 7], state: "minecraft:polished_deepslate"},
        {pos: [13, 3, 10], state: "minecraft:deepslate_tile_stairs{facing:east,half:bottom,shape:straight,waterlogged:false}"},
        {pos: [13, 3, 11], state: "minecraft:deepslate_tile_stairs{facing:east,half:bottom,shape:straight,waterlogged:false}"},
        {pos: [13, 3, 13], state: "minecraft:polished_deepslate"},
        {pos: [14, 3, 10], state: "minecraft:deepslate_tiles"},
        {pos: [15, 3, 10], state: "minecraft:deepslate_tiles"},
        {pos: [16, 3, 10], state: "minecraft:polished_deepslate"},
        {pos: [17, 3, 10], state: "minecraft:deepslate_tiles"},
        {pos: [0, 4, 10], state: "minecraft:deepslate_tiles"},
        {pos: [1, 4, 7], state: "minecraft:polished_deepslate"},
        {pos: [1, 4, 10], state: "minecraft:deepslate_tiles"},
        {pos: [1, 4, 13], state: "minecraft:polished_deepslate"},
        {pos: [2, 4, 10], state: "minecraft:deepslate_tiles"},
        {pos: [3, 4, 10], state: "minecraft:chiseled_deepslate"},
        {pos: [4, 4, 10], state: "minecraft:deepslate_tiles"},
        {pos: [5, 4, 10], state: "minecraft:chiseled_deepslate"},
        {pos: [6, 4, 9], state: "minecraft:deepslate_tile_stairs{facing:west,half:bottom,shape:straight,waterlogged:false}"},
        {pos: [6, 4, 10], state: "minecraft:deepslate_tile_stairs{facing:west,half:bottom,shape:straight,waterlogged:false}"},
        {pos: [7, 4, 7], state: "minecraft:polished_deepslate"},
        {pos: [7, 4, 13], state: "minecraft:polished_deepslate"},
        {pos: [8, 4, 7], state: "minecraft:soul_lantern{hanging:true,waterlogged:false}"},
        {pos: [8, 4, 13], state: "minecraft:soul_lantern{hanging:true,waterlogged:false}"},
        {pos: [12, 4, 7], state: "minecraft:soul_lantern{hanging:true,waterlogged:false}"},
        {pos: [12, 4, 13], state: "minecraft:soul_lantern{hanging:true,waterlogged:false}"},
        {pos: [13, 4, 7], state: "minecraft:polished_deepslate"},
        {pos: [13, 4, 13], state: "minecraft:polished_deepslate"},
        {pos: [14, 4, 10], state: "minecraft:deepslate_tile_stairs{facing:east,half:bottom,shape:straight,waterlogged:false}"},
        {pos: [14, 4, 11], state: "minecraft:deepslate_tile_stairs{facing:east,half:bottom,shape:straight,waterlogged:false}"},
        {pos: [15, 4, 10], state: "minecraft:chiseled_deepslate"},
        {pos: [16, 4, 10], state: "minecraft:deepslate_tiles"},
        {pos: [17, 4, 10], state: "minecraft:chiseled_deepslate"},
        {pos: [0, 5, 6], state: "minecraft:deepslate_bricks"},
        {pos: [0, 5, 7], state: "minecraft:deepslate_bricks"},
        {pos: [0, 5, 8], state: "minecraft:gray_wool"},
        {pos: [0, 5, 9], state: "minecraft:gray_wool"},
        {pos: [0, 5, 10], state: "minecraft:deepslate_bricks"},
        {pos: [0, 5, 11], state: "minecraft:gray_wool"},
        {pos: [0, 5, 12], state: "minecraft:gray_wool"},
        {pos: [0, 5, 13], state: "minecraft:deepslate_bricks"},
        {pos: [0, 5, 14], state: "minecraft:deepslate_bricks"},
        {pos: [1, 5, 6], state: "minecraft:deepslate_bricks"},
        {pos: [1, 5, 7], state: "minecraft:deepslate_bricks"},
        {pos: [1, 5, 8], state: "minecraft:gray_wool"},
        {pos: [1, 5, 9], state: "minecraft:gray_wool"},
        {pos: [1, 5, 10], state: "minecraft:deepslate_bricks"},
        {pos: [1, 5, 11], state: "minecraft:gray_wool"},
        {pos: [1, 5, 12], state: "minecraft:gray_wool"},
        {pos: [1, 5, 13], state: "minecraft:deepslate_bricks"},
        {pos: [1, 5, 14], state: "minecraft:deepslate_bricks"},
        {pos: [2, 5, 6], state: "minecraft:deepslate_bricks"},
        {pos: [2, 5, 7], state: "minecraft:deepslate_bricks"},
        {pos: [2, 5, 8], state: "minecraft:gray_wool"},
        {pos: [2, 5, 9], state: "minecraft:gray_wool"},
        {pos: [2, 5, 10], state: "minecraft:deepslate_tiles"},
        {pos: [2, 5, 11], state: "minecraft:gray_wool"},
        {pos: [2, 5, 12], state: "minecraft:gray_wool"},
        {pos: [2, 5, 13], state: "minecraft:deepslate_bricks"},
        {pos: [2, 5, 14], state: "minecraft:deepslate_bricks"},
        {pos: [3, 5, 6], state: "minecraft:deepslate_bricks"},
        {pos: [3, 5, 7], state: "minecraft:deepslate_bricks"},
        {pos: [3, 5, 8], state: "minecraft:gray_wool"},
        {pos: [3, 5, 9], state: "minecraft:gray_wool"},
        {pos: [3, 5, 10], state: "minecraft:deepslate_tiles"},
        {pos: [3, 5, 11], state: "minecraft:gray_wool"},
        {pos: [3, 5, 12], state: "minecraft:gray_wool"},
        {pos: [3, 5, 13], state: "minecraft:deepslate_bricks"},
        {pos: [3, 5, 14], state: "minecraft:deepslate_bricks"},
        {pos: [4, 5, 6], state: "minecraft:deepslate_bricks"},
        {pos: [4, 5, 7], state: "minecraft:deepslate_bricks"},
        {pos: [4, 5, 8], state: "minecraft:gray_wool"},
        {pos: [4, 5, 9], state: "minecraft:gray_wool"},
        {pos: [4, 5, 10], state: "minecraft:deepslate_tiles"},
        {pos: [4, 5, 11], state: "minecraft:gray_wool"},
        {pos: [4, 5, 12], state: "minecraft:gray_wool"},
        {pos: [4, 5, 13], state: "minecraft:deepslate_bricks"},
        {pos: [4, 5, 14], state: "minecraft:deepslate_bricks"},
        {pos: [5, 5, 6], state: "minecraft:deepslate_bricks"},
        {pos: [5, 5, 7], state: "minecraft:deepslate_bricks"},
        {pos: [5, 5, 8], state: "minecraft:deepslate_tiles"},
        {pos: [5, 5, 9], state: "minecraft:deepslate_tile_stairs{facing:west,half:bottom,shape:straight,waterlogged:false}"},
        {pos: [5, 5, 10], state: "minecraft:deepslate_tile_stairs{facing:west,half:bottom,shape:straight,waterlogged:false}"},
        {pos: [5, 5, 11], state: "minecraft:deepslate_tiles"},
        {pos: [5, 5, 12], state: "minecraft:deepslate_tiles"},
        {pos: [5, 5, 13], state: "minecraft:deepslate_bricks"},
        {pos: [5, 5, 14], state: "minecraft:deepslate_bricks"},
        {pos: [6, 5, 6], state: "minecraft:deepslate_bricks"},
        {pos: [6, 5, 7], state: "minecraft:deepslate_bricks"},
        {pos: [6, 5, 13], state: "minecraft:deepslate_bricks"},
        {pos: [6, 5, 14], state: "minecraft:deepslate_bricks"},
        {pos: [7, 5, 6], state: "minecraft:deepslate_bricks"},
        {pos: [7, 5, 7], state: "minecraft:deepslate_bricks"},
        {pos: [7, 5, 13], state: "minecraft:deepslate_bricks"},
        {pos: [7, 5, 14], state: "minecraft:deepslate_bricks"},
        {pos: [8, 5, 7], state: "minecraft:polished_deepslate_wall{east:none,north:none,south:none,up:true,waterlogged:false,west:low}"},
        {pos: [8, 5, 13], state: "minecraft:polished_deepslate_wall{east:none,north:none,south:none,up:true,waterlogged:false,west:low}"},
        {pos: [12, 5, 7], state: "minecraft:polished_deepslate_wall{east:low,north:none,south:none,up:true,waterlogged:false,west:none}"},
        {pos: [12, 5, 13], state: "minecraft:polished_deepslate_wall{east:low,north:none,south:none,up:true,waterlogged:false,west:none}"},
        {pos: [13, 5, 6], state: "minecraft:deepslate_bricks"},
        {pos: [13, 5, 7], state: "minecraft:deepslate_bricks"},
        {pos: [13, 5, 13], state: "minecraft:deepslate_bricks"},
        {pos: [13, 5, 14], state: "minecraft:deepslate_bricks"},
        {pos: [14, 5, 6], state: "minecraft:deepslate_bricks"},
        {pos: [14, 5, 7], state: "minecraft:deepslate_bricks"},
        {pos: [14, 5, 13], state: "minecraft:deepslate_bricks"},
        {pos: [14, 5, 14], state: "minecraft:deepslate_bricks"},
        {pos: [15, 5, 6], state: "minecraft:deepslate_bricks"},
        {pos: [15, 5, 7], state: "minecraft:deepslate_bricks"},
        {pos: [15, 5, 8], state: "minecraft:deepslate_tiles"},
        {pos: [15, 5, 9], state: "minecraft:deepslate_tiles"},
        {pos: [15, 5, 10], state: "minecraft:deepslate_tile_stairs{facing:east,half:bottom,shape:straight,waterlogged:false}"},
        {pos: [15, 5, 11], state: "minecraft:deepslate_tile_stairs{facing:east,half:bottom,shape:straight,waterlogged:false}"},
        {pos: [15, 5, 12], state: "minecraft:deepslate_tiles"},
        {pos: [15, 5, 13], state: "minecraft:deepslate_bricks"},
        {pos: [15, 5, 14], state: "minecraft:deepslate_bricks"},
        {pos: [16, 5, 6], state: "minecraft:deepslate_bricks"},
        {pos: [16, 5, 7], state: "minecraft:deepslate_bricks"},
        {pos: [16, 5, 8], state: "minecraft:gray_wool"},
        {pos: [16, 5, 9], state: "minecraft:gray_wool"},
        {pos: [16, 5, 10], state: "minecraft:deepslate_tiles"},
        {pos: [16, 5, 11], state: "minecraft:gray_wool"},
        {pos: [16, 5, 12], state: "minecraft:gray_wool"},
        {pos: [16, 5, 13], state: "minecraft:deepslate_bricks"},
        {pos: [16, 5, 14], state: "minecraft:deepslate_bricks"},
        {pos: [17, 5, 6], state: "minecraft:deepslate_bricks"},
        {pos: [17, 5, 7], state: "minecraft:deepslate_bricks"},
        {pos: [17, 5, 8], state: "minecraft:gray_wool"},
        {pos: [17, 5, 9], state: "minecraft:gray_wool"},
        {pos: [17, 5, 10], state: "minecraft:deepslate_tiles"},
        {pos: [17, 5, 11], state: "minecraft:gray_wool"},
        {pos: [17, 5, 12], state: "minecraft:gray_wool"},
        {pos: [17, 5, 13], state: "minecraft:deepslate_bricks"},
        {pos: [17, 5, 14], state: "minecraft:deepslate_bricks"},
        {pos: [0, 6, 10], state: "minecraft:chiseled_deepslate"},
        {pos: [1, 6, 7], state: "minecraft:deepslate_bricks"},
        {pos: [1, 6, 13], state: "minecraft:deepslate_bricks"},
        {pos: [2, 6, 10], state: "minecraft:chiseled_deepslate"},
        {pos: [3, 6, 7], state: "minecraft:deepslate_bricks"},
        {pos: [3, 6, 13], state: "minecraft:deepslate_bricks"},
        {pos: [5, 6, 7], state: "minecraft:deepslate_bricks"},
        {pos: [5, 6, 13], state: "minecraft:deepslate_bricks"},
        {pos: [7, 6, 7], state: "minecraft:deepslate_bricks"},
        {pos: [7, 6, 13], state: "minecraft:deepslate_bricks"},
        {pos: [13, 6, 7], state: "minecraft:deepslate_bricks"},
        {pos: [13, 6, 13], state: "minecraft:deepslate_bricks"},
        {pos: [15, 6, 7], state: "minecraft:deepslate_bricks"},
        {pos: [15, 6, 13], state: "minecraft:deepslate_bricks"},
        {pos: [17, 6, 7], state: "minecraft:deepslate_bricks"},
        {pos: [17, 6, 13], state: "minecraft:deepslate_bricks"}
    ],
    entities: [],
    palette: [
        "minecraft:deepslate_tiles",
        "minecraft:gray_wool",
        "minecraft:chiseled_deepslate",
        "minecraft:deepslate_bricks",
        "minecraft:polished_deepslate",
        "minecraft:deepslate_tile_stairs{facing:south,half:bottom,shape:straight,waterlogged:false}",
        "minecraft:deepslate_tile_stairs{facing:north,half:bottom,shape:straight,waterlogged:false}",
        "minecraft:deepslate_tile_slab{type:bottom,waterlogged:false}",
        "minecraft:deepslate_brick_stairs{facing:north,half:bottom,shape:straight,waterlogged:false}",
        "minecraft:deepslate_tile_stairs{facing:west,half:bottom,shape:straight,waterlogged:false}",
        "minecraft:deepslate_tile_stairs{facing:east,half:bottom,shape:straight,waterlogged:false}",
        "minecraft:soul_lantern{hanging:true,waterlogged:false}",
        "minecraft:polished_deepslate_wall{east:none,north:none,south:none,up:true,waterlogged:false,west:low}",
        "minecraft:polished_deepslate_wall{east:low,north:none,south:none,up:true,waterlogged:false,west:none}",
        "minecraft:jigsaw{orientation:west_up}",
        "minecraft:jigsaw{orientation:north_up}",
        "minecraft:jigsaw{orientation:south_up}",
        "minecraft:jigsaw{orientation:east_up}"
    ]
}
