{
    size: [5, 6, 6],
    data: [
        {pos: [0, 0, 0], state: "minecraft:sand"},
        {pos: [0, 0, 1], state: "minecraft:sand"},
        {pos: [0, 0, 2], state: "minecraft:sand"},
        {pos: [0, 0, 3], state: "minecraft:sand"},
        {pos: [0, 0, 4], state: "minecraft:sand"},
        {pos: [0, 0, 5], state: "minecraft:sand"},
        {pos: [1, 0, 0], state: "minecraft:sand"},
        {pos: [1, 0, 1], state: "minecraft:sand"},
        {pos: [1, 0, 2], state: "minecraft:terracotta"},
        {pos: [1, 0, 3], state: "minecraft:smooth_sandstone"},
        {pos: [1, 0, 4], state: "minecraft:terracotta"},
        {pos: [1, 0, 5], state: "minecraft:sand"},
        {pos: [2, 0, 0], state: "minecraft:smooth_sandstone"},
        {pos: [2, 0, 1], state: "minecraft:smooth_sandstone"},
        {pos: [2, 0, 2], state: "minecraft:smooth_sandstone"},
        {pos: [2, 0, 3], state: "minecraft:terracotta"},
        {pos: [2, 0, 4], state: "minecraft:smooth_sandstone"},
        {pos: [2, 0, 5], state: "minecraft:sand"},
        {pos: [3, 0, 0], state: "minecraft:sand"},
        {pos: [3, 0, 1], state: "minecraft:sand"},
        {pos: [3, 0, 2], state: "minecraft:terracotta"},
        {pos: [3, 0, 3], state: "minecraft:jigsaw{orientation:up_north}", nbt: {final_state: "minecraft:smooth_sandstone", id: "minecraft:jigsaw", joint: "rollable", name: "minecraft:bottom", pool: "minecraft:village/desert/villagers", target: "minecraft:bottom"}},
        {pos: [3, 0, 4], state: "minecraft:terracotta"},
        {pos: [3, 0, 5], state: "minecraft:sand"},
        {pos: [4, 0, 0], state: "minecraft:sand"},
        {pos: [4, 0, 1], state: "minecraft:sand"},
        {pos: [4, 0, 2], state: "minecraft:sand"},
        {pos: [4, 0, 3], state: "minecraft:sand"},
        {pos: [4, 0, 4], state: "minecraft:sand"},
        {pos: [4, 0, 5], state: "minecraft:sand"},
        {pos: [0, 1, 0], state: "minecraft:air"},
        {pos: [0, 1, 1], state: "minecraft:smooth_sandstone"},
        {pos: [0, 1, 2], state: "minecraft:cut_sandstone"},
        {pos: [0, 1, 3], state: "minecraft:smooth_sandstone"},
        {pos: [0, 1, 4], state: "minecraft:cut_sandstone"},
        {pos: [0, 1, 5], state: "minecraft:smooth_sandstone"},
        {pos: [1, 1, 0], state: "minecraft:potted_cactus"},
        {pos: [1, 1, 1], state: "minecraft:smooth_sandstone"},
        {pos: [1, 1, 2], state: "minecraft:crafting_table"},
        {pos: [1, 1, 3], state: "minecraft:lime_bed{facing:south,occupied:false,part:foot}", nbt: {id: "minecraft:bed"}},
        {pos: [1, 1, 4], state: "minecraft:lime_bed{facing:south,occupied:false,part:head}", nbt: {id: "minecraft:bed"}},
        {pos: [1, 1, 5], state: "minecraft:cut_sandstone"},
        {pos: [2, 1, 0], state: "minecraft:jigsaw{orientation:north_up}", nbt: {final_state: "minecraft:structure_void", id: "minecraft:jigsaw", joint: "aligned", name: "minecraft:building_entrance", pool: "minecraft:empty", target: "minecraft:building_entrance"}},
        {pos: [2, 1, 1], state: "minecraft:jungle_door{facing:north,half:lower,hinge:left,open:false,powered:false}"},
        {pos: [2, 1, 2], state: "minecraft:air"},
        {pos: [2, 1, 3], state: "minecraft:air"},
        {pos: [2, 1, 4], state: "minecraft:air"},
        {pos: [2, 1, 5], state: "minecraft:smooth_sandstone"},
        {pos: [3, 1, 0], state: "minecraft:air"},
        {pos: [3, 1, 1], state: "minecraft:smooth_sandstone"},
        {pos: [3, 1, 2], state: "minecraft:air"},
        {pos: [3, 1, 3], state: "minecraft:air"},
        {pos: [3, 1, 4], state: "minecraft:air"},
        {pos: [3, 1, 5], state: "minecraft:cut_sandstone"},
        {pos: [4, 1, 0], state: "minecraft:air"},
        {pos: [4, 1, 1], state: "minecraft:smooth_sandstone"},
        {pos: [4, 1, 2], state: "minecraft:cut_sandstone"},
        {pos: [4, 1, 3], state: "minecraft:smooth_sandstone"},
        {pos: [4, 1, 4], state: "minecraft:cut_sandstone"},
        {pos: [4, 1, 5], state: "minecraft:smooth_sandstone"},
        {pos: [0, 2, 0], state: "minecraft:air"},
        {pos: [0, 2, 1], state: "minecraft:smooth_sandstone"},
        {pos: [0, 2, 2], state: "minecraft:cut_sandstone"},
        {pos: [0, 2, 3], state: "minecraft:smooth_sandstone"},
        {pos: [0, 2, 4], state: "minecraft:cut_sandstone"},
        {pos: [0, 2, 5], state: "minecraft:smooth_sandstone"},
        {pos: [1, 2, 0], state: "minecraft:air"},
        {pos: [1, 2, 1], state: "minecraft:smooth_sandstone"},
        {pos: [1, 2, 2], state: "minecraft:air"},
        {pos: [1, 2, 3], state: "minecraft:air"},
        {pos: [1, 2, 4], state: "minecraft:air"},
        {pos: [1, 2, 5], state: "minecraft:cut_sandstone"},
        {pos: [2, 2, 0], state: "minecraft:air"},
        {pos: [2, 2, 1], state: "minecraft:jungle_door{facing:north,half:upper,hinge:left,open:false,powered:false}"},
        {pos: [2, 2, 2], state: "minecraft:air"},
        {pos: [2, 2, 3], state: "minecraft:air"},
        {pos: [2, 2, 4], state: "minecraft:air"},
        {pos: [2, 2, 5], state: "minecraft:smooth_sandstone"},
        {pos: [3, 2, 0], state: "minecraft:air"},
        {pos: [3, 2, 1], state: "minecraft:smooth_sandstone"},
        {pos: [3, 2, 2], state: "minecraft:air"},
        {pos: [3, 2, 3], state: "minecraft:air"},
        {pos: [3, 2, 4], state: "minecraft:air"},
        {pos: [3, 2, 5], state: "minecraft:cut_sandstone"},
        {pos: [4, 2, 0], state: "minecraft:air"},
        {pos: [4, 2, 1], state: "minecraft:smooth_sandstone"},
        {pos: [4, 2, 2], state: "minecraft:cut_sandstone"},
        {pos: [4, 2, 3], state: "minecraft:smooth_sandstone"},
        {pos: [4, 2, 4], state: "minecraft:cut_sandstone"},
        {pos: [4, 2, 5], state: "minecraft:smooth_sandstone"},
        {pos: [0, 3, 0], state: "minecraft:air"},
        {pos: [0, 3, 1], state: "minecraft:smooth_sandstone"},
        {pos: [0, 3, 2], state: "minecraft:cut_sandstone"},
        {pos: [0, 3, 3], state: "minecraft:smooth_sandstone"},
        {pos: [0, 3, 4], state: "minecraft:cut_sandstone"},
        {pos: [0, 3, 5], state: "minecraft:smooth_sandstone"},
        {pos: [1, 3, 0], state: "minecraft:jungle_button{face:wall,facing:north,powered:false}"},
        {pos: [1, 3, 1], state: "minecraft:smooth_sandstone"},
        {pos: [1, 3, 2], state: "minecraft:air"},
        {pos: [1, 3, 3], state: "minecraft:air"},
        {pos: [1, 3, 4], state: "minecraft:air"},
        {pos: [1, 3, 5], state: "minecraft:air"},
        {pos: [2, 3, 0], state: "minecraft:jungle_button{face:wall,facing:north,powered:false}"},
        {pos: [2, 3, 1], state: "minecraft:smooth_sandstone"},
        {pos: [2, 3, 2], state: "minecraft:air"},
        {pos: [2, 3, 3], state: "minecraft:air"},
        {pos: [2, 3, 4], state: "minecraft:wall_torch{facing:north}"},
        {pos: [2, 3, 5], state: "minecraft:smooth_sandstone"},
        {pos: [3, 3, 0], state: "minecraft:jungle_button{face:wall,facing:north,powered:false}"},
        {pos: [3, 3, 1], state: "minecraft:smooth_sandstone"},
        {pos: [3, 3, 2], state: "minecraft:air"},
        {pos: [3, 3, 3], state: "minecraft:air"},
        {pos: [3, 3, 4], state: "minecraft:air"},
        {pos: [3, 3, 5], state: "minecraft:air"},
        {pos: [4, 3, 0], state: "minecraft:air"},
        {pos: [4, 3, 1], state: "minecraft:smooth_sandstone"},
        {pos: [4, 3, 2], state: "minecraft:cut_sandstone"},
        {pos: [4, 3, 3], state: "minecraft:smooth_sandstone"},
        {pos: [4, 3, 4], state: "minecraft:cut_sandstone"},
        {pos: [4, 3, 5], state: "minecraft:smooth_sandstone"},
        {pos: [0, 4, 0], state: "minecraft:air"},
        {pos: [0, 4, 1], state: "minecraft:cut_sandstone"},
        {pos: [0, 4, 2], state: "minecraft:cut_sandstone"},
        {pos: [0, 4, 3], state: "minecraft:cut_sandstone"},
        {pos: [0, 4, 4], state: "minecraft:cut_sandstone"},
        {pos: [0, 4, 5], state: "minecraft:cut_sandstone"},
        {pos: [1, 4, 0], state: "minecraft:air"},
        {pos: [1, 4, 1], state: "minecraft:cut_sandstone"},
        {pos: [1, 4, 2], state: "minecraft:cut_sandstone"},
        {pos: [1, 4, 3], state: "minecraft:cut_sandstone"},
        {pos: [1, 4, 4], state: "minecraft:cut_sandstone"},
        {pos: [1, 4, 5], state: "minecraft:cut_sandstone"},
        {pos: [2, 4, 0], state: "minecraft:air"},
        {pos: [2, 4, 1], state: "minecraft:cut_sandstone"},
        {pos: [2, 4, 2], state: "minecraft:cut_sandstone"},
        {pos: [2, 4, 3], state: "minecraft:cut_sandstone"},
        {pos: [2, 4, 4], state: "minecraft:cut_sandstone"},
        {pos: [2, 4, 5], state: "minecraft:cut_sandstone"},
        {pos: [3, 4, 0], state: "minecraft:air"},
        {pos: [3, 4, 1], state: "minecraft:cut_sandstone"},
        {pos: [3, 4, 2], state: "minecraft:cut_sandstone"},
        {pos: [3, 4, 3], state: "minecraft:cut_sandstone"},
        {pos: [3, 4, 4], state: "minecraft:cut_sandstone"},
        {pos: [3, 4, 5], state: "minecraft:cut_sandstone"},
        {pos: [4, 4, 0], state: "minecraft:air"},
        {pos: [4, 4, 1], state: "minecraft:cut_sandstone"},
        {pos: [4, 4, 2], state: "minecraft:cut_sandstone"},
        {pos: [4, 4, 3], state: "minecraft:cut_sandstone"},
        {pos: [4, 4, 4], state: "minecraft:cut_sandstone"},
        {pos: [4, 4, 5], state: "minecraft:cut_sandstone"},
        {pos: [0, 5, 0], state: "minecraft:air"},
        {pos: [0, 5, 1], state: "minecraft:cut_sandstone"},
        {pos: [0, 5, 2], state: "minecraft:air"},
        {pos: [0, 5, 3], state: "minecraft:cut_sandstone"},
        {pos: [0, 5, 4], state: "minecraft:air"},
        {pos: [0, 5, 5], state: "minecraft:cut_sandstone"},
        {pos: [1, 5, 0], state: "minecraft:air"},
        {pos: [1, 5, 1], state: "minecraft:air"},
        {pos: [1, 5, 2], state: "minecraft:air"},
        {pos: [1, 5, 3], state: "minecraft:air"},
        {pos: [1, 5, 4], state: "minecraft:air"},
        {pos: [1, 5, 5], state: "minecraft:air"},
        {pos: [2, 5, 0], state: "minecraft:air"},
        {pos: [2, 5, 1], state: "minecraft:cut_sandstone"},
        {pos: [2, 5, 2], state: "minecraft:air"},
        {pos: [2, 5, 3], state: "minecraft:air"},
        {pos: [2, 5, 4], state: "minecraft:air"},
        {pos: [2, 5, 5], state: "minecraft:cut_sandstone"},
        {pos: [3, 5, 0], state: "minecraft:air"},
        {pos: [3, 5, 1], state: "minecraft:air"},
        {pos: [3, 5, 2], state: "minecraft:air"},
        {pos: [3, 5, 3], state: "minecraft:air"},
        {pos: [3, 5, 4], state: "minecraft:air"},
        {pos: [3, 5, 5], state: "minecraft:air"},
        {pos: [4, 5, 0], state: "minecraft:air"},
        {pos: [4, 5, 1], state: "minecraft:cut_sandstone"},
        {pos: [4, 5, 2], state: "minecraft:air"},
        {pos: [4, 5, 3], state: "minecraft:cut_sandstone"},
        {pos: [4, 5, 4], state: "minecraft:air"},
        {pos: [4, 5, 5], state: "minecraft:cut_sandstone"}
    ],
    entities: [],
    palette: [
        "minecraft:sand",
        "minecraft:terracotta",
        "minecraft:smooth_sandstone",
        "minecraft:cut_sandstone",
        "minecraft:crafting_table",
        "minecraft:air",
        "minecraft:potted_cactus",
        "minecraft:jungle_door{facing:north,half:lower,hinge:left,open:false,powered:false}",
        "minecraft:jungle_door{facing:north,half:upper,hinge:left,open:false,powered:false}",
        "minecraft:jungle_button{face:wall,facing:north,powered:false}",
        "minecraft:wall_torch{facing:north}",
        "minecraft:jigsaw{orientation:up_north}",
        "minecraft:lime_bed{facing:south,occupied:false,part:foot}",
        "minecraft:lime_bed{facing:south,occupied:false,part:head}",
        "minecraft:jigsaw{orientation:north_up}"
    ]
}
