{
    size: [11, 6, 5],
    data: [
        {pos: [0, 0, 0], state: "minecraft:sand"},
        {pos: [0, 0, 1], state: "minecraft:sand"},
        {pos: [0, 0, 2], state: "minecraft:sand"},
        {pos: [0, 0, 3], state: "minecraft:sand"},
        {pos: [0, 0, 4], state: "minecraft:sand"},
        {pos: [1, 0, 0], state: "minecraft:sand"},
        {pos: [1, 0, 1], state: "minecraft:water{level:0}"},
        {pos: [1, 0, 2], state: "minecraft:sand"},
        {pos: [1, 0, 3], state: "minecraft:sand"},
        {pos: [1, 0, 4], state: "minecraft:sand"},
        {pos: [2, 0, 0], state: "minecraft:sand"},
        {pos: [2, 0, 1], state: "minecraft:sand"},
        {pos: [2, 0, 2], state: "minecraft:sand"},
        {pos: [2, 0, 3], state: "minecraft:sand"},
        {pos: [2, 0, 4], state: "minecraft:sand"},
        {pos: [3, 0, 0], state: "minecraft:sand"},
        {pos: [3, 0, 1], state: "minecraft:sand"},
        {pos: [3, 0, 2], state: "minecraft:jigsaw{orientation:up_north}", nbt: {final_state: "minecraft:sand", id: "minecraft:jigsaw", joint: "rollable", name: "minecraft:bottom", pool: "minecraft:village/common/sheep", target: "minecraft:bottom"}},
        {pos: [3, 0, 3], state: "minecraft:sand"},
        {pos: [3, 0, 4], state: "minecraft:sand"},
        {pos: [4, 0, 0], state: "minecraft:sand"},
        {pos: [4, 0, 1], state: "minecraft:sand"},
        {pos: [4, 0, 2], state: "minecraft:smooth_sandstone"},
        {pos: [4, 0, 3], state: "minecraft:sand"},
        {pos: [4, 0, 4], state: "minecraft:sand"},
        {pos: [5, 0, 0], state: "minecraft:sand"},
        {pos: [5, 0, 1], state: "minecraft:sand"},
        {pos: [5, 0, 2], state: "minecraft:smooth_sandstone"},
        {pos: [5, 0, 3], state: "minecraft:sand"},
        {pos: [5, 0, 4], state: "minecraft:sand"},
        {pos: [6, 0, 0], state: "minecraft:sand"},
        {pos: [6, 0, 1], state: "minecraft:smooth_sandstone"},
        {pos: [6, 0, 2], state: "minecraft:smooth_sandstone"},
        {pos: [6, 0, 3], state: "minecraft:smooth_sandstone"},
        {pos: [6, 0, 4], state: "minecraft:sand"},
        {pos: [7, 0, 0], state: "minecraft:sand"},
        {pos: [7, 0, 1], state: "minecraft:smooth_sandstone"},
        {pos: [7, 0, 2], state: "minecraft:smooth_sandstone"},
        {pos: [7, 0, 3], state: "minecraft:sand"},
        {pos: [7, 0, 4], state: "minecraft:sand"},
        {pos: [8, 0, 0], state: "minecraft:sand"},
        {pos: [8, 0, 1], state: "minecraft:smooth_sandstone"},
        {pos: [8, 0, 2], state: "minecraft:smooth_sandstone"},
        {pos: [8, 0, 3], state: "minecraft:sand"},
        {pos: [8, 0, 4], state: "minecraft:sand"},
        {pos: [9, 0, 0], state: "minecraft:sand"},
        {pos: [9, 0, 1], state: "minecraft:sand"},
        {pos: [9, 0, 2], state: "minecraft:smooth_sandstone"},
        {pos: [9, 0, 3], state: "minecraft:sand"},
        {pos: [9, 0, 4], state: "minecraft:sand"},
        {pos: [10, 0, 0], state: "minecraft:sand"},
        {pos: [10, 0, 1], state: "minecraft:sand"},
        {pos: [10, 0, 2], state: "minecraft:sand"},
        {pos: [10, 0, 3], state: "minecraft:sand"},
        {pos: [10, 0, 4], state: "minecraft:sand"},
        {pos: [0, 1, 0], state: "minecraft:cut_sandstone"},
        {pos: [0, 1, 1], state: "minecraft:sandstone_wall{east:none,north:low,south:low,up:false,waterlogged:false,west:none}"},
        {pos: [0, 1, 2], state: "minecraft:sandstone_wall{east:none,north:low,south:low,up:false,waterlogged:false,west:none}"},
        {pos: [0, 1, 3], state: "minecraft:cut_sandstone"},
        {pos: [0, 1, 4], state: "minecraft:air"},
        {pos: [1, 1, 0], state: "minecraft:sandstone_wall{east:low,north:none,south:none,up:false,waterlogged:false,west:low}"},
        {pos: [1, 1, 2], state: "minecraft:air"},
        {pos: [1, 1, 3], state: "minecraft:sandstone_wall{east:low,north:none,south:none,up:false,waterlogged:false,west:low}"},
        {pos: [1, 1, 4], state: "minecraft:air"},
        {pos: [2, 1, 0], state: "minecraft:sandstone_wall{east:low,north:none,south:none,up:false,waterlogged:false,west:low}"},
        {pos: [2, 1, 2], state: "minecraft:air"},
        {pos: [2, 1, 3], state: "minecraft:sandstone_wall{east:low,north:none,south:none,up:false,waterlogged:false,west:low}"},
        {pos: [2, 1, 4], state: "minecraft:air"},
        {pos: [3, 1, 0], state: "minecraft:sandstone_wall{east:low,north:none,south:none,up:false,waterlogged:false,west:low}"},
        {pos: [3, 1, 2], state: "minecraft:air"},
        {pos: [3, 1, 3], state: "minecraft:sandstone_wall{east:low,north:none,south:none,up:false,waterlogged:false,west:low}"},
        {pos: [3, 1, 4], state: "minecraft:air"},
        {pos: [4, 1, 0], state: "minecraft:cut_sandstone"},
        {pos: [4, 1, 1], state: "minecraft:hay_block{axis:y}"},
        {pos: [4, 1, 2], state: "minecraft:air"},
        {pos: [4, 1, 3], state: "minecraft:cut_sandstone"},
        {pos: [4, 1, 4], state: "minecraft:cut_sandstone"},
        {pos: [5, 1, 0], state: "minecraft:smooth_sandstone"},
        {pos: [5, 1, 1], state: "minecraft:hay_block{axis:x}"},
        {pos: [5, 1, 2], state: "minecraft:air"},
        {pos: [5, 1, 3], state: "minecraft:smooth_sandstone"},
        {pos: [5, 1, 4], state: "minecraft:jigsaw{orientation:south_up}", nbt: {final_state: "minecraft:structure_void", id: "minecraft:jigsaw", joint: "aligned", name: "minecraft:building_entrance", pool: "minecraft:empty", target: "minecraft:building_entrance"}},
        {pos: [6, 1, 0], state: "minecraft:smooth_sandstone"},
        {pos: [6, 1, 1], state: "minecraft:air"},
        {pos: [6, 1, 2], state: "minecraft:air"},
        {pos: [6, 1, 3], state: "minecraft:jungle_door{facing:south,half:lower,hinge:right,open:false,powered:false}"},
        {pos: [6, 1, 4], state: "minecraft:air"},
        {pos: [7, 1, 0], state: "minecraft:smooth_sandstone"},
        {pos: [7, 1, 1], state: "minecraft:air"},
        {pos: [7, 1, 2], state: "minecraft:air"},
        {pos: [7, 1, 3], state: "minecraft:smooth_sandstone"},
        {pos: [7, 1, 4], state: "minecraft:air"},
        {pos: [8, 1, 0], state: "minecraft:smooth_sandstone"},
        {pos: [8, 1, 1], state: "minecraft:air"},
        {pos: [8, 1, 2], state: "minecraft:air"},
        {pos: [8, 1, 3], state: "minecraft:smooth_sandstone"},
        {pos: [8, 1, 4], state: "minecraft:cut_sandstone"},
        {pos: [9, 1, 0], state: "minecraft:smooth_sandstone"},
        {pos: [9, 1, 1], state: "minecraft:loom{facing:east}"},
        {pos: [9, 1, 2], state: "minecraft:loom{facing:east}"},
        {pos: [9, 1, 3], state: "minecraft:smooth_sandstone"},
        {pos: [9, 1, 4], state: "minecraft:air"},
        {pos: [10, 1, 0], state: "minecraft:cut_sandstone"},
        {pos: [10, 1, 1], state: "minecraft:smooth_sandstone"},
        {pos: [10, 1, 2], state: "minecraft:smooth_sandstone"},
        {pos: [10, 1, 3], state: "minecraft:cut_sandstone"},
        {pos: [10, 1, 4], state: "minecraft:air"},
        {pos: [0, 2, 0], state: "minecraft:cut_sandstone"},
        {pos: [0, 2, 2], state: "minecraft:air"},
        {pos: [0, 2, 3], state: "minecraft:cut_sandstone"},
        {pos: [0, 2, 4], state: "minecraft:air"},
        {pos: [1, 2, 2], state: "minecraft:air"},
        {pos: [1, 2, 3], state: "minecraft:air"},
        {pos: [1, 2, 4], state: "minecraft:air"},
        {pos: [2, 2, 2], state: "minecraft:air"},
        {pos: [2, 2, 3], state: "minecraft:air"},
        {pos: [2, 2, 4], state: "minecraft:air"},
        {pos: [3, 2, 2], state: "minecraft:air"},
        {pos: [3, 2, 3], state: "minecraft:air"},
        {pos: [3, 2, 4], state: "minecraft:air"},
        {pos: [4, 2, 0], state: "minecraft:cut_sandstone"},
        {pos: [4, 2, 1], state: "minecraft:air"},
        {pos: [4, 2, 2], state: "minecraft:air"},
        {pos: [4, 2, 3], state: "minecraft:cut_sandstone"},
        {pos: [4, 2, 4], state: "minecraft:potted_cactus"},
        {pos: [5, 2, 0], state: "minecraft:smooth_sandstone"},
        {pos: [5, 2, 1], state: "minecraft:air"},
        {pos: [5, 2, 2], state: "minecraft:air"},
        {pos: [5, 2, 3], state: "minecraft:smooth_sandstone"},
        {pos: [5, 2, 4], state: "minecraft:air"},
        {pos: [6, 2, 0], state: "minecraft:sandstone_slab{type:bottom,waterlogged:false}"},
        {pos: [6, 2, 1], state: "minecraft:air"},
        {pos: [6, 2, 2], state: "minecraft:air"},
        {pos: [6, 2, 3], state: "minecraft:jungle_door{facing:south,half:upper,hinge:right,open:false,powered:false}"},
        {pos: [6, 2, 4], state: "minecraft:air"},
        {pos: [7, 2, 0], state: "minecraft:smooth_sandstone"},
        {pos: [7, 2, 1], state: "minecraft:air"},
        {pos: [7, 2, 2], state: "minecraft:air"},
        {pos: [7, 2, 3], state: "minecraft:smooth_sandstone"},
        {pos: [7, 2, 4], state: "minecraft:air"},
        {pos: [8, 2, 0], state: "minecraft:sandstone_slab{type:bottom,waterlogged:false}"},
        {pos: [8, 2, 1], state: "minecraft:air"},
        {pos: [8, 2, 2], state: "minecraft:air"},
        {pos: [8, 2, 3], state: "minecraft:sandstone_slab{type:bottom,waterlogged:false}"},
        {pos: [8, 2, 4], state: "minecraft:potted_cactus"},
        {pos: [9, 2, 0], state: "minecraft:smooth_sandstone"},
        {pos: [9, 2, 1], state: "minecraft:air"},
        {pos: [9, 2, 2], state: "minecraft:air"},
        {pos: [9, 2, 3], state: "minecraft:smooth_sandstone"},
        {pos: [9, 2, 4], state: "minecraft:air"},
        {pos: [10, 2, 0], state: "minecraft:cut_sandstone"},
        {pos: [10, 2, 1], state: "minecraft:smooth_sandstone"},
        {pos: [10, 2, 2], state: "minecraft:smooth_sandstone"},
        {pos: [10, 2, 3], state: "minecraft:cut_sandstone"},
        {pos: [10, 2, 4], state: "minecraft:air"},
        {pos: [0, 3, 0], state: "minecraft:cut_sandstone"},
        {pos: [0, 3, 2], state: "minecraft:air"},
        {pos: [0, 3, 3], state: "minecraft:cut_sandstone"},
        {pos: [0, 3, 4], state: "minecraft:air"},
        {pos: [1, 3, 1], state: "minecraft:air"},
        {pos: [1, 3, 2], state: "minecraft:air"},
        {pos: [1, 3, 3], state: "minecraft:air"},
        {pos: [1, 3, 4], state: "minecraft:air"},
        {pos: [2, 3, 2], state: "minecraft:air"},
        {pos: [2, 3, 3], state: "minecraft:air"},
        {pos: [2, 3, 4], state: "minecraft:air"},
        {pos: [3, 3, 0], state: "minecraft:wall_torch{facing:west}"},
        {pos: [3, 3, 2], state: "minecraft:air"},
        {pos: [3, 3, 3], state: "minecraft:wall_torch{facing:west}"},
        {pos: [3, 3, 4], state: "minecraft:air"},
        {pos: [4, 3, 0], state: "minecraft:cut_sandstone"},
        {pos: [4, 3, 1], state: "minecraft:smooth_sandstone"},
        {pos: [4, 3, 2], state: "minecraft:smooth_sandstone"},
        {pos: [4, 3, 3], state: "minecraft:cut_sandstone"},
        {pos: [4, 3, 4], state: "minecraft:air"},
        {pos: [5, 3, 0], state: "minecraft:smooth_sandstone"},
        {pos: [5, 3, 1], state: "minecraft:wall_torch{facing:east}"},
        {pos: [5, 3, 2], state: "minecraft:air"},
        {pos: [5, 3, 3], state: "minecraft:smooth_sandstone"},
        {pos: [5, 3, 4], state: "minecraft:air"},
        {pos: [6, 3, 0], state: "minecraft:sandstone_slab{type:top,waterlogged:false}"},
        {pos: [6, 3, 1], state: "minecraft:air"},
        {pos: [6, 3, 2], state: "minecraft:air"},
        {pos: [6, 3, 3], state: "minecraft:smooth_sandstone"},
        {pos: [6, 3, 4], state: "minecraft:wall_torch{facing:south}"},
        {pos: [7, 3, 0], state: "minecraft:smooth_sandstone"},
        {pos: [7, 3, 1], state: "minecraft:air"},
        {pos: [7, 3, 2], state: "minecraft:air"},
        {pos: [7, 3, 3], state: "minecraft:smooth_sandstone"},
        {pos: [7, 3, 4], state: "minecraft:air"},
        {pos: [8, 3, 0], state: "minecraft:sandstone_slab{type:top,waterlogged:false}"},
        {pos: [8, 3, 1], state: "minecraft:air"},
        {pos: [8, 3, 2], state: "minecraft:air"},
        {pos: [8, 3, 3], state: "minecraft:sandstone_slab{type:top,waterlogged:false}"},
        {pos: [8, 3, 4], state: "minecraft:air"},
        {pos: [9, 3, 0], state: "minecraft:smooth_sandstone"},
        {pos: [9, 3, 1], state: "minecraft:wall_torch{facing:west}"},
        {pos: [9, 3, 2], state: "minecraft:wall_torch{facing:west}"},
        {pos: [9, 3, 3], state: "minecraft:smooth_sandstone"},
        {pos: [9, 3, 4], state: "minecraft:air"},
        {pos: [10, 3, 0], state: "minecraft:cut_sandstone"},
        {pos: [10, 3, 1], state: "minecraft:smooth_sandstone"},
        {pos: [10, 3, 2], state: "minecraft:smooth_sandstone"},
        {pos: [10, 3, 3], state: "minecraft:cut_sandstone"},
        {pos: [10, 3, 4], state: "minecraft:air"},
        {pos: [0, 4, 0], state: "minecraft:cut_sandstone"},
        {pos: [0, 4, 1], state: "minecraft:sandstone_slab{type:bottom,waterlogged:false}"},
        {pos: [0, 4, 2], state: "minecraft:sandstone_slab{type:bottom,waterlogged:false}"},
        {pos: [0, 4, 3], state: "minecraft:cut_sandstone"},
        {pos: [0, 4, 4], state: "minecraft:air"},
        {pos: [1, 4, 0], state: "minecraft:sandstone_slab{type:bottom,waterlogged:false}"},
        {pos: [1, 4, 1], state: "minecraft:sandstone_slab{type:bottom,waterlogged:false}"},
        {pos: [1, 4, 2], state: "minecraft:sandstone_slab{type:bottom,waterlogged:false}"},
        {pos: [1, 4, 3], state: "minecraft:sandstone_slab{type:bottom,waterlogged:false}"},
        {pos: [1, 4, 4], state: "minecraft:air"},
        {pos: [2, 4, 0], state: "minecraft:sandstone_slab{type:bottom,waterlogged:false}"},
        {pos: [2, 4, 1], state: "minecraft:sandstone_slab{type:bottom,waterlogged:false}"},
        {pos: [2, 4, 2], state: "minecraft:sandstone_slab{type:bottom,waterlogged:false}"},
        {pos: [2, 4, 3], state: "minecraft:sandstone_slab{type:bottom,waterlogged:false}"},
        {pos: [2, 4, 4], state: "minecraft:air"},
        {pos: [3, 4, 0], state: "minecraft:sandstone_slab{type:bottom,waterlogged:false}"},
        {pos: [3, 4, 1], state: "minecraft:sandstone_slab{type:bottom,waterlogged:false}"},
        {pos: [3, 4, 2], state: "minecraft:sandstone_slab{type:bottom,waterlogged:false}"},
        {pos: [3, 4, 3], state: "minecraft:sandstone_slab{type:bottom,waterlogged:false}"},
        {pos: [3, 4, 4], state: "minecraft:air"},
        {pos: [4, 4, 0], state: "minecraft:cut_sandstone"},
        {pos: [4, 4, 1], state: "minecraft:smooth_sandstone"},
        {pos: [4, 4, 2], state: "minecraft:smooth_sandstone"},
        {pos: [4, 4, 3], state: "minecraft:cut_sandstone"},
        {pos: [4, 4, 4], state: "minecraft:air"},
        {pos: [5, 4, 0], state: "minecraft:smooth_sandstone"},
        {pos: [5, 4, 1], state: "minecraft:air"},
        {pos: [5, 4, 2], state: "minecraft:air"},
        {pos: [5, 4, 3], state: "minecraft:smooth_sandstone"},
        {pos: [5, 4, 4], state: "minecraft:air"},
        {pos: [6, 4, 0], state: "minecraft:smooth_sandstone"},
        {pos: [6, 4, 1], state: "minecraft:air"},
        {pos: [6, 4, 2], state: "minecraft:air"},
        {pos: [6, 4, 3], state: "minecraft:smooth_sandstone"},
        {pos: [6, 4, 4], state: "minecraft:air"},
        {pos: [7, 4, 0], state: "minecraft:smooth_sandstone"},
        {pos: [7, 4, 1], state: "minecraft:air"},
        {pos: [7, 4, 2], state: "minecraft:air"},
        {pos: [7, 4, 3], state: "minecraft:smooth_sandstone"},
        {pos: [7, 4, 4], state: "minecraft:air"},
        {pos: [8, 4, 0], state: "minecraft:smooth_sandstone"},
        {pos: [8, 4, 1], state: "minecraft:air"},
        {pos: [8, 4, 2], state: "minecraft:air"},
        {pos: [8, 4, 3], state: "minecraft:smooth_sandstone"},
        {pos: [8, 4, 4], state: "minecraft:air"},
        {pos: [9, 4, 0], state: "minecraft:smooth_sandstone"},
        {pos: [9, 4, 1], state: "minecraft:air"},
        {pos: [9, 4, 2], state: "minecraft:air"},
        {pos: [9, 4, 3], state: "minecraft:smooth_sandstone"},
        {pos: [9, 4, 4], state: "minecraft:air"},
        {pos: [10, 4, 0], state: "minecraft:cut_sandstone"},
        {pos: [10, 4, 1], state: "minecraft:smooth_sandstone"},
        {pos: [10, 4, 2], state: "minecraft:smooth_sandstone"},
        {pos: [10, 4, 3], state: "minecraft:cut_sandstone"},
        {pos: [10, 4, 4], state: "minecraft:air"},
        {pos: [0, 5, 2], state: "minecraft:air"},
        {pos: [0, 5, 3], state: "minecraft:air"},
        {pos: [0, 5, 4], state: "minecraft:air"},
        {pos: [1, 5, 2], state: "minecraft:air"},
        {pos: [1, 5, 3], state: "minecraft:air"},
        {pos: [1, 5, 4], state: "minecraft:air"},
        {pos: [2, 5, 2], state: "minecraft:air"},
        {pos: [2, 5, 3], state: "minecraft:air"},
        {pos: [2, 5, 4], state: "minecraft:air"},
        {pos: [3, 5, 2], state: "minecraft:air"},
        {pos: [3, 5, 3], state: "minecraft:air"},
        {pos: [3, 5, 4], state: "minecraft:air"},
        {pos: [4, 5, 0], state: "minecraft:cut_sandstone"},
        {pos: [4, 5, 1], state: "minecraft:sandstone_slab{type:bottom,waterlogged:false}"},
        {pos: [4, 5, 2], state: "minecraft:sandstone_slab{type:bottom,waterlogged:false}"},
        {pos: [4, 5, 3], state: "minecraft:cut_sandstone"},
        {pos: [4, 5, 4], state: "minecraft:air"},
        {pos: [5, 5, 0], state: "minecraft:sandstone_slab{type:bottom,waterlogged:false}"},
        {pos: [5, 5, 1], state: "minecraft:sandstone_slab{type:bottom,waterlogged:false}"},
        {pos: [5, 5, 2], state: "minecraft:sandstone_slab{type:bottom,waterlogged:false}"},
        {pos: [5, 5, 3], state: "minecraft:sandstone_slab{type:bottom,waterlogged:false}"},
        {pos: [5, 5, 4], state: "minecraft:air"},
        {pos: [6, 5, 0], state: "minecraft:sandstone_slab{type:bottom,waterlogged:false}"},
        {pos: [6, 5, 1], state: "minecraft:sandstone_slab{type:bottom,waterlogged:false}"},
        {pos: [6, 5, 2], state: "minecraft:sandstone_slab{type:bottom,waterlogged:false}"},
        {pos: [6, 5, 3], state: "minecraft:sandstone_slab{type:bottom,waterlogged:false}"},
        {pos: [6, 5, 4], state: "minecraft:air"},
        {pos: [7, 5, 0], state: "minecraft:sandstone_slab{type:bottom,waterlogged:false}"},
        {pos: [7, 5, 1], state: "minecraft:sandstone_slab{type:bottom,waterlogged:false}"},
        {pos: [7, 5, 2], state: "minecraft:sandstone_slab{type:bottom,waterlogged:false}"},
        {pos: [7, 5, 3], state: "minecraft:sandstone_slab{type:bottom,waterlogged:false}"},
        {pos: [7, 5, 4], state: "minecraft:air"},
        {pos: [8, 5, 0], state: "minecraft:sandstone_slab{type:bottom,waterlogged:false}"},
        {pos: [8, 5, 1], state: "minecraft:sandstone_slab{type:bottom,waterlogged:false}"},
        {pos: [8, 5, 2], state: "minecraft:sandstone_slab{type:bottom,waterlogged:false}"},
        {pos: [8, 5, 3], state: "minecraft:sandstone_slab{type:bottom,waterlogged:false}"},
        {pos: [8, 5, 4], state: "minecraft:air"},
        {pos: [9, 5, 0], state: "minecraft:sandstone_slab{type:bottom,waterlogged:false}"},
        {pos: [9, 5, 1], state: "minecraft:sandstone_slab{type:bottom,waterlogged:false}"},
        {pos: [9, 5, 2], state: "minecraft:sandstone_slab{type:bottom,waterlogged:false}"},
        {pos: [9, 5, 3], state: "minecraft:sandstone_slab{type:bottom,waterlogged:false}"},
        {pos: [9, 5, 4], state: "minecraft:air"},
        {pos: [10, 5, 0], state: "minecraft:cut_sandstone"},
        {pos: [10, 5, 1], state: "minecraft:sandstone_slab{type:bottom,waterlogged:false}"},
        {pos: [10, 5, 2], state: "minecraft:sandstone_slab{type:bottom,waterlogged:false}"},
        {pos: [10, 5, 3], state: "minecraft:cut_sandstone"},
        {pos: [10, 5, 4], state: "minecraft:air"}
    ],
    entities: [],
    palette: [
        "minecraft:sand",
        "minecraft:smooth_sandstone",
        "minecraft:cut_sandstone",
        "minecraft:hay_block{axis:y}",
        "minecraft:hay_block{axis:x}",
        "minecraft:loom{facing:east}",
        "minecraft:water{level:0}",
        "minecraft:sandstone_wall{east:none,north:low,south:low,up:false,waterlogged:false,west:none}",
        "minecraft:air",
        "minecraft:sandstone_wall{east:low,north:none,south:none,up:false,waterlogged:false,west:low}",
        "minecraft:jungle_door{facing:south,half:lower,hinge:right,open:false,powered:false}",
        "minecraft:potted_cactus",
        "minecraft:sandstone_slab{type:bottom,waterlogged:false}",
        "minecraft:jungle_door{facing:south,half:upper,hinge:right,open:false,powered:false}",
        "minecraft:wall_torch{facing:west}",
        "minecraft:wall_torch{facing:east}",
        "minecraft:sandstone_slab{type:top,waterlogged:false}",
        "minecraft:wall_torch{facing:south}",
        "minecraft:jigsaw{orientation:up_north}",
        "minecraft:jigsaw{orientation:south_up}"
    ]
}
