{
    DataVersion: 2856,
    size: [10, 6, 7],
    data: [
        {pos: [0, 0, 0], state: "minecraft:cut_sandstone"},
        {pos: [0, 0, 1], state: "minecraft:cut_sandstone"},
        {pos: [0, 0, 2], state: "minecraft:cut_sandstone"},
        {pos: [0, 0, 3], state: "minecraft:cut_sandstone"},
        {pos: [0, 0, 4], state: "minecraft:cut_sandstone"},
        {pos: [0, 0, 5], state: "minecraft:cut_sandstone"},
        {pos: [0, 0, 6], state: "minecraft:air"},
        {pos: [1, 0, 0], state: "minecraft:cut_sandstone"},
        {pos: [1, 0, 1], state: "minecraft:smooth_sandstone"},
        {pos: [1, 0, 2], state: "minecraft:smooth_sandstone"},
        {pos: [1, 0, 3], state: "minecraft:smooth_sandstone"},
        {pos: [1, 0, 4], state: "minecraft:smooth_sandstone"},
        {pos: [1, 0, 5], state: "minecraft:cut_sandstone"},
        {pos: [1, 0, 6], state: "minecraft:air"},
        {pos: [2, 0, 0], state: "minecraft:cut_sandstone"},
        {pos: [2, 0, 1], state: "minecraft:smooth_sandstone"},
        {pos: [2, 0, 2], state: "minecraft:smooth_sandstone"},
        {pos: [2, 0, 3], state: "minecraft:smooth_sandstone"},
        {pos: [2, 0, 4], state: "minecraft:smooth_sandstone"},
        {pos: [2, 0, 5], state: "minecraft:cut_sandstone"},
        {pos: [2, 0, 6], state: "minecraft:air"},
        {pos: [3, 0, 0], state: "minecraft:cut_sandstone"},
        {pos: [3, 0, 1], state: "minecraft:smooth_sandstone"},
        {pos: [3, 0, 2], state: "minecraft:smooth_sandstone"},
        {pos: [3, 0, 3], state: "minecraft:smooth_sandstone"},
        {pos: [3, 0, 4], state: "minecraft:smooth_sandstone"},
        {pos: [3, 0, 5], state: "minecraft:cut_sandstone"},
        {pos: [3, 0, 6], state: "minecraft:air"},
        {pos: [4, 0, 0], state: "minecraft:cut_sandstone"},
        {pos: [4, 0, 1], state: "minecraft:cut_sandstone"},
        {pos: [4, 0, 2], state: "minecraft:cut_sandstone"},
        {pos: [4, 0, 3], state: "minecraft:cut_sandstone"},
        {pos: [4, 0, 4], state: "minecraft:cut_sandstone"},
        {pos: [4, 0, 5], state: "minecraft:cut_sandstone"},
        {pos: [4, 0, 6], state: "minecraft:cut_sandstone"},
        {pos: [5, 0, 0], state: "minecraft:jigsaw{orientation:north_up}", nbt: {final_state: "minecraft:smooth_sandstone_stairs[facing=south]", id: "minecraft:jigsaw", joint: "aligned", name: "minecraft:building_entrance", pool: "minecraft:empty", target: "minecraft:building_entrance"}},
        {pos: [5, 0, 1], state: "minecraft:cut_sandstone"},
        {pos: [5, 0, 2], state: "minecraft:cut_sandstone"},
        {pos: [5, 0, 3], state: "minecraft:cut_sandstone"},
        {pos: [5, 0, 4], state: "minecraft:cut_sandstone"},
        {pos: [5, 0, 5], state: "minecraft:cut_sandstone"},
        {pos: [5, 0, 6], state: "minecraft:cut_sandstone"},
        {pos: [6, 0, 0], state: "minecraft:smooth_sandstone_stairs{facing:south,half:bottom,shape:straight,waterlogged:false}"},
        {pos: [6, 0, 1], state: "minecraft:cut_sandstone"},
        {pos: [6, 0, 2], state: "minecraft:cut_sandstone"},
        {pos: [6, 0, 3], state: "minecraft:cut_sandstone"},
        {pos: [6, 0, 4], state: "minecraft:cut_sandstone"},
        {pos: [6, 0, 5], state: "minecraft:cut_sandstone"},
        {pos: [6, 0, 6], state: "minecraft:cut_sandstone"},
        {pos: [7, 0, 0], state: "minecraft:smooth_sandstone_stairs{facing:south,half:bottom,shape:straight,waterlogged:false}"},
        {pos: [7, 0, 1], state: "minecraft:cut_sandstone"},
        {pos: [7, 0, 2], state: "minecraft:cut_sandstone"},
        {pos: [7, 0, 3], state: "minecraft:cut_sandstone"},
        {pos: [7, 0, 4], state: "minecraft:cut_sandstone"},
        {pos: [7, 0, 5], state: "minecraft:cut_sandstone"},
        {pos: [7, 0, 6], state: "minecraft:cut_sandstone"},
        {pos: [8, 0, 0], state: "minecraft:air"},
        {pos: [8, 0, 1], state: "minecraft:cut_sandstone"},
        {pos: [8, 0, 2], state: "minecraft:cut_sandstone"},
        {pos: [8, 0, 3], state: "minecraft:cut_sandstone"},
        {pos: [8, 0, 4], state: "minecraft:cut_sandstone"},
        {pos: [8, 0, 5], state: "minecraft:cut_sandstone"},
        {pos: [8, 0, 6], state: "minecraft:cut_sandstone"},
        {pos: [9, 0, 0], state: "minecraft:air"},
        {pos: [9, 0, 1], state: "minecraft:cut_sandstone"},
        {pos: [9, 0, 2], state: "minecraft:cut_sandstone"},
        {pos: [9, 0, 3], state: "minecraft:cut_sandstone"},
        {pos: [9, 0, 4], state: "minecraft:cut_sandstone"},
        {pos: [9, 0, 5], state: "minecraft:cut_sandstone"},
        {pos: [9, 0, 6], state: "minecraft:cut_sandstone"},
        {pos: [0, 1, 0], state: "minecraft:cut_sandstone"},
        {pos: [0, 1, 1], state: "minecraft:smooth_sandstone"},
        {pos: [0, 1, 2], state: "minecraft:smooth_sandstone"},
        {pos: [0, 1, 3], state: "minecraft:smooth_sandstone"},
        {pos: [0, 1, 4], state: "minecraft:smooth_sandstone"},
        {pos: [0, 1, 5], state: "minecraft:cut_sandstone"},
        {pos: [0, 1, 6], state: "minecraft:air"},
        {pos: [1, 1, 0], state: "minecraft:smooth_sandstone"},
        {pos: [1, 1, 1], state: "minecraft:smooth_sandstone_stairs{facing:west,half:bottom,shape:straight,waterlogged:false}"},
        {pos: [1, 1, 2], state: "minecraft:chest{facing:east,type:single,waterlogged:false}", nbt: {LootTable: "minecraft:chests/village/village_weaponsmith", id: "minecraft:chest"}},
        {pos: [1, 1, 3], state: "minecraft:air"},
        {pos: [1, 1, 4], state: "minecraft:air"},
        {pos: [1, 1, 5], state: "minecraft:smooth_sandstone"},
        {pos: [1, 1, 6], state: "minecraft:air"},
        {pos: [2, 1, 0], state: "minecraft:smooth_sandstone"},
        {pos: [2, 1, 1], state: "minecraft:air"},
        {pos: [2, 1, 2], state: "minecraft:air"},
        {pos: [2, 1, 3], state: "minecraft:air"},
        {pos: [2, 1, 4], state: "minecraft:grindstone{face:floor,facing:south}"},
        {pos: [2, 1, 5], state: "minecraft:smooth_sandstone"},
        {pos: [2, 1, 6], state: "minecraft:air"},
        {pos: [3, 1, 0], state: "minecraft:smooth_sandstone"},
        {pos: [3, 1, 1], state: "minecraft:air"},
        {pos: [3, 1, 2], state: "minecraft:air"},
        {pos: [3, 1, 3], state: "minecraft:air"},
        {pos: [3, 1, 4], state: "minecraft:air"},
        {pos: [3, 1, 5], state: "minecraft:smooth_sandstone"},
        {pos: [3, 1, 6], state: "minecraft:air"},
        {pos: [4, 1, 0], state: "minecraft:cut_sandstone"},
        {pos: [4, 1, 1], state: "minecraft:air"},
        {pos: [4, 1, 2], state: "minecraft:air"},
        {pos: [4, 1, 3], state: "minecraft:cut_sandstone"},
        {pos: [4, 1, 4], state: "minecraft:smooth_sandstone"},
        {pos: [4, 1, 5], state: "minecraft:cut_sandstone"},
        {pos: [4, 1, 6], state: "minecraft:cut_sandstone"},
        {pos: [5, 1, 0], state: "minecraft:air"},
        {pos: [5, 1, 1], state: "minecraft:air"},
        {pos: [5, 1, 2], state: "minecraft:air"},
        {pos: [5, 1, 3], state: "minecraft:cobblestone"},
        {pos: [5, 1, 4], state: "minecraft:cobblestone"},
        {pos: [5, 1, 5], state: "minecraft:cobblestone"},
        {pos: [5, 1, 6], state: "minecraft:smooth_sandstone"},
        {pos: [6, 1, 0], state: "minecraft:air"},
        {pos: [6, 1, 1], state: "minecraft:air"},
        {pos: [6, 1, 2], state: "minecraft:air"},
        {pos: [6, 1, 3], state: "minecraft:cobblestone"},
        {pos: [6, 1, 4], state: "minecraft:lava{level:0}"},
        {pos: [6, 1, 5], state: "minecraft:cobblestone"},
        {pos: [6, 1, 6], state: "minecraft:smooth_sandstone"},
        {pos: [7, 1, 0], state: "minecraft:air"},
        {pos: [7, 1, 1], state: "minecraft:air"},
        {pos: [7, 1, 2], state: "minecraft:air"},
        {pos: [7, 1, 3], state: "minecraft:cobblestone"},
        {pos: [7, 1, 4], state: "minecraft:lava{level:0}"},
        {pos: [7, 1, 5], state: "minecraft:cobblestone"},
        {pos: [7, 1, 6], state: "minecraft:smooth_sandstone"},
        {pos: [8, 1, 0], state: "minecraft:air"},
        {pos: [8, 1, 1], state: "minecraft:cut_sandstone"},
        {pos: [8, 1, 2], state: "minecraft:cobblestone"},
        {pos: [8, 1, 3], state: "minecraft:cobblestone"},
        {pos: [8, 1, 4], state: "minecraft:cobblestone"},
        {pos: [8, 1, 5], state: "minecraft:cobblestone"},
        {pos: [8, 1, 6], state: "minecraft:smooth_sandstone"},
        {pos: [9, 1, 0], state: "minecraft:air"},
        {pos: [9, 1, 1], state: "minecraft:cut_sandstone"},
        {pos: [9, 1, 2], state: "minecraft:cut_sandstone"},
        {pos: [9, 1, 3], state: "minecraft:cut_sandstone"},
        {pos: [9, 1, 4], state: "minecraft:cut_sandstone"},
        {pos: [9, 1, 5], state: "minecraft:cut_sandstone"},
        {pos: [9, 1, 6], state: "minecraft:cut_sandstone"},
        {pos: [0, 2, 0], state: "minecraft:cut_sandstone"},
        {pos: [0, 2, 1], state: "minecraft:smooth_sandstone"},
        {pos: [0, 2, 2], state: "minecraft:smooth_sandstone"},
        {pos: [0, 2, 3], state: "minecraft:smooth_sandstone"},
        {pos: [0, 2, 4], state: "minecraft:smooth_sandstone"},
        {pos: [0, 2, 5], state: "minecraft:cut_sandstone"},
        {pos: [0, 2, 6], state: "minecraft:air"},
        {pos: [1, 2, 0], state: "minecraft:smooth_sandstone"},
        {pos: [1, 2, 1], state: "minecraft:air"},
        {pos: [1, 2, 2], state: "minecraft:air"},
        {pos: [1, 2, 3], state: "minecraft:air"},
        {pos: [1, 2, 4], state: "minecraft:air"},
        {pos: [1, 2, 5], state: "minecraft:smooth_sandstone"},
        {pos: [1, 2, 6], state: "minecraft:air"},
        {pos: [2, 2, 0], state: "minecraft:sandstone_slab{type:bottom,waterlogged:false}"},
        {pos: [2, 2, 1], state: "minecraft:air"},
        {pos: [2, 2, 2], state: "minecraft:air"},
        {pos: [2, 2, 3], state: "minecraft:air"},
        {pos: [2, 2, 4], state: "minecraft:air"},
        {pos: [2, 2, 5], state: "minecraft:sandstone_slab{type:bottom,waterlogged:false}"},
        {pos: [2, 2, 6], state: "minecraft:air"},
        {pos: [3, 2, 0], state: "minecraft:smooth_sandstone"},
        {pos: [3, 2, 1], state: "minecraft:air"},
        {pos: [3, 2, 2], state: "minecraft:air"},
        {pos: [3, 2, 3], state: "minecraft:air"},
        {pos: [3, 2, 4], state: "minecraft:air"},
        {pos: [3, 2, 5], state: "minecraft:smooth_sandstone"},
        {pos: [3, 2, 6], state: "minecraft:air"},
        {pos: [4, 2, 0], state: "minecraft:cut_sandstone"},
        {pos: [4, 2, 1], state: "minecraft:air"},
        {pos: [4, 2, 2], state: "minecraft:air"},
        {pos: [4, 2, 3], state: "minecraft:cut_sandstone"},
        {pos: [4, 2, 4], state: "minecraft:smooth_sandstone"},
        {pos: [4, 2, 5], state: "minecraft:cut_sandstone"},
        {pos: [4, 2, 6], state: "minecraft:cut_sandstone"},
        {pos: [5, 2, 0], state: "minecraft:air"},
        {pos: [5, 2, 1], state: "minecraft:air"},
        {pos: [5, 2, 2], state: "minecraft:air"},
        {pos: [5, 2, 3], state: "minecraft:air"},
        {pos: [5, 2, 4], state: "minecraft:furnace{facing:north,lit:false}", nbt: {BurnTime: 0s, CookTime: 0s, CookTimeTotal: 0s, Items: [], RecipesUsed: {}, id: "minecraft:furnace"}},
        {pos: [5, 2, 5], state: "minecraft:cobblestone"},
        {pos: [5, 2, 6], state: "minecraft:smooth_sandstone"},
        {pos: [6, 2, 0], state: "minecraft:air"},
        {pos: [6, 2, 1], state: "minecraft:air"},
        {pos: [6, 2, 2], state: "minecraft:air"},
        {pos: [6, 2, 3], state: "minecraft:air"},
        {pos: [6, 2, 4], state: "minecraft:air"},
        {pos: [6, 2, 5], state: "minecraft:cobblestone"},
        {pos: [6, 2, 6], state: "minecraft:smooth_sandstone"},
        {pos: [7, 2, 0], state: "minecraft:air"},
        {pos: [7, 2, 1], state: "minecraft:air"},
        {pos: [7, 2, 2], state: "minecraft:air"},
        {pos: [7, 2, 3], state: "minecraft:air"},
        {pos: [7, 2, 4], state: "minecraft:air"},
        {pos: [7, 2, 5], state: "minecraft:cobblestone"},
        {pos: [7, 2, 6], state: "minecraft:smooth_sandstone"},
        {pos: [8, 2, 0], state: "minecraft:air"},
        {pos: [8, 2, 1], state: "minecraft:sandstone_wall{east:none,north:none,south:none,up:true,waterlogged:false,west:none}"},
        {pos: [8, 2, 2], state: "minecraft:iron_bars{east:false,north:false,south:true,waterlogged:false,west:false}"},
        {pos: [8, 2, 3], state: "minecraft:iron_bars{east:false,north:true,south:true,waterlogged:false,west:false}"},
        {pos: [8, 2, 4], state: "minecraft:iron_bars{east:false,north:true,south:true,waterlogged:false,west:false}"},
        {pos: [8, 2, 5], state: "minecraft:cobblestone"},
        {pos: [8, 2, 6], state: "minecraft:smooth_sandstone"},
        {pos: [9, 2, 0], state: "minecraft:air"},
        {pos: [9, 2, 1], state: "minecraft:air"},
        {pos: [9, 2, 2], state: "minecraft:potted_cactus"},
        {pos: [9, 2, 3], state: "minecraft:air"},
        {pos: [9, 2, 4], state: "minecraft:air"},
        {pos: [9, 2, 5], state: "minecraft:cut_sandstone"},
        {pos: [9, 2, 6], state: "minecraft:cut_sandstone"},
        {pos: [0, 3, 0], state: "minecraft:cut_sandstone"},
        {pos: [0, 3, 1], state: "minecraft:smooth_sandstone"},
        {pos: [0, 3, 2], state: "minecraft:smooth_sandstone"},
        {pos: [0, 3, 3], state: "minecraft:smooth_sandstone"},
        {pos: [0, 3, 4], state: "minecraft:smooth_sandstone"},
        {pos: [0, 3, 5], state: "minecraft:cut_sandstone"},
        {pos: [0, 3, 6], state: "minecraft:air"},
        {pos: [1, 3, 0], state: "minecraft:smooth_sandstone"},
        {pos: [1, 3, 1], state: "minecraft:air"},
        {pos: [1, 3, 2], state: "minecraft:air"},
        {pos: [1, 3, 3], state: "minecraft:air"},
        {pos: [1, 3, 4], state: "minecraft:air"},
        {pos: [1, 3, 5], state: "minecraft:smooth_sandstone"},
        {pos: [1, 3, 6], state: "minecraft:air"},
        {pos: [2, 3, 0], state: "minecraft:sandstone_slab{type:top,waterlogged:false}"},
        {pos: [2, 3, 1], state: "minecraft:air"},
        {pos: [2, 3, 2], state: "minecraft:air"},
        {pos: [2, 3, 3], state: "minecraft:air"},
        {pos: [2, 3, 4], state: "minecraft:air"},
        {pos: [2, 3, 5], state: "minecraft:sandstone_slab{type:top,waterlogged:false}"},
        {pos: [2, 3, 6], state: "minecraft:air"},
        {pos: [3, 3, 0], state: "minecraft:smooth_sandstone"},
        {pos: [3, 3, 1], state: "minecraft:air"},
        {pos: [3, 3, 2], state: "minecraft:air"},
        {pos: [3, 3, 3], state: "minecraft:wall_torch{facing:west}"},
        {pos: [3, 3, 4], state: "minecraft:air"},
        {pos: [3, 3, 5], state: "minecraft:smooth_sandstone"},
        {pos: [3, 3, 6], state: "minecraft:air"},
        {pos: [4, 3, 0], state: "minecraft:cut_sandstone"},
        {pos: [4, 3, 1], state: "minecraft:smooth_sandstone_stairs{facing:north,half:top,shape:straight,waterlogged:false}"},
        {pos: [4, 3, 2], state: "minecraft:smooth_sandstone_stairs{facing:south,half:top,shape:straight,waterlogged:false}"},
        {pos: [4, 3, 3], state: "minecraft:cut_sandstone"},
        {pos: [4, 3, 4], state: "minecraft:smooth_sandstone"},
        {pos: [4, 3, 5], state: "minecraft:cut_sandstone"},
        {pos: [4, 3, 6], state: "minecraft:cut_sandstone"},
        {pos: [5, 3, 0], state: "minecraft:air"},
        {pos: [5, 3, 1], state: "minecraft:air"},
        {pos: [5, 3, 2], state: "minecraft:air"},
        {pos: [5, 3, 3], state: "minecraft:air"},
        {pos: [5, 3, 4], state: "minecraft:furnace{facing:north,lit:false}", nbt: {BurnTime: 0s, CookTime: 0s, CookTimeTotal: 0s, Items: [], RecipesUsed: {}, id: "minecraft:furnace"}},
        {pos: [5, 3, 5], state: "minecraft:cobblestone"},
        {pos: [5, 3, 6], state: "minecraft:smooth_sandstone"},
        {pos: [6, 3, 0], state: "minecraft:air"},
        {pos: [6, 3, 1], state: "minecraft:air"},
        {pos: [6, 3, 2], state: "minecraft:air"},
        {pos: [6, 3, 3], state: "minecraft:air"},
        {pos: [6, 3, 4], state: "minecraft:air"},
        {pos: [6, 3, 5], state: "minecraft:cobblestone"},
        {pos: [6, 3, 6], state: "minecraft:smooth_sandstone"},
        {pos: [7, 3, 0], state: "minecraft:air"},
        {pos: [7, 3, 1], state: "minecraft:air"},
        {pos: [7, 3, 2], state: "minecraft:air"},
        {pos: [7, 3, 3], state: "minecraft:air"},
        {pos: [7, 3, 4], state: "minecraft:air"},
        {pos: [7, 3, 5], state: "minecraft:cobblestone"},
        {pos: [7, 3, 6], state: "minecraft:smooth_sandstone"},
        {pos: [8, 3, 0], state: "minecraft:air"},
        {pos: [8, 3, 1], state: "minecraft:sandstone_wall{east:none,north:none,south:none,up:true,waterlogged:false,west:none}"},
        {pos: [8, 3, 2], state: "minecraft:iron_bars{east:false,north:false,south:true,waterlogged:false,west:false}"},
        {pos: [8, 3, 3], state: "minecraft:iron_bars{east:false,north:true,south:true,waterlogged:false,west:false}"},
        {pos: [8, 3, 4], state: "minecraft:iron_bars{east:false,north:true,south:true,waterlogged:false,west:false}"},
        {pos: [8, 3, 5], state: "minecraft:cobblestone"},
        {pos: [8, 3, 6], state: "minecraft:smooth_sandstone"},
        {pos: [9, 3, 0], state: "minecraft:air"},
        {pos: [9, 3, 1], state: "minecraft:air"},
        {pos: [9, 3, 2], state: "minecraft:air"},
        {pos: [9, 3, 3], state: "minecraft:air"},
        {pos: [9, 3, 4], state: "minecraft:air"},
        {pos: [9, 3, 5], state: "minecraft:cut_sandstone"},
        {pos: [9, 3, 6], state: "minecraft:cut_sandstone"},
        {pos: [0, 4, 0], state: "minecraft:cut_sandstone"},
        {pos: [0, 4, 1], state: "minecraft:smooth_sandstone"},
        {pos: [0, 4, 2], state: "minecraft:smooth_sandstone"},
        {pos: [0, 4, 3], state: "minecraft:smooth_sandstone"},
        {pos: [0, 4, 4], state: "minecraft:smooth_sandstone"},
        {pos: [0, 4, 5], state: "minecraft:cut_sandstone"},
        {pos: [0, 4, 6], state: "minecraft:air"},
        {pos: [1, 4, 0], state: "minecraft:smooth_sandstone"},
        {pos: [1, 4, 1], state: "minecraft:air"},
        {pos: [1, 4, 2], state: "minecraft:air"},
        {pos: [1, 4, 3], state: "minecraft:air"},
        {pos: [1, 4, 4], state: "minecraft:air"},
        {pos: [1, 4, 5], state: "minecraft:smooth_sandstone"},
        {pos: [1, 4, 6], state: "minecraft:air"},
        {pos: [2, 4, 0], state: "minecraft:smooth_sandstone"},
        {pos: [2, 4, 1], state: "minecraft:air"},
        {pos: [2, 4, 2], state: "minecraft:air"},
        {pos: [2, 4, 3], state: "minecraft:air"},
        {pos: [2, 4, 4], state: "minecraft:air"},
        {pos: [2, 4, 5], state: "minecraft:smooth_sandstone"},
        {pos: [2, 4, 6], state: "minecraft:air"},
        {pos: [3, 4, 0], state: "minecraft:smooth_sandstone"},
        {pos: [3, 4, 1], state: "minecraft:air"},
        {pos: [3, 4, 2], state: "minecraft:air"},
        {pos: [3, 4, 3], state: "minecraft:air"},
        {pos: [3, 4, 4], state: "minecraft:air"},
        {pos: [3, 4, 5], state: "minecraft:smooth_sandstone"},
        {pos: [3, 4, 6], state: "minecraft:air"},
        {pos: [4, 4, 0], state: "minecraft:cut_sandstone"},
        {pos: [4, 4, 1], state: "minecraft:smooth_sandstone"},
        {pos: [4, 4, 2], state: "minecraft:smooth_sandstone"},
        {pos: [4, 4, 3], state: "minecraft:cut_sandstone"},
        {pos: [4, 4, 4], state: "minecraft:smooth_sandstone"},
        {pos: [4, 4, 5], state: "minecraft:smooth_sandstone"},
        {pos: [4, 4, 6], state: "minecraft:cut_sandstone"},
        {pos: [5, 4, 0], state: "minecraft:air"},
        {pos: [5, 4, 1], state: "minecraft:air"},
        {pos: [5, 4, 2], state: "minecraft:air"},
        {pos: [5, 4, 3], state: "minecraft:air"},
        {pos: [5, 4, 4], state: "minecraft:air"},
        {pos: [5, 4, 5], state: "minecraft:cobblestone"},
        {pos: [5, 4, 6], state: "minecraft:smooth_sandstone"},
        {pos: [6, 4, 0], state: "minecraft:air"},
        {pos: [6, 4, 1], state: "minecraft:air"},
        {pos: [6, 4, 2], state: "minecraft:air"},
        {pos: [6, 4, 3], state: "minecraft:air"},
        {pos: [6, 4, 4], state: "minecraft:air"},
        {pos: [6, 4, 5], state: "minecraft:cobblestone"},
        {pos: [6, 4, 6], state: "minecraft:smooth_sandstone"},
        {pos: [7, 4, 0], state: "minecraft:air"},
        {pos: [7, 4, 1], state: "minecraft:air"},
        {pos: [7, 4, 2], state: "minecraft:air"},
        {pos: [7, 4, 3], state: "minecraft:air"},
        {pos: [7, 4, 4], state: "minecraft:air"},
        {pos: [7, 4, 5], state: "minecraft:cobblestone"},
        {pos: [7, 4, 6], state: "minecraft:smooth_sandstone"},
        {pos: [8, 4, 0], state: "minecraft:air"},
        {pos: [8, 4, 1], state: "minecraft:sandstone_wall{east:none,north:none,south:none,up:true,waterlogged:false,west:none}"},
        {pos: [8, 4, 2], state: "minecraft:iron_bars{east:false,north:false,south:true,waterlogged:false,west:false}"},
        {pos: [8, 4, 3], state: "minecraft:iron_bars{east:false,north:true,south:true,waterlogged:false,west:false}"},
        {pos: [8, 4, 4], state: "minecraft:iron_bars{east:false,north:true,south:true,waterlogged:false,west:false}"},
        {pos: [8, 4, 5], state: "minecraft:cobblestone"},
        {pos: [8, 4, 6], state: "minecraft:smooth_sandstone"},
        {pos: [9, 4, 0], state: "minecraft:air"},
        {pos: [9, 4, 1], state: "minecraft:air"},
        {pos: [9, 4, 2], state: "minecraft:air"},
        {pos: [9, 4, 3], state: "minecraft:air"},
        {pos: [9, 4, 4], state: "minecraft:air"},
        {pos: [9, 4, 5], state: "minecraft:cut_sandstone"},
        {pos: [9, 4, 6], state: "minecraft:cut_sandstone"},
        {pos: [0, 5, 0], state: "minecraft:cut_sandstone"},
        {pos: [0, 5, 1], state: "minecraft:smooth_sandstone_slab{type:bottom,waterlogged:false}"},
        {pos: [0, 5, 2], state: "minecraft:smooth_sandstone_slab{type:bottom,waterlogged:false}"},
        {pos: [0, 5, 3], state: "minecraft:smooth_sandstone_slab{type:bottom,waterlogged:false}"},
        {pos: [0, 5, 4], state: "minecraft:smooth_sandstone_slab{type:bottom,waterlogged:false}"},
        {pos: [0, 5, 5], state: "minecraft:cut_sandstone"},
        {pos: [0, 5, 6], state: "minecraft:air"},
        {pos: [1, 5, 0], state: "minecraft:smooth_sandstone_slab{type:bottom,waterlogged:false}"},
        {pos: [1, 5, 1], state: "minecraft:smooth_sandstone_slab{type:bottom,waterlogged:false}"},
        {pos: [1, 5, 2], state: "minecraft:smooth_sandstone_slab{type:bottom,waterlogged:false}"},
        {pos: [1, 5, 3], state: "minecraft:smooth_sandstone_slab{type:bottom,waterlogged:false}"},
        {pos: [1, 5, 4], state: "minecraft:smooth_sandstone_slab{type:bottom,waterlogged:false}"},
        {pos: [1, 5, 5], state: "minecraft:smooth_sandstone_slab{type:bottom,waterlogged:false}"},
        {pos: [1, 5, 6], state: "minecraft:air"},
        {pos: [2, 5, 0], state: "minecraft:smooth_sandstone_slab{type:bottom,waterlogged:false}"},
        {pos: [2, 5, 1], state: "minecraft:smooth_sandstone_slab{type:bottom,waterlogged:false}"},
        {pos: [2, 5, 2], state: "minecraft:smooth_sandstone_slab{type:bottom,waterlogged:false}"},
        {pos: [2, 5, 3], state: "minecraft:smooth_sandstone_slab{type:bottom,waterlogged:false}"},
        {pos: [2, 5, 4], state: "minecraft:smooth_sandstone_slab{type:bottom,waterlogged:false}"},
        {pos: [2, 5, 5], state: "minecraft:smooth_sandstone_slab{type:bottom,waterlogged:false}"},
        {pos: [2, 5, 6], state: "minecraft:air"},
        {pos: [3, 5, 0], state: "minecraft:smooth_sandstone_slab{type:bottom,waterlogged:false}"},
        {pos: [3, 5, 1], state: "minecraft:smooth_sandstone_slab{type:bottom,waterlogged:false}"},
        {pos: [3, 5, 2], state: "minecraft:smooth_sandstone_slab{type:bottom,waterlogged:false}"},
        {pos: [3, 5, 3], state: "minecraft:smooth_sandstone_slab{type:bottom,waterlogged:false}"},
        {pos: [3, 5, 4], state: "minecraft:smooth_sandstone_slab{type:bottom,waterlogged:false}"},
        {pos: [3, 5, 5], state: "minecraft:smooth_sandstone_slab{type:bottom,waterlogged:false}"},
        {pos: [3, 5, 6], state: "minecraft:air"},
        {pos: [4, 5, 0], state: "minecraft:cut_sandstone"},
        {pos: [4, 5, 1], state: "minecraft:smooth_sandstone_slab{type:bottom,waterlogged:false}"},
        {pos: [4, 5, 2], state: "minecraft:smooth_sandstone_slab{type:bottom,waterlogged:false}"},
        {pos: [4, 5, 3], state: "minecraft:smooth_sandstone_slab{type:bottom,waterlogged:false}"},
        {pos: [4, 5, 4], state: "minecraft:smooth_sandstone_slab{type:bottom,waterlogged:false}"},
        {pos: [4, 5, 5], state: "minecraft:smooth_sandstone_slab{type:bottom,waterlogged:false}"},
        {pos: [4, 5, 6], state: "minecraft:cut_sandstone"},
        {pos: [5, 5, 0], state: "minecraft:air"},
        {pos: [5, 5, 1], state: "minecraft:smooth_sandstone_slab{type:bottom,waterlogged:false}"},
        {pos: [5, 5, 2], state: "minecraft:smooth_sandstone_slab{type:bottom,waterlogged:false}"},
        {pos: [5, 5, 3], state: "minecraft:smooth_sandstone_slab{type:bottom,waterlogged:false}"},
        {pos: [5, 5, 4], state: "minecraft:smooth_sandstone_slab{type:bottom,waterlogged:false}"},
        {pos: [5, 5, 5], state: "minecraft:smooth_sandstone_slab{type:bottom,waterlogged:false}"},
        {pos: [5, 5, 6], state: "minecraft:smooth_sandstone_slab{type:bottom,waterlogged:false}"},
        {pos: [6, 5, 0], state: "minecraft:air"},
        {pos: [6, 5, 1], state: "minecraft:smooth_sandstone_slab{type:bottom,waterlogged:false}"},
        {pos: [6, 5, 2], state: "minecraft:smooth_sandstone_slab{type:bottom,waterlogged:false}"},
        {pos: [6, 5, 3], state: "minecraft:air"},
        {pos: [6, 5, 4], state: "minecraft:air"},
        {pos: [6, 5, 5], state: "minecraft:smooth_sandstone_slab{type:bottom,waterlogged:false}"},
        {pos: [6, 5, 6], state: "minecraft:smooth_sandstone_slab{type:bottom,waterlogged:false}"},
        {pos: [7, 5, 0], state: "minecraft:air"},
        {pos: [7, 5, 1], state: "minecraft:smooth_sandstone_slab{type:bottom,waterlogged:false}"},
        {pos: [7, 5, 2], state: "minecraft:smooth_sandstone_slab{type:bottom,waterlogged:false}"},
        {pos: [7, 5, 3], state: "minecraft:air"},
        {pos: [7, 5, 4], state: "minecraft:air"},
        {pos: [7, 5, 5], state: "minecraft:smooth_sandstone_slab{type:bottom,waterlogged:false}"},
        {pos: [7, 5, 6], state: "minecraft:smooth_sandstone_slab{type:bottom,waterlogged:false}"},
        {pos: [8, 5, 0], state: "minecraft:air"},
        {pos: [8, 5, 1], state: "minecraft:smooth_sandstone_slab{type:bottom,waterlogged:false}"},
        {pos: [8, 5, 2], state: "minecraft:smooth_sandstone_slab{type:bottom,waterlogged:false}"},
        {pos: [8, 5, 3], state: "minecraft:smooth_sandstone_slab{type:bottom,waterlogged:false}"},
        {pos: [8, 5, 4], state: "minecraft:smooth_sandstone_slab{type:bottom,waterlogged:false}"},
        {pos: [8, 5, 5], state: "minecraft:smooth_sandstone_slab{type:bottom,waterlogged:false}"},
        {pos: [8, 5, 6], state: "minecraft:smooth_sandstone_slab{type:bottom,waterlogged:false}"},
        {pos: [9, 5, 0], state: "minecraft:air"},
        {pos: [9, 5, 1], state: "minecraft:air"},
        {pos: [9, 5, 2], state: "minecraft:air"},
        {pos: [9, 5, 3], state: "minecraft:air"},
        {pos: [9, 5, 4], state: "minecraft:air"},
        {pos: [9, 5, 5], state: "minecraft:cut_sandstone"},
        {pos: [9, 5, 6], state: "minecraft:cut_sandstone"}
    ],
    entities: [],
    palette: [
        "minecraft:cut_sandstone",
        "minecraft:smooth_sandstone",
        "minecraft:cobblestone",
        "minecraft:air",
        "minecraft:smooth_sandstone_stairs{facing:south,half:bottom,shape:straight,waterlogged:false}",
        "minecraft:smooth_sandstone_stairs{facing:west,half:bottom,shape:straight,waterlogged:false}",
        "minecraft:grindstone{face:floor,facing:south}",
        "minecraft:lava{level:0}",
        "minecraft:sandstone_slab{type:bottom,waterlogged:false}",
        "minecraft:sandstone_wall{east:none,north:none,south:none,up:true,waterlogged:false,west:none}",
        "minecraft:iron_bars{east:false,north:false,south:true,waterlogged:false,west:false}",
        "minecraft:iron_bars{east:false,north:true,south:true,waterlogged:false,west:false}",
        "minecraft:potted_cactus",
        "minecraft:sandstone_slab{type:top,waterlogged:false}",
        "minecraft:wall_torch{facing:west}",
        "minecraft:smooth_sandstone_stairs{facing:north,half:top,shape:straight,waterlogged:false}",
        "minecraft:smooth_sandstone_stairs{facing:south,half:top,shape:straight,waterlogged:false}",
        "minecraft:smooth_sandstone_slab{type:bottom,waterlogged:false}",
        "minecraft:jigsaw{orientation:north_up}",
        "minecraft:chest{facing:east,type:single,waterlogged:false}",
        "minecraft:furnace{facing:north,lit:false}"
    ]
}
