{
    size: [11, 7, 13],
    data: [
        {pos: [0, 0, 0], state: "minecraft:sand"},
        {pos: [0, 0, 1], state: "minecraft:sand"},
        {pos: [0, 0, 2], state: "minecraft:sand"},
        {pos: [0, 0, 3], state: "minecraft:sand"},
        {pos: [0, 0, 4], state: "minecraft:sand"},
        {pos: [0, 0, 5], state: "minecraft:sand"},
        {pos: [0, 0, 6], state: "minecraft:sand"},
        {pos: [0, 0, 7], state: "minecraft:sand"},
        {pos: [0, 0, 8], state: "minecraft:sand"},
        {pos: [0, 0, 9], state: "minecraft:sand"},
        {pos: [0, 0, 10], state: "minecraft:sand"},
        {pos: [0, 0, 11], state: "minecraft:sand"},
        {pos: [0, 0, 12], state: "minecraft:sand"},
        {pos: [1, 0, 0], state: "minecraft:sand"},
        {pos: [1, 0, 1], state: "minecraft:sand"},
        {pos: [1, 0, 2], state: "minecraft:sand"},
        {pos: [1, 0, 3], state: "minecraft:sand"},
        {pos: [1, 0, 4], state: "minecraft:sand"},
        {pos: [1, 0, 5], state: "minecraft:sand"},
        {pos: [1, 0, 6], state: "minecraft:sand"},
        {pos: [1, 0, 7], state: "minecraft:sand"},
        {pos: [1, 0, 8], state: "minecraft:sand"},
        {pos: [1, 0, 9], state: "minecraft:sand"},
        {pos: [1, 0, 10], state: "minecraft:sand"},
        {pos: [1, 0, 11], state: "minecraft:sand"},
        {pos: [1, 0, 12], state: "minecraft:sand"},
        {pos: [2, 0, 0], state: "minecraft:sand"},
        {pos: [2, 0, 1], state: "minecraft:sand"},
        {pos: [2, 0, 2], state: "minecraft:sand"},
        {pos: [2, 0, 3], state: "minecraft:sand"},
        {pos: [2, 0, 4], state: "minecraft:sand"},
        {pos: [2, 0, 5], state: "minecraft:sand"},
        {pos: [2, 0, 6], state: "minecraft:sand"},
        {pos: [2, 0, 7], state: "minecraft:sand"},
        {pos: [2, 0, 8], state: "minecraft:sand"},
        {pos: [2, 0, 9], state: "minecraft:sand"},
        {pos: [2, 0, 10], state: "minecraft:sand"},
        {pos: [2, 0, 11], state: "minecraft:sand"},
        {pos: [2, 0, 12], state: "minecraft:sand"},
        {pos: [3, 0, 0], state: "minecraft:sand"},
        {pos: [3, 0, 1], state: "minecraft:sand"},
        {pos: [3, 0, 2], state: "minecraft:sand"},
        {pos: [3, 0, 3], state: "minecraft:sand"},
        {pos: [3, 0, 4], state: "minecraft:sand"},
        {pos: [3, 0, 5], state: "minecraft:sand"},
        {pos: [3, 0, 6], state: "minecraft:sand"},
        {pos: [3, 0, 7], state: "minecraft:sand"},
        {pos: [3, 0, 8], state: "minecraft:sand"},
        {pos: [3, 0, 9], state: "minecraft:sand"},
        {pos: [3, 0, 10], state: "minecraft:sand"},
        {pos: [3, 0, 11], state: "minecraft:sand"},
        {pos: [3, 0, 12], state: "minecraft:sand"},
        {pos: [4, 0, 0], state: "minecraft:sand"},
        {pos: [4, 0, 1], state: "minecraft:sand"},
        {pos: [4, 0, 2], state: "minecraft:sand"},
        {pos: [4, 0, 3], state: "minecraft:sand"},
        {pos: [4, 0, 4], state: "minecraft:sand"},
        {pos: [4, 0, 5], state: "minecraft:sand"},
        {pos: [4, 0, 6], state: "minecraft:sand"},
        {pos: [4, 0, 7], state: "minecraft:sand"},
        {pos: [4, 0, 8], state: "minecraft:sand"},
        {pos: [4, 0, 9], state: "minecraft:sand"},
        {pos: [4, 0, 10], state: "minecraft:sand"},
        {pos: [4, 0, 11], state: "minecraft:sand"},
        {pos: [4, 0, 12], state: "minecraft:sand"},
        {pos: [5, 0, 0], state: "minecraft:sand"},
        {pos: [5, 0, 1], state: "minecraft:sand"},
        {pos: [5, 0, 2], state: "minecraft:sand"},
        {pos: [5, 0, 3], state: "minecraft:sand"},
        {pos: [5, 0, 4], state: "minecraft:sand"},
        {pos: [5, 0, 5], state: "minecraft:sand"},
        {pos: [5, 0, 6], state: "minecraft:sand"},
        {pos: [5, 0, 7], state: "minecraft:sand"},
        {pos: [5, 0, 8], state: "minecraft:sand"},
        {pos: [5, 0, 9], state: "minecraft:sand"},
        {pos: [5, 0, 10], state: "minecraft:sand"},
        {pos: [5, 0, 11], state: "minecraft:sand"},
        {pos: [5, 0, 12], state: "minecraft:sand"},
        {pos: [6, 0, 0], state: "minecraft:sand"},
        {pos: [6, 0, 1], state: "minecraft:sand"},
        {pos: [6, 0, 2], state: "minecraft:sand"},
        {pos: [6, 0, 3], state: "minecraft:sand"},
        {pos: [6, 0, 4], state: "minecraft:sand"},
        {pos: [6, 0, 5], state: "minecraft:sand"},
        {pos: [6, 0, 6], state: "minecraft:sand"},
        {pos: [6, 0, 7], state: "minecraft:sand"},
        {pos: [6, 0, 8], state: "minecraft:sand"},
        {pos: [6, 0, 9], state: "minecraft:sand"},
        {pos: [6, 0, 10], state: "minecraft:sand"},
        {pos: [6, 0, 11], state: "minecraft:sand"},
        {pos: [6, 0, 12], state: "minecraft:sand"},
        {pos: [7, 0, 0], state: "minecraft:sand"},
        {pos: [7, 0, 1], state: "minecraft:sand"},
        {pos: [7, 0, 2], state: "minecraft:sand"},
        {pos: [7, 0, 3], state: "minecraft:sand"},
        {pos: [7, 0, 4], state: "minecraft:sand"},
        {pos: [7, 0, 5], state: "minecraft:sand"},
        {pos: [7, 0, 6], state: "minecraft:sand"},
        {pos: [7, 0, 7], state: "minecraft:sand"},
        {pos: [7, 0, 8], state: "minecraft:sand"},
        {pos: [7, 0, 9], state: "minecraft:sand"},
        {pos: [7, 0, 10], state: "minecraft:sand"},
        {pos: [7, 0, 11], state: "minecraft:sand"},
        {pos: [7, 0, 12], state: "minecraft:sand"},
        {pos: [8, 0, 0], state: "minecraft:sand"},
        {pos: [8, 0, 1], state: "minecraft:sand"},
        {pos: [8, 0, 2], state: "minecraft:sand"},
        {pos: [8, 0, 3], state: "minecraft:sand"},
        {pos: [8, 0, 4], state: "minecraft:sand"},
        {pos: [8, 0, 5], state: "minecraft:sand"},
        {pos: [8, 0, 6], state: "minecraft:sand"},
        {pos: [8, 0, 7], state: "minecraft:sand"},
        {pos: [8, 0, 8], state: "minecraft:sand"},
        {pos: [8, 0, 9], state: "minecraft:sand"},
        {pos: [8, 0, 10], state: "minecraft:sand"},
        {pos: [8, 0, 11], state: "minecraft:sand"},
        {pos: [8, 0, 12], state: "minecraft:sand"},
        {pos: [9, 0, 0], state: "minecraft:sand"},
        {pos: [9, 0, 1], state: "minecraft:sand"},
        {pos: [9, 0, 2], state: "minecraft:sand"},
        {pos: [9, 0, 3], state: "minecraft:sand"},
        {pos: [9, 0, 4], state: "minecraft:sand"},
        {pos: [9, 0, 5], state: "minecraft:sand"},
        {pos: [9, 0, 6], state: "minecraft:sand"},
        {pos: [9, 0, 7], state: "minecraft:sand"},
        {pos: [9, 0, 8], state: "minecraft:sand"},
        {pos: [9, 0, 9], state: "minecraft:sand"},
        {pos: [9, 0, 10], state: "minecraft:sand"},
        {pos: [9, 0, 11], state: "minecraft:sand"},
        {pos: [9, 0, 12], state: "minecraft:sand"},
        {pos: [10, 0, 0], state: "minecraft:sand"},
        {pos: [10, 0, 1], state: "minecraft:sand"},
        {pos: [10, 0, 2], state: "minecraft:sand"},
        {pos: [10, 0, 3], state: "minecraft:sand"},
        {pos: [10, 0, 4], state: "minecraft:sand"},
        {pos: [10, 0, 5], state: "minecraft:sand"},
        {pos: [10, 0, 6], state: "minecraft:sand"},
        {pos: [10, 0, 7], state: "minecraft:sand"},
        {pos: [10, 0, 8], state: "minecraft:sand"},
        {pos: [10, 0, 9], state: "minecraft:sand"},
        {pos: [10, 0, 10], state: "minecraft:sand"},
        {pos: [10, 0, 11], state: "minecraft:sand"},
        {pos: [10, 0, 12], state: "minecraft:sand"},
        {pos: [0, 1, 2], state: "minecraft:sand"},
        {pos: [0, 1, 5], state: "minecraft:sand"},
        {pos: [0, 1, 6], state: "minecraft:sand"},
        {pos: [0, 1, 7], state: "minecraft:sand"},
        {pos: [1, 1, 2], state: "minecraft:sand"},
        {pos: [1, 1, 3], state: "minecraft:sand"},
        {pos: [1, 1, 4], state: "minecraft:sand"},
        {pos: [1, 1, 5], state: "minecraft:farmland{moisture:7}"},
        {pos: [1, 1, 6], state: "minecraft:farmland{moisture:7}"},
        {pos: [1, 1, 7], state: "minecraft:farmland{moisture:7}"},
        {pos: [1, 1, 8], state: "minecraft:sand"},
        {pos: [1, 1, 9], state: "minecraft:sand"},
        {pos: [1, 1, 10], state: "minecraft:sand"},
        {pos: [2, 1, 2], state: "minecraft:sand"},
        {pos: [2, 1, 3], state: "minecraft:farmland{moisture:7}"},
        {pos: [2, 1, 4], state: "minecraft:farmland{moisture:7}"},
        {pos: [2, 1, 5], state: "minecraft:farmland{moisture:7}"},
        {pos: [2, 1, 6], state: "minecraft:water{level:0}"},
        {pos: [2, 1, 7], state: "minecraft:farmland{moisture:7}"},
        {pos: [2, 1, 8], state: "minecraft:farmland{moisture:7}"},
        {pos: [2, 1, 9], state: "minecraft:farmland{moisture:7}"},
        {pos: [2, 1, 10], state: "minecraft:sand"},
        {pos: [2, 1, 11], state: "minecraft:sand"},
        {pos: [2, 1, 12], state: "minecraft:sand"},
        {pos: [3, 1, 1], state: "minecraft:sand"},
        {pos: [3, 1, 2], state: "minecraft:sand"},
        {pos: [3, 1, 3], state: "minecraft:sand"},
        {pos: [3, 1, 4], state: "minecraft:farmland{moisture:7}"},
        {pos: [3, 1, 5], state: "minecraft:farmland{moisture:7}"},
        {pos: [3, 1, 6], state: "minecraft:farmland{moisture:7}"},
        {pos: [3, 1, 7], state: "minecraft:farmland{moisture:7}"},
        {pos: [3, 1, 8], state: "minecraft:farmland{moisture:7}"},
        {pos: [3, 1, 9], state: "minecraft:sand"},
        {pos: [3, 1, 10], state: "minecraft:sand"},
        {pos: [3, 1, 11], state: "minecraft:sand"},
        {pos: [3, 1, 12], state: "minecraft:sand"},
        {pos: [4, 1, 1], state: "minecraft:sand"},
        {pos: [4, 1, 2], state: "minecraft:sand"},
        {pos: [4, 1, 3], state: "minecraft:sand"},
        {pos: [4, 1, 4], state: "minecraft:sand"},
        {pos: [4, 1, 5], state: "minecraft:farmland{moisture:7}"},
        {pos: [4, 1, 6], state: "minecraft:farmland{moisture:7}"},
        {pos: [4, 1, 7], state: "minecraft:farmland{moisture:7}"},
        {pos: [4, 1, 8], state: "minecraft:farmland{moisture:7}"},
        {pos: [4, 1, 9], state: "minecraft:farmland{moisture:7}"},
        {pos: [4, 1, 10], state: "minecraft:sand"},
        {pos: [4, 1, 11], state: "minecraft:sand"},
        {pos: [4, 1, 12], state: "minecraft:sand"},
        {pos: [5, 1, 1], state: "minecraft:sand"},
        {pos: [5, 1, 2], state: "minecraft:sand"},
        {pos: [5, 1, 3], state: "minecraft:sand"},
        {pos: [5, 1, 4], state: "minecraft:farmland{moisture:7}"},
        {pos: [5, 1, 5], state: "minecraft:farmland{moisture:7}"},
        {pos: [5, 1, 6], state: "minecraft:farmland{moisture:7}"},
        {pos: [5, 1, 7], state: "minecraft:farmland{moisture:7}"},
        {pos: [5, 1, 8], state: "minecraft:farmland{moisture:7}"},
        {pos: [5, 1, 9], state: "minecraft:sand"},
        {pos: [5, 1, 10], state: "minecraft:sand"},
        {pos: [5, 1, 11], state: "minecraft:sand"},
        {pos: [5, 1, 12], state: "minecraft:sand"},
        {pos: [6, 1, 1], state: "minecraft:sand"},
        {pos: [6, 1, 2], state: "minecraft:sand"},
        {pos: [6, 1, 3], state: "minecraft:farmland{moisture:7}"},
        {pos: [6, 1, 4], state: "minecraft:farmland{moisture:7}"},
        {pos: [6, 1, 5], state: "minecraft:farmland{moisture:7}"},
        {pos: [6, 1, 6], state: "minecraft:farmland{moisture:7}"},
        {pos: [6, 1, 7], state: "minecraft:farmland{moisture:7}"},
        {pos: [6, 1, 8], state: "minecraft:farmland{moisture:7}"},
        {pos: [6, 1, 9], state: "minecraft:farmland{moisture:7}"},
        {pos: [6, 1, 10], state: "minecraft:farmland{moisture:7}"},
        {pos: [6, 1, 11], state: "minecraft:sand"},
        {pos: [6, 1, 12], state: "minecraft:sand"},
        {pos: [7, 1, 1], state: "minecraft:sand"},
        {pos: [7, 1, 2], state: "minecraft:sand"},
        {pos: [7, 1, 3], state: "minecraft:sand"},
        {pos: [7, 1, 4], state: "minecraft:sand"},
        {pos: [7, 1, 5], state: "minecraft:sand"},
        {pos: [7, 1, 6], state: "minecraft:sand"},
        {pos: [7, 1, 7], state: "minecraft:farmland{moisture:7}"},
        {pos: [7, 1, 8], state: "minecraft:water{level:0}"},
        {pos: [7, 1, 9], state: "minecraft:farmland{moisture:7}"},
        {pos: [7, 1, 10], state: "minecraft:farmland{moisture:7}"},
        {pos: [7, 1, 11], state: "minecraft:farmland{moisture:7}"},
        {pos: [7, 1, 12], state: "minecraft:sand"},
        {pos: [8, 1, 1], state: "minecraft:sand"},
        {pos: [8, 1, 2], state: "minecraft:smooth_sandstone"},
        {pos: [8, 1, 3], state: "minecraft:smooth_sandstone"},
        {pos: [8, 1, 4], state: "minecraft:smooth_sandstone"},
        {pos: [8, 1, 5], state: "minecraft:sand"},
        {pos: [8, 1, 6], state: "minecraft:farmland{moisture:7}"},
        {pos: [8, 1, 7], state: "minecraft:farmland{moisture:7}"},
        {pos: [8, 1, 8], state: "minecraft:farmland{moisture:7}"},
        {pos: [8, 1, 9], state: "minecraft:farmland{moisture:7}"},
        {pos: [8, 1, 10], state: "minecraft:sand"},
        {pos: [8, 1, 11], state: "minecraft:sand"},
        {pos: [8, 1, 12], state: "minecraft:sand"},
        {pos: [9, 1, 1], state: "minecraft:sand"},
        {pos: [9, 1, 2], state: "minecraft:sand"},
        {pos: [9, 1, 3], state: "minecraft:sand"},
        {pos: [9, 1, 4], state: "minecraft:sand"},
        {pos: [9, 1, 5], state: "minecraft:sand"},
        {pos: [9, 1, 6], state: "minecraft:sand"},
        {pos: [9, 1, 7], state: "minecraft:sand"},
        {pos: [9, 1, 8], state: "minecraft:sand"},
        {pos: [9, 1, 9], state: "minecraft:sand"},
        {pos: [9, 1, 10], state: "minecraft:sand"},
        {pos: [10, 1, 2], state: "minecraft:sand"},
        {pos: [10, 1, 3], state: "minecraft:sand"},
        {pos: [10, 1, 4], state: "minecraft:sand"},
        {pos: [10, 1, 5], state: "minecraft:sand"},
        {pos: [10, 1, 6], state: "minecraft:sand"},
        {pos: [10, 1, 7], state: "minecraft:sand"},
        {pos: [10, 1, 8], state: "minecraft:sand"},
        {pos: [10, 1, 9], state: "minecraft:sand"},
        {pos: [0, 2, 2], state: "minecraft:hay_block{axis:z}"},
        {pos: [0, 2, 6], state: "minecraft:jigsaw{orientation:west_up}", nbt: {final_state: "minecraft:structure_void", id: "minecraft:jigsaw", joint: "aligned", name: "minecraft:building_entrance", pool: "minecraft:empty", target: "minecraft:building_entrance"}},
        {pos: [1, 2, 5], state: "minecraft:wheat{age:5}"},
        {pos: [1, 2, 6], state: "minecraft:wheat{age:1}"},
        {pos: [1, 2, 7], state: "minecraft:wheat{age:3}"},
        {pos: [2, 2, 3], state: "minecraft:wheat{age:2}"},
        {pos: [2, 2, 4], state: "minecraft:wheat{age:6}"},
        {pos: [2, 2, 5], state: "minecraft:wheat{age:4}"},
        {pos: [2, 2, 7], state: "minecraft:wheat{age:1}"},
        {pos: [2, 2, 8], state: "minecraft:wheat{age:3}"},
        {pos: [2, 2, 9], state: "minecraft:wheat{age:7}"},
        {pos: [2, 2, 12], state: "minecraft:hay_block{axis:x}"},
        {pos: [3, 2, 1], state: "minecraft:hay_block{axis:z}"},
        {pos: [3, 2, 3], state: "minecraft:hay_block{axis:x}"},
        {pos: [3, 2, 4], state: "minecraft:wheat{age:7}"},
        {pos: [3, 2, 5], state: "minecraft:wheat{age:5}"},
        {pos: [3, 2, 6], state: "minecraft:wheat{age:6}"},
        {pos: [3, 2, 7], state: "minecraft:wheat{age:2}"},
        {pos: [3, 2, 8], state: "minecraft:wheat{age:6}"},
        {pos: [3, 2, 9], state: "minecraft:hay_block{axis:z}"},
        {pos: [3, 2, 11], state: "minecraft:hay_block{axis:y}"},
        {pos: [4, 2, 2], state: "minecraft:hay_block{axis:z}"},
        {pos: [4, 2, 3], state: "minecraft:composter{level:0}"},
        {pos: [4, 2, 4], state: "minecraft:hay_block{axis:z}"},
        {pos: [4, 2, 5], state: "minecraft:wheat{age:7}"},
        {pos: [4, 2, 6], state: "minecraft:wheat{age:7}"},
        {pos: [4, 2, 7], state: "minecraft:wheat{age:7}"},
        {pos: [4, 2, 8], state: "minecraft:wheat{age:7}"},
        {pos: [4, 2, 9], state: "minecraft:wheat{age:7}"},
        {pos: [4, 2, 10], state: "minecraft:hay_block{axis:x}"},
        {pos: [4, 2, 11], state: "minecraft:hay_block{axis:y}"},
        {pos: [4, 2, 12], state: "minecraft:hay_block{axis:z}"},
        {pos: [5, 2, 1], state: "minecraft:hay_block{axis:y}"},
        {pos: [5, 2, 4], state: "minecraft:wheat{age:7}"},
        {pos: [5, 2, 5], state: "minecraft:wheat{age:7}"},
        {pos: [5, 2, 6], state: "minecraft:wheat{age:7}"},
        {pos: [5, 2, 7], state: "minecraft:wheat{age:7}"},
        {pos: [5, 2, 8], state: "minecraft:wheat{age:7}"},
        {pos: [5, 2, 9], state: "minecraft:composter{level:0}"},
        {pos: [5, 2, 10], state: "minecraft:hay_block{axis:y}"},
        {pos: [5, 2, 12], state: "minecraft:hay_block{axis:y}"},
        {pos: [6, 2, 3], state: "minecraft:wheat{age:7}"},
        {pos: [6, 2, 4], state: "minecraft:wheat{age:7}"},
        {pos: [6, 2, 5], state: "minecraft:wheat{age:7}"},
        {pos: [6, 2, 6], state: "minecraft:wheat{age:7}"},
        {pos: [6, 2, 7], state: "minecraft:wheat{age:7}"},
        {pos: [6, 2, 8], state: "minecraft:wheat{age:7}"},
        {pos: [6, 2, 9], state: "minecraft:wheat{age:7}"},
        {pos: [6, 2, 10], state: "minecraft:wheat{age:4}"},
        {pos: [7, 2, 1], state: "minecraft:smooth_sandstone_stairs{facing:south,half:bottom,shape:inner_left,waterlogged:false}"},
        {pos: [7, 2, 2], state: "minecraft:smooth_sandstone"},
        {pos: [7, 2, 3], state: "minecraft:smooth_sandstone"},
        {pos: [7, 2, 4], state: "minecraft:smooth_sandstone"},
        {pos: [7, 2, 5], state: "minecraft:smooth_sandstone_stairs{facing:east,half:bottom,shape:inner_left,waterlogged:false}"},
        {pos: [7, 2, 7], state: "minecraft:wheat{age:7}"},
        {pos: [7, 2, 9], state: "minecraft:wheat{age:7}"},
        {pos: [7, 2, 10], state: "minecraft:wheat{age:7}"},
        {pos: [7, 2, 11], state: "minecraft:wheat{age:7}"},
        {pos: [7, 2, 12], state: "minecraft:hay_block{axis:z}"},
        {pos: [8, 2, 1], state: "minecraft:smooth_sandstone"},
        {pos: [8, 2, 2], state: "minecraft:water{level:0}"},
        {pos: [8, 2, 3], state: "minecraft:water{level:0}"},
        {pos: [8, 2, 4], state: "minecraft:water{level:0}"},
        {pos: [8, 2, 5], state: "minecraft:smooth_sandstone"},
        {pos: [8, 2, 6], state: "minecraft:wheat{age:7}"},
        {pos: [8, 2, 7], state: "minecraft:wheat{age:5}"},
        {pos: [8, 2, 8], state: "minecraft:wheat{age:7}"},
        {pos: [8, 2, 9], state: "minecraft:wheat{age:7}"},
        {pos: [9, 2, 1], state: "minecraft:smooth_sandstone_stairs{facing:south,half:bottom,shape:inner_right,waterlogged:false}"},
        {pos: [9, 2, 2], state: "minecraft:smooth_sandstone"},
        {pos: [9, 2, 3], state: "minecraft:smooth_sandstone"},
        {pos: [9, 2, 4], state: "minecraft:smooth_sandstone"},
        {pos: [9, 2, 5], state: "minecraft:smooth_sandstone_stairs{facing:west,half:bottom,shape:inner_right,waterlogged:false}"},
        {pos: [9, 2, 6], state: "minecraft:hay_block{axis:x}"},
        {pos: [9, 2, 9], state: "minecraft:hay_block{axis:z}"},
        {pos: [10, 2, 7], state: "minecraft:hay_block{axis:y}"},
        {pos: [4, 3, 2], state: "minecraft:hay_block{axis:y}"},
        {pos: [4, 3, 11], state: "minecraft:hay_block{axis:z}"},
        {pos: [6, 3, 1], state: "minecraft:air"},
        {pos: [6, 3, 2], state: "minecraft:air"},
        {pos: [7, 3, 1], state: "minecraft:air"}
    ],
    entities: [],
    palette: [
        "minecraft:sand",
        "minecraft:smooth_sandstone",
        "minecraft:hay_block{axis:z}",
        "minecraft:hay_block{axis:x}",
        "minecraft:hay_block{axis:y}",
        "minecraft:farmland{moisture:7}",
        "minecraft:water{level:0}",
        "minecraft:wheat{age:5}",
        "minecraft:wheat{age:1}",
        "minecraft:wheat{age:3}",
        "minecraft:wheat{age:2}",
        "minecraft:wheat{age:6}",
        "minecraft:wheat{age:4}",
        "minecraft:wheat{age:7}",
        "minecraft:composter{level:0}",
        "minecraft:smooth_sandstone_stairs{facing:south,half:bottom,shape:inner_left,waterlogged:false}",
        "minecraft:smooth_sandstone_stairs{facing:east,half:bottom,shape:inner_left,waterlogged:false}",
        "minecraft:smooth_sandstone_stairs{facing:south,half:bottom,shape:inner_right,waterlogged:false}",
        "minecraft:smooth_sandstone_stairs{facing:west,half:bottom,shape:inner_right,waterlogged:false}",
        "minecraft:air",
        "minecraft:jigsaw{orientation:west_up}"
    ]
}
