{
    DataVersion: 2856,
    size: [9, 9, 9],
    data: [
        {pos: [0, 0, 0], state: "minecraft:sand"},
        {pos: [0, 0, 1], state: "minecraft:sand"},
        {pos: [0, 0, 2], state: "minecraft:sand"},
        {pos: [0, 0, 3], state: "minecraft:sand"},
        {pos: [0, 0, 4], state: "minecraft:sand"},
        {pos: [0, 0, 5], state: "minecraft:sand"},
        {pos: [0, 0, 6], state: "minecraft:sand"},
        {pos: [0, 0, 7], state: "minecraft:sand"},
        {pos: [0, 0, 8], state: "minecraft:sand"},
        {pos: [1, 0, 0], state: "minecraft:sand"},
        {pos: [1, 0, 1], state: "minecraft:sand"},
        {pos: [1, 0, 2], state: "minecraft:sand"},
        {pos: [1, 0, 3], state: "minecraft:sand"},
        {pos: [1, 0, 4], state: "minecraft:sand"},
        {pos: [1, 0, 5], state: "minecraft:sand"},
        {pos: [1, 0, 6], state: "minecraft:sand"},
        {pos: [1, 0, 7], state: "minecraft:sand"},
        {pos: [1, 0, 8], state: "minecraft:sand"},
        {pos: [2, 0, 0], state: "minecraft:sand"},
        {pos: [2, 0, 1], state: "minecraft:sand"},
        {pos: [2, 0, 2], state: "minecraft:sand"},
        {pos: [2, 0, 3], state: "minecraft:sand"},
        {pos: [2, 0, 4], state: "minecraft:sand"},
        {pos: [2, 0, 5], state: "minecraft:sand"},
        {pos: [2, 0, 6], state: "minecraft:sand"},
        {pos: [2, 0, 7], state: "minecraft:sand"},
        {pos: [2, 0, 8], state: "minecraft:sand"},
        {pos: [3, 0, 0], state: "minecraft:sand"},
        {pos: [3, 0, 1], state: "minecraft:sand"},
        {pos: [3, 0, 2], state: "minecraft:sand"},
        {pos: [3, 0, 3], state: "minecraft:sand"},
        {pos: [3, 0, 4], state: "minecraft:sand"},
        {pos: [3, 0, 5], state: "minecraft:sand"},
        {pos: [3, 0, 6], state: "minecraft:sand"},
        {pos: [3, 0, 7], state: "minecraft:sand"},
        {pos: [3, 0, 8], state: "minecraft:sand"},
        {pos: [4, 0, 0], state: "minecraft:smooth_sandstone"},
        {pos: [4, 0, 1], state: "minecraft:light_blue_glazed_terracotta{facing:south}"},
        {pos: [4, 0, 2], state: "minecraft:light_blue_glazed_terracotta{facing:east}"},
        {pos: [4, 0, 3], state: "minecraft:light_blue_glazed_terracotta{facing:south}"},
        {pos: [4, 0, 4], state: "minecraft:sand"},
        {pos: [4, 0, 5], state: "minecraft:sand"},
        {pos: [4, 0, 6], state: "minecraft:sand"},
        {pos: [4, 0, 7], state: "minecraft:sand"},
        {pos: [4, 0, 8], state: "minecraft:sand"},
        {pos: [5, 0, 0], state: "minecraft:smooth_sandstone"},
        {pos: [5, 0, 1], state: "minecraft:light_blue_glazed_terracotta{facing:west}"},
        {pos: [5, 0, 2], state: "minecraft:light_blue_glazed_terracotta{facing:north}"},
        {pos: [5, 0, 3], state: "minecraft:light_blue_glazed_terracotta{facing:west}"},
        {pos: [5, 0, 4], state: "minecraft:smooth_sandstone"},
        {pos: [5, 0, 5], state: "minecraft:sand"},
        {pos: [5, 0, 6], state: "minecraft:sand"},
        {pos: [5, 0, 7], state: "minecraft:sand"},
        {pos: [5, 0, 8], state: "minecraft:sand"},
        {pos: [6, 0, 0], state: "minecraft:smooth_sandstone"},
        {pos: [6, 0, 1], state: "minecraft:light_blue_glazed_terracotta{facing:south}"},
        {pos: [6, 0, 2], state: "minecraft:light_blue_glazed_terracotta{facing:east}"},
        {pos: [6, 0, 3], state: "minecraft:light_blue_glazed_terracotta{facing:south}"},
        {pos: [6, 0, 4], state: "minecraft:sand"},
        {pos: [6, 0, 5], state: "minecraft:sand"},
        {pos: [6, 0, 6], state: "minecraft:sand"},
        {pos: [6, 0, 7], state: "minecraft:sand"},
        {pos: [6, 0, 8], state: "minecraft:sand"},
        {pos: [7, 0, 0], state: "minecraft:smooth_sandstone"},
        {pos: [7, 0, 1], state: "minecraft:light_blue_glazed_terracotta{facing:west}"},
        {pos: [7, 0, 2], state: "minecraft:light_blue_glazed_terracotta{facing:north}"},
        {pos: [7, 0, 3], state: "minecraft:light_blue_glazed_terracotta{facing:west}"},
        {pos: [7, 0, 4], state: "minecraft:sand"},
        {pos: [7, 0, 5], state: "minecraft:sand"},
        {pos: [7, 0, 6], state: "minecraft:sand"},
        {pos: [7, 0, 7], state: "minecraft:sand"},
        {pos: [7, 0, 8], state: "minecraft:sand"},
        {pos: [8, 0, 0], state: "minecraft:sand"},
        {pos: [8, 0, 1], state: "minecraft:sand"},
        {pos: [8, 0, 2], state: "minecraft:sand"},
        {pos: [8, 0, 3], state: "minecraft:sand"},
        {pos: [8, 0, 4], state: "minecraft:sand"},
        {pos: [8, 0, 5], state: "minecraft:sand"},
        {pos: [8, 0, 6], state: "minecraft:sand"},
        {pos: [8, 0, 7], state: "minecraft:sand"},
        {pos: [8, 0, 8], state: "minecraft:sand"},
        {pos: [0, 1, 0], state: "minecraft:sand"},
        {pos: [0, 1, 1], state: "minecraft:sand"},
        {pos: [0, 1, 2], state: "minecraft:sand"},
        {pos: [0, 1, 3], state: "minecraft:sand"},
        {pos: [0, 1, 4], state: "minecraft:sand"},
        {pos: [0, 1, 5], state: "minecraft:sand"},
        {pos: [0, 1, 6], state: "minecraft:sand"},
        {pos: [0, 1, 7], state: "minecraft:sand"},
        {pos: [0, 1, 8], state: "minecraft:sand"},
        {pos: [1, 1, 0], state: "minecraft:sand"},
        {pos: [1, 1, 1], state: "minecraft:sand"},
        {pos: [1, 1, 2], state: "minecraft:sand"},
        {pos: [1, 1, 3], state: "minecraft:sand"},
        {pos: [1, 1, 4], state: "minecraft:sand"},
        {pos: [1, 1, 5], state: "minecraft:sand"},
        {pos: [1, 1, 6], state: "minecraft:sand"},
        {pos: [1, 1, 7], state: "minecraft:sand"},
        {pos: [1, 1, 8], state: "minecraft:sand"},
        {pos: [2, 1, 0], state: "minecraft:sand"},
        {pos: [2, 1, 1], state: "minecraft:sand"},
        {pos: [2, 1, 2], state: "minecraft:sand"},
        {pos: [2, 1, 3], state: "minecraft:sand"},
        {pos: [2, 1, 4], state: "minecraft:sand"},
        {pos: [2, 1, 5], state: "minecraft:sand"},
        {pos: [2, 1, 6], state: "minecraft:sand"},
        {pos: [2, 1, 7], state: "minecraft:sand"},
        {pos: [2, 1, 8], state: "minecraft:sand"},
        {pos: [3, 1, 0], state: "minecraft:smooth_sandstone"},
        {pos: [3, 1, 1], state: "minecraft:smooth_sandstone"},
        {pos: [3, 1, 2], state: "minecraft:smooth_sandstone"},
        {pos: [3, 1, 3], state: "minecraft:smooth_sandstone"},
        {pos: [3, 1, 4], state: "minecraft:sand"},
        {pos: [3, 1, 5], state: "minecraft:sand"},
        {pos: [3, 1, 6], state: "minecraft:sand"},
        {pos: [3, 1, 7], state: "minecraft:sand"},
        {pos: [3, 1, 8], state: "minecraft:sand"},
        {pos: [4, 1, 0], state: "minecraft:smooth_sandstone"},
        {pos: [4, 1, 1], state: "minecraft:air"},
        {pos: [4, 1, 2], state: "minecraft:air"},
        {pos: [4, 1, 3], state: "minecraft:air"},
        {pos: [4, 1, 4], state: "minecraft:smooth_sandstone"},
        {pos: [4, 1, 5], state: "minecraft:sand"},
        {pos: [4, 1, 6], state: "minecraft:sand"},
        {pos: [4, 1, 7], state: "minecraft:sand"},
        {pos: [4, 1, 8], state: "minecraft:sand"},
        {pos: [5, 1, 0], state: "minecraft:smooth_sandstone"},
        {pos: [5, 1, 1], state: "minecraft:air"},
        {pos: [5, 1, 2], state: "minecraft:air"},
        {pos: [5, 1, 3], state: "minecraft:air"},
        {pos: [5, 1, 4], state: "minecraft:air"},
        {pos: [5, 1, 5], state: "minecraft:smooth_sandstone_stairs{facing:south,half:bottom,shape:straight,waterlogged:false}"},
        {pos: [5, 1, 6], state: "minecraft:sand"},
        {pos: [5, 1, 7], state: "minecraft:sand"},
        {pos: [5, 1, 8], state: "minecraft:sand"},
        {pos: [6, 1, 0], state: "minecraft:smooth_sandstone"},
        {pos: [6, 1, 1], state: "minecraft:air"},
        {pos: [6, 1, 2], state: "minecraft:air"},
        {pos: [6, 1, 3], state: "minecraft:air"},
        {pos: [6, 1, 4], state: "minecraft:smooth_sandstone"},
        {pos: [6, 1, 5], state: "minecraft:sand"},
        {pos: [6, 1, 6], state: "minecraft:sand"},
        {pos: [6, 1, 7], state: "minecraft:sand"},
        {pos: [6, 1, 8], state: "minecraft:sand"},
        {pos: [7, 1, 0], state: "minecraft:smooth_sandstone"},
        {pos: [7, 1, 1], state: "minecraft:air"},
        {pos: [7, 1, 2], state: "minecraft:air"},
        {pos: [7, 1, 3], state: "minecraft:air"},
        {pos: [7, 1, 4], state: "minecraft:smooth_sandstone"},
        {pos: [7, 1, 5], state: "minecraft:sand"},
        {pos: [7, 1, 6], state: "minecraft:sand"},
        {pos: [7, 1, 7], state: "minecraft:sand"},
        {pos: [7, 1, 8], state: "minecraft:sand"},
        {pos: [8, 1, 0], state: "minecraft:smooth_sandstone"},
        {pos: [8, 1, 1], state: "minecraft:smooth_sandstone"},
        {pos: [8, 1, 2], state: "minecraft:smooth_sandstone"},
        {pos: [8, 1, 3], state: "minecraft:smooth_sandstone"},
        {pos: [8, 1, 4], state: "minecraft:sand"},
        {pos: [8, 1, 5], state: "minecraft:sand"},
        {pos: [8, 1, 6], state: "minecraft:sand"},
        {pos: [8, 1, 7], state: "minecraft:sand"},
        {pos: [8, 1, 8], state: "minecraft:sand"},
        {pos: [0, 2, 0], state: "minecraft:sand"},
        {pos: [0, 2, 1], state: "minecraft:sand"},
        {pos: [0, 2, 2], state: "minecraft:sand"},
        {pos: [0, 2, 3], state: "minecraft:sand"},
        {pos: [0, 2, 4], state: "minecraft:sand"},
        {pos: [0, 2, 5], state: "minecraft:sand"},
        {pos: [0, 2, 6], state: "minecraft:smooth_sandstone"},
        {pos: [0, 2, 7], state: "minecraft:air"},
        {pos: [0, 2, 8], state: "minecraft:air"},
        {pos: [1, 2, 0], state: "minecraft:sand"},
        {pos: [1, 2, 1], state: "minecraft:sand"},
        {pos: [1, 2, 2], state: "minecraft:sand"},
        {pos: [1, 2, 3], state: "minecraft:sand"},
        {pos: [1, 2, 4], state: "minecraft:sand"},
        {pos: [1, 2, 5], state: "minecraft:air"},
        {pos: [1, 2, 6], state: "minecraft:smooth_sandstone"},
        {pos: [1, 2, 7], state: "minecraft:sand"},
        {pos: [1, 2, 8], state: "minecraft:air"},
        {pos: [2, 2, 0], state: "minecraft:sand"},
        {pos: [2, 2, 1], state: "minecraft:sand"},
        {pos: [2, 2, 2], state: "minecraft:sand"},
        {pos: [2, 2, 3], state: "minecraft:sand"},
        {pos: [2, 2, 4], state: "minecraft:sand"},
        {pos: [2, 2, 5], state: "minecraft:air"},
        {pos: [2, 2, 6], state: "minecraft:smooth_sandstone"},
        {pos: [2, 2, 7], state: "minecraft:air"},
        {pos: [2, 2, 8], state: "minecraft:sand"},
        {pos: [3, 2, 0], state: "minecraft:smooth_sandstone"},
        {pos: [3, 2, 1], state: "minecraft:smooth_sandstone"},
        {pos: [3, 2, 2], state: "minecraft:smooth_sandstone"},
        {pos: [3, 2, 3], state: "minecraft:smooth_sandstone"},
        {pos: [3, 2, 4], state: "minecraft:sand"},
        {pos: [3, 2, 5], state: "minecraft:sand"},
        {pos: [3, 2, 6], state: "minecraft:smooth_sandstone"},
        {pos: [3, 2, 7], state: "minecraft:sand"},
        {pos: [3, 2, 8], state: "minecraft:sand"},
        {pos: [4, 2, 0], state: "minecraft:smooth_sandstone"},
        {pos: [4, 2, 1], state: "minecraft:jungle_button{face:wall,facing:south,powered:false}"},
        {pos: [4, 2, 2], state: "minecraft:jungle_button{face:wall,facing:east,powered:false}"},
        {pos: [4, 2, 3], state: "minecraft:jungle_button{face:wall,facing:east,powered:false}"},
        {pos: [4, 2, 4], state: "minecraft:smooth_sandstone"},
        {pos: [4, 2, 5], state: "minecraft:smooth_sandstone"},
        {pos: [4, 2, 6], state: "minecraft:smooth_sandstone"},
        {pos: [4, 2, 7], state: "minecraft:smooth_sandstone"},
        {pos: [4, 2, 8], state: "minecraft:sand"},
        {pos: [5, 2, 0], state: "minecraft:smooth_sandstone"},
        {pos: [5, 2, 1], state: "minecraft:jungle_button{face:wall,facing:south,powered:false}"},
        {pos: [5, 2, 2], state: "minecraft:air"},
        {pos: [5, 2, 3], state: "minecraft:air"},
        {pos: [5, 2, 4], state: "minecraft:air"},
        {pos: [5, 2, 5], state: "minecraft:air"},
        {pos: [5, 2, 6], state: "minecraft:smooth_sandstone_stairs{facing:south,half:bottom,shape:straight,waterlogged:false}"},
        {pos: [5, 2, 7], state: "minecraft:smooth_sandstone"},
        {pos: [5, 2, 8], state: "minecraft:sand"},
        {pos: [6, 2, 0], state: "minecraft:smooth_sandstone"},
        {pos: [6, 2, 1], state: "minecraft:jungle_button{face:wall,facing:south,powered:false}"},
        {pos: [6, 2, 2], state: "minecraft:air"},
        {pos: [6, 2, 3], state: "minecraft:jungle_button{face:wall,facing:north,powered:false}"},
        {pos: [6, 2, 4], state: "minecraft:smooth_sandstone"},
        {pos: [6, 2, 5], state: "minecraft:smooth_sandstone"},
        {pos: [6, 2, 6], state: "minecraft:smooth_sandstone"},
        {pos: [6, 2, 7], state: "minecraft:smooth_sandstone"},
        {pos: [6, 2, 8], state: "minecraft:sand"},
        {pos: [7, 2, 0], state: "minecraft:smooth_sandstone"},
        {pos: [7, 2, 1], state: "minecraft:jungle_button{face:wall,facing:south,powered:false}"},
        {pos: [7, 2, 2], state: "minecraft:jungle_button{face:wall,facing:west,powered:false}"},
        {pos: [7, 2, 3], state: "minecraft:jungle_button{face:wall,facing:west,powered:false}"},
        {pos: [7, 2, 4], state: "minecraft:smooth_sandstone"},
        {pos: [7, 2, 5], state: "minecraft:sand"},
        {pos: [7, 2, 6], state: "minecraft:sand"},
        {pos: [7, 2, 7], state: "minecraft:sand"},
        {pos: [7, 2, 8], state: "minecraft:sand"},
        {pos: [8, 2, 0], state: "minecraft:smooth_sandstone"},
        {pos: [8, 2, 1], state: "minecraft:smooth_sandstone"},
        {pos: [8, 2, 2], state: "minecraft:smooth_sandstone"},
        {pos: [8, 2, 3], state: "minecraft:smooth_sandstone"},
        {pos: [8, 2, 4], state: "minecraft:sand"},
        {pos: [8, 2, 5], state: "minecraft:air"},
        {pos: [8, 2, 6], state: "minecraft:air"},
        {pos: [8, 2, 7], state: "minecraft:air"},
        {pos: [8, 2, 8], state: "minecraft:air"},
        {pos: [0, 3, 0], state: "minecraft:smooth_sandstone_stairs{facing:south,half:bottom,shape:outer_left,waterlogged:false}"},
        {pos: [0, 3, 1], state: "minecraft:smooth_sandstone_stairs{facing:east,half:bottom,shape:straight,waterlogged:false}"},
        {pos: [0, 3, 2], state: "minecraft:smooth_sandstone_stairs{facing:east,half:bottom,shape:straight,waterlogged:false}"},
        {pos: [0, 3, 3], state: "minecraft:smooth_sandstone_stairs{facing:east,half:bottom,shape:straight,waterlogged:false}"},
        {pos: [0, 3, 4], state: "minecraft:smooth_sandstone_stairs{facing:north,half:bottom,shape:outer_right,waterlogged:false}"},
        {pos: [0, 3, 5], state: "minecraft:jigsaw{orientation:west_up}", nbt: {final_state: "minecraft:structure_void", id: "minecraft:jigsaw", joint: "aligned", name: "minecraft:building_entrance", pool: "minecraft:empty", target: "minecraft:building_entrance"}},
        {pos: [0, 3, 6], state: "minecraft:air"},
        {pos: [0, 3, 7], state: "minecraft:air"},
        {pos: [0, 3, 8], state: "minecraft:air"},
        {pos: [1, 3, 0], state: "minecraft:smooth_sandstone_stairs{facing:south,half:bottom,shape:straight,waterlogged:false}"},
        {pos: [1, 3, 1], state: "minecraft:smooth_sandstone"},
        {pos: [1, 3, 2], state: "minecraft:smooth_sandstone"},
        {pos: [1, 3, 3], state: "minecraft:smooth_sandstone"},
        {pos: [1, 3, 4], state: "minecraft:smooth_sandstone_stairs{facing:north,half:bottom,shape:straight,waterlogged:false}"},
        {pos: [1, 3, 5], state: "minecraft:air"},
        {pos: [1, 3, 6], state: "minecraft:air"},
        {pos: [1, 3, 7], state: "minecraft:potted_cactus"},
        {pos: [1, 3, 8], state: "minecraft:air"},
        {pos: [2, 3, 0], state: "minecraft:smooth_sandstone_stairs{facing:south,half:bottom,shape:straight,waterlogged:false}"},
        {pos: [2, 3, 1], state: "minecraft:smooth_sandstone"},
        {pos: [2, 3, 2], state: "minecraft:smooth_sandstone"},
        {pos: [2, 3, 3], state: "minecraft:smooth_sandstone"},
        {pos: [2, 3, 4], state: "minecraft:smooth_sandstone_stairs{facing:north,half:bottom,shape:straight,waterlogged:false}"},
        {pos: [2, 3, 5], state: "minecraft:air"},
        {pos: [2, 3, 6], state: "minecraft:air"},
        {pos: [2, 3, 7], state: "minecraft:air"},
        {pos: [2, 3, 8], state: "minecraft:potted_cactus"},
        {pos: [3, 3, 0], state: "minecraft:smooth_sandstone"},
        {pos: [3, 3, 1], state: "minecraft:smooth_sandstone"},
        {pos: [3, 3, 2], state: "minecraft:smooth_sandstone"},
        {pos: [3, 3, 3], state: "minecraft:smooth_sandstone"},
        {pos: [3, 3, 4], state: "minecraft:smooth_sandstone"},
        {pos: [3, 3, 5], state: "minecraft:smooth_sandstone"},
        {pos: [3, 3, 6], state: "minecraft:jungle_door{facing:west,half:lower,hinge:left,open:false,powered:false}"},
        {pos: [3, 3, 7], state: "minecraft:smooth_sandstone"},
        {pos: [3, 3, 8], state: "minecraft:smooth_sandstone"},
        {pos: [4, 3, 0], state: "minecraft:smooth_sandstone"},
        {pos: [4, 3, 1], state: "minecraft:air"},
        {pos: [4, 3, 2], state: "minecraft:wall_torch{facing:east}"},
        {pos: [4, 3, 3], state: "minecraft:air"},
        {pos: [4, 3, 4], state: "minecraft:smooth_sandstone"},
        {pos: [4, 3, 5], state: "minecraft:air"},
        {pos: [4, 3, 6], state: "minecraft:air"},
        {pos: [4, 3, 7], state: "minecraft:air"},
        {pos: [4, 3, 8], state: "minecraft:smooth_sandstone"},
        {pos: [5, 3, 0], state: "minecraft:smooth_sandstone"},
        {pos: [5, 3, 1], state: "minecraft:air"},
        {pos: [5, 3, 2], state: "minecraft:air"},
        {pos: [5, 3, 3], state: "minecraft:air"},
        {pos: [5, 3, 4], state: "minecraft:air"},
        {pos: [5, 3, 5], state: "minecraft:air"},
        {pos: [5, 3, 6], state: "minecraft:air"},
        {pos: [5, 3, 7], state: "minecraft:air"},
        {pos: [5, 3, 8], state: "minecraft:smooth_sandstone"},
        {pos: [6, 3, 0], state: "minecraft:smooth_sandstone"},
        {pos: [6, 3, 1], state: "minecraft:air"},
        {pos: [6, 3, 2], state: "minecraft:air"},
        {pos: [6, 3, 3], state: "minecraft:air"},
        {pos: [6, 3, 4], state: "minecraft:smooth_sandstone"},
        {pos: [6, 3, 5], state: "minecraft:air"},
        {pos: [6, 3, 6], state: "minecraft:air"},
        {pos: [6, 3, 7], state: "minecraft:air"},
        {pos: [6, 3, 8], state: "minecraft:smooth_sandstone"},
        {pos: [7, 3, 0], state: "minecraft:smooth_sandstone"},
        {pos: [7, 3, 1], state: "minecraft:air"},
        {pos: [7, 3, 2], state: "minecraft:wall_torch{facing:west}"},
        {pos: [7, 3, 3], state: "minecraft:air"},
        {pos: [7, 3, 4], state: "minecraft:smooth_sandstone"},
        {pos: [7, 3, 5], state: "minecraft:smooth_sandstone"},
        {pos: [7, 3, 6], state: "minecraft:smooth_sandstone"},
        {pos: [7, 3, 7], state: "minecraft:smooth_sandstone"},
        {pos: [7, 3, 8], state: "minecraft:smooth_sandstone"},
        {pos: [8, 3, 0], state: "minecraft:smooth_sandstone"},
        {pos: [8, 3, 1], state: "minecraft:smooth_sandstone"},
        {pos: [8, 3, 2], state: "minecraft:smooth_sandstone"},
        {pos: [8, 3, 3], state: "minecraft:smooth_sandstone"},
        {pos: [8, 3, 4], state: "minecraft:smooth_sandstone"},
        {pos: [8, 3, 5], state: "minecraft:air"},
        {pos: [8, 3, 6], state: "minecraft:air"},
        {pos: [8, 3, 7], state: "minecraft:air"},
        {pos: [8, 3, 8], state: "minecraft:air"},
        {pos: [0, 4, 0], state: "minecraft:air"},
        {pos: [0, 4, 1], state: "minecraft:air"},
        {pos: [0, 4, 2], state: "minecraft:air"},
        {pos: [0, 4, 3], state: "minecraft:air"},
        {pos: [0, 4, 4], state: "minecraft:air"},
        {pos: [0, 4, 5], state: "minecraft:air"},
        {pos: [0, 4, 6], state: "minecraft:air"},
        {pos: [0, 4, 7], state: "minecraft:air"},
        {pos: [0, 4, 8], state: "minecraft:air"},
        {pos: [1, 4, 0], state: "minecraft:air"},
        {pos: [1, 4, 1], state: "minecraft:smooth_sandstone_stairs{facing:east,half:bottom,shape:outer_right,waterlogged:false}"},
        {pos: [1, 4, 2], state: "minecraft:smooth_sandstone_stairs{facing:east,half:bottom,shape:straight,waterlogged:false}"},
        {pos: [1, 4, 3], state: "minecraft:smooth_sandstone_stairs{facing:east,half:bottom,shape:outer_left,waterlogged:false}"},
        {pos: [1, 4, 4], state: "minecraft:air"},
        {pos: [1, 4, 5], state: "minecraft:air"},
        {pos: [1, 4, 6], state: "minecraft:air"},
        {pos: [1, 4, 7], state: "minecraft:air"},
        {pos: [1, 4, 8], state: "minecraft:air"},
        {pos: [2, 4, 0], state: "minecraft:air"},
        {pos: [2, 4, 1], state: "minecraft:smooth_sandstone_stairs{facing:south,half:bottom,shape:straight,waterlogged:false}"},
        {pos: [2, 4, 2], state: "minecraft:smooth_sandstone"},
        {pos: [2, 4, 3], state: "minecraft:smooth_sandstone_stairs{facing:north,half:bottom,shape:straight,waterlogged:false}"},
        {pos: [2, 4, 4], state: "minecraft:air"},
        {pos: [2, 4, 5], state: "minecraft:wall_torch{facing:west}"},
        {pos: [2, 4, 6], state: "minecraft:air"},
        {pos: [2, 4, 7], state: "minecraft:wall_torch{facing:west}"},
        {pos: [2, 4, 8], state: "minecraft:air"},
        {pos: [3, 4, 0], state: "minecraft:smooth_sandstone"},
        {pos: [3, 4, 1], state: "minecraft:smooth_sandstone"},
        {pos: [3, 4, 2], state: "minecraft:smooth_sandstone"},
        {pos: [3, 4, 3], state: "minecraft:smooth_sandstone"},
        {pos: [3, 4, 4], state: "minecraft:smooth_sandstone"},
        {pos: [3, 4, 5], state: "minecraft:smooth_sandstone"},
        {pos: [3, 4, 6], state: "minecraft:jungle_door{facing:west,half:upper,hinge:left,open:false,powered:false}"},
        {pos: [3, 4, 7], state: "minecraft:smooth_sandstone"},
        {pos: [3, 4, 8], state: "minecraft:smooth_sandstone"},
        {pos: [4, 4, 0], state: "minecraft:smooth_sandstone"},
        {pos: [4, 4, 1], state: "minecraft:smooth_sandstone"},
        {pos: [4, 4, 2], state: "minecraft:smooth_sandstone"},
        {pos: [4, 4, 3], state: "minecraft:smooth_sandstone"},
        {pos: [4, 4, 4], state: "minecraft:smooth_sandstone"},
        {pos: [4, 4, 5], state: "minecraft:air"},
        {pos: [4, 4, 6], state: "minecraft:air"},
        {pos: [4, 4, 7], state: "minecraft:air"},
        {pos: [4, 4, 8], state: "minecraft:smooth_sandstone"},
        {pos: [5, 4, 0], state: "minecraft:smooth_sandstone"},
        {pos: [5, 4, 1], state: "minecraft:smooth_sandstone"},
        {pos: [5, 4, 2], state: "minecraft:smooth_sandstone"},
        {pos: [5, 4, 3], state: "minecraft:smooth_sandstone"},
        {pos: [5, 4, 4], state: "minecraft:smooth_sandstone"},
        {pos: [5, 4, 5], state: "minecraft:air"},
        {pos: [5, 4, 6], state: "minecraft:air"},
        {pos: [5, 4, 7], state: "minecraft:air"},
        {pos: [5, 4, 8], state: "minecraft:smooth_sandstone"},
        {pos: [6, 4, 0], state: "minecraft:smooth_sandstone"},
        {pos: [6, 4, 1], state: "minecraft:smooth_sandstone"},
        {pos: [6, 4, 2], state: "minecraft:smooth_sandstone"},
        {pos: [6, 4, 3], state: "minecraft:smooth_sandstone"},
        {pos: [6, 4, 4], state: "minecraft:smooth_sandstone"},
        {pos: [6, 4, 5], state: "minecraft:air"},
        {pos: [6, 4, 6], state: "minecraft:wall_torch{facing:west}"},
        {pos: [6, 4, 7], state: "minecraft:air"},
        {pos: [6, 4, 8], state: "minecraft:smooth_sandstone"},
        {pos: [7, 4, 0], state: "minecraft:smooth_sandstone"},
        {pos: [7, 4, 1], state: "minecraft:smooth_sandstone"},
        {pos: [7, 4, 2], state: "minecraft:smooth_sandstone"},
        {pos: [7, 4, 3], state: "minecraft:smooth_sandstone"},
        {pos: [7, 4, 4], state: "minecraft:smooth_sandstone"},
        {pos: [7, 4, 5], state: "minecraft:smooth_sandstone"},
        {pos: [7, 4, 6], state: "minecraft:smooth_sandstone"},
        {pos: [7, 4, 7], state: "minecraft:smooth_sandstone"},
        {pos: [7, 4, 8], state: "minecraft:smooth_sandstone"},
        {pos: [8, 4, 0], state: "minecraft:smooth_sandstone"},
        {pos: [8, 4, 1], state: "minecraft:smooth_sandstone"},
        {pos: [8, 4, 2], state: "minecraft:smooth_sandstone"},
        {pos: [8, 4, 3], state: "minecraft:smooth_sandstone"},
        {pos: [8, 4, 4], state: "minecraft:smooth_sandstone"},
        {pos: [8, 4, 5], state: "minecraft:air"},
        {pos: [8, 4, 6], state: "minecraft:air"},
        {pos: [8, 4, 7], state: "minecraft:air"},
        {pos: [8, 4, 8], state: "minecraft:air"},
        {pos: [0, 5, 0], state: "minecraft:air"},
        {pos: [0, 5, 1], state: "minecraft:air"},
        {pos: [0, 5, 2], state: "minecraft:air"},
        {pos: [0, 5, 3], state: "minecraft:air"},
        {pos: [0, 5, 4], state: "minecraft:air"},
        {pos: [0, 5, 5], state: "minecraft:air"},
        {pos: [0, 5, 6], state: "minecraft:air"},
        {pos: [0, 5, 7], state: "minecraft:air"},
        {pos: [0, 5, 8], state: "minecraft:air"},
        {pos: [1, 5, 0], state: "minecraft:air"},
        {pos: [1, 5, 1], state: "minecraft:air"},
        {pos: [1, 5, 2], state: "minecraft:air"},
        {pos: [1, 5, 3], state: "minecraft:air"},
        {pos: [1, 5, 4], state: "minecraft:air"},
        {pos: [1, 5, 5], state: "minecraft:air"},
        {pos: [1, 5, 6], state: "minecraft:air"},
        {pos: [1, 5, 7], state: "minecraft:air"},
        {pos: [1, 5, 8], state: "minecraft:air"},
        {pos: [2, 5, 0], state: "minecraft:air"},
        {pos: [2, 5, 1], state: "minecraft:air"},
        {pos: [2, 5, 2], state: "minecraft:air"},
        {pos: [2, 5, 3], state: "minecraft:air"},
        {pos: [2, 5, 4], state: "minecraft:air"},
        {pos: [2, 5, 5], state: "minecraft:air"},
        {pos: [2, 5, 6], state: "minecraft:air"},
        {pos: [2, 5, 7], state: "minecraft:air"},
        {pos: [2, 5, 8], state: "minecraft:air"},
        {pos: [3, 5, 0], state: "minecraft:smooth_sandstone"},
        {pos: [3, 5, 1], state: "minecraft:smooth_sandstone"},
        {pos: [3, 5, 2], state: "minecraft:jungle_door{facing:west,half:lower,hinge:right,open:false,powered:false}"},
        {pos: [3, 5, 3], state: "minecraft:smooth_sandstone"},
        {pos: [3, 5, 4], state: "minecraft:smooth_sandstone"},
        {pos: [3, 5, 5], state: "minecraft:smooth_sandstone"},
        {pos: [3, 5, 6], state: "minecraft:smooth_sandstone"},
        {pos: [3, 5, 7], state: "minecraft:smooth_sandstone"},
        {pos: [3, 5, 8], state: "minecraft:smooth_sandstone"},
        {pos: [4, 5, 0], state: "minecraft:smooth_sandstone"},
        {pos: [4, 5, 1], state: "minecraft:air"},
        {pos: [4, 5, 2], state: "minecraft:air"},
        {pos: [4, 5, 3], state: "minecraft:air"},
        {pos: [4, 5, 4], state: "minecraft:smooth_sandstone"},
        {pos: [4, 5, 5], state: "minecraft:smooth_sandstone_slab{type:top,waterlogged:false}"},
        {pos: [4, 5, 6], state: "minecraft:smooth_sandstone_slab{type:top,waterlogged:false}"},
        {pos: [4, 5, 7], state: "minecraft:smooth_sandstone_slab{type:top,waterlogged:false}"},
        {pos: [4, 5, 8], state: "minecraft:smooth_sandstone"},
        {pos: [5, 5, 0], state: "minecraft:smooth_sandstone"},
        {pos: [5, 5, 1], state: "minecraft:air"},
        {pos: [5, 5, 2], state: "minecraft:air"},
        {pos: [5, 5, 3], state: "minecraft:air"},
        {pos: [5, 5, 4], state: "minecraft:smooth_sandstone"},
        {pos: [5, 5, 5], state: "minecraft:smooth_sandstone_slab{type:top,waterlogged:false}"},
        {pos: [5, 5, 6], state: "minecraft:smooth_sandstone_slab{type:top,waterlogged:false}"},
        {pos: [5, 5, 7], state: "minecraft:smooth_sandstone_slab{type:top,waterlogged:false}"},
        {pos: [5, 5, 8], state: "minecraft:smooth_sandstone"},
        {pos: [6, 5, 0], state: "minecraft:smooth_sandstone"},
        {pos: [6, 5, 1], state: "minecraft:smithing_table"},
        {pos: [6, 5, 2], state: "minecraft:air"},
        {pos: [6, 5, 3], state: "minecraft:air"},
        {pos: [6, 5, 4], state: "minecraft:smooth_sandstone"},
        {pos: [6, 5, 5], state: "minecraft:smooth_sandstone_slab{type:top,waterlogged:false}"},
        {pos: [6, 5, 6], state: "minecraft:smooth_sandstone_slab{type:top,waterlogged:false}"},
        {pos: [6, 5, 7], state: "minecraft:smooth_sandstone_slab{type:top,waterlogged:false}"},
        {pos: [6, 5, 8], state: "minecraft:smooth_sandstone"},
        {pos: [7, 5, 0], state: "minecraft:smooth_sandstone"},
        {pos: [7, 5, 1], state: "minecraft:chest{facing:south,type:single,waterlogged:false}", nbt: {LootTable: "minecraft:chests/village/village_toolsmith", id: "minecraft:chest"}},
        {pos: [7, 5, 2], state: "minecraft:air"},
        {pos: [7, 5, 3], state: "minecraft:air"},
        {pos: [7, 5, 4], state: "minecraft:smooth_sandstone"},
        {pos: [7, 5, 5], state: "minecraft:smooth_sandstone"},
        {pos: [7, 5, 6], state: "minecraft:smooth_sandstone"},
        {pos: [7, 5, 7], state: "minecraft:smooth_sandstone"},
        {pos: [7, 5, 8], state: "minecraft:smooth_sandstone"},
        {pos: [8, 5, 0], state: "minecraft:smooth_sandstone"},
        {pos: [8, 5, 1], state: "minecraft:smooth_sandstone"},
        {pos: [8, 5, 2], state: "minecraft:smooth_sandstone"},
        {pos: [8, 5, 3], state: "minecraft:smooth_sandstone"},
        {pos: [8, 5, 4], state: "minecraft:smooth_sandstone"},
        {pos: [8, 5, 5], state: "minecraft:air"},
        {pos: [8, 5, 6], state: "minecraft:air"},
        {pos: [8, 5, 7], state: "minecraft:air"},
        {pos: [8, 5, 8], state: "minecraft:air"},
        {pos: [0, 6, 0], state: "minecraft:air"},
        {pos: [0, 6, 1], state: "minecraft:air"},
        {pos: [0, 6, 2], state: "minecraft:air"},
        {pos: [0, 6, 3], state: "minecraft:air"},
        {pos: [0, 6, 4], state: "minecraft:air"},
        {pos: [0, 6, 5], state: "minecraft:air"},
        {pos: [0, 6, 6], state: "minecraft:air"},
        {pos: [0, 6, 7], state: "minecraft:air"},
        {pos: [0, 6, 8], state: "minecraft:air"},
        {pos: [1, 6, 0], state: "minecraft:air"},
        {pos: [1, 6, 1], state: "minecraft:air"},
        {pos: [1, 6, 2], state: "minecraft:air"},
        {pos: [1, 6, 3], state: "minecraft:air"},
        {pos: [1, 6, 4], state: "minecraft:air"},
        {pos: [1, 6, 5], state: "minecraft:air"},
        {pos: [1, 6, 6], state: "minecraft:air"},
        {pos: [1, 6, 7], state: "minecraft:air"},
        {pos: [1, 6, 8], state: "minecraft:air"},
        {pos: [2, 6, 0], state: "minecraft:air"},
        {pos: [2, 6, 1], state: "minecraft:wall_torch{facing:west}"},
        {pos: [2, 6, 2], state: "minecraft:air"},
        {pos: [2, 6, 3], state: "minecraft:wall_torch{facing:west}"},
        {pos: [2, 6, 4], state: "minecraft:air"},
        {pos: [2, 6, 5], state: "minecraft:air"},
        {pos: [2, 6, 6], state: "minecraft:air"},
        {pos: [2, 6, 7], state: "minecraft:air"},
        {pos: [2, 6, 8], state: "minecraft:air"},
        {pos: [3, 6, 0], state: "minecraft:smooth_sandstone"},
        {pos: [3, 6, 1], state: "minecraft:smooth_sandstone"},
        {pos: [3, 6, 2], state: "minecraft:jungle_door{facing:west,half:upper,hinge:right,open:false,powered:false}"},
        {pos: [3, 6, 3], state: "minecraft:smooth_sandstone"},
        {pos: [3, 6, 4], state: "minecraft:smooth_sandstone"},
        {pos: [3, 6, 5], state: "minecraft:air"},
        {pos: [3, 6, 6], state: "minecraft:smooth_sandstone_slab{type:bottom,waterlogged:false}"},
        {pos: [3, 6, 7], state: "minecraft:air"},
        {pos: [3, 6, 8], state: "minecraft:smooth_sandstone_slab{type:bottom,waterlogged:false}"},
        {pos: [4, 6, 0], state: "minecraft:terracotta"},
        {pos: [4, 6, 1], state: "minecraft:air"},
        {pos: [4, 6, 2], state: "minecraft:air"},
        {pos: [4, 6, 3], state: "minecraft:air"},
        {pos: [4, 6, 4], state: "minecraft:smooth_sandstone"},
        {pos: [4, 6, 5], state: "minecraft:air"},
        {pos: [4, 6, 6], state: "minecraft:air"},
        {pos: [4, 6, 7], state: "minecraft:air"},
        {pos: [4, 6, 8], state: "minecraft:air"},
        {pos: [5, 6, 0], state: "minecraft:terracotta"},
        {pos: [5, 6, 1], state: "minecraft:air"},
        {pos: [5, 6, 2], state: "minecraft:air"},
        {pos: [5, 6, 3], state: "minecraft:air"},
        {pos: [5, 6, 4], state: "minecraft:smooth_sandstone"},
        {pos: [5, 6, 5], state: "minecraft:air"},
        {pos: [5, 6, 6], state: "minecraft:air"},
        {pos: [5, 6, 7], state: "minecraft:air"},
        {pos: [5, 6, 8], state: "minecraft:smooth_sandstone_slab{type:bottom,waterlogged:false}"},
        {pos: [6, 6, 0], state: "minecraft:terracotta"},
        {pos: [6, 6, 1], state: "minecraft:air"},
        {pos: [6, 6, 2], state: "minecraft:air"},
        {pos: [6, 6, 3], state: "minecraft:air"},
        {pos: [6, 6, 4], state: "minecraft:smooth_sandstone"},
        {pos: [6, 6, 5], state: "minecraft:air"},
        {pos: [6, 6, 6], state: "minecraft:air"},
        {pos: [6, 6, 7], state: "minecraft:air"},
        {pos: [6, 6, 8], state: "minecraft:air"},
        {pos: [7, 6, 0], state: "minecraft:terracotta"},
        {pos: [7, 6, 1], state: "minecraft:air"},
        {pos: [7, 6, 2], state: "minecraft:wall_torch{facing:west}"},
        {pos: [7, 6, 3], state: "minecraft:air"},
        {pos: [7, 6, 4], state: "minecraft:smooth_sandstone"},
        {pos: [7, 6, 5], state: "minecraft:air"},
        {pos: [7, 6, 6], state: "minecraft:smooth_sandstone_slab{type:bottom,waterlogged:false}"},
        {pos: [7, 6, 7], state: "minecraft:air"},
        {pos: [7, 6, 8], state: "minecraft:smooth_sandstone_slab{type:bottom,waterlogged:false}"},
        {pos: [8, 6, 0], state: "minecraft:smooth_sandstone"},
        {pos: [8, 6, 1], state: "minecraft:terracotta"},
        {pos: [8, 6, 2], state: "minecraft:terracotta"},
        {pos: [8, 6, 3], state: "minecraft:terracotta"},
        {pos: [8, 6, 4], state: "minecraft:smooth_sandstone"},
        {pos: [8, 6, 5], state: "minecraft:air"},
        {pos: [8, 6, 6], state: "minecraft:air"},
        {pos: [8, 6, 7], state: "minecraft:air"},
        {pos: [8, 6, 8], state: "minecraft:air"},
        {pos: [0, 7, 0], state: "minecraft:air"},
        {pos: [0, 7, 1], state: "minecraft:air"},
        {pos: [0, 7, 2], state: "minecraft:air"},
        {pos: [0, 7, 3], state: "minecraft:air"},
        {pos: [0, 7, 4], state: "minecraft:air"},
        {pos: [0, 7, 5], state: "minecraft:air"},
        {pos: [0, 7, 6], state: "minecraft:air"},
        {pos: [0, 7, 7], state: "minecraft:air"},
        {pos: [0, 7, 8], state: "minecraft:air"},
        {pos: [1, 7, 0], state: "minecraft:air"},
        {pos: [1, 7, 1], state: "minecraft:air"},
        {pos: [1, 7, 2], state: "minecraft:air"},
        {pos: [1, 7, 3], state: "minecraft:air"},
        {pos: [1, 7, 4], state: "minecraft:air"},
        {pos: [1, 7, 5], state: "minecraft:air"},
        {pos: [1, 7, 6], state: "minecraft:air"},
        {pos: [1, 7, 7], state: "minecraft:air"},
        {pos: [1, 7, 8], state: "minecraft:air"},
        {pos: [2, 7, 0], state: "minecraft:air"},
        {pos: [2, 7, 1], state: "minecraft:air"},
        {pos: [2, 7, 2], state: "minecraft:air"},
        {pos: [2, 7, 3], state: "minecraft:air"},
        {pos: [2, 7, 4], state: "minecraft:air"},
        {pos: [2, 7, 5], state: "minecraft:air"},
        {pos: [2, 7, 6], state: "minecraft:air"},
        {pos: [2, 7, 7], state: "minecraft:air"},
        {pos: [2, 7, 8], state: "minecraft:air"},
        {pos: [3, 7, 0], state: "minecraft:smooth_sandstone"},
        {pos: [3, 7, 1], state: "minecraft:smooth_sandstone"},
        {pos: [3, 7, 2], state: "minecraft:smooth_sandstone"},
        {pos: [3, 7, 3], state: "minecraft:smooth_sandstone"},
        {pos: [3, 7, 4], state: "minecraft:smooth_sandstone"},
        {pos: [3, 7, 5], state: "minecraft:air"},
        {pos: [3, 7, 6], state: "minecraft:air"},
        {pos: [3, 7, 7], state: "minecraft:air"},
        {pos: [3, 7, 8], state: "minecraft:air"},
        {pos: [4, 7, 0], state: "minecraft:smooth_sandstone_slab{type:double,waterlogged:false}"},
        {pos: [4, 7, 1], state: "minecraft:smooth_sandstone_slab{type:top,waterlogged:false}"},
        {pos: [4, 7, 2], state: "minecraft:smooth_sandstone_slab{type:top,waterlogged:false}"},
        {pos: [4, 7, 3], state: "minecraft:smooth_sandstone_slab{type:top,waterlogged:false}"},
        {pos: [4, 7, 4], state: "minecraft:smooth_sandstone"},
        {pos: [4, 7, 5], state: "minecraft:air"},
        {pos: [4, 7, 6], state: "minecraft:air"},
        {pos: [4, 7, 7], state: "minecraft:air"},
        {pos: [4, 7, 8], state: "minecraft:air"},
        {pos: [5, 7, 0], state: "minecraft:smooth_sandstone_slab{type:double,waterlogged:false}"},
        {pos: [5, 7, 1], state: "minecraft:smooth_sandstone_slab{type:top,waterlogged:false}"},
        {pos: [5, 7, 2], state: "minecraft:smooth_sandstone_slab{type:top,waterlogged:false}"},
        {pos: [5, 7, 3], state: "minecraft:smooth_sandstone_slab{type:top,waterlogged:false}"},
        {pos: [5, 7, 4], state: "minecraft:smooth_sandstone"},
        {pos: [5, 7, 5], state: "minecraft:air"},
        {pos: [5, 7, 6], state: "minecraft:air"},
        {pos: [5, 7, 7], state: "minecraft:air"},
        {pos: [5, 7, 8], state: "minecraft:air"},
        {pos: [6, 7, 0], state: "minecraft:smooth_sandstone_slab{type:double,waterlogged:false}"},
        {pos: [6, 7, 1], state: "minecraft:smooth_sandstone_slab{type:top,waterlogged:false}"},
        {pos: [6, 7, 2], state: "minecraft:smooth_sandstone_slab{type:top,waterlogged:false}"},
        {pos: [6, 7, 3], state: "minecraft:smooth_sandstone_slab{type:top,waterlogged:false}"},
        {pos: [6, 7, 4], state: "minecraft:smooth_sandstone"},
        {pos: [6, 7, 5], state: "minecraft:air"},
        {pos: [6, 7, 6], state: "minecraft:air"},
        {pos: [6, 7, 7], state: "minecraft:air"},
        {pos: [6, 7, 8], state: "minecraft:air"},
        {pos: [7, 7, 0], state: "minecraft:smooth_sandstone_slab{type:double,waterlogged:false}"},
        {pos: [7, 7, 1], state: "minecraft:smooth_sandstone_slab{type:top,waterlogged:false}"},
        {pos: [7, 7, 2], state: "minecraft:smooth_sandstone_slab{type:top,waterlogged:false}"},
        {pos: [7, 7, 3], state: "minecraft:smooth_sandstone_slab{type:top,waterlogged:false}"},
        {pos: [7, 7, 4], state: "minecraft:smooth_sandstone"},
        {pos: [7, 7, 5], state: "minecraft:air"},
        {pos: [7, 7, 6], state: "minecraft:air"},
        {pos: [7, 7, 7], state: "minecraft:air"},
        {pos: [7, 7, 8], state: "minecraft:air"},
        {pos: [8, 7, 0], state: "minecraft:smooth_sandstone"},
        {pos: [8, 7, 1], state: "minecraft:smooth_sandstone"},
        {pos: [8, 7, 2], state: "minecraft:smooth_sandstone"},
        {pos: [8, 7, 3], state: "minecraft:smooth_sandstone"},
        {pos: [8, 7, 4], state: "minecraft:smooth_sandstone"},
        {pos: [8, 7, 5], state: "minecraft:air"},
        {pos: [8, 7, 6], state: "minecraft:air"},
        {pos: [8, 7, 7], state: "minecraft:air"},
        {pos: [8, 7, 8], state: "minecraft:air"},
        {pos: [0, 8, 0], state: "minecraft:air"},
        {pos: [0, 8, 1], state: "minecraft:air"},
        {pos: [0, 8, 2], state: "minecraft:air"},
        {pos: [0, 8, 3], state: "minecraft:air"},
        {pos: [0, 8, 4], state: "minecraft:air"},
        {pos: [0, 8, 5], state: "minecraft:air"},
        {pos: [0, 8, 6], state: "minecraft:air"},
        {pos: [0, 8, 7], state: "minecraft:air"},
        {pos: [0, 8, 8], state: "minecraft:air"},
        {pos: [1, 8, 0], state: "minecraft:air"},
        {pos: [1, 8, 1], state: "minecraft:air"},
        {pos: [1, 8, 2], state: "minecraft:air"},
        {pos: [1, 8, 3], state: "minecraft:air"},
        {pos: [1, 8, 4], state: "minecraft:air"},
        {pos: [1, 8, 5], state: "minecraft:air"},
        {pos: [1, 8, 6], state: "minecraft:air"},
        {pos: [1, 8, 7], state: "minecraft:air"},
        {pos: [1, 8, 8], state: "minecraft:air"},
        {pos: [2, 8, 0], state: "minecraft:air"},
        {pos: [2, 8, 1], state: "minecraft:air"},
        {pos: [2, 8, 2], state: "minecraft:air"},
        {pos: [2, 8, 3], state: "minecraft:air"},
        {pos: [2, 8, 4], state: "minecraft:air"},
        {pos: [2, 8, 5], state: "minecraft:air"},
        {pos: [2, 8, 6], state: "minecraft:air"},
        {pos: [2, 8, 7], state: "minecraft:air"},
        {pos: [2, 8, 8], state: "minecraft:air"},
        {pos: [3, 8, 0], state: "minecraft:smooth_sandstone_slab{type:bottom,waterlogged:false}"},
        {pos: [3, 8, 1], state: "minecraft:air"},
        {pos: [3, 8, 2], state: "minecraft:smooth_sandstone_slab{type:bottom,waterlogged:false}"},
        {pos: [3, 8, 3], state: "minecraft:air"},
        {pos: [3, 8, 4], state: "minecraft:smooth_sandstone_slab{type:bottom,waterlogged:false}"},
        {pos: [3, 8, 5], state: "minecraft:air"},
        {pos: [3, 8, 6], state: "minecraft:air"},
        {pos: [3, 8, 7], state: "minecraft:air"},
        {pos: [3, 8, 8], state: "minecraft:air"},
        {pos: [4, 8, 0], state: "minecraft:air"},
        {pos: [4, 8, 1], state: "minecraft:air"},
        {pos: [4, 8, 2], state: "minecraft:air"},
        {pos: [4, 8, 3], state: "minecraft:air"},
        {pos: [4, 8, 4], state: "minecraft:air"},
        {pos: [4, 8, 5], state: "minecraft:air"},
        {pos: [4, 8, 6], state: "minecraft:air"},
        {pos: [4, 8, 7], state: "minecraft:air"},
        {pos: [4, 8, 8], state: "minecraft:air"},
        {pos: [5, 8, 0], state: "minecraft:smooth_sandstone_slab{type:bottom,waterlogged:false}"},
        {pos: [5, 8, 1], state: "minecraft:air"},
        {pos: [5, 8, 2], state: "minecraft:air"},
        {pos: [5, 8, 3], state: "minecraft:air"},
        {pos: [5, 8, 4], state: "minecraft:smooth_sandstone_slab{type:bottom,waterlogged:false}"},
        {pos: [5, 8, 5], state: "minecraft:air"},
        {pos: [5, 8, 6], state: "minecraft:air"},
        {pos: [5, 8, 7], state: "minecraft:air"},
        {pos: [5, 8, 8], state: "minecraft:air"},
        {pos: [6, 8, 0], state: "minecraft:smooth_sandstone_slab{type:bottom,waterlogged:false}"},
        {pos: [6, 8, 1], state: "minecraft:air"},
        {pos: [6, 8, 2], state: "minecraft:air"},
        {pos: [6, 8, 3], state: "minecraft:air"},
        {pos: [6, 8, 4], state: "minecraft:smooth_sandstone_slab{type:bottom,waterlogged:false}"},
        {pos: [6, 8, 5], state: "minecraft:air"},
        {pos: [6, 8, 6], state: "minecraft:air"},
        {pos: [6, 8, 7], state: "minecraft:air"},
        {pos: [6, 8, 8], state: "minecraft:air"},
        {pos: [7, 8, 0], state: "minecraft:air"},
        {pos: [7, 8, 1], state: "minecraft:air"},
        {pos: [7, 8, 2], state: "minecraft:air"},
        {pos: [7, 8, 3], state: "minecraft:air"},
        {pos: [7, 8, 4], state: "minecraft:air"},
        {pos: [7, 8, 5], state: "minecraft:air"},
        {pos: [7, 8, 6], state: "minecraft:air"},
        {pos: [7, 8, 7], state: "minecraft:air"},
        {pos: [7, 8, 8], state: "minecraft:air"},
        {pos: [8, 8, 0], state: "minecraft:smooth_sandstone_slab{type:bottom,waterlogged:false}"},
        {pos: [8, 8, 1], state: "minecraft:air"},
        {pos: [8, 8, 2], state: "minecraft:smooth_sandstone_slab{type:bottom,waterlogged:false}"},
        {pos: [8, 8, 3], state: "minecraft:air"},
        {pos: [8, 8, 4], state: "minecraft:smooth_sandstone_slab{type:bottom,waterlogged:false}"},
        {pos: [8, 8, 5], state: "minecraft:air"},
        {pos: [8, 8, 6], state: "minecraft:air"},
        {pos: [8, 8, 7], state: "minecraft:air"},
        {pos: [8, 8, 8], state: "minecraft:air"}
    ],
    entities: [],
    palette: [
        "minecraft:sand",
        "minecraft:smooth_sandstone",
        "minecraft:light_blue_glazed_terracotta{facing:south}",
        "minecraft:light_blue_glazed_terracotta{facing:east}",
        "minecraft:light_blue_glazed_terracotta{facing:west}",
        "minecraft:light_blue_glazed_terracotta{facing:north}",
        "minecraft:smithing_table",
        "minecraft:terracotta",
        "minecraft:smooth_sandstone_slab{type:double,waterlogged:false}",
        "minecraft:air",
        "minecraft:smooth_sandstone_stairs{facing:south,half:bottom,shape:straight,waterlogged:false}",
        "minecraft:jungle_button{face:wall,facing:south,powered:false}",
        "minecraft:jungle_button{face:wall,facing:east,powered:false}",
        "minecraft:jungle_button{face:wall,facing:north,powered:false}",
        "minecraft:jungle_button{face:wall,facing:west,powered:false}",
        "minecraft:smooth_sandstone_stairs{facing:south,half:bottom,shape:outer_left,waterlogged:false}",
        "minecraft:smooth_sandstone_stairs{facing:east,half:bottom,shape:straight,waterlogged:false}",
        "minecraft:smooth_sandstone_stairs{facing:north,half:bottom,shape:outer_right,waterlogged:false}",
        "minecraft:smooth_sandstone_stairs{facing:north,half:bottom,shape:straight,waterlogged:false}",
        "minecraft:potted_cactus",
        "minecraft:jungle_door{facing:west,half:lower,hinge:left,open:false,powered:false}",
        "minecraft:wall_torch{facing:east}",
        "minecraft:wall_torch{facing:west}",
        "minecraft:smooth_sandstone_stairs{facing:east,half:bottom,shape:outer_right,waterlogged:false}",
        "minecraft:smooth_sandstone_stairs{facing:east,half:bottom,shape:outer_left,waterlogged:false}",
        "minecraft:jungle_door{facing:west,half:upper,hinge:left,open:false,powered:false}",
        "minecraft:jungle_door{facing:west,half:lower,hinge:right,open:false,powered:false}",
        "minecraft:smooth_sandstone_slab{type:top,waterlogged:false}",
        "minecraft:jungle_door{facing:west,half:upper,hinge:right,open:false,powered:false}",
        "minecraft:smooth_sandstone_slab{type:bottom,waterlogged:false}",
        "minecraft:jigsaw{orientation:west_up}",
        "minecraft:chest{facing:south,type:single,waterlogged:false}"
    ]
}
