{
    size: [6, 4, 6],
    data: [
        {pos: [0, 0, 0], state: "minecraft:sulfur"},
        {pos: [0, 0, 4], state: "minecraft:sulfur"},
        {pos: [1, 0, 2], state: "minecraft:sulfur"},
        {pos: [1, 0, 3], state: "minecraft:sulfur"},
        {pos: [1, 0, 4], state: "minecraft:sulfur"},
        {pos: [1, 0, 5], state: "minecraft:sulfur"},
        {pos: [2, 0, 1], state: "minecraft:sulfur"},
        {pos: [2, 0, 2], state: "minecraft:sulfur"},
        {pos: [2, 0, 3], state: "minecraft:sulfur"},
        {pos: [2, 0, 4], state: "minecraft:sulfur"},
        {pos: [2, 0, 5], state: "minecraft:sulfur"},
        {pos: [3, 0, 0], state: "minecraft:sulfur"},
        {pos: [3, 0, 1], state: "minecraft:sulfur"},
        {pos: [3, 0, 2], state: "minecraft:magma_block"},
        {pos: [3, 0, 3], state: "minecraft:sulfur"},
        {pos: [3, 0, 4], state: "minecraft:sulfur"},
        {pos: [3, 0, 5], state: "minecraft:sulfur"},
        {pos: [4, 0, 0], state: "minecraft:sulfur"},
        {pos: [4, 0, 1], state: "minecraft:sulfur"},
        {pos: [4, 0, 2], state: "minecraft:sulfur"},
        {pos: [4, 0, 3], state: "minecraft:sulfur"},
        {pos: [4, 0, 4], state: "minecraft:sulfur"},
        {pos: [4, 0, 5], state: "minecraft:sulfur"},
        {pos: [5, 0, 3], state: "minecraft:sulfur"},
        {pos: [5, 0, 4], state: "minecraft:sulfur"},
        {pos: [1, 1, 3], state: "minecraft:sulfur"},
        {pos: [1, 1, 4], state: "minecraft:sulfur"},
        {pos: [2, 1, 2], state: "minecraft:sulfur"},
        {pos: [2, 1, 3], state: "minecraft:sulfur"},
        {pos: [2, 1, 4], state: "minecraft:sulfur"},
        {pos: [2, 1, 5], state: "minecraft:sulfur"},
        {pos: [3, 1, 1], state: "minecraft:sulfur"},
        {pos: [3, 1, 2], state: "minecraft:potent_sulfur{potent_sulfur_state:dormant}"},
        {pos: [3, 1, 3], state: "minecraft:sulfur"},
        {pos: [3, 1, 4], state: "minecraft:sulfur"},
        {pos: [3, 1, 5], state: "minecraft:sulfur"},
        {pos: [4, 1, 0], state: "minecraft:sulfur"},
        {pos: [4, 1, 1], state: "minecraft:sulfur"},
        {pos: [4, 1, 2], state: "minecraft:sulfur"},
        {pos: [4, 1, 3], state: "minecraft:sulfur"},
        {pos: [4, 1, 4], state: "minecraft:sulfur"},
        {pos: [5, 1, 2], state: "minecraft:sulfur"},
        {pos: [5, 1, 3], state: "minecraft:sulfur"},
        {pos: [5, 1, 4], state: "minecraft:sulfur"},
        {pos: [2, 2, 2], state: "minecraft:sulfur"},
        {pos: [2, 2, 3], state: "minecraft:sulfur"},
        {pos: [2, 2, 4], state: "minecraft:sulfur"},
        {pos: [3, 2, 1], state: "minecraft:sulfur"},
        {pos: [3, 2, 2], state: "minecraft:water{level:0}"},
        {pos: [3, 2, 3], state: "minecraft:water{level:0}"},
        {pos: [3, 2, 4], state: "minecraft:sulfur"},
        {pos: [4, 2, 1], state: "minecraft:sulfur"},
        {pos: [4, 2, 2], state: "minecraft:water{level:0}"},
        {pos: [4, 2, 3], state: "minecraft:water{level:0}"},
        {pos: [4, 2, 4], state: "minecraft:sulfur"},
        {pos: [5, 2, 1], state: "minecraft:sulfur"},
        {pos: [5, 2, 2], state: "minecraft:sulfur"},
        {pos: [5, 2, 3], state: "minecraft:sulfur"},
        {pos: [2, 3, 3], state: "minecraft:sulfur"},
        {pos: [3, 3, 4], state: "minecraft:sulfur"},
        {pos: [4, 3, 1], state: "minecraft:sulfur"},
        {pos: [5, 3, 2], state: "minecraft:sulfur"}
    ],
    entities: [],
    palette: [
        "minecraft:sulfur",
        "minecraft:magma_block",
        "minecraft:potent_sulfur{potent_sulfur_state:dormant}",
        "minecraft:water{level:0}"
    ]
}
