{
    size: [9, 11, 9],
    data: [
        {pos: [1, 0, 3], state: "minecraft:tuff"},
        {pos: [1, 0, 4], state: "minecraft:tuff"},
        {pos: [1, 0, 5], state: "minecraft:granite"},
        {pos: [2, 0, 2], state: "minecraft:cinnabar"},
        {pos: [2, 0, 3], state: "minecraft:granite"},
        {pos: [2, 0, 4], state: "minecraft:cinnabar"},
        {pos: [2, 0, 5], state: "minecraft:stone"},
        {pos: [2, 0, 6], state: "minecraft:stone"},
        {pos: [3, 0, 1], state: "minecraft:tuff"},
        {pos: [3, 0, 2], state: "minecraft:tuff"},
        {pos: [3, 0, 3], state: "minecraft:cinnabar"},
        {pos: [3, 0, 4], state: "minecraft:sulfur"},
        {pos: [3, 0, 5], state: "minecraft:granite"},
        {pos: [3, 0, 6], state: "minecraft:stone"},
        {pos: [3, 0, 7], state: "minecraft:tuff"},
        {pos: [4, 0, 1], state: "minecraft:stone"},
        {pos: [4, 0, 2], state: "minecraft:stone"},
        {pos: [4, 0, 3], state: "minecraft:granite"},
        {pos: [4, 0, 4], state: "minecraft:sulfur"},
        {pos: [4, 0, 5], state: "minecraft:sulfur"},
        {pos: [4, 0, 6], state: "minecraft:tuff"},
        {pos: [4, 0, 7], state: "minecraft:tuff"},
        {pos: [5, 0, 2], state: "minecraft:stone"},
        {pos: [5, 0, 3], state: "minecraft:granite"},
        {pos: [5, 0, 4], state: "minecraft:sulfur"},
        {pos: [5, 0, 5], state: "minecraft:granite"},
        {pos: [5, 0, 6], state: "minecraft:stone"},
        {pos: [5, 0, 7], state: "minecraft:tuff"},
        {pos: [6, 0, 2], state: "minecraft:stone"},
        {pos: [6, 0, 3], state: "minecraft:granite"},
        {pos: [6, 0, 4], state: "minecraft:stone"},
        {pos: [6, 0, 5], state: "minecraft:granite"},
        {pos: [6, 0, 6], state: "minecraft:stone"},
        {pos: [6, 0, 7], state: "minecraft:stone"},
        {pos: [7, 0, 3], state: "minecraft:tuff"},
        {pos: [7, 0, 4], state: "minecraft:tuff"},
        {pos: [7, 0, 5], state: "minecraft:tuff"},
        {pos: [7, 0, 6], state: "minecraft:tuff"},
        {pos: [0, 1, 3], state: "minecraft:tuff"},
        {pos: [0, 1, 4], state: "minecraft:tuff"},
        {pos: [0, 1, 5], state: "minecraft:stone"},
        {pos: [1, 1, 2], state: "minecraft:tuff"},
        {pos: [1, 1, 3], state: "minecraft:stone"},
        {pos: [1, 1, 4], state: "minecraft:tuff"},
        {pos: [1, 1, 5], state: "minecraft:granite"},
        {pos: [1, 1, 6], state: "minecraft:stone"},
        {pos: [2, 1, 1], state: "minecraft:granite"},
        {pos: [2, 1, 2], state: "minecraft:granite"},
        {pos: [2, 1, 3], state: "minecraft:granite"},
        {pos: [2, 1, 4], state: "minecraft:cinnabar"},
        {pos: [2, 1, 5], state: "minecraft:stone"},
        {pos: [2, 1, 6], state: "minecraft:stone"},
        {pos: [2, 1, 7], state: "minecraft:stone"},
        {pos: [3, 1, 0], state: "minecraft:stone"},
        {pos: [3, 1, 1], state: "minecraft:stone"},
        {pos: [3, 1, 2], state: "minecraft:tuff"},
        {pos: [3, 1, 3], state: "minecraft:cinnabar"},
        {pos: [3, 1, 4], state: "minecraft:granite"},
        {pos: [3, 1, 5], state: "minecraft:tuff"},
        {pos: [3, 1, 6], state: "minecraft:tuff"},
        {pos: [3, 1, 7], state: "minecraft:tuff"},
        {pos: [3, 1, 8], state: "minecraft:stone"},
        {pos: [4, 1, 0], state: "minecraft:granite"},
        {pos: [4, 1, 1], state: "minecraft:stone"},
        {pos: [4, 1, 2], state: "minecraft:stone"},
        {pos: [4, 1, 3], state: "minecraft:sulfur"},
        {pos: [4, 1, 4], state: "minecraft:sulfur"},
        {pos: [4, 1, 5], state: "minecraft:cinnabar"},
        {pos: [4, 1, 6], state: "minecraft:tuff"},
        {pos: [4, 1, 7], state: "minecraft:tuff"},
        {pos: [4, 1, 8], state: "minecraft:tuff"},
        {pos: [5, 1, 1], state: "minecraft:tuff"},
        {pos: [5, 1, 2], state: "minecraft:stone"},
        {pos: [5, 1, 3], state: "minecraft:cinnabar"},
        {pos: [5, 1, 4], state: "minecraft:cinnabar"},
        {pos: [5, 1, 5], state: "minecraft:cinnabar"},
        {pos: [5, 1, 6], state: "minecraft:stone"},
        {pos: [5, 1, 7], state: "minecraft:tuff"},
        {pos: [5, 1, 8], state: "minecraft:tuff"},
        {pos: [6, 1, 1], state: "minecraft:stone"},
        {pos: [6, 1, 2], state: "minecraft:cinnabar"},
        {pos: [6, 1, 3], state: "minecraft:cinnabar"},
        {pos: [6, 1, 4], state: "minecraft:cinnabar"},
        {pos: [6, 1, 5], state: "minecraft:granite"},
        {pos: [6, 1, 6], state: "minecraft:stone"},
        {pos: [6, 1, 7], state: "minecraft:stone"},
        {pos: [6, 1, 8], state: "minecraft:tuff"},
        {pos: [7, 1, 2], state: "minecraft:tuff"},
        {pos: [7, 1, 3], state: "minecraft:granite"},
        {pos: [7, 1, 4], state: "minecraft:cinnabar"},
        {pos: [7, 1, 5], state: "minecraft:stone"},
        {pos: [7, 1, 6], state: "minecraft:stone"},
        {pos: [7, 1, 7], state: "minecraft:granite"},
        {pos: [8, 1, 3], state: "minecraft:granite"},
        {pos: [8, 1, 4], state: "minecraft:tuff"},
        {pos: [8, 1, 5], state: "minecraft:tuff"},
        {pos: [8, 1, 6], state: "minecraft:stone"},
        {pos: [0, 2, 3], state: "minecraft:stone"},
        {pos: [0, 2, 4], state: "minecraft:tuff"},
        {pos: [0, 2, 5], state: "minecraft:tuff"},
        {pos: [1, 2, 2], state: "minecraft:tuff"},
        {pos: [1, 2, 3], state: "minecraft:tuff"},
        {pos: [1, 2, 4], state: "minecraft:tuff"},
        {pos: [1, 2, 5], state: "minecraft:tuff"},
        {pos: [1, 2, 6], state: "minecraft:stone"},
        {pos: [2, 2, 1], state: "minecraft:stone"},
        {pos: [2, 2, 2], state: "minecraft:stone"},
        {pos: [2, 2, 4], state: "minecraft:granite"},
        {pos: [2, 2, 5], state: "minecraft:tuff"},
        {pos: [2, 2, 6], state: "minecraft:stone"},
        {pos: [2, 2, 7], state: "minecraft:tuff"},
        {pos: [3, 2, 0], state: "minecraft:stone"},
        {pos: [3, 2, 1], state: "minecraft:tuff"},
        {pos: [3, 2, 2], state: "minecraft:cinnabar"},
        {pos: [3, 2, 3], state: "minecraft:cinnabar"},
        {pos: [3, 2, 4], state: "minecraft:sulfur"},
        {pos: [3, 2, 5], state: "minecraft:tuff"},
        {pos: [3, 2, 6], state: "minecraft:tuff"},
        {pos: [3, 2, 7], state: "minecraft:tuff"},
        {pos: [3, 2, 8], state: "minecraft:stone"},
        {pos: [4, 2, 0], state: "minecraft:granite"},
        {pos: [4, 2, 1], state: "minecraft:stone"},
        {pos: [4, 2, 2], state: "minecraft:tuff"},
        {pos: [4, 2, 3], state: "minecraft:granite"},
        {pos: [4, 2, 4], state: "minecraft:sulfur"},
        {pos: [4, 2, 5], state: "minecraft:sulfur"},
        {pos: [4, 2, 6], state: "minecraft:stone"},
        {pos: [4, 2, 7], state: "minecraft:tuff"},
        {pos: [4, 2, 8], state: "minecraft:stone"},
        {pos: [5, 2, 1], state: "minecraft:tuff"},
        {pos: [5, 2, 2], state: "minecraft:stone"},
        {pos: [5, 2, 3], state: "minecraft:cinnabar"},
        {pos: [5, 2, 4], state: "minecraft:granite"},
        {pos: [5, 2, 5], state: "minecraft:cinnabar"},
        {pos: [5, 2, 6], state: "minecraft:stone"},
        {pos: [5, 2, 7], state: "minecraft:tuff"},
        {pos: [5, 2, 8], state: "minecraft:granite"},
        {pos: [6, 2, 1], state: "minecraft:granite"},
        {pos: [6, 2, 2], state: "minecraft:cinnabar"},
        {pos: [6, 2, 3], state: "minecraft:cinnabar"},
        {pos: [6, 2, 4], state: "minecraft:granite"},
        {pos: [6, 2, 5], state: "minecraft:granite"},
        {pos: [6, 2, 6], state: "minecraft:tuff"},
        {pos: [6, 2, 7], state: "minecraft:tuff"},
        {pos: [6, 2, 8], state: "minecraft:tuff"},
        {pos: [7, 2, 2], state: "minecraft:tuff"},
        {pos: [7, 2, 3], state: "minecraft:cinnabar"},
        {pos: [7, 2, 4], state: "minecraft:granite"},
        {pos: [7, 2, 5], state: "minecraft:granite"},
        {pos: [7, 2, 6], state: "minecraft:cinnabar"},
        {pos: [7, 2, 7], state: "minecraft:tuff"},
        {pos: [8, 2, 3], state: "minecraft:granite"},
        {pos: [8, 2, 4], state: "minecraft:tuff"},
        {pos: [8, 2, 5], state: "minecraft:stone"},
        {pos: [8, 2, 6], state: "minecraft:stone"},
        {pos: [0, 3, 3], state: "minecraft:stone"},
        {pos: [0, 3, 4], state: "minecraft:stone"},
        {pos: [0, 3, 5], state: "minecraft:granite"},
        {pos: [1, 3, 2], state: "minecraft:tuff"},
        {pos: [1, 3, 3], state: "minecraft:tuff"},
        {pos: [1, 3, 4], state: "minecraft:tuff"},
        {pos: [1, 3, 5], state: "minecraft:tuff"},
        {pos: [1, 3, 6], state: "minecraft:tuff"},
        {pos: [2, 3, 1], state: "minecraft:stone"},
        {pos: [2, 3, 2], state: "minecraft:stone"},
        {pos: [2, 3, 3], state: "minecraft:stone"},
        {pos: [2, 3, 4], state: "minecraft:cinnabar"},
        {pos: [2, 3, 5], state: "minecraft:tuff"},
        {pos: [2, 3, 6], state: "minecraft:tuff"},
        {pos: [2, 3, 7], state: "minecraft:tuff"},
        {pos: [3, 3, 0], state: "minecraft:stone"},
        {pos: [3, 3, 1], state: "minecraft:tuff"},
        {pos: [3, 3, 2], state: "minecraft:granite"},
        {pos: [3, 3, 3], state: "minecraft:granite"},
        {pos: [3, 3, 4], state: "minecraft:granite"},
        {pos: [3, 3, 5], state: "minecraft:granite"},
        {pos: [3, 3, 6], state: "minecraft:tuff"},
        {pos: [3, 3, 7], state: "minecraft:tuff"},
        {pos: [3, 3, 8], state: "minecraft:tuff"},
        {pos: [4, 3, 0], state: "minecraft:tuff"},
        {pos: [4, 3, 1], state: "minecraft:stone"},
        {pos: [4, 3, 2], state: "minecraft:cinnabar"},
        {pos: [4, 3, 3], state: "minecraft:cinnabar"},
        {pos: [4, 3, 4], state: "minecraft:sulfur"},
        {pos: [4, 3, 5], state: "minecraft:sulfur"},
        {pos: [4, 3, 6], state: "minecraft:tuff"},
        {pos: [4, 3, 7], state: "minecraft:stone"},
        {pos: [4, 3, 8], state: "minecraft:tuff"},
        {pos: [5, 3, 1], state: "minecraft:stone"},
        {pos: [5, 3, 2], state: "minecraft:granite"},
        {pos: [5, 3, 3], state: "minecraft:sulfur"},
        {pos: [5, 3, 4], state: "minecraft:sulfur"},
        {pos: [5, 3, 5], state: "minecraft:sulfur"},
        {pos: [5, 3, 6], state: "minecraft:stone"},
        {pos: [5, 3, 7], state: "minecraft:stone"},
        {pos: [5, 3, 8], state: "minecraft:granite"},
        {pos: [6, 3, 1], state: "minecraft:granite"},
        {pos: [6, 3, 2], state: "minecraft:granite"},
        {pos: [6, 3, 3], state: "minecraft:granite"},
        {pos: [6, 3, 4], state: "minecraft:granite"},
        {pos: [6, 3, 5], state: "minecraft:cinnabar"},
        {pos: [6, 3, 6], state: "minecraft:tuff"},
        {pos: [6, 3, 7], state: "minecraft:stone"},
        {pos: [6, 3, 8], state: "minecraft:granite"},
        {pos: [7, 3, 2], state: "minecraft:stone"},
        {pos: [7, 3, 3], state: "minecraft:granite"},
        {pos: [7, 3, 4], state: "minecraft:granite"},
        {pos: [7, 3, 5], state: "minecraft:granite"},
        {pos: [7, 3, 6], state: "minecraft:granite"},
        {pos: [7, 3, 7], state: "minecraft:tuff"},
        {pos: [8, 3, 3], state: "minecraft:granite"},
        {pos: [8, 3, 4], state: "minecraft:tuff"},
        {pos: [8, 3, 5], state: "minecraft:stone"},
        {pos: [8, 3, 6], state: "minecraft:stone"},
        {pos: [0, 4, 3], state: "minecraft:stone"},
        {pos: [0, 4, 4], state: "minecraft:stone"},
        {pos: [0, 4, 5], state: "minecraft:granite"},
        {pos: [1, 4, 2], state: "minecraft:stone"},
        {pos: [1, 4, 3], state: "minecraft:tuff"},
        {pos: [1, 4, 4], state: "minecraft:tuff"},
        {pos: [1, 4, 5], state: "minecraft:tuff"},
        {pos: [1, 4, 6], state: "minecraft:stone"},
        {pos: [2, 4, 1], state: "minecraft:tuff"},
        {pos: [2, 4, 2], state: "minecraft:granite"},
        {pos: [2, 4, 3], state: "minecraft:sulfur"},
        {pos: [2, 4, 4], state: "minecraft:granite"},
        {pos: [2, 4, 5], state: "minecraft:granite"},
        {pos: [2, 4, 6], state: "minecraft:tuff"},
        {pos: [2, 4, 7], state: "minecraft:tuff"},
        {pos: [3, 4, 0], state: "minecraft:tuff"},
        {pos: [3, 4, 1], state: "minecraft:granite"},
        {pos: [3, 4, 2], state: "minecraft:sulfur"},
        {pos: [3, 4, 3], state: "minecraft:sulfur"},
        {pos: [3, 4, 4], state: "minecraft:sulfur"},
        {pos: [3, 4, 5], state: "minecraft:sulfur"},
        {pos: [3, 4, 6], state: "minecraft:tuff"},
        {pos: [3, 4, 7], state: "minecraft:stone"},
        {pos: [3, 4, 8], state: "minecraft:tuff"},
        {pos: [4, 4, 0], state: "minecraft:tuff"},
        {pos: [4, 4, 1], state: "minecraft:tuff"},
        {pos: [4, 4, 2], state: "minecraft:sulfur"},
        {pos: [4, 4, 3], state: "minecraft:sulfur"},
        {pos: [4, 4, 4], state: "minecraft:sulfur"},
        {pos: [4, 4, 5], state: "minecraft:magma_block"},
        {pos: [4, 4, 6], state: "minecraft:sulfur"},
        {pos: [4, 4, 7], state: "minecraft:tuff"},
        {pos: [4, 4, 8], state: "minecraft:tuff"},
        {pos: [5, 4, 1], state: "minecraft:tuff"},
        {pos: [5, 4, 2], state: "minecraft:cinnabar"},
        {pos: [5, 4, 3], state: "minecraft:sulfur"},
        {pos: [5, 4, 4], state: "minecraft:sulfur"},
        {pos: [5, 4, 5], state: "minecraft:sulfur"},
        {pos: [5, 4, 6], state: "minecraft:cinnabar"},
        {pos: [5, 4, 7], state: "minecraft:tuff"},
        {pos: [5, 4, 8], state: "minecraft:stone"},
        {pos: [6, 4, 1], state: "minecraft:stone"},
        {pos: [6, 4, 2], state: "minecraft:granite"},
        {pos: [6, 4, 3], state: "minecraft:granite"},
        {pos: [6, 4, 4], state: "minecraft:sulfur"},
        {pos: [6, 4, 5], state: "minecraft:sulfur"},
        {pos: [6, 4, 6], state: "minecraft:cinnabar"},
        {pos: [6, 4, 7], state: "minecraft:tuff"},
        {pos: [6, 4, 8], state: "minecraft:tuff"},
        {pos: [7, 4, 2], state: "minecraft:stone"},
        {pos: [7, 4, 3], state: "minecraft:granite"},
        {pos: [7, 4, 4], state: "minecraft:cinnabar"},
        {pos: [7, 4, 5], state: "minecraft:cinnabar"},
        {pos: [7, 4, 6], state: "minecraft:granite"},
        {pos: [7, 4, 7], state: "minecraft:stone"},
        {pos: [8, 4, 3], state: "minecraft:stone"},
        {pos: [8, 4, 4], state: "minecraft:tuff"},
        {pos: [8, 4, 5], state: "minecraft:tuff"},
        {pos: [8, 4, 6], state: "minecraft:tuff"},
        {pos: [0, 5, 3], state: "minecraft:tuff"},
        {pos: [0, 5, 4], state: "minecraft:stone"},
        {pos: [0, 5, 5], state: "minecraft:tuff"},
        {pos: [1, 5, 2], state: "minecraft:stone"},
        {pos: [1, 5, 3], state: "minecraft:cinnabar"},
        {pos: [1, 5, 4], state: "minecraft:granite"},
        {pos: [1, 5, 5], state: "minecraft:cinnabar"},
        {pos: [1, 5, 6], state: "minecraft:stone"},
        {pos: [2, 5, 1], state: "minecraft:tuff"},
        {pos: [2, 5, 2], state: "minecraft:cinnabar"},
        {pos: [2, 5, 3], state: "minecraft:sulfur"},
        {pos: [2, 5, 4], state: "minecraft:sulfur"},
        {pos: [2, 5, 5], state: "minecraft:sulfur"},
        {pos: [2, 5, 6], state: "minecraft:cinnabar"},
        {pos: [2, 5, 7], state: "minecraft:tuff"},
        {pos: [3, 5, 0], state: "minecraft:tuff"},
        {pos: [3, 5, 1], state: "minecraft:granite"},
        {pos: [3, 5, 2], state: "minecraft:sulfur"},
        {pos: [3, 5, 3], state: "minecraft:sulfur"},
        {pos: [3, 5, 4], state: "minecraft:sulfur"},
        {pos: [3, 5, 5], state: "minecraft:sulfur"},
        {pos: [3, 5, 6], state: "minecraft:cinnabar"},
        {pos: [3, 5, 7], state: "minecraft:tuff"},
        {pos: [3, 5, 8], state: "minecraft:tuff"},
        {pos: [4, 5, 0], state: "minecraft:tuff"},
        {pos: [4, 5, 1], state: "minecraft:cinnabar"},
        {pos: [4, 5, 2], state: "minecraft:sulfur"},
        {pos: [4, 5, 3], state: "minecraft:sulfur"},
        {pos: [4, 5, 4], state: "minecraft:sulfur_spike{thickness:tip,vertical_direction:up,waterlogged:true}"},
        {pos: [4, 5, 5], state: "minecraft:potent_sulfur{potent_sulfur_state:dormant}"},
        {pos: [4, 5, 6], state: "minecraft:sulfur"},
        {pos: [4, 5, 7], state: "minecraft:granite"},
        {pos: [4, 5, 8], state: "minecraft:stone"},
        {pos: [5, 5, 1], state: "minecraft:tuff"},
        {pos: [5, 5, 2], state: "minecraft:cinnabar"},
        {pos: [5, 5, 3], state: "minecraft:sulfur"},
        {pos: [5, 5, 4], state: "minecraft:water{level:0}"},
        {pos: [5, 5, 5], state: "minecraft:water{level:0}"},
        {pos: [5, 5, 6], state: "minecraft:sulfur"},
        {pos: [5, 5, 7], state: "minecraft:granite"},
        {pos: [5, 5, 8], state: "minecraft:stone"},
        {pos: [6, 5, 1], state: "minecraft:tuff"},
        {pos: [6, 5, 2], state: "minecraft:granite"},
        {pos: [6, 5, 3], state: "minecraft:granite"},
        {pos: [6, 5, 4], state: "minecraft:sulfur"},
        {pos: [6, 5, 5], state: "minecraft:sulfur"},
        {pos: [6, 5, 6], state: "minecraft:cinnabar"},
        {pos: [6, 5, 7], state: "minecraft:cinnabar"},
        {pos: [6, 5, 8], state: "minecraft:tuff"},
        {pos: [7, 5, 2], state: "minecraft:stone"},
        {pos: [7, 5, 3], state: "minecraft:cinnabar"},
        {pos: [7, 5, 4], state: "minecraft:granite"},
        {pos: [7, 5, 5], state: "minecraft:granite"},
        {pos: [7, 5, 6], state: "minecraft:cinnabar"},
        {pos: [7, 5, 7], state: "minecraft:tuff"},
        {pos: [8, 5, 3], state: "minecraft:stone"},
        {pos: [8, 5, 4], state: "minecraft:tuff"},
        {pos: [8, 5, 5], state: "minecraft:tuff"},
        {pos: [8, 5, 6], state: "minecraft:tuff"},
        {pos: [0, 6, 3], state: "minecraft:tuff"},
        {pos: [0, 6, 4], state: "minecraft:tuff"},
        {pos: [0, 6, 5], state: "minecraft:tuff"},
        {pos: [1, 6, 2], state: "minecraft:tuff"},
        {pos: [1, 6, 3], state: "minecraft:granite"},
        {pos: [1, 6, 4], state: "minecraft:cinnabar"},
        {pos: [1, 6, 5], state: "minecraft:granite"},
        {pos: [1, 6, 6], state: "minecraft:tuff"},
        {pos: [2, 6, 1], state: "minecraft:tuff"},
        {pos: [2, 6, 2], state: "minecraft:granite"},
        {pos: [2, 6, 3], state: "minecraft:sulfur"},
        {pos: [2, 6, 4], state: "minecraft:sulfur"},
        {pos: [2, 6, 5], state: "minecraft:sulfur"},
        {pos: [2, 6, 6], state: "minecraft:granite"},
        {pos: [2, 6, 7], state: "minecraft:tuff"},
        {pos: [3, 6, 0], state: "minecraft:tuff"},
        {pos: [3, 6, 1], state: "minecraft:cinnabar"},
        {pos: [3, 6, 2], state: "minecraft:sulfur"},
        {pos: [3, 6, 3], state: "minecraft:sulfur"},
        {pos: [3, 6, 4], state: "minecraft:water{level:0}"},
        {pos: [3, 6, 5], state: "minecraft:water{level:0}"},
        {pos: [3, 6, 6], state: "minecraft:sulfur"},
        {pos: [3, 6, 7], state: "minecraft:cinnabar"},
        {pos: [3, 6, 8], state: "minecraft:tuff"},
        {pos: [4, 6, 0], state: "minecraft:tuff"},
        {pos: [4, 6, 1], state: "minecraft:granite"},
        {pos: [4, 6, 2], state: "minecraft:sulfur"},
        {pos: [4, 6, 3], state: "minecraft:water{level:0}"},
        {pos: [4, 6, 4], state: "minecraft:water{level:0}"},
        {pos: [4, 6, 5], state: "minecraft:water{level:0}"},
        {pos: [4, 6, 6], state: "minecraft:sulfur"},
        {pos: [4, 6, 7], state: "minecraft:granite"},
        {pos: [4, 6, 8], state: "minecraft:tuff"},
        {pos: [5, 6, 1], state: "minecraft:tuff"},
        {pos: [5, 6, 2], state: "minecraft:cinnabar"},
        {pos: [5, 6, 3], state: "minecraft:sulfur"},
        {pos: [5, 6, 4], state: "minecraft:water{level:0}"},
        {pos: [5, 6, 5], state: "minecraft:water{level:0}"},
        {pos: [5, 6, 6], state: "minecraft:sulfur"},
        {pos: [5, 6, 7], state: "minecraft:cinnabar"},
        {pos: [5, 6, 8], state: "minecraft:tuff"},
        {pos: [6, 6, 1], state: "minecraft:tuff"},
        {pos: [6, 6, 2], state: "minecraft:granite"},
        {pos: [6, 6, 3], state: "minecraft:sulfur"},
        {pos: [6, 6, 4], state: "minecraft:sulfur"},
        {pos: [6, 6, 5], state: "minecraft:sulfur"},
        {pos: [6, 6, 6], state: "minecraft:sulfur"},
        {pos: [6, 6, 7], state: "minecraft:granite"},
        {pos: [6, 6, 8], state: "minecraft:tuff"},
        {pos: [7, 6, 2], state: "minecraft:tuff"},
        {pos: [7, 6, 3], state: "minecraft:cinnabar"},
        {pos: [7, 6, 4], state: "minecraft:granite"},
        {pos: [7, 6, 5], state: "minecraft:granite"},
        {pos: [7, 6, 6], state: "minecraft:cinnabar"},
        {pos: [7, 6, 7], state: "minecraft:tuff"},
        {pos: [8, 6, 3], state: "minecraft:tuff"},
        {pos: [8, 6, 4], state: "minecraft:tuff"},
        {pos: [8, 6, 5], state: "minecraft:tuff"},
        {pos: [8, 6, 6], state: "minecraft:tuff"},
        {pos: [0, 7, 3], state: "minecraft:air"},
        {pos: [0, 7, 4], state: "minecraft:air"},
        {pos: [0, 7, 5], state: "minecraft:air"},
        {pos: [1, 7, 2], state: "minecraft:air"},
        {pos: [1, 7, 3], state: "minecraft:air"},
        {pos: [1, 7, 4], state: "minecraft:air"},
        {pos: [1, 7, 5], state: "minecraft:air"},
        {pos: [1, 7, 6], state: "minecraft:air"},
        {pos: [2, 7, 1], state: "minecraft:air"},
        {pos: [2, 7, 2], state: "minecraft:air"},
        {pos: [2, 7, 3], state: "minecraft:air"},
        {pos: [2, 7, 4], state: "minecraft:sulfur"},
        {pos: [2, 7, 5], state: "minecraft:sulfur"},
        {pos: [2, 7, 6], state: "minecraft:air"},
        {pos: [2, 7, 7], state: "minecraft:air"},
        {pos: [3, 7, 0], state: "minecraft:air"},
        {pos: [3, 7, 1], state: "minecraft:air"},
        {pos: [3, 7, 2], state: "minecraft:air"},
        {pos: [3, 7, 3], state: "minecraft:air"},
        {pos: [3, 7, 4], state: "minecraft:air"},
        {pos: [3, 7, 5], state: "minecraft:air"},
        {pos: [3, 7, 6], state: "minecraft:air"},
        {pos: [3, 7, 7], state: "minecraft:air"},
        {pos: [3, 7, 8], state: "minecraft:air"},
        {pos: [4, 7, 0], state: "minecraft:air"},
        {pos: [4, 7, 1], state: "minecraft:air"},
        {pos: [4, 7, 2], state: "minecraft:sulfur_spike{thickness:tip,vertical_direction:up,waterlogged:false}"},
        {pos: [4, 7, 3], state: "minecraft:air"},
        {pos: [4, 7, 4], state: "minecraft:air"},
        {pos: [4, 7, 5], state: "minecraft:air"},
        {pos: [4, 7, 6], state: "minecraft:sulfur"},
        {pos: [4, 7, 7], state: "minecraft:air"},
        {pos: [4, 7, 8], state: "minecraft:air"},
        {pos: [5, 7, 1], state: "minecraft:air"},
        {pos: [5, 7, 2], state: "minecraft:air"},
        {pos: [5, 7, 3], state: "minecraft:air"},
        {pos: [5, 7, 4], state: "minecraft:air"},
        {pos: [5, 7, 5], state: "minecraft:air"},
        {pos: [5, 7, 6], state: "minecraft:sulfur"},
        {pos: [5, 7, 7], state: "minecraft:air"},
        {pos: [5, 7, 8], state: "minecraft:air"},
        {pos: [6, 7, 1], state: "minecraft:air"},
        {pos: [6, 7, 2], state: "minecraft:air"},
        {pos: [6, 7, 3], state: "minecraft:air"},
        {pos: [6, 7, 4], state: "minecraft:sulfur_spike{thickness:tip,vertical_direction:up,waterlogged:false}"},
        {pos: [6, 7, 5], state: "minecraft:sulfur"},
        {pos: [6, 7, 6], state: "minecraft:sulfur"},
        {pos: [6, 7, 7], state: "minecraft:air"},
        {pos: [6, 7, 8], state: "minecraft:air"},
        {pos: [7, 7, 2], state: "minecraft:air"},
        {pos: [7, 7, 3], state: "minecraft:air"},
        {pos: [7, 7, 4], state: "minecraft:air"},
        {pos: [7, 7, 5], state: "minecraft:air"},
        {pos: [7, 7, 6], state: "minecraft:air"},
        {pos: [7, 7, 7], state: "minecraft:air"},
        {pos: [8, 7, 3], state: "minecraft:air"},
        {pos: [8, 7, 4], state: "minecraft:air"},
        {pos: [8, 7, 5], state: "minecraft:air"},
        {pos: [8, 7, 6], state: "minecraft:air"},
        {pos: [0, 8, 2], state: "minecraft:air"},
        {pos: [0, 8, 3], state: "minecraft:air"},
        {pos: [0, 8, 4], state: "minecraft:air"},
        {pos: [0, 8, 5], state: "minecraft:air"},
        {pos: [0, 8, 6], state: "minecraft:air"},
        {pos: [1, 8, 2], state: "minecraft:air"},
        {pos: [1, 8, 3], state: "minecraft:air"},
        {pos: [1, 8, 4], state: "minecraft:air"},
        {pos: [1, 8, 5], state: "minecraft:air"},
        {pos: [1, 8, 6], state: "minecraft:air"},
        {pos: [2, 8, 0], state: "minecraft:air"},
        {pos: [2, 8, 1], state: "minecraft:air"},
        {pos: [2, 8, 2], state: "minecraft:air"},
        {pos: [2, 8, 3], state: "minecraft:air"},
        {pos: [2, 8, 4], state: "minecraft:sulfur_spike{thickness:tip,vertical_direction:up,waterlogged:false}"},
        {pos: [2, 8, 5], state: "minecraft:air"},
        {pos: [2, 8, 6], state: "minecraft:air"},
        {pos: [2, 8, 7], state: "minecraft:air"},
        {pos: [3, 8, 0], state: "minecraft:air"},
        {pos: [3, 8, 1], state: "minecraft:air"},
        {pos: [3, 8, 2], state: "minecraft:air"},
        {pos: [3, 8, 3], state: "minecraft:air"},
        {pos: [3, 8, 4], state: "minecraft:air"},
        {pos: [3, 8, 5], state: "minecraft:air"},
        {pos: [3, 8, 6], state: "minecraft:air"},
        {pos: [3, 8, 7], state: "minecraft:air"},
        {pos: [3, 8, 8], state: "minecraft:air"},
        {pos: [4, 8, 0], state: "minecraft:air"},
        {pos: [4, 8, 1], state: "minecraft:air"},
        {pos: [4, 8, 2], state: "minecraft:air"},
        {pos: [4, 8, 3], state: "minecraft:air"},
        {pos: [4, 8, 4], state: "minecraft:air"},
        {pos: [4, 8, 5], state: "minecraft:air"},
        {pos: [4, 8, 6], state: "minecraft:sulfur_spike{thickness:tip,vertical_direction:up,waterlogged:false}"},
        {pos: [4, 8, 7], state: "minecraft:air"},
        {pos: [4, 8, 8], state: "minecraft:air"},
        {pos: [5, 8, 0], state: "minecraft:air"},
        {pos: [5, 8, 1], state: "minecraft:air"},
        {pos: [5, 8, 2], state: "minecraft:air"},
        {pos: [5, 8, 3], state: "minecraft:air"},
        {pos: [5, 8, 4], state: "minecraft:air"},
        {pos: [5, 8, 5], state: "minecraft:air"},
        {pos: [5, 8, 6], state: "minecraft:sulfur"},
        {pos: [5, 8, 7], state: "minecraft:air"},
        {pos: [5, 8, 8], state: "minecraft:air"},
        {pos: [6, 8, 1], state: "minecraft:air"},
        {pos: [6, 8, 2], state: "minecraft:air"},
        {pos: [6, 8, 3], state: "minecraft:air"},
        {pos: [6, 8, 4], state: "minecraft:sulfur_spike{thickness:tip,vertical_direction:up,waterlogged:false}"},
        {pos: [6, 8, 5], state: "minecraft:sulfur"},
        {pos: [6, 8, 6], state: "minecraft:air"},
        {pos: [6, 8, 7], state: "minecraft:air"},
        {pos: [6, 8, 8], state: "minecraft:air"},
        {pos: [7, 8, 2], state: "minecraft:air"},
        {pos: [7, 8, 3], state: "minecraft:air"},
        {pos: [7, 8, 4], state: "minecraft:air"},
        {pos: [7, 8, 5], state: "minecraft:air"},
        {pos: [7, 8, 6], state: "minecraft:air"},
        {pos: [7, 8, 7], state: "minecraft:air"},
        {pos: [8, 8, 2], state: "minecraft:air"},
        {pos: [8, 8, 3], state: "minecraft:air"},
        {pos: [8, 8, 4], state: "minecraft:air"},
        {pos: [8, 8, 5], state: "minecraft:air"},
        {pos: [8, 8, 6], state: "minecraft:air"},
        {pos: [0, 9, 2], state: "minecraft:air"},
        {pos: [0, 9, 3], state: "minecraft:air"},
        {pos: [0, 9, 4], state: "minecraft:air"},
        {pos: [0, 9, 5], state: "minecraft:air"},
        {pos: [0, 9, 6], state: "minecraft:air"},
        {pos: [1, 9, 1], state: "minecraft:air"},
        {pos: [1, 9, 2], state: "minecraft:air"},
        {pos: [1, 9, 3], state: "minecraft:air"},
        {pos: [1, 9, 4], state: "minecraft:air"},
        {pos: [1, 9, 5], state: "minecraft:air"},
        {pos: [1, 9, 6], state: "minecraft:air"},
        {pos: [1, 9, 7], state: "minecraft:air"},
        {pos: [2, 9, 0], state: "minecraft:air"},
        {pos: [2, 9, 1], state: "minecraft:air"},
        {pos: [2, 9, 2], state: "minecraft:air"},
        {pos: [2, 9, 3], state: "minecraft:air"},
        {pos: [2, 9, 4], state: "minecraft:air"},
        {pos: [2, 9, 5], state: "minecraft:air"},
        {pos: [2, 9, 6], state: "minecraft:air"},
        {pos: [2, 9, 7], state: "minecraft:air"},
        {pos: [2, 9, 8], state: "minecraft:air"},
        {pos: [3, 9, 0], state: "minecraft:air"},
        {pos: [3, 9, 1], state: "minecraft:air"},
        {pos: [3, 9, 2], state: "minecraft:air"},
        {pos: [3, 9, 3], state: "minecraft:air"},
        {pos: [3, 9, 4], state: "minecraft:air"},
        {pos: [3, 9, 5], state: "minecraft:air"},
        {pos: [3, 9, 6], state: "minecraft:air"},
        {pos: [3, 9, 7], state: "minecraft:air"},
        {pos: [3, 9, 8], state: "minecraft:air"},
        {pos: [4, 9, 0], state: "minecraft:air"},
        {pos: [4, 9, 1], state: "minecraft:air"},
        {pos: [4, 9, 2], state: "minecraft:air"},
        {pos: [4, 9, 3], state: "minecraft:air"},
        {pos: [4, 9, 4], state: "minecraft:air"},
        {pos: [4, 9, 5], state: "minecraft:air"},
        {pos: [4, 9, 6], state: "minecraft:air"},
        {pos: [4, 9, 7], state: "minecraft:air"},
        {pos: [4, 9, 8], state: "minecraft:air"},
        {pos: [5, 9, 0], state: "minecraft:air"},
        {pos: [5, 9, 1], state: "minecraft:air"},
        {pos: [5, 9, 2], state: "minecraft:air"},
        {pos: [5, 9, 3], state: "minecraft:air"},
        {pos: [5, 9, 4], state: "minecraft:air"},
        {pos: [5, 9, 5], state: "minecraft:air"},
        {pos: [5, 9, 6], state: "minecraft:sulfur"},
        {pos: [5, 9, 7], state: "minecraft:air"},
        {pos: [5, 9, 8], state: "minecraft:air"},
        {pos: [6, 9, 0], state: "minecraft:air"},
        {pos: [6, 9, 1], state: "minecraft:air"},
        {pos: [6, 9, 2], state: "minecraft:air"},
        {pos: [6, 9, 3], state: "minecraft:air"},
        {pos: [6, 9, 4], state: "minecraft:air"},
        {pos: [6, 9, 5], state: "minecraft:sulfur_spike{thickness:tip,vertical_direction:up,waterlogged:false}"},
        {pos: [6, 9, 6], state: "minecraft:air"},
        {pos: [6, 9, 7], state: "minecraft:air"},
        {pos: [6, 9, 8], state: "minecraft:air"},
        {pos: [7, 9, 1], state: "minecraft:air"},
        {pos: [7, 9, 2], state: "minecraft:air"},
        {pos: [7, 9, 3], state: "minecraft:air"},
        {pos: [7, 9, 4], state: "minecraft:air"},
        {pos: [7, 9, 5], state: "minecraft:air"},
        {pos: [7, 9, 6], state: "minecraft:air"},
        {pos: [7, 9, 7], state: "minecraft:air"},
        {pos: [7, 9, 8], state: "minecraft:air"},
        {pos: [8, 9, 2], state: "minecraft:air"},
        {pos: [8, 9, 3], state: "minecraft:air"},
        {pos: [8, 9, 4], state: "minecraft:air"},
        {pos: [8, 9, 5], state: "minecraft:air"},
        {pos: [8, 9, 6], state: "minecraft:air"},
        {pos: [0, 10, 1], state: "minecraft:air"},
        {pos: [0, 10, 2], state: "minecraft:air"},
        {pos: [0, 10, 3], state: "minecraft:air"},
        {pos: [0, 10, 4], state: "minecraft:air"},
        {pos: [0, 10, 5], state: "minecraft:air"},
        {pos: [0, 10, 6], state: "minecraft:air"},
        {pos: [0, 10, 7], state: "minecraft:air"},
        {pos: [1, 10, 0], state: "minecraft:air"},
        {pos: [1, 10, 1], state: "minecraft:air"},
        {pos: [1, 10, 2], state: "minecraft:air"},
        {pos: [1, 10, 3], state: "minecraft:air"},
        {pos: [1, 10, 4], state: "minecraft:air"},
        {pos: [1, 10, 5], state: "minecraft:air"},
        {pos: [1, 10, 6], state: "minecraft:air"},
        {pos: [1, 10, 7], state: "minecraft:air"},
        {pos: [1, 10, 8], state: "minecraft:air"},
        {pos: [2, 10, 0], state: "minecraft:air"},
        {pos: [2, 10, 1], state: "minecraft:air"},
        {pos: [2, 10, 2], state: "minecraft:air"},
        {pos: [2, 10, 3], state: "minecraft:air"},
        {pos: [2, 10, 4], state: "minecraft:air"},
        {pos: [2, 10, 5], state: "minecraft:air"},
        {pos: [2, 10, 6], state: "minecraft:air"},
        {pos: [2, 10, 7], state: "minecraft:air"},
        {pos: [2, 10, 8], state: "minecraft:air"},
        {pos: [3, 10, 0], state: "minecraft:air"},
        {pos: [3, 10, 1], state: "minecraft:air"},
        {pos: [3, 10, 2], state: "minecraft:air"},
        {pos: [3, 10, 3], state: "minecraft:air"},
        {pos: [3, 10, 4], state: "minecraft:air"},
        {pos: [3, 10, 5], state: "minecraft:air"},
        {pos: [3, 10, 6], state: "minecraft:air"},
        {pos: [3, 10, 7], state: "minecraft:air"},
        {pos: [3, 10, 8], state: "minecraft:air"},
        {pos: [4, 10, 0], state: "minecraft:air"},
        {pos: [4, 10, 1], state: "minecraft:air"},
        {pos: [4, 10, 2], state: "minecraft:air"},
        {pos: [4, 10, 3], state: "minecraft:air"},
        {pos: [4, 10, 4], state: "minecraft:air"},
        {pos: [4, 10, 5], state: "minecraft:air"},
        {pos: [4, 10, 6], state: "minecraft:air"},
        {pos: [4, 10, 7], state: "minecraft:air"},
        {pos: [4, 10, 8], state: "minecraft:air"},
        {pos: [5, 10, 0], state: "minecraft:air"},
        {pos: [5, 10, 1], state: "minecraft:air"},
        {pos: [5, 10, 2], state: "minecraft:air"},
        {pos: [5, 10, 3], state: "minecraft:air"},
        {pos: [5, 10, 4], state: "minecraft:air"},
        {pos: [5, 10, 5], state: "minecraft:air"},
        {pos: [5, 10, 6], state: "minecraft:sulfur_spike{thickness:tip,vertical_direction:up,waterlogged:false}"},
        {pos: [5, 10, 7], state: "minecraft:air"},
        {pos: [5, 10, 8], state: "minecraft:air"},
        {pos: [6, 10, 0], state: "minecraft:air"},
        {pos: [6, 10, 1], state: "minecraft:air"},
        {pos: [6, 10, 2], state: "minecraft:air"},
        {pos: [6, 10, 3], state: "minecraft:air"},
        {pos: [6, 10, 4], state: "minecraft:air"},
        {pos: [6, 10, 5], state: "minecraft:air"},
        {pos: [6, 10, 6], state: "minecraft:air"},
        {pos: [6, 10, 7], state: "minecraft:air"},
        {pos: [6, 10, 8], state: "minecraft:air"},
        {pos: [7, 10, 0], state: "minecraft:air"},
        {pos: [7, 10, 1], state: "minecraft:air"},
        {pos: [7, 10, 2], state: "minecraft:air"},
        {pos: [7, 10, 3], state: "minecraft:air"},
        {pos: [7, 10, 4], state: "minecraft:air"},
        {pos: [7, 10, 5], state: "minecraft:air"},
        {pos: [7, 10, 6], state: "minecraft:air"},
        {pos: [7, 10, 7], state: "minecraft:air"},
        {pos: [7, 10, 8], state: "minecraft:air"},
        {pos: [8, 10, 1], state: "minecraft:air"},
        {pos: [8, 10, 2], state: "minecraft:air"},
        {pos: [8, 10, 3], state: "minecraft:air"},
        {pos: [8, 10, 4], state: "minecraft:air"},
        {pos: [8, 10, 5], state: "minecraft:air"},
        {pos: [8, 10, 6], state: "minecraft:air"},
        {pos: [8, 10, 7], state: "minecraft:air"}
    ],
    entities: [],
    palette: [
        "minecraft:tuff",
        "minecraft:granite",
        "minecraft:cinnabar",
        "minecraft:stone",
        "minecraft:sulfur",
        "minecraft:magma_block",
        "minecraft:potent_sulfur{potent_sulfur_state:dormant}",
        "minecraft:sulfur_spike{thickness:tip,vertical_direction:up,waterlogged:true}",
        "minecraft:water{level:0}",
        "minecraft:air",
        "minecraft:sulfur_spike{thickness:tip,vertical_direction:up,waterlogged:false}"
    ]
}
