{
    size: [10, 10, 11],
    data: [
        {pos: [0, 0, 3], state: "minecraft:dirt"},
        {pos: [0, 0, 5], state: "minecraft:dirt"},
        {pos: [0, 0, 7], state: "minecraft:pale_moss_block"},
        {pos: [0, 0, 8], state: "minecraft:pale_moss_block"},
        {pos: [1, 0, 2], state: "minecraft:dirt"},
        {pos: [1, 0, 3], state: "minecraft:dirt"},
        {pos: [1, 0, 4], state: "minecraft:dirt"},
        {pos: [1, 0, 5], state: "minecraft:dirt"},
        {pos: [1, 0, 6], state: "minecraft:pale_moss_block"},
        {pos: [1, 0, 7], state: "minecraft:dirt"},
        {pos: [1, 0, 8], state: "minecraft:dirt"},
        {pos: [1, 0, 9], state: "minecraft:dirt"},
        {pos: [2, 0, 1], state: "minecraft:pale_moss_block"},
        {pos: [2, 0, 2], state: "minecraft:dirt"},
        {pos: [2, 0, 3], state: "minecraft:dirt"},
        {pos: [2, 0, 4], state: "minecraft:dirt"},
        {pos: [2, 0, 5], state: "minecraft:dirt_path"},
        {pos: [2, 0, 6], state: "minecraft:dirt"},
        {pos: [2, 0, 7], state: "minecraft:dirt"},
        {pos: [2, 0, 8], state: "minecraft:dirt"},
        {pos: [2, 0, 9], state: "minecraft:dirt"},
        {pos: [3, 0, 2], state: "minecraft:dirt"},
        {pos: [3, 0, 3], state: "minecraft:dirt"},
        {pos: [3, 0, 4], state: "minecraft:dirt"},
        {pos: [3, 0, 5], state: "minecraft:dirt_path"},
        {pos: [3, 0, 6], state: "minecraft:dirt_path"},
        {pos: [3, 0, 7], state: "minecraft:dirt"},
        {pos: [3, 0, 8], state: "minecraft:dirt"},
        {pos: [3, 0, 9], state: "minecraft:dirt"},
        {pos: [3, 0, 10], state: "minecraft:dirt"},
        {pos: [4, 0, 0], state: "minecraft:pale_moss_block"},
        {pos: [4, 0, 1], state: "minecraft:dirt"},
        {pos: [4, 0, 2], state: "minecraft:dirt"},
        {pos: [4, 0, 3], state: "minecraft:dirt"},
        {pos: [4, 0, 4], state: "minecraft:oxidized_copper_chest{facing:south,type:single,waterlogged:false}", nbt: {Items: [], LootTable: "minecraft:chests/abandoned_camp_secret_chest", components: {}, id: "minecraft:chest"}},
        {pos: [4, 0, 5], state: "minecraft:dirt_path"},
        {pos: [4, 0, 6], state: "minecraft:dirt_path"},
        {pos: [4, 0, 7], state: "minecraft:grass_block{snowy:false}"},
        {pos: [4, 0, 8], state: "minecraft:dirt_path"},
        {pos: [4, 0, 9], state: "minecraft:dirt"},
        {pos: [4, 0, 10], state: "minecraft:dirt"},
        {pos: [5, 0, 1], state: "minecraft:pale_moss_block"},
        {pos: [5, 0, 2], state: "minecraft:dirt"},
        {pos: [5, 0, 3], state: "minecraft:dirt"},
        {pos: [5, 0, 4], state: "minecraft:dirt"},
        {pos: [5, 0, 5], state: "minecraft:dirt_path"},
        {pos: [5, 0, 6], state: "minecraft:grass_block{snowy:false}"},
        {pos: [5, 0, 7], state: "minecraft:dirt_path"},
        {pos: [5, 0, 8], state: "minecraft:dirt_path"},
        {pos: [5, 0, 9], state: "minecraft:dirt"},
        {pos: [5, 0, 10], state: "minecraft:dirt"},
        {pos: [6, 0, 2], state: "minecraft:pale_moss_block"},
        {pos: [6, 0, 3], state: "minecraft:dirt"},
        {pos: [6, 0, 4], state: "minecraft:dirt"},
        {pos: [6, 0, 5], state: "minecraft:dirt_path"},
        {pos: [6, 0, 6], state: "minecraft:dirt_path"},
        {pos: [6, 0, 7], state: "minecraft:dirt_path"},
        {pos: [6, 0, 8], state: "minecraft:dirt_path"},
        {pos: [6, 0, 9], state: "minecraft:dirt"},
        {pos: [6, 0, 10], state: "minecraft:dirt"},
        {pos: [7, 0, 0], state: "minecraft:pale_moss_block"},
        {pos: [7, 0, 1], state: "minecraft:dirt"},
        {pos: [7, 0, 2], state: "minecraft:dirt"},
        {pos: [7, 0, 3], state: "minecraft:dirt"},
        {pos: [7, 0, 4], state: "minecraft:dirt"},
        {pos: [7, 0, 5], state: "minecraft:dirt_path"},
        {pos: [7, 0, 6], state: "minecraft:dirt_path"},
        {pos: [7, 0, 7], state: "minecraft:dirt_path"},
        {pos: [7, 0, 8], state: "minecraft:dirt"},
        {pos: [7, 0, 9], state: "minecraft:dirt"},
        {pos: [7, 0, 10], state: "minecraft:dirt"},
        {pos: [8, 0, 0], state: "minecraft:pale_moss_block"},
        {pos: [8, 0, 1], state: "minecraft:dirt"},
        {pos: [8, 0, 2], state: "minecraft:dirt"},
        {pos: [8, 0, 3], state: "minecraft:dirt"},
        {pos: [8, 0, 4], state: "minecraft:dirt"},
        {pos: [8, 0, 5], state: "minecraft:dirt_path"},
        {pos: [8, 0, 6], state: "minecraft:dirt_path"},
        {pos: [8, 0, 7], state: "minecraft:dirt"},
        {pos: [8, 0, 8], state: "minecraft:dirt"},
        {pos: [9, 0, 2], state: "minecraft:dirt"},
        {pos: [9, 0, 3], state: "minecraft:dirt"},
        {pos: [9, 0, 4], state: "minecraft:dirt_path"},
        {pos: [9, 0, 5], state: "minecraft:dirt_path"},
        {pos: [0, 1, 3], state: "minecraft:pale_moss_block"},
        {pos: [0, 1, 5], state: "minecraft:grass_block{snowy:false}"},
        {pos: [1, 1, 2], state: "minecraft:pale_moss_block"},
        {pos: [1, 1, 3], state: "minecraft:dirt"},
        {pos: [1, 1, 4], state: "minecraft:dirt"},
        {pos: [1, 1, 5], state: "minecraft:pale_moss_block"},
        {pos: [1, 1, 7], state: "minecraft:grass_block{snowy:false}"},
        {pos: [1, 1, 8], state: "minecraft:grass_block{snowy:false}"},
        {pos: [1, 1, 9], state: "minecraft:pale_moss_block"},
        {pos: [2, 1, 2], state: "minecraft:grass_block{snowy:false}"},
        {pos: [2, 1, 3], state: "minecraft:dirt"},
        {pos: [2, 1, 4], state: "minecraft:dirt"},
        {pos: [2, 1, 6], state: "minecraft:pale_moss_block"},
        {pos: [2, 1, 7], state: "minecraft:pale_moss_block"},
        {pos: [2, 1, 8], state: "minecraft:grass_block{snowy:false}"},
        {pos: [2, 1, 9], state: "minecraft:pale_moss_block"},
        {pos: [3, 1, 2], state: "minecraft:pale_moss_block"},
        {pos: [3, 1, 3], state: "minecraft:dirt"},
        {pos: [3, 1, 4], state: "minecraft:grass_block{snowy:false}"},
        {pos: [3, 1, 7], state: "minecraft:grass_block{snowy:false}"},
        {pos: [3, 1, 8], state: "minecraft:grass_block{snowy:false}"},
        {pos: [3, 1, 9], state: "minecraft:grass_block{snowy:false}"},
        {pos: [3, 1, 10], state: "minecraft:grass_block{snowy:false}"},
        {pos: [4, 1, 1], state: "minecraft:pale_moss_block"},
        {pos: [4, 1, 2], state: "minecraft:pale_moss_block"},
        {pos: [4, 1, 3], state: "minecraft:dirt"},
        {pos: [4, 1, 4], state: "minecraft:chest{facing:south,type:single,waterlogged:false}", nbt: {Items: [], LootTable: "minecraft:chests/abandoned_camp_common_chest", components: {}, id: "minecraft:chest"}},
        {pos: [4, 1, 7], state: "minecraft:closed_eyeblossom"},
        {pos: [4, 1, 9], state: "minecraft:grass_block{snowy:false}"},
        {pos: [4, 1, 10], state: "minecraft:pale_moss_block"},
        {pos: [5, 1, 2], state: "minecraft:grass_block{snowy:false}"},
        {pos: [5, 1, 3], state: "minecraft:grass_block{snowy:false}"},
        {pos: [5, 1, 4], state: "minecraft:grass_block{snowy:false}"},
        {pos: [5, 1, 6], state: "minecraft:campfire{facing:west,lit:false,signal_fire:false,waterlogged:false}", nbt: {CookingTimes: [I; 0, 0, 0, 0], CookingTotalTimes: [I; 0, 0, 0, 0], Items: [], components: {}, id: "minecraft:campfire"}},
        {pos: [5, 1, 9], state: "minecraft:grass_block{snowy:false}"},
        {pos: [5, 1, 10], state: "minecraft:grass_block{snowy:false}"},
        {pos: [6, 1, 3], state: "minecraft:grass_block{snowy:false}"},
        {pos: [6, 1, 4], state: "minecraft:jigsaw{orientation:up_west}", nbt: {components: {}, final_state: "minecraft:dirt", id: "minecraft:jigsaw", joint: "rollable", name: "minecraft:bottom", placement_priority: 0, pool: "minecraft:abandoned_camp/trees/pale_oak", selection_priority: 0, target: "minecraft:bottom"}},
        {pos: [6, 1, 9], state: "minecraft:grass_block{snowy:false}"},
        {pos: [6, 1, 10], state: "minecraft:pale_moss_block"},
        {pos: [7, 1, 1], state: "minecraft:pale_moss_block"},
        {pos: [7, 1, 2], state: "minecraft:grass_block{snowy:false}"},
        {pos: [7, 1, 3], state: "minecraft:dirt"},
        {pos: [7, 1, 4], state: "minecraft:pale_moss_block"},
        {pos: [7, 1, 8], state: "minecraft:grass_block{snowy:false}"},
        {pos: [7, 1, 9], state: "minecraft:grass_block{snowy:false}"},
        {pos: [7, 1, 10], state: "minecraft:pale_moss_block"},
        {pos: [8, 1, 1], state: "minecraft:grass_block{snowy:false}"},
        {pos: [8, 1, 2], state: "minecraft:grass_block{snowy:false}"},
        {pos: [8, 1, 3], state: "minecraft:grass_block{snowy:false}"},
        {pos: [8, 1, 4], state: "minecraft:grass_block{snowy:false}"},
        {pos: [8, 1, 7], state: "minecraft:grass_block{snowy:false}"},
        {pos: [8, 1, 8], state: "minecraft:pale_moss_block"},
        {pos: [9, 1, 2], state: "minecraft:grass_block{snowy:false}"},
        {pos: [9, 1, 3], state: "minecraft:pale_moss_block"},
        {pos: [0, 2, 5], state: "minecraft:pale_moss_carpet{bottom:true,east:none,north:none,south:none,west:none}"},
        {pos: [1, 2, 3], state: "minecraft:pale_moss_block"},
        {pos: [1, 2, 4], state: "minecraft:pale_moss_block"},
        {pos: [1, 2, 8], state: "minecraft:closed_eyeblossom"},
        {pos: [2, 2, 2], state: "minecraft:pale_moss_carpet{bottom:true,east:none,north:none,south:low,west:none}"},
        {pos: [2, 2, 3], state: "minecraft:grass_block{snowy:false}"},
        {pos: [2, 2, 4], state: "minecraft:grass_block{snowy:false}"},
        {pos: [3, 2, 2], state: "minecraft:pale_moss_carpet{bottom:true,east:none,north:none,south:low,west:none}"},
        {pos: [3, 2, 3], state: "minecraft:grass_block{snowy:false}"},
        {pos: [3, 2, 4], state: "minecraft:pale_moss_carpet{bottom:true,east:none,north:low,south:none,west:low}"},
        {pos: [3, 2, 7], state: "minecraft:closed_eyeblossom"},
        {pos: [3, 2, 9], state: "minecraft:pale_moss_carpet{bottom:true,east:none,north:none,south:none,west:none}"},
        {pos: [3, 2, 10], state: "minecraft:pale_moss_carpet{bottom:true,east:none,north:none,south:none,west:none}"},
        {pos: [4, 2, 3], state: "minecraft:grass_block{snowy:false}"},
        {pos: [5, 2, 2], state: "minecraft:pale_moss_carpet{bottom:true,east:none,north:none,south:none,west:none}"},
        {pos: [5, 2, 9], state: "minecraft:closed_eyeblossom"},
        {pos: [7, 2, 2], state: "minecraft:pale_moss_carpet{bottom:true,east:none,north:none,south:low,west:none}"},
        {pos: [7, 2, 3], state: "minecraft:pale_moss_block"},
        {pos: [7, 2, 4], state: "minecraft:pale_moss_carpet{bottom:true,east:none,north:low,south:none,west:none}"},
        {pos: [7, 2, 8], state: "minecraft:closed_eyeblossom"},
        {pos: [8, 2, 3], state: "minecraft:pale_moss_carpet{bottom:true,east:none,north:none,south:none,west:low}"},
        {pos: [8, 2, 4], state: "minecraft:pale_moss_carpet{bottom:true,east:none,north:none,south:none,west:none}"},
        {pos: [2, 3, 4], state: "minecraft:closed_eyeblossom"},
        {pos: [3, 3, 3], state: "minecraft:closed_eyeblossom"}
    ],
    entities: [
        {blockPos: [6, 0, 7], pos: [6.5d, 0.9375d, 7.5d], nbt: {Air: 300s, Fire: 0s, Invulnerable: 0b, Motion: [0.0d, 0.0d, 0.0d], OnGround: 0b, PortalCooldown: 0, Pos: [-87.5d, -60.0625d, 648.5d], Rotation: [90.0f, 0.0f], UUID: [I; -1348903150, -1052620614, -1482960989, -636744468], block_pos: [I; -88, -61, 648], color: "light_gray", fall_distance: 0.0d, id: "minecraft:cushion"}}
    ],
    palette: [
        "minecraft:dirt",
        "minecraft:pale_moss_block",
        "minecraft:grass_block{snowy:false}",
        "minecraft:dirt_path",
        "minecraft:closed_eyeblossom",
        "minecraft:pale_moss_carpet{bottom:true,east:none,north:none,south:none,west:none}",
        "minecraft:pale_moss_carpet{bottom:true,east:none,north:none,south:low,west:none}",
        "minecraft:pale_moss_carpet{bottom:true,east:none,north:low,south:none,west:low}",
        "minecraft:pale_moss_carpet{bottom:true,east:none,north:low,south:none,west:none}",
        "minecraft:pale_moss_carpet{bottom:true,east:none,north:none,south:none,west:low}",
        "minecraft:oxidized_copper_chest{facing:south,type:single,waterlogged:false}",
        "minecraft:chest{facing:south,type:single,waterlogged:false}",
        "minecraft:campfire{facing:west,lit:false,signal_fire:false,waterlogged:false}",
        "minecraft:jigsaw{orientation:up_west}"
    ]
}
