{
    size: [10, 10, 10],
    data: [
        {pos: [0, 0, 4], state: "minecraft:pale_moss_block"},
        {pos: [0, 0, 5], state: "minecraft:dirt"},
        {pos: [0, 0, 8], state: "minecraft:pale_moss_block"},
        {pos: [1, 0, 1], state: "minecraft:pale_moss_block"},
        {pos: [1, 0, 3], state: "minecraft:dirt"},
        {pos: [1, 0, 4], state: "minecraft:dirt"},
        {pos: [1, 0, 5], state: "minecraft:dirt"},
        {pos: [1, 0, 6], state: "minecraft:dirt"},
        {pos: [2, 0, 2], state: "minecraft:dirt"},
        {pos: [2, 0, 3], state: "minecraft:dirt"},
        {pos: [2, 0, 4], state: "minecraft:dirt"},
        {pos: [2, 0, 5], state: "minecraft:dirt"},
        {pos: [2, 0, 6], state: "minecraft:dirt"},
        {pos: [2, 0, 7], state: "minecraft:dirt"},
        {pos: [3, 0, 1], state: "minecraft:pale_moss_block"},
        {pos: [3, 0, 2], state: "minecraft:dirt"},
        {pos: [3, 0, 3], state: "minecraft:dirt"},
        {pos: [3, 0, 4], state: "minecraft:dirt"},
        {pos: [3, 0, 5], state: "minecraft:dirt"},
        {pos: [3, 0, 6], state: "minecraft:dirt"},
        {pos: [3, 0, 7], state: "minecraft:dirt"},
        {pos: [3, 0, 8], state: "minecraft:dirt"},
        {pos: [4, 0, 0], state: "minecraft:pale_moss_block"},
        {pos: [4, 0, 1], state: "minecraft:dirt"},
        {pos: [4, 0, 2], state: "minecraft:dirt"},
        {pos: [4, 0, 3], state: "minecraft:dirt"},
        {pos: [4, 0, 4], state: "minecraft:dirt"},
        {pos: [4, 0, 5], state: "minecraft:dirt"},
        {pos: [4, 0, 6], state: "minecraft:dirt"},
        {pos: [4, 0, 7], state: "minecraft:dirt"},
        {pos: [4, 0, 8], state: "minecraft:dirt"},
        {pos: [4, 0, 9], state: "minecraft:pale_moss_block"},
        {pos: [5, 0, 1], state: "minecraft:dirt"},
        {pos: [5, 0, 2], state: "minecraft:dirt"},
        {pos: [5, 0, 3], state: "minecraft:dirt"},
        {pos: [5, 0, 4], state: "minecraft:dirt_path"},
        {pos: [5, 0, 5], state: "minecraft:dirt"},
        {pos: [5, 0, 6], state: "minecraft:dirt"},
        {pos: [5, 0, 7], state: "minecraft:dirt"},
        {pos: [5, 0, 9], state: "minecraft:pale_moss_block"},
        {pos: [6, 0, 1], state: "minecraft:dirt"},
        {pos: [6, 0, 2], state: "minecraft:dirt"},
        {pos: [6, 0, 3], state: "minecraft:dirt_path"},
        {pos: [6, 0, 4], state: "minecraft:dirt"},
        {pos: [6, 0, 5], state: "minecraft:dirt_path"},
        {pos: [6, 0, 6], state: "minecraft:dirt"},
        {pos: [6, 0, 7], state: "minecraft:dirt"},
        {pos: [7, 0, 0], state: "minecraft:pale_moss_block"},
        {pos: [7, 0, 1], state: "minecraft:dirt"},
        {pos: [7, 0, 2], state: "minecraft:dirt"},
        {pos: [7, 0, 3], state: "minecraft:dirt_path"},
        {pos: [7, 0, 4], state: "minecraft:dirt_path"},
        {pos: [7, 0, 5], state: "minecraft:dirt_path"},
        {pos: [7, 0, 6], state: "minecraft:dirt"},
        {pos: [7, 0, 7], state: "minecraft:dirt"},
        {pos: [7, 0, 8], state: "minecraft:pale_moss_block"},
        {pos: [8, 0, 0], state: "minecraft:pale_moss_block"},
        {pos: [8, 0, 1], state: "minecraft:dirt_path"},
        {pos: [8, 0, 2], state: "minecraft:dirt_path"},
        {pos: [8, 0, 3], state: "minecraft:dirt_path"},
        {pos: [8, 0, 4], state: "minecraft:grass_block{snowy:false}"},
        {pos: [8, 0, 5], state: "minecraft:dirt_path"},
        {pos: [8, 0, 6], state: "minecraft:dirt"},
        {pos: [8, 0, 7], state: "minecraft:pale_moss_block"},
        {pos: [9, 0, 2], state: "minecraft:dirt_path"},
        {pos: [9, 0, 3], state: "minecraft:dirt_path"},
        {pos: [9, 0, 4], state: "minecraft:jigsaw{orientation:east_up}", nbt: {components: {}, final_state: "minecraft:dirt_path", id: "minecraft:jigsaw", joint: "rollable", name: "minecraft:end_connector", placement_priority: 0, pool: "minecraft:empty", selection_priority: 0, target: "minecraft:connector"}},
        {pos: [9, 0, 5], state: "minecraft:dirt_path"},
        {pos: [9, 0, 6], state: "minecraft:pale_moss_block"},
        {pos: [0, 1, 5], state: "minecraft:grass_block{snowy:false}"},
        {pos: [1, 1, 3], state: "minecraft:pale_moss_block"},
        {pos: [1, 1, 4], state: "minecraft:grass_block{snowy:false}"},
        {pos: [1, 1, 5], state: "minecraft:grass_block{snowy:false}"},
        {pos: [1, 1, 6], state: "minecraft:grass_block{snowy:false}"},
        {pos: [2, 1, 2], state: "minecraft:grass_block{snowy:false}"},
        {pos: [2, 1, 3], state: "minecraft:grass_block{snowy:false}"},
        {pos: [2, 1, 4], state: "minecraft:grass_block{snowy:false}"},
        {pos: [2, 1, 5], state: "minecraft:grass_block{snowy:false}"},
        {pos: [2, 1, 6], state: "minecraft:grass_block{snowy:false}"},
        {pos: [2, 1, 7], state: "minecraft:pale_moss_block"},
        {pos: [3, 1, 2], state: "minecraft:grass_block{snowy:false}"},
        {pos: [3, 1, 3], state: "minecraft:dirt"},
        {pos: [3, 1, 4], state: "minecraft:dirt"},
        {pos: [3, 1, 5], state: "minecraft:dirt"},
        {pos: [3, 1, 6], state: "minecraft:dirt"},
        {pos: [3, 1, 7], state: "minecraft:grass_block{snowy:false}"},
        {pos: [3, 1, 8], state: "minecraft:grass_block{snowy:false}"},
        {pos: [4, 1, 1], state: "minecraft:grass_block{snowy:false}"},
        {pos: [4, 1, 2], state: "minecraft:dirt"},
        {pos: [4, 1, 3], state: "minecraft:dirt"},
        {pos: [4, 1, 4], state: "minecraft:dirt"},
        {pos: [4, 1, 5], state: "minecraft:dirt"},
        {pos: [4, 1, 6], state: "minecraft:dirt"},
        {pos: [4, 1, 7], state: "minecraft:grass_block{snowy:false}"},
        {pos: [4, 1, 8], state: "minecraft:grass_block{snowy:false}"},
        {pos: [5, 1, 1], state: "minecraft:grass_block{snowy:false}"},
        {pos: [5, 1, 2], state: "minecraft:dirt"},
        {pos: [5, 1, 3], state: "minecraft:pale_moss_block"},
        {pos: [5, 1, 4], state: "minecraft:pale_moss_carpet{bottom:true,east:low,north:low,south:low,west:low}"},
        {pos: [5, 1, 5], state: "minecraft:dirt"},
        {pos: [5, 1, 6], state: "minecraft:dirt"},
        {pos: [5, 1, 7], state: "minecraft:grass_block{snowy:false}"},
        {pos: [6, 1, 1], state: "minecraft:grass_block{snowy:false}"},
        {pos: [6, 1, 2], state: "minecraft:dirt"},
        {pos: [6, 1, 3], state: "minecraft:pale_moss_carpet{bottom:true,east:none,north:low,south:low,west:low}"},
        {pos: [6, 1, 4], state: "minecraft:barrel{facing:up,open:false}", nbt: {LootTable: "minecraft:barrels/abandoned_camp_barrel", components: {}, id: "minecraft:barrel"}},
        {pos: [6, 1, 5], state: "minecraft:pale_moss_carpet{bottom:true,east:none,north:low,south:low,west:low}"},
        {pos: [6, 1, 6], state: "minecraft:dirt"},
        {pos: [6, 1, 7], state: "minecraft:grass_block{snowy:false}"},
        {pos: [7, 1, 1], state: "minecraft:grass_block{snowy:false}"},
        {pos: [7, 1, 2], state: "minecraft:dirt"},
        {pos: [7, 1, 4], state: "minecraft:pale_hanging_moss{tip:true}"},
        {pos: [7, 1, 5], state: "minecraft:pale_moss_carpet{bottom:true,east:none,north:none,south:low,west:none}"},
        {pos: [7, 1, 6], state: "minecraft:dirt"},
        {pos: [7, 1, 7], state: "minecraft:pale_moss_block"},
        {pos: [8, 1, 4], state: "minecraft:campfire{facing:west,lit:false,signal_fire:false,waterlogged:false}", nbt: {CookingTimes: [I; 0, 0, 0, 0], CookingTotalTimes: [I; 0, 0, 0, 0], Items: [], components: {}, id: "minecraft:campfire"}},
        {pos: [8, 1, 6], state: "minecraft:pale_moss_block"},
        {pos: [1, 2, 5], state: "minecraft:tall_grass{half:lower}"},
        {pos: [2, 2, 3], state: "minecraft:tall_grass{half:lower}"},
        {pos: [2, 2, 4], state: "minecraft:pale_moss_carpet{bottom:true,east:low,north:none,south:none,west:none}"},
        {pos: [3, 2, 3], state: "minecraft:grass_block{snowy:false}"},
        {pos: [3, 2, 4], state: "minecraft:grass_block{snowy:false}"},
        {pos: [3, 2, 5], state: "minecraft:grass_block{snowy:false}"},
        {pos: [3, 2, 6], state: "minecraft:pale_moss_block"},
        {pos: [3, 2, 8], state: "minecraft:pale_moss_carpet{bottom:true,east:none,north:none,south:none,west:none}"},
        {pos: [4, 2, 1], state: "minecraft:tall_grass{half:lower}"},
        {pos: [4, 2, 2], state: "minecraft:pale_moss_block"},
        {pos: [4, 2, 3], state: "minecraft:dirt"},
        {pos: [4, 2, 4], state: "minecraft:dirt"},
        {pos: [4, 2, 5], state: "minecraft:grass_block{snowy:false}"},
        {pos: [4, 2, 6], state: "minecraft:grass_block{snowy:false}"},
        {pos: [4, 2, 7], state: "minecraft:pale_moss_carpet{bottom:true,east:none,north:low,south:none,west:none}"},
        {pos: [5, 2, 2], state: "minecraft:grass_block{snowy:false}"},
        {pos: [5, 2, 3], state: "minecraft:dirt"},
        {pos: [5, 2, 4], state: "minecraft:dirt"},
        {pos: [5, 2, 5], state: "minecraft:dirt"},
        {pos: [5, 2, 6], state: "minecraft:grass_block{snowy:false}"},
        {pos: [5, 2, 7], state: "minecraft:tall_grass{half:lower}"},
        {pos: [6, 2, 1], state: "minecraft:tall_grass{half:lower}"},
        {pos: [6, 2, 2], state: "minecraft:grass_block{snowy:false}"},
        {pos: [6, 2, 5], state: "minecraft:dirt"},
        {pos: [6, 2, 6], state: "minecraft:pale_moss_block"},
        {pos: [7, 2, 2], state: "minecraft:grass_block{snowy:false}"},
        {pos: [7, 2, 3], state: "minecraft:pale_hanging_moss{tip:true}"},
        {pos: [7, 2, 4], state: "minecraft:pale_hanging_moss{tip:false}"},
        {pos: [7, 2, 5], state: "minecraft:pale_hanging_moss{tip:true}"},
        {pos: [7, 2, 6], state: "minecraft:grass_block{snowy:false}"},
        {pos: [1, 3, 5], state: "minecraft:tall_grass{half:upper}"},
        {pos: [2, 3, 3], state: "minecraft:tall_grass{half:upper}"},
        {pos: [3, 3, 5], state: "minecraft:pale_moss_carpet{bottom:true,east:none,north:none,south:none,west:none}"},
        {pos: [4, 3, 1], state: "minecraft:tall_grass{half:upper}"},
        {pos: [4, 3, 3], state: "minecraft:pale_moss_block"},
        {pos: [4, 3, 4], state: "minecraft:grass_block{snowy:false}"},
        {pos: [4, 3, 6], state: "minecraft:tall_grass{half:lower}"},
        {pos: [5, 3, 2], state: "minecraft:pale_moss_carpet{bottom:true,east:none,north:none,south:low,west:none}"},
        {pos: [5, 3, 3], state: "minecraft:grass_block{snowy:false}"},
        {pos: [5, 3, 4], state: "minecraft:grass_block{snowy:false}"},
        {pos: [5, 3, 5], state: "minecraft:grass_block{snowy:false}"},
        {pos: [5, 3, 7], state: "minecraft:tall_grass{half:upper}"},
        {pos: [6, 3, 1], state: "minecraft:tall_grass{half:upper}"},
        {pos: [6, 3, 3], state: "minecraft:grass_block{snowy:false}"},
        {pos: [6, 3, 4], state: "minecraft:jigsaw{orientation:up_west}", nbt: {components: {}, final_state: "minecraft:dirt", id: "minecraft:jigsaw", joint: "rollable", name: "minecraft:down", placement_priority: 0, pool: "minecraft:abandoned_camp/trees/pale_oak", selection_priority: 0, target: "minecraft:down"}},
        {pos: [6, 3, 5], state: "minecraft:pale_moss_block"},
        {pos: [7, 3, 2], state: "minecraft:pale_moss_carpet{bottom:true,east:none,north:none,south:low,west:none}"},
        {pos: [7, 3, 3], state: "minecraft:grass_block{snowy:false}"},
        {pos: [7, 3, 4], state: "minecraft:grass_block{snowy:false}"},
        {pos: [7, 3, 5], state: "minecraft:grass_block{snowy:false}"},
        {pos: [4, 4, 6], state: "minecraft:tall_grass{half:upper}"}
    ],
    entities: [
        {blockPos: [8, 0, 3], pos: [8.5d, 0.9375d, 3.5d], nbt: {Air: 300s, Fire: 0s, Invulnerable: 0b, Motion: [0.0d, 0.0d, 0.0d], OnGround: 0b, PortalCooldown: 0, Pos: [-85.5d, -60.0625d, 630.5d], Rotation: [90.0f, 0.0f], UUID: [I; -1654844066, 1066880404, -1209804175, -2013760285], block_pos: [I; -86, -61, 630], color: "white", fall_distance: 0.0d, id: "minecraft:cushion"}}
    ],
    palette: [
        "minecraft:pale_moss_block",
        "minecraft:dirt",
        "minecraft:grass_block{snowy:false}",
        "minecraft:dirt_path",
        "minecraft:pale_moss_carpet{bottom:true,east:low,north:low,south:low,west:low}",
        "minecraft:pale_moss_carpet{bottom:true,east:none,north:low,south:low,west:low}",
        "minecraft:pale_hanging_moss{tip:true}",
        "minecraft:pale_moss_carpet{bottom:true,east:none,north:none,south:low,west:none}",
        "minecraft:tall_grass{half:lower}",
        "minecraft:pale_moss_carpet{bottom:true,east:low,north:none,south:none,west:none}",
        "minecraft:pale_moss_carpet{bottom:true,east:none,north:none,south:none,west:none}",
        "minecraft:pale_moss_carpet{bottom:true,east:none,north:low,south:none,west:none}",
        "minecraft:pale_hanging_moss{tip:false}",
        "minecraft:tall_grass{half:upper}",
        "minecraft:jigsaw{orientation:east_up}",
        "minecraft:barrel{facing:up,open:false}",
        "minecraft:campfire{facing:west,lit:false,signal_fire:false,waterlogged:false}",
        "minecraft:jigsaw{orientation:up_west}"
    ]
}
