{
    size: [10, 10, 10],
    data: [
        {pos: [0, 0, 5], state: "minecraft:dirt"},
        {pos: [0, 0, 6], state: "minecraft:dirt"},
        {pos: [0, 0, 7], state: "minecraft:dirt"},
        {pos: [1, 0, 3], state: "minecraft:dirt"},
        {pos: [1, 0, 4], state: "minecraft:dirt"},
        {pos: [1, 0, 5], state: "minecraft:dirt"},
        {pos: [1, 0, 6], state: "minecraft:dirt"},
        {pos: [1, 0, 7], state: "minecraft:dirt"},
        {pos: [1, 0, 8], state: "minecraft:dirt"},
        {pos: [2, 0, 1], state: "minecraft:dirt"},
        {pos: [2, 0, 2], state: "minecraft:dirt"},
        {pos: [2, 0, 3], state: "minecraft:dirt"},
        {pos: [2, 0, 4], state: "minecraft:dirt"},
        {pos: [2, 0, 5], state: "minecraft:dirt"},
        {pos: [2, 0, 6], state: "minecraft:grass_block{snowy:false}"},
        {pos: [2, 0, 7], state: "minecraft:dirt"},
        {pos: [2, 0, 8], state: "minecraft:dirt"},
        {pos: [2, 0, 9], state: "minecraft:dirt"},
        {pos: [3, 0, 1], state: "minecraft:dirt"},
        {pos: [3, 0, 2], state: "minecraft:dirt"},
        {pos: [3, 0, 3], state: "minecraft:dirt"},
        {pos: [3, 0, 4], state: "minecraft:dirt"},
        {pos: [3, 0, 5], state: "minecraft:dirt"},
        {pos: [3, 0, 6], state: "minecraft:dirt"},
        {pos: [3, 0, 7], state: "minecraft:dirt"},
        {pos: [3, 0, 8], state: "minecraft:dirt"},
        {pos: [3, 0, 9], state: "minecraft:dirt"},
        {pos: [4, 0, 1], state: "minecraft:dirt"},
        {pos: [4, 0, 2], state: "minecraft:dirt"},
        {pos: [4, 0, 3], state: "minecraft:dirt"},
        {pos: [4, 0, 4], state: "minecraft:dirt"},
        {pos: [4, 0, 5], state: "minecraft:dirt"},
        {pos: [4, 0, 6], state: "minecraft:dirt"},
        {pos: [4, 0, 7], state: "minecraft:dirt"},
        {pos: [4, 0, 8], state: "minecraft:dirt"},
        {pos: [4, 0, 9], state: "minecraft:dirt"},
        {pos: [5, 0, 1], state: "minecraft:dirt"},
        {pos: [5, 0, 2], state: "minecraft:dirt"},
        {pos: [5, 0, 3], state: "minecraft:dirt"},
        {pos: [5, 0, 4], state: "minecraft:dirt"},
        {pos: [5, 0, 5], state: "minecraft:dirt"},
        {pos: [5, 0, 6], state: "minecraft:grass_block{snowy:false}"},
        {pos: [5, 0, 7], state: "minecraft:dirt"},
        {pos: [5, 0, 8], state: "minecraft:dirt"},
        {pos: [5, 0, 9], state: "minecraft:dirt"},
        {pos: [6, 0, 1], state: "minecraft:dirt"},
        {pos: [6, 0, 2], state: "minecraft:dirt"},
        {pos: [6, 0, 3], state: "minecraft:dirt"},
        {pos: [6, 0, 4], state: "minecraft:grass_block{snowy:false}"},
        {pos: [6, 0, 5], state: "minecraft:oxidized_copper_chest{facing:south,type:single,waterlogged:false}", nbt: {Items: [], LootTable: "minecraft:chests/abandoned_camp_secret_chest", components: {}, id: "minecraft:chest"}},
        {pos: [6, 0, 6], state: "minecraft:grass_block{snowy:false}"},
        {pos: [6, 0, 7], state: "minecraft:dirt"},
        {pos: [6, 0, 8], state: "minecraft:dirt"},
        {pos: [6, 0, 9], state: "minecraft:dirt"},
        {pos: [7, 0, 1], state: "minecraft:dirt"},
        {pos: [7, 0, 2], state: "minecraft:dirt"},
        {pos: [7, 0, 3], state: "minecraft:grass_block{snowy:false}"},
        {pos: [7, 0, 4], state: "minecraft:dirt_path"},
        {pos: [7, 0, 5], state: "minecraft:grass_block{snowy:false}"},
        {pos: [7, 0, 6], state: "minecraft:grass_block{snowy:false}"},
        {pos: [7, 0, 7], state: "minecraft:dirt"},
        {pos: [7, 0, 8], state: "minecraft:dirt"},
        {pos: [7, 0, 9], state: "minecraft:dirt"},
        {pos: [8, 0, 2], state: "minecraft:dirt"},
        {pos: [8, 0, 3], state: "minecraft:dirt_path"},
        {pos: [8, 0, 4], state: "minecraft:dirt_path"},
        {pos: [8, 0, 5], state: "minecraft:dirt_path"},
        {pos: [8, 0, 6], state: "minecraft:grass_block{snowy:false}"},
        {pos: [8, 0, 8], state: "minecraft:dirt"},
        {pos: [9, 0, 3], state: "minecraft:dirt_path"},
        {pos: [9, 0, 4], state: "minecraft:jigsaw{orientation:east_up}", nbt: {components: {}, final_state: "minecraft:dirt_path", id: "minecraft:jigsaw", joint: "rollable", name: "minecraft:end_connector", placement_priority: 0, pool: "minecraft:empty", selection_priority: 0, target: "minecraft:connector"}},
        {pos: [9, 0, 5], state: "minecraft:dirt_path"},
        {pos: [9, 0, 6], state: "minecraft:dirt_path"},
        {pos: [0, 1, 5], state: "minecraft:grass_block{snowy:false}"},
        {pos: [0, 1, 6], state: "minecraft:pale_moss_block"},
        {pos: [0, 1, 7], state: "minecraft:pale_moss_block"},
        {pos: [1, 1, 3], state: "minecraft:pale_moss_block"},
        {pos: [1, 1, 4], state: "minecraft:pale_moss_block"},
        {pos: [1, 1, 5], state: "minecraft:dirt"},
        {pos: [1, 1, 6], state: "minecraft:dirt"},
        {pos: [1, 1, 7], state: "minecraft:grass_block{snowy:false}"},
        {pos: [1, 1, 8], state: "minecraft:pale_moss_block"},
        {pos: [2, 1, 1], state: "minecraft:pale_moss_block"},
        {pos: [2, 1, 2], state: "minecraft:pale_moss_block"},
        {pos: [2, 1, 3], state: "minecraft:grass_block{snowy:false}"},
        {pos: [2, 1, 4], state: "minecraft:dirt"},
        {pos: [2, 1, 5], state: "minecraft:dirt"},
        {pos: [2, 1, 7], state: "minecraft:dirt"},
        {pos: [2, 1, 8], state: "minecraft:dirt"},
        {pos: [2, 1, 9], state: "minecraft:pale_moss_block"},
        {pos: [3, 1, 1], state: "minecraft:grass_block{snowy:false}"},
        {pos: [3, 1, 2], state: "minecraft:dirt"},
        {pos: [3, 1, 3], state: "minecraft:dirt"},
        {pos: [3, 1, 4], state: "minecraft:dirt"},
        {pos: [3, 1, 5], state: "minecraft:dirt"},
        {pos: [3, 1, 6], state: "minecraft:dirt"},
        {pos: [3, 1, 7], state: "minecraft:dirt"},
        {pos: [3, 1, 8], state: "minecraft:dirt"},
        {pos: [3, 1, 9], state: "minecraft:pale_moss_block"},
        {pos: [4, 1, 1], state: "minecraft:pale_moss_block"},
        {pos: [4, 1, 2], state: "minecraft:dirt"},
        {pos: [4, 1, 3], state: "minecraft:dirt"},
        {pos: [4, 1, 4], state: "minecraft:dirt"},
        {pos: [4, 1, 5], state: "minecraft:dirt"},
        {pos: [4, 1, 6], state: "minecraft:dirt"},
        {pos: [4, 1, 7], state: "minecraft:dirt"},
        {pos: [4, 1, 8], state: "minecraft:dirt"},
        {pos: [4, 1, 9], state: "minecraft:grass_block{snowy:false}"},
        {pos: [5, 1, 1], state: "minecraft:pale_moss_block"},
        {pos: [5, 1, 2], state: "minecraft:dirt"},
        {pos: [5, 1, 3], state: "minecraft:dirt"},
        {pos: [5, 1, 4], state: "minecraft:dirt"},
        {pos: [5, 1, 5], state: "minecraft:dirt"},
        {pos: [5, 1, 6], state: "minecraft:pale_moss_carpet{bottom:true,east:none,north:low,south:low,west:low}"},
        {pos: [5, 1, 7], state: "minecraft:dirt"},
        {pos: [5, 1, 8], state: "minecraft:dirt"},
        {pos: [5, 1, 9], state: "minecraft:pale_moss_block"},
        {pos: [6, 1, 1], state: "minecraft:pale_moss_block"},
        {pos: [6, 1, 2], state: "minecraft:dirt"},
        {pos: [6, 1, 3], state: "minecraft:dirt"},
        {pos: [6, 1, 4], state: "minecraft:pale_hanging_moss{tip:true}"},
        {pos: [6, 1, 5], state: "minecraft:pale_moss_carpet{bottom:true,east:none,north:none,south:none,west:low}"},
        {pos: [6, 1, 6], state: "minecraft:pale_moss_carpet{bottom:true,east:none,north:none,south:low,west:none}"},
        {pos: [6, 1, 7], state: "minecraft:dirt"},
        {pos: [6, 1, 8], state: "minecraft:dirt"},
        {pos: [6, 1, 9], state: "minecraft:grass_block{snowy:false}"},
        {pos: [7, 1, 1], state: "minecraft:grass_block{snowy:false}"},
        {pos: [7, 1, 2], state: "minecraft:dirt"},
        {pos: [7, 1, 3], state: "minecraft:pale_moss_carpet{bottom:true,east:none,north:tall,south:none,west:low}"},
        {pos: [7, 1, 5], state: "minecraft:campfire{facing:north,lit:false,signal_fire:false,waterlogged:false}", nbt: {CookingTimes: [I; 0, 0, 0, 0], CookingTotalTimes: [I; 0, 0, 0, 0], Items: [], components: {}, id: "minecraft:campfire"}},
        {pos: [7, 1, 6], state: "minecraft:pale_moss_carpet{bottom:true,east:none,north:none,south:low,west:none}"},
        {pos: [7, 1, 7], state: "minecraft:dirt"},
        {pos: [7, 1, 8], state: "minecraft:pale_moss_block"},
        {pos: [7, 1, 9], state: "minecraft:pale_moss_block"},
        {pos: [8, 1, 2], state: "minecraft:pale_moss_block"},
        {pos: [8, 1, 6], state: "minecraft:chest{facing:north,type:single,waterlogged:false}", nbt: {Items: [], LootTable: "minecraft:chests/abandoned_camp_common_chest", components: {}, id: "minecraft:chest"}},
        {pos: [8, 1, 8], state: "minecraft:grass_block{snowy:false}"},
        {pos: [1, 2, 5], state: "minecraft:grass_block{snowy:false}"},
        {pos: [1, 2, 6], state: "minecraft:pale_moss_block"},
        {pos: [1, 2, 7], state: "minecraft:tall_grass{half:lower}"},
        {pos: [2, 2, 3], state: "minecraft:pale_moss_carpet{bottom:true,east:low,north:none,south:low,west:none}"},
        {pos: [2, 2, 4], state: "minecraft:pale_moss_block"},
        {pos: [2, 2, 5], state: "minecraft:grass_block{snowy:false}"},
        {pos: [2, 2, 6], state: "minecraft:grass_block{snowy:false}"},
        {pos: [2, 2, 7], state: "minecraft:grass_block{snowy:false}"},
        {pos: [2, 2, 8], state: "minecraft:pale_moss_block"},
        {pos: [3, 2, 1], state: "minecraft:tall_grass{half:lower}"},
        {pos: [3, 2, 2], state: "minecraft:pale_moss_block"},
        {pos: [3, 2, 3], state: "minecraft:pale_moss_block"},
        {pos: [3, 2, 4], state: "minecraft:pale_moss_block"},
        {pos: [3, 2, 5], state: "minecraft:dirt"},
        {pos: [3, 2, 6], state: "minecraft:grass_block{snowy:false}"},
        {pos: [3, 2, 7], state: "minecraft:pale_moss_block"},
        {pos: [3, 2, 8], state: "minecraft:pale_moss_block"},
        {pos: [3, 2, 9], state: "minecraft:tall_grass{half:lower}"},
        {pos: [4, 2, 2], state: "minecraft:pale_moss_block"},
        {pos: [4, 2, 3], state: "minecraft:dirt"},
        {pos: [4, 2, 4], state: "minecraft:dirt"},
        {pos: [4, 2, 5], state: "minecraft:dirt"},
        {pos: [4, 2, 6], state: "minecraft:dirt"},
        {pos: [4, 2, 7], state: "minecraft:grass_block{snowy:false}"},
        {pos: [4, 2, 8], state: "minecraft:grass_block{snowy:false}"},
        {pos: [5, 2, 2], state: "minecraft:pale_moss_block"},
        {pos: [5, 2, 3], state: "minecraft:dirt"},
        {pos: [5, 2, 4], state: "minecraft:dirt"},
        {pos: [5, 2, 5], state: "minecraft:dirt"},
        {pos: [5, 2, 6], state: "minecraft:pale_hanging_moss{tip:true}"},
        {pos: [5, 2, 7], state: "minecraft:grass_block{snowy:false}"},
        {pos: [5, 2, 8], state: "minecraft:pale_moss_block"},
        {pos: [6, 2, 1], state: "minecraft:pale_moss_carpet{bottom:true,east:none,north:none,south:low,west:none}"},
        {pos: [6, 2, 2], state: "minecraft:grass_block{snowy:false}"},
        {pos: [6, 2, 3], state: "minecraft:grass_block{snowy:false}"},
        {pos: [6, 2, 4], state: "minecraft:pale_hanging_moss{tip:false}"},
        {pos: [6, 2, 5], state: "minecraft:pale_hanging_moss{tip:true}"},
        {pos: [6, 2, 7], state: "minecraft:grass_block{snowy:false}"},
        {pos: [6, 2, 8], state: "minecraft:grass_block{snowy:false}"},
        {pos: [6, 2, 9], state: "minecraft:tall_grass{half:lower}"},
        {pos: [7, 2, 2], state: "minecraft:pale_moss_block"},
        {pos: [7, 2, 3], state: "minecraft:pale_moss_carpet{bottom:false,east:none,north:low,south:none,west:none}"},
        {pos: [7, 2, 7], state: "minecraft:grass_block{snowy:false}"},
        {pos: [7, 2, 8], state: "minecraft:pale_moss_carpet{bottom:true,east:none,north:low,south:none,west:low}"},
        {pos: [1, 3, 5], state: "minecraft:tall_grass{half:lower}"},
        {pos: [1, 3, 7], state: "minecraft:tall_grass{half:upper}"},
        {pos: [2, 3, 5], state: "minecraft:pale_moss_carpet{bottom:true,east:low,north:none,south:none,west:none}"},
        {pos: [2, 3, 7], state: "minecraft:pale_moss_carpet{bottom:true,east:none,north:none,south:none,west:none}"},
        {pos: [3, 3, 1], state: "minecraft:tall_grass{half:upper}"},
        {pos: [3, 3, 3], state: "minecraft:pale_moss_carpet{bottom:true,east:low,north:none,south:low,west:none}"},
        {pos: [3, 3, 4], state: "minecraft:grass_block{snowy:false}"},
        {pos: [3, 3, 5], state: "minecraft:pale_moss_block"},
        {pos: [3, 3, 6], state: "minecraft:pale_moss_carpet{bottom:true,east:low,north:low,south:none,west:none}"},
        {pos: [3, 3, 9], state: "minecraft:tall_grass{half:upper}"},
        {pos: [4, 3, 3], state: "minecraft:pale_moss_block"},
        {pos: [4, 3, 4], state: "minecraft:pale_moss_block"},
        {pos: [4, 3, 5], state: "minecraft:jigsaw{orientation:up_north}", nbt: {components: {}, final_state: "minecraft:dirt", id: "minecraft:jigsaw", joint: "rollable", name: "minecraft:down", placement_priority: 0, pool: "minecraft:abandoned_camp/trees/pale_oak", selection_priority: 0, target: "minecraft:down"}},
        {pos: [4, 3, 6], state: "minecraft:grass_block{snowy:false}"},
        {pos: [4, 3, 7], state: "minecraft:pale_moss_carpet{bottom:true,east:none,north:low,south:none,west:none}"},
        {pos: [4, 3, 8], state: "minecraft:pale_moss_carpet{bottom:true,east:none,north:none,south:none,west:none}"},
        {pos: [5, 3, 3], state: "minecraft:pale_moss_block"},
        {pos: [5, 3, 4], state: "minecraft:grass_block{snowy:false}"},
        {pos: [5, 3, 5], state: "minecraft:grass_block{snowy:false}"},
        {pos: [5, 3, 6], state: "minecraft:grass_block{snowy:false}"},
        {pos: [6, 3, 2], state: "minecraft:tall_grass{half:lower}"},
        {pos: [6, 3, 4], state: "minecraft:grass_block{snowy:false}"},
        {pos: [6, 3, 5], state: "minecraft:grass_block{snowy:false}"},
        {pos: [6, 3, 7], state: "minecraft:tall_grass{half:lower}"},
        {pos: [6, 3, 8], state: "minecraft:pale_moss_carpet{bottom:true,east:none,north:none,south:none,west:none}"},
        {pos: [6, 3, 9], state: "minecraft:tall_grass{half:upper}"},
        {pos: [1, 4, 5], state: "minecraft:tall_grass{half:upper}"},
        {pos: [5, 4, 6], state: "minecraft:tall_grass{half:lower}"},
        {pos: [6, 4, 2], state: "minecraft:tall_grass{half:upper}"},
        {pos: [6, 4, 4], state: "minecraft:tall_grass{half:lower}"},
        {pos: [6, 4, 5], state: "minecraft:closed_eyeblossom"},
        {pos: [6, 4, 7], state: "minecraft:tall_grass{half:upper}"},
        {pos: [5, 5, 6], state: "minecraft:tall_grass{half:upper}"},
        {pos: [6, 5, 4], state: "minecraft:tall_grass{half:upper}"}
    ],
    entities: [
        {blockPos: [8, 0, 4], pos: [8.5d, 0.9375d, 4.5d], nbt: {Air: 300s, Fire: 0s, Invulnerable: 0b, Motion: [0.0d, 0.0d, 0.0d], OnGround: 0b, PortalCooldown: 0, Pos: [-102.5d, -60.0625d, 631.5d], Rotation: [90.0f, 0.0f], UUID: [I; 327971733, -1096136897, -1502033061, -2011922023], block_pos: [I; -103, -61, 631], color: "white", fall_distance: 0.0d, id: "minecraft:cushion"}}
    ],
    palette: [
        "minecraft:dirt",
        "minecraft:grass_block{snowy:false}",
        "minecraft:pale_moss_block",
        "minecraft:dirt_path",
        "minecraft:pale_moss_carpet{bottom:true,east:none,north:low,south:low,west:low}",
        "minecraft:pale_hanging_moss{tip:true}",
        "minecraft:pale_moss_carpet{bottom:true,east:none,north:none,south:none,west:low}",
        "minecraft:pale_moss_carpet{bottom:true,east:none,north:none,south:low,west:none}",
        "minecraft:pale_moss_carpet{bottom:true,east:none,north:tall,south:none,west:low}",
        "minecraft:tall_grass{half:lower}",
        "minecraft:pale_moss_carpet{bottom:true,east:low,north:none,south:low,west:none}",
        "minecraft:pale_hanging_moss{tip:false}",
        "minecraft:pale_moss_carpet{bottom:false,east:none,north:low,south:none,west:none}",
        "minecraft:pale_moss_carpet{bottom:true,east:none,north:low,south:none,west:low}",
        "minecraft:tall_grass{half:upper}",
        "minecraft:pale_moss_carpet{bottom:true,east:low,north:none,south:none,west:none}",
        "minecraft:pale_moss_carpet{bottom:true,east:none,north:none,south:none,west:none}",
        "minecraft:pale_moss_carpet{bottom:true,east:low,north:low,south:none,west:none}",
        "minecraft:pale_moss_carpet{bottom:true,east:none,north:low,south:none,west:none}",
        "minecraft:closed_eyeblossom",
        "minecraft:oxidized_copper_chest{facing:south,type:single,waterlogged:false}",
        "minecraft:jigsaw{orientation:east_up}",
        "minecraft:campfire{facing:north,lit:false,signal_fire:false,waterlogged:false}",
        "minecraft:chest{facing:north,type:single,waterlogged:false}",
        "minecraft:jigsaw{orientation:up_north}"
    ]
}
