{
    size: [10, 10, 10],
    data: [
        {pos: [2, 0, 3], state: "minecraft:grass_block{snowy:false}"},
        {pos: [2, 0, 4], state: "minecraft:dirt"},
        {pos: [2, 0, 5], state: "minecraft:grass_block{snowy:false}"},
        {pos: [2, 0, 7], state: "minecraft:grass_block{snowy:false}"},
        {pos: [3, 0, 2], state: "minecraft:grass_block{snowy:false}"},
        {pos: [3, 0, 3], state: "minecraft:dirt"},
        {pos: [3, 0, 4], state: "minecraft:dirt"},
        {pos: [3, 0, 5], state: "minecraft:dirt"},
        {pos: [3, 0, 6], state: "minecraft:dirt"},
        {pos: [3, 0, 7], state: "minecraft:grass_block{snowy:false}"},
        {pos: [4, 0, 2], state: "minecraft:grass_block{snowy:false}"},
        {pos: [4, 0, 3], state: "minecraft:dirt"},
        {pos: [4, 0, 4], state: "minecraft:dirt"},
        {pos: [4, 0, 5], state: "minecraft:dirt"},
        {pos: [4, 0, 6], state: "minecraft:dirt"},
        {pos: [4, 0, 7], state: "minecraft:dirt"},
        {pos: [4, 0, 8], state: "minecraft:grass_block{snowy:false}"},
        {pos: [5, 0, 0], state: "minecraft:pale_moss_block"},
        {pos: [5, 0, 2], state: "minecraft:dirt"},
        {pos: [5, 0, 3], state: "minecraft:dirt"},
        {pos: [5, 0, 4], state: "minecraft:dirt"},
        {pos: [5, 0, 5], state: "minecraft:dirt"},
        {pos: [5, 0, 6], state: "minecraft:dirt"},
        {pos: [5, 0, 7], state: "minecraft:dirt"},
        {pos: [5, 0, 8], state: "minecraft:grass_block{snowy:false}"},
        {pos: [6, 0, 2], state: "minecraft:pale_moss_block"},
        {pos: [6, 0, 3], state: "minecraft:dirt"},
        {pos: [6, 0, 4], state: "minecraft:dirt"},
        {pos: [6, 0, 5], state: "minecraft:grass_block{snowy:false}"},
        {pos: [6, 0, 6], state: "minecraft:dirt"},
        {pos: [6, 0, 7], state: "minecraft:dirt"},
        {pos: [7, 0, 3], state: "minecraft:dirt_path"},
        {pos: [7, 0, 4], state: "minecraft:dirt_path"},
        {pos: [7, 0, 5], state: "minecraft:dirt_path"},
        {pos: [7, 0, 6], state: "minecraft:dirt"},
        {pos: [7, 0, 7], state: "minecraft:dirt"},
        {pos: [8, 0, 2], state: "minecraft:dirt_path"},
        {pos: [8, 0, 3], state: "minecraft:dirt_path"},
        {pos: [8, 0, 4], state: "minecraft:dirt"},
        {pos: [8, 0, 5], state: "minecraft:dirt_path"},
        {pos: [8, 0, 6], state: "minecraft:dirt_path"},
        {pos: [8, 0, 7], state: "minecraft:pale_moss_block"},
        {pos: [9, 0, 2], state: "minecraft:dirt_path"},
        {pos: [9, 0, 3], state: "minecraft:dirt_path"},
        {pos: [9, 0, 4], state: "minecraft:jigsaw{orientation:east_up}", nbt: {components: {}, final_state: "minecraft:dirt_path", id: "minecraft:jigsaw", joint: "rollable", name: "minecraft:end_connector", placement_priority: 0, pool: "minecraft:empty", selection_priority: 0, target: "minecraft:connector"}},
        {pos: [9, 0, 5], state: "minecraft:dirt_path"},
        {pos: [9, 0, 6], state: "minecraft:dirt_path"},
        {pos: [2, 1, 3], state: "minecraft:pale_moss_carpet{bottom:true,east:low,north:none,south:low,west:none}"},
        {pos: [2, 1, 4], state: "minecraft:grass_block{snowy:false}"},
        {pos: [2, 1, 5], state: "minecraft:pale_moss_carpet{bottom:true,east:low,north:low,south:none,west:none}"},
        {pos: [2, 1, 7], state: "minecraft:pale_moss_carpet{bottom:true,east:none,north:none,south:none,west:none}"},
        {pos: [3, 1, 2], state: "minecraft:pale_moss_carpet{bottom:true,east:none,north:none,south:low,west:none}"},
        {pos: [3, 1, 3], state: "minecraft:pale_moss_block"},
        {pos: [3, 1, 4], state: "minecraft:grass_block{snowy:false}"},
        {pos: [3, 1, 5], state: "minecraft:grass_block{snowy:false}"},
        {pos: [3, 1, 6], state: "minecraft:pale_moss_block"},
        {pos: [3, 1, 7], state: "minecraft:pale_moss_carpet{bottom:true,east:low,north:low,south:none,west:none}"},
        {pos: [4, 1, 2], state: "minecraft:pale_moss_carpet{bottom:true,east:low,north:none,south:low,west:none}"},
        {pos: [4, 1, 3], state: "minecraft:grass_block{snowy:false}"},
        {pos: [4, 1, 4], state: "minecraft:dirt"},
        {pos: [4, 1, 5], state: "minecraft:dirt"},
        {pos: [4, 1, 6], state: "minecraft:pale_moss_block"},
        {pos: [4, 1, 7], state: "minecraft:pale_moss_block"},
        {pos: [4, 1, 8], state: "minecraft:pale_moss_carpet{bottom:true,east:none,north:low,south:none,west:none}"},
        {pos: [5, 1, 2], state: "minecraft:grass_block{snowy:false}"},
        {pos: [5, 1, 3], state: "minecraft:pale_moss_block"},
        {pos: [5, 1, 4], state: "minecraft:dirt"},
        {pos: [5, 1, 5], state: "minecraft:dirt"},
        {pos: [5, 1, 6], state: "minecraft:grass_block{snowy:false}"},
        {pos: [5, 1, 7], state: "minecraft:pale_moss_block"},
        {pos: [5, 1, 8], state: "minecraft:pale_moss_carpet{bottom:true,east:none,north:low,south:none,west:none}"},
        {pos: [6, 1, 2], state: "minecraft:pale_moss_carpet{bottom:true,east:none,north:none,south:low,west:low}"},
        {pos: [6, 1, 3], state: "minecraft:pale_moss_block"},
        {pos: [6, 1, 4], state: "minecraft:barrel{facing:east,open:false}", nbt: {LootTable: "minecraft:barrels/abandoned_camp_barrel", components: {}, id: "minecraft:barrel"}},
        {pos: [6, 1, 5], state: "minecraft:chest{facing:east,type:single,waterlogged:false}", nbt: {LootTable: "minecraft:chests/abandoned_camp_common_chest", components: {}, id: "minecraft:chest"}},
        {pos: [6, 1, 6], state: "minecraft:pale_moss_block"},
        {pos: [6, 1, 7], state: "minecraft:grass_block{snowy:false}"},
        {pos: [7, 1, 6], state: "minecraft:resin_block"},
        {pos: [7, 1, 7], state: "minecraft:pale_moss_block"},
        {pos: [8, 1, 4], state: "minecraft:campfire{facing:west,lit:false,signal_fire:false,waterlogged:false}", nbt: {CookingTimes: [I; 0, 0, 0, 0], CookingTotalTimes: [I; 0, 0, 0, 0], Items: [], components: {}, id: "minecraft:campfire"}},
        {pos: [8, 1, 7], state: "minecraft:tall_grass{half:lower}"},
        {pos: [3, 2, 3], state: "minecraft:pale_moss_carpet{bottom:true,east:none,north:none,south:none,west:none}"},
        {pos: [3, 2, 6], state: "minecraft:pale_moss_carpet{bottom:true,east:low,north:none,south:none,west:none}"},
        {pos: [4, 2, 3], state: "minecraft:pale_moss_carpet{bottom:true,east:none,north:none,south:tall,west:none}"},
        {pos: [4, 2, 4], state: "minecraft:pale_oak_log{axis:y}"},
        {pos: [4, 2, 5], state: "minecraft:pale_oak_log{axis:y}"},
        {pos: [4, 2, 6], state: "minecraft:pale_moss_block"},
        {pos: [5, 2, 2], state: "minecraft:tall_grass{half:lower}"},
        {pos: [5, 2, 3], state: "minecraft:pale_moss_carpet{bottom:true,east:none,north:none,south:low,west:none}"},
        {pos: [5, 2, 4], state: "minecraft:pale_oak_log{axis:y}"},
        {pos: [5, 2, 5], state: "minecraft:pale_oak_log{axis:y}"},
        {pos: [5, 2, 6], state: "minecraft:pale_moss_carpet{bottom:true,east:low,north:tall,south:none,west:low}"},
        {pos: [6, 2, 3], state: "minecraft:pale_moss_carpet{bottom:true,east:none,north:none,south:none,west:none}"},
        {pos: [6, 2, 6], state: "minecraft:resin_block"},
        {pos: [6, 2, 7], state: "minecraft:tall_grass{half:lower}"},
        {pos: [7, 2, 7], state: "minecraft:resin_block"},
        {pos: [8, 2, 7], state: "minecraft:tall_grass{half:upper}"},
        {pos: [4, 3, 1], state: "minecraft:pale_hanging_moss{tip:true}"},
        {pos: [4, 3, 3], state: "minecraft:pale_moss_carpet{bottom:false,east:none,north:none,south:low,west:none}"},
        {pos: [4, 3, 4], state: "minecraft:pale_oak_log{axis:y}"},
        {pos: [4, 3, 5], state: "minecraft:pale_oak_log{axis:y}"},
        {pos: [5, 3, 2], state: "minecraft:tall_grass{half:upper}"},
        {pos: [5, 3, 4], state: "minecraft:pale_oak_log{axis:y}"},
        {pos: [5, 3, 5], state: "minecraft:pale_oak_log{axis:y}"},
        {pos: [5, 3, 6], state: "minecraft:pale_moss_carpet{bottom:false,east:none,north:low,south:none,west:none}"},
        {pos: [6, 3, 7], state: "minecraft:tall_grass{half:upper}"},
        {pos: [7, 3, 2], state: "minecraft:pale_hanging_moss{tip:true}"},
        {pos: [7, 3, 5], state: "minecraft:pale_hanging_moss{tip:true}"},
        {pos: [2, 4, 6], state: "minecraft:pale_hanging_moss{tip:true}"},
        {pos: [4, 4, 1], state: "minecraft:pale_hanging_moss{tip:false}"},
        {pos: [4, 4, 4], state: "minecraft:pale_oak_log{axis:y}"},
        {pos: [4, 4, 5], state: "minecraft:creaking_heart{axis:y,creaking_heart_state:dormant,natural:false}", nbt: {components: {}, id: "minecraft:creaking_heart"}},
        {pos: [4, 4, 7], state: "minecraft:pale_hanging_moss{tip:true}"},
        {pos: [5, 4, 1], state: "minecraft:pale_hanging_moss{tip:true}"},
        {pos: [5, 4, 3], state: "minecraft:pale_oak_log{axis:y}"},
        {pos: [5, 4, 4], state: "minecraft:pale_oak_log{axis:y}"},
        {pos: [5, 4, 5], state: "minecraft:pale_oak_log{axis:y}"},
        {pos: [7, 4, 2], state: "minecraft:pale_hanging_moss{tip:false}"},
        {pos: [7, 4, 4], state: "minecraft:pale_hanging_moss{tip:true}"},
        {pos: [7, 4, 5], state: "minecraft:pale_hanging_moss{tip:false}"},
        {pos: [7, 4, 7], state: "minecraft:pale_hanging_moss{tip:true}"},
        {pos: [2, 5, 6], state: "minecraft:pale_hanging_moss{tip:false}"},
        {pos: [4, 5, 1], state: "minecraft:pale_hanging_moss{tip:false}"},
        {pos: [4, 5, 4], state: "minecraft:pale_oak_log{axis:y}"},
        {pos: [4, 5, 5], state: "minecraft:pale_oak_log{axis:y}"},
        {pos: [4, 5, 7], state: "minecraft:pale_hanging_moss{tip:false}"},
        {pos: [5, 5, 1], state: "minecraft:pale_hanging_moss{tip:false}"},
        {pos: [5, 5, 3], state: "minecraft:pale_oak_log{axis:y}"},
        {pos: [5, 5, 4], state: "minecraft:pale_oak_log{axis:y}"},
        {pos: [5, 5, 5], state: "minecraft:pale_oak_log{axis:y}"},
        {pos: [5, 5, 6], state: "minecraft:pale_hanging_moss{tip:true}"},
        {pos: [7, 5, 2], state: "minecraft:pale_hanging_moss{tip:false}"},
        {pos: [7, 5, 4], state: "minecraft:pale_hanging_moss{tip:false}"},
        {pos: [7, 5, 5], state: "minecraft:pale_hanging_moss{tip:false}"},
        {pos: [7, 5, 7], state: "minecraft:pale_hanging_moss{tip:false}"},
        {pos: [2, 6, 4], state: "minecraft:pale_hanging_moss{tip:true}"},
        {pos: [2, 6, 5], state: "minecraft:pale_hanging_moss{tip:true}"},
        {pos: [2, 6, 6], state: "minecraft:pale_hanging_moss{tip:false}"},
        {pos: [2, 6, 7], state: "minecraft:pale_hanging_moss{tip:true}"},
        {pos: [3, 6, 5], state: "minecraft:pale_hanging_moss{tip:true}"},
        {pos: [4, 6, 1], state: "minecraft:pale_hanging_moss{tip:false}"},
        {pos: [4, 6, 3], state: "minecraft:pale_hanging_moss{tip:true}"},
        {pos: [4, 6, 4], state: "minecraft:pale_oak_log{axis:y}"},
        {pos: [4, 6, 5], state: "minecraft:pale_oak_log{axis:y}"},
        {pos: [4, 6, 7], state: "minecraft:pale_hanging_moss{tip:false}"},
        {pos: [5, 6, 1], state: "minecraft:pale_hanging_moss{tip:false}"},
        {pos: [5, 6, 2], state: "minecraft:pale_hanging_moss{tip:true}"},
        {pos: [5, 6, 3], state: "minecraft:pale_oak_log{axis:y}"},
        {pos: [5, 6, 4], state: "minecraft:pale_oak_log{axis:y}"},
        {pos: [5, 6, 5], state: "minecraft:pale_oak_log{axis:y}"},
        {pos: [5, 6, 6], state: "minecraft:pale_hanging_moss{tip:false}"},
        {pos: [6, 6, 3], state: "minecraft:pale_hanging_moss{tip:true}"},
        {pos: [7, 6, 2], state: "minecraft:pale_hanging_moss{tip:false}"},
        {pos: [7, 6, 4], state: "minecraft:pale_hanging_moss{tip:false}"},
        {pos: [7, 6, 5], state: "minecraft:pale_hanging_moss{tip:false}"},
        {pos: [7, 6, 6], state: "minecraft:pale_hanging_moss{tip:true}"},
        {pos: [7, 6, 7], state: "minecraft:pale_hanging_moss{tip:false}"},
        {pos: [2, 7, 2], state: "minecraft:pale_oak_leaves{distance:4,persistent:false,waterlogged:false}"},
        {pos: [2, 7, 3], state: "minecraft:pale_oak_leaves{distance:3,persistent:false,waterlogged:false}"},
        {pos: [2, 7, 4], state: "minecraft:pale_oak_leaves{distance:2,persistent:false,waterlogged:false}"},
        {pos: [2, 7, 5], state: "minecraft:pale_oak_leaves{distance:2,persistent:false,waterlogged:false}"},
        {pos: [2, 7, 6], state: "minecraft:pale_oak_leaves{distance:3,persistent:false,waterlogged:false}"},
        {pos: [2, 7, 7], state: "minecraft:pale_oak_leaves{distance:4,persistent:false,waterlogged:false}"},
        {pos: [3, 7, 2], state: "minecraft:pale_oak_leaves{distance:3,persistent:false,waterlogged:false}"},
        {pos: [3, 7, 3], state: "minecraft:pale_oak_leaves{distance:2,persistent:false,waterlogged:false}"},
        {pos: [3, 7, 4], state: "minecraft:pale_oak_leaves{distance:1,persistent:false,waterlogged:false}"},
        {pos: [3, 7, 5], state: "minecraft:pale_oak_leaves{distance:1,persistent:false,waterlogged:false}"},
        {pos: [3, 7, 6], state: "minecraft:pale_oak_leaves{distance:2,persistent:false,waterlogged:false}"},
        {pos: [3, 7, 7], state: "minecraft:pale_oak_leaves{distance:3,persistent:false,waterlogged:false}"},
        {pos: [4, 7, 1], state: "minecraft:pale_oak_leaves{distance:3,persistent:false,waterlogged:false}"},
        {pos: [4, 7, 2], state: "minecraft:pale_oak_leaves{distance:2,persistent:false,waterlogged:false}"},
        {pos: [4, 7, 3], state: "minecraft:pale_oak_leaves{distance:1,persistent:false,waterlogged:false}"},
        {pos: [4, 7, 4], state: "minecraft:pale_oak_log{axis:y}"},
        {pos: [4, 7, 5], state: "minecraft:pale_oak_log{axis:y}"},
        {pos: [4, 7, 6], state: "minecraft:pale_oak_leaves{distance:1,persistent:false,waterlogged:false}"},
        {pos: [4, 7, 7], state: "minecraft:pale_oak_leaves{distance:2,persistent:false,waterlogged:false}"},
        {pos: [5, 7, 1], state: "minecraft:pale_oak_leaves{distance:2,persistent:false,waterlogged:false}"},
        {pos: [5, 7, 2], state: "minecraft:pale_oak_leaves{distance:1,persistent:false,waterlogged:false}"},
        {pos: [5, 7, 3], state: "minecraft:pale_oak_log{axis:y}"},
        {pos: [5, 7, 4], state: "minecraft:pale_oak_log{axis:y}"},
        {pos: [5, 7, 5], state: "minecraft:pale_oak_log{axis:y}"},
        {pos: [5, 7, 6], state: "minecraft:pale_oak_leaves{distance:1,persistent:false,waterlogged:false}"},
        {pos: [5, 7, 7], state: "minecraft:pale_oak_leaves{distance:2,persistent:false,waterlogged:false}"},
        {pos: [6, 7, 1], state: "minecraft:pale_oak_leaves{distance:3,persistent:false,waterlogged:false}"},
        {pos: [6, 7, 2], state: "minecraft:pale_oak_leaves{distance:2,persistent:false,waterlogged:false}"},
        {pos: [6, 7, 3], state: "minecraft:pale_oak_leaves{distance:1,persistent:false,waterlogged:false}"},
        {pos: [6, 7, 4], state: "minecraft:pale_oak_leaves{distance:1,persistent:false,waterlogged:false}"},
        {pos: [6, 7, 5], state: "minecraft:pale_oak_leaves{distance:1,persistent:false,waterlogged:false}"},
        {pos: [6, 7, 6], state: "minecraft:pale_oak_leaves{distance:2,persistent:false,waterlogged:false}"},
        {pos: [6, 7, 7], state: "minecraft:pale_oak_leaves{distance:3,persistent:false,waterlogged:false}"},
        {pos: [7, 7, 2], state: "minecraft:pale_oak_leaves{distance:3,persistent:false,waterlogged:false}"},
        {pos: [7, 7, 3], state: "minecraft:pale_oak_leaves{distance:2,persistent:false,waterlogged:false}"},
        {pos: [7, 7, 4], state: "minecraft:pale_oak_leaves{distance:2,persistent:false,waterlogged:false}"},
        {pos: [7, 7, 5], state: "minecraft:pale_oak_leaves{distance:2,persistent:false,waterlogged:false}"},
        {pos: [7, 7, 6], state: "minecraft:pale_oak_leaves{distance:3,persistent:false,waterlogged:false}"},
        {pos: [7, 7, 7], state: "minecraft:pale_oak_leaves{distance:4,persistent:false,waterlogged:false}"},
        {pos: [1, 8, 2], state: "minecraft:pale_oak_leaves{distance:5,persistent:false,waterlogged:false}"},
        {pos: [1, 8, 3], state: "minecraft:pale_oak_leaves{distance:4,persistent:false,waterlogged:false}"},
        {pos: [1, 8, 4], state: "minecraft:pale_oak_leaves{distance:3,persistent:false,waterlogged:false}"},
        {pos: [1, 8, 5], state: "minecraft:pale_oak_leaves{distance:3,persistent:false,waterlogged:false}"},
        {pos: [1, 8, 6], state: "minecraft:pale_oak_leaves{distance:4,persistent:false,waterlogged:false}"},
        {pos: [2, 8, 1], state: "minecraft:pale_oak_leaves{distance:5,persistent:false,waterlogged:false}"},
        {pos: [2, 8, 2], state: "minecraft:pale_oak_leaves{distance:4,persistent:false,waterlogged:false}"},
        {pos: [2, 8, 3], state: "minecraft:pale_oak_leaves{distance:3,persistent:false,waterlogged:false}"},
        {pos: [2, 8, 4], state: "minecraft:pale_oak_leaves{distance:2,persistent:false,waterlogged:false}"},
        {pos: [2, 8, 5], state: "minecraft:pale_oak_leaves{distance:2,persistent:false,waterlogged:false}"},
        {pos: [2, 8, 6], state: "minecraft:pale_oak_leaves{distance:3,persistent:false,waterlogged:false}"},
        {pos: [2, 8, 7], state: "minecraft:pale_oak_leaves{distance:4,persistent:false,waterlogged:false}"},
        {pos: [2, 8, 8], state: "minecraft:pale_oak_leaves{distance:5,persistent:false,waterlogged:false}"},
        {pos: [3, 8, 1], state: "minecraft:pale_oak_leaves{distance:4,persistent:false,waterlogged:false}"},
        {pos: [3, 8, 2], state: "minecraft:pale_oak_leaves{distance:3,persistent:false,waterlogged:false}"},
        {pos: [3, 8, 3], state: "minecraft:pale_oak_leaves{distance:2,persistent:false,waterlogged:false}"},
        {pos: [3, 8, 4], state: "minecraft:pale_oak_leaves{distance:1,persistent:false,waterlogged:false}"},
        {pos: [3, 8, 5], state: "minecraft:pale_oak_leaves{distance:1,persistent:false,waterlogged:false}"},
        {pos: [3, 8, 6], state: "minecraft:pale_oak_leaves{distance:2,persistent:false,waterlogged:false}"},
        {pos: [3, 8, 7], state: "minecraft:pale_oak_leaves{distance:3,persistent:false,waterlogged:false}"},
        {pos: [3, 8, 8], state: "minecraft:pale_oak_leaves{distance:4,persistent:false,waterlogged:false}"},
        {pos: [4, 8, 1], state: "minecraft:pale_oak_leaves{distance:3,persistent:false,waterlogged:false}"},
        {pos: [4, 8, 2], state: "minecraft:pale_oak_leaves{distance:2,persistent:false,waterlogged:false}"},
        {pos: [4, 8, 3], state: "minecraft:pale_oak_leaves{distance:1,persistent:false,waterlogged:false}"},
        {pos: [4, 8, 4], state: "minecraft:pale_oak_log{axis:y}"},
        {pos: [4, 8, 5], state: "minecraft:pale_oak_log{axis:y}"},
        {pos: [4, 8, 6], state: "minecraft:pale_oak_leaves{distance:1,persistent:false,waterlogged:false}"},
        {pos: [4, 8, 7], state: "minecraft:pale_oak_leaves{distance:2,persistent:false,waterlogged:false}"},
        {pos: [4, 8, 8], state: "minecraft:pale_oak_leaves{distance:3,persistent:false,waterlogged:false}"},
        {pos: [5, 8, 1], state: "minecraft:pale_oak_leaves{distance:3,persistent:false,waterlogged:false}"},
        {pos: [5, 8, 2], state: "minecraft:pale_oak_leaves{distance:2,persistent:false,waterlogged:false}"},
        {pos: [5, 8, 3], state: "minecraft:pale_oak_leaves{distance:1,persistent:false,waterlogged:false}"},
        {pos: [5, 8, 4], state: "minecraft:pale_oak_log{axis:y}"},
        {pos: [5, 8, 5], state: "minecraft:pale_oak_log{axis:y}"},
        {pos: [5, 8, 6], state: "minecraft:pale_oak_leaves{distance:1,persistent:false,waterlogged:false}"},
        {pos: [5, 8, 7], state: "minecraft:pale_oak_leaves{distance:2,persistent:false,waterlogged:false}"},
        {pos: [5, 8, 8], state: "minecraft:pale_oak_leaves{distance:3,persistent:false,waterlogged:false}"},
        {pos: [6, 8, 1], state: "minecraft:pale_oak_leaves{distance:4,persistent:false,waterlogged:false}"},
        {pos: [6, 8, 2], state: "minecraft:pale_oak_leaves{distance:3,persistent:false,waterlogged:false}"},
        {pos: [6, 8, 3], state: "minecraft:pale_oak_leaves{distance:2,persistent:false,waterlogged:false}"},
        {pos: [6, 8, 4], state: "minecraft:pale_oak_leaves{distance:1,persistent:false,waterlogged:false}"},
        {pos: [6, 8, 5], state: "minecraft:pale_oak_leaves{distance:1,persistent:false,waterlogged:false}"},
        {pos: [6, 8, 6], state: "minecraft:pale_oak_leaves{distance:2,persistent:false,waterlogged:false}"},
        {pos: [6, 8, 7], state: "minecraft:pale_oak_leaves{distance:3,persistent:false,waterlogged:false}"},
        {pos: [6, 8, 8], state: "minecraft:pale_oak_leaves{distance:4,persistent:false,waterlogged:false}"},
        {pos: [7, 8, 2], state: "minecraft:pale_oak_leaves{distance:4,persistent:false,waterlogged:false}"},
        {pos: [7, 8, 3], state: "minecraft:pale_oak_leaves{distance:3,persistent:false,waterlogged:false}"},
        {pos: [7, 8, 4], state: "minecraft:pale_oak_leaves{distance:2,persistent:false,waterlogged:false}"},
        {pos: [7, 8, 5], state: "minecraft:pale_oak_leaves{distance:2,persistent:false,waterlogged:false}"},
        {pos: [7, 8, 6], state: "minecraft:pale_oak_leaves{distance:3,persistent:false,waterlogged:false}"},
        {pos: [8, 8, 2], state: "minecraft:pale_oak_leaves{distance:5,persistent:false,waterlogged:false}"},
        {pos: [8, 8, 3], state: "minecraft:pale_oak_leaves{distance:4,persistent:false,waterlogged:false}"},
        {pos: [8, 8, 4], state: "minecraft:pale_oak_leaves{distance:3,persistent:false,waterlogged:false}"},
        {pos: [8, 8, 5], state: "minecraft:pale_oak_leaves{distance:3,persistent:false,waterlogged:false}"},
        {pos: [8, 8, 6], state: "minecraft:pale_oak_leaves{distance:4,persistent:false,waterlogged:false}"},
        {pos: [2, 9, 4], state: "minecraft:pale_oak_leaves{distance:3,persistent:false,waterlogged:false}"},
        {pos: [2, 9, 5], state: "minecraft:pale_oak_leaves{distance:3,persistent:false,waterlogged:false}"},
        {pos: [3, 9, 3], state: "minecraft:pale_oak_leaves{distance:3,persistent:false,waterlogged:false}"},
        {pos: [3, 9, 4], state: "minecraft:pale_oak_leaves{distance:2,persistent:false,waterlogged:false}"},
        {pos: [3, 9, 5], state: "minecraft:pale_oak_leaves{distance:2,persistent:false,waterlogged:false}"},
        {pos: [3, 9, 6], state: "minecraft:pale_oak_leaves{distance:3,persistent:false,waterlogged:false}"},
        {pos: [4, 9, 2], state: "minecraft:pale_oak_leaves{distance:3,persistent:false,waterlogged:false}"},
        {pos: [4, 9, 3], state: "minecraft:pale_oak_leaves{distance:2,persistent:false,waterlogged:false}"},
        {pos: [4, 9, 4], state: "minecraft:pale_oak_leaves{distance:1,persistent:false,waterlogged:false}"},
        {pos: [4, 9, 5], state: "minecraft:pale_oak_leaves{distance:1,persistent:false,waterlogged:false}"},
        {pos: [4, 9, 6], state: "minecraft:pale_oak_leaves{distance:2,persistent:false,waterlogged:false}"},
        {pos: [4, 9, 7], state: "minecraft:pale_oak_leaves{distance:3,persistent:false,waterlogged:false}"},
        {pos: [5, 9, 2], state: "minecraft:pale_oak_leaves{distance:3,persistent:false,waterlogged:false}"},
        {pos: [5, 9, 3], state: "minecraft:pale_oak_leaves{distance:2,persistent:false,waterlogged:false}"},
        {pos: [5, 9, 4], state: "minecraft:pale_oak_leaves{distance:1,persistent:false,waterlogged:false}"},
        {pos: [5, 9, 5], state: "minecraft:pale_oak_leaves{distance:1,persistent:false,waterlogged:false}"},
        {pos: [5, 9, 6], state: "minecraft:pale_oak_leaves{distance:2,persistent:false,waterlogged:false}"},
        {pos: [5, 9, 7], state: "minecraft:pale_oak_leaves{distance:3,persistent:false,waterlogged:false}"},
        {pos: [6, 9, 3], state: "minecraft:pale_oak_leaves{distance:3,persistent:false,waterlogged:false}"},
        {pos: [6, 9, 4], state: "minecraft:pale_oak_leaves{distance:2,persistent:false,waterlogged:false}"},
        {pos: [6, 9, 5], state: "minecraft:pale_oak_leaves{distance:2,persistent:false,waterlogged:false}"},
        {pos: [6, 9, 6], state: "minecraft:pale_oak_leaves{distance:3,persistent:false,waterlogged:false}"},
        {pos: [7, 9, 4], state: "minecraft:pale_oak_leaves{distance:3,persistent:false,waterlogged:false}"},
        {pos: [7, 9, 5], state: "minecraft:pale_oak_leaves{distance:3,persistent:false,waterlogged:false}"}
    ],
    entities: [
        {blockPos: [8, 0, 3], pos: [8.5d, 0.9375d, 3.5d], nbt: {Air: 300s, Fire: 0s, Invulnerable: 0b, Motion: [0.0d, 0.0d, 0.0d], OnGround: 0b, PortalCooldown: 0, Pos: [-85.5d, -60.0625d, 660.5d], Rotation: [90.0f, 0.0f], UUID: [I; 1197559094, 1767063921, -1680016986, 1675023202], block_pos: [I; -86, -61, 660], color: "gray", fall_distance: 0.0d, id: "minecraft:cushion"}}
    ],
    palette: [
        "minecraft:grass_block{snowy:false}",
        "minecraft:dirt",
        "minecraft:pale_moss_block",
        "minecraft:resin_block",
        "minecraft:pale_oak_log{axis:y}",
        "minecraft:pale_oak_leaves{distance:4,persistent:false,waterlogged:false}",
        "minecraft:pale_oak_leaves{distance:3,persistent:false,waterlogged:false}",
        "minecraft:pale_oak_leaves{distance:2,persistent:false,waterlogged:false}",
        "minecraft:pale_oak_leaves{distance:1,persistent:false,waterlogged:false}",
        "minecraft:pale_oak_leaves{distance:5,persistent:false,waterlogged:false}",
        "minecraft:dirt_path",
        "minecraft:pale_moss_carpet{bottom:true,east:low,north:none,south:low,west:none}",
        "minecraft:pale_moss_carpet{bottom:true,east:low,north:low,south:none,west:none}",
        "minecraft:pale_moss_carpet{bottom:true,east:none,north:none,south:none,west:none}",
        "minecraft:pale_moss_carpet{bottom:true,east:none,north:none,south:low,west:none}",
        "minecraft:pale_moss_carpet{bottom:true,east:none,north:low,south:none,west:none}",
        "minecraft:pale_moss_carpet{bottom:true,east:none,north:none,south:low,west:low}",
        "minecraft:tall_grass{half:lower}",
        "minecraft:pale_moss_carpet{bottom:true,east:low,north:none,south:none,west:none}",
        "minecraft:pale_moss_carpet{bottom:true,east:none,north:none,south:tall,west:none}",
        "minecraft:pale_moss_carpet{bottom:true,east:low,north:tall,south:none,west:low}",
        "minecraft:tall_grass{half:upper}",
        "minecraft:pale_hanging_moss{tip:true}",
        "minecraft:pale_moss_carpet{bottom:false,east:none,north:none,south:low,west:none}",
        "minecraft:pale_moss_carpet{bottom:false,east:none,north:low,south:none,west:none}",
        "minecraft:pale_hanging_moss{tip:false}",
        "minecraft:jigsaw{orientation:east_up}",
        "minecraft:barrel{facing:east,open:false}",
        "minecraft:chest{facing:east,type:single,waterlogged:false}",
        "minecraft:campfire{facing:west,lit:false,signal_fire:false,waterlogged:false}",
        "minecraft:creaking_heart{axis:y,creaking_heart_state:dormant,natural:false}"
    ]
}
