{
    size: [5, 7, 10],
    data: [
        {pos: [0, 0, 1], state: "minecraft:tuff_bricks"},
        {pos: [0, 0, 2], state: "minecraft:tuff_bricks"},
        {pos: [0, 0, 3], state: "minecraft:tuff_bricks"},
        {pos: [0, 0, 6], state: "minecraft:air"},
        {pos: [0, 0, 7], state: "minecraft:tuff_bricks"},
        {pos: [0, 0, 8], state: "minecraft:tuff_bricks"},
        {pos: [1, 0, 0], state: "minecraft:waxed_oxidized_copper"},
        {pos: [1, 0, 1], state: "minecraft:tuff_bricks"},
        {pos: [1, 0, 2], state: "minecraft:tuff_bricks"},
        {pos: [1, 0, 3], state: "minecraft:tuff_bricks"},
        {pos: [1, 0, 4], state: "minecraft:tuff_bricks"},
        {pos: [1, 0, 5], state: "minecraft:tuff_bricks"},
        {pos: [1, 0, 6], state: "minecraft:tuff_bricks"},
        {pos: [1, 0, 7], state: "minecraft:tuff_bricks"},
        {pos: [1, 0, 8], state: "minecraft:tuff_bricks"},
        {pos: [1, 0, 9], state: "minecraft:tuff_bricks"},
        {pos: [2, 0, 0], state: "minecraft:waxed_oxidized_copper"},
        {pos: [2, 0, 1], state: "minecraft:tuff_bricks"},
        {pos: [2, 0, 2], state: "minecraft:tuff_bricks"},
        {pos: [2, 0, 3], state: "minecraft:tuff_bricks"},
        {pos: [2, 0, 4], state: "minecraft:tuff_bricks"},
        {pos: [2, 0, 5], state: "minecraft:tuff_bricks"},
        {pos: [2, 0, 6], state: "minecraft:tuff_bricks"},
        {pos: [2, 0, 7], state: "minecraft:tuff_bricks"},
        {pos: [2, 0, 8], state: "minecraft:tuff_bricks"},
        {pos: [2, 0, 9], state: "minecraft:tuff_bricks"},
        {pos: [3, 0, 0], state: "minecraft:waxed_oxidized_copper"},
        {pos: [3, 0, 1], state: "minecraft:tuff_bricks"},
        {pos: [3, 0, 2], state: "minecraft:tuff_bricks"},
        {pos: [3, 0, 3], state: "minecraft:tuff_bricks"},
        {pos: [3, 0, 4], state: "minecraft:tuff_bricks"},
        {pos: [3, 0, 5], state: "minecraft:tuff_bricks"},
        {pos: [3, 0, 6], state: "minecraft:tuff_bricks"},
        {pos: [3, 0, 7], state: "minecraft:tuff_bricks"},
        {pos: [3, 0, 8], state: "minecraft:tuff_bricks"},
        {pos: [3, 0, 9], state: "minecraft:tuff_bricks"},
        {pos: [4, 0, 1], state: "minecraft:tuff_bricks"},
        {pos: [4, 0, 2], state: "minecraft:tuff_bricks"},
        {pos: [4, 0, 3], state: "minecraft:air"},
        {pos: [4, 0, 6], state: "minecraft:air"},
        {pos: [4, 0, 7], state: "minecraft:tuff_bricks"},
        {pos: [4, 0, 8], state: "minecraft:tuff_bricks"},
        {pos: [0, 1, 1], state: "minecraft:waxed_oxidized_cut_copper_stairs{facing:east,half:bottom,shape:outer_right,waterlogged:false}"},
        {pos: [0, 1, 2], state: "minecraft:waxed_oxidized_cut_copper_stairs{facing:east,half:bottom,shape:straight,waterlogged:false}"},
        {pos: [0, 1, 3], state: "minecraft:tuff_bricks"},
        {pos: [0, 1, 5], state: "minecraft:air"},
        {pos: [0, 1, 6], state: "minecraft:air"},
        {pos: [0, 1, 7], state: "minecraft:tuff_bricks"},
        {pos: [0, 1, 8], state: "minecraft:tuff_bricks"},
        {pos: [1, 1, 0], state: "minecraft:air"},
        {pos: [1, 1, 1], state: "minecraft:waxed_oxidized_cut_copper_stairs{facing:south,half:bottom,shape:straight,waterlogged:false}"},
        {pos: [1, 1, 2], state: "minecraft:waxed_oxidized_copper"},
        {pos: [1, 1, 3], state: "minecraft:tuff_bricks"},
        {pos: [1, 1, 4], state: "minecraft:tuff_bricks"},
        {pos: [1, 1, 5], state: "minecraft:waxed_copper_grate{waterlogged:false}"},
        {pos: [1, 1, 6], state: "minecraft:tuff_bricks"},
        {pos: [1, 1, 7], state: "minecraft:tuff_bricks"},
        {pos: [1, 1, 8], state: "minecraft:tuff_bricks"},
        {pos: [1, 1, 9], state: "minecraft:tuff_bricks"},
        {pos: [2, 1, 0], state: "minecraft:air"},
        {pos: [2, 1, 1], state: "minecraft:waxed_oxidized_cut_copper_stairs{facing:south,half:bottom,shape:straight,waterlogged:false}"},
        {pos: [2, 1, 2], state: "minecraft:waxed_oxidized_copper"},
        {pos: [2, 1, 3], state: "minecraft:tuff_bricks"},
        {pos: [2, 1, 4], state: "minecraft:tuff_bricks"},
        {pos: [2, 1, 5], state: "minecraft:waxed_copper_grate{waterlogged:false}"},
        {pos: [2, 1, 6], state: "minecraft:waxed_copper_grate{waterlogged:false}"},
        {pos: [2, 1, 7], state: "minecraft:waxed_copper_grate{waterlogged:false}"},
        {pos: [2, 1, 8], state: "minecraft:waxed_copper_grate{waterlogged:false}"},
        {pos: [2, 1, 9], state: "minecraft:waxed_copper_grate{waterlogged:false}"},
        {pos: [3, 1, 0], state: "minecraft:air"},
        {pos: [3, 1, 1], state: "minecraft:waxed_oxidized_cut_copper_stairs{facing:south,half:bottom,shape:straight,waterlogged:false}"},
        {pos: [3, 1, 2], state: "minecraft:waxed_oxidized_copper"},
        {pos: [3, 1, 3], state: "minecraft:tuff_bricks"},
        {pos: [3, 1, 4], state: "minecraft:tuff_bricks"},
        {pos: [3, 1, 5], state: "minecraft:waxed_copper_grate{waterlogged:false}"},
        {pos: [3, 1, 6], state: "minecraft:tuff_bricks"},
        {pos: [3, 1, 7], state: "minecraft:tuff_bricks"},
        {pos: [3, 1, 8], state: "minecraft:tuff_bricks"},
        {pos: [3, 1, 9], state: "minecraft:tuff_bricks"},
        {pos: [4, 1, 1], state: "minecraft:waxed_oxidized_cut_copper_stairs{facing:west,half:bottom,shape:outer_left,waterlogged:false}"},
        {pos: [4, 1, 2], state: "minecraft:waxed_oxidized_cut_copper_stairs{facing:west,half:bottom,shape:straight,waterlogged:false}"},
        {pos: [4, 1, 3], state: "minecraft:air"},
        {pos: [4, 1, 6], state: "minecraft:air"},
        {pos: [4, 1, 7], state: "minecraft:tuff_bricks"},
        {pos: [4, 1, 8], state: "minecraft:tuff_bricks"},
        {pos: [0, 2, 1], state: "minecraft:air"},
        {pos: [0, 2, 2], state: "minecraft:air"},
        {pos: [0, 2, 3], state: "minecraft:tuff_bricks"},
        {pos: [0, 2, 5], state: "minecraft:air"},
        {pos: [0, 2, 6], state: "minecraft:air"},
        {pos: [0, 2, 7], state: "minecraft:waxed_copper_bulb{lit:true,powered:false}"},
        {pos: [0, 2, 8], state: "minecraft:tuff_bricks"},
        {pos: [1, 2, 0], state: "minecraft:air"},
        {pos: [1, 2, 1], state: "minecraft:air"},
        {pos: [1, 2, 2], state: "minecraft:waxed_oxidized_cut_copper_stairs{facing:south,half:bottom,shape:straight,waterlogged:false}"},
        {pos: [1, 2, 3], state: "minecraft:waxed_oxidized_copper"},
        {pos: [1, 2, 4], state: "minecraft:tuff_bricks"},
        {pos: [1, 2, 5], state: "minecraft:tuff_bricks"},
        {pos: [1, 2, 6], state: "minecraft:tuff_bricks"},
        {pos: [1, 2, 7], state: "minecraft:tuff_bricks"},
        {pos: [1, 2, 8], state: "minecraft:tuff_bricks"},
        {pos: [1, 2, 9], state: "minecraft:tuff_bricks"},
        {pos: [2, 2, 0], state: "minecraft:jigsaw{orientation:north_up}", nbt: {final_state: "minecraft:air", id: "minecraft:jigsaw", joint: "rollable", name: "minecraft:upper_arm", placement_priority: 0, pool: "minecraft:empty", selection_priority: 0, target: "minecraft:empty"}},
        {pos: [2, 2, 1], state: "minecraft:air"},
        {pos: [2, 2, 2], state: "minecraft:waxed_oxidized_cut_copper_stairs{facing:south,half:bottom,shape:straight,waterlogged:false}"},
        {pos: [2, 2, 3], state: "minecraft:waxed_oxidized_copper"},
        {pos: [2, 2, 4], state: "minecraft:tuff_bricks"},
        {pos: [2, 2, 5], state: "minecraft:tuff_bricks"},
        {pos: [2, 2, 6], state: "minecraft:tuff_bricks"},
        {pos: [2, 2, 7], state: "minecraft:tuff_bricks"},
        {pos: [2, 2, 8], state: "minecraft:tuff_bricks"},
        {pos: [2, 2, 9], state: "minecraft:tuff_bricks"},
        {pos: [3, 2, 0], state: "minecraft:air"},
        {pos: [3, 2, 1], state: "minecraft:air"},
        {pos: [3, 2, 2], state: "minecraft:waxed_oxidized_cut_copper_stairs{facing:south,half:bottom,shape:straight,waterlogged:false}"},
        {pos: [3, 2, 3], state: "minecraft:waxed_oxidized_copper"},
        {pos: [3, 2, 4], state: "minecraft:tuff_bricks"},
        {pos: [3, 2, 5], state: "minecraft:tuff_bricks"},
        {pos: [3, 2, 6], state: "minecraft:tuff_bricks"},
        {pos: [3, 2, 7], state: "minecraft:tuff_bricks"},
        {pos: [3, 2, 8], state: "minecraft:tuff_bricks"},
        {pos: [3, 2, 9], state: "minecraft:tuff_bricks"},
        {pos: [4, 2, 1], state: "minecraft:air"},
        {pos: [4, 2, 2], state: "minecraft:air"},
        {pos: [4, 2, 3], state: "minecraft:air"},
        {pos: [4, 2, 6], state: "minecraft:air"},
        {pos: [4, 2, 7], state: "minecraft:waxed_copper_bulb{lit:true,powered:false}"},
        {pos: [4, 2, 8], state: "minecraft:tuff_bricks"},
        {pos: [0, 3, 1], state: "minecraft:air"},
        {pos: [0, 3, 2], state: "minecraft:air"},
        {pos: [0, 3, 3], state: "minecraft:waxed_copper_block"},
        {pos: [0, 3, 6], state: "minecraft:air"},
        {pos: [0, 3, 7], state: "minecraft:waxed_copper_block"},
        {pos: [0, 3, 8], state: "minecraft:waxed_copper_block"},
        {pos: [1, 3, 0], state: "minecraft:air"},
        {pos: [1, 3, 1], state: "minecraft:air"},
        {pos: [1, 3, 2], state: "minecraft:air"},
        {pos: [1, 3, 3], state: "minecraft:waxed_oxidized_cut_copper_stairs{facing:south,half:bottom,shape:straight,waterlogged:false}"},
        {pos: [1, 3, 4], state: "minecraft:waxed_oxidized_cut_copper_slab{type:bottom,waterlogged:false}"},
        {pos: [1, 3, 5], state: "minecraft:waxed_oxidized_cut_copper_stairs{facing:south,half:bottom,shape:straight,waterlogged:false}"},
        {pos: [1, 3, 6], state: "minecraft:waxed_oxidized_copper"},
        {pos: [1, 3, 7], state: "minecraft:waxed_oxidized_copper"},
        {pos: [1, 3, 8], state: "minecraft:waxed_oxidized_copper"},
        {pos: [1, 3, 9], state: "minecraft:waxed_copper_block"},
        {pos: [2, 3, 0], state: "minecraft:air"},
        {pos: [2, 3, 1], state: "minecraft:air"},
        {pos: [2, 3, 2], state: "minecraft:air"},
        {pos: [2, 3, 3], state: "minecraft:waxed_oxidized_cut_copper_stairs{facing:south,half:bottom,shape:straight,waterlogged:false}"},
        {pos: [2, 3, 4], state: "minecraft:waxed_oxidized_cut_copper_slab{type:bottom,waterlogged:false}"},
        {pos: [2, 3, 5], state: "minecraft:waxed_oxidized_cut_copper_stairs{facing:south,half:bottom,shape:straight,waterlogged:false}"},
        {pos: [2, 3, 6], state: "minecraft:waxed_oxidized_copper"},
        {pos: [2, 3, 7], state: "minecraft:waxed_oxidized_copper"},
        {pos: [2, 3, 8], state: "minecraft:waxed_oxidized_copper"},
        {pos: [2, 3, 9], state: "minecraft:waxed_copper_block"},
        {pos: [3, 3, 0], state: "minecraft:air"},
        {pos: [3, 3, 1], state: "minecraft:air"},
        {pos: [3, 3, 2], state: "minecraft:air"},
        {pos: [3, 3, 3], state: "minecraft:waxed_oxidized_cut_copper_stairs{facing:south,half:bottom,shape:straight,waterlogged:false}"},
        {pos: [3, 3, 4], state: "minecraft:waxed_oxidized_cut_copper_slab{type:bottom,waterlogged:false}"},
        {pos: [3, 3, 5], state: "minecraft:waxed_oxidized_cut_copper_stairs{facing:south,half:bottom,shape:straight,waterlogged:false}"},
        {pos: [3, 3, 6], state: "minecraft:waxed_oxidized_copper"},
        {pos: [3, 3, 7], state: "minecraft:waxed_oxidized_copper"},
        {pos: [3, 3, 8], state: "minecraft:waxed_oxidized_copper"},
        {pos: [3, 3, 9], state: "minecraft:waxed_copper_block"},
        {pos: [4, 3, 1], state: "minecraft:air"},
        {pos: [4, 3, 2], state: "minecraft:air"},
        {pos: [4, 3, 3], state: "minecraft:air"},
        {pos: [4, 3, 6], state: "minecraft:waxed_copper_block"},
        {pos: [4, 3, 7], state: "minecraft:waxed_copper_block"},
        {pos: [4, 3, 8], state: "minecraft:waxed_copper_block"},
        {pos: [0, 4, 1], state: "minecraft:air"},
        {pos: [0, 4, 2], state: "minecraft:air"},
        {pos: [0, 4, 3], state: "minecraft:air"},
        {pos: [0, 4, 6], state: "minecraft:air"},
        {pos: [0, 4, 7], state: "minecraft:air"},
        {pos: [0, 4, 8], state: "minecraft:air"},
        {pos: [1, 4, 0], state: "minecraft:air"},
        {pos: [1, 4, 1], state: "minecraft:air"},
        {pos: [1, 4, 2], state: "minecraft:air"},
        {pos: [1, 4, 3], state: "minecraft:air"},
        {pos: [1, 4, 4], state: "minecraft:air"},
        {pos: [1, 4, 5], state: "minecraft:air"},
        {pos: [1, 4, 6], state: "minecraft:air"},
        {pos: [1, 4, 7], state: "minecraft:air"},
        {pos: [1, 4, 8], state: "minecraft:air"},
        {pos: [1, 4, 9], state: "minecraft:air"},
        {pos: [2, 4, 0], state: "minecraft:air"},
        {pos: [2, 4, 1], state: "minecraft:air"},
        {pos: [2, 4, 2], state: "minecraft:air"},
        {pos: [2, 4, 3], state: "minecraft:air"},
        {pos: [2, 4, 4], state: "minecraft:air"},
        {pos: [2, 4, 5], state: "minecraft:air"},
        {pos: [2, 4, 6], state: "minecraft:air"},
        {pos: [2, 4, 7], state: "minecraft:air"},
        {pos: [2, 4, 8], state: "minecraft:air"},
        {pos: [2, 4, 9], state: "minecraft:air"},
        {pos: [3, 4, 0], state: "minecraft:air"},
        {pos: [3, 4, 1], state: "minecraft:air"},
        {pos: [3, 4, 2], state: "minecraft:air"},
        {pos: [3, 4, 3], state: "minecraft:air"},
        {pos: [3, 4, 4], state: "minecraft:air"},
        {pos: [3, 4, 5], state: "minecraft:air"},
        {pos: [3, 4, 6], state: "minecraft:air"},
        {pos: [3, 4, 7], state: "minecraft:air"},
        {pos: [3, 4, 8], state: "minecraft:air"},
        {pos: [3, 4, 9], state: "minecraft:air"},
        {pos: [4, 4, 1], state: "minecraft:air"},
        {pos: [4, 4, 2], state: "minecraft:air"},
        {pos: [4, 4, 3], state: "minecraft:air"},
        {pos: [4, 4, 6], state: "minecraft:air"},
        {pos: [4, 4, 7], state: "minecraft:air"},
        {pos: [4, 4, 8], state: "minecraft:air"},
        {pos: [0, 5, 1], state: "minecraft:air"},
        {pos: [0, 5, 2], state: "minecraft:air"},
        {pos: [0, 5, 3], state: "minecraft:air"},
        {pos: [0, 5, 6], state: "minecraft:air"},
        {pos: [0, 5, 7], state: "minecraft:air"},
        {pos: [0, 5, 8], state: "minecraft:air"},
        {pos: [1, 5, 0], state: "minecraft:air"},
        {pos: [1, 5, 1], state: "minecraft:air"},
        {pos: [1, 5, 2], state: "minecraft:air"},
        {pos: [1, 5, 3], state: "minecraft:air"},
        {pos: [1, 5, 4], state: "minecraft:air"},
        {pos: [1, 5, 5], state: "minecraft:air"},
        {pos: [1, 5, 6], state: "minecraft:air"},
        {pos: [1, 5, 7], state: "minecraft:air"},
        {pos: [1, 5, 8], state: "minecraft:air"},
        {pos: [1, 5, 9], state: "minecraft:air"},
        {pos: [2, 5, 0], state: "minecraft:air"},
        {pos: [2, 5, 1], state: "minecraft:air"},
        {pos: [2, 5, 2], state: "minecraft:air"},
        {pos: [2, 5, 3], state: "minecraft:air"},
        {pos: [2, 5, 4], state: "minecraft:air"},
        {pos: [2, 5, 5], state: "minecraft:air"},
        {pos: [2, 5, 6], state: "minecraft:air"},
        {pos: [2, 5, 7], state: "minecraft:jigsaw{orientation:south_up}", nbt: {final_state: "minecraft:air", id: "minecraft:jigsaw", joint: "aligned", name: "minecraft:empty", placement_priority: 1, pool: "minecraft:trial_chambers/spawner/melee", selection_priority: 1, target: "minecraft:spawner_connector"}},
        {pos: [2, 5, 8], state: "minecraft:air"},
        {pos: [2, 5, 9], state: "minecraft:air"},
        {pos: [3, 5, 0], state: "minecraft:air"},
        {pos: [3, 5, 1], state: "minecraft:air"},
        {pos: [3, 5, 2], state: "minecraft:air"},
        {pos: [3, 5, 3], state: "minecraft:air"},
        {pos: [3, 5, 4], state: "minecraft:air"},
        {pos: [3, 5, 5], state: "minecraft:air"},
        {pos: [3, 5, 6], state: "minecraft:air"},
        {pos: [3, 5, 7], state: "minecraft:air"},
        {pos: [3, 5, 8], state: "minecraft:air"},
        {pos: [3, 5, 9], state: "minecraft:air"},
        {pos: [4, 5, 1], state: "minecraft:air"},
        {pos: [4, 5, 2], state: "minecraft:air"},
        {pos: [4, 5, 3], state: "minecraft:air"},
        {pos: [4, 5, 6], state: "minecraft:air"},
        {pos: [4, 5, 7], state: "minecraft:air"},
        {pos: [4, 5, 8], state: "minecraft:air"},
        {pos: [0, 6, 1], state: "minecraft:polished_tuff"},
        {pos: [0, 6, 2], state: "minecraft:polished_tuff"},
        {pos: [0, 6, 3], state: "minecraft:polished_tuff"},
        {pos: [0, 6, 6], state: "minecraft:polished_tuff"},
        {pos: [0, 6, 7], state: "minecraft:polished_tuff"},
        {pos: [0, 6, 8], state: "minecraft:polished_tuff"},
        {pos: [1, 6, 0], state: "minecraft:polished_tuff"},
        {pos: [1, 6, 1], state: "minecraft:polished_tuff"},
        {pos: [1, 6, 2], state: "minecraft:polished_tuff"},
        {pos: [1, 6, 3], state: "minecraft:polished_tuff"},
        {pos: [1, 6, 4], state: "minecraft:polished_tuff"},
        {pos: [1, 6, 5], state: "minecraft:polished_tuff"},
        {pos: [1, 6, 6], state: "minecraft:polished_tuff"},
        {pos: [1, 6, 7], state: "minecraft:polished_tuff"},
        {pos: [1, 6, 8], state: "minecraft:polished_tuff"},
        {pos: [1, 6, 9], state: "minecraft:polished_tuff"},
        {pos: [2, 6, 0], state: "minecraft:polished_tuff"},
        {pos: [2, 6, 1], state: "minecraft:polished_tuff"},
        {pos: [2, 6, 2], state: "minecraft:polished_tuff"},
        {pos: [2, 6, 3], state: "minecraft:polished_tuff"},
        {pos: [2, 6, 4], state: "minecraft:polished_tuff"},
        {pos: [2, 6, 5], state: "minecraft:polished_tuff"},
        {pos: [2, 6, 6], state: "minecraft:polished_tuff"},
        {pos: [2, 6, 7], state: "minecraft:polished_tuff"},
        {pos: [2, 6, 8], state: "minecraft:polished_tuff"},
        {pos: [2, 6, 9], state: "minecraft:polished_tuff"},
        {pos: [3, 6, 0], state: "minecraft:polished_tuff"},
        {pos: [3, 6, 1], state: "minecraft:polished_tuff"},
        {pos: [3, 6, 2], state: "minecraft:polished_tuff"},
        {pos: [3, 6, 3], state: "minecraft:polished_tuff"},
        {pos: [3, 6, 4], state: "minecraft:polished_tuff"},
        {pos: [3, 6, 5], state: "minecraft:polished_tuff"},
        {pos: [3, 6, 6], state: "minecraft:polished_tuff"},
        {pos: [3, 6, 7], state: "minecraft:polished_tuff"},
        {pos: [3, 6, 8], state: "minecraft:polished_tuff"},
        {pos: [3, 6, 9], state: "minecraft:polished_tuff"},
        {pos: [4, 6, 1], state: "minecraft:polished_tuff"},
        {pos: [4, 6, 2], state: "minecraft:polished_tuff"},
        {pos: [4, 6, 3], state: "minecraft:polished_tuff"},
        {pos: [4, 6, 6], state: "minecraft:polished_tuff"},
        {pos: [4, 6, 7], state: "minecraft:polished_tuff"},
        {pos: [4, 6, 8], state: "minecraft:polished_tuff"}
    ],
    entities: [],
    palette: [
        "minecraft:tuff_bricks",
        "minecraft:waxed_oxidized_copper",
        "minecraft:waxed_copper_grate{waterlogged:false}",
        "minecraft:waxed_copper_bulb{lit:true,powered:false}",
        "minecraft:waxed_copper_block",
        "minecraft:polished_tuff",
        "minecraft:air",
        "minecraft:waxed_oxidized_cut_copper_stairs{facing:east,half:bottom,shape:outer_right,waterlogged:false}",
        "minecraft:waxed_oxidized_cut_copper_stairs{facing:east,half:bottom,shape:straight,waterlogged:false}",
        "minecraft:waxed_oxidized_cut_copper_stairs{facing:south,half:bottom,shape:straight,waterlogged:false}",
        "minecraft:waxed_oxidized_cut_copper_stairs{facing:west,half:bottom,shape:outer_left,waterlogged:false}",
        "minecraft:waxed_oxidized_cut_copper_stairs{facing:west,half:bottom,shape:straight,waterlogged:false}",
        "minecraft:waxed_oxidized_cut_copper_slab{type:bottom,waterlogged:false}",
        "minecraft:jigsaw{orientation:north_up}",
        "minecraft:jigsaw{orientation:south_up}"
    ]
}
