{
    size: [11, 10, 10],
    data: [
        {pos: [0, 0, 0], state: "minecraft:grass_block{snowy:false}"},
        {pos: [0, 0, 1], state: "minecraft:grass_block{snowy:false}"},
        {pos: [0, 0, 2], state: "minecraft:grass_block{snowy:false}"},
        {pos: [0, 0, 3], state: "minecraft:grass_block{snowy:false}"},
        {pos: [0, 0, 4], state: "minecraft:grass_block{snowy:false}"},
        {pos: [0, 0, 5], state: "minecraft:grass_block{snowy:false}"},
        {pos: [0, 0, 6], state: "minecraft:grass_block{snowy:false}"},
        {pos: [0, 0, 7], state: "minecraft:grass_block{snowy:false}"},
        {pos: [0, 0, 8], state: "minecraft:grass_block{snowy:false}"},
        {pos: [0, 0, 9], state: "minecraft:grass_block{snowy:false}"},
        {pos: [1, 0, 0], state: "minecraft:grass_block{snowy:false}"},
        {pos: [1, 0, 1], state: "minecraft:grass_block{snowy:false}"},
        {pos: [1, 0, 2], state: "minecraft:grass_block{snowy:false}"},
        {pos: [1, 0, 3], state: "minecraft:dirt"},
        {pos: [1, 0, 4], state: "minecraft:dirt"},
        {pos: [1, 0, 5], state: "minecraft:dirt"},
        {pos: [1, 0, 6], state: "minecraft:dirt"},
        {pos: [1, 0, 7], state: "minecraft:dirt"},
        {pos: [1, 0, 8], state: "minecraft:dirt"},
        {pos: [1, 0, 9], state: "minecraft:dirt"},
        {pos: [2, 0, 0], state: "minecraft:grass_block{snowy:false}"},
        {pos: [2, 0, 1], state: "minecraft:dirt"},
        {pos: [2, 0, 2], state: "minecraft:dirt"},
        {pos: [2, 0, 3], state: "minecraft:grass_block{snowy:false}"},
        {pos: [2, 0, 4], state: "minecraft:dirt"},
        {pos: [2, 0, 5], state: "minecraft:dirt"},
        {pos: [2, 0, 6], state: "minecraft:dirt"},
        {pos: [2, 0, 7], state: "minecraft:dirt"},
        {pos: [2, 0, 8], state: "minecraft:dirt"},
        {pos: [2, 0, 9], state: "minecraft:dirt"},
        {pos: [3, 0, 0], state: "minecraft:grass_block{snowy:false}"},
        {pos: [3, 0, 1], state: "minecraft:grass_block{snowy:false}"},
        {pos: [3, 0, 2], state: "minecraft:grass_block{snowy:false}"},
        {pos: [3, 0, 3], state: "minecraft:dirt"},
        {pos: [3, 0, 4], state: "minecraft:dirt"},
        {pos: [3, 0, 5], state: "minecraft:dirt"},
        {pos: [3, 0, 6], state: "minecraft:clay"},
        {pos: [3, 0, 7], state: "minecraft:clay"},
        {pos: [3, 0, 8], state: "minecraft:dirt"},
        {pos: [3, 0, 9], state: "minecraft:dirt"},
        {pos: [4, 0, 0], state: "minecraft:grass_block{snowy:false}"},
        {pos: [4, 0, 1], state: "minecraft:grass_block{snowy:false}"},
        {pos: [4, 0, 2], state: "minecraft:dirt"},
        {pos: [4, 0, 3], state: "minecraft:dirt"},
        {pos: [4, 0, 4], state: "minecraft:dirt"},
        {pos: [4, 0, 5], state: "minecraft:clay"},
        {pos: [4, 0, 6], state: "minecraft:dirt"},
        {pos: [4, 0, 7], state: "minecraft:dirt"},
        {pos: [4, 0, 8], state: "minecraft:dirt"},
        {pos: [4, 0, 9], state: "minecraft:dirt"},
        {pos: [5, 0, 0], state: "minecraft:grass_block{snowy:false}"},
        {pos: [5, 0, 1], state: "minecraft:grass_block{snowy:false}"},
        {pos: [5, 0, 2], state: "minecraft:grass_block{snowy:false}"},
        {pos: [5, 0, 3], state: "minecraft:grass_block{snowy:false}"},
        {pos: [5, 0, 4], state: "minecraft:dirt"},
        {pos: [5, 0, 5], state: "minecraft:dirt"},
        {pos: [5, 0, 6], state: "minecraft:dirt"},
        {pos: [5, 0, 7], state: "minecraft:dirt"},
        {pos: [5, 0, 8], state: "minecraft:dirt"},
        {pos: [5, 0, 9], state: "minecraft:grass_block{snowy:false}"},
        {pos: [6, 0, 0], state: "minecraft:grass_block{snowy:false}"},
        {pos: [6, 0, 1], state: "minecraft:grass_block{snowy:false}"},
        {pos: [6, 0, 2], state: "minecraft:grass_block{snowy:false}"},
        {pos: [6, 0, 3], state: "minecraft:grass_block{snowy:false}"},
        {pos: [6, 0, 4], state: "minecraft:dirt"},
        {pos: [6, 0, 5], state: "minecraft:dirt"},
        {pos: [6, 0, 6], state: "minecraft:dirt"},
        {pos: [6, 0, 7], state: "minecraft:dirt"},
        {pos: [6, 0, 8], state: "minecraft:grass_block{snowy:false}"},
        {pos: [6, 0, 9], state: "minecraft:grass_block{snowy:false}"},
        {pos: [7, 0, 0], state: "minecraft:grass_block{snowy:false}"},
        {pos: [7, 0, 1], state: "minecraft:grass_block{snowy:false}"},
        {pos: [7, 0, 2], state: "minecraft:grass_block{snowy:false}"},
        {pos: [7, 0, 3], state: "minecraft:dirt"},
        {pos: [7, 0, 4], state: "minecraft:dirt"},
        {pos: [7, 0, 5], state: "minecraft:dirt"},
        {pos: [7, 0, 6], state: "minecraft:dirt"},
        {pos: [7, 0, 7], state: "minecraft:dirt"},
        {pos: [7, 0, 8], state: "minecraft:grass_block{snowy:false}"},
        {pos: [7, 0, 9], state: "minecraft:grass_block{snowy:false}"},
        {pos: [8, 0, 0], state: "minecraft:grass_block{snowy:false}"},
        {pos: [8, 0, 1], state: "minecraft:grass_block{snowy:false}"},
        {pos: [8, 0, 2], state: "minecraft:dirt"},
        {pos: [8, 0, 3], state: "minecraft:dirt"},
        {pos: [8, 0, 4], state: "minecraft:dirt"},
        {pos: [8, 0, 5], state: "minecraft:dirt"},
        {pos: [8, 0, 6], state: "minecraft:dirt"},
        {pos: [8, 0, 7], state: "minecraft:grass_block{snowy:false}"},
        {pos: [8, 0, 8], state: "minecraft:dirt"},
        {pos: [8, 0, 9], state: "minecraft:grass_block{snowy:false}"},
        {pos: [9, 0, 0], state: "minecraft:grass_block{snowy:false}"},
        {pos: [9, 0, 1], state: "minecraft:grass_block{snowy:false}"},
        {pos: [9, 0, 2], state: "minecraft:dirt"},
        {pos: [9, 0, 3], state: "minecraft:dirt"},
        {pos: [9, 0, 4], state: "minecraft:dirt"},
        {pos: [9, 0, 5], state: "minecraft:dirt"},
        {pos: [9, 0, 6], state: "minecraft:dirt"},
        {pos: [9, 0, 7], state: "minecraft:dirt"},
        {pos: [9, 0, 8], state: "minecraft:grass_block{snowy:false}"},
        {pos: [9, 0, 9], state: "minecraft:grass_block{snowy:false}"},
        {pos: [10, 0, 0], state: "minecraft:grass_block{snowy:false}"},
        {pos: [10, 0, 1], state: "minecraft:grass_block{snowy:false}"},
        {pos: [10, 0, 2], state: "minecraft:grass_block{snowy:false}"},
        {pos: [10, 0, 3], state: "minecraft:dirt"},
        {pos: [10, 0, 4], state: "minecraft:dirt"},
        {pos: [10, 0, 5], state: "minecraft:dirt"},
        {pos: [10, 0, 6], state: "minecraft:grass_block{snowy:false}"},
        {pos: [10, 0, 7], state: "minecraft:grass_block{snowy:false}"},
        {pos: [10, 0, 8], state: "minecraft:grass_block{snowy:false}"},
        {pos: [10, 0, 9], state: "minecraft:grass_block{snowy:false}"},
        {pos: [1, 1, 3], state: "minecraft:grass_block{snowy:false}"},
        {pos: [1, 1, 4], state: "minecraft:clay"},
        {pos: [1, 1, 5], state: "minecraft:clay"},
        {pos: [1, 1, 6], state: "minecraft:clay"},
        {pos: [1, 1, 7], state: "minecraft:clay"},
        {pos: [1, 1, 8], state: "minecraft:clay"},
        {pos: [1, 1, 9], state: "minecraft:clay"},
        {pos: [2, 1, 1], state: "minecraft:grass_block{snowy:false}"},
        {pos: [2, 1, 2], state: "minecraft:grass_block{snowy:false}"},
        {pos: [2, 1, 4], state: "minecraft:clay"},
        {pos: [2, 1, 5], state: "minecraft:seagrass"},
        {pos: [2, 1, 6], state: "minecraft:water{level:0}"},
        {pos: [2, 1, 7], state: "minecraft:seagrass"},
        {pos: [2, 1, 8], state: "minecraft:water{level:0}"},
        {pos: [2, 1, 9], state: "minecraft:clay"},
        {pos: [3, 1, 3], state: "minecraft:grass_block{snowy:false}"},
        {pos: [3, 1, 4], state: "minecraft:clay"},
        {pos: [3, 1, 5], state: "minecraft:water{level:0}"},
        {pos: [3, 1, 6], state: "minecraft:seagrass"},
        {pos: [3, 1, 7], state: "minecraft:water{level:0}"},
        {pos: [3, 1, 8], state: "minecraft:seagrass"},
        {pos: [3, 1, 9], state: "minecraft:clay"},
        {pos: [4, 1, 2], state: "minecraft:dirt"},
        {pos: [4, 1, 3], state: "minecraft:grass_block{snowy:false}"},
        {pos: [4, 1, 4], state: "minecraft:clay"},
        {pos: [4, 1, 5], state: "minecraft:water{level:0}"},
        {pos: [4, 1, 6], state: "minecraft:seagrass"},
        {pos: [4, 1, 7], state: "minecraft:seagrass"},
        {pos: [4, 1, 8], state: "minecraft:water{level:0}"},
        {pos: [4, 1, 9], state: "minecraft:clay"},
        {pos: [5, 1, 4], state: "minecraft:grass_block{snowy:false}"},
        {pos: [5, 1, 5], state: "minecraft:clay"},
        {pos: [5, 1, 6], state: "minecraft:seagrass"},
        {pos: [5, 1, 7], state: "minecraft:water{level:0}"},
        {pos: [5, 1, 8], state: "minecraft:clay"},
        {pos: [6, 1, 4], state: "minecraft:dirt_path"},
        {pos: [6, 1, 5], state: "minecraft:dirt_path"},
        {pos: [6, 1, 6], state: "minecraft:clay"},
        {pos: [6, 1, 7], state: "minecraft:clay"},
        {pos: [7, 1, 3], state: "minecraft:dirt_path"},
        {pos: [7, 1, 4], state: "minecraft:grass_block{snowy:false}"},
        {pos: [7, 1, 5], state: "minecraft:dirt_path"},
        {pos: [7, 1, 6], state: "minecraft:dirt_path"},
        {pos: [7, 1, 7], state: "minecraft:clay"},
        {pos: [8, 1, 2], state: "minecraft:dirt_path"},
        {pos: [8, 1, 3], state: "minecraft:grass_block{snowy:false}"},
        {pos: [8, 1, 4], state: "minecraft:dirt_path"},
        {pos: [8, 1, 5], state: "minecraft:dirt_path"},
        {pos: [8, 1, 6], state: "minecraft:dirt"},
        {pos: [8, 1, 7], state: "minecraft:oxidized_copper_chest{facing:east,type:single,waterlogged:false}", nbt: {LootTable: "minecraft:chests/abandoned_camp_secret_chest", components: {}, id: "minecraft:chest"}},
        {pos: [9, 1, 2], state: "minecraft:dirt_path"},
        {pos: [9, 1, 3], state: "minecraft:grass_block{snowy:false}"},
        {pos: [9, 1, 4], state: "minecraft:dirt_path"},
        {pos: [9, 1, 5], state: "minecraft:dirt_path"},
        {pos: [9, 1, 6], state: "minecraft:dirt_path"},
        {pos: [9, 1, 7], state: "minecraft:dirt_path"},
        {pos: [10, 1, 3], state: "minecraft:dirt_path"},
        {pos: [10, 1, 4], state: "minecraft:jigsaw{orientation:east_up}", nbt: {components: {}, final_state: "minecraft:dirt_path", id: "minecraft:jigsaw", joint: "rollable", name: "minecraft:end_connector", placement_priority: 0, pool: "minecraft:empty", selection_priority: 0, target: "minecraft:connector"}},
        {pos: [10, 1, 5], state: "minecraft:dirt_path"},
        {pos: [1, 2, 3], state: "minecraft:short_grass"},
        {pos: [2, 2, 1], state: "minecraft:short_grass"},
        {pos: [2, 2, 2], state: "minecraft:short_grass"},
        {pos: [2, 2, 6], state: "minecraft:lily_pad"},
        {pos: [3, 2, 3], state: "minecraft:short_grass"},
        {pos: [3, 2, 5], state: "minecraft:lily_pad"},
        {pos: [3, 2, 7], state: "minecraft:lily_pad"},
        {pos: [4, 2, 2], state: "minecraft:mushroom_stem{down:true,east:true,north:true,south:true,up:false,west:true}"},
        {pos: [5, 2, 2], state: "minecraft:cobweb"},
        {pos: [5, 2, 4], state: "minecraft:short_grass"},
        {pos: [5, 2, 6], state: "minecraft:lily_pad"},
        {pos: [7, 2, 4], state: "minecraft:campfire{facing:west,lit:false,signal_fire:false,waterlogged:false}", nbt: {CookingTimes: [I; 0, 0, 0, 0], CookingTotalTimes: [I; 0, 0, 0, 0], Items: [], components: {}, id: "minecraft:campfire"}},
        {pos: [7, 2, 7], state: "minecraft:cobweb"},
        {pos: [8, 2, 6], state: "minecraft:barrel{facing:up,open:false}", nbt: {LootTable: "minecraft:barrels/abandoned_camp_barrel", components: {}, id: "minecraft:barrel"}},
        {pos: [8, 2, 7], state: "minecraft:mushroom_stem{down:true,east:true,north:true,south:true,up:false,west:true}"},
        {pos: [9, 2, 3], state: "minecraft:cobweb"},
        {pos: [4, 3, 1], state: "minecraft:cobweb"},
        {pos: [4, 3, 2], state: "minecraft:mushroom_stem{down:false,east:true,north:true,south:true,up:false,west:true}"},
        {pos: [5, 3, 2], state: "minecraft:cobweb"},
        {pos: [7, 3, 7], state: "minecraft:cobweb"},
        {pos: [8, 3, 7], state: "minecraft:mushroom_stem{down:false,east:true,north:true,south:true,up:false,west:true}"},
        {pos: [4, 4, 2], state: "minecraft:mushroom_stem{down:false,east:true,north:true,south:true,up:false,west:true}"},
        {pos: [5, 4, 2], state: "minecraft:cobweb"},
        {pos: [7, 4, 7], state: "minecraft:cobweb"},
        {pos: [8, 4, 6], state: "minecraft:cobweb"},
        {pos: [8, 4, 7], state: "minecraft:mushroom_stem{down:false,east:true,north:true,south:true,up:false,west:true}"},
        {pos: [2, 5, 1], state: "minecraft:red_mushroom_block{down:false,east:false,north:true,south:false,up:false,west:true}"},
        {pos: [2, 5, 2], state: "minecraft:red_mushroom_block{down:false,east:false,north:false,south:false,up:false,west:true}"},
        {pos: [2, 5, 3], state: "minecraft:red_mushroom_block{down:false,east:false,north:false,south:true,up:false,west:true}"},
        {pos: [3, 5, 0], state: "minecraft:red_mushroom_block{down:false,east:false,north:true,south:false,up:false,west:true}"},
        {pos: [3, 5, 4], state: "minecraft:red_mushroom_block{down:false,east:false,north:false,south:true,up:false,west:true}"},
        {pos: [4, 5, 0], state: "minecraft:red_mushroom_block{down:false,east:false,north:true,south:false,up:false,west:false}"},
        {pos: [4, 5, 2], state: "minecraft:mushroom_stem{down:false,east:true,north:true,south:true,up:false,west:true}"},
        {pos: [4, 5, 4], state: "minecraft:red_mushroom_block{down:false,east:false,north:false,south:true,up:false,west:false}"},
        {pos: [5, 5, 0], state: "minecraft:red_mushroom_block{down:false,east:true,north:true,south:false,up:false,west:false}"},
        {pos: [5, 5, 4], state: "minecraft:red_mushroom_block{down:false,east:true,north:false,south:true,up:false,west:false}"},
        {pos: [6, 5, 1], state: "minecraft:red_mushroom_block{down:false,east:true,north:true,south:false,up:false,west:false}"},
        {pos: [6, 5, 2], state: "minecraft:red_mushroom_block{down:false,east:true,north:false,south:false,up:false,west:false}"},
        {pos: [6, 5, 3], state: "minecraft:red_mushroom_block{down:false,east:true,north:false,south:true,up:false,west:false}"},
        {pos: [8, 5, 6], state: "minecraft:cobweb"},
        {pos: [8, 5, 7], state: "minecraft:mushroom_stem{down:false,east:true,north:true,south:true,up:true,west:true}"},
        {pos: [2, 6, 1], state: "minecraft:red_mushroom_block{down:false,east:false,north:true,south:false,up:false,west:true}"},
        {pos: [2, 6, 2], state: "minecraft:red_mushroom_block{down:false,east:false,north:false,south:false,up:false,west:true}"},
        {pos: [2, 6, 3], state: "minecraft:red_mushroom_block{down:false,east:false,north:false,south:true,up:false,west:true}"},
        {pos: [3, 6, 0], state: "minecraft:red_mushroom_block{down:false,east:false,north:true,south:false,up:false,west:true}"},
        {pos: [3, 6, 4], state: "minecraft:red_mushroom_block{down:false,east:false,north:false,south:true,up:false,west:true}"},
        {pos: [4, 6, 0], state: "minecraft:red_mushroom_block{down:false,east:false,north:true,south:false,up:false,west:false}"},
        {pos: [4, 6, 2], state: "minecraft:mushroom_stem{down:false,east:true,north:true,south:true,up:false,west:true}"},
        {pos: [4, 6, 4], state: "minecraft:red_mushroom_block{down:false,east:false,north:false,south:true,up:false,west:false}"},
        {pos: [5, 6, 0], state: "minecraft:red_mushroom_block{down:false,east:true,north:true,south:false,up:false,west:false}"},
        {pos: [5, 6, 4], state: "minecraft:red_mushroom_block{down:false,east:true,north:false,south:true,up:false,west:false}"},
        {pos: [6, 6, 1], state: "minecraft:red_mushroom_block{down:false,east:true,north:true,south:false,up:false,west:false}"},
        {pos: [6, 6, 2], state: "minecraft:red_mushroom_block{down:false,east:true,north:false,south:false,up:false,west:false}"},
        {pos: [6, 6, 3], state: "minecraft:red_mushroom_block{down:false,east:true,north:false,south:true,up:false,west:false}"},
        {pos: [6, 6, 6], state: "minecraft:brown_mushroom_block{down:true,east:false,north:true,south:false,up:true,west:true}"},
        {pos: [6, 6, 7], state: "minecraft:brown_mushroom_block{down:true,east:false,north:false,south:false,up:true,west:true}"},
        {pos: [6, 6, 8], state: "minecraft:brown_mushroom_block{down:true,east:false,north:false,south:true,up:true,west:true}"},
        {pos: [7, 6, 5], state: "minecraft:brown_mushroom_block{down:true,east:false,north:true,south:false,up:true,west:true}"},
        {pos: [7, 6, 6], state: "minecraft:brown_mushroom_block{down:true,east:false,north:false,south:false,up:true,west:false}"},
        {pos: [7, 6, 7], state: "minecraft:brown_mushroom_block{down:true,east:false,north:false,south:false,up:true,west:false}"},
        {pos: [7, 6, 8], state: "minecraft:brown_mushroom_block{down:true,east:false,north:false,south:false,up:true,west:false}"},
        {pos: [7, 6, 9], state: "minecraft:brown_mushroom_block{down:true,east:false,north:false,south:true,up:true,west:true}"},
        {pos: [8, 6, 5], state: "minecraft:brown_mushroom_block{down:true,east:false,north:true,south:false,up:true,west:false}"},
        {pos: [8, 6, 6], state: "minecraft:brown_mushroom_block{down:true,east:false,north:false,south:false,up:true,west:false}"},
        {pos: [8, 6, 7], state: "minecraft:brown_mushroom_block{down:true,east:false,north:false,south:false,up:true,west:false}"},
        {pos: [8, 6, 8], state: "minecraft:brown_mushroom_block{down:true,east:false,north:false,south:false,up:true,west:false}"},
        {pos: [8, 6, 9], state: "minecraft:brown_mushroom_block{down:true,east:false,north:false,south:true,up:true,west:false}"},
        {pos: [9, 6, 5], state: "minecraft:brown_mushroom_block{down:true,east:true,north:true,south:false,up:true,west:false}"},
        {pos: [9, 6, 6], state: "minecraft:brown_mushroom_block{down:true,east:false,north:false,south:false,up:true,west:false}"},
        {pos: [9, 6, 7], state: "minecraft:brown_mushroom_block{down:true,east:false,north:false,south:false,up:true,west:false}"},
        {pos: [9, 6, 8], state: "minecraft:brown_mushroom_block{down:true,east:false,north:false,south:false,up:true,west:false}"},
        {pos: [9, 6, 9], state: "minecraft:brown_mushroom_block{down:true,east:true,north:false,south:true,up:true,west:false}"},
        {pos: [10, 6, 6], state: "minecraft:brown_mushroom_block{down:true,east:true,north:true,south:false,up:true,west:false}"},
        {pos: [10, 6, 7], state: "minecraft:brown_mushroom_block{down:true,east:true,north:false,south:false,up:true,west:false}"},
        {pos: [10, 6, 8], state: "minecraft:brown_mushroom_block{down:true,east:true,north:false,south:true,up:true,west:false}"},
        {pos: [2, 7, 1], state: "minecraft:red_mushroom_block{down:false,east:false,north:true,south:false,up:true,west:true}"},
        {pos: [2, 7, 2], state: "minecraft:red_mushroom_block{down:false,east:false,north:false,south:false,up:true,west:true}"},
        {pos: [2, 7, 3], state: "minecraft:red_mushroom_block{down:false,east:false,north:false,south:true,up:true,west:true}"},
        {pos: [3, 7, 0], state: "minecraft:red_mushroom_block{down:false,east:false,north:true,south:false,up:true,west:true}"},
        {pos: [3, 7, 4], state: "minecraft:red_mushroom_block{down:false,east:false,north:false,south:true,up:true,west:true}"},
        {pos: [4, 7, 0], state: "minecraft:red_mushroom_block{down:false,east:false,north:true,south:false,up:true,west:false}"},
        {pos: [4, 7, 2], state: "minecraft:mushroom_stem{down:false,east:true,north:true,south:true,up:true,west:true}"},
        {pos: [4, 7, 4], state: "minecraft:red_mushroom_block{down:false,east:false,north:false,south:true,up:true,west:false}"},
        {pos: [5, 7, 0], state: "minecraft:red_mushroom_block{down:false,east:true,north:true,south:false,up:true,west:false}"},
        {pos: [5, 7, 4], state: "minecraft:red_mushroom_block{down:false,east:true,north:false,south:true,up:true,west:false}"},
        {pos: [6, 7, 1], state: "minecraft:red_mushroom_block{down:false,east:true,north:true,south:false,up:true,west:false}"},
        {pos: [6, 7, 2], state: "minecraft:red_mushroom_block{down:false,east:true,north:false,south:false,up:true,west:false}"},
        {pos: [6, 7, 3], state: "minecraft:red_mushroom_block{down:false,east:true,north:false,south:true,up:true,west:false}"},
        {pos: [3, 8, 1], state: "minecraft:red_mushroom_block{down:false,east:false,north:true,south:false,up:true,west:true}"},
        {pos: [3, 8, 2], state: "minecraft:red_mushroom_block{down:false,east:false,north:false,south:false,up:true,west:true}"},
        {pos: [3, 8, 3], state: "minecraft:red_mushroom_block{down:false,east:false,north:false,south:true,up:true,west:true}"},
        {pos: [4, 8, 1], state: "minecraft:red_mushroom_block{down:false,east:false,north:true,south:false,up:true,west:false}"},
        {pos: [4, 8, 2], state: "minecraft:red_mushroom_block{down:true,east:false,north:false,south:false,up:true,west:false}"},
        {pos: [4, 8, 3], state: "minecraft:red_mushroom_block{down:false,east:false,north:false,south:true,up:true,west:false}"},
        {pos: [5, 8, 1], state: "minecraft:red_mushroom_block{down:false,east:true,north:true,south:false,up:true,west:false}"},
        {pos: [5, 8, 2], state: "minecraft:red_mushroom_block{down:false,east:true,north:false,south:false,up:true,west:false}"},
        {pos: [5, 8, 3], state: "minecraft:red_mushroom_block{down:false,east:true,north:false,south:true,up:true,west:false}"}
    ],
    entities: [
        {blockPos: [8, 1, 5], pos: [8.5d, 1.9375d, 5.5d], nbt: {Air: 300s, Fire: 0s, Invulnerable: 0b, Motion: [0.0d, 0.0d, 0.0d], OnGround: 0b, PortalCooldown: 0, Pos: [-85.5d, -60.0625d, 467.5d], Rotation: [90.0f, 0.0f], UUID: [I; 250658999, 1395018639, -1810121144, 43777593], block_pos: [I; -86, -61, 467], color: "green", fall_distance: 0.0d, id: "minecraft:cushion"}}
    ],
    palette: [
        "minecraft:grass_block{snowy:false}",
        "minecraft:dirt",
        "minecraft:clay",
        "minecraft:mushroom_stem{down:true,east:true,north:true,south:true,up:false,west:true}",
        "minecraft:mushroom_stem{down:false,east:true,north:true,south:true,up:false,west:true}",
        "minecraft:red_mushroom_block{down:false,east:false,north:true,south:false,up:false,west:true}",
        "minecraft:red_mushroom_block{down:false,east:false,north:false,south:false,up:false,west:true}",
        "minecraft:red_mushroom_block{down:false,east:false,north:false,south:true,up:false,west:true}",
        "minecraft:red_mushroom_block{down:false,east:false,north:true,south:false,up:false,west:false}",
        "minecraft:red_mushroom_block{down:false,east:false,north:false,south:true,up:false,west:false}",
        "minecraft:red_mushroom_block{down:false,east:true,north:true,south:false,up:false,west:false}",
        "minecraft:red_mushroom_block{down:false,east:true,north:false,south:true,up:false,west:false}",
        "minecraft:red_mushroom_block{down:false,east:true,north:false,south:false,up:false,west:false}",
        "minecraft:mushroom_stem{down:false,east:true,north:true,south:true,up:true,west:true}",
        "minecraft:brown_mushroom_block{down:true,east:false,north:true,south:false,up:true,west:true}",
        "minecraft:brown_mushroom_block{down:true,east:false,north:false,south:false,up:true,west:true}",
        "minecraft:brown_mushroom_block{down:true,east:false,north:false,south:true,up:true,west:true}",
        "minecraft:brown_mushroom_block{down:true,east:false,north:false,south:false,up:true,west:false}",
        "minecraft:brown_mushroom_block{down:true,east:false,north:true,south:false,up:true,west:false}",
        "minecraft:brown_mushroom_block{down:true,east:false,north:false,south:true,up:true,west:false}",
        "minecraft:brown_mushroom_block{down:true,east:true,north:true,south:false,up:true,west:false}",
        "minecraft:brown_mushroom_block{down:true,east:true,north:false,south:true,up:true,west:false}",
        "minecraft:brown_mushroom_block{down:true,east:true,north:false,south:false,up:true,west:false}",
        "minecraft:red_mushroom_block{down:false,east:false,north:true,south:false,up:true,west:true}",
        "minecraft:red_mushroom_block{down:false,east:false,north:false,south:false,up:true,west:true}",
        "minecraft:red_mushroom_block{down:false,east:false,north:false,south:true,up:true,west:true}",
        "minecraft:red_mushroom_block{down:false,east:false,north:true,south:false,up:true,west:false}",
        "minecraft:red_mushroom_block{down:false,east:false,north:false,south:true,up:true,west:false}",
        "minecraft:red_mushroom_block{down:false,east:true,north:true,south:false,up:true,west:false}",
        "minecraft:red_mushroom_block{down:false,east:true,north:false,south:true,up:true,west:false}",
        "minecraft:red_mushroom_block{down:false,east:true,north:false,south:false,up:true,west:false}",
        "minecraft:red_mushroom_block{down:true,east:false,north:false,south:false,up:true,west:false}",
        "minecraft:seagrass",
        "minecraft:water{level:0}",
        "minecraft:dirt_path",
        "minecraft:short_grass",
        "minecraft:lily_pad",
        "minecraft:cobweb",
        "minecraft:oxidized_copper_chest{facing:east,type:single,waterlogged:false}",
        "minecraft:jigsaw{orientation:east_up}",
        "minecraft:campfire{facing:west,lit:false,signal_fire:false,waterlogged:false}",
        "minecraft:barrel{facing:up,open:false}"
    ]
}
