{
    size: [11, 10, 11],
    data: [
        {pos: [0, 0, 0], state: "minecraft:grass_block{snowy:false}"},
        {pos: [0, 0, 1], state: "minecraft:grass_block{snowy:false}"},
        {pos: [0, 0, 2], state: "minecraft:grass_block{snowy:false}"},
        {pos: [0, 0, 3], state: "minecraft:grass_block{snowy:false}"},
        {pos: [0, 0, 4], state: "minecraft:grass_block{snowy:false}"},
        {pos: [0, 0, 5], state: "minecraft:grass_block{snowy:false}"},
        {pos: [0, 0, 6], state: "minecraft:grass_block{snowy:false}"},
        {pos: [0, 0, 7], state: "minecraft:grass_block{snowy:false}"},
        {pos: [0, 0, 8], state: "minecraft:grass_block{snowy:false}"},
        {pos: [0, 0, 9], state: "minecraft:grass_block{snowy:false}"},
        {pos: [0, 0, 10], state: "minecraft:grass_block{snowy:false}"},
        {pos: [1, 0, 0], state: "minecraft:grass_block{snowy:false}"},
        {pos: [1, 0, 1], state: "minecraft:grass_block{snowy:false}"},
        {pos: [1, 0, 2], state: "minecraft:grass_block{snowy:false}"},
        {pos: [1, 0, 3], state: "minecraft:dirt"},
        {pos: [1, 0, 4], state: "minecraft:grass_block{snowy:false}"},
        {pos: [1, 0, 5], state: "minecraft:grass_block{snowy:false}"},
        {pos: [1, 0, 6], state: "minecraft:dirt"},
        {pos: [1, 0, 7], state: "minecraft:dirt"},
        {pos: [1, 0, 8], state: "minecraft:dirt"},
        {pos: [1, 0, 9], state: "minecraft:dirt"},
        {pos: [1, 0, 10], state: "minecraft:dirt"},
        {pos: [2, 0, 0], state: "minecraft:grass_block{snowy:false}"},
        {pos: [2, 0, 1], state: "minecraft:dirt"},
        {pos: [2, 0, 2], state: "minecraft:dirt"},
        {pos: [2, 0, 3], state: "minecraft:dirt"},
        {pos: [2, 0, 4], state: "minecraft:grass_block{snowy:false}"},
        {pos: [2, 0, 5], state: "minecraft:dirt"},
        {pos: [2, 0, 6], state: "minecraft:clay"},
        {pos: [2, 0, 7], state: "minecraft:clay"},
        {pos: [2, 0, 8], state: "minecraft:clay"},
        {pos: [2, 0, 9], state: "minecraft:clay"},
        {pos: [2, 0, 10], state: "minecraft:dirt"},
        {pos: [3, 0, 0], state: "minecraft:grass_block{snowy:false}"},
        {pos: [3, 0, 1], state: "minecraft:grass_block{snowy:false}"},
        {pos: [3, 0, 2], state: "minecraft:dirt"},
        {pos: [3, 0, 3], state: "minecraft:dirt"},
        {pos: [3, 0, 4], state: "minecraft:dirt"},
        {pos: [3, 0, 5], state: "minecraft:dirt"},
        {pos: [3, 0, 6], state: "minecraft:clay"},
        {pos: [3, 0, 7], state: "minecraft:clay"},
        {pos: [3, 0, 8], state: "minecraft:clay"},
        {pos: [3, 0, 9], state: "minecraft:clay"},
        {pos: [3, 0, 10], state: "minecraft:grass_block{snowy:false}"},
        {pos: [4, 0, 0], state: "minecraft:grass_block{snowy:false}"},
        {pos: [4, 0, 1], state: "minecraft:grass_block{snowy:false}"},
        {pos: [4, 0, 2], state: "minecraft:grass_block{snowy:false}"},
        {pos: [4, 0, 3], state: "minecraft:dirt"},
        {pos: [4, 0, 4], state: "minecraft:dirt"},
        {pos: [4, 0, 5], state: "minecraft:dirt"},
        {pos: [4, 0, 6], state: "minecraft:dirt"},
        {pos: [4, 0, 7], state: "minecraft:clay"},
        {pos: [4, 0, 8], state: "minecraft:clay"},
        {pos: [4, 0, 9], state: "minecraft:clay"},
        {pos: [4, 0, 10], state: "minecraft:dirt"},
        {pos: [5, 0, 0], state: "minecraft:grass_block{snowy:false}"},
        {pos: [5, 0, 1], state: "minecraft:grass_block{snowy:false}"},
        {pos: [5, 0, 2], state: "minecraft:grass_block{snowy:false}"},
        {pos: [5, 0, 3], state: "minecraft:dirt"},
        {pos: [5, 0, 4], state: "minecraft:dirt"},
        {pos: [5, 0, 5], state: "minecraft:grass_block{snowy:false}"},
        {pos: [5, 0, 6], state: "minecraft:dirt"},
        {pos: [5, 0, 7], state: "minecraft:dirt"},
        {pos: [5, 0, 8], state: "minecraft:dirt"},
        {pos: [5, 0, 9], state: "minecraft:dirt"},
        {pos: [5, 0, 10], state: "minecraft:grass_block{snowy:false}"},
        {pos: [6, 0, 0], state: "minecraft:grass_block{snowy:false}"},
        {pos: [6, 0, 1], state: "minecraft:grass_block{snowy:false}"},
        {pos: [6, 0, 2], state: "minecraft:grass_block{snowy:false}"},
        {pos: [6, 0, 3], state: "minecraft:grass_block{snowy:false}"},
        {pos: [6, 0, 4], state: "minecraft:grass_block{snowy:false}"},
        {pos: [6, 0, 5], state: "minecraft:dirt"},
        {pos: [6, 0, 6], state: "minecraft:grass_block{snowy:false}"},
        {pos: [6, 0, 7], state: "minecraft:grass_block{snowy:false}"},
        {pos: [6, 0, 8], state: "minecraft:dirt"},
        {pos: [6, 0, 9], state: "minecraft:grass_block{snowy:false}"},
        {pos: [6, 0, 10], state: "minecraft:grass_block{snowy:false}"},
        {pos: [7, 0, 0], state: "minecraft:grass_block{snowy:false}"},
        {pos: [7, 0, 1], state: "minecraft:grass_block{snowy:false}"},
        {pos: [7, 0, 2], state: "minecraft:grass_block{snowy:false}"},
        {pos: [7, 0, 3], state: "minecraft:grass_block{snowy:false}"},
        {pos: [7, 0, 4], state: "minecraft:dirt"},
        {pos: [7, 0, 5], state: "minecraft:dirt"},
        {pos: [7, 0, 6], state: "minecraft:dirt"},
        {pos: [7, 0, 7], state: "minecraft:grass_block{snowy:false}"},
        {pos: [7, 0, 8], state: "minecraft:dirt"},
        {pos: [7, 0, 9], state: "minecraft:dirt"},
        {pos: [7, 0, 10], state: "minecraft:grass_block{snowy:false}"},
        {pos: [8, 0, 0], state: "minecraft:grass_block{snowy:false}"},
        {pos: [8, 0, 1], state: "minecraft:grass_block{snowy:false}"},
        {pos: [8, 0, 2], state: "minecraft:grass_block{snowy:false}"},
        {pos: [8, 0, 3], state: "minecraft:grass_block{snowy:false}"},
        {pos: [8, 0, 4], state: "minecraft:grass_block{snowy:false}"},
        {pos: [8, 0, 5], state: "minecraft:dirt"},
        {pos: [8, 0, 6], state: "minecraft:dirt"},
        {pos: [8, 0, 7], state: "minecraft:dirt"},
        {pos: [8, 0, 8], state: "minecraft:dirt"},
        {pos: [8, 0, 9], state: "minecraft:dirt"},
        {pos: [8, 0, 10], state: "minecraft:grass_block{snowy:false}"},
        {pos: [9, 0, 0], state: "minecraft:grass_block{snowy:false}"},
        {pos: [9, 0, 1], state: "minecraft:grass_block{snowy:false}"},
        {pos: [9, 0, 2], state: "minecraft:grass_block{snowy:false}"},
        {pos: [9, 0, 3], state: "minecraft:dirt"},
        {pos: [9, 0, 4], state: "minecraft:dirt"},
        {pos: [9, 0, 5], state: "minecraft:dirt"},
        {pos: [9, 0, 6], state: "minecraft:dirt"},
        {pos: [9, 0, 7], state: "minecraft:dirt"},
        {pos: [9, 0, 8], state: "minecraft:dirt"},
        {pos: [9, 0, 9], state: "minecraft:grass_block{snowy:false}"},
        {pos: [9, 0, 10], state: "minecraft:grass_block{snowy:false}"},
        {pos: [10, 0, 0], state: "minecraft:grass_block{snowy:false}"},
        {pos: [10, 0, 1], state: "minecraft:grass_block{snowy:false}"},
        {pos: [10, 0, 2], state: "minecraft:grass_block{snowy:false}"},
        {pos: [10, 0, 3], state: "minecraft:dirt"},
        {pos: [10, 0, 4], state: "minecraft:dirt"},
        {pos: [10, 0, 5], state: "minecraft:dirt"},
        {pos: [10, 0, 6], state: "minecraft:dirt"},
        {pos: [10, 0, 7], state: "minecraft:dirt"},
        {pos: [10, 0, 8], state: "minecraft:dirt"},
        {pos: [10, 0, 9], state: "minecraft:grass_block{snowy:false}"},
        {pos: [10, 0, 10], state: "minecraft:grass_block{snowy:false}"},
        {pos: [1, 1, 3], state: "minecraft:dirt"},
        {pos: [1, 1, 6], state: "minecraft:clay"},
        {pos: [1, 1, 7], state: "minecraft:clay"},
        {pos: [1, 1, 8], state: "minecraft:grass_block{snowy:false}"},
        {pos: [1, 1, 9], state: "minecraft:clay"},
        {pos: [1, 1, 10], state: "minecraft:clay"},
        {pos: [2, 1, 1], state: "minecraft:dirt"},
        {pos: [2, 1, 2], state: "minecraft:dirt"},
        {pos: [2, 1, 3], state: "minecraft:dirt"},
        {pos: [2, 1, 5], state: "minecraft:clay"},
        {pos: [2, 1, 6], state: "minecraft:seagrass"},
        {pos: [2, 1, 7], state: "minecraft:seagrass"},
        {pos: [2, 1, 8], state: "minecraft:water{level:0}"},
        {pos: [2, 1, 9], state: "minecraft:water{level:0}"},
        {pos: [2, 1, 10], state: "minecraft:grass_block{snowy:false}"},
        {pos: [3, 1, 2], state: "minecraft:dirt"},
        {pos: [3, 1, 3], state: "minecraft:dirt"},
        {pos: [3, 1, 4], state: "minecraft:dirt"},
        {pos: [3, 1, 5], state: "minecraft:clay"},
        {pos: [3, 1, 6], state: "minecraft:seagrass"},
        {pos: [3, 1, 7], state: "minecraft:water{level:0}"},
        {pos: [3, 1, 8], state: "minecraft:seagrass"},
        {pos: [3, 1, 9], state: "minecraft:clay"},
        {pos: [4, 1, 3], state: "minecraft:dirt"},
        {pos: [4, 1, 4], state: "minecraft:dirt"},
        {pos: [4, 1, 5], state: "minecraft:grass_block{snowy:false}"},
        {pos: [4, 1, 6], state: "minecraft:clay"},
        {pos: [4, 1, 7], state: "minecraft:seagrass"},
        {pos: [4, 1, 8], state: "minecraft:water{level:0}"},
        {pos: [4, 1, 9], state: "minecraft:water{level:0}"},
        {pos: [4, 1, 10], state: "minecraft:clay"},
        {pos: [5, 1, 3], state: "minecraft:dirt"},
        {pos: [5, 1, 4], state: "minecraft:grass_block{snowy:false}"},
        {pos: [5, 1, 6], state: "minecraft:clay"},
        {pos: [5, 1, 7], state: "minecraft:clay"},
        {pos: [5, 1, 8], state: "minecraft:grass_block{snowy:false}"},
        {pos: [5, 1, 9], state: "minecraft:clay"},
        {pos: [6, 1, 5], state: "minecraft:dirt_path"},
        {pos: [6, 1, 7], state: "minecraft:vine{east:false,north:true,south:false,up:false,west:false}"},
        {pos: [6, 1, 8], state: "minecraft:grass_block{snowy:false}"},
        {pos: [7, 1, 0], state: "minecraft:vine{east:false,north:false,south:false,up:false,west:true}"},
        {pos: [7, 1, 3], state: "minecraft:vine{east:false,north:false,south:false,up:false,west:true}"},
        {pos: [7, 1, 4], state: "minecraft:dirt_path"},
        {pos: [7, 1, 5], state: "minecraft:dirt_path"},
        {pos: [7, 1, 6], state: "minecraft:dirt_path"},
        {pos: [7, 1, 8], state: "minecraft:grass_block{snowy:false}"},
        {pos: [7, 1, 9], state: "minecraft:grass_block{snowy:false}"},
        {pos: [8, 1, 5], state: "minecraft:dirt_path"},
        {pos: [8, 1, 6], state: "minecraft:dirt_path"},
        {pos: [8, 1, 7], state: "minecraft:dirt_path"},
        {pos: [8, 1, 8], state: "minecraft:grass_block{snowy:false}"},
        {pos: [8, 1, 9], state: "minecraft:grass_block{snowy:false}"},
        {pos: [9, 1, 3], state: "minecraft:dirt_path"},
        {pos: [9, 1, 4], state: "minecraft:dirt_path"},
        {pos: [9, 1, 5], state: "minecraft:grass_block{snowy:false}"},
        {pos: [9, 1, 6], state: "minecraft:dirt_path"},
        {pos: [9, 1, 7], state: "minecraft:dirt_path"},
        {pos: [9, 1, 8], state: "minecraft:dirt_path"},
        {pos: [10, 1, 3], state: "minecraft:dirt_path"},
        {pos: [10, 1, 4], state: "minecraft:dirt_path"},
        {pos: [10, 1, 5], state: "minecraft:jigsaw{orientation:east_up}", nbt: {components: {}, final_state: "minecraft:dirt_path", id: "minecraft:jigsaw", joint: "rollable", name: "minecraft:end_connector", placement_priority: 0, pool: "minecraft:empty", selection_priority: 0, target: "minecraft:connector"}},
        {pos: [10, 1, 6], state: "minecraft:dirt_path"},
        {pos: [10, 1, 7], state: "minecraft:dirt_path"},
        {pos: [10, 1, 8], state: "minecraft:dirt_path"},
        {pos: [1, 2, 3], state: "minecraft:grass_block{snowy:false}"},
        {pos: [1, 2, 7], state: "minecraft:vine{east:false,north:true,south:false,up:false,west:false}"},
        {pos: [2, 2, 1], state: "minecraft:grass_block{snowy:false}"},
        {pos: [2, 2, 2], state: "minecraft:grass_block{snowy:false}"},
        {pos: [2, 2, 3], state: "minecraft:grass_block{snowy:false}"},
        {pos: [2, 2, 4], state: "minecraft:cobweb"},
        {pos: [2, 2, 9], state: "minecraft:lily_pad"},
        {pos: [2, 2, 10], state: "minecraft:firefly_bush"},
        {pos: [3, 2, 2], state: "minecraft:grass_block{snowy:false}"},
        {pos: [3, 2, 3], state: "minecraft:dirt"},
        {pos: [3, 2, 4], state: "minecraft:grass_block{snowy:false}"},
        {pos: [3, 2, 7], state: "minecraft:lily_pad"},
        {pos: [4, 2, 2], state: "minecraft:cobweb"},
        {pos: [4, 2, 3], state: "minecraft:grass_block{snowy:false}"},
        {pos: [4, 2, 4], state: "minecraft:grass_block{snowy:false}"},
        {pos: [4, 2, 5], state: "minecraft:firefly_bush"},
        {pos: [4, 2, 7], state: "minecraft:vine{east:false,north:true,south:false,up:false,west:false}"},
        {pos: [4, 2, 8], state: "minecraft:lily_pad"},
        {pos: [5, 2, 3], state: "minecraft:grass_block{snowy:false}"},
        {pos: [5, 2, 4], state: "minecraft:short_grass"},
        {pos: [5, 2, 8], state: "minecraft:firefly_bush"},
        {pos: [6, 2, 6], state: "minecraft:cobweb"},
        {pos: [6, 2, 7], state: "minecraft:vine{east:false,north:true,south:false,up:false,west:false}"},
        {pos: [6, 2, 8], state: "minecraft:short_grass"},
        {pos: [7, 2, 0], state: "minecraft:vine{east:false,north:false,south:false,up:false,west:true}"},
        {pos: [7, 2, 3], state: "minecraft:vine{east:false,north:false,south:false,up:false,west:true}"},
        {pos: [7, 2, 4], state: "minecraft:vine{east:false,north:false,south:false,up:false,west:true}"},
        {pos: [7, 2, 6], state: "minecraft:vine{east:false,north:false,south:false,up:false,west:true}"},
        {pos: [7, 2, 8], state: "minecraft:short_grass"},
        {pos: [7, 2, 9], state: "minecraft:short_grass"},
        {pos: [8, 2, 2], state: "minecraft:cobweb"},
        {pos: [8, 2, 8], state: "minecraft:chest{facing:east,type:single,waterlogged:false}", nbt: {Items: [], LootTable: "minecraft:chests/abandoned_camp_common_chest", components: {}, id: "minecraft:chest"}},
        {pos: [8, 2, 9], state: "minecraft:short_grass"},
        {pos: [9, 2, 5], state: "minecraft:campfire{facing:west,lit:false,signal_fire:false,waterlogged:false}", nbt: {CookingTimes: [I; 0, 0, 0, 0], CookingTotalTimes: [I; 0, 0, 0, 0], Items: [], components: {}, id: "minecraft:campfire"}},
        {pos: [1, 3, 3], state: "minecraft:short_grass"},
        {pos: [1, 3, 7], state: "minecraft:vine{east:false,north:true,south:false,up:false,west:false}"},
        {pos: [2, 3, 3], state: "minecraft:vine{east:true,north:false,south:false,up:false,west:false}"},
        {pos: [3, 3, 2], state: "minecraft:short_grass"},
        {pos: [3, 3, 3], state: "minecraft:oak_log{axis:y}"},
        {pos: [3, 3, 4], state: "minecraft:short_grass"},
        {pos: [3, 3, 7], state: "minecraft:vine{east:false,north:true,south:false,up:false,west:false}"},
        {pos: [4, 3, 3], state: "minecraft:vine{east:false,north:false,south:false,up:false,west:true}"},
        {pos: [4, 3, 4], state: "minecraft:red_mushroom"},
        {pos: [4, 3, 7], state: "minecraft:vine{east:false,north:true,south:false,up:false,west:false}"},
        {pos: [5, 3, 3], state: "minecraft:short_grass"},
        {pos: [6, 3, 7], state: "minecraft:vine{east:false,north:true,south:false,up:false,west:false}"},
        {pos: [7, 3, 0], state: "minecraft:vine{east:false,north:false,south:false,up:false,west:true}"},
        {pos: [7, 3, 3], state: "minecraft:vine{east:false,north:false,south:false,up:false,west:true}"},
        {pos: [7, 3, 4], state: "minecraft:vine{east:false,north:false,south:false,up:false,west:true}"},
        {pos: [7, 3, 6], state: "minecraft:vine{east:false,north:false,south:false,up:false,west:true}"},
        {pos: [1, 4, 7], state: "minecraft:vine{east:false,north:true,south:false,up:false,west:false}"},
        {pos: [2, 4, 3], state: "minecraft:vine{east:true,north:false,south:false,up:false,west:false}"},
        {pos: [3, 4, 2], state: "minecraft:vine{east:false,north:false,south:true,up:false,west:false}"},
        {pos: [3, 4, 3], state: "minecraft:oak_log{axis:y}"},
        {pos: [3, 4, 4], state: "minecraft:vine{east:false,north:true,south:false,up:false,west:false}"},
        {pos: [3, 4, 7], state: "minecraft:vine{east:false,north:true,south:false,up:false,west:false}"},
        {pos: [4, 4, 3], state: "minecraft:vine{east:false,north:false,south:false,up:false,west:true}"},
        {pos: [4, 4, 7], state: "minecraft:vine{east:false,north:true,south:false,up:false,west:false}"},
        {pos: [6, 4, 7], state: "minecraft:vine{east:false,north:true,south:false,up:false,west:false}"},
        {pos: [7, 4, 0], state: "minecraft:vine{east:false,north:false,south:false,up:false,west:true}"},
        {pos: [7, 4, 3], state: "minecraft:vine{east:false,north:false,south:false,up:false,west:true}"},
        {pos: [7, 4, 4], state: "minecraft:vine{east:false,north:false,south:false,up:false,west:true}"},
        {pos: [7, 4, 6], state: "minecraft:vine{east:false,north:false,south:false,up:false,west:true}"},
        {pos: [1, 5, 7], state: "minecraft:vine{east:false,north:true,south:false,up:false,west:false}"},
        {pos: [3, 5, 2], state: "minecraft:vine{east:false,north:false,south:true,up:true,west:false}"},
        {pos: [3, 5, 3], state: "minecraft:oak_log{axis:y}"},
        {pos: [3, 5, 4], state: "minecraft:vine{east:false,north:true,south:false,up:true,west:false}"},
        {pos: [3, 5, 7], state: "minecraft:vine{east:false,north:true,south:false,up:false,west:false}"},
        {pos: [4, 5, 3], state: "minecraft:cobweb"},
        {pos: [4, 5, 7], state: "minecraft:vine{east:false,north:true,south:false,up:false,west:false}"},
        {pos: [6, 5, 3], state: "minecraft:vine{east:false,north:false,south:false,up:true,west:false}"},
        {pos: [6, 5, 7], state: "minecraft:vine{east:false,north:true,south:false,up:false,west:false}"},
        {pos: [7, 5, 0], state: "minecraft:vine{east:false,north:false,south:false,up:false,west:true}"},
        {pos: [7, 5, 3], state: "minecraft:vine{east:false,north:false,south:false,up:false,west:true}"},
        {pos: [7, 5, 4], state: "minecraft:vine{east:false,north:false,south:false,up:false,west:true}"},
        {pos: [7, 5, 6], state: "minecraft:vine{east:false,north:false,south:false,up:false,west:true}"},
        {pos: [0, 6, 0], state: "minecraft:oak_leaves{distance:6,persistent:true,waterlogged:false}"},
        {pos: [0, 6, 1], state: "minecraft:oak_leaves{distance:5,persistent:true,waterlogged:false}"},
        {pos: [0, 6, 2], state: "minecraft:oak_leaves{distance:4,persistent:true,waterlogged:false}"},
        {pos: [0, 6, 3], state: "minecraft:oak_leaves{distance:3,persistent:true,waterlogged:false}"},
        {pos: [0, 6, 4], state: "minecraft:oak_leaves{distance:4,persistent:true,waterlogged:false}"},
        {pos: [0, 6, 5], state: "minecraft:oak_leaves{distance:5,persistent:true,waterlogged:false}"},
        {pos: [0, 6, 6], state: "minecraft:oak_leaves{distance:6,persistent:true,waterlogged:false}"},
        {pos: [1, 6, 0], state: "minecraft:oak_leaves{distance:5,persistent:true,waterlogged:false}"},
        {pos: [1, 6, 1], state: "minecraft:oak_leaves{distance:4,persistent:true,waterlogged:false}"},
        {pos: [1, 6, 2], state: "minecraft:oak_leaves{distance:3,persistent:true,waterlogged:false}"},
        {pos: [1, 6, 3], state: "minecraft:oak_leaves{distance:2,persistent:true,waterlogged:false}"},
        {pos: [1, 6, 4], state: "minecraft:oak_leaves{distance:3,persistent:true,waterlogged:false}"},
        {pos: [1, 6, 5], state: "minecraft:oak_leaves{distance:4,persistent:true,waterlogged:false}"},
        {pos: [1, 6, 6], state: "minecraft:oak_leaves{distance:5,persistent:true,waterlogged:false}"},
        {pos: [1, 6, 7], state: "minecraft:vine{east:false,north:true,south:false,up:false,west:false}"},
        {pos: [2, 6, 0], state: "minecraft:oak_leaves{distance:4,persistent:true,waterlogged:false}"},
        {pos: [2, 6, 1], state: "minecraft:oak_leaves{distance:3,persistent:true,waterlogged:false}"},
        {pos: [2, 6, 2], state: "minecraft:oak_leaves{distance:2,persistent:true,waterlogged:false}"},
        {pos: [2, 6, 3], state: "minecraft:oak_leaves{distance:1,persistent:true,waterlogged:false}"},
        {pos: [2, 6, 4], state: "minecraft:oak_leaves{distance:2,persistent:true,waterlogged:false}"},
        {pos: [2, 6, 5], state: "minecraft:oak_leaves{distance:3,persistent:true,waterlogged:false}"},
        {pos: [2, 6, 6], state: "minecraft:oak_leaves{distance:4,persistent:true,waterlogged:false}"},
        {pos: [3, 6, 0], state: "minecraft:oak_leaves{distance:3,persistent:true,waterlogged:false}"},
        {pos: [3, 6, 1], state: "minecraft:oak_leaves{distance:2,persistent:true,waterlogged:false}"},
        {pos: [3, 6, 2], state: "minecraft:oak_leaves{distance:1,persistent:true,waterlogged:false}"},
        {pos: [3, 6, 3], state: "minecraft:oak_log{axis:y}"},
        {pos: [3, 6, 4], state: "minecraft:oak_leaves{distance:1,persistent:true,waterlogged:false}"},
        {pos: [3, 6, 5], state: "minecraft:oak_leaves{distance:2,persistent:true,waterlogged:false}"},
        {pos: [3, 6, 6], state: "minecraft:oak_leaves{distance:3,persistent:true,waterlogged:false}"},
        {pos: [3, 6, 7], state: "minecraft:vine{east:false,north:true,south:false,up:false,west:false}"},
        {pos: [4, 6, 0], state: "minecraft:oak_leaves{distance:4,persistent:true,waterlogged:false}"},
        {pos: [4, 6, 1], state: "minecraft:oak_leaves{distance:3,persistent:true,waterlogged:false}"},
        {pos: [4, 6, 2], state: "minecraft:oak_leaves{distance:2,persistent:true,waterlogged:false}"},
        {pos: [4, 6, 3], state: "minecraft:oak_leaves{distance:1,persistent:true,waterlogged:false}"},
        {pos: [4, 6, 4], state: "minecraft:oak_leaves{distance:2,persistent:true,waterlogged:false}"},
        {pos: [4, 6, 5], state: "minecraft:oak_leaves{distance:3,persistent:true,waterlogged:false}"},
        {pos: [4, 6, 6], state: "minecraft:oak_leaves{distance:4,persistent:true,waterlogged:false}"},
        {pos: [4, 6, 7], state: "minecraft:vine{east:false,north:true,south:false,up:false,west:false}"},
        {pos: [5, 6, 0], state: "minecraft:oak_leaves{distance:5,persistent:true,waterlogged:false}"},
        {pos: [5, 6, 1], state: "minecraft:oak_leaves{distance:4,persistent:true,waterlogged:false}"},
        {pos: [5, 6, 2], state: "minecraft:oak_leaves{distance:3,persistent:true,waterlogged:false}"},
        {pos: [5, 6, 3], state: "minecraft:oak_leaves{distance:2,persistent:true,waterlogged:false}"},
        {pos: [5, 6, 4], state: "minecraft:oak_leaves{distance:3,persistent:true,waterlogged:false}"},
        {pos: [5, 6, 5], state: "minecraft:oak_leaves{distance:4,persistent:true,waterlogged:false}"},
        {pos: [5, 6, 6], state: "minecraft:oak_leaves{distance:5,persistent:true,waterlogged:false}"},
        {pos: [6, 6, 0], state: "minecraft:oak_leaves{distance:6,persistent:true,waterlogged:false}"},
        {pos: [6, 6, 1], state: "minecraft:oak_leaves{distance:5,persistent:true,waterlogged:false}"},
        {pos: [6, 6, 2], state: "minecraft:oak_leaves{distance:4,persistent:true,waterlogged:false}"},
        {pos: [6, 6, 3], state: "minecraft:oak_leaves{distance:3,persistent:true,waterlogged:false}"},
        {pos: [6, 6, 4], state: "minecraft:oak_leaves{distance:4,persistent:true,waterlogged:false}"},
        {pos: [6, 6, 5], state: "minecraft:oak_leaves{distance:5,persistent:true,waterlogged:false}"},
        {pos: [6, 6, 6], state: "minecraft:oak_leaves{distance:6,persistent:true,waterlogged:false}"},
        {pos: [6, 6, 7], state: "minecraft:vine{east:false,north:true,south:false,up:false,west:false}"},
        {pos: [7, 6, 0], state: "minecraft:vine{east:false,north:false,south:false,up:false,west:true}"},
        {pos: [7, 6, 3], state: "minecraft:vine{east:false,north:false,south:false,up:false,west:true}"},
        {pos: [7, 6, 4], state: "minecraft:vine{east:false,north:false,south:false,up:false,west:true}"},
        {pos: [7, 6, 6], state: "minecraft:vine{east:false,north:false,south:false,up:false,west:true}"},
        {pos: [1, 7, 1], state: "minecraft:oak_leaves{distance:4,persistent:true,waterlogged:false}"},
        {pos: [1, 7, 2], state: "minecraft:oak_leaves{distance:3,persistent:true,waterlogged:false}"},
        {pos: [1, 7, 3], state: "minecraft:oak_leaves{distance:2,persistent:true,waterlogged:false}"},
        {pos: [1, 7, 4], state: "minecraft:oak_leaves{distance:3,persistent:true,waterlogged:false}"},
        {pos: [1, 7, 5], state: "minecraft:oak_leaves{distance:4,persistent:true,waterlogged:false}"},
        {pos: [2, 7, 1], state: "minecraft:oak_leaves{distance:3,persistent:true,waterlogged:false}"},
        {pos: [2, 7, 2], state: "minecraft:oak_leaves{distance:2,persistent:true,waterlogged:false}"},
        {pos: [2, 7, 3], state: "minecraft:oak_leaves{distance:1,persistent:true,waterlogged:false}"},
        {pos: [2, 7, 4], state: "minecraft:oak_leaves{distance:2,persistent:true,waterlogged:false}"},
        {pos: [2, 7, 5], state: "minecraft:oak_leaves{distance:3,persistent:true,waterlogged:false}"},
        {pos: [3, 7, 1], state: "minecraft:oak_leaves{distance:2,persistent:true,waterlogged:false}"},
        {pos: [3, 7, 2], state: "minecraft:oak_leaves{distance:1,persistent:true,waterlogged:false}"},
        {pos: [3, 7, 3], state: "minecraft:oak_log{axis:y}"},
        {pos: [3, 7, 4], state: "minecraft:oak_leaves{distance:1,persistent:true,waterlogged:false}"},
        {pos: [3, 7, 5], state: "minecraft:oak_leaves{distance:2,persistent:true,waterlogged:false}"},
        {pos: [4, 7, 1], state: "minecraft:oak_leaves{distance:3,persistent:true,waterlogged:false}"},
        {pos: [4, 7, 2], state: "minecraft:oak_leaves{distance:2,persistent:true,waterlogged:false}"},
        {pos: [4, 7, 3], state: "minecraft:oak_leaves{distance:1,persistent:true,waterlogged:false}"},
        {pos: [4, 7, 4], state: "minecraft:oak_leaves{distance:2,persistent:true,waterlogged:false}"},
        {pos: [4, 7, 5], state: "minecraft:oak_leaves{distance:3,persistent:true,waterlogged:false}"},
        {pos: [5, 7, 1], state: "minecraft:oak_leaves{distance:4,persistent:true,waterlogged:false}"},
        {pos: [5, 7, 2], state: "minecraft:oak_leaves{distance:3,persistent:true,waterlogged:false}"},
        {pos: [5, 7, 3], state: "minecraft:oak_leaves{distance:2,persistent:true,waterlogged:false}"},
        {pos: [5, 7, 4], state: "minecraft:oak_leaves{distance:3,persistent:true,waterlogged:false}"},
        {pos: [5, 7, 5], state: "minecraft:oak_leaves{distance:4,persistent:true,waterlogged:false}"},
        {pos: [1, 8, 2], state: "minecraft:oak_leaves{distance:4,persistent:true,waterlogged:false}"},
        {pos: [1, 8, 3], state: "minecraft:oak_leaves{distance:3,persistent:true,waterlogged:false}"},
        {pos: [1, 8, 4], state: "minecraft:oak_leaves{distance:4,persistent:true,waterlogged:false}"},
        {pos: [2, 8, 1], state: "minecraft:oak_leaves{distance:4,persistent:true,waterlogged:false}"},
        {pos: [2, 8, 2], state: "minecraft:oak_leaves{distance:3,persistent:true,waterlogged:false}"},
        {pos: [2, 8, 3], state: "minecraft:oak_leaves{distance:2,persistent:true,waterlogged:false}"},
        {pos: [2, 8, 4], state: "minecraft:oak_leaves{distance:3,persistent:true,waterlogged:false}"},
        {pos: [2, 8, 5], state: "minecraft:oak_leaves{distance:4,persistent:true,waterlogged:false}"},
        {pos: [3, 8, 1], state: "minecraft:oak_leaves{distance:3,persistent:true,waterlogged:false}"},
        {pos: [3, 8, 2], state: "minecraft:oak_leaves{distance:2,persistent:true,waterlogged:false}"},
        {pos: [3, 8, 3], state: "minecraft:oak_leaves{distance:1,persistent:true,waterlogged:false}"},
        {pos: [3, 8, 4], state: "minecraft:oak_leaves{distance:2,persistent:true,waterlogged:false}"},
        {pos: [3, 8, 5], state: "minecraft:oak_leaves{distance:3,persistent:true,waterlogged:false}"},
        {pos: [4, 8, 1], state: "minecraft:oak_leaves{distance:4,persistent:true,waterlogged:false}"},
        {pos: [4, 8, 2], state: "minecraft:oak_leaves{distance:3,persistent:true,waterlogged:false}"},
        {pos: [4, 8, 3], state: "minecraft:oak_leaves{distance:2,persistent:true,waterlogged:false}"},
        {pos: [4, 8, 4], state: "minecraft:oak_leaves{distance:3,persistent:true,waterlogged:false}"},
        {pos: [4, 8, 5], state: "minecraft:oak_leaves{distance:4,persistent:true,waterlogged:false}"},
        {pos: [5, 8, 2], state: "minecraft:oak_leaves{distance:4,persistent:true,waterlogged:false}"},
        {pos: [5, 8, 3], state: "minecraft:oak_leaves{distance:3,persistent:true,waterlogged:false}"},
        {pos: [5, 8, 4], state: "minecraft:oak_leaves{distance:4,persistent:true,waterlogged:false}"}
    ],
    entities: [
        {blockPos: [8, 1, 5], pos: [8.5d, 1.9375d, 5.5d], nbt: {Air: 300s, Fire: 0s, Invulnerable: 0b, Motion: [0.0d, 0.0d, 0.0d], OnGround: 0b, PortalCooldown: 0, Pos: [-86.5d, -60.0625d, 451.5d], Rotation: [90.0f, 0.0f], UUID: [I; 268210954, 1153385864, -1724357080, -29737110], block_pos: [I; -87, -61, 451], color: "light_gray", fall_distance: 0.0d, id: "minecraft:cushion"}},
        {blockPos: [9, 1, 6], pos: [9.5d, 1.9375d, 6.5d], nbt: {Air: 300s, Fire: 0s, Invulnerable: 0b, Motion: [0.0d, 0.0d, 0.0d], OnGround: 0b, PortalCooldown: 0, Pos: [-85.5d, -60.0625d, 452.5d], Rotation: [90.0f, 0.0f], UUID: [I; -1883483753, -1895611954, -1135681983, -265678882], block_pos: [I; -86, -61, 452], color: "gray", fall_distance: 0.0d, id: "minecraft:cushion"}}
    ],
    palette: [
        "minecraft:grass_block{snowy:false}",
        "minecraft:dirt",
        "minecraft:clay",
        "minecraft:oak_log{axis:y}",
        "minecraft:oak_leaves{distance:6,persistent:true,waterlogged:false}",
        "minecraft:oak_leaves{distance:5,persistent:true,waterlogged:false}",
        "minecraft:oak_leaves{distance:4,persistent:true,waterlogged:false}",
        "minecraft:oak_leaves{distance:3,persistent:true,waterlogged:false}",
        "minecraft:oak_leaves{distance:2,persistent:true,waterlogged:false}",
        "minecraft:oak_leaves{distance:1,persistent:true,waterlogged:false}",
        "minecraft:seagrass",
        "minecraft:water{level:0}",
        "minecraft:dirt_path",
        "minecraft:vine{east:false,north:true,south:false,up:false,west:false}",
        "minecraft:vine{east:false,north:false,south:false,up:false,west:true}",
        "minecraft:cobweb",
        "minecraft:lily_pad",
        "minecraft:firefly_bush",
        "minecraft:short_grass",
        "minecraft:vine{east:true,north:false,south:false,up:false,west:false}",
        "minecraft:red_mushroom",
        "minecraft:vine{east:false,north:false,south:true,up:false,west:false}",
        "minecraft:vine{east:false,north:false,south:true,up:true,west:false}",
        "minecraft:vine{east:false,north:true,south:false,up:true,west:false}",
        "minecraft:vine{east:false,north:false,south:false,up:true,west:false}",
        "minecraft:jigsaw{orientation:east_up}",
        "minecraft:chest{facing:east,type:single,waterlogged:false}",
        "minecraft:campfire{facing:west,lit:false,signal_fire:false,waterlogged:false}"
    ]
}
