{
    size: [12, 10, 10],
    data: [
        {pos: [0, 0, 0], state: "minecraft:grass_block{snowy:false}"},
        {pos: [0, 0, 1], state: "minecraft:grass_block{snowy:false}"},
        {pos: [0, 0, 2], state: "minecraft:grass_block{snowy:false}"},
        {pos: [0, 0, 3], state: "minecraft:grass_block{snowy:false}"},
        {pos: [0, 0, 4], state: "minecraft:grass_block{snowy:false}"},
        {pos: [0, 0, 5], state: "minecraft:grass_block{snowy:false}"},
        {pos: [0, 0, 6], state: "minecraft:grass_block{snowy:false}"},
        {pos: [0, 0, 7], state: "minecraft:grass_block{snowy:false}"},
        {pos: [0, 0, 8], state: "minecraft:grass_block{snowy:false}"},
        {pos: [0, 0, 9], state: "minecraft:grass_block{snowy:false}"},
        {pos: [1, 0, 0], state: "minecraft:grass_block{snowy:false}"},
        {pos: [1, 0, 1], state: "minecraft:grass_block{snowy:false}"},
        {pos: [1, 0, 2], state: "minecraft:grass_block{snowy:false}"},
        {pos: [1, 0, 3], state: "minecraft:grass_block{snowy:false}"},
        {pos: [1, 0, 4], state: "minecraft:grass_block{snowy:false}"},
        {pos: [1, 0, 5], state: "minecraft:grass_block{snowy:false}"},
        {pos: [1, 0, 6], state: "minecraft:grass_block{snowy:false}"},
        {pos: [1, 0, 7], state: "minecraft:dirt"},
        {pos: [1, 0, 8], state: "minecraft:grass_block{snowy:false}"},
        {pos: [1, 0, 9], state: "minecraft:grass_block{snowy:false}"},
        {pos: [2, 0, 0], state: "minecraft:dirt"},
        {pos: [2, 0, 1], state: "minecraft:dirt"},
        {pos: [2, 0, 2], state: "minecraft:dirt"},
        {pos: [2, 0, 3], state: "minecraft:dirt"},
        {pos: [2, 0, 4], state: "minecraft:dirt"},
        {pos: [2, 0, 5], state: "minecraft:dirt"},
        {pos: [2, 0, 6], state: "minecraft:grass_block{snowy:false}"},
        {pos: [2, 0, 7], state: "minecraft:grass_block{snowy:false}"},
        {pos: [2, 0, 8], state: "minecraft:grass_block{snowy:false}"},
        {pos: [2, 0, 9], state: "minecraft:grass_block{snowy:false}"},
        {pos: [3, 0, 0], state: "minecraft:dirt"},
        {pos: [3, 0, 1], state: "minecraft:dirt"},
        {pos: [3, 0, 2], state: "minecraft:clay"},
        {pos: [3, 0, 3], state: "minecraft:dirt"},
        {pos: [3, 0, 4], state: "minecraft:dirt"},
        {pos: [3, 0, 5], state: "minecraft:dirt"},
        {pos: [3, 0, 6], state: "minecraft:dirt"},
        {pos: [3, 0, 7], state: "minecraft:dirt"},
        {pos: [3, 0, 8], state: "minecraft:dirt"},
        {pos: [3, 0, 9], state: "minecraft:grass_block{snowy:false}"},
        {pos: [4, 0, 0], state: "minecraft:clay"},
        {pos: [4, 0, 1], state: "minecraft:dirt"},
        {pos: [4, 0, 2], state: "minecraft:clay"},
        {pos: [4, 0, 3], state: "minecraft:dirt"},
        {pos: [4, 0, 4], state: "minecraft:dirt"},
        {pos: [4, 0, 5], state: "minecraft:dirt"},
        {pos: [4, 0, 6], state: "minecraft:dirt"},
        {pos: [4, 0, 7], state: "minecraft:dirt"},
        {pos: [4, 0, 8], state: "minecraft:dirt"},
        {pos: [4, 0, 9], state: "minecraft:clay"},
        {pos: [5, 0, 0], state: "minecraft:dirt"},
        {pos: [5, 0, 1], state: "minecraft:clay"},
        {pos: [5, 0, 2], state: "minecraft:dirt"},
        {pos: [5, 0, 3], state: "minecraft:dirt"},
        {pos: [5, 0, 4], state: "minecraft:dirt"},
        {pos: [5, 0, 5], state: "minecraft:dirt"},
        {pos: [5, 0, 6], state: "minecraft:dirt"},
        {pos: [5, 0, 7], state: "minecraft:clay"},
        {pos: [5, 0, 8], state: "minecraft:dirt"},
        {pos: [5, 0, 9], state: "minecraft:dirt"},
        {pos: [6, 0, 0], state: "minecraft:grass_block{snowy:false}"},
        {pos: [6, 0, 1], state: "minecraft:dirt"},
        {pos: [6, 0, 2], state: "minecraft:dirt"},
        {pos: [6, 0, 3], state: "minecraft:dirt"},
        {pos: [6, 0, 4], state: "minecraft:grass_block{snowy:false}"},
        {pos: [6, 0, 5], state: "minecraft:dirt"},
        {pos: [6, 0, 6], state: "minecraft:clay"},
        {pos: [6, 0, 7], state: "minecraft:clay"},
        {pos: [6, 0, 8], state: "minecraft:dirt"},
        {pos: [6, 0, 9], state: "minecraft:grass_block{snowy:false}"},
        {pos: [7, 0, 0], state: "minecraft:grass_block{snowy:false}"},
        {pos: [7, 0, 1], state: "minecraft:grass_block{snowy:false}"},
        {pos: [7, 0, 2], state: "minecraft:grass_block{snowy:false}"},
        {pos: [7, 0, 3], state: "minecraft:dirt"},
        {pos: [7, 0, 4], state: "minecraft:dirt"},
        {pos: [7, 0, 5], state: "minecraft:grass_block{snowy:false}"},
        {pos: [7, 0, 6], state: "minecraft:dirt"},
        {pos: [7, 0, 7], state: "minecraft:dirt"},
        {pos: [7, 0, 8], state: "minecraft:dirt"},
        {pos: [7, 0, 9], state: "minecraft:grass_block{snowy:false}"},
        {pos: [8, 0, 0], state: "minecraft:grass_block{snowy:false}"},
        {pos: [8, 0, 1], state: "minecraft:grass_block{snowy:false}"},
        {pos: [8, 0, 2], state: "minecraft:grass_block{snowy:false}"},
        {pos: [8, 0, 3], state: "minecraft:dirt"},
        {pos: [8, 0, 4], state: "minecraft:dirt"},
        {pos: [8, 0, 5], state: "minecraft:grass_block{snowy:false}"},
        {pos: [8, 0, 6], state: "minecraft:grass_block{snowy:false}"},
        {pos: [8, 0, 7], state: "minecraft:dirt"},
        {pos: [8, 0, 8], state: "minecraft:grass_block{snowy:false}"},
        {pos: [8, 0, 9], state: "minecraft:grass_block{snowy:false}"},
        {pos: [9, 0, 0], state: "minecraft:grass_block{snowy:false}"},
        {pos: [9, 0, 1], state: "minecraft:grass_block{snowy:false}"},
        {pos: [9, 0, 2], state: "minecraft:grass_block{snowy:false}"},
        {pos: [9, 0, 3], state: "minecraft:dirt"},
        {pos: [9, 0, 4], state: "minecraft:dirt"},
        {pos: [9, 0, 5], state: "minecraft:grass_block{snowy:false}"},
        {pos: [9, 0, 6], state: "minecraft:dirt"},
        {pos: [9, 0, 7], state: "minecraft:dirt"},
        {pos: [9, 0, 8], state: "minecraft:grass_block{snowy:false}"},
        {pos: [9, 0, 9], state: "minecraft:grass_block{snowy:false}"},
        {pos: [10, 0, 0], state: "minecraft:grass_block{snowy:false}"},
        {pos: [10, 0, 1], state: "minecraft:grass_block{snowy:false}"},
        {pos: [10, 0, 2], state: "minecraft:dirt"},
        {pos: [10, 0, 3], state: "minecraft:dirt"},
        {pos: [10, 0, 4], state: "minecraft:dirt"},
        {pos: [10, 0, 5], state: "minecraft:dirt"},
        {pos: [10, 0, 6], state: "minecraft:dirt"},
        {pos: [10, 0, 7], state: "minecraft:grass_block{snowy:false}"},
        {pos: [10, 0, 8], state: "minecraft:grass_block{snowy:false}"},
        {pos: [10, 0, 9], state: "minecraft:grass_block{snowy:false}"},
        {pos: [11, 0, 0], state: "minecraft:grass_block{snowy:false}"},
        {pos: [11, 0, 1], state: "minecraft:grass_block{snowy:false}"},
        {pos: [11, 0, 2], state: "minecraft:grass_block{snowy:false}"},
        {pos: [11, 0, 3], state: "minecraft:dirt"},
        {pos: [11, 0, 4], state: "minecraft:dirt"},
        {pos: [11, 0, 5], state: "minecraft:dirt"},
        {pos: [11, 0, 6], state: "minecraft:dirt"},
        {pos: [11, 0, 7], state: "minecraft:grass_block{snowy:false}"},
        {pos: [11, 0, 8], state: "minecraft:grass_block{snowy:false}"},
        {pos: [11, 0, 9], state: "minecraft:grass_block{snowy:false}"},
        {pos: [0, 1, 3], state: "minecraft:vine{east:true,north:false,south:false,up:false,west:false}"},
        {pos: [0, 1, 5], state: "minecraft:vine{east:true,north:false,south:false,up:false,west:false}"},
        {pos: [0, 1, 6], state: "minecraft:vine{east:true,north:false,south:false,up:false,west:false}"},
        {pos: [1, 1, 1], state: "minecraft:vine{east:false,north:false,south:true,up:false,west:false}"},
        {pos: [1, 1, 7], state: "minecraft:grass_block{snowy:false}"},
        {pos: [2, 1, 0], state: "minecraft:grass_block{snowy:false}"},
        {pos: [2, 1, 1], state: "minecraft:clay"},
        {pos: [2, 1, 2], state: "minecraft:clay"},
        {pos: [2, 1, 3], state: "minecraft:clay"},
        {pos: [2, 1, 4], state: "minecraft:dirt"},
        {pos: [2, 1, 5], state: "minecraft:dirt"},
        {pos: [3, 1, 0], state: "minecraft:clay"},
        {pos: [3, 1, 1], state: "minecraft:water{level:0}"},
        {pos: [3, 1, 2], state: "minecraft:seagrass"},
        {pos: [3, 1, 3], state: "minecraft:clay"},
        {pos: [3, 1, 4], state: "minecraft:dirt"},
        {pos: [3, 1, 5], state: "minecraft:dirt"},
        {pos: [3, 1, 6], state: "minecraft:dirt"},
        {pos: [3, 1, 7], state: "minecraft:clay"},
        {pos: [3, 1, 8], state: "minecraft:grass_block{snowy:false}"},
        {pos: [4, 1, 0], state: "minecraft:clay"},
        {pos: [4, 1, 1], state: "minecraft:seagrass"},
        {pos: [4, 1, 2], state: "minecraft:seagrass"},
        {pos: [4, 1, 3], state: "minecraft:water{level:0}"},
        {pos: [4, 1, 4], state: "minecraft:grass_block{snowy:false}"},
        {pos: [4, 1, 5], state: "minecraft:dirt"},
        {pos: [4, 1, 6], state: "minecraft:clay"},
        {pos: [4, 1, 7], state: "minecraft:water{level:0}"},
        {pos: [4, 1, 8], state: "minecraft:seagrass"},
        {pos: [4, 1, 9], state: "minecraft:clay"},
        {pos: [5, 1, 0], state: "minecraft:clay"},
        {pos: [5, 1, 1], state: "minecraft:water{level:0}"},
        {pos: [5, 1, 2], state: "minecraft:seagrass"},
        {pos: [5, 1, 3], state: "minecraft:clay"},
        {pos: [5, 1, 4], state: "minecraft:dirt"},
        {pos: [5, 1, 5], state: "minecraft:grass_block{snowy:false}"},
        {pos: [5, 1, 6], state: "minecraft:seagrass"},
        {pos: [5, 1, 7], state: "minecraft:water{level:0}"},
        {pos: [5, 1, 8], state: "minecraft:seagrass"},
        {pos: [5, 1, 9], state: "minecraft:clay"},
        {pos: [6, 1, 1], state: "minecraft:clay"},
        {pos: [6, 1, 2], state: "minecraft:clay"},
        {pos: [6, 1, 3], state: "minecraft:grass_block{snowy:false}"},
        {pos: [6, 1, 5], state: "minecraft:clay"},
        {pos: [6, 1, 6], state: "minecraft:seagrass"},
        {pos: [6, 1, 7], state: "minecraft:water{level:0}"},
        {pos: [6, 1, 8], state: "minecraft:clay"},
        {pos: [7, 1, 3], state: "minecraft:dirt_path"},
        {pos: [7, 1, 4], state: "minecraft:grass_block{snowy:false}"},
        {pos: [7, 1, 6], state: "minecraft:clay"},
        {pos: [7, 1, 7], state: "minecraft:seagrass"},
        {pos: [7, 1, 8], state: "minecraft:clay"},
        {pos: [8, 1, 2], state: "minecraft:vine{east:false,north:false,south:false,up:false,west:true}"},
        {pos: [8, 1, 3], state: "minecraft:dirt_path"},
        {pos: [8, 1, 4], state: "minecraft:dirt_path"},
        {pos: [8, 1, 5], state: "minecraft:vine{east:false,north:false,south:false,up:false,west:true}"},
        {pos: [8, 1, 7], state: "minecraft:clay"},
        {pos: [8, 1, 8], state: "minecraft:vine{east:false,north:false,south:false,up:false,west:true}"},
        {pos: [9, 1, 3], state: "minecraft:dirt_path"},
        {pos: [9, 1, 4], state: "minecraft:grass_block{snowy:false}"},
        {pos: [9, 1, 6], state: "minecraft:dirt"},
        {pos: [9, 1, 7], state: "minecraft:grass_block{snowy:false}"},
        {pos: [10, 1, 2], state: "minecraft:dirt_path"},
        {pos: [10, 1, 3], state: "minecraft:dirt_path"},
        {pos: [10, 1, 4], state: "minecraft:dirt_path"},
        {pos: [10, 1, 5], state: "minecraft:dirt_path"},
        {pos: [10, 1, 6], state: "minecraft:dirt_path"},
        {pos: [11, 1, 3], state: "minecraft:dirt_path"},
        {pos: [11, 1, 4], state: "minecraft:jigsaw{orientation:east_up}", nbt: {components: {}, final_state: "minecraft:dirt_path", id: "minecraft:jigsaw", joint: "rollable", name: "minecraft:end_connector", placement_priority: 0, pool: "minecraft:empty", selection_priority: 0, target: "minecraft:connector"}},
        {pos: [11, 1, 5], state: "minecraft:dirt_path"},
        {pos: [11, 1, 6], state: "minecraft:dirt_path"},
        {pos: [0, 2, 3], state: "minecraft:vine{east:true,north:false,south:false,up:false,west:false}"},
        {pos: [0, 2, 5], state: "minecraft:vine{east:true,north:false,south:false,up:false,west:false}"},
        {pos: [0, 2, 6], state: "minecraft:vine{east:true,north:false,south:false,up:false,west:false}"},
        {pos: [1, 2, 1], state: "minecraft:vine{east:false,north:false,south:true,up:false,west:false}"},
        {pos: [1, 2, 7], state: "minecraft:short_grass"},
        {pos: [2, 2, 0], state: "minecraft:blue_orchid"},
        {pos: [2, 2, 1], state: "minecraft:vine{east:false,north:false,south:true,up:false,west:false}"},
        {pos: [2, 2, 4], state: "minecraft:grass_block{snowy:false}"},
        {pos: [2, 2, 5], state: "minecraft:grass_block{snowy:false}"},
        {pos: [3, 2, 1], state: "minecraft:lily_pad"},
        {pos: [3, 2, 4], state: "minecraft:grass_block{snowy:false}"},
        {pos: [3, 2, 5], state: "minecraft:grass_block{snowy:false}"},
        {pos: [3, 2, 6], state: "minecraft:grass_block{snowy:false}"},
        {pos: [3, 2, 8], state: "minecraft:blue_orchid"},
        {pos: [4, 2, 2], state: "minecraft:lily_pad"},
        {pos: [4, 2, 4], state: "minecraft:short_grass"},
        {pos: [4, 2, 5], state: "minecraft:dirt"},
        {pos: [4, 2, 6], state: "minecraft:vine{east:false,north:true,south:false,up:false,west:false}"},
        {pos: [4, 2, 8], state: "minecraft:lily_pad"},
        {pos: [5, 2, 1], state: "minecraft:vine{east:false,north:false,south:true,up:false,west:false}"},
        {pos: [5, 2, 4], state: "minecraft:grass_block{snowy:false}"},
        {pos: [5, 2, 5], state: "minecraft:short_grass"},
        {pos: [6, 2, 1], state: "minecraft:vine{east:false,north:false,south:true,up:false,west:false}"},
        {pos: [6, 2, 3], state: "minecraft:blue_orchid"},
        {pos: [6, 2, 7], state: "minecraft:lily_pad"},
        {pos: [7, 2, 4], state: "minecraft:chest{facing:east,type:single,waterlogged:false}", nbt: {Items: [], LootTable: "minecraft:chests/abandoned_camp_common_chest", components: {}, id: "minecraft:chest"}},
        {pos: [8, 2, 2], state: "minecraft:vine{east:false,north:false,south:false,up:false,west:true}"},
        {pos: [8, 2, 4], state: "minecraft:vine{east:false,north:false,south:false,up:false,west:true}"},
        {pos: [8, 2, 5], state: "minecraft:vine{east:false,north:false,south:false,up:false,west:true}"},
        {pos: [8, 2, 7], state: "minecraft:vine{east:false,north:false,south:false,up:false,west:true}"},
        {pos: [8, 2, 8], state: "minecraft:vine{east:false,north:false,south:false,up:false,west:true}"},
        {pos: [9, 2, 4], state: "minecraft:campfire{facing:west,lit:false,signal_fire:false,waterlogged:false}", nbt: {CookingTimes: [I; 0, 0, 0, 0], CookingTotalTimes: [I; 0, 0, 0, 0], Items: [], components: {}, id: "minecraft:campfire"}},
        {pos: [9, 2, 6], state: "minecraft:barrel{facing:up,open:false}", nbt: {Items: [], LootTable: "minecraft:barrels/abandoned_camp_barrel", components: {}, id: "minecraft:barrel"}},
        {pos: [9, 2, 7], state: "minecraft:blue_orchid"},
        {pos: [0, 3, 3], state: "minecraft:vine{east:true,north:false,south:false,up:false,west:false}"},
        {pos: [0, 3, 5], state: "minecraft:vine{east:true,north:false,south:false,up:false,west:false}"},
        {pos: [0, 3, 6], state: "minecraft:vine{east:true,north:false,south:false,up:false,west:false}"},
        {pos: [1, 3, 1], state: "minecraft:vine{east:false,north:false,south:true,up:false,west:false}"},
        {pos: [2, 3, 1], state: "minecraft:vine{east:false,north:false,south:true,up:false,west:false}"},
        {pos: [2, 3, 4], state: "minecraft:short_grass"},
        {pos: [3, 3, 5], state: "minecraft:vine{east:true,north:false,south:false,up:false,west:false}"},
        {pos: [3, 3, 6], state: "minecraft:blue_orchid"},
        {pos: [4, 3, 4], state: "minecraft:vine{east:false,north:false,south:true,up:false,west:false}"},
        {pos: [4, 3, 5], state: "minecraft:oak_log{axis:y}"},
        {pos: [4, 3, 6], state: "minecraft:vine{east:false,north:true,south:false,up:false,west:false}"},
        {pos: [5, 3, 1], state: "minecraft:vine{east:false,north:false,south:true,up:false,west:false}"},
        {pos: [5, 3, 4], state: "minecraft:blue_orchid"},
        {pos: [5, 3, 5], state: "minecraft:vine{east:false,north:false,south:false,up:false,west:true}"},
        {pos: [6, 3, 1], state: "minecraft:vine{east:false,north:false,south:true,up:false,west:false}"},
        {pos: [8, 3, 2], state: "minecraft:vine{east:false,north:false,south:false,up:false,west:true}"},
        {pos: [8, 3, 4], state: "minecraft:vine{east:false,north:false,south:false,up:false,west:true}"},
        {pos: [8, 3, 5], state: "minecraft:vine{east:false,north:false,south:false,up:false,west:true}"},
        {pos: [8, 3, 7], state: "minecraft:vine{east:false,north:false,south:false,up:false,west:true}"},
        {pos: [8, 3, 8], state: "minecraft:vine{east:false,north:false,south:false,up:false,west:true}"},
        {pos: [0, 4, 3], state: "minecraft:vine{east:true,north:false,south:false,up:false,west:false}"},
        {pos: [0, 4, 5], state: "minecraft:vine{east:true,north:false,south:false,up:false,west:false}"},
        {pos: [0, 4, 6], state: "minecraft:vine{east:true,north:false,south:false,up:false,west:false}"},
        {pos: [1, 4, 1], state: "minecraft:vine{east:false,north:false,south:true,up:false,west:false}"},
        {pos: [2, 4, 1], state: "minecraft:vine{east:false,north:false,south:true,up:false,west:false}"},
        {pos: [3, 4, 5], state: "minecraft:vine{east:true,north:false,south:false,up:false,west:false}"},
        {pos: [4, 4, 4], state: "minecraft:vine{east:false,north:false,south:true,up:false,west:false}"},
        {pos: [4, 4, 5], state: "minecraft:oak_log{axis:y}"},
        {pos: [4, 4, 6], state: "minecraft:vine{east:false,north:true,south:false,up:false,west:false}"},
        {pos: [5, 4, 1], state: "minecraft:vine{east:false,north:false,south:true,up:false,west:false}"},
        {pos: [5, 4, 5], state: "minecraft:vine{east:false,north:false,south:false,up:false,west:true}"},
        {pos: [6, 4, 1], state: "minecraft:vine{east:false,north:false,south:true,up:false,west:false}"},
        {pos: [8, 4, 2], state: "minecraft:vine{east:false,north:false,south:false,up:false,west:true}"},
        {pos: [8, 4, 4], state: "minecraft:vine{east:false,north:false,south:false,up:false,west:true}"},
        {pos: [8, 4, 5], state: "minecraft:vine{east:false,north:false,south:false,up:false,west:true}"},
        {pos: [8, 4, 7], state: "minecraft:vine{east:false,north:false,south:false,up:false,west:true}"},
        {pos: [8, 4, 8], state: "minecraft:vine{east:false,north:false,south:false,up:false,west:true}"},
        {pos: [0, 5, 3], state: "minecraft:vine{east:true,north:false,south:false,up:false,west:false}"},
        {pos: [0, 5, 5], state: "minecraft:vine{east:true,north:false,south:false,up:false,west:false}"},
        {pos: [0, 5, 6], state: "minecraft:vine{east:true,north:false,south:false,up:false,west:false}"},
        {pos: [1, 5, 1], state: "minecraft:vine{east:false,north:false,south:true,up:false,west:false}"},
        {pos: [2, 5, 1], state: "minecraft:vine{east:false,north:false,south:true,up:false,west:false}"},
        {pos: [3, 5, 5], state: "minecraft:vine{east:true,north:false,south:false,up:true,west:false}"},
        {pos: [4, 5, 4], state: "minecraft:vine{east:false,north:false,south:true,up:true,west:false}"},
        {pos: [4, 5, 5], state: "minecraft:oak_log{axis:y}"},
        {pos: [4, 5, 6], state: "minecraft:vine{east:false,north:true,south:false,up:true,west:false}"},
        {pos: [5, 5, 1], state: "minecraft:vine{east:false,north:false,south:true,up:false,west:false}"},
        {pos: [5, 5, 5], state: "minecraft:vine{east:false,north:false,south:false,up:true,west:true}"},
        {pos: [6, 5, 1], state: "minecraft:vine{east:false,north:false,south:true,up:false,west:false}"},
        {pos: [8, 5, 2], state: "minecraft:vine{east:false,north:false,south:false,up:false,west:true}"},
        {pos: [8, 5, 4], state: "minecraft:vine{east:false,north:false,south:false,up:false,west:true}"},
        {pos: [8, 5, 5], state: "minecraft:vine{east:false,north:false,south:false,up:false,west:true}"},
        {pos: [8, 5, 7], state: "minecraft:vine{east:false,north:false,south:false,up:false,west:true}"},
        {pos: [8, 5, 8], state: "minecraft:vine{east:false,north:false,south:false,up:false,west:true}"},
        {pos: [0, 6, 3], state: "minecraft:vine{east:true,north:false,south:false,up:false,west:false}"},
        {pos: [0, 6, 5], state: "minecraft:vine{east:true,north:false,south:false,up:false,west:false}"},
        {pos: [0, 6, 6], state: "minecraft:vine{east:true,north:false,south:false,up:false,west:false}"},
        {pos: [1, 6, 1], state: "minecraft:vine{east:false,north:false,south:true,up:false,west:false}"},
        {pos: [1, 6, 2], state: "minecraft:oak_leaves{distance:6,persistent:true,waterlogged:false}"},
        {pos: [1, 6, 3], state: "minecraft:oak_leaves{distance:5,persistent:true,waterlogged:false}"},
        {pos: [1, 6, 4], state: "minecraft:oak_leaves{distance:4,persistent:true,waterlogged:false}"},
        {pos: [1, 6, 5], state: "minecraft:oak_leaves{distance:3,persistent:true,waterlogged:false}"},
        {pos: [1, 6, 6], state: "minecraft:oak_leaves{distance:4,persistent:true,waterlogged:false}"},
        {pos: [1, 6, 7], state: "minecraft:oak_leaves{distance:5,persistent:true,waterlogged:false}"},
        {pos: [1, 6, 8], state: "minecraft:oak_leaves{distance:6,persistent:true,waterlogged:false}"},
        {pos: [2, 6, 1], state: "minecraft:vine{east:false,north:false,south:true,up:false,west:false}"},
        {pos: [2, 6, 2], state: "minecraft:oak_leaves{distance:5,persistent:true,waterlogged:false}"},
        {pos: [2, 6, 3], state: "minecraft:oak_leaves{distance:4,persistent:true,waterlogged:false}"},
        {pos: [2, 6, 4], state: "minecraft:oak_leaves{distance:3,persistent:true,waterlogged:false}"},
        {pos: [2, 6, 5], state: "minecraft:oak_leaves{distance:2,persistent:true,waterlogged:false}"},
        {pos: [2, 6, 6], state: "minecraft:oak_leaves{distance:3,persistent:true,waterlogged:false}"},
        {pos: [2, 6, 7], state: "minecraft:oak_leaves{distance:4,persistent:true,waterlogged:false}"},
        {pos: [2, 6, 8], state: "minecraft:oak_leaves{distance:5,persistent:true,waterlogged:false}"},
        {pos: [3, 6, 2], state: "minecraft:oak_leaves{distance:4,persistent:true,waterlogged:false}"},
        {pos: [3, 6, 3], state: "minecraft:oak_leaves{distance:3,persistent:true,waterlogged:false}"},
        {pos: [3, 6, 4], state: "minecraft:oak_leaves{distance:2,persistent:true,waterlogged:false}"},
        {pos: [3, 6, 5], state: "minecraft:oak_leaves{distance:1,persistent:true,waterlogged:false}"},
        {pos: [3, 6, 6], state: "minecraft:oak_leaves{distance:2,persistent:true,waterlogged:false}"},
        {pos: [3, 6, 7], state: "minecraft:oak_leaves{distance:3,persistent:true,waterlogged:false}"},
        {pos: [3, 6, 8], state: "minecraft:oak_leaves{distance:4,persistent:true,waterlogged:false}"},
        {pos: [4, 6, 2], state: "minecraft:oak_leaves{distance:3,persistent:true,waterlogged:false}"},
        {pos: [4, 6, 3], state: "minecraft:oak_leaves{distance:2,persistent:true,waterlogged:false}"},
        {pos: [4, 6, 4], state: "minecraft:oak_leaves{distance:1,persistent:true,waterlogged:false}"},
        {pos: [4, 6, 5], state: "minecraft:oak_log{axis:y}"},
        {pos: [4, 6, 6], state: "minecraft:oak_leaves{distance:1,persistent:true,waterlogged:false}"},
        {pos: [4, 6, 7], state: "minecraft:oak_leaves{distance:2,persistent:true,waterlogged:false}"},
        {pos: [4, 6, 8], state: "minecraft:oak_leaves{distance:3,persistent:true,waterlogged:false}"},
        {pos: [5, 6, 1], state: "minecraft:vine{east:false,north:false,south:true,up:false,west:false}"},
        {pos: [5, 6, 2], state: "minecraft:oak_leaves{distance:4,persistent:true,waterlogged:false}"},
        {pos: [5, 6, 3], state: "minecraft:oak_leaves{distance:3,persistent:true,waterlogged:false}"},
        {pos: [5, 6, 4], state: "minecraft:oak_leaves{distance:2,persistent:true,waterlogged:false}"},
        {pos: [5, 6, 5], state: "minecraft:oak_leaves{distance:1,persistent:true,waterlogged:false}"},
        {pos: [5, 6, 6], state: "minecraft:oak_leaves{distance:2,persistent:true,waterlogged:false}"},
        {pos: [5, 6, 7], state: "minecraft:oak_leaves{distance:3,persistent:true,waterlogged:false}"},
        {pos: [5, 6, 8], state: "minecraft:oak_leaves{distance:4,persistent:true,waterlogged:false}"},
        {pos: [6, 6, 1], state: "minecraft:vine{east:false,north:false,south:true,up:false,west:false}"},
        {pos: [6, 6, 2], state: "minecraft:oak_leaves{distance:5,persistent:true,waterlogged:false}"},
        {pos: [6, 6, 3], state: "minecraft:oak_leaves{distance:4,persistent:true,waterlogged:false}"},
        {pos: [6, 6, 4], state: "minecraft:oak_leaves{distance:3,persistent:true,waterlogged:false}"},
        {pos: [6, 6, 5], state: "minecraft:oak_leaves{distance:2,persistent:true,waterlogged:false}"},
        {pos: [6, 6, 6], state: "minecraft:oak_leaves{distance:3,persistent:true,waterlogged:false}"},
        {pos: [6, 6, 7], state: "minecraft:oak_leaves{distance:4,persistent:true,waterlogged:false}"},
        {pos: [6, 6, 8], state: "minecraft:oak_leaves{distance:5,persistent:true,waterlogged:false}"},
        {pos: [7, 6, 2], state: "minecraft:oak_leaves{distance:6,persistent:true,waterlogged:false}"},
        {pos: [7, 6, 3], state: "minecraft:oak_leaves{distance:5,persistent:true,waterlogged:false}"},
        {pos: [7, 6, 4], state: "minecraft:oak_leaves{distance:4,persistent:true,waterlogged:false}"},
        {pos: [7, 6, 5], state: "minecraft:oak_leaves{distance:3,persistent:true,waterlogged:false}"},
        {pos: [7, 6, 6], state: "minecraft:oak_leaves{distance:4,persistent:true,waterlogged:false}"},
        {pos: [7, 6, 7], state: "minecraft:oak_leaves{distance:5,persistent:true,waterlogged:false}"},
        {pos: [7, 6, 8], state: "minecraft:oak_leaves{distance:6,persistent:true,waterlogged:false}"},
        {pos: [8, 6, 2], state: "minecraft:vine{east:false,north:false,south:false,up:false,west:true}"},
        {pos: [8, 6, 4], state: "minecraft:vine{east:false,north:false,south:false,up:false,west:true}"},
        {pos: [8, 6, 5], state: "minecraft:vine{east:false,north:false,south:false,up:false,west:true}"},
        {pos: [8, 6, 7], state: "minecraft:vine{east:false,north:false,south:false,up:false,west:true}"},
        {pos: [8, 6, 8], state: "minecraft:vine{east:false,north:false,south:false,up:false,west:true}"},
        {pos: [2, 7, 3], state: "minecraft:oak_leaves{distance:4,persistent:true,waterlogged:false}"},
        {pos: [2, 7, 4], state: "minecraft:oak_leaves{distance:3,persistent:true,waterlogged:false}"},
        {pos: [2, 7, 5], state: "minecraft:oak_leaves{distance:2,persistent:true,waterlogged:false}"},
        {pos: [2, 7, 6], state: "minecraft:oak_leaves{distance:3,persistent:true,waterlogged:false}"},
        {pos: [2, 7, 7], state: "minecraft:oak_leaves{distance:4,persistent:true,waterlogged:false}"},
        {pos: [3, 7, 3], state: "minecraft:oak_leaves{distance:3,persistent:true,waterlogged:false}"},
        {pos: [3, 7, 4], state: "minecraft:oak_leaves{distance:2,persistent:true,waterlogged:false}"},
        {pos: [3, 7, 5], state: "minecraft:oak_leaves{distance:1,persistent:true,waterlogged:false}"},
        {pos: [3, 7, 6], state: "minecraft:oak_leaves{distance:2,persistent:true,waterlogged:false}"},
        {pos: [3, 7, 7], state: "minecraft:oak_leaves{distance:3,persistent:true,waterlogged:false}"},
        {pos: [4, 7, 3], state: "minecraft:oak_leaves{distance:2,persistent:true,waterlogged:false}"},
        {pos: [4, 7, 4], state: "minecraft:oak_leaves{distance:1,persistent:true,waterlogged:false}"},
        {pos: [4, 7, 5], state: "minecraft:oak_log{axis:y}"},
        {pos: [4, 7, 6], state: "minecraft:oak_leaves{distance:1,persistent:true,waterlogged:false}"},
        {pos: [4, 7, 7], state: "minecraft:oak_leaves{distance:2,persistent:true,waterlogged:false}"},
        {pos: [5, 7, 3], state: "minecraft:oak_leaves{distance:3,persistent:true,waterlogged:false}"},
        {pos: [5, 7, 4], state: "minecraft:oak_leaves{distance:2,persistent:true,waterlogged:false}"},
        {pos: [5, 7, 5], state: "minecraft:oak_leaves{distance:1,persistent:true,waterlogged:false}"},
        {pos: [5, 7, 6], state: "minecraft:oak_leaves{distance:2,persistent:true,waterlogged:false}"},
        {pos: [5, 7, 7], state: "minecraft:oak_leaves{distance:3,persistent:true,waterlogged:false}"},
        {pos: [6, 7, 3], state: "minecraft:oak_leaves{distance:4,persistent:true,waterlogged:false}"},
        {pos: [6, 7, 4], state: "minecraft:oak_leaves{distance:3,persistent:true,waterlogged:false}"},
        {pos: [6, 7, 5], state: "minecraft:oak_leaves{distance:2,persistent:true,waterlogged:false}"},
        {pos: [6, 7, 6], state: "minecraft:oak_leaves{distance:3,persistent:true,waterlogged:false}"},
        {pos: [6, 7, 7], state: "minecraft:oak_leaves{distance:4,persistent:true,waterlogged:false}"},
        {pos: [2, 8, 4], state: "minecraft:oak_leaves{distance:4,persistent:true,waterlogged:false}"},
        {pos: [2, 8, 5], state: "minecraft:oak_leaves{distance:3,persistent:true,waterlogged:false}"},
        {pos: [2, 8, 6], state: "minecraft:oak_leaves{distance:4,persistent:true,waterlogged:false}"},
        {pos: [3, 8, 3], state: "minecraft:oak_leaves{distance:4,persistent:true,waterlogged:false}"},
        {pos: [3, 8, 4], state: "minecraft:oak_leaves{distance:3,persistent:true,waterlogged:false}"},
        {pos: [3, 8, 5], state: "minecraft:oak_leaves{distance:2,persistent:true,waterlogged:false}"},
        {pos: [3, 8, 6], state: "minecraft:oak_leaves{distance:3,persistent:true,waterlogged:false}"},
        {pos: [3, 8, 7], state: "minecraft:oak_leaves{distance:4,persistent:true,waterlogged:false}"},
        {pos: [4, 8, 3], state: "minecraft:oak_leaves{distance:3,persistent:true,waterlogged:false}"},
        {pos: [4, 8, 4], state: "minecraft:oak_leaves{distance:2,persistent:true,waterlogged:false}"},
        {pos: [4, 8, 5], state: "minecraft:oak_leaves{distance:1,persistent:true,waterlogged:false}"},
        {pos: [4, 8, 6], state: "minecraft:oak_leaves{distance:2,persistent:true,waterlogged:false}"},
        {pos: [4, 8, 7], state: "minecraft:oak_leaves{distance:3,persistent:true,waterlogged:false}"},
        {pos: [5, 8, 3], state: "minecraft:oak_leaves{distance:4,persistent:true,waterlogged:false}"},
        {pos: [5, 8, 4], state: "minecraft:oak_leaves{distance:3,persistent:true,waterlogged:false}"},
        {pos: [5, 8, 5], state: "minecraft:oak_leaves{distance:2,persistent:true,waterlogged:false}"},
        {pos: [5, 8, 6], state: "minecraft:oak_leaves{distance:3,persistent:true,waterlogged:false}"},
        {pos: [5, 8, 7], state: "minecraft:oak_leaves{distance:4,persistent:true,waterlogged:false}"},
        {pos: [6, 8, 4], state: "minecraft:oak_leaves{distance:4,persistent:true,waterlogged:false}"},
        {pos: [6, 8, 5], state: "minecraft:oak_leaves{distance:3,persistent:true,waterlogged:false}"},
        {pos: [6, 8, 6], state: "minecraft:oak_leaves{distance:4,persistent:true,waterlogged:false}"}
    ],
    entities: [
        {blockPos: [8, 1, 3], pos: [8.5d, 1.9375d, 3.5d], nbt: {Air: 300s, Fire: 0s, Invulnerable: 0b, Motion: [0.0d, 0.0d, 0.0d], OnGround: 0b, PortalCooldown: 0, Pos: [-87.5d, -60.0625d, 480.5d], Rotation: [90.0f, 0.0f], UUID: [I; -1937218603, -1107999103, -2030115128, -2100916108], block_pos: [I; -88, -61, 480], color: "black", fall_distance: 0.0d, id: "minecraft:cushion"}},
        {blockPos: [10, 1, 5], pos: [10.5d, 1.9375d, 5.5d], nbt: {Air: 300s, Fire: 0s, Invulnerable: 0b, Motion: [0.0d, 0.0d, 0.0d], OnGround: 0b, PortalCooldown: 0, Pos: [-85.5d, -60.0625d, 482.5d], Rotation: [90.0f, 0.0f], UUID: [I; -412476361, -574011874, -1802980412, 400786165], block_pos: [I; -86, -61, 482], color: "black", fall_distance: 0.0d, id: "minecraft:cushion"}}
    ],
    palette: [
        "minecraft:grass_block{snowy:false}",
        "minecraft:dirt",
        "minecraft:clay",
        "minecraft:oak_log{axis:y}",
        "minecraft:oak_leaves{distance:6,persistent:true,waterlogged:false}",
        "minecraft:oak_leaves{distance:5,persistent:true,waterlogged:false}",
        "minecraft:oak_leaves{distance:4,persistent:true,waterlogged:false}",
        "minecraft:oak_leaves{distance:3,persistent:true,waterlogged:false}",
        "minecraft:oak_leaves{distance:2,persistent:true,waterlogged:false}",
        "minecraft:oak_leaves{distance:1,persistent:true,waterlogged:false}",
        "minecraft:vine{east:true,north:false,south:false,up:false,west:false}",
        "minecraft:vine{east:false,north:false,south:true,up:false,west:false}",
        "minecraft:water{level:0}",
        "minecraft:seagrass",
        "minecraft:dirt_path",
        "minecraft:vine{east:false,north:false,south:false,up:false,west:true}",
        "minecraft:short_grass",
        "minecraft:blue_orchid",
        "minecraft:lily_pad",
        "minecraft:vine{east:false,north:true,south:false,up:false,west:false}",
        "minecraft:vine{east:true,north:false,south:false,up:true,west:false}",
        "minecraft:vine{east:false,north:false,south:true,up:true,west:false}",
        "minecraft:vine{east:false,north:true,south:false,up:true,west:false}",
        "minecraft:vine{east:false,north:false,south:false,up:true,west:true}",
        "minecraft:jigsaw{orientation:east_up}",
        "minecraft:chest{facing:east,type:single,waterlogged:false}",
        "minecraft:campfire{facing:west,lit:false,signal_fire:false,waterlogged:false}",
        "minecraft:barrel{facing:up,open:false}"
    ]
}
