{
    size: [11, 27, 5],
    data: [
        {pos: [3, 0, 1], state: "minecraft:tuff_bricks"},
        {pos: [3, 0, 2], state: "minecraft:tuff_bricks"},
        {pos: [3, 0, 3], state: "minecraft:tuff_bricks"},
        {pos: [4, 0, 1], state: "minecraft:tuff_bricks"},
        {pos: [4, 0, 2], state: "minecraft:tuff_bricks"},
        {pos: [4, 0, 3], state: "minecraft:tuff_bricks"},
        {pos: [5, 0, 1], state: "minecraft:tuff_bricks"},
        {pos: [5, 0, 2], state: "minecraft:tuff_bricks"},
        {pos: [5, 0, 3], state: "minecraft:tuff_bricks"},
        {pos: [6, 0, 1], state: "minecraft:tuff_bricks"},
        {pos: [6, 0, 2], state: "minecraft:tuff_bricks"},
        {pos: [6, 0, 3], state: "minecraft:tuff_bricks"},
        {pos: [3, 1, 1], state: "minecraft:tuff_bricks"},
        {pos: [3, 1, 2], state: "minecraft:tuff_bricks"},
        {pos: [3, 1, 3], state: "minecraft:tuff_bricks"},
        {pos: [4, 1, 1], state: "minecraft:tuff_bricks"},
        {pos: [4, 1, 2], state: "minecraft:pointed_dripstone{thickness:tip,vertical_direction:up,waterlogged:false}"},
        {pos: [4, 1, 3], state: "minecraft:tuff_bricks"},
        {pos: [5, 1, 1], state: "minecraft:tuff_bricks"},
        {pos: [5, 1, 2], state: "minecraft:pointed_dripstone{thickness:tip,vertical_direction:up,waterlogged:false}"},
        {pos: [5, 1, 3], state: "minecraft:tuff_bricks"},
        {pos: [6, 1, 1], state: "minecraft:tuff_bricks"},
        {pos: [6, 1, 2], state: "minecraft:tuff_bricks"},
        {pos: [6, 1, 3], state: "minecraft:tuff_bricks"},
        {pos: [3, 2, 1], state: "minecraft:tuff_bricks"},
        {pos: [3, 2, 2], state: "minecraft:tuff_bricks"},
        {pos: [3, 2, 3], state: "minecraft:tuff_bricks"},
        {pos: [4, 2, 1], state: "minecraft:tuff_bricks"},
        {pos: [4, 2, 2], state: "minecraft:air"},
        {pos: [4, 2, 3], state: "minecraft:tuff_bricks"},
        {pos: [5, 2, 1], state: "minecraft:tuff_bricks"},
        {pos: [5, 2, 2], state: "minecraft:ladder{facing:west,waterlogged:false}"},
        {pos: [5, 2, 3], state: "minecraft:tuff_bricks"},
        {pos: [6, 2, 1], state: "minecraft:tuff_bricks"},
        {pos: [6, 2, 2], state: "minecraft:tuff_bricks"},
        {pos: [6, 2, 3], state: "minecraft:tuff_bricks"},
        {pos: [3, 3, 1], state: "minecraft:tuff_bricks"},
        {pos: [3, 3, 2], state: "minecraft:tuff_bricks"},
        {pos: [3, 3, 3], state: "minecraft:tuff_bricks"},
        {pos: [4, 3, 1], state: "minecraft:tuff_bricks"},
        {pos: [4, 3, 2], state: "minecraft:air"},
        {pos: [4, 3, 3], state: "minecraft:tuff_bricks"},
        {pos: [5, 3, 1], state: "minecraft:tuff_bricks"},
        {pos: [5, 3, 2], state: "minecraft:ladder{facing:west,waterlogged:false}"},
        {pos: [5, 3, 3], state: "minecraft:tuff_bricks"},
        {pos: [6, 3, 1], state: "minecraft:tuff_bricks"},
        {pos: [6, 3, 2], state: "minecraft:tuff_bricks"},
        {pos: [6, 3, 3], state: "minecraft:tuff_bricks"},
        {pos: [3, 4, 1], state: "minecraft:tuff_bricks"},
        {pos: [3, 4, 2], state: "minecraft:tuff_bricks"},
        {pos: [3, 4, 3], state: "minecraft:tuff_bricks"},
        {pos: [4, 4, 1], state: "minecraft:tuff_bricks"},
        {pos: [4, 4, 2], state: "minecraft:air"},
        {pos: [4, 4, 3], state: "minecraft:tuff_bricks"},
        {pos: [5, 4, 1], state: "minecraft:tuff_bricks"},
        {pos: [5, 4, 2], state: "minecraft:ladder{facing:west,waterlogged:false}"},
        {pos: [5, 4, 3], state: "minecraft:tuff_bricks"},
        {pos: [6, 4, 1], state: "minecraft:tuff_bricks"},
        {pos: [6, 4, 2], state: "minecraft:tuff_bricks"},
        {pos: [6, 4, 3], state: "minecraft:tuff_bricks"},
        {pos: [3, 5, 1], state: "minecraft:tuff_bricks"},
        {pos: [3, 5, 2], state: "minecraft:tuff_bricks"},
        {pos: [3, 5, 3], state: "minecraft:tuff_bricks"},
        {pos: [4, 5, 1], state: "minecraft:tuff_bricks"},
        {pos: [4, 5, 2], state: "minecraft:air"},
        {pos: [4, 5, 3], state: "minecraft:tuff_bricks"},
        {pos: [5, 5, 1], state: "minecraft:tuff_bricks"},
        {pos: [5, 5, 2], state: "minecraft:ladder{facing:west,waterlogged:false}"},
        {pos: [5, 5, 3], state: "minecraft:tuff_bricks"},
        {pos: [6, 5, 1], state: "minecraft:tuff_bricks"},
        {pos: [6, 5, 2], state: "minecraft:tuff_bricks"},
        {pos: [6, 5, 3], state: "minecraft:tuff_bricks"},
        {pos: [3, 6, 1], state: "minecraft:tuff_bricks"},
        {pos: [3, 6, 2], state: "minecraft:tuff_bricks"},
        {pos: [3, 6, 3], state: "minecraft:tuff_bricks"},
        {pos: [4, 6, 1], state: "minecraft:tuff_bricks"},
        {pos: [4, 6, 2], state: "minecraft:air"},
        {pos: [4, 6, 3], state: "minecraft:tuff_bricks"},
        {pos: [5, 6, 1], state: "minecraft:tuff_bricks"},
        {pos: [5, 6, 2], state: "minecraft:ladder{facing:west,waterlogged:false}"},
        {pos: [5, 6, 3], state: "minecraft:tuff_bricks"},
        {pos: [6, 6, 1], state: "minecraft:tuff_bricks"},
        {pos: [6, 6, 2], state: "minecraft:tuff_bricks"},
        {pos: [6, 6, 3], state: "minecraft:tuff_bricks"},
        {pos: [3, 7, 1], state: "minecraft:tuff_bricks"},
        {pos: [3, 7, 2], state: "minecraft:tuff_bricks"},
        {pos: [3, 7, 3], state: "minecraft:tuff_bricks"},
        {pos: [4, 7, 1], state: "minecraft:tuff_bricks"},
        {pos: [4, 7, 2], state: "minecraft:air"},
        {pos: [4, 7, 3], state: "minecraft:tuff_bricks"},
        {pos: [5, 7, 1], state: "minecraft:tuff_bricks"},
        {pos: [5, 7, 2], state: "minecraft:ladder{facing:west,waterlogged:false}"},
        {pos: [5, 7, 3], state: "minecraft:tuff_bricks"},
        {pos: [6, 7, 1], state: "minecraft:tuff_bricks"},
        {pos: [6, 7, 2], state: "minecraft:tuff_bricks"},
        {pos: [6, 7, 3], state: "minecraft:tuff_bricks"},
        {pos: [3, 8, 1], state: "minecraft:tuff_bricks"},
        {pos: [3, 8, 2], state: "minecraft:tuff_bricks"},
        {pos: [3, 8, 3], state: "minecraft:tuff_bricks"},
        {pos: [4, 8, 1], state: "minecraft:tuff_bricks"},
        {pos: [4, 8, 2], state: "minecraft:air"},
        {pos: [4, 8, 3], state: "minecraft:tuff_bricks"},
        {pos: [5, 8, 1], state: "minecraft:tuff_bricks"},
        {pos: [5, 8, 2], state: "minecraft:ladder{facing:west,waterlogged:false}"},
        {pos: [5, 8, 3], state: "minecraft:tuff_bricks"},
        {pos: [6, 8, 1], state: "minecraft:tuff_bricks"},
        {pos: [6, 8, 2], state: "minecraft:tuff_bricks"},
        {pos: [6, 8, 3], state: "minecraft:tuff_bricks"},
        {pos: [3, 9, 1], state: "minecraft:tuff_bricks"},
        {pos: [3, 9, 2], state: "minecraft:tuff_bricks"},
        {pos: [3, 9, 3], state: "minecraft:tuff_bricks"},
        {pos: [4, 9, 1], state: "minecraft:tuff_bricks"},
        {pos: [4, 9, 2], state: "minecraft:air"},
        {pos: [4, 9, 3], state: "minecraft:tuff_bricks"},
        {pos: [5, 9, 1], state: "minecraft:tuff_bricks"},
        {pos: [5, 9, 2], state: "minecraft:ladder{facing:west,waterlogged:false}"},
        {pos: [5, 9, 3], state: "minecraft:tuff_bricks"},
        {pos: [6, 9, 1], state: "minecraft:tuff_bricks"},
        {pos: [6, 9, 2], state: "minecraft:tuff_bricks"},
        {pos: [6, 9, 3], state: "minecraft:tuff_bricks"},
        {pos: [0, 10, 0], state: "minecraft:tuff_bricks"},
        {pos: [0, 10, 1], state: "minecraft:tuff_bricks"},
        {pos: [0, 10, 2], state: "minecraft:tuff_bricks"},
        {pos: [0, 10, 3], state: "minecraft:tuff_bricks"},
        {pos: [0, 10, 4], state: "minecraft:tuff_bricks"},
        {pos: [1, 10, 0], state: "minecraft:tuff_bricks"},
        {pos: [1, 10, 1], state: "minecraft:tuff_bricks"},
        {pos: [1, 10, 2], state: "minecraft:tuff_bricks"},
        {pos: [1, 10, 3], state: "minecraft:tuff_bricks"},
        {pos: [1, 10, 4], state: "minecraft:tuff_bricks"},
        {pos: [2, 10, 0], state: "minecraft:tuff_bricks"},
        {pos: [2, 10, 1], state: "minecraft:tuff_bricks"},
        {pos: [2, 10, 2], state: "minecraft:tuff_bricks"},
        {pos: [2, 10, 3], state: "minecraft:tuff_bricks"},
        {pos: [2, 10, 4], state: "minecraft:tuff_bricks"},
        {pos: [3, 10, 0], state: "minecraft:tuff_bricks"},
        {pos: [3, 10, 1], state: "minecraft:tuff_bricks"},
        {pos: [3, 10, 2], state: "minecraft:tuff_bricks"},
        {pos: [3, 10, 3], state: "minecraft:tuff_bricks"},
        {pos: [3, 10, 4], state: "minecraft:tuff_bricks"},
        {pos: [4, 10, 0], state: "minecraft:tuff_bricks"},
        {pos: [4, 10, 1], state: "minecraft:tuff_bricks"},
        {pos: [4, 10, 2], state: "minecraft:air"},
        {pos: [4, 10, 3], state: "minecraft:tuff_bricks"},
        {pos: [4, 10, 4], state: "minecraft:tuff_bricks"},
        {pos: [5, 10, 0], state: "minecraft:tuff_bricks"},
        {pos: [5, 10, 1], state: "minecraft:tuff_bricks"},
        {pos: [5, 10, 2], state: "minecraft:ladder{facing:west,waterlogged:false}"},
        {pos: [5, 10, 3], state: "minecraft:tuff_bricks"},
        {pos: [5, 10, 4], state: "minecraft:tuff_bricks"},
        {pos: [6, 10, 0], state: "minecraft:tuff_bricks"},
        {pos: [6, 10, 1], state: "minecraft:tuff_bricks"},
        {pos: [6, 10, 2], state: "minecraft:tuff_bricks"},
        {pos: [6, 10, 3], state: "minecraft:tuff_bricks"},
        {pos: [6, 10, 4], state: "minecraft:tuff_bricks"},
        {pos: [7, 10, 0], state: "minecraft:tuff_bricks"},
        {pos: [7, 10, 1], state: "minecraft:tuff_bricks"},
        {pos: [7, 10, 2], state: "minecraft:tuff_bricks"},
        {pos: [7, 10, 3], state: "minecraft:tuff_bricks"},
        {pos: [7, 10, 4], state: "minecraft:tuff_bricks"},
        {pos: [8, 10, 0], state: "minecraft:tuff_bricks"},
        {pos: [8, 10, 1], state: "minecraft:tuff_bricks"},
        {pos: [8, 10, 2], state: "minecraft:tuff_bricks"},
        {pos: [8, 10, 3], state: "minecraft:tuff_bricks"},
        {pos: [8, 10, 4], state: "minecraft:tuff_bricks"},
        {pos: [9, 10, 0], state: "minecraft:tuff_bricks"},
        {pos: [9, 10, 1], state: "minecraft:tuff_bricks"},
        {pos: [9, 10, 2], state: "minecraft:tuff_bricks"},
        {pos: [9, 10, 3], state: "minecraft:tuff_bricks"},
        {pos: [9, 10, 4], state: "minecraft:tuff_bricks"},
        {pos: [10, 10, 0], state: "minecraft:tuff_bricks"},
        {pos: [10, 10, 1], state: "minecraft:tuff_bricks"},
        {pos: [10, 10, 2], state: "minecraft:tuff_bricks"},
        {pos: [10, 10, 3], state: "minecraft:tuff_bricks"},
        {pos: [10, 10, 4], state: "minecraft:tuff_bricks"},
        {pos: [0, 11, 0], state: "minecraft:tuff_bricks"},
        {pos: [0, 11, 1], state: "minecraft:tuff_bricks"},
        {pos: [0, 11, 2], state: "minecraft:tuff_bricks"},
        {pos: [0, 11, 3], state: "minecraft:tuff_bricks"},
        {pos: [0, 11, 4], state: "minecraft:tuff_bricks"},
        {pos: [1, 11, 0], state: "minecraft:tuff_bricks"},
        {pos: [1, 11, 1], state: "minecraft:tuff_bricks"},
        {pos: [1, 11, 2], state: "minecraft:tuff_bricks"},
        {pos: [1, 11, 3], state: "minecraft:tuff_bricks"},
        {pos: [1, 11, 4], state: "minecraft:tuff_bricks"},
        {pos: [2, 11, 0], state: "minecraft:tuff_bricks"},
        {pos: [2, 11, 1], state: "minecraft:tuff_bricks"},
        {pos: [2, 11, 2], state: "minecraft:tuff_bricks"},
        {pos: [2, 11, 3], state: "minecraft:tuff_bricks"},
        {pos: [2, 11, 4], state: "minecraft:tuff_bricks"},
        {pos: [3, 11, 0], state: "minecraft:tuff_bricks"},
        {pos: [3, 11, 1], state: "minecraft:waxed_oxidized_copper"},
        {pos: [3, 11, 2], state: "minecraft:waxed_oxidized_copper"},
        {pos: [3, 11, 3], state: "minecraft:waxed_oxidized_cut_copper"},
        {pos: [3, 11, 4], state: "minecraft:tuff_bricks"},
        {pos: [4, 11, 0], state: "minecraft:tuff_bricks"},
        {pos: [4, 11, 1], state: "minecraft:waxed_oxidized_copper"},
        {pos: [4, 11, 2], state: "minecraft:air"},
        {pos: [4, 11, 3], state: "minecraft:waxed_oxidized_cut_copper"},
        {pos: [4, 11, 4], state: "minecraft:tuff_bricks"},
        {pos: [5, 11, 0], state: "minecraft:tuff_bricks"},
        {pos: [5, 11, 1], state: "minecraft:waxed_oxidized_cut_copper"},
        {pos: [5, 11, 2], state: "minecraft:waxed_oxidized_cut_copper"},
        {pos: [5, 11, 3], state: "minecraft:waxed_oxidized_cut_copper"},
        {pos: [5, 11, 4], state: "minecraft:tuff_bricks"},
        {pos: [6, 11, 0], state: "minecraft:tuff_bricks"},
        {pos: [6, 11, 1], state: "minecraft:waxed_oxidized_copper"},
        {pos: [6, 11, 2], state: "minecraft:waxed_oxidized_copper"},
        {pos: [6, 11, 3], state: "minecraft:waxed_oxidized_copper"},
        {pos: [6, 11, 4], state: "minecraft:tuff_bricks"},
        {pos: [7, 11, 0], state: "minecraft:tuff_bricks"},
        {pos: [7, 11, 1], state: "minecraft:waxed_oxidized_copper"},
        {pos: [7, 11, 2], state: "minecraft:waxed_oxidized_copper"},
        {pos: [7, 11, 3], state: "minecraft:waxed_oxidized_copper"},
        {pos: [7, 11, 4], state: "minecraft:tuff_bricks"},
        {pos: [8, 11, 0], state: "minecraft:tuff_bricks"},
        {pos: [8, 11, 1], state: "minecraft:waxed_oxidized_copper"},
        {pos: [8, 11, 2], state: "minecraft:waxed_oxidized_copper"},
        {pos: [8, 11, 3], state: "minecraft:waxed_oxidized_copper"},
        {pos: [8, 11, 4], state: "minecraft:tuff_bricks"},
        {pos: [9, 11, 0], state: "minecraft:tuff_bricks"},
        {pos: [9, 11, 1], state: "minecraft:waxed_oxidized_copper"},
        {pos: [9, 11, 2], state: "minecraft:waxed_oxidized_copper"},
        {pos: [9, 11, 3], state: "minecraft:waxed_oxidized_copper"},
        {pos: [9, 11, 4], state: "minecraft:tuff_bricks"},
        {pos: [10, 11, 0], state: "minecraft:tuff_bricks"},
        {pos: [10, 11, 1], state: "minecraft:waxed_oxidized_copper"},
        {pos: [10, 11, 2], state: "minecraft:waxed_oxidized_copper"},
        {pos: [10, 11, 3], state: "minecraft:waxed_oxidized_copper"},
        {pos: [10, 11, 4], state: "minecraft:tuff_bricks"},
        {pos: [0, 12, 0], state: "minecraft:tuff_bricks"},
        {pos: [0, 12, 1], state: "minecraft:tuff_bricks"},
        {pos: [0, 12, 2], state: "minecraft:tuff_bricks"},
        {pos: [0, 12, 3], state: "minecraft:tuff_bricks"},
        {pos: [0, 12, 4], state: "minecraft:tuff_bricks"},
        {pos: [1, 12, 0], state: "minecraft:tuff_bricks"},
        {pos: [1, 12, 1], state: "minecraft:tuff_bricks"},
        {pos: [1, 12, 2], state: "minecraft:tuff_bricks"},
        {pos: [1, 12, 3], state: "minecraft:tuff_bricks"},
        {pos: [1, 12, 4], state: "minecraft:tuff_bricks"},
        {pos: [2, 12, 0], state: "minecraft:waxed_copper_block"},
        {pos: [2, 12, 1], state: "minecraft:waxed_copper_block"},
        {pos: [2, 12, 2], state: "minecraft:waxed_copper_block"},
        {pos: [2, 12, 3], state: "minecraft:waxed_copper_block"},
        {pos: [2, 12, 4], state: "minecraft:waxed_copper_block"},
        {pos: [3, 12, 0], state: "minecraft:waxed_copper_block"},
        {pos: [3, 12, 1], state: "minecraft:waxed_oxidized_copper"},
        {pos: [3, 12, 2], state: "minecraft:waxed_oxidized_cut_copper_stairs{facing:north,half:bottom,shape:straight,waterlogged:false}"},
        {pos: [3, 12, 3], state: "minecraft:air"},
        {pos: [3, 12, 4], state: "minecraft:waxed_copper_block"},
        {pos: [4, 12, 0], state: "minecraft:waxed_copper_block"},
        {pos: [4, 12, 1], state: "minecraft:waxed_oxidized_copper"},
        {pos: [4, 12, 2], state: "minecraft:air"},
        {pos: [4, 12, 3], state: "minecraft:air"},
        {pos: [4, 12, 4], state: "minecraft:waxed_copper_block"},
        {pos: [5, 12, 0], state: "minecraft:waxed_copper_block"},
        {pos: [5, 12, 1], state: "minecraft:air"},
        {pos: [5, 12, 2], state: "minecraft:air"},
        {pos: [5, 12, 3], state: "minecraft:air"},
        {pos: [5, 12, 4], state: "minecraft:waxed_copper_block"},
        {pos: [6, 12, 0], state: "minecraft:waxed_copper_block"},
        {pos: [6, 12, 1], state: "minecraft:air"},
        {pos: [6, 12, 2], state: "minecraft:air"},
        {pos: [6, 12, 3], state: "minecraft:air"},
        {pos: [6, 12, 4], state: "minecraft:waxed_copper_block"},
        {pos: [7, 12, 0], state: "minecraft:waxed_copper_block"},
        {pos: [7, 12, 1], state: "minecraft:air"},
        {pos: [7, 12, 2], state: "minecraft:air"},
        {pos: [7, 12, 3], state: "minecraft:air"},
        {pos: [7, 12, 4], state: "minecraft:waxed_copper_block"},
        {pos: [8, 12, 0], state: "minecraft:waxed_copper_block"},
        {pos: [8, 12, 1], state: "minecraft:air"},
        {pos: [8, 12, 2], state: "minecraft:air"},
        {pos: [8, 12, 3], state: "minecraft:air"},
        {pos: [8, 12, 4], state: "minecraft:waxed_copper_block"},
        {pos: [9, 12, 0], state: "minecraft:waxed_copper_block"},
        {pos: [9, 12, 1], state: "minecraft:air"},
        {pos: [9, 12, 2], state: "minecraft:air"},
        {pos: [9, 12, 3], state: "minecraft:air"},
        {pos: [9, 12, 4], state: "minecraft:waxed_copper_block"},
        {pos: [10, 12, 0], state: "minecraft:waxed_copper_block"},
        {pos: [10, 12, 1], state: "minecraft:air"},
        {pos: [10, 12, 2], state: "minecraft:air"},
        {pos: [10, 12, 3], state: "minecraft:air"},
        {pos: [10, 12, 4], state: "minecraft:waxed_copper_block"},
        {pos: [0, 13, 0], state: "minecraft:tuff_bricks"},
        {pos: [0, 13, 1], state: "minecraft:tuff_bricks"},
        {pos: [0, 13, 2], state: "minecraft:tuff_bricks"},
        {pos: [0, 13, 3], state: "minecraft:tuff_bricks"},
        {pos: [0, 13, 4], state: "minecraft:tuff_bricks"},
        {pos: [1, 13, 0], state: "minecraft:tuff_bricks"},
        {pos: [1, 13, 1], state: "minecraft:tuff_bricks"},
        {pos: [1, 13, 2], state: "minecraft:tuff_bricks"},
        {pos: [1, 13, 3], state: "minecraft:tuff_bricks"},
        {pos: [1, 13, 4], state: "minecraft:tuff_bricks"},
        {pos: [2, 13, 0], state: "minecraft:tuff_bricks"},
        {pos: [2, 13, 1], state: "minecraft:tuff_bricks"},
        {pos: [2, 13, 2], state: "minecraft:tuff_bricks"},
        {pos: [2, 13, 3], state: "minecraft:tuff_bricks"},
        {pos: [2, 13, 4], state: "minecraft:tuff_bricks"},
        {pos: [3, 13, 0], state: "minecraft:tuff_bricks"},
        {pos: [3, 13, 1], state: "minecraft:air"},
        {pos: [3, 13, 2], state: "minecraft:air"},
        {pos: [3, 13, 3], state: "minecraft:air"},
        {pos: [3, 13, 4], state: "minecraft:tuff_bricks"},
        {pos: [4, 13, 0], state: "minecraft:tuff_bricks"},
        {pos: [4, 13, 1], state: "minecraft:waxed_oxidized_cut_copper_stairs{facing:east,half:bottom,shape:straight,waterlogged:false}"},
        {pos: [4, 13, 2], state: "minecraft:air"},
        {pos: [4, 13, 3], state: "minecraft:air"},
        {pos: [4, 13, 4], state: "minecraft:tuff_bricks"},
        {pos: [5, 13, 0], state: "minecraft:tuff_bricks"},
        {pos: [5, 13, 1], state: "minecraft:waxed_oxidized_copper"},
        {pos: [5, 13, 2], state: "minecraft:waxed_oxidized_copper"},
        {pos: [5, 13, 3], state: "minecraft:air"},
        {pos: [5, 13, 4], state: "minecraft:tuff_bricks"},
        {pos: [6, 13, 0], state: "minecraft:tuff_bricks"},
        {pos: [6, 13, 1], state: "minecraft:air"},
        {pos: [6, 13, 2], state: "minecraft:air"},
        {pos: [6, 13, 3], state: "minecraft:air"},
        {pos: [6, 13, 4], state: "minecraft:tuff_bricks"},
        {pos: [7, 13, 0], state: "minecraft:waxed_copper_bulb{lit:true,powered:false}"},
        {pos: [7, 13, 1], state: "minecraft:air"},
        {pos: [7, 13, 2], state: "minecraft:air"},
        {pos: [7, 13, 3], state: "minecraft:air"},
        {pos: [7, 13, 4], state: "minecraft:tuff_bricks"},
        {pos: [8, 13, 0], state: "minecraft:tuff_bricks"},
        {pos: [8, 13, 1], state: "minecraft:air"},
        {pos: [8, 13, 2], state: "minecraft:air"},
        {pos: [8, 13, 3], state: "minecraft:air"},
        {pos: [8, 13, 4], state: "minecraft:tuff_bricks"},
        {pos: [9, 13, 0], state: "minecraft:tuff_bricks"},
        {pos: [9, 13, 1], state: "minecraft:air"},
        {pos: [9, 13, 2], state: "minecraft:air"},
        {pos: [9, 13, 3], state: "minecraft:air"},
        {pos: [9, 13, 4], state: "minecraft:tuff_bricks"},
        {pos: [10, 13, 0], state: "minecraft:tuff_bricks"},
        {pos: [10, 13, 1], state: "minecraft:air"},
        {pos: [10, 13, 2], state: "minecraft:jigsaw{orientation:east_up}", nbt: {final_state: "minecraft:air", id: "minecraft:jigsaw", joint: "rollable", name: "minecraft:empty", placement_priority: 0, pool: "minecraft:trial_chambers/hallway", selection_priority: 0, target: "minecraft:in_connector"}},
        {pos: [10, 13, 3], state: "minecraft:air"},
        {pos: [10, 13, 4], state: "minecraft:tuff_bricks"},
        {pos: [0, 14, 0], state: "minecraft:tuff_bricks"},
        {pos: [0, 14, 1], state: "minecraft:tuff_bricks"},
        {pos: [0, 14, 2], state: "minecraft:tuff_bricks"},
        {pos: [0, 14, 3], state: "minecraft:tuff_bricks"},
        {pos: [0, 14, 4], state: "minecraft:tuff_bricks"},
        {pos: [1, 14, 0], state: "minecraft:tuff_bricks"},
        {pos: [1, 14, 1], state: "minecraft:tuff_bricks"},
        {pos: [1, 14, 2], state: "minecraft:tuff_bricks"},
        {pos: [1, 14, 3], state: "minecraft:tuff_bricks"},
        {pos: [1, 14, 4], state: "minecraft:tuff_bricks"},
        {pos: [2, 14, 0], state: "minecraft:chiseled_tuff_bricks"},
        {pos: [2, 14, 1], state: "minecraft:chiseled_tuff_bricks"},
        {pos: [2, 14, 2], state: "minecraft:chiseled_tuff_bricks"},
        {pos: [2, 14, 3], state: "minecraft:chiseled_tuff_bricks"},
        {pos: [2, 14, 4], state: "minecraft:chiseled_tuff_bricks"},
        {pos: [3, 14, 0], state: "minecraft:chiseled_tuff_bricks"},
        {pos: [3, 14, 1], state: "minecraft:air"},
        {pos: [3, 14, 2], state: "minecraft:air"},
        {pos: [3, 14, 3], state: "minecraft:air"},
        {pos: [3, 14, 4], state: "minecraft:chiseled_tuff_bricks"},
        {pos: [4, 14, 0], state: "minecraft:chiseled_tuff_bricks"},
        {pos: [4, 14, 1], state: "minecraft:air"},
        {pos: [4, 14, 2], state: "minecraft:air"},
        {pos: [4, 14, 3], state: "minecraft:waxed_oxidized_copper"},
        {pos: [4, 14, 4], state: "minecraft:chiseled_tuff_bricks"},
        {pos: [5, 14, 0], state: "minecraft:chiseled_tuff_bricks"},
        {pos: [5, 14, 1], state: "minecraft:air"},
        {pos: [5, 14, 2], state: "minecraft:waxed_oxidized_cut_copper_stairs{facing:south,half:bottom,shape:straight,waterlogged:false}"},
        {pos: [5, 14, 3], state: "minecraft:waxed_oxidized_copper"},
        {pos: [5, 14, 4], state: "minecraft:chiseled_tuff_bricks"},
        {pos: [6, 14, 0], state: "minecraft:chiseled_tuff_bricks"},
        {pos: [6, 14, 1], state: "minecraft:air"},
        {pos: [6, 14, 2], state: "minecraft:air"},
        {pos: [6, 14, 3], state: "minecraft:air"},
        {pos: [6, 14, 4], state: "minecraft:chiseled_tuff_bricks"},
        {pos: [7, 14, 0], state: "minecraft:chiseled_tuff_bricks"},
        {pos: [7, 14, 1], state: "minecraft:air"},
        {pos: [7, 14, 2], state: "minecraft:air"},
        {pos: [7, 14, 3], state: "minecraft:air"},
        {pos: [7, 14, 4], state: "minecraft:chiseled_tuff_bricks"},
        {pos: [8, 14, 0], state: "minecraft:chiseled_tuff_bricks"},
        {pos: [8, 14, 1], state: "minecraft:air"},
        {pos: [8, 14, 2], state: "minecraft:air"},
        {pos: [8, 14, 3], state: "minecraft:air"},
        {pos: [8, 14, 4], state: "minecraft:chiseled_tuff_bricks"},
        {pos: [9, 14, 0], state: "minecraft:chiseled_tuff_bricks"},
        {pos: [9, 14, 1], state: "minecraft:air"},
        {pos: [9, 14, 2], state: "minecraft:air"},
        {pos: [9, 14, 3], state: "minecraft:air"},
        {pos: [9, 14, 4], state: "minecraft:chiseled_tuff_bricks"},
        {pos: [10, 14, 0], state: "minecraft:chiseled_tuff_bricks"},
        {pos: [10, 14, 1], state: "minecraft:air"},
        {pos: [10, 14, 2], state: "minecraft:air"},
        {pos: [10, 14, 3], state: "minecraft:air"},
        {pos: [10, 14, 4], state: "minecraft:chiseled_tuff_bricks"},
        {pos: [0, 15, 0], state: "minecraft:tuff_bricks"},
        {pos: [0, 15, 1], state: "minecraft:tuff_bricks"},
        {pos: [0, 15, 2], state: "minecraft:tuff_bricks"},
        {pos: [0, 15, 3], state: "minecraft:tuff_bricks"},
        {pos: [0, 15, 4], state: "minecraft:tuff_bricks"},
        {pos: [1, 15, 0], state: "minecraft:tuff_bricks"},
        {pos: [1, 15, 1], state: "minecraft:tuff_bricks"},
        {pos: [1, 15, 2], state: "minecraft:tuff_bricks"},
        {pos: [1, 15, 3], state: "minecraft:tuff_bricks"},
        {pos: [1, 15, 4], state: "minecraft:tuff_bricks"},
        {pos: [2, 15, 0], state: "minecraft:tuff_bricks"},
        {pos: [2, 15, 1], state: "minecraft:tuff_bricks"},
        {pos: [2, 15, 2], state: "minecraft:tuff_bricks"},
        {pos: [2, 15, 3], state: "minecraft:tuff_bricks"},
        {pos: [2, 15, 4], state: "minecraft:tuff_bricks"},
        {pos: [3, 15, 0], state: "minecraft:tuff_bricks"},
        {pos: [3, 15, 1], state: "minecraft:air"},
        {pos: [3, 15, 2], state: "minecraft:waxed_oxidized_copper"},
        {pos: [3, 15, 3], state: "minecraft:waxed_oxidized_copper"},
        {pos: [3, 15, 4], state: "minecraft:tuff_bricks"},
        {pos: [4, 15, 0], state: "minecraft:tuff_bricks"},
        {pos: [4, 15, 1], state: "minecraft:air"},
        {pos: [4, 15, 2], state: "minecraft:air"},
        {pos: [4, 15, 3], state: "minecraft:waxed_oxidized_cut_copper_stairs{facing:west,half:bottom,shape:straight,waterlogged:false}"},
        {pos: [4, 15, 4], state: "minecraft:tuff_bricks"},
        {pos: [5, 15, 0], state: "minecraft:tuff_bricks"},
        {pos: [5, 15, 1], state: "minecraft:air"},
        {pos: [5, 15, 2], state: "minecraft:air"},
        {pos: [5, 15, 3], state: "minecraft:air"},
        {pos: [5, 15, 4], state: "minecraft:tuff_bricks"},
        {pos: [6, 15, 0], state: "minecraft:tuff_bricks"},
        {pos: [6, 15, 1], state: "minecraft:air"},
        {pos: [6, 15, 2], state: "minecraft:air"},
        {pos: [6, 15, 3], state: "minecraft:air"},
        {pos: [6, 15, 4], state: "minecraft:tuff_bricks"},
        {pos: [7, 15, 0], state: "minecraft:tuff_bricks"},
        {pos: [7, 15, 1], state: "minecraft:air"},
        {pos: [7, 15, 2], state: "minecraft:air"},
        {pos: [7, 15, 3], state: "minecraft:air"},
        {pos: [7, 15, 4], state: "minecraft:tuff_bricks"},
        {pos: [8, 15, 0], state: "minecraft:tuff_bricks"},
        {pos: [8, 15, 1], state: "minecraft:air"},
        {pos: [8, 15, 2], state: "minecraft:air"},
        {pos: [8, 15, 3], state: "minecraft:air"},
        {pos: [8, 15, 4], state: "minecraft:tuff_bricks"},
        {pos: [9, 15, 0], state: "minecraft:tuff_bricks"},
        {pos: [9, 15, 1], state: "minecraft:air"},
        {pos: [9, 15, 2], state: "minecraft:air"},
        {pos: [9, 15, 3], state: "minecraft:air"},
        {pos: [9, 15, 4], state: "minecraft:tuff_bricks"},
        {pos: [10, 15, 0], state: "minecraft:tuff_bricks"},
        {pos: [10, 15, 1], state: "minecraft:air"},
        {pos: [10, 15, 2], state: "minecraft:air"},
        {pos: [10, 15, 3], state: "minecraft:air"},
        {pos: [10, 15, 4], state: "minecraft:tuff_bricks"},
        {pos: [0, 16, 0], state: "minecraft:tuff_bricks"},
        {pos: [0, 16, 1], state: "minecraft:tuff_bricks"},
        {pos: [0, 16, 2], state: "minecraft:tuff_bricks"},
        {pos: [0, 16, 3], state: "minecraft:tuff_bricks"},
        {pos: [0, 16, 4], state: "minecraft:tuff_bricks"},
        {pos: [1, 16, 0], state: "minecraft:tuff_bricks"},
        {pos: [1, 16, 1], state: "minecraft:tuff_bricks"},
        {pos: [1, 16, 2], state: "minecraft:tuff_bricks"},
        {pos: [1, 16, 3], state: "minecraft:tuff_bricks"},
        {pos: [1, 16, 4], state: "minecraft:tuff_bricks"},
        {pos: [2, 16, 0], state: "minecraft:tuff_bricks"},
        {pos: [2, 16, 1], state: "minecraft:polished_tuff"},
        {pos: [2, 16, 2], state: "minecraft:polished_tuff"},
        {pos: [2, 16, 3], state: "minecraft:polished_tuff"},
        {pos: [2, 16, 4], state: "minecraft:tuff_bricks"},
        {pos: [3, 16, 0], state: "minecraft:tuff_bricks"},
        {pos: [3, 16, 1], state: "minecraft:waxed_oxidized_copper"},
        {pos: [3, 16, 2], state: "minecraft:waxed_oxidized_cut_copper_stairs{facing:north,half:bottom,shape:straight,waterlogged:false}"},
        {pos: [3, 16, 3], state: "minecraft:air"},
        {pos: [3, 16, 4], state: "minecraft:tuff_bricks"},
        {pos: [4, 16, 0], state: "minecraft:tuff_bricks"},
        {pos: [4, 16, 1], state: "minecraft:waxed_oxidized_copper"},
        {pos: [4, 16, 2], state: "minecraft:air"},
        {pos: [4, 16, 3], state: "minecraft:air"},
        {pos: [4, 16, 4], state: "minecraft:tuff_bricks"},
        {pos: [5, 16, 0], state: "minecraft:tuff_bricks"},
        {pos: [5, 16, 1], state: "minecraft:air"},
        {pos: [5, 16, 2], state: "minecraft:air"},
        {pos: [5, 16, 3], state: "minecraft:air"},
        {pos: [5, 16, 4], state: "minecraft:tuff_bricks"},
        {pos: [6, 16, 0], state: "minecraft:tuff_bricks"},
        {pos: [6, 16, 1], state: "minecraft:air"},
        {pos: [6, 16, 2], state: "minecraft:air"},
        {pos: [6, 16, 3], state: "minecraft:air"},
        {pos: [6, 16, 4], state: "minecraft:tuff_bricks"},
        {pos: [7, 16, 0], state: "minecraft:tuff_bricks"},
        {pos: [7, 16, 1], state: "minecraft:air"},
        {pos: [7, 16, 2], state: "minecraft:air"},
        {pos: [7, 16, 3], state: "minecraft:air"},
        {pos: [7, 16, 4], state: "minecraft:tuff_bricks"},
        {pos: [8, 16, 0], state: "minecraft:tuff_bricks"},
        {pos: [8, 16, 1], state: "minecraft:polished_tuff"},
        {pos: [8, 16, 2], state: "minecraft:polished_tuff"},
        {pos: [8, 16, 3], state: "minecraft:polished_tuff"},
        {pos: [8, 16, 4], state: "minecraft:tuff_bricks"},
        {pos: [9, 16, 0], state: "minecraft:tuff_bricks"},
        {pos: [9, 16, 1], state: "minecraft:polished_tuff"},
        {pos: [9, 16, 2], state: "minecraft:polished_tuff"},
        {pos: [9, 16, 3], state: "minecraft:polished_tuff"},
        {pos: [9, 16, 4], state: "minecraft:tuff_bricks"},
        {pos: [10, 16, 0], state: "minecraft:tuff_bricks"},
        {pos: [10, 16, 1], state: "minecraft:polished_tuff"},
        {pos: [10, 16, 2], state: "minecraft:polished_tuff"},
        {pos: [10, 16, 3], state: "minecraft:polished_tuff"},
        {pos: [10, 16, 4], state: "minecraft:tuff_bricks"},
        {pos: [0, 17, 0], state: "minecraft:tuff_bricks"},
        {pos: [0, 17, 1], state: "minecraft:tuff_bricks"},
        {pos: [0, 17, 2], state: "minecraft:tuff_bricks"},
        {pos: [0, 17, 3], state: "minecraft:tuff_bricks"},
        {pos: [0, 17, 4], state: "minecraft:tuff_bricks"},
        {pos: [1, 17, 0], state: "minecraft:tuff_bricks"},
        {pos: [1, 17, 1], state: "minecraft:tuff_bricks"},
        {pos: [1, 17, 2], state: "minecraft:tuff_bricks"},
        {pos: [1, 17, 3], state: "minecraft:tuff_bricks"},
        {pos: [1, 17, 4], state: "minecraft:tuff_bricks"},
        {pos: [2, 17, 0], state: "minecraft:tuff_bricks"},
        {pos: [2, 17, 1], state: "minecraft:tuff_bricks"},
        {pos: [2, 17, 2], state: "minecraft:tuff_bricks"},
        {pos: [2, 17, 3], state: "minecraft:tuff_bricks"},
        {pos: [2, 17, 4], state: "minecraft:tuff_bricks"},
        {pos: [3, 17, 0], state: "minecraft:tuff_bricks"},
        {pos: [3, 17, 1], state: "minecraft:air"},
        {pos: [3, 17, 2], state: "minecraft:air"},
        {pos: [3, 17, 3], state: "minecraft:air"},
        {pos: [3, 17, 4], state: "minecraft:tuff_bricks"},
        {pos: [4, 17, 0], state: "minecraft:tuff_bricks"},
        {pos: [4, 17, 1], state: "minecraft:waxed_oxidized_cut_copper_stairs{facing:east,half:bottom,shape:straight,waterlogged:false}"},
        {pos: [4, 17, 2], state: "minecraft:air"},
        {pos: [4, 17, 3], state: "minecraft:air"},
        {pos: [4, 17, 4], state: "minecraft:tuff_bricks"},
        {pos: [5, 17, 0], state: "minecraft:tuff_bricks"},
        {pos: [5, 17, 1], state: "minecraft:waxed_oxidized_copper"},
        {pos: [5, 17, 2], state: "minecraft:waxed_oxidized_copper"},
        {pos: [5, 17, 3], state: "minecraft:air"},
        {pos: [5, 17, 4], state: "minecraft:tuff_bricks"},
        {pos: [6, 17, 0], state: "minecraft:tuff_bricks"},
        {pos: [6, 17, 1], state: "minecraft:polished_tuff"},
        {pos: [6, 17, 2], state: "minecraft:polished_tuff"},
        {pos: [6, 17, 3], state: "minecraft:polished_tuff"},
        {pos: [6, 17, 4], state: "minecraft:tuff_bricks"},
        {pos: [7, 17, 0], state: "minecraft:tuff_bricks"},
        {pos: [7, 17, 1], state: "minecraft:polished_tuff"},
        {pos: [7, 17, 2], state: "minecraft:polished_tuff"},
        {pos: [7, 17, 3], state: "minecraft:polished_tuff"},
        {pos: [7, 17, 4], state: "minecraft:tuff_bricks"},
        {pos: [8, 17, 0], state: "minecraft:tuff_bricks"},
        {pos: [8, 17, 1], state: "minecraft:tuff_bricks"},
        {pos: [8, 17, 2], state: "minecraft:tuff_bricks"},
        {pos: [8, 17, 3], state: "minecraft:tuff_bricks"},
        {pos: [8, 17, 4], state: "minecraft:tuff_bricks"},
        {pos: [9, 17, 0], state: "minecraft:tuff_bricks"},
        {pos: [9, 17, 1], state: "minecraft:tuff_bricks"},
        {pos: [9, 17, 2], state: "minecraft:tuff_bricks"},
        {pos: [9, 17, 3], state: "minecraft:tuff_bricks"},
        {pos: [9, 17, 4], state: "minecraft:tuff_bricks"},
        {pos: [10, 17, 0], state: "minecraft:tuff_bricks"},
        {pos: [10, 17, 1], state: "minecraft:tuff_bricks"},
        {pos: [10, 17, 2], state: "minecraft:tuff_bricks"},
        {pos: [10, 17, 3], state: "minecraft:tuff_bricks"},
        {pos: [10, 17, 4], state: "minecraft:tuff_bricks"},
        {pos: [0, 18, 0], state: "minecraft:tuff_bricks"},
        {pos: [0, 18, 1], state: "minecraft:tuff_bricks"},
        {pos: [0, 18, 2], state: "minecraft:tuff_bricks"},
        {pos: [0, 18, 3], state: "minecraft:tuff_bricks"},
        {pos: [0, 18, 4], state: "minecraft:tuff_bricks"},
        {pos: [1, 18, 0], state: "minecraft:tuff_bricks"},
        {pos: [1, 18, 1], state: "minecraft:tuff_bricks"},
        {pos: [1, 18, 2], state: "minecraft:tuff_bricks"},
        {pos: [1, 18, 3], state: "minecraft:tuff_bricks"},
        {pos: [1, 18, 4], state: "minecraft:tuff_bricks"},
        {pos: [2, 18, 0], state: "minecraft:tuff_bricks"},
        {pos: [2, 18, 1], state: "minecraft:tuff_bricks"},
        {pos: [2, 18, 2], state: "minecraft:tuff_bricks"},
        {pos: [2, 18, 3], state: "minecraft:tuff_bricks"},
        {pos: [2, 18, 4], state: "minecraft:tuff_bricks"},
        {pos: [3, 18, 0], state: "minecraft:tuff_bricks"},
        {pos: [3, 18, 1], state: "minecraft:air"},
        {pos: [3, 18, 2], state: "minecraft:air"},
        {pos: [3, 18, 3], state: "minecraft:air"},
        {pos: [3, 18, 4], state: "minecraft:tuff_bricks"},
        {pos: [4, 18, 0], state: "minecraft:tuff_bricks"},
        {pos: [4, 18, 1], state: "minecraft:air"},
        {pos: [4, 18, 2], state: "minecraft:air"},
        {pos: [4, 18, 3], state: "minecraft:waxed_oxidized_copper"},
        {pos: [4, 18, 4], state: "minecraft:tuff_bricks"},
        {pos: [5, 18, 0], state: "minecraft:tuff_bricks"},
        {pos: [5, 18, 1], state: "minecraft:air"},
        {pos: [5, 18, 2], state: "minecraft:waxed_oxidized_cut_copper_stairs{facing:south,half:bottom,shape:straight,waterlogged:false}"},
        {pos: [5, 18, 3], state: "minecraft:waxed_oxidized_copper"},
        {pos: [5, 18, 4], state: "minecraft:tuff_bricks"},
        {pos: [6, 18, 0], state: "minecraft:tuff_bricks"},
        {pos: [6, 18, 1], state: "minecraft:tuff_bricks"},
        {pos: [6, 18, 2], state: "minecraft:tuff_bricks"},
        {pos: [6, 18, 3], state: "minecraft:tuff_bricks"},
        {pos: [6, 18, 4], state: "minecraft:tuff_bricks"},
        {pos: [7, 18, 0], state: "minecraft:tuff_bricks"},
        {pos: [7, 18, 1], state: "minecraft:tuff_bricks"},
        {pos: [7, 18, 2], state: "minecraft:tuff_bricks"},
        {pos: [7, 18, 3], state: "minecraft:tuff_bricks"},
        {pos: [7, 18, 4], state: "minecraft:tuff_bricks"},
        {pos: [8, 18, 0], state: "minecraft:tuff_bricks"},
        {pos: [8, 18, 1], state: "minecraft:tuff_bricks"},
        {pos: [8, 18, 2], state: "minecraft:tuff_bricks"},
        {pos: [8, 18, 3], state: "minecraft:tuff_bricks"},
        {pos: [8, 18, 4], state: "minecraft:tuff_bricks"},
        {pos: [9, 18, 0], state: "minecraft:tuff_bricks"},
        {pos: [9, 18, 1], state: "minecraft:tuff_bricks"},
        {pos: [9, 18, 2], state: "minecraft:tuff_bricks"},
        {pos: [9, 18, 3], state: "minecraft:tuff_bricks"},
        {pos: [9, 18, 4], state: "minecraft:tuff_bricks"},
        {pos: [10, 18, 0], state: "minecraft:tuff_bricks"},
        {pos: [10, 18, 1], state: "minecraft:tuff_bricks"},
        {pos: [10, 18, 2], state: "minecraft:tuff_bricks"},
        {pos: [10, 18, 3], state: "minecraft:tuff_bricks"},
        {pos: [10, 18, 4], state: "minecraft:tuff_bricks"},
        {pos: [0, 19, 0], state: "minecraft:tuff_bricks"},
        {pos: [0, 19, 1], state: "minecraft:tuff_bricks"},
        {pos: [0, 19, 2], state: "minecraft:tuff_bricks"},
        {pos: [0, 19, 3], state: "minecraft:tuff_bricks"},
        {pos: [0, 19, 4], state: "minecraft:tuff_bricks"},
        {pos: [1, 19, 0], state: "minecraft:tuff_bricks"},
        {pos: [1, 19, 1], state: "minecraft:tuff_bricks"},
        {pos: [1, 19, 2], state: "minecraft:tuff_bricks"},
        {pos: [1, 19, 3], state: "minecraft:tuff_bricks"},
        {pos: [1, 19, 4], state: "minecraft:tuff_bricks"},
        {pos: [2, 19, 0], state: "minecraft:tuff_bricks"},
        {pos: [2, 19, 1], state: "minecraft:tuff_bricks"},
        {pos: [2, 19, 2], state: "minecraft:tuff_bricks"},
        {pos: [2, 19, 3], state: "minecraft:tuff_bricks"},
        {pos: [2, 19, 4], state: "minecraft:tuff_bricks"},
        {pos: [3, 19, 0], state: "minecraft:tuff_bricks"},
        {pos: [3, 19, 1], state: "minecraft:air"},
        {pos: [3, 19, 2], state: "minecraft:waxed_oxidized_copper"},
        {pos: [3, 19, 3], state: "minecraft:waxed_oxidized_copper"},
        {pos: [3, 19, 4], state: "minecraft:tuff_bricks"},
        {pos: [4, 19, 0], state: "minecraft:tuff_bricks"},
        {pos: [4, 19, 1], state: "minecraft:air"},
        {pos: [4, 19, 2], state: "minecraft:air"},
        {pos: [4, 19, 3], state: "minecraft:waxed_oxidized_cut_copper_stairs{facing:west,half:bottom,shape:straight,waterlogged:false}"},
        {pos: [4, 19, 4], state: "minecraft:tuff_bricks"},
        {pos: [5, 19, 0], state: "minecraft:tuff_bricks"},
        {pos: [5, 19, 1], state: "minecraft:air"},
        {pos: [5, 19, 2], state: "minecraft:air"},
        {pos: [5, 19, 3], state: "minecraft:air"},
        {pos: [5, 19, 4], state: "minecraft:tuff_bricks"},
        {pos: [6, 19, 0], state: "minecraft:tuff_bricks"},
        {pos: [6, 19, 1], state: "minecraft:tuff_bricks"},
        {pos: [6, 19, 2], state: "minecraft:tuff_bricks"},
        {pos: [6, 19, 3], state: "minecraft:tuff_bricks"},
        {pos: [6, 19, 4], state: "minecraft:tuff_bricks"},
        {pos: [7, 19, 0], state: "minecraft:tuff_bricks"},
        {pos: [7, 19, 1], state: "minecraft:tuff_bricks"},
        {pos: [7, 19, 2], state: "minecraft:tuff_bricks"},
        {pos: [7, 19, 3], state: "minecraft:tuff_bricks"},
        {pos: [7, 19, 4], state: "minecraft:tuff_bricks"},
        {pos: [8, 19, 0], state: "minecraft:tuff_bricks"},
        {pos: [8, 19, 1], state: "minecraft:tuff_bricks"},
        {pos: [8, 19, 2], state: "minecraft:tuff_bricks"},
        {pos: [8, 19, 3], state: "minecraft:tuff_bricks"},
        {pos: [8, 19, 4], state: "minecraft:tuff_bricks"},
        {pos: [9, 19, 0], state: "minecraft:tuff_bricks"},
        {pos: [9, 19, 1], state: "minecraft:tuff_bricks"},
        {pos: [9, 19, 2], state: "minecraft:tuff_bricks"},
        {pos: [9, 19, 3], state: "minecraft:tuff_bricks"},
        {pos: [9, 19, 4], state: "minecraft:tuff_bricks"},
        {pos: [10, 19, 0], state: "minecraft:tuff_bricks"},
        {pos: [10, 19, 1], state: "minecraft:tuff_bricks"},
        {pos: [10, 19, 2], state: "minecraft:tuff_bricks"},
        {pos: [10, 19, 3], state: "minecraft:tuff_bricks"},
        {pos: [10, 19, 4], state: "minecraft:tuff_bricks"},
        {pos: [0, 20, 0], state: "minecraft:tuff_bricks"},
        {pos: [0, 20, 1], state: "minecraft:tuff_bricks"},
        {pos: [0, 20, 2], state: "minecraft:tuff_bricks"},
        {pos: [0, 20, 3], state: "minecraft:tuff_bricks"},
        {pos: [0, 20, 4], state: "minecraft:tuff_bricks"},
        {pos: [1, 20, 0], state: "minecraft:tuff_bricks"},
        {pos: [1, 20, 1], state: "minecraft:tuff_bricks"},
        {pos: [1, 20, 2], state: "minecraft:tuff_bricks"},
        {pos: [1, 20, 3], state: "minecraft:tuff_bricks"},
        {pos: [1, 20, 4], state: "minecraft:tuff_bricks"},
        {pos: [2, 20, 0], state: "minecraft:tuff_bricks"},
        {pos: [2, 20, 1], state: "minecraft:tuff_bricks"},
        {pos: [2, 20, 2], state: "minecraft:tuff_bricks"},
        {pos: [2, 20, 3], state: "minecraft:tuff_bricks"},
        {pos: [2, 20, 4], state: "minecraft:tuff_bricks"},
        {pos: [3, 20, 0], state: "minecraft:tuff_bricks"},
        {pos: [3, 20, 1], state: "minecraft:waxed_oxidized_copper"},
        {pos: [3, 20, 2], state: "minecraft:waxed_oxidized_cut_copper_stairs{facing:north,half:bottom,shape:straight,waterlogged:false}"},
        {pos: [3, 20, 3], state: "minecraft:air"},
        {pos: [3, 20, 4], state: "minecraft:tuff_bricks"},
        {pos: [4, 20, 0], state: "minecraft:tuff_bricks"},
        {pos: [4, 20, 1], state: "minecraft:waxed_oxidized_copper"},
        {pos: [4, 20, 2], state: "minecraft:air"},
        {pos: [4, 20, 3], state: "minecraft:air"},
        {pos: [4, 20, 4], state: "minecraft:tuff_bricks"},
        {pos: [5, 20, 0], state: "minecraft:tuff_bricks"},
        {pos: [5, 20, 1], state: "minecraft:air"},
        {pos: [5, 20, 2], state: "minecraft:air"},
        {pos: [5, 20, 3], state: "minecraft:air"},
        {pos: [5, 20, 4], state: "minecraft:tuff_bricks"},
        {pos: [6, 20, 0], state: "minecraft:tuff_bricks"},
        {pos: [6, 20, 1], state: "minecraft:polished_tuff"},
        {pos: [6, 20, 2], state: "minecraft:polished_tuff"},
        {pos: [6, 20, 3], state: "minecraft:polished_tuff"},
        {pos: [6, 20, 4], state: "minecraft:tuff_bricks"},
        {pos: [7, 20, 0], state: "minecraft:tuff_bricks"},
        {pos: [7, 20, 1], state: "minecraft:polished_tuff"},
        {pos: [7, 20, 2], state: "minecraft:polished_tuff"},
        {pos: [7, 20, 3], state: "minecraft:polished_tuff"},
        {pos: [7, 20, 4], state: "minecraft:tuff_bricks"},
        {pos: [8, 20, 0], state: "minecraft:tuff_bricks"},
        {pos: [8, 20, 1], state: "minecraft:tuff_bricks"},
        {pos: [8, 20, 2], state: "minecraft:tuff_bricks"},
        {pos: [8, 20, 3], state: "minecraft:tuff_bricks"},
        {pos: [8, 20, 4], state: "minecraft:tuff_bricks"},
        {pos: [9, 20, 0], state: "minecraft:tuff_bricks"},
        {pos: [9, 20, 1], state: "minecraft:tuff_bricks"},
        {pos: [9, 20, 2], state: "minecraft:tuff_bricks"},
        {pos: [9, 20, 3], state: "minecraft:tuff_bricks"},
        {pos: [9, 20, 4], state: "minecraft:tuff_bricks"},
        {pos: [10, 20, 0], state: "minecraft:tuff_bricks"},
        {pos: [10, 20, 1], state: "minecraft:tuff_bricks"},
        {pos: [10, 20, 2], state: "minecraft:tuff_bricks"},
        {pos: [10, 20, 3], state: "minecraft:tuff_bricks"},
        {pos: [10, 20, 4], state: "minecraft:tuff_bricks"},
        {pos: [0, 21, 0], state: "minecraft:tuff_bricks"},
        {pos: [0, 21, 1], state: "minecraft:tuff_bricks"},
        {pos: [0, 21, 2], state: "minecraft:tuff_bricks"},
        {pos: [0, 21, 3], state: "minecraft:tuff_bricks"},
        {pos: [0, 21, 4], state: "minecraft:tuff_bricks"},
        {pos: [1, 21, 0], state: "minecraft:tuff_bricks"},
        {pos: [1, 21, 1], state: "minecraft:tuff_bricks"},
        {pos: [1, 21, 2], state: "minecraft:tuff_bricks"},
        {pos: [1, 21, 3], state: "minecraft:tuff_bricks"},
        {pos: [1, 21, 4], state: "minecraft:tuff_bricks"},
        {pos: [2, 21, 0], state: "minecraft:tuff_bricks"},
        {pos: [2, 21, 1], state: "minecraft:tuff_bricks"},
        {pos: [2, 21, 2], state: "minecraft:tuff_bricks"},
        {pos: [2, 21, 3], state: "minecraft:tuff_bricks"},
        {pos: [2, 21, 4], state: "minecraft:tuff_bricks"},
        {pos: [3, 21, 0], state: "minecraft:tuff_bricks"},
        {pos: [3, 21, 1], state: "minecraft:air"},
        {pos: [3, 21, 2], state: "minecraft:air"},
        {pos: [3, 21, 3], state: "minecraft:air"},
        {pos: [3, 21, 4], state: "minecraft:tuff_bricks"},
        {pos: [4, 21, 0], state: "minecraft:tuff_bricks"},
        {pos: [4, 21, 1], state: "minecraft:waxed_oxidized_cut_copper_stairs{facing:east,half:bottom,shape:straight,waterlogged:false}"},
        {pos: [4, 21, 2], state: "minecraft:air"},
        {pos: [4, 21, 3], state: "minecraft:air"},
        {pos: [4, 21, 4], state: "minecraft:tuff_bricks"},
        {pos: [5, 21, 0], state: "minecraft:tuff_bricks"},
        {pos: [5, 21, 1], state: "minecraft:waxed_oxidized_copper"},
        {pos: [5, 21, 2], state: "minecraft:waxed_oxidized_copper"},
        {pos: [5, 21, 3], state: "minecraft:air"},
        {pos: [5, 21, 4], state: "minecraft:tuff_bricks"},
        {pos: [6, 21, 0], state: "minecraft:tuff_bricks"},
        {pos: [6, 21, 1], state: "minecraft:waxed_oxidized_copper"},
        {pos: [6, 21, 2], state: "minecraft:waxed_oxidized_copper"},
        {pos: [6, 21, 3], state: "minecraft:waxed_copper_block"},
        {pos: [6, 21, 4], state: "minecraft:waxed_copper_block"},
        {pos: [7, 21, 0], state: "minecraft:tuff_bricks"},
        {pos: [7, 21, 1], state: "minecraft:waxed_oxidized_copper"},
        {pos: [7, 21, 2], state: "minecraft:waxed_oxidized_copper"},
        {pos: [7, 21, 3], state: "minecraft:waxed_oxidized_copper"},
        {pos: [7, 21, 4], state: "minecraft:tuff_bricks"},
        {pos: [8, 21, 0], state: "minecraft:tuff_bricks"},
        {pos: [8, 21, 1], state: "minecraft:waxed_oxidized_copper"},
        {pos: [8, 21, 2], state: "minecraft:waxed_oxidized_copper"},
        {pos: [8, 21, 3], state: "minecraft:waxed_oxidized_copper"},
        {pos: [8, 21, 4], state: "minecraft:tuff_bricks"},
        {pos: [9, 21, 0], state: "minecraft:tuff_bricks"},
        {pos: [9, 21, 1], state: "minecraft:waxed_oxidized_copper"},
        {pos: [9, 21, 2], state: "minecraft:waxed_oxidized_copper"},
        {pos: [9, 21, 3], state: "minecraft:waxed_oxidized_copper"},
        {pos: [9, 21, 4], state: "minecraft:tuff_bricks"},
        {pos: [10, 21, 0], state: "minecraft:tuff_bricks"},
        {pos: [10, 21, 1], state: "minecraft:waxed_oxidized_copper"},
        {pos: [10, 21, 2], state: "minecraft:waxed_oxidized_copper"},
        {pos: [10, 21, 3], state: "minecraft:waxed_oxidized_copper"},
        {pos: [10, 21, 4], state: "minecraft:tuff_bricks"},
        {pos: [0, 22, 0], state: "minecraft:tuff_bricks"},
        {pos: [0, 22, 1], state: "minecraft:tuff_bricks"},
        {pos: [0, 22, 2], state: "minecraft:tuff_bricks"},
        {pos: [0, 22, 3], state: "minecraft:tuff_bricks"},
        {pos: [0, 22, 4], state: "minecraft:tuff_bricks"},
        {pos: [1, 22, 0], state: "minecraft:tuff_bricks"},
        {pos: [1, 22, 1], state: "minecraft:tuff_bricks"},
        {pos: [1, 22, 2], state: "minecraft:tuff_bricks"},
        {pos: [1, 22, 3], state: "minecraft:tuff_bricks"},
        {pos: [1, 22, 4], state: "minecraft:tuff_bricks"},
        {pos: [2, 22, 0], state: "minecraft:waxed_copper_block"},
        {pos: [2, 22, 1], state: "minecraft:waxed_copper_block"},
        {pos: [2, 22, 2], state: "minecraft:waxed_copper_block"},
        {pos: [2, 22, 3], state: "minecraft:waxed_copper_block"},
        {pos: [2, 22, 4], state: "minecraft:waxed_copper_block"},
        {pos: [3, 22, 0], state: "minecraft:waxed_copper_block"},
        {pos: [3, 22, 1], state: "minecraft:air"},
        {pos: [3, 22, 2], state: "minecraft:air"},
        {pos: [3, 22, 3], state: "minecraft:air"},
        {pos: [3, 22, 4], state: "minecraft:waxed_copper_block"},
        {pos: [4, 22, 0], state: "minecraft:waxed_copper_block"},
        {pos: [4, 22, 1], state: "minecraft:air"},
        {pos: [4, 22, 2], state: "minecraft:air"},
        {pos: [4, 22, 3], state: "minecraft:air"},
        {pos: [4, 22, 4], state: "minecraft:waxed_copper_block"},
        {pos: [5, 22, 0], state: "minecraft:waxed_copper_block"},
        {pos: [5, 22, 1], state: "minecraft:air"},
        {pos: [5, 22, 2], state: "minecraft:air"},
        {pos: [5, 22, 3], state: "minecraft:air"},
        {pos: [5, 22, 4], state: "minecraft:waxed_copper_block"},
        {pos: [6, 22, 0], state: "minecraft:waxed_copper_block"},
        {pos: [6, 22, 1], state: "minecraft:air"},
        {pos: [6, 22, 2], state: "minecraft:air"},
        {pos: [6, 22, 3], state: "minecraft:air"},
        {pos: [6, 22, 4], state: "minecraft:waxed_copper_block"},
        {pos: [7, 22, 0], state: "minecraft:waxed_copper_block"},
        {pos: [7, 22, 1], state: "minecraft:air"},
        {pos: [7, 22, 2], state: "minecraft:air"},
        {pos: [7, 22, 3], state: "minecraft:air"},
        {pos: [7, 22, 4], state: "minecraft:waxed_copper_block"},
        {pos: [8, 22, 0], state: "minecraft:waxed_copper_block"},
        {pos: [8, 22, 1], state: "minecraft:air"},
        {pos: [8, 22, 2], state: "minecraft:air"},
        {pos: [8, 22, 3], state: "minecraft:air"},
        {pos: [8, 22, 4], state: "minecraft:waxed_copper_block"},
        {pos: [9, 22, 0], state: "minecraft:waxed_copper_block"},
        {pos: [9, 22, 1], state: "minecraft:air"},
        {pos: [9, 22, 2], state: "minecraft:air"},
        {pos: [9, 22, 3], state: "minecraft:air"},
        {pos: [9, 22, 4], state: "minecraft:waxed_copper_block"},
        {pos: [10, 22, 0], state: "minecraft:waxed_copper_block"},
        {pos: [10, 22, 1], state: "minecraft:air"},
        {pos: [10, 22, 2], state: "minecraft:air"},
        {pos: [10, 22, 3], state: "minecraft:air"},
        {pos: [10, 22, 4], state: "minecraft:waxed_copper_block"},
        {pos: [0, 23, 0], state: "minecraft:tuff_bricks"},
        {pos: [0, 23, 1], state: "minecraft:tuff_bricks"},
        {pos: [0, 23, 2], state: "minecraft:tuff_bricks"},
        {pos: [0, 23, 3], state: "minecraft:tuff_bricks"},
        {pos: [0, 23, 4], state: "minecraft:tuff_bricks"},
        {pos: [1, 23, 0], state: "minecraft:tuff_bricks"},
        {pos: [1, 23, 1], state: "minecraft:tuff_bricks"},
        {pos: [1, 23, 2], state: "minecraft:tuff_bricks"},
        {pos: [1, 23, 3], state: "minecraft:tuff_bricks"},
        {pos: [1, 23, 4], state: "minecraft:tuff_bricks"},
        {pos: [2, 23, 0], state: "minecraft:tuff_bricks"},
        {pos: [2, 23, 1], state: "minecraft:tuff_bricks"},
        {pos: [2, 23, 2], state: "minecraft:waxed_copper_bulb{lit:true,powered:false}"},
        {pos: [2, 23, 3], state: "minecraft:tuff_bricks"},
        {pos: [2, 23, 4], state: "minecraft:tuff_bricks"},
        {pos: [3, 23, 0], state: "minecraft:tuff_bricks"},
        {pos: [3, 23, 1], state: "minecraft:air"},
        {pos: [3, 23, 2], state: "minecraft:air"},
        {pos: [3, 23, 3], state: "minecraft:air"},
        {pos: [3, 23, 4], state: "minecraft:tuff_bricks"},
        {pos: [4, 23, 0], state: "minecraft:tuff_bricks"},
        {pos: [4, 23, 1], state: "minecraft:air"},
        {pos: [4, 23, 2], state: "minecraft:air"},
        {pos: [4, 23, 3], state: "minecraft:air"},
        {pos: [4, 23, 4], state: "minecraft:tuff_bricks"},
        {pos: [5, 23, 0], state: "minecraft:tuff_bricks"},
        {pos: [5, 23, 1], state: "minecraft:air"},
        {pos: [5, 23, 2], state: "minecraft:air"},
        {pos: [5, 23, 3], state: "minecraft:air"},
        {pos: [5, 23, 4], state: "minecraft:tuff_bricks"},
        {pos: [6, 23, 0], state: "minecraft:tuff_bricks"},
        {pos: [6, 23, 1], state: "minecraft:air"},
        {pos: [6, 23, 2], state: "minecraft:air"},
        {pos: [6, 23, 3], state: "minecraft:air"},
        {pos: [6, 23, 4], state: "minecraft:waxed_copper_bulb{lit:true,powered:false}"},
        {pos: [7, 23, 0], state: "minecraft:tuff_bricks"},
        {pos: [7, 23, 1], state: "minecraft:air"},
        {pos: [7, 23, 2], state: "minecraft:air"},
        {pos: [7, 23, 3], state: "minecraft:air"},
        {pos: [7, 23, 4], state: "minecraft:tuff_bricks"},
        {pos: [8, 23, 0], state: "minecraft:tuff_bricks"},
        {pos: [8, 23, 1], state: "minecraft:air"},
        {pos: [8, 23, 2], state: "minecraft:air"},
        {pos: [8, 23, 3], state: "minecraft:air"},
        {pos: [8, 23, 4], state: "minecraft:tuff_bricks"},
        {pos: [9, 23, 0], state: "minecraft:tuff_bricks"},
        {pos: [9, 23, 1], state: "minecraft:air"},
        {pos: [9, 23, 2], state: "minecraft:air"},
        {pos: [9, 23, 3], state: "minecraft:air"},
        {pos: [9, 23, 4], state: "minecraft:tuff_bricks"},
        {pos: [10, 23, 0], state: "minecraft:tuff_bricks"},
        {pos: [10, 23, 1], state: "minecraft:air"},
        {pos: [10, 23, 2], state: "minecraft:jigsaw{orientation:east_up}", nbt: {final_state: "minecraft:air", id: "minecraft:jigsaw", joint: "rollable", name: "minecraft:lower_corridor_connector", placement_priority: 0, pool: "minecraft:empty", selection_priority: 0, target: "minecraft:empty"}},
        {pos: [10, 23, 3], state: "minecraft:air"},
        {pos: [10, 23, 4], state: "minecraft:tuff_bricks"},
        {pos: [0, 24, 0], state: "minecraft:tuff_bricks"},
        {pos: [0, 24, 1], state: "minecraft:tuff_bricks"},
        {pos: [0, 24, 2], state: "minecraft:tuff_bricks"},
        {pos: [0, 24, 3], state: "minecraft:tuff_bricks"},
        {pos: [0, 24, 4], state: "minecraft:tuff_bricks"},
        {pos: [1, 24, 0], state: "minecraft:tuff_bricks"},
        {pos: [1, 24, 1], state: "minecraft:tuff_bricks"},
        {pos: [1, 24, 2], state: "minecraft:tuff_bricks"},
        {pos: [1, 24, 3], state: "minecraft:tuff_bricks"},
        {pos: [1, 24, 4], state: "minecraft:tuff_bricks"},
        {pos: [2, 24, 0], state: "minecraft:chiseled_tuff_bricks"},
        {pos: [2, 24, 1], state: "minecraft:chiseled_tuff_bricks"},
        {pos: [2, 24, 2], state: "minecraft:chiseled_tuff_bricks"},
        {pos: [2, 24, 3], state: "minecraft:chiseled_tuff_bricks"},
        {pos: [2, 24, 4], state: "minecraft:chiseled_tuff_bricks"},
        {pos: [3, 24, 0], state: "minecraft:chiseled_tuff_bricks"},
        {pos: [3, 24, 1], state: "minecraft:air"},
        {pos: [3, 24, 2], state: "minecraft:air"},
        {pos: [3, 24, 3], state: "minecraft:air"},
        {pos: [3, 24, 4], state: "minecraft:chiseled_tuff_bricks"},
        {pos: [4, 24, 0], state: "minecraft:chiseled_tuff_bricks"},
        {pos: [4, 24, 1], state: "minecraft:air"},
        {pos: [4, 24, 2], state: "minecraft:air"},
        {pos: [4, 24, 3], state: "minecraft:air"},
        {pos: [4, 24, 4], state: "minecraft:chiseled_tuff_bricks"},
        {pos: [5, 24, 0], state: "minecraft:chiseled_tuff_bricks"},
        {pos: [5, 24, 1], state: "minecraft:air"},
        {pos: [5, 24, 2], state: "minecraft:air"},
        {pos: [5, 24, 3], state: "minecraft:air"},
        {pos: [5, 24, 4], state: "minecraft:chiseled_tuff_bricks"},
        {pos: [6, 24, 0], state: "minecraft:chiseled_tuff_bricks"},
        {pos: [6, 24, 1], state: "minecraft:air"},
        {pos: [6, 24, 2], state: "minecraft:air"},
        {pos: [6, 24, 3], state: "minecraft:air"},
        {pos: [6, 24, 4], state: "minecraft:chiseled_tuff_bricks"},
        {pos: [7, 24, 0], state: "minecraft:chiseled_tuff_bricks"},
        {pos: [7, 24, 1], state: "minecraft:air"},
        {pos: [7, 24, 2], state: "minecraft:air"},
        {pos: [7, 24, 3], state: "minecraft:air"},
        {pos: [7, 24, 4], state: "minecraft:chiseled_tuff_bricks"},
        {pos: [8, 24, 0], state: "minecraft:chiseled_tuff_bricks"},
        {pos: [8, 24, 1], state: "minecraft:air"},
        {pos: [8, 24, 2], state: "minecraft:air"},
        {pos: [8, 24, 3], state: "minecraft:air"},
        {pos: [8, 24, 4], state: "minecraft:chiseled_tuff_bricks"},
        {pos: [9, 24, 0], state: "minecraft:chiseled_tuff_bricks"},
        {pos: [9, 24, 1], state: "minecraft:air"},
        {pos: [9, 24, 2], state: "minecraft:air"},
        {pos: [9, 24, 3], state: "minecraft:air"},
        {pos: [9, 24, 4], state: "minecraft:chiseled_tuff_bricks"},
        {pos: [10, 24, 0], state: "minecraft:chiseled_tuff_bricks"},
        {pos: [10, 24, 1], state: "minecraft:air"},
        {pos: [10, 24, 2], state: "minecraft:air"},
        {pos: [10, 24, 3], state: "minecraft:air"},
        {pos: [10, 24, 4], state: "minecraft:chiseled_tuff_bricks"},
        {pos: [0, 25, 0], state: "minecraft:tuff_bricks"},
        {pos: [0, 25, 1], state: "minecraft:tuff_bricks"},
        {pos: [0, 25, 2], state: "minecraft:tuff_bricks"},
        {pos: [0, 25, 3], state: "minecraft:tuff_bricks"},
        {pos: [0, 25, 4], state: "minecraft:tuff_bricks"},
        {pos: [1, 25, 0], state: "minecraft:tuff_bricks"},
        {pos: [1, 25, 1], state: "minecraft:tuff_bricks"},
        {pos: [1, 25, 2], state: "minecraft:tuff_bricks"},
        {pos: [1, 25, 3], state: "minecraft:tuff_bricks"},
        {pos: [1, 25, 4], state: "minecraft:tuff_bricks"},
        {pos: [2, 25, 0], state: "minecraft:tuff_bricks"},
        {pos: [2, 25, 1], state: "minecraft:tuff_bricks"},
        {pos: [2, 25, 2], state: "minecraft:tuff_bricks"},
        {pos: [2, 25, 3], state: "minecraft:tuff_bricks"},
        {pos: [2, 25, 4], state: "minecraft:tuff_bricks"},
        {pos: [3, 25, 0], state: "minecraft:tuff_bricks"},
        {pos: [3, 25, 1], state: "minecraft:polished_tuff"},
        {pos: [3, 25, 2], state: "minecraft:polished_tuff"},
        {pos: [3, 25, 3], state: "minecraft:polished_tuff"},
        {pos: [3, 25, 4], state: "minecraft:tuff_bricks"},
        {pos: [4, 25, 0], state: "minecraft:tuff_bricks"},
        {pos: [4, 25, 1], state: "minecraft:polished_tuff"},
        {pos: [4, 25, 2], state: "minecraft:polished_tuff"},
        {pos: [4, 25, 3], state: "minecraft:polished_tuff"},
        {pos: [4, 25, 4], state: "minecraft:tuff_bricks"},
        {pos: [5, 25, 0], state: "minecraft:tuff_bricks"},
        {pos: [5, 25, 1], state: "minecraft:polished_tuff"},
        {pos: [5, 25, 2], state: "minecraft:polished_tuff"},
        {pos: [5, 25, 3], state: "minecraft:polished_tuff"},
        {pos: [5, 25, 4], state: "minecraft:tuff_bricks"},
        {pos: [6, 25, 0], state: "minecraft:tuff_bricks"},
        {pos: [6, 25, 1], state: "minecraft:polished_tuff"},
        {pos: [6, 25, 2], state: "minecraft:polished_tuff"},
        {pos: [6, 25, 3], state: "minecraft:polished_tuff"},
        {pos: [6, 25, 4], state: "minecraft:tuff_bricks"},
        {pos: [7, 25, 0], state: "minecraft:tuff_bricks"},
        {pos: [7, 25, 1], state: "minecraft:polished_tuff"},
        {pos: [7, 25, 2], state: "minecraft:polished_tuff"},
        {pos: [7, 25, 3], state: "minecraft:polished_tuff"},
        {pos: [7, 25, 4], state: "minecraft:tuff_bricks"},
        {pos: [8, 25, 0], state: "minecraft:tuff_bricks"},
        {pos: [8, 25, 1], state: "minecraft:polished_tuff"},
        {pos: [8, 25, 2], state: "minecraft:polished_tuff"},
        {pos: [8, 25, 3], state: "minecraft:polished_tuff"},
        {pos: [8, 25, 4], state: "minecraft:tuff_bricks"},
        {pos: [9, 25, 0], state: "minecraft:tuff_bricks"},
        {pos: [9, 25, 1], state: "minecraft:polished_tuff"},
        {pos: [9, 25, 2], state: "minecraft:polished_tuff"},
        {pos: [9, 25, 3], state: "minecraft:polished_tuff"},
        {pos: [9, 25, 4], state: "minecraft:tuff_bricks"},
        {pos: [10, 25, 0], state: "minecraft:tuff_bricks"},
        {pos: [10, 25, 1], state: "minecraft:polished_tuff"},
        {pos: [10, 25, 2], state: "minecraft:polished_tuff"},
        {pos: [10, 25, 3], state: "minecraft:polished_tuff"},
        {pos: [10, 25, 4], state: "minecraft:tuff_bricks"},
        {pos: [0, 26, 0], state: "minecraft:tuff_bricks"},
        {pos: [0, 26, 1], state: "minecraft:tuff_bricks"},
        {pos: [0, 26, 2], state: "minecraft:tuff_bricks"},
        {pos: [0, 26, 3], state: "minecraft:tuff_bricks"},
        {pos: [0, 26, 4], state: "minecraft:tuff_bricks"},
        {pos: [1, 26, 0], state: "minecraft:tuff_bricks"},
        {pos: [1, 26, 1], state: "minecraft:tuff_bricks"},
        {pos: [1, 26, 2], state: "minecraft:tuff_bricks"},
        {pos: [1, 26, 3], state: "minecraft:tuff_bricks"},
        {pos: [1, 26, 4], state: "minecraft:tuff_bricks"},
        {pos: [2, 26, 0], state: "minecraft:tuff_bricks"},
        {pos: [2, 26, 1], state: "minecraft:tuff_bricks"},
        {pos: [2, 26, 2], state: "minecraft:tuff_bricks"},
        {pos: [2, 26, 3], state: "minecraft:tuff_bricks"},
        {pos: [2, 26, 4], state: "minecraft:tuff_bricks"},
        {pos: [3, 26, 0], state: "minecraft:tuff_bricks"},
        {pos: [3, 26, 1], state: "minecraft:tuff_bricks"},
        {pos: [3, 26, 2], state: "minecraft:tuff_bricks"},
        {pos: [3, 26, 3], state: "minecraft:tuff_bricks"},
        {pos: [3, 26, 4], state: "minecraft:tuff_bricks"},
        {pos: [4, 26, 0], state: "minecraft:tuff_bricks"},
        {pos: [4, 26, 1], state: "minecraft:tuff_bricks"},
        {pos: [4, 26, 2], state: "minecraft:tuff_bricks"},
        {pos: [4, 26, 3], state: "minecraft:tuff_bricks"},
        {pos: [4, 26, 4], state: "minecraft:tuff_bricks"},
        {pos: [5, 26, 0], state: "minecraft:tuff_bricks"},
        {pos: [5, 26, 1], state: "minecraft:tuff_bricks"},
        {pos: [5, 26, 2], state: "minecraft:tuff_bricks"},
        {pos: [5, 26, 3], state: "minecraft:tuff_bricks"},
        {pos: [5, 26, 4], state: "minecraft:tuff_bricks"},
        {pos: [6, 26, 0], state: "minecraft:tuff_bricks"},
        {pos: [6, 26, 1], state: "minecraft:tuff_bricks"},
        {pos: [6, 26, 2], state: "minecraft:tuff_bricks"},
        {pos: [6, 26, 3], state: "minecraft:tuff_bricks"},
        {pos: [6, 26, 4], state: "minecraft:tuff_bricks"},
        {pos: [7, 26, 0], state: "minecraft:tuff_bricks"},
        {pos: [7, 26, 1], state: "minecraft:tuff_bricks"},
        {pos: [7, 26, 2], state: "minecraft:tuff_bricks"},
        {pos: [7, 26, 3], state: "minecraft:tuff_bricks"},
        {pos: [7, 26, 4], state: "minecraft:tuff_bricks"},
        {pos: [8, 26, 0], state: "minecraft:tuff_bricks"},
        {pos: [8, 26, 1], state: "minecraft:tuff_bricks"},
        {pos: [8, 26, 2], state: "minecraft:tuff_bricks"},
        {pos: [8, 26, 3], state: "minecraft:tuff_bricks"},
        {pos: [8, 26, 4], state: "minecraft:tuff_bricks"},
        {pos: [9, 26, 0], state: "minecraft:tuff_bricks"},
        {pos: [9, 26, 1], state: "minecraft:tuff_bricks"},
        {pos: [9, 26, 2], state: "minecraft:tuff_bricks"},
        {pos: [9, 26, 3], state: "minecraft:tuff_bricks"},
        {pos: [9, 26, 4], state: "minecraft:tuff_bricks"},
        {pos: [10, 26, 0], state: "minecraft:tuff_bricks"},
        {pos: [10, 26, 1], state: "minecraft:tuff_bricks"},
        {pos: [10, 26, 2], state: "minecraft:tuff_bricks"},
        {pos: [10, 26, 3], state: "minecraft:tuff_bricks"},
        {pos: [10, 26, 4], state: "minecraft:tuff_bricks"}
    ],
    entities: [],
    palette: [
        "minecraft:tuff_bricks",
        "minecraft:waxed_oxidized_copper",
        "minecraft:waxed_oxidized_cut_copper",
        "minecraft:waxed_copper_block",
        "minecraft:waxed_copper_bulb{lit:true,powered:false}",
        "minecraft:chiseled_tuff_bricks",
        "minecraft:polished_tuff",
        "minecraft:pointed_dripstone{thickness:tip,vertical_direction:up,waterlogged:false}",
        "minecraft:air",
        "minecraft:ladder{facing:west,waterlogged:false}",
        "minecraft:waxed_oxidized_cut_copper_stairs{facing:north,half:bottom,shape:straight,waterlogged:false}",
        "minecraft:waxed_oxidized_cut_copper_stairs{facing:east,half:bottom,shape:straight,waterlogged:false}",
        "minecraft:waxed_oxidized_cut_copper_stairs{facing:south,half:bottom,shape:straight,waterlogged:false}",
        "minecraft:waxed_oxidized_cut_copper_stairs{facing:west,half:bottom,shape:straight,waterlogged:false}",
        "minecraft:jigsaw{orientation:east_up}"
    ]
}
