{
    size: [9, 6, 11],
    data: [
        {pos: [0, 0, 4], state: "minecraft:dirt_path"},
        {pos: [0, 0, 5], state: "minecraft:dirt_path"},
        {pos: [0, 0, 6], state: "minecraft:dirt_path"},
        {pos: [1, 0, 2], state: "minecraft:jigsaw{orientation:up_north}", nbt: {final_state: "minecraft:grass_block", id: "minecraft:jigsaw", joint: "rollable", name: "minecraft:bottom", pool: "minecraft:village/common/cats", target: "minecraft:bottom"}},
        {pos: [1, 0, 3], state: "minecraft:dirt_path"},
        {pos: [1, 0, 4], state: "minecraft:dirt_path"},
        {pos: [1, 0, 5], state: "minecraft:dirt_path"},
        {pos: [1, 0, 6], state: "minecraft:dirt_path"},
        {pos: [1, 0, 7], state: "minecraft:dirt_path"},
        {pos: [2, 0, 1], state: "minecraft:dirt_path"},
        {pos: [2, 0, 2], state: "minecraft:dirt_path"},
        {pos: [2, 0, 3], state: "minecraft:dirt_path"},
        {pos: [2, 0, 4], state: "minecraft:dirt_path"},
        {pos: [2, 0, 5], state: "minecraft:dirt_path"},
        {pos: [2, 0, 6], state: "minecraft:dirt_path"},
        {pos: [2, 0, 7], state: "minecraft:dirt_path"},
        {pos: [2, 0, 8], state: "minecraft:dirt_path"},
        {pos: [2, 0, 9], state: "minecraft:dirt_path"},
        {pos: [3, 0, 0], state: "minecraft:dirt_path"},
        {pos: [3, 0, 1], state: "minecraft:dirt_path"},
        {pos: [3, 0, 2], state: "minecraft:dirt_path"},
        {pos: [3, 0, 3], state: "minecraft:dirt_path"},
        {pos: [3, 0, 4], state: "minecraft:dirt_path"},
        {pos: [3, 0, 5], state: "minecraft:dirt_path"},
        {pos: [3, 0, 6], state: "minecraft:dirt_path"},
        {pos: [3, 0, 7], state: "minecraft:dirt_path"},
        {pos: [3, 0, 8], state: "minecraft:dirt_path"},
        {pos: [3, 0, 9], state: "minecraft:dirt_path"},
        {pos: [3, 0, 10], state: "minecraft:dirt_path"},
        {pos: [4, 0, 0], state: "minecraft:dirt_path"},
        {pos: [4, 0, 1], state: "minecraft:dirt_path"},
        {pos: [4, 0, 2], state: "minecraft:dirt_path"},
        {pos: [4, 0, 3], state: "minecraft:acacia_wood{axis:y}"},
        {pos: [4, 0, 4], state: "minecraft:dirt_path"},
        {pos: [4, 0, 5], state: "minecraft:dirt_path"},
        {pos: [4, 0, 6], state: "minecraft:dirt_path"},
        {pos: [4, 0, 7], state: "minecraft:acacia_wood{axis:x}"},
        {pos: [4, 0, 8], state: "minecraft:dirt_path"},
        {pos: [4, 0, 9], state: "minecraft:dirt_path"},
        {pos: [4, 0, 10], state: "minecraft:dirt_path"},
        {pos: [5, 0, 0], state: "minecraft:dirt_path"},
        {pos: [5, 0, 1], state: "minecraft:dirt_path"},
        {pos: [5, 0, 2], state: "minecraft:dirt_path"},
        {pos: [5, 0, 3], state: "minecraft:dirt_path"},
        {pos: [5, 0, 4], state: "minecraft:dirt_path"},
        {pos: [5, 0, 5], state: "minecraft:dirt_path"},
        {pos: [5, 0, 6], state: "minecraft:dirt_path"},
        {pos: [5, 0, 7], state: "minecraft:dirt_path"},
        {pos: [5, 0, 8], state: "minecraft:dirt_path"},
        {pos: [5, 0, 9], state: "minecraft:dirt_path"},
        {pos: [5, 0, 10], state: "minecraft:dirt_path"},
        {pos: [6, 0, 1], state: "minecraft:dirt_path"},
        {pos: [6, 0, 2], state: "minecraft:dirt_path"},
        {pos: [6, 0, 3], state: "minecraft:dirt_path"},
        {pos: [6, 0, 4], state: "minecraft:dirt_path"},
        {pos: [6, 0, 5], state: "minecraft:dirt_path"},
        {pos: [6, 0, 6], state: "minecraft:dirt_path"},
        {pos: [6, 0, 7], state: "minecraft:dirt_path"},
        {pos: [6, 0, 8], state: "minecraft:dirt_path"},
        {pos: [6, 0, 9], state: "minecraft:dirt_path"},
        {pos: [7, 0, 1], state: "minecraft:jigsaw{orientation:up_north}", nbt: {final_state: "minecraft:grass_block", id: "minecraft:jigsaw", joint: "rollable", name: "minecraft:bottom", pool: "minecraft:village/common/cats", target: "minecraft:bottom"}},
        {pos: [7, 0, 3], state: "minecraft:dirt_path"},
        {pos: [7, 0, 4], state: "minecraft:dirt_path"},
        {pos: [7, 0, 5], state: "minecraft:dirt_path"},
        {pos: [7, 0, 6], state: "minecraft:dirt_path"},
        {pos: [7, 0, 7], state: "minecraft:dirt_path"},
        {pos: [8, 0, 4], state: "minecraft:dirt_path"},
        {pos: [8, 0, 5], state: "minecraft:dirt_path"},
        {pos: [8, 0, 6], state: "minecraft:dirt_path"},
        {pos: [8, 0, 9], state: "minecraft:jigsaw{orientation:up_north}", nbt: {final_state: "minecraft:grass_block", id: "minecraft:jigsaw", joint: "rollable", name: "minecraft:bottom", pool: "minecraft:village/common/cats", target: "minecraft:bottom"}},
        {pos: [0, 1, 5], state: "minecraft:jigsaw{orientation:west_up}", nbt: {final_state: "minecraft:structure_void", id: "minecraft:jigsaw", joint: "aligned", name: "minecraft:street", pool: "minecraft:village/savanna/zombie/streets", target: "minecraft:street"}},
        {pos: [3, 1, 2], state: "minecraft:acacia_wood{axis:y}"},
        {pos: [3, 1, 3], state: "minecraft:acacia_wood{axis:y}"},
        {pos: [3, 1, 4], state: "minecraft:acacia_wood{axis:y}"},
        {pos: [3, 1, 6], state: "minecraft:acacia_wood{axis:y}"},
        {pos: [3, 1, 7], state: "minecraft:acacia_wood{axis:y}"},
        {pos: [3, 1, 8], state: "minecraft:acacia_wood{axis:y}"},
        {pos: [4, 1, 0], state: "minecraft:jigsaw{orientation:north_up}", nbt: {final_state: "minecraft:structure_void", id: "minecraft:jigsaw", joint: "aligned", name: "minecraft:street", pool: "minecraft:village/savanna/zombie/streets", target: "minecraft:street"}},
        {pos: [4, 1, 2], state: "minecraft:acacia_wood{axis:x}"},
        {pos: [4, 1, 3], state: "minecraft:water{level:0}"},
        {pos: [4, 1, 4], state: "minecraft:acacia_wood{axis:x}"},
        {pos: [4, 1, 6], state: "minecraft:acacia_wood{axis:x}"},
        {pos: [4, 1, 7], state: "minecraft:water{level:0}"},
        {pos: [4, 1, 8], state: "minecraft:acacia_wood{axis:x}"},
        {pos: [4, 1, 10], state: "minecraft:jigsaw{orientation:south_up}", nbt: {final_state: "minecraft:structure_void", id: "minecraft:jigsaw", joint: "aligned", name: "minecraft:street", pool: "minecraft:village/savanna/zombie/streets", target: "minecraft:street"}},
        {pos: [5, 1, 2], state: "minecraft:acacia_wood{axis:y}"},
        {pos: [5, 1, 3], state: "minecraft:acacia_wood{axis:y}"},
        {pos: [5, 1, 4], state: "minecraft:acacia_wood{axis:y}"},
        {pos: [5, 1, 6], state: "minecraft:acacia_wood{axis:y}"},
        {pos: [5, 1, 7], state: "minecraft:acacia_wood{axis:y}"},
        {pos: [5, 1, 8], state: "minecraft:acacia_wood{axis:y}"},
        {pos: [8, 1, 5], state: "minecraft:jigsaw{orientation:east_up}", nbt: {final_state: "minecraft:structure_void", id: "minecraft:jigsaw", joint: "aligned", name: "minecraft:street", pool: "minecraft:village/savanna/zombie/streets", target: "minecraft:street"}},
        {pos: [3, 2, 4], state: "minecraft:acacia_fence{east:false,north:false,south:false,waterlogged:false,west:false}"},
        {pos: [3, 2, 6], state: "minecraft:acacia_fence{east:false,north:false,south:false,waterlogged:false,west:false}"},
        {pos: [5, 2, 4], state: "minecraft:acacia_fence{east:false,north:false,south:false,waterlogged:false,west:false}"},
        {pos: [5, 2, 6], state: "minecraft:acacia_fence{east:false,north:false,south:false,waterlogged:false,west:false}"},
        {pos: [3, 3, 4], state: "minecraft:acacia_fence{east:false,north:false,south:false,waterlogged:false,west:false}"},
        {pos: [3, 3, 6], state: "minecraft:acacia_fence{east:false,north:false,south:false,waterlogged:false,west:false}"},
        {pos: [4, 3, 5], state: "minecraft:bell{attachment:ceiling,facing:east,powered:false}", nbt: {id: "minecraft:bell"}},
        {pos: [5, 3, 4], state: "minecraft:acacia_fence{east:false,north:false,south:false,waterlogged:false,west:false}"},
        {pos: [5, 3, 6], state: "minecraft:acacia_fence{east:false,north:false,south:false,waterlogged:false,west:false}"},
        {pos: [3, 4, 4], state: "minecraft:acacia_slab{type:bottom,waterlogged:false}"},
        {pos: [3, 4, 5], state: "minecraft:acacia_slab{type:bottom,waterlogged:false}"},
        {pos: [3, 4, 6], state: "minecraft:acacia_slab{type:bottom,waterlogged:false}"},
        {pos: [4, 4, 4], state: "minecraft:acacia_slab{type:bottom,waterlogged:false}"},
        {pos: [4, 4, 5], state: "minecraft:acacia_slab{type:double,waterlogged:false}"},
        {pos: [4, 4, 6], state: "minecraft:acacia_slab{type:bottom,waterlogged:false}"},
        {pos: [5, 4, 4], state: "minecraft:acacia_slab{type:bottom,waterlogged:false}"},
        {pos: [5, 4, 5], state: "minecraft:acacia_slab{type:bottom,waterlogged:false}"},
        {pos: [5, 4, 6], state: "minecraft:acacia_slab{type:bottom,waterlogged:false}"},
        {pos: [4, 5, 5], state: "minecraft:torch"}
    ],
    entities: [],
    palette: [
        "minecraft:acacia_wood{axis:y}",
        "minecraft:acacia_wood{axis:x}",
        "minecraft:acacia_slab{type:double,waterlogged:false}",
        "minecraft:dirt_path",
        "minecraft:water{level:0}",
        "minecraft:acacia_fence{east:false,north:false,south:false,waterlogged:false,west:false}",
        "minecraft:acacia_slab{type:bottom,waterlogged:false}",
        "minecraft:torch",
        "minecraft:jigsaw{orientation:up_north}",
        "minecraft:jigsaw{orientation:west_up}",
        "minecraft:jigsaw{orientation:north_up}",
        "minecraft:jigsaw{orientation:south_up}",
        "minecraft:jigsaw{orientation:east_up}",
        "minecraft:bell{attachment:ceiling,facing:east,powered:false}"
    ]
}
