{
    DataVersion: 2856,
    size: [16, 24, 16],
    data: [
        {pos: [0, 0, 0], state: "minecraft:blackstone"},
        {pos: [0, 0, 1], state: "minecraft:blackstone"},
        {pos: [0, 0, 2], state: "minecraft:blackstone"},
        {pos: [0, 0, 3], state: "minecraft:blackstone"},
        {pos: [0, 0, 4], state: "minecraft:blackstone"},
        {pos: [0, 0, 5], state: "minecraft:blackstone"},
        {pos: [0, 0, 6], state: "minecraft:blackstone"},
        {pos: [0, 0, 7], state: "minecraft:blackstone"},
        {pos: [0, 0, 8], state: "minecraft:blackstone"},
        {pos: [0, 0, 9], state: "minecraft:blackstone"},
        {pos: [0, 0, 10], state: "minecraft:blackstone"},
        {pos: [0, 0, 11], state: "minecraft:blackstone"},
        {pos: [0, 0, 12], state: "minecraft:blackstone"},
        {pos: [0, 0, 13], state: "minecraft:blackstone"},
        {pos: [0, 0, 14], state: "minecraft:blackstone"},
        {pos: [0, 0, 15], state: "minecraft:blackstone"},
        {pos: [1, 0, 0], state: "minecraft:blackstone"},
        {pos: [1, 0, 1], state: "minecraft:blackstone"},
        {pos: [1, 0, 2], state: "minecraft:blackstone"},
        {pos: [1, 0, 3], state: "minecraft:blackstone"},
        {pos: [1, 0, 4], state: "minecraft:blackstone"},
        {pos: [1, 0, 5], state: "minecraft:blackstone"},
        {pos: [1, 0, 6], state: "minecraft:blackstone"},
        {pos: [1, 0, 7], state: "minecraft:blackstone"},
        {pos: [1, 0, 8], state: "minecraft:blackstone"},
        {pos: [1, 0, 9], state: "minecraft:blackstone"},
        {pos: [1, 0, 10], state: "minecraft:blackstone"},
        {pos: [1, 0, 11], state: "minecraft:blackstone"},
        {pos: [1, 0, 12], state: "minecraft:blackstone"},
        {pos: [1, 0, 13], state: "minecraft:blackstone"},
        {pos: [2, 0, 0], state: "minecraft:blackstone"},
        {pos: [2, 0, 1], state: "minecraft:blackstone"},
        {pos: [2, 0, 2], state: "minecraft:blackstone"},
        {pos: [2, 0, 3], state: "minecraft:blackstone"},
        {pos: [2, 0, 4], state: "minecraft:blackstone"},
        {pos: [2, 0, 5], state: "minecraft:blackstone"},
        {pos: [2, 0, 6], state: "minecraft:blackstone"},
        {pos: [2, 0, 7], state: "minecraft:blackstone"},
        {pos: [2, 0, 8], state: "minecraft:blackstone"},
        {pos: [2, 0, 9], state: "minecraft:blackstone"},
        {pos: [2, 0, 10], state: "minecraft:blackstone"},
        {pos: [2, 0, 11], state: "minecraft:blackstone"},
        {pos: [2, 0, 12], state: "minecraft:blackstone"},
        {pos: [2, 0, 13], state: "minecraft:blackstone"},
        {pos: [3, 0, 0], state: "minecraft:blackstone"},
        {pos: [3, 0, 1], state: "minecraft:blackstone"},
        {pos: [3, 0, 2], state: "minecraft:blackstone"},
        {pos: [3, 0, 3], state: "minecraft:blackstone"},
        {pos: [3, 0, 4], state: "minecraft:blackstone"},
        {pos: [3, 0, 5], state: "minecraft:blackstone"},
        {pos: [3, 0, 6], state: "minecraft:blackstone"},
        {pos: [3, 0, 7], state: "minecraft:blackstone"},
        {pos: [3, 0, 8], state: "minecraft:blackstone"},
        {pos: [3, 0, 9], state: "minecraft:blackstone"},
        {pos: [3, 0, 10], state: "minecraft:blackstone"},
        {pos: [3, 0, 11], state: "minecraft:blackstone"},
        {pos: [3, 0, 12], state: "minecraft:blackstone"},
        {pos: [3, 0, 13], state: "minecraft:blackstone"},
        {pos: [3, 0, 14], state: "minecraft:blackstone"},
        {pos: [4, 0, 0], state: "minecraft:blackstone"},
        {pos: [4, 0, 1], state: "minecraft:blackstone"},
        {pos: [4, 0, 2], state: "minecraft:blackstone"},
        {pos: [4, 0, 3], state: "minecraft:blackstone"},
        {pos: [4, 0, 4], state: "minecraft:blackstone"},
        {pos: [4, 0, 5], state: "minecraft:blackstone"},
        {pos: [4, 0, 6], state: "minecraft:blackstone"},
        {pos: [4, 0, 7], state: "minecraft:blackstone"},
        {pos: [4, 0, 8], state: "minecraft:blackstone"},
        {pos: [4, 0, 9], state: "minecraft:blackstone"},
        {pos: [4, 0, 10], state: "minecraft:blackstone"},
        {pos: [4, 0, 11], state: "minecraft:blackstone"},
        {pos: [4, 0, 12], state: "minecraft:blackstone"},
        {pos: [4, 0, 13], state: "minecraft:blackstone"},
        {pos: [4, 0, 14], state: "minecraft:blackstone"},
        {pos: [4, 0, 15], state: "minecraft:blackstone"},
        {pos: [5, 0, 0], state: "minecraft:blackstone"},
        {pos: [5, 0, 1], state: "minecraft:blackstone"},
        {pos: [5, 0, 2], state: "minecraft:blackstone"},
        {pos: [5, 0, 3], state: "minecraft:blackstone"},
        {pos: [5, 0, 4], state: "minecraft:blackstone"},
        {pos: [5, 0, 5], state: "minecraft:blackstone"},
        {pos: [5, 0, 6], state: "minecraft:blackstone"},
        {pos: [5, 0, 7], state: "minecraft:blackstone"},
        {pos: [5, 0, 8], state: "minecraft:blackstone"},
        {pos: [5, 0, 9], state: "minecraft:blackstone"},
        {pos: [5, 0, 10], state: "minecraft:blackstone"},
        {pos: [5, 0, 11], state: "minecraft:blackstone"},
        {pos: [5, 0, 12], state: "minecraft:blackstone"},
        {pos: [5, 0, 13], state: "minecraft:blackstone"},
        {pos: [5, 0, 14], state: "minecraft:blackstone"},
        {pos: [6, 0, 0], state: "minecraft:blackstone"},
        {pos: [6, 0, 1], state: "minecraft:blackstone"},
        {pos: [6, 0, 2], state: "minecraft:blackstone"},
        {pos: [6, 0, 3], state: "minecraft:blackstone"},
        {pos: [6, 0, 4], state: "minecraft:blackstone"},
        {pos: [6, 0, 5], state: "minecraft:blackstone"},
        {pos: [6, 0, 6], state: "minecraft:blackstone"},
        {pos: [6, 0, 7], state: "minecraft:blackstone"},
        {pos: [6, 0, 8], state: "minecraft:blackstone"},
        {pos: [6, 0, 9], state: "minecraft:blackstone"},
        {pos: [6, 0, 10], state: "minecraft:blackstone"},
        {pos: [6, 0, 11], state: "minecraft:blackstone"},
        {pos: [6, 0, 12], state: "minecraft:blackstone"},
        {pos: [6, 0, 13], state: "minecraft:blackstone"},
        {pos: [6, 0, 14], state: "minecraft:blackstone"},
        {pos: [7, 0, 0], state: "minecraft:blackstone"},
        {pos: [7, 0, 1], state: "minecraft:blackstone"},
        {pos: [7, 0, 2], state: "minecraft:blackstone"},
        {pos: [7, 0, 3], state: "minecraft:blackstone"},
        {pos: [7, 0, 4], state: "minecraft:blackstone"},
        {pos: [7, 0, 5], state: "minecraft:blackstone"},
        {pos: [7, 0, 6], state: "minecraft:blackstone"},
        {pos: [7, 0, 7], state: "minecraft:blackstone"},
        {pos: [7, 0, 8], state: "minecraft:blackstone"},
        {pos: [7, 0, 9], state: "minecraft:blackstone"},
        {pos: [7, 0, 10], state: "minecraft:blackstone"},
        {pos: [7, 0, 11], state: "minecraft:blackstone"},
        {pos: [7, 0, 12], state: "minecraft:blackstone"},
        {pos: [7, 0, 13], state: "minecraft:blackstone"},
        {pos: [7, 0, 14], state: "minecraft:blackstone"},
        {pos: [7, 0, 15], state: "minecraft:blackstone"},
        {pos: [8, 0, 0], state: "minecraft:blackstone"},
        {pos: [8, 0, 1], state: "minecraft:blackstone"},
        {pos: [8, 0, 2], state: "minecraft:blackstone"},
        {pos: [8, 0, 3], state: "minecraft:blackstone"},
        {pos: [8, 0, 4], state: "minecraft:blackstone"},
        {pos: [8, 0, 5], state: "minecraft:blackstone"},
        {pos: [8, 0, 6], state: "minecraft:blackstone"},
        {pos: [8, 0, 7], state: "minecraft:blackstone"},
        {pos: [8, 0, 8], state: "minecraft:blackstone"},
        {pos: [8, 0, 9], state: "minecraft:blackstone"},
        {pos: [8, 0, 10], state: "minecraft:blackstone"},
        {pos: [8, 0, 11], state: "minecraft:blackstone"},
        {pos: [8, 0, 12], state: "minecraft:blackstone"},
        {pos: [8, 0, 13], state: "minecraft:blackstone"},
        {pos: [8, 0, 14], state: "minecraft:blackstone"},
        {pos: [8, 0, 15], state: "minecraft:blackstone"},
        {pos: [9, 0, 0], state: "minecraft:blackstone"},
        {pos: [9, 0, 1], state: "minecraft:blackstone"},
        {pos: [9, 0, 2], state: "minecraft:blackstone"},
        {pos: [9, 0, 3], state: "minecraft:blackstone"},
        {pos: [9, 0, 4], state: "minecraft:blackstone"},
        {pos: [9, 0, 5], state: "minecraft:blackstone"},
        {pos: [9, 0, 6], state: "minecraft:blackstone"},
        {pos: [9, 0, 7], state: "minecraft:blackstone"},
        {pos: [9, 0, 8], state: "minecraft:blackstone"},
        {pos: [9, 0, 9], state: "minecraft:blackstone"},
        {pos: [9, 0, 10], state: "minecraft:blackstone"},
        {pos: [9, 0, 11], state: "minecraft:blackstone"},
        {pos: [9, 0, 12], state: "minecraft:blackstone"},
        {pos: [9, 0, 13], state: "minecraft:blackstone"},
        {pos: [9, 0, 14], state: "minecraft:blackstone"},
        {pos: [10, 0, 0], state: "minecraft:blackstone"},
        {pos: [10, 0, 1], state: "minecraft:blackstone"},
        {pos: [10, 0, 2], state: "minecraft:blackstone"},
        {pos: [10, 0, 3], state: "minecraft:blackstone"},
        {pos: [10, 0, 4], state: "minecraft:blackstone"},
        {pos: [10, 0, 5], state: "minecraft:blackstone"},
        {pos: [10, 0, 6], state: "minecraft:blackstone"},
        {pos: [10, 0, 7], state: "minecraft:blackstone"},
        {pos: [10, 0, 8], state: "minecraft:blackstone"},
        {pos: [10, 0, 9], state: "minecraft:blackstone"},
        {pos: [10, 0, 10], state: "minecraft:blackstone"},
        {pos: [10, 0, 11], state: "minecraft:blackstone"},
        {pos: [10, 0, 12], state: "minecraft:blackstone"},
        {pos: [10, 0, 13], state: "minecraft:blackstone"},
        {pos: [10, 0, 14], state: "minecraft:blackstone"},
        {pos: [11, 0, 0], state: "minecraft:blackstone"},
        {pos: [11, 0, 1], state: "minecraft:blackstone"},
        {pos: [11, 0, 2], state: "minecraft:blackstone"},
        {pos: [11, 0, 3], state: "minecraft:blackstone"},
        {pos: [11, 0, 4], state: "minecraft:blackstone"},
        {pos: [11, 0, 5], state: "minecraft:blackstone"},
        {pos: [11, 0, 6], state: "minecraft:blackstone"},
        {pos: [11, 0, 7], state: "minecraft:blackstone"},
        {pos: [11, 0, 8], state: "minecraft:blackstone"},
        {pos: [11, 0, 9], state: "minecraft:blackstone"},
        {pos: [11, 0, 10], state: "minecraft:blackstone"},
        {pos: [11, 0, 11], state: "minecraft:blackstone"},
        {pos: [11, 0, 12], state: "minecraft:blackstone"},
        {pos: [11, 0, 13], state: "minecraft:blackstone"},
        {pos: [11, 0, 14], state: "minecraft:blackstone"},
        {pos: [11, 0, 15], state: "minecraft:blackstone"},
        {pos: [12, 0, 0], state: "minecraft:blackstone"},
        {pos: [12, 0, 1], state: "minecraft:blackstone"},
        {pos: [12, 0, 2], state: "minecraft:blackstone"},
        {pos: [12, 0, 3], state: "minecraft:blackstone"},
        {pos: [12, 0, 4], state: "minecraft:blackstone"},
        {pos: [12, 0, 5], state: "minecraft:blackstone"},
        {pos: [12, 0, 6], state: "minecraft:blackstone"},
        {pos: [12, 0, 7], state: "minecraft:blackstone"},
        {pos: [12, 0, 8], state: "minecraft:blackstone"},
        {pos: [12, 0, 9], state: "minecraft:blackstone"},
        {pos: [12, 0, 10], state: "minecraft:blackstone"},
        {pos: [12, 0, 11], state: "minecraft:blackstone"},
        {pos: [12, 0, 12], state: "minecraft:blackstone"},
        {pos: [12, 0, 13], state: "minecraft:blackstone"},
        {pos: [12, 0, 14], state: "minecraft:blackstone"},
        {pos: [13, 0, 0], state: "minecraft:blackstone"},
        {pos: [13, 0, 1], state: "minecraft:blackstone"},
        {pos: [13, 0, 2], state: "minecraft:blackstone"},
        {pos: [13, 0, 3], state: "minecraft:blackstone"},
        {pos: [13, 0, 4], state: "minecraft:blackstone"},
        {pos: [13, 0, 5], state: "minecraft:blackstone"},
        {pos: [13, 0, 6], state: "minecraft:blackstone"},
        {pos: [13, 0, 7], state: "minecraft:blackstone"},
        {pos: [13, 0, 8], state: "minecraft:blackstone"},
        {pos: [13, 0, 9], state: "minecraft:blackstone"},
        {pos: [13, 0, 10], state: "minecraft:blackstone"},
        {pos: [13, 0, 11], state: "minecraft:blackstone"},
        {pos: [13, 0, 12], state: "minecraft:blackstone"},
        {pos: [13, 0, 13], state: "minecraft:blackstone"},
        {pos: [13, 0, 14], state: "minecraft:blackstone"},
        {pos: [14, 0, 0], state: "minecraft:blackstone"},
        {pos: [14, 0, 1], state: "minecraft:blackstone"},
        {pos: [14, 0, 2], state: "minecraft:blackstone"},
        {pos: [14, 0, 3], state: "minecraft:blackstone"},
        {pos: [14, 0, 4], state: "minecraft:blackstone"},
        {pos: [14, 0, 5], state: "minecraft:blackstone"},
        {pos: [14, 0, 6], state: "minecraft:blackstone"},
        {pos: [14, 0, 7], state: "minecraft:blackstone"},
        {pos: [14, 0, 8], state: "minecraft:blackstone"},
        {pos: [14, 0, 9], state: "minecraft:blackstone"},
        {pos: [14, 0, 10], state: "minecraft:blackstone"},
        {pos: [14, 0, 11], state: "minecraft:blackstone"},
        {pos: [14, 0, 12], state: "minecraft:blackstone"},
        {pos: [14, 0, 13], state: "minecraft:blackstone"},
        {pos: [14, 0, 14], state: "minecraft:blackstone"},
        {pos: [15, 0, 0], state: "minecraft:blackstone"},
        {pos: [15, 0, 1], state: "minecraft:blackstone"},
        {pos: [15, 0, 2], state: "minecraft:blackstone"},
        {pos: [15, 0, 3], state: "minecraft:blackstone"},
        {pos: [15, 0, 4], state: "minecraft:blackstone"},
        {pos: [15, 0, 5], state: "minecraft:blackstone"},
        {pos: [15, 0, 6], state: "minecraft:blackstone"},
        {pos: [15, 0, 7], state: "minecraft:cracked_polished_blackstone_bricks"},
        {pos: [15, 0, 8], state: "minecraft:cracked_polished_blackstone_bricks"},
        {pos: [15, 0, 9], state: "minecraft:cracked_polished_blackstone_bricks"},
        {pos: [15, 0, 10], state: "minecraft:cracked_polished_blackstone_bricks"},
        {pos: [15, 0, 11], state: "minecraft:cracked_polished_blackstone_bricks"},
        {pos: [15, 0, 12], state: "minecraft:cracked_polished_blackstone_bricks"},
        {pos: [15, 0, 13], state: "minecraft:blackstone"},
        {pos: [15, 0, 14], state: "minecraft:blackstone"},
        {pos: [0, 1, 0], state: "minecraft:blackstone"},
        {pos: [0, 1, 1], state: "minecraft:blackstone"},
        {pos: [0, 1, 2], state: "minecraft:blackstone"},
        {pos: [0, 1, 3], state: "minecraft:blackstone"},
        {pos: [0, 1, 4], state: "minecraft:blackstone"},
        {pos: [0, 1, 5], state: "minecraft:blackstone"},
        {pos: [0, 1, 6], state: "minecraft:blackstone"},
        {pos: [0, 1, 7], state: "minecraft:blackstone"},
        {pos: [0, 1, 8], state: "minecraft:blackstone"},
        {pos: [0, 1, 12], state: "minecraft:blackstone"},
        {pos: [0, 1, 13], state: "minecraft:blackstone"},
        {pos: [0, 1, 14], state: "minecraft:blackstone"},
        {pos: [0, 1, 15], state: "minecraft:blackstone"},
        {pos: [1, 1, 0], state: "minecraft:blackstone"},
        {pos: [1, 1, 1], state: "minecraft:blackstone"},
        {pos: [1, 1, 2], state: "minecraft:blackstone"},
        {pos: [1, 1, 3], state: "minecraft:blackstone"},
        {pos: [1, 1, 4], state: "minecraft:blackstone"},
        {pos: [1, 1, 5], state: "minecraft:blackstone"},
        {pos: [1, 1, 6], state: "minecraft:blackstone"},
        {pos: [1, 1, 7], state: "minecraft:blackstone"},
        {pos: [1, 1, 8], state: "minecraft:blackstone"},
        {pos: [1, 1, 9], state: "minecraft:blackstone"},
        {pos: [1, 1, 11], state: "minecraft:blackstone"},
        {pos: [1, 1, 12], state: "minecraft:blackstone"},
        {pos: [1, 1, 13], state: "minecraft:blackstone"},
        {pos: [1, 1, 14], state: "minecraft:blackstone"},
        {pos: [2, 1, 0], state: "minecraft:blackstone"},
        {pos: [2, 1, 1], state: "minecraft:blackstone"},
        {pos: [2, 1, 2], state: "minecraft:blackstone"},
        {pos: [2, 1, 3], state: "minecraft:blackstone"},
        {pos: [2, 1, 4], state: "minecraft:blackstone"},
        {pos: [2, 1, 5], state: "minecraft:blackstone"},
        {pos: [2, 1, 6], state: "minecraft:blackstone"},
        {pos: [2, 1, 7], state: "minecraft:blackstone"},
        {pos: [2, 1, 8], state: "minecraft:blackstone"},
        {pos: [2, 1, 9], state: "minecraft:blackstone"},
        {pos: [2, 1, 10], state: "minecraft:blackstone"},
        {pos: [2, 1, 11], state: "minecraft:blackstone"},
        {pos: [2, 1, 12], state: "minecraft:blackstone"},
        {pos: [2, 1, 13], state: "minecraft:blackstone"},
        {pos: [2, 1, 14], state: "minecraft:blackstone"},
        {pos: [3, 1, 0], state: "minecraft:blackstone"},
        {pos: [3, 1, 1], state: "minecraft:blackstone"},
        {pos: [3, 1, 2], state: "minecraft:blackstone"},
        {pos: [3, 1, 3], state: "minecraft:blackstone"},
        {pos: [3, 1, 4], state: "minecraft:blackstone"},
        {pos: [3, 1, 5], state: "minecraft:blackstone"},
        {pos: [3, 1, 6], state: "minecraft:blackstone"},
        {pos: [3, 1, 7], state: "minecraft:blackstone"},
        {pos: [3, 1, 8], state: "minecraft:blackstone"},
        {pos: [3, 1, 9], state: "minecraft:blackstone"},
        {pos: [3, 1, 10], state: "minecraft:blackstone"},
        {pos: [3, 1, 11], state: "minecraft:blackstone"},
        {pos: [3, 1, 12], state: "minecraft:blackstone"},
        {pos: [3, 1, 13], state: "minecraft:blackstone"},
        {pos: [3, 1, 14], state: "minecraft:blackstone"},
        {pos: [3, 1, 15], state: "minecraft:blackstone"},
        {pos: [4, 1, 0], state: "minecraft:blackstone"},
        {pos: [4, 1, 1], state: "minecraft:blackstone"},
        {pos: [4, 1, 2], state: "minecraft:blackstone"},
        {pos: [4, 1, 3], state: "minecraft:blackstone"},
        {pos: [4, 1, 4], state: "minecraft:blackstone"},
        {pos: [4, 1, 5], state: "minecraft:blackstone"},
        {pos: [4, 1, 6], state: "minecraft:blackstone"},
        {pos: [4, 1, 7], state: "minecraft:blackstone"},
        {pos: [4, 1, 8], state: "minecraft:blackstone"},
        {pos: [4, 1, 9], state: "minecraft:blackstone"},
        {pos: [4, 1, 10], state: "minecraft:blackstone"},
        {pos: [4, 1, 11], state: "minecraft:blackstone"},
        {pos: [4, 1, 12], state: "minecraft:blackstone"},
        {pos: [4, 1, 13], state: "minecraft:blackstone"},
        {pos: [4, 1, 14], state: "minecraft:blackstone"},
        {pos: [4, 1, 15], state: "minecraft:blackstone"},
        {pos: [5, 1, 0], state: "minecraft:jigsaw{orientation:north_up}", nbt: {final_state: "minecraft:blackstone", id: "minecraft:jigsaw", joint: "rollable", name: "minecraft:wall_base", pool: "minecraft:bastion/units/edge_wall_units", target: "minecraft:edge_wall_exit"}},
        {pos: [5, 1, 1], state: "minecraft:blackstone"},
        {pos: [5, 1, 2], state: "minecraft:blackstone"},
        {pos: [5, 1, 3], state: "minecraft:blackstone"},
        {pos: [5, 1, 4], state: "minecraft:blackstone"},
        {pos: [5, 1, 5], state: "minecraft:blackstone"},
        {pos: [5, 1, 6], state: "minecraft:blackstone"},
        {pos: [5, 1, 7], state: "minecraft:blackstone"},
        {pos: [5, 1, 8], state: "minecraft:blackstone"},
        {pos: [5, 1, 9], state: "minecraft:blackstone"},
        {pos: [5, 1, 10], state: "minecraft:blackstone"},
        {pos: [5, 1, 11], state: "minecraft:blackstone"},
        {pos: [5, 1, 12], state: "minecraft:blackstone"},
        {pos: [5, 1, 13], state: "minecraft:blackstone"},
        {pos: [5, 1, 14], state: "minecraft:blackstone"},
        {pos: [5, 1, 15], state: "minecraft:blackstone"},
        {pos: [6, 1, 0], state: "minecraft:blackstone"},
        {pos: [6, 1, 1], state: "minecraft:blackstone"},
        {pos: [6, 1, 2], state: "minecraft:blackstone"},
        {pos: [6, 1, 3], state: "minecraft:blackstone"},
        {pos: [6, 1, 4], state: "minecraft:blackstone"},
        {pos: [6, 1, 5], state: "minecraft:blackstone"},
        {pos: [6, 1, 6], state: "minecraft:blackstone"},
        {pos: [6, 1, 7], state: "minecraft:blackstone"},
        {pos: [6, 1, 8], state: "minecraft:blackstone"},
        {pos: [6, 1, 9], state: "minecraft:blackstone"},
        {pos: [6, 1, 10], state: "minecraft:blackstone"},
        {pos: [6, 1, 11], state: "minecraft:blackstone"},
        {pos: [6, 1, 12], state: "minecraft:blackstone"},
        {pos: [6, 1, 13], state: "minecraft:blackstone"},
        {pos: [6, 1, 14], state: "minecraft:blackstone"},
        {pos: [7, 1, 0], state: "minecraft:blackstone"},
        {pos: [7, 1, 1], state: "minecraft:blackstone"},
        {pos: [7, 1, 2], state: "minecraft:blackstone"},
        {pos: [7, 1, 3], state: "minecraft:blackstone"},
        {pos: [7, 1, 4], state: "minecraft:blackstone"},
        {pos: [7, 1, 5], state: "minecraft:blackstone"},
        {pos: [7, 1, 6], state: "minecraft:blackstone"},
        {pos: [7, 1, 7], state: "minecraft:blackstone"},
        {pos: [7, 1, 8], state: "minecraft:blackstone"},
        {pos: [7, 1, 9], state: "minecraft:blackstone"},
        {pos: [7, 1, 10], state: "minecraft:blackstone"},
        {pos: [7, 1, 11], state: "minecraft:blackstone"},
        {pos: [7, 1, 12], state: "minecraft:blackstone"},
        {pos: [7, 1, 13], state: "minecraft:blackstone"},
        {pos: [7, 1, 14], state: "minecraft:blackstone"},
        {pos: [7, 1, 15], state: "minecraft:blackstone"},
        {pos: [8, 1, 0], state: "minecraft:blackstone"},
        {pos: [8, 1, 1], state: "minecraft:blackstone"},
        {pos: [8, 1, 2], state: "minecraft:blackstone"},
        {pos: [8, 1, 3], state: "minecraft:blackstone"},
        {pos: [8, 1, 4], state: "minecraft:blackstone"},
        {pos: [8, 1, 5], state: "minecraft:blackstone"},
        {pos: [8, 1, 6], state: "minecraft:blackstone"},
        {pos: [8, 1, 7], state: "minecraft:blackstone"},
        {pos: [8, 1, 8], state: "minecraft:blackstone"},
        {pos: [8, 1, 9], state: "minecraft:blackstone"},
        {pos: [8, 1, 10], state: "minecraft:blackstone"},
        {pos: [8, 1, 11], state: "minecraft:blackstone"},
        {pos: [8, 1, 12], state: "minecraft:blackstone"},
        {pos: [8, 1, 13], state: "minecraft:blackstone"},
        {pos: [8, 1, 14], state: "minecraft:blackstone"},
        {pos: [9, 1, 0], state: "minecraft:blackstone"},
        {pos: [9, 1, 1], state: "minecraft:blackstone"},
        {pos: [9, 1, 2], state: "minecraft:blackstone"},
        {pos: [9, 1, 3], state: "minecraft:blackstone"},
        {pos: [9, 1, 4], state: "minecraft:blackstone"},
        {pos: [9, 1, 5], state: "minecraft:blackstone"},
        {pos: [9, 1, 6], state: "minecraft:blackstone"},
        {pos: [9, 1, 7], state: "minecraft:blackstone"},
        {pos: [9, 1, 8], state: "minecraft:blackstone"},
        {pos: [9, 1, 9], state: "minecraft:blackstone"},
        {pos: [9, 1, 10], state: "minecraft:blackstone"},
        {pos: [9, 1, 11], state: "minecraft:blackstone"},
        {pos: [9, 1, 12], state: "minecraft:blackstone"},
        {pos: [9, 1, 13], state: "minecraft:blackstone"},
        {pos: [9, 1, 14], state: "minecraft:blackstone"},
        {pos: [10, 1, 0], state: "minecraft:blackstone"},
        {pos: [10, 1, 1], state: "minecraft:blackstone"},
        {pos: [10, 1, 2], state: "minecraft:blackstone"},
        {pos: [10, 1, 3], state: "minecraft:blackstone"},
        {pos: [10, 1, 4], state: "minecraft:blackstone"},
        {pos: [10, 1, 5], state: "minecraft:blackstone"},
        {pos: [10, 1, 6], state: "minecraft:blackstone"},
        {pos: [10, 1, 7], state: "minecraft:blackstone"},
        {pos: [10, 1, 8], state: "minecraft:blackstone"},
        {pos: [10, 1, 9], state: "minecraft:blackstone"},
        {pos: [10, 1, 10], state: "minecraft:blackstone"},
        {pos: [10, 1, 11], state: "minecraft:blackstone"},
        {pos: [10, 1, 12], state: "minecraft:blackstone"},
        {pos: [10, 1, 13], state: "minecraft:blackstone"},
        {pos: [10, 1, 14], state: "minecraft:blackstone"},
        {pos: [10, 1, 15], state: "minecraft:blackstone"},
        {pos: [11, 1, 0], state: "minecraft:blackstone"},
        {pos: [11, 1, 1], state: "minecraft:blackstone"},
        {pos: [11, 1, 2], state: "minecraft:blackstone"},
        {pos: [11, 1, 3], state: "minecraft:blackstone"},
        {pos: [11, 1, 4], state: "minecraft:blackstone"},
        {pos: [11, 1, 5], state: "minecraft:blackstone"},
        {pos: [11, 1, 6], state: "minecraft:blackstone"},
        {pos: [11, 1, 7], state: "minecraft:blackstone"},
        {pos: [11, 1, 8], state: "minecraft:blackstone"},
        {pos: [11, 1, 9], state: "minecraft:blackstone"},
        {pos: [11, 1, 10], state: "minecraft:blackstone"},
        {pos: [11, 1, 11], state: "minecraft:blackstone"},
        {pos: [11, 1, 12], state: "minecraft:blackstone"},
        {pos: [11, 1, 13], state: "minecraft:blackstone"},
        {pos: [11, 1, 14], state: "minecraft:blackstone"},
        {pos: [11, 1, 15], state: "minecraft:blackstone"},
        {pos: [12, 1, 0], state: "minecraft:blackstone"},
        {pos: [12, 1, 1], state: "minecraft:blackstone"},
        {pos: [12, 1, 2], state: "minecraft:blackstone"},
        {pos: [12, 1, 3], state: "minecraft:blackstone"},
        {pos: [12, 1, 4], state: "minecraft:blackstone"},
        {pos: [12, 1, 5], state: "minecraft:blackstone"},
        {pos: [12, 1, 6], state: "minecraft:blackstone"},
        {pos: [12, 1, 7], state: "minecraft:blackstone"},
        {pos: [12, 1, 8], state: "minecraft:blackstone"},
        {pos: [12, 1, 9], state: "minecraft:blackstone"},
        {pos: [12, 1, 10], state: "minecraft:blackstone"},
        {pos: [12, 1, 11], state: "minecraft:blackstone"},
        {pos: [12, 1, 12], state: "minecraft:blackstone"},
        {pos: [12, 1, 13], state: "minecraft:blackstone"},
        {pos: [12, 1, 14], state: "minecraft:blackstone"},
        {pos: [12, 1, 15], state: "minecraft:blackstone"},
        {pos: [13, 1, 0], state: "minecraft:blackstone"},
        {pos: [13, 1, 1], state: "minecraft:blackstone"},
        {pos: [13, 1, 2], state: "minecraft:blackstone"},
        {pos: [13, 1, 3], state: "minecraft:blackstone"},
        {pos: [13, 1, 4], state: "minecraft:blackstone"},
        {pos: [13, 1, 5], state: "minecraft:blackstone"},
        {pos: [13, 1, 6], state: "minecraft:blackstone"},
        {pos: [13, 1, 7], state: "minecraft:blackstone"},
        {pos: [13, 1, 8], state: "minecraft:blackstone"},
        {pos: [13, 1, 9], state: "minecraft:blackstone"},
        {pos: [13, 1, 10], state: "minecraft:blackstone"},
        {pos: [13, 1, 11], state: "minecraft:blackstone"},
        {pos: [13, 1, 12], state: "minecraft:blackstone"},
        {pos: [13, 1, 13], state: "minecraft:blackstone"},
        {pos: [13, 1, 14], state: "minecraft:blackstone"},
        {pos: [14, 1, 0], state: "minecraft:blackstone"},
        {pos: [14, 1, 1], state: "minecraft:blackstone"},
        {pos: [14, 1, 2], state: "minecraft:blackstone"},
        {pos: [14, 1, 3], state: "minecraft:blackstone"},
        {pos: [14, 1, 4], state: "minecraft:blackstone"},
        {pos: [14, 1, 5], state: "minecraft:blackstone"},
        {pos: [14, 1, 6], state: "minecraft:blackstone"},
        {pos: [14, 1, 7], state: "minecraft:blackstone"},
        {pos: [14, 1, 8], state: "minecraft:blackstone"},
        {pos: [14, 1, 9], state: "minecraft:blackstone"},
        {pos: [14, 1, 10], state: "minecraft:blackstone"},
        {pos: [14, 1, 11], state: "minecraft:blackstone"},
        {pos: [14, 1, 12], state: "minecraft:blackstone"},
        {pos: [14, 1, 13], state: "minecraft:blackstone"},
        {pos: [14, 1, 14], state: "minecraft:blackstone"},
        {pos: [14, 1, 15], state: "minecraft:blackstone"},
        {pos: [15, 1, 0], state: "minecraft:jigsaw{orientation:east_up}", nbt: {final_state: "minecraft:blackstone", id: "minecraft:jigsaw", joint: "rollable", name: "minecraft:path_connected_wall", pool: "minecraft:bastion/units/walls/wall_bases", target: "minecraft:wall_connected_wall"}},
        {pos: [15, 1, 1], state: "minecraft:blackstone"},
        {pos: [15, 1, 2], state: "minecraft:blackstone"},
        {pos: [15, 1, 3], state: "minecraft:blackstone"},
        {pos: [15, 1, 4], state: "minecraft:blackstone"},
        {pos: [15, 1, 5], state: "minecraft:blackstone"},
        {pos: [15, 1, 6], state: "minecraft:blackstone"},
        {pos: [15, 1, 7], state: "minecraft:cracked_polished_blackstone_bricks"},
        {pos: [15, 1, 8], state: "minecraft:cracked_polished_blackstone_bricks"},
        {pos: [15, 1, 9], state: "minecraft:cracked_polished_blackstone_bricks"},
        {pos: [15, 1, 10], state: "minecraft:cracked_polished_blackstone_bricks"},
        {pos: [15, 1, 11], state: "minecraft:cracked_polished_blackstone_bricks"},
        {pos: [15, 1, 12], state: "minecraft:cracked_polished_blackstone_bricks"},
        {pos: [15, 1, 13], state: "minecraft:blackstone"},
        {pos: [15, 1, 14], state: "minecraft:blackstone"},
        {pos: [15, 1, 15], state: "minecraft:blackstone"},
        {pos: [0, 2, 0], state: "minecraft:blackstone"},
        {pos: [0, 2, 1], state: "minecraft:blackstone"},
        {pos: [0, 2, 2], state: "minecraft:blackstone"},
        {pos: [0, 2, 3], state: "minecraft:blackstone"},
        {pos: [0, 2, 4], state: "minecraft:blackstone"},
        {pos: [0, 2, 5], state: "minecraft:blackstone"},
        {pos: [0, 2, 6], state: "minecraft:blackstone"},
        {pos: [0, 2, 7], state: "minecraft:blackstone"},
        {pos: [0, 2, 13], state: "minecraft:blackstone"},
        {pos: [0, 2, 14], state: "minecraft:blackstone"},
        {pos: [0, 2, 15], state: "minecraft:blackstone"},
        {pos: [1, 2, 0], state: "minecraft:blackstone"},
        {pos: [1, 2, 1], state: "minecraft:blackstone"},
        {pos: [1, 2, 2], state: "minecraft:blackstone"},
        {pos: [1, 2, 3], state: "minecraft:blackstone"},
        {pos: [1, 2, 4], state: "minecraft:blackstone"},
        {pos: [1, 2, 5], state: "minecraft:blackstone"},
        {pos: [1, 2, 6], state: "minecraft:blackstone"},
        {pos: [1, 2, 7], state: "minecraft:blackstone"},
        {pos: [1, 2, 12], state: "minecraft:blackstone"},
        {pos: [1, 2, 13], state: "minecraft:blackstone"},
        {pos: [1, 2, 14], state: "minecraft:blackstone"},
        {pos: [1, 2, 15], state: "minecraft:blackstone"},
        {pos: [2, 2, 0], state: "minecraft:blackstone"},
        {pos: [2, 2, 1], state: "minecraft:blackstone"},
        {pos: [2, 2, 2], state: "minecraft:blackstone"},
        {pos: [2, 2, 3], state: "minecraft:jigsaw{orientation:up_east}", nbt: {final_state: "minecraft:polished_blackstone_bricks", id: "minecraft:jigsaw", joint: "rollable", name: "minecraft:empty", pool: "minecraft:bastion/mobs/piglin", target: "minecraft:mob_connector"}},
        {pos: [2, 2, 4], state: "minecraft:blackstone"},
        {pos: [2, 2, 5], state: "minecraft:gilded_blackstone"},
        {pos: [2, 2, 6], state: "minecraft:blackstone"},
        {pos: [2, 2, 7], state: "minecraft:blackstone"},
        {pos: [2, 2, 8], state: "minecraft:blackstone"},
        {pos: [2, 2, 9], state: "minecraft:blackstone"},
        {pos: [2, 2, 10], state: "minecraft:cracked_polished_blackstone_bricks"},
        {pos: [2, 2, 11], state: "minecraft:blackstone"},
        {pos: [2, 2, 12], state: "minecraft:blackstone"},
        {pos: [2, 2, 13], state: "minecraft:blackstone"},
        {pos: [2, 2, 14], state: "minecraft:blackstone"},
        {pos: [3, 2, 0], state: "minecraft:blackstone"},
        {pos: [3, 2, 1], state: "minecraft:blackstone"},
        {pos: [3, 2, 2], state: "minecraft:blackstone"},
        {pos: [3, 2, 3], state: "minecraft:blackstone"},
        {pos: [3, 2, 4], state: "minecraft:blackstone"},
        {pos: [3, 2, 5], state: "minecraft:blackstone"},
        {pos: [3, 2, 6], state: "minecraft:blackstone"},
        {pos: [3, 2, 7], state: "minecraft:blackstone"},
        {pos: [3, 2, 8], state: "minecraft:blackstone"},
        {pos: [3, 2, 9], state: "minecraft:blackstone"},
        {pos: [3, 2, 10], state: "minecraft:blackstone"},
        {pos: [3, 2, 11], state: "minecraft:blackstone"},
        {pos: [3, 2, 12], state: "minecraft:blackstone"},
        {pos: [3, 2, 13], state: "minecraft:blackstone"},
        {pos: [3, 2, 14], state: "minecraft:blackstone"},
        {pos: [3, 2, 15], state: "minecraft:blackstone"},
        {pos: [4, 2, 0], state: "minecraft:blackstone"},
        {pos: [4, 2, 1], state: "minecraft:blackstone"},
        {pos: [4, 2, 2], state: "minecraft:blackstone"},
        {pos: [4, 2, 3], state: "minecraft:blackstone"},
        {pos: [4, 2, 4], state: "minecraft:blackstone"},
        {pos: [4, 2, 5], state: "minecraft:blackstone"},
        {pos: [4, 2, 6], state: "minecraft:blackstone"},
        {pos: [4, 2, 7], state: "minecraft:blackstone"},
        {pos: [4, 2, 8], state: "minecraft:blackstone"},
        {pos: [4, 2, 9], state: "minecraft:blackstone"},
        {pos: [4, 2, 10], state: "minecraft:blackstone"},
        {pos: [4, 2, 11], state: "minecraft:blackstone"},
        {pos: [4, 2, 12], state: "minecraft:blackstone"},
        {pos: [4, 2, 13], state: "minecraft:blackstone"},
        {pos: [4, 2, 14], state: "minecraft:blackstone"},
        {pos: [4, 2, 15], state: "minecraft:blackstone"},
        {pos: [5, 2, 0], state: "minecraft:blackstone"},
        {pos: [5, 2, 1], state: "minecraft:blackstone"},
        {pos: [5, 2, 2], state: "minecraft:blackstone"},
        {pos: [5, 2, 3], state: "minecraft:blackstone"},
        {pos: [5, 2, 4], state: "minecraft:blackstone"},
        {pos: [5, 2, 5], state: "minecraft:blackstone"},
        {pos: [5, 2, 6], state: "minecraft:blackstone"},
        {pos: [5, 2, 7], state: "minecraft:blackstone"},
        {pos: [5, 2, 8], state: "minecraft:blackstone"},
        {pos: [5, 2, 9], state: "minecraft:blackstone"},
        {pos: [5, 2, 10], state: "minecraft:blackstone"},
        {pos: [5, 2, 11], state: "minecraft:blackstone"},
        {pos: [5, 2, 12], state: "minecraft:blackstone"},
        {pos: [5, 2, 13], state: "minecraft:blackstone"},
        {pos: [5, 2, 14], state: "minecraft:blackstone"},
        {pos: [5, 2, 15], state: "minecraft:blackstone"},
        {pos: [6, 2, 0], state: "minecraft:blackstone"},
        {pos: [6, 2, 1], state: "minecraft:blackstone"},
        {pos: [6, 2, 2], state: "minecraft:blackstone"},
        {pos: [6, 2, 3], state: "minecraft:blackstone"},
        {pos: [6, 2, 4], state: "minecraft:blackstone"},
        {pos: [6, 2, 5], state: "minecraft:blackstone"},
        {pos: [6, 2, 6], state: "minecraft:blackstone"},
        {pos: [6, 2, 7], state: "minecraft:blackstone"},
        {pos: [6, 2, 8], state: "minecraft:blackstone"},
        {pos: [6, 2, 9], state: "minecraft:blackstone"},
        {pos: [6, 2, 10], state: "minecraft:blackstone"},
        {pos: [6, 2, 11], state: "minecraft:blackstone"},
        {pos: [6, 2, 12], state: "minecraft:blackstone"},
        {pos: [6, 2, 13], state: "minecraft:blackstone"},
        {pos: [6, 2, 14], state: "minecraft:blackstone"},
        {pos: [7, 2, 0], state: "minecraft:blackstone"},
        {pos: [7, 2, 1], state: "minecraft:blackstone"},
        {pos: [7, 2, 2], state: "minecraft:blackstone"},
        {pos: [7, 2, 3], state: "minecraft:blackstone"},
        {pos: [7, 2, 4], state: "minecraft:blackstone"},
        {pos: [7, 2, 5], state: "minecraft:blackstone"},
        {pos: [7, 2, 6], state: "minecraft:blackstone"},
        {pos: [7, 2, 7], state: "minecraft:blackstone"},
        {pos: [7, 2, 8], state: "minecraft:blackstone"},
        {pos: [7, 2, 9], state: "minecraft:blackstone"},
        {pos: [7, 2, 10], state: "minecraft:blackstone"},
        {pos: [7, 2, 11], state: "minecraft:blackstone"},
        {pos: [7, 2, 12], state: "minecraft:blackstone"},
        {pos: [7, 2, 13], state: "minecraft:blackstone"},
        {pos: [7, 2, 14], state: "minecraft:blackstone"},
        {pos: [7, 2, 15], state: "minecraft:blackstone"},
        {pos: [8, 2, 0], state: "minecraft:blackstone"},
        {pos: [8, 2, 1], state: "minecraft:blackstone"},
        {pos: [8, 2, 2], state: "minecraft:blackstone"},
        {pos: [8, 2, 3], state: "minecraft:blackstone"},
        {pos: [8, 2, 4], state: "minecraft:blackstone"},
        {pos: [8, 2, 5], state: "minecraft:blackstone"},
        {pos: [8, 2, 6], state: "minecraft:blackstone"},
        {pos: [8, 2, 7], state: "minecraft:blackstone"},
        {pos: [8, 2, 8], state: "minecraft:blackstone"},
        {pos: [8, 2, 9], state: "minecraft:blackstone"},
        {pos: [8, 2, 10], state: "minecraft:blackstone"},
        {pos: [8, 2, 11], state: "minecraft:blackstone"},
        {pos: [8, 2, 12], state: "minecraft:blackstone"},
        {pos: [8, 2, 13], state: "minecraft:blackstone"},
        {pos: [8, 2, 14], state: "minecraft:blackstone"},
        {pos: [8, 2, 15], state: "minecraft:blackstone"},
        {pos: [9, 2, 0], state: "minecraft:blackstone"},
        {pos: [9, 2, 1], state: "minecraft:blackstone"},
        {pos: [9, 2, 2], state: "minecraft:blackstone"},
        {pos: [9, 2, 3], state: "minecraft:blackstone"},
        {pos: [9, 2, 4], state: "minecraft:blackstone"},
        {pos: [9, 2, 5], state: "minecraft:blackstone"},
        {pos: [9, 2, 6], state: "minecraft:blackstone"},
        {pos: [9, 2, 7], state: "minecraft:blackstone"},
        {pos: [9, 2, 8], state: "minecraft:blackstone"},
        {pos: [9, 2, 9], state: "minecraft:blackstone"},
        {pos: [9, 2, 10], state: "minecraft:blackstone"},
        {pos: [9, 2, 11], state: "minecraft:blackstone"},
        {pos: [9, 2, 12], state: "minecraft:blackstone"},
        {pos: [9, 2, 13], state: "minecraft:blackstone"},
        {pos: [9, 2, 14], state: "minecraft:blackstone"},
        {pos: [10, 2, 0], state: "minecraft:blackstone"},
        {pos: [10, 2, 1], state: "minecraft:blackstone"},
        {pos: [10, 2, 2], state: "minecraft:blackstone"},
        {pos: [10, 2, 3], state: "minecraft:blackstone"},
        {pos: [10, 2, 4], state: "minecraft:blackstone"},
        {pos: [10, 2, 5], state: "minecraft:blackstone"},
        {pos: [10, 2, 6], state: "minecraft:blackstone"},
        {pos: [10, 2, 7], state: "minecraft:blackstone"},
        {pos: [10, 2, 8], state: "minecraft:blackstone"},
        {pos: [10, 2, 9], state: "minecraft:blackstone"},
        {pos: [10, 2, 10], state: "minecraft:blackstone"},
        {pos: [10, 2, 11], state: "minecraft:blackstone"},
        {pos: [10, 2, 12], state: "minecraft:blackstone"},
        {pos: [10, 2, 13], state: "minecraft:blackstone"},
        {pos: [10, 2, 14], state: "minecraft:blackstone"},
        {pos: [10, 2, 15], state: "minecraft:blackstone"},
        {pos: [11, 2, 0], state: "minecraft:blackstone"},
        {pos: [11, 2, 1], state: "minecraft:blackstone"},
        {pos: [11, 2, 2], state: "minecraft:blackstone"},
        {pos: [11, 2, 3], state: "minecraft:blackstone"},
        {pos: [11, 2, 4], state: "minecraft:blackstone"},
        {pos: [11, 2, 5], state: "minecraft:blackstone"},
        {pos: [11, 2, 6], state: "minecraft:blackstone"},
        {pos: [11, 2, 7], state: "minecraft:blackstone"},
        {pos: [11, 2, 8], state: "minecraft:blackstone"},
        {pos: [11, 2, 9], state: "minecraft:blackstone"},
        {pos: [11, 2, 10], state: "minecraft:blackstone"},
        {pos: [11, 2, 11], state: "minecraft:blackstone"},
        {pos: [11, 2, 12], state: "minecraft:blackstone"},
        {pos: [11, 2, 13], state: "minecraft:blackstone"},
        {pos: [11, 2, 14], state: "minecraft:blackstone"},
        {pos: [11, 2, 15], state: "minecraft:blackstone"},
        {pos: [12, 2, 0], state: "minecraft:blackstone"},
        {pos: [12, 2, 1], state: "minecraft:blackstone"},
        {pos: [12, 2, 2], state: "minecraft:blackstone"},
        {pos: [12, 2, 3], state: "minecraft:blackstone"},
        {pos: [12, 2, 4], state: "minecraft:blackstone"},
        {pos: [12, 2, 5], state: "minecraft:blackstone"},
        {pos: [12, 2, 6], state: "minecraft:blackstone"},
        {pos: [12, 2, 7], state: "minecraft:blackstone"},
        {pos: [12, 2, 8], state: "minecraft:blackstone"},
        {pos: [12, 2, 9], state: "minecraft:blackstone"},
        {pos: [12, 2, 10], state: "minecraft:blackstone"},
        {pos: [12, 2, 11], state: "minecraft:blackstone"},
        {pos: [12, 2, 12], state: "minecraft:blackstone"},
        {pos: [12, 2, 13], state: "minecraft:blackstone"},
        {pos: [12, 2, 14], state: "minecraft:blackstone"},
        {pos: [12, 2, 15], state: "minecraft:blackstone"},
        {pos: [13, 2, 0], state: "minecraft:blackstone"},
        {pos: [13, 2, 1], state: "minecraft:blackstone"},
        {pos: [13, 2, 2], state: "minecraft:blackstone"},
        {pos: [13, 2, 3], state: "minecraft:blackstone"},
        {pos: [13, 2, 4], state: "minecraft:blackstone"},
        {pos: [13, 2, 5], state: "minecraft:blackstone"},
        {pos: [13, 2, 6], state: "minecraft:blackstone"},
        {pos: [13, 2, 7], state: "minecraft:blackstone"},
        {pos: [13, 2, 8], state: "minecraft:blackstone"},
        {pos: [13, 2, 9], state: "minecraft:blackstone"},
        {pos: [13, 2, 10], state: "minecraft:blackstone"},
        {pos: [13, 2, 11], state: "minecraft:blackstone"},
        {pos: [13, 2, 12], state: "minecraft:blackstone"},
        {pos: [13, 2, 13], state: "minecraft:blackstone"},
        {pos: [13, 2, 14], state: "minecraft:blackstone"},
        {pos: [14, 2, 0], state: "minecraft:blackstone"},
        {pos: [14, 2, 1], state: "minecraft:blackstone"},
        {pos: [14, 2, 2], state: "minecraft:blackstone"},
        {pos: [14, 2, 3], state: "minecraft:blackstone"},
        {pos: [14, 2, 4], state: "minecraft:blackstone"},
        {pos: [14, 2, 5], state: "minecraft:blackstone"},
        {pos: [14, 2, 6], state: "minecraft:blackstone"},
        {pos: [14, 2, 7], state: "minecraft:blackstone"},
        {pos: [14, 2, 8], state: "minecraft:blackstone"},
        {pos: [14, 2, 9], state: "minecraft:blackstone"},
        {pos: [14, 2, 10], state: "minecraft:blackstone"},
        {pos: [14, 2, 11], state: "minecraft:blackstone"},
        {pos: [14, 2, 12], state: "minecraft:blackstone"},
        {pos: [14, 2, 13], state: "minecraft:blackstone"},
        {pos: [14, 2, 14], state: "minecraft:blackstone"},
        {pos: [14, 2, 15], state: "minecraft:blackstone"},
        {pos: [15, 2, 0], state: "minecraft:blackstone"},
        {pos: [15, 2, 1], state: "minecraft:blackstone"},
        {pos: [15, 2, 2], state: "minecraft:blackstone"},
        {pos: [15, 2, 3], state: "minecraft:blackstone"},
        {pos: [15, 2, 4], state: "minecraft:blackstone"},
        {pos: [15, 2, 5], state: "minecraft:blackstone"},
        {pos: [15, 2, 6], state: "minecraft:blackstone"},
        {pos: [15, 2, 7], state: "minecraft:blackstone"},
        {pos: [15, 2, 8], state: "minecraft:blackstone"},
        {pos: [15, 2, 9], state: "minecraft:cracked_polished_blackstone_bricks"},
        {pos: [15, 2, 10], state: "minecraft:cracked_polished_blackstone_bricks"},
        {pos: [15, 2, 11], state: "minecraft:cracked_polished_blackstone_bricks"},
        {pos: [15, 2, 12], state: "minecraft:cracked_polished_blackstone_bricks"},
        {pos: [15, 2, 13], state: "minecraft:blackstone"},
        {pos: [15, 2, 14], state: "minecraft:blackstone"},
        {pos: [15, 2, 15], state: "minecraft:blackstone"},
        {pos: [0, 3, 0], state: "minecraft:blackstone"},
        {pos: [0, 3, 1], state: "minecraft:blackstone"},
        {pos: [0, 3, 2], state: "minecraft:blackstone"},
        {pos: [0, 3, 3], state: "minecraft:blackstone"},
        {pos: [0, 3, 4], state: "minecraft:blackstone"},
        {pos: [0, 3, 5], state: "minecraft:blackstone"},
        {pos: [0, 3, 6], state: "minecraft:blackstone"},
        {pos: [0, 3, 7], state: "minecraft:blackstone"},
        {pos: [0, 3, 12], state: "minecraft:blackstone"},
        {pos: [0, 3, 13], state: "minecraft:blackstone"},
        {pos: [0, 3, 14], state: "minecraft:blackstone"},
        {pos: [1, 3, 0], state: "minecraft:air"},
        {pos: [1, 3, 1], state: "minecraft:air"},
        {pos: [1, 3, 2], state: "minecraft:blackstone"},
        {pos: [1, 3, 3], state: "minecraft:blackstone"},
        {pos: [1, 3, 4], state: "minecraft:blackstone"},
        {pos: [1, 3, 5], state: "minecraft:blackstone"},
        {pos: [1, 3, 6], state: "minecraft:blackstone"},
        {pos: [1, 3, 7], state: "minecraft:blackstone"},
        {pos: [1, 3, 8], state: "minecraft:blackstone"},
        {pos: [1, 3, 9], state: "minecraft:blackstone"},
        {pos: [1, 3, 11], state: "minecraft:blackstone"},
        {pos: [1, 3, 12], state: "minecraft:blackstone"},
        {pos: [1, 3, 13], state: "minecraft:blackstone"},
        {pos: [1, 3, 14], state: "minecraft:blackstone"},
        {pos: [2, 3, 0], state: "minecraft:air"},
        {pos: [2, 3, 1], state: "minecraft:air"},
        {pos: [2, 3, 2], state: "minecraft:blackstone"},
        {pos: [2, 3, 3], state: "minecraft:air"},
        {pos: [2, 3, 4], state: "minecraft:gilded_blackstone"},
        {pos: [2, 3, 5], state: "minecraft:gilded_blackstone"},
        {pos: [2, 3, 6], state: "minecraft:blackstone"},
        {pos: [2, 3, 7], state: "minecraft:blackstone"},
        {pos: [2, 3, 8], state: "minecraft:blackstone"},
        {pos: [2, 3, 9], state: "minecraft:blackstone"},
        {pos: [2, 3, 10], state: "minecraft:blackstone"},
        {pos: [2, 3, 11], state: "minecraft:blackstone"},
        {pos: [2, 3, 12], state: "minecraft:blackstone"},
        {pos: [2, 3, 13], state: "minecraft:blackstone"},
        {pos: [2, 3, 14], state: "minecraft:blackstone"},
        {pos: [3, 3, 0], state: "minecraft:air"},
        {pos: [3, 3, 1], state: "minecraft:air"},
        {pos: [3, 3, 2], state: "minecraft:blackstone"},
        {pos: [3, 3, 3], state: "minecraft:blackstone"},
        {pos: [3, 3, 4], state: "minecraft:blackstone"},
        {pos: [3, 3, 5], state: "minecraft:gilded_blackstone"},
        {pos: [3, 3, 6], state: "minecraft:blackstone"},
        {pos: [3, 3, 7], state: "minecraft:blackstone"},
        {pos: [3, 3, 8], state: "minecraft:blackstone"},
        {pos: [3, 3, 9], state: "minecraft:blackstone"},
        {pos: [3, 3, 10], state: "minecraft:blackstone"},
        {pos: [3, 3, 11], state: "minecraft:blackstone"},
        {pos: [3, 3, 12], state: "minecraft:blackstone"},
        {pos: [3, 3, 13], state: "minecraft:blackstone"},
        {pos: [3, 3, 14], state: "minecraft:blackstone"},
        {pos: [4, 3, 0], state: "minecraft:air"},
        {pos: [4, 3, 1], state: "minecraft:blackstone"},
        {pos: [4, 3, 2], state: "minecraft:blackstone"},
        {pos: [4, 3, 3], state: "minecraft:gilded_blackstone"},
        {pos: [4, 3, 4], state: "minecraft:blackstone"},
        {pos: [4, 3, 5], state: "minecraft:gilded_blackstone"},
        {pos: [4, 3, 6], state: "minecraft:blackstone"},
        {pos: [4, 3, 7], state: "minecraft:blackstone"},
        {pos: [4, 3, 8], state: "minecraft:blackstone"},
        {pos: [4, 3, 9], state: "minecraft:blackstone"},
        {pos: [4, 3, 10], state: "minecraft:blackstone"},
        {pos: [4, 3, 11], state: "minecraft:cracked_polished_blackstone_bricks"},
        {pos: [4, 3, 12], state: "minecraft:cracked_polished_blackstone_bricks"},
        {pos: [4, 3, 13], state: "minecraft:blackstone"},
        {pos: [4, 3, 14], state: "minecraft:blackstone"},
        {pos: [5, 3, 0], state: "minecraft:blackstone"},
        {pos: [5, 3, 1], state: "minecraft:blackstone"},
        {pos: [5, 3, 2], state: "minecraft:blackstone"},
        {pos: [5, 3, 3], state: "minecraft:blackstone"},
        {pos: [5, 3, 4], state: "minecraft:blackstone"},
        {pos: [5, 3, 5], state: "minecraft:blackstone"},
        {pos: [5, 3, 6], state: "minecraft:blackstone"},
        {pos: [5, 3, 7], state: "minecraft:blackstone"},
        {pos: [5, 3, 8], state: "minecraft:blackstone"},
        {pos: [5, 3, 9], state: "minecraft:blackstone"},
        {pos: [5, 3, 10], state: "minecraft:gold_block"},
        {pos: [5, 3, 11], state: "minecraft:gold_block"},
        {pos: [5, 3, 12], state: "minecraft:cracked_polished_blackstone_bricks"},
        {pos: [5, 3, 13], state: "minecraft:blackstone"},
        {pos: [5, 3, 14], state: "minecraft:blackstone"},
        {pos: [6, 3, 0], state: "minecraft:blackstone"},
        {pos: [6, 3, 1], state: "minecraft:blackstone"},
        {pos: [6, 3, 2], state: "minecraft:blackstone"},
        {pos: [6, 3, 3], state: "minecraft:blackstone"},
        {pos: [6, 3, 4], state: "minecraft:blackstone"},
        {pos: [6, 3, 5], state: "minecraft:blackstone"},
        {pos: [6, 3, 6], state: "minecraft:blackstone"},
        {pos: [6, 3, 7], state: "minecraft:blackstone"},
        {pos: [6, 3, 8], state: "minecraft:blackstone"},
        {pos: [6, 3, 9], state: "minecraft:blackstone"},
        {pos: [6, 3, 10], state: "minecraft:cracked_polished_blackstone_bricks"},
        {pos: [6, 3, 11], state: "minecraft:gold_block"},
        {pos: [6, 3, 12], state: "minecraft:gold_block"},
        {pos: [6, 3, 13], state: "minecraft:blackstone"},
        {pos: [6, 3, 14], state: "minecraft:blackstone"},
        {pos: [7, 3, 0], state: "minecraft:blackstone"},
        {pos: [7, 3, 1], state: "minecraft:blackstone"},
        {pos: [7, 3, 2], state: "minecraft:blackstone"},
        {pos: [7, 3, 3], state: "minecraft:blackstone"},
        {pos: [7, 3, 4], state: "minecraft:blackstone"},
        {pos: [7, 3, 5], state: "minecraft:blackstone"},
        {pos: [7, 3, 6], state: "minecraft:blackstone"},
        {pos: [7, 3, 7], state: "minecraft:blackstone"},
        {pos: [7, 3, 8], state: "minecraft:blackstone"},
        {pos: [7, 3, 9], state: "minecraft:blackstone"},
        {pos: [7, 3, 10], state: "minecraft:gold_block"},
        {pos: [7, 3, 11], state: "minecraft:blackstone"},
        {pos: [7, 3, 12], state: "minecraft:blackstone"},
        {pos: [7, 3, 13], state: "minecraft:blackstone"},
        {pos: [7, 3, 14], state: "minecraft:blackstone"},
        {pos: [8, 3, 0], state: "minecraft:cracked_polished_blackstone_bricks"},
        {pos: [8, 3, 1], state: "minecraft:blackstone"},
        {pos: [8, 3, 2], state: "minecraft:blackstone"},
        {pos: [8, 3, 3], state: "minecraft:blackstone"},
        {pos: [8, 3, 4], state: "minecraft:blackstone"},
        {pos: [8, 3, 5], state: "minecraft:blackstone"},
        {pos: [8, 3, 6], state: "minecraft:blackstone"},
        {pos: [8, 3, 7], state: "minecraft:blackstone"},
        {pos: [8, 3, 8], state: "minecraft:blackstone"},
        {pos: [8, 3, 9], state: "minecraft:blackstone"},
        {pos: [8, 3, 10], state: "minecraft:blackstone"},
        {pos: [8, 3, 11], state: "minecraft:blackstone"},
        {pos: [8, 3, 12], state: "minecraft:blackstone"},
        {pos: [8, 3, 13], state: "minecraft:blackstone"},
        {pos: [8, 3, 14], state: "minecraft:blackstone"},
        {pos: [9, 3, 0], state: "minecraft:cracked_polished_blackstone_bricks"},
        {pos: [9, 3, 1], state: "minecraft:blackstone"},
        {pos: [9, 3, 2], state: "minecraft:blackstone"},
        {pos: [9, 3, 3], state: "minecraft:blackstone"},
        {pos: [9, 3, 4], state: "minecraft:blackstone"},
        {pos: [9, 3, 5], state: "minecraft:blackstone"},
        {pos: [9, 3, 6], state: "minecraft:blackstone"},
        {pos: [9, 3, 7], state: "minecraft:blackstone"},
        {pos: [9, 3, 8], state: "minecraft:blackstone"},
        {pos: [9, 3, 9], state: "minecraft:blackstone"},
        {pos: [9, 3, 10], state: "minecraft:blackstone"},
        {pos: [9, 3, 11], state: "minecraft:blackstone"},
        {pos: [9, 3, 12], state: "minecraft:blackstone"},
        {pos: [9, 3, 13], state: "minecraft:blackstone"},
        {pos: [9, 3, 14], state: "minecraft:blackstone"},
        {pos: [10, 3, 0], state: "minecraft:cracked_polished_blackstone_bricks"},
        {pos: [10, 3, 1], state: "minecraft:blackstone"},
        {pos: [10, 3, 2], state: "minecraft:blackstone"},
        {pos: [10, 3, 3], state: "minecraft:blackstone"},
        {pos: [10, 3, 4], state: "minecraft:blackstone"},
        {pos: [10, 3, 5], state: "minecraft:blackstone"},
        {pos: [10, 3, 6], state: "minecraft:blackstone"},
        {pos: [10, 3, 7], state: "minecraft:blackstone"},
        {pos: [10, 3, 8], state: "minecraft:blackstone"},
        {pos: [10, 3, 9], state: "minecraft:blackstone"},
        {pos: [10, 3, 10], state: "minecraft:blackstone"},
        {pos: [10, 3, 11], state: "minecraft:blackstone"},
        {pos: [10, 3, 12], state: "minecraft:blackstone"},
        {pos: [10, 3, 13], state: "minecraft:blackstone"},
        {pos: [10, 3, 14], state: "minecraft:blackstone"},
        {pos: [11, 3, 0], state: "minecraft:blackstone"},
        {pos: [11, 3, 1], state: "minecraft:blackstone"},
        {pos: [11, 3, 2], state: "minecraft:blackstone"},
        {pos: [11, 3, 3], state: "minecraft:blackstone"},
        {pos: [11, 3, 4], state: "minecraft:blackstone"},
        {pos: [11, 3, 5], state: "minecraft:blackstone"},
        {pos: [11, 3, 6], state: "minecraft:blackstone"},
        {pos: [11, 3, 7], state: "minecraft:blackstone"},
        {pos: [11, 3, 8], state: "minecraft:blackstone"},
        {pos: [11, 3, 9], state: "minecraft:blackstone"},
        {pos: [11, 3, 10], state: "minecraft:blackstone"},
        {pos: [11, 3, 11], state: "minecraft:blackstone"},
        {pos: [11, 3, 12], state: "minecraft:blackstone"},
        {pos: [11, 3, 13], state: "minecraft:blackstone"},
        {pos: [11, 3, 14], state: "minecraft:blackstone"},
        {pos: [12, 3, 0], state: "minecraft:blackstone"},
        {pos: [12, 3, 1], state: "minecraft:blackstone"},
        {pos: [12, 3, 2], state: "minecraft:blackstone"},
        {pos: [12, 3, 3], state: "minecraft:blackstone"},
        {pos: [12, 3, 4], state: "minecraft:blackstone"},
        {pos: [12, 3, 5], state: "minecraft:blackstone"},
        {pos: [12, 3, 6], state: "minecraft:blackstone"},
        {pos: [12, 3, 7], state: "minecraft:blackstone"},
        {pos: [12, 3, 8], state: "minecraft:blackstone"},
        {pos: [12, 3, 9], state: "minecraft:blackstone"},
        {pos: [12, 3, 10], state: "minecraft:blackstone"},
        {pos: [12, 3, 11], state: "minecraft:blackstone"},
        {pos: [12, 3, 12], state: "minecraft:blackstone"},
        {pos: [12, 3, 13], state: "minecraft:blackstone"},
        {pos: [12, 3, 14], state: "minecraft:blackstone"},
        {pos: [13, 3, 0], state: "minecraft:blackstone"},
        {pos: [13, 3, 1], state: "minecraft:blackstone"},
        {pos: [13, 3, 2], state: "minecraft:blackstone"},
        {pos: [13, 3, 3], state: "minecraft:blackstone"},
        {pos: [13, 3, 4], state: "minecraft:blackstone"},
        {pos: [13, 3, 5], state: "minecraft:blackstone"},
        {pos: [13, 3, 6], state: "minecraft:blackstone"},
        {pos: [13, 3, 7], state: "minecraft:blackstone"},
        {pos: [13, 3, 8], state: "minecraft:blackstone"},
        {pos: [13, 3, 9], state: "minecraft:blackstone"},
        {pos: [13, 3, 10], state: "minecraft:blackstone"},
        {pos: [13, 3, 11], state: "minecraft:blackstone"},
        {pos: [13, 3, 12], state: "minecraft:blackstone"},
        {pos: [13, 3, 13], state: "minecraft:blackstone"},
        {pos: [13, 3, 14], state: "minecraft:blackstone"},
        {pos: [14, 3, 0], state: "minecraft:blackstone"},
        {pos: [14, 3, 1], state: "minecraft:blackstone"},
        {pos: [14, 3, 2], state: "minecraft:blackstone"},
        {pos: [14, 3, 3], state: "minecraft:blackstone"},
        {pos: [14, 3, 4], state: "minecraft:blackstone"},
        {pos: [14, 3, 5], state: "minecraft:blackstone"},
        {pos: [14, 3, 6], state: "minecraft:blackstone"},
        {pos: [14, 3, 7], state: "minecraft:blackstone"},
        {pos: [14, 3, 8], state: "minecraft:blackstone"},
        {pos: [14, 3, 9], state: "minecraft:blackstone"},
        {pos: [14, 3, 10], state: "minecraft:blackstone"},
        {pos: [14, 3, 11], state: "minecraft:blackstone"},
        {pos: [14, 3, 12], state: "minecraft:blackstone"},
        {pos: [14, 3, 13], state: "minecraft:blackstone"},
        {pos: [14, 3, 14], state: "minecraft:blackstone"},
        {pos: [15, 3, 0], state: "minecraft:blackstone"},
        {pos: [15, 3, 1], state: "minecraft:blackstone"},
        {pos: [15, 3, 2], state: "minecraft:blackstone"},
        {pos: [15, 3, 3], state: "minecraft:blackstone"},
        {pos: [15, 3, 4], state: "minecraft:blackstone"},
        {pos: [15, 3, 5], state: "minecraft:blackstone"},
        {pos: [15, 3, 6], state: "minecraft:blackstone"},
        {pos: [15, 3, 7], state: "minecraft:blackstone"},
        {pos: [15, 3, 8], state: "minecraft:blackstone"},
        {pos: [15, 3, 9], state: "minecraft:blackstone"},
        {pos: [15, 3, 10], state: "minecraft:cracked_polished_blackstone_bricks"},
        {pos: [15, 3, 11], state: "minecraft:cracked_polished_blackstone_bricks"},
        {pos: [15, 3, 12], state: "minecraft:cracked_polished_blackstone_bricks"},
        {pos: [15, 3, 13], state: "minecraft:blackstone"},
        {pos: [15, 3, 14], state: "minecraft:blackstone"},
        {pos: [0, 4, 0], state: "minecraft:blackstone"},
        {pos: [0, 4, 1], state: "minecraft:blackstone"},
        {pos: [0, 4, 2], state: "minecraft:blackstone"},
        {pos: [0, 4, 3], state: "minecraft:blackstone"},
        {pos: [0, 4, 4], state: "minecraft:gilded_blackstone"},
        {pos: [0, 4, 5], state: "minecraft:blackstone"},
        {pos: [0, 4, 6], state: "minecraft:blackstone"},
        {pos: [0, 4, 7], state: "minecraft:blackstone"},
        {pos: [0, 4, 8], state: "minecraft:blackstone"},
        {pos: [0, 4, 12], state: "minecraft:blackstone"},
        {pos: [0, 4, 13], state: "minecraft:blackstone"},
        {pos: [0, 4, 14], state: "minecraft:blackstone"},
        {pos: [0, 4, 15], state: "minecraft:blackstone"},
        {pos: [1, 4, 0], state: "minecraft:air"},
        {pos: [1, 4, 1], state: "minecraft:air"},
        {pos: [1, 4, 2], state: "minecraft:air"},
        {pos: [1, 4, 3], state: "minecraft:air"},
        {pos: [1, 4, 4], state: "minecraft:air"},
        {pos: [1, 4, 5], state: "minecraft:blackstone"},
        {pos: [1, 4, 6], state: "minecraft:blackstone"},
        {pos: [1, 4, 7], state: "minecraft:blackstone"},
        {pos: [1, 4, 8], state: "minecraft:blackstone"},
        {pos: [1, 4, 9], state: "minecraft:blackstone"},
        {pos: [1, 4, 11], state: "minecraft:blackstone"},
        {pos: [1, 4, 12], state: "minecraft:blackstone"},
        {pos: [1, 4, 13], state: "minecraft:blackstone"},
        {pos: [1, 4, 14], state: "minecraft:blackstone"},
        {pos: [1, 4, 15], state: "minecraft:blackstone"},
        {pos: [2, 4, 0], state: "minecraft:air"},
        {pos: [2, 4, 1], state: "minecraft:air"},
        {pos: [2, 4, 2], state: "minecraft:air"},
        {pos: [2, 4, 3], state: "minecraft:air"},
        {pos: [2, 4, 4], state: "minecraft:air"},
        {pos: [2, 4, 5], state: "minecraft:chest{facing:north,type:left,waterlogged:false}", nbt: {LootTable: "minecraft:chests/bastion_other", id: "minecraft:chest"}},
        {pos: [2, 4, 6], state: "minecraft:blackstone"},
        {pos: [2, 4, 7], state: "minecraft:blackstone"},
        {pos: [2, 4, 8], state: "minecraft:blackstone"},
        {pos: [2, 4, 9], state: "minecraft:blackstone"},
        {pos: [2, 4, 10], state: "minecraft:blackstone"},
        {pos: [2, 4, 11], state: "minecraft:blackstone"},
        {pos: [2, 4, 12], state: "minecraft:blackstone"},
        {pos: [2, 4, 13], state: "minecraft:blackstone"},
        {pos: [2, 4, 14], state: "minecraft:blackstone"},
        {pos: [3, 4, 0], state: "minecraft:air"},
        {pos: [3, 4, 1], state: "minecraft:air"},
        {pos: [3, 4, 2], state: "minecraft:air"},
        {pos: [3, 4, 3], state: "minecraft:air"},
        {pos: [3, 4, 4], state: "minecraft:air"},
        {pos: [3, 4, 5], state: "minecraft:chest{facing:north,type:right,waterlogged:false}", nbt: {LootTable: "minecraft:chests/bastion_other", id: "minecraft:chest"}},
        {pos: [3, 4, 6], state: "minecraft:blackstone"},
        {pos: [3, 4, 7], state: "minecraft:blackstone"},
        {pos: [3, 4, 8], state: "minecraft:blackstone"},
        {pos: [3, 4, 9], state: "minecraft:blackstone"},
        {pos: [3, 4, 10], state: "minecraft:blackstone"},
        {pos: [3, 4, 11], state: "minecraft:blackstone"},
        {pos: [3, 4, 12], state: "minecraft:blackstone"},
        {pos: [3, 4, 13], state: "minecraft:blackstone"},
        {pos: [3, 4, 14], state: "minecraft:blackstone"},
        {pos: [3, 4, 15], state: "minecraft:blackstone"},
        {pos: [4, 4, 0], state: "minecraft:air"},
        {pos: [4, 4, 1], state: "minecraft:air"},
        {pos: [4, 4, 2], state: "minecraft:air"},
        {pos: [4, 4, 3], state: "minecraft:air"},
        {pos: [4, 4, 4], state: "minecraft:air"},
        {pos: [4, 4, 5], state: "minecraft:air"},
        {pos: [4, 4, 6], state: "minecraft:blackstone"},
        {pos: [4, 4, 7], state: "minecraft:blackstone"},
        {pos: [4, 4, 8], state: "minecraft:blackstone"},
        {pos: [4, 4, 9], state: "minecraft:blackstone"},
        {pos: [4, 4, 10], state: "minecraft:blackstone"},
        {pos: [4, 4, 11], state: "minecraft:cracked_polished_blackstone_bricks"},
        {pos: [4, 4, 12], state: "minecraft:cracked_polished_blackstone_bricks"},
        {pos: [4, 4, 13], state: "minecraft:blackstone"},
        {pos: [4, 4, 14], state: "minecraft:blackstone"},
        {pos: [4, 4, 15], state: "minecraft:blackstone"},
        {pos: [5, 4, 0], state: "minecraft:blackstone"},
        {pos: [5, 4, 1], state: "minecraft:air"},
        {pos: [5, 4, 2], state: "minecraft:air"},
        {pos: [5, 4, 3], state: "minecraft:air"},
        {pos: [5, 4, 4], state: "minecraft:blackstone"},
        {pos: [5, 4, 5], state: "minecraft:blackstone"},
        {pos: [5, 4, 6], state: "minecraft:blackstone"},
        {pos: [5, 4, 7], state: "minecraft:blackstone"},
        {pos: [5, 4, 8], state: "minecraft:blackstone"},
        {pos: [5, 4, 9], state: "minecraft:cracked_polished_blackstone_bricks"},
        {pos: [5, 4, 10], state: "minecraft:cracked_polished_blackstone_bricks"},
        {pos: [5, 4, 11], state: "minecraft:cracked_polished_blackstone_bricks"},
        {pos: [5, 4, 12], state: "minecraft:cracked_polished_blackstone_bricks"},
        {pos: [5, 4, 13], state: "minecraft:air"},
        {pos: [5, 4, 14], state: "minecraft:blackstone"},
        {pos: [5, 4, 15], state: "minecraft:blackstone"},
        {pos: [6, 4, 0], state: "minecraft:blackstone"},
        {pos: [6, 4, 1], state: "minecraft:blackstone"},
        {pos: [6, 4, 2], state: "minecraft:blackstone"},
        {pos: [6, 4, 3], state: "minecraft:blackstone"},
        {pos: [6, 4, 4], state: "minecraft:blackstone"},
        {pos: [6, 4, 5], state: "minecraft:blackstone"},
        {pos: [6, 4, 6], state: "minecraft:blackstone"},
        {pos: [6, 4, 7], state: "minecraft:blackstone"},
        {pos: [6, 4, 8], state: "minecraft:blackstone"},
        {pos: [6, 4, 9], state: "minecraft:cracked_polished_blackstone_bricks"},
        {pos: [6, 4, 10], state: "minecraft:cracked_polished_blackstone_bricks"},
        {pos: [6, 4, 11], state: "minecraft:cracked_polished_blackstone_bricks"},
        {pos: [6, 4, 12], state: "minecraft:cracked_polished_blackstone_bricks"},
        {pos: [6, 4, 13], state: "minecraft:cracked_polished_blackstone_bricks"},
        {pos: [6, 4, 14], state: "minecraft:blackstone"},
        {pos: [7, 4, 0], state: "minecraft:blackstone"},
        {pos: [7, 4, 1], state: "minecraft:blackstone"},
        {pos: [7, 4, 2], state: "minecraft:blackstone"},
        {pos: [7, 4, 3], state: "minecraft:blackstone"},
        {pos: [7, 4, 4], state: "minecraft:blackstone"},
        {pos: [7, 4, 5], state: "minecraft:blackstone"},
        {pos: [7, 4, 6], state: "minecraft:blackstone"},
        {pos: [7, 4, 7], state: "minecraft:blackstone"},
        {pos: [7, 4, 8], state: "minecraft:blackstone"},
        {pos: [7, 4, 9], state: "minecraft:gold_block"},
        {pos: [7, 4, 10], state: "minecraft:cracked_polished_blackstone_bricks"},
        {pos: [7, 4, 11], state: "minecraft:gold_block"},
        {pos: [7, 4, 12], state: "minecraft:cracked_polished_blackstone_bricks"},
        {pos: [7, 4, 13], state: "minecraft:gold_block"},
        {pos: [7, 4, 14], state: "minecraft:blackstone"},
        {pos: [7, 4, 15], state: "minecraft:blackstone"},
        {pos: [8, 4, 0], state: "minecraft:blackstone"},
        {pos: [8, 4, 1], state: "minecraft:blackstone"},
        {pos: [8, 4, 2], state: "minecraft:blackstone"},
        {pos: [8, 4, 3], state: "minecraft:blackstone"},
        {pos: [8, 4, 4], state: "minecraft:blackstone"},
        {pos: [8, 4, 5], state: "minecraft:blackstone"},
        {pos: [8, 4, 6], state: "minecraft:blackstone"},
        {pos: [8, 4, 7], state: "minecraft:blackstone"},
        {pos: [8, 4, 8], state: "minecraft:blackstone"},
        {pos: [8, 4, 9], state: "minecraft:blackstone"},
        {pos: [8, 4, 10], state: "minecraft:blackstone"},
        {pos: [8, 4, 11], state: "minecraft:blackstone"},
        {pos: [8, 4, 12], state: "minecraft:gold_block"},
        {pos: [8, 4, 13], state: "minecraft:air"},
        {pos: [8, 4, 14], state: "minecraft:blackstone"},
        {pos: [8, 4, 15], state: "minecraft:blackstone"},
        {pos: [9, 4, 0], state: "minecraft:cracked_polished_blackstone_bricks"},
        {pos: [9, 4, 1], state: "minecraft:blackstone"},
        {pos: [9, 4, 2], state: "minecraft:blackstone"},
        {pos: [9, 4, 3], state: "minecraft:blackstone"},
        {pos: [9, 4, 4], state: "minecraft:blackstone"},
        {pos: [9, 4, 5], state: "minecraft:blackstone"},
        {pos: [9, 4, 6], state: "minecraft:blackstone"},
        {pos: [9, 4, 7], state: "minecraft:blackstone"},
        {pos: [9, 4, 8], state: "minecraft:blackstone"},
        {pos: [9, 4, 9], state: "minecraft:blackstone"},
        {pos: [9, 4, 10], state: "minecraft:blackstone"},
        {pos: [9, 4, 11], state: "minecraft:blackstone"},
        {pos: [9, 4, 12], state: "minecraft:blackstone"},
        {pos: [9, 4, 13], state: "minecraft:blackstone"},
        {pos: [9, 4, 14], state: "minecraft:blackstone"},
        {pos: [10, 4, 0], state: "minecraft:cracked_polished_blackstone_bricks"},
        {pos: [10, 4, 1], state: "minecraft:blackstone"},
        {pos: [10, 4, 2], state: "minecraft:blackstone"},
        {pos: [10, 4, 3], state: "minecraft:blackstone"},
        {pos: [10, 4, 4], state: "minecraft:blackstone"},
        {pos: [10, 4, 5], state: "minecraft:blackstone"},
        {pos: [10, 4, 6], state: "minecraft:blackstone"},
        {pos: [10, 4, 7], state: "minecraft:blackstone"},
        {pos: [10, 4, 8], state: "minecraft:blackstone"},
        {pos: [10, 4, 9], state: "minecraft:blackstone"},
        {pos: [10, 4, 10], state: "minecraft:blackstone"},
        {pos: [10, 4, 11], state: "minecraft:blackstone"},
        {pos: [10, 4, 12], state: "minecraft:blackstone"},
        {pos: [10, 4, 13], state: "minecraft:blackstone"},
        {pos: [10, 4, 14], state: "minecraft:blackstone"},
        {pos: [10, 4, 15], state: "minecraft:blackstone"},
        {pos: [11, 4, 0], state: "minecraft:cracked_polished_blackstone_bricks"},
        {pos: [11, 4, 1], state: "minecraft:blackstone"},
        {pos: [11, 4, 2], state: "minecraft:blackstone"},
        {pos: [11, 4, 3], state: "minecraft:blackstone"},
        {pos: [11, 4, 4], state: "minecraft:blackstone"},
        {pos: [11, 4, 5], state: "minecraft:blackstone"},
        {pos: [11, 4, 6], state: "minecraft:blackstone"},
        {pos: [11, 4, 7], state: "minecraft:blackstone"},
        {pos: [11, 4, 8], state: "minecraft:blackstone"},
        {pos: [11, 4, 9], state: "minecraft:blackstone"},
        {pos: [11, 4, 10], state: "minecraft:blackstone"},
        {pos: [11, 4, 11], state: "minecraft:blackstone"},
        {pos: [11, 4, 12], state: "minecraft:blackstone"},
        {pos: [11, 4, 13], state: "minecraft:blackstone"},
        {pos: [11, 4, 14], state: "minecraft:blackstone"},
        {pos: [11, 4, 15], state: "minecraft:blackstone"},
        {pos: [12, 4, 0], state: "minecraft:blackstone"},
        {pos: [12, 4, 1], state: "minecraft:blackstone"},
        {pos: [12, 4, 2], state: "minecraft:blackstone"},
        {pos: [12, 4, 3], state: "minecraft:blackstone"},
        {pos: [12, 4, 4], state: "minecraft:blackstone"},
        {pos: [12, 4, 5], state: "minecraft:blackstone"},
        {pos: [12, 4, 6], state: "minecraft:blackstone"},
        {pos: [12, 4, 7], state: "minecraft:blackstone"},
        {pos: [12, 4, 8], state: "minecraft:blackstone"},
        {pos: [12, 4, 9], state: "minecraft:blackstone"},
        {pos: [12, 4, 10], state: "minecraft:blackstone"},
        {pos: [12, 4, 11], state: "minecraft:blackstone"},
        {pos: [12, 4, 12], state: "minecraft:blackstone"},
        {pos: [12, 4, 13], state: "minecraft:blackstone"},
        {pos: [12, 4, 14], state: "minecraft:blackstone"},
        {pos: [12, 4, 15], state: "minecraft:blackstone"},
        {pos: [13, 4, 0], state: "minecraft:blackstone"},
        {pos: [13, 4, 1], state: "minecraft:blackstone"},
        {pos: [13, 4, 2], state: "minecraft:blackstone"},
        {pos: [13, 4, 3], state: "minecraft:blackstone"},
        {pos: [13, 4, 4], state: "minecraft:blackstone"},
        {pos: [13, 4, 5], state: "minecraft:blackstone"},
        {pos: [13, 4, 6], state: "minecraft:blackstone"},
        {pos: [13, 4, 7], state: "minecraft:blackstone"},
        {pos: [13, 4, 8], state: "minecraft:blackstone"},
        {pos: [13, 4, 9], state: "minecraft:blackstone"},
        {pos: [13, 4, 10], state: "minecraft:blackstone"},
        {pos: [13, 4, 11], state: "minecraft:blackstone"},
        {pos: [13, 4, 12], state: "minecraft:blackstone"},
        {pos: [13, 4, 13], state: "minecraft:blackstone"},
        {pos: [13, 4, 14], state: "minecraft:blackstone"},
        {pos: [14, 4, 0], state: "minecraft:blackstone"},
        {pos: [14, 4, 1], state: "minecraft:blackstone"},
        {pos: [14, 4, 2], state: "minecraft:blackstone"},
        {pos: [14, 4, 3], state: "minecraft:blackstone"},
        {pos: [14, 4, 4], state: "minecraft:blackstone"},
        {pos: [14, 4, 5], state: "minecraft:blackstone"},
        {pos: [14, 4, 6], state: "minecraft:blackstone"},
        {pos: [14, 4, 7], state: "minecraft:blackstone"},
        {pos: [14, 4, 8], state: "minecraft:blackstone"},
        {pos: [14, 4, 9], state: "minecraft:blackstone"},
        {pos: [14, 4, 10], state: "minecraft:blackstone"},
        {pos: [14, 4, 11], state: "minecraft:blackstone"},
        {pos: [14, 4, 12], state: "minecraft:blackstone"},
        {pos: [14, 4, 13], state: "minecraft:blackstone"},
        {pos: [14, 4, 14], state: "minecraft:blackstone"},
        {pos: [14, 4, 15], state: "minecraft:blackstone"},
        {pos: [15, 4, 1], state: "minecraft:blackstone"},
        {pos: [15, 4, 2], state: "minecraft:blackstone"},
        {pos: [15, 4, 3], state: "minecraft:blackstone"},
        {pos: [15, 4, 4], state: "minecraft:blackstone"},
        {pos: [15, 4, 5], state: "minecraft:blackstone"},
        {pos: [15, 4, 6], state: "minecraft:blackstone"},
        {pos: [15, 4, 7], state: "minecraft:blackstone"},
        {pos: [15, 4, 8], state: "minecraft:blackstone"},
        {pos: [15, 4, 9], state: "minecraft:blackstone"},
        {pos: [15, 4, 10], state: "minecraft:blackstone"},
        {pos: [15, 4, 11], state: "minecraft:cracked_polished_blackstone_bricks"},
        {pos: [15, 4, 12], state: "minecraft:cracked_polished_blackstone_bricks"},
        {pos: [15, 4, 13], state: "minecraft:blackstone"},
        {pos: [15, 4, 14], state: "minecraft:blackstone"},
        {pos: [15, 4, 15], state: "minecraft:blackstone"},
        {pos: [0, 5, 0], state: "minecraft:blackstone"},
        {pos: [0, 5, 1], state: "minecraft:blackstone"},
        {pos: [0, 5, 2], state: "minecraft:blackstone"},
        {pos: [0, 5, 3], state: "minecraft:gilded_blackstone"},
        {pos: [0, 5, 4], state: "minecraft:blackstone"},
        {pos: [0, 5, 5], state: "minecraft:blackstone"},
        {pos: [0, 5, 6], state: "minecraft:cracked_polished_blackstone_bricks"},
        {pos: [0, 5, 7], state: "minecraft:cracked_polished_blackstone_bricks"},
        {pos: [0, 5, 8], state: "minecraft:blackstone"},
        {pos: [0, 5, 9], state: "minecraft:blackstone"},
        {pos: [0, 5, 10], state: "minecraft:blackstone"},
        {pos: [0, 5, 11], state: "minecraft:blackstone"},
        {pos: [0, 5, 12], state: "minecraft:blackstone"},
        {pos: [0, 5, 13], state: "minecraft:cracked_polished_blackstone_bricks"},
        {pos: [0, 5, 14], state: "minecraft:blackstone"},
        {pos: [0, 5, 15], state: "minecraft:blackstone"},
        {pos: [1, 5, 0], state: "minecraft:air"},
        {pos: [1, 5, 1], state: "minecraft:air"},
        {pos: [1, 5, 2], state: "minecraft:air"},
        {pos: [1, 5, 3], state: "minecraft:air"},
        {pos: [1, 5, 4], state: "minecraft:air"},
        {pos: [1, 5, 5], state: "minecraft:blackstone"},
        {pos: [1, 5, 6], state: "minecraft:blackstone"},
        {pos: [1, 5, 7], state: "minecraft:blackstone"},
        {pos: [1, 5, 8], state: "minecraft:blackstone"},
        {pos: [1, 5, 9], state: "minecraft:blackstone"},
        {pos: [1, 5, 10], state: "minecraft:blackstone"},
        {pos: [1, 5, 11], state: "minecraft:blackstone"},
        {pos: [1, 5, 12], state: "minecraft:blackstone"},
        {pos: [1, 5, 13], state: "minecraft:blackstone"},
        {pos: [1, 5, 14], state: "minecraft:blackstone"},
        {pos: [2, 5, 0], state: "minecraft:air"},
        {pos: [2, 5, 1], state: "minecraft:air"},
        {pos: [2, 5, 2], state: "minecraft:air"},
        {pos: [2, 5, 3], state: "minecraft:air"},
        {pos: [2, 5, 4], state: "minecraft:air"},
        {pos: [2, 5, 5], state: "minecraft:air"},
        {pos: [2, 5, 6], state: "minecraft:blackstone"},
        {pos: [2, 5, 7], state: "minecraft:blackstone"},
        {pos: [2, 5, 8], state: "minecraft:blackstone"},
        {pos: [2, 5, 9], state: "minecraft:blackstone"},
        {pos: [2, 5, 10], state: "minecraft:blackstone"},
        {pos: [2, 5, 11], state: "minecraft:blackstone"},
        {pos: [2, 5, 12], state: "minecraft:blackstone"},
        {pos: [2, 5, 13], state: "minecraft:blackstone"},
        {pos: [2, 5, 14], state: "minecraft:blackstone"},
        {pos: [3, 5, 0], state: "minecraft:air"},
        {pos: [3, 5, 1], state: "minecraft:air"},
        {pos: [3, 5, 2], state: "minecraft:air"},
        {pos: [3, 5, 3], state: "minecraft:air"},
        {pos: [3, 5, 4], state: "minecraft:air"},
        {pos: [3, 5, 5], state: "minecraft:air"},
        {pos: [3, 5, 6], state: "minecraft:gilded_blackstone"},
        {pos: [3, 5, 7], state: "minecraft:blackstone"},
        {pos: [3, 5, 8], state: "minecraft:blackstone"},
        {pos: [3, 5, 9], state: "minecraft:blackstone"},
        {pos: [3, 5, 10], state: "minecraft:blackstone"},
        {pos: [3, 5, 11], state: "minecraft:cracked_polished_blackstone_bricks"},
        {pos: [3, 5, 12], state: "minecraft:chiseled_polished_blackstone"},
        {pos: [3, 5, 13], state: "minecraft:cracked_polished_blackstone_bricks"},
        {pos: [3, 5, 14], state: "minecraft:blackstone"},
        {pos: [3, 5, 15], state: "minecraft:blackstone"},
        {pos: [4, 5, 0], state: "minecraft:air"},
        {pos: [4, 5, 1], state: "minecraft:air"},
        {pos: [4, 5, 2], state: "minecraft:air"},
        {pos: [4, 5, 3], state: "minecraft:air"},
        {pos: [4, 5, 4], state: "minecraft:air"},
        {pos: [4, 5, 5], state: "minecraft:air"},
        {pos: [4, 5, 6], state: "minecraft:blackstone"},
        {pos: [4, 5, 7], state: "minecraft:blackstone"},
        {pos: [4, 5, 8], state: "minecraft:blackstone"},
        {pos: [4, 5, 9], state: "minecraft:blackstone"},
        {pos: [4, 5, 10], state: "minecraft:jigsaw{orientation:up_east}", nbt: {final_state: "minecraft:cracked_polished_blackstone_bricks", id: "minecraft:jigsaw", joint: "aligned", name: "minecraft:empty", pool: "minecraft:bastion/mobs/piglin", target: "minecraft:mob_connector"}},
        {pos: [4, 5, 11], state: "minecraft:cracked_polished_blackstone_bricks"},
        {pos: [4, 5, 12], state: "minecraft:chiseled_polished_blackstone"},
        {pos: [4, 5, 13], state: "minecraft:cracked_polished_blackstone_bricks"},
        {pos: [4, 5, 14], state: "minecraft:blackstone"},
        {pos: [5, 5, 0], state: "minecraft:blackstone"},
        {pos: [5, 5, 1], state: "minecraft:air"},
        {pos: [5, 5, 2], state: "minecraft:air"},
        {pos: [5, 5, 3], state: "minecraft:air"},
        {pos: [5, 5, 4], state: "minecraft:air"},
        {pos: [5, 5, 5], state: "minecraft:blackstone"},
        {pos: [5, 5, 6], state: "minecraft:blackstone"},
        {pos: [5, 5, 7], state: "minecraft:blackstone"},
        {pos: [5, 5, 8], state: "minecraft:blackstone"},
        {pos: [5, 5, 9], state: "minecraft:blackstone"},
        {pos: [5, 5, 10], state: "minecraft:chiseled_polished_blackstone"},
        {pos: [5, 5, 11], state: "minecraft:cracked_polished_blackstone_bricks"},
        {pos: [5, 5, 12], state: "minecraft:chiseled_polished_blackstone"},
        {pos: [5, 5, 13], state: "minecraft:cracked_polished_blackstone_bricks"},
        {pos: [5, 5, 14], state: "minecraft:blackstone"},
        {pos: [5, 5, 15], state: "minecraft:blackstone"},
        {pos: [6, 5, 0], state: "minecraft:blackstone"},
        {pos: [6, 5, 1], state: "minecraft:air"},
        {pos: [6, 5, 2], state: "minecraft:air"},
        {pos: [6, 5, 3], state: "minecraft:blackstone"},
        {pos: [6, 5, 4], state: "minecraft:blackstone"},
        {pos: [6, 5, 5], state: "minecraft:blackstone"},
        {pos: [6, 5, 6], state: "minecraft:blackstone"},
        {pos: [6, 5, 7], state: "minecraft:blackstone"},
        {pos: [6, 5, 8], state: "minecraft:blackstone"},
        {pos: [6, 5, 9], state: "minecraft:blackstone"},
        {pos: [6, 5, 10], state: "minecraft:blackstone"},
        {pos: [6, 5, 11], state: "minecraft:cracked_polished_blackstone_bricks"},
        {pos: [6, 5, 12], state: "minecraft:chiseled_polished_blackstone"},
        {pos: [6, 5, 13], state: "minecraft:blackstone"},
        {pos: [6, 5, 14], state: "minecraft:blackstone"},
        {pos: [6, 5, 15], state: "minecraft:blackstone"},
        {pos: [7, 5, 0], state: "minecraft:blackstone"},
        {pos: [7, 5, 1], state: "minecraft:blackstone"},
        {pos: [7, 5, 2], state: "minecraft:blackstone"},
        {pos: [7, 5, 3], state: "minecraft:blackstone"},
        {pos: [7, 5, 4], state: "minecraft:blackstone"},
        {pos: [7, 5, 5], state: "minecraft:blackstone"},
        {pos: [7, 5, 6], state: "minecraft:blackstone"},
        {pos: [7, 5, 7], state: "minecraft:blackstone"},
        {pos: [7, 5, 8], state: "minecraft:blackstone"},
        {pos: [7, 5, 9], state: "minecraft:blackstone"},
        {pos: [7, 5, 10], state: "minecraft:blackstone"},
        {pos: [7, 5, 11], state: "minecraft:blackstone"},
        {pos: [7, 5, 12], state: "minecraft:blackstone"},
        {pos: [7, 5, 13], state: "minecraft:blackstone"},
        {pos: [7, 5, 14], state: "minecraft:blackstone"},
        {pos: [7, 5, 15], state: "minecraft:blackstone"},
        {pos: [8, 5, 0], state: "minecraft:blackstone"},
        {pos: [8, 5, 1], state: "minecraft:blackstone"},
        {pos: [8, 5, 2], state: "minecraft:blackstone"},
        {pos: [8, 5, 3], state: "minecraft:blackstone"},
        {pos: [8, 5, 4], state: "minecraft:blackstone"},
        {pos: [8, 5, 5], state: "minecraft:blackstone"},
        {pos: [8, 5, 6], state: "minecraft:blackstone"},
        {pos: [8, 5, 7], state: "minecraft:blackstone"},
        {pos: [8, 5, 8], state: "minecraft:blackstone"},
        {pos: [8, 5, 9], state: "minecraft:blackstone"},
        {pos: [8, 5, 10], state: "minecraft:blackstone"},
        {pos: [8, 5, 11], state: "minecraft:blackstone"},
        {pos: [8, 5, 12], state: "minecraft:blackstone"},
        {pos: [8, 5, 13], state: "minecraft:blackstone"},
        {pos: [8, 5, 14], state: "minecraft:blackstone"},
        {pos: [8, 5, 15], state: "minecraft:blackstone"},
        {pos: [9, 5, 0], state: "minecraft:cracked_polished_blackstone_bricks"},
        {pos: [9, 5, 1], state: "minecraft:blackstone"},
        {pos: [9, 5, 2], state: "minecraft:blackstone"},
        {pos: [9, 5, 3], state: "minecraft:blackstone"},
        {pos: [9, 5, 4], state: "minecraft:blackstone"},
        {pos: [9, 5, 5], state: "minecraft:blackstone"},
        {pos: [9, 5, 6], state: "minecraft:blackstone"},
        {pos: [9, 5, 7], state: "minecraft:blackstone"},
        {pos: [9, 5, 8], state: "minecraft:blackstone"},
        {pos: [9, 5, 9], state: "minecraft:blackstone"},
        {pos: [9, 5, 10], state: "minecraft:blackstone"},
        {pos: [9, 5, 11], state: "minecraft:blackstone"},
        {pos: [9, 5, 12], state: "minecraft:blackstone"},
        {pos: [9, 5, 13], state: "minecraft:blackstone"},
        {pos: [9, 5, 14], state: "minecraft:blackstone"},
        {pos: [10, 5, 0], state: "minecraft:blackstone"},
        {pos: [10, 5, 1], state: "minecraft:blackstone"},
        {pos: [10, 5, 2], state: "minecraft:blackstone"},
        {pos: [10, 5, 3], state: "minecraft:blackstone"},
        {pos: [10, 5, 4], state: "minecraft:blackstone"},
        {pos: [10, 5, 5], state: "minecraft:blackstone"},
        {pos: [10, 5, 6], state: "minecraft:blackstone"},
        {pos: [10, 5, 7], state: "minecraft:blackstone"},
        {pos: [10, 5, 8], state: "minecraft:blackstone"},
        {pos: [10, 5, 9], state: "minecraft:blackstone"},
        {pos: [10, 5, 10], state: "minecraft:blackstone"},
        {pos: [10, 5, 11], state: "minecraft:blackstone"},
        {pos: [10, 5, 12], state: "minecraft:blackstone"},
        {pos: [10, 5, 13], state: "minecraft:blackstone"},
        {pos: [10, 5, 14], state: "minecraft:blackstone"},
        {pos: [10, 5, 15], state: "minecraft:blackstone"},
        {pos: [11, 5, 0], state: "minecraft:blackstone"},
        {pos: [11, 5, 1], state: "minecraft:blackstone"},
        {pos: [11, 5, 2], state: "minecraft:blackstone"},
        {pos: [11, 5, 3], state: "minecraft:blackstone"},
        {pos: [11, 5, 4], state: "minecraft:blackstone"},
        {pos: [11, 5, 5], state: "minecraft:blackstone"},
        {pos: [11, 5, 6], state: "minecraft:blackstone"},
        {pos: [11, 5, 7], state: "minecraft:blackstone"},
        {pos: [11, 5, 8], state: "minecraft:blackstone"},
        {pos: [11, 5, 9], state: "minecraft:blackstone"},
        {pos: [11, 5, 10], state: "minecraft:blackstone"},
        {pos: [11, 5, 11], state: "minecraft:blackstone"},
        {pos: [11, 5, 12], state: "minecraft:blackstone"},
        {pos: [11, 5, 13], state: "minecraft:blackstone"},
        {pos: [11, 5, 14], state: "minecraft:blackstone"},
        {pos: [11, 5, 15], state: "minecraft:blackstone"},
        {pos: [12, 5, 0], state: "minecraft:blackstone"},
        {pos: [12, 5, 1], state: "minecraft:blackstone"},
        {pos: [12, 5, 2], state: "minecraft:blackstone"},
        {pos: [12, 5, 3], state: "minecraft:blackstone"},
        {pos: [12, 5, 4], state: "minecraft:blackstone"},
        {pos: [12, 5, 5], state: "minecraft:blackstone"},
        {pos: [12, 5, 6], state: "minecraft:blackstone"},
        {pos: [12, 5, 7], state: "minecraft:blackstone"},
        {pos: [12, 5, 8], state: "minecraft:blackstone"},
        {pos: [12, 5, 9], state: "minecraft:blackstone"},
        {pos: [12, 5, 10], state: "minecraft:blackstone"},
        {pos: [12, 5, 11], state: "minecraft:blackstone"},
        {pos: [12, 5, 12], state: "minecraft:blackstone"},
        {pos: [12, 5, 13], state: "minecraft:blackstone"},
        {pos: [12, 5, 14], state: "minecraft:blackstone"},
        {pos: [12, 5, 15], state: "minecraft:blackstone"},
        {pos: [13, 5, 0], state: "minecraft:blackstone"},
        {pos: [13, 5, 1], state: "minecraft:blackstone"},
        {pos: [13, 5, 2], state: "minecraft:blackstone"},
        {pos: [13, 5, 3], state: "minecraft:blackstone"},
        {pos: [13, 5, 4], state: "minecraft:blackstone"},
        {pos: [13, 5, 5], state: "minecraft:blackstone"},
        {pos: [13, 5, 6], state: "minecraft:blackstone"},
        {pos: [13, 5, 7], state: "minecraft:blackstone"},
        {pos: [13, 5, 8], state: "minecraft:blackstone"},
        {pos: [13, 5, 9], state: "minecraft:blackstone"},
        {pos: [13, 5, 10], state: "minecraft:blackstone"},
        {pos: [13, 5, 11], state: "minecraft:blackstone"},
        {pos: [13, 5, 12], state: "minecraft:blackstone"},
        {pos: [13, 5, 13], state: "minecraft:blackstone"},
        {pos: [13, 5, 14], state: "minecraft:blackstone"},
        {pos: [14, 5, 1], state: "minecraft:blackstone"},
        {pos: [14, 5, 2], state: "minecraft:blackstone"},
        {pos: [14, 5, 3], state: "minecraft:blackstone"},
        {pos: [14, 5, 4], state: "minecraft:blackstone"},
        {pos: [14, 5, 5], state: "minecraft:blackstone"},
        {pos: [14, 5, 6], state: "minecraft:blackstone"},
        {pos: [14, 5, 7], state: "minecraft:blackstone"},
        {pos: [14, 5, 8], state: "minecraft:blackstone"},
        {pos: [14, 5, 9], state: "minecraft:blackstone"},
        {pos: [14, 5, 10], state: "minecraft:blackstone"},
        {pos: [14, 5, 11], state: "minecraft:blackstone"},
        {pos: [14, 5, 12], state: "minecraft:blackstone"},
        {pos: [14, 5, 13], state: "minecraft:blackstone"},
        {pos: [14, 5, 14], state: "minecraft:blackstone"},
        {pos: [14, 5, 15], state: "minecraft:blackstone"},
        {pos: [15, 5, 1], state: "minecraft:air"},
        {pos: [15, 5, 2], state: "minecraft:blackstone"},
        {pos: [15, 5, 3], state: "minecraft:blackstone"},
        {pos: [15, 5, 4], state: "minecraft:blackstone"},
        {pos: [15, 5, 5], state: "minecraft:blackstone"},
        {pos: [15, 5, 6], state: "minecraft:blackstone"},
        {pos: [15, 5, 7], state: "minecraft:blackstone"},
        {pos: [15, 5, 8], state: "minecraft:blackstone"},
        {pos: [15, 5, 9], state: "minecraft:blackstone"},
        {pos: [15, 5, 10], state: "minecraft:blackstone"},
        {pos: [15, 5, 11], state: "minecraft:blackstone"},
        {pos: [15, 5, 12], state: "minecraft:blackstone"},
        {pos: [15, 5, 13], state: "minecraft:blackstone"},
        {pos: [15, 5, 14], state: "minecraft:blackstone"},
        {pos: [15, 5, 15], state: "minecraft:blackstone"},
        {pos: [0, 6, 0], state: "minecraft:blackstone"},
        {pos: [0, 6, 1], state: "minecraft:blackstone"},
        {pos: [0, 6, 2], state: "minecraft:blackstone"},
        {pos: [0, 6, 3], state: "minecraft:blackstone"},
        {pos: [0, 6, 4], state: "minecraft:blackstone"},
        {pos: [0, 6, 5], state: "minecraft:blackstone"},
        {pos: [0, 6, 6], state: "minecraft:blackstone"},
        {pos: [0, 6, 7], state: "minecraft:blackstone"},
        {pos: [0, 6, 8], state: "minecraft:blackstone"},
        {pos: [0, 6, 9], state: "minecraft:blackstone"},
        {pos: [0, 6, 10], state: "minecraft:blackstone"},
        {pos: [0, 6, 11], state: "minecraft:cracked_polished_blackstone_bricks"},
        {pos: [0, 6, 12], state: "minecraft:cracked_polished_blackstone_bricks"},
        {pos: [0, 6, 13], state: "minecraft:blackstone"},
        {pos: [0, 6, 14], state: "minecraft:blackstone"},
        {pos: [0, 6, 15], state: "minecraft:blackstone"},
        {pos: [1, 6, 0], state: "minecraft:blackstone"},
        {pos: [1, 6, 1], state: "minecraft:air"},
        {pos: [1, 6, 2], state: "minecraft:air"},
        {pos: [1, 6, 3], state: "minecraft:air"},
        {pos: [1, 6, 4], state: "minecraft:air"},
        {pos: [1, 6, 5], state: "minecraft:blackstone"},
        {pos: [1, 6, 6], state: "minecraft:blackstone"},
        {pos: [1, 6, 7], state: "minecraft:blackstone"},
        {pos: [1, 6, 8], state: "minecraft:blackstone"},
        {pos: [1, 6, 9], state: "minecraft:blackstone"},
        {pos: [1, 6, 10], state: "minecraft:blackstone"},
        {pos: [1, 6, 11], state: "minecraft:blackstone"},
        {pos: [1, 6, 12], state: "minecraft:blackstone"},
        {pos: [1, 6, 13], state: "minecraft:blackstone"},
        {pos: [1, 6, 14], state: "minecraft:blackstone"},
        {pos: [1, 6, 15], state: "minecraft:blackstone"},
        {pos: [2, 6, 0], state: "minecraft:air"},
        {pos: [2, 6, 1], state: "minecraft:air"},
        {pos: [2, 6, 2], state: "minecraft:air"},
        {pos: [2, 6, 3], state: "minecraft:air"},
        {pos: [2, 6, 4], state: "minecraft:air"},
        {pos: [2, 6, 5], state: "minecraft:air"},
        {pos: [2, 6, 6], state: "minecraft:blackstone"},
        {pos: [2, 6, 7], state: "minecraft:blackstone"},
        {pos: [2, 6, 8], state: "minecraft:blackstone"},
        {pos: [2, 6, 9], state: "minecraft:blackstone"},
        {pos: [2, 6, 10], state: "minecraft:blackstone"},
        {pos: [2, 6, 11], state: "minecraft:blackstone"},
        {pos: [2, 6, 12], state: "minecraft:blackstone"},
        {pos: [2, 6, 13], state: "minecraft:blackstone"},
        {pos: [2, 6, 14], state: "minecraft:blackstone"},
        {pos: [3, 6, 0], state: "minecraft:air"},
        {pos: [3, 6, 1], state: "minecraft:air"},
        {pos: [3, 6, 2], state: "minecraft:air"},
        {pos: [3, 6, 3], state: "minecraft:air"},
        {pos: [3, 6, 4], state: "minecraft:air"},
        {pos: [3, 6, 5], state: "minecraft:air"},
        {pos: [3, 6, 6], state: "minecraft:blackstone"},
        {pos: [3, 6, 7], state: "minecraft:blackstone"},
        {pos: [3, 6, 8], state: "minecraft:blackstone"},
        {pos: [3, 6, 9], state: "minecraft:blackstone"},
        {pos: [3, 6, 10], state: "minecraft:blackstone"},
        {pos: [3, 6, 11], state: "minecraft:air"},
        {pos: [3, 6, 12], state: "minecraft:cracked_polished_blackstone_bricks"},
        {pos: [3, 6, 13], state: "minecraft:cracked_polished_blackstone_bricks"},
        {pos: [3, 6, 14], state: "minecraft:blackstone"},
        {pos: [3, 6, 15], state: "minecraft:blackstone"},
        {pos: [4, 6, 0], state: "minecraft:blackstone"},
        {pos: [4, 6, 1], state: "minecraft:air"},
        {pos: [4, 6, 2], state: "minecraft:air"},
        {pos: [4, 6, 3], state: "minecraft:air"},
        {pos: [4, 6, 4], state: "minecraft:air"},
        {pos: [4, 6, 5], state: "minecraft:air"},
        {pos: [4, 6, 6], state: "minecraft:blackstone"},
        {pos: [4, 6, 7], state: "minecraft:blackstone"},
        {pos: [4, 6, 8], state: "minecraft:blackstone"},
        {pos: [4, 6, 9], state: "minecraft:blackstone"},
        {pos: [4, 6, 10], state: "minecraft:air"},
        {pos: [4, 6, 11], state: "minecraft:cracked_polished_blackstone_bricks"},
        {pos: [4, 6, 12], state: "minecraft:air"},
        {pos: [4, 6, 13], state: "minecraft:air"},
        {pos: [4, 6, 14], state: "minecraft:blackstone"},
        {pos: [4, 6, 15], state: "minecraft:blackstone"},
        {pos: [5, 6, 0], state: "minecraft:blackstone"},
        {pos: [5, 6, 1], state: "minecraft:air"},
        {pos: [5, 6, 2], state: "minecraft:air"},
        {pos: [5, 6, 3], state: "minecraft:air"},
        {pos: [5, 6, 4], state: "minecraft:air"},
        {pos: [5, 6, 5], state: "minecraft:blackstone"},
        {pos: [5, 6, 6], state: "minecraft:blackstone"},
        {pos: [5, 6, 7], state: "minecraft:blackstone"},
        {pos: [5, 6, 8], state: "minecraft:jigsaw{orientation:up_south}", nbt: {final_state: "minecraft:polished_blackstone_bricks", id: "minecraft:jigsaw", joint: "rollable", name: "minecraft:empty", pool: "minecraft:bastion/mobs/piglin", target: "minecraft:mob_connector"}},
        {pos: [5, 6, 9], state: "minecraft:blackstone"},
        {pos: [5, 6, 10], state: "minecraft:air"},
        {pos: [5, 6, 11], state: "minecraft:air"},
        {pos: [5, 6, 12], state: "minecraft:air"},
        {pos: [5, 6, 13], state: "minecraft:cracked_polished_blackstone_bricks"},
        {pos: [6, 6, 0], state: "minecraft:blackstone"},
        {pos: [6, 6, 1], state: "minecraft:air"},
        {pos: [6, 6, 2], state: "minecraft:air"},
        {pos: [6, 6, 3], state: "minecraft:blackstone"},
        {pos: [6, 6, 4], state: "minecraft:blackstone"},
        {pos: [6, 6, 5], state: "minecraft:blackstone"},
        {pos: [6, 6, 6], state: "minecraft:blackstone"},
        {pos: [6, 6, 7], state: "minecraft:blackstone"},
        {pos: [6, 6, 8], state: "minecraft:blackstone"},
        {pos: [6, 6, 9], state: "minecraft:blackstone"},
        {pos: [6, 6, 10], state: "minecraft:blackstone"},
        {pos: [6, 6, 11], state: "minecraft:air"},
        {pos: [6, 6, 12], state: "minecraft:air"},
        {pos: [6, 6, 13], state: "minecraft:blackstone"},
        {pos: [7, 6, 0], state: "minecraft:blackstone"},
        {pos: [7, 6, 1], state: "minecraft:air"},
        {pos: [7, 6, 2], state: "minecraft:air"},
        {pos: [7, 6, 3], state: "minecraft:blackstone"},
        {pos: [7, 6, 4], state: "minecraft:blackstone"},
        {pos: [7, 6, 5], state: "minecraft:blackstone"},
        {pos: [7, 6, 6], state: "minecraft:blackstone"},
        {pos: [7, 6, 7], state: "minecraft:blackstone"},
        {pos: [7, 6, 8], state: "minecraft:blackstone"},
        {pos: [7, 6, 9], state: "minecraft:blackstone"},
        {pos: [7, 6, 10], state: "minecraft:blackstone"},
        {pos: [7, 6, 11], state: "minecraft:blackstone"},
        {pos: [7, 6, 12], state: "minecraft:blackstone"},
        {pos: [7, 6, 13], state: "minecraft:blackstone"},
        {pos: [8, 6, 0], state: "minecraft:blackstone"},
        {pos: [8, 6, 1], state: "minecraft:blackstone"},
        {pos: [8, 6, 2], state: "minecraft:blackstone"},
        {pos: [8, 6, 3], state: "minecraft:blackstone"},
        {pos: [8, 6, 4], state: "minecraft:blackstone"},
        {pos: [8, 6, 5], state: "minecraft:blackstone"},
        {pos: [8, 6, 6], state: "minecraft:blackstone"},
        {pos: [8, 6, 7], state: "minecraft:blackstone"},
        {pos: [8, 6, 8], state: "minecraft:blackstone"},
        {pos: [8, 6, 9], state: "minecraft:blackstone"},
        {pos: [8, 6, 10], state: "minecraft:blackstone"},
        {pos: [8, 6, 11], state: "minecraft:blackstone"},
        {pos: [8, 6, 12], state: "minecraft:blackstone"},
        {pos: [8, 6, 13], state: "minecraft:blackstone"},
        {pos: [8, 6, 14], state: "minecraft:blackstone"},
        {pos: [8, 6, 15], state: "minecraft:blackstone"},
        {pos: [9, 6, 0], state: "minecraft:blackstone"},
        {pos: [9, 6, 1], state: "minecraft:blackstone"},
        {pos: [9, 6, 2], state: "minecraft:blackstone"},
        {pos: [9, 6, 3], state: "minecraft:blackstone"},
        {pos: [9, 6, 4], state: "minecraft:blackstone"},
        {pos: [9, 6, 5], state: "minecraft:blackstone"},
        {pos: [9, 6, 6], state: "minecraft:blackstone"},
        {pos: [9, 6, 7], state: "minecraft:blackstone"},
        {pos: [9, 6, 8], state: "minecraft:blackstone"},
        {pos: [9, 6, 9], state: "minecraft:blackstone"},
        {pos: [9, 6, 10], state: "minecraft:blackstone"},
        {pos: [9, 6, 11], state: "minecraft:blackstone"},
        {pos: [9, 6, 12], state: "minecraft:blackstone"},
        {pos: [9, 6, 13], state: "minecraft:blackstone"},
        {pos: [9, 6, 14], state: "minecraft:blackstone"},
        {pos: [10, 6, 0], state: "minecraft:blackstone"},
        {pos: [10, 6, 1], state: "minecraft:blackstone"},
        {pos: [10, 6, 2], state: "minecraft:blackstone"},
        {pos: [10, 6, 3], state: "minecraft:blackstone"},
        {pos: [10, 6, 4], state: "minecraft:blackstone"},
        {pos: [10, 6, 5], state: "minecraft:blackstone"},
        {pos: [10, 6, 6], state: "minecraft:blackstone"},
        {pos: [10, 6, 7], state: "minecraft:blackstone"},
        {pos: [10, 6, 8], state: "minecraft:blackstone"},
        {pos: [10, 6, 9], state: "minecraft:blackstone"},
        {pos: [10, 6, 10], state: "minecraft:blackstone"},
        {pos: [10, 6, 11], state: "minecraft:blackstone"},
        {pos: [10, 6, 12], state: "minecraft:blackstone"},
        {pos: [10, 6, 13], state: "minecraft:blackstone"},
        {pos: [10, 6, 14], state: "minecraft:blackstone"},
        {pos: [10, 6, 15], state: "minecraft:blackstone"},
        {pos: [11, 6, 0], state: "minecraft:blackstone"},
        {pos: [11, 6, 1], state: "minecraft:blackstone"},
        {pos: [11, 6, 2], state: "minecraft:blackstone"},
        {pos: [11, 6, 3], state: "minecraft:blackstone"},
        {pos: [11, 6, 4], state: "minecraft:blackstone"},
        {pos: [11, 6, 5], state: "minecraft:blackstone"},
        {pos: [11, 6, 6], state: "minecraft:blackstone"},
        {pos: [11, 6, 7], state: "minecraft:blackstone"},
        {pos: [11, 6, 8], state: "minecraft:blackstone"},
        {pos: [11, 6, 9], state: "minecraft:blackstone"},
        {pos: [11, 6, 10], state: "minecraft:blackstone"},
        {pos: [11, 6, 11], state: "minecraft:blackstone"},
        {pos: [11, 6, 12], state: "minecraft:blackstone"},
        {pos: [11, 6, 13], state: "minecraft:blackstone"},
        {pos: [11, 6, 14], state: "minecraft:blackstone"},
        {pos: [11, 6, 15], state: "minecraft:blackstone"},
        {pos: [12, 6, 0], state: "minecraft:blackstone"},
        {pos: [12, 6, 1], state: "minecraft:blackstone"},
        {pos: [12, 6, 2], state: "minecraft:blackstone"},
        {pos: [12, 6, 3], state: "minecraft:blackstone"},
        {pos: [12, 6, 4], state: "minecraft:blackstone"},
        {pos: [12, 6, 5], state: "minecraft:blackstone"},
        {pos: [12, 6, 6], state: "minecraft:blackstone"},
        {pos: [12, 6, 7], state: "minecraft:blackstone"},
        {pos: [12, 6, 8], state: "minecraft:blackstone"},
        {pos: [12, 6, 9], state: "minecraft:blackstone"},
        {pos: [12, 6, 10], state: "minecraft:blackstone"},
        {pos: [12, 6, 11], state: "minecraft:blackstone"},
        {pos: [12, 6, 12], state: "minecraft:blackstone"},
        {pos: [12, 6, 13], state: "minecraft:blackstone"},
        {pos: [12, 6, 14], state: "minecraft:blackstone"},
        {pos: [12, 6, 15], state: "minecraft:blackstone"},
        {pos: [13, 6, 0], state: "minecraft:blackstone"},
        {pos: [13, 6, 1], state: "minecraft:blackstone"},
        {pos: [13, 6, 2], state: "minecraft:blackstone"},
        {pos: [13, 6, 3], state: "minecraft:blackstone"},
        {pos: [13, 6, 4], state: "minecraft:blackstone"},
        {pos: [13, 6, 5], state: "minecraft:blackstone"},
        {pos: [13, 6, 6], state: "minecraft:blackstone"},
        {pos: [13, 6, 7], state: "minecraft:blackstone"},
        {pos: [13, 6, 8], state: "minecraft:blackstone"},
        {pos: [13, 6, 9], state: "minecraft:blackstone"},
        {pos: [13, 6, 10], state: "minecraft:blackstone"},
        {pos: [13, 6, 11], state: "minecraft:blackstone"},
        {pos: [13, 6, 12], state: "minecraft:blackstone"},
        {pos: [13, 6, 13], state: "minecraft:blackstone"},
        {pos: [13, 6, 14], state: "minecraft:blackstone"},
        {pos: [14, 6, 1], state: "minecraft:blackstone"},
        {pos: [14, 6, 2], state: "minecraft:blackstone"},
        {pos: [14, 6, 3], state: "minecraft:blackstone"},
        {pos: [14, 6, 4], state: "minecraft:blackstone"},
        {pos: [14, 6, 5], state: "minecraft:blackstone"},
        {pos: [14, 6, 6], state: "minecraft:blackstone"},
        {pos: [14, 6, 7], state: "minecraft:blackstone"},
        {pos: [14, 6, 8], state: "minecraft:blackstone"},
        {pos: [14, 6, 9], state: "minecraft:blackstone"},
        {pos: [14, 6, 10], state: "minecraft:blackstone"},
        {pos: [14, 6, 11], state: "minecraft:blackstone"},
        {pos: [14, 6, 12], state: "minecraft:blackstone"},
        {pos: [14, 6, 13], state: "minecraft:blackstone"},
