{
    size: [10, 10, 10],
    data: [
        {pos: [0, 0, 0], state: "minecraft:stone"},
        {pos: [0, 0, 1], state: "minecraft:stone"},
        {pos: [0, 0, 2], state: "minecraft:stone"},
        {pos: [0, 0, 3], state: "minecraft:stone"},
        {pos: [0, 0, 4], state: "minecraft:stone"},
        {pos: [0, 0, 5], state: "minecraft:stone"},
        {pos: [0, 0, 6], state: "minecraft:stone"},
        {pos: [0, 0, 7], state: "minecraft:stone"},
        {pos: [0, 0, 8], state: "minecraft:stone"},
        {pos: [0, 0, 9], state: "minecraft:stone"},
        {pos: [1, 0, 0], state: "minecraft:stone"},
        {pos: [1, 0, 1], state: "minecraft:stone"},
        {pos: [1, 0, 2], state: "minecraft:stone"},
        {pos: [1, 0, 3], state: "minecraft:stone"},
        {pos: [1, 0, 4], state: "minecraft:stone"},
        {pos: [1, 0, 5], state: "minecraft:stone"},
        {pos: [1, 0, 6], state: "minecraft:stone"},
        {pos: [1, 0, 7], state: "minecraft:stone"},
        {pos: [1, 0, 8], state: "minecraft:stone"},
        {pos: [1, 0, 9], state: "minecraft:stone"},
        {pos: [2, 0, 0], state: "minecraft:stone"},
        {pos: [2, 0, 1], state: "minecraft:stone"},
        {pos: [2, 0, 2], state: "minecraft:stone"},
        {pos: [2, 0, 3], state: "minecraft:stone"},
        {pos: [2, 0, 4], state: "minecraft:stone"},
        {pos: [2, 0, 5], state: "minecraft:stone"},
        {pos: [2, 0, 6], state: "minecraft:stone"},
        {pos: [2, 0, 7], state: "minecraft:stone"},
        {pos: [2, 0, 8], state: "minecraft:stone"},
        {pos: [2, 0, 9], state: "minecraft:stone"},
        {pos: [3, 0, 0], state: "minecraft:stone"},
        {pos: [3, 0, 1], state: "minecraft:stone"},
        {pos: [3, 0, 2], state: "minecraft:stone"},
        {pos: [3, 0, 3], state: "minecraft:stone"},
        {pos: [3, 0, 4], state: "minecraft:stone"},
        {pos: [3, 0, 5], state: "minecraft:stone"},
        {pos: [3, 0, 6], state: "minecraft:gravel"},
        {pos: [3, 0, 7], state: "minecraft:oak_fence{east:true,north:true,south:true,waterlogged:false,west:true}"},
        {pos: [3, 0, 8], state: "minecraft:iron_ore"},
        {pos: [3, 0, 9], state: "minecraft:stone"},
        {pos: [4, 0, 0], state: "minecraft:stone"},
        {pos: [4, 0, 1], state: "minecraft:stone"},
        {pos: [4, 0, 2], state: "minecraft:stone"},
        {pos: [4, 0, 3], state: "minecraft:stone"},
        {pos: [4, 0, 4], state: "minecraft:stone"},
        {pos: [4, 0, 5], state: "minecraft:stone"},
        {pos: [4, 0, 6], state: "minecraft:gravel"},
        {pos: [4, 0, 7], state: "minecraft:gravel"},
        {pos: [4, 0, 8], state: "minecraft:gravel"},
        {pos: [4, 0, 9], state: "minecraft:stone"},
        {pos: [5, 0, 0], state: "minecraft:stone"},
        {pos: [5, 0, 1], state: "minecraft:stone"},
        {pos: [5, 0, 2], state: "minecraft:stone"},
        {pos: [5, 0, 3], state: "minecraft:stone"},
        {pos: [5, 0, 4], state: "minecraft:stone"},
        {pos: [5, 0, 5], state: "minecraft:stone"},
        {pos: [5, 0, 6], state: "minecraft:stone"},
        {pos: [5, 0, 7], state: "minecraft:oak_fence{east:true,north:true,south:true,waterlogged:false,west:true}"},
        {pos: [5, 0, 8], state: "minecraft:iron_ore"},
        {pos: [5, 0, 9], state: "minecraft:stone"},
        {pos: [6, 0, 0], state: "minecraft:stone"},
        {pos: [6, 0, 1], state: "minecraft:stone"},
        {pos: [6, 0, 2], state: "minecraft:cobblestone"},
        {pos: [6, 0, 3], state: "minecraft:stone"},
        {pos: [6, 0, 4], state: "minecraft:iron_ore"},
        {pos: [6, 0, 5], state: "minecraft:stone"},
        {pos: [6, 0, 6], state: "minecraft:stone"},
        {pos: [6, 0, 7], state: "minecraft:iron_ore"},
        {pos: [6, 0, 8], state: "minecraft:stone"},
        {pos: [6, 0, 9], state: "minecraft:stone"},
        {pos: [7, 0, 0], state: "minecraft:stone"},
        {pos: [7, 0, 1], state: "minecraft:stone"},
        {pos: [7, 0, 2], state: "minecraft:stone"},
        {pos: [7, 0, 3], state: "minecraft:stone"},
        {pos: [7, 0, 4], state: "minecraft:iron_ore"},
        {pos: [7, 0, 5], state: "minecraft:oxidized_copper_chest{facing:south,type:single,waterlogged:false}", nbt: {Items: [], LootTable: "minecraft:chests/abandoned_camp_secret_chest", components: {}, id: "minecraft:chest"}},
        {pos: [7, 0, 6], state: "minecraft:stone"},
        {pos: [7, 0, 7], state: "minecraft:iron_ore"},
        {pos: [7, 0, 8], state: "minecraft:iron_ore"},
        {pos: [7, 0, 9], state: "minecraft:stone"},
        {pos: [8, 0, 0], state: "minecraft:stone"},
        {pos: [8, 0, 1], state: "minecraft:stone"},
        {pos: [8, 0, 2], state: "minecraft:stone"},
        {pos: [8, 0, 3], state: "minecraft:stone"},
        {pos: [8, 0, 4], state: "minecraft:stone"},
        {pos: [8, 0, 5], state: "minecraft:stone"},
        {pos: [8, 0, 6], state: "minecraft:stone"},
        {pos: [8, 0, 7], state: "minecraft:stone"},
        {pos: [8, 0, 8], state: "minecraft:stone"},
        {pos: [8, 0, 9], state: "minecraft:stone"},
        {pos: [9, 0, 0], state: "minecraft:stone"},
        {pos: [9, 0, 1], state: "minecraft:stone"},
        {pos: [9, 0, 2], state: "minecraft:stone"},
        {pos: [9, 0, 3], state: "minecraft:stone"},
        {pos: [9, 0, 4], state: "minecraft:stone"},
        {pos: [9, 0, 5], state: "minecraft:stone"},
        {pos: [9, 0, 6], state: "minecraft:stone"},
        {pos: [9, 0, 7], state: "minecraft:stone"},
        {pos: [9, 0, 8], state: "minecraft:stone"},
        {pos: [9, 0, 9], state: "minecraft:stone"},
        {pos: [0, 1, 0], state: "minecraft:stone"},
        {pos: [0, 1, 1], state: "minecraft:stone"},
        {pos: [0, 1, 2], state: "minecraft:stone"},
        {pos: [0, 1, 3], state: "minecraft:stone"},
        {pos: [0, 1, 4], state: "minecraft:stone"},
        {pos: [0, 1, 5], state: "minecraft:stone"},
        {pos: [0, 1, 6], state: "minecraft:stone"},
        {pos: [0, 1, 7], state: "minecraft:stone"},
        {pos: [0, 1, 8], state: "minecraft:stone"},
        {pos: [0, 1, 9], state: "minecraft:stone"},
        {pos: [1, 1, 0], state: "minecraft:stone"},
        {pos: [1, 1, 1], state: "minecraft:stone"},
        {pos: [1, 1, 2], state: "minecraft:stone"},
        {pos: [1, 1, 3], state: "minecraft:stone"},
        {pos: [1, 1, 4], state: "minecraft:stone"},
        {pos: [1, 1, 5], state: "minecraft:stone"},
        {pos: [1, 1, 6], state: "minecraft:stone"},
        {pos: [1, 1, 7], state: "minecraft:stone"},
        {pos: [1, 1, 8], state: "minecraft:stone"},
        {pos: [1, 1, 9], state: "minecraft:stone"},
        {pos: [2, 1, 0], state: "minecraft:stone"},
        {pos: [2, 1, 1], state: "minecraft:stone"},
        {pos: [2, 1, 2], state: "minecraft:stone"},
        {pos: [2, 1, 3], state: "minecraft:stone"},
        {pos: [2, 1, 4], state: "minecraft:stone"},
        {pos: [2, 1, 5], state: "minecraft:stone"},
        {pos: [2, 1, 6], state: "minecraft:gravel"},
        {pos: [2, 1, 7], state: "minecraft:stone"},
        {pos: [2, 1, 8], state: "minecraft:stone"},
        {pos: [2, 1, 9], state: "minecraft:stone"},
        {pos: [3, 1, 0], state: "minecraft:stone"},
        {pos: [3, 1, 1], state: "minecraft:stone"},
        {pos: [3, 1, 2], state: "minecraft:stone"},
        {pos: [3, 1, 3], state: "minecraft:stone"},
        {pos: [3, 1, 4], state: "minecraft:stone"},
        {pos: [3, 1, 5], state: "minecraft:stone"},
        {pos: [3, 1, 6], state: "minecraft:gravel"},
        {pos: [3, 1, 7], state: "minecraft:oak_fence{east:true,north:true,south:true,waterlogged:false,west:true}"},
        {pos: [3, 1, 8], state: "minecraft:gravel"},
        {pos: [3, 1, 9], state: "minecraft:stone"},
        {pos: [4, 1, 0], state: "minecraft:stone"},
        {pos: [4, 1, 1], state: "minecraft:stone"},
        {pos: [4, 1, 2], state: "minecraft:stone"},
        {pos: [4, 1, 3], state: "minecraft:stone"},
        {pos: [4, 1, 4], state: "minecraft:stone"},
        {pos: [4, 1, 5], state: "minecraft:gravel"},
        {pos: [4, 1, 6], state: "minecraft:gravel"},
        {pos: [4, 1, 7], state: "minecraft:gravel"},
        {pos: [4, 1, 8], state: "minecraft:gravel"},
        {pos: [4, 1, 9], state: "minecraft:stone"},
        {pos: [5, 1, 0], state: "minecraft:stone"},
        {pos: [5, 1, 1], state: "minecraft:stone"},
        {pos: [5, 1, 2], state: "minecraft:stone"},
        {pos: [5, 1, 3], state: "minecraft:stone"},
        {pos: [5, 1, 4], state: "minecraft:stone"},
        {pos: [5, 1, 5], state: "minecraft:stone"},
        {pos: [5, 1, 6], state: "minecraft:gravel"},
        {pos: [5, 1, 7], state: "minecraft:oak_fence{east:true,north:true,south:true,waterlogged:false,west:true}"},
        {pos: [5, 1, 8], state: "minecraft:gravel"},
        {pos: [5, 1, 9], state: "minecraft:stone"},
        {pos: [6, 1, 0], state: "minecraft:stone"},
        {pos: [6, 1, 1], state: "minecraft:stone"},
        {pos: [6, 1, 2], state: "minecraft:stone"},
        {pos: [6, 1, 3], state: "minecraft:stone"},
        {pos: [6, 1, 4], state: "minecraft:iron_ore"},
        {pos: [6, 1, 5], state: "minecraft:stone"},
        {pos: [6, 1, 6], state: "minecraft:stone"},
        {pos: [6, 1, 7], state: "minecraft:gravel"},
        {pos: [6, 1, 8], state: "minecraft:stone"},
        {pos: [6, 1, 9], state: "minecraft:stone"},
        {pos: [7, 1, 0], state: "minecraft:stone"},
        {pos: [7, 1, 1], state: "minecraft:stone"},
        {pos: [7, 1, 2], state: "minecraft:stone"},
        {pos: [7, 1, 3], state: "minecraft:stone"},
        {pos: [7, 1, 4], state: "minecraft:iron_ore"},
        {pos: [7, 1, 5], state: "minecraft:stone"},
        {pos: [7, 1, 6], state: "minecraft:stone"},
        {pos: [7, 1, 7], state: "minecraft:iron_ore"},
        {pos: [7, 1, 8], state: "minecraft:stone"},
        {pos: [7, 1, 9], state: "minecraft:stone"},
        {pos: [8, 1, 0], state: "minecraft:stone"},
        {pos: [8, 1, 1], state: "minecraft:stone"},
        {pos: [8, 1, 2], state: "minecraft:stone"},
        {pos: [8, 1, 3], state: "minecraft:stone"},
        {pos: [8, 1, 4], state: "minecraft:stone"},
        {pos: [8, 1, 5], state: "minecraft:stone"},
        {pos: [8, 1, 6], state: "minecraft:stone"},
        {pos: [8, 1, 7], state: "minecraft:stone"},
        {pos: [8, 1, 8], state: "minecraft:stone"},
        {pos: [8, 1, 9], state: "minecraft:stone"},
        {pos: [9, 1, 0], state: "minecraft:stone"},
        {pos: [9, 1, 1], state: "minecraft:stone"},
        {pos: [9, 1, 2], state: "minecraft:stone"},
        {pos: [9, 1, 3], state: "minecraft:stone"},
        {pos: [9, 1, 4], state: "minecraft:stone"},
        {pos: [9, 1, 5], state: "minecraft:stone"},
        {pos: [9, 1, 6], state: "minecraft:stone"},
        {pos: [9, 1, 7], state: "minecraft:stone"},
        {pos: [9, 1, 8], state: "minecraft:stone"},
        {pos: [9, 1, 9], state: "minecraft:stone"},
        {pos: [0, 2, 3], state: "minecraft:grass_block{snowy:false}"},
        {pos: [0, 2, 4], state: "minecraft:grass_block{snowy:false}"},
        {pos: [0, 2, 7], state: "minecraft:grass_block{snowy:false}"},
        {pos: [1, 2, 1], state: "minecraft:dirt"},
        {pos: [1, 2, 2], state: "minecraft:dirt"},
        {pos: [1, 2, 3], state: "minecraft:dirt"},
        {pos: [1, 2, 4], state: "minecraft:dirt"},
        {pos: [1, 2, 5], state: "minecraft:grass_block{snowy:false}"},
        {pos: [1, 2, 6], state: "minecraft:grass_block{snowy:false}"},
        {pos: [1, 2, 7], state: "minecraft:grass_block{snowy:false}"},
        {pos: [1, 2, 8], state: "minecraft:jigsaw{orientation:up_east}", nbt: {components: {}, final_state: "minecraft:dirt", id: "minecraft:jigsaw", joint: "rollable", name: "minecraft:bottom", placement_priority: 0, pool: "minecraft:abandoned_camp/trees/birch", selection_priority: 0, target: "minecraft:bottom"}},
        {pos: [2, 2, 1], state: "minecraft:dirt_path"},
        {pos: [2, 2, 2], state: "minecraft:dirt_path"},
        {pos: [2, 2, 3], state: "minecraft:dirt_path"},
        {pos: [2, 2, 4], state: "minecraft:grass_block{snowy:false}"},
        {pos: [2, 2, 5], state: "minecraft:gravel"},
        {pos: [2, 2, 6], state: "minecraft:cobweb"},
        {pos: [2, 2, 7], state: "minecraft:grass_block{snowy:false}"},
        {pos: [3, 2, 0], state: "minecraft:grass_block{snowy:false}"},
        {pos: [3, 2, 1], state: "minecraft:dirt_path"},
        {pos: [3, 2, 2], state: "minecraft:dirt"},
        {pos: [3, 2, 3], state: "minecraft:dirt_path"},
        {pos: [3, 2, 4], state: "minecraft:cobweb"},
        {pos: [3, 2, 5], state: "minecraft:oak_fence{east:false,north:false,south:true,waterlogged:false,west:true}"},
        {pos: [3, 2, 6], state: "minecraft:gravel"},
        {pos: [3, 2, 7], state: "minecraft:oak_planks"},
        {pos: [4, 2, 0], state: "minecraft:grass_block{snowy:false}"},
        {pos: [4, 2, 1], state: "minecraft:dirt_path"},
        {pos: [4, 2, 2], state: "minecraft:dirt_path"},
        {pos: [4, 2, 3], state: "minecraft:dirt_path"},
        {pos: [4, 2, 4], state: "minecraft:gravel"},
        {pos: [4, 2, 5], state: "minecraft:cobweb"},
        {pos: [4, 2, 6], state: "minecraft:gravel"},
        {pos: [4, 2, 7], state: "minecraft:oak_planks"},
        {pos: [5, 2, 0], state: "minecraft:grass_block{snowy:false}"},
        {pos: [5, 2, 1], state: "minecraft:dirt_path"},
        {pos: [5, 2, 2], state: "minecraft:dirt_path"},
        {pos: [5, 2, 3], state: "minecraft:dirt_path"},
        {pos: [5, 2, 4], state: "minecraft:gravel"},
        {pos: [5, 2, 5], state: "minecraft:oak_fence{east:false,north:true,south:false,waterlogged:false,west:false}"},
        {pos: [5, 2, 6], state: "minecraft:cobweb"},
        {pos: [5, 2, 7], state: "minecraft:oak_planks"},
        {pos: [6, 2, 0], state: "minecraft:grass_block{snowy:false}"},
        {pos: [6, 2, 1], state: "minecraft:grass_block{snowy:false}"},
        {pos: [6, 2, 2], state: "minecraft:dirt_path"},
        {pos: [6, 2, 3], state: "minecraft:dirt_path"},
        {pos: [6, 2, 4], state: "minecraft:dirt_path"},
        {pos: [7, 2, 1], state: "minecraft:grass_block{snowy:false}"},
        {pos: [7, 2, 2], state: "minecraft:grass_block{snowy:false}"},
        {pos: [7, 2, 3], state: "minecraft:dirt_path"},
        {pos: [7, 2, 4], state: "minecraft:dirt_path"},
        {pos: [7, 2, 6], state: "minecraft:stone"},
        {pos: [7, 2, 7], state: "minecraft:jigsaw{orientation:up_west}", nbt: {components: {}, final_state: "minecraft:dirt", id: "minecraft:jigsaw", joint: "rollable", name: "minecraft:bottom", placement_priority: 0, pool: "minecraft:abandoned_camp/trees/birch", selection_priority: 0, target: "minecraft:bottom"}},
        {pos: [8, 2, 4], state: "minecraft:dirt_path"},
        {pos: [9, 2, 4], state: "minecraft:jigsaw{orientation:east_up}", nbt: {components: {}, final_state: "minecraft:dirt_path", id: "minecraft:jigsaw", joint: "rollable", name: "minecraft:end_connector", placement_priority: 0, pool: "minecraft:empty", selection_priority: 0, target: "minecraft:connector"}},
        {pos: [1, 3, 1], state: "minecraft:birch_log{axis:z}"},
        {pos: [1, 3, 2], state: "minecraft:birch_log{axis:z}"},
        {pos: [1, 3, 3], state: "minecraft:birch_log{axis:z}"},
        {pos: [1, 3, 4], state: "minecraft:birch_log{axis:z}"},
        {pos: [1, 3, 5], state: "minecraft:leaf_litter{facing:east,segment_amount:1}"},
        {pos: [2, 3, 4], state: "minecraft:leaf_litter{facing:east,segment_amount:1}"},
        {pos: [3, 3, 2], state: "minecraft:campfire{facing:west,lit:false,signal_fire:false,waterlogged:false}", nbt: {CookingTimes: [I; 0, 0, 0, 0], CookingTotalTimes: [I; 0, 0, 0, 0], Items: [], components: {}, id: "minecraft:campfire"}},
        {pos: [3, 3, 5], state: "minecraft:oak_fence{east:false,north:false,south:false,waterlogged:false,west:false}"},
        {pos: [4, 3, 0], state: "minecraft:chest{facing:south,type:single,waterlogged:false}", nbt: {Items: [], LootTable: "minecraft:chests/abandoned_camp_common_chest", components: {}, id: "minecraft:chest"}},
        {pos: [5, 3, 5], state: "minecraft:oak_fence{east:false,north:false,south:false,waterlogged:false,west:false}"},
        {pos: [7, 3, 1], state: "minecraft:bush"},
        {pos: [7, 3, 2], state: "minecraft:bush"},
        {pos: [3, 4, 5], state: "minecraft:oak_planks"},
        {pos: [4, 4, 5], state: "minecraft:oak_planks"},
        {pos: [5, 4, 5], state: "minecraft:oak_planks"}
    ],
    entities: [
        {blockPos: [3, 2, 1], pos: [3.5d, 2.9375d, 1.5d], nbt: {Air: 300s, Fire: 0s, Invulnerable: 0b, Motion: [0.0d, 0.0d, 0.0d], OnGround: 0b, PortalCooldown: 0, Pos: [-107.5d, -60.0625d, 88.5d], Rotation: [90.0f, 0.0f], UUID: [I; 1987681462, 671105073, -1545475337, 611882372], block_pos: [I; -108, -61, 88], color: "blue", fall_distance: 0.0d, id: "minecraft:cushion"}}
    ],
    palette: [
        "minecraft:stone",
        "minecraft:gravel",
        "minecraft:iron_ore",
        "minecraft:cobblestone",
        "minecraft:grass_block{snowy:false}",
        "minecraft:dirt",
        "minecraft:oak_planks",
        "minecraft:birch_log{axis:z}",
        "minecraft:oak_fence{east:true,north:true,south:true,waterlogged:false,west:true}",
        "minecraft:dirt_path",
        "minecraft:cobweb",
        "minecraft:oak_fence{east:false,north:false,south:true,waterlogged:false,west:true}",
        "minecraft:oak_fence{east:false,north:true,south:false,waterlogged:false,west:false}",
        "minecraft:leaf_litter{facing:east,segment_amount:1}",
        "minecraft:oak_fence{east:false,north:false,south:false,waterlogged:false,west:false}",
        "minecraft:bush",
        "minecraft:oxidized_copper_chest{facing:south,type:single,waterlogged:false}",
        "minecraft:jigsaw{orientation:up_east}",
        "minecraft:jigsaw{orientation:up_west}",
        "minecraft:jigsaw{orientation:east_up}",
        "minecraft:campfire{facing:west,lit:false,signal_fire:false,waterlogged:false}",
        "minecraft:chest{facing:south,type:single,waterlogged:false}"
    ]
}
