{
    size: [14, 24, 14],
    data: [
        {pos: [1, 0, 0], state: "minecraft:deepslate{axis:y}"},
        {pos: [1, 0, 1], state: "minecraft:deepslate{axis:y}"},
        {pos: [1, 0, 2], state: "minecraft:deepslate{axis:y}"},
        {pos: [1, 0, 3], state: "minecraft:deepslate{axis:y}"},
        {pos: [1, 0, 4], state: "minecraft:deepslate{axis:y}"},
        {pos: [1, 0, 5], state: "minecraft:deepslate_bricks"},
        {pos: [1, 0, 6], state: "minecraft:deepslate_bricks"},
        {pos: [1, 0, 7], state: "minecraft:deepslate_bricks"},
        {pos: [1, 0, 8], state: "minecraft:deepslate_bricks"},
        {pos: [1, 0, 9], state: "minecraft:deepslate_bricks"},
        {pos: [1, 0, 10], state: "minecraft:deepslate_bricks"},
        {pos: [1, 0, 11], state: "minecraft:deepslate_bricks"},
        {pos: [1, 0, 12], state: "minecraft:deepslate_bricks"},
        {pos: [2, 0, 0], state: "minecraft:deepslate{axis:y}"},
        {pos: [2, 0, 1], state: "minecraft:deepslate_bricks"},
        {pos: [2, 0, 2], state: "minecraft:deepslate_bricks"},
        {pos: [2, 0, 3], state: "minecraft:deepslate_bricks"},
        {pos: [2, 0, 4], state: "minecraft:deepslate_bricks"},
        {pos: [2, 0, 5], state: "minecraft:deepslate_bricks"},
        {pos: [2, 0, 6], state: "minecraft:deepslate_bricks"},
        {pos: [2, 0, 7], state: "minecraft:deepslate_bricks"},
        {pos: [2, 0, 8], state: "minecraft:deepslate_bricks"},
        {pos: [2, 0, 9], state: "minecraft:deepslate_bricks"},
        {pos: [2, 0, 10], state: "minecraft:deepslate_bricks"},
        {pos: [2, 0, 11], state: "minecraft:deepslate_bricks"},
        {pos: [2, 0, 12], state: "minecraft:deepslate_bricks"},
        {pos: [3, 0, 0], state: "minecraft:deepslate{axis:y}"},
        {pos: [3, 0, 1], state: "minecraft:deepslate_bricks"},
        {pos: [3, 0, 2], state: "minecraft:deepslate_bricks"},
        {pos: [3, 0, 3], state: "minecraft:deepslate_bricks"},
        {pos: [3, 0, 4], state: "minecraft:deepslate_bricks"},
        {pos: [3, 0, 5], state: "minecraft:deepslate_bricks"},
        {pos: [3, 0, 6], state: "minecraft:deepslate_bricks"},
        {pos: [3, 0, 7], state: "minecraft:deepslate_bricks"},
        {pos: [3, 0, 8], state: "minecraft:deepslate_bricks"},
        {pos: [3, 0, 9], state: "minecraft:deepslate_bricks"},
        {pos: [3, 0, 10], state: "minecraft:deepslate_bricks"},
        {pos: [3, 0, 11], state: "minecraft:deepslate_bricks"},
        {pos: [3, 0, 12], state: "minecraft:deepslate_bricks"},
        {pos: [4, 0, 0], state: "minecraft:deepslate_bricks"},
        {pos: [4, 0, 1], state: "minecraft:deepslate_bricks"},
        {pos: [4, 0, 2], state: "minecraft:deepslate_bricks"},
        {pos: [4, 0, 3], state: "minecraft:deepslate_bricks"},
        {pos: [4, 0, 4], state: "minecraft:deepslate_bricks"},
        {pos: [4, 0, 5], state: "minecraft:deepslate_bricks"},
        {pos: [4, 0, 6], state: "minecraft:deepslate_bricks"},
        {pos: [4, 0, 7], state: "minecraft:deepslate_bricks"},
        {pos: [4, 0, 8], state: "minecraft:deepslate_bricks"},
        {pos: [4, 0, 9], state: "minecraft:deepslate_bricks"},
        {pos: [4, 0, 10], state: "minecraft:deepslate_bricks"},
        {pos: [4, 0, 11], state: "minecraft:deepslate_bricks"},
        {pos: [4, 0, 12], state: "minecraft:deepslate_bricks"},
        {pos: [5, 0, 0], state: "minecraft:deepslate_bricks"},
        {pos: [5, 0, 1], state: "minecraft:deepslate_bricks"},
        {pos: [5, 0, 2], state: "minecraft:deepslate_bricks"},
        {pos: [5, 0, 3], state: "minecraft:deepslate_bricks"},
        {pos: [5, 0, 4], state: "minecraft:deepslate_bricks"},
        {pos: [5, 0, 5], state: "minecraft:deepslate_bricks"},
        {pos: [5, 0, 6], state: "minecraft:deepslate_bricks"},
        {pos: [5, 0, 7], state: "minecraft:deepslate{axis:y}"},
        {pos: [5, 0, 8], state: "minecraft:deepslate_bricks"},
        {pos: [5, 0, 9], state: "minecraft:deepslate_bricks"},
        {pos: [5, 0, 10], state: "minecraft:deepslate_bricks"},
        {pos: [5, 0, 11], state: "minecraft:deepslate_bricks"},
        {pos: [5, 0, 12], state: "minecraft:deepslate_bricks"},
        {pos: [6, 0, 0], state: "minecraft:deepslate_bricks"},
        {pos: [6, 0, 1], state: "minecraft:deepslate_bricks"},
        {pos: [6, 0, 2], state: "minecraft:deepslate{axis:y}"},
        {pos: [6, 0, 3], state: "minecraft:deepslate{axis:y}"},
        {pos: [6, 0, 4], state: "minecraft:deepslate{axis:y}"},
        {pos: [6, 0, 5], state: "minecraft:deepslate_bricks"},
        {pos: [6, 0, 6], state: "minecraft:deepslate_bricks"},
        {pos: [6, 0, 7], state: "minecraft:deepslate_bricks"},
        {pos: [6, 0, 8], state: "minecraft:deepslate_bricks"},
        {pos: [6, 0, 9], state: "minecraft:deepslate_bricks"},
        {pos: [6, 0, 10], state: "minecraft:deepslate_bricks"},
        {pos: [6, 0, 11], state: "minecraft:deepslate_bricks"},
        {pos: [6, 0, 12], state: "minecraft:deepslate_bricks"},
        {pos: [7, 0, 0], state: "minecraft:jigsaw{orientation:north_up}", nbt: {final_state: "minecraft:deepslate_bricks", id: "minecraft:jigsaw", joint: "rollable", name: "minecraft:connect_bottom_right_corner", pool: "minecraft:empty", target: "minecraft:empty"}},
        {pos: [7, 0, 1], state: "minecraft:deepslate_bricks"},
        {pos: [7, 0, 2], state: "minecraft:deepslate_bricks"},
        {pos: [7, 0, 3], state: "minecraft:deepslate{axis:y}"},
        {pos: [7, 0, 4], state: "minecraft:deepslate{axis:y}"},
        {pos: [7, 0, 5], state: "minecraft:deepslate{axis:y}"},
        {pos: [7, 0, 6], state: "minecraft:deepslate{axis:y}"},
        {pos: [7, 0, 7], state: "minecraft:deepslate_bricks"},
        {pos: [7, 0, 8], state: "minecraft:deepslate{axis:y}"},
        {pos: [7, 0, 9], state: "minecraft:deepslate_bricks"},
        {pos: [7, 0, 10], state: "minecraft:deepslate_bricks"},
        {pos: [7, 0, 11], state: "minecraft:deepslate_bricks"},
        {pos: [7, 0, 12], state: "minecraft:deepslate_bricks"},
        {pos: [8, 0, 0], state: "minecraft:deepslate_bricks"},
        {pos: [8, 0, 1], state: "minecraft:deepslate_bricks"},
        {pos: [8, 0, 2], state: "minecraft:deepslate_bricks"},
        {pos: [8, 0, 3], state: "minecraft:deepslate_bricks"},
        {pos: [8, 0, 4], state: "minecraft:deepslate{axis:y}"},
        {pos: [8, 0, 5], state: "minecraft:deepslate{axis:y}"},
        {pos: [8, 0, 6], state: "minecraft:deepslate_bricks"},
        {pos: [8, 0, 7], state: "minecraft:deepslate_bricks"},
        {pos: [8, 0, 8], state: "minecraft:deepslate{axis:y}"},
        {pos: [8, 0, 9], state: "minecraft:deepslate_bricks"},
        {pos: [8, 0, 10], state: "minecraft:deepslate_bricks"},
        {pos: [8, 0, 11], state: "minecraft:deepslate_bricks"},
        {pos: [8, 0, 12], state: "minecraft:deepslate_bricks"},
        {pos: [9, 0, 0], state: "minecraft:deepslate_bricks"},
        {pos: [9, 0, 1], state: "minecraft:deepslate_bricks"},
        {pos: [9, 0, 2], state: "minecraft:deepslate_bricks"},
        {pos: [9, 0, 3], state: "minecraft:deepslate_bricks"},
        {pos: [9, 0, 4], state: "minecraft:deepslate_bricks"},
        {pos: [9, 0, 5], state: "minecraft:deepslate_bricks"},
        {pos: [9, 0, 6], state: "minecraft:deepslate_bricks"},
        {pos: [9, 0, 7], state: "minecraft:deepslate_bricks"},
        {pos: [9, 0, 8], state: "minecraft:deepslate_bricks"},
        {pos: [9, 0, 9], state: "minecraft:deepslate_bricks"},
        {pos: [9, 0, 10], state: "minecraft:deepslate_bricks"},
        {pos: [9, 0, 11], state: "minecraft:deepslate_bricks"},
        {pos: [9, 0, 12], state: "minecraft:deepslate_bricks"},
        {pos: [10, 0, 0], state: "minecraft:deepslate_bricks"},
        {pos: [10, 0, 1], state: "minecraft:deepslate_bricks"},
        {pos: [10, 0, 2], state: "minecraft:deepslate_bricks"},
        {pos: [10, 0, 3], state: "minecraft:deepslate_bricks"},
        {pos: [10, 0, 4], state: "minecraft:deepslate_bricks"},
        {pos: [10, 0, 5], state: "minecraft:deepslate_bricks"},
        {pos: [10, 0, 6], state: "minecraft:deepslate{axis:y}"},
        {pos: [10, 0, 7], state: "minecraft:deepslate_bricks"},
        {pos: [10, 0, 8], state: "minecraft:deepslate_bricks"},
        {pos: [10, 0, 9], state: "minecraft:deepslate_bricks"},
        {pos: [10, 0, 10], state: "minecraft:deepslate_bricks"},
        {pos: [10, 0, 11], state: "minecraft:deepslate_bricks"},
        {pos: [10, 0, 12], state: "minecraft:deepslate_bricks"},
        {pos: [11, 0, 0], state: "minecraft:deepslate_bricks"},
        {pos: [11, 0, 1], state: "minecraft:deepslate_bricks"},
        {pos: [11, 0, 2], state: "minecraft:deepslate_bricks"},
        {pos: [11, 0, 3], state: "minecraft:deepslate_bricks"},
        {pos: [11, 0, 4], state: "minecraft:deepslate_bricks"},
        {pos: [11, 0, 5], state: "minecraft:deepslate{axis:y}"},
        {pos: [11, 0, 6], state: "minecraft:deepslate{axis:y}"},
        {pos: [11, 0, 7], state: "minecraft:deepslate{axis:y}"},
        {pos: [11, 0, 8], state: "minecraft:deepslate_bricks"},
        {pos: [11, 0, 9], state: "minecraft:deepslate_bricks"},
        {pos: [11, 0, 10], state: "minecraft:deepslate_bricks"},
        {pos: [11, 0, 11], state: "minecraft:deepslate_bricks"},
        {pos: [11, 0, 12], state: "minecraft:deepslate_bricks"},
        {pos: [12, 0, 0], state: "minecraft:deepslate_bricks"},
        {pos: [12, 0, 1], state: "minecraft:deepslate_bricks"},
        {pos: [12, 0, 2], state: "minecraft:deepslate_bricks"},
        {pos: [12, 0, 3], state: "minecraft:deepslate_bricks"},
        {pos: [12, 0, 4], state: "minecraft:deepslate{axis:y}"},
        {pos: [12, 0, 5], state: "minecraft:deepslate{axis:y}"},
        {pos: [12, 0, 6], state: "minecraft:deepslate{axis:y}"},
        {pos: [12, 0, 7], state: "minecraft:deepslate_bricks"},
        {pos: [12, 0, 8], state: "minecraft:deepslate_bricks"},
        {pos: [12, 0, 9], state: "minecraft:deepslate_bricks"},
        {pos: [12, 0, 10], state: "minecraft:deepslate_bricks"},
        {pos: [12, 0, 11], state: "minecraft:deepslate_bricks"},
        {pos: [12, 0, 12], state: "minecraft:deepslate_bricks"},
        {pos: [13, 0, 0], state: "minecraft:deepslate_bricks"},
        {pos: [13, 0, 1], state: "minecraft:deepslate_bricks"},
        {pos: [13, 0, 2], state: "minecraft:deepslate_bricks"},
        {pos: [13, 0, 3], state: "minecraft:deepslate_bricks"},
        {pos: [13, 0, 4], state: "minecraft:deepslate_bricks"},
        {pos: [13, 0, 5], state: "minecraft:deepslate_bricks"},
        {pos: [13, 0, 6], state: "minecraft:deepslate_bricks"},
        {pos: [13, 0, 7], state: "minecraft:deepslate_bricks"},
        {pos: [13, 0, 8], state: "minecraft:deepslate_bricks"},
        {pos: [13, 0, 9], state: "minecraft:deepslate_bricks"},
        {pos: [13, 0, 10], state: "minecraft:deepslate_bricks"},
        {pos: [13, 0, 11], state: "minecraft:deepslate_bricks"},
        {pos: [13, 0, 12], state: "minecraft:deepslate_bricks"},
        {pos: [1, 1, 0], state: "minecraft:deepslate_bricks"},
        {pos: [1, 1, 1], state: "minecraft:deepslate_bricks"},
        {pos: [1, 1, 2], state: "minecraft:deepslate_bricks"},
        {pos: [1, 1, 3], state: "minecraft:deepslate_bricks"},
        {pos: [1, 1, 4], state: "minecraft:deepslate_bricks"},
        {pos: [1, 1, 5], state: "minecraft:gray_wool"},
        {pos: [1, 1, 6], state: "minecraft:deepslate_tiles"},
        {pos: [1, 1, 7], state: "minecraft:deepslate_tiles"},
        {pos: [1, 1, 8], state: "minecraft:deepslate_bricks"},
        {pos: [1, 1, 9], state: "minecraft:deepslate_tiles"},
        {pos: [1, 1, 10], state: "minecraft:deepslate_tiles"},
        {pos: [1, 1, 11], state: "minecraft:deepslate_bricks"},
        {pos: [1, 1, 12], state: "minecraft:deepslate_bricks"},
        {pos: [2, 1, 0], state: "minecraft:gray_wool"},
        {pos: [2, 1, 1], state: "minecraft:gray_wool"},
        {pos: [2, 1, 2], state: "minecraft:gray_wool"},
        {pos: [2, 1, 3], state: "minecraft:gray_wool"},
        {pos: [2, 1, 4], state: "minecraft:gray_wool"},
        {pos: [2, 1, 5], state: "minecraft:gray_wool"},
        {pos: [2, 1, 6], state: "minecraft:gray_wool"},
        {pos: [2, 1, 7], state: "minecraft:gray_wool"},
        {pos: [2, 1, 8], state: "minecraft:gray_wool"},
        {pos: [2, 1, 9], state: "minecraft:gray_wool"},
        {pos: [2, 1, 10], state: "minecraft:gray_wool"},
        {pos: [2, 1, 11], state: "minecraft:gray_wool"},
        {pos: [2, 1, 12], state: "minecraft:deepslate_bricks"},
        {pos: [3, 1, 0], state: "minecraft:gray_wool"},
        {pos: [3, 1, 1], state: "minecraft:deepslate_bricks"},
        {pos: [3, 1, 2], state: "minecraft:deepslate_bricks"},
        {pos: [3, 1, 3], state: "minecraft:gray_wool"},
        {pos: [3, 1, 4], state: "minecraft:deepslate_bricks"},
        {pos: [3, 1, 5], state: "minecraft:deepslate_bricks"},
        {pos: [3, 1, 6], state: "minecraft:gray_wool"},
        {pos: [3, 1, 7], state: "minecraft:deepslate_bricks"},
        {pos: [3, 1, 8], state: "minecraft:deepslate_bricks"},
        {pos: [3, 1, 9], state: "minecraft:deepslate_bricks"},
        {pos: [3, 1, 10], state: "minecraft:deepslate_bricks"},
        {pos: [3, 1, 11], state: "minecraft:gray_wool"},
        {pos: [3, 1, 12], state: "minecraft:deepslate_tiles"},
        {pos: [4, 1, 1], state: "minecraft:deepslate_brick_stairs{facing:west,half:bottom,shape:straight,waterlogged:false}"},
        {pos: [4, 1, 2], state: "minecraft:deepslate_brick_stairs{facing:west,half:bottom,shape:straight,waterlogged:false}"},
        {pos: [4, 1, 4], state: "minecraft:deepslate_brick_stairs{facing:west,half:bottom,shape:straight,waterlogged:false}"},
        {pos: [4, 1, 5], state: "minecraft:deepslate_brick_stairs{facing:west,half:bottom,shape:straight,waterlogged:false}"},
        {pos: [4, 1, 7], state: "minecraft:deepslate_brick_stairs{facing:west,half:bottom,shape:straight,waterlogged:false}"},
        {pos: [4, 1, 8], state: "minecraft:deepslate_brick_stairs{facing:west,half:bottom,shape:straight,waterlogged:false}"},
        {pos: [4, 1, 9], state: "minecraft:deepslate_brick_stairs{facing:west,half:bottom,shape:inner_left,waterlogged:false}"},
        {pos: [4, 1, 10], state: "minecraft:deepslate_bricks"},
        {pos: [4, 1, 11], state: "minecraft:gray_wool"},
        {pos: [4, 1, 12], state: "minecraft:deepslate_tiles"},
        {pos: [5, 1, 9], state: "minecraft:deepslate_brick_stairs{facing:south,half:bottom,shape:straight,waterlogged:false}"},
        {pos: [5, 1, 10], state: "minecraft:deepslate_bricks"},
        {pos: [5, 1, 11], state: "minecraft:gray_wool"},
        {pos: [5, 1, 12], state: "minecraft:deepslate_bricks"},
        {pos: [6, 1, 9], state: "minecraft:deepslate_brick_stairs{facing:south,half:bottom,shape:straight,waterlogged:false}"},
        {pos: [6, 1, 10], state: "minecraft:deepslate_bricks"},
        {pos: [6, 1, 11], state: "minecraft:gray_wool"},
        {pos: [6, 1, 12], state: "minecraft:deepslate_tiles"},
        {pos: [7, 1, 10], state: "minecraft:gray_wool"},
        {pos: [7, 1, 11], state: "minecraft:gray_wool"},
        {pos: [7, 1, 12], state: "minecraft:deepslate_tiles"},
        {pos: [8, 1, 9], state: "minecraft:deepslate_brick_stairs{facing:south,half:bottom,shape:straight,waterlogged:false}"},
        {pos: [8, 1, 10], state: "minecraft:deepslate_bricks"},
        {pos: [8, 1, 11], state: "minecraft:gray_wool"},
        {pos: [8, 1, 12], state: "minecraft:deepslate_bricks"},
        {pos: [9, 1, 9], state: "minecraft:deepslate_brick_stairs{facing:south,half:bottom,shape:straight,waterlogged:false}"},
        {pos: [9, 1, 10], state: "minecraft:deepslate_bricks"},
        {pos: [9, 1, 11], state: "minecraft:gray_wool"},
        {pos: [9, 1, 12], state: "minecraft:deepslate_tiles"},
        {pos: [10, 1, 1], state: "minecraft:deepslate_brick_stairs{facing:south,half:bottom,shape:straight,waterlogged:false}"},
        {pos: [10, 1, 2], state: "minecraft:gray_wool"},
        {pos: [10, 1, 3], state: "minecraft:gray_wool"},
        {pos: [10, 1, 10], state: "minecraft:gray_wool"},
        {pos: [10, 1, 11], state: "minecraft:gray_wool"},
        {pos: [10, 1, 12], state: "minecraft:dark_oak_planks"},
        {pos: [11, 1, 0], state: "minecraft:deepslate{axis:y}"},
        {pos: [11, 1, 1], state: "minecraft:deepslate{axis:y}"},
        {pos: [11, 1, 2], state: "minecraft:deepslate{axis:y}"},
        {pos: [11, 1, 3], state: "minecraft:gray_wool"},
        {pos: [11, 1, 9], state: "minecraft:deepslate_brick_stairs{facing:south,half:bottom,shape:straight,waterlogged:false}"},
        {pos: [11, 1, 10], state: "minecraft:deepslate_bricks"},
        {pos: [11, 1, 11], state: "minecraft:gray_wool"},
        {pos: [12, 1, 0], state: "minecraft:gray_wool"},
        {pos: [12, 1, 1], state: "minecraft:gray_wool"},
        {pos: [12, 1, 2], state: "minecraft:deepslate{axis:y}"},
        {pos: [12, 1, 3], state: "minecraft:deepslate_brick_stairs{facing:west,half:bottom,shape:straight,waterlogged:false}"},
        {pos: [12, 1, 9], state: "minecraft:deepslate_brick_stairs{facing:south,half:bottom,shape:straight,waterlogged:false}"},
        {pos: [12, 1, 10], state: "minecraft:deepslate_bricks"},
        {pos: [12, 1, 11], state: "minecraft:gray_wool"},
        {pos: [12, 1, 12], state: "minecraft:dark_oak_planks"},
        {pos: [13, 1, 0], state: "minecraft:deepslate{axis:y}"},
        {pos: [13, 1, 1], state: "minecraft:gray_wool"},
        {pos: [13, 1, 2], state: "minecraft:deepslate{axis:y}"},
        {pos: [13, 1, 10], state: "minecraft:gray_wool"},
        {pos: [13, 1, 11], state: "minecraft:gray_wool"},
        {pos: [13, 1, 12], state: "minecraft:gray_wool"},
        {pos: [1, 2, 0], state: "minecraft:deepslate_tiles"},
        {pos: [1, 2, 1], state: "minecraft:deepslate_tiles"},
        {pos: [1, 2, 2], state: "minecraft:deepslate_bricks"},
        {pos: [1, 2, 3], state: "minecraft:chiseled_deepslate"},
        {pos: [1, 2, 4], state: "minecraft:deepslate{axis:y}"},
        {pos: [1, 2, 5], state: "minecraft:gray_wool"},
        {pos: [1, 2, 6], state: "minecraft:deepslate_tiles"},
        {pos: [1, 2, 7], state: "minecraft:deepslate_tiles"},
        {pos: [1, 2, 8], state: "minecraft:deepslate_bricks"},
        {pos: [1, 2, 9], state: "minecraft:deepslate_tiles"},
        {pos: [1, 2, 10], state: "minecraft:deepslate_tiles"},
        {pos: [1, 2, 11], state: "minecraft:deepslate_bricks"},
        {pos: [1, 2, 12], state: "minecraft:chiseled_deepslate"},
        {pos: [2, 2, 0], state: "minecraft:gray_wool"},
        {pos: [2, 2, 1], state: "minecraft:gray_wool"},
        {pos: [2, 2, 2], state: "minecraft:gray_wool"},
        {pos: [2, 2, 3], state: "minecraft:gray_wool"},
        {pos: [2, 2, 4], state: "minecraft:gray_wool"},
        {pos: [2, 2, 5], state: "minecraft:gray_wool"},
        {pos: [2, 2, 6], state: "minecraft:gray_wool"},
        {pos: [2, 2, 7], state: "minecraft:gray_wool"},
        {pos: [2, 2, 8], state: "minecraft:gray_wool"},
        {pos: [2, 2, 9], state: "minecraft:gray_wool"},
        {pos: [2, 2, 10], state: "minecraft:gray_wool"},
        {pos: [2, 2, 11], state: "minecraft:gray_wool"},
        {pos: [2, 2, 12], state: "minecraft:deepslate_tiles"},
        {pos: [3, 2, 0], state: "minecraft:gray_wool"},
        {pos: [3, 2, 1], state: "minecraft:chiseled_deepslate"},
        {pos: [3, 2, 2], state: "minecraft:chiseled_deepslate"},
        {pos: [3, 2, 3], state: "minecraft:gray_wool"},
        {pos: [3, 2, 4], state: "minecraft:chiseled_deepslate"},
        {pos: [3, 2, 5], state: "minecraft:chiseled_deepslate"},
        {pos: [3, 2, 6], state: "minecraft:gray_wool"},
        {pos: [3, 2, 8], state: "minecraft:chiseled_deepslate"},
        {pos: [3, 2, 9], state: "minecraft:chiseled_deepslate"},
        {pos: [3, 2, 10], state: "minecraft:chiseled_deepslate"},
        {pos: [3, 2, 11], state: "minecraft:gray_wool"},
        {pos: [3, 2, 12], state: "minecraft:deepslate_tiles"},
        {pos: [4, 2, 10], state: "minecraft:chiseled_deepslate"},
        {pos: [4, 2, 11], state: "minecraft:gray_wool"},
        {pos: [4, 2, 12], state: "minecraft:deepslate_tiles"},
        {pos: [5, 2, 10], state: "minecraft:chiseled_deepslate"},
        {pos: [5, 2, 11], state: "minecraft:gray_wool"},
        {pos: [5, 2, 12], state: "minecraft:deepslate_bricks"},
        {pos: [6, 2, 10], state: "minecraft:chiseled_deepslate"},
        {pos: [6, 2, 11], state: "minecraft:gray_wool"},
        {pos: [6, 2, 12], state: "minecraft:deepslate_tiles"},
        {pos: [7, 2, 10], state: "minecraft:gray_wool"},
        {pos: [7, 2, 11], state: "minecraft:gray_wool"},
        {pos: [7, 2, 12], state: "minecraft:deepslate_tiles"},
        {pos: [8, 2, 11], state: "minecraft:gray_wool"},
        {pos: [8, 2, 12], state: "minecraft:deepslate_bricks"},
        {pos: [9, 2, 10], state: "minecraft:chiseled_deepslate"},
        {pos: [9, 2, 11], state: "minecraft:gray_wool"},
        {pos: [9, 2, 12], state: "minecraft:dark_oak_planks"},
        {pos: [10, 2, 2], state: "minecraft:gray_wool"},
        {pos: [10, 2, 3], state: "minecraft:gray_wool"},
        {pos: [10, 2, 10], state: "minecraft:gray_wool"},
        {pos: [10, 2, 11], state: "minecraft:gray_wool"},
        {pos: [11, 2, 0], state: "minecraft:deepslate_bricks"},
        {pos: [11, 2, 1], state: "minecraft:deepslate_bricks"},
        {pos: [11, 2, 2], state: "minecraft:deepslate_bricks"},
        {pos: [11, 2, 3], state: "minecraft:gray_wool"},
        {pos: [11, 2, 10], state: "minecraft:chiseled_deepslate"},
        {pos: [11, 2, 11], state: "minecraft:gray_wool"},
        {pos: [12, 2, 0], state: "minecraft:gray_wool"},
        {pos: [12, 2, 1], state: "minecraft:gray_wool"},
        {pos: [12, 2, 2], state: "minecraft:deepslate_bricks"},
        {pos: [12, 2, 10], state: "minecraft:chiseled_deepslate"},
        {pos: [12, 2, 11], state: "minecraft:gray_wool"},
        {pos: [12, 2, 12], state: "minecraft:dark_oak_planks"},
        {pos: [13, 2, 0], state: "minecraft:deepslate{axis:y}"},
        {pos: [13, 2, 1], state: "minecraft:gray_wool"},
        {pos: [13, 2, 2], state: "minecraft:deepslate_bricks"},
        {pos: [13, 2, 10], state: "minecraft:gray_wool"},
        {pos: [13, 2, 11], state: "minecraft:gray_wool"},
        {pos: [13, 2, 12], state: "minecraft:gray_wool"},
        {pos: [1, 3, 0], state: "minecraft:deepslate_tile_stairs{facing:east,half:top,shape:straight,waterlogged:false}"},
        {pos: [1, 3, 1], state: "minecraft:deepslate_tile_stairs{facing:east,half:top,shape:straight,waterlogged:false}"},
        {pos: [1, 3, 2], state: "minecraft:deepslate_bricks"},
        {pos: [1, 3, 3], state: "minecraft:chiseled_deepslate"},
        {pos: [1, 3, 4], state: "minecraft:gray_wool"},
        {pos: [1, 3, 5], state: "minecraft:deepslate{axis:y}"},
        {pos: [1, 3, 8], state: "minecraft:deepslate_bricks"},
        {pos: [1, 3, 9], state: "minecraft:deepslate_tile_stairs{facing:east,half:bottom,shape:straight,waterlogged:false}"},
        {pos: [1, 3, 10], state: "minecraft:deepslate_tile_stairs{facing:east,half:bottom,shape:straight,waterlogged:false}"},
        {pos: [1, 3, 11], state: "minecraft:deepslate_bricks"},
        {pos: [1, 3, 12], state: "minecraft:chiseled_deepslate"},
        {pos: [2, 3, 0], state: "minecraft:gray_wool"},
        {pos: [2, 3, 1], state: "minecraft:gray_wool"},
        {pos: [2, 3, 2], state: "minecraft:gray_wool"},
        {pos: [2, 3, 3], state: "minecraft:gray_wool"},
        {pos: [2, 3, 4], state: "minecraft:gray_wool"},
        {pos: [2, 3, 5], state: "minecraft:gray_wool"},
        {pos: [2, 3, 8], state: "minecraft:gray_wool"},
        {pos: [2, 3, 9], state: "minecraft:gray_wool"},
        {pos: [2, 3, 10], state: "minecraft:gray_wool"},
        {pos: [2, 3, 11], state: "minecraft:gray_wool"},
        {pos: [2, 3, 12], state: "minecraft:deepslate_tile_stairs{facing:north,half:top,shape:straight,waterlogged:false}"},
        {pos: [3, 3, 0], state: "minecraft:gray_wool"},
        {pos: [3, 3, 1], state: "minecraft:deepslate_tile_stairs{facing:west,half:bottom,shape:straight,waterlogged:false}"},
        {pos: [3, 3, 2], state: "minecraft:deepslate_tile_stairs{facing:west,half:bottom,shape:straight,waterlogged:false}"},
        {pos: [3, 3, 3], state: "minecraft:gray_wool"},
        {pos: [3, 3, 4], state: "minecraft:deepslate_tile_stairs{facing:west,half:bottom,shape:straight,waterlogged:false}"},
        {pos: [3, 3, 8], state: "minecraft:deepslate_tile_stairs{facing:west,half:bottom,shape:straight,waterlogged:false}"},
        {pos: [3, 3, 9], state: "minecraft:deepslate_tile_stairs{facing:west,half:bottom,shape:straight,waterlogged:false}"},
        {pos: [3, 3, 10], state: "minecraft:deepslate_tile_stairs{facing:south,half:bottom,shape:inner_right,waterlogged:false}"},
        {pos: [3, 3, 11], state: "minecraft:gray_wool"},
        {pos: [3, 3, 12], state: "minecraft:deepslate_tile_stairs{facing:north,half:top,shape:straight,waterlogged:false}"},
        {pos: [4, 3, 10], state: "minecraft:deepslate_tile_stairs{facing:south,half:bottom,shape:straight,waterlogged:false}"},
        {pos: [4, 3, 11], state: "minecraft:gray_wool"},
        {pos: [4, 3, 12], state: "minecraft:deepslate_tile_stairs{facing:north,half:top,shape:straight,waterlogged:false}"},
        {pos: [5, 3, 10], state: "minecraft:deepslate_tile_stairs{facing:south,half:bottom,shape:straight,waterlogged:false}"},
        {pos: [5, 3, 11], state: "minecraft:gray_wool"},
        {pos: [5, 3, 12], state: "minecraft:deepslate_bricks"},
        {pos: [6, 3, 10], state: "minecraft:deepslate_tile_stairs{facing:south,half:bottom,shape:straight,waterlogged:false}"},
        {pos: [6, 3, 11], state: "minecraft:gray_wool"},
        {pos: [6, 3, 12], state: "minecraft:deepslate_tile_stairs{facing:north,half:top,shape:straight,waterlogged:false}"},
        {pos: [7, 3, 10], state: "minecraft:gray_wool"},
        {pos: [7, 3, 11], state: "minecraft:gray_wool"},
        {pos: [7, 3, 12], state: "minecraft:deepslate_tile_stairs{facing:north,half:top,shape:straight,waterlogged:false}"},
        {pos: [8, 3, 11], state: "minecraft:gray_wool"},
        {pos: [8, 3, 12], state: "minecraft:dark_oak_planks"},
        {pos: [9, 3, 11], state: "minecraft:dark_oak_planks"},
        {pos: [9, 3, 12], state: "minecraft:light_blue_carpet"},
        {pos: [10, 3, 0], state: "minecraft:chiseled_deepslate"},
        {pos: [10, 3, 1], state: "minecraft:deepslate_tile_stairs{facing:east,half:top,shape:straight,waterlogged:false}"},
        {pos: [10, 3, 2], state: "minecraft:gray_wool"},
        {pos: [10, 3, 3], state: "minecraft:gray_wool"},
        {pos: [11, 3, 0], state: "minecraft:deepslate_bricks"},
        {pos: [11, 3, 1], state: "minecraft:deepslate_bricks"},
        {pos: [11, 3, 2], state: "minecraft:deepslate_bricks"},
        {pos: [11, 3, 3], state: "minecraft:gray_wool"},
        {pos: [11, 3, 10], state: "minecraft:deepslate_tile_stairs{facing:south,half:bottom,shape:straight,waterlogged:false}"},
        {pos: [11, 3, 11], state: "minecraft:gray_wool"},
        {pos: [12, 3, 0], state: "minecraft:gray_wool"},
        {pos: [12, 3, 1], state: "minecraft:gray_wool"},
        {pos: [12, 3, 2], state: "minecraft:deepslate_bricks"},
        {pos: [12, 3, 3], state: "minecraft:deepslate_tile_stairs{facing:north,half:top,shape:straight,waterlogged:false}"},
        {pos: [12, 3, 10], state: "minecraft:deepslate_tile_stairs{facing:south,half:bottom,shape:straight,waterlogged:false}"},
        {pos: [12, 3, 11], state: "minecraft:gray_wool"},
        {pos: [12, 3, 12], state: "minecraft:dark_oak_planks"},
        {pos: [13, 3, 0], state: "minecraft:deepslate_bricks"},
        {pos: [13, 3, 1], state: "minecraft:gray_wool"},
        {pos: [13, 3, 2], state: "minecraft:deepslate_bricks"},
        {pos: [13, 3, 3], state: "minecraft:chiseled_deepslate"},
        {pos: [13, 3, 10], state: "minecraft:gray_wool"},
        {pos: [13, 3, 11], state: "minecraft:gray_wool"},
        {pos: [13, 3, 12], state: "minecraft:gray_wool"},
        {pos: [0, 4, 0], state: "minecraft:deepslate_tile_stairs{facing:east,half:top,shape:straight,waterlogged:false}"},
        {pos: [0, 4, 1], state: "minecraft:deepslate_tile_stairs{facing:east,half:top,shape:straight,waterlogged:false}"},
        {pos: [0, 4, 6], state: "minecraft:deepslate_tile_stairs{facing:east,half:top,shape:straight,waterlogged:false}"},
        {pos: [0, 4, 7], state: "minecraft:deepslate_tile_stairs{facing:east,half:top,shape:straight,waterlogged:false}"},
        {pos: [0, 4, 8], state: "minecraft:deepslate_tile_stairs{facing:east,half:top,shape:straight,waterlogged:false}"},
        {pos: [0, 4, 9], state: "minecraft:deepslate_tile_stairs{facing:east,half:top,shape:straight,waterlogged:false}"},
        {pos: [0, 4, 10], state: "minecraft:deepslate_tile_stairs{facing:east,half:top,shape:straight,waterlogged:false}"},
        {pos: [0, 4, 11], state: "minecraft:deepslate_bricks"},
        {pos: [0, 4, 12], state: "minecraft:deepslate_bricks"},
        {pos: [0, 4, 13], state: "minecraft:deepslate_bricks"},
        {pos: [1, 4, 0], state: "minecraft:gray_wool"},
        {pos: [1, 4, 1], state: "minecraft:gray_wool"},
        {pos: [1, 4, 2], state: "minecraft:gray_wool"},
        {pos: [1, 4, 6], state: "minecraft:gray_wool"},
        {pos: [1, 4, 7], state: "minecraft:gray_wool"},
        {pos: [1, 4, 8], state: "minecraft:gray_wool"},
        {pos: [1, 4, 9], state: "minecraft:gray_wool"},
        {pos: [1, 4, 10], state: "minecraft:gray_wool"},
        {pos: [1, 4, 11], state: "minecraft:gray_wool"},
        {pos: [1, 4, 12], state: "minecraft:gray_wool"},
        {pos: [1, 4, 13], state: "minecraft:deepslate_bricks"},
        {pos: [2, 4, 0], state: "minecraft:gray_wool"},
        {pos: [2, 4, 1], state: "minecraft:gray_wool"},
        {pos: [2, 4, 2], state: "minecraft:gray_wool"},
        {pos: [2, 4, 3], state: "minecraft:gray_wool"},
        {pos: [2, 4, 4], state: "minecraft:deepslate{axis:y}"},
        {pos: [2, 4, 8], state: "minecraft:gray_wool"},
        {pos: [2, 4, 9], state: "minecraft:gray_wool"},
        {pos: [2, 4, 10], state: "minecraft:gray_wool"},
        {pos: [2, 4, 11], state: "minecraft:gray_wool"},
        {pos: [2, 4, 12], state: "minecraft:gray_wool"},
        {pos: [2, 4, 13], state: "minecraft:deepslate_bricks"},
        {pos: [3, 4, 0], state: "minecraft:gray_wool"},
        {pos: [3, 4, 1], state: "minecraft:deepslate_tile_stairs{facing:west,half:top,shape:straight,waterlogged:false}"},
        {pos: [3, 4, 2], state: "minecraft:deepslate_tile_stairs{facing:west,half:top,shape:straight,waterlogged:false}"},
        {pos: [3, 4, 8], state: "minecraft:deepslate_tile_stairs{facing:west,half:top,shape:straight,waterlogged:false}"},
        {pos: [3, 4, 9], state: "minecraft:deepslate_tile_stairs{facing:west,half:top,shape:straight,waterlogged:false}"},
        {pos: [3, 4, 10], state: "minecraft:deepslate_tile_stairs{facing:south,half:top,shape:inner_right,waterlogged:false}"},
        {pos: [3, 4, 11], state: "minecraft:gray_wool"},
        {pos: [3, 4, 12], state: "minecraft:gray_wool"},
        {pos: [3, 4, 13], state: "minecraft:deepslate_tile_stairs{facing:north,half:top,shape:straight,waterlogged:false}"},
        {pos: [4, 4, 10], state: "minecraft:deepslate_tile_stairs{facing:south,half:top,shape:straight,waterlogged:false}"},
        {pos: [4, 4, 11], state: "minecraft:gray_wool"},
        {pos: [4, 4, 12], state: "minecraft:gray_wool"},
        {pos: [4, 4, 13], state: "minecraft:deepslate_tile_stairs{facing:north,half:top,shape:straight,waterlogged:false}"},
        {pos: [5, 4, 10], state: "minecraft:deepslate_tile_stairs{facing:south,half:top,shape:straight,waterlogged:false}"},
        {pos: [5, 4, 11], state: "minecraft:gray_wool"},
        {pos: [5, 4, 12], state: "minecraft:gray_wool"},
        {pos: [5, 4, 13], state: "minecraft:deepslate_tile_stairs{facing:north,half:top,shape:straight,waterlogged:false}"},
        {pos: [6, 4, 10], state: "minecraft:deepslate_tile_stairs{facing:south,half:top,shape:straight,waterlogged:false}"},
        {pos: [6, 4, 11], state: "minecraft:gray_wool"},
        {pos: [6, 4, 12], state: "minecraft:gray_wool"},
        {pos: [6, 4, 13], state: "minecraft:deepslate_tile_stairs{facing:north,half:top,shape:straight,waterlogged:false}"},
        {pos: [7, 4, 10], state: "minecraft:gray_wool"},
        {pos: [7, 4, 11], state: "minecraft:gray_wool"},
        {pos: [7, 4, 12], state: "minecraft:dark_oak_planks"},
        {pos: [7, 4, 13], state: "minecraft:deepslate_tile_stairs{facing:north,half:top,shape:straight,waterlogged:false}"},
        {pos: [8, 4, 12], state: "minecraft:light_blue_carpet"},
        {pos: [10, 4, 0], state: "minecraft:deepslate_tile_stairs{facing:east,half:bottom,shape:straight,waterlogged:false}"},
        {pos: [10, 4, 1], state: "minecraft:deepslate_tile_stairs{facing:east,half:bottom,shape:straight,waterlogged:false}"},
        {pos: [10, 4, 2], state: "minecraft:gray_wool"},
        {pos: [10, 4, 3], state: "minecraft:gray_wool"},
        {pos: [11, 4, 0], state: "minecraft:deepslate_bricks"},
        {pos: [11, 4, 1], state: "minecraft:deepslate_bricks"},
        {pos: [11, 4, 2], state: "minecraft:deepslate_bricks"},
        {pos: [11, 4, 3], state: "minecraft:gray_wool"},
        {pos: [11, 4, 10], state: "minecraft:deepslate_tile_stairs{facing:south,half:top,shape:straight,waterlogged:false}"},
        {pos: [11, 4, 11], state: "minecraft:gray_wool"},
        {pos: [12, 4, 0], state: "minecraft:deepslate_bricks"},
        {pos: [12, 4, 1], state: "minecraft:deepslate_bricks"},
        {pos: [12, 4, 2], state: "minecraft:deepslate_bricks"},
        {pos: [12, 4, 3], state: "minecraft:deepslate_tile_stairs{facing:north,half:bottom,shape:straight,waterlogged:false}"},
        {pos: [12, 4, 10], state: "minecraft:deepslate_tile_stairs{facing:south,half:top,shape:straight,waterlogged:false}"},
        {pos: [12, 4, 11], state: "minecraft:gray_wool"},
        {pos: [12, 4, 12], state: "minecraft:gray_wool"},
        {pos: [12, 4, 13], state: "minecraft:deepslate_tile_stairs{facing:north,half:top,shape:straight,waterlogged:false}"},
        {pos: [13, 4, 0], state: "minecraft:deepslate_bricks"},
        {pos: [13, 4, 1], state: "minecraft:deepslate_bricks"},
        {pos: [13, 4, 2], state: "minecraft:deepslate_bricks"},
        {pos: [13, 4, 3], state: "minecraft:deepslate_tile_stairs{facing:north,half:bottom,shape:straight,waterlogged:false}"},
        {pos: [13, 4, 10], state: "minecraft:gray_wool"},
        {pos: [13, 4, 11], state: "minecraft:gray_wool"},
        {pos: [13, 4, 12], state: "minecraft:gray_wool"},
        {pos: [13, 4, 13], state: "minecraft:deepslate_tile_stairs{facing:north,half:top,shape:straight,waterlogged:false}"},
        {pos: [0, 5, 0], state: "minecraft:chiseled_deepslate"},
        {pos: [0, 5, 1], state: "minecraft:chiseled_deepslate"},
        {pos: [0, 5, 2], state: "minecraft:deepslate_tile_wall{east:none,north:low,south:none,up:true,waterlogged:false,west:none}"},
        {pos: [0, 5, 7], state: "minecraft:chiseled_deepslate"},
        {pos: [0, 5, 8], state: "minecraft:deepslate_tile_wall{east:none,north:low,south:low,up:false,waterlogged:false,west:none}"},
        {pos: [0, 5, 9], state: "minecraft:chiseled_deepslate"},
        {pos: [0, 5, 10], state: "minecraft:chiseled_deepslate"},
        {pos: [0, 5, 11], state: "minecraft:deepslate_tile_wall{east:none,north:low,south:low,up:false,waterlogged:false,west:none}"},
        {pos: [0, 5, 12], state: "minecraft:chiseled_deepslate"},
        {pos: [0, 5, 13], state: "minecraft:chiseled_deepslate"},
        {pos: [1, 5, 13], state: "minecraft:chiseled_deepslate"},
        {pos: [2, 5, 13], state: "minecraft:deepslate_tile_wall{east:low,north:none,south:none,up:false,waterlogged:false,west:low}"},
        {pos: [3, 5, 0], state: "minecraft:deepslate_tile_stairs{facing:east,half:bottom,shape:straight,waterlogged:false}"},
        {pos: [3, 5, 1], state: "minecraft:chiseled_deepslate"},
        {pos: [3, 5, 2], state: "minecraft:chiseled_deepslate"},
        {pos: [3, 5, 8], state: "minecraft:chiseled_deepslate"},
        {pos: [3, 5, 9], state: "minecraft:deepslate_tile_stairs{facing:east,half:bottom,shape:straight,waterlogged:false}"},
        {pos: [3, 5, 10], state: "minecraft:chiseled_deepslate"},
        {pos: [3, 5, 13], state: "minecraft:chiseled_deepslate"},
        {pos: [4, 5, 0], state: "minecraft:deepslate_tile_stairs{facing:west,half:top,shape:straight,waterlogged:false}"},
        {pos: [4, 5, 1], state: "minecraft:chiseled_deepslate"},
        {pos: [4, 5, 2], state: "minecraft:chiseled_deepslate"},
        {pos: [4, 5, 10], state: "minecraft:deepslate_tile_stairs{facing:north,half:bottom,shape:straight,waterlogged:false}"},
        {pos: [4, 5, 13], state: "minecraft:chiseled_deepslate"},
        {pos: [5, 5, 10], state: "minecraft:chiseled_deepslate"},
        {pos: [5, 5, 13], state: "minecraft:deepslate_tile_wall{east:low,north:none,south:none,up:false,waterlogged:false,west:low}"},
        {pos: [6, 5, 10], state: "minecraft:chiseled_deepslate"},
        {pos: [6, 5, 13], state: "minecraft:chiseled_deepslate"},
        {pos: [7, 5, 10], state: "minecraft:deepslate_tile_stairs{facing:north,half:bottom,shape:straight,waterlogged:false}"},
        {pos: [7, 5, 12], state: "minecraft:light_blue_carpet"},
        {pos: [7, 5, 13], state: "minecraft:chiseled_deepslate"},
        {pos: [8, 5, 13], state: "minecraft:deepslate_tile_wall{east:none,north:none,south:none,up:true,waterlogged:false,west:low}"},
        {pos: [10, 5, 0], state: "minecraft:deepslate_tile_stairs{facing:east,half:top,shape:straight,waterlogged:false}"},
        {pos: [10, 5, 1], state: "minecraft:deepslate_tile_stairs{facing:east,half:top,shape:straight,waterlogged:false}"},
        {pos: [10, 5, 2], state: "minecraft:gray_wool"},
        {pos: [10, 5, 3], state: "minecraft:gray_wool"},
        {pos: [11, 5, 3], state: "minecraft:gray_wool"},
        {pos: [11, 5, 10], state: "minecraft:chiseled_deepslate"},
        {pos: [12, 5, 0], state: "minecraft:gray_wool"},
        {pos: [12, 5, 1], state: "minecraft:gray_wool"},
        {pos: [12, 5, 3], state: "minecraft:deepslate_tile_stairs{facing:north,half:top,shape:straight,waterlogged:false}"},
        {pos: [12, 5, 10], state: "minecraft:chiseled_deepslate"},
        {pos: [12, 5, 13], state: "minecraft:chiseled_deepslate"},
        {pos: [13, 5, 1], state: "minecraft:gray_wool"},
        {pos: [13, 5, 3], state: "minecraft:deepslate_tile_stairs{facing:north,half:top,shape:straight,waterlogged:false}"},
        {pos: [13, 5, 10], state: "minecraft:deepslate_tile_stairs{facing:north,half:bottom,shape:straight,waterlogged:false}"},
        {pos: [13, 5, 13], state: "minecraft:chiseled_deepslate"},
        {pos: [0, 6, 0], state: "minecraft:deepslate_tile_stairs{facing:east,half:bottom,shape:straight,waterlogged:false}"},
        {pos: [0, 6, 1], state: "minecraft:deepslate_tile_stairs{facing:east,half:bottom,shape:straight,waterlogged:false}"},
        {pos: [0, 6, 7], state: "minecraft:deepslate_tile_stairs{facing:east,half:bottom,shape:straight,waterlogged:false}"},
        {pos: [0, 6, 9], state: "minecraft:deepslate_tile_stairs{facing:east,half:bottom,shape:straight,waterlogged:false}"},
        {pos: [0, 6, 10], state: "minecraft:deepslate_tile_stairs{facing:east,half:bottom,shape:straight,waterlogged:false}"},
        {pos: [0, 6, 12], state: "minecraft:deepslate_tile_stairs{facing:east,half:bottom,shape:straight,waterlogged:false}"},
        {pos: [0, 6, 13], state: "minecraft:deepslate_tile_stairs{facing:east,half:bottom,shape:outer_left,waterlogged:false}"},
        {pos: [1, 6, 13], state: "minecraft:deepslate_tile_stairs{facing:north,half:bottom,shape:straight,waterlogged:false}"},
        {pos: [3, 6, 1], state: "minecraft:deepslate_tile_stairs{facing:east,half:bottom,shape:straight,waterlogged:false}"},
        {pos: [3, 6, 2], state: "minecraft:deepslate_tile_stairs{facing:east,half:bottom,shape:straight,waterlogged:false}"},
        {pos: [3, 6, 7], state: "minecraft:deepslate_tile_stairs{facing:east,half:bottom,shape:straight,waterlogged:false}"},
        {pos: [3, 6, 8], state: "minecraft:deepslate_tile_stairs{facing:east,half:bottom,shape:straight,waterlogged:false}"},
        {pos: [3, 6, 9], state: "minecraft:deepslate_tile_stairs{facing:east,half:bottom,shape:straight,waterlogged:false}"},
        {pos: [3, 6, 10], state: "minecraft:deepslate_tile_stairs{facing:east,half:bottom,shape:outer_left,waterlogged:false}"},
        {pos: [3, 6, 13], state: "minecraft:deepslate_tile_stairs{facing:north,half:bottom,shape:straight,waterlogged:false}"},
        {pos: [4, 6, 1], state: "minecraft:deepslate_tile_stairs{facing:west,half:bottom,shape:straight,waterlogged:false}"},
        {pos: [4, 6, 2], state: "minecraft:deepslate_tile_stairs{facing:west,half:bottom,shape:straight,waterlogged:false}"},
        {pos: [4, 6, 10], state: "minecraft:deepslate_tile_stairs{facing:north,half:bottom,shape:straight,waterlogged:false}"},
        {pos: [4, 6, 13], state: "minecraft:deepslate_tile_stairs{facing:north,half:bottom,shape:straight,waterlogged:false}"},
        {pos: [5, 6, 10], state: "minecraft:deepslate_tile_stairs{facing:north,half:bottom,shape:straight,waterlogged:false}"},
        {pos: [6, 6, 10], state: "minecraft:deepslate_tile_stairs{facing:north,half:bottom,shape:straight,waterlogged:false}"},
        {pos: [6, 6, 13], state: "minecraft:deepslate_tile_stairs{facing:north,half:bottom,shape:straight,waterlogged:false}"},
        {pos: [7, 6, 13], state: "minecraft:deepslate_tile_stairs{facing:north,half:bottom,shape:straight,waterlogged:false}"},
        {pos: [10, 6, 0], state: "minecraft:deepslate_tile_stairs{facing:east,half:bottom,shape:straight,waterlogged:false}"},
        {pos: [10, 6, 3], state: "minecraft:gray_wool"},
        {pos: [11, 6, 10], state: "minecraft:deepslate_tile_stairs{facing:north,half:bottom,shape:straight,waterlogged:false}"},
        {pos: [12, 6, 0], state: "minecraft:gray_wool"},
        {pos: [12, 6, 1], state: "minecraft:gray_wool"},
        {pos: [12, 6, 10], state: "minecraft:deepslate_tile_stairs{facing:north,half:bottom,shape:straight,waterlogged:false}"},
        {pos: [12, 6, 13], state: "minecraft:deepslate_tile_stairs{facing:north,half:bottom,shape:straight,waterlogged:false}"},
        {pos: [13, 6, 1], state: "minecraft:gray_wool"},
        {pos: [13, 6, 3], state: "minecraft:deepslate_tile_stairs{facing:north,half:bottom,shape:straight,waterlogged:false}"},
        {pos: [13, 6, 13], state: "minecraft:deepslate_tile_stairs{facing:north,half:bottom,shape:straight,waterlogged:false}"},
        {pos: [0, 7, 0], state: "minecraft:deepslate_tile_stairs{facing:north,half:bottom,shape:straight,waterlogged:false}"},
        {pos: [0, 7, 1], state: "minecraft:deepslate_tile_stairs{facing:south,half:bottom,shape:straight,waterlogged:false}"},
        {pos: [0, 7, 9], state: "minecraft:deepslate_tile_stairs{facing:north,half:bottom,shape:straight,waterlogged:false}"},
        {pos: [0, 7, 10], state: "minecraft:deepslate_tile_stairs{facing:south,half:bottom,shape:straight,waterlogged:false}"},
        {pos: [0, 7, 12], state: "minecraft:deepslate_tile_stairs{facing:north,half:bottom,shape:straight,waterlogged:false}"},
        {pos: [0, 7, 13], state: "minecraft:deepslate_tile_slab{type:bottom,waterlogged:false}"},
        {pos: [1, 7, 13], state: "minecraft:deepslate_tile_stairs{facing:east,half:bottom,shape:straight,waterlogged:false}"},
        {pos: [3, 7, 1], state: "minecraft:deepslate_tile_stairs{facing:north,half:bottom,shape:straight,waterlogged:false}"},
        {pos: [3, 7, 2], state: "minecraft:deepslate_tile_stairs{facing:south,half:bottom,shape:straight,waterlogged:false}"},
        {pos: [3, 7, 7], state: "minecraft:deepslate_tile_stairs{facing:north,half:bottom,shape:straight,waterlogged:false}"},
        {pos: [3, 7, 8], state: "minecraft:deepslate_tile_stairs{facing:south,half:bottom,shape:straight,waterlogged:false}"},
        {pos: [3, 7, 9], state: "minecraft:deepslate_tile_slab{type:bottom,waterlogged:false}"},
        {pos: [3, 7, 10], state: "minecraft:deepslate_tile_slab{type:bottom,waterlogged:false}"},
        {pos: [3, 7, 13], state: "minecraft:deepslate_tile_stairs{facing:west,half:bottom,shape:straight,waterlogged:false}"},
        {pos: [4, 7, 10], state: "minecraft:deepslate_tile_slab{type:bottom,waterlogged:false}"},
        {pos: [4, 7, 13], state: "minecraft:deepslate_tile_stairs{facing:east,half:bottom,shape:straight,waterlogged:false}"},
        {pos: [5, 7, 10], state: "minecraft:deepslate_tile_stairs{facing:west,half:bottom,shape:straight,waterlogged:false}"},
        {pos: [6, 7, 10], state: "minecraft:deepslate_tile_stairs{facing:east,half:bottom,shape:straight,waterlogged:false}"},
        {pos: [6, 7, 13], state: "minecraft:deepslate_tile_stairs{facing:west,half:bottom,shape:straight,waterlogged:false}"},
        {pos: [7, 7, 13], state: "minecraft:deepslate_tile_stairs{facing:east,half:bottom,shape:straight,waterlogged:false}"},
        {pos: [11, 7, 10], state: "minecraft:deepslate_tile_stairs{facing:west,half:bottom,shape:straight,waterlogged:false}"},
        {pos: [12, 7, 10], state: "minecraft:deepslate_tile_stairs{facing:east,half:bottom,shape:straight,waterlogged:false}"},
        {pos: [12, 7, 13], state: "minecraft:deepslate_tile_stairs{facing:west,half:bottom,shape:straight,waterlogged:false}"},
        {pos: [13, 7, 13], state: "minecraft:deepslate_tile_stairs{facing:east,half:bottom,shape:straight,waterlogged:false}"}
    ],
    entities: [],
    palette: [
        "minecraft:deepslate{axis:y}",
        "minecraft:deepslate_bricks",
        "minecraft:gray_wool",
        "minecraft:deepslate_tiles",
        "minecraft:dark_oak_planks",
        "minecraft:chiseled_deepslate",
        "minecraft:deepslate_brick_stairs{facing:west,half:bottom,shape:straight,waterlogged:false}",
        "minecraft:deepslate_brick_stairs{facing:west,half:bottom,shape:inner_left,waterlogged:false}",
        "minecraft:deepslate_brick_stairs{facing:south,half:bottom,shape:straight,waterlogged:false}",
        "minecraft:deepslate_tile_stairs{facing:east,half:top,shape:straight,waterlogged:false}",
        "minecraft:deepslate_tile_stairs{facing:east,half:bottom,shape:straight,waterlogged:false}",
        "minecraft:deepslate_tile_stairs{facing:north,half:top,shape:straight,waterlogged:false}",
        "minecraft:deepslate_tile_stairs{facing:west,half:bottom,shape:straight,waterlogged:false}",
        "minecraft:deepslate_tile_stairs{facing:south,half:bottom,shape:inner_right,waterlogged:false}",
        "minecraft:deepslate_tile_stairs{facing:south,half:bottom,shape:straight,waterlogged:false}",
        "minecraft:light_blue_carpet",
        "minecraft:deepslate_tile_stairs{facing:west,half:top,shape:straight,waterlogged:false}",
        "minecraft:deepslate_tile_stairs{facing:south,half:top,shape:inner_right,waterlogged:false}",
        "minecraft:deepslate_tile_stairs{facing:south,half:top,shape:straight,waterlogged:false}",
        "minecraft:deepslate_tile_stairs{facing:north,half:bottom,shape:straight,waterlogged:false}",
        "minecraft:deepslate_tile_wall{east:none,north:low,south:none,up:true,waterlogged:false,west:none}",
        "minecraft:deepslate_tile_wall{east:none,north:low,south:low,up:false,waterlogged:false,west:none}",
        "minecraft:deepslate_tile_wall{east:low,north:none,south:none,up:false,waterlogged:false,west:low}",
        "minecraft:deepslate_tile_wall{east:none,north:none,south:none,up:true,waterlogged:false,west:low}",
        "minecraft:deepslate_tile_stairs{facing:east,half:bottom,shape:outer_left,waterlogged:false}",
        "minecraft:deepslate_tile_slab{type:bottom,waterlogged:false}",
        "minecraft:jigsaw{orientation:north_up}"
    ]
}
