{
    size: [10, 10, 10],
    data: [
        {pos: [1, 0, 6], state: "minecraft:podzol{snowy:false}"},
        {pos: [1, 0, 7], state: "minecraft:podzol{snowy:false}"},
        {pos: [2, 0, 6], state: "minecraft:podzol{snowy:false}"},
        {pos: [2, 0, 7], state: "minecraft:jigsaw{orientation:up_north}", nbt: {components: {}, final_state: "minecraft:dirt", id: "minecraft:jigsaw", joint: "rollable", name: "minecraft:bottom", placement_priority: 0, pool: "minecraft:abandoned_camp/trees/thick_spruce", selection_priority: 0, target: "minecraft:bottom"}},
        {pos: [3, 0, 3], state: "minecraft:oxidized_copper_chest{facing:north,type:single,waterlogged:false}", nbt: {Items: [], LootTable: "minecraft:chests/abandoned_camp_secret_chest", components: {}, id: "minecraft:chest"}},
        {pos: [4, 0, 4], state: "minecraft:dirt"},
        {pos: [4, 0, 5], state: "minecraft:dirt_path"},
        {pos: [4, 0, 7], state: "minecraft:mossy_cobblestone"},
        {pos: [5, 0, 3], state: "minecraft:dirt_path"},
        {pos: [5, 0, 4], state: "minecraft:dirt_path"},
        {pos: [5, 0, 5], state: "minecraft:dirt_path"},
        {pos: [5, 0, 6], state: "minecraft:mossy_cobblestone"},
        {pos: [5, 0, 7], state: "minecraft:mossy_cobblestone"},
        {pos: [5, 0, 8], state: "minecraft:mossy_cobblestone"},
        {pos: [6, 0, 0], state: "minecraft:mossy_cobblestone"},
        {pos: [6, 0, 1], state: "minecraft:mossy_cobblestone"},
        {pos: [6, 0, 2], state: "minecraft:mossy_cobblestone"},
        {pos: [6, 0, 3], state: "minecraft:dirt_path"},
        {pos: [6, 0, 4], state: "minecraft:dirt"},
        {pos: [6, 0, 5], state: "minecraft:dirt_path"},
        {pos: [6, 0, 7], state: "minecraft:mossy_cobblestone"},
        {pos: [7, 0, 0], state: "minecraft:mossy_cobblestone"},
        {pos: [7, 0, 1], state: "minecraft:mossy_cobblestone"},
        {pos: [7, 0, 2], state: "minecraft:mossy_cobblestone"},
        {pos: [7, 0, 3], state: "minecraft:dirt_path"},
        {pos: [7, 0, 4], state: "minecraft:dirt_path"},
        {pos: [7, 0, 5], state: "minecraft:dirt_path"},
        {pos: [8, 0, 0], state: "minecraft:mossy_cobblestone"},
        {pos: [8, 0, 1], state: "minecraft:mossy_cobblestone"},
        {pos: [8, 0, 2], state: "minecraft:mossy_cobblestone"},
        {pos: [8, 0, 4], state: "minecraft:dirt_path"},
        {pos: [8, 0, 5], state: "minecraft:dirt_path"},
        {pos: [9, 0, 4], state: "minecraft:jigsaw{orientation:east_up}", nbt: {components: {}, final_state: "minecraft:dirt_path", id: "minecraft:jigsaw", joint: "rollable", name: "minecraft:end_connector", placement_priority: 0, pool: "minecraft:empty", selection_priority: 0, target: "minecraft:connector"}},
        {pos: [9, 0, 5], state: "minecraft:dirt_path"},
        {pos: [2, 1, 3], state: "minecraft:mossy_cobblestone"},
        {pos: [3, 1, 2], state: "minecraft:mossy_cobblestone"},
        {pos: [3, 1, 3], state: "minecraft:mossy_cobblestone"},
        {pos: [3, 1, 4], state: "minecraft:mossy_cobblestone"},
        {pos: [4, 1, 3], state: "minecraft:mossy_cobblestone"},
        {pos: [4, 1, 4], state: "minecraft:barrel{facing:east,open:false}", nbt: {Items: [], LootTable: "minecraft:barrels/abandoned_camp_barrel", components: {}, id: "minecraft:barrel"}},
        {pos: [4, 1, 6], state: "minecraft:mossy_cobblestone"},
        {pos: [4, 1, 7], state: "minecraft:mossy_cobblestone"},
        {pos: [4, 1, 8], state: "minecraft:mossy_cobblestone"},
        {pos: [5, 1, 6], state: "minecraft:mossy_cobblestone"},
        {pos: [5, 1, 7], state: "minecraft:mossy_cobblestone"},
        {pos: [5, 1, 8], state: "minecraft:mossy_cobblestone"},
        {pos: [6, 1, 1], state: "minecraft:mossy_cobblestone"},
        {pos: [6, 1, 4], state: "minecraft:campfire{facing:west,lit:false,signal_fire:false,waterlogged:false}", nbt: {CookingTimes: [I; 0, 0, 0, 0], CookingTotalTimes: [I; 0, 0, 0, 0], Items: [], components: {}, id: "minecraft:campfire"}},
        {pos: [6, 1, 6], state: "minecraft:mossy_cobblestone"},
        {pos: [6, 1, 7], state: "minecraft:mossy_cobblestone"},
        {pos: [6, 1, 8], state: "minecraft:mossy_cobblestone"},
        {pos: [7, 1, 0], state: "minecraft:mossy_cobblestone"},
        {pos: [7, 1, 1], state: "minecraft:mossy_cobblestone"},
        {pos: [7, 1, 2], state: "minecraft:mossy_cobblestone"},
        {pos: [8, 1, 1], state: "minecraft:mossy_cobblestone"},
        {pos: [2, 2, 2], state: "minecraft:mossy_cobblestone"},
        {pos: [2, 2, 3], state: "minecraft:mossy_cobblestone"},
        {pos: [2, 2, 4], state: "minecraft:mossy_cobblestone"},
        {pos: [3, 2, 2], state: "minecraft:mossy_cobblestone"},
        {pos: [3, 2, 3], state: "minecraft:mossy_cobblestone"},
        {pos: [3, 2, 4], state: "minecraft:mossy_cobblestone"},
        {pos: [4, 2, 2], state: "minecraft:mossy_cobblestone"},
        {pos: [4, 2, 3], state: "minecraft:mossy_cobblestone"},
        {pos: [4, 2, 4], state: "minecraft:mossy_cobblestone"},
        {pos: [4, 2, 7], state: "minecraft:mossy_cobblestone"},
        {pos: [5, 2, 6], state: "minecraft:mossy_cobblestone"},
        {pos: [5, 2, 7], state: "minecraft:mossy_cobblestone"},
        {pos: [5, 2, 8], state: "minecraft:mossy_cobblestone"},
        {pos: [6, 2, 7], state: "minecraft:mossy_cobblestone"},
        {pos: [2, 3, 3], state: "minecraft:mossy_cobblestone"},
        {pos: [3, 3, 2], state: "minecraft:mossy_cobblestone"},
        {pos: [3, 3, 3], state: "minecraft:mossy_cobblestone"},
        {pos: [3, 3, 4], state: "minecraft:mossy_cobblestone"},
        {pos: [4, 3, 3], state: "minecraft:mossy_cobblestone"}
    ],
    entities: [
        {blockPos: [5, 0, 5], pos: [5.5d, 0.9375d, 5.5d], nbt: {Air: 300s, Fire: 0s, Invulnerable: 0b, Motion: [0.0d, 0.0d, 0.0d], OnGround: 0b, PortalCooldown: 0, Pos: [-105.5d, -60.0625d, 272.5d], Rotation: [0.0f, 0.0f], UUID: [I; 856008082, 794774454, -1219681363, -803614846], block_pos: [I; -106, -61, 272], color: "brown", fall_distance: 0.0d, id: "minecraft:cushion"}},
        {blockPos: [6, 0, 3], pos: [6.5d, 0.9375d, 3.5d], nbt: {Air: 300s, Fire: 0s, Invulnerable: 0b, Motion: [0.0d, 0.0d, 0.0d], OnGround: 0b, PortalCooldown: 0, Pos: [-104.5d, -60.0625d, 270.5d], Rotation: [90.0f, 0.0f], UUID: [I; -1407646115, 1454721428, -1876823568, 164735619], block_pos: [I; -105, -61, 270], color: "brown", fall_distance: 0.0d, id: "minecraft:cushion"}}
    ],
    palette: [
        "minecraft:podzol{snowy:false}",
        "minecraft:dirt",
        "minecraft:mossy_cobblestone",
        "minecraft:dirt_path",
        "minecraft:jigsaw{orientation:up_north}",
        "minecraft:oxidized_copper_chest{facing:north,type:single,waterlogged:false}",
        "minecraft:jigsaw{orientation:east_up}",
        "minecraft:barrel{facing:east,open:false}",
        "minecraft:campfire{facing:west,lit:false,signal_fire:false,waterlogged:false}"
    ]
}
