{
    size: [5, 5, 5],
    data: [
        {pos: [0, 0, 0], state: "minecraft:sand"},
        {pos: [0, 0, 1], state: "minecraft:sand"},
        {pos: [0, 0, 2], state: "minecraft:sand"},
        {pos: [0, 0, 3], state: "minecraft:sand"},
        {pos: [0, 0, 4], state: "minecraft:sand"},
        {pos: [1, 0, 0], state: "minecraft:sand"},
        {pos: [1, 0, 1], state: "minecraft:smooth_sandstone"},
        {pos: [1, 0, 2], state: "minecraft:smooth_sandstone"},
        {pos: [1, 0, 3], state: "minecraft:smooth_sandstone"},
        {pos: [1, 0, 4], state: "minecraft:sand"},
        {pos: [2, 0, 0], state: "minecraft:smooth_sandstone"},
        {pos: [2, 0, 1], state: "minecraft:smooth_sandstone"},
        {pos: [2, 0, 2], state: "minecraft:jigsaw{orientation:up_north}", nbt: {final_state: "minecraft:smooth_sandstone", id: "minecraft:jigsaw", joint: "rollable", name: "minecraft:bottom", pool: "minecraft:village/desert/zombie/villagers", target: "minecraft:bottom"}},
        {pos: [2, 0, 3], state: "minecraft:smooth_sandstone"},
        {pos: [2, 0, 4], state: "minecraft:sand"},
        {pos: [3, 0, 0], state: "minecraft:sand"},
        {pos: [3, 0, 1], state: "minecraft:smooth_sandstone"},
        {pos: [3, 0, 2], state: "minecraft:smooth_sandstone"},
        {pos: [3, 0, 3], state: "minecraft:smooth_sandstone"},
        {pos: [3, 0, 4], state: "minecraft:sand"},
        {pos: [4, 0, 0], state: "minecraft:sand"},
        {pos: [4, 0, 1], state: "minecraft:sand"},
        {pos: [4, 0, 2], state: "minecraft:sand"},
        {pos: [4, 0, 3], state: "minecraft:sand"},
        {pos: [4, 0, 4], state: "minecraft:sand"},
        {pos: [0, 1, 0], state: "minecraft:terracotta"},
        {pos: [0, 1, 1], state: "minecraft:smooth_sandstone"},
        {pos: [0, 1, 2], state: "minecraft:smooth_sandstone"},
        {pos: [0, 1, 3], state: "minecraft:smooth_sandstone"},
        {pos: [0, 1, 4], state: "minecraft:terracotta"},
        {pos: [1, 1, 0], state: "minecraft:jigsaw{orientation:north_up}", nbt: {final_state: "minecraft:smooth_sandstone", id: "minecraft:jigsaw", joint: "aligned", name: "minecraft:building_entrance", pool: "minecraft:empty", target: "minecraft:building_entrance"}},
        {pos: [1, 1, 1], state: "minecraft:sandstone_stairs{facing:north,half:bottom,shape:straight,waterlogged:false}"},
        {pos: [1, 1, 2], state: "minecraft:terracotta"},
        {pos: [1, 1, 3], state: "minecraft:sandstone_stairs{facing:south,half:bottom,shape:straight,waterlogged:false}"},
        {pos: [1, 1, 4], state: "minecraft:smooth_sandstone"},
        {pos: [2, 1, 0], state: "minecraft:jungle_door{facing:north,half:lower,hinge:right,open:false,powered:false}"},
        {pos: [2, 1, 1], state: "minecraft:air"},
        {pos: [2, 1, 2], state: "minecraft:air"},
        {pos: [2, 1, 3], state: "minecraft:air"},
        {pos: [2, 1, 4], state: "minecraft:smooth_sandstone"},
        {pos: [3, 1, 0], state: "minecraft:smooth_sandstone"},
        {pos: [3, 1, 1], state: "minecraft:lime_bed{facing:north,occupied:false,part:head}", nbt: {id: "minecraft:bed"}},
        {pos: [3, 1, 2], state: "minecraft:lime_bed{facing:north,occupied:false,part:foot}", nbt: {id: "minecraft:bed"}},
        {pos: [3, 1, 3], state: "minecraft:crafting_table"},
        {pos: [3, 1, 4], state: "minecraft:smooth_sandstone"},
        {pos: [4, 1, 0], state: "minecraft:terracotta"},
        {pos: [4, 1, 1], state: "minecraft:smooth_sandstone"},
        {pos: [4, 1, 2], state: "minecraft:smooth_sandstone"},
        {pos: [4, 1, 3], state: "minecraft:smooth_sandstone"},
        {pos: [4, 1, 4], state: "minecraft:terracotta"},
        {pos: [0, 2, 0], state: "minecraft:terracotta"},
        {pos: [0, 2, 1], state: "minecraft:smooth_sandstone"},
        {pos: [0, 2, 2], state: "minecraft:smooth_sandstone"},
        {pos: [0, 2, 3], state: "minecraft:smooth_sandstone"},
        {pos: [0, 2, 4], state: "minecraft:terracotta"},
        {pos: [1, 2, 0], state: "minecraft:smooth_sandstone"},
        {pos: [1, 2, 1], state: "minecraft:air"},
        {pos: [1, 2, 2], state: "minecraft:sea_pickle{pickles:2,waterlogged:false}"},
        {pos: [1, 2, 3], state: "minecraft:air"},
        {pos: [1, 2, 4], state: "minecraft:smooth_sandstone"},
        {pos: [2, 2, 0], state: "minecraft:jungle_door{facing:north,half:upper,hinge:right,open:false,powered:false}"},
        {pos: [2, 2, 1], state: "minecraft:air"},
        {pos: [2, 2, 2], state: "minecraft:air"},
        {pos: [2, 2, 3], state: "minecraft:air"},
        {pos: [2, 2, 4], state: "minecraft:smooth_sandstone_slab{type:double,waterlogged:false}"},
        {pos: [3, 2, 0], state: "minecraft:smooth_sandstone"},
        {pos: [3, 2, 1], state: "minecraft:air"},
        {pos: [3, 2, 2], state: "minecraft:air"},
        {pos: [3, 2, 3], state: "minecraft:air"},
        {pos: [3, 2, 4], state: "minecraft:smooth_sandstone"},
        {pos: [4, 2, 0], state: "minecraft:terracotta"},
        {pos: [4, 2, 1], state: "minecraft:smooth_sandstone"},
        {pos: [4, 2, 2], state: "minecraft:smooth_sandstone_slab{type:double,waterlogged:false}"},
        {pos: [4, 2, 3], state: "minecraft:smooth_sandstone"},
        {pos: [4, 2, 4], state: "minecraft:terracotta"},
        {pos: [0, 3, 0], state: "minecraft:terracotta"},
        {pos: [0, 3, 1], state: "minecraft:smooth_sandstone"},
        {pos: [0, 3, 2], state: "minecraft:smooth_sandstone_slab{type:top,waterlogged:false}"},
        {pos: [0, 3, 3], state: "minecraft:smooth_sandstone"},
        {pos: [0, 3, 4], state: "minecraft:terracotta"},
        {pos: [1, 3, 0], state: "minecraft:smooth_sandstone"},
        {pos: [1, 3, 1], state: "minecraft:air"},
        {pos: [1, 3, 2], state: "minecraft:air"},
        {pos: [1, 3, 3], state: "minecraft:air"},
        {pos: [1, 3, 4], state: "minecraft:smooth_sandstone"},
        {pos: [2, 3, 0], state: "minecraft:smooth_sandstone"},
        {pos: [2, 3, 1], state: "minecraft:wall_torch{facing:south}"},
        {pos: [2, 3, 2], state: "minecraft:air"},
        {pos: [2, 3, 3], state: "minecraft:air"},
        {pos: [2, 3, 4], state: "minecraft:smooth_sandstone_slab{type:top,waterlogged:false}"},
        {pos: [3, 3, 0], state: "minecraft:smooth_sandstone"},
        {pos: [3, 3, 1], state: "minecraft:air"},
        {pos: [3, 3, 2], state: "minecraft:air"},
        {pos: [3, 3, 3], state: "minecraft:air"},
        {pos: [3, 3, 4], state: "minecraft:smooth_sandstone"},
        {pos: [4, 3, 0], state: "minecraft:terracotta"},
        {pos: [4, 3, 1], state: "minecraft:smooth_sandstone"},
        {pos: [4, 3, 2], state: "minecraft:smooth_sandstone_slab{type:top,waterlogged:false}"},
        {pos: [4, 3, 3], state: "minecraft:smooth_sandstone"},
        {pos: [4, 3, 4], state: "minecraft:terracotta"},
        {pos: [0, 4, 0], state: "minecraft:terracotta"},
        {pos: [0, 4, 1], state: "minecraft:sandstone_slab{type:bottom,waterlogged:false}"},
        {pos: [0, 4, 2], state: "minecraft:sandstone_slab{type:bottom,waterlogged:false}"},
        {pos: [0, 4, 3], state: "minecraft:sandstone_slab{type:bottom,waterlogged:false}"},
        {pos: [0, 4, 4], state: "minecraft:terracotta"},
        {pos: [1, 4, 0], state: "minecraft:sandstone_slab{type:bottom,waterlogged:false}"},
        {pos: [1, 4, 1], state: "minecraft:smooth_sandstone_slab{type:bottom,waterlogged:false}"},
        {pos: [1, 4, 2], state: "minecraft:smooth_sandstone_slab{type:bottom,waterlogged:false}"},
        {pos: [1, 4, 3], state: "minecraft:smooth_sandstone_slab{type:bottom,waterlogged:false}"},
        {pos: [1, 4, 4], state: "minecraft:sandstone_slab{type:bottom,waterlogged:false}"},
        {pos: [2, 4, 0], state: "minecraft:sandstone_slab{type:bottom,waterlogged:false}"},
        {pos: [2, 4, 1], state: "minecraft:smooth_sandstone_slab{type:bottom,waterlogged:false}"},
        {pos: [2, 4, 2], state: "minecraft:smooth_sandstone_slab{type:bottom,waterlogged:false}"},
        {pos: [2, 4, 3], state: "minecraft:smooth_sandstone_slab{type:bottom,waterlogged:false}"},
        {pos: [2, 4, 4], state: "minecraft:sandstone_slab{type:bottom,waterlogged:false}"},
        {pos: [3, 4, 0], state: "minecraft:sandstone_slab{type:bottom,waterlogged:false}"},
        {pos: [3, 4, 1], state: "minecraft:smooth_sandstone_slab{type:bottom,waterlogged:false}"},
        {pos: [3, 4, 2], state: "minecraft:smooth_sandstone_slab{type:bottom,waterlogged:false}"},
        {pos: [3, 4, 3], state: "minecraft:smooth_sandstone_slab{type:bottom,waterlogged:false}"},
        {pos: [3, 4, 4], state: "minecraft:sandstone_slab{type:bottom,waterlogged:false}"},
        {pos: [4, 4, 0], state: "minecraft:terracotta"},
        {pos: [4, 4, 1], state: "minecraft:sandstone_slab{type:bottom,waterlogged:false}"},
        {pos: [4, 4, 2], state: "minecraft:sandstone_slab{type:bottom,waterlogged:false}"},
        {pos: [4, 4, 3], state: "minecraft:sandstone_slab{type:bottom,waterlogged:false}"},
        {pos: [4, 4, 4], state: "minecraft:terracotta"}
    ],
    entities: [],
    palette: [
        "minecraft:sand",
        "minecraft:smooth_sandstone",
        "minecraft:terracotta",
        "minecraft:crafting_table",
        "minecraft:smooth_sandstone_slab{type:double,waterlogged:false}",
        "minecraft:sandstone_stairs{facing:north,half:bottom,shape:straight,waterlogged:false}",
        "minecraft:sandstone_stairs{facing:south,half:bottom,shape:straight,waterlogged:false}",
        "minecraft:jungle_door{facing:north,half:lower,hinge:right,open:false,powered:false}",
        "minecraft:air",
        "minecraft:sea_pickle{pickles:2,waterlogged:false}",
        "minecraft:jungle_door{facing:north,half:upper,hinge:right,open:false,powered:false}",
        "minecraft:smooth_sandstone_slab{type:top,waterlogged:false}",
        "minecraft:wall_torch{facing:south}",
        "minecraft:sandstone_slab{type:bottom,waterlogged:false}",
        "minecraft:smooth_sandstone_slab{type:bottom,waterlogged:false}",
        "minecraft:jigsaw{orientation:up_north}",
        "minecraft:jigsaw{orientation:north_up}",
        "minecraft:lime_bed{facing:north,occupied:false,part:head}",
        "minecraft:lime_bed{facing:north,occupied:false,part:foot}"
    ]
}
