{
    size: [10, 10, 10],
    data: [
        {pos: [1, 0, 2], state: "minecraft:dirt"},
        {pos: [1, 0, 3], state: "minecraft:dirt"},
        {pos: [1, 0, 4], state: "minecraft:dirt"},
        {pos: [1, 0, 5], state: "minecraft:dirt"},
        {pos: [2, 0, 2], state: "minecraft:dirt"},
        {pos: [2, 0, 3], state: "minecraft:dirt"},
        {pos: [2, 0, 4], state: "minecraft:dirt"},
        {pos: [2, 0, 5], state: "minecraft:dirt"},
        {pos: [2, 0, 6], state: "minecraft:dirt"},
        {pos: [2, 0, 7], state: "minecraft:dirt"},
        {pos: [3, 0, 2], state: "minecraft:dirt"},
        {pos: [3, 0, 3], state: "minecraft:dirt"},
        {pos: [3, 0, 4], state: "minecraft:dirt"},
        {pos: [3, 0, 5], state: "minecraft:dirt"},
        {pos: [3, 0, 6], state: "minecraft:dirt"},
        {pos: [3, 0, 7], state: "minecraft:dirt"},
        {pos: [3, 0, 8], state: "minecraft:dirt"},
        {pos: [4, 0, 2], state: "minecraft:dirt"},
        {pos: [4, 0, 3], state: "minecraft:dirt"},
        {pos: [4, 0, 4], state: "minecraft:dirt"},
        {pos: [4, 0, 5], state: "minecraft:dirt"},
        {pos: [4, 0, 6], state: "minecraft:dirt"},
        {pos: [4, 0, 7], state: "minecraft:dirt"},
        {pos: [5, 0, 2], state: "minecraft:dirt"},
        {pos: [5, 0, 3], state: "minecraft:dirt"},
        {pos: [5, 0, 4], state: "minecraft:dirt"},
        {pos: [5, 0, 5], state: "minecraft:dirt"},
        {pos: [5, 0, 6], state: "minecraft:dirt"},
        {pos: [5, 0, 7], state: "minecraft:dirt"},
        {pos: [5, 0, 8], state: "minecraft:dirt"},
        {pos: [6, 0, 2], state: "minecraft:dirt"},
        {pos: [6, 0, 3], state: "minecraft:dirt"},
        {pos: [6, 0, 4], state: "minecraft:dirt"},
        {pos: [6, 0, 5], state: "minecraft:dirt"},
        {pos: [6, 0, 6], state: "minecraft:dirt"},
        {pos: [6, 0, 7], state: "minecraft:dirt"},
        {pos: [6, 0, 8], state: "minecraft:dirt"},
        {pos: [7, 0, 3], state: "minecraft:dirt_path"},
        {pos: [7, 0, 4], state: "minecraft:dirt_path"},
        {pos: [7, 0, 5], state: "minecraft:dirt"},
        {pos: [7, 0, 6], state: "minecraft:dirt"},
        {pos: [7, 0, 7], state: "minecraft:dirt"},
        {pos: [7, 0, 8], state: "minecraft:dirt"},
        {pos: [8, 0, 3], state: "minecraft:dirt_path"},
        {pos: [8, 0, 4], state: "minecraft:dirt_path"},
        {pos: [9, 0, 4], state: "minecraft:jigsaw{orientation:east_up}", nbt: {components: {}, final_state: "minecraft:dirt_path", id: "minecraft:jigsaw", joint: "rollable", name: "minecraft:end_connector", placement_priority: 0, pool: "minecraft:empty", selection_priority: 0, target: "minecraft:connector"}},
        {pos: [1, 1, 2], state: "minecraft:grass_block{snowy:false}"},
        {pos: [1, 1, 3], state: "minecraft:stone"},
        {pos: [1, 1, 4], state: "minecraft:stone"},
        {pos: [1, 1, 5], state: "minecraft:stone"},
        {pos: [2, 1, 2], state: "minecraft:dirt"},
        {pos: [2, 1, 3], state: "minecraft:stone"},
        {pos: [2, 1, 4], state: "minecraft:stone"},
        {pos: [2, 1, 5], state: "minecraft:stone"},
        {pos: [2, 1, 6], state: "minecraft:dirt"},
        {pos: [2, 1, 7], state: "minecraft:grass_block{snowy:false}"},
        {pos: [3, 1, 2], state: "minecraft:stone"},
        {pos: [3, 1, 3], state: "minecraft:stone"},
        {pos: [3, 1, 4], state: "minecraft:dirt"},
        {pos: [3, 1, 5], state: "minecraft:stone"},
        {pos: [3, 1, 6], state: "minecraft:stone"},
        {pos: [3, 1, 7], state: "minecraft:stone"},
        {pos: [3, 1, 8], state: "minecraft:grass_block{snowy:false}"},
        {pos: [4, 1, 2], state: "minecraft:stone"},
        {pos: [4, 1, 3], state: "minecraft:stone"},
        {pos: [4, 1, 4], state: "minecraft:stone"},
        {pos: [4, 1, 5], state: "minecraft:stone"},
        {pos: [4, 1, 6], state: "minecraft:stone"},
        {pos: [4, 1, 7], state: "minecraft:stone"},
        {pos: [5, 1, 2], state: "minecraft:grass_block{snowy:false}"},
        {pos: [5, 1, 3], state: "minecraft:stone"},
        {pos: [5, 1, 4], state: "minecraft:stone"},
        {pos: [5, 1, 5], state: "minecraft:stone"},
        {pos: [5, 1, 6], state: "minecraft:stone"},
        {pos: [5, 1, 7], state: "minecraft:stone"},
        {pos: [5, 1, 8], state: "minecraft:grass_block{snowy:false}"},
        {pos: [6, 1, 2], state: "minecraft:grass_block{snowy:false}"},
        {pos: [6, 1, 3], state: "minecraft:grass_block{snowy:false}"},
        {pos: [6, 1, 4], state: "minecraft:stone"},
        {pos: [6, 1, 5], state: "minecraft:stone"},
        {pos: [6, 1, 6], state: "minecraft:stone"},
        {pos: [6, 1, 7], state: "minecraft:stone"},
        {pos: [6, 1, 8], state: "minecraft:stone"},
        {pos: [7, 1, 5], state: "minecraft:oak_stairs{facing:south,half:bottom,shape:straight,waterlogged:false}"},
        {pos: [7, 1, 6], state: "minecraft:dirt_path"},
        {pos: [7, 1, 7], state: "minecraft:dirt_path"},
        {pos: [7, 1, 8], state: "minecraft:grass_block{snowy:false}"},
        {pos: [1, 2, 3], state: "minecraft:grass_block{snowy:false}"},
        {pos: [1, 2, 4], state: "minecraft:grass_block{snowy:false}"},
        {pos: [2, 2, 2], state: "minecraft:grass_block{snowy:false}"},
        {pos: [2, 2, 3], state: "minecraft:jigsaw{orientation:up_west}", nbt: {components: {}, final_state: "minecraft:dirt", id: "minecraft:jigsaw", joint: "rollable", name: "minecraft:bottom", placement_priority: 0, pool: "minecraft:abandoned_camp/trees/birch_bees", selection_priority: 0, target: "minecraft:bottom"}},
        {pos: [2, 2, 4], state: "minecraft:grass_block{snowy:false}"},
        {pos: [2, 2, 5], state: "minecraft:grass_block{snowy:false}"},
        {pos: [2, 2, 6], state: "minecraft:grass_block{snowy:false}"},
        {pos: [2, 2, 7], state: "minecraft:wildflowers{facing:south,flower_amount:3}"},
        {pos: [3, 2, 3], state: "minecraft:grass_block{snowy:false}"},
        {pos: [3, 2, 4], state: "minecraft:dirt_path"},
        {pos: [3, 2, 5], state: "minecraft:dirt_path"},
        {pos: [3, 2, 6], state: "minecraft:oxidized_copper_chest{facing:north,type:single,waterlogged:false}", nbt: {Items: [], LootTable: "minecraft:chests/abandoned_camp_secret_chest", components: {}, id: "minecraft:chest"}},
        {pos: [3, 2, 7], state: "minecraft:grass_block{snowy:false}"},
        {pos: [3, 2, 8], state: "minecraft:dandelion"},
        {pos: [4, 2, 3], state: "minecraft:grass_block{snowy:false}"},
        {pos: [4, 2, 4], state: "minecraft:dirt_path"},
        {pos: [4, 2, 5], state: "minecraft:dirt"},
        {pos: [4, 2, 6], state: "minecraft:dirt_path"},
        {pos: [4, 2, 7], state: "minecraft:grass_block{snowy:false}"},
        {pos: [5, 2, 2], state: "minecraft:wildflowers{facing:north,flower_amount:4}"},
        {pos: [5, 2, 3], state: "minecraft:grass_block{snowy:false}"},
        {pos: [5, 2, 4], state: "minecraft:dirt_path"},
        {pos: [5, 2, 5], state: "minecraft:dirt_path"},
        {pos: [5, 2, 6], state: "minecraft:dirt_path"},
        {pos: [5, 2, 7], state: "minecraft:dirt_path"},
        {pos: [5, 2, 8], state: "minecraft:wildflowers{facing:east,flower_amount:3}"},
        {pos: [6, 2, 2], state: "minecraft:wildflowers{facing:north,flower_amount:1}"},
        {pos: [6, 2, 3], state: "minecraft:poppy"},
        {pos: [6, 2, 4], state: "minecraft:grass_block{snowy:false}"},
        {pos: [6, 2, 5], state: "minecraft:grass_block{snowy:false}"},
        {pos: [6, 2, 6], state: "minecraft:grass_block{snowy:false}"},
        {pos: [6, 2, 7], state: "minecraft:oak_stairs{facing:west,half:bottom,shape:straight,waterlogged:false}"},
        {pos: [7, 2, 8], state: "minecraft:wildflowers{facing:east,flower_amount:3}"},
        {pos: [1, 3, 3], state: "minecraft:wildflowers{facing:south,flower_amount:4}"},
        {pos: [1, 3, 4], state: "minecraft:wildflowers{facing:south,flower_amount:3}"},
        {pos: [2, 3, 2], state: "minecraft:wildflowers{facing:south,flower_amount:3}"},
        {pos: [2, 3, 4], state: "minecraft:dandelion"},
        {pos: [2, 3, 5], state: "minecraft:wildflowers{facing:south,flower_amount:2}"},
        {pos: [3, 3, 6], state: "minecraft:barrel{facing:east,open:false}", nbt: {Items: [], LootTable: "minecraft:barrels/abandoned_camp_barrel", components: {}, id: "minecraft:barrel"}},
        {pos: [3, 3, 7], state: "minecraft:wildflowers{facing:west,flower_amount:2}"},
        {pos: [4, 3, 3], state: "minecraft:wildflowers{facing:west,flower_amount:4}"},
        {pos: [4, 3, 5], state: "minecraft:campfire{facing:west,lit:false,signal_fire:false,waterlogged:false}", nbt: {CookingTimes: [I; 0, 0, 0, 0], CookingTotalTimes: [I; 0, 0, 0, 0], Items: [], components: {}, id: "minecraft:campfire"}},
        {pos: [6, 3, 5], state: "minecraft:poppy"}
    ],
    entities: [
        {blockPos: [3, 2, 4], pos: [3.5d, 2.9375d, 4.5d], nbt: {Air: 300s, Fire: 0s, Invulnerable: 0b, Motion: [0.0d, 0.0d, 0.0d], OnGround: 0b, PortalCooldown: 0, Pos: [-107.5d, -58.0625d, -43.5d], Rotation: [90.0f, 0.0f], UUID: [I; -1242408236, 1047940829, -1396311312, -1764504774], block_pos: [I; -108, -59, -44], color: "red", fall_distance: 0.0d, id: "minecraft:cushion"}},
        {blockPos: [5, 2, 4], pos: [5.5d, 2.9375d, 4.5d], nbt: {Air: 300s, Fire: 0s, Invulnerable: 0b, Motion: [0.0d, 0.0d, 0.0d], OnGround: 0b, PortalCooldown: 0, Pos: [-105.5d, -58.0625d, -43.5d], Rotation: [180.0f, 0.0f], UUID: [I; 1113026416, -1930934017, -2027335839, -199362108], block_pos: [I; -106, -59, -44], color: "red", fall_distance: 0.0d, id: "minecraft:cushion"}}
    ],
    palette: [
        "minecraft:dirt",
        "minecraft:grass_block{snowy:false}",
        "minecraft:stone",
        "minecraft:dirt_path",
        "minecraft:oak_stairs{facing:south,half:bottom,shape:straight,waterlogged:false}",
        "minecraft:wildflowers{facing:south,flower_amount:3}",
        "minecraft:dandelion",
        "minecraft:wildflowers{facing:north,flower_amount:4}",
        "minecraft:wildflowers{facing:east,flower_amount:3}",
        "minecraft:wildflowers{facing:north,flower_amount:1}",
        "minecraft:poppy",
        "minecraft:oak_stairs{facing:west,half:bottom,shape:straight,waterlogged:false}",
        "minecraft:wildflowers{facing:south,flower_amount:4}",
        "minecraft:wildflowers{facing:south,flower_amount:2}",
        "minecraft:wildflowers{facing:west,flower_amount:2}",
        "minecraft:wildflowers{facing:west,flower_amount:4}",
        "minecraft:jigsaw{orientation:east_up}",
        "minecraft:jigsaw{orientation:up_west}",
        "minecraft:oxidized_copper_chest{facing:north,type:single,waterlogged:false}",
        "minecraft:barrel{facing:east,open:false}",
        "minecraft:campfire{facing:west,lit:false,signal_fire:false,waterlogged:false}"
    ]
}
