{
    size: [9, 7, 10],
    data: [
        {pos: [0, 0, 0], state: "minecraft:bricks"},
        {pos: [0, 0, 1], state: "minecraft:bricks"},
        {pos: [0, 0, 2], state: "minecraft:bricks"},
        {pos: [0, 0, 3], state: "minecraft:bricks"},
        {pos: [0, 0, 4], state: "minecraft:bricks"},
        {pos: [0, 0, 5], state: "minecraft:bricks"},
        {pos: [0, 0, 6], state: "minecraft:bricks"},
        {pos: [0, 0, 7], state: "minecraft:bricks"},
        {pos: [0, 0, 8], state: "minecraft:bricks"},
        {pos: [0, 0, 9], state: "minecraft:bricks"},
        {pos: [1, 0, 0], state: "minecraft:bricks"},
        {pos: [1, 0, 1], state: "minecraft:bricks"},
        {pos: [1, 0, 2], state: "minecraft:bricks"},
        {pos: [1, 0, 3], state: "minecraft:bricks"},
        {pos: [1, 0, 4], state: "minecraft:bricks"},
        {pos: [1, 0, 5], state: "minecraft:bricks"},
        {pos: [1, 0, 6], state: "minecraft:bricks"},
        {pos: [1, 0, 7], state: "minecraft:bricks"},
        {pos: [1, 0, 8], state: "minecraft:bricks"},
        {pos: [1, 0, 9], state: "minecraft:bricks"},
        {pos: [2, 0, 0], state: "minecraft:bricks"},
        {pos: [2, 0, 1], state: "minecraft:bricks"},
        {pos: [2, 0, 2], state: "minecraft:bricks"},
        {pos: [2, 0, 3], state: "minecraft:bricks"},
        {pos: [2, 0, 4], state: "minecraft:bricks"},
        {pos: [2, 0, 5], state: "minecraft:bricks"},
        {pos: [2, 0, 6], state: "minecraft:bricks"},
        {pos: [2, 0, 7], state: "minecraft:bricks"},
        {pos: [2, 0, 8], state: "minecraft:bricks"},
        {pos: [2, 0, 9], state: "minecraft:bricks"},
        {pos: [3, 0, 0], state: "minecraft:bricks"},
        {pos: [3, 0, 1], state: "minecraft:bricks"},
        {pos: [3, 0, 2], state: "minecraft:bricks"},
        {pos: [3, 0, 3], state: "minecraft:bricks"},
        {pos: [3, 0, 4], state: "minecraft:bricks"},
        {pos: [3, 0, 5], state: "minecraft:bricks"},
        {pos: [3, 0, 6], state: "minecraft:bricks"},
        {pos: [3, 0, 7], state: "minecraft:bricks"},
        {pos: [3, 0, 8], state: "minecraft:bricks"},
        {pos: [3, 0, 9], state: "minecraft:bricks"},
        {pos: [4, 0, 0], state: "minecraft:bricks"},
        {pos: [4, 0, 1], state: "minecraft:bricks"},
        {pos: [4, 0, 2], state: "minecraft:bricks"},
        {pos: [4, 0, 3], state: "minecraft:bricks"},
        {pos: [4, 0, 4], state: "minecraft:bricks"},
        {pos: [4, 0, 5], state: "minecraft:bricks"},
        {pos: [4, 0, 6], state: "minecraft:bricks"},
        {pos: [4, 0, 7], state: "minecraft:bricks"},
        {pos: [4, 0, 8], state: "minecraft:bricks"},
        {pos: [4, 0, 9], state: "minecraft:bricks"},
        {pos: [5, 0, 0], state: "minecraft:bricks"},
        {pos: [5, 0, 1], state: "minecraft:bricks"},
        {pos: [5, 0, 2], state: "minecraft:bricks"},
        {pos: [5, 0, 3], state: "minecraft:bricks"},
        {pos: [5, 0, 4], state: "minecraft:bricks"},
        {pos: [5, 0, 5], state: "minecraft:bricks"},
        {pos: [5, 0, 6], state: "minecraft:bricks"},
        {pos: [5, 0, 7], state: "minecraft:bricks"},
        {pos: [5, 0, 8], state: "minecraft:bricks"},
        {pos: [5, 0, 9], state: "minecraft:bricks"},
        {pos: [6, 0, 0], state: "minecraft:bricks"},
        {pos: [6, 0, 1], state: "minecraft:bricks"},
        {pos: [6, 0, 2], state: "minecraft:bricks"},
        {pos: [6, 0, 3], state: "minecraft:bricks"},
        {pos: [6, 0, 4], state: "minecraft:bricks"},
        {pos: [6, 0, 5], state: "minecraft:bricks"},
        {pos: [6, 0, 6], state: "minecraft:bricks"},
        {pos: [6, 0, 7], state: "minecraft:bricks"},
        {pos: [6, 0, 8], state: "minecraft:bricks"},
        {pos: [6, 0, 9], state: "minecraft:bricks"},
        {pos: [7, 0, 0], state: "minecraft:bricks"},
        {pos: [7, 0, 1], state: "minecraft:bricks"},
        {pos: [7, 0, 2], state: "minecraft:bricks"},
        {pos: [7, 0, 3], state: "minecraft:bricks"},
        {pos: [7, 0, 4], state: "minecraft:bricks"},
        {pos: [7, 0, 5], state: "minecraft:bricks"},
        {pos: [7, 0, 6], state: "minecraft:bricks"},
        {pos: [7, 0, 7], state: "minecraft:bricks"},
        {pos: [7, 0, 8], state: "minecraft:bricks"},
        {pos: [7, 0, 9], state: "minecraft:bricks"},
        {pos: [8, 0, 0], state: "minecraft:bricks"},
        {pos: [8, 0, 1], state: "minecraft:bricks"},
        {pos: [8, 0, 2], state: "minecraft:bricks"},
        {pos: [8, 0, 3], state: "minecraft:bricks"},
        {pos: [8, 0, 4], state: "minecraft:bricks"},
        {pos: [8, 0, 5], state: "minecraft:bricks"},
        {pos: [8, 0, 6], state: "minecraft:bricks"},
        {pos: [8, 0, 7], state: "minecraft:bricks"},
        {pos: [8, 0, 8], state: "minecraft:bricks"},
        {pos: [8, 0, 9], state: "minecraft:bricks"},
        {pos: [0, 1, 0], state: "minecraft:bricks"},
        {pos: [0, 1, 1], state: "minecraft:bricks"},
        {pos: [0, 1, 2], state: "minecraft:bricks"},
        {pos: [0, 1, 3], state: "minecraft:bricks"},
        {pos: [0, 1, 4], state: "minecraft:bricks"},
        {pos: [0, 1, 5], state: "minecraft:bricks"},
        {pos: [0, 1, 6], state: "minecraft:bricks"},
        {pos: [0, 1, 7], state: "minecraft:bricks"},
        {pos: [0, 1, 8], state: "minecraft:bricks"},
        {pos: [0, 1, 9], state: "minecraft:bricks"},
        {pos: [1, 1, 0], state: "minecraft:bricks"},
        {pos: [1, 1, 1], state: "minecraft:bricks"},
        {pos: [1, 1, 2], state: "minecraft:bricks"},
        {pos: [1, 1, 3], state: "minecraft:bricks"},
        {pos: [1, 1, 4], state: "minecraft:bricks"},
        {pos: [1, 1, 5], state: "minecraft:bricks"},
        {pos: [1, 1, 6], state: "minecraft:bricks"},
        {pos: [1, 1, 7], state: "minecraft:bricks"},
        {pos: [1, 1, 8], state: "minecraft:bricks"},
        {pos: [1, 1, 9], state: "minecraft:bricks"},
        {pos: [2, 1, 0], state: "minecraft:bricks"},
        {pos: [2, 1, 1], state: "minecraft:bricks"},
        {pos: [2, 1, 2], state: "minecraft:bricks"},
        {pos: [2, 1, 3], state: "minecraft:bricks"},
        {pos: [2, 1, 4], state: "minecraft:bricks"},
        {pos: [2, 1, 5], state: "minecraft:bricks"},
        {pos: [2, 1, 6], state: "minecraft:bricks"},
        {pos: [2, 1, 7], state: "minecraft:bricks"},
        {pos: [2, 1, 8], state: "minecraft:bricks"},
        {pos: [2, 1, 9], state: "minecraft:bricks"},
        {pos: [3, 1, 0], state: "minecraft:bricks"},
        {pos: [3, 1, 1], state: "minecraft:bricks"},
        {pos: [3, 1, 2], state: "minecraft:bricks"},
        {pos: [3, 1, 3], state: "minecraft:packed_mud"},
        {pos: [3, 1, 4], state: "minecraft:packed_mud"},
        {pos: [3, 1, 5], state: "minecraft:packed_mud"},
        {pos: [3, 1, 6], state: "minecraft:packed_mud"},
        {pos: [3, 1, 7], state: "minecraft:bricks"},
        {pos: [3, 1, 8], state: "minecraft:bricks"},
        {pos: [3, 1, 9], state: "minecraft:orange_terracotta"},
        {pos: [4, 1, 0], state: "minecraft:bricks"},
        {pos: [4, 1, 1], state: "minecraft:bricks"},
        {pos: [4, 1, 2], state: "minecraft:bricks"},
        {pos: [4, 1, 3], state: "minecraft:packed_mud"},
        {pos: [4, 1, 4], state: "minecraft:mud"},
        {pos: [4, 1, 5], state: "minecraft:bricks"},
        {pos: [4, 1, 6], state: "minecraft:bricks"},
        {pos: [4, 1, 7], state: "minecraft:bricks"},
        {pos: [4, 1, 8], state: "minecraft:bricks"},
        {pos: [4, 1, 9], state: "minecraft:orange_terracotta"},
        {pos: [5, 1, 0], state: "minecraft:bricks"},
        {pos: [5, 1, 1], state: "minecraft:bricks"},
        {pos: [5, 1, 2], state: "minecraft:bricks"},
        {pos: [5, 1, 3], state: "minecraft:packed_mud"},
        {pos: [5, 1, 4], state: "minecraft:packed_mud"},
        {pos: [5, 1, 5], state: "minecraft:mud"},
        {pos: [5, 1, 6], state: "minecraft:mud"},
        {pos: [5, 1, 7], state: "minecraft:bricks"},
        {pos: [5, 1, 8], state: "minecraft:bricks"},
        {pos: [5, 1, 9], state: "minecraft:orange_terracotta"},
        {pos: [6, 1, 0], state: "minecraft:jigsaw{orientation:north_up}", nbt: {final_state: "minecraft:mud_bricks", id: "minecraft:jigsaw", joint: "rollable", name: "minecraft:road_hall_anchor", pool: "minecraft:trail_ruins/tower", target: "minecraft:road_anchor"}},
        {pos: [6, 1, 1], state: "minecraft:bricks"},
        {pos: [6, 1, 2], state: "minecraft:bricks"},
        {pos: [6, 1, 3], state: "minecraft:bricks"},
        {pos: [6, 1, 4], state: "minecraft:bricks"},
        {pos: [6, 1, 5], state: "minecraft:bricks"},
        {pos: [6, 1, 6], state: "minecraft:bricks"},
        {pos: [6, 1, 7], state: "minecraft:bricks"},
        {pos: [6, 1, 8], state: "minecraft:bricks"},
        {pos: [6, 1, 9], state: "minecraft:bricks"},
        {pos: [7, 1, 0], state: "minecraft:bricks"},
        {pos: [7, 1, 1], state: "minecraft:bricks"},
        {pos: [7, 1, 2], state: "minecraft:bricks"},
        {pos: [7, 1, 3], state: "minecraft:bricks"},
        {pos: [7, 1, 4], state: "minecraft:bricks"},
        {pos: [7, 1, 5], state: "minecraft:bricks"},
        {pos: [7, 1, 6], state: "minecraft:bricks"},
        {pos: [7, 1, 7], state: "minecraft:bricks"},
        {pos: [7, 1, 8], state: "minecraft:bricks"},
        {pos: [7, 1, 9], state: "minecraft:bricks"},
        {pos: [8, 1, 0], state: "minecraft:bricks"},
        {pos: [8, 1, 1], state: "minecraft:bricks"},
        {pos: [8, 1, 2], state: "minecraft:orange_terracotta"},
        {pos: [8, 1, 3], state: "minecraft:orange_terracotta"},
        {pos: [8, 1, 4], state: "minecraft:orange_terracotta"},
        {pos: [8, 1, 5], state: "minecraft:orange_terracotta"},
        {pos: [8, 1, 6], state: "minecraft:orange_terracotta"},
        {pos: [8, 1, 7], state: "minecraft:bricks"},
        {pos: [8, 1, 8], state: "minecraft:bricks"},
        {pos: [8, 1, 9], state: "minecraft:bricks"},
        {pos: [0, 2, 0], state: "minecraft:bricks"},
        {pos: [0, 2, 1], state: "minecraft:white_terracotta"},
        {pos: [0, 2, 2], state: "minecraft:bricks"},
        {pos: [0, 2, 3], state: "minecraft:gravel"},
        {pos: [0, 2, 4], state: "minecraft:gravel"},
        {pos: [0, 2, 5], state: "minecraft:gravel"},
        {pos: [0, 2, 6], state: "minecraft:gravel"},
        {pos: [0, 2, 7], state: "minecraft:gravel"},
        {pos: [0, 2, 8], state: "minecraft:gravel"},
        {pos: [0, 2, 9], state: "minecraft:bricks"},
        {pos: [1, 2, 0], state: "minecraft:gravel"},
        {pos: [1, 2, 1], state: "minecraft:gravel"},
        {pos: [1, 2, 2], state: "minecraft:gravel"},
        {pos: [1, 2, 3], state: "minecraft:gravel"},
        {pos: [1, 2, 4], state: "minecraft:bricks"},
        {pos: [1, 2, 5], state: "minecraft:gravel"},
        {pos: [1, 2, 6], state: "minecraft:bricks"},
        {pos: [1, 2, 7], state: "minecraft:gravel"},
        {pos: [1, 2, 8], state: "minecraft:gravel"},
        {pos: [1, 2, 9], state: "minecraft:gravel"},
        {pos: [2, 2, 0], state: "minecraft:gravel"},
        {pos: [2, 2, 1], state: "minecraft:bricks"},
        {pos: [2, 2, 2], state: "minecraft:gravel"},
        {pos: [2, 2, 3], state: "minecraft:bricks"},
        {pos: [2, 2, 4], state: "minecraft:mud_brick_stairs{facing:east,half:bottom,shape:straight,waterlogged:false}"},
        {pos: [2, 2, 5], state: "minecraft:mud_brick_stairs{facing:east,half:bottom,shape:straight,waterlogged:false}"},
        {pos: [2, 2, 6], state: "minecraft:mud_brick_stairs{facing:east,half:bottom,shape:straight,waterlogged:false}"},
        {pos: [2, 2, 7], state: "minecraft:white_terracotta"},
        {pos: [2, 2, 8], state: "minecraft:bricks"},
        {pos: [2, 2, 9], state: "minecraft:gravel"},
        {pos: [3, 2, 0], state: "minecraft:gravel"},
        {pos: [3, 2, 1], state: "minecraft:gravel"},
        {pos: [3, 2, 2], state: "minecraft:gravel"},
        {pos: [3, 2, 3], state: "minecraft:gravel"},
        {pos: [3, 2, 4], state: "minecraft:packed_mud"},
        {pos: [3, 2, 5], state: "minecraft:packed_mud"},
        {pos: [3, 2, 6], state: "minecraft:gravel"},
        {pos: [3, 2, 7], state: "minecraft:light_blue_glazed_terracotta{facing:east}"},
        {pos: [3, 2, 8], state: "minecraft:gravel"},
        {pos: [3, 2, 9], state: "minecraft:gravel"},
        {pos: [4, 2, 0], state: "minecraft:gravel"},
        {pos: [4, 2, 1], state: "minecraft:gravel"},
        {pos: [4, 2, 2], state: "minecraft:gravel"},
        {pos: [4, 2, 3], state: "minecraft:packed_mud"},
        {pos: [4, 2, 4], state: "minecraft:packed_mud"},
        {pos: [4, 2, 5], state: "minecraft:bricks"},
        {pos: [4, 2, 6], state: "minecraft:bricks"},
        {pos: [4, 2, 7], state: "minecraft:gravel"},
        {pos: [4, 2, 8], state: "minecraft:gravel"},
        {pos: [4, 2, 9], state: "minecraft:gravel"},
        {pos: [5, 2, 0], state: "minecraft:gravel"},
        {pos: [5, 2, 1], state: "minecraft:gravel"},
        {pos: [5, 2, 2], state: "minecraft:gravel"},
        {pos: [5, 2, 3], state: "minecraft:packed_mud"},
        {pos: [5, 2, 4], state: "minecraft:packed_mud"},
        {pos: [5, 2, 5], state: "minecraft:packed_mud"},
        {pos: [5, 2, 6], state: "minecraft:packed_mud"},
        {pos: [5, 2, 7], state: "minecraft:gravel"},
        {pos: [5, 2, 8], state: "minecraft:bricks"},
        {pos: [5, 2, 9], state: "minecraft:gravel"},
        {pos: [6, 2, 0], state: "minecraft:gravel"},
        {pos: [6, 2, 1], state: "minecraft:gravel"},
        {pos: [6, 2, 2], state: "minecraft:white_terracotta"},
        {pos: [6, 2, 3], state: "minecraft:mud_brick_stairs{facing:west,half:bottom,shape:straight,waterlogged:false}"},
        {pos: [6, 2, 4], state: "minecraft:mud_brick_stairs{facing:west,half:bottom,shape:straight,waterlogged:false}"},
        {pos: [6, 2, 5], state: "minecraft:light_blue_glazed_terracotta{facing:south}"},
        {pos: [6, 2, 6], state: "minecraft:mud_brick_stairs{facing:west,half:bottom,shape:straight,waterlogged:false}"},
        {pos: [6, 2, 7], state: "minecraft:gravel"},
        {pos: [6, 2, 8], state: "minecraft:gravel"},
        {pos: [6, 2, 9], state: "minecraft:gravel"},
        {pos: [7, 2, 0], state: "minecraft:bricks"},
        {pos: [7, 2, 1], state: "minecraft:bricks"},
        {pos: [7, 2, 2], state: "minecraft:bricks"},
        {pos: [7, 2, 3], state: "minecraft:gravel"},
        {pos: [7, 2, 4], state: "minecraft:bricks"},
        {pos: [7, 2, 5], state: "minecraft:gravel"},
        {pos: [7, 2, 6], state: "minecraft:gravel"},
        {pos: [7, 2, 7], state: "minecraft:gravel"},
        {pos: [7, 2, 8], state: "minecraft:gravel"},
        {pos: [7, 2, 9], state: "minecraft:gravel"},
        {pos: [8, 2, 0], state: "minecraft:bricks"},
        {pos: [8, 2, 1], state: "minecraft:mud_brick_slab{type:bottom,waterlogged:false}"},
        {pos: [8, 2, 2], state: "minecraft:gravel"},
        {pos: [8, 2, 3], state: "minecraft:gravel"},
        {pos: [8, 2, 4], state: "minecraft:gravel"},
        {pos: [8, 2, 5], state: "minecraft:gravel"},
        {pos: [8, 2, 6], state: "minecraft:jigsaw{orientation:east_up}", nbt: {final_state: "minecraft:mud_bricks", id: "minecraft:jigsaw", joint: "rollable", name: "minecraft:hall_room_anchor", pool: "minecraft:trail_ruins/tower/additions", target: "minecraft:room_anchor"}},
        {pos: [8, 2, 7], state: "minecraft:gravel"},
        {pos: [8, 2, 8], state: "minecraft:gravel"},
        {pos: [8, 2, 9], state: "minecraft:bricks"},
        {pos: [0, 3, 0], state: "minecraft:bricks"},
        {pos: [0, 3, 1], state: "minecraft:gravel"},
        {pos: [0, 3, 2], state: "minecraft:gravel"},
        {pos: [0, 3, 3], state: "minecraft:gravel"},
        {pos: [0, 3, 4], state: "minecraft:gravel"},
        {pos: [0, 3, 5], state: "minecraft:gravel"},
        {pos: [0, 3, 6], state: "minecraft:gravel"},
        {pos: [0, 3, 7], state: "minecraft:gravel"},
        {pos: [0, 3, 8], state: "minecraft:gravel"},
        {pos: [0, 3, 9], state: "minecraft:bricks"},
        {pos: [1, 3, 0], state: "minecraft:gravel"},
        {pos: [1, 3, 1], state: "minecraft:gravel"},
        {pos: [1, 3, 2], state: "minecraft:gravel"},
        {pos: [1, 3, 3], state: "minecraft:gravel"},
        {pos: [1, 3, 4], state: "minecraft:gravel"},
        {pos: [1, 3, 5], state: "minecraft:gravel"},
        {pos: [1, 3, 6], state: "minecraft:gravel"},
        {pos: [1, 3, 7], state: "minecraft:gravel"},
        {pos: [1, 3, 8], state: "minecraft:gravel"},
        {pos: [1, 3, 9], state: "minecraft:gravel"},
        {pos: [2, 3, 0], state: "minecraft:gravel"},
        {pos: [2, 3, 1], state: "minecraft:gravel"},
        {pos: [2, 3, 2], state: "minecraft:gravel"},
        {pos: [2, 3, 3], state: "minecraft:gravel"},
        {pos: [2, 3, 4], state: "minecraft:gravel"},
        {pos: [2, 3, 5], state: "minecraft:gravel"},
        {pos: [2, 3, 6], state: "minecraft:bricks"},
        {pos: [2, 3, 7], state: "minecraft:gravel"},
        {pos: [2, 3, 8], state: "minecraft:gravel"},
        {pos: [2, 3, 9], state: "minecraft:gravel"},
        {pos: [3, 3, 0], state: "minecraft:gravel"},
        {pos: [3, 3, 1], state: "minecraft:gravel"},
        {pos: [3, 3, 2], state: "minecraft:gravel"},
        {pos: [3, 3, 3], state: "minecraft:gravel"},
        {pos: [3, 3, 4], state: "minecraft:bricks"},
        {pos: [3, 3, 5], state: "minecraft:gravel"},
        {pos: [3, 3, 6], state: "minecraft:gravel"},
        {pos: [3, 3, 7], state: "minecraft:gravel"},
        {pos: [3, 3, 8], state: "minecraft:gravel"},
        {pos: [3, 3, 9], state: "minecraft:gravel"},
        {pos: [4, 3, 0], state: "minecraft:gravel"},
        {pos: [4, 3, 1], state: "minecraft:gravel"},
        {pos: [4, 3, 2], state: "minecraft:gravel"},
        {pos: [4, 3, 3], state: "minecraft:gravel"},
        {pos: [4, 3, 4], state: "minecraft:light_blue_glazed_terracotta{facing:south}"},
        {pos: [4, 3, 5], state: "minecraft:gravel"},
        {pos: [4, 3, 6], state: "minecraft:bricks"},
        {pos: [4, 3, 7], state: "minecraft:gravel"},
        {pos: [4, 3, 8], state: "minecraft:gravel"},
        {pos: [4, 3, 9], state: "minecraft:gravel"},
        {pos: [5, 3, 0], state: "minecraft:gravel"},
        {pos: [5, 3, 1], state: "minecraft:gravel"},
        {pos: [5, 3, 2], state: "minecraft:gravel"},
        {pos: [5, 3, 3], state: "minecraft:gravel"},
        {pos: [5, 3, 4], state: "minecraft:bricks"},
        {pos: [5, 3, 5], state: "minecraft:gravel"},
        {pos: [5, 3, 6], state: "minecraft:bricks"},
        {pos: [5, 3, 7], state: "minecraft:gravel"},
        {pos: [5, 3, 8], state: "minecraft:gravel"},
        {pos: [5, 3, 9], state: "minecraft:gravel"},
        {pos: [6, 3, 0], state: "minecraft:gravel"},
        {pos: [6, 3, 1], state: "minecraft:gravel"},
        {pos: [6, 3, 2], state: "minecraft:gravel"},
        {pos: [6, 3, 3], state: "minecraft:gravel"},
        {pos: [6, 3, 4], state: "minecraft:bricks"},
        {pos: [6, 3, 5], state: "minecraft:bricks"},
        {pos: [6, 3, 6], state: "minecraft:gravel"},
        {pos: [6, 3, 7], state: "minecraft:gravel"},
        {pos: [6, 3, 8], state: "minecraft:gravel"},
        {pos: [6, 3, 9], state: "minecraft:gravel"},
        {pos: [7, 3, 0], state: "minecraft:gravel"},
        {pos: [7, 3, 1], state: "minecraft:bricks"},
        {pos: [7, 3, 2], state: "minecraft:gravel"},
        {pos: [7, 3, 3], state: "minecraft:gravel"},
        {pos: [7, 3, 4], state: "minecraft:gravel"},
        {pos: [7, 3, 5], state: "minecraft:gravel"},
        {pos: [7, 3, 6], state: "minecraft:gravel"},
        {pos: [7, 3, 7], state: "minecraft:gravel"},
        {pos: [7, 3, 8], state: "minecraft:gravel"},
        {pos: [7, 3, 9], state: "minecraft:gravel"},
        {pos: [8, 3, 0], state: "minecraft:gravel"},
        {pos: [8, 3, 1], state: "minecraft:gravel"},
        {pos: [8, 3, 2], state: "minecraft:gravel"},
        {pos: [8, 3, 3], state: "minecraft:gravel"},
        {pos: [8, 3, 4], state: "minecraft:gravel"},
        {pos: [8, 3, 5], state: "minecraft:gravel"},
        {pos: [8, 3, 6], state: "minecraft:gravel"},
        {pos: [8, 3, 7], state: "minecraft:gravel"},
        {pos: [8, 3, 8], state: "minecraft:gravel"},
        {pos: [8, 3, 9], state: "minecraft:bricks"},
        {pos: [0, 4, 2], state: "minecraft:gravel"},
        {pos: [0, 4, 3], state: "minecraft:gravel"},
        {pos: [0, 4, 4], state: "minecraft:gravel"},
        {pos: [0, 4, 5], state: "minecraft:gravel"},
        {pos: [0, 4, 6], state: "minecraft:gravel"},
        {pos: [0, 4, 7], state: "minecraft:gravel"},
        {pos: [0, 4, 8], state: "minecraft:gravel"},
        {pos: [0, 4, 9], state: "minecraft:white_terracotta"},
        {pos: [1, 4, 2], state: "minecraft:gravel"},
        {pos: [1, 4, 3], state: "minecraft:gravel"},
        {pos: [1, 4, 4], state: "minecraft:gravel"},
        {pos: [1, 4, 5], state: "minecraft:gravel"},
        {pos: [1, 4, 6], state: "minecraft:gravel"},
        {pos: [1, 4, 7], state: "minecraft:gravel"},
        {pos: [1, 4, 8], state: "minecraft:gravel"},
        {pos: [1, 4, 9], state: "minecraft:gravel"},
        {pos: [2, 4, 0], state: "minecraft:gravel"},
        {pos: [2, 4, 1], state: "minecraft:gravel"},
        {pos: [2, 4, 2], state: "minecraft:gravel"},
        {pos: [2, 4, 3], state: "minecraft:gravel"},
        {pos: [2, 4, 4], state: "minecraft:gravel"},
        {pos: [2, 4, 5], state: "minecraft:gravel"},
        {pos: [2, 4, 6], state: "minecraft:gravel"},
        {pos: [2, 4, 7], state: "minecraft:gravel"},
        {pos: [2, 4, 8], state: "minecraft:gravel"},
        {pos: [3, 4, 0], state: "minecraft:gravel"},
        {pos: [3, 4, 1], state: "minecraft:gravel"},
        {pos: [3, 4, 2], state: "minecraft:gravel"},
        {pos: [3, 4, 3], state: "minecraft:gravel"},
        {pos: [3, 4, 4], state: "minecraft:light_blue_glazed_terracotta{facing:south}"},
        {pos: [3, 4, 5], state: "minecraft:gravel"},
        {pos: [3, 4, 6], state: "minecraft:gravel"},
        {pos: [3, 4, 7], state: "minecraft:gravel"},
        {pos: [3, 4, 8], state: "minecraft:gravel"},
        {pos: [4, 4, 0], state: "minecraft:gravel"},
        {pos: [4, 4, 1], state: "minecraft:gravel"},
        {pos: [4, 4, 2], state: "minecraft:gravel"},
        {pos: [4, 4, 3], state: "minecraft:gravel"},
        {pos: [4, 4, 4], state: "minecraft:gravel"},
        {pos: [4, 4, 5], state: "minecraft:gravel"},
        {pos: [4, 4, 6], state: "minecraft:gravel"},
        {pos: [4, 4, 7], state: "minecraft:gravel"},
        {pos: [4, 4, 8], state: "minecraft:gravel"},
        {pos: [5, 4, 0], state: "minecraft:gravel"},
        {pos: [5, 4, 1], state: "minecraft:gravel"},
        {pos: [5, 4, 2], state: "minecraft:gravel"},
        {pos: [5, 4, 3], state: "minecraft:gravel"},
        {pos: [5, 4, 4], state: "minecraft:gravel"},
        {pos: [5, 4, 5], state: "minecraft:gravel"},
        {pos: [5, 4, 6], state: "minecraft:gravel"},
        {pos: [5, 4, 7], state: "minecraft:gravel"},
        {pos: [5, 4, 8], state: "minecraft:gravel"},
        {pos: [6, 4, 0], state: "minecraft:gravel"},
        {pos: [6, 4, 1], state: "minecraft:gravel"},
        {pos: [6, 4, 2], state: "minecraft:gravel"},
        {pos: [6, 4, 3], state: "minecraft:gravel"},
        {pos: [6, 4, 4], state: "minecraft:gravel"},
        {pos: [6, 4, 5], state: "minecraft:gravel"},
        {pos: [6, 4, 6], state: "minecraft:gravel"},
        {pos: [6, 4, 7], state: "minecraft:gravel"},
        {pos: [6, 4, 8], state: "minecraft:gravel"},
        {pos: [6, 4, 9], state: "minecraft:gravel"},
        {pos: [7, 4, 0], state: "minecraft:gravel"},
        {pos: [7, 4, 1], state: "minecraft:gravel"},
        {pos: [7, 4, 3], state: "minecraft:gravel"},
        {pos: [7, 4, 4], state: "minecraft:gravel"},
        {pos: [7, 4, 6], state: "minecraft:gravel"},
        {pos: [7, 4, 7], state: "minecraft:gravel"},
        {pos: [7, 4, 8], state: "minecraft:gravel"},
        {pos: [7, 4, 9], state: "minecraft:gravel"},
        {pos: [8, 4, 0], state: "minecraft:gravel"},
        {pos: [8, 4, 1], state: "minecraft:gravel"},
        {pos: [8, 4, 2], state: "minecraft:gravel"},
        {pos: [8, 4, 3], state: "minecraft:gravel"},
        {pos: [8, 4, 7], state: "minecraft:gravel"},
        {pos: [8, 4, 8], state: "minecraft:gravel"},
        {pos: [8, 4, 9], state: "minecraft:white_terracotta"},
        {pos: [0, 5, 3], state: "minecraft:gravel"},
        {pos: [0, 5, 4], state: "minecraft:gravel"},
        {pos: [0, 5, 5], state: "minecraft:gravel"},
        {pos: [0, 5, 6], state: "minecraft:gravel"},
        {pos: [0, 5, 7], state: "minecraft:gravel"},
        {pos: [0, 5, 8], state: "minecraft:gravel"},
        {pos: [0, 5, 9], state: "minecraft:bricks"},
        {pos: [1, 5, 2], state: "minecraft:gravel"},
        {pos: [1, 5, 3], state: "minecraft:gravel"},
        {pos: [1, 5, 4], state: "minecraft:gravel"},
        {pos: [1, 5, 5], state: "minecraft:gravel"},
        {pos: [1, 5, 6], state: "minecraft:gravel"},
        {pos: [1, 5, 7], state: "minecraft:gravel"},
        {pos: [1, 5, 8], state: "minecraft:gravel"},
        {pos: [1, 5, 9], state: "minecraft:gravel"},
        {pos: [2, 5, 2], state: "minecraft:gravel"},
        {pos: [2, 5, 3], state: "minecraft:gravel"},
        {pos: [2, 5, 4], state: "minecraft:gravel"},
        {pos: [2, 5, 5], state: "minecraft:gravel"},
        {pos: [2, 5, 6], state: "minecraft:gravel"},
        {pos: [2, 5, 7], state: "minecraft:gravel"},
        {pos: [2, 5, 8], state: "minecraft:gravel"},
        {pos: [3, 5, 0], state: "minecraft:gravel"},
        {pos: [3, 5, 1], state: "minecraft:gravel"},
        {pos: [3, 5, 2], state: "minecraft:gravel"},
        {pos: [3, 5, 3], state: "minecraft:gravel"},
        {pos: [3, 5, 5], state: "minecraft:gravel"},
        {pos: [3, 5, 6], state: "minecraft:gravel"},
        {pos: [3, 5, 7], state: "minecraft:gravel"},
        {pos: [4, 5, 0], state: "minecraft:gravel"},
        {pos: [4, 5, 1], state: "minecraft:gravel"},
        {pos: [4, 5, 2], state: "minecraft:gravel"},
        {pos: [4, 5, 3], state: "minecraft:gravel"},
        {pos: [4, 5, 5], state: "minecraft:gravel"},
        {pos: [4, 5, 6], state: "minecraft:gravel"},
        {pos: [4, 5, 7], state: "minecraft:gravel"},
        {pos: [4, 5, 8], state: "minecraft:gravel"},
        {pos: [5, 5, 0], state: "minecraft:gravel"},
        {pos: [5, 5, 1], state: "minecraft:gravel"},
        {pos: [5, 5, 2], state: "minecraft:gravel"},
        {pos: [5, 5, 3], state: "minecraft:gravel"},
        {pos: [5, 5, 4], state: "minecraft:gravel"},
        {pos: [5, 5, 6], state: "minecraft:gravel"},
        {pos: [5, 5, 7], state: "minecraft:gravel"},
        {pos: [5, 5, 8], state: "minecraft:gravel"},
        {pos: [6, 5, 0], state: "minecraft:gravel"},
        {pos: [6, 5, 1], state: "minecraft:gravel"},
        {pos: [6, 5, 2], state: "minecraft:gravel"},
        {pos: [6, 5, 3], state: "minecraft:gravel"},
        {pos: [6, 5, 4], state: "minecraft:gravel"},
        {pos: [6, 5, 5], state: "minecraft:gravel"},
        {pos: [6, 5, 6], state: "minecraft:gravel"},
        {pos: [6, 5, 7], state: "minecraft:gravel"},
        {pos: [6, 5, 8], state: "minecraft:gravel"},
        {pos: [7, 5, 0], state: "minecraft:gravel"},
        {pos: [7, 5, 3], state: "minecraft:gravel"},
        {pos: [7, 5, 4], state: "minecraft:gravel"},
        {pos: [7, 5, 6], state: "minecraft:gravel"},
        {pos: [7, 5, 7], state: "minecraft:gravel"},
        {pos: [7, 5, 8], state: "minecraft:gravel"},
        {pos: [7, 5, 9], state: "minecraft:gravel"},
        {pos: [8, 5, 0], state: "minecraft:gravel"},
        {pos: [8, 5, 7], state: "minecraft:gravel"},
        {pos: [8, 5, 8], state: "minecraft:gravel"},
        {pos: [8, 5, 9], state: "minecraft:bricks"},
        {pos: [0, 6, 8], state: "minecraft:bricks"},
        {pos: [0, 6, 9], state: "minecraft:bricks"},
        {pos: [1, 6, 3], state: "minecraft:bricks"},
        {pos: [1, 6, 4], state: "minecraft:bricks"},
        {pos: [1, 6, 5], state: "minecraft:bricks"},
        {pos: [1, 6, 6], state: "minecraft:bricks"},
        {pos: [1, 6, 7], state: "minecraft:bricks"},
        {pos: [1, 6, 8], state: "minecraft:bricks"},
        {pos: [1, 6, 9], state: "minecraft:bricks"},
        {pos: [2, 6, 8], state: "minecraft:bricks"},
        {pos: [4, 6, 1], state: "minecraft:gravel"},
        {pos: [7, 6, 3], state: "minecraft:bricks"},
        {pos: [7, 6, 4], state: "minecraft:bricks"},
        {pos: [7, 6, 5], state: "minecraft:bricks"},
        {pos: [7, 6, 6], state: "minecraft:bricks"},
        {pos: [7, 6, 7], state: "minecraft:bricks"},
        {pos: [7, 6, 8], state: "minecraft:bricks"},
        {pos: [7, 6, 9], state: "minecraft:bricks"},
        {pos: [8, 6, 8], state: "minecraft:bricks"},
        {pos: [8, 6, 9], state: "minecraft:bricks"}
    ],
    entities: [],
    palette: [
        "minecraft:bricks",
        "minecraft:packed_mud",
        "minecraft:orange_terracotta",
        "minecraft:white_terracotta",
        "minecraft:gravel",
        "minecraft:light_blue_glazed_terracotta{facing:east}",
        "minecraft:light_blue_glazed_terracotta{facing:south}",
        "minecraft:mud",
        "minecraft:mud_brick_stairs{facing:east,half:bottom,shape:straight,waterlogged:false}",
        "minecraft:mud_brick_stairs{facing:west,half:bottom,shape:straight,waterlogged:false}",
        "minecraft:mud_brick_slab{type:bottom,waterlogged:false}",
        "minecraft:jigsaw{orientation:north_up}",
        "minecraft:jigsaw{orientation:east_up}"
    ]
}
