{
    size: [5, 5, 5],
    data: [
        {pos: [0, 0, 1], state: "minecraft:bricks"},
        {pos: [0, 0, 2], state: "minecraft:bricks"},
        {pos: [0, 0, 3], state: "minecraft:bricks"},
        {pos: [1, 0, 0], state: "minecraft:bricks"},
        {pos: [1, 0, 1], state: "minecraft:bricks"},
        {pos: [1, 0, 2], state: "minecraft:bricks"},
        {pos: [1, 0, 3], state: "minecraft:bricks"},
        {pos: [1, 0, 4], state: "minecraft:bricks"},
        {pos: [2, 0, 0], state: "minecraft:bricks"},
        {pos: [2, 0, 1], state: "minecraft:bricks"},
        {pos: [2, 0, 2], state: "minecraft:bricks"},
        {pos: [2, 0, 3], state: "minecraft:bricks"},
        {pos: [2, 0, 4], state: "minecraft:bricks"},
        {pos: [3, 0, 0], state: "minecraft:bricks"},
        {pos: [3, 0, 1], state: "minecraft:bricks"},
        {pos: [3, 0, 2], state: "minecraft:bricks"},
        {pos: [3, 0, 3], state: "minecraft:bricks"},
        {pos: [3, 0, 4], state: "minecraft:bricks"},
        {pos: [4, 0, 1], state: "minecraft:bricks"},
        {pos: [4, 0, 2], state: "minecraft:bricks"},
        {pos: [4, 0, 3], state: "minecraft:bricks"},
        {pos: [0, 1, 1], state: "minecraft:bricks"},
        {pos: [0, 1, 2], state: "minecraft:bricks"},
        {pos: [0, 1, 3], state: "minecraft:bricks"},
        {pos: [1, 1, 0], state: "minecraft:bricks"},
        {pos: [1, 1, 1], state: "minecraft:gravel"},
        {pos: [1, 1, 2], state: "minecraft:gravel"},
        {pos: [1, 1, 3], state: "minecraft:gravel"},
        {pos: [1, 1, 4], state: "minecraft:bricks"},
        {pos: [2, 1, 0], state: "minecraft:bricks"},
        {pos: [2, 1, 1], state: "minecraft:gravel"},
        {pos: [2, 1, 2], state: "minecraft:gravel"},
        {pos: [2, 1, 3], state: "minecraft:loom{facing:north}"},
        {pos: [2, 1, 4], state: "minecraft:bricks"},
        {pos: [3, 1, 0], state: "minecraft:bricks"},
        {pos: [3, 1, 1], state: "minecraft:gravel"},
        {pos: [3, 1, 2], state: "minecraft:white_terracotta"},
        {pos: [3, 1, 3], state: "minecraft:gravel"},
        {pos: [3, 1, 4], state: "minecraft:bricks"},
        {pos: [4, 1, 1], state: "minecraft:bricks"},
        {pos: [4, 1, 2], state: "minecraft:bricks"},
        {pos: [4, 1, 3], state: "minecraft:bricks"},
        {pos: [0, 2, 1], state: "minecraft:bricks"},
        {pos: [0, 2, 2], state: "minecraft:bricks"},
        {pos: [0, 2, 3], state: "minecraft:bricks"},
        {pos: [1, 2, 0], state: "minecraft:bricks"},
        {pos: [1, 2, 1], state: "minecraft:gravel"},
        {pos: [1, 2, 2], state: "minecraft:gravel"},
        {pos: [1, 2, 3], state: "minecraft:gravel"},
        {pos: [1, 2, 4], state: "minecraft:bricks"},
        {pos: [2, 2, 0], state: "minecraft:jigsaw{orientation:north_up}", nbt: {final_state: "minecraft:gravel", id: "minecraft:jigsaw", joint: "rollable", name: "minecraft:room_anchor", pool: "minecraft:trail_ruins/tower/additions", target: "minecraft:hall_room_anchor"}},
        {pos: [2, 2, 1], state: "minecraft:gravel"},
        {pos: [2, 2, 2], state: "minecraft:gravel"},
        {pos: [2, 2, 3], state: "minecraft:gravel"},
        {pos: [2, 2, 4], state: "minecraft:bricks"},
        {pos: [3, 2, 0], state: "minecraft:bricks"},
        {pos: [3, 2, 1], state: "minecraft:gravel"},
        {pos: [3, 2, 2], state: "minecraft:gravel"},
        {pos: [3, 2, 3], state: "minecraft:gravel"},
        {pos: [3, 2, 4], state: "minecraft:bricks"},
        {pos: [4, 2, 1], state: "minecraft:bricks"},
        {pos: [4, 2, 2], state: "minecraft:bricks"},
        {pos: [4, 2, 3], state: "minecraft:bricks"},
        {pos: [0, 3, 1], state: "minecraft:blue_terracotta"},
        {pos: [0, 3, 2], state: "minecraft:blue_terracotta"},
        {pos: [0, 3, 3], state: "minecraft:blue_terracotta"},
        {pos: [1, 3, 0], state: "minecraft:blue_terracotta"},
        {pos: [1, 3, 1], state: "minecraft:gravel"},
        {pos: [1, 3, 2], state: "minecraft:gravel"},
        {pos: [1, 3, 3], state: "minecraft:gravel"},
        {pos: [1, 3, 4], state: "minecraft:blue_terracotta"},
        {pos: [2, 3, 0], state: "minecraft:gravel"},
        {pos: [2, 3, 1], state: "minecraft:gravel"},
        {pos: [2, 3, 2], state: "minecraft:gravel"},
        {pos: [2, 3, 3], state: "minecraft:gravel"},
        {pos: [2, 3, 4], state: "minecraft:blue_terracotta"},
        {pos: [3, 3, 0], state: "minecraft:gravel"},
        {pos: [3, 3, 1], state: "minecraft:gravel"},
        {pos: [3, 3, 2], state: "minecraft:gravel"},
        {pos: [3, 3, 3], state: "minecraft:gravel"},
        {pos: [3, 3, 4], state: "minecraft:blue_terracotta"},
        {pos: [4, 3, 1], state: "minecraft:blue_terracotta"},
        {pos: [4, 3, 2], state: "minecraft:blue_terracotta"},
        {pos: [4, 3, 3], state: "minecraft:blue_terracotta"},
        {pos: [1, 4, 1], state: "minecraft:white_terracotta"},
        {pos: [1, 4, 2], state: "minecraft:white_terracotta"},
        {pos: [1, 4, 3], state: "minecraft:white_terracotta"},
        {pos: [2, 4, 2], state: "minecraft:white_terracotta"},
        {pos: [2, 4, 3], state: "minecraft:white_terracotta"},
        {pos: [3, 4, 2], state: "minecraft:white_terracotta"},
        {pos: [3, 4, 3], state: "minecraft:white_terracotta"}
    ],
    entities: [],
    palette: [
        "minecraft:bricks",
        "minecraft:gravel",
        "minecraft:loom{facing:north}",
        "minecraft:white_terracotta",
        "minecraft:blue_terracotta",
        "minecraft:jigsaw{orientation:north_up}"
    ]
}
