{
    DataVersion: 2856,
    size: [7, 6, 7],
    data: [
        {pos: [0, 0, 0], state: "minecraft:spruce_planks"},
        {pos: [0, 0, 1], state: "minecraft:spruce_planks"},
        {pos: [0, 0, 2], state: "minecraft:spruce_planks"},
        {pos: [0, 0, 3], state: "minecraft:spruce_planks"},
        {pos: [0, 0, 4], state: "minecraft:spruce_planks"},
        {pos: [0, 0, 5], state: "minecraft:spruce_planks"},
        {pos: [0, 0, 6], state: "minecraft:snow{layers:5}"},
        {pos: [1, 0, 0], state: "minecraft:snow{layers:1}"},
        {pos: [1, 0, 1], state: "minecraft:stripped_spruce_wood{axis:y}"},
        {pos: [1, 0, 2], state: "minecraft:spruce_planks"},
        {pos: [1, 0, 3], state: "minecraft:spruce_planks"},
        {pos: [1, 0, 4], state: "minecraft:stripped_spruce_wood{axis:y}"},
        {pos: [1, 0, 5], state: "minecraft:snow{layers:6}"},
        {pos: [1, 0, 6], state: "minecraft:snow{layers:4}"},
        {pos: [2, 0, 0], state: "minecraft:snow{layers:1}"},
        {pos: [2, 0, 1], state: "minecraft:stripped_spruce_wood{axis:y}"},
        {pos: [2, 0, 2], state: "minecraft:spruce_planks"},
        {pos: [2, 0, 3], state: "minecraft:spruce_planks"},
        {pos: [2, 0, 4], state: "minecraft:stripped_spruce_wood{axis:y}"},
        {pos: [2, 0, 5], state: "minecraft:spruce_stairs{facing:north,half:bottom,shape:straight,waterlogged:false}"},
        {pos: [2, 0, 6], state: "minecraft:air"},
        {pos: [3, 0, 0], state: "minecraft:snow{layers:1}"},
        {pos: [3, 0, 1], state: "minecraft:stripped_spruce_wood{axis:y}"},
        {pos: [3, 0, 2], state: "minecraft:jigsaw{orientation:up_north}", nbt: {final_state: "minecraft:spruce_planks", id: "minecraft:jigsaw", joint: "rollable", name: "minecraft:bottom", pool: "minecraft:village/snowy/zombie/villagers", target: "minecraft:bottom"}},
        {pos: [3, 0, 3], state: "minecraft:spruce_planks"},
        {pos: [3, 0, 4], state: "minecraft:stripped_spruce_wood{axis:y}"},
        {pos: [3, 0, 5], state: "minecraft:spruce_stairs{facing:north,half:bottom,shape:straight,waterlogged:false}"},
        {pos: [3, 0, 6], state: "minecraft:jigsaw{orientation:south_up}", nbt: {final_state: "minecraft:structure_void", id: "minecraft:jigsaw", joint: "aligned", name: "minecraft:building_entrance", pool: "minecraft:empty", target: "minecraft:building_entrance"}},
        {pos: [4, 0, 0], state: "minecraft:snow{layers:1}"},
        {pos: [4, 0, 1], state: "minecraft:stripped_spruce_wood{axis:y}"},
        {pos: [4, 0, 2], state: "minecraft:spruce_planks"},
        {pos: [4, 0, 3], state: "minecraft:spruce_planks"},
        {pos: [4, 0, 4], state: "minecraft:stripped_spruce_wood{axis:y}"},
        {pos: [4, 0, 5], state: "minecraft:snow_block"},
        {pos: [4, 0, 6], state: "minecraft:snow{layers:7}"},
        {pos: [5, 0, 0], state: "minecraft:spruce_planks"},
        {pos: [5, 0, 1], state: "minecraft:spruce_planks"},
        {pos: [5, 0, 2], state: "minecraft:spruce_planks"},
        {pos: [5, 0, 3], state: "minecraft:spruce_planks"},
        {pos: [5, 0, 4], state: "minecraft:spruce_planks"},
        {pos: [5, 0, 5], state: "minecraft:spruce_planks"},
        {pos: [5, 0, 6], state: "minecraft:snow_block"},
        {pos: [6, 0, 0], state: "minecraft:grass"},
        {pos: [6, 0, 1], state: "minecraft:snow{layers:1}"},
        {pos: [6, 0, 2], state: "minecraft:grass"},
        {pos: [6, 0, 3], state: "minecraft:snow{layers:7}"},
        {pos: [6, 0, 4], state: "minecraft:snow_block"},
        {pos: [6, 0, 5], state: "minecraft:snow_block"},
        {pos: [6, 0, 6], state: "minecraft:grass"},
        {pos: [0, 1, 0], state: "minecraft:spruce_planks"},
        {pos: [0, 1, 1], state: "minecraft:spruce_planks"},
        {pos: [0, 1, 2], state: "minecraft:spruce_planks"},
        {pos: [0, 1, 3], state: "minecraft:spruce_planks"},
        {pos: [0, 1, 4], state: "minecraft:spruce_planks"},
        {pos: [0, 1, 5], state: "minecraft:spruce_planks"},
        {pos: [0, 1, 6], state: "minecraft:air"},
        {pos: [1, 1, 0], state: "minecraft:air"},
        {pos: [1, 1, 1], state: "minecraft:stripped_spruce_wood{axis:y}"},
        {pos: [1, 1, 2], state: "minecraft:spruce_planks"},
        {pos: [1, 1, 3], state: "minecraft:spruce_planks"},
        {pos: [1, 1, 4], state: "minecraft:stripped_spruce_wood{axis:y}"},
        {pos: [1, 1, 5], state: "minecraft:air"},
        {pos: [1, 1, 6], state: "minecraft:air"},
        {pos: [2, 1, 0], state: "minecraft:air"},
        {pos: [2, 1, 1], state: "minecraft:stripped_spruce_wood{axis:y}"},
        {pos: [2, 1, 2], state: "minecraft:blue_bed{facing:north,occupied:false,part:head}", nbt: {id: "minecraft:bed"}},
        {pos: [2, 1, 3], state: "minecraft:blue_bed{facing:north,occupied:false,part:foot}", nbt: {id: "minecraft:bed"}},
        {pos: [2, 1, 4], state: "minecraft:spruce_door{facing:north,half:lower,hinge:left,open:false,powered:false}"},
        {pos: [2, 1, 5], state: "minecraft:air"},
        {pos: [2, 1, 6], state: "minecraft:air"},
        {pos: [3, 1, 0], state: "minecraft:air"},
        {pos: [3, 1, 1], state: "minecraft:stripped_spruce_wood{axis:y}"},
        {pos: [3, 1, 2], state: "minecraft:air"},
        {pos: [3, 1, 3], state: "minecraft:air"},
        {pos: [3, 1, 4], state: "minecraft:spruce_door{facing:north,half:lower,hinge:right,open:false,powered:false}"},
        {pos: [3, 1, 5], state: "minecraft:air"},
        {pos: [3, 1, 6], state: "minecraft:air"},
        {pos: [4, 1, 0], state: "minecraft:air"},
        {pos: [4, 1, 1], state: "minecraft:stripped_spruce_wood{axis:y}"},
        {pos: [4, 1, 2], state: "minecraft:furnace{facing:west,lit:false}", nbt: {BurnTime: 0s, CookTime: 0s, CookTimeTotal: 0s, Items: [], RecipesUsed: {}, id: "minecraft:furnace"}},
        {pos: [4, 1, 3], state: "minecraft:furnace{facing:west,lit:false}", nbt: {BurnTime: 0s, CookTime: 0s, CookTimeTotal: 0s, Items: [], RecipesUsed: {}, id: "minecraft:furnace"}},
        {pos: [4, 1, 4], state: "minecraft:stripped_spruce_wood{axis:y}"},
        {pos: [4, 1, 5], state: "minecraft:snow{layers:4}"},
        {pos: [4, 1, 6], state: "minecraft:air"},
        {pos: [5, 1, 0], state: "minecraft:spruce_planks"},
        {pos: [5, 1, 1], state: "minecraft:spruce_planks"},
        {pos: [5, 1, 2], state: "minecraft:spruce_planks"},
        {pos: [5, 1, 3], state: "minecraft:spruce_planks"},
        {pos: [5, 1, 4], state: "minecraft:spruce_planks"},
        {pos: [5, 1, 5], state: "minecraft:spruce_planks"},
        {pos: [5, 1, 6], state: "minecraft:snow{layers:4}"},
        {pos: [6, 1, 0], state: "minecraft:air"},
        {pos: [6, 1, 1], state: "minecraft:air"},
        {pos: [6, 1, 2], state: "minecraft:air"},
        {pos: [6, 1, 3], state: "minecraft:air"},
        {pos: [6, 1, 4], state: "minecraft:snow_block"},
        {pos: [6, 1, 5], state: "minecraft:snow{layers:1}"},
        {pos: [6, 1, 6], state: "minecraft:air"},
        {pos: [0, 2, 0], state: "minecraft:spruce_stairs{facing:east,half:bottom,shape:straight,waterlogged:false}"},
        {pos: [0, 2, 1], state: "minecraft:spruce_stairs{facing:east,half:bottom,shape:straight,waterlogged:false}"},
        {pos: [0, 2, 2], state: "minecraft:snow{layers:1}"},
        {pos: [0, 2, 3], state: "minecraft:snow{layers:1}"},
        {pos: [0, 2, 4], state: "minecraft:spruce_stairs{facing:east,half:bottom,shape:straight,waterlogged:false}"},
        {pos: [0, 2, 5], state: "minecraft:spruce_stairs{facing:east,half:bottom,shape:straight,waterlogged:false}"},
        {pos: [0, 2, 6], state: "minecraft:air"},
        {pos: [1, 2, 0], state: "minecraft:spruce_planks"},
        {pos: [1, 2, 1], state: "minecraft:spruce_planks"},
        {pos: [1, 2, 2], state: "minecraft:spruce_planks"},
        {pos: [1, 2, 3], state: "minecraft:spruce_planks"},
        {pos: [1, 2, 4], state: "minecraft:stripped_spruce_wood{axis:y}"},
        {pos: [1, 2, 5], state: "minecraft:spruce_stairs{facing:west,half:top,shape:straight,waterlogged:false}"},
        {pos: [1, 2, 6], state: "minecraft:lantern{hanging:true,waterlogged:false}"},
        {pos: [2, 2, 0], state: "minecraft:air"},
        {pos: [2, 2, 1], state: "minecraft:stripped_spruce_wood{axis:y}"},
        {pos: [2, 2, 2], state: "minecraft:air"},
        {pos: [2, 2, 3], state: "minecraft:air"},
        {pos: [2, 2, 4], state: "minecraft:spruce_door{facing:north,half:upper,hinge:left,open:false,powered:false}"},
        {pos: [2, 2, 5], state: "minecraft:air"},
        {pos: [2, 2, 6], state: "minecraft:air"},
        {pos: [3, 2, 0], state: "minecraft:air"},
        {pos: [3, 2, 1], state: "minecraft:stripped_spruce_wood{axis:y}"},
        {pos: [3, 2, 2], state: "minecraft:air"},
        {pos: [3, 2, 3], state: "minecraft:air"},
        {pos: [3, 2, 4], state: "minecraft:spruce_door{facing:north,half:upper,hinge:right,open:false,powered:false}"},
        {pos: [3, 2, 5], state: "minecraft:air"},
        {pos: [3, 2, 6], state: "minecraft:air"},
        {pos: [4, 2, 0], state: "minecraft:spruce_planks"},
        {pos: [4, 2, 1], state: "minecraft:spruce_planks"},
        {pos: [4, 2, 2], state: "minecraft:spruce_planks"},
        {pos: [4, 2, 3], state: "minecraft:spruce_planks"},
        {pos: [4, 2, 4], state: "minecraft:stripped_spruce_wood{axis:y}"},
        {pos: [4, 2, 5], state: "minecraft:spruce_stairs{facing:east,half:top,shape:straight,waterlogged:false}"},
        {pos: [4, 2, 6], state: "minecraft:lantern{hanging:true,waterlogged:false}"},
        {pos: [5, 2, 0], state: "minecraft:spruce_stairs{facing:west,half:bottom,shape:straight,waterlogged:false}"},
        {pos: [5, 2, 1], state: "minecraft:spruce_stairs{facing:west,half:bottom,shape:straight,waterlogged:false}"},
        {pos: [5, 2, 2], state: "minecraft:snow{layers:2}"},
        {pos: [5, 2, 3], state: "minecraft:snow{layers:4}"},
        {pos: [5, 2, 4], state: "minecraft:spruce_stairs{facing:west,half:bottom,shape:straight,waterlogged:false}"},
        {pos: [5, 2, 5], state: "minecraft:spruce_stairs{facing:west,half:bottom,shape:straight,waterlogged:false}"},
        {pos: [5, 2, 6], state: "minecraft:air"},
        {pos: [6, 2, 0], state: "minecraft:air"},
        {pos: [6, 2, 1], state: "minecraft:air"},
        {pos: [6, 2, 2], state: "minecraft:air"},
        {pos: [6, 2, 3], state: "minecraft:air"},
        {pos: [6, 2, 4], state: "minecraft:snow{layers:1}"},
        {pos: [6, 2, 5], state: "minecraft:air"},
        {pos: [6, 2, 6], state: "minecraft:air"},
        {pos: [0, 3, 0], state: "minecraft:air"},
        {pos: [0, 3, 1], state: "minecraft:air"},
        {pos: [0, 3, 2], state: "minecraft:air"},
        {pos: [0, 3, 3], state: "minecraft:air"},
        {pos: [0, 3, 4], state: "minecraft:air"},
        {pos: [0, 3, 5], state: "minecraft:air"},
        {pos: [0, 3, 6], state: "minecraft:air"},
        {pos: [1, 3, 0], state: "minecraft:spruce_planks"},
        {pos: [1, 3, 1], state: "minecraft:spruce_planks"},
        {pos: [1, 3, 2], state: "minecraft:spruce_planks"},
        {pos: [1, 3, 3], state: "minecraft:spruce_planks"},
        {pos: [1, 3, 4], state: "minecraft:spruce_planks"},
        {pos: [1, 3, 5], state: "minecraft:spruce_planks"},
        {pos: [1, 3, 6], state: "minecraft:spruce_fence{east:false,north:true,south:false,waterlogged:false,west:false}"},
        {pos: [2, 3, 0], state: "minecraft:air"},
        {pos: [2, 3, 1], state: "minecraft:stripped_spruce_wood{axis:x}"},
        {pos: [2, 3, 2], state: "minecraft:air"},
        {pos: [2, 3, 3], state: "minecraft:wall_torch{facing:north}"},
        {pos: [2, 3, 4], state: "minecraft:stripped_spruce_wood{axis:y}"},
        {pos: [2, 3, 5], state: "minecraft:air"},
        {pos: [2, 3, 6], state: "minecraft:air"},
        {pos: [3, 3, 0], state: "minecraft:air"},
        {pos: [3, 3, 1], state: "minecraft:stripped_spruce_wood{axis:y}"},
        {pos: [3, 3, 2], state: "minecraft:air"},
        {pos: [3, 3, 3], state: "minecraft:wall_torch{facing:north}"},
        {pos: [3, 3, 4], state: "minecraft:stripped_spruce_wood{axis:y}"},
        {pos: [3, 3, 5], state: "minecraft:air"},
        {pos: [3, 3, 6], state: "minecraft:air"},
        {pos: [4, 3, 0], state: "minecraft:spruce_planks"},
        {pos: [4, 3, 1], state: "minecraft:spruce_planks"},
        {pos: [4, 3, 2], state: "minecraft:spruce_planks"},
        {pos: [4, 3, 3], state: "minecraft:spruce_planks"},
        {pos: [4, 3, 4], state: "minecraft:spruce_planks"},
        {pos: [4, 3, 5], state: "minecraft:spruce_planks"},
        {pos: [4, 3, 6], state: "minecraft:spruce_fence{east:false,north:true,south:false,waterlogged:false,west:false}"},
        {pos: [5, 3, 0], state: "minecraft:air"},
        {pos: [5, 3, 1], state: "minecraft:air"},
        {pos: [5, 3, 2], state: "minecraft:air"},
        {pos: [5, 3, 3], state: "minecraft:air"},
        {pos: [5, 3, 4], state: "minecraft:air"},
        {pos: [5, 3, 5], state: "minecraft:air"},
        {pos: [5, 3, 6], state: "minecraft:air"},
        {pos: [6, 3, 0], state: "minecraft:air"},
        {pos: [6, 3, 1], state: "minecraft:air"},
        {pos: [6, 3, 2], state: "minecraft:air"},
        {pos: [6, 3, 3], state: "minecraft:air"},
        {pos: [6, 3, 4], state: "minecraft:air"},
        {pos: [6, 3, 5], state: "minecraft:air"},
        {pos: [6, 3, 6], state: "minecraft:air"},
        {pos: [0, 4, 0], state: "minecraft:air"},
        {pos: [0, 4, 1], state: "minecraft:air"},
        {pos: [0, 4, 2], state: "minecraft:air"},
        {pos: [0, 4, 3], state: "minecraft:air"},
        {pos: [0, 4, 4], state: "minecraft:air"},
        {pos: [0, 4, 5], state: "minecraft:air"},
        {pos: [0, 4, 6], state: "minecraft:air"},
        {pos: [1, 4, 0], state: "minecraft:spruce_stairs{facing:east,half:bottom,shape:straight,waterlogged:false}"},
        {pos: [1, 4, 1], state: "minecraft:spruce_stairs{facing:east,half:bottom,shape:straight,waterlogged:false}"},
        {pos: [1, 4, 2], state: "minecraft:snow{layers:1}"},
        {pos: [1, 4, 3], state: "minecraft:snow{layers:1}"},
        {pos: [1, 4, 4], state: "minecraft:spruce_stairs{facing:east,half:bottom,shape:straight,waterlogged:false}"},
        {pos: [1, 4, 5], state: "minecraft:spruce_stairs{facing:east,half:bottom,shape:straight,waterlogged:false}"},
        {pos: [1, 4, 6], state: "minecraft:air"},
        {pos: [2, 4, 0], state: "minecraft:spruce_planks"},
        {pos: [2, 4, 1], state: "minecraft:spruce_planks"},
        {pos: [2, 4, 2], state: "minecraft:spruce_planks"},
        {pos: [2, 4, 3], state: "minecraft:spruce_planks"},
        {pos: [2, 4, 4], state: "minecraft:stripped_spruce_wood{axis:y}"},
        {pos: [2, 4, 5], state: "minecraft:spruce_stairs{facing:west,half:top,shape:straight,waterlogged:false}"},
        {pos: [2, 4, 6], state: "minecraft:air"},
        {pos: [3, 4, 0], state: "minecraft:spruce_planks"},
        {pos: [3, 4, 1], state: "minecraft:spruce_planks"},
        {pos: [3, 4, 2], state: "minecraft:spruce_planks"},
        {pos: [3, 4, 3], state: "minecraft:spruce_planks"},
        {pos: [3, 4, 4], state: "minecraft:stripped_spruce_wood{axis:y}"},
        {pos: [3, 4, 5], state: "minecraft:spruce_stairs{facing:east,half:top,shape:straight,waterlogged:false}"},
        {pos: [3, 4, 6], state: "minecraft:air"},
        {pos: [4, 4, 0], state: "minecraft:spruce_stairs{facing:west,half:bottom,shape:straight,waterlogged:false}"},
        {pos: [4, 4, 1], state: "minecraft:spruce_stairs{facing:west,half:bottom,shape:straight,waterlogged:false}"},
        {pos: [4, 4, 2], state: "minecraft:snow{layers:4}"},
        {pos: [4, 4, 3], state: "minecraft:snow{layers:1}"},
        {pos: [4, 4, 4], state: "minecraft:spruce_stairs{facing:west,half:bottom,shape:straight,waterlogged:false}"},
        {pos: [4, 4, 5], state: "minecraft:spruce_stairs{facing:west,half:bottom,shape:straight,waterlogged:false}"},
        {pos: [4, 4, 6], state: "minecraft:air"},
        {pos: [5, 4, 0], state: "minecraft:air"},
        {pos: [5, 4, 1], state: "minecraft:air"},
        {pos: [5, 4, 2], state: "minecraft:air"},
        {pos: [5, 4, 3], state: "minecraft:air"},
        {pos: [5, 4, 4], state: "minecraft:air"},
        {pos: [5, 4, 5], state: "minecraft:air"},
        {pos: [5, 4, 6], state: "minecraft:air"},
        {pos: [6, 4, 0], state: "minecraft:air"},
        {pos: [6, 4, 1], state: "minecraft:air"},
        {pos: [6, 4, 2], state: "minecraft:air"},
        {pos: [6, 4, 3], state: "minecraft:air"},
        {pos: [6, 4, 4], state: "minecraft:air"},
        {pos: [6, 4, 5], state: "minecraft:air"},
        {pos: [6, 4, 6], state: "minecraft:air"},
        {pos: [0, 5, 0], state: "minecraft:air"},
        {pos: [0, 5, 1], state: "minecraft:air"},
        {pos: [0, 5, 2], state: "minecraft:air"},
        {pos: [0, 5, 3], state: "minecraft:air"},
        {pos: [0, 5, 4], state: "minecraft:air"},
        {pos: [0, 5, 5], state: "minecraft:air"},
        {pos: [0, 5, 6], state: "minecraft:air"},
        {pos: [1, 5, 0], state: "minecraft:air"},
        {pos: [1, 5, 1], state: "minecraft:air"},
        {pos: [1, 5, 2], state: "minecraft:air"},
        {pos: [1, 5, 3], state: "minecraft:air"},
        {pos: [1, 5, 4], state: "minecraft:air"},
        {pos: [1, 5, 5], state: "minecraft:air"},
        {pos: [1, 5, 6], state: "minecraft:air"},
        {pos: [2, 5, 0], state: "minecraft:spruce_slab{type:bottom,waterlogged:false}"},
        {pos: [2, 5, 1], state: "minecraft:spruce_slab{type:bottom,waterlogged:false}"},
        {pos: [2, 5, 2], state: "minecraft:spruce_slab{type:bottom,waterlogged:false}"},
        {pos: [2, 5, 3], state: "minecraft:spruce_slab{type:bottom,waterlogged:false}"},
        {pos: [2, 5, 4], state: "minecraft:spruce_slab{type:bottom,waterlogged:false}"},
        {pos: [2, 5, 5], state: "minecraft:spruce_slab{type:bottom,waterlogged:false}"},
        {pos: [2, 5, 6], state: "minecraft:air"},
        {pos: [3, 5, 0], state: "minecraft:spruce_slab{type:bottom,waterlogged:false}"},
        {pos: [3, 5, 1], state: "minecraft:spruce_slab{type:bottom,waterlogged:false}"},
        {pos: [3, 5, 2], state: "minecraft:spruce_slab{type:bottom,waterlogged:false}"},
        {pos: [3, 5, 3], state: "minecraft:spruce_slab{type:bottom,waterlogged:false}"},
        {pos: [3, 5, 4], state: "minecraft:spruce_slab{type:bottom,waterlogged:false}"},
        {pos: [3, 5, 5], state: "minecraft:spruce_slab{type:bottom,waterlogged:false}"},
        {pos: [3, 5, 6], state: "minecraft:air"},
        {pos: [4, 5, 0], state: "minecraft:air"},
        {pos: [4, 5, 1], state: "minecraft:air"},
        {pos: [4, 5, 2], state: "minecraft:air"},
        {pos: [4, 5, 3], state: "minecraft:air"},
        {pos: [4, 5, 4], state: "minecraft:air"},
        {pos: [4, 5, 5], state: "minecraft:air"},
        {pos: [4, 5, 6], state: "minecraft:air"},
        {pos: [5, 5, 0], state: "minecraft:air"},
        {pos: [5, 5, 1], state: "minecraft:air"},
        {pos: [5, 5, 2], state: "minecraft:air"},
        {pos: [5, 5, 3], state: "minecraft:air"},
        {pos: [5, 5, 4], state: "minecraft:air"},
        {pos: [5, 5, 5], state: "minecraft:air"},
        {pos: [5, 5, 6], state: "minecraft:air"},
        {pos: [6, 5, 0], state: "minecraft:air"},
        {pos: [6, 5, 1], state: "minecraft:air"},
        {pos: [6, 5, 2], state: "minecraft:air"},
        {pos: [6, 5, 3], state: "minecraft:air"},
        {pos: [6, 5, 4], state: "minecraft:air"},
        {pos: [6, 5, 5], state: "minecraft:air"},
        {pos: [6, 5, 6], state: "minecraft:air"}
    ],
    entities: [],
    palette: [
        "minecraft:spruce_planks",
        "minecraft:stripped_spruce_wood{axis:y}",
        "minecraft:snow_block",
        "minecraft:stripped_spruce_wood{axis:x}",
        "minecraft:snow{layers:5}",
        "minecraft:snow{layers:1}",
        "minecraft:snow{layers:6}",
        "minecraft:snow{layers:4}",
        "minecraft:spruce_stairs{facing:north,half:bottom,shape:straight,waterlogged:false}",
        "minecraft:air",
        "minecraft:snow{layers:7}",
        "minecraft:grass",
        "minecraft:spruce_door{facing:north,half:lower,hinge:left,open:false,powered:false}",
        "minecraft:spruce_door{facing:north,half:lower,hinge:right,open:false,powered:false}",
        "minecraft:spruce_stairs{facing:east,half:bottom,shape:straight,waterlogged:false}",
        "minecraft:spruce_stairs{facing:west,half:top,shape:straight,waterlogged:false}",
        "minecraft:lantern{hanging:true,waterlogged:false}",
        "minecraft:spruce_door{facing:north,half:upper,hinge:left,open:false,powered:false}",
        "minecraft:spruce_door{facing:north,half:upper,hinge:right,open:false,powered:false}",
        "minecraft:spruce_stairs{facing:east,half:top,shape:straight,waterlogged:false}",
        "minecraft:spruce_stairs{facing:west,half:bottom,shape:straight,waterlogged:false}",
        "minecraft:snow{layers:2}",
        "minecraft:spruce_fence{east:false,north:true,south:false,waterlogged:false,west:false}",
        "minecraft:wall_torch{facing:north}",
        "minecraft:spruce_slab{type:bottom,waterlogged:false}",
        "minecraft:jigsaw{orientation:up_north}",
        "minecraft:jigsaw{orientation:south_up}",
        "minecraft:blue_bed{facing:north,occupied:false,part:head}",
        "minecraft:blue_bed{facing:north,occupied:false,part:foot}",
        "minecraft:furnace{facing:west,lit:false}"
    ]
}
