{
    DataVersion: 2856,
    size: [8, 5, 7],
    data: [
        {pos: [0, 0, 0], state: "minecraft:grass_block{snowy:true}"},
        {pos: [0, 0, 1], state: "minecraft:grass_block{snowy:true}"},
        {pos: [0, 0, 2], state: "minecraft:grass_block{snowy:true}"},
        {pos: [0, 0, 3], state: "minecraft:dirt"},
        {pos: [0, 0, 4], state: "minecraft:dirt"},
        {pos: [0, 0, 5], state: "minecraft:grass_block{snowy:true}"},
        {pos: [0, 0, 6], state: "minecraft:grass_block{snowy:true}"},
        {pos: [1, 0, 0], state: "minecraft:grass_block{snowy:true}"},
        {pos: [1, 0, 1], state: "minecraft:dirt"},
        {pos: [1, 0, 2], state: "minecraft:dirt"},
        {pos: [1, 0, 3], state: "minecraft:grass_block{snowy:false}"},
        {pos: [1, 0, 4], state: "minecraft:dirt"},
        {pos: [1, 0, 5], state: "minecraft:dirt"},
        {pos: [1, 0, 6], state: "minecraft:grass_block{snowy:true}"},
        {pos: [2, 0, 0], state: "minecraft:grass_block{snowy:true}"},
        {pos: [2, 0, 1], state: "minecraft:dirt"},
        {pos: [2, 0, 2], state: "minecraft:grass_block{snowy:false}"},
        {pos: [2, 0, 3], state: "minecraft:grass_block{snowy:false}"},
        {pos: [2, 0, 4], state: "minecraft:grass_block{snowy:false}"},
        {pos: [2, 0, 5], state: "minecraft:dirt"},
        {pos: [2, 0, 6], state: "minecraft:grass_block{snowy:true}"},
        {pos: [3, 0, 0], state: "minecraft:dirt"},
        {pos: [3, 0, 1], state: "minecraft:dirt"},
        {pos: [3, 0, 2], state: "minecraft:grass_block{snowy:false}"},
        {pos: [3, 0, 3], state: "minecraft:grass_block{snowy:false}"},
        {pos: [3, 0, 4], state: "minecraft:dirt"},
        {pos: [3, 0, 5], state: "minecraft:dirt"},
        {pos: [3, 0, 6], state: "minecraft:grass_block{snowy:true}"},
        {pos: [4, 0, 0], state: "minecraft:grass_block{snowy:true}"},
        {pos: [4, 0, 1], state: "minecraft:dirt"},
        {pos: [4, 0, 2], state: "minecraft:grass_block{snowy:false}"},
        {pos: [4, 0, 3], state: "minecraft:jigsaw{orientation:up_north}", nbt: {final_state: "minecraft:grass_block", id: "minecraft:jigsaw", joint: "rollable", name: "minecraft:bottom", pool: "minecraft:village/snowy/zombie/villagers", target: "minecraft:bottom"}},
        {pos: [4, 0, 4], state: "minecraft:grass_block{snowy:false}"},
        {pos: [4, 0, 5], state: "minecraft:dirt"},
        {pos: [4, 0, 6], state: "minecraft:grass_block{snowy:true}"},
        {pos: [5, 0, 0], state: "minecraft:grass_block{snowy:true}"},
        {pos: [5, 0, 1], state: "minecraft:grass_block{snowy:true}"},
        {pos: [5, 0, 2], state: "minecraft:dirt"},
        {pos: [5, 0, 3], state: "minecraft:grass_block{snowy:false}"},
        {pos: [5, 0, 4], state: "minecraft:dirt"},
        {pos: [5, 0, 5], state: "minecraft:grass_block{snowy:true}"},
        {pos: [5, 0, 6], state: "minecraft:grass_block{snowy:true}"},
        {pos: [6, 0, 0], state: "minecraft:grass_block{snowy:true}"},
        {pos: [6, 0, 1], state: "minecraft:grass_block{snowy:true}"},
        {pos: [6, 0, 2], state: "minecraft:dirt"},
        {pos: [6, 0, 3], state: "minecraft:grass_block{snowy:false}"},
        {pos: [6, 0, 4], state: "minecraft:dirt"},
        {pos: [6, 0, 5], state: "minecraft:grass_block{snowy:true}"},
        {pos: [6, 0, 6], state: "minecraft:grass_block{snowy:true}"},
        {pos: [7, 0, 0], state: "minecraft:grass_block{snowy:true}"},
        {pos: [7, 0, 1], state: "minecraft:grass_block{snowy:true}"},
        {pos: [7, 0, 2], state: "minecraft:dirt"},
        {pos: [7, 0, 3], state: "minecraft:dirt"},
        {pos: [7, 0, 4], state: "minecraft:grass_block{snowy:true}"},
        {pos: [7, 0, 5], state: "minecraft:grass_block{snowy:true}"},
        {pos: [7, 0, 6], state: "minecraft:grass_block{snowy:true}"},
        {pos: [0, 1, 0], state: "minecraft:snow{layers:1}"},
        {pos: [0, 1, 1], state: "minecraft:snow{layers:1}"},
        {pos: [0, 1, 2], state: "minecraft:snow{layers:4}"},
        {pos: [0, 1, 3], state: "minecraft:jigsaw{orientation:west_up}", nbt: {final_state: "minecraft:structure_void", id: "minecraft:jigsaw", joint: "aligned", name: "minecraft:building_entrance", pool: "minecraft:empty", target: "minecraft:building_entrance"}},
        {pos: [0, 1, 4], state: "minecraft:snow{layers:8}"},
        {pos: [0, 1, 5], state: "minecraft:snow{layers:1}"},
        {pos: [0, 1, 6], state: "minecraft:snow{layers:1}"},
        {pos: [1, 1, 0], state: "minecraft:snow{layers:1}"},
        {pos: [1, 1, 1], state: "minecraft:snow_block"},
        {pos: [1, 1, 2], state: "minecraft:snow_block"},
        {pos: [1, 1, 3], state: "minecraft:spruce_door{facing:west,half:lower,hinge:right,open:false,powered:false}"},
        {pos: [1, 1, 4], state: "minecraft:snow_block"},
        {pos: [1, 1, 5], state: "minecraft:snow_block"},
        {pos: [1, 1, 6], state: "minecraft:snow{layers:1}"},
        {pos: [2, 1, 0], state: "minecraft:snow{layers:6}"},
        {pos: [2, 1, 1], state: "minecraft:snow_block"},
        {pos: [2, 1, 2], state: "minecraft:air"},
        {pos: [2, 1, 3], state: "minecraft:air"},
        {pos: [2, 1, 4], state: "minecraft:spruce_stairs{facing:south,half:bottom,shape:straight,waterlogged:false}"},
        {pos: [2, 1, 5], state: "minecraft:snow_block"},
        {pos: [2, 1, 6], state: "minecraft:snow{layers:1}"},
        {pos: [3, 1, 0], state: "minecraft:snow_block"},
        {pos: [3, 1, 1], state: "minecraft:snow_block"},
        {pos: [3, 1, 2], state: "minecraft:white_bed{facing:east,occupied:false,part:foot}", nbt: {id: "minecraft:bed"}},
        {pos: [3, 1, 3], state: "minecraft:air"},
        {pos: [3, 1, 4], state: "minecraft:furnace{facing:north,lit:false}", nbt: {BurnTime: 0s, CookTime: 0s, CookTimeTotal: 0s, Items: [], RecipesUsed: {}, id: "minecraft:furnace"}},
        {pos: [3, 1, 5], state: "minecraft:snow_block"},
        {pos: [3, 1, 6], state: "minecraft:snow{layers:5}"},
        {pos: [4, 1, 0], state: "minecraft:snow{layers:5}"},
        {pos: [4, 1, 1], state: "minecraft:snow_block"},
        {pos: [4, 1, 2], state: "minecraft:white_bed{facing:east,occupied:false,part:head}", nbt: {id: "minecraft:bed"}},
        {pos: [4, 1, 3], state: "minecraft:air"},
        {pos: [4, 1, 4], state: "minecraft:spruce_stairs{facing:south,half:bottom,shape:straight,waterlogged:false}"},
        {pos: [4, 1, 5], state: "minecraft:snow_block"},
        {pos: [4, 1, 6], state: "minecraft:snow{layers:1}"},
        {pos: [5, 1, 0], state: "minecraft:snow{layers:1}"},
        {pos: [5, 1, 1], state: "minecraft:snow{layers:7}"},
        {pos: [5, 1, 2], state: "minecraft:snow_block"},
        {pos: [5, 1, 3], state: "minecraft:air"},
        {pos: [5, 1, 4], state: "minecraft:snow_block"},
        {pos: [5, 1, 5], state: "minecraft:snow{layers:1}"},
        {pos: [5, 1, 6], state: "minecraft:snow{layers:1}"},
        {pos: [6, 1, 0], state: "minecraft:snow{layers:1}"},
        {pos: [6, 1, 1], state: "minecraft:snow{layers:4}"},
        {pos: [6, 1, 2], state: "minecraft:snow_block"},
        {pos: [6, 1, 3], state: "minecraft:air"},
        {pos: [6, 1, 4], state: "minecraft:snow_block"},
        {pos: [6, 1, 5], state: "minecraft:snow{layers:6}"},
        {pos: [6, 1, 6], state: "minecraft:snow{layers:1}"},
        {pos: [7, 1, 0], state: "minecraft:snow{layers:1}"},
        {pos: [7, 1, 1], state: "minecraft:snow{layers:1}"},
        {pos: [7, 1, 2], state: "minecraft:snow{layers:8}"},
        {pos: [7, 1, 3], state: "minecraft:snow_block"},
        {pos: [7, 1, 4], state: "minecraft:snow{layers:1}"},
        {pos: [7, 1, 5], state: "minecraft:snow{layers:1}"},
        {pos: [7, 1, 6], state: "minecraft:snow{layers:1}"},
        {pos: [0, 2, 0], state: "minecraft:air"},
        {pos: [0, 2, 1], state: "minecraft:air"},
        {pos: [0, 2, 2], state: "minecraft:air"},
        {pos: [0, 2, 3], state: "minecraft:air"},
        {pos: [0, 2, 4], state: "minecraft:air"},
        {pos: [0, 2, 5], state: "minecraft:air"},
        {pos: [0, 2, 6], state: "minecraft:air"},
        {pos: [1, 2, 0], state: "minecraft:air"},
        {pos: [1, 2, 1], state: "minecraft:air"},
        {pos: [1, 2, 2], state: "minecraft:snow_block"},
        {pos: [1, 2, 3], state: "minecraft:spruce_door{facing:west,half:upper,hinge:right,open:false,powered:false}"},
        {pos: [1, 2, 4], state: "minecraft:snow_block"},
        {pos: [1, 2, 5], state: "minecraft:snow{layers:2}"},
        {pos: [1, 2, 6], state: "minecraft:air"},
        {pos: [2, 2, 0], state: "minecraft:air"},
        {pos: [2, 2, 1], state: "minecraft:snow_block"},
        {pos: [2, 2, 2], state: "minecraft:wall_torch{facing:east}"},
        {pos: [2, 2, 3], state: "minecraft:air"},
        {pos: [2, 2, 4], state: "minecraft:wall_torch{facing:east}"},
        {pos: [2, 2, 5], state: "minecraft:snow_block"},
        {pos: [2, 2, 6], state: "minecraft:air"},
        {pos: [3, 2, 0], state: "minecraft:air"},
        {pos: [3, 2, 1], state: "minecraft:snow_block"},
        {pos: [3, 2, 2], state: "minecraft:air"},
        {pos: [3, 2, 3], state: "minecraft:air"},
        {pos: [3, 2, 4], state: "minecraft:air"},
        {pos: [3, 2, 5], state: "minecraft:snow_block"},
        {pos: [3, 2, 6], state: "minecraft:air"},
        {pos: [4, 2, 0], state: "minecraft:air"},
        {pos: [4, 2, 1], state: "minecraft:snow_block"},
        {pos: [4, 2, 2], state: "minecraft:air"},
        {pos: [4, 2, 3], state: "minecraft:air"},
        {pos: [4, 2, 4], state: "minecraft:air"},
        {pos: [4, 2, 5], state: "minecraft:snow_block"},
        {pos: [4, 2, 6], state: "minecraft:air"},
        {pos: [5, 2, 0], state: "minecraft:air"},
        {pos: [5, 2, 1], state: "minecraft:air"},
        {pos: [5, 2, 2], state: "minecraft:snow_block"},
        {pos: [5, 2, 3], state: "minecraft:air"},
        {pos: [5, 2, 4], state: "minecraft:snow_block"},
        {pos: [5, 2, 5], state: "minecraft:air"},
        {pos: [5, 2, 6], state: "minecraft:air"},
        {pos: [6, 2, 0], state: "minecraft:air"},
        {pos: [6, 2, 1], state: "minecraft:air"},
        {pos: [6, 2, 2], state: "minecraft:snow_block"},
        {pos: [6, 2, 3], state: "minecraft:lantern{hanging:true,waterlogged:false}"},
        {pos: [6, 2, 4], state: "minecraft:snow_block"},
        {pos: [6, 2, 5], state: "minecraft:air"},
        {pos: [6, 2, 6], state: "minecraft:air"},
        {pos: [7, 2, 0], state: "minecraft:air"},
        {pos: [7, 2, 1], state: "minecraft:air"},
        {pos: [7, 2, 2], state: "minecraft:air"},
        {pos: [7, 2, 3], state: "minecraft:snow_block"},
        {pos: [7, 2, 4], state: "minecraft:air"},
        {pos: [7, 2, 5], state: "minecraft:air"},
        {pos: [7, 2, 6], state: "minecraft:air"},
        {pos: [0, 3, 0], state: "minecraft:air"},
        {pos: [0, 3, 1], state: "minecraft:air"},
        {pos: [0, 3, 2], state: "minecraft:air"},
        {pos: [0, 3, 3], state: "minecraft:air"},
        {pos: [0, 3, 4], state: "minecraft:air"},
        {pos: [0, 3, 5], state: "minecraft:air"},
        {pos: [0, 3, 6], state: "minecraft:air"},
        {pos: [1, 3, 0], state: "minecraft:air"},
        {pos: [1, 3, 1], state: "minecraft:air"},
        {pos: [1, 3, 2], state: "minecraft:snow_block"},
        {pos: [1, 3, 3], state: "minecraft:snow_block"},
        {pos: [1, 3, 4], state: "minecraft:snow_block"},
        {pos: [1, 3, 5], state: "minecraft:air"},
        {pos: [1, 3, 6], state: "minecraft:air"},
        {pos: [2, 3, 0], state: "minecraft:air"},
        {pos: [2, 3, 1], state: "minecraft:air"},
        {pos: [2, 3, 2], state: "minecraft:snow_block"},
        {pos: [2, 3, 3], state: "minecraft:snow_block"},
        {pos: [2, 3, 4], state: "minecraft:snow_block"},
        {pos: [2, 3, 5], state: "minecraft:snow{layers:1}"},
        {pos: [2, 3, 6], state: "minecraft:air"},
        {pos: [3, 3, 0], state: "minecraft:air"},
        {pos: [3, 3, 1], state: "minecraft:air"},
        {pos: [3, 3, 2], state: "minecraft:snow_block"},
        {pos: [3, 3, 3], state: "minecraft:snow_block"},
        {pos: [3, 3, 4], state: "minecraft:snow_block"},
        {pos: [3, 3, 5], state: "minecraft:snow{layers:1}"},
        {pos: [3, 3, 6], state: "minecraft:air"},
        {pos: [4, 3, 0], state: "minecraft:air"},
        {pos: [4, 3, 1], state: "minecraft:air"},
        {pos: [4, 3, 2], state: "minecraft:snow_block"},
        {pos: [4, 3, 3], state: "minecraft:snow_block"},
        {pos: [4, 3, 4], state: "minecraft:snow_block"},
        {pos: [4, 3, 5], state: "minecraft:snow{layers:1}"},
        {pos: [4, 3, 6], state: "minecraft:air"},
        {pos: [5, 3, 0], state: "minecraft:air"},
        {pos: [5, 3, 1], state: "minecraft:air"},
        {pos: [5, 3, 2], state: "minecraft:snow{layers:1}"},
        {pos: [5, 3, 3], state: "minecraft:snow_block"},
        {pos: [5, 3, 4], state: "minecraft:snow{layers:1}"},
        {pos: [5, 3, 5], state: "minecraft:air"},
        {pos: [5, 3, 6], state: "minecraft:air"},
        {pos: [6, 3, 0], state: "minecraft:air"},
        {pos: [6, 3, 1], state: "minecraft:air"},
        {pos: [6, 3, 2], state: "minecraft:snow{layers:1}"},
        {pos: [6, 3, 3], state: "minecraft:snow_block"},
        {pos: [6, 3, 4], state: "minecraft:snow{layers:1}"},
        {pos: [6, 3, 5], state: "minecraft:air"},
        {pos: [6, 3, 6], state: "minecraft:air"},
        {pos: [7, 3, 0], state: "minecraft:air"},
        {pos: [7, 3, 1], state: "minecraft:air"},
        {pos: [7, 3, 2], state: "minecraft:air"},
        {pos: [7, 3, 3], state: "minecraft:snow{layers:1}"},
        {pos: [7, 3, 4], state: "minecraft:air"},
        {pos: [7, 3, 5], state: "minecraft:air"},
        {pos: [7, 3, 6], state: "minecraft:air"},
        {pos: [0, 4, 0], state: "minecraft:air"},
        {pos: [0, 4, 1], state: "minecraft:air"},
        {pos: [0, 4, 2], state: "minecraft:air"},
        {pos: [0, 4, 3], state: "minecraft:air"},
        {pos: [0, 4, 4], state: "minecraft:air"},
        {pos: [0, 4, 5], state: "minecraft:air"},
        {pos: [0, 4, 6], state: "minecraft:air"},
        {pos: [1, 4, 0], state: "minecraft:air"},
        {pos: [1, 4, 1], state: "minecraft:air"},
        {pos: [1, 4, 2], state: "minecraft:air"},
        {pos: [1, 4, 3], state: "minecraft:air"},
        {pos: [1, 4, 4], state: "minecraft:snow{layers:1}"},
        {pos: [1, 4, 5], state: "minecraft:air"},
        {pos: [1, 4, 6], state: "minecraft:air"},
        {pos: [2, 4, 0], state: "minecraft:air"},
        {pos: [2, 4, 1], state: "minecraft:air"},
        {pos: [2, 4, 2], state: "minecraft:air"},
        {pos: [2, 4, 3], state: "minecraft:snow_block"},
        {pos: [2, 4, 4], state: "minecraft:air"},
        {pos: [2, 4, 5], state: "minecraft:air"},
        {pos: [2, 4, 6], state: "minecraft:air"},
        {pos: [3, 4, 0], state: "minecraft:air"},
        {pos: [3, 4, 1], state: "minecraft:air"},
        {pos: [3, 4, 2], state: "minecraft:snow{layers:3}"},
        {pos: [3, 4, 3], state: "minecraft:snow_block"},
        {pos: [3, 4, 4], state: "minecraft:air"},
        {pos: [3, 4, 5], state: "minecraft:air"},
        {pos: [3, 4, 6], state: "minecraft:air"},
        {pos: [4, 4, 0], state: "minecraft:air"},
        {pos: [4, 4, 1], state: "minecraft:air"},
        {pos: [4, 4, 2], state: "minecraft:snow{layers:1}"},
        {pos: [4, 4, 3], state: "minecraft:snow_block"},
        {pos: [4, 4, 4], state: "minecraft:air"},
        {pos: [4, 4, 5], state: "minecraft:air"},
        {pos: [4, 4, 6], state: "minecraft:air"},
        {pos: [5, 4, 0], state: "minecraft:air"},
        {pos: [5, 4, 1], state: "minecraft:air"},
        {pos: [5, 4, 2], state: "minecraft:air"},
        {pos: [5, 4, 3], state: "minecraft:air"},
        {pos: [5, 4, 4], state: "minecraft:air"},
        {pos: [5, 4, 5], state: "minecraft:air"},
        {pos: [5, 4, 6], state: "minecraft:air"},
        {pos: [6, 4, 0], state: "minecraft:air"},
        {pos: [6, 4, 1], state: "minecraft:air"},
        {pos: [6, 4, 2], state: "minecraft:air"},
        {pos: [6, 4, 3], state: "minecraft:snow{layers:1}"},
        {pos: [6, 4, 4], state: "minecraft:air"},
        {pos: [6, 4, 5], state: "minecraft:air"},
        {pos: [6, 4, 6], state: "minecraft:air"},
        {pos: [7, 4, 0], state: "minecraft:air"},
        {pos: [7, 4, 1], state: "minecraft:air"},
        {pos: [7, 4, 2], state: "minecraft:air"},
        {pos: [7, 4, 3], state: "minecraft:air"},
        {pos: [7, 4, 4], state: "minecraft:air"},
        {pos: [7, 4, 5], state: "minecraft:air"},
        {pos: [7, 4, 6], state: "minecraft:air"}
    ],
    entities: [],
    palette: [
        "minecraft:grass_block{snowy:true}",
        "minecraft:dirt",
        "minecraft:grass_block{snowy:false}",
        "minecraft:snow_block",
        "minecraft:snow{layers:1}",
        "minecraft:snow{layers:4}",
        "minecraft:snow{layers:8}",
        "minecraft:spruce_door{facing:west,half:lower,hinge:right,open:false,powered:false}",
        "minecraft:snow{layers:6}",
        "minecraft:air",
        "minecraft:spruce_stairs{facing:south,half:bottom,shape:straight,waterlogged:false}",
        "minecraft:snow{layers:5}",
        "minecraft:snow{layers:7}",
        "minecraft:spruce_door{facing:west,half:upper,hinge:right,open:false,powered:false}",
        "minecraft:snow{layers:2}",
        "minecraft:wall_torch{facing:east}",
        "minecraft:lantern{hanging:true,waterlogged:false}",
        "minecraft:snow{layers:3}",
        "minecraft:jigsaw{orientation:up_north}",
        "minecraft:jigsaw{orientation:west_up}",
        "minecraft:white_bed{facing:east,occupied:false,part:foot}",
        "minecraft:furnace{facing:north,lit:false}",
        "minecraft:white_bed{facing:east,occupied:false,part:head}"
    ]
}
