{
    DataVersion: 2856,
    size: [6, 7, 7],
    data: [
        {pos: [0, 0, 0], state: "minecraft:air"},
        {pos: [0, 0, 1], state: "minecraft:spruce_fence{east:true,north:false,south:false,waterlogged:false,west:false}"},
        {pos: [0, 0, 2], state: "minecraft:spruce_stairs{facing:south,half:bottom,shape:outer_left,waterlogged:false}"},
        {pos: [0, 0, 3], state: "minecraft:jigsaw{orientation:west_up}", nbt: {final_state: "minecraft:spruce_stairs[facing=east]", id: "minecraft:jigsaw", joint: "aligned", name: "minecraft:building_entrance", pool: "minecraft:empty", target: "minecraft:building_entrance"}},
        {pos: [0, 0, 4], state: "minecraft:spruce_stairs{facing:north,half:bottom,shape:outer_right,waterlogged:false}"},
        {pos: [0, 0, 5], state: "minecraft:spruce_fence{east:true,north:false,south:false,waterlogged:false,west:false}"},
        {pos: [0, 0, 6], state: "minecraft:air"},
        {pos: [1, 0, 0], state: "minecraft:air"},
        {pos: [1, 0, 1], state: "minecraft:stripped_spruce_log{axis:y}"},
        {pos: [1, 0, 2], state: "minecraft:stripped_spruce_log{axis:y}"},
        {pos: [1, 0, 3], state: "minecraft:stripped_spruce_log{axis:y}"},
        {pos: [1, 0, 4], state: "minecraft:stripped_spruce_log{axis:y}"},
        {pos: [1, 0, 5], state: "minecraft:stripped_spruce_log{axis:y}"},
        {pos: [1, 0, 6], state: "minecraft:air"},
        {pos: [2, 0, 0], state: "minecraft:snow{layers:1}"},
        {pos: [2, 0, 1], state: "minecraft:stripped_spruce_log{axis:y}"},
        {pos: [2, 0, 2], state: "minecraft:stripped_spruce_log{axis:y}"},
        {pos: [2, 0, 3], state: "minecraft:jigsaw{orientation:up_north}", nbt: {final_state: "minecraft:stripped_spruce_log", id: "minecraft:jigsaw", joint: "rollable", name: "minecraft:bottom", pool: "minecraft:village/snowy/villagers", target: "minecraft:bottom"}},
        {pos: [2, 0, 4], state: "minecraft:stripped_spruce_log{axis:y}"},
        {pos: [2, 0, 5], state: "minecraft:stripped_spruce_log{axis:y}"},
        {pos: [2, 0, 6], state: "minecraft:snow{layers:1}"},
        {pos: [3, 0, 0], state: "minecraft:snow{layers:1}"},
        {pos: [3, 0, 1], state: "minecraft:stripped_spruce_log{axis:y}"},
        {pos: [3, 0, 2], state: "minecraft:stripped_spruce_log{axis:y}"},
        {pos: [3, 0, 3], state: "minecraft:stripped_spruce_log{axis:y}"},
        {pos: [3, 0, 4], state: "minecraft:stripped_spruce_log{axis:y}"},
        {pos: [3, 0, 5], state: "minecraft:stripped_spruce_log{axis:y}"},
        {pos: [3, 0, 6], state: "minecraft:snow{layers:1}"},
        {pos: [4, 0, 0], state: "minecraft:snow{layers:1}"},
        {pos: [4, 0, 1], state: "minecraft:stripped_spruce_log{axis:y}"},
        {pos: [4, 0, 2], state: "minecraft:stripped_spruce_log{axis:y}"},
        {pos: [4, 0, 3], state: "minecraft:stripped_spruce_log{axis:y}"},
        {pos: [4, 0, 4], state: "minecraft:stripped_spruce_log{axis:y}"},
        {pos: [4, 0, 5], state: "minecraft:stripped_spruce_log{axis:y}"},
        {pos: [4, 0, 6], state: "minecraft:snow{layers:1}"},
        {pos: [5, 0, 0], state: "minecraft:snow{layers:1}"},
        {pos: [5, 0, 1], state: "minecraft:snow{layers:1}"},
        {pos: [5, 0, 2], state: "minecraft:snow{layers:1}"},
        {pos: [5, 0, 3], state: "minecraft:snow{layers:1}"},
        {pos: [5, 0, 4], state: "minecraft:snow{layers:1}"},
        {pos: [5, 0, 5], state: "minecraft:snow{layers:1}"},
        {pos: [5, 0, 6], state: "minecraft:snow{layers:1}"},
        {pos: [0, 1, 0], state: "minecraft:spruce_slab{type:top,waterlogged:false}"},
        {pos: [0, 1, 1], state: "minecraft:lantern{hanging:false,waterlogged:false}"},
        {pos: [0, 1, 2], state: "minecraft:air"},
        {pos: [0, 1, 3], state: "minecraft:air"},
        {pos: [0, 1, 4], state: "minecraft:air"},
        {pos: [0, 1, 5], state: "minecraft:lantern{hanging:false,waterlogged:false}"},
        {pos: [0, 1, 6], state: "minecraft:spruce_slab{type:top,waterlogged:false}"},
        {pos: [1, 1, 0], state: "minecraft:air"},
        {pos: [1, 1, 1], state: "minecraft:stripped_spruce_log{axis:y}"},
        {pos: [1, 1, 2], state: "minecraft:stripped_spruce_log{axis:y}"},
        {pos: [1, 1, 3], state: "minecraft:spruce_door{facing:east,half:lower,hinge:left,open:false,powered:false}"},
        {pos: [1, 1, 4], state: "minecraft:stripped_spruce_log{axis:y}"},
        {pos: [1, 1, 5], state: "minecraft:stripped_spruce_log{axis:y}"},
        {pos: [1, 1, 6], state: "minecraft:air"},
        {pos: [2, 1, 0], state: "minecraft:spruce_slab{type:top,waterlogged:false}"},
        {pos: [2, 1, 1], state: "minecraft:stripped_spruce_log{axis:y}"},
        {pos: [2, 1, 2], state: "minecraft:white_bed{facing:east,occupied:false,part:foot}", nbt: {id: "minecraft:bed"}},
        {pos: [2, 1, 3], state: "minecraft:air"},
        {pos: [2, 1, 4], state: "minecraft:spruce_stairs{facing:south,half:bottom,shape:straight,waterlogged:false}"},
        {pos: [2, 1, 5], state: "minecraft:stripped_spruce_log{axis:y}"},
        {pos: [2, 1, 6], state: "minecraft:spruce_slab{type:top,waterlogged:false}"},
        {pos: [3, 1, 0], state: "minecraft:spruce_slab{type:top,waterlogged:false}"},
        {pos: [3, 1, 1], state: "minecraft:stripped_spruce_log{axis:y}"},
        {pos: [3, 1, 2], state: "minecraft:white_bed{facing:east,occupied:false,part:head}", nbt: {id: "minecraft:bed"}},
        {pos: [3, 1, 3], state: "minecraft:air"},
        {pos: [3, 1, 4], state: "minecraft:spruce_stairs{facing:south,half:bottom,shape:straight,waterlogged:false}"},
        {pos: [3, 1, 5], state: "minecraft:stripped_spruce_log{axis:y}"},
        {pos: [3, 1, 6], state: "minecraft:spruce_slab{type:top,waterlogged:false}"},
        {pos: [4, 1, 0], state: "minecraft:air"},
        {pos: [4, 1, 1], state: "minecraft:stripped_spruce_log{axis:y}"},
        {pos: [4, 1, 2], state: "minecraft:stripped_spruce_log{axis:y}"},
        {pos: [4, 1, 3], state: "minecraft:stripped_spruce_log{axis:x}"},
        {pos: [4, 1, 4], state: "minecraft:stripped_spruce_log{axis:y}"},
        {pos: [4, 1, 5], state: "minecraft:stripped_spruce_log{axis:y}"},
        {pos: [4, 1, 6], state: "minecraft:air"},
        {pos: [5, 1, 0], state: "minecraft:spruce_slab{type:top,waterlogged:false}"},
        {pos: [5, 1, 1], state: "minecraft:air"},
        {pos: [5, 1, 2], state: "minecraft:air"},
        {pos: [5, 1, 3], state: "minecraft:air"},
        {pos: [5, 1, 4], state: "minecraft:air"},
        {pos: [5, 1, 5], state: "minecraft:air"},
        {pos: [5, 1, 6], state: "minecraft:spruce_slab{type:top,waterlogged:false}"},
        {pos: [0, 2, 0], state: "minecraft:spruce_planks"},
        {pos: [0, 2, 1], state: "minecraft:air"},
        {pos: [0, 2, 2], state: "minecraft:air"},
        {pos: [0, 2, 3], state: "minecraft:air"},
        {pos: [0, 2, 4], state: "minecraft:air"},
        {pos: [0, 2, 5], state: "minecraft:air"},
        {pos: [0, 2, 6], state: "minecraft:spruce_planks"},
        {pos: [1, 2, 0], state: "minecraft:spruce_planks"},
        {pos: [1, 2, 1], state: "minecraft:stripped_spruce_log{axis:y}"},
        {pos: [1, 2, 2], state: "minecraft:stripped_spruce_log{axis:y}"},
        {pos: [1, 2, 3], state: "minecraft:spruce_door{facing:east,half:upper,hinge:left,open:false,powered:false}"},
        {pos: [1, 2, 4], state: "minecraft:stripped_spruce_log{axis:y}"},
        {pos: [1, 2, 5], state: "minecraft:stripped_spruce_log{axis:y}"},
        {pos: [1, 2, 6], state: "minecraft:spruce_planks"},
        {pos: [2, 2, 0], state: "minecraft:spruce_planks"},
        {pos: [2, 2, 1], state: "minecraft:stripped_spruce_log{axis:y}"},
        {pos: [2, 2, 2], state: "minecraft:air"},
        {pos: [2, 2, 3], state: "minecraft:air"},
        {pos: [2, 2, 4], state: "minecraft:air"},
        {pos: [2, 2, 5], state: "minecraft:stripped_spruce_log{axis:y}"},
        {pos: [2, 2, 6], state: "minecraft:spruce_planks"},
        {pos: [3, 2, 0], state: "minecraft:spruce_planks"},
        {pos: [3, 2, 1], state: "minecraft:stripped_spruce_log{axis:y}"},
        {pos: [3, 2, 2], state: "minecraft:air"},
        {pos: [3, 2, 3], state: "minecraft:air"},
        {pos: [3, 2, 4], state: "minecraft:air"},
        {pos: [3, 2, 5], state: "minecraft:stripped_spruce_log{axis:y}"},
        {pos: [3, 2, 6], state: "minecraft:spruce_planks"},
        {pos: [4, 2, 0], state: "minecraft:spruce_planks"},
        {pos: [4, 2, 1], state: "minecraft:stripped_spruce_log{axis:y}"},
        {pos: [4, 2, 2], state: "minecraft:stripped_spruce_log{axis:x}"},
        {pos: [4, 2, 3], state: "minecraft:glass_pane{east:false,north:true,south:true,waterlogged:false,west:false}"},
        {pos: [4, 2, 4], state: "minecraft:stripped_spruce_log{axis:x}"},
        {pos: [4, 2, 5], state: "minecraft:stripped_spruce_log{axis:y}"},
        {pos: [4, 2, 6], state: "minecraft:spruce_planks"},
        {pos: [5, 2, 0], state: "minecraft:spruce_planks"},
        {pos: [5, 2, 1], state: "minecraft:air"},
        {pos: [5, 2, 2], state: "minecraft:air"},
        {pos: [5, 2, 3], state: "minecraft:air"},
        {pos: [5, 2, 4], state: "minecraft:air"},
        {pos: [5, 2, 5], state: "minecraft:air"},
        {pos: [5, 2, 6], state: "minecraft:spruce_planks"},
        {pos: [0, 3, 0], state: "minecraft:spruce_slab{type:bottom,waterlogged:false}"},
        {pos: [0, 3, 1], state: "minecraft:spruce_planks"},
        {pos: [0, 3, 2], state: "minecraft:air"},
        {pos: [0, 3, 3], state: "minecraft:air"},
        {pos: [0, 3, 4], state: "minecraft:air"},
        {pos: [0, 3, 5], state: "minecraft:spruce_planks"},
        {pos: [0, 3, 6], state: "minecraft:spruce_slab{type:bottom,waterlogged:false}"},
        {pos: [1, 3, 0], state: "minecraft:air"},
        {pos: [1, 3, 1], state: "minecraft:spruce_planks"},
        {pos: [1, 3, 2], state: "minecraft:stripped_spruce_log{axis:y}"},
        {pos: [1, 3, 3], state: "minecraft:stripped_spruce_log{axis:y}"},
        {pos: [1, 3, 4], state: "minecraft:stripped_spruce_log{axis:y}"},
        {pos: [1, 3, 5], state: "minecraft:spruce_planks"},
        {pos: [1, 3, 6], state: "minecraft:air"},
        {pos: [2, 3, 0], state: "minecraft:spruce_slab{type:bottom,waterlogged:false}"},
        {pos: [2, 3, 1], state: "minecraft:spruce_planks"},
        {pos: [2, 3, 2], state: "minecraft:air"},
        {pos: [2, 3, 3], state: "minecraft:air"},
        {pos: [2, 3, 4], state: "minecraft:air"},
        {pos: [2, 3, 5], state: "minecraft:spruce_planks"},
        {pos: [2, 3, 6], state: "minecraft:spruce_slab{type:bottom,waterlogged:false}"},
        {pos: [3, 3, 0], state: "minecraft:spruce_slab{type:bottom,waterlogged:false}"},
        {pos: [3, 3, 1], state: "minecraft:spruce_planks"},
        {pos: [3, 3, 2], state: "minecraft:air"},
        {pos: [3, 3, 3], state: "minecraft:air"},
        {pos: [3, 3, 4], state: "minecraft:air"},
        {pos: [3, 3, 5], state: "minecraft:spruce_planks"},
        {pos: [3, 3, 6], state: "minecraft:spruce_slab{type:bottom,waterlogged:false}"},
        {pos: [4, 3, 0], state: "minecraft:air"},
        {pos: [4, 3, 1], state: "minecraft:spruce_planks"},
        {pos: [4, 3, 2], state: "minecraft:stripped_spruce_log{axis:y}"},
        {pos: [4, 3, 3], state: "minecraft:stripped_spruce_log{axis:x}"},
        {pos: [4, 3, 4], state: "minecraft:stripped_spruce_log{axis:y}"},
        {pos: [4, 3, 5], state: "minecraft:spruce_planks"},
        {pos: [4, 3, 6], state: "minecraft:air"},
        {pos: [5, 3, 0], state: "minecraft:spruce_slab{type:bottom,waterlogged:false}"},
        {pos: [5, 3, 1], state: "minecraft:spruce_planks"},
        {pos: [5, 3, 2], state: "minecraft:air"},
        {pos: [5, 3, 3], state: "minecraft:air"},
        {pos: [5, 3, 4], state: "minecraft:air"},
        {pos: [5, 3, 5], state: "minecraft:spruce_planks"},
        {pos: [5, 3, 6], state: "minecraft:spruce_slab{type:bottom,waterlogged:false}"},
        {pos: [0, 4, 0], state: "minecraft:air"},
        {pos: [0, 4, 1], state: "minecraft:spruce_slab{type:bottom,waterlogged:false}"},
        {pos: [0, 4, 2], state: "minecraft:spruce_planks"},
        {pos: [0, 4, 3], state: "minecraft:air"},
        {pos: [0, 4, 4], state: "minecraft:spruce_planks"},
        {pos: [0, 4, 5], state: "minecraft:spruce_slab{type:bottom,waterlogged:false}"},
        {pos: [0, 4, 6], state: "minecraft:air"},
        {pos: [1, 4, 0], state: "minecraft:air"},
        {pos: [1, 4, 1], state: "minecraft:air"},
        {pos: [1, 4, 2], state: "minecraft:spruce_planks"},
        {pos: [1, 4, 3], state: "minecraft:stripped_spruce_log{axis:y}"},
        {pos: [1, 4, 4], state: "minecraft:spruce_planks"},
        {pos: [1, 4, 5], state: "minecraft:air"},
        {pos: [1, 4, 6], state: "minecraft:air"},
        {pos: [2, 4, 0], state: "minecraft:air"},
        {pos: [2, 4, 1], state: "minecraft:spruce_slab{type:bottom,waterlogged:false}"},
        {pos: [2, 4, 2], state: "minecraft:spruce_planks"},
        {pos: [2, 4, 3], state: "minecraft:air"},
        {pos: [2, 4, 4], state: "minecraft:spruce_planks"},
        {pos: [2, 4, 5], state: "minecraft:spruce_slab{type:bottom,waterlogged:false}"},
        {pos: [2, 4, 6], state: "minecraft:air"},
        {pos: [3, 4, 0], state: "minecraft:air"},
        {pos: [3, 4, 1], state: "minecraft:spruce_slab{type:bottom,waterlogged:false}"},
        {pos: [3, 4, 2], state: "minecraft:spruce_planks"},
        {pos: [3, 4, 3], state: "minecraft:lantern{hanging:true,waterlogged:false}"},
        {pos: [3, 4, 4], state: "minecraft:spruce_planks"},
        {pos: [3, 4, 5], state: "minecraft:spruce_slab{type:bottom,waterlogged:false}"},
        {pos: [3, 4, 6], state: "minecraft:air"},
        {pos: [4, 4, 0], state: "minecraft:air"},
        {pos: [4, 4, 1], state: "minecraft:air"},
        {pos: [4, 4, 2], state: "minecraft:spruce_planks"},
        {pos: [4, 4, 3], state: "minecraft:stripped_spruce_log{axis:y}"},
        {pos: [4, 4, 4], state: "minecraft:spruce_planks"},
        {pos: [4, 4, 5], state: "minecraft:air"},
        {pos: [4, 4, 6], state: "minecraft:air"},
        {pos: [5, 4, 0], state: "minecraft:air"},
        {pos: [5, 4, 1], state: "minecraft:spruce_slab{type:bottom,waterlogged:false}"},
        {pos: [5, 4, 2], state: "minecraft:spruce_planks"},
        {pos: [5, 4, 3], state: "minecraft:air"},
        {pos: [5, 4, 4], state: "minecraft:spruce_planks"},
        {pos: [5, 4, 5], state: "minecraft:spruce_slab{type:bottom,waterlogged:false}"},
        {pos: [5, 4, 6], state: "minecraft:air"},
        {pos: [0, 5, 0], state: "minecraft:air"},
        {pos: [0, 5, 1], state: "minecraft:air"},
        {pos: [0, 5, 2], state: "minecraft:spruce_slab{type:bottom,waterlogged:false}"},
        {pos: [0, 5, 3], state: "minecraft:spruce_planks"},
        {pos: [0, 5, 4], state: "minecraft:spruce_slab{type:bottom,waterlogged:false}"},
        {pos: [0, 5, 5], state: "minecraft:air"},
        {pos: [0, 5, 6], state: "minecraft:air"},
        {pos: [1, 5, 0], state: "minecraft:air"},
        {pos: [1, 5, 1], state: "minecraft:air"},
        {pos: [1, 5, 2], state: "minecraft:air"},
        {pos: [1, 5, 3], state: "minecraft:spruce_planks"},
        {pos: [1, 5, 4], state: "minecraft:air"},
        {pos: [1, 5, 5], state: "minecraft:air"},
        {pos: [1, 5, 6], state: "minecraft:air"},
        {pos: [2, 5, 0], state: "minecraft:air"},
        {pos: [2, 5, 1], state: "minecraft:air"},
        {pos: [2, 5, 2], state: "minecraft:spruce_slab{type:bottom,waterlogged:false}"},
        {pos: [2, 5, 3], state: "minecraft:spruce_planks"},
        {pos: [2, 5, 4], state: "minecraft:spruce_slab{type:bottom,waterlogged:false}"},
        {pos: [2, 5, 5], state: "minecraft:air"},
        {pos: [2, 5, 6], state: "minecraft:air"},
        {pos: [3, 5, 0], state: "minecraft:air"},
        {pos: [3, 5, 1], state: "minecraft:air"},
        {pos: [3, 5, 2], state: "minecraft:spruce_slab{type:bottom,waterlogged:false}"},
        {pos: [3, 5, 3], state: "minecraft:spruce_planks"},
        {pos: [3, 5, 4], state: "minecraft:spruce_slab{type:bottom,waterlogged:false}"},
        {pos: [3, 5, 5], state: "minecraft:air"},
        {pos: [3, 5, 6], state: "minecraft:air"},
        {pos: [4, 5, 0], state: "minecraft:air"},
        {pos: [4, 5, 1], state: "minecraft:air"},
        {pos: [4, 5, 2], state: "minecraft:air"},
        {pos: [4, 5, 3], state: "minecraft:spruce_planks"},
        {pos: [4, 5, 4], state: "minecraft:air"},
        {pos: [4, 5, 5], state: "minecraft:air"},
        {pos: [4, 5, 6], state: "minecraft:air"},
        {pos: [5, 5, 0], state: "minecraft:air"},
        {pos: [5, 5, 1], state: "minecraft:air"},
        {pos: [5, 5, 2], state: "minecraft:spruce_slab{type:bottom,waterlogged:false}"},
        {pos: [5, 5, 3], state: "minecraft:spruce_planks"},
        {pos: [5, 5, 4], state: "minecraft:spruce_slab{type:bottom,waterlogged:false}"},
        {pos: [5, 5, 5], state: "minecraft:air"},
        {pos: [5, 5, 6], state: "minecraft:air"},
        {pos: [0, 6, 0], state: "minecraft:air"},
        {pos: [0, 6, 1], state: "minecraft:air"},
        {pos: [0, 6, 2], state: "minecraft:air"},
        {pos: [0, 6, 3], state: "minecraft:spruce_slab{type:bottom,waterlogged:false}"},
        {pos: [0, 6, 4], state: "minecraft:air"},
        {pos: [0, 6, 5], state: "minecraft:air"},
        {pos: [0, 6, 6], state: "minecraft:air"},
        {pos: [1, 6, 0], state: "minecraft:air"},
        {pos: [1, 6, 1], state: "minecraft:air"},
        {pos: [1, 6, 2], state: "minecraft:air"},
        {pos: [1, 6, 3], state: "minecraft:air"},
        {pos: [1, 6, 4], state: "minecraft:air"},
        {pos: [1, 6, 5], state: "minecraft:air"},
        {pos: [1, 6, 6], state: "minecraft:air"},
        {pos: [2, 6, 0], state: "minecraft:air"},
        {pos: [2, 6, 1], state: "minecraft:air"},
        {pos: [2, 6, 2], state: "minecraft:air"},
        {pos: [2, 6, 3], state: "minecraft:spruce_slab{type:bottom,waterlogged:false}"},
        {pos: [2, 6, 4], state: "minecraft:air"},
        {pos: [2, 6, 5], state: "minecraft:air"},
        {pos: [2, 6, 6], state: "minecraft:air"},
        {pos: [3, 6, 0], state: "minecraft:air"},
        {pos: [3, 6, 1], state: "minecraft:air"},
        {pos: [3, 6, 2], state: "minecraft:air"},
        {pos: [3, 6, 3], state: "minecraft:spruce_slab{type:bottom,waterlogged:false}"},
        {pos: [3, 6, 4], state: "minecraft:air"},
        {pos: [3, 6, 5], state: "minecraft:air"},
        {pos: [3, 6, 6], state: "minecraft:air"},
        {pos: [4, 6, 0], state: "minecraft:air"},
        {pos: [4, 6, 1], state: "minecraft:air"},
        {pos: [4, 6, 2], state: "minecraft:air"},
        {pos: [4, 6, 3], state: "minecraft:air"},
        {pos: [4, 6, 4], state: "minecraft:air"},
        {pos: [4, 6, 5], state: "minecraft:air"},
        {pos: [4, 6, 6], state: "minecraft:air"},
        {pos: [5, 6, 0], state: "minecraft:air"},
        {pos: [5, 6, 1], state: "minecraft:air"},
        {pos: [5, 6, 2], state: "minecraft:air"},
        {pos: [5, 6, 3], state: "minecraft:spruce_slab{type:bottom,waterlogged:false}"},
        {pos: [5, 6, 4], state: "minecraft:air"},
        {pos: [5, 6, 5], state: "minecraft:air"},
        {pos: [5, 6, 6], state: "minecraft:air"}
    ],
    entities: [],
    palette: [
        "minecraft:stripped_spruce_log{axis:y}",
        "minecraft:stripped_spruce_log{axis:x}",
        "minecraft:spruce_planks",
        "minecraft:air",
        "minecraft:spruce_fence{east:true,north:false,south:false,waterlogged:false,west:false}",
        "minecraft:spruce_stairs{facing:south,half:bottom,shape:outer_left,waterlogged:false}",
        "minecraft:spruce_stairs{facing:north,half:bottom,shape:outer_right,waterlogged:false}",
        "minecraft:snow{layers:1}",
        "minecraft:spruce_slab{type:top,waterlogged:false}",
        "minecraft:lantern{hanging:false,waterlogged:false}",
        "minecraft:spruce_door{facing:east,half:lower,hinge:left,open:false,powered:false}",
        "minecraft:spruce_stairs{facing:south,half:bottom,shape:straight,waterlogged:false}",
        "minecraft:spruce_door{facing:east,half:upper,hinge:left,open:false,powered:false}",
        "minecraft:glass_pane{east:false,north:true,south:true,waterlogged:false,west:false}",
        "minecraft:spruce_slab{type:bottom,waterlogged:false}",
        "minecraft:lantern{hanging:true,waterlogged:false}",
        "minecraft:jigsaw{orientation:west_up}",
        "minecraft:jigsaw{orientation:up_north}",
        "minecraft:white_bed{facing:east,occupied:false,part:foot}",
        "minecraft:white_bed{facing:east,occupied:false,part:head}"
    ]
}
