{
    DataVersion: 2856,
    size: [7, 5, 6],
    data: [
        {pos: [0, 0, 0], state: "minecraft:grass_block{snowy:true}"},
        {pos: [0, 0, 1], state: "minecraft:grass_block{snowy:true}"},
        {pos: [0, 0, 2], state: "minecraft:grass_block{snowy:true}"},
        {pos: [0, 0, 3], state: "minecraft:grass_block{snowy:true}"},
        {pos: [0, 0, 4], state: "minecraft:grass_block{snowy:true}"},
        {pos: [0, 0, 5], state: "minecraft:grass_block{snowy:false}"},
        {pos: [1, 0, 0], state: "minecraft:grass_block{snowy:true}"},
        {pos: [1, 0, 1], state: "minecraft:dirt"},
        {pos: [1, 0, 2], state: "minecraft:dirt"},
        {pos: [1, 0, 3], state: "minecraft:dirt"},
        {pos: [1, 0, 4], state: "minecraft:grass_block{snowy:true}"},
        {pos: [1, 0, 5], state: "minecraft:grass_block{snowy:true}"},
        {pos: [2, 0, 0], state: "minecraft:dirt"},
        {pos: [2, 0, 1], state: "minecraft:dirt"},
        {pos: [2, 0, 2], state: "minecraft:grass_block{snowy:false}"},
        {pos: [2, 0, 3], state: "minecraft:grass_block{snowy:false}"},
        {pos: [2, 0, 4], state: "minecraft:dirt"},
        {pos: [2, 0, 5], state: "minecraft:grass_block{snowy:true}"},
        {pos: [3, 0, 0], state: "minecraft:dirt"},
        {pos: [3, 0, 1], state: "minecraft:grass_block{snowy:false}"},
        {pos: [3, 0, 2], state: "minecraft:jigsaw{orientation:up_north}", nbt: {final_state: "minecraft:grass_block", id: "minecraft:jigsaw", joint: "rollable", name: "minecraft:bottom", pool: "minecraft:village/snowy/villagers", target: "minecraft:bottom"}},
        {pos: [3, 0, 3], state: "minecraft:grass_block{snowy:false}"},
        {pos: [3, 0, 4], state: "minecraft:grass_block{snowy:false}"},
        {pos: [3, 0, 5], state: "minecraft:grass_block{snowy:false}"},
        {pos: [4, 0, 0], state: "minecraft:dirt"},
        {pos: [4, 0, 1], state: "minecraft:grass_block{snowy:false}"},
        {pos: [4, 0, 2], state: "minecraft:grass_block{snowy:false}"},
        {pos: [4, 0, 3], state: "minecraft:grass_block{snowy:false}"},
        {pos: [4, 0, 4], state: "minecraft:dirt"},
        {pos: [4, 0, 5], state: "minecraft:grass_block{snowy:true}"},
        {pos: [5, 0, 0], state: "minecraft:grass_block{snowy:true}"},
        {pos: [5, 0, 1], state: "minecraft:dirt"},
        {pos: [5, 0, 2], state: "minecraft:dirt"},
        {pos: [5, 0, 3], state: "minecraft:dirt"},
        {pos: [5, 0, 4], state: "minecraft:dirt"},
        {pos: [5, 0, 5], state: "minecraft:grass_block{snowy:true}"},
        {pos: [6, 0, 0], state: "minecraft:grass_block{snowy:true}"},
        {pos: [6, 0, 1], state: "minecraft:grass_block{snowy:true}"},
        {pos: [6, 0, 2], state: "minecraft:grass_block{snowy:true}"},
        {pos: [6, 0, 3], state: "minecraft:grass_block{snowy:true}"},
        {pos: [6, 0, 4], state: "minecraft:grass_block{snowy:true}"},
        {pos: [6, 0, 5], state: "minecraft:grass_block{snowy:true}"},
        {pos: [0, 1, 0], state: "minecraft:snow{layers:1}"},
        {pos: [0, 1, 1], state: "minecraft:snow{layers:1}"},
        {pos: [0, 1, 2], state: "minecraft:snow{layers:1}"},
        {pos: [0, 1, 3], state: "minecraft:snow{layers:5}"},
        {pos: [0, 1, 4], state: "minecraft:snow{layers:3}"},
        {pos: [0, 1, 5], state: "minecraft:grass"},
        {pos: [1, 1, 0], state: "minecraft:snow{layers:1}"},
        {pos: [1, 1, 1], state: "minecraft:packed_ice"},
        {pos: [1, 1, 2], state: "minecraft:packed_ice"},
        {pos: [1, 1, 3], state: "minecraft:packed_ice"},
        {pos: [1, 1, 4], state: "minecraft:snow{layers:5}"},
        {pos: [1, 1, 5], state: "minecraft:snow{layers:1}"},
        {pos: [2, 1, 0], state: "minecraft:packed_ice"},
        {pos: [2, 1, 1], state: "minecraft:stripped_spruce_log{axis:y}"},
        {pos: [2, 1, 2], state: "minecraft:air"},
        {pos: [2, 1, 3], state: "minecraft:air"},
        {pos: [2, 1, 4], state: "minecraft:packed_ice"},
        {pos: [2, 1, 5], state: "minecraft:snow{layers:2}"},
        {pos: [3, 1, 0], state: "minecraft:packed_ice"},
        {pos: [3, 1, 1], state: "minecraft:blue_bed{facing:west,occupied:false,part:head}", nbt: {id: "minecraft:bed"}},
        {pos: [3, 1, 2], state: "minecraft:air"},
        {pos: [3, 1, 3], state: "minecraft:air"},
        {pos: [3, 1, 4], state: "minecraft:spruce_door{facing:south,half:lower,hinge:left,open:false,powered:false}"},
        {pos: [3, 1, 5], state: "minecraft:jigsaw{orientation:south_up}", nbt: {final_state: "minecraft:structure_void", id: "minecraft:jigsaw", joint: "aligned", name: "minecraft:building_entrance", pool: "minecraft:empty", target: "minecraft:building_entrance"}},
        {pos: [4, 1, 0], state: "minecraft:packed_ice"},
        {pos: [4, 1, 1], state: "minecraft:blue_bed{facing:west,occupied:false,part:foot}", nbt: {id: "minecraft:bed"}},
        {pos: [4, 1, 2], state: "minecraft:air"},
        {pos: [4, 1, 3], state: "minecraft:air"},
        {pos: [4, 1, 4], state: "minecraft:packed_ice"},
        {pos: [4, 1, 5], state: "minecraft:snow{layers:6}"},
        {pos: [5, 1, 0], state: "minecraft:snow{layers:1}"},
        {pos: [5, 1, 1], state: "minecraft:packed_ice"},
        {pos: [5, 1, 2], state: "minecraft:packed_ice"},
        {pos: [5, 1, 3], state: "minecraft:packed_ice"},
        {pos: [5, 1, 4], state: "minecraft:snow_block"},
        {pos: [5, 1, 5], state: "minecraft:snow{layers:3}"},
        {pos: [6, 1, 0], state: "minecraft:snow{layers:1}"},
        {pos: [6, 1, 1], state: "minecraft:snow{layers:1}"},
        {pos: [6, 1, 2], state: "minecraft:snow{layers:1}"},
        {pos: [6, 1, 3], state: "minecraft:snow{layers:1}"},
        {pos: [6, 1, 4], state: "minecraft:snow{layers:5}"},
        {pos: [6, 1, 5], state: "minecraft:snow{layers:1}"},
        {pos: [0, 2, 0], state: "minecraft:air"},
        {pos: [0, 2, 1], state: "minecraft:air"},
        {pos: [0, 2, 2], state: "minecraft:air"},
        {pos: [0, 2, 3], state: "minecraft:air"},
        {pos: [0, 2, 4], state: "minecraft:air"},
        {pos: [0, 2, 5], state: "minecraft:air"},
        {pos: [1, 2, 0], state: "minecraft:air"},
        {pos: [1, 2, 1], state: "minecraft:packed_ice"},
        {pos: [1, 2, 2], state: "minecraft:glass_pane{east:false,north:true,south:true,waterlogged:false,west:false}"},
        {pos: [1, 2, 3], state: "minecraft:packed_ice"},
        {pos: [1, 2, 4], state: "minecraft:air"},
        {pos: [1, 2, 5], state: "minecraft:air"},
        {pos: [2, 2, 0], state: "minecraft:packed_ice"},
        {pos: [2, 2, 1], state: "minecraft:torch"},
        {pos: [2, 2, 2], state: "minecraft:air"},
        {pos: [2, 2, 3], state: "minecraft:air"},
        {pos: [2, 2, 4], state: "minecraft:packed_ice"},
        {pos: [2, 2, 5], state: "minecraft:air"},
        {pos: [3, 2, 0], state: "minecraft:packed_ice"},
        {pos: [3, 2, 1], state: "minecraft:air"},
        {pos: [3, 2, 2], state: "minecraft:air"},
        {pos: [3, 2, 3], state: "minecraft:air"},
        {pos: [3, 2, 4], state: "minecraft:spruce_door{facing:south,half:upper,hinge:left,open:false,powered:false}"},
        {pos: [3, 2, 5], state: "minecraft:air"},
        {pos: [4, 2, 0], state: "minecraft:packed_ice"},
        {pos: [4, 2, 1], state: "minecraft:air"},
        {pos: [4, 2, 2], state: "minecraft:air"},
        {pos: [4, 2, 3], state: "minecraft:air"},
        {pos: [4, 2, 4], state: "minecraft:packed_ice"},
        {pos: [4, 2, 5], state: "minecraft:air"},
        {pos: [5, 2, 0], state: "minecraft:air"},
        {pos: [5, 2, 1], state: "minecraft:packed_ice"},
        {pos: [5, 2, 2], state: "minecraft:glass_pane{east:false,north:true,south:true,waterlogged:false,west:false}"},
        {pos: [5, 2, 3], state: "minecraft:packed_ice"},
        {pos: [5, 2, 4], state: "minecraft:snow{layers:2}"},
        {pos: [5, 2, 5], state: "minecraft:air"},
        {pos: [6, 2, 0], state: "minecraft:air"},
        {pos: [6, 2, 1], state: "minecraft:air"},
        {pos: [6, 2, 2], state: "minecraft:air"},
        {pos: [6, 2, 3], state: "minecraft:air"},
        {pos: [6, 2, 4], state: "minecraft:air"},
        {pos: [6, 2, 5], state: "minecraft:air"},
        {pos: [0, 3, 0], state: "minecraft:air"},
        {pos: [0, 3, 1], state: "minecraft:air"},
        {pos: [0, 3, 2], state: "minecraft:air"},
        {pos: [0, 3, 3], state: "minecraft:air"},
        {pos: [0, 3, 4], state: "minecraft:air"},
        {pos: [0, 3, 5], state: "minecraft:air"},
        {pos: [1, 3, 0], state: "minecraft:air"},
        {pos: [1, 3, 1], state: "minecraft:packed_ice"},
        {pos: [1, 3, 2], state: "minecraft:packed_ice"},
        {pos: [1, 3, 3], state: "minecraft:packed_ice"},
        {pos: [1, 3, 4], state: "minecraft:air"},
        {pos: [1, 3, 5], state: "minecraft:air"},
        {pos: [2, 3, 0], state: "minecraft:packed_ice"},
        {pos: [2, 3, 1], state: "minecraft:air"},
        {pos: [2, 3, 2], state: "minecraft:air"},
        {pos: [2, 3, 3], state: "minecraft:air"},
        {pos: [2, 3, 4], state: "minecraft:packed_ice"},
        {pos: [2, 3, 5], state: "minecraft:air"},
        {pos: [3, 3, 0], state: "minecraft:packed_ice"},
        {pos: [3, 3, 1], state: "minecraft:air"},
        {pos: [3, 3, 2], state: "minecraft:air"},
        {pos: [3, 3, 3], state: "minecraft:air"},
        {pos: [3, 3, 4], state: "minecraft:packed_ice"},
        {pos: [3, 3, 5], state: "minecraft:air"},
        {pos: [4, 3, 0], state: "minecraft:packed_ice"},
        {pos: [4, 3, 1], state: "minecraft:air"},
        {pos: [4, 3, 2], state: "minecraft:air"},
        {pos: [4, 3, 3], state: "minecraft:air"},
        {pos: [4, 3, 4], state: "minecraft:packed_ice"},
        {pos: [4, 3, 5], state: "minecraft:air"},
        {pos: [5, 3, 0], state: "minecraft:air"},
        {pos: [5, 3, 1], state: "minecraft:packed_ice"},
        {pos: [5, 3, 2], state: "minecraft:packed_ice"},
        {pos: [5, 3, 3], state: "minecraft:packed_ice"},
        {pos: [5, 3, 4], state: "minecraft:air"},
        {pos: [5, 3, 5], state: "minecraft:air"},
        {pos: [6, 3, 0], state: "minecraft:air"},
        {pos: [6, 3, 1], state: "minecraft:air"},
        {pos: [6, 3, 2], state: "minecraft:air"},
        {pos: [6, 3, 3], state: "minecraft:air"},
        {pos: [6, 3, 4], state: "minecraft:air"},
        {pos: [6, 3, 5], state: "minecraft:air"},
        {pos: [0, 4, 0], state: "minecraft:air"},
        {pos: [0, 4, 1], state: "minecraft:air"},
        {pos: [0, 4, 2], state: "minecraft:air"},
        {pos: [0, 4, 3], state: "minecraft:air"},
        {pos: [0, 4, 4], state: "minecraft:air"},
        {pos: [0, 4, 5], state: "minecraft:air"},
        {pos: [1, 4, 0], state: "minecraft:air"},
        {pos: [1, 4, 1], state: "minecraft:air"},
        {pos: [1, 4, 2], state: "minecraft:air"},
        {pos: [1, 4, 3], state: "minecraft:air"},
        {pos: [1, 4, 4], state: "minecraft:air"},
        {pos: [1, 4, 5], state: "minecraft:air"},
        {pos: [2, 4, 0], state: "minecraft:air"},
        {pos: [2, 4, 1], state: "minecraft:packed_ice"},
        {pos: [2, 4, 2], state: "minecraft:packed_ice"},
        {pos: [2, 4, 3], state: "minecraft:packed_ice"},
        {pos: [2, 4, 4], state: "minecraft:air"},
        {pos: [2, 4, 5], state: "minecraft:air"},
        {pos: [3, 4, 0], state: "minecraft:air"},
        {pos: [3, 4, 1], state: "minecraft:packed_ice"},
        {pos: [3, 4, 2], state: "minecraft:packed_ice"},
        {pos: [3, 4, 3], state: "minecraft:packed_ice"},
        {pos: [3, 4, 4], state: "minecraft:air"},
        {pos: [3, 4, 5], state: "minecraft:air"},
        {pos: [4, 4, 0], state: "minecraft:air"},
        {pos: [4, 4, 1], state: "minecraft:packed_ice"},
        {pos: [4, 4, 2], state: "minecraft:packed_ice"},
        {pos: [4, 4, 3], state: "minecraft:packed_ice"},
        {pos: [4, 4, 4], state: "minecraft:air"},
        {pos: [4, 4, 5], state: "minecraft:air"},
        {pos: [5, 4, 0], state: "minecraft:air"},
        {pos: [5, 4, 1], state: "minecraft:air"},
        {pos: [5, 4, 2], state: "minecraft:air"},
        {pos: [5, 4, 3], state: "minecraft:air"},
        {pos: [5, 4, 4], state: "minecraft:air"},
        {pos: [5, 4, 5], state: "minecraft:air"},
        {pos: [6, 4, 0], state: "minecraft:air"},
        {pos: [6, 4, 1], state: "minecraft:air"},
        {pos: [6, 4, 2], state: "minecraft:air"},
        {pos: [6, 4, 3], state: "minecraft:air"},
        {pos: [6, 4, 4], state: "minecraft:air"},
        {pos: [6, 4, 5], state: "minecraft:air"}
    ],
    entities: [],
    palette: [
        "minecraft:grass_block{snowy:true}",
        "minecraft:grass_block{snowy:false}",
        "minecraft:dirt",
        "minecraft:packed_ice",
        "minecraft:stripped_spruce_log{axis:y}",
        "minecraft:snow_block",
        "minecraft:snow{layers:1}",
        "minecraft:snow{layers:5}",
        "minecraft:snow{layers:3}",
        "minecraft:grass",
        "minecraft:air",
        "minecraft:snow{layers:2}",
        "minecraft:spruce_door{facing:south,half:lower,hinge:left,open:false,powered:false}",
        "minecraft:snow{layers:6}",
        "minecraft:glass_pane{east:false,north:true,south:true,waterlogged:false,west:false}",
        "minecraft:torch",
        "minecraft:spruce_door{facing:south,half:upper,hinge:left,open:false,powered:false}",
        "minecraft:jigsaw{orientation:up_north}",
        "minecraft:blue_bed{facing:west,occupied:false,part:head}",
        "minecraft:jigsaw{orientation:south_up}",
        "minecraft:blue_bed{facing:west,occupied:false,part:foot}"
    ]
}
