{
    size: [9, 9, 28],
    data: [
        {pos: [0, 0, 21], state: "minecraft:oak_stairs{facing:east,half:top,shape:outer_right,waterlogged:false}"},
        {pos: [0, 0, 22], state: "minecraft:oak_stairs{facing:east,half:top,shape:outer_right,waterlogged:false}"},
        {pos: [0, 0, 23], state: "minecraft:oak_stairs{facing:east,half:top,shape:outer_right,waterlogged:false}"},
        {pos: [1, 0, 20], state: "minecraft:oak_stairs{facing:south,half:bottom,shape:outer_right,waterlogged:false}"},
        {pos: [1, 0, 21], state: "minecraft:oak_planks"},
        {pos: [1, 0, 22], state: "minecraft:oak_planks"},
        {pos: [1, 0, 23], state: "minecraft:oak_planks"},
        {pos: [2, 0, 8], state: "minecraft:oak_planks"},
        {pos: [2, 0, 9], state: "minecraft:oak_stairs{facing:north,half:bottom,shape:outer_right,waterlogged:false}"},
        {pos: [2, 0, 18], state: "minecraft:oak_stairs{facing:south,half:bottom,shape:outer_right,waterlogged:false}"},
        {pos: [2, 0, 19], state: "minecraft:oak_planks"},
        {pos: [2, 0, 20], state: "minecraft:oak_planks"},
        {pos: [2, 0, 21], state: "minecraft:oak_planks"},
        {pos: [2, 0, 23], state: "minecraft:oak_planks"},
        {pos: [3, 0, 8], state: "minecraft:oak_stairs{facing:south,half:top,shape:outer_right,waterlogged:false}"},
        {pos: [3, 0, 9], state: "minecraft:oak_planks"},
        {pos: [3, 0, 10], state: "minecraft:oak_planks"},
        {pos: [3, 0, 11], state: "minecraft:spruce_fence{east:false,north:false,south:false,waterlogged:false,west:false}"},
        {pos: [3, 0, 12], state: "minecraft:spruce_fence{east:false,north:false,south:false,waterlogged:false,west:false}"},
        {pos: [3, 0, 13], state: "minecraft:spruce_fence{east:false,north:false,south:false,waterlogged:false,west:false}"},
        {pos: [3, 0, 15], state: "minecraft:spruce_fence{east:false,north:false,south:false,waterlogged:false,west:false}"},
        {pos: [3, 0, 16], state: "minecraft:spruce_fence{east:false,north:false,south:false,waterlogged:false,west:false}"},
        {pos: [3, 0, 17], state: "minecraft:spruce_fence{east:false,north:false,south:false,waterlogged:false,west:false}"},
        {pos: [3, 0, 18], state: "minecraft:oak_planks"},
        {pos: [3, 0, 19], state: "minecraft:oak_planks"},
        {pos: [3, 0, 20], state: "minecraft:oak_planks"},
        {pos: [3, 0, 21], state: "minecraft:oak_stairs{facing:west,half:top,shape:outer_right,waterlogged:false}"},
        {pos: [3, 0, 22], state: "minecraft:oak_stairs{facing:west,half:top,shape:outer_right,waterlogged:false}"},
        {pos: [3, 0, 23], state: "minecraft:oak_stairs{facing:north,half:top,shape:outer_right,waterlogged:false}"},
        {pos: [4, 0, 9], state: "minecraft:oak_stairs{facing:west,half:top,shape:outer_right,waterlogged:false}"},
        {pos: [4, 0, 10], state: "minecraft:oak_stairs{facing:west,half:top,shape:outer_right,waterlogged:false}"},
        {pos: [4, 0, 11], state: "minecraft:oak_stairs{facing:west,half:top,shape:outer_right,waterlogged:false}"},
        {pos: [4, 0, 12], state: "minecraft:oak_stairs{facing:west,half:top,shape:outer_right,waterlogged:false}"},
        {pos: [4, 0, 13], state: "minecraft:oak_stairs{facing:west,half:top,shape:outer_right,waterlogged:false}"},
        {pos: [4, 0, 14], state: "minecraft:oak_stairs{facing:west,half:top,shape:outer_right,waterlogged:false}"},
        {pos: [4, 0, 15], state: "minecraft:oak_stairs{facing:west,half:top,shape:outer_right,waterlogged:false}"},
        {pos: [4, 0, 16], state: "minecraft:oak_stairs{facing:west,half:top,shape:outer_right,waterlogged:false}"},
        {pos: [4, 0, 17], state: "minecraft:oak_stairs{facing:west,half:top,shape:outer_right,waterlogged:false}"},
        {pos: [4, 0, 18], state: "minecraft:oak_stairs{facing:west,half:top,shape:outer_right,waterlogged:false}"},
        {pos: [4, 0, 19], state: "minecraft:oak_stairs{facing:west,half:top,shape:outer_right,waterlogged:false}"},
        {pos: [4, 0, 20], state: "minecraft:oak_stairs{facing:west,half:top,shape:outer_right,waterlogged:false}"},
        {pos: [0, 1, 21], state: "minecraft:oak_planks"},
        {pos: [0, 1, 23], state: "minecraft:spruce_fence{east:false,north:false,south:false,waterlogged:false,west:false}"},
        {pos: [0, 1, 24], state: "minecraft:spruce_fence{east:false,north:false,south:false,waterlogged:false,west:false}"},
        {pos: [0, 1, 25], state: "minecraft:oak_planks"},
        {pos: [1, 1, 21], state: "minecraft:oak_planks"},
        {pos: [1, 1, 22], state: "minecraft:spruce_planks"},
        {pos: [1, 1, 23], state: "minecraft:spruce_planks"},
        {pos: [1, 1, 24], state: "minecraft:oak_planks"},
        {pos: [1, 1, 25], state: "minecraft:oak_planks"},
        {pos: [2, 1, 6], state: "minecraft:oak_planks"},
        {pos: [2, 1, 7], state: "minecraft:oak_planks"},
        {pos: [2, 1, 8], state: "minecraft:oak_stairs{facing:north,half:bottom,shape:outer_right,waterlogged:false}"},
        {pos: [2, 1, 19], state: "minecraft:spruce_stairs{facing:south,half:bottom,shape:outer_right,waterlogged:false}"},
        {pos: [2, 1, 20], state: "minecraft:spruce_planks"},
        {pos: [2, 1, 21], state: "minecraft:oak_fence{east:false,north:false,south:false,waterlogged:false,west:false}"},
        {pos: [2, 1, 23], state: "minecraft:oak_fence{east:false,north:false,south:false,waterlogged:false,west:false}"},
        {pos: [2, 1, 24], state: "minecraft:oak_planks"},
        {pos: [2, 1, 25], state: "minecraft:oak_planks"},
        {pos: [3, 1, 6], state: "minecraft:oak_stairs{facing:west,half:top,shape:outer_right,waterlogged:false}"},
        {pos: [3, 1, 7], state: "minecraft:oak_planks"},
        {pos: [3, 1, 8], state: "minecraft:oak_planks"},
        {pos: [3, 1, 18], state: "minecraft:spruce_stairs{facing:south,half:bottom,shape:outer_right,waterlogged:false}"},
        {pos: [3, 1, 19], state: "minecraft:spruce_planks"},
        {pos: [3, 1, 20], state: "minecraft:oak_planks"},
        {pos: [3, 1, 21], state: "minecraft:oak_planks"},
        {pos: [3, 1, 22], state: "minecraft:oak_stairs{facing:east,half:bottom,shape:outer_right,waterlogged:false}"},
        {pos: [3, 1, 23], state: "minecraft:oak_planks"},
        {pos: [3, 1, 24], state: "minecraft:oak_planks"},
        {pos: [3, 1, 25], state: "minecraft:oak_stairs{facing:north,half:top,shape:outer_right,waterlogged:false}"},
        {pos: [4, 1, 7], state: "minecraft:oak_stairs{facing:west,half:top,shape:outer_right,waterlogged:false}"},
        {pos: [4, 1, 8], state: "minecraft:oak_planks"},
        {pos: [4, 1, 9], state: "minecraft:spruce_planks"},
        {pos: [4, 1, 10], state: "minecraft:spruce_planks"},
        {pos: [4, 1, 11], state: "minecraft:spruce_planks"},
        {pos: [4, 1, 12], state: "minecraft:spruce_planks"},
        {pos: [4, 1, 13], state: "minecraft:spruce_planks"},
        {pos: [4, 1, 14], state: "minecraft:spruce_planks"},
        {pos: [4, 1, 15], state: "minecraft:spruce_planks"},
        {pos: [4, 1, 16], state: "minecraft:spruce_planks"},
        {pos: [4, 1, 17], state: "minecraft:spruce_planks"},
        {pos: [4, 1, 18], state: "minecraft:spruce_planks"},
        {pos: [4, 1, 19], state: "minecraft:oak_planks"},
        {pos: [4, 1, 20], state: "minecraft:oak_planks"},
        {pos: [4, 1, 21], state: "minecraft:oak_planks"},
        {pos: [4, 1, 22], state: "minecraft:oak_planks"},
        {pos: [4, 1, 23], state: "minecraft:oak_planks"},
        {pos: [4, 1, 24], state: "minecraft:oak_planks"},
        {pos: [5, 1, 8], state: "minecraft:oak_stairs{facing:west,half:top,shape:outer_right,waterlogged:false}"},
        {pos: [5, 1, 9], state: "minecraft:oak_planks"},
        {pos: [5, 1, 10], state: "minecraft:oak_planks"},
        {pos: [5, 1, 11], state: "minecraft:oak_planks"},
        {pos: [5, 1, 13], state: "minecraft:oak_planks"},
        {pos: [5, 1, 14], state: "minecraft:oak_planks"},
        {pos: [5, 1, 16], state: "minecraft:oak_planks"},
        {pos: [5, 1, 17], state: "minecraft:oak_planks"},
        {pos: [5, 1, 19], state: "minecraft:oak_planks"},
        {pos: [5, 1, 20], state: "minecraft:oak_planks"},
        {pos: [5, 1, 21], state: "minecraft:oak_stairs{facing:west,half:top,shape:outer_right,waterlogged:false}"},
        {pos: [5, 1, 22], state: "minecraft:oak_stairs{facing:west,half:top,shape:outer_right,waterlogged:false}"},
        {pos: [5, 1, 23], state: "minecraft:oak_stairs{facing:west,half:top,shape:outer_right,waterlogged:false}"},
        {pos: [5, 1, 24], state: "minecraft:oak_stairs{facing:west,half:top,shape:outer_right,waterlogged:false}"},
        {pos: [6, 1, 9], state: "minecraft:oak_stairs{facing:west,half:top,shape:outer_right,waterlogged:false}"},
        {pos: [6, 1, 10], state: "minecraft:oak_stairs{facing:west,half:top,shape:outer_right,waterlogged:false}"},
        {pos: [6, 1, 11], state: "minecraft:oak_stairs{facing:west,half:top,shape:outer_right,waterlogged:false}"},
        {pos: [6, 1, 12], state: "minecraft:oak_stairs{facing:west,half:top,shape:outer_right,waterlogged:false}"},
        {pos: [6, 1, 13], state: "minecraft:oak_stairs{facing:west,half:top,shape:outer_right,waterlogged:false}"},
        {pos: [6, 1, 14], state: "minecraft:oak_stairs{facing:west,half:top,shape:outer_right,waterlogged:false}"},
        {pos: [6, 1, 15], state: "minecraft:oak_stairs{facing:west,half:top,shape:outer_right,waterlogged:false}"},
        {pos: [6, 1, 16], state: "minecraft:oak_stairs{facing:west,half:top,shape:outer_right,waterlogged:false}"},
        {pos: [6, 1, 17], state: "minecraft:oak_stairs{facing:west,half:top,shape:outer_right,waterlogged:false}"},
        {pos: [6, 1, 18], state: "minecraft:oak_stairs{facing:west,half:top,shape:outer_right,waterlogged:false}"},
        {pos: [6, 1, 19], state: "minecraft:oak_stairs{facing:west,half:top,shape:outer_right,waterlogged:false}"},
        {pos: [6, 1, 20], state: "minecraft:oak_stairs{facing:west,half:top,shape:outer_right,waterlogged:false}"},
        {pos: [0, 2, 26], state: "minecraft:oak_planks"},
        {pos: [1, 2, 21], state: "minecraft:spruce_planks"},
        {pos: [1, 2, 22], state: "minecraft:spruce_planks"},
        {pos: [1, 2, 23], state: "minecraft:spruce_planks"},
        {pos: [1, 2, 24], state: "minecraft:spruce_planks"},
        {pos: [1, 2, 25], state: "minecraft:spruce_planks"},
        {pos: [1, 2, 26], state: "minecraft:oak_planks"},
        {pos: [2, 2, 5], state: "minecraft:oak_planks"},
        {pos: [2, 2, 19], state: "minecraft:oak_planks"},
        {pos: [2, 2, 20], state: "minecraft:spruce_planks"},
        {pos: [2, 2, 25], state: "minecraft:oak_fence{east:false,north:false,south:false,waterlogged:false,west:false}"},
        {pos: [2, 2, 26], state: "minecraft:oak_stairs{facing:north,half:top,shape:outer_right,waterlogged:false}"},
        {pos: [3, 2, 5], state: "minecraft:oak_planks"},
        {pos: [3, 2, 6], state: "minecraft:spruce_planks"},
        {pos: [3, 2, 7], state: "minecraft:spruce_planks"},
        {pos: [3, 2, 19], state: "minecraft:oak_planks"},
        {pos: [3, 2, 24], state: "minecraft:chest{facing:north,type:single,waterlogged:false}", nbt: {Items: [], id: "minecraft:chest"}},
        {pos: [3, 2, 25], state: "minecraft:oak_planks"},
        {pos: [4, 2, 5], state: "minecraft:oak_stairs{facing:west,half:top,shape:outer_right,waterlogged:false}"},
        {pos: [4, 2, 6], state: "minecraft:oak_stairs{facing:west,half:top,shape:outer_right,waterlogged:false}"},
        {pos: [4, 2, 7], state: "minecraft:oak_planks"},
        {pos: [4, 2, 8], state: "minecraft:spruce_planks"},
        {pos: [4, 2, 9], state: "minecraft:spruce_planks"},
        {pos: [4, 2, 10], state: "minecraft:spruce_planks"},
        {pos: [4, 2, 11], state: "minecraft:spruce_planks"},
        {pos: [4, 2, 12], state: "minecraft:spruce_stairs{facing:west,half:bottom,shape:outer_right,waterlogged:false}"},
        {pos: [4, 2, 13], state: "minecraft:spruce_planks"},
        {pos: [4, 2, 14], state: "minecraft:spruce_planks"},
        {pos: [4, 2, 15], state: "minecraft:spruce_stairs{facing:west,half:bottom,shape:outer_right,waterlogged:false}"},
        {pos: [4, 2, 16], state: "minecraft:spruce_planks"},
        {pos: [4, 2, 17], state: "minecraft:spruce_planks"},
        {pos: [4, 2, 18], state: "minecraft:spruce_planks"},
        {pos: [4, 2, 19], state: "minecraft:spruce_planks"},
        {pos: [4, 2, 20], state: "minecraft:oak_stairs{facing:east,half:bottom,shape:outer_right,waterlogged:false}"},
        {pos: [4, 2, 24], state: "minecraft:oak_stairs{facing:south,half:bottom,shape:outer_right,waterlogged:false}"},
        {pos: [4, 2, 25], state: "minecraft:oak_stairs{facing:north,half:top,shape:outer_right,waterlogged:false}"},
        {pos: [5, 2, 7], state: "minecraft:oak_stairs{facing:west,half:top,shape:outer_right,waterlogged:false}"},
        {pos: [5, 2, 8], state: "minecraft:oak_planks"},
        {pos: [5, 2, 9], state: "minecraft:oak_planks"},
        {pos: [5, 2, 10], state: "minecraft:oak_planks"},
        {pos: [5, 2, 11], state: "minecraft:oak_planks"},
        {pos: [5, 2, 13], state: "minecraft:oak_planks"},
        {pos: [5, 2, 14], state: "minecraft:oak_planks"},
        {pos: [5, 2, 16], state: "minecraft:oak_planks"},
        {pos: [5, 2, 17], state: "minecraft:oak_planks"},
        {pos: [5, 2, 19], state: "minecraft:oak_planks"},
        {pos: [5, 2, 20], state: "minecraft:oak_planks"},
        {pos: [5, 2, 21], state: "minecraft:spruce_planks"},
        {pos: [5, 2, 22], state: "minecraft:spruce_planks"},
        {pos: [5, 2, 23], state: "minecraft:spruce_planks"},
        {pos: [5, 2, 24], state: "minecraft:spruce_planks"},
        {pos: [5, 2, 25], state: "minecraft:oak_stairs{facing:north,half:top,shape:outer_right,waterlogged:false}"},
        {pos: [6, 2, 8], state: "minecraft:oak_stairs{facing:west,half:top,shape:outer_right,waterlogged:false}"},
        {pos: [6, 2, 9], state: "minecraft:oak_planks"},
        {pos: [6, 2, 10], state: "minecraft:oak_planks"},
        {pos: [6, 2, 11], state: "minecraft:oak_planks"},
        {pos: [6, 2, 12], state: "minecraft:oak_stairs{facing:east,half:bottom,shape:outer_right,waterlogged:false}"},
        {pos: [6, 2, 13], state: "minecraft:oak_planks"},
        {pos: [6, 2, 14], state: "minecraft:oak_planks"},
        {pos: [6, 2, 15], state: "minecraft:oak_stairs{facing:east,half:bottom,shape:outer_right,waterlogged:false}"},
        {pos: [6, 2, 16], state: "minecraft:oak_planks"},
        {pos: [6, 2, 17], state: "minecraft:oak_planks"},
        {pos: [6, 2, 18], state: "minecraft:oak_stairs{facing:east,half:bottom,shape:outer_right,waterlogged:false}"},
        {pos: [6, 2, 19], state: "minecraft:oak_planks"},
        {pos: [6, 2, 20], state: "minecraft:oak_planks"},
        {pos: [6, 2, 21], state: "minecraft:oak_stairs{facing:west,half:top,shape:outer_right,waterlogged:false}"},
        {pos: [6, 2, 22], state: "minecraft:oak_stairs{facing:west,half:top,shape:outer_right,waterlogged:false}"},
        {pos: [6, 2, 23], state: "minecraft:oak_stairs{facing:west,half:top,shape:outer_right,waterlogged:false}"},
        {pos: [6, 2, 24], state: "minecraft:oak_stairs{facing:west,half:top,shape:outer_right,waterlogged:false}"},
        {pos: [7, 2, 9], state: "minecraft:oak_stairs{facing:west,half:top,shape:outer_right,waterlogged:false}"},
        {pos: [7, 2, 10], state: "minecraft:oak_stairs{facing:west,half:top,shape:outer_right,waterlogged:false}"},
        {pos: [7, 2, 11], state: "minecraft:oak_stairs{facing:west,half:top,shape:outer_right,waterlogged:false}"},
        {pos: [7, 2, 12], state: "minecraft:oak_stairs{facing:west,half:top,shape:outer_right,waterlogged:false}"},
        {pos: [7, 2, 13], state: "minecraft:oak_stairs{facing:west,half:top,shape:outer_right,waterlogged:false}"},
        {pos: [7, 2, 14], state: "minecraft:oak_stairs{facing:west,half:top,shape:outer_right,waterlogged:false}"},
        {pos: [7, 2, 15], state: "minecraft:oak_stairs{facing:west,half:top,shape:outer_right,waterlogged:false}"},
        {pos: [7, 2, 16], state: "minecraft:oak_stairs{facing:west,half:top,shape:outer_right,waterlogged:false}"},
        {pos: [7, 2, 17], state: "minecraft:oak_stairs{facing:west,half:top,shape:outer_right,waterlogged:false}"},
        {pos: [7, 2, 18], state: "minecraft:oak_stairs{facing:west,half:top,shape:outer_right,waterlogged:false}"},
        {pos: [7, 2, 19], state: "minecraft:oak_stairs{facing:west,half:top,shape:outer_right,waterlogged:false}"},
        {pos: [7, 2, 20], state: "minecraft:oak_stairs{facing:west,half:top,shape:outer_right,waterlogged:false}"},
        {pos: [0, 3, 21], state: "minecraft:oak_planks"},
        {pos: [0, 3, 26], state: "minecraft:spruce_fence{east:false,north:false,south:false,waterlogged:false,west:false}"},
        {pos: [0, 3, 27], state: "minecraft:spruce_fence{east:false,north:false,south:false,waterlogged:false,west:false}"},
        {pos: [1, 3, 2], state: "minecraft:spruce_fence{east:false,north:false,south:false,waterlogged:false,west:false}"},
        {pos: [1, 3, 3], state: "minecraft:spruce_fence{east:false,north:false,south:false,waterlogged:false,west:false}"},
        {pos: [1, 3, 4], state: "minecraft:spruce_fence{east:false,north:false,south:false,waterlogged:false,west:false}"},
        {pos: [1, 3, 21], state: "minecraft:spruce_planks"},
        {pos: [1, 3, 22], state: "minecraft:spruce_planks"},
        {pos: [1, 3, 23], state: "minecraft:spruce_planks"},
        {pos: [1, 3, 24], state: "minecraft:spruce_planks"},
        {pos: [1, 3, 25], state: "minecraft:spruce_planks"},
        {pos: [1, 3, 26], state: "minecraft:spruce_planks"},
        {pos: [1, 3, 27], state: "minecraft:oak_stairs{facing:north,half:top,shape:outer_right,waterlogged:false}"},
        {pos: [2, 3, 2], state: "minecraft:spruce_fence{east:false,north:false,south:false,waterlogged:false,west:false}"},
        {pos: [2, 3, 3], state: "minecraft:oak_stairs{facing:south,half:bottom,shape:outer_right,waterlogged:false}"},
        {pos: [2, 3, 4], state: "minecraft:oak_planks"},
        {pos: [2, 3, 20], state: "minecraft:spruce_planks"},
        {pos: [2, 3, 26], state: "minecraft:oak_planks"},
        {pos: [3, 3, 3], state: "minecraft:oak_stairs{facing:south,half:top,shape:outer_right,waterlogged:false}"},
        {pos: [3, 3, 4], state: "minecraft:oak_planks"},
        {pos: [3, 3, 5], state: "minecraft:spruce_planks"},
        {pos: [3, 3, 6], state: "minecraft:spruce_planks"},
        {pos: [3, 3, 7], state: "minecraft:spruce_stairs{facing:north,half:bottom,shape:outer_right,waterlogged:false}"},
        {pos: [3, 3, 19], state: "minecraft:oak_planks"},
        {pos: [3, 3, 24], state: "minecraft:structure_block{mode:data}", nbt: {author: "CascadianBacon", id: "minecraft:structure_block", ignoreEntities: 1b, integrity: 1.0f, metadata: "treasure_chest", mirror: "NONE", mode: "DATA", name: "", posX: 0, posY: 1, posZ: 0, powered: 0b, rotation: "NONE", seed: 0L, showair: 0b, showboundingbox: 1b, sizeX: 0, sizeY: 0, sizeZ: 0}},
        {pos: [3, 3, 25], state: "minecraft:oak_stairs{facing:south,half:bottom,shape:outer_right,waterlogged:false}"},
        {pos: [3, 3, 26], state: "minecraft:oak_stairs{facing:north,half:top,shape:outer_right,waterlogged:false}"},
        {pos: [4, 3, 4], state: "minecraft:oak_stairs{facing:south,half:top,shape:outer_right,waterlogged:false}"},
        {pos: [4, 3, 5], state: "minecraft:oak_planks"},
        {pos: [4, 3, 6], state: "minecraft:oak_planks"},
        {pos: [4, 3, 7], state: "minecraft:spruce_planks"},
        {pos: [4, 3, 8], state: "minecraft:spruce_planks"},
        {pos: [4, 3, 9], state: "minecraft:oak_trapdoor{facing:east,half:bottom,open:true,powered:false,waterlogged:false}"},
        {pos: [4, 3, 10], state: "minecraft:oak_trapdoor{facing:east,half:bottom,open:true,powered:false,waterlogged:false}"},
        {pos: [4, 3, 11], state: "minecraft:spruce_planks"},
        {pos: [4, 3, 12], state: "minecraft:oak_trapdoor{facing:east,half:bottom,open:true,powered:false,waterlogged:false}"},
        {pos: [4, 3, 13], state: "minecraft:oak_trapdoor{facing:east,half:bottom,open:true,powered:false,waterlogged:false}"},
        {pos: [4, 3, 14], state: "minecraft:oak_trapdoor{facing:east,half:bottom,open:true,powered:false,waterlogged:false}"},
        {pos: [4, 3, 15], state: "minecraft:oak_trapdoor{facing:east,half:bottom,open:true,powered:false,waterlogged:false}"},
        {pos: [4, 3, 16], state: "minecraft:spruce_planks"},
        {pos: [4, 3, 17], state: "minecraft:spruce_planks"},
        {pos: [4, 3, 18], state: "minecraft:spruce_planks"},
        {pos: [4, 3, 19], state: "minecraft:spruce_planks"},
        {pos: [4, 3, 25], state: "minecraft:oak_planks"},
        {pos: [5, 3, 5], state: "minecraft:oak_stairs{facing:west,half:top,shape:outer_right,waterlogged:false}"},
        {pos: [5, 3, 6], state: "minecraft:oak_stairs{facing:west,half:top,shape:outer_right,waterlogged:false}"},
        {pos: [5, 3, 7], state: "minecraft:oak_planks"},
        {pos: [5, 3, 8], state: "minecraft:chest{facing:south,type:single,waterlogged:false}", nbt: {Items: [], id: "minecraft:chest"}},
        {pos: [5, 3, 20], state: "minecraft:spruce_planks"},
        {pos: [5, 3, 21], state: "minecraft:spruce_planks"},
        {pos: [5, 3, 22], state: "minecraft:spruce_planks"},
        {pos: [5, 3, 23], state: "minecraft:spruce_planks"},
        {pos: [5, 3, 24], state: "minecraft:spruce_planks"},
        {pos: [5, 3, 25], state: "minecraft:oak_planks"},
        {pos: [6, 3, 7], state: "minecraft:oak_stairs{facing:west,half:top,shape:outer_right,waterlogged:false}"},
        {pos: [6, 3, 8], state: "minecraft:oak_planks"},
        {pos: [6, 3, 19], state: "minecraft:chest{facing:north,type:single,waterlogged:false}", nbt: {Items: [], id: "minecraft:chest"}},
        {pos: [6, 3, 20], state: "minecraft:spruce_planks"},
        {pos: [6, 3, 21], state: "minecraft:oak_planks"},
        {pos: [6, 3, 22], state: "minecraft:oak_planks"},
        {pos: [6, 3, 23], state: "minecraft:oak_planks"},
        {pos: [6, 3, 24], state: "minecraft:oak_planks"},
        {pos: [7, 3, 8], state: "minecraft:oak_stairs{facing:west,half:top,shape:outer_right,waterlogged:false}"},
        {pos: [7, 3, 9], state: "minecraft:oak_planks"},
        {pos: [7, 3, 10], state: "minecraft:oak_planks"},
        {pos: [7, 3, 11], state: "minecraft:oak_planks"},
        {pos: [7, 3, 12], state: "minecraft:oak_planks"},
        {pos: [7, 3, 13], state: "minecraft:oak_planks"},
        {pos: [7, 3, 14], state: "minecraft:oak_planks"},
        {pos: [7, 3, 15], state: "minecraft:oak_planks"},
        {pos: [7, 3, 16], state: "minecraft:oak_planks"},
        {pos: [7, 3, 17], state: "minecraft:oak_planks"},
        {pos: [7, 3, 18], state: "minecraft:oak_planks"},
        {pos: [7, 3, 19], state: "minecraft:oak_planks"},
        {pos: [7, 3, 20], state: "minecraft:oak_planks"},
        {pos: [7, 3, 21], state: "minecraft:oak_stairs{facing:west,half:top,shape:outer_right,waterlogged:false}"},
        {pos: [7, 3, 22], state: "minecraft:oak_stairs{facing:west,half:top,shape:outer_right,waterlogged:false}"},
        {pos: [7, 3, 23], state: "minecraft:oak_stairs{facing:west,half:top,shape:outer_right,waterlogged:false}"},
        {pos: [0, 4, 0], state: "minecraft:spruce_stairs{facing:south,half:top,shape:outer_right,waterlogged:false}"},
        {pos: [0, 4, 1], state: "minecraft:spruce_stairs{facing:north,half:bottom,shape:outer_right,waterlogged:false}"},
        {pos: [0, 4, 21], state: "minecraft:oak_planks"},
        {pos: [0, 4, 27], state: "minecraft:spruce_fence{east:false,north:false,south:false,waterlogged:false,west:false}"},
        {pos: [1, 4, 1], state: "minecraft:spruce_stairs{facing:south,half:top,shape:outer_right,waterlogged:false}"},
        {pos: [1, 4, 2], state: "minecraft:spruce_planks"},
        {pos: [1, 4, 3], state: "minecraft:spruce_stairs{facing:north,half:bottom,shape:outer_right,waterlogged:false}"},
        {pos: [1, 4, 21], state: "minecraft:spruce_planks"},
        {pos: [1, 4, 22], state: "minecraft:spruce_planks"},
        {pos: [1, 4, 23], state: "minecraft:spruce_planks"},
        {pos: [1, 4, 24], state: "minecraft:spruce_planks"},
        {pos: [1, 4, 25], state: "minecraft:spruce_planks"},
        {pos: [1, 4, 26], state: "minecraft:spruce_planks"},
        {pos: [1, 4, 27], state: "minecraft:oak_planks"},
        {pos: [2, 4, 2], state: "minecraft:spruce_stairs{facing:south,half:top,shape:outer_right,waterlogged:false}"},
        {pos: [2, 4, 3], state: "minecraft:spruce_planks"},
        {pos: [2, 4, 4], state: "minecraft:spruce_stairs{facing:north,half:bottom,shape:outer_right,waterlogged:false}"},
        {pos: [3, 4, 3], state: "minecraft:spruce_planks"},
        {pos: [3, 4, 4], state: "minecraft:spruce_planks"},
        {pos: [3, 4, 5], state: "minecraft:spruce_planks"},
        {pos: [3, 4, 6], state: "minecraft:spruce_planks"},
        {pos: [3, 4, 7], state: "minecraft:oak_log{axis:x}"},
        {pos: [3, 4, 11], state: "minecraft:oak_log{axis:x}"},
        {pos: [3, 4, 16], state: "minecraft:oak_log{axis:x}"},
        {pos: [3, 4, 26], state: "minecraft:oak_planks"},
        {pos: [4, 4, 3], state: "minecraft:spruce_stairs{facing:south,half:top,shape:outer_right,waterlogged:false}"},
        {pos: [4, 4, 4], state: "minecraft:spruce_planks"},
        {pos: [4, 4, 5], state: "minecraft:oak_planks"},
        {pos: [4, 4, 6], state: "minecraft:oak_planks"},
        {pos: [4, 4, 7], state: "minecraft:oak_log{axis:x}"},
        {pos: [4, 4, 8], state: "minecraft:spruce_planks"},
        {pos: [4, 4, 11], state: "minecraft:oak_log{axis:x}"},
        {pos: [4, 4, 12], state: "minecraft:oak_trapdoor{facing:east,half:bottom,open:true,powered:false,waterlogged:false}"},
        {pos: [4, 4, 15], state: "minecraft:oak_trapdoor{facing:east,half:bottom,open:true,powered:false,waterlogged:false}"},
        {pos: [4, 4, 16], state: "minecraft:oak_log{axis:x}"},
        {pos: [4, 4, 17], state: "minecraft:spruce_planks"},
        {pos: [4, 4, 18], state: "minecraft:spruce_planks"},
        {pos: [4, 4, 19], state: "minecraft:spruce_planks"},
        {pos: [4, 4, 25], state: "minecraft:oak_planks"},
        {pos: [4, 4, 26], state: "minecraft:oak_stairs{facing:north,half:top,shape:outer_right,waterlogged:false}"},
        {pos: [5, 4, 4], state: "minecraft:spruce_stairs{facing:south,half:top,shape:outer_right,waterlogged:false}"},
        {pos: [5, 4, 5], state: "minecraft:spruce_planks"},
        {pos: [5, 4, 6], state: "minecraft:oak_planks"},
        {pos: [5, 4, 7], state: "minecraft:oak_planks"},
        {pos: [5, 4, 8], state: "minecraft:structure_block{mode:data}", nbt: {author: "CascadianBacon", id: "minecraft:structure_block", ignoreEntities: 1b, integrity: 1.0f, metadata: "supply_chest", mirror: "NONE", mode: "DATA", name: "", posX: 0, posY: 1, posZ: 0, powered: 0b, rotation: "NONE", seed: 0L, showair: 0b, showboundingbox: 1b, sizeX: 0, sizeY: 0, sizeZ: 0}},
        {pos: [5, 4, 11], state: "minecraft:oak_log{axis:x}"},
        {pos: [5, 4, 16], state: "minecraft:oak_log{axis:x}"},
        {pos: [5, 4, 20], state: "minecraft:spruce_planks"},
        {pos: [5, 4, 21], state: "minecraft:spruce_planks"},
        {pos: [5, 4, 22], state: "minecraft:spruce_planks"},
        {pos: [5, 4, 23], state: "minecraft:spruce_planks"},
        {pos: [5, 4, 24], state: "minecraft:spruce_planks"},
        {pos: [5, 4, 25], state: "minecraft:spruce_fence{east:false,north:false,south:false,waterlogged:false,west:false}"},
        {pos: [6, 4, 5], state: "minecraft:spruce_stairs{facing:south,half:top,shape:outer_right,waterlogged:false}"},
        {pos: [6, 4, 6], state: "minecraft:spruce_planks"},
        {pos: [6, 4, 7], state: "minecraft:oak_planks"},
        {pos: [6, 4, 8], state: "minecraft:oak_planks"},
        {pos: [6, 4, 11], state: "minecraft:oak_log{axis:x}"},
        {pos: [6, 4, 16], state: "minecraft:oak_log{axis:x}"},
        {pos: [6, 4, 19], state: "minecraft:structure_block{mode:data}", nbt: {author: "CascadianBacon", id: "minecraft:structure_block", ignoreEntities: 1b, integrity: 1.0f, metadata: "map_chest", mirror: "NONE", mode: "DATA", name: "", posX: 0, posY: 1, posZ: 0, powered: 0b, rotation: "NONE", seed: 0L, showair: 0b, showboundingbox: 1b, sizeX: 0, sizeY: 0, sizeZ: 0}},
        {pos: [6, 4, 20], state: "minecraft:spruce_planks"},
        {pos: [6, 4, 21], state: "minecraft:oak_planks"},
        {pos: [6, 4, 22], state: "minecraft:oak_planks"},
        {pos: [6, 4, 23], state: "minecraft:oak_planks"},
        {pos: [6, 4, 24], state: "minecraft:spruce_planks"},
        {pos: [7, 4, 6], state: "minecraft:spruce_stairs{facing:south,half:top,shape:outer_right,waterlogged:false}"},
        {pos: [7, 4, 7], state: "minecraft:spruce_planks"},
        {pos: [7, 4, 8], state: "minecraft:spruce_planks"},
        {pos: [7, 4, 9], state: "minecraft:oak_planks"},
        {pos: [7, 4, 10], state: "minecraft:oak_planks"},
        {pos: [7, 4, 11], state: "minecraft:oak_planks"},
        {pos: [7, 4, 12], state: "minecraft:oak_planks"},
        {pos: [7, 4, 13], state: "minecraft:oak_planks"},
        {pos: [7, 4, 14], state: "minecraft:oak_planks"},
        {pos: [7, 4, 15], state: "minecraft:oak_planks"},
        {pos: [7, 4, 16], state: "minecraft:oak_planks"},
        {pos: [7, 4, 17], state: "minecraft:oak_planks"},
        {pos: [7, 4, 18], state: "minecraft:oak_planks"},
        {pos: [7, 4, 19], state: "minecraft:oak_planks"},
        {pos: [7, 4, 20], state: "minecraft:oak_planks"},
        {pos: [7, 4, 21], state: "minecraft:spruce_planks"},
        {pos: [7, 4, 22], state: "minecraft:spruce_planks"},
        {pos: [7, 4, 23], state: "minecraft:spruce_planks"},
        {pos: [8, 4, 8], state: "minecraft:spruce_stairs{facing:south,half:top,shape:outer_right,waterlogged:false}"},
        {pos: [8, 4, 9], state: "minecraft:spruce_planks"},
        {pos: [8, 4, 10], state: "minecraft:spruce_planks"},
        {pos: [8, 4, 11], state: "minecraft:spruce_planks"},
        {pos: [8, 4, 12], state: "minecraft:spruce_planks"},
        {pos: [8, 4, 13], state: "minecraft:spruce_planks"},
        {pos: [8, 4, 14], state: "minecraft:spruce_planks"},
        {pos: [8, 4, 15], state: "minecraft:spruce_planks"},
        {pos: [8, 4, 16], state: "minecraft:spruce_planks"},
        {pos: [8, 4, 17], state: "minecraft:spruce_planks"},
        {pos: [8, 4, 18], state: "minecraft:spruce_planks"},
        {pos: [8, 4, 19], state: "minecraft:spruce_planks"},
        {pos: [8, 4, 20], state: "minecraft:spruce_planks"},
        {pos: [8, 4, 21], state: "minecraft:spruce_stairs{facing:north,half:top,shape:outer_right,waterlogged:false}"},
        {pos: [0, 5, 21], state: "minecraft:oak_planks"},
        {pos: [0, 5, 26], state: "minecraft:spruce_fence{east:false,north:false,south:false,waterlogged:false,west:false}"},
        {pos: [0, 5, 27], state: "minecraft:spruce_fence{east:false,north:false,south:false,waterlogged:false,west:false}"},
        {pos: [1, 5, 2], state: "minecraft:spruce_fence{east:false,north:false,south:false,waterlogged:false,west:false}"},
        {pos: [1, 5, 3], state: "minecraft:spruce_fence{east:false,north:false,south:false,waterlogged:false,west:false}"},
        {pos: [1, 5, 4], state: "minecraft:spruce_fence{east:false,north:false,south:false,waterlogged:false,west:false}"},
        {pos: [1, 5, 21], state: "minecraft:spruce_planks"},
        {pos: [1, 5, 22], state: "minecraft:spruce_planks"},
        {pos: [1, 5, 23], state: "minecraft:spruce_planks"},
        {pos: [1, 5, 24], state: "minecraft:spruce_planks"},
        {pos: [1, 5, 25], state: "minecraft:spruce_planks"},
        {pos: [1, 5, 26], state: "minecraft:spruce_planks"},
        {pos: [1, 5, 27], state: "minecraft:oak_stairs{facing:north,half:bottom,shape:outer_right,waterlogged:false}"},
        {pos: [2, 5, 2], state: "minecraft:spruce_fence{east:false,north:false,south:false,waterlogged:false,west:false}"},
        {pos: [2, 5, 3], state: "minecraft:oak_stairs{facing:south,half:bottom,shape:outer_right,waterlogged:false}"},
        {pos: [2, 5, 4], state: "minecraft:oak_planks"},
        {pos: [2, 5, 20], state: "minecraft:spruce_planks"},
        {pos: [2, 5, 26], state: "minecraft:oak_planks"},
        {pos: [3, 5, 3], state: "minecraft:oak_stairs{facing:south,half:bottom,shape:outer_right,waterlogged:false}"},
        {pos: [3, 5, 4], state: "minecraft:oak_planks"},
        {pos: [3, 5, 5], state: "minecraft:spruce_planks"},
        {pos: [3, 5, 6], state: "minecraft:spruce_planks"},
        {pos: [3, 5, 7], state: "minecraft:spruce_stairs{facing:north,half:top,shape:outer_right,waterlogged:false}"},
        {pos: [3, 5, 19], state: "minecraft:oak_planks"},
        {pos: [3, 5, 25], state: "minecraft:oak_stairs{facing:south,half:top,shape:outer_right,waterlogged:false}"},
        {pos: [3, 5, 26], state: "minecraft:oak_stairs{facing:north,half:bottom,shape:outer_right,waterlogged:false}"},
        {pos: [4, 5, 4], state: "minecraft:oak_stairs{facing:south,half:bottom,shape:outer_right,waterlogged:false}"},
        {pos: [4, 5, 5], state: "minecraft:oak_planks"},
        {pos: [4, 5, 6], state: "minecraft:oak_planks"},
        {pos: [4, 5, 7], state: "minecraft:spruce_planks"},
        {pos: [4, 5, 8], state: "minecraft:spruce_planks"},
        {pos: [4, 5, 9], state: "minecraft:oak_trapdoor{facing:east,half:top,open:true,powered:false,waterlogged:false}"},
        {pos: [4, 5, 10], state: "minecraft:oak_trapdoor{facing:east,half:top,open:true,powered:false,waterlogged:false}"},
        {pos: [4, 5, 11], state: "minecraft:spruce_planks"},
        {pos: [4, 5, 12], state: "minecraft:oak_trapdoor{facing:east,half:top,open:true,powered:false,waterlogged:false}"},
        {pos: [4, 5, 13], state: "minecraft:oak_trapdoor{facing:east,half:top,open:true,powered:false,waterlogged:false}"},
        {pos: [4, 5, 14], state: "minecraft:oak_trapdoor{facing:east,half:top,open:true,powered:false,waterlogged:false}"},
        {pos: [4, 5, 15], state: "minecraft:oak_trapdoor{facing:east,half:top,open:true,powered:false,waterlogged:false}"},
        {pos: [4, 5, 16], state: "minecraft:spruce_planks"},
        {pos: [4, 5, 17], state: "minecraft:spruce_planks"},
        {pos: [4, 5, 18], state: "minecraft:spruce_planks"},
        {pos: [4, 5, 19], state: "minecraft:spruce_planks"},
        {pos: [4, 5, 25], state: "minecraft:oak_planks"},
        {pos: [5, 5, 5], state: "minecraft:oak_stairs{facing:west,half:bottom,shape:outer_right,waterlogged:false}"},
        {pos: [5, 5, 6], state: "minecraft:oak_stairs{facing:west,half:bottom,shape:outer_right,waterlogged:false}"},
        {pos: [5, 5, 7], state: "minecraft:oak_planks"},
        {pos: [5, 5, 16], state: "minecraft:oak_planks"},
        {pos: [5, 5, 20], state: "minecraft:spruce_planks"},
        {pos: [5, 5, 21], state: "minecraft:spruce_planks"},
        {pos: [5, 5, 22], state: "minecraft:spruce_planks"},
        {pos: [5, 5, 23], state: "minecraft:spruce_planks"},
        {pos: [5, 5, 24], state: "minecraft:spruce_planks"},
        {pos: [5, 5, 25], state: "minecraft:oak_planks"},
        {pos: [6, 5, 7], state: "minecraft:oak_stairs{facing:west,half:bottom,shape:outer_right,waterlogged:false}"},
        {pos: [6, 5, 8], state: "minecraft:oak_planks"},
        {pos: [6, 5, 16], state: "minecraft:oak_planks"},
        {pos: [6, 5, 20], state: "minecraft:spruce_planks"},
        {pos: [6, 5, 21], state: "minecraft:oak_planks"},
        {pos: [6, 5, 22], state: "minecraft:oak_planks"},
        {pos: [6, 5, 23], state: "minecraft:oak_planks"},
        {pos: [6, 5, 24], state: "minecraft:oak_planks"},
        {pos: [7, 5, 8], state: "minecraft:oak_stairs{facing:west,half:bottom,shape:outer_right,waterlogged:false}"},
        {pos: [7, 5, 9], state: "minecraft:oak_planks"},
        {pos: [7, 5, 10], state: "minecraft:oak_planks"},
        {pos: [7, 5, 11], state: "minecraft:oak_planks"},
        {pos: [7, 5, 12], state: "minecraft:oak_planks"},
        {pos: [7, 5, 13], state: "minecraft:oak_planks"},
        {pos: [7, 5, 14], state: "minecraft:oak_planks"},
        {pos: [7, 5, 15], state: "minecraft:oak_planks"},
        {pos: [7, 5, 16], state: "minecraft:oak_planks"},
        {pos: [7, 5, 17], state: "minecraft:oak_planks"},
        {pos: [7, 5, 18], state: "minecraft:oak_planks"},
        {pos: [7, 5, 19], state: "minecraft:oak_planks"},
        {pos: [7, 5, 20], state: "minecraft:oak_planks"},
        {pos: [7, 5, 21], state: "minecraft:oak_stairs{facing:west,half:bottom,shape:outer_right,waterlogged:false}"},
        {pos: [7, 5, 22], state: "minecraft:oak_stairs{facing:west,half:bottom,shape:outer_right,waterlogged:false}"},
        {pos: [7, 5, 23], state: "minecraft:oak_stairs{facing:west,half:bottom,shape:outer_right,waterlogged:false}"},
        {pos: [0, 6, 26], state: "minecraft:oak_planks"},
        {pos: [1, 6, 21], state: "minecraft:spruce_planks"},
        {pos: [1, 6, 22], state: "minecraft:spruce_planks"},
        {pos: [1, 6, 23], state: "minecraft:spruce_planks"},
        {pos: [1, 6, 24], state: "minecraft:spruce_planks"},
        {pos: [1, 6, 25], state: "minecraft:spruce_planks"},
        {pos: [1, 6, 26], state: "minecraft:oak_planks"},
        {pos: [2, 6, 5], state: "minecraft:oak_planks"},
        {pos: [2, 6, 19], state: "minecraft:oak_planks"},
        {pos: [2, 6, 20], state: "minecraft:spruce_planks"},
        {pos: [2, 6, 25], state: "minecraft:oak_fence{east:false,north:false,south:false,waterlogged:false,west:false}"},
        {pos: [2, 6, 26], state: "minecraft:oak_stairs{facing:north,half:bottom,shape:outer_right,waterlogged:false}"},
        {pos: [3, 6, 5], state: "minecraft:oak_planks"},
        {pos: [3, 6, 6], state: "minecraft:spruce_planks"},
        {pos: [3, 6, 7], state: "minecraft:spruce_planks"},
        {pos: [3, 6, 19], state: "minecraft:oak_planks"},
        {pos: [3, 6, 25], state: "minecraft:oak_planks"},
        {pos: [4, 6, 5], state: "minecraft:oak_stairs{facing:west,half:bottom,shape:outer_right,waterlogged:false}"},
        {pos: [4, 6, 6], state: "minecraft:oak_stairs{facing:west,half:bottom,shape:outer_right,waterlogged:false}"},
        {pos: [4, 6, 7], state: "minecraft:oak_planks"},
        {pos: [4, 6, 8], state: "minecraft:spruce_planks"},
        {pos: [4, 6, 9], state: "minecraft:spruce_planks"},
        {pos: [4, 6, 10], state: "minecraft:spruce_planks"},
        {pos: [4, 6, 11], state: "minecraft:spruce_planks"},
        {pos: [4, 6, 12], state: "minecraft:spruce_stairs{facing:west,half:top,shape:outer_right,waterlogged:false}"},
        {pos: [4, 6, 13], state: "minecraft:spruce_planks"},
        {pos: [4, 6, 14], state: "minecraft:spruce_planks"},
        {pos: [4, 6, 15], state: "minecraft:spruce_stairs{facing:west,half:top,shape:outer_right,waterlogged:false}"},
        {pos: [4, 6, 16], state: "minecraft:spruce_planks"},
        {pos: [4, 6, 17], state: "minecraft:spruce_planks"},
        {pos: [4, 6, 18], state: "minecraft:spruce_planks"},
        {pos: [4, 6, 19], state: "minecraft:spruce_planks"},
        {pos: [4, 6, 20], state: "minecraft:oak_stairs{facing:east,half:top,shape:outer_right,waterlogged:false}"},
        {pos: [4, 6, 24], state: "minecraft:oak_stairs{facing:south,half:top,shape:outer_right,waterlogged:false}"},
        {pos: [4, 6, 25], state: "minecraft:oak_stairs{facing:north,half:bottom,shape:outer_right,waterlogged:false}"},
        {pos: [5, 6, 7], state: "minecraft:oak_stairs{facing:west,half:bottom,shape:outer_right,waterlogged:false}"},
        {pos: [5, 6, 8], state: "minecraft:oak_planks"},
        {pos: [5, 6, 9], state: "minecraft:oak_planks"},
        {pos: [5, 6, 10], state: "minecraft:oak_planks"},
        {pos: [5, 6, 11], state: "minecraft:oak_planks"},
        {pos: [5, 6, 13], state: "minecraft:oak_planks"},
        {pos: [5, 6, 14], state: "minecraft:oak_planks"},
        {pos: [5, 6, 16], state: "minecraft:oak_planks"},
        {pos: [5, 6, 17], state: "minecraft:oak_planks"},
        {pos: [5, 6, 19], state: "minecraft:oak_planks"},
        {pos: [5, 6, 20], state: "minecraft:oak_planks"},
        {pos: [5, 6, 21], state: "minecraft:spruce_planks"},
        {pos: [5, 6, 22], state: "minecraft:spruce_planks"},
        {pos: [5, 6, 23], state: "minecraft:spruce_planks"},
        {pos: [5, 6, 24], state: "minecraft:spruce_planks"},
        {pos: [5, 6, 25], state: "minecraft:oak_stairs{facing:north,half:bottom,shape:outer_right,waterlogged:false}"},
        {pos: [6, 6, 8], state: "minecraft:oak_stairs{facing:west,half:bottom,shape:outer_right,waterlogged:false}"},
        {pos: [6, 6, 9], state: "minecraft:oak_planks"},
        {pos: [6, 6, 10], state: "minecraft:oak_planks"},
        {pos: [6, 6, 11], state: "minecraft:oak_planks"},
        {pos: [6, 6, 12], state: "minecraft:oak_stairs{facing:east,half:top,shape:outer_right,waterlogged:false}"},
        {pos: [6, 6, 13], state: "minecraft:oak_planks"},
        {pos: [6, 6, 14], state: "minecraft:oak_planks"},
        {pos: [6, 6, 15], state: "minecraft:oak_stairs{facing:east,half:top,shape:outer_right,waterlogged:false}"},
        {pos: [6, 6, 16], state: "minecraft:oak_planks"},
        {pos: [6, 6, 17], state: "minecraft:oak_planks"},
        {pos: [6, 6, 18], state: "minecraft:oak_stairs{facing:east,half:top,shape:outer_right,waterlogged:false}"},
        {pos: [6, 6, 19], state: "minecraft:oak_planks"},
        {pos: [6, 6, 20], state: "minecraft:oak_planks"},
        {pos: [6, 6, 21], state: "minecraft:oak_stairs{facing:west,half:bottom,shape:outer_right,waterlogged:false}"},
        {pos: [6, 6, 22], state: "minecraft:oak_stairs{facing:west,half:bottom,shape:outer_right,waterlogged:false}"},
        {pos: [6, 6, 23], state: "minecraft:oak_stairs{facing:west,half:bottom,shape:outer_right,waterlogged:false}"},
        {pos: [6, 6, 24], state: "minecraft:oak_stairs{facing:west,half:bottom,shape:outer_right,waterlogged:false}"},
        {pos: [7, 6, 9], state: "minecraft:oak_stairs{facing:west,half:bottom,shape:outer_right,waterlogged:false}"},
        {pos: [7, 6, 10], state: "minecraft:oak_stairs{facing:west,half:bottom,shape:outer_right,waterlogged:false}"},
        {pos: [7, 6, 11], state: "minecraft:oak_stairs{facing:west,half:bottom,shape:outer_right,waterlogged:false}"},
        {pos: [7, 6, 12], state: "minecraft:oak_stairs{facing:west,half:bottom,shape:outer_right,waterlogged:false}"},
        {pos: [7, 6, 13], state: "minecraft:oak_stairs{facing:west,half:bottom,shape:outer_right,waterlogged:false}"},
        {pos: [7, 6, 14], state: "minecraft:oak_stairs{facing:west,half:bottom,shape:outer_right,waterlogged:false}"},
        {pos: [7, 6, 15], state: "minecraft:oak_stairs{facing:west,half:bottom,shape:outer_right,waterlogged:false}"},
        {pos: [7, 6, 16], state: "minecraft:oak_stairs{facing:west,half:bottom,shape:outer_right,waterlogged:false}"},
        {pos: [7, 6, 17], state: "minecraft:oak_stairs{facing:west,half:bottom,shape:outer_right,waterlogged:false}"},
        {pos: [7, 6, 18], state: "minecraft:oak_stairs{facing:west,half:bottom,shape:outer_right,waterlogged:false}"},
        {pos: [7, 6, 19], state: "minecraft:oak_stairs{facing:west,half:bottom,shape:outer_right,waterlogged:false}"},
        {pos: [7, 6, 20], state: "minecraft:oak_stairs{facing:west,half:bottom,shape:outer_right,waterlogged:false}"},
        {pos: [0, 7, 21], state: "minecraft:oak_planks"},
        {pos: [0, 7, 23], state: "minecraft:spruce_fence{east:false,north:false,south:false,waterlogged:false,west:false}"},
        {pos: [0, 7, 24], state: "minecraft:spruce_fence{east:false,north:false,south:false,waterlogged:false,west:false}"},
        {pos: [0, 7, 25], state: "minecraft:oak_planks"},
        {pos: [1, 7, 21], state: "minecraft:oak_planks"},
        {pos: [1, 7, 22], state: "minecraft:spruce_planks"},
        {pos: [1, 7, 23], state: "minecraft:spruce_planks"},
        {pos: [1, 7, 24], state: "minecraft:oak_planks"},
        {pos: [1, 7, 25], state: "minecraft:oak_planks"},
        {pos: [2, 7, 6], state: "minecraft:oak_planks"},
        {pos: [2, 7, 7], state: "minecraft:oak_planks"},
        {pos: [2, 7, 8], state: "minecraft:oak_stairs{facing:north,half:top,shape:outer_right,waterlogged:false}"},
        {pos: [2, 7, 19], state: "minecraft:spruce_stairs{facing:south,half:top,shape:outer_right,waterlogged:false}"},
        {pos: [2, 7, 20], state: "minecraft:spruce_planks"},
        {pos: [2, 7, 21], state: "minecraft:oak_fence{east:false,north:false,south:false,waterlogged:false,west:false}"},
        {pos: [2, 7, 23], state: "minecraft:oak_fence{east:false,north:false,south:false,waterlogged:false,west:false}"},
        {pos: [2, 7, 24], state: "minecraft:oak_planks"},
        {pos: [2, 7, 25], state: "minecraft:oak_planks"},
        {pos: [3, 7, 6], state: "minecraft:oak_stairs{facing:west,half:bottom,shape:outer_right,waterlogged:false}"},
        {pos: [3, 7, 7], state: "minecraft:oak_planks"},
        {pos: [3, 7, 8], state: "minecraft:oak_planks"},
        {pos: [3, 7, 18], state: "minecraft:spruce_stairs{facing:south,half:top,shape:outer_right,waterlogged:false}"},
        {pos: [3, 7, 19], state: "minecraft:spruce_planks"},
        {pos: [3, 7, 20], state: "minecraft:oak_planks"},
        {pos: [3, 7, 21], state: "minecraft:oak_planks"},
        {pos: [3, 7, 22], state: "minecraft:oak_stairs{facing:east,half:top,shape:outer_right,waterlogged:false}"},
        {pos: [3, 7, 23], state: "minecraft:oak_planks"},
        {pos: [3, 7, 24], state: "minecraft:oak_planks"},
        {pos: [3, 7, 25], state: "minecraft:oak_stairs{facing:north,half:bottom,shape:outer_right,waterlogged:false}"},
        {pos: [4, 7, 7], state: "minecraft:oak_stairs{facing:west,half:bottom,shape:outer_right,waterlogged:false}"},
        {pos: [4, 7, 8], state: "minecraft:oak_planks"},
        {pos: [4, 7, 9], state: "minecraft:spruce_planks"},
        {pos: [4, 7, 10], state: "minecraft:spruce_planks"},
        {pos: [4, 7, 11], state: "minecraft:spruce_planks"},
        {pos: [4, 7, 12], state: "minecraft:spruce_planks"},
        {pos: [4, 7, 13], state: "minecraft:spruce_planks"},
        {pos: [4, 7, 14], state: "minecraft:spruce_planks"},
        {pos: [4, 7, 15], state: "minecraft:spruce_planks"},
        {pos: [4, 7, 16], state: "minecraft:spruce_planks"},
        {pos: [4, 7, 17], state: "minecraft:spruce_planks"},
        {pos: [4, 7, 18], state: "minecraft:spruce_planks"},
        {pos: [4, 7, 19], state: "minecraft:oak_planks"},
        {pos: [4, 7, 20], state: "minecraft:oak_planks"},
        {pos: [4, 7, 21], state: "minecraft:oak_planks"},
        {pos: [4, 7, 22], state: "minecraft:oak_planks"},
        {pos: [4, 7, 23], state: "minecraft:oak_planks"},
        {pos: [4, 7, 24], state: "minecraft:oak_planks"},
        {pos: [5, 7, 8], state: "minecraft:oak_stairs{facing:west,half:bottom,shape:outer_right,waterlogged:false}"},
        {pos: [5, 7, 9], state: "minecraft:oak_planks"},
        {pos: [5, 7, 10], state: "minecraft:oak_planks"},
        {pos: [5, 7, 11], state: "minecraft:oak_planks"},
        {pos: [5, 7, 13], state: "minecraft:oak_planks"},
        {pos: [5, 7, 14], state: "minecraft:oak_planks"},
        {pos: [5, 7, 16], state: "minecraft:oak_planks"},
        {pos: [5, 7, 17], state: "minecraft:oak_planks"},
        {pos: [5, 7, 19], state: "minecraft:oak_planks"},
        {pos: [5, 7, 20], state: "minecraft:oak_planks"},
        {pos: [5, 7, 21], state: "minecraft:oak_stairs{facing:west,half:bottom,shape:outer_right,waterlogged:false}"},
        {pos: [5, 7, 22], state: "minecraft:oak_stairs{facing:west,half:bottom,shape:outer_right,waterlogged:false}"},
        {pos: [5, 7, 23], state: "minecraft:oak_stairs{facing:west,half:bottom,shape:outer_right,waterlogged:false}"},
        {pos: [5, 7, 24], state: "minecraft:oak_stairs{facing:west,half:bottom,shape:outer_right,waterlogged:false}"},
        {pos: [6, 7, 9], state: "minecraft:oak_stairs{facing:west,half:bottom,shape:outer_right,waterlogged:false}"},
        {pos: [6, 7, 10], state: "minecraft:oak_stairs{facing:west,half:bottom,shape:outer_right,waterlogged:false}"},
        {pos: [6, 7, 11], state: "minecraft:oak_stairs{facing:west,half:bottom,shape:outer_right,waterlogged:false}"},
        {pos: [6, 7, 12], state: "minecraft:oak_stairs{facing:west,half:bottom,shape:outer_right,waterlogged:false}"},
        {pos: [6, 7, 13], state: "minecraft:oak_stairs{facing:west,half:bottom,shape:outer_right,waterlogged:false}"},
        {pos: [6, 7, 14], state: "minecraft:oak_stairs{facing:west,half:bottom,shape:outer_right,waterlogged:false}"},
        {pos: [6, 7, 15], state: "minecraft:oak_stairs{facing:west,half:bottom,shape:outer_right,waterlogged:false}"},
        {pos: [6, 7, 16], state: "minecraft:oak_stairs{facing:west,half:bottom,shape:outer_right,waterlogged:false}"},
        {pos: [6, 7, 17], state: "minecraft:oak_stairs{facing:west,half:bottom,shape:outer_right,waterlogged:false}"},
        {pos: [6, 7, 18], state: "minecraft:oak_stairs{facing:west,half:bottom,shape:outer_right,waterlogged:false}"},
        {pos: [6, 7, 19], state: "minecraft:oak_stairs{facing:west,half:bottom,shape:outer_right,waterlogged:false}"},
        {pos: [6, 7, 20], state: "minecraft:oak_stairs{facing:west,half:bottom,shape:outer_right,waterlogged:false}"},
        {pos: [0, 8, 21], state: "minecraft:oak_stairs{facing:east,half:bottom,shape:outer_right,waterlogged:false}"},
        {pos: [0, 8, 22], state: "minecraft:oak_stairs{facing:east,half:bottom,shape:outer_right,waterlogged:false}"},
        {pos: [0, 8, 23], state: "minecraft:oak_stairs{facing:east,half:bottom,shape:outer_right,waterlogged:false}"},
        {pos: [1, 8, 20], state: "minecraft:oak_stairs{facing:south,half:bottom,shape:outer_right,waterlogged:false}"},
        {pos: [1, 8, 21], state: "minecraft:oak_planks"},
        {pos: [1, 8, 22], state: "minecraft:oak_planks"},
        {pos: [1, 8, 23], state: "minecraft:oak_planks"},
        {pos: [2, 8, 8], state: "minecraft:oak_planks"},
        {pos: [2, 8, 9], state: "minecraft:oak_stairs{facing:north,half:top,shape:outer_right,waterlogged:false}"},
        {pos: [2, 8, 18], state: "minecraft:oak_stairs{facing:south,half:top,shape:outer_right,waterlogged:false}"},
        {pos: [2, 8, 19], state: "minecraft:oak_planks"},
        {pos: [2, 8, 20], state: "minecraft:oak_planks"},
        {pos: [2, 8, 21], state: "minecraft:oak_planks"},
        {pos: [2, 8, 23], state: "minecraft:oak_planks"},
        {pos: [3, 8, 8], state: "minecraft:oak_stairs{facing:south,half:bottom,shape:outer_right,waterlogged:false}"},
        {pos: [3, 8, 9], state: "minecraft:oak_planks"},
        {pos: [3, 8, 10], state: "minecraft:oak_planks"},
        {pos: [3, 8, 11], state: "minecraft:spruce_fence{east:false,north:false,south:false,waterlogged:false,west:false}"},
        {pos: [3, 8, 12], state: "minecraft:spruce_fence{east:false,north:false,south:false,waterlogged:false,west:false}"},
        {pos: [3, 8, 13], state: "minecraft:spruce_fence{east:false,north:false,south:false,waterlogged:false,west:false}"},
        {pos: [3, 8, 15], state: "minecraft:spruce_fence{east:false,north:false,south:false,waterlogged:false,west:false}"},
        {pos: [3, 8, 16], state: "minecraft:spruce_fence{east:false,north:false,south:false,waterlogged:false,west:false}"},
        {pos: [3, 8, 17], state: "minecraft:spruce_fence{east:false,north:false,south:false,waterlogged:false,west:false}"},
        {pos: [3, 8, 18], state: "minecraft:oak_planks"},
        {pos: [3, 8, 19], state: "minecraft:oak_planks"},
        {pos: [3, 8, 20], state: "minecraft:oak_planks"},
        {pos: [3, 8, 21], state: "minecraft:oak_stairs{facing:west,half:bottom,shape:outer_right,waterlogged:false}"},
        {pos: [3, 8, 22], state: "minecraft:oak_stairs{facing:west,half:bottom,shape:outer_right,waterlogged:false}"},
        {pos: [3, 8, 23], state: "minecraft:oak_stairs{facing:north,half:bottom,shape:outer_right,waterlogged:false}"},
        {pos: [4, 8, 9], state: "minecraft:oak_stairs{facing:west,half:bottom,shape:outer_right,waterlogged:false}"},
        {pos: [4, 8, 10], state: "minecraft:oak_stairs{facing:west,half:bottom,shape:outer_right,waterlogged:false}"},
        {pos: [4, 8, 11], state: "minecraft:oak_stairs{facing:west,half:bottom,shape:outer_right,waterlogged:false}"},
        {pos: [4, 8, 12], state: "minecraft:oak_stairs{facing:west,half:bottom,shape:outer_right,waterlogged:false}"},
        {pos: [4, 8, 13], state: "minecraft:oak_stairs{facing:west,half:bottom,shape:outer_right,waterlogged:false}"},
        {pos: [4, 8, 14], state: "minecraft:oak_stairs{facing:west,half:bottom,shape:outer_right,waterlogged:false}"},
        {pos: [4, 8, 15], state: "minecraft:oak_stairs{facing:west,half:bottom,shape:outer_right,waterlogged:false}"},
        {pos: [4, 8, 16], state: "minecraft:oak_stairs{facing:west,half:bottom,shape:outer_right,waterlogged:false}"},
        {pos: [4, 8, 17], state: "minecraft:oak_stairs{facing:west,half:bottom,shape:outer_right,waterlogged:false}"},
        {pos: [4, 8, 18], state: "minecraft:oak_stairs{facing:west,half:bottom,shape:outer_right,waterlogged:false}"},
        {pos: [4, 8, 19], state: "minecraft:oak_stairs{facing:west,half:bottom,shape:outer_right,waterlogged:false}"},
        {pos: [4, 8, 20], state: "minecraft:oak_stairs{facing:west,half:bottom,shape:outer_right,waterlogged:false}"}
    ],
    entities: [],
    palette: [
        "minecraft:oak_planks",
        "minecraft:spruce_planks",
        "minecraft:oak_log{axis:x}",
        "minecraft:oak_stairs{facing:east,half:top,shape:outer_right,waterlogged:false}",
        "minecraft:oak_stairs{facing:south,half:bottom,shape:outer_right,waterlogged:false}",
        "minecraft:oak_stairs{facing:north,half:bottom,shape:outer_right,waterlogged:false}",
        "minecraft:oak_stairs{facing:south,half:top,shape:outer_right,waterlogged:false}",
        "minecraft:spruce_fence{east:false,north:false,south:false,waterlogged:false,west:false}",
        "minecraft:oak_stairs{facing:west,half:top,shape:outer_right,waterlogged:false}",
        "minecraft:oak_stairs{facing:north,half:top,shape:outer_right,waterlogged:false}",
        "minecraft:spruce_stairs{facing:south,half:bottom,shape:outer_right,waterlogged:false}",
        "minecraft:oak_fence{east:false,north:false,south:false,waterlogged:false,west:false}",
        "minecraft:oak_stairs{facing:east,half:bottom,shape:outer_right,waterlogged:false}",
        "minecraft:spruce_stairs{facing:west,half:bottom,shape:outer_right,waterlogged:false}",
        "minecraft:spruce_stairs{facing:north,half:bottom,shape:outer_right,waterlogged:false}",
        "minecraft:oak_trapdoor{facing:east,half:bottom,open:true,powered:false,waterlogged:false}",
        "minecraft:spruce_stairs{facing:south,half:top,shape:outer_right,waterlogged:false}",
        "minecraft:spruce_stairs{facing:north,half:top,shape:outer_right,waterlogged:false}",
        "minecraft:oak_trapdoor{facing:east,half:top,open:true,powered:false,waterlogged:false}",
        "minecraft:oak_stairs{facing:west,half:bottom,shape:outer_right,waterlogged:false}",
        "minecraft:spruce_stairs{facing:west,half:top,shape:outer_right,waterlogged:false}",
        "minecraft:chest{facing:north,type:single,waterlogged:false}",
        "minecraft:structure_block{mode:data}",
        "minecraft:chest{facing:south,type:single,waterlogged:false}"
    ],
    palettes: [
        {
            "minecraft:chest{facing:north,type:single,waterlogged:false}": "minecraft:chest{facing:north,type:single,waterlogged:false}",
            "minecraft:chest{facing:south,type:single,waterlogged:false}": "minecraft:chest{facing:south,type:single,waterlogged:false}",
            "minecraft:oak_fence{east:false,north:false,south:false,waterlogged:false,west:false}": "minecraft:oak_fence{east:false,north:false,south:false,waterlogged:false,west:false}",
            "minecraft:oak_log{axis:x}": "minecraft:oak_log{axis:x}",
            "minecraft:oak_planks": "minecraft:oak_planks",
            "minecraft:oak_stairs{facing:east,half:bottom,shape:outer_right,waterlogged:false}": "minecraft:oak_stairs{facing:east,half:bottom,shape:outer_right,waterlogged:false}",
            "minecraft:oak_stairs{facing:east,half:top,shape:outer_right,waterlogged:false}": "minecraft:oak_stairs{facing:east,half:top,shape:outer_right,waterlogged:false}",
            "minecraft:oak_stairs{facing:north,half:bottom,shape:outer_right,waterlogged:false}": "minecraft:oak_stairs{facing:north,half:bottom,shape:outer_right,waterlogged:false}",
            "minecraft:oak_stairs{facing:north,half:top,shape:outer_right,waterlogged:false}": "minecraft:oak_stairs{facing:north,half:top,shape:outer_right,waterlogged:false}",
            "minecraft:oak_stairs{facing:south,half:bottom,shape:outer_right,waterlogged:false}": "minecraft:oak_stairs{facing:south,half:bottom,shape:outer_right,waterlogged:false}",
            "minecraft:oak_stairs{facing:south,half:top,shape:outer_right,waterlogged:false}": "minecraft:oak_stairs{facing:south,half:top,shape:outer_right,waterlogged:false}",
            "minecraft:oak_stairs{facing:west,half:bottom,shape:outer_right,waterlogged:false}": "minecraft:oak_stairs{facing:west,half:bottom,shape:outer_right,waterlogged:false}",
            "minecraft:oak_stairs{facing:west,half:top,shape:outer_right,waterlogged:false}": "minecraft:oak_stairs{facing:west,half:top,shape:outer_right,waterlogged:false}",
            "minecraft:oak_trapdoor{facing:east,half:bottom,open:true,powered:false,waterlogged:false}": "minecraft:oak_trapdoor{facing:east,half:bottom,open:true,powered:false,waterlogged:false}",
            "minecraft:oak_trapdoor{facing:east,half:top,open:true,powered:false,waterlogged:false}": "minecraft:oak_trapdoor{facing:east,half:top,open:true,powered:false,waterlogged:false}",
            "minecraft:spruce_fence{east:false,north:false,south:false,waterlogged:false,west:false}": "minecraft:spruce_fence{east:false,north:false,south:false,waterlogged:false,west:false}",
            "minecraft:spruce_planks": "minecraft:spruce_planks",
            "minecraft:spruce_stairs{facing:north,half:bottom,shape:outer_right,waterlogged:false}": "minecraft:spruce_stairs{facing:north,half:bottom,shape:outer_right,waterlogged:false}",
            "minecraft:spruce_stairs{facing:north,half:top,shape:outer_right,waterlogged:false}": "minecraft:spruce_stairs{facing:north,half:top,shape:outer_right,waterlogged:false}",
            "minecraft:spruce_stairs{facing:south,half:bottom,shape:outer_right,waterlogged:false}": "minecraft:spruce_stairs{facing:south,half:bottom,shape:outer_right,waterlogged:false}",
            "minecraft:spruce_stairs{facing:south,half:top,shape:outer_right,waterlogged:false}": "minecraft:spruce_stairs{facing:south,half:top,shape:outer_right,waterlogged:false}",
            "minecraft:spruce_stairs{facing:west,half:bottom,shape:outer_right,waterlogged:false}": "minecraft:spruce_stairs{facing:west,half:bottom,shape:outer_right,waterlogged:false}",
            "minecraft:spruce_stairs{facing:west,half:top,shape:outer_right,waterlogged:false}": "minecraft:spruce_stairs{facing:west,half:top,shape:outer_right,waterlogged:false}",
            "minecraft:structure_block{mode:data}": "minecraft:structure_block{mode:data}"
        },
        {
            "minecraft:chest{facing:north,type:single,waterlogged:false}": "minecraft:chest{facing:north,type:single,waterlogged:false}",
            "minecraft:chest{facing:south,type:single,waterlogged:false}": "minecraft:chest{facing:south,type:single,waterlogged:false}",
            "minecraft:oak_fence{east:false,north:false,south:false,waterlogged:false,west:false}": "minecraft:jungle_fence{east:false,north:false,south:false,waterlogged:false,west:false}",
            "minecraft:oak_log{axis:x}": "minecraft:jungle_log{axis:x}",
            "minecraft:oak_planks": "minecraft:jungle_planks",
            "minecraft:oak_stairs{facing:east,half:bottom,shape:outer_right,waterlogged:false}": "minecraft:jungle_stairs{facing:east,half:bottom,shape:outer_right,waterlogged:false}",
            "minecraft:oak_stairs{facing:east,half:top,shape:outer_right,waterlogged:false}": "minecraft:jungle_stairs{facing:east,half:top,shape:outer_right,waterlogged:false}",
            "minecraft:oak_stairs{facing:north,half:bottom,shape:outer_right,waterlogged:false}": "minecraft:jungle_stairs{facing:north,half:bottom,shape:outer_right,waterlogged:false}",
            "minecraft:oak_stairs{facing:north,half:top,shape:outer_right,waterlogged:false}": "minecraft:jungle_stairs{facing:north,half:top,shape:outer_right,waterlogged:false}",
            "minecraft:oak_stairs{facing:south,half:bottom,shape:outer_right,waterlogged:false}": "minecraft:jungle_stairs{facing:south,half:bottom,shape:outer_right,waterlogged:false}",
            "minecraft:oak_stairs{facing:south,half:top,shape:outer_right,waterlogged:false}": "minecraft:jungle_stairs{facing:south,half:top,shape:outer_right,waterlogged:false}",
            "minecraft:oak_stairs{facing:west,half:bottom,shape:outer_right,waterlogged:false}": "minecraft:jungle_stairs{facing:west,half:bottom,shape:outer_right,waterlogged:false}",
            "minecraft:oak_stairs{facing:west,half:top,shape:outer_right,waterlogged:false}": "minecraft:jungle_stairs{facing:west,half:top,shape:outer_right,waterlogged:false}",
            "minecraft:oak_trapdoor{facing:east,half:bottom,open:true,powered:false,waterlogged:false}": "minecraft:jungle_trapdoor{facing:east,half:bottom,open:true,powered:false,waterlogged:false}",
            "minecraft:oak_trapdoor{facing:east,half:top,open:true,powered:false,waterlogged:false}": "minecraft:jungle_trapdoor{facing:east,half:top,open:true,powered:false,waterlogged:false}",
            "minecraft:spruce_fence{east:false,north:false,south:false,waterlogged:false,west:false}": "minecraft:spruce_fence{east:false,north:false,south:false,waterlogged:false,west:false}",
            "minecraft:spruce_planks": "minecraft:spruce_planks",
            "minecraft:spruce_stairs{facing:north,half:bottom,shape:outer_right,waterlogged:false}": "minecraft:spruce_stairs{facing:north,half:bottom,shape:outer_right,waterlogged:false}",
            "minecraft:spruce_stairs{facing:north,half:top,shape:outer_right,waterlogged:false}": "minecraft:spruce_stairs{facing:north,half:top,shape:outer_right,waterlogged:false}",
            "minecraft:spruce_stairs{facing:south,half:bottom,shape:outer_right,waterlogged:false}": "minecraft:spruce_stairs{facing:south,half:bottom,shape:outer_right,waterlogged:false}",
            "minecraft:spruce_stairs{facing:south,half:top,shape:outer_right,waterlogged:false}": "minecraft:spruce_stairs{facing:south,half:top,shape:outer_right,waterlogged:false}",
            "minecraft:spruce_stairs{facing:west,half:bottom,shape:outer_right,waterlogged:false}": "minecraft:spruce_stairs{facing:west,half:bottom,shape:outer_right,waterlogged:false}",
            "minecraft:spruce_stairs{facing:west,half:top,shape:outer_right,waterlogged:false}": "minecraft:spruce_stairs{facing:west,half:top,shape:outer_right,waterlogged:false}",
            "minecraft:structure_block{mode:data}": "minecraft:structure_block{mode:data}"
        },
        {
            "minecraft:chest{facing:north,type:single,waterlogged:false}": "minecraft:chest{facing:north,type:single,waterlogged:false}",
            "minecraft:chest{facing:south,type:single,waterlogged:false}": "minecraft:chest{facing:south,type:single,waterlogged:false}",
            "minecraft:oak_fence{east:false,north:false,south:false,waterlogged:false,west:false}": "minecraft:dark_oak_fence{east:false,north:false,south:false,waterlogged:false,west:false}",
            "minecraft:oak_log{axis:x}": "minecraft:dark_oak_log{axis:x}",
            "minecraft:oak_planks": "minecraft:dark_oak_planks",
            "minecraft:oak_stairs{facing:east,half:bottom,shape:outer_right,waterlogged:false}": "minecraft:dark_oak_stairs{facing:east,half:bottom,shape:outer_right,waterlogged:false}",
            "minecraft:oak_stairs{facing:east,half:top,shape:outer_right,waterlogged:false}": "minecraft:dark_oak_stairs{facing:east,half:top,shape:outer_right,waterlogged:false}",
            "minecraft:oak_stairs{facing:north,half:bottom,shape:outer_right,waterlogged:false}": "minecraft:dark_oak_stairs{facing:north,half:bottom,shape:outer_right,waterlogged:false}",
            "minecraft:oak_stairs{facing:north,half:top,shape:outer_right,waterlogged:false}": "minecraft:dark_oak_stairs{facing:north,half:top,shape:outer_right,waterlogged:false}",
            "minecraft:oak_stairs{facing:south,half:bottom,shape:outer_right,waterlogged:false}": "minecraft:dark_oak_stairs{facing:south,half:bottom,shape:outer_right,waterlogged:false}",
            "minecraft:oak_stairs{facing:south,half:top,shape:outer_right,waterlogged:false}": "minecraft:dark_oak_stairs{facing:south,half:top,shape:outer_right,waterlogged:false}",
            "minecraft:oak_stairs{facing:west,half:bottom,shape:outer_right,waterlogged:false}": "minecraft:dark_oak_stairs{facing:west,half:bottom,shape:outer_right,waterlogged:false}",
            "minecraft:oak_stairs{facing:west,half:top,shape:outer_right,waterlogged:false}": "minecraft:dark_oak_stairs{facing:west,half:top,shape:outer_right,waterlogged:false}",
            "minecraft:oak_trapdoor{facing:east,half:bottom,open:true,powered:false,waterlogged:false}": "minecraft:dark_oak_trapdoor{facing:east,half:bottom,open:true,powered:false,waterlogged:false}",
            "minecraft:oak_trapdoor{facing:east,half:top,open:true,powered:false,waterlogged:false}": "minecraft:dark_oak_trapdoor{facing:east,half:top,open:true,powered:false,waterlogged:false}",
            "minecraft:spruce_fence{east:false,north:false,south:false,waterlogged:false,west:false}": "minecraft:jungle_fence{east:false,north:false,south:false,waterlogged:false,west:false}",
            "minecraft:spruce_planks": "minecraft:jungle_planks",
            "minecraft:spruce_stairs{facing:north,half:bottom,shape:outer_right,waterlogged:false}": "minecraft:jungle_stairs{facing:north,half:bottom,shape:outer_right,waterlogged:false}",
            "minecraft:spruce_stairs{facing:north,half:top,shape:outer_right,waterlogged:false}": "minecraft:jungle_stairs{facing:north,half:top,shape:outer_right,waterlogged:false}",
            "minecraft:spruce_stairs{facing:south,half:bottom,shape:outer_right,waterlogged:false}": "minecraft:jungle_stairs{facing:south,half:bottom,shape:outer_right,waterlogged:false}",
            "minecraft:spruce_stairs{facing:south,half:top,shape:outer_right,waterlogged:false}": "minecraft:jungle_stairs{facing:south,half:top,shape:outer_right,waterlogged:false}",
            "minecraft:spruce_stairs{facing:west,half:bottom,shape:outer_right,waterlogged:false}": "minecraft:jungle_stairs{facing:west,half:bottom,shape:outer_right,waterlogged:false}",
            "minecraft:spruce_stairs{facing:west,half:top,shape:outer_right,waterlogged:false}": "minecraft:jungle_stairs{facing:west,half:top,shape:outer_right,waterlogged:false}",
            "minecraft:structure_block{mode:data}": "minecraft:structure_block{mode:data}"
        },
        {
            "minecraft:chest{facing:north,type:single,waterlogged:false}": "minecraft:chest{facing:north,type:single,waterlogged:false}",
            "minecraft:chest{facing:south,type:single,waterlogged:false}": "minecraft:chest{facing:south,type:single,waterlogged:false}",
            "minecraft:oak_fence{east:false,north:false,south:false,waterlogged:false,west:false}": "minecraft:dark_oak_fence{east:false,north:false,south:false,waterlogged:false,west:false}",
            "minecraft:oak_log{axis:x}": "minecraft:dark_oak_log{axis:x}",
            "minecraft:oak_planks": "minecraft:dark_oak_planks",
            "minecraft:oak_stairs{facing:east,half:bottom,shape:outer_right,waterlogged:false}": "minecraft:dark_oak_stairs{facing:east,half:bottom,shape:outer_right,waterlogged:false}",
            "minecraft:oak_stairs{facing:east,half:top,shape:outer_right,waterlogged:false}": "minecraft:dark_oak_stairs{facing:east,half:top,shape:outer_right,waterlogged:false}",
            "minecraft:oak_stairs{facing:north,half:bottom,shape:outer_right,waterlogged:false}": "minecraft:dark_oak_stairs{facing:north,half:bottom,shape:outer_right,waterlogged:false}",
            "minecraft:oak_stairs{facing:north,half:top,shape:outer_right,waterlogged:false}": "minecraft:dark_oak_stairs{facing:north,half:top,shape:outer_right,waterlogged:false}",
            "minecraft:oak_stairs{facing:south,half:bottom,shape:outer_right,waterlogged:false}": "minecraft:dark_oak_stairs{facing:south,half:bottom,shape:outer_right,waterlogged:false}",
            "minecraft:oak_stairs{facing:south,half:top,shape:outer_right,waterlogged:false}": "minecraft:dark_oak_stairs{facing:south,half:top,shape:outer_right,waterlogged:false}",
            "minecraft:oak_stairs{facing:west,half:bottom,shape:outer_right,waterlogged:false}": "minecraft:dark_oak_stairs{facing:west,half:bottom,shape:outer_right,waterlogged:false}",
            "minecraft:oak_stairs{facing:west,half:top,shape:outer_right,waterlogged:false}": "minecraft:dark_oak_stairs{facing:west,half:top,shape:outer_right,waterlogged:false}",
            "minecraft:oak_trapdoor{facing:east,half:bottom,open:true,powered:false,waterlogged:false}": "minecraft:dark_oak_trapdoor{facing:east,half:bottom,open:true,powered:false,waterlogged:false}",
            "minecraft:oak_trapdoor{facing:east,half:top,open:true,powered:false,waterlogged:false}": "minecraft:dark_oak_trapdoor{facing:east,half:top,open:true,powered:false,waterlogged:false}",
            "minecraft:spruce_fence{east:false,north:false,south:false,waterlogged:false,west:false}": "minecraft:spruce_fence{east:false,north:false,south:false,waterlogged:false,west:false}",
            "minecraft:spruce_planks": "minecraft:spruce_planks",
            "minecraft:spruce_stairs{facing:north,half:bottom,shape:outer_right,waterlogged:false}": "minecraft:spruce_stairs{facing:north,half:bottom,shape:outer_right,waterlogged:false}",
            "minecraft:spruce_stairs{facing:north,half:top,shape:outer_right,waterlogged:false}": "minecraft:spruce_stairs{facing:north,half:top,shape:outer_right,waterlogged:false}",
            "minecraft:spruce_stairs{facing:south,half:bottom,shape:outer_right,waterlogged:false}": "minecraft:spruce_stairs{facing:south,half:bottom,shape:outer_right,waterlogged:false}",
            "minecraft:spruce_stairs{facing:south,half:top,shape:outer_right,waterlogged:false}": "minecraft:spruce_stairs{facing:south,half:top,shape:outer_right,waterlogged:false}",
            "minecraft:spruce_stairs{facing:west,half:bottom,shape:outer_right,waterlogged:false}": "minecraft:spruce_stairs{facing:west,half:bottom,shape:outer_right,waterlogged:false}",
            "minecraft:spruce_stairs{facing:west,half:top,shape:outer_right,waterlogged:false}": "minecraft:spruce_stairs{facing:west,half:top,shape:outer_right,waterlogged:false}",
            "minecraft:structure_block{mode:data}": "minecraft:structure_block{mode:data}"
        },
        {
            "minecraft:chest{facing:north,type:single,waterlogged:false}": "minecraft:chest{facing:north,type:single,waterlogged:false}",
            "minecraft:chest{facing:south,type:single,waterlogged:false}": "minecraft:chest{facing:south,type:single,waterlogged:false}",
            "minecraft:oak_fence{east:false,north:false,south:false,waterlogged:false,west:false}": "minecraft:spruce_fence{east:false,north:false,south:false,waterlogged:false,west:false}",
            "minecraft:oak_log{axis:x}": "minecraft:spruce_log{axis:x}",
            "minecraft:oak_planks": "minecraft:spruce_planks",
            "minecraft:oak_stairs{facing:east,half:bottom,shape:outer_right,waterlogged:false}": "minecraft:spruce_stairs{facing:east,half:bottom,shape:outer_right,waterlogged:false}",
            "minecraft:oak_stairs{facing:east,half:top,shape:outer_right,waterlogged:false}": "minecraft:spruce_stairs{facing:east,half:top,shape:outer_right,waterlogged:false}",
            "minecraft:oak_stairs{facing:north,half:bottom,shape:outer_right,waterlogged:false}": "minecraft:spruce_stairs{facing:north,half:bottom,shape:outer_right,waterlogged:false}",
            "minecraft:oak_stairs{facing:north,half:top,shape:outer_right,waterlogged:false}": "minecraft:spruce_stairs{facing:north,half:top,shape:outer_right,waterlogged:false}",
            "minecraft:oak_stairs{facing:south,half:bottom,shape:outer_right,waterlogged:false}": "minecraft:spruce_stairs{facing:south,half:bottom,shape:outer_right,waterlogged:false}",
            "minecraft:oak_stairs{facing:south,half:top,shape:outer_right,waterlogged:false}": "minecraft:spruce_stairs{facing:south,half:top,shape:outer_right,waterlogged:false}",
            "minecraft:oak_stairs{facing:west,half:bottom,shape:outer_right,waterlogged:false}": "minecraft:spruce_stairs{facing:west,half:bottom,shape:outer_right,waterlogged:false}",
            "minecraft:oak_stairs{facing:west,half:top,shape:outer_right,waterlogged:false}": "minecraft:spruce_stairs{facing:west,half:top,shape:outer_right,waterlogged:false}",
            "minecraft:oak_trapdoor{facing:east,half:bottom,open:true,powered:false,waterlogged:false}": "minecraft:spruce_trapdoor{facing:east,half:bottom,open:true,powered:false,waterlogged:false}",
            "minecraft:oak_trapdoor{facing:east,half:top,open:true,powered:false,waterlogged:false}": "minecraft:spruce_trapdoor{facing:east,half:top,open:true,powered:false,waterlogged:false}",
            "minecraft:spruce_fence{east:false,north:false,south:false,waterlogged:false,west:false}": "minecraft:oak_fence{east:false,north:false,south:false,waterlogged:false,west:false}",
            "minecraft:spruce_planks": "minecraft:oak_planks",
            "minecraft:spruce_stairs{facing:north,half:bottom,shape:outer_right,waterlogged:false}": "minecraft:oak_stairs{facing:north,half:bottom,shape:outer_right,waterlogged:false}",
            "minecraft:spruce_stairs{facing:north,half:top,shape:outer_right,waterlogged:false}": "minecraft:oak_stairs{facing:north,half:top,shape:outer_right,waterlogged:false}",
            "minecraft:spruce_stairs{facing:south,half:bottom,shape:outer_right,waterlogged:false}": "minecraft:oak_stairs{facing:south,half:bottom,shape:outer_right,waterlogged:false}",
            "minecraft:spruce_stairs{facing:south,half:top,shape:outer_right,waterlogged:false}": "minecraft:oak_stairs{facing:south,half:top,shape:outer_right,waterlogged:false}",
            "minecraft:spruce_stairs{facing:west,half:bottom,shape:outer_right,waterlogged:false}": "minecraft:oak_stairs{facing:west,half:bottom,shape:outer_right,waterlogged:false}",
            "minecraft:spruce_stairs{facing:west,half:top,shape:outer_right,waterlogged:false}": "minecraft:oak_stairs{facing:west,half:top,shape:outer_right,waterlogged:false}",
            "minecraft:structure_block{mode:data}": "minecraft:structure_block{mode:data}"
        },
        {
            "minecraft:chest{facing:north,type:single,waterlogged:false}": "minecraft:chest{facing:north,type:single,waterlogged:false}",
            "minecraft:chest{facing:south,type:single,waterlogged:false}": "minecraft:chest{facing:south,type:single,waterlogged:false}",
            "minecraft:oak_fence{east:false,north:false,south:false,waterlogged:false,west:false}": "minecraft:spruce_fence{east:false,north:false,south:false,waterlogged:false,west:false}",
            "minecraft:oak_log{axis:x}": "minecraft:spruce_log{axis:x}",
            "minecraft:oak_planks": "minecraft:spruce_planks",
            "minecraft:oak_stairs{facing:east,half:bottom,shape:outer_right,waterlogged:false}": "minecraft:spruce_stairs{facing:east,half:bottom,shape:outer_right,waterlogged:false}",
            "minecraft:oak_stairs{facing:east,half:top,shape:outer_right,waterlogged:false}": "minecraft:spruce_stairs{facing:east,half:top,shape:outer_right,waterlogged:false}",
            "minecraft:oak_stairs{facing:north,half:bottom,shape:outer_right,waterlogged:false}": "minecraft:spruce_stairs{facing:north,half:bottom,shape:outer_right,waterlogged:false}",
            "minecraft:oak_stairs{facing:north,half:top,shape:outer_right,waterlogged:false}": "minecraft:spruce_stairs{facing:north,half:top,shape:outer_right,waterlogged:false}",
            "minecraft:oak_stairs{facing:south,half:bottom,shape:outer_right,waterlogged:false}": "minecraft:spruce_stairs{facing:south,half:bottom,shape:outer_right,waterlogged:false}",
            "minecraft:oak_stairs{facing:south,half:top,shape:outer_right,waterlogged:false}": "minecraft:spruce_stairs{facing:south,half:top,shape:outer_right,waterlogged:false}",
            "minecraft:oak_stairs{facing:west,half:bottom,shape:outer_right,waterlogged:false}": "minecraft:spruce_stairs{facing:west,half:bottom,shape:outer_right,waterlogged:false}",
            "minecraft:oak_stairs{facing:west,half:top,shape:outer_right,waterlogged:false}": "minecraft:spruce_stairs{facing:west,half:top,shape:outer_right,waterlogged:false}",
            "minecraft:oak_trapdoor{facing:east,half:bottom,open:true,powered:false,waterlogged:false}": "minecraft:spruce_trapdoor{facing:east,half:bottom,open:true,powered:false,waterlogged:false}",
            "minecraft:oak_trapdoor{facing:east,half:top,open:true,powered:false,waterlogged:false}": "minecraft:spruce_trapdoor{facing:east,half:top,open:true,powered:false,waterlogged:false}",
            "minecraft:spruce_fence{east:false,north:false,south:false,waterlogged:false,west:false}": "minecraft:jungle_fence{east:false,north:false,south:false,waterlogged:false,west:false}",
            "minecraft:spruce_planks": "minecraft:jungle_planks",
            "minecraft:spruce_stairs{facing:north,half:bottom,shape:outer_right,waterlogged:false}": "minecraft:jungle_stairs{facing:north,half:bottom,shape:outer_right,waterlogged:false}",
            "minecraft:spruce_stairs{facing:north,half:top,shape:outer_right,waterlogged:false}": "minecraft:jungle_stairs{facing:north,half:top,shape:outer_right,waterlogged:false}",
            "minecraft:spruce_stairs{facing:south,half:bottom,shape:outer_right,waterlogged:false}": "minecraft:jungle_stairs{facing:south,half:bottom,shape:outer_right,waterlogged:false}",
            "minecraft:spruce_stairs{facing:south,half:top,shape:outer_right,waterlogged:false}": "minecraft:jungle_stairs{facing:south,half:top,shape:outer_right,waterlogged:false}",
            "minecraft:spruce_stairs{facing:west,half:bottom,shape:outer_right,waterlogged:false}": "minecraft:jungle_stairs{facing:west,half:bottom,shape:outer_right,waterlogged:false}",
            "minecraft:spruce_stairs{facing:west,half:top,shape:outer_right,waterlogged:false}": "minecraft:jungle_stairs{facing:west,half:top,shape:outer_right,waterlogged:false}",
            "minecraft:structure_block{mode:data}": "minecraft:structure_block{mode:data}"
        },
        {
            "minecraft:chest{facing:north,type:single,waterlogged:false}": "minecraft:chest{facing:north,type:single,waterlogged:false}",
            "minecraft:chest{facing:south,type:single,waterlogged:false}": "minecraft:chest{facing:south,type:single,waterlogged:false}",
            "minecraft:oak_fence{east:false,north:false,south:false,waterlogged:false,west:false}": "minecraft:spruce_fence{east:false,north:false,south:false,waterlogged:false,west:false}",
            "minecraft:oak_log{axis:x}": "minecraft:spruce_log{axis:x}",
            "minecraft:oak_planks": "minecraft:spruce_planks",
            "minecraft:oak_stairs{facing:east,half:bottom,shape:outer_right,waterlogged:false}": "minecraft:spruce_stairs{facing:east,half:bottom,shape:outer_right,waterlogged:false}",
            "minecraft:oak_stairs{facing:east,half:top,shape:outer_right,waterlogged:false}": "minecraft:spruce_stairs{facing:east,half:top,shape:outer_right,waterlogged:false}",
            "minecraft:oak_stairs{facing:north,half:bottom,shape:outer_right,waterlogged:false}": "minecraft:spruce_stairs{facing:north,half:bottom,shape:outer_right,waterlogged:false}",
            "minecraft:oak_stairs{facing:north,half:top,shape:outer_right,waterlogged:false}": "minecraft:spruce_stairs{facing:north,half:top,shape:outer_right,waterlogged:false}",
            "minecraft:oak_stairs{facing:south,half:bottom,shape:outer_right,waterlogged:false}": "minecraft:spruce_stairs{facing:south,half:bottom,shape:outer_right,waterlogged:false}",
            "minecraft:oak_stairs{facing:south,half:top,shape:outer_right,waterlogged:false}": "minecraft:spruce_stairs{facing:south,half:top,shape:outer_right,waterlogged:false}",
            "minecraft:oak_stairs{facing:west,half:bottom,shape:outer_right,waterlogged:false}": "minecraft:spruce_stairs{facing:west,half:bottom,shape:outer_right,waterlogged:false}",
            "minecraft:oak_stairs{facing:west,half:top,shape:outer_right,waterlogged:false}": "minecraft:spruce_stairs{facing:west,half:top,shape:outer_right,waterlogged:false}",
            "minecraft:oak_trapdoor{facing:east,half:bottom,open:true,powered:false,waterlogged:false}": "minecraft:spruce_trapdoor{facing:east,half:bottom,open:true,powered:false,waterlogged:false}",
            "minecraft:oak_trapdoor{facing:east,half:top,open:true,powered:false,waterlogged:false}": "minecraft:spruce_trapdoor{facing:east,half:top,open:true,powered:false,waterlogged:false}",
            "minecraft:spruce_fence{east:false,north:false,south:false,waterlogged:false,west:false}": "minecraft:dark_oak_fence{east:false,north:false,south:false,waterlogged:false,west:false}",
            "minecraft:spruce_planks": "minecraft:dark_oak_planks",
            "minecraft:spruce_stairs{facing:north,half:bottom,shape:outer_right,waterlogged:false}": "minecraft:dark_oak_stairs{facing:north,half:bottom,shape:outer_right,waterlogged:false}",
            "minecraft:spruce_stairs{facing:north,half:top,shape:outer_right,waterlogged:false}": "minecraft:dark_oak_stairs{facing:north,half:top,shape:outer_right,waterlogged:false}",
            "minecraft:spruce_stairs{facing:south,half:bottom,shape:outer_right,waterlogged:false}": "minecraft:dark_oak_stairs{facing:south,half:bottom,shape:outer_right,waterlogged:false}",
            "minecraft:spruce_stairs{facing:south,half:top,shape:outer_right,waterlogged:false}": "minecraft:dark_oak_stairs{facing:south,half:top,shape:outer_right,waterlogged:false}",
            "minecraft:spruce_stairs{facing:west,half:bottom,shape:outer_right,waterlogged:false}": "minecraft:dark_oak_stairs{facing:west,half:bottom,shape:outer_right,waterlogged:false}",
            "minecraft:spruce_stairs{facing:west,half:top,shape:outer_right,waterlogged:false}": "minecraft:dark_oak_stairs{facing:west,half:top,shape:outer_right,waterlogged:false}",
            "minecraft:structure_block{mode:data}": "minecraft:structure_block{mode:data}"
        },
        {
            "minecraft:chest{facing:north,type:single,waterlogged:false}": "minecraft:chest{facing:north,type:single,waterlogged:false}",
            "minecraft:chest{facing:south,type:single,waterlogged:false}": "minecraft:chest{facing:south,type:single,waterlogged:false}",
            "minecraft:oak_fence{east:false,north:false,south:false,waterlogged:false,west:false}": "minecraft:oak_fence{east:false,north:false,south:false,waterlogged:false,west:false}",
            "minecraft:oak_log{axis:x}": "minecraft:oak_log{axis:x}",
            "minecraft:oak_planks": "minecraft:oak_planks",
            "minecraft:oak_stairs{facing:east,half:bottom,shape:outer_right,waterlogged:false}": "minecraft:oak_stairs{facing:east,half:bottom,shape:outer_right,waterlogged:false}",
            "minecraft:oak_stairs{facing:east,half:top,shape:outer_right,waterlogged:false}": "minecraft:oak_stairs{facing:east,half:top,shape:outer_right,waterlogged:false}",
            "minecraft:oak_stairs{facing:north,half:bottom,shape:outer_right,waterlogged:false}": "minecraft:oak_stairs{facing:north,half:bottom,shape:outer_right,waterlogged:false}",
            "minecraft:oak_stairs{facing:north,half:top,shape:outer_right,waterlogged:false}": "minecraft:oak_stairs{facing:north,half:top,shape:outer_right,waterlogged:false}",
            "minecraft:oak_stairs{facing:south,half:bottom,shape:outer_right,waterlogged:false}": "minecraft:oak_stairs{facing:south,half:bottom,shape:outer_right,waterlogged:false}",
            "minecraft:oak_stairs{facing:south,half:top,shape:outer_right,waterlogged:false}": "minecraft:oak_stairs{facing:south,half:top,shape:outer_right,waterlogged:false}",
            "minecraft:oak_stairs{facing:west,half:bottom,shape:outer_right,waterlogged:false}": "minecraft:oak_stairs{facing:west,half:bottom,shape:outer_right,waterlogged:false}",
            "minecraft:oak_stairs{facing:west,half:top,shape:outer_right,waterlogged:false}": "minecraft:oak_stairs{facing:west,half:top,shape:outer_right,waterlogged:false}",
            "minecraft:oak_trapdoor{facing:east,half:bottom,open:true,powered:false,waterlogged:false}": "minecraft:oak_trapdoor{facing:east,half:bottom,open:true,powered:false,waterlogged:false}",
            "minecraft:oak_trapdoor{facing:east,half:top,open:true,powered:false,waterlogged:false}": "minecraft:oak_trapdoor{facing:east,half:top,open:true,powered:false,waterlogged:false}",
            "minecraft:spruce_fence{east:false,north:false,south:false,waterlogged:false,west:false}": "minecraft:birch_fence{east:false,north:false,south:false,waterlogged:false,west:false}",
            "minecraft:spruce_planks": "minecraft:birch_planks",
            "minecraft:spruce_stairs{facing:north,half:bottom,shape:outer_right,waterlogged:false}": "minecraft:birch_stairs{facing:north,half:bottom,shape:outer_right,waterlogged:false}",
            "minecraft:spruce_stairs{facing:north,half:top,shape:outer_right,waterlogged:false}": "minecraft:birch_stairs{facing:north,half:top,shape:outer_right,waterlogged:false}",
            "minecraft:spruce_stairs{facing:south,half:bottom,shape:outer_right,waterlogged:false}": "minecraft:birch_stairs{facing:south,half:bottom,shape:outer_right,waterlogged:false}",
            "minecraft:spruce_stairs{facing:south,half:top,shape:outer_right,waterlogged:false}": "minecraft:birch_stairs{facing:south,half:top,shape:outer_right,waterlogged:false}",
            "minecraft:spruce_stairs{facing:west,half:bottom,shape:outer_right,waterlogged:false}": "minecraft:birch_stairs{facing:west,half:bottom,shape:outer_right,waterlogged:false}",
            "minecraft:spruce_stairs{facing:west,half:top,shape:outer_right,waterlogged:false}": "minecraft:birch_stairs{facing:west,half:top,shape:outer_right,waterlogged:false}",
            "minecraft:structure_block{mode:data}": "minecraft:structure_block{mode:data}"
        }
    ]
}
