{
    size: [10, 10, 10],
    data: [
        {pos: [1, 0, 3], state: "minecraft:grass_block{snowy:false}"},
        {pos: [1, 0, 4], state: "minecraft:dirt"},
        {pos: [1, 0, 5], state: "minecraft:dirt"},
        {pos: [1, 0, 6], state: "minecraft:mossy_cobblestone"},
        {pos: [1, 0, 7], state: "minecraft:dirt"},
        {pos: [1, 0, 8], state: "minecraft:mossy_cobblestone"},
        {pos: [2, 0, 2], state: "minecraft:grass_block{snowy:false}"},
        {pos: [2, 0, 3], state: "minecraft:dirt"},
        {pos: [2, 0, 4], state: "minecraft:dirt"},
        {pos: [2, 0, 5], state: "minecraft:dirt"},
        {pos: [2, 0, 6], state: "minecraft:dirt"},
        {pos: [2, 0, 7], state: "minecraft:dirt"},
        {pos: [2, 0, 8], state: "minecraft:mossy_cobblestone"},
        {pos: [3, 0, 1], state: "minecraft:grass_block{snowy:false}"},
        {pos: [3, 0, 2], state: "minecraft:dirt"},
        {pos: [3, 0, 3], state: "minecraft:gravel"},
        {pos: [3, 0, 4], state: "minecraft:gravel"},
        {pos: [3, 0, 5], state: "minecraft:gravel"},
        {pos: [3, 0, 6], state: "minecraft:gravel"},
        {pos: [3, 0, 7], state: "minecraft:dirt"},
        {pos: [3, 0, 8], state: "minecraft:mossy_cobblestone"},
        {pos: [4, 0, 1], state: "minecraft:dirt"},
        {pos: [4, 0, 2], state: "minecraft:dirt"},
        {pos: [4, 0, 3], state: "minecraft:gravel"},
        {pos: [4, 0, 4], state: "minecraft:gravel"},
        {pos: [4, 0, 5], state: "minecraft:gravel"},
        {pos: [4, 0, 6], state: "minecraft:gravel"},
        {pos: [4, 0, 7], state: "minecraft:dirt"},
        {pos: [4, 0, 8], state: "minecraft:dirt"},
        {pos: [5, 0, 1], state: "minecraft:dirt"},
        {pos: [5, 0, 2], state: "minecraft:dirt"},
        {pos: [5, 0, 3], state: "minecraft:dirt"},
        {pos: [5, 0, 4], state: "minecraft:gravel"},
        {pos: [5, 0, 5], state: "minecraft:gravel"},
        {pos: [5, 0, 6], state: "minecraft:gravel"},
        {pos: [5, 0, 7], state: "minecraft:dirt"},
        {pos: [5, 0, 8], state: "minecraft:dirt"},
        {pos: [6, 0, 1], state: "minecraft:dirt"},
        {pos: [6, 0, 2], state: "minecraft:dirt"},
        {pos: [6, 0, 3], state: "minecraft:dirt_path"},
        {pos: [6, 0, 4], state: "minecraft:dirt_path"},
        {pos: [6, 0, 5], state: "minecraft:gravel"},
        {pos: [6, 0, 6], state: "minecraft:gravel"},
        {pos: [6, 0, 7], state: "minecraft:dirt"},
        {pos: [6, 0, 8], state: "minecraft:dirt"},
        {pos: [7, 0, 1], state: "minecraft:dirt_path"},
        {pos: [7, 0, 2], state: "minecraft:dirt_path"},
        {pos: [7, 0, 3], state: "minecraft:gravel"},
        {pos: [7, 0, 4], state: "minecraft:dirt_path"},
        {pos: [7, 0, 5], state: "minecraft:dirt_path"},
        {pos: [7, 0, 6], state: "minecraft:dirt"},
        {pos: [7, 0, 7], state: "minecraft:dirt"},
        {pos: [8, 0, 1], state: "minecraft:grass_block{snowy:false}"},
        {pos: [8, 0, 2], state: "minecraft:dirt_path"},
        {pos: [8, 0, 3], state: "minecraft:dirt_path"},
        {pos: [8, 0, 4], state: "minecraft:dirt_path"},
        {pos: [8, 0, 5], state: "minecraft:dirt_path"},
        {pos: [8, 0, 6], state: "minecraft:dirt_path"},
        {pos: [8, 0, 7], state: "minecraft:dirt"},
        {pos: [9, 0, 3], state: "minecraft:dirt_path"},
        {pos: [9, 0, 4], state: "minecraft:jigsaw{orientation:east_up}", nbt: {components: {}, final_state: "minecraft:dirt_path", id: "minecraft:jigsaw", joint: "rollable", name: "minecraft:end_connector", placement_priority: 0, pool: "minecraft:empty", selection_priority: 0, target: "minecraft:connector"}},
        {pos: [9, 0, 5], state: "minecraft:dirt_path"},
        {pos: [9, 0, 6], state: "minecraft:dirt_path"},
        {pos: [1, 1, 4], state: "minecraft:stone"},
        {pos: [1, 1, 5], state: "minecraft:stone"},
        {pos: [1, 1, 6], state: "minecraft:mossy_cobblestone"},
        {pos: [1, 1, 7], state: "minecraft:mossy_cobblestone"},
        {pos: [2, 1, 3], state: "minecraft:stone"},
        {pos: [2, 1, 4], state: "minecraft:stone"},
        {pos: [2, 1, 5], state: "minecraft:stone"},
        {pos: [2, 1, 6], state: "minecraft:stone"},
        {pos: [2, 1, 7], state: "minecraft:stone"},
        {pos: [2, 1, 8], state: "minecraft:mossy_cobblestone"},
        {pos: [3, 1, 2], state: "minecraft:cobblestone"},
        {pos: [3, 1, 3], state: "minecraft:stone"},
        {pos: [3, 1, 7], state: "minecraft:stone"},
        {pos: [4, 1, 1], state: "minecraft:stone"},
        {pos: [4, 1, 2], state: "minecraft:stone"},
        {pos: [4, 1, 7], state: "minecraft:stone"},
        {pos: [4, 1, 8], state: "minecraft:mossy_cobblestone"},
        {pos: [5, 1, 1], state: "minecraft:stone"},
        {pos: [5, 1, 2], state: "minecraft:stone"},
        {pos: [5, 1, 3], state: "minecraft:chest{facing:east,type:single,waterlogged:false}", nbt: {Items: [], LootTable: "minecraft:chests/abandoned_camp_common_chest", components: {}, id: "minecraft:chest"}},
        {pos: [5, 1, 7], state: "minecraft:stone"},
        {pos: [5, 1, 8], state: "minecraft:stone"},
        {pos: [6, 1, 1], state: "minecraft:cobblestone"},
        {pos: [6, 1, 7], state: "minecraft:stone"},
        {pos: [6, 1, 8], state: "minecraft:mossy_cobblestone"},
        {pos: [7, 1, 3], state: "minecraft:campfire{facing:west,lit:false,signal_fire:false,waterlogged:false}", nbt: {CookingTimes: [I; 0, 0, 0, 0], CookingTotalTimes: [I; 0, 0, 0, 0], Items: [], components: {}, id: "minecraft:campfire"}},
        {pos: [7, 1, 7], state: "minecraft:stone"},
        {pos: [8, 1, 1], state: "minecraft:spruce_fence{east:false,north:false,south:false,waterlogged:false,west:false}"},
        {pos: [2, 2, 4], state: "minecraft:cobblestone"},
        {pos: [2, 2, 5], state: "minecraft:stone"},
        {pos: [2, 2, 6], state: "minecraft:cobblestone"},
        {pos: [3, 2, 3], state: "minecraft:stone"},
        {pos: [3, 2, 4], state: "minecraft:stone"},
        {pos: [3, 2, 5], state: "minecraft:stone"},
        {pos: [3, 2, 6], state: "minecraft:stone"},
        {pos: [3, 2, 7], state: "minecraft:stone"},
        {pos: [4, 2, 2], state: "minecraft:stone"},
        {pos: [4, 2, 3], state: "minecraft:stone"},
        {pos: [4, 2, 6], state: "minecraft:stone"},
        {pos: [4, 2, 7], state: "minecraft:mossy_cobblestone"},
        {pos: [5, 2, 2], state: "minecraft:cobblestone"},
        {pos: [5, 2, 6], state: "minecraft:stone"},
        {pos: [5, 2, 7], state: "minecraft:stone"},
        {pos: [6, 2, 6], state: "minecraft:stone"},
        {pos: [6, 2, 7], state: "minecraft:mossy_cobblestone"},
        {pos: [3, 3, 4], state: "minecraft:stone"},
        {pos: [3, 3, 5], state: "minecraft:stone"},
        {pos: [3, 3, 6], state: "minecraft:stone"},
        {pos: [4, 3, 3], state: "minecraft:mossy_cobblestone"},
        {pos: [4, 3, 4], state: "minecraft:stone"},
        {pos: [4, 3, 5], state: "minecraft:mossy_cobblestone"},
        {pos: [4, 3, 6], state: "minecraft:stone"},
        {pos: [5, 3, 3], state: "minecraft:stone"},
        {pos: [5, 3, 4], state: "minecraft:stone"},
        {pos: [5, 3, 5], state: "minecraft:stone"},
        {pos: [5, 3, 6], state: "minecraft:mossy_cobblestone"},
        {pos: [6, 3, 4], state: "minecraft:stone"},
        {pos: [6, 3, 5], state: "minecraft:stone"},
        {pos: [4, 4, 4], state: "minecraft:mossy_cobblestone"},
        {pos: [5, 4, 4], state: "minecraft:mossy_cobblestone"},
        {pos: [5, 4, 5], state: "minecraft:mossy_cobblestone"}
    ],
    entities: [
        {blockPos: [6, 1, 5], pos: [6.5d, 1.0d, 5.5d], nbt: {Air: 300s, Fire: 0s, Invulnerable: 0b, Motion: [0.0d, 0.0d, 0.0d], OnGround: 0b, PortalCooldown: 0, Pos: [-87.5d, -60.0d, 257.5d], Rotation: [90.0f, 0.0f], UUID: [I; -401043630, -96843476, -1915955837, -479721412], block_pos: [I; -88, -60, 257], color: "brown", fall_distance: 0.0d, id: "minecraft:cushion"}}
    ],
    palette: [
        "minecraft:grass_block{snowy:false}",
        "minecraft:dirt",
        "minecraft:mossy_cobblestone",
        "minecraft:gravel",
        "minecraft:stone",
        "minecraft:cobblestone",
        "minecraft:dirt_path",
        "minecraft:spruce_fence{east:false,north:false,south:false,waterlogged:false,west:false}",
        "minecraft:jigsaw{orientation:east_up}",
        "minecraft:chest{facing:east,type:single,waterlogged:false}",
        "minecraft:campfire{facing:west,lit:false,signal_fire:false,waterlogged:false}"
    ]
}
