{
    size: [12, 10, 12],
    data: [
        {pos: [2, 0, 5], state: "minecraft:dirt"},
        {pos: [2, 0, 6], state: "minecraft:dirt"},
        {pos: [2, 0, 7], state: "minecraft:dirt"},
        {pos: [2, 0, 8], state: "minecraft:dirt"},
        {pos: [2, 0, 9], state: "minecraft:dirt"},
        {pos: [3, 0, 4], state: "minecraft:dirt"},
        {pos: [3, 0, 5], state: "minecraft:dirt"},
        {pos: [3, 0, 6], state: "minecraft:dirt"},
        {pos: [3, 0, 7], state: "minecraft:dirt"},
        {pos: [3, 0, 8], state: "minecraft:dirt"},
        {pos: [3, 0, 9], state: "minecraft:dirt"},
        {pos: [3, 0, 10], state: "minecraft:dirt"},
        {pos: [4, 0, 3], state: "minecraft:mossy_cobblestone"},
        {pos: [4, 0, 4], state: "minecraft:dirt"},
        {pos: [4, 0, 5], state: "minecraft:dirt"},
        {pos: [4, 0, 6], state: "minecraft:gravel"},
        {pos: [4, 0, 7], state: "minecraft:gravel"},
        {pos: [4, 0, 8], state: "minecraft:gravel"},
        {pos: [4, 0, 9], state: "minecraft:gravel"},
        {pos: [4, 0, 10], state: "minecraft:gravel"},
        {pos: [5, 0, 3], state: "minecraft:dirt"},
        {pos: [5, 0, 4], state: "minecraft:dirt"},
        {pos: [5, 0, 5], state: "minecraft:gravel"},
        {pos: [5, 0, 6], state: "minecraft:gravel"},
        {pos: [5, 0, 7], state: "minecraft:gravel"},
        {pos: [5, 0, 8], state: "minecraft:dirt_path"},
        {pos: [5, 0, 9], state: "minecraft:dirt_path"},
        {pos: [5, 0, 10], state: "minecraft:dirt_path"},
        {pos: [5, 0, 11], state: "minecraft:dirt_path"},
        {pos: [6, 0, 4], state: "minecraft:dirt"},
        {pos: [6, 0, 5], state: "minecraft:gravel"},
        {pos: [6, 0, 6], state: "minecraft:gravel"},
        {pos: [6, 0, 7], state: "minecraft:dirt_path"},
        {pos: [6, 0, 8], state: "minecraft:dirt"},
        {pos: [6, 0, 9], state: "minecraft:dirt_path"},
        {pos: [6, 0, 11], state: "minecraft:dirt_path"},
        {pos: [7, 0, 3], state: "minecraft:grass_block{snowy:false}"},
        {pos: [7, 0, 4], state: "minecraft:grass_block{snowy:false}"},
        {pos: [7, 0, 7], state: "minecraft:dirt_path"},
        {pos: [7, 0, 8], state: "minecraft:dirt_path"},
        {pos: [7, 0, 9], state: "minecraft:dirt_path"},
        {pos: [7, 0, 10], state: "minecraft:dirt_path"},
        {pos: [7, 0, 11], state: "minecraft:dirt_path"},
        {pos: [8, 0, 3], state: "minecraft:grass_block{snowy:false}"},
        {pos: [8, 0, 4], state: "minecraft:jigsaw{orientation:up_south}", nbt: {components: {}, final_state: "minecraft:dirt", id: "minecraft:jigsaw", joint: "rollable", name: "minecraft:bottom", placement_priority: 0, pool: "minecraft:abandoned_camp/trees/spruce_on_snow", selection_priority: 0, target: "minecraft:bottom"}},
        {pos: [8, 0, 6], state: "minecraft:grass_block{snowy:false}"},
        {pos: [8, 0, 7], state: "minecraft:dirt_path"},
        {pos: [8, 0, 8], state: "minecraft:dirt_path"},
        {pos: [8, 0, 9], state: "minecraft:dirt_path"},
        {pos: [8, 0, 11], state: "minecraft:dirt_path"},
        {pos: [9, 0, 6], state: "minecraft:dirt_path"},
        {pos: [9, 0, 7], state: "minecraft:dirt_path"},
        {pos: [9, 0, 8], state: "minecraft:dirt_path"},
        {pos: [9, 0, 9], state: "minecraft:dirt_path"},
        {pos: [9, 0, 10], state: "minecraft:dirt_path"},
        {pos: [10, 0, 6], state: "minecraft:dirt_path"},
        {pos: [10, 0, 7], state: "minecraft:dirt_path"},
        {pos: [11, 0, 6], state: "minecraft:jigsaw{orientation:east_up}", nbt: {components: {}, final_state: "minecraft:dirt_path", id: "minecraft:jigsaw", joint: "rollable", name: "minecraft:end_connector", placement_priority: 0, pool: "minecraft:empty", selection_priority: 0, target: "minecraft:connector"}},
        {pos: [11, 0, 7], state: "minecraft:dirt_path"},
        {pos: [2, 1, 5], state: "minecraft:mossy_cobblestone"},
        {pos: [2, 1, 6], state: "minecraft:stone"},
        {pos: [2, 1, 7], state: "minecraft:cobblestone"},
        {pos: [2, 1, 8], state: "minecraft:mossy_cobblestone"},
        {pos: [2, 1, 9], state: "minecraft:cobblestone"},
        {pos: [3, 1, 4], state: "minecraft:stone"},
        {pos: [3, 1, 5], state: "minecraft:cobblestone"},
        {pos: [3, 1, 8], state: "minecraft:barrel{facing:east,open:false}", nbt: {Items: [], LootTable: "minecraft:barrels/abandoned_camp_barrel", components: {}, id: "minecraft:barrel"}},
        {pos: [3, 1, 9], state: "minecraft:stone"},
        {pos: [3, 1, 10], state: "minecraft:mossy_cobblestone"},
        {pos: [4, 1, 4], state: "minecraft:cobblestone"},
        {pos: [4, 1, 5], state: "minecraft:stone"},
        {pos: [5, 1, 3], state: "minecraft:mossy_cobblestone"},
        {pos: [5, 1, 4], state: "minecraft:stone"},
        {pos: [6, 1, 4], state: "minecraft:stone"},
        {pos: [6, 1, 8], state: "minecraft:campfire{facing:west,lit:false,signal_fire:false,waterlogged:false}", nbt: {CookingTimes: [I; 0, 0, 0, 0], CookingTotalTimes: [I; 0, 0, 0, 0], Items: [], components: {}, id: "minecraft:campfire"}},
        {pos: [8, 1, 6], state: "minecraft:spruce_fence{east:false,north:false,south:false,waterlogged:false,west:false}"},
        {pos: [2, 2, 8], state: "minecraft:mossy_cobblestone"},
        {pos: [3, 2, 5], state: "minecraft:mossy_cobblestone"},
        {pos: [3, 2, 6], state: "minecraft:mossy_cobblestone"},
        {pos: [3, 2, 7], state: "minecraft:mossy_cobblestone"},
        {pos: [3, 2, 8], state: "minecraft:mossy_cobblestone"},
        {pos: [3, 2, 9], state: "minecraft:mossy_cobblestone"},
        {pos: [4, 2, 5], state: "minecraft:stone"},
        {pos: [4, 2, 6], state: "minecraft:stone"},
        {pos: [4, 2, 9], state: "minecraft:mossy_cobblestone"},
        {pos: [5, 2, 4], state: "minecraft:mossy_cobblestone"},
        {pos: [5, 2, 5], state: "minecraft:stone"},
        {pos: [6, 2, 4], state: "minecraft:mossy_cobblestone"},
        {pos: [3, 3, 7], state: "minecraft:stone"},
        {pos: [4, 3, 5], state: "minecraft:mossy_cobblestone"},
        {pos: [4, 3, 6], state: "minecraft:cobblestone"},
        {pos: [4, 3, 7], state: "minecraft:cobblestone"},
        {pos: [4, 3, 8], state: "minecraft:cobblestone"},
        {pos: [5, 3, 5], state: "minecraft:stone"},
        {pos: [5, 3, 6], state: "minecraft:stone"},
        {pos: [5, 3, 7], state: "minecraft:cobblestone"},
        {pos: [6, 3, 4], state: "minecraft:stone"},
        {pos: [6, 3, 5], state: "minecraft:stone"},
        {pos: [6, 3, 6], state: "minecraft:cobblestone"}
    ],
    entities: [
        {blockPos: [5, 0, 8], pos: [5.5d, 0.9375d, 8.5d], nbt: {Air: 300s, Fire: 0s, Invulnerable: 0b, Motion: [0.0d, 0.0d, 0.0d], OnGround: 0b, PortalCooldown: 0, Pos: [-88.5d, -60.0625d, 228.5d], Rotation: [90.0f, 0.0f], UUID: [I; -1873152992, 1290555341, -1375735411, -2094044909], block_pos: [I; -89, -61, 228], color: "green", fall_distance: 0.0d, id: "minecraft:cushion"}},
        {blockPos: [6, 1, 6], pos: [6.5d, 1.0d, 6.5d], nbt: {Air: 300s, Fire: 0s, Invulnerable: 0b, Motion: [0.0d, 0.0d, 0.0d], OnGround: 0b, PortalCooldown: 0, Pos: [-87.5d, -60.0d, 226.5d], Rotation: [180.0f, 0.0f], UUID: [I; 1307216140, 1902133758, -2100703924, -452494899], block_pos: [I; -88, -60, 226], color: "brown", fall_distance: 0.0d, id: "minecraft:cushion"}}
    ],
    palette: [
        "minecraft:dirt",
        "minecraft:mossy_cobblestone",
        "minecraft:gravel",
        "minecraft:grass_block{snowy:false}",
        "minecraft:stone",
        "minecraft:cobblestone",
        "minecraft:dirt_path",
        "minecraft:spruce_fence{east:false,north:false,south:false,waterlogged:false,west:false}",
        "minecraft:jigsaw{orientation:up_south}",
        "minecraft:jigsaw{orientation:east_up}",
        "minecraft:barrel{facing:east,open:false}",
        "minecraft:campfire{facing:west,lit:false,signal_fire:false,waterlogged:false}"
    ]
}
