{
    size: [10, 10, 10],
    data: [
        {pos: [2, 0, 6], state: "minecraft:mossy_cobblestone"},
        {pos: [2, 0, 7], state: "minecraft:mossy_cobblestone"},
        {pos: [2, 0, 8], state: "minecraft:mossy_cobblestone"},
        {pos: [3, 0, 2], state: "minecraft:oxidized_copper_chest{facing:east,type:single,waterlogged:false}", nbt: {Items: [], LootTable: "minecraft:chests/abandoned_camp_secret_chest", components: {}, id: "minecraft:chest"}},
        {pos: [3, 0, 6], state: "minecraft:mossy_cobblestone"},
        {pos: [3, 0, 7], state: "minecraft:mossy_cobblestone"},
        {pos: [3, 0, 8], state: "minecraft:mossy_cobblestone"},
        {pos: [4, 0, 4], state: "minecraft:dirt_path"},
        {pos: [4, 0, 5], state: "minecraft:dirt_path"},
        {pos: [4, 0, 6], state: "minecraft:mossy_cobblestone"},
        {pos: [4, 0, 7], state: "minecraft:mossy_cobblestone"},
        {pos: [4, 0, 8], state: "minecraft:mossy_cobblestone"},
        {pos: [5, 0, 3], state: "minecraft:grass_block{snowy:false}"},
        {pos: [5, 0, 4], state: "minecraft:dirt_path"},
        {pos: [5, 0, 5], state: "minecraft:dirt_path"},
        {pos: [5, 0, 6], state: "minecraft:dirt_path"},
        {pos: [5, 0, 7], state: "minecraft:dirt_path"},
        {pos: [6, 0, 1], state: "minecraft:podzol{snowy:false}"},
        {pos: [6, 0, 2], state: "minecraft:podzol{snowy:false}"},
        {pos: [6, 0, 3], state: "minecraft:dirt_path"},
        {pos: [6, 0, 4], state: "minecraft:grass_block{snowy:false}"},
        {pos: [6, 0, 5], state: "minecraft:dirt_path"},
        {pos: [6, 0, 6], state: "minecraft:dirt_path"},
        {pos: [7, 0, 1], state: "minecraft:podzol{snowy:false}"},
        {pos: [7, 0, 2], state: "minecraft:jigsaw{orientation:up_east}", nbt: {components: {}, final_state: "minecraft:dirt", id: "minecraft:jigsaw", joint: "rollable", name: "minecraft:bottom", placement_priority: 0, pool: "minecraft:abandoned_camp/trees/mega_pine", selection_priority: 0, target: "minecraft:bottom"}},
        {pos: [7, 0, 3], state: "minecraft:dirt_path"},
        {pos: [7, 0, 4], state: "minecraft:dirt_path"},
        {pos: [7, 0, 5], state: "minecraft:dirt_path"},
        {pos: [7, 0, 7], state: "minecraft:mossy_cobblestone"},
        {pos: [8, 0, 4], state: "minecraft:dirt_path"},
        {pos: [8, 0, 5], state: "minecraft:dirt_path"},
        {pos: [8, 0, 6], state: "minecraft:mossy_cobblestone"},
        {pos: [8, 0, 7], state: "minecraft:mossy_cobblestone"},
        {pos: [8, 0, 8], state: "minecraft:mossy_cobblestone"},
        {pos: [9, 0, 4], state: "minecraft:jigsaw{orientation:east_up}", nbt: {components: {}, final_state: "minecraft:dirt_path", id: "minecraft:jigsaw", joint: "rollable", name: "minecraft:end_connector", placement_priority: 0, pool: "minecraft:empty", selection_priority: 0, target: "minecraft:connector"}},
        {pos: [9, 0, 5], state: "minecraft:dirt_path"},
        {pos: [9, 0, 7], state: "minecraft:mossy_cobblestone"},
        {pos: [2, 1, 2], state: "minecraft:mossy_cobblestone"},
        {pos: [2, 1, 7], state: "minecraft:mossy_cobblestone"},
        {pos: [3, 1, 1], state: "minecraft:mossy_cobblestone"},
        {pos: [3, 1, 2], state: "minecraft:mossy_cobblestone"},
        {pos: [3, 1, 3], state: "minecraft:mossy_cobblestone"},
        {pos: [3, 1, 6], state: "minecraft:mossy_cobblestone"},
        {pos: [3, 1, 7], state: "minecraft:mossy_cobblestone"},
        {pos: [3, 1, 8], state: "minecraft:mossy_cobblestone"},
        {pos: [4, 1, 2], state: "minecraft:mossy_cobblestone"},
        {pos: [4, 1, 7], state: "minecraft:mossy_cobblestone"},
        {pos: [5, 1, 3], state: "minecraft:chest{facing:east,type:single,waterlogged:false}", nbt: {Items: [], LootTable: "minecraft:chests/abandoned_camp_common_chest", components: {}, id: "minecraft:chest"}},
        {pos: [6, 1, 4], state: "minecraft:campfire{facing:west,lit:false,signal_fire:false,waterlogged:false}", nbt: {CookingTimes: [I; 0, 0, 0, 0], CookingTotalTimes: [I; 0, 0, 0, 0], Items: [], components: {}, id: "minecraft:campfire"}},
        {pos: [7, 1, 6], state: "minecraft:mossy_cobblestone"},
        {pos: [7, 1, 7], state: "minecraft:mossy_cobblestone"},
        {pos: [7, 1, 8], state: "minecraft:mossy_cobblestone"},
        {pos: [8, 1, 6], state: "minecraft:mossy_cobblestone"},
        {pos: [8, 1, 7], state: "minecraft:mossy_cobblestone"},
        {pos: [8, 1, 8], state: "minecraft:mossy_cobblestone"},
        {pos: [9, 1, 6], state: "minecraft:mossy_cobblestone"},
        {pos: [9, 1, 7], state: "minecraft:mossy_cobblestone"},
        {pos: [9, 1, 8], state: "minecraft:mossy_cobblestone"},
        {pos: [2, 2, 1], state: "minecraft:mossy_cobblestone"},
        {pos: [2, 2, 2], state: "minecraft:mossy_cobblestone"},
        {pos: [2, 2, 3], state: "minecraft:mossy_cobblestone"},
        {pos: [3, 2, 1], state: "minecraft:mossy_cobblestone"},
        {pos: [3, 2, 2], state: "minecraft:mossy_cobblestone"},
        {pos: [3, 2, 3], state: "minecraft:mossy_cobblestone"},
        {pos: [4, 2, 1], state: "minecraft:mossy_cobblestone"},
        {pos: [4, 2, 2], state: "minecraft:mossy_cobblestone"},
        {pos: [4, 2, 3], state: "minecraft:mossy_cobblestone"},
        {pos: [7, 2, 7], state: "minecraft:mossy_cobblestone"},
        {pos: [8, 2, 6], state: "minecraft:mossy_cobblestone"},
        {pos: [8, 2, 7], state: "minecraft:mossy_cobblestone"},
        {pos: [8, 2, 8], state: "minecraft:mossy_cobblestone"},
        {pos: [9, 2, 7], state: "minecraft:mossy_cobblestone"},
        {pos: [2, 3, 2], state: "minecraft:mossy_cobblestone"},
        {pos: [3, 3, 1], state: "minecraft:mossy_cobblestone"},
        {pos: [3, 3, 2], state: "minecraft:mossy_cobblestone"},
        {pos: [3, 3, 3], state: "minecraft:mossy_cobblestone"},
        {pos: [4, 3, 2], state: "minecraft:mossy_cobblestone"}
    ],
    entities: [
        {blockPos: [6, 0, 3], pos: [6.5d, 0.9375d, 3.5d], nbt: {Air: 300s, Fire: 0s, Invulnerable: 0b, Motion: [0.0d, 0.0d, 0.0d], OnGround: 0b, PortalCooldown: 0, Pos: [-104.5d, -60.0625d, 225.5d], Rotation: [90.0f, 0.0f], UUID: [I; 977809131, 1059015783, -1672180861, -1818617641], block_pos: [I; -105, -61, 225], color: "green", fall_distance: 0.0d, id: "minecraft:cushion"}},
        {blockPos: [7, 0, 5], pos: [7.5d, 0.9375d, 5.5d], nbt: {Air: 300s, Fire: 0s, Invulnerable: 0b, Motion: [0.0d, 0.0d, 0.0d], OnGround: 0b, PortalCooldown: 0, Pos: [-103.5d, -60.0625d, 227.5d], Rotation: [90.0f, 0.0f], UUID: [I; 2015922119, -1352972579, -1124772188, 1624056353], block_pos: [I; -104, -61, 227], color: "green", fall_distance: 0.0d, id: "minecraft:cushion"}}
    ],
    palette: [
        "minecraft:mossy_cobblestone",
        "minecraft:grass_block{snowy:false}",
        "minecraft:podzol{snowy:false}",
        "minecraft:dirt_path",
        "minecraft:oxidized_copper_chest{facing:east,type:single,waterlogged:false}",
        "minecraft:jigsaw{orientation:up_east}",
        "minecraft:jigsaw{orientation:east_up}",
        "minecraft:chest{facing:east,type:single,waterlogged:false}",
        "minecraft:campfire{facing:west,lit:false,signal_fire:false,waterlogged:false}"
    ]
}
