{
    size: [5, 4, 5],
    data: [
        {pos: [0, 0, 0], state: "minecraft:coal_ore"},
        {pos: [1, 0, 1], state: "minecraft:coal_ore"},
        {pos: [1, 0, 2], state: "minecraft:coal_ore"},
        {pos: [1, 0, 3], state: "minecraft:coal_ore"},
        {pos: [1, 0, 4], state: "minecraft:coal_ore"},
        {pos: [2, 0, 1], state: "minecraft:coal_ore"},
        {pos: [2, 0, 2], state: "minecraft:coal_ore"},
        {pos: [2, 0, 3], state: "minecraft:coal_ore"},
        {pos: [2, 0, 4], state: "minecraft:coal_ore"},
        {pos: [3, 0, 1], state: "minecraft:coal_ore"},
        {pos: [3, 0, 2], state: "minecraft:coal_ore"},
        {pos: [3, 0, 3], state: "minecraft:coal_ore"},
        {pos: [3, 0, 4], state: "minecraft:coal_ore"},
        {pos: [4, 0, 0], state: "minecraft:coal_ore"},
        {pos: [0, 1, 0], state: "minecraft:coal_ore"},
        {pos: [0, 1, 1], state: "minecraft:coal_ore"},
        {pos: [0, 1, 2], state: "minecraft:coal_ore"},
        {pos: [0, 1, 3], state: "minecraft:coal_ore"},
        {pos: [0, 1, 4], state: "minecraft:coal_ore"},
        {pos: [1, 1, 0], state: "minecraft:coal_ore"},
        {pos: [1, 1, 4], state: "minecraft:coal_ore"},
        {pos: [2, 1, 0], state: "minecraft:coal_ore"},
        {pos: [2, 1, 4], state: "minecraft:coal_ore"},
        {pos: [3, 1, 0], state: "minecraft:coal_ore"},
        {pos: [3, 1, 4], state: "minecraft:coal_ore"},
        {pos: [4, 1, 0], state: "minecraft:coal_ore"},
        {pos: [4, 1, 1], state: "minecraft:coal_ore"},
        {pos: [4, 1, 2], state: "minecraft:coal_ore"},
        {pos: [4, 1, 3], state: "minecraft:coal_ore"},
        {pos: [4, 1, 4], state: "minecraft:coal_ore"},
        {pos: [0, 2, 0], state: "minecraft:coal_ore"},
        {pos: [0, 2, 1], state: "minecraft:coal_ore"},
        {pos: [0, 2, 2], state: "minecraft:coal_ore"},
        {pos: [0, 2, 3], state: "minecraft:coal_ore"},
        {pos: [0, 2, 4], state: "minecraft:coal_ore"},
        {pos: [1, 2, 4], state: "minecraft:coal_ore"},
        {pos: [2, 2, 0], state: "minecraft:coal_ore"},
        {pos: [2, 2, 4], state: "minecraft:coal_ore"},
        {pos: [3, 2, 4], state: "minecraft:coal_ore"},
        {pos: [4, 2, 0], state: "minecraft:coal_ore"},
        {pos: [4, 2, 1], state: "minecraft:coal_ore"},
        {pos: [4, 2, 2], state: "minecraft:coal_ore"},
        {pos: [4, 2, 3], state: "minecraft:coal_ore"},
        {pos: [4, 2, 4], state: "minecraft:coal_ore"},
        {pos: [0, 3, 0], state: "minecraft:coal_ore"},
        {pos: [1, 3, 0], state: "minecraft:coal_ore"},
        {pos: [1, 3, 1], state: "minecraft:coal_ore"},
        {pos: [1, 3, 2], state: "minecraft:coal_ore"},
        {pos: [1, 3, 3], state: "minecraft:coal_ore"},
        {pos: [2, 3, 0], state: "minecraft:coal_ore"},
        {pos: [2, 3, 1], state: "minecraft:coal_ore"},
        {pos: [2, 3, 2], state: "minecraft:coal_ore"},
        {pos: [2, 3, 3], state: "minecraft:coal_ore"},
        {pos: [3, 3, 0], state: "minecraft:coal_ore"},
        {pos: [3, 3, 1], state: "minecraft:coal_ore"},
        {pos: [3, 3, 2], state: "minecraft:coal_ore"},
        {pos: [3, 3, 3], state: "minecraft:coal_ore"},
        {pos: [4, 3, 0], state: "minecraft:coal_ore"}
    ],
    entities: [],
    palette: [
        "minecraft:coal_ore"
    ]
}
