{
    size: [10, 3, 10],
    data: [
        {pos: [2, 0, 3], state: "minecraft:grass_block{snowy:false}"},
        {pos: [2, 0, 4], state: "minecraft:dirt_path"},
        {pos: [3, 0, 4], state: "minecraft:grass_block{snowy:false}"},
        {pos: [4, 0, 2], state: "minecraft:dirt"},
        {pos: [4, 0, 4], state: "minecraft:dirt_path"},
        {pos: [5, 0, 2], state: "minecraft:dirt"},
        {pos: [6, 0, 2], state: "minecraft:dirt"},
        {pos: [6, 0, 3], state: "minecraft:dirt"},
        {pos: [7, 0, 3], state: "minecraft:dirt"},
        {pos: [7, 0, 7], state: "minecraft:dirt_path"},
        {pos: [8, 0, 4], state: "minecraft:dirt_path"},
        {pos: [8, 0, 5], state: "minecraft:dirt_path"},
        {pos: [8, 0, 6], state: "minecraft:dirt_path"},
        {pos: [8, 0, 7], state: "minecraft:dirt_path"},
        {pos: [9, 0, 4], state: "minecraft:jigsaw{orientation:east_up}", nbt: {components: {}, final_state: "minecraft:dirt_path", id: "minecraft:jigsaw", joint: "rollable", name: "minecraft:end_connector", placement_priority: 0, pool: "minecraft:empty", selection_priority: 0, target: "minecraft:connector"}},
        {pos: [9, 0, 5], state: "minecraft:dirt"},
        {pos: [9, 0, 6], state: "minecraft:dirt_path"},
        {pos: [2, 1, 3], state: "minecraft:chest{facing:east,type:single,waterlogged:false}", nbt: {LootTable: "minecraft:chests/abandoned_camp_common_chest", components: {}, id: "minecraft:chest"}},
        {pos: [3, 1, 3], state: "minecraft:cobweb"},
        {pos: [3, 1, 4], state: "minecraft:campfire{facing:west,lit:false,signal_fire:false,waterlogged:false}", nbt: {CookingTimes: [I; 0, 0, 0, 0], CookingTotalTimes: [I; 0, 0, 0, 0], Items: [], components: {}, id: "minecraft:campfire"}},
        {pos: [4, 1, 2], state: "minecraft:stone"},
        {pos: [5, 1, 2], state: "minecraft:stone"},
        {pos: [5, 1, 4], state: "minecraft:cobweb"},
        {pos: [6, 1, 2], state: "minecraft:stone"},
        {pos: [6, 1, 3], state: "minecraft:stone"},
        {pos: [7, 1, 3], state: "minecraft:stone"},
        {pos: [7, 1, 6], state: "minecraft:cobweb"},
        {pos: [9, 1, 5], state: "minecraft:cobweb"},
        {pos: [4, 2, 2], state: "minecraft:cobweb"},
        {pos: [4, 2, 3], state: "minecraft:cobweb"},
        {pos: [5, 2, 2], state: "minecraft:stone"},
        {pos: [5, 2, 3], state: "minecraft:cobweb"},
        {pos: [6, 2, 2], state: "minecraft:cobweb"}
    ],
    entities: [
        {blockPos: [4, 0, 4], pos: [4.5d, 0.9375d, 4.5d], nbt: {Air: 300s, Fire: 0s, Invulnerable: 0b, Motion: [0.0d, 0.0d, 0.0d], OnGround: 0b, PortalCooldown: 0, Pos: [-60.5d, -60.0625d, 38.5d], Rotation: [180.0f, 0.0f], UUID: [I; -1256197203, 1077823143, -1805136446, -638338746], block_pos: [I; -61, -61, 38], color: "brown", fall_distance: 0.0d, id: "minecraft:cushion"}}
    ],
    palette: [
        "minecraft:grass_block{snowy:false}",
        "minecraft:dirt",
        "minecraft:stone",
        "minecraft:dirt_path",
        "minecraft:cobweb",
        "minecraft:jigsaw{orientation:east_up}",
        "minecraft:chest{facing:east,type:single,waterlogged:false}",
        "minecraft:campfire{facing:west,lit:false,signal_fire:false,waterlogged:false}"
    ]
}
