{
    size: [10, 5, 10],
    data: [
        {pos: [1, 0, 6], state: "minecraft:stone"},
        {pos: [1, 0, 7], state: "minecraft:stone"},
        {pos: [1, 0, 8], state: "minecraft:stone"},
        {pos: [2, 0, 4], state: "minecraft:stone"},
        {pos: [2, 0, 5], state: "minecraft:stone"},
        {pos: [2, 0, 6], state: "minecraft:dirt"},
        {pos: [2, 0, 7], state: "minecraft:dirt"},
        {pos: [2, 0, 8], state: "minecraft:dirt"},
        {pos: [2, 0, 9], state: "minecraft:stone"},
        {pos: [3, 0, 3], state: "minecraft:dirt"},
        {pos: [3, 0, 4], state: "minecraft:dirt"},
        {pos: [3, 0, 5], state: "minecraft:dirt"},
        {pos: [3, 0, 6], state: "minecraft:stone"},
        {pos: [3, 0, 7], state: "minecraft:stone"},
        {pos: [3, 0, 8], state: "minecraft:stone"},
        {pos: [3, 0, 9], state: "minecraft:stone"},
        {pos: [4, 0, 3], state: "minecraft:dirt"},
        {pos: [4, 0, 4], state: "minecraft:dirt"},
        {pos: [4, 0, 5], state: "minecraft:dirt"},
        {pos: [4, 0, 6], state: "minecraft:stone"},
        {pos: [4, 0, 7], state: "minecraft:stone"},
        {pos: [4, 0, 8], state: "minecraft:stone"},
        {pos: [4, 0, 9], state: "minecraft:dirt"},
        {pos: [5, 0, 4], state: "minecraft:dirt"},
        {pos: [5, 0, 5], state: "minecraft:stone"},
        {pos: [5, 0, 6], state: "minecraft:stone"},
        {pos: [5, 0, 7], state: "minecraft:dirt"},
        {pos: [5, 0, 8], state: "minecraft:dirt"},
        {pos: [6, 0, 4], state: "minecraft:dirt"},
        {pos: [6, 0, 5], state: "minecraft:dirt"},
        {pos: [6, 0, 6], state: "minecraft:dirt"},
        {pos: [6, 0, 7], state: "minecraft:dirt"},
        {pos: [7, 0, 4], state: "minecraft:dirt"},
        {pos: [7, 0, 5], state: "minecraft:dirt"},
        {pos: [7, 0, 6], state: "minecraft:dirt"},
        {pos: [8, 0, 4], state: "minecraft:dirt"},
        {pos: [8, 0, 5], state: "minecraft:dirt"},
        {pos: [8, 0, 6], state: "minecraft:dirt"},
        {pos: [8, 0, 7], state: "minecraft:dirt"},
        {pos: [9, 0, 4], state: "minecraft:dirt"},
        {pos: [9, 0, 5], state: "minecraft:dirt"},
        {pos: [1, 1, 6], state: "minecraft:stone"},
        {pos: [1, 1, 7], state: "minecraft:stone"},
        {pos: [1, 1, 8], state: "minecraft:stone"},
        {pos: [2, 1, 4], state: "minecraft:stone"},
        {pos: [2, 1, 5], state: "minecraft:stone"},
        {pos: [2, 1, 6], state: "minecraft:stone"},
        {pos: [2, 1, 7], state: "minecraft:stone"},
        {pos: [2, 1, 8], state: "minecraft:stone"},
        {pos: [2, 1, 9], state: "minecraft:stone"},
        {pos: [3, 1, 3], state: "minecraft:stone"},
        {pos: [3, 1, 4], state: "minecraft:gravel"},
        {pos: [3, 1, 5], state: "minecraft:gravel"},
        {pos: [3, 1, 6], state: "minecraft:gravel"},
        {pos: [3, 1, 7], state: "minecraft:cobweb"},
        {pos: [3, 1, 8], state: "minecraft:cobweb"},
        {pos: [3, 1, 9], state: "minecraft:stone"},
        {pos: [4, 1, 3], state: "minecraft:stone"},
        {pos: [4, 1, 4], state: "minecraft:gravel"},
        {pos: [4, 1, 5], state: "minecraft:stone"},
        {pos: [4, 1, 6], state: "minecraft:gravel"},
        {pos: [4, 1, 7], state: "minecraft:gravel"},
        {pos: [4, 1, 8], state: "minecraft:gravel"},
        {pos: [4, 1, 9], state: "minecraft:stone"},
        {pos: [5, 1, 4], state: "minecraft:stone"},
        {pos: [5, 1, 5], state: "minecraft:cobweb"},
        {pos: [5, 1, 6], state: "minecraft:gravel"},
        {pos: [5, 1, 7], state: "minecraft:gravel"},
        {pos: [5, 1, 8], state: "minecraft:gravel"},
        {pos: [6, 1, 4], state: "minecraft:dirt"},
        {pos: [6, 1, 5], state: "minecraft:stone"},
        {pos: [6, 1, 6], state: "minecraft:gravel"},
        {pos: [6, 1, 7], state: "minecraft:dirt"},
        {pos: [7, 1, 4], state: "minecraft:dirt"},
        {pos: [7, 1, 5], state: "minecraft:dirt"},
        {pos: [7, 1, 6], state: "minecraft:dirt"},
        {pos: [8, 1, 4], state: "minecraft:dirt"},
        {pos: [8, 1, 5], state: "minecraft:dirt"},
        {pos: [8, 1, 6], state: "minecraft:dirt"},
        {pos: [8, 1, 7], state: "minecraft:dirt"},
        {pos: [9, 1, 4], state: "minecraft:dirt"},
        {pos: [9, 1, 5], state: "minecraft:dirt"},
        {pos: [1, 2, 6], state: "minecraft:stone"},
        {pos: [1, 2, 7], state: "minecraft:stone"},
        {pos: [1, 2, 8], state: "minecraft:stone"},
        {pos: [2, 2, 4], state: "minecraft:stone"},
        {pos: [2, 2, 5], state: "minecraft:stone"},
        {pos: [2, 2, 6], state: "minecraft:cobweb"},
        {pos: [2, 2, 7], state: "minecraft:gravel"},
        {pos: [2, 2, 8], state: "minecraft:cobweb"},
        {pos: [2, 2, 9], state: "minecraft:stone"},
        {pos: [3, 2, 3], state: "minecraft:stone"},
        {pos: [3, 2, 4], state: "minecraft:cobweb"},
        {pos: [3, 2, 5], state: "minecraft:cobweb"},
        {pos: [3, 2, 6], state: "minecraft:gravel"},
        {pos: [3, 2, 7], state: "minecraft:cobweb"},
        {pos: [3, 2, 8], state: "minecraft:cobweb"},
        {pos: [3, 2, 9], state: "minecraft:stone"},
        {pos: [4, 2, 3], state: "minecraft:stone"},
        {pos: [4, 2, 4], state: "minecraft:cobweb"},
        {pos: [4, 2, 5], state: "minecraft:cobweb"},
        {pos: [4, 2, 6], state: "minecraft:gravel"},
        {pos: [4, 2, 7], state: "minecraft:gravel"},
        {pos: [4, 2, 8], state: "minecraft:gravel"},
        {pos: [4, 2, 9], state: "minecraft:stone"},
        {pos: [5, 2, 4], state: "minecraft:stone"},
        {pos: [5, 2, 5], state: "minecraft:cobweb"},
        {pos: [5, 2, 6], state: "minecraft:gravel"},
        {pos: [5, 2, 7], state: "minecraft:cobweb"},
        {pos: [5, 2, 8], state: "minecraft:gravel"},
        {pos: [6, 2, 4], state: "minecraft:dirt_path"},
        {pos: [6, 2, 5], state: "minecraft:stone"},
        {pos: [6, 2, 6], state: "minecraft:gravel"},
        {pos: [6, 2, 7], state: "minecraft:gravel"},
        {pos: [7, 2, 4], state: "minecraft:dirt_path"},
        {pos: [7, 2, 5], state: "minecraft:dirt_path"},
        {pos: [7, 2, 6], state: "minecraft:dirt_path"},
        {pos: [8, 2, 4], state: "minecraft:dirt_path"},
        {pos: [8, 2, 5], state: "minecraft:dirt_path"},
        {pos: [8, 2, 6], state: "minecraft:dirt_path"},
        {pos: [8, 2, 7], state: "minecraft:dirt"},
        {pos: [9, 2, 4], state: "minecraft:jigsaw{orientation:east_up}", nbt: {components: {}, final_state: "minecraft:dirt_path", id: "minecraft:jigsaw", joint: "rollable", name: "minecraft:end_connector", placement_priority: 0, pool: "minecraft:empty", selection_priority: 0, target: "minecraft:connector"}},
        {pos: [9, 2, 5], state: "minecraft:dirt_path"},
        {pos: [4, 3, 9], state: "minecraft:cobweb"},
        {pos: [8, 3, 7], state: "minecraft:chest{facing:north,type:single,waterlogged:false}", nbt: {Items: [], LootTable: "minecraft:chests/abandoned_camp_common_chest", components: {}, id: "minecraft:chest"}}
    ],
    entities: [],
    palette: [
        "minecraft:stone",
        "minecraft:dirt",
        "minecraft:gravel",
        "minecraft:cobweb",
        "minecraft:dirt_path",
        "minecraft:jigsaw{orientation:east_up}",
        "minecraft:chest{facing:north,type:single,waterlogged:false}"
    ]
}
