{
    size: [10, 5, 10],
    data: [
        {pos: [1, 0, 2], state: "minecraft:stone"},
        {pos: [1, 0, 3], state: "minecraft:stone"},
        {pos: [1, 0, 4], state: "minecraft:stone"},
        {pos: [1, 0, 5], state: "minecraft:stone"},
        {pos: [2, 0, 1], state: "minecraft:stone"},
        {pos: [2, 0, 2], state: "minecraft:gravel"},
        {pos: [2, 0, 3], state: "minecraft:dirt"},
        {pos: [2, 0, 4], state: "minecraft:grass_block{snowy:false}"},
        {pos: [2, 0, 5], state: "minecraft:dirt"},
        {pos: [2, 0, 6], state: "minecraft:gravel"},
        {pos: [3, 0, 1], state: "minecraft:stone"},
        {pos: [3, 0, 2], state: "minecraft:stone"},
        {pos: [3, 0, 3], state: "minecraft:stone"},
        {pos: [3, 0, 4], state: "minecraft:gravel"},
        {pos: [3, 0, 5], state: "minecraft:grass_block{snowy:false}"},
        {pos: [3, 0, 6], state: "minecraft:stone"},
        {pos: [4, 0, 1], state: "minecraft:stone"},
        {pos: [4, 0, 2], state: "minecraft:dirt"},
        {pos: [4, 0, 3], state: "minecraft:dirt"},
        {pos: [4, 0, 4], state: "minecraft:gravel"},
        {pos: [4, 0, 5], state: "minecraft:dirt"},
        {pos: [4, 0, 6], state: "minecraft:stone"},
        {pos: [5, 0, 2], state: "minecraft:stone"},
        {pos: [5, 0, 3], state: "minecraft:dirt"},
        {pos: [5, 0, 4], state: "minecraft:dirt"},
        {pos: [5, 0, 5], state: "minecraft:dirt"},
        {pos: [5, 0, 6], state: "minecraft:dirt"},
        {pos: [6, 0, 3], state: "minecraft:stone"},
        {pos: [6, 0, 4], state: "minecraft:dirt"},
        {pos: [6, 0, 5], state: "minecraft:dirt"},
        {pos: [6, 0, 6], state: "minecraft:dirt"},
        {pos: [6, 0, 7], state: "minecraft:dirt"},
        {pos: [6, 0, 8], state: "minecraft:dirt"},
        {pos: [7, 0, 5], state: "minecraft:dirt"},
        {pos: [7, 0, 6], state: "minecraft:dirt"},
        {pos: [7, 0, 7], state: "minecraft:dirt"},
        {pos: [7, 0, 9], state: "minecraft:dirt"},
        {pos: [8, 0, 5], state: "minecraft:dirt"},
        {pos: [8, 0, 6], state: "minecraft:dirt"},
        {pos: [8, 0, 7], state: "minecraft:dirt"},
        {pos: [8, 0, 8], state: "minecraft:dirt"},
        {pos: [9, 0, 4], state: "minecraft:dirt"},
        {pos: [9, 0, 6], state: "minecraft:dirt"},
        {pos: [9, 0, 7], state: "minecraft:dirt"},
        {pos: [1, 1, 2], state: "minecraft:stone"},
        {pos: [1, 1, 3], state: "minecraft:stone"},
        {pos: [1, 1, 4], state: "minecraft:stone"},
        {pos: [1, 1, 5], state: "minecraft:stone"},
        {pos: [2, 1, 1], state: "minecraft:stone"},
        {pos: [2, 1, 2], state: "minecraft:gravel"},
        {pos: [2, 1, 3], state: "minecraft:dirt"},
        {pos: [2, 1, 4], state: "minecraft:cobweb"},
        {pos: [2, 1, 5], state: "minecraft:grass_block{snowy:false}"},
        {pos: [2, 1, 6], state: "minecraft:stone"},
        {pos: [3, 1, 1], state: "minecraft:stone"},
        {pos: [3, 1, 2], state: "minecraft:stone"},
        {pos: [3, 1, 3], state: "minecraft:cobweb"},
        {pos: [3, 1, 4], state: "minecraft:oxidized_copper_golem_statue{copper_golem_pose:sitting,facing:east,waterlogged:false}", nbt: {components: {}, id: "minecraft:copper_golem_statue"}},
        {pos: [3, 1, 5], state: "minecraft:cobweb"},
        {pos: [3, 1, 6], state: "minecraft:stone"},
        {pos: [4, 1, 1], state: "minecraft:stone"},
        {pos: [4, 1, 2], state: "minecraft:stone"},
        {pos: [4, 1, 3], state: "minecraft:gravel"},
        {pos: [4, 1, 5], state: "minecraft:gravel"},
        {pos: [4, 1, 6], state: "minecraft:stone"},
        {pos: [5, 1, 2], state: "minecraft:gravel"},
        {pos: [5, 1, 3], state: "minecraft:gravel"},
        {pos: [5, 1, 4], state: "minecraft:gravel"},
        {pos: [5, 1, 5], state: "minecraft:gravel"},
        {pos: [5, 1, 6], state: "minecraft:dirt"},
        {pos: [6, 1, 3], state: "minecraft:stone"},
        {pos: [6, 1, 4], state: "minecraft:dirt"},
        {pos: [6, 1, 5], state: "minecraft:dirt"},
        {pos: [6, 1, 6], state: "minecraft:dirt"},
        {pos: [6, 1, 7], state: "minecraft:dirt"},
        {pos: [6, 1, 8], state: "minecraft:dirt"},
        {pos: [7, 1, 5], state: "minecraft:dirt"},
        {pos: [7, 1, 6], state: "minecraft:dirt"},
        {pos: [7, 1, 7], state: "minecraft:dirt"},
        {pos: [7, 1, 9], state: "minecraft:dirt"},
        {pos: [8, 1, 5], state: "minecraft:dirt"},
        {pos: [8, 1, 6], state: "minecraft:dirt"},
        {pos: [8, 1, 7], state: "minecraft:dirt"},
        {pos: [8, 1, 8], state: "minecraft:dirt"},
        {pos: [9, 1, 4], state: "minecraft:dirt"},
        {pos: [9, 1, 6], state: "minecraft:dirt"},
        {pos: [9, 1, 7], state: "minecraft:dirt"},
        {pos: [1, 2, 2], state: "minecraft:stone"},
        {pos: [1, 2, 3], state: "minecraft:stone"},
        {pos: [1, 2, 4], state: "minecraft:stone"},
        {pos: [1, 2, 5], state: "minecraft:stone"},
        {pos: [2, 2, 2], state: "minecraft:stone"},
        {pos: [2, 2, 3], state: "minecraft:gravel"},
        {pos: [2, 2, 4], state: "minecraft:cobweb"},
        {pos: [2, 2, 5], state: "minecraft:cobweb"},
        {pos: [2, 2, 6], state: "minecraft:stone"},
        {pos: [3, 2, 1], state: "minecraft:stone"},
        {pos: [3, 2, 2], state: "minecraft:stone"},
        {pos: [3, 2, 3], state: "minecraft:cobweb"},
        {pos: [3, 2, 4], state: "minecraft:cobweb"},
        {pos: [3, 2, 5], state: "minecraft:cobweb"},
        {pos: [3, 2, 6], state: "minecraft:stone"},
        {pos: [4, 2, 1], state: "minecraft:stone"},
        {pos: [4, 2, 2], state: "minecraft:stone"},
        {pos: [4, 2, 3], state: "minecraft:gravel"},
        {pos: [4, 2, 4], state: "minecraft:cobweb"},
        {pos: [4, 2, 5], state: "minecraft:gravel"},
        {pos: [4, 2, 6], state: "minecraft:stone"},
        {pos: [5, 2, 2], state: "minecraft:gravel"},
        {pos: [5, 2, 3], state: "minecraft:gravel"},
        {pos: [5, 2, 4], state: "minecraft:cobweb"},
        {pos: [5, 2, 5], state: "minecraft:gravel"},
        {pos: [5, 2, 6], state: "minecraft:dirt_path"},
        {pos: [6, 2, 3], state: "minecraft:cobweb"},
        {pos: [6, 2, 4], state: "minecraft:gravel"},
        {pos: [6, 2, 5], state: "minecraft:dirt_path"},
        {pos: [6, 2, 6], state: "minecraft:dirt_path"},
        {pos: [6, 2, 7], state: "minecraft:dirt_path"},
        {pos: [6, 2, 8], state: "minecraft:dirt_path"},
        {pos: [7, 2, 5], state: "minecraft:dirt_path"},
        {pos: [7, 2, 6], state: "minecraft:dirt"},
        {pos: [7, 2, 7], state: "minecraft:dirt_path"},
        {pos: [7, 2, 9], state: "minecraft:dirt_path"},
        {pos: [8, 2, 5], state: "minecraft:dirt_path"},
        {pos: [8, 2, 6], state: "minecraft:dirt_path"},
        {pos: [8, 2, 7], state: "minecraft:dirt_path"},
        {pos: [8, 2, 8], state: "minecraft:dirt"},
        {pos: [9, 2, 4], state: "minecraft:jigsaw{orientation:east_up}", nbt: {components: {}, final_state: "minecraft:dirt_path", id: "minecraft:jigsaw", joint: "rollable", name: "minecraft:end_connector", placement_priority: 0, pool: "minecraft:empty", selection_priority: 0, target: "minecraft:connector"}},
        {pos: [9, 2, 6], state: "minecraft:dirt_path"},
        {pos: [9, 2, 7], state: "minecraft:dirt_path"},
        {pos: [2, 3, 5], state: "minecraft:cobweb"},
        {pos: [7, 3, 6], state: "minecraft:campfire{facing:west,lit:false,signal_fire:false,waterlogged:false}", nbt: {CookingTimes: [I; 0, 0, 0, 0], CookingTotalTimes: [I; 0, 0, 0, 0], Items: [], components: {}, id: "minecraft:campfire"}},
        {pos: [8, 3, 8], state: "minecraft:chest{facing:north,type:single,waterlogged:false}", nbt: {LootTable: "minecraft:chests/abandoned_camp_common_chest", components: {}, id: "minecraft:chest"}}
    ],
    entities: [
        {blockPos: [7, 2, 7], pos: [7.5d, 2.9375d, 7.5d], nbt: {Air: 300s, Fire: 0s, Invulnerable: 0b, Motion: [0.0d, 0.0d, 0.0d], OnGround: 0b, PortalCooldown: 0, Pos: [-57.5d, -60.0625d, 54.5d], Rotation: [180.0f, 0.0f], UUID: [I; -1335699809, -561887618, -2110095759, 187837532], block_pos: [I; -58, -61, 54], color: "blue", fall_distance: 0.0d, id: "minecraft:cushion"}}
    ],
    palette: [
        "minecraft:stone",
        "minecraft:gravel",
        "minecraft:dirt",
        "minecraft:grass_block{snowy:false}",
        "minecraft:cobweb",
        "minecraft:dirt_path",
        "minecraft:oxidized_copper_golem_statue{copper_golem_pose:sitting,facing:east,waterlogged:false}",
        "minecraft:jigsaw{orientation:east_up}",
        "minecraft:campfire{facing:west,lit:false,signal_fire:false,waterlogged:false}",
        "minecraft:chest{facing:north,type:single,waterlogged:false}"
    ]
}
