{
    size: [3, 12, 3],
    data: [
        {pos: [0, 0, 0], state: "minecraft:waxed_oxidized_copper"},
        {pos: [0, 0, 1], state: "minecraft:waxed_oxidized_copper"},
        {pos: [0, 0, 2], state: "minecraft:waxed_oxidized_copper"},
        {pos: [1, 0, 0], state: "minecraft:waxed_oxidized_copper"},
        {pos: [1, 0, 1], state: "minecraft:jigsaw{orientation:down_west}", nbt: {final_state: "minecraft:waxed_oxidized_copper", id: "minecraft:jigsaw", joint: "rollable", name: "minecraft:lower_addon", placement_priority: 0, pool: "minecraft:empty", selection_priority: 0, target: "minecraft:empty"}},
        {pos: [1, 0, 2], state: "minecraft:waxed_oxidized_copper"},
        {pos: [2, 0, 0], state: "minecraft:waxed_oxidized_copper"},
        {pos: [2, 0, 1], state: "minecraft:waxed_oxidized_copper"},
        {pos: [2, 0, 2], state: "minecraft:waxed_oxidized_copper"},
        {pos: [0, 1, 0], state: "minecraft:air"},
        {pos: [0, 1, 1], state: "minecraft:air"},
        {pos: [0, 1, 2], state: "minecraft:air"},
        {pos: [1, 1, 0], state: "minecraft:air"},
        {pos: [1, 1, 1], state: "minecraft:air"},
        {pos: [1, 1, 2], state: "minecraft:air"},
        {pos: [2, 1, 0], state: "minecraft:air"},
        {pos: [2, 1, 1], state: "minecraft:air"},
        {pos: [2, 1, 2], state: "minecraft:air"},
        {pos: [0, 2, 0], state: "minecraft:air"},
        {pos: [0, 2, 1], state: "minecraft:air"},
        {pos: [0, 2, 2], state: "minecraft:air"},
        {pos: [1, 2, 0], state: "minecraft:air"},
        {pos: [1, 2, 1], state: "minecraft:air"},
        {pos: [1, 2, 2], state: "minecraft:air"},
        {pos: [2, 2, 0], state: "minecraft:air"},
        {pos: [2, 2, 1], state: "minecraft:air"},
        {pos: [2, 2, 2], state: "minecraft:air"},
        {pos: [0, 3, 0], state: "minecraft:air"},
        {pos: [0, 3, 1], state: "minecraft:air"},
        {pos: [0, 3, 2], state: "minecraft:air"},
        {pos: [1, 3, 0], state: "minecraft:air"},
        {pos: [1, 3, 1], state: "minecraft:air"},
        {pos: [1, 3, 2], state: "minecraft:air"},
        {pos: [2, 3, 0], state: "minecraft:air"},
        {pos: [2, 3, 1], state: "minecraft:air"},
        {pos: [2, 3, 2], state: "minecraft:air"},
        {pos: [0, 4, 0], state: "minecraft:air"},
        {pos: [0, 4, 1], state: "minecraft:air"},
        {pos: [0, 4, 2], state: "minecraft:air"},
        {pos: [1, 4, 0], state: "minecraft:air"},
        {pos: [1, 4, 1], state: "minecraft:air"},
        {pos: [1, 4, 2], state: "minecraft:air"},
        {pos: [2, 4, 0], state: "minecraft:air"},
        {pos: [2, 4, 1], state: "minecraft:air"},
        {pos: [2, 4, 2], state: "minecraft:air"},
        {pos: [0, 5, 0], state: "minecraft:polished_tuff"},
        {pos: [0, 5, 1], state: "minecraft:polished_tuff"},
        {pos: [0, 5, 2], state: "minecraft:polished_tuff"},
        {pos: [1, 5, 0], state: "minecraft:polished_tuff"},
        {pos: [1, 5, 1], state: "minecraft:polished_tuff"},
        {pos: [1, 5, 2], state: "minecraft:polished_tuff"},
        {pos: [2, 5, 0], state: "minecraft:polished_tuff"},
        {pos: [2, 5, 1], state: "minecraft:polished_tuff"},
        {pos: [2, 5, 2], state: "minecraft:polished_tuff"},
        {pos: [0, 6, 0], state: "minecraft:waxed_copper_block"},
        {pos: [0, 6, 1], state: "minecraft:waxed_copper_block"},
        {pos: [0, 6, 2], state: "minecraft:waxed_copper_block"},
        {pos: [1, 6, 0], state: "minecraft:waxed_copper_block"},
        {pos: [1, 6, 1], state: "minecraft:tuff_bricks"},
        {pos: [1, 6, 2], state: "minecraft:waxed_copper_block"},
        {pos: [2, 6, 0], state: "minecraft:waxed_copper_block"},
        {pos: [2, 6, 1], state: "minecraft:waxed_copper_block"},
        {pos: [2, 6, 2], state: "minecraft:waxed_copper_block"},
        {pos: [0, 7, 0], state: "minecraft:tuff_bricks"},
        {pos: [0, 7, 1], state: "minecraft:tuff_bricks"},
        {pos: [0, 7, 2], state: "minecraft:tuff_bricks"},
        {pos: [1, 7, 0], state: "minecraft:tuff_bricks"},
        {pos: [1, 7, 1], state: "minecraft:tuff_bricks"},
        {pos: [1, 7, 2], state: "minecraft:tuff_bricks"},
        {pos: [2, 7, 0], state: "minecraft:tuff_bricks"},
        {pos: [2, 7, 1], state: "minecraft:tuff_bricks"},
        {pos: [2, 7, 2], state: "minecraft:tuff_bricks"},
        {pos: [0, 8, 0], state: "minecraft:tuff_bricks"},
        {pos: [0, 8, 1], state: "minecraft:tuff_bricks"},
        {pos: [0, 8, 2], state: "minecraft:tuff_bricks"},
        {pos: [1, 8, 0], state: "minecraft:tuff_bricks"},
        {pos: [1, 8, 1], state: "minecraft:tuff_bricks"},
        {pos: [1, 8, 2], state: "minecraft:tuff_bricks"},
        {pos: [2, 8, 0], state: "minecraft:tuff_bricks"},
        {pos: [2, 8, 1], state: "minecraft:tuff_bricks"},
        {pos: [2, 8, 2], state: "minecraft:tuff_bricks"},
        {pos: [0, 9, 0], state: "minecraft:chiseled_tuff_bricks"},
        {pos: [0, 9, 1], state: "minecraft:chiseled_tuff_bricks"},
        {pos: [0, 9, 2], state: "minecraft:chiseled_tuff_bricks"},
        {pos: [1, 9, 0], state: "minecraft:chiseled_tuff_bricks"},
        {pos: [1, 9, 1], state: "minecraft:tuff_bricks"},
        {pos: [1, 9, 2], state: "minecraft:chiseled_tuff_bricks"},
        {pos: [2, 9, 0], state: "minecraft:chiseled_tuff_bricks"},
        {pos: [2, 9, 1], state: "minecraft:chiseled_tuff_bricks"},
        {pos: [2, 9, 2], state: "minecraft:chiseled_tuff_bricks"},
        {pos: [0, 10, 0], state: "minecraft:waxed_copper_block"},
        {pos: [0, 10, 1], state: "minecraft:waxed_copper_block"},
        {pos: [0, 10, 2], state: "minecraft:waxed_copper_block"},
        {pos: [1, 10, 0], state: "minecraft:waxed_copper_block"},
        {pos: [1, 10, 1], state: "minecraft:waxed_oxidized_copper"},
        {pos: [1, 10, 2], state: "minecraft:waxed_copper_block"},
        {pos: [2, 10, 0], state: "minecraft:waxed_copper_block"},
        {pos: [2, 10, 1], state: "minecraft:waxed_copper_block"},
        {pos: [2, 10, 2], state: "minecraft:waxed_copper_block"},
        {pos: [0, 11, 0], state: "minecraft:tuff_bricks"},
        {pos: [0, 11, 1], state: "minecraft:tuff_bricks"},
        {pos: [0, 11, 2], state: "minecraft:tuff_bricks"},
        {pos: [1, 11, 0], state: "minecraft:tuff_bricks"},
        {pos: [1, 11, 1], state: "minecraft:tuff_bricks"},
        {pos: [1, 11, 2], state: "minecraft:tuff_bricks"},
        {pos: [2, 11, 0], state: "minecraft:tuff_bricks"},
        {pos: [2, 11, 1], state: "minecraft:tuff_bricks"},
        {pos: [2, 11, 2], state: "minecraft:tuff_bricks"}
    ],
    entities: [],
    palette: [
        "minecraft:waxed_oxidized_copper",
        "minecraft:polished_tuff",
        "minecraft:waxed_copper_block",
        "minecraft:tuff_bricks",
        "minecraft:chiseled_tuff_bricks",
        "minecraft:air",
        "minecraft:jigsaw{orientation:down_west}"
    ]
}
