{
    size: [5, 12, 5],
    data: [
        {pos: [0, 0, 0], state: "minecraft:tuff_bricks"},
        {pos: [0, 0, 1], state: "minecraft:tuff_bricks"},
        {pos: [0, 0, 2], state: "minecraft:tuff_bricks"},
        {pos: [0, 0, 3], state: "minecraft:tuff_bricks"},
        {pos: [0, 0, 4], state: "minecraft:tuff_bricks"},
        {pos: [1, 0, 0], state: "minecraft:tuff_bricks"},
        {pos: [1, 0, 1], state: "minecraft:tuff_bricks"},
        {pos: [1, 0, 2], state: "minecraft:tuff_bricks"},
        {pos: [1, 0, 3], state: "minecraft:tuff_bricks"},
        {pos: [1, 0, 4], state: "minecraft:tuff_bricks"},
        {pos: [2, 0, 0], state: "minecraft:tuff_bricks"},
        {pos: [2, 0, 1], state: "minecraft:tuff_bricks"},
        {pos: [2, 0, 2], state: "minecraft:jigsaw{orientation:down_north}", nbt: {final_state: "minecraft:tuff_bricks", id: "minecraft:jigsaw", joint: "rollable", name: "minecraft:lower_addon", placement_priority: 0, pool: "minecraft:empty", selection_priority: 0, target: "minecraft:empty"}},
        {pos: [2, 0, 3], state: "minecraft:tuff_bricks"},
        {pos: [2, 0, 4], state: "minecraft:tuff_bricks"},
        {pos: [3, 0, 0], state: "minecraft:tuff_bricks"},
        {pos: [3, 0, 1], state: "minecraft:tuff_bricks"},
        {pos: [3, 0, 2], state: "minecraft:tuff_bricks"},
        {pos: [3, 0, 3], state: "minecraft:tuff_bricks"},
        {pos: [3, 0, 4], state: "minecraft:tuff_bricks"},
        {pos: [4, 0, 0], state: "minecraft:tuff_bricks"},
        {pos: [4, 0, 1], state: "minecraft:tuff_bricks"},
        {pos: [4, 0, 2], state: "minecraft:tuff_bricks"},
        {pos: [4, 0, 3], state: "minecraft:tuff_bricks"},
        {pos: [4, 0, 4], state: "minecraft:tuff_bricks"},
        {pos: [0, 1, 0], state: "minecraft:tuff_bricks"},
        {pos: [0, 1, 1], state: "minecraft:tuff_bricks"},
        {pos: [0, 1, 2], state: "minecraft:tuff_bricks"},
        {pos: [0, 1, 3], state: "minecraft:tuff_bricks"},
        {pos: [0, 1, 4], state: "minecraft:tuff_bricks"},
        {pos: [1, 1, 0], state: "minecraft:tuff_bricks"},
        {pos: [1, 1, 1], state: "minecraft:tuff_bricks"},
        {pos: [1, 1, 2], state: "minecraft:tuff_bricks"},
        {pos: [1, 1, 3], state: "minecraft:tuff_bricks"},
        {pos: [1, 1, 4], state: "minecraft:tuff_bricks"},
        {pos: [2, 1, 0], state: "minecraft:tuff_bricks"},
        {pos: [2, 1, 1], state: "minecraft:tuff_bricks"},
        {pos: [2, 1, 2], state: "minecraft:tuff_bricks"},
        {pos: [2, 1, 3], state: "minecraft:tuff_bricks"},
        {pos: [2, 1, 4], state: "minecraft:tuff_bricks"},
        {pos: [3, 1, 0], state: "minecraft:tuff_bricks"},
        {pos: [3, 1, 1], state: "minecraft:tuff_bricks"},
        {pos: [3, 1, 2], state: "minecraft:tuff_bricks"},
        {pos: [3, 1, 3], state: "minecraft:tuff_bricks"},
        {pos: [3, 1, 4], state: "minecraft:tuff_bricks"},
        {pos: [4, 1, 0], state: "minecraft:tuff_bricks"},
        {pos: [4, 1, 1], state: "minecraft:tuff_bricks"},
        {pos: [4, 1, 2], state: "minecraft:tuff_bricks"},
        {pos: [4, 1, 3], state: "minecraft:tuff_bricks"},
        {pos: [4, 1, 4], state: "minecraft:tuff_bricks"},
        {pos: [0, 2, 0], state: "minecraft:waxed_copper_block"},
        {pos: [0, 2, 1], state: "minecraft:waxed_copper_block"},
        {pos: [0, 2, 2], state: "minecraft:waxed_copper_block"},
        {pos: [0, 2, 3], state: "minecraft:waxed_copper_block"},
        {pos: [0, 2, 4], state: "minecraft:waxed_copper_block"},
        {pos: [1, 2, 0], state: "minecraft:waxed_copper_block"},
        {pos: [1, 2, 1], state: "minecraft:tuff_bricks"},
        {pos: [1, 2, 2], state: "minecraft:tuff_bricks"},
        {pos: [1, 2, 3], state: "minecraft:tuff_bricks"},
        {pos: [1, 2, 4], state: "minecraft:waxed_copper_block"},
        {pos: [2, 2, 0], state: "minecraft:waxed_copper_block"},
        {pos: [2, 2, 1], state: "minecraft:tuff_bricks"},
        {pos: [2, 2, 2], state: "minecraft:tuff_bricks"},
        {pos: [2, 2, 3], state: "minecraft:tuff_bricks"},
        {pos: [2, 2, 4], state: "minecraft:waxed_copper_block"},
        {pos: [3, 2, 0], state: "minecraft:waxed_copper_block"},
        {pos: [3, 2, 1], state: "minecraft:tuff_bricks"},
        {pos: [3, 2, 2], state: "minecraft:tuff_bricks"},
        {pos: [3, 2, 3], state: "minecraft:tuff_bricks"},
        {pos: [3, 2, 4], state: "minecraft:waxed_copper_block"},
        {pos: [4, 2, 0], state: "minecraft:waxed_copper_block"},
        {pos: [4, 2, 1], state: "minecraft:waxed_copper_block"},
        {pos: [4, 2, 2], state: "minecraft:waxed_copper_block"},
        {pos: [4, 2, 3], state: "minecraft:waxed_copper_block"},
        {pos: [4, 2, 4], state: "minecraft:waxed_copper_block"},
        {pos: [0, 3, 0], state: "minecraft:waxed_copper_block"},
        {pos: [0, 3, 1], state: "minecraft:waxed_copper_grate{waterlogged:false}"},
        {pos: [0, 3, 2], state: "minecraft:waxed_copper_grate{waterlogged:false}"},
        {pos: [0, 3, 3], state: "minecraft:waxed_copper_grate{waterlogged:false}"},
        {pos: [0, 3, 4], state: "minecraft:waxed_copper_block"},
        {pos: [1, 3, 0], state: "minecraft:waxed_copper_grate{waterlogged:false}"},
        {pos: [1, 3, 1], state: "minecraft:air"},
        {pos: [1, 3, 2], state: "minecraft:air"},
        {pos: [1, 3, 3], state: "minecraft:air"},
        {pos: [1, 3, 4], state: "minecraft:waxed_copper_grate{waterlogged:false}"},
        {pos: [2, 3, 0], state: "minecraft:waxed_copper_grate{waterlogged:false}"},
        {pos: [2, 3, 1], state: "minecraft:air"},
        {pos: [2, 3, 2], state: "minecraft:air"},
        {pos: [2, 3, 3], state: "minecraft:air"},
        {pos: [2, 3, 4], state: "minecraft:waxed_copper_grate{waterlogged:false}"},
        {pos: [3, 3, 0], state: "minecraft:waxed_copper_grate{waterlogged:false}"},
        {pos: [3, 3, 1], state: "minecraft:air"},
        {pos: [3, 3, 2], state: "minecraft:air"},
        {pos: [3, 3, 3], state: "minecraft:air"},
        {pos: [3, 3, 4], state: "minecraft:waxed_copper_grate{waterlogged:false}"},
        {pos: [4, 3, 0], state: "minecraft:waxed_copper_block"},
        {pos: [4, 3, 1], state: "minecraft:waxed_copper_grate{waterlogged:false}"},
        {pos: [4, 3, 2], state: "minecraft:waxed_copper_grate{waterlogged:false}"},
        {pos: [4, 3, 3], state: "minecraft:waxed_copper_grate{waterlogged:false}"},
        {pos: [4, 3, 4], state: "minecraft:waxed_copper_block"},
        {pos: [0, 4, 0], state: "minecraft:waxed_copper_block"},
        {pos: [0, 4, 1], state: "minecraft:waxed_copper_block"},
        {pos: [0, 4, 2], state: "minecraft:waxed_copper_block"},
        {pos: [0, 4, 3], state: "minecraft:waxed_copper_block"},
        {pos: [0, 4, 4], state: "minecraft:waxed_copper_block"},
        {pos: [1, 4, 0], state: "minecraft:waxed_copper_block"},
        {pos: [1, 4, 1], state: "minecraft:air"},
        {pos: [1, 4, 2], state: "minecraft:air"},
        {pos: [1, 4, 3], state: "minecraft:air"},
        {pos: [1, 4, 4], state: "minecraft:waxed_copper_block"},
        {pos: [2, 4, 0], state: "minecraft:waxed_copper_block"},
        {pos: [2, 4, 1], state: "minecraft:air"},
        {pos: [2, 4, 2], state: "minecraft:jigsaw{orientation:north_up}", nbt: {final_state: "minecraft:observer[facing=down,powered=false]", id: "minecraft:jigsaw", joint: "aligned", name: "minecraft:empty", placement_priority: 1, pool: "minecraft:trial_chambers/spawner/all", selection_priority: 1, target: "minecraft:spawner_connector"}},
        {pos: [2, 4, 3], state: "minecraft:air"},
        {pos: [2, 4, 4], state: "minecraft:waxed_copper_block"},
        {pos: [3, 4, 0], state: "minecraft:waxed_copper_block"},
        {pos: [3, 4, 1], state: "minecraft:air"},
        {pos: [3, 4, 2], state: "minecraft:air"},
        {pos: [3, 4, 3], state: "minecraft:air"},
        {pos: [3, 4, 4], state: "minecraft:waxed_copper_block"},
        {pos: [4, 4, 0], state: "minecraft:waxed_copper_block"},
        {pos: [4, 4, 1], state: "minecraft:waxed_copper_block"},
        {pos: [4, 4, 2], state: "minecraft:waxed_copper_block"},
        {pos: [4, 4, 3], state: "minecraft:waxed_copper_block"},
        {pos: [4, 4, 4], state: "minecraft:waxed_copper_block"},
        {pos: [0, 5, 0], state: "minecraft:tuff_bricks"},
        {pos: [0, 5, 1], state: "minecraft:tuff_bricks"},
        {pos: [0, 5, 2], state: "minecraft:tuff_bricks"},
        {pos: [0, 5, 3], state: "minecraft:tuff_bricks"},
        {pos: [0, 5, 4], state: "minecraft:tuff_bricks"},
        {pos: [1, 5, 0], state: "minecraft:tuff_bricks"},
        {pos: [1, 5, 1], state: "minecraft:tuff_bricks"},
        {pos: [1, 5, 2], state: "minecraft:tuff_bricks"},
        {pos: [1, 5, 3], state: "minecraft:tuff_bricks"},
        {pos: [1, 5, 4], state: "minecraft:tuff_bricks"},
        {pos: [2, 5, 0], state: "minecraft:tuff_bricks"},
        {pos: [2, 5, 1], state: "minecraft:tuff_bricks"},
        {pos: [2, 5, 2], state: "minecraft:tuff_bricks"},
        {pos: [2, 5, 3], state: "minecraft:tuff_bricks"},
        {pos: [2, 5, 4], state: "minecraft:tuff_bricks"},
        {pos: [3, 5, 0], state: "minecraft:tuff_bricks"},
        {pos: [3, 5, 1], state: "minecraft:tuff_bricks"},
        {pos: [3, 5, 2], state: "minecraft:tuff_bricks"},
        {pos: [3, 5, 3], state: "minecraft:tuff_bricks"},
        {pos: [3, 5, 4], state: "minecraft:tuff_bricks"},
        {pos: [4, 5, 0], state: "minecraft:tuff_bricks"},
        {pos: [4, 5, 1], state: "minecraft:tuff_bricks"},
        {pos: [4, 5, 2], state: "minecraft:tuff_bricks"},
        {pos: [4, 5, 3], state: "minecraft:tuff_bricks"},
        {pos: [4, 5, 4], state: "minecraft:tuff_bricks"},
        {pos: [0, 6, 0], state: "minecraft:tuff_bricks"},
        {pos: [0, 6, 1], state: "minecraft:tuff_bricks"},
        {pos: [0, 6, 2], state: "minecraft:tuff_bricks"},
        {pos: [0, 6, 3], state: "minecraft:tuff_bricks"},
        {pos: [0, 6, 4], state: "minecraft:tuff_bricks"},
        {pos: [1, 6, 0], state: "minecraft:tuff_bricks"},
        {pos: [1, 6, 1], state: "minecraft:air"},
        {pos: [1, 6, 2], state: "minecraft:air"},
        {pos: [1, 6, 3], state: "minecraft:air"},
        {pos: [1, 6, 4], state: "minecraft:tuff_bricks"},
        {pos: [2, 6, 0], state: "minecraft:tuff_bricks"},
        {pos: [2, 6, 1], state: "minecraft:air"},
        {pos: [2, 6, 2], state: "minecraft:tnt{unstable:false}"},
        {pos: [2, 6, 3], state: "minecraft:air"},
        {pos: [2, 6, 4], state: "minecraft:tuff_bricks"},
        {pos: [3, 6, 0], state: "minecraft:tuff_bricks"},
        {pos: [3, 6, 1], state: "minecraft:air"},
        {pos: [3, 6, 2], state: "minecraft:air"},
        {pos: [3, 6, 3], state: "minecraft:air"},
        {pos: [3, 6, 4], state: "minecraft:tuff_bricks"},
        {pos: [4, 6, 0], state: "minecraft:tuff_bricks"},
        {pos: [4, 6, 1], state: "minecraft:tuff_bricks"},
        {pos: [4, 6, 2], state: "minecraft:tuff_bricks"},
        {pos: [4, 6, 3], state: "minecraft:tuff_bricks"},
        {pos: [4, 6, 4], state: "minecraft:tuff_bricks"},
        {pos: [0, 7, 0], state: "minecraft:tuff_bricks"},
        {pos: [0, 7, 1], state: "minecraft:chiseled_tuff_bricks"},
        {pos: [0, 7, 2], state: "minecraft:chiseled_tuff"},
        {pos: [0, 7, 3], state: "minecraft:chiseled_tuff_bricks"},
        {pos: [0, 7, 4], state: "minecraft:tuff_bricks"},
        {pos: [1, 7, 0], state: "minecraft:chiseled_tuff_bricks"},
        {pos: [1, 7, 1], state: "minecraft:air"},
        {pos: [1, 7, 2], state: "minecraft:air"},
        {pos: [1, 7, 3], state: "minecraft:air"},
        {pos: [1, 7, 4], state: "minecraft:chiseled_tuff_bricks"},
        {pos: [2, 7, 0], state: "minecraft:chiseled_tuff"},
        {pos: [2, 7, 1], state: "minecraft:air"},
        {pos: [2, 7, 2], state: "minecraft:tnt{unstable:false}"},
        {pos: [2, 7, 3], state: "minecraft:air"},
        {pos: [2, 7, 4], state: "minecraft:chiseled_tuff"},
        {pos: [3, 7, 0], state: "minecraft:chiseled_tuff_bricks"},
        {pos: [3, 7, 1], state: "minecraft:air"},
        {pos: [3, 7, 2], state: "minecraft:air"},
        {pos: [3, 7, 3], state: "minecraft:air"},
        {pos: [3, 7, 4], state: "minecraft:chiseled_tuff_bricks"},
        {pos: [4, 7, 0], state: "minecraft:tuff_bricks"},
        {pos: [4, 7, 1], state: "minecraft:chiseled_tuff_bricks"},
        {pos: [4, 7, 2], state: "minecraft:chiseled_tuff"},
        {pos: [4, 7, 3], state: "minecraft:chiseled_tuff_bricks"},
        {pos: [4, 7, 4], state: "minecraft:tuff_bricks"},
        {pos: [0, 8, 0], state: "minecraft:tuff_bricks"},
        {pos: [0, 8, 1], state: "minecraft:tuff_bricks"},
        {pos: [0, 8, 2], state: "minecraft:tuff_bricks"},
        {pos: [0, 8, 3], state: "minecraft:tuff_bricks"},
        {pos: [0, 8, 4], state: "minecraft:tuff_bricks"},
        {pos: [1, 8, 0], state: "minecraft:tuff_bricks"},
        {pos: [1, 8, 1], state: "minecraft:air"},
        {pos: [1, 8, 2], state: "minecraft:air"},
        {pos: [1, 8, 3], state: "minecraft:air"},
        {pos: [1, 8, 4], state: "minecraft:tuff_bricks"},
        {pos: [2, 8, 0], state: "minecraft:tuff_bricks"},
        {pos: [2, 8, 1], state: "minecraft:air"},
        {pos: [2, 8, 2], state: "minecraft:air"},
        {pos: [2, 8, 3], state: "minecraft:air"},
        {pos: [2, 8, 4], state: "minecraft:tuff_bricks"},
        {pos: [3, 8, 0], state: "minecraft:tuff_bricks"},
        {pos: [3, 8, 1], state: "minecraft:air"},
        {pos: [3, 8, 2], state: "minecraft:air"},
        {pos: [3, 8, 3], state: "minecraft:air"},
        {pos: [3, 8, 4], state: "minecraft:tuff_bricks"},
        {pos: [4, 8, 0], state: "minecraft:tuff_bricks"},
        {pos: [4, 8, 1], state: "minecraft:tuff_bricks"},
        {pos: [4, 8, 2], state: "minecraft:tuff_bricks"},
        {pos: [4, 8, 3], state: "minecraft:tuff_bricks"},
        {pos: [4, 8, 4], state: "minecraft:tuff_bricks"},
        {pos: [0, 9, 0], state: "minecraft:chiseled_tuff_bricks"},
        {pos: [0, 9, 1], state: "minecraft:chiseled_tuff_bricks"},
        {pos: [0, 9, 2], state: "minecraft:waxed_copper_bulb{lit:true,powered:false}"},
        {pos: [0, 9, 3], state: "minecraft:chiseled_tuff_bricks"},
        {pos: [0, 9, 4], state: "minecraft:chiseled_tuff_bricks"},
        {pos: [1, 9, 0], state: "minecraft:chiseled_tuff_bricks"},
        {pos: [1, 9, 1], state: "minecraft:air"},
        {pos: [1, 9, 2], state: "minecraft:air"},
        {pos: [1, 9, 3], state: "minecraft:air"},
        {pos: [1, 9, 4], state: "minecraft:chiseled_tuff_bricks"},
        {pos: [2, 9, 0], state: "minecraft:waxed_copper_bulb{lit:true,powered:false}"},
        {pos: [2, 9, 1], state: "minecraft:air"},
        {pos: [2, 9, 2], state: "minecraft:air"},
        {pos: [2, 9, 3], state: "minecraft:air"},
        {pos: [2, 9, 4], state: "minecraft:waxed_copper_bulb{lit:true,powered:false}"},
        {pos: [3, 9, 0], state: "minecraft:chiseled_tuff_bricks"},
        {pos: [3, 9, 1], state: "minecraft:air"},
        {pos: [3, 9, 2], state: "minecraft:air"},
        {pos: [3, 9, 3], state: "minecraft:air"},
        {pos: [3, 9, 4], state: "minecraft:chiseled_tuff_bricks"},
        {pos: [4, 9, 0], state: "minecraft:chiseled_tuff_bricks"},
        {pos: [4, 9, 1], state: "minecraft:chiseled_tuff_bricks"},
        {pos: [4, 9, 2], state: "minecraft:waxed_copper_bulb{lit:true,powered:false}"},
        {pos: [4, 9, 3], state: "minecraft:chiseled_tuff_bricks"},
        {pos: [4, 9, 4], state: "minecraft:chiseled_tuff_bricks"},
        {pos: [0, 10, 0], state: "minecraft:waxed_copper_block"},
        {pos: [0, 10, 1], state: "minecraft:waxed_copper_block"},
        {pos: [0, 10, 2], state: "minecraft:waxed_copper_block"},
        {pos: [0, 10, 3], state: "minecraft:waxed_copper_block"},
        {pos: [0, 10, 4], state: "minecraft:waxed_copper_block"},
        {pos: [1, 10, 0], state: "minecraft:waxed_copper_block"},
        {pos: [1, 10, 1], state: "minecraft:air"},
        {pos: [1, 10, 2], state: "minecraft:air"},
        {pos: [1, 10, 3], state: "minecraft:air"},
        {pos: [1, 10, 4], state: "minecraft:waxed_copper_block"},
        {pos: [2, 10, 0], state: "minecraft:waxed_copper_block"},
        {pos: [2, 10, 1], state: "minecraft:air"},
        {pos: [2, 10, 2], state: "minecraft:air"},
        {pos: [2, 10, 3], state: "minecraft:air"},
        {pos: [2, 10, 4], state: "minecraft:waxed_copper_block"},
        {pos: [3, 10, 0], state: "minecraft:waxed_copper_block"},
        {pos: [3, 10, 1], state: "minecraft:air"},
        {pos: [3, 10, 2], state: "minecraft:air"},
        {pos: [3, 10, 3], state: "minecraft:air"},
        {pos: [3, 10, 4], state: "minecraft:waxed_copper_block"},
        {pos: [4, 10, 0], state: "minecraft:waxed_copper_block"},
        {pos: [4, 10, 1], state: "minecraft:waxed_copper_block"},
        {pos: [4, 10, 2], state: "minecraft:waxed_copper_block"},
        {pos: [4, 10, 3], state: "minecraft:waxed_copper_block"},
        {pos: [4, 10, 4], state: "minecraft:waxed_copper_block"},
        {pos: [0, 11, 0], state: "minecraft:polished_tuff"},
        {pos: [0, 11, 1], state: "minecraft:polished_tuff"},
        {pos: [0, 11, 2], state: "minecraft:polished_tuff"},
        {pos: [0, 11, 3], state: "minecraft:polished_tuff"},
        {pos: [0, 11, 4], state: "minecraft:polished_tuff"},
        {pos: [1, 11, 0], state: "minecraft:polished_tuff"},
        {pos: [1, 11, 1], state: "minecraft:polished_tuff"},
        {pos: [1, 11, 2], state: "minecraft:polished_tuff"},
        {pos: [1, 11, 3], state: "minecraft:polished_tuff"},
        {pos: [1, 11, 4], state: "minecraft:polished_tuff"},
        {pos: [2, 11, 0], state: "minecraft:polished_tuff"},
        {pos: [2, 11, 1], state: "minecraft:polished_tuff"},
        {pos: [2, 11, 2], state: "minecraft:polished_tuff"},
        {pos: [2, 11, 3], state: "minecraft:polished_tuff"},
        {pos: [2, 11, 4], state: "minecraft:polished_tuff"},
        {pos: [3, 11, 0], state: "minecraft:polished_tuff"},
        {pos: [3, 11, 1], state: "minecraft:polished_tuff"},
        {pos: [3, 11, 2], state: "minecraft:polished_tuff"},
        {pos: [3, 11, 3], state: "minecraft:polished_tuff"},
        {pos: [3, 11, 4], state: "minecraft:polished_tuff"},
        {pos: [4, 11, 0], state: "minecraft:polished_tuff"},
        {pos: [4, 11, 1], state: "minecraft:polished_tuff"},
        {pos: [4, 11, 2], state: "minecraft:polished_tuff"},
        {pos: [4, 11, 3], state: "minecraft:polished_tuff"},
        {pos: [4, 11, 4], state: "minecraft:polished_tuff"}
    ],
    entities: [],
    palette: [
        "minecraft:tuff_bricks",
        "minecraft:waxed_copper_block",
        "minecraft:waxed_copper_grate{waterlogged:false}",
        "minecraft:tnt{unstable:false}",
        "minecraft:chiseled_tuff_bricks",
        "minecraft:chiseled_tuff",
        "minecraft:waxed_copper_bulb{lit:true,powered:false}",
        "minecraft:polished_tuff",
        "minecraft:air",
        "minecraft:jigsaw{orientation:down_north}",
        "minecraft:jigsaw{orientation:north_up}"
    ]
}
