{
    size: [12, 10, 10],
    data: [
        {pos: [2, 0, 8], state: "minecraft:dirt"},
        {pos: [3, 0, 3], state: "minecraft:dirt"},
        {pos: [3, 0, 4], state: "minecraft:dirt"},
        {pos: [3, 0, 6], state: "minecraft:dirt_path"},
        {pos: [3, 0, 7], state: "minecraft:dirt"},
        {pos: [3, 0, 8], state: "minecraft:dirt"},
        {pos: [4, 0, 2], state: "minecraft:dirt"},
        {pos: [4, 0, 3], state: "minecraft:dirt"},
        {pos: [4, 0, 4], state: "minecraft:dirt"},
        {pos: [4, 0, 5], state: "minecraft:dirt"},
        {pos: [4, 0, 6], state: "minecraft:dirt_path"},
        {pos: [4, 0, 7], state: "minecraft:gravel"},
        {pos: [4, 0, 8], state: "minecraft:gravel"},
        {pos: [5, 0, 3], state: "minecraft:dirt"},
        {pos: [5, 0, 4], state: "minecraft:dirt"},
        {pos: [5, 0, 5], state: "minecraft:oxidized_copper_chest{facing:south,type:single,waterlogged:false}", nbt: {Items: [], LootTable: "minecraft:chests/abandoned_camp_secret_chest", components: {}, id: "minecraft:chest"}},
        {pos: [5, 0, 6], state: "minecraft:gravel"},
        {pos: [5, 0, 7], state: "minecraft:dirt_path"},
        {pos: [5, 0, 8], state: "minecraft:gravel"},
        {pos: [6, 0, 3], state: "minecraft:dirt"},
        {pos: [6, 0, 4], state: "minecraft:gravel"},
        {pos: [6, 0, 5], state: "minecraft:dirt_path"},
        {pos: [6, 0, 6], state: "minecraft:dirt_path"},
        {pos: [6, 0, 7], state: "minecraft:gravel"},
        {pos: [6, 0, 8], state: "minecraft:dirt"},
        {pos: [7, 0, 3], state: "minecraft:gravel"},
        {pos: [7, 0, 4], state: "minecraft:dirt_path"},
        {pos: [7, 0, 5], state: "minecraft:dirt"},
        {pos: [7, 0, 6], state: "minecraft:gravel"},
        {pos: [7, 0, 7], state: "minecraft:dirt"},
        {pos: [7, 0, 8], state: "minecraft:dirt"},
        {pos: [7, 0, 9], state: "minecraft:dirt"},
        {pos: [8, 0, 3], state: "minecraft:dirt_path"},
        {pos: [8, 0, 4], state: "minecraft:dirt_path"},
        {pos: [8, 0, 5], state: "minecraft:dirt_path"},
        {pos: [8, 0, 6], state: "minecraft:gravel"},
        {pos: [8, 0, 7], state: "minecraft:dirt"},
        {pos: [9, 0, 4], state: "minecraft:dirt_path"},
        {pos: [9, 0, 5], state: "minecraft:dirt_path"},
        {pos: [9, 0, 6], state: "minecraft:dirt_path"},
        {pos: [10, 0, 3], state: "minecraft:dirt_path"},
        {pos: [10, 0, 4], state: "minecraft:dirt_path"},
        {pos: [10, 0, 5], state: "minecraft:dirt_path"},
        {pos: [10, 0, 6], state: "minecraft:dirt_path"},
        {pos: [11, 0, 3], state: "minecraft:dirt_path"},
        {pos: [11, 0, 4], state: "minecraft:jigsaw{orientation:east_up}", nbt: {components: {}, final_state: "minecraft:dirt_path", id: "minecraft:jigsaw", joint: "rollable", name: "minecraft:end_connector", placement_priority: 0, pool: "minecraft:empty", selection_priority: 0, target: "minecraft:connector"}},
        {pos: [11, 0, 5], state: "minecraft:dirt_path"},
        {pos: [2, 1, 8], state: "minecraft:stone"},
        {pos: [3, 1, 3], state: "minecraft:stone"},
        {pos: [3, 1, 4], state: "minecraft:stone"},
        {pos: [3, 1, 7], state: "minecraft:stone"},
        {pos: [3, 1, 8], state: "minecraft:stone"},
        {pos: [4, 1, 2], state: "minecraft:stone"},
        {pos: [4, 1, 3], state: "minecraft:stone"},
        {pos: [4, 1, 4], state: "minecraft:stone"},
        {pos: [4, 1, 5], state: "minecraft:stone"},
        {pos: [5, 1, 3], state: "minecraft:stone"},
        {pos: [5, 1, 4], state: "minecraft:coal_ore"},
        {pos: [5, 1, 5], state: "minecraft:stone"},
        {pos: [6, 1, 3], state: "minecraft:stone"},
        {pos: [6, 1, 4], state: "minecraft:chest{facing:east,type:single,waterlogged:false}", nbt: {Items: [], LootTable: "minecraft:chests/abandoned_camp_common_chest", components: {}, id: "minecraft:chest"}},
        {pos: [6, 1, 8], state: "minecraft:stone"},
        {pos: [7, 1, 5], state: "minecraft:campfire{facing:north,lit:false,signal_fire:false,waterlogged:false}", nbt: {CookingTimes: [I; 0, 0, 0, 0], CookingTotalTimes: [I; 0, 0, 0, 0], Items: [], components: {}, id: "minecraft:campfire"}},
        {pos: [7, 1, 7], state: "minecraft:stone"},
        {pos: [7, 1, 8], state: "minecraft:stone"},
        {pos: [7, 1, 9], state: "minecraft:stone"},
        {pos: [8, 1, 7], state: "minecraft:stone"},
        {pos: [3, 2, 7], state: "minecraft:coal_ore"},
        {pos: [3, 2, 8], state: "minecraft:stone"},
        {pos: [4, 2, 3], state: "minecraft:coal_ore"},
        {pos: [4, 2, 4], state: "minecraft:stone"},
        {pos: [4, 2, 5], state: "minecraft:stone"},
        {pos: [5, 2, 3], state: "minecraft:coal_ore"},
        {pos: [5, 2, 4], state: "minecraft:coal_ore"},
        {pos: [7, 2, 7], state: "minecraft:coal_ore"},
        {pos: [7, 2, 8], state: "minecraft:stone"},
        {pos: [3, 3, 8], state: "minecraft:stone"},
        {pos: [4, 3, 4], state: "minecraft:stone"},
        {pos: [5, 3, 3], state: "minecraft:stone"},
        {pos: [5, 3, 4], state: "minecraft:stone"},
        {pos: [7, 3, 7], state: "minecraft:stone"},
        {pos: [5, 4, 3], state: "minecraft:stone"},
        {pos: [5, 4, 4], state: "minecraft:stone"},
        {pos: [7, 4, 7], state: "minecraft:stone"},
        {pos: [5, 5, 3], state: "minecraft:stone"},
        {pos: [5, 5, 4], state: "minecraft:stone"},
        {pos: [5, 6, 3], state: "minecraft:stone"}
    ],
    entities: [
        {blockPos: [8, 0, 4], pos: [8.5d, 0.9375d, 4.5d], nbt: {Air: 300s, Fire: 0s, Invulnerable: 0b, Motion: [0.0d, 0.0d, 0.0d], OnGround: 0b, PortalCooldown: 0, Pos: [-103.5d, -60.0625d, 46.5d], Rotation: [90.0f, 0.0f], UUID: [I; 79660156, 1340359704, -1987447266, -102632312], block_pos: [I; -104, -61, 46], color: "cyan", fall_distance: 0.0d, id: "minecraft:cushion"}},
        {blockPos: [7, 1, 6], pos: [7.5d, 1.0d, 6.5d], nbt: {Air: 300s, Fire: 0s, Invulnerable: 0b, Motion: [0.0d, 0.0d, 0.0d], OnGround: 0b, PortalCooldown: 0, Pos: [-104.5d, -60.0d, 48.5d], Rotation: [90.0f, 0.0f], UUID: [I; -409494956, 1928416195, -1374377749, 934129156], block_pos: [I; -105, -60, 48], color: "light_gray", fall_distance: 0.0d, id: "minecraft:cushion"}}
    ],
    palette: [
        "minecraft:dirt",
        "minecraft:gravel",
        "minecraft:stone",
        "minecraft:coal_ore",
        "minecraft:dirt_path",
        "minecraft:oxidized_copper_chest{facing:south,type:single,waterlogged:false}",
        "minecraft:jigsaw{orientation:east_up}",
        "minecraft:chest{facing:east,type:single,waterlogged:false}",
        "minecraft:campfire{facing:north,lit:false,signal_fire:false,waterlogged:false}"
    ]
}
