{
    size: [17, 23, 17],
    data: [
        {pos: [4, 0, 3], state: "minecraft:deepslate_tile_stairs{facing:east,half:bottom,shape:straight,waterlogged:false}"},
        {pos: [4, 0, 4], state: "minecraft:deepslate_tile_stairs{facing:east,half:bottom,shape:straight,waterlogged:false}"},
        {pos: [4, 0, 6], state: "minecraft:deepslate_tile_stairs{facing:east,half:bottom,shape:straight,waterlogged:false}"},
        {pos: [4, 0, 7], state: "minecraft:deepslate_tile_stairs{facing:east,half:bottom,shape:straight,waterlogged:false}"},
        {pos: [4, 0, 10], state: "minecraft:deepslate_tile_stairs{facing:east,half:bottom,shape:straight,waterlogged:false}"},
        {pos: [4, 0, 11], state: "minecraft:deepslate_tile_stairs{facing:east,half:bottom,shape:straight,waterlogged:false}"},
        {pos: [4, 0, 13], state: "minecraft:deepslate_tile_stairs{facing:east,half:bottom,shape:straight,waterlogged:false}"},
        {pos: [4, 0, 14], state: "minecraft:deepslate_tile_stairs{facing:east,half:bottom,shape:straight,waterlogged:false}"},
        {pos: [5, 0, 1], state: "minecraft:deepslate_tiles"},
        {pos: [5, 0, 2], state: "minecraft:deepslate_tiles"},
        {pos: [5, 0, 3], state: "minecraft:deepslate_tiles"},
        {pos: [5, 0, 4], state: "minecraft:deepslate_tiles"},
        {pos: [5, 0, 5], state: "minecraft:deepslate_tiles"},
        {pos: [5, 0, 6], state: "minecraft:deepslate_tiles"},
        {pos: [5, 0, 7], state: "minecraft:deepslate_tiles"},
        {pos: [5, 0, 8], state: "minecraft:deepslate_tiles"},
        {pos: [5, 0, 9], state: "minecraft:deepslate_tiles"},
        {pos: [5, 0, 10], state: "minecraft:deepslate_tiles"},
        {pos: [5, 0, 11], state: "minecraft:deepslate_tiles"},
        {pos: [5, 0, 12], state: "minecraft:deepslate_tiles"},
        {pos: [5, 0, 13], state: "minecraft:deepslate_tiles"},
        {pos: [5, 0, 14], state: "minecraft:deepslate_tiles"},
        {pos: [5, 0, 15], state: "minecraft:deepslate_tiles"},
        {pos: [6, 0, 1], state: "minecraft:deepslate_tiles"},
        {pos: [6, 0, 2], state: "minecraft:deepslate_tiles"},
        {pos: [6, 0, 3], state: "minecraft:deepslate_tiles"},
        {pos: [6, 0, 4], state: "minecraft:deepslate_tiles"},
        {pos: [6, 0, 5], state: "minecraft:deepslate_tiles"},
        {pos: [6, 0, 6], state: "minecraft:deepslate_tiles"},
        {pos: [6, 0, 7], state: "minecraft:deepslate_tiles"},
        {pos: [6, 0, 8], state: "minecraft:deepslate_tiles"},
        {pos: [6, 0, 9], state: "minecraft:deepslate_tiles"},
        {pos: [6, 0, 10], state: "minecraft:deepslate_tiles"},
        {pos: [6, 0, 11], state: "minecraft:deepslate_tiles"},
        {pos: [6, 0, 12], state: "minecraft:deepslate_tiles"},
        {pos: [6, 0, 13], state: "minecraft:deepslate_tiles"},
        {pos: [6, 0, 14], state: "minecraft:deepslate_tiles"},
        {pos: [6, 0, 15], state: "minecraft:deepslate_tiles"},
        {pos: [7, 0, 1], state: "minecraft:deepslate_tile_stairs{facing:south,half:bottom,shape:straight,waterlogged:false}"},
        {pos: [7, 0, 2], state: "minecraft:deepslate_tiles"},
        {pos: [7, 0, 3], state: "minecraft:deepslate_tiles"},
        {pos: [7, 0, 4], state: "minecraft:deepslate_tiles"},
        {pos: [7, 0, 5], state: "minecraft:deepslate_tiles"},
        {pos: [7, 0, 6], state: "minecraft:deepslate_tiles"},
        {pos: [7, 0, 7], state: "minecraft:deepslate_tiles"},
        {pos: [7, 0, 8], state: "minecraft:deepslate_tiles"},
        {pos: [7, 0, 9], state: "minecraft:deepslate_tiles"},
        {pos: [7, 0, 10], state: "minecraft:deepslate_tiles"},
        {pos: [7, 0, 11], state: "minecraft:deepslate_tiles"},
        {pos: [7, 0, 12], state: "minecraft:deepslate_tiles"},
        {pos: [7, 0, 13], state: "minecraft:deepslate_tiles"},
        {pos: [7, 0, 14], state: "minecraft:deepslate_tiles"},
        {pos: [7, 0, 15], state: "minecraft:deepslate_tile_stairs{facing:north,half:bottom,shape:straight,waterlogged:false}"},
        {pos: [8, 0, 1], state: "minecraft:deepslate_tile_stairs{facing:south,half:bottom,shape:straight,waterlogged:false}"},
        {pos: [8, 0, 2], state: "minecraft:deepslate_tiles"},
        {pos: [8, 0, 3], state: "minecraft:deepslate_tiles"},
        {pos: [8, 0, 4], state: "minecraft:deepslate_tiles"},
        {pos: [8, 0, 5], state: "minecraft:deepslate_tiles"},
        {pos: [8, 0, 6], state: "minecraft:deepslate_tiles"},
        {pos: [8, 0, 7], state: "minecraft:deepslate_tiles"},
        {pos: [8, 0, 8], state: "minecraft:deepslate_tiles"},
        {pos: [8, 0, 9], state: "minecraft:deepslate_tiles"},
        {pos: [8, 0, 10], state: "minecraft:deepslate_tiles"},
        {pos: [8, 0, 11], state: "minecraft:deepslate_tiles"},
        {pos: [8, 0, 12], state: "minecraft:deepslate_tiles"},
        {pos: [8, 0, 13], state: "minecraft:deepslate_tiles"},
        {pos: [8, 0, 14], state: "minecraft:deepslate_tiles"},
        {pos: [8, 0, 15], state: "minecraft:deepslate_tile_stairs{facing:north,half:bottom,shape:straight,waterlogged:false}"},
        {pos: [9, 0, 0], state: "minecraft:jigsaw{orientation:north_up}", nbt: {final_state: "minecraft:air", id: "minecraft:jigsaw", joint: "rollable", name: "minecraft:connect_structure", pool: "minecraft:empty", target: "minecraft:empty"}},
        {pos: [9, 0, 1], state: "minecraft:deepslate_tiles"},
        {pos: [9, 0, 2], state: "minecraft:deepslate_tiles"},
        {pos: [9, 0, 3], state: "minecraft:deepslate_tiles"},
        {pos: [9, 0, 4], state: "minecraft:deepslate_tiles"},
        {pos: [9, 0, 5], state: "minecraft:deepslate_tiles"},
        {pos: [9, 0, 6], state: "minecraft:deepslate_tiles"},
        {pos: [9, 0, 7], state: "minecraft:deepslate_tiles"},
        {pos: [9, 0, 8], state: "minecraft:deepslate_tiles"},
        {pos: [9, 0, 9], state: "minecraft:deepslate_tiles"},
        {pos: [9, 0, 10], state: "minecraft:deepslate_tiles"},
        {pos: [9, 0, 11], state: "minecraft:deepslate_tiles"},
        {pos: [9, 0, 12], state: "minecraft:deepslate_tiles"},
        {pos: [9, 0, 13], state: "minecraft:deepslate_tiles"},
        {pos: [9, 0, 14], state: "minecraft:deepslate_tiles"},
        {pos: [9, 0, 15], state: "minecraft:deepslate_tiles"},
        {pos: [10, 0, 1], state: "minecraft:deepslate_tile_stairs{facing:south,half:bottom,shape:straight,waterlogged:false}"},
        {pos: [10, 0, 2], state: "minecraft:deepslate_tiles"},
        {pos: [10, 0, 3], state: "minecraft:deepslate_tiles"},
        {pos: [10, 0, 4], state: "minecraft:deepslate_tiles"},
        {pos: [10, 0, 5], state: "minecraft:deepslate_tiles"},
        {pos: [10, 0, 6], state: "minecraft:deepslate_tiles"},
        {pos: [10, 0, 7], state: "minecraft:deepslate_tiles"},
        {pos: [10, 0, 8], state: "minecraft:deepslate_tiles"},
        {pos: [10, 0, 9], state: "minecraft:deepslate_tiles"},
        {pos: [10, 0, 10], state: "minecraft:deepslate_tiles"},
        {pos: [10, 0, 11], state: "minecraft:deepslate_tiles"},
        {pos: [10, 0, 12], state: "minecraft:deepslate_tiles"},
        {pos: [10, 0, 13], state: "minecraft:deepslate_tiles"},
        {pos: [10, 0, 14], state: "minecraft:deepslate_tiles"},
        {pos: [10, 0, 15], state: "minecraft:deepslate_tile_stairs{facing:north,half:bottom,shape:straight,waterlogged:false}"},
        {pos: [11, 0, 1], state: "minecraft:deepslate_tile_stairs{facing:south,half:bottom,shape:straight,waterlogged:false}"},
        {pos: [11, 0, 2], state: "minecraft:deepslate_tiles"},
        {pos: [11, 0, 3], state: "minecraft:deepslate_tiles"},
        {pos: [11, 0, 4], state: "minecraft:deepslate_tiles"},
        {pos: [11, 0, 5], state: "minecraft:deepslate_tiles"},
        {pos: [11, 0, 6], state: "minecraft:deepslate_tiles"},
        {pos: [11, 0, 7], state: "minecraft:deepslate_tiles"},
        {pos: [11, 0, 8], state: "minecraft:deepslate_tiles"},
        {pos: [11, 0, 9], state: "minecraft:deepslate_tiles"},
        {pos: [11, 0, 10], state: "minecraft:deepslate_tiles"},
        {pos: [11, 0, 11], state: "minecraft:deepslate_tiles"},
        {pos: [11, 0, 12], state: "minecraft:deepslate_tiles"},
        {pos: [11, 0, 13], state: "minecraft:deepslate_tiles"},
        {pos: [11, 0, 14], state: "minecraft:deepslate_tiles"},
        {pos: [11, 0, 15], state: "minecraft:deepslate_tile_stairs{facing:north,half:bottom,shape:straight,waterlogged:false}"},
        {pos: [12, 0, 1], state: "minecraft:deepslate_tiles"},
        {pos: [12, 0, 2], state: "minecraft:deepslate_tiles"},
        {pos: [12, 0, 3], state: "minecraft:deepslate_tiles"},
        {pos: [12, 0, 4], state: "minecraft:deepslate_tiles"},
        {pos: [12, 0, 5], state: "minecraft:deepslate_tiles"},
        {pos: [12, 0, 6], state: "minecraft:deepslate_tiles"},
        {pos: [12, 0, 7], state: "minecraft:deepslate_tiles"},
        {pos: [12, 0, 8], state: "minecraft:deepslate_tiles"},
        {pos: [12, 0, 9], state: "minecraft:deepslate_tiles"},
        {pos: [12, 0, 10], state: "minecraft:deepslate_tiles"},
        {pos: [12, 0, 11], state: "minecraft:deepslate_tiles"},
        {pos: [12, 0, 12], state: "minecraft:deepslate_tiles"},
        {pos: [12, 0, 13], state: "minecraft:deepslate_tiles"},
        {pos: [12, 0, 14], state: "minecraft:deepslate_tiles"},
        {pos: [12, 0, 15], state: "minecraft:deepslate_tiles"},
        {pos: [13, 0, 1], state: "minecraft:deepslate_tiles"},
        {pos: [13, 0, 2], state: "minecraft:deepslate_tiles"},
        {pos: [13, 0, 3], state: "minecraft:deepslate_tiles"},
        {pos: [13, 0, 4], state: "minecraft:deepslate_tiles"},
        {pos: [13, 0, 5], state: "minecraft:deepslate_tiles"},
        {pos: [13, 0, 6], state: "minecraft:deepslate_tiles"},
        {pos: [13, 0, 7], state: "minecraft:deepslate_tiles"},
        {pos: [13, 0, 8], state: "minecraft:deepslate_tiles"},
        {pos: [13, 0, 9], state: "minecraft:deepslate_tiles"},
        {pos: [13, 0, 10], state: "minecraft:deepslate_tiles"},
        {pos: [13, 0, 11], state: "minecraft:deepslate_tiles"},
        {pos: [13, 0, 12], state: "minecraft:deepslate_tiles"},
        {pos: [13, 0, 13], state: "minecraft:deepslate_tiles"},
        {pos: [13, 0, 14], state: "minecraft:deepslate_tiles"},
        {pos: [13, 0, 15], state: "minecraft:deepslate_tiles"},
        {pos: [14, 0, 3], state: "minecraft:deepslate_tile_stairs{facing:west,half:bottom,shape:straight,waterlogged:false}"},
        {pos: [14, 0, 4], state: "minecraft:deepslate_tile_stairs{facing:west,half:bottom,shape:straight,waterlogged:false}"},
        {pos: [14, 0, 6], state: "minecraft:deepslate_tile_stairs{facing:west,half:bottom,shape:straight,waterlogged:false}"},
        {pos: [14, 0, 7], state: "minecraft:deepslate_tile_stairs{facing:west,half:bottom,shape:straight,waterlogged:false}"},
        {pos: [14, 0, 10], state: "minecraft:deepslate_tile_stairs{facing:west,half:bottom,shape:straight,waterlogged:false}"},
        {pos: [14, 0, 11], state: "minecraft:deepslate_tile_stairs{facing:west,half:bottom,shape:straight,waterlogged:false}"},
        {pos: [14, 0, 13], state: "minecraft:deepslate_tile_stairs{facing:west,half:bottom,shape:straight,waterlogged:false}"},
        {pos: [14, 0, 14], state: "minecraft:deepslate_tile_stairs{facing:west,half:bottom,shape:straight,waterlogged:false}"},
        {pos: [6, 1, 2], state: "minecraft:deepslate_bricks"},
        {pos: [6, 1, 5], state: "minecraft:deepslate_bricks"},
        {pos: [6, 1, 8], state: "minecraft:deepslate_bricks"},
        {pos: [6, 1, 9], state: "minecraft:deepslate_bricks"},
        {pos: [6, 1, 12], state: "minecraft:deepslate_bricks"},
        {pos: [6, 1, 15], state: "minecraft:deepslate_bricks"},
        {pos: [7, 1, 5], state: "minecraft:chest{facing:north,type:single,waterlogged:false}", nbt: {LootTable: "minecraft:chests/ancient_city", id: "minecraft:chest"}},
        {pos: [7, 1, 6], state: "minecraft:deepslate_bricks"},
        {pos: [7, 1, 7], state: "minecraft:deepslate_bricks"},
        {pos: [7, 1, 8], state: "minecraft:deepslate_bricks"},
        {pos: [7, 1, 9], state: "minecraft:deepslate_tile_stairs{facing:north,half:bottom,shape:straight,waterlogged:false}"},
        {pos: [8, 1, 6], state: "minecraft:deepslate_bricks"},
        {pos: [8, 1, 7], state: "minecraft:deepslate_bricks"},
        {pos: [8, 1, 8], state: "minecraft:deepslate_bricks"},
        {pos: [8, 1, 9], state: "minecraft:deepslate_tile_stairs{facing:north,half:bottom,shape:straight,waterlogged:false}"},
        {pos: [9, 1, 2], state: "minecraft:deepslate_bricks"},
        {pos: [9, 1, 5], state: "minecraft:deepslate_bricks"},
        {pos: [9, 1, 8], state: "minecraft:deepslate_bricks"},
        {pos: [9, 1, 9], state: "minecraft:deepslate_bricks"},
        {pos: [9, 1, 12], state: "minecraft:deepslate_bricks"},
        {pos: [9, 1, 15], state: "minecraft:deepslate_bricks"},
        {pos: [12, 1, 2], state: "minecraft:deepslate_bricks"},
        {pos: [12, 1, 5], state: "minecraft:deepslate_bricks"},
        {pos: [12, 1, 8], state: "minecraft:deepslate_bricks"},
        {pos: [12, 1, 9], state: "minecraft:deepslate_bricks"},
        {pos: [12, 1, 12], state: "minecraft:deepslate_bricks"},
        {pos: [12, 1, 15], state: "minecraft:deepslate_bricks"},
        {pos: [6, 2, 2], state: "minecraft:deepslate_bricks"},
        {pos: [6, 2, 5], state: "minecraft:deepslate_bricks"},
        {pos: [6, 2, 8], state: "minecraft:deepslate_bricks"},
        {pos: [6, 2, 9], state: "minecraft:deepslate_bricks"},
        {pos: [6, 2, 12], state: "minecraft:deepslate_bricks"},
        {pos: [6, 2, 15], state: "minecraft:deepslate_bricks"},
        {pos: [7, 2, 6], state: "minecraft:deepslate_bricks"},
        {pos: [7, 2, 7], state: "minecraft:deepslate_bricks"},
        {pos: [7, 2, 8], state: "minecraft:deepslate_tile_stairs{facing:north,half:bottom,shape:straight,waterlogged:false}"},
        {pos: [8, 2, 6], state: "minecraft:deepslate_bricks"},
        {pos: [8, 2, 7], state: "minecraft:deepslate_bricks"},
        {pos: [8, 2, 8], state: "minecraft:deepslate_tile_stairs{facing:north,half:bottom,shape:straight,waterlogged:false}"},
        {pos: [9, 2, 2], state: "minecraft:deepslate_bricks"},
        {pos: [9, 2, 5], state: "minecraft:deepslate_bricks"},
        {pos: [9, 2, 8], state: "minecraft:deepslate_bricks"},
        {pos: [9, 2, 9], state: "minecraft:deepslate_bricks"},
        {pos: [9, 2, 12], state: "minecraft:deepslate_bricks"},
        {pos: [9, 2, 15], state: "minecraft:deepslate_bricks"},
        {pos: [12, 2, 2], state: "minecraft:deepslate_bricks"},
        {pos: [12, 2, 5], state: "minecraft:deepslate_bricks"},
        {pos: [12, 2, 8], state: "minecraft:deepslate_bricks"},
        {pos: [12, 2, 9], state: "minecraft:deepslate_bricks"},
        {pos: [12, 2, 12], state: "minecraft:deepslate_bricks"},
        {pos: [12, 2, 15], state: "minecraft:deepslate_bricks"},
        {pos: [6, 3, 2], state: "minecraft:deepslate_bricks"},
        {pos: [6, 3, 5], state: "minecraft:deepslate_bricks"},
        {pos: [6, 3, 8], state: "minecraft:deepslate_bricks"},
        {pos: [6, 3, 9], state: "minecraft:deepslate_bricks"},
        {pos: [6, 3, 12], state: "minecraft:deepslate_bricks"},
        {pos: [6, 3, 15], state: "minecraft:deepslate_bricks"},
        {pos: [7, 3, 5], state: "minecraft:deepslate_bricks"},
        {pos: [7, 3, 6], state: "minecraft:deepslate_bricks"},
        {pos: [7, 3, 7], state: "minecraft:deepslate_tile_stairs{facing:north,half:bottom,shape:straight,waterlogged:false}"},
        {pos: [8, 3, 5], state: "minecraft:deepslate_bricks"},
        {pos: [8, 3, 6], state: "minecraft:deepslate_bricks"},
        {pos: [8, 3, 7], state: "minecraft:deepslate_tile_stairs{facing:north,half:bottom,shape:straight,waterlogged:false}"},
        {pos: [9, 3, 2], state: "minecraft:deepslate_bricks"},
        {pos: [9, 3, 5], state: "minecraft:deepslate_bricks"},
        {pos: [9, 3, 8], state: "minecraft:deepslate_bricks"},
        {pos: [9, 3, 9], state: "minecraft:deepslate_bricks"},
        {pos: [9, 3, 12], state: "minecraft:deepslate_bricks"},
        {pos: [9, 3, 15], state: "minecraft:deepslate_bricks"},
        {pos: [12, 3, 2], state: "minecraft:deepslate_bricks"},
        {pos: [12, 3, 5], state: "minecraft:deepslate_bricks"},
        {pos: [12, 3, 8], state: "minecraft:deepslate_bricks"},
        {pos: [12, 3, 9], state: "minecraft:deepslate_bricks"},
        {pos: [12, 3, 12], state: "minecraft:deepslate_bricks"},
        {pos: [12, 3, 15], state: "minecraft:deepslate_bricks"},
        {pos: [6, 4, 2], state: "minecraft:deepslate_bricks"},
        {pos: [6, 4, 5], state: "minecraft:deepslate_bricks"},
        {pos: [6, 4, 8], state: "minecraft:deepslate_bricks"},
        {pos: [6, 4, 9], state: "minecraft:deepslate_bricks"},
        {pos: [6, 4, 12], state: "minecraft:deepslate_bricks"},
        {pos: [6, 4, 15], state: "minecraft:deepslate_bricks"},
        {pos: [7, 4, 4], state: "minecraft:deepslate_bricks"},
        {pos: [7, 4, 5], state: "minecraft:deepslate_bricks"},
        {pos: [7, 4, 6], state: "minecraft:deepslate_tile_stairs{facing:north,half:bottom,shape:straight,waterlogged:false}"},
        {pos: [8, 4, 4], state: "minecraft:deepslate_bricks"},
        {pos: [8, 4, 5], state: "minecraft:deepslate_bricks"},
        {pos: [8, 4, 6], state: "minecraft:deepslate_tile_stairs{facing:north,half:bottom,shape:straight,waterlogged:false}"},
        {pos: [9, 4, 2], state: "minecraft:deepslate_bricks"},
        {pos: [9, 4, 5], state: "minecraft:deepslate_bricks"},
        {pos: [9, 4, 8], state: "minecraft:deepslate_bricks"},
        {pos: [9, 4, 9], state: "minecraft:deepslate_bricks"},
        {pos: [9, 4, 12], state: "minecraft:deepslate_bricks"},
        {pos: [9, 4, 15], state: "minecraft:deepslate_bricks"},
        {pos: [12, 4, 2], state: "minecraft:deepslate_bricks"},
        {pos: [12, 4, 5], state: "minecraft:deepslate_bricks"},
        {pos: [12, 4, 8], state: "minecraft:deepslate_bricks"},
        {pos: [12, 4, 9], state: "minecraft:deepslate_bricks"},
        {pos: [12, 4, 12], state: "minecraft:deepslate_bricks"},
        {pos: [12, 4, 15], state: "minecraft:deepslate_bricks"},
        {pos: [6, 5, 2], state: "minecraft:deepslate_bricks"},
        {pos: [6, 5, 5], state: "minecraft:deepslate_bricks"},
        {pos: [6, 5, 8], state: "minecraft:deepslate_bricks"},
        {pos: [6, 5, 9], state: "minecraft:deepslate_bricks"},
        {pos: [6, 5, 12], state: "minecraft:deepslate_bricks"},
        {pos: [6, 5, 15], state: "minecraft:deepslate_bricks"},
        {pos: [7, 5, 3], state: "minecraft:deepslate_bricks"},
        {pos: [7, 5, 4], state: "minecraft:deepslate_bricks"},
        {pos: [7, 5, 5], state: "minecraft:deepslate_tile_stairs{facing:north,half:bottom,shape:straight,waterlogged:false}"},
        {pos: [8, 5, 3], state: "minecraft:deepslate_bricks"},
        {pos: [8, 5, 4], state: "minecraft:deepslate_bricks"},
        {pos: [8, 5, 5], state: "minecraft:deepslate_tile_stairs{facing:north,half:bottom,shape:straight,waterlogged:false}"},
        {pos: [9, 5, 2], state: "minecraft:deepslate_bricks"},
        {pos: [9, 5, 5], state: "minecraft:deepslate_bricks"},
        {pos: [9, 5, 8], state: "minecraft:deepslate_bricks"},
        {pos: [9, 5, 9], state: "minecraft:deepslate_bricks"},
        {pos: [9, 5, 12], state: "minecraft:deepslate_bricks"},
        {pos: [9, 5, 15], state: "minecraft:deepslate_bricks"},
        {pos: [12, 5, 2], state: "minecraft:deepslate_bricks"},
        {pos: [12, 5, 5], state: "minecraft:deepslate_bricks"},
        {pos: [12, 5, 8], state: "minecraft:deepslate_bricks"},
        {pos: [12, 5, 9], state: "minecraft:deepslate_bricks"},
        {pos: [12, 5, 12], state: "minecraft:deepslate_bricks"},
        {pos: [12, 5, 15], state: "minecraft:deepslate_bricks"},
        {pos: [4, 6, 1], state: "minecraft:deepslate_bricks"},
        {pos: [4, 6, 2], state: "minecraft:deepslate_bricks"},
        {pos: [4, 6, 3], state: "minecraft:deepslate_bricks"},
        {pos: [4, 6, 4], state: "minecraft:deepslate_bricks"},
        {pos: [4, 6, 5], state: "minecraft:deepslate_bricks"},
        {pos: [4, 6, 6], state: "minecraft:deepslate_bricks"},
        {pos: [4, 6, 7], state: "minecraft:deepslate_bricks"},
        {pos: [4, 6, 8], state: "minecraft:deepslate_bricks"},
        {pos: [4, 6, 9], state: "minecraft:deepslate_bricks"},
        {pos: [4, 6, 10], state: "minecraft:deepslate_bricks"},
        {pos: [4, 6, 11], state: "minecraft:deepslate_bricks"},
        {pos: [4, 6, 12], state: "minecraft:deepslate_bricks"},
        {pos: [4, 6, 13], state: "minecraft:deepslate_bricks"},
        {pos: [4, 6, 14], state: "minecraft:deepslate_bricks"},
        {pos: [4, 6, 15], state: "minecraft:deepslate_bricks"},
        {pos: [4, 6, 16], state: "minecraft:deepslate_bricks"},
        {pos: [5, 6, 1], state: "minecraft:deepslate_bricks"},
        {pos: [5, 6, 2], state: "minecraft:deepslate_bricks"},
        {pos: [5, 6, 3], state: "minecraft:deepslate_bricks"},
        {pos: [5, 6, 4], state: "minecraft:deepslate_bricks"},
        {pos: [5, 6, 5], state: "minecraft:deepslate_bricks"},
        {pos: [5, 6, 6], state: "minecraft:deepslate_bricks"},
        {pos: [5, 6, 7], state: "minecraft:deepslate_bricks"},
        {pos: [5, 6, 8], state: "minecraft:deepslate_bricks"},
        {pos: [5, 6, 9], state: "minecraft:deepslate_bricks"},
        {pos: [5, 6, 10], state: "minecraft:deepslate_bricks"},
        {pos: [5, 6, 11], state: "minecraft:deepslate_bricks"},
        {pos: [5, 6, 12], state: "minecraft:deepslate_bricks"},
        {pos: [5, 6, 13], state: "minecraft:deepslate_bricks"},
        {pos: [5, 6, 14], state: "minecraft:deepslate_bricks"},
        {pos: [5, 6, 15], state: "minecraft:deepslate_bricks"},
        {pos: [5, 6, 16], state: "minecraft:deepslate_bricks"},
        {pos: [6, 6, 1], state: "minecraft:deepslate_bricks"},
        {pos: [6, 6, 2], state: "minecraft:deepslate_bricks"},
        {pos: [6, 6, 3], state: "minecraft:deepslate_bricks"},
        {pos: [6, 6, 4], state: "minecraft:deepslate_bricks"},
        {pos: [6, 6, 5], state: "minecraft:deepslate_bricks"},
        {pos: [6, 6, 6], state: "minecraft:deepslate_bricks"},
        {pos: [6, 6, 7], state: "minecraft:deepslate_bricks"},
        {pos: [6, 6, 8], state: "minecraft:deepslate_bricks"},
        {pos: [6, 6, 9], state: "minecraft:deepslate_bricks"},
        {pos: [6, 6, 10], state: "minecraft:deepslate_bricks"},
        {pos: [6, 6, 11], state: "minecraft:deepslate_bricks"},
        {pos: [6, 6, 12], state: "minecraft:deepslate_bricks"},
        {pos: [6, 6, 13], state: "minecraft:deepslate_bricks"},
        {pos: [6, 6, 14], state: "minecraft:deepslate_bricks"},
        {pos: [6, 6, 15], state: "minecraft:deepslate_bricks"},
        {pos: [6, 6, 16], state: "minecraft:deepslate_bricks"},
        {pos: [7, 6, 1], state: "minecraft:deepslate_bricks"},
        {pos: [7, 6, 2], state: "minecraft:deepslate_bricks"},
        {pos: [7, 6, 3], state: "minecraft:deepslate_bricks"},
        {pos: [7, 6, 4], state: "minecraft:deepslate_tile_stairs{facing:north,half:bottom,shape:straight,waterlogged:false}"},
        {pos: [7, 6, 12], state: "minecraft:deepslate_bricks"},
        {pos: [7, 6, 13], state: "minecraft:deepslate_bricks"},
        {pos: [7, 6, 14], state: "minecraft:deepslate_bricks"},
        {pos: [7, 6, 15], state: "minecraft:deepslate_bricks"},
        {pos: [7, 6, 16], state: "minecraft:deepslate_bricks"},
        {pos: [8, 6, 1], state: "minecraft:deepslate_bricks"},
        {pos: [8, 6, 2], state: "minecraft:deepslate_bricks"},
        {pos: [8, 6, 3], state: "minecraft:deepslate_bricks"},
        {pos: [8, 6, 4], state: "minecraft:deepslate_tile_stairs{facing:north,half:bottom,shape:straight,waterlogged:false}"},
        {pos: [8, 6, 12], state: "minecraft:deepslate_bricks"},
        {pos: [8, 6, 13], state: "minecraft:deepslate_bricks"},
        {pos: [8, 6, 14], state: "minecraft:deepslate_bricks"},
        {pos: [8, 6, 15], state: "minecraft:deepslate_bricks"},
        {pos: [8, 6, 16], state: "minecraft:deepslate_bricks"},
        {pos: [9, 6, 1], state: "minecraft:deepslate_bricks"},
        {pos: [9, 6, 2], state: "minecraft:deepslate_bricks"},
        {pos: [9, 6, 3], state: "minecraft:deepslate_bricks"},
        {pos: [9, 6, 4], state: "minecraft:deepslate_bricks"},
        {pos: [9, 6, 5], state: "minecraft:deepslate_bricks"},
        {pos: [9, 6, 6], state: "minecraft:deepslate_bricks"},
        {pos: [9, 6, 7], state: "minecraft:deepslate_bricks"},
        {pos: [9, 6, 8], state: "minecraft:deepslate_bricks"},
        {pos: [9, 6, 9], state: "minecraft:deepslate_bricks"},
        {pos: [9, 6, 10], state: "minecraft:deepslate_bricks"},
        {pos: [9, 6, 11], state: "minecraft:deepslate_bricks"},
        {pos: [9, 6, 12], state: "minecraft:deepslate_bricks"},
        {pos: [9, 6, 13], state: "minecraft:deepslate_bricks"},
        {pos: [9, 6, 14], state: "minecraft:deepslate_bricks"},
        {pos: [9, 6, 15], state: "minecraft:deepslate_bricks"},
        {pos: [9, 6, 16], state: "minecraft:deepslate_bricks"},
        {pos: [10, 6, 1], state: "minecraft:deepslate_bricks"},
        {pos: [10, 6, 2], state: "minecraft:deepslate_bricks"},
        {pos: [10, 6, 3], state: "minecraft:deepslate_bricks"},
        {pos: [10, 6, 4], state: "minecraft:deepslate_bricks"},
        {pos: [10, 6, 5], state: "minecraft:deepslate_bricks"},
        {pos: [10, 6, 6], state: "minecraft:deepslate_bricks"},
        {pos: [10, 6, 7], state: "minecraft:deepslate_bricks"},
        {pos: [10, 6, 8], state: "minecraft:deepslate_bricks"},
        {pos: [10, 6, 9], state: "minecraft:deepslate_bricks"},
        {pos: [10, 6, 10], state: "minecraft:deepslate_bricks"},
        {pos: [10, 6, 11], state: "minecraft:deepslate_bricks"},
        {pos: [10, 6, 12], state: "minecraft:deepslate_bricks"},
        {pos: [10, 6, 13], state: "minecraft:deepslate_bricks"},
        {pos: [10, 6, 14], state: "minecraft:deepslate_bricks"},
        {pos: [10, 6, 15], state: "minecraft:deepslate_bricks"},
        {pos: [10, 6, 16], state: "minecraft:deepslate_bricks"},
        {pos: [11, 6, 1], state: "minecraft:deepslate_bricks"},
        {pos: [11, 6, 2], state: "minecraft:deepslate_bricks"},
        {pos: [11, 6, 3], state: "minecraft:deepslate_bricks"},
        {pos: [11, 6, 4], state: "minecraft:deepslate_bricks"},
        {pos: [11, 6, 5], state: "minecraft:deepslate_bricks"},
        {pos: [11, 6, 6], state: "minecraft:deepslate_bricks"},
        {pos: [11, 6, 7], state: "minecraft:deepslate_bricks"},
        {pos: [11, 6, 8], state: "minecraft:deepslate_bricks"},
        {pos: [11, 6, 9], state: "minecraft:deepslate_bricks"},
        {pos: [11, 6, 10], state: "minecraft:deepslate_bricks"},
        {pos: [11, 6, 11], state: "minecraft:deepslate_bricks"},
        {pos: [11, 6, 12], state: "minecraft:deepslate_bricks"},
        {pos: [11, 6, 13], state: "minecraft:deepslate_bricks"},
        {pos: [11, 6, 14], state: "minecraft:deepslate_bricks"},
        {pos: [11, 6, 15], state: "minecraft:deepslate_bricks"},
        {pos: [11, 6, 16], state: "minecraft:deepslate_bricks"},
        {pos: [12, 6, 1], state: "minecraft:deepslate_bricks"},
        {pos: [12, 6, 2], state: "minecraft:deepslate_bricks"},
        {pos: [12, 6, 3], state: "minecraft:deepslate_bricks"},
        {pos: [12, 6, 4], state: "minecraft:deepslate_bricks"},
        {pos: [12, 6, 5], state: "minecraft:deepslate_bricks"},
        {pos: [12, 6, 6], state: "minecraft:deepslate_bricks"},
        {pos: [12, 6, 7], state: "minecraft:deepslate_bricks"},
        {pos: [12, 6, 8], state: "minecraft:deepslate_bricks"},
        {pos: [12, 6, 9], state: "minecraft:deepslate_bricks"},
        {pos: [12, 6, 10], state: "minecraft:deepslate_bricks"},
        {pos: [12, 6, 11], state: "minecraft:deepslate_bricks"},
        {pos: [12, 6, 12], state: "minecraft:deepslate_bricks"},
        {pos: [12, 6, 13], state: "minecraft:deepslate_bricks"},
        {pos: [12, 6, 14], state: "minecraft:deepslate_bricks"},
        {pos: [12, 6, 15], state: "minecraft:deepslate_bricks"},
        {pos: [12, 6, 16], state: "minecraft:deepslate_bricks"},
        {pos: [13, 6, 1], state: "minecraft:deepslate_bricks"},
        {pos: [13, 6, 2], state: "minecraft:deepslate_bricks"},
        {pos: [13, 6, 3], state: "minecraft:deepslate_bricks"},
        {pos: [13, 6, 4], state: "minecraft:deepslate_bricks"},
        {pos: [13, 6, 5], state: "minecraft:deepslate_bricks"},
        {pos: [13, 6, 6], state: "minecraft:deepslate_bricks"},
        {pos: [13, 6, 7], state: "minecraft:deepslate_bricks"},
        {pos: [13, 6, 8], state: "minecraft:deepslate_bricks"},
        {pos: [13, 6, 9], state: "minecraft:deepslate_bricks"},
        {pos: [13, 6, 10], state: "minecraft:deepslate_bricks"},
        {pos: [13, 6, 11], state: "minecraft:deepslate_bricks"},
        {pos: [13, 6, 12], state: "minecraft:deepslate_bricks"},
        {pos: [13, 6, 13], state: "minecraft:deepslate_bricks"},
        {pos: [13, 6, 14], state: "minecraft:deepslate_bricks"},
        {pos: [13, 6, 15], state: "minecraft:deepslate_bricks"},
        {pos: [13, 6, 16], state: "minecraft:deepslate_bricks"},
        {pos: [14, 6, 1], state: "minecraft:deepslate_bricks"},
        {pos: [14, 6, 2], state: "minecraft:deepslate_bricks"},
        {pos: [14, 6, 3], state: "minecraft:deepslate_bricks"},
        {pos: [14, 6, 4], state: "minecraft:deepslate_bricks"},
        {pos: [14, 6, 5], state: "minecraft:deepslate_bricks"},
        {pos: [14, 6, 6], state: "minecraft:deepslate_bricks"},
        {pos: [14, 6, 7], state: "minecraft:deepslate_bricks"},
        {pos: [14, 6, 8], state: "minecraft:deepslate_bricks"},
        {pos: [14, 6, 9], state: "minecraft:deepslate_bricks"},
        {pos: [14, 6, 10], state: "minecraft:deepslate_bricks"},
        {pos: [14, 6, 11], state: "minecraft:deepslate_bricks"},
        {pos: [14, 6, 12], state: "minecraft:deepslate_bricks"},
        {pos: [14, 6, 13], state: "minecraft:deepslate_bricks"},
        {pos: [14, 6, 14], state: "minecraft:deepslate_bricks"},
        {pos: [14, 6, 15], state: "minecraft:deepslate_bricks"},
        {pos: [14, 6, 16], state: "minecraft:deepslate_bricks"},
        {pos: [15, 6, 5], state: "minecraft:deepslate_bricks"},
        {pos: [15, 6, 6], state: "minecraft:deepslate_bricks"},
        {pos: [15, 6, 7], state: "minecraft:deepslate_bricks"},
        {pos: [15, 6, 8], state: "minecraft:deepslate_bricks"},
        {pos: [15, 6, 9], state: "minecraft:deepslate_bricks"},
        {pos: [15, 6, 10], state: "minecraft:deepslate_bricks"},
        {pos: [15, 6, 11], state: "minecraft:deepslate_bricks"},
        {pos: [15, 6, 12], state: "minecraft:deepslate_bricks"},
        {pos: [16, 6, 5], state: "minecraft:deepslate_bricks"},
        {pos: [16, 6, 6], state: "minecraft:deepslate_bricks"},
        {pos: [16, 6, 7], state: "minecraft:deepslate_bricks"},
        {pos: [16, 6, 8], state: "minecraft:deepslate_bricks"},
        {pos: [16, 6, 9], state: "minecraft:deepslate_bricks"},
        {pos: [16, 6, 10], state: "minecraft:deepslate_bricks"},
        {pos: [16, 6, 11], state: "minecraft:deepslate_bricks"},
        {pos: [16, 6, 12], state: "minecraft:deepslate_bricks"},
        {pos: [4, 7, 2], state: "minecraft:deepslate_bricks"},
        {pos: [4, 7, 5], state: "minecraft:deepslate_bricks"},
        {pos: [4, 7, 8], state: "minecraft:deepslate_bricks"},
        {pos: [4, 7, 9], state: "minecraft:deepslate_bricks"},
        {pos: [4, 7, 12], state: "minecraft:deepslate_bricks"},
        {pos: [4, 7, 15], state: "minecraft:deepslate_bricks"},
        {pos: [5, 7, 2], state: "minecraft:gray_carpet"},
        {pos: [5, 7, 3], state: "minecraft:gray_carpet"},
        {pos: [5, 7, 4], state: "minecraft:gray_carpet"},
        {pos: [5, 7, 5], state: "minecraft:gray_carpet"},
        {pos: [5, 7, 6], state: "minecraft:gray_carpet"},
        {pos: [5, 7, 7], state: "minecraft:gray_carpet"},
        {pos: [5, 7, 8], state: "minecraft:gray_carpet"},
        {pos: [5, 7, 9], state: "minecraft:gray_carpet"},
        {pos: [5, 7, 10], state: "minecraft:gray_carpet"},
        {pos: [5, 7, 11], state: "minecraft:gray_carpet"},
        {pos: [5, 7, 12], state: "minecraft:gray_carpet"},
        {pos: [5, 7, 13], state: "minecraft:gray_carpet"},
        {pos: [5, 7, 14], state: "minecraft:gray_carpet"},
        {pos: [5, 7, 15], state: "minecraft:gray_carpet"},
        {pos: [6, 7, 2], state: "minecraft:gray_carpet"},
        {pos: [6, 7, 3], state: "minecraft:gray_carpet"},
        {pos: [6, 7, 4], state: "minecraft:deepslate_tile_wall{east:none,north:none,south:low,up:true,waterlogged:false,west:none}"},
        {pos: [6, 7, 5], state: "minecraft:deepslate_tile_wall{east:none,north:low,south:low,up:false,waterlogged:false,west:none}"},
        {pos: [6, 7, 6], state: "minecraft:deepslate_tile_wall{east:none,north:low,south:low,up:false,waterlogged:false,west:none}"},
        {pos: [6, 7, 7], state: "minecraft:deepslate_tile_wall{east:none,north:low,south:low,up:false,waterlogged:false,west:none}"},
        {pos: [6, 7, 8], state: "minecraft:deepslate_tile_wall{east:none,north:low,south:low,up:false,waterlogged:false,west:none}"},
        {pos: [6, 7, 9], state: "minecraft:deepslate_tile_wall{east:none,north:low,south:low,up:false,waterlogged:false,west:none}"},
        {pos: [6, 7, 10], state: "minecraft:deepslate_tile_wall{east:none,north:low,south:low,up:false,waterlogged:false,west:none}"},
        {pos: [6, 7, 11], state: "minecraft:deepslate_tile_wall{east:none,north:low,south:low,up:false,waterlogged:false,west:none}"},
        {pos: [6, 7, 12], state: "minecraft:deepslate_tile_wall{east:tall,north:low,south:none,up:true,waterlogged:false,west:none}"},
        {pos: [6, 7, 13], state: "minecraft:gray_carpet"},
        {pos: [6, 7, 14], state: "minecraft:gray_carpet"},
        {pos: [6, 7, 15], state: "minecraft:gray_carpet"},
        {pos: [7, 7, 2], state: "minecraft:gray_carpet"},
        {pos: [7, 7, 3], state: "minecraft:gray_carpet"},
        {pos: [7, 7, 12], state: "minecraft:deepslate_tile_wall{east:tall,north:none,south:none,up:false,waterlogged:false,west:tall}"},
        {pos: [7, 7, 13], state: "minecraft:gray_carpet"},
        {pos: [7, 7, 14], state: "minecraft:gray_carpet"},
        {pos: [7, 7, 15], state: "minecraft:gray_carpet"},
        {pos: [8, 7, 2], state: "minecraft:gray_carpet"},
        {pos: [8, 7, 3], state: "minecraft:gray_carpet"},
        {pos: [8, 7, 12], state: "minecraft:deepslate_tile_wall{east:tall,north:none,south:none,up:false,waterlogged:false,west:tall}"},
        {pos: [8, 7, 13], state: "minecraft:gray_carpet"},
        {pos: [8, 7, 14], state: "minecraft:gray_carpet"},
        {pos: [8, 7, 15], state: "minecraft:gray_carpet"},
        {pos: [9, 7, 2], state: "minecraft:gray_carpet"},
        {pos: [9, 7, 3], state: "minecraft:gray_carpet"},
        {pos: [9, 7, 4], state: "minecraft:deepslate_tile_wall{east:none,north:none,south:low,up:true,waterlogged:false,west:none}"},
        {pos: [9, 7, 5], state: "minecraft:deepslate_tile_wall{east:none,north:low,south:low,up:false,waterlogged:false,west:none}"},
        {pos: [9, 7, 6], state: "minecraft:deepslate_tile_wall{east:none,north:low,south:low,up:false,waterlogged:false,west:none}"},
        {pos: [9, 7, 7], state: "minecraft:deepslate_tile_wall{east:none,north:low,south:low,up:false,waterlogged:false,west:none}"},
        {pos: [9, 7, 8], state: "minecraft:deepslate_tile_wall{east:none,north:low,south:low,up:false,waterlogged:false,west:none}"},
        {pos: [9, 7, 9], state: "minecraft:deepslate_tile_wall{east:none,north:low,south:low,up:false,waterlogged:false,west:none}"},
        {pos: [9, 7, 10], state: "minecraft:deepslate_tile_wall{east:none,north:low,south:low,up:false,waterlogged:false,west:none}"},
        {pos: [9, 7, 11], state: "minecraft:deepslate_tile_wall{east:none,north:low,south:low,up:false,waterlogged:false,west:none}"},
        {pos: [9, 7, 12], state: "minecraft:deepslate_tile_wall{east:none,north:low,south:none,up:true,waterlogged:false,west:tall}"},
        {pos: [9, 7, 13], state: "minecraft:gray_carpet"},
        {pos: [9, 7, 14], state: "minecraft:gray_carpet"},
        {pos: [9, 7, 15], state: "minecraft:gray_carpet"},
        {pos: [10, 7, 2], state: "minecraft:gray_carpet"},
        {pos: [10, 7, 3], state: "minecraft:gray_carpet"},
        {pos: [10, 7, 4], state: "minecraft:gray_carpet"},
        {pos: [10, 7, 5], state: "minecraft:gray_carpet"},
        {pos: [10, 7, 6], state: "minecraft:gray_carpet"},
        {pos: [10, 7, 7], state: "minecraft:gray_carpet"},
        {pos: [10, 7, 8], state: "minecraft:gray_carpet"},
        {pos: [10, 7, 9], state: "minecraft:gray_carpet"},
        {pos: [10, 7, 10], state: "minecraft:gray_carpet"},
        {pos: [10, 7, 11], state: "minecraft:gray_carpet"},
        {pos: [10, 7, 12], state: "minecraft:gray_carpet"},
        {pos: [10, 7, 13], state: "minecraft:gray_carpet"},
        {pos: [10, 7, 14], state: "minecraft:gray_carpet"},
        {pos: [10, 7, 15], state: "minecraft:gray_carpet"},
        {pos: [11, 7, 2], state: "minecraft:gray_carpet"},
        {pos: [11, 7, 3], state: "minecraft:gray_carpet"},
        {pos: [11, 7, 4], state: "minecraft:gray_carpet"},
        {pos: [11, 7, 5], state: "minecraft:deepslate_tile_wall{east:tall,north:none,south:none,up:true,waterlogged:false,west:none}"},
        {pos: [11, 7, 8], state: "minecraft:deepslate_tile_wall{east:tall,north:none,south:none,up:true,waterlogged:false,west:none}"},
        {pos: [11, 7, 12], state: "minecraft:deepslate_tile_wall{east:tall,north:none,south:none,up:true,waterlogged:false,west:none}"},
        {pos: [11, 7, 13], state: "minecraft:gray_carpet"},
        {pos: [11, 7, 14], state: "minecraft:gray_carpet"},
        {pos: [11, 7, 15], state: "minecraft:gray_carpet"},
        {pos: [12, 7, 2], state: "minecraft:gray_carpet"},
        {pos: [12, 7, 3], state: "minecraft:gray_carpet"},
        {pos: [12, 7, 4], state: "minecraft:gray_carpet"},
        {pos: [12, 7, 5], state: "minecraft:deepslate_tile_wall{east:tall,north:none,south:none,up:false,waterlogged:false,west:tall}"},
        {pos: [12, 7, 8], state: "minecraft:deepslate_tile_wall{east:tall,north:none,south:none,up:false,waterlogged:false,west:tall}"},
        {pos: [12, 7, 12], state: "minecraft:deepslate_tile_wall{east:tall,north:none,south:none,up:false,waterlogged:false,west:tall}"},
        {pos: [12, 7, 13], state: "minecraft:gray_carpet"},
        {pos: [12, 7, 14], state: "minecraft:gray_carpet"},
        {pos: [12, 7, 15], state: "minecraft:gray_carpet"},
        {pos: [13, 7, 2], state: "minecraft:gray_carpet"},
        {pos: [13, 7, 3], state: "minecraft:gray_carpet"},
        {pos: [13, 7, 4], state: "minecraft:gray_carpet"},
        {pos: [13, 7, 5], state: "minecraft:deepslate_tile_wall{east:tall,north:none,south:none,up:false,waterlogged:false,west:tall}"},
        {pos: [13, 7, 8], state: "minecraft:deepslate_tile_wall{east:tall,north:none,south:none,up:false,waterlogged:false,west:tall}"},
        {pos: [13, 7, 9], state: "minecraft:chest{facing:west,type:single,waterlogged:false}", nbt: {LootTable: "minecraft:chests/ancient_city", id: "minecraft:chest"}},
        {pos: [13, 7, 12], state: "minecraft:deepslate_tile_wall{east:tall,north:none,south:none,up:false,waterlogged:false,west:tall}"},
        {pos: [13, 7, 13], state: "minecraft:gray_carpet"},
        {pos: [13, 7, 14], state: "minecraft:gray_carpet"},
        {pos: [13, 7, 15], state: "minecraft:gray_carpet"},
        {pos: [14, 7, 2], state: "minecraft:deepslate_bricks"},
        {pos: [14, 7, 5], state: "minecraft:deepslate_bricks"},
        {pos: [14, 7, 8], state: "minecraft:deepslate_bricks"},
        {pos: [14, 7, 9], state: "minecraft:deepslate_bricks"},
        {pos: [14, 7, 12], state: "minecraft:deepslate_bricks"},
        {pos: [14, 7, 15], state: "minecraft:deepslate_bricks"},
        {pos: [15, 7, 5], state: "minecraft:deepslate_tile_wall{east:low,north:none,south:none,up:false,waterlogged:false,west:low}"},
        {pos: [15, 7, 12], state: "minecraft:deepslate_tile_wall{east:low,north:none,south:none,up:false,waterlogged:false,west:low}"},
        {pos: [16, 7, 5], state: "minecraft:deepslate_tile_wall{east:none,north:none,south:low,up:true,waterlogged:false,west:low}"},
        {pos: [16, 7, 6], state: "minecraft:deepslate_tile_wall{east:none,north:low,south:low,up:false,waterlogged:false,west:none}"},
        {pos: [16, 7, 7], state: "minecraft:deepslate_tile_wall{east:none,north:low,south:low,up:false,waterlogged:false,west:none}"},
        {pos: [16, 7, 8], state: "minecraft:deepslate_tile_wall{east:none,north:low,south:low,up:false,waterlogged:false,west:none}"},
        {pos: [16, 7, 9], state: "minecraft:deepslate_tile_wall{east:none,north:low,south:low,up:false,waterlogged:false,west:none}"},
        {pos: [16, 7, 10], state: "minecraft:deepslate_tile_wall{east:none,north:low,south:low,up:false,waterlogged:false,west:none}"},
        {pos: [16, 7, 11], state: "minecraft:deepslate_tile_wall{east:none,north:low,south:low,up:false,waterlogged:false,west:none}"},
        {pos: [16, 7, 12], state: "minecraft:deepslate_tile_wall{east:none,north:low,south:none,up:true,waterlogged:false,west:low}"},
        {pos: [4, 8, 2], state: "minecraft:deepslate_bricks"},
        {pos: [4, 8, 5], state: "minecraft:deepslate_bricks"},
        {pos: [4, 8, 8], state: "minecraft:deepslate_bricks"},
        {pos: [4, 8, 9], state: "minecraft:deepslate_bricks"},
        {pos: [4, 8, 12], state: "minecraft:deepslate_bricks"},
        {pos: [4, 8, 15], state: "minecraft:deepslate_bricks"},
        {pos: [6, 8, 4], state: "minecraft:soul_lantern{hanging:false,waterlogged:false}"},
        {pos: [6, 8, 12], state: "minecraft:deepslate_tile_wall{east:tall,north:none,south:none,up:true,waterlogged:false,west:none}"},
        {pos: [7, 8, 12], state: "minecraft:deepslate_tile_wall{east:tall,north:none,south:none,up:false,waterlogged:false,west:tall}"},
        {pos: [8, 8, 12], state: "minecraft:deepslate_tile_wall{east:tall,north:none,south:none,up:false,waterlogged:false,west:tall}"},
        {pos: [9, 8, 4], state: "minecraft:soul_lantern{hanging:false,waterlogged:false}"},
        {pos: [9, 8, 12], state: "minecraft:deepslate_tile_wall{east:none,north:none,south:none,up:true,waterlogged:false,west:tall}"},
        {pos: [11, 8, 5], state: "minecraft:deepslate_tile_wall{east:tall,north:none,south:none,up:true,waterlogged:false,west:none}"},
        {pos: [11, 8, 8], state: "minecraft:deepslate_tile_wall{east:tall,north:none,south:none,up:true,waterlogged:false,west:none}"},
        {pos: [11, 8, 12], state: "minecraft:deepslate_tile_wall{east:tall,north:none,south:none,up:true,waterlogged:false,west:none}"},
        {pos: [12, 8, 5], state: "minecraft:deepslate_tile_wall{east:tall,north:none,south:none,up:false,waterlogged:false,west:tall}"},
        {pos: [12, 8, 8], state: "minecraft:deepslate_tile_wall{east:tall,north:none,south:none,up:false,waterlogged:false,west:tall}"},
        {pos: [12, 8, 12], state: "minecraft:deepslate_tile_wall{east:tall,north:none,south:none,up:false,waterlogged:false,west:tall}"},
        {pos: [13, 8, 5], state: "minecraft:deepslate_tile_wall{east:tall,north:none,south:none,up:false,waterlogged:false,west:tall}"},
        {pos: [13, 8, 8], state: "minecraft:deepslate_tile_wall{east:tall,north:none,south:none,up:false,waterlogged:false,west:tall}"},
        {pos: [13, 8, 12], state: "minecraft:deepslate_tile_wall{east:tall,north:none,south:none,up:false,waterlogged:false,west:tall}"},
        {pos: [14, 8, 2], state: "minecraft:deepslate_bricks"},
        {pos: [14, 8, 5], state: "minecraft:deepslate_bricks"},
        {pos: [14, 8, 8], state: "minecraft:deepslate_bricks"},
        {pos: [14, 8, 9], state: "minecraft:deepslate_bricks"},
        {pos: [14, 8, 12], state: "minecraft:deepslate_bricks"},
        {pos: [14, 8, 15], state: "minecraft:deepslate_bricks"},
        {pos: [4, 9, 2], state: "minecraft:deepslate_bricks"},
        {pos: [4, 9, 5], state: "minecraft:deepslate_bricks"},
        {pos: [4, 9, 8], state: "minecraft:deepslate_bricks"},
        {pos: [4, 9, 9], state: "minecraft:deepslate_bricks"},
        {pos: [4, 9, 12], state: "minecraft:deepslate_bricks"},
        {pos: [4, 9, 15], state: "minecraft:deepslate_bricks"},
        {pos: [6, 9, 12], state: "minecraft:deepslate_tile_wall{east:low,north:none,south:none,up:true,waterlogged:false,west:none}"},
        {pos: [7, 9, 12], state: "minecraft:deepslate_tile_wall{east:low,north:none,south:none,up:false,waterlogged:false,west:low}"},
        {pos: [8, 9, 12], state: "minecraft:deepslate_tile_wall{east:low,north:none,south:none,up:false,waterlogged:false,west:low}"},
        {pos: [9, 9, 12], state: "minecraft:deepslate_tile_wall{east:none,north:none,south:none,up:true,waterlogged:false,west:low}"},
        {pos: [11, 9, 5], state: "minecraft:deepslate_tile_wall{east:low,north:none,south:none,up:true,waterlogged:false,west:none}"},
        {pos: [11, 9, 8], state: "minecraft:deepslate_tile_wall{east:low,north:none,south:none,up:true,waterlogged:false,west:none}"},
        {pos: [11, 9, 12], state: "minecraft:deepslate_tile_wall{east:low,north:none,south:none,up:true,waterlogged:false,west:none}"},
        {pos: [12, 9, 5], state: "minecraft:deepslate_tile_wall{east:low,north:none,south:none,up:false,waterlogged:false,west:low}"},
        {pos: [12, 9, 8], state: "minecraft:deepslate_tile_wall{east:low,north:none,south:none,up:false,waterlogged:false,west:low}"},
        {pos: [12, 9, 12], state: "minecraft:deepslate_tile_wall{east:low,north:none,south:none,up:false,waterlogged:false,west:low}"},
        {pos: [13, 9, 5], state: "minecraft:deepslate_tile_wall{east:low,north:none,south:none,up:false,waterlogged:false,west:low}"},
        {pos: [13, 9, 8], state: "minecraft:deepslate_tile_wall{east:low,north:none,south:none,up:false,waterlogged:false,west:low}"},
        {pos: [13, 9, 12], state: "minecraft:deepslate_tile_wall{east:low,north:none,south:none,up:false,waterlogged:false,west:low}"},
        {pos: [14, 9, 2], state: "minecraft:deepslate_bricks"},
        {pos: [14, 9, 5], state: "minecraft:deepslate_bricks"},
        {pos: [14, 9, 8], state: "minecraft:deepslate_bricks"},
        {pos: [14, 9, 9], state: "minecraft:deepslate_bricks"},
        {pos: [14, 9, 12], state: "minecraft:deepslate_bricks"},
        {pos: [14, 9, 15], state: "minecraft:deepslate_bricks"},
        {pos: [4, 10, 2], state: "minecraft:deepslate_bricks"},
        {pos: [4, 10, 5], state: "minecraft:deepslate_bricks"},
        {pos: [4, 10, 8], state: "minecraft:deepslate_bricks"},
        {pos: [4, 10, 9], state: "minecraft:deepslate_bricks"},
        {pos: [4, 10, 12], state: "minecraft:deepslate_bricks"},
        {pos: [4, 10, 15], state: "minecraft:deepslate_bricks"},
        {pos: [6, 10, 12], state: "minecraft:soul_lantern{hanging:false,waterlogged:false}"},
        {pos: [9, 10, 12], state: "minecraft:soul_lantern{hanging:false,waterlogged:false}"},
        {pos: [11, 10, 5], state: "minecraft:soul_lantern{hanging:false,waterlogged:false}"},
        {pos: [11, 10, 8], state: "minecraft:soul_lantern{hanging:false,waterlogged:false}"},
        {pos: [11, 10, 12], state: "minecraft:soul_lantern{hanging:false,waterlogged:false}"},
        {pos: [14, 10, 2], state: "minecraft:deepslate_bricks"},
        {pos: [14, 10, 5], state: "minecraft:deepslate_bricks"},
        {pos: [14, 10, 8], state: "minecraft:deepslate_bricks"},
        {pos: [14, 10, 9], state: "minecraft:deepslate_bricks"},
        {pos: [14, 10, 12], state: "minecraft:deepslate_bricks"},
        {pos: [14, 10, 15], state: "minecraft:deepslate_bricks"},
        {pos: [3, 11, 1], state: "minecraft:deepslate_tiles"},
        {pos: [3, 11, 2], state: "minecraft:deepslate_tiles"},
        {pos: [3, 11, 3], state: "minecraft:deepslate_tiles"},
        {pos: [3, 11, 4], state: "minecraft:deepslate_tiles"},
        {pos: [3, 11, 5], state: "minecraft:deepslate_tiles"},
        {pos: [3, 11, 6], state: "minecraft:deepslate_tiles"},
        {pos: [3, 11, 7], state: "minecraft:deepslate_tiles"},
        {pos: [3, 11, 8], state: "minecraft:deepslate_tiles"},
        {pos: [3, 11, 9], state: "minecraft:deepslate_tiles"},
        {pos: [3, 11, 10], state: "minecraft:deepslate_tiles"},
        {pos: [3, 11, 11], state: "minecraft:deepslate_tiles"},
        {pos: [3, 11, 12], state: "minecraft:deepslate_tiles"},
        {pos: [3, 11, 13], state: "minecraft:deepslate_tiles"},
        {pos: [3, 11, 14], state: "minecraft:deepslate_tiles"},
        {pos: [3, 11, 15], state: "minecraft:deepslate_tiles"},
        {pos: [3, 11, 16], state: "minecraft:deepslate_tiles"},
        {pos: [4, 11, 1], state: "minecraft:deepslate_tiles"},
        {pos: [4, 11, 2], state: "minecraft:deepslate_tiles"},
        {pos: [4, 11, 3], state: "minecraft:deepslate_tiles"},
        {pos: [4, 11, 4], state: "minecraft:deepslate_tiles"},
        {pos: [4, 11, 5], state: "minecraft:deepslate_tiles"},
        {pos: [4, 11, 6], state: "minecraft:deepslate_tiles"},
        {pos: [4, 11, 7], state: "minecraft:deepslate_tiles"},
        {pos: [4, 11, 8], state: "minecraft:deepslate_tiles"},
        {pos: [4, 11, 9], state: "minecraft:deepslate_tiles"},
        {pos: [4, 11, 10], state: "minecraft:deepslate_tiles"},
        {pos: [4, 11, 11], state: "minecraft:deepslate_tiles"},
        {pos: [4, 11, 12], state: "minecraft:deepslate_tiles"},
        {pos: [4, 11, 13], state: "minecraft:deepslate_tiles"},
        {pos: [4, 11, 14], state: "minecraft:deepslate_tiles"},
        {pos: [4, 11, 15], state: "minecraft:deepslate_tiles"},
        {pos: [4, 11, 16], state: "minecraft:deepslate_tiles"},
        {pos: [5, 11, 2], state: "minecraft:deepslate_tiles"},
        {pos: [5, 11, 5], state: "minecraft:deepslate_tiles"},
        {pos: [5, 11, 12], state: "minecraft:deepslate_tiles"},
        {pos: [5, 11, 15], state: "minecraft:deepslate_tiles"},
        {pos: [6, 11, 2], state: "minecraft:deepslate_tiles"},
        {pos: [6, 11, 5], state: "minecraft:deepslate_tiles"},
        {pos: [6, 11, 12], state: "minecraft:deepslate_tiles"},
        {pos: [6, 11, 15], state: "minecraft:deepslate_tiles"},
        {pos: [7, 11, 2], state: "minecraft:deepslate_tiles"},
        {pos: [7, 11, 5], state: "minecraft:deepslate_tiles"},
        {pos: [7, 11, 12], state: "minecraft:deepslate_tiles"},
        {pos: [7, 11, 15], state: "minecraft:deepslate_tiles"},
        {pos: [8, 11, 2], state: "minecraft:deepslate_tiles"},
        {pos: [8, 11, 5], state: "minecraft:deepslate_tiles"},
        {pos: [8, 11, 12], state: "minecraft:deepslate_tiles"},
        {pos: [8, 11, 15], state: "minecraft:deepslate_tiles"},
        {pos: [9, 11, 2], state: "minecraft:deepslate_tiles"},
        {pos: [9, 11, 5], state: "minecraft:deepslate_tiles"},
        {pos: [9, 11, 12], state: "minecraft:deepslate_tiles"},
        {pos: [9, 11, 15], state: "minecraft:deepslate_tiles"},
        {pos: [10, 11, 2], state: "minecraft:deepslate_tiles"},
        {pos: [10, 11, 5], state: "minecraft:deepslate_tiles"},
        {pos: [10, 11, 12], state: "minecraft:deepslate_tiles"},
        {pos: [10, 11, 15], state: "minecraft:deepslate_tiles"},
        {pos: [11, 11, 2], state: "minecraft:deepslate_tiles"},
        {pos: [11, 11, 5], state: "minecraft:deepslate_tiles"},
        {pos: [11, 11, 12], state: "minecraft:deepslate_tiles"},
        {pos: [11, 11, 15], state: "minecraft:deepslate_tiles"},
        {pos: [12, 11, 2], state: "minecraft:deepslate_tiles"},
        {pos: [12, 11, 5], state: "minecraft:deepslate_tiles"},
        {pos: [12, 11, 12], state: "minecraft:deepslate_tiles"},
        {pos: [12, 11, 15], state: "minecraft:deepslate_tiles"},
        {pos: [13, 11, 2], state: "minecraft:deepslate_tiles"},
        {pos: [13, 11, 5], state: "minecraft:deepslate_tiles"},
        {pos: [13, 11, 12], state: "minecraft:deepslate_tiles"},
        {pos: [13, 11, 15], state: "minecraft:deepslate_tiles"},
        {pos: [14, 11, 1], state: "minecraft:deepslate_tiles"},
        {pos: [14, 11, 2], state: "minecraft:deepslate_tiles"},
        {pos: [14, 11, 3], state: "minecraft:deepslate_tiles"},
        {pos: [14, 11, 4], state: "minecraft:deepslate_tiles"},
        {pos: [14, 11, 5], state: "minecraft:deepslate_tiles"},
        {pos: [14, 11, 6], state: "minecraft:deepslate_tiles"},
        {pos: [14, 11, 7], state: "minecraft:deepslate_tiles"},
        {pos: [14, 11, 8], state: "minecraft:deepslate_tiles"},
        {pos: [14, 11, 9], state: "minecraft:deepslate_tiles"},
        {pos: [14, 11, 10], state: "minecraft:deepslate_tiles"},
        {pos: [14, 11, 11], state: "minecraft:deepslate_tiles"},
        {pos: [14, 11, 12], state: "minecraft:deepslate_tiles"},
        {pos: [14, 11, 13], state: "minecraft:deepslate_tiles"},
        {pos: [14, 11, 14], state: "minecraft:deepslate_tiles"},
        {pos: [14, 11, 15], state: "minecraft:deepslate_tiles"},
        {pos: [14, 11, 16], state: "minecraft:deepslate_tiles"},
        {pos: [15, 11, 1], state: "minecraft:deepslate_tiles"},
        {pos: [15, 11, 2], state: "minecraft:deepslate_tiles"},
        {pos: [15, 11, 3], state: "minecraft:deepslate_tiles"},
        {pos: [15, 11, 4], state: "minecraft:deepslate_tiles"},
        {pos: [15, 11, 5], state: "minecraft:deepslate_tiles"},
        {pos: [15, 11, 6], state: "minecraft:deepslate_tiles"},
        {pos: [15, 11, 7], state: "minecraft:deepslate_tiles"},
        {pos: [15, 11, 8], state: "minecraft:deepslate_tiles"},
        {pos: [15, 11, 9], state: "minecraft:deepslate_tiles"},
        {pos: [15, 11, 10], state: "minecraft:deepslate_tiles"},
        {pos: [15, 11, 11], state: "minecraft:deepslate_tiles"},
        {pos: [15, 11, 12], state: "minecraft:deepslate_tiles"},
        {pos: [15, 11, 13], state: "minecraft:deepslate_tiles"},
        {pos: [15, 11, 14], state: "minecraft:deepslate_tiles"},
        {pos: [15, 11, 15], state: "minecraft:deepslate_tiles"},
        {pos: [15, 11, 16], state: "minecraft:deepslate_tiles"},
        {pos: [4, 12, 1], state: "minecraft:deepslate_tile_stairs{facing:east,half:bottom,shape:straight,waterlogged:false}"},
        {pos: [4, 12, 2], state: "minecraft:deepslate_tile_stairs{facing:east,half:bottom,shape:straight,waterlogged:false}"},
        {pos: [4, 12, 3], state: "minecraft:deepslate_tile_stairs{facing:east,half:bottom,shape:straight,waterlogged:false}"},
        {pos: [4, 12, 4], state: "minecraft:deepslate_tile_stairs{facing:east,half:bottom,shape:straight,waterlogged:false}"},
        {pos: [4, 12, 5], state: "minecraft:deepslate_tile_stairs{facing:east,half:bottom,shape:straight,waterlogged:false}"},
        {pos: [4, 12, 6], state: "minecraft:deepslate_tile_stairs{facing:east,half:bottom,shape:straight,waterlogged:false}"},
        {pos: [4, 12, 7], state: "minecraft:deepslate_tile_stairs{facing:east,half:bottom,shape:straight,waterlogged:false}"},
        {pos: [4, 12, 8], state: "minecraft:deepslate_tile_stairs{facing:east,half:bottom,shape:straight,waterlogged:false}"},
        {pos: [4, 12, 9], state: "minecraft:deepslate_tile_stairs{facing:east,half:bottom,shape:straight,waterlogged:false}"},
        {pos: [4, 12, 10], state: "minecraft:deepslate_tile_stairs{facing:east,half:bottom,shape:straight,waterlogged:false}"},
        {pos: [4, 12, 11], state: "minecraft:deepslate_tile_stairs{facing:east,half:bottom,shape:straight,waterlogged:false}"},
        {pos: [4, 12, 12], state: "minecraft:deepslate_tile_stairs{facing:east,half:bottom,shape:straight,waterlogged:false}"},
        {pos: [4, 12, 13], state: "minecraft:deepslate_tile_stairs{facing:east,half:bottom,shape:straight,waterlogged:false}"},
        {pos: [4, 12, 14], state: "minecraft:deepslate_tile_stairs{facing:east,half:bottom,shape:straight,waterlogged:false}"},
        {pos: [4, 12, 15], state: "minecraft:deepslate_tile_stairs{facing:east,half:bottom,shape:straight,waterlogged:false}"},
        {pos: [4, 12, 16], state: "minecraft:deepslate_tile_stairs{facing:east,half:bottom,shape:straight,waterlogged:false}"},
        {pos: [5, 12, 1], state: "minecraft:deepslate_tiles"},
        {pos: [5, 12, 2], state: "minecraft:deepslate_tiles"},
        {pos: [5, 12, 3], state: "minecraft:deepslate_tiles"},
        {pos: [5, 12, 4], state: "minecraft:deepslate_tiles"},
        {pos: [5, 12, 5], state: "minecraft:deepslate_tiles"},
        {pos: [5, 12, 6], state: "minecraft:deepslate_tiles"},
        {pos: [5, 12, 7], state: "minecraft:deepslate_tiles"},
        {pos: [5, 12, 8], state: "minecraft:deepslate_tiles"},
        {pos: [5, 12, 9], state: "minecraft:deepslate_tiles"},
        {pos: [5, 12, 10], state: "minecraft:deepslate_tiles"},
        {pos: [5, 12, 11], state: "minecraft:deepslate_tiles"},
        {pos: [5, 12, 12], state: "minecraft:deepslate_tiles"},
        {pos: [5, 12, 13], state: "minecraft:deepslate_tiles"},
        {pos: [5, 12, 14], state: "minecraft:deepslate_tiles"},
        {pos: [5, 12, 15], state: "minecraft:deepslate_tiles"},
        {pos: [5, 12, 16], state: "minecraft:deepslate_tiles"},
        {pos: [6, 12, 1], state: "minecraft:deepslate_tiles"},
        {pos: [6, 12, 2], state: "minecraft:deepslate_tiles"},
        {pos: [6, 12, 3], state: "minecraft:deepslate_tiles"},
        {pos: [6, 12, 4], state: "minecraft:deepslate_tiles"},
        {pos: [6, 12, 5], state: "minecraft:deepslate_tiles"},
        {pos: [6, 12, 6], state: "minecraft:deepslate_tiles"},
        {pos: [6, 12, 7], state: "minecraft:deepslate_tiles"},
        {pos: [6, 12, 8], state: "minecraft:deepslate_tiles"},
        {pos: [6, 12, 9], state: "minecraft:deepslate_tiles"},
        {pos: [6, 12, 10], state: "minecraft:deepslate_tiles"},
        {pos: [6, 12, 11], state: "minecraft:deepslate_tiles"},
        {pos: [6, 12, 12], state: "minecraft:deepslate_tiles"},
        {pos: [6, 12, 13], state: "minecraft:deepslate_tiles"},
        {pos: [6, 12, 14], state: "minecraft:deepslate_tiles"},
        {pos: [6, 12, 15], state: "minecraft:deepslate_tiles"},
        {pos: [6, 12, 16], state: "minecraft:deepslate_tiles"},
        {pos: [7, 12, 1], state: "minecraft:deepslate_tiles"},
        {pos: [7, 12, 2], state: "minecraft:deepslate_tiles"},
        {pos: [7, 12, 3], state: "minecraft:deepslate_tiles"},
        {pos: [7, 12, 4], state: "minecraft:deepslate_tiles"},
        {pos: [7, 12, 5], state: "minecraft:deepslate_tiles"},
        {pos: [7, 12, 6], state: "minecraft:deepslate_tiles"},
        {pos: [7, 12, 7], state: "minecraft:deepslate_tiles"},
        {pos: [7, 12, 8], state: "minecraft:deepslate_tiles"},
        {pos: [7, 12, 9], state: "minecraft:deepslate_tiles"},
        {pos: [7, 12, 10], state: "minecraft:deepslate_tiles"},
        {pos: [7, 12, 11], state: "minecraft:deepslate_tiles"},
        {pos: [7, 12, 12], state: "minecraft:deepslate_tiles"},
        {pos: [7, 12, 13], state: "minecraft:deepslate_tiles"},
        {pos: [7, 12, 14], state: "minecraft:deepslate_tiles"},
        {pos: [7, 12, 15], state: "minecraft:deepslate_tiles"},
        {pos: [7, 12, 16], state: "minecraft:deepslate_tiles"},
        {pos: [8, 12, 1], state: "minecraft:deepslate_tiles"},
        {pos: [8, 12, 2], state: "minecraft:deepslate_tiles"},
        {pos: [8, 12, 3], state: "minecraft:deepslate_tiles"},
        {pos: [8, 12, 4], state: "minecraft:deepslate_tiles"},
        {pos: [8, 12, 5], state: "minecraft:deepslate_tiles"},
        {pos: [8, 12, 6], state: "minecraft:deepslate_tiles"},
        {pos: [8, 12, 7], state: "minecraft:deepslate_tiles"},
        {pos: [8, 12, 8], state: "minecraft:deepslate_tiles"},
        {pos: [8, 12, 9], state: "minecraft:deepslate_tiles"},
        {pos: [8, 12, 10], state: "minecraft:deepslate_tiles"},
        {pos: [8, 12, 11], state: "minecraft:deepslate_tiles"},
        {pos: [8, 12, 12], state: "minecraft:deepslate_tiles"},
        {pos: [8, 12, 13], state: "minecraft:deepslate_tiles"},
        {pos: [8, 12, 14], state: "minecraft:deepslate_tiles"},
        {pos: [8, 12, 15], state: "minecraft:deepslate_tiles"},
        {pos: [8, 12, 16], state: "minecraft:deepslate_tiles"},
        {pos: [9, 12, 1], state: "minecraft:deepslate_tiles"},
        {pos: [9, 12, 2], state: "minecraft:deepslate_tiles"},
        {pos: [9, 12, 3], state: "minecraft:deepslate_tiles"},
        {pos: [9, 12, 4], state: "minecraft:deepslate_tiles"},
        {pos: [9, 12, 5], state: "minecraft:deepslate_tiles"},
        {pos: [9, 12, 6], state: "minecraft:deepslate_tiles"},
        {pos: [9, 12, 7], state: "minecraft:deepslate_tiles"},
        {pos: [9, 12, 8], state: "minecraft:deepslate_tiles"},
        {pos: [9, 12, 9], state: "minecraft:deepslate_tiles"},
        {pos: [9, 12, 10], state: "minecraft:deepslate_tiles"},
        {pos: [9, 12, 11], state: "minecraft:deepslate_tiles"},
        {pos: [9, 12, 12], state: "minecraft:deepslate_tiles"},
        {pos: [9, 12, 13], state: "minecraft:deepslate_tiles"},
        {pos: [9, 12, 14], state: "minecraft:deepslate_tiles"},
        {pos: [9, 12, 15], state: "minecraft:deepslate_tiles"},
        {pos: [9, 12, 16], state: "minecraft:deepslate_tiles"},
        {pos: [10, 12, 1], state: "minecraft:deepslate_tiles"},
        {pos: [10, 12, 2], state: "minecraft:deepslate_tiles"},
        {pos: [10, 12, 3], state: "minecraft:deepslate_tiles"},
        {pos: [10, 12, 4], state: "minecraft:deepslate_tiles"},
        {pos: [10, 12, 5], state: "minecraft:deepslate_tiles"},
        {pos: [10, 12, 6], state: "minecraft:deepslate_tiles"},
        {pos: [10, 12, 7], state: "minecraft:deepslate_tiles"},
        {pos: [10, 12, 8], state: "minecraft:deepslate_tiles"},
        {pos: [10, 12, 9], state: "minecraft:deepslate_tiles"},
        {pos: [10, 12, 10], state: "minecraft:deepslate_tiles"},
        {pos: [10, 12, 11], state: "minecraft:deepslate_tiles"},
        {pos: [10, 12, 12], state: "minecraft:deepslate_tiles"},
        {pos: [10, 12, 13], state: "minecraft:deepslate_tiles"},
        {pos: [10, 12, 14], state: "minecraft:deepslate_tiles"},
        {pos: [10, 12, 15], state: "minecraft:deepslate_tiles"},
        {pos: [10, 12, 16], state: "minecraft:deepslate_tiles"},
        {pos: [11, 12, 1], state: "minecraft:deepslate_tiles"},
        {pos: [11, 12, 2], state: "minecraft:deepslate_tiles"},
        {pos: [11, 12, 3], state: "minecraft:deepslate_tiles"},
        {pos: [11, 12, 4], state: "minecraft:deepslate_tiles"},
        {pos: [11, 12, 5], state: "minecraft:deepslate_tiles"},
        {pos: [11, 12, 6], state: "minecraft:deepslate_tiles"},
        {pos: [11, 12, 7], state: "minecraft:deepslate_tiles"},
        {pos: [11, 12, 8], state: "minecraft:deepslate_tiles"},
        {pos: [11, 12, 9], state: "minecraft:deepslate_tiles"},
        {pos: [11, 12, 10], state: "minecraft:deepslate_tiles"},
        {pos: [11, 12, 11], state: "minecraft:deepslate_tiles"},
        {pos: [11, 12, 12], state: "minecraft:deepslate_tiles"},
        {pos: [11, 12, 13], state: "minecraft:deepslate_tiles"},
        {pos: [11, 12, 14], state: "minecraft:deepslate_tiles"},
        {pos: [11, 12, 15], state: "minecraft:deepslate_tiles"},
        {pos: [11, 12, 16], state: "minecraft:deepslate_tiles"},
        {pos: [12, 12, 1], state: "minecraft:deepslate_tiles"},
        {pos: [12, 12, 2], state: "minecraft:deepslate_tiles"},
        {pos: [12, 12, 3], state: "minecraft:deepslate_tiles"},
        {pos: [12, 12, 4], state: "minecraft:deepslate_tiles"},
        {pos: [12, 12, 5], state: "minecraft:deepslate_tiles"},
        {pos: [12, 12, 6], state: "minecraft:deepslate_tiles"},
        {pos: [12, 12, 7], state: "minecraft:deepslate_tiles"},
        {pos: [12, 12, 8], state: "minecraft:deepslate_tiles"},
        {pos: [12, 12, 9], state: "minecraft:deepslate_tiles"},
        {pos: [12, 12, 10], state: "minecraft:deepslate_tiles"},
        {pos: [12, 12, 11], state: "minecraft:deepslate_tiles"},
        {pos: [12, 12, 12], state: "minecraft:deepslate_tiles"},
        {pos: [12, 12, 13], state: "minecraft:deepslate_tiles"},
        {pos: [12, 12, 14], state: "minecraft:deepslate_tiles"},
        {pos: [12, 12, 15], state: "minecraft:deepslate_tiles"},
        {pos: [12, 12, 16], state: "minecraft:deepslate_tiles"},
        {pos: [13, 12, 1], state: "minecraft:deepslate_tiles"},
        {pos: [13, 12, 2], state: "minecraft:deepslate_tiles"},
        {pos: [13, 12, 3], state: "minecraft:deepslate_tiles"},
        {pos: [13, 12, 4], state: "minecraft:deepslate_tiles"},
        {pos: [13, 12, 5], state: "minecraft:deepslate_tiles"},
        {pos: [13, 12, 6], state: "minecraft:deepslate_tiles"},
        {pos: [13, 12, 7], state: "minecraft:deepslate_tiles"},
        {pos: [13, 12, 8], state: "minecraft:deepslate_tiles"},
        {pos: [13, 12, 9], state: "minecraft:deepslate_tiles"},
        {pos: [13, 12, 10], state: "minecraft:deepslate_tiles"},
        {pos: [13, 12, 11], state: "minecraft:deepslate_tiles"},
        {pos: [13, 12, 12], state: "minecraft:deepslate_tiles"},
        {pos: [13, 12, 13], state: "minecraft:deepslate_tiles"},
        {pos: [13, 12, 14], state: "minecraft:deepslate_tiles"},
        {pos: [13, 12, 15], state: "minecraft:deepslate_tiles"},
        {pos: [13, 12, 16], state: "minecraft:deepslate_tiles"},
        {pos: [14, 12, 1], state: "minecraft:deepslate_tile_stairs{facing:west,half:bottom,shape:straight,waterlogged:false}"},
        {pos: [14, 12, 2], state: "minecraft:deepslate_tile_stairs{facing:west,half:bottom,shape:straight,waterlogged:false}"},
        {pos: [14, 12, 3], state: "minecraft:deepslate_tile_stairs{facing:west,half:bottom,shape:straight,waterlogged:false}"},
        {pos: [14, 12, 4], state: "minecraft:deepslate_tile_stairs{facing:west,half:bottom,shape:straight,waterlogged:false}"},
        {pos: [14, 12, 5], state: "minecraft:deepslate_tile_stairs{facing:west,half:bottom,shape:straight,waterlogged:false}"},
        {pos: [14, 12, 6], state: "minecraft:deepslate_tile_stairs{facing:west,half:bottom,shape:straight,waterlogged:false}"},
        {pos: [14, 12, 7], state: "minecraft:deepslate_tile_stairs{facing:west,half:bottom,shape:straight,waterlogged:false}"},
        {pos: [14, 12, 8], state: "minecraft:deepslate_tile_stairs{facing:west,half:bottom,shape:straight,waterlogged:false}"},
        {pos: [14, 12, 9], state: "minecraft:deepslate_tile_stairs{facing:west,half:bottom,shape:straight,waterlogged:false}"},
        {pos: [14, 12, 10], state: "minecraft:deepslate_tile_stairs{facing:west,half:bottom,shape:straight,waterlogged:false}"},
        {pos: [14, 12, 11], state: "minecraft:deepslate_tile_stairs{facing:west,half:bottom,shape:straight,waterlogged:false}"},
        {pos: [14, 12, 12], state: "minecraft:deepslate_tile_stairs{facing:west,half:bottom,shape:straight,waterlogged:false}"},
        {pos: [14, 12, 13], state: "minecraft:deepslate_tile_stairs{facing:west,half:bottom,shape:straight,waterlogged:false}"},
        {pos: [14, 12, 14], state: "minecraft:deepslate_tile_stairs{facing:west,half:bottom,shape:straight,waterlogged:false}"},
        {pos: [14, 12, 15], state: "minecraft:deepslate_tile_stairs{facing:west,half:bottom,shape:straight,waterlogged:false}"},
        {pos: [14, 12, 16], state: "minecraft:deepslate_tile_stairs{facing:west,half:bottom,shape:straight,waterlogged:false}"}
    ],
    entities: [],
    palette: [
        "minecraft:deepslate_tiles",
        "minecraft:deepslate_bricks",
        "minecraft:deepslate_tile_stairs{facing:east,half:bottom,shape:straight,waterlogged:false}",
        "minecraft:deepslate_tile_stairs{facing:south,half:bottom,shape:straight,waterlogged:false}",
        "minecraft:deepslate_tile_stairs{facing:north,half:bottom,shape:straight,waterlogged:false}",
        "minecraft:deepslate_tile_stairs{facing:west,half:bottom,shape:straight,waterlogged:false}",
        "minecraft:gray_carpet",
        "minecraft:deepslate_tile_wall{east:none,north:none,south:low,up:true,waterlogged:false,west:none}",
        "minecraft:deepslate_tile_wall{east:none,north:low,south:low,up:false,waterlogged:false,west:none}",
        "minecraft:deepslate_tile_wall{east:tall,north:low,south:none,up:true,waterlogged:false,west:none}",
        "minecraft:deepslate_tile_wall{east:tall,north:none,south:none,up:false,waterlogged:false,west:tall}",
        "minecraft:deepslate_tile_wall{east:none,north:low,south:none,up:true,waterlogged:false,west:tall}",
        "minecraft:deepslate_tile_wall{east:tall,north:none,south:none,up:true,waterlogged:false,west:none}",
        "minecraft:deepslate_tile_wall{east:low,north:none,south:none,up:false,waterlogged:false,west:low}",
        "minecraft:deepslate_tile_wall{east:none,north:none,south:low,up:true,waterlogged:false,west:low}",
        "minecraft:deepslate_tile_wall{east:none,north:low,south:none,up:true,waterlogged:false,west:low}",
        "minecraft:soul_lantern{hanging:false,waterlogged:false}",
        "minecraft:deepslate_tile_wall{east:none,north:none,south:none,up:true,waterlogged:false,west:tall}",
        "minecraft:deepslate_tile_wall{east:low,north:none,south:none,up:true,waterlogged:false,west:none}",
        "minecraft:deepslate_tile_wall{east:none,north:none,south:none,up:true,waterlogged:false,west:low}",
        "minecraft:jigsaw{orientation:north_up}",
        "minecraft:chest{facing:north,type:single,waterlogged:false}",
        "minecraft:chest{facing:west,type:single,waterlogged:false}"
    ]
}
