{
    size: [21, 15, 21],
    data: [
        {pos: [7, 0, 7], state: "minecraft:deepslate_tiles"},
        {pos: [7, 0, 8], state: "minecraft:deepslate_tiles"},
        {pos: [7, 0, 9], state: "minecraft:deepslate_tiles"},
        {pos: [7, 0, 10], state: "minecraft:deepslate_tiles"},
        {pos: [7, 0, 11], state: "minecraft:deepslate_tiles"},
        {pos: [7, 0, 12], state: "minecraft:deepslate_tiles"},
        {pos: [7, 0, 13], state: "minecraft:deepslate_tiles"},
        {pos: [7, 0, 14], state: "minecraft:deepslate_tiles"},
        {pos: [7, 0, 15], state: "minecraft:deepslate_tiles"},
        {pos: [7, 0, 16], state: "minecraft:deepslate_tiles"},
        {pos: [7, 0, 17], state: "minecraft:deepslate_tiles"},
        {pos: [7, 0, 18], state: "minecraft:deepslate_tiles"},
        {pos: [7, 0, 19], state: "minecraft:deepslate_tiles"},
        {pos: [7, 0, 20], state: "minecraft:deepslate_tiles"},
        {pos: [8, 0, 7], state: "minecraft:deepslate_tiles"},
        {pos: [8, 0, 8], state: "minecraft:gray_wool"},
        {pos: [8, 0, 9], state: "minecraft:gray_wool"},
        {pos: [8, 0, 10], state: "minecraft:gray_wool"},
        {pos: [8, 0, 11], state: "minecraft:gray_wool"},
        {pos: [8, 0, 12], state: "minecraft:gray_wool"},
        {pos: [8, 0, 13], state: "minecraft:gray_wool"},
        {pos: [8, 0, 14], state: "minecraft:gray_wool"},
        {pos: [8, 0, 15], state: "minecraft:gray_wool"},
        {pos: [8, 0, 16], state: "minecraft:gray_wool"},
        {pos: [8, 0, 17], state: "minecraft:gray_wool"},
        {pos: [8, 0, 18], state: "minecraft:gray_wool"},
        {pos: [8, 0, 19], state: "minecraft:gray_wool"},
        {pos: [8, 0, 20], state: "minecraft:gray_wool"},
        {pos: [9, 0, 7], state: "minecraft:deepslate_tiles"},
        {pos: [9, 0, 8], state: "minecraft:gray_wool"},
        {pos: [9, 0, 9], state: "minecraft:gray_wool"},
        {pos: [9, 0, 10], state: "minecraft:gray_wool"},
        {pos: [9, 0, 11], state: "minecraft:gray_wool"},
        {pos: [9, 0, 12], state: "minecraft:gray_wool"},
        {pos: [9, 0, 13], state: "minecraft:gray_wool"},
        {pos: [9, 0, 14], state: "minecraft:gray_wool"},
        {pos: [9, 0, 15], state: "minecraft:gray_wool"},
        {pos: [9, 0, 16], state: "minecraft:gray_wool"},
        {pos: [9, 0, 17], state: "minecraft:gray_wool"},
        {pos: [9, 0, 18], state: "minecraft:gray_wool"},
        {pos: [9, 0, 19], state: "minecraft:gray_wool"},
        {pos: [9, 0, 20], state: "minecraft:gray_wool"},
        {pos: [10, 0, 7], state: "minecraft:deepslate_tiles"},
        {pos: [10, 0, 8], state: "minecraft:gray_wool"},
        {pos: [10, 0, 9], state: "minecraft:gray_wool"},
        {pos: [10, 0, 10], state: "minecraft:deepslate_tiles"},
        {pos: [10, 0, 11], state: "minecraft:gray_wool"},
        {pos: [10, 0, 12], state: "minecraft:gray_wool"},
        {pos: [10, 0, 13], state: "minecraft:deepslate_tiles"},
        {pos: [10, 0, 14], state: "minecraft:deepslate_tiles"},
        {pos: [10, 0, 15], state: "minecraft:deepslate_tiles"},
        {pos: [10, 0, 16], state: "minecraft:deepslate_tiles"},
        {pos: [10, 0, 17], state: "minecraft:deepslate_tiles"},
        {pos: [10, 0, 18], state: "minecraft:deepslate_tiles"},
        {pos: [10, 0, 19], state: "minecraft:deepslate_tiles"},
        {pos: [10, 0, 20], state: "minecraft:jigsaw{orientation:south_up}", nbt: {final_state: "minecraft:deepslate_tiles", id: "minecraft:jigsaw", joint: "rollable", name: "minecraft:connect_wall", pool: "minecraft:ancient_city/walls/no_corners", target: "minecraft:connect_wall"}},
        {pos: [11, 0, 7], state: "minecraft:deepslate_tiles"},
        {pos: [11, 0, 8], state: "minecraft:gray_wool"},
        {pos: [11, 0, 9], state: "minecraft:gray_wool"},
        {pos: [11, 0, 10], state: "minecraft:gray_wool"},
        {pos: [11, 0, 11], state: "minecraft:gray_wool"},
        {pos: [11, 0, 12], state: "minecraft:gray_wool"},
        {pos: [11, 0, 13], state: "minecraft:gray_wool"},
        {pos: [11, 0, 14], state: "minecraft:gray_wool"},
        {pos: [11, 0, 15], state: "minecraft:gray_wool"},
        {pos: [11, 0, 16], state: "minecraft:gray_wool"},
        {pos: [11, 0, 17], state: "minecraft:gray_wool"},
        {pos: [11, 0, 18], state: "minecraft:gray_wool"},
        {pos: [11, 0, 19], state: "minecraft:gray_wool"},
        {pos: [11, 0, 20], state: "minecraft:gray_wool"},
        {pos: [12, 0, 7], state: "minecraft:deepslate_tiles"},
        {pos: [12, 0, 8], state: "minecraft:gray_wool"},
        {pos: [12, 0, 9], state: "minecraft:gray_wool"},
        {pos: [12, 0, 10], state: "minecraft:gray_wool"},
        {pos: [12, 0, 11], state: "minecraft:gray_wool"},
        {pos: [12, 0, 12], state: "minecraft:gray_wool"},
        {pos: [12, 0, 13], state: "minecraft:gray_wool"},
        {pos: [12, 0, 14], state: "minecraft:gray_wool"},
        {pos: [12, 0, 15], state: "minecraft:gray_wool"},
        {pos: [12, 0, 16], state: "minecraft:gray_wool"},
        {pos: [12, 0, 17], state: "minecraft:gray_wool"},
        {pos: [12, 0, 18], state: "minecraft:gray_wool"},
        {pos: [12, 0, 19], state: "minecraft:gray_wool"},
        {pos: [12, 0, 20], state: "minecraft:gray_wool"},
        {pos: [13, 0, 7], state: "minecraft:deepslate_tiles"},
        {pos: [13, 0, 8], state: "minecraft:gray_wool"},
        {pos: [13, 0, 9], state: "minecraft:gray_wool"},
        {pos: [13, 0, 10], state: "minecraft:deepslate_tiles"},
        {pos: [13, 0, 11], state: "minecraft:gray_wool"},
        {pos: [13, 0, 12], state: "minecraft:gray_wool"},
        {pos: [13, 0, 13], state: "minecraft:deepslate_tiles"},
        {pos: [13, 0, 14], state: "minecraft:deepslate_tiles"},
        {pos: [13, 0, 15], state: "minecraft:deepslate_tiles"},
        {pos: [13, 0, 16], state: "minecraft:deepslate_tiles"},
        {pos: [13, 0, 17], state: "minecraft:deepslate_tiles"},
        {pos: [13, 0, 18], state: "minecraft:deepslate_tiles"},
        {pos: [13, 0, 19], state: "minecraft:deepslate_tiles"},
        {pos: [13, 0, 20], state: "minecraft:deepslate_tiles"},
        {pos: [14, 0, 7], state: "minecraft:deepslate_tiles"},
        {pos: [14, 0, 8], state: "minecraft:gray_wool"},
        {pos: [14, 0, 9], state: "minecraft:gray_wool"},
        {pos: [14, 0, 10], state: "minecraft:deepslate_tiles"},
        {pos: [14, 0, 11], state: "minecraft:gray_wool"},
        {pos: [14, 0, 12], state: "minecraft:gray_wool"},
        {pos: [14, 0, 13], state: "minecraft:deepslate_tiles"},
        {pos: [15, 0, 7], state: "minecraft:deepslate_tiles"},
        {pos: [15, 0, 8], state: "minecraft:gray_wool"},
        {pos: [15, 0, 9], state: "minecraft:gray_wool"},
        {pos: [15, 0, 10], state: "minecraft:deepslate_tiles"},
        {pos: [15, 0, 11], state: "minecraft:gray_wool"},
        {pos: [15, 0, 12], state: "minecraft:gray_wool"},
        {pos: [15, 0, 13], state: "minecraft:deepslate_tiles"},
        {pos: [16, 0, 7], state: "minecraft:deepslate_tiles"},
        {pos: [16, 0, 8], state: "minecraft:gray_wool"},
        {pos: [16, 0, 9], state: "minecraft:gray_wool"},
        {pos: [16, 0, 10], state: "minecraft:deepslate_tiles"},
        {pos: [16, 0, 11], state: "minecraft:gray_wool"},
        {pos: [16, 0, 12], state: "minecraft:gray_wool"},
        {pos: [16, 0, 13], state: "minecraft:deepslate_tiles"},
        {pos: [17, 0, 7], state: "minecraft:deepslate_tiles"},
        {pos: [17, 0, 8], state: "minecraft:gray_wool"},
        {pos: [17, 0, 9], state: "minecraft:gray_wool"},
        {pos: [17, 0, 10], state: "minecraft:deepslate_tiles"},
        {pos: [17, 0, 11], state: "minecraft:gray_wool"},
        {pos: [17, 0, 12], state: "minecraft:gray_wool"},
        {pos: [17, 0, 13], state: "minecraft:deepslate_tiles"},
        {pos: [18, 0, 7], state: "minecraft:deepslate_tiles"},
        {pos: [18, 0, 8], state: "minecraft:gray_wool"},
        {pos: [18, 0, 9], state: "minecraft:gray_wool"},
        {pos: [18, 0, 10], state: "minecraft:deepslate_tiles"},
        {pos: [18, 0, 11], state: "minecraft:gray_wool"},
        {pos: [18, 0, 12], state: "minecraft:gray_wool"},
        {pos: [18, 0, 13], state: "minecraft:deepslate_tiles"},
        {pos: [19, 0, 7], state: "minecraft:deepslate_tiles"},
        {pos: [19, 0, 8], state: "minecraft:gray_wool"},
        {pos: [19, 0, 9], state: "minecraft:gray_wool"},
        {pos: [19, 0, 10], state: "minecraft:deepslate_tiles"},
        {pos: [19, 0, 11], state: "minecraft:gray_wool"},
        {pos: [19, 0, 12], state: "minecraft:gray_wool"},
        {pos: [19, 0, 13], state: "minecraft:deepslate_tiles"},
        {pos: [20, 0, 7], state: "minecraft:deepslate_tiles"},
        {pos: [20, 0, 8], state: "minecraft:gray_wool"},
        {pos: [20, 0, 9], state: "minecraft:gray_wool"},
        {pos: [20, 0, 10], state: "minecraft:jigsaw{orientation:east_up}", nbt: {final_state: "minecraft:deepslate_tiles", id: "minecraft:jigsaw", joint: "rollable", name: "minecraft:connect_wall", pool: "minecraft:ancient_city/walls/no_corners", target: "minecraft:connect_wall"}},
        {pos: [20, 0, 11], state: "minecraft:gray_wool"},
        {pos: [20, 0, 12], state: "minecraft:gray_wool"},
        {pos: [20, 0, 13], state: "minecraft:deepslate_tiles"},
        {pos: [7, 1, 7], state: "minecraft:deepslate_bricks"},
        {pos: [7, 1, 8], state: "minecraft:deepslate_bricks"},
        {pos: [7, 1, 9], state: "minecraft:deepslate_bricks"},
        {pos: [7, 1, 11], state: "minecraft:deepslate_bricks"},
        {pos: [7, 1, 12], state: "minecraft:deepslate_bricks"},
        {pos: [7, 1, 13], state: "minecraft:deepslate_bricks"},
        {pos: [7, 1, 15], state: "minecraft:deepslate_bricks"},
        {pos: [7, 1, 16], state: "minecraft:deepslate_bricks"},
        {pos: [7, 1, 17], state: "minecraft:deepslate_bricks"},
        {pos: [7, 1, 19], state: "minecraft:deepslate_bricks"},
        {pos: [7, 1, 20], state: "minecraft:deepslate_bricks"},
        {pos: [8, 1, 7], state: "minecraft:deepslate_bricks"},
        {pos: [8, 1, 8], state: "minecraft:gray_wool"},
        {pos: [8, 1, 9], state: "minecraft:gray_wool"},
        {pos: [8, 1, 10], state: "minecraft:gray_wool"},
        {pos: [8, 1, 11], state: "minecraft:gray_wool"},
        {pos: [8, 1, 12], state: "minecraft:gray_wool"},
        {pos: [8, 1, 13], state: "minecraft:gray_wool"},
        {pos: [8, 1, 14], state: "minecraft:gray_wool"},
        {pos: [8, 1, 15], state: "minecraft:gray_wool"},
        {pos: [8, 1, 16], state: "minecraft:gray_wool"},
        {pos: [8, 1, 17], state: "minecraft:gray_wool"},
        {pos: [8, 1, 18], state: "minecraft:gray_wool"},
        {pos: [8, 1, 19], state: "minecraft:gray_wool"},
        {pos: [8, 1, 20], state: "minecraft:gray_wool"},
        {pos: [9, 1, 7], state: "minecraft:deepslate_bricks"},
        {pos: [9, 1, 8], state: "minecraft:gray_wool"},
        {pos: [9, 1, 9], state: "minecraft:gray_wool"},
        {pos: [9, 1, 10], state: "minecraft:gray_wool"},
        {pos: [9, 1, 11], state: "minecraft:gray_wool"},
        {pos: [9, 1, 12], state: "minecraft:gray_wool"},
        {pos: [9, 1, 13], state: "minecraft:gray_wool"},
        {pos: [9, 1, 14], state: "minecraft:gray_wool"},
        {pos: [9, 1, 15], state: "minecraft:gray_wool"},
        {pos: [9, 1, 16], state: "minecraft:gray_wool"},
        {pos: [9, 1, 17], state: "minecraft:gray_wool"},
        {pos: [9, 1, 18], state: "minecraft:gray_wool"},
        {pos: [9, 1, 19], state: "minecraft:gray_wool"},
        {pos: [9, 1, 20], state: "minecraft:gray_wool"},
        {pos: [10, 1, 8], state: "minecraft:gray_wool"},
        {pos: [10, 1, 9], state: "minecraft:gray_wool"},
        {pos: [10, 1, 10], state: "minecraft:deepslate_bricks"},
        {pos: [10, 1, 11], state: "minecraft:gray_wool"},
        {pos: [10, 1, 12], state: "minecraft:gray_wool"},
        {pos: [10, 1, 13], state: "minecraft:deepslate_bricks"},
        {pos: [10, 1, 14], state: "minecraft:deepslate_bricks"},
        {pos: [10, 1, 15], state: "minecraft:deepslate_bricks"},
        {pos: [10, 1, 16], state: "minecraft:deepslate_bricks"},
        {pos: [10, 1, 17], state: "minecraft:deepslate_bricks"},
        {pos: [10, 1, 18], state: "minecraft:deepslate_bricks"},
        {pos: [10, 1, 19], state: "minecraft:deepslate_bricks"},
        {pos: [10, 1, 20], state: "minecraft:deepslate_bricks"},
        {pos: [11, 1, 7], state: "minecraft:deepslate_bricks"},
        {pos: [11, 1, 8], state: "minecraft:gray_wool"},
        {pos: [11, 1, 9], state: "minecraft:gray_wool"},
        {pos: [11, 1, 10], state: "minecraft:gray_wool"},
        {pos: [11, 1, 11], state: "minecraft:gray_wool"},
        {pos: [11, 1, 12], state: "minecraft:gray_wool"},
        {pos: [11, 1, 13], state: "minecraft:gray_wool"},
        {pos: [11, 1, 14], state: "minecraft:gray_wool"},
        {pos: [11, 1, 15], state: "minecraft:gray_wool"},
        {pos: [11, 1, 16], state: "minecraft:gray_wool"},
        {pos: [11, 1, 17], state: "minecraft:gray_wool"},
        {pos: [11, 1, 18], state: "minecraft:gray_wool"},
        {pos: [11, 1, 19], state: "minecraft:gray_wool"},
        {pos: [11, 1, 20], state: "minecraft:gray_wool"},
        {pos: [12, 1, 7], state: "minecraft:deepslate_bricks"},
        {pos: [12, 1, 8], state: "minecraft:gray_wool"},
        {pos: [12, 1, 9], state: "minecraft:gray_wool"},
        {pos: [12, 1, 10], state: "minecraft:gray_wool"},
        {pos: [12, 1, 11], state: "minecraft:gray_wool"},
        {pos: [12, 1, 12], state: "minecraft:gray_wool"},
        {pos: [12, 1, 13], state: "minecraft:gray_wool"},
        {pos: [12, 1, 14], state: "minecraft:gray_wool"},
        {pos: [12, 1, 15], state: "minecraft:gray_wool"},
        {pos: [12, 1, 16], state: "minecraft:gray_wool"},
        {pos: [12, 1, 17], state: "minecraft:gray_wool"},
        {pos: [12, 1, 18], state: "minecraft:gray_wool"},
        {pos: [12, 1, 19], state: "minecraft:gray_wool"},
        {pos: [12, 1, 20], state: "minecraft:gray_wool"},
        {pos: [13, 1, 7], state: "minecraft:deepslate_bricks"},
        {pos: [13, 1, 8], state: "minecraft:gray_wool"},
        {pos: [13, 1, 9], state: "minecraft:gray_wool"},
        {pos: [13, 1, 10], state: "minecraft:deepslate_bricks"},
        {pos: [13, 1, 11], state: "minecraft:gray_wool"},
        {pos: [13, 1, 12], state: "minecraft:gray_wool"},
        {pos: [13, 1, 13], state: "minecraft:deepslate_bricks"},
        {pos: [13, 1, 15], state: "minecraft:deepslate_bricks"},
        {pos: [13, 1, 16], state: "minecraft:deepslate_bricks"},
        {pos: [13, 1, 17], state: "minecraft:deepslate_bricks"},
        {pos: [13, 1, 19], state: "minecraft:deepslate_bricks"},
        {pos: [13, 1, 20], state: "minecraft:deepslate_bricks"},
        {pos: [14, 1, 8], state: "minecraft:gray_wool"},
        {pos: [14, 1, 9], state: "minecraft:gray_wool"},
        {pos: [14, 1, 10], state: "minecraft:deepslate_bricks"},
        {pos: [14, 1, 11], state: "minecraft:gray_wool"},
        {pos: [14, 1, 12], state: "minecraft:gray_wool"},
        {pos: [15, 1, 7], state: "minecraft:deepslate_bricks"},
        {pos: [15, 1, 8], state: "minecraft:gray_wool"},
        {pos: [15, 1, 9], state: "minecraft:gray_wool"},
        {pos: [15, 1, 10], state: "minecraft:deepslate_bricks"},
        {pos: [15, 1, 11], state: "minecraft:gray_wool"},
        {pos: [15, 1, 12], state: "minecraft:gray_wool"},
        {pos: [15, 1, 13], state: "minecraft:deepslate_bricks"},
        {pos: [16, 1, 7], state: "minecraft:deepslate_bricks"},
        {pos: [16, 1, 8], state: "minecraft:gray_wool"},
        {pos: [16, 1, 9], state: "minecraft:gray_wool"},
        {pos: [16, 1, 10], state: "minecraft:deepslate_bricks"},
        {pos: [16, 1, 11], state: "minecraft:gray_wool"},
        {pos: [16, 1, 12], state: "minecraft:gray_wool"},
        {pos: [16, 1, 13], state: "minecraft:deepslate_bricks"},
        {pos: [17, 1, 7], state: "minecraft:deepslate_bricks"},
        {pos: [17, 1, 8], state: "minecraft:gray_wool"},
        {pos: [17, 1, 9], state: "minecraft:gray_wool"},
        {pos: [17, 1, 10], state: "minecraft:deepslate_bricks"},
        {pos: [17, 1, 11], state: "minecraft:gray_wool"},
        {pos: [17, 1, 12], state: "minecraft:gray_wool"},
        {pos: [17, 1, 13], state: "minecraft:deepslate_bricks"},
        {pos: [18, 1, 8], state: "minecraft:gray_wool"},
        {pos: [18, 1, 9], state: "minecraft:gray_wool"},
        {pos: [18, 1, 10], state: "minecraft:deepslate_bricks"},
        {pos: [18, 1, 11], state: "minecraft:gray_wool"},
        {pos: [18, 1, 12], state: "minecraft:gray_wool"},
        {pos: [19, 1, 7], state: "minecraft:deepslate_bricks"},
        {pos: [19, 1, 8], state: "minecraft:gray_wool"},
        {pos: [19, 1, 9], state: "minecraft:gray_wool"},
        {pos: [19, 1, 10], state: "minecraft:deepslate_bricks"},
        {pos: [19, 1, 11], state: "minecraft:gray_wool"},
        {pos: [19, 1, 12], state: "minecraft:gray_wool"},
        {pos: [19, 1, 13], state: "minecraft:deepslate_bricks"},
        {pos: [20, 1, 7], state: "minecraft:deepslate_bricks"},
        {pos: [20, 1, 8], state: "minecraft:gray_wool"},
        {pos: [20, 1, 9], state: "minecraft:gray_wool"},
        {pos: [20, 1, 10], state: "minecraft:deepslate_bricks"},
        {pos: [20, 1, 11], state: "minecraft:gray_wool"},
        {pos: [20, 1, 12], state: "minecraft:gray_wool"},
        {pos: [20, 1, 13], state: "minecraft:deepslate_bricks"},
        {pos: [7, 2, 7], state: "minecraft:polished_deepslate"},
        {pos: [7, 2, 8], state: "minecraft:polished_deepslate"},
        {pos: [7, 2, 12], state: "minecraft:polished_deepslate"},
        {pos: [7, 2, 16], state: "minecraft:polished_deepslate"},
        {pos: [7, 2, 20], state: "minecraft:polished_deepslate"},
        {pos: [8, 2, 7], state: "minecraft:polished_deepslate"},
        {pos: [10, 2, 10], state: "minecraft:chiseled_deepslate"},
        {pos: [10, 2, 13], state: "minecraft:deepslate_tiles"},
        {pos: [10, 2, 14], state: "minecraft:deepslate_tiles"},
        {pos: [10, 2, 15], state: "minecraft:deepslate_tiles"},
        {pos: [10, 2, 16], state: "minecraft:deepslate_tiles"},
        {pos: [10, 2, 17], state: "minecraft:deepslate_tiles"},
        {pos: [10, 2, 18], state: "minecraft:deepslate_tiles"},
        {pos: [10, 2, 19], state: "minecraft:deepslate_tiles"},
        {pos: [10, 2, 20], state: "minecraft:deepslate_tiles"},
        {pos: [12, 2, 7], state: "minecraft:polished_deepslate"},
        {pos: [13, 2, 10], state: "minecraft:deepslate_tiles"},
        {pos: [13, 2, 13], state: "minecraft:polished_deepslate"},
        {pos: [13, 2, 16], state: "minecraft:polished_deepslate"},
        {pos: [13, 2, 20], state: "minecraft:polished_deepslate"},
        {pos: [14, 2, 10], state: "minecraft:deepslate_tiles"},
        {pos: [15, 2, 10], state: "minecraft:deepslate_tiles"},
        {pos: [16, 2, 7], state: "minecraft:polished_deepslate"},
        {pos: [16, 2, 10], state: "minecraft:deepslate_tiles"},
        {pos: [16, 2, 13], state: "minecraft:polished_deepslate"},
        {pos: [17, 2, 10], state: "minecraft:deepslate_tiles"},
        {pos: [18, 2, 10], state: "minecraft:deepslate_tiles"},
        {pos: [19, 2, 10], state: "minecraft:deepslate_tiles"},
        {pos: [20, 2, 7], state: "minecraft:polished_deepslate"},
        {pos: [20, 2, 10], state: "minecraft:deepslate_tiles"},
        {pos: [20, 2, 13], state: "minecraft:polished_deepslate"},
        {pos: [7, 3, 7], state: "minecraft:polished_deepslate"},
        {pos: [7, 3, 12], state: "minecraft:polished_deepslate"},
        {pos: [7, 3, 16], state: "minecraft:polished_deepslate"},
        {pos: [7, 3, 20], state: "minecraft:polished_deepslate"},
        {pos: [10, 3, 10], state: "minecraft:deepslate_tiles"},
        {pos: [10, 3, 13], state: "minecraft:deepslate_bricks"},
        {pos: [10, 3, 14], state: "minecraft:deepslate_bricks"},
        {pos: [10, 3, 15], state: "minecraft:deepslate_bricks"},
        {pos: [10, 3, 16], state: "minecraft:deepslate_bricks"},
        {pos: [10, 3, 17], state: "minecraft:deepslate_bricks"},
        {pos: [10, 3, 18], state: "minecraft:deepslate_bricks"},
        {pos: [10, 3, 19], state: "minecraft:deepslate_bricks"},
        {pos: [10, 3, 20], state: "minecraft:deepslate_bricks"},
        {pos: [12, 3, 7], state: "minecraft:polished_deepslate"},
        {pos: [13, 3, 10], state: "minecraft:deepslate_bricks"},
        {pos: [13, 3, 13], state: "minecraft:polished_deepslate"},
        {pos: [13, 3, 16], state: "minecraft:polished_deepslate"},
        {pos: [13, 3, 20], state: "minecraft:polished_deepslate"},
        {pos: [14, 3, 10], state: "minecraft:deepslate_bricks"},
        {pos: [15, 3, 10], state: "minecraft:deepslate_bricks"},
        {pos: [16, 3, 7], state: "minecraft:polished_deepslate"},
        {pos: [16, 3, 10], state: "minecraft:deepslate_bricks"},
        {pos: [16, 3, 13], state: "minecraft:polished_deepslate"},
        {pos: [17, 3, 10], state: "minecraft:deepslate_bricks"},
        {pos: [18, 3, 10], state: "minecraft:deepslate_bricks"},
        {pos: [19, 3, 10], state: "minecraft:deepslate_bricks"},
        {pos: [20, 3, 7], state: "minecraft:polished_deepslate"},
        {pos: [20, 3, 10], state: "minecraft:deepslate_bricks"},
        {pos: [20, 3, 13], state: "minecraft:polished_deepslate"},
        {pos: [7, 4, 7], state: "minecraft:polished_deepslate"},
        {pos: [7, 4, 12], state: "minecraft:polished_deepslate"},
        {pos: [7, 4, 14], state: "minecraft:soul_lantern{hanging:true,waterlogged:false}"},
        {pos: [7, 4, 16], state: "minecraft:polished_deepslate"},
        {pos: [7, 4, 20], state: "minecraft:polished_deepslate"},
        {pos: [10, 4, 10], state: "minecraft:chiseled_deepslate"},
        {pos: [10, 4, 13], state: "minecraft:deepslate_tiles"},
        {pos: [10, 4, 14], state: "minecraft:deepslate_tiles"},
        {pos: [10, 4, 15], state: "minecraft:deepslate_tiles"},
        {pos: [10, 4, 16], state: "minecraft:deepslate_tiles"},
        {pos: [10, 4, 17], state: "minecraft:deepslate_tiles"},
        {pos: [10, 4, 18], state: "minecraft:deepslate_tiles"},
        {pos: [10, 4, 19], state: "minecraft:deepslate_tiles"},
        {pos: [10, 4, 20], state: "minecraft:deepslate_tiles"},
        {pos: [12, 4, 7], state: "minecraft:polished_deepslate"},
        {pos: [13, 4, 10], state: "minecraft:deepslate_tiles"},
        {pos: [13, 4, 13], state: "minecraft:polished_deepslate"},
        {pos: [13, 4, 16], state: "minecraft:polished_deepslate"},
        {pos: [13, 4, 18], state: "minecraft:soul_lantern{hanging:true,waterlogged:false}"},
        {pos: [13, 4, 20], state: "minecraft:polished_deepslate"},
        {pos: [14, 4, 7], state: "minecraft:soul_lantern{hanging:true,waterlogged:false}"},
        {pos: [14, 4, 10], state: "minecraft:deepslate_tiles"},
        {pos: [15, 4, 10], state: "minecraft:deepslate_tiles"},
        {pos: [16, 4, 7], state: "minecraft:polished_deepslate"},
        {pos: [16, 4, 10], state: "minecraft:deepslate_tiles"},
        {pos: [16, 4, 13], state: "minecraft:polished_deepslate"},
        {pos: [17, 4, 10], state: "minecraft:deepslate_tiles"},
        {pos: [18, 4, 10], state: "minecraft:deepslate_tiles"},
        {pos: [18, 4, 13], state: "minecraft:soul_lantern{hanging:true,waterlogged:false}"},
        {pos: [19, 4, 10], state: "minecraft:deepslate_tiles"},
        {pos: [20, 4, 7], state: "minecraft:polished_deepslate"},
        {pos: [20, 4, 10], state: "minecraft:deepslate_tiles"},
        {pos: [20, 4, 13], state: "minecraft:polished_deepslate"},
        {pos: [6, 5, 6], state: "minecraft:deepslate_bricks"},
        {pos: [6, 5, 7], state: "minecraft:deepslate_bricks"},
        {pos: [6, 5, 8], state: "minecraft:deepslate_bricks"},
        {pos: [6, 5, 9], state: "minecraft:deepslate_bricks"},
        {pos: [6, 5, 10], state: "minecraft:deepslate_bricks"},
        {pos: [6, 5, 11], state: "minecraft:deepslate_bricks"},
        {pos: [6, 5, 12], state: "minecraft:deepslate_bricks"},
        {pos: [6, 5, 13], state: "minecraft:deepslate_bricks"},
        {pos: [6, 5, 14], state: "minecraft:deepslate_bricks"},
        {pos: [6, 5, 15], state: "minecraft:deepslate_bricks"},
        {pos: [6, 5, 16], state: "minecraft:deepslate_bricks"},
        {pos: [6, 5, 17], state: "minecraft:deepslate_bricks"},
        {pos: [6, 5, 18], state: "minecraft:deepslate_bricks"},
        {pos: [6, 5, 19], state: "minecraft:deepslate_bricks"},
        {pos: [6, 5, 20], state: "minecraft:deepslate_bricks"},
        {pos: [7, 5, 6], state: "minecraft:deepslate_bricks"},
        {pos: [7, 5, 7], state: "minecraft:deepslate_bricks"},
        {pos: [7, 5, 8], state: "minecraft:deepslate_bricks"},
        {pos: [7, 5, 9], state: "minecraft:deepslate_bricks"},
        {pos: [7, 5, 10], state: "minecraft:deepslate_bricks"},
        {pos: [7, 5, 11], state: "minecraft:deepslate_bricks"},
        {pos: [7, 5, 12], state: "minecraft:deepslate_bricks"},
        {pos: [7, 5, 13], state: "minecraft:deepslate_bricks"},
        {pos: [7, 5, 14], state: "minecraft:deepslate_bricks"},
        {pos: [7, 5, 15], state: "minecraft:deepslate_bricks"},
        {pos: [7, 5, 16], state: "minecraft:deepslate_bricks"},
        {pos: [7, 5, 17], state: "minecraft:deepslate_bricks"},
        {pos: [7, 5, 18], state: "minecraft:deepslate_bricks"},
        {pos: [7, 5, 19], state: "minecraft:deepslate_bricks"},
        {pos: [7, 5, 20], state: "minecraft:deepslate_bricks"},
        {pos: [8, 5, 6], state: "minecraft:deepslate_bricks"},
        {pos: [8, 5, 7], state: "minecraft:deepslate_bricks"},
        {pos: [8, 5, 8], state: "minecraft:gray_wool"},
        {pos: [8, 5, 9], state: "minecraft:gray_wool"},
        {pos: [8, 5, 10], state: "minecraft:gray_wool"},
        {pos: [8, 5, 11], state: "minecraft:gray_wool"},
        {pos: [8, 5, 12], state: "minecraft:gray_wool"},
        {pos: [8, 5, 13], state: "minecraft:gray_wool"},
        {pos: [8, 5, 14], state: "minecraft:gray_wool"},
        {pos: [8, 5, 15], state: "minecraft:gray_wool"},
        {pos: [8, 5, 16], state: "minecraft:gray_wool"},
        {pos: [8, 5, 17], state: "minecraft:gray_wool"},
        {pos: [8, 5, 18], state: "minecraft:gray_wool"},
        {pos: [8, 5, 19], state: "minecraft:gray_wool"},
        {pos: [8, 5, 20], state: "minecraft:gray_wool"},
        {pos: [9, 5, 6], state: "minecraft:deepslate_bricks"},
        {pos: [9, 5, 7], state: "minecraft:deepslate_bricks"},
        {pos: [9, 5, 8], state: "minecraft:gray_wool"},
        {pos: [9, 5, 9], state: "minecraft:polished_deepslate"},
        {pos: [9, 5, 10], state: "minecraft:polished_deepslate"},
        {pos: [9, 5, 11], state: "minecraft:polished_deepslate"},
        {pos: [9, 5, 12], state: "minecraft:polished_deepslate"},
        {pos: [9, 5, 13], state: "minecraft:polished_deepslate"},
        {pos: [9, 5, 14], state: "minecraft:gray_wool"},
        {pos: [9, 5, 15], state: "minecraft:gray_wool"},
        {pos: [9, 5, 16], state: "minecraft:gray_wool"},
        {pos: [9, 5, 17], state: "minecraft:gray_wool"},
        {pos: [9, 5, 18], state: "minecraft:gray_wool"},
        {pos: [9, 5, 19], state: "minecraft:gray_wool"},
        {pos: [9, 5, 20], state: "minecraft:gray_wool"},
        {pos: [10, 5, 6], state: "minecraft:deepslate_bricks"},
        {pos: [10, 5, 7], state: "minecraft:deepslate_bricks"},
        {pos: [10, 5, 8], state: "minecraft:gray_wool"},
        {pos: [10, 5, 9], state: "minecraft:polished_deepslate"},
        {pos: [10, 5, 10], state: "minecraft:polished_deepslate"},
        {pos: [10, 5, 13], state: "minecraft:deepslate_bricks"},
        {pos: [10, 5, 14], state: "minecraft:deepslate_bricks"},
        {pos: [10, 5, 15], state: "minecraft:deepslate_bricks"},
        {pos: [10, 5, 16], state: "minecraft:deepslate_bricks"},
        {pos: [10, 5, 17], state: "minecraft:deepslate_bricks"},
        {pos: [10, 5, 18], state: "minecraft:deepslate_bricks"},
        {pos: [10, 5, 19], state: "minecraft:deepslate_bricks"},
        {pos: [10, 5, 20], state: "minecraft:deepslate_bricks"},
        {pos: [11, 5, 6], state: "minecraft:deepslate_bricks"},
        {pos: [11, 5, 7], state: "minecraft:deepslate_bricks"},
        {pos: [11, 5, 8], state: "minecraft:gray_wool"},
        {pos: [11, 5, 9], state: "minecraft:polished_deepslate"},
        {pos: [11, 5, 11], state: "minecraft:polished_deepslate"},
        {pos: [11, 5, 12], state: "minecraft:polished_deepslate"},
        {pos: [11, 5, 13], state: "minecraft:polished_deepslate"},
        {pos: [11, 5, 14], state: "minecraft:gray_wool"},
        {pos: [11, 5, 15], state: "minecraft:gray_wool"},
        {pos: [11, 5, 16], state: "minecraft:gray_wool"},
        {pos: [11, 5, 17], state: "minecraft:gray_wool"},
        {pos: [11, 5, 18], state: "minecraft:gray_wool"},
        {pos: [11, 5, 19], state: "minecraft:gray_wool"},
        {pos: [11, 5, 20], state: "minecraft:gray_wool"},
        {pos: [12, 5, 6], state: "minecraft:deepslate_bricks"},
        {pos: [12, 5, 7], state: "minecraft:deepslate_bricks"},
        {pos: [12, 5, 8], state: "minecraft:gray_wool"},
        {pos: [12, 5, 9], state: "minecraft:polished_deepslate"},
        {pos: [12, 5, 11], state: "minecraft:polished_deepslate"},
        {pos: [12, 5, 12], state: "minecraft:gray_wool"},
        {pos: [12, 5, 13], state: "minecraft:gray_wool"},
        {pos: [12, 5, 14], state: "minecraft:gray_wool"},
        {pos: [12, 5, 15], state: "minecraft:gray_wool"},
        {pos: [12, 5, 16], state: "minecraft:gray_wool"},
        {pos: [12, 5, 17], state: "minecraft:gray_wool"},
        {pos: [12, 5, 18], state: "minecraft:gray_wool"},
        {pos: [12, 5, 19], state: "minecraft:gray_wool"},
        {pos: [12, 5, 20], state: "minecraft:gray_wool"},
        {pos: [13, 5, 6], state: "minecraft:deepslate_bricks"},
        {pos: [13, 5, 7], state: "minecraft:deepslate_bricks"},
        {pos: [13, 5, 8], state: "minecraft:gray_wool"},
        {pos: [13, 5, 9], state: "minecraft:polished_deepslate"},
        {pos: [13, 5, 10], state: "minecraft:deepslate_bricks"},
        {pos: [13, 5, 11], state: "minecraft:polished_deepslate"},
        {pos: [13, 5, 12], state: "minecraft:gray_wool"},
        {pos: [13, 5, 13], state: "minecraft:deepslate_bricks"},
        {pos: [13, 5, 14], state: "minecraft:deepslate_bricks"},
        {pos: [13, 5, 15], state: "minecraft:deepslate_bricks"},
        {pos: [13, 5, 16], state: "minecraft:deepslate_bricks"},
        {pos: [13, 5, 17], state: "minecraft:deepslate_bricks"},
        {pos: [13, 5, 18], state: "minecraft:deepslate_bricks"},
        {pos: [13, 5, 19], state: "minecraft:deepslate_bricks"},
        {pos: [13, 5, 20], state: "minecraft:deepslate_bricks"},
        {pos: [14, 5, 6], state: "minecraft:deepslate_bricks"},
        {pos: [14, 5, 7], state: "minecraft:deepslate_bricks"},
        {pos: [14, 5, 8], state: "minecraft:gray_wool"},
        {pos: [14, 5, 9], state: "minecraft:gray_wool"},
        {pos: [14, 5, 10], state: "minecraft:deepslate_bricks"},
        {pos: [14, 5, 11], state: "minecraft:gray_wool"},
        {pos: [14, 5, 12], state: "minecraft:gray_wool"},
        {pos: [14, 5, 13], state: "minecraft:deepslate_bricks"},
        {pos: [14, 5, 14], state: "minecraft:deepslate_bricks"},
        {pos: [14, 5, 15], state: "minecraft:deepslate_bricks"},
        {pos: [14, 5, 16], state: "minecraft:deepslate_bricks"},
        {pos: [14, 5, 17], state: "minecraft:deepslate_bricks"},
        {pos: [14, 5, 18], state: "minecraft:deepslate_bricks"},
        {pos: [14, 5, 19], state: "minecraft:deepslate_bricks"},
        {pos: [14, 5, 20], state: "minecraft:deepslate_bricks"},
        {pos: [15, 5, 6], state: "minecraft:deepslate_bricks"},
        {pos: [15, 5, 7], state: "minecraft:deepslate_bricks"},
        {pos: [15, 5, 8], state: "minecraft:gray_wool"},
        {pos: [15, 5, 9], state: "minecraft:gray_wool"},
        {pos: [15, 5, 10], state: "minecraft:deepslate_bricks"},
        {pos: [15, 5, 11], state: "minecraft:gray_wool"},
        {pos: [15, 5, 12], state: "minecraft:gray_wool"},
        {pos: [15, 5, 13], state: "minecraft:deepslate_bricks"},
        {pos: [15, 5, 14], state: "minecraft:deepslate_bricks"},
        {pos: [16, 5, 6], state: "minecraft:deepslate_bricks"},
        {pos: [16, 5, 7], state: "minecraft:deepslate_bricks"},
        {pos: [16, 5, 8], state: "minecraft:gray_wool"},
        {pos: [16, 5, 9], state: "minecraft:gray_wool"},
        {pos: [16, 5, 10], state: "minecraft:deepslate_bricks"},
        {pos: [16, 5, 11], state: "minecraft:gray_wool"},
        {pos: [16, 5, 12], state: "minecraft:gray_wool"},
        {pos: [16, 5, 13], state: "minecraft:deepslate_bricks"},
        {pos: [16, 5, 14], state: "minecraft:deepslate_bricks"},
        {pos: [17, 5, 6], state: "minecraft:deepslate_bricks"},
        {pos: [17, 5, 7], state: "minecraft:deepslate_bricks"},
        {pos: [17, 5, 8], state: "minecraft:gray_wool"},
        {pos: [17, 5, 9], state: "minecraft:gray_wool"},
        {pos: [17, 5, 10], state: "minecraft:deepslate_bricks"},
        {pos: [17, 5, 11], state: "minecraft:gray_wool"},
        {pos: [17, 5, 12], state: "minecraft:gray_wool"},
        {pos: [17, 5, 13], state: "minecraft:deepslate_bricks"},
        {pos: [17, 5, 14], state: "minecraft:deepslate_bricks"},
        {pos: [18, 5, 6], state: "minecraft:deepslate_bricks"},
        {pos: [18, 5, 7], state: "minecraft:deepslate_bricks"},
        {pos: [18, 5, 8], state: "minecraft:gray_wool"},
        {pos: [18, 5, 9], state: "minecraft:gray_wool"},
        {pos: [18, 5, 10], state: "minecraft:deepslate_bricks"},
        {pos: [18, 5, 11], state: "minecraft:gray_wool"},
        {pos: [18, 5, 12], state: "minecraft:gray_wool"},
        {pos: [18, 5, 13], state: "minecraft:deepslate_bricks"},
        {pos: [18, 5, 14], state: "minecraft:deepslate_bricks"},
        {pos: [19, 5, 6], state: "minecraft:deepslate_bricks"},
        {pos: [19, 5, 7], state: "minecraft:deepslate_bricks"},
        {pos: [19, 5, 8], state: "minecraft:gray_wool"},
        {pos: [19, 5, 9], state: "minecraft:gray_wool"},
        {pos: [19, 5, 10], state: "minecraft:deepslate_bricks"},
        {pos: [19, 5, 11], state: "minecraft:gray_wool"},
        {pos: [19, 5, 12], state: "minecraft:gray_wool"},
        {pos: [19, 5, 13], state: "minecraft:deepslate_bricks"},
        {pos: [19, 5, 14], state: "minecraft:deepslate_bricks"},
        {pos: [20, 5, 6], state: "minecraft:deepslate_bricks"},
        {pos: [20, 5, 7], state: "minecraft:deepslate_bricks"},
        {pos: [20, 5, 8], state: "minecraft:gray_wool"},
        {pos: [20, 5, 9], state: "minecraft:gray_wool"},
        {pos: [20, 5, 10], state: "minecraft:deepslate_bricks"},
        {pos: [20, 5, 11], state: "minecraft:gray_wool"},
        {pos: [20, 5, 12], state: "minecraft:gray_wool"},
        {pos: [20, 5, 13], state: "minecraft:deepslate_bricks"},
        {pos: [20, 5, 14], state: "minecraft:deepslate_bricks"},
        {pos: [7, 6, 7], state: "minecraft:deepslate_bricks"},
        {pos: [7, 6, 8], state: "minecraft:deepslate_bricks"},
        {pos: [7, 6, 10], state: "minecraft:deepslate_bricks"},
        {pos: [7, 6, 12], state: "minecraft:deepslate_bricks"},
        {pos: [7, 6, 14], state: "minecraft:deepslate_bricks"},
        {pos: [7, 6, 16], state: "minecraft:deepslate_bricks"},
        {pos: [7, 6, 18], state: "minecraft:deepslate_bricks"},
        {pos: [7, 6, 20], state: "minecraft:deepslate_bricks"},
        {pos: [8, 6, 7], state: "minecraft:deepslate_bricks"},
        {pos: [10, 6, 7], state: "minecraft:deepslate_bricks"},
        {pos: [10, 6, 10], state: "minecraft:polished_deepslate"},
        {pos: [10, 6, 15], state: "minecraft:polished_deepslate"},
        {pos: [10, 6, 17], state: "minecraft:polished_deepslate"},
        {pos: [10, 6, 19], state: "minecraft:polished_deepslate"},
        {pos: [12, 6, 7], state: "minecraft:deepslate_bricks"},
        {pos: [13, 6, 10], state: "minecraft:polished_deepslate"},
        {pos: [13, 6, 13], state: "minecraft:deepslate_bricks"},
        {pos: [13, 6, 14], state: "minecraft:deepslate_bricks"},
        {pos: [13, 6, 16], state: "minecraft:deepslate_bricks"},
        {pos: [13, 6, 18], state: "minecraft:deepslate_bricks"},
        {pos: [13, 6, 20], state: "minecraft:deepslate_bricks"},
        {pos: [14, 6, 7], state: "minecraft:deepslate_bricks"},
        {pos: [14, 6, 13], state: "minecraft:deepslate_bricks"},
        {pos: [15, 6, 10], state: "minecraft:polished_deepslate"},
        {pos: [16, 6, 7], state: "minecraft:deepslate_bricks"},
        {pos: [16, 6, 13], state: "minecraft:deepslate_bricks"},
        {pos: [17, 6, 10], state: "minecraft:polished_deepslate"},
        {pos: [18, 6, 7], state: "minecraft:deepslate_bricks"},
        {pos: [18, 6, 13], state: "minecraft:deepslate_bricks"},
        {pos: [19, 6, 10], state: "minecraft:polished_deepslate"},
        {pos: [20, 6, 7], state: "minecraft:deepslate_bricks"},
        {pos: [20, 6, 13], state: "minecraft:deepslate_bricks"},
        {pos: [10, 7, 10], state: "minecraft:chiseled_deepslate"},
        {pos: [10, 8, 10], state: "minecraft:soul_lantern{hanging:false,waterlogged:false}"}
    ],
    entities: [],
    palette: [
        "minecraft:deepslate_tiles",
        "minecraft:gray_wool",
        "minecraft:deepslate_bricks",
        "minecraft:polished_deepslate",
        "minecraft:chiseled_deepslate",
        "minecraft:soul_lantern{hanging:true,waterlogged:false}",
        "minecraft:soul_lantern{hanging:false,waterlogged:false}",
        "minecraft:jigsaw{orientation:south_up}",
        "minecraft:jigsaw{orientation:east_up}"
    ]
}
