{
    size: [18, 15, 21],
    data: [
        {pos: [0, 0, 7], state: "minecraft:deepslate_tiles"},
        {pos: [0, 0, 8], state: "minecraft:gray_wool"},
        {pos: [0, 0, 9], state: "minecraft:gray_wool"},
        {pos: [0, 0, 10], state: "minecraft:jigsaw{orientation:west_up}", nbt: {final_state: "minecraft:deepslate_tiles", id: "minecraft:jigsaw", joint: "rollable", name: "minecraft:connect_wall", pool: "minecraft:ancient_city/walls", target: "minecraft:connect_wall"}},
        {pos: [0, 0, 11], state: "minecraft:gray_wool"},
        {pos: [0, 0, 12], state: "minecraft:gray_wool"},
        {pos: [0, 0, 13], state: "minecraft:deepslate_tiles"},
        {pos: [1, 0, 7], state: "minecraft:deepslate_tiles"},
        {pos: [1, 0, 8], state: "minecraft:gray_wool"},
        {pos: [1, 0, 9], state: "minecraft:gray_wool"},
        {pos: [1, 0, 10], state: "minecraft:deepslate_tiles"},
        {pos: [1, 0, 11], state: "minecraft:gray_wool"},
        {pos: [1, 0, 12], state: "minecraft:gray_wool"},
        {pos: [1, 0, 13], state: "minecraft:deepslate_tiles"},
        {pos: [2, 0, 7], state: "minecraft:deepslate_tiles"},
        {pos: [2, 0, 8], state: "minecraft:gray_wool"},
        {pos: [2, 0, 9], state: "minecraft:gray_wool"},
        {pos: [2, 0, 10], state: "minecraft:deepslate_tiles"},
        {pos: [2, 0, 11], state: "minecraft:gray_wool"},
        {pos: [2, 0, 12], state: "minecraft:gray_wool"},
        {pos: [2, 0, 13], state: "minecraft:deepslate_tiles"},
        {pos: [3, 0, 7], state: "minecraft:deepslate_tiles"},
        {pos: [3, 0, 8], state: "minecraft:gray_wool"},
        {pos: [3, 0, 9], state: "minecraft:gray_wool"},
        {pos: [3, 0, 10], state: "minecraft:deepslate_tiles"},
        {pos: [3, 0, 11], state: "minecraft:gray_wool"},
        {pos: [3, 0, 12], state: "minecraft:gray_wool"},
        {pos: [3, 0, 13], state: "minecraft:deepslate_tiles"},
        {pos: [4, 0, 4], state: "minecraft:deepslate_tile_slab{type:bottom,waterlogged:false}"},
        {pos: [4, 0, 5], state: "minecraft:deepslate_tiles"},
        {pos: [4, 0, 6], state: "minecraft:deepslate_tiles"},
        {pos: [4, 0, 7], state: "minecraft:deepslate_tiles"},
        {pos: [4, 0, 8], state: "minecraft:gray_wool"},
        {pos: [4, 0, 9], state: "minecraft:gray_wool"},
        {pos: [4, 0, 10], state: "minecraft:deepslate_tiles"},
        {pos: [4, 0, 11], state: "minecraft:gray_wool"},
        {pos: [4, 0, 12], state: "minecraft:gray_wool"},
        {pos: [4, 0, 13], state: "minecraft:deepslate_tiles"},
        {pos: [4, 0, 14], state: "minecraft:deepslate_tiles"},
        {pos: [4, 0, 15], state: "minecraft:deepslate_tiles"},
        {pos: [4, 0, 16], state: "minecraft:deepslate_tile_slab{type:bottom,waterlogged:false}"},
        {pos: [5, 0, 3], state: "minecraft:deepslate_tile_slab{type:bottom,waterlogged:false}"},
        {pos: [5, 0, 4], state: "minecraft:deepslate_tiles"},
        {pos: [5, 0, 5], state: "minecraft:deepslate_tiles"},
        {pos: [5, 0, 6], state: "minecraft:deepslate_tiles"},
        {pos: [5, 0, 7], state: "minecraft:deepslate_tiles"},
        {pos: [5, 0, 8], state: "minecraft:gray_wool"},
        {pos: [5, 0, 9], state: "minecraft:gray_wool"},
        {pos: [5, 0, 10], state: "minecraft:deepslate_tiles"},
        {pos: [5, 0, 11], state: "minecraft:gray_wool"},
        {pos: [5, 0, 12], state: "minecraft:gray_wool"},
        {pos: [5, 0, 13], state: "minecraft:deepslate_tiles"},
        {pos: [5, 0, 14], state: "minecraft:deepslate_tiles"},
        {pos: [5, 0, 15], state: "minecraft:deepslate_tiles"},
        {pos: [5, 0, 16], state: "minecraft:deepslate_tiles"},
        {pos: [5, 0, 17], state: "minecraft:deepslate_tile_slab{type:bottom,waterlogged:false}"},
        {pos: [6, 0, 3], state: "minecraft:deepslate_tile_slab{type:bottom,waterlogged:false}"},
        {pos: [6, 0, 4], state: "minecraft:deepslate_tiles"},
        {pos: [6, 0, 5], state: "minecraft:deepslate_tiles"},
        {pos: [6, 0, 6], state: "minecraft:deepslate_tiles"},
        {pos: [6, 0, 7], state: "minecraft:deepslate_tiles"},
        {pos: [6, 0, 8], state: "minecraft:gray_wool"},
        {pos: [6, 0, 9], state: "minecraft:gray_wool"},
        {pos: [6, 0, 10], state: "minecraft:deepslate_tiles"},
        {pos: [6, 0, 11], state: "minecraft:gray_wool"},
        {pos: [6, 0, 12], state: "minecraft:gray_wool"},
        {pos: [6, 0, 13], state: "minecraft:deepslate_tiles"},
        {pos: [6, 0, 14], state: "minecraft:deepslate_tiles"},
        {pos: [6, 0, 15], state: "minecraft:deepslate_tiles"},
        {pos: [6, 0, 16], state: "minecraft:deepslate_tiles"},
        {pos: [6, 0, 17], state: "minecraft:deepslate_tile_slab{type:bottom,waterlogged:false}"},
        {pos: [7, 0, 3], state: "minecraft:deepslate_tile_slab{type:bottom,waterlogged:false}"},
        {pos: [7, 0, 4], state: "minecraft:deepslate_tiles"},
        {pos: [7, 0, 5], state: "minecraft:deepslate_tiles"},
        {pos: [7, 0, 6], state: "minecraft:deepslate_tiles"},
        {pos: [7, 0, 7], state: "minecraft:deepslate_tiles"},
        {pos: [7, 0, 8], state: "minecraft:gray_wool"},
        {pos: [7, 0, 9], state: "minecraft:gray_wool"},
        {pos: [7, 0, 10], state: "minecraft:deepslate_tiles"},
        {pos: [7, 0, 11], state: "minecraft:gray_wool"},
        {pos: [7, 0, 12], state: "minecraft:gray_wool"},
        {pos: [7, 0, 13], state: "minecraft:deepslate_tiles"},
        {pos: [7, 0, 14], state: "minecraft:deepslate_tiles"},
        {pos: [7, 0, 15], state: "minecraft:deepslate_tiles"},
        {pos: [7, 0, 16], state: "minecraft:deepslate_tiles"},
        {pos: [7, 0, 17], state: "minecraft:deepslate_tile_slab{type:bottom,waterlogged:false}"},
        {pos: [8, 0, 3], state: "minecraft:deepslate_tile_slab{type:bottom,waterlogged:false}"},
        {pos: [8, 0, 4], state: "minecraft:deepslate_tiles"},
        {pos: [8, 0, 5], state: "minecraft:deepslate_tiles"},
        {pos: [8, 0, 6], state: "minecraft:deepslate_tiles"},
        {pos: [8, 0, 7], state: "minecraft:deepslate_tiles"},
        {pos: [8, 0, 8], state: "minecraft:gray_wool"},
        {pos: [8, 0, 9], state: "minecraft:gray_wool"},
        {pos: [8, 0, 10], state: "minecraft:deepslate_tiles"},
        {pos: [8, 0, 11], state: "minecraft:gray_wool"},
        {pos: [8, 0, 12], state: "minecraft:gray_wool"},
        {pos: [8, 0, 13], state: "minecraft:deepslate_tiles"},
        {pos: [8, 0, 14], state: "minecraft:deepslate_tiles"},
        {pos: [8, 0, 15], state: "minecraft:deepslate_tiles"},
        {pos: [8, 0, 16], state: "minecraft:deepslate_tiles"},
        {pos: [8, 0, 17], state: "minecraft:deepslate_tile_slab{type:bottom,waterlogged:false}"},
        {pos: [9, 0, 0], state: "minecraft:jigsaw{orientation:north_up}", nbt: {final_state: "minecraft:structure_void", id: "minecraft:jigsaw", joint: "rollable", name: "minecraft:empty", pool: "minecraft:ancient_city/structures", target: "minecraft:connect_structure"}},
        {pos: [9, 0, 3], state: "minecraft:deepslate_tile_slab{type:bottom,waterlogged:false}"},
        {pos: [9, 0, 4], state: "minecraft:deepslate_tiles"},
        {pos: [9, 0, 5], state: "minecraft:deepslate_tiles"},
        {pos: [9, 0, 6], state: "minecraft:deepslate_tiles"},
        {pos: [9, 0, 7], state: "minecraft:deepslate_tiles"},
        {pos: [9, 0, 8], state: "minecraft:gray_wool"},
        {pos: [9, 0, 9], state: "minecraft:gray_wool"},
        {pos: [9, 0, 10], state: "minecraft:deepslate_tiles"},
        {pos: [9, 0, 11], state: "minecraft:gray_wool"},
        {pos: [9, 0, 12], state: "minecraft:gray_wool"},
        {pos: [9, 0, 13], state: "minecraft:deepslate_tiles"},
        {pos: [9, 0, 14], state: "minecraft:deepslate_tiles"},
        {pos: [9, 0, 15], state: "minecraft:deepslate_tiles"},
        {pos: [9, 0, 16], state: "minecraft:deepslate_tiles"},
        {pos: [9, 0, 17], state: "minecraft:deepslate_tile_slab{type:bottom,waterlogged:false}"},
        {pos: [9, 0, 20], state: "minecraft:jigsaw{orientation:south_up}", nbt: {final_state: "minecraft:deepslate_tile_slab", id: "minecraft:jigsaw", joint: "rollable", name: "minecraft:empty", pool: "minecraft:ancient_city/structures", target: "minecraft:connect_structure"}},
        {pos: [10, 0, 3], state: "minecraft:deepslate_tile_slab{type:bottom,waterlogged:false}"},
        {pos: [10, 0, 4], state: "minecraft:deepslate_tiles"},
        {pos: [10, 0, 5], state: "minecraft:deepslate_tiles"},
        {pos: [10, 0, 6], state: "minecraft:deepslate_tiles"},
        {pos: [10, 0, 7], state: "minecraft:deepslate_tiles"},
        {pos: [10, 0, 8], state: "minecraft:gray_wool"},
        {pos: [10, 0, 9], state: "minecraft:gray_wool"},
        {pos: [10, 0, 10], state: "minecraft:deepslate_tiles"},
        {pos: [10, 0, 11], state: "minecraft:gray_wool"},
        {pos: [10, 0, 12], state: "minecraft:gray_wool"},
        {pos: [10, 0, 13], state: "minecraft:deepslate_tiles"},
        {pos: [10, 0, 14], state: "minecraft:deepslate_tiles"},
        {pos: [10, 0, 15], state: "minecraft:deepslate_tiles"},
        {pos: [10, 0, 16], state: "minecraft:deepslate_tiles"},
        {pos: [10, 0, 17], state: "minecraft:deepslate_tile_slab{type:bottom,waterlogged:false}"},
        {pos: [11, 0, 3], state: "minecraft:deepslate_tile_slab{type:bottom,waterlogged:false}"},
        {pos: [11, 0, 4], state: "minecraft:deepslate_tiles"},
        {pos: [11, 0, 5], state: "minecraft:deepslate_tiles"},
        {pos: [11, 0, 6], state: "minecraft:deepslate_tiles"},
        {pos: [11, 0, 7], state: "minecraft:deepslate_tiles"},
        {pos: [11, 0, 8], state: "minecraft:gray_wool"},
        {pos: [11, 0, 9], state: "minecraft:gray_wool"},
        {pos: [11, 0, 10], state: "minecraft:deepslate_tiles"},
        {pos: [11, 0, 11], state: "minecraft:gray_wool"},
        {pos: [11, 0, 12], state: "minecraft:gray_wool"},
        {pos: [11, 0, 13], state: "minecraft:deepslate_tiles"},
        {pos: [11, 0, 14], state: "minecraft:deepslate_tiles"},
        {pos: [11, 0, 15], state: "minecraft:deepslate_tiles"},
        {pos: [11, 0, 16], state: "minecraft:deepslate_tiles"},
        {pos: [11, 0, 17], state: "minecraft:deepslate_tile_slab{type:bottom,waterlogged:false}"},
        {pos: [12, 0, 3], state: "minecraft:deepslate_tile_slab{type:bottom,waterlogged:false}"},
        {pos: [12, 0, 4], state: "minecraft:deepslate_tiles"},
        {pos: [12, 0, 5], state: "minecraft:deepslate_tiles"},
        {pos: [12, 0, 6], state: "minecraft:deepslate_tiles"},
        {pos: [12, 0, 7], state: "minecraft:deepslate_tiles"},
        {pos: [12, 0, 8], state: "minecraft:gray_wool"},
        {pos: [12, 0, 9], state: "minecraft:gray_wool"},
        {pos: [12, 0, 10], state: "minecraft:deepslate_tiles"},
        {pos: [12, 0, 11], state: "minecraft:gray_wool"},
        {pos: [12, 0, 12], state: "minecraft:gray_wool"},
        {pos: [12, 0, 13], state: "minecraft:deepslate_tiles"},
        {pos: [12, 0, 14], state: "minecraft:deepslate_tiles"},
        {pos: [12, 0, 15], state: "minecraft:deepslate_tiles"},
        {pos: [12, 0, 16], state: "minecraft:deepslate_tiles"},
        {pos: [12, 0, 17], state: "minecraft:deepslate_tile_slab{type:bottom,waterlogged:false}"},
        {pos: [13, 0, 4], state: "minecraft:deepslate_tile_slab{type:bottom,waterlogged:false}"},
        {pos: [13, 0, 5], state: "minecraft:deepslate_tiles"},
        {pos: [13, 0, 6], state: "minecraft:deepslate_tiles"},
        {pos: [13, 0, 7], state: "minecraft:deepslate_tiles"},
        {pos: [13, 0, 8], state: "minecraft:gray_wool"},
        {pos: [13, 0, 9], state: "minecraft:gray_wool"},
        {pos: [13, 0, 10], state: "minecraft:deepslate_tiles"},
        {pos: [13, 0, 11], state: "minecraft:gray_wool"},
        {pos: [13, 0, 12], state: "minecraft:gray_wool"},
        {pos: [13, 0, 13], state: "minecraft:deepslate_tiles"},
        {pos: [13, 0, 14], state: "minecraft:deepslate_tiles"},
        {pos: [13, 0, 15], state: "minecraft:deepslate_tiles"},
        {pos: [14, 0, 7], state: "minecraft:deepslate_tiles"},
        {pos: [14, 0, 8], state: "minecraft:gray_wool"},
        {pos: [14, 0, 9], state: "minecraft:gray_wool"},
        {pos: [14, 0, 10], state: "minecraft:deepslate_tiles"},
        {pos: [14, 0, 11], state: "minecraft:gray_wool"},
        {pos: [14, 0, 12], state: "minecraft:gray_wool"},
        {pos: [14, 0, 13], state: "minecraft:deepslate_tiles"},
        {pos: [15, 0, 7], state: "minecraft:deepslate_tiles"},
        {pos: [15, 0, 8], state: "minecraft:gray_wool"},
        {pos: [15, 0, 9], state: "minecraft:gray_wool"},
        {pos: [15, 0, 10], state: "minecraft:deepslate_tiles"},
        {pos: [15, 0, 11], state: "minecraft:gray_wool"},
        {pos: [15, 0, 12], state: "minecraft:gray_wool"},
        {pos: [15, 0, 13], state: "minecraft:deepslate_tiles"},
        {pos: [16, 0, 7], state: "minecraft:deepslate_tiles"},
        {pos: [16, 0, 8], state: "minecraft:gray_wool"},
        {pos: [16, 0, 9], state: "minecraft:gray_wool"},
        {pos: [16, 0, 10], state: "minecraft:deepslate_tiles"},
        {pos: [16, 0, 11], state: "minecraft:gray_wool"},
        {pos: [16, 0, 12], state: "minecraft:gray_wool"},
        {pos: [16, 0, 13], state: "minecraft:deepslate_tiles"},
        {pos: [17, 0, 7], state: "minecraft:deepslate_tiles"},
        {pos: [17, 0, 8], state: "minecraft:gray_wool"},
        {pos: [17, 0, 9], state: "minecraft:gray_wool"},
        {pos: [17, 0, 10], state: "minecraft:deepslate_tiles"},
        {pos: [17, 0, 11], state: "minecraft:gray_wool"},
        {pos: [17, 0, 12], state: "minecraft:gray_wool"},
        {pos: [17, 0, 13], state: "minecraft:deepslate_tiles"},
        {pos: [0, 1, 7], state: "minecraft:deepslate_bricks"},
        {pos: [0, 1, 8], state: "minecraft:gray_wool"},
        {pos: [0, 1, 9], state: "minecraft:gray_wool"},
        {pos: [0, 1, 10], state: "minecraft:deepslate_tiles"},
        {pos: [0, 1, 11], state: "minecraft:gray_wool"},
        {pos: [0, 1, 12], state: "minecraft:gray_wool"},
        {pos: [0, 1, 13], state: "minecraft:deepslate_bricks"},
        {pos: [1, 1, 7], state: "minecraft:deepslate_bricks"},
        {pos: [1, 1, 8], state: "minecraft:gray_wool"},
        {pos: [1, 1, 9], state: "minecraft:gray_wool"},
        {pos: [1, 1, 10], state: "minecraft:deepslate_tiles"},
        {pos: [1, 1, 11], state: "minecraft:gray_wool"},
        {pos: [1, 1, 12], state: "minecraft:gray_wool"},
        {pos: [1, 1, 13], state: "minecraft:deepslate_bricks"},
        {pos: [2, 1, 7], state: "minecraft:deepslate_bricks"},
        {pos: [2, 1, 8], state: "minecraft:gray_wool"},
        {pos: [2, 1, 9], state: "minecraft:gray_wool"},
        {pos: [2, 1, 10], state: "minecraft:deepslate_tiles"},
        {pos: [2, 1, 11], state: "minecraft:gray_wool"},
        {pos: [2, 1, 12], state: "minecraft:gray_wool"},
        {pos: [2, 1, 13], state: "minecraft:deepslate_bricks"},
        {pos: [3, 1, 7], state: "minecraft:deepslate_bricks"},
        {pos: [3, 1, 8], state: "minecraft:gray_wool"},
        {pos: [3, 1, 9], state: "minecraft:gray_wool"},
        {pos: [3, 1, 10], state: "minecraft:deepslate_tiles"},
        {pos: [3, 1, 11], state: "minecraft:gray_wool"},
        {pos: [3, 1, 12], state: "minecraft:gray_wool"},
        {pos: [3, 1, 13], state: "minecraft:deepslate_bricks"},
        {pos: [14, 1, 7], state: "minecraft:deepslate_bricks"},
        {pos: [14, 1, 8], state: "minecraft:gray_wool"},
        {pos: [14, 1, 9], state: "minecraft:gray_wool"},
        {pos: [14, 1, 10], state: "minecraft:deepslate_tiles"},
        {pos: [14, 1, 11], state: "minecraft:gray_wool"},
        {pos: [14, 1, 12], state: "minecraft:gray_wool"},
        {pos: [14, 1, 13], state: "minecraft:deepslate_bricks"},
        {pos: [15, 1, 7], state: "minecraft:deepslate_bricks"},
        {pos: [15, 1, 8], state: "minecraft:gray_wool"},
        {pos: [15, 1, 9], state: "minecraft:gray_wool"},
        {pos: [15, 1, 10], state: "minecraft:deepslate_tiles"},
        {pos: [15, 1, 11], state: "minecraft:gray_wool"},
        {pos: [15, 1, 12], state: "minecraft:gray_wool"},
        {pos: [15, 1, 13], state: "minecraft:deepslate_bricks"},
        {pos: [16, 1, 7], state: "minecraft:deepslate_bricks"},
        {pos: [16, 1, 8], state: "minecraft:gray_wool"},
        {pos: [16, 1, 9], state: "minecraft:gray_wool"},
        {pos: [16, 1, 10], state: "minecraft:deepslate_tiles"},
        {pos: [16, 1, 11], state: "minecraft:gray_wool"},
        {pos: [16, 1, 12], state: "minecraft:gray_wool"},
        {pos: [16, 1, 13], state: "minecraft:deepslate_bricks"},
        {pos: [17, 1, 7], state: "minecraft:deepslate_bricks"},
        {pos: [17, 1, 8], state: "minecraft:gray_wool"},
        {pos: [17, 1, 9], state: "minecraft:gray_wool"},
        {pos: [17, 1, 10], state: "minecraft:deepslate_bricks"},
        {pos: [17, 1, 11], state: "minecraft:gray_wool"},
        {pos: [17, 1, 12], state: "minecraft:gray_wool"},
        {pos: [17, 1, 13], state: "minecraft:deepslate_bricks"},
        {pos: [0, 2, 7], state: "minecraft:deepslate_bricks"},
        {pos: [0, 2, 10], state: "minecraft:deepslate_bricks"},
        {pos: [0, 2, 13], state: "minecraft:deepslate_bricks"},
        {pos: [1, 2, 10], state: "minecraft:deepslate_tiles"},
        {pos: [2, 2, 10], state: "minecraft:deepslate_tiles"},
        {pos: [3, 2, 7], state: "minecraft:deepslate_bricks"},
        {pos: [3, 2, 10], state: "minecraft:deepslate_tile_stairs{facing:west,half:bottom,shape:straight,waterlogged:false}"},
        {pos: [3, 2, 13], state: "minecraft:deepslate_bricks"},
        {pos: [14, 2, 7], state: "minecraft:deepslate_bricks"},
        {pos: [14, 2, 10], state: "minecraft:deepslate_tile_stairs{facing:east,half:bottom,shape:straight,waterlogged:false}"},
        {pos: [14, 2, 13], state: "minecraft:deepslate_bricks"},
        {pos: [15, 2, 10], state: "minecraft:deepslate_tiles"},
        {pos: [16, 2, 10], state: "minecraft:deepslate_tiles"},
        {pos: [17, 2, 7], state: "minecraft:deepslate_bricks"},
        {pos: [17, 2, 10], state: "minecraft:deepslate_bricks"},
        {pos: [17, 2, 13], state: "minecraft:deepslate_bricks"},
        {pos: [0, 3, 7], state: "minecraft:deepslate_bricks"},
        {pos: [0, 3, 10], state: "minecraft:deepslate_bricks"},
        {pos: [0, 3, 13], state: "minecraft:deepslate_bricks"},
        {pos: [1, 3, 10], state: "minecraft:deepslate_tiles"},
        {pos: [2, 3, 10], state: "minecraft:chiseled_deepslate"},
        {pos: [3, 3, 7], state: "minecraft:deepslate_bricks"},
        {pos: [3, 3, 13], state: "minecraft:deepslate_bricks"},
        {pos: [14, 3, 7], state: "minecraft:deepslate_bricks"},
        {pos: [14, 3, 13], state: "minecraft:deepslate_bricks"},
        {pos: [15, 3, 10], state: "minecraft:chiseled_deepslate"},
        {pos: [16, 3, 10], state: "minecraft:deepslate_tiles"},
        {pos: [17, 3, 7], state: "minecraft:deepslate_bricks"},
        {pos: [17, 3, 10], state: "minecraft:deepslate_bricks"},
        {pos: [17, 3, 13], state: "minecraft:deepslate_bricks"},
        {pos: [0, 4, 7], state: "minecraft:deepslate_bricks"},
        {pos: [0, 4, 10], state: "minecraft:deepslate_bricks"},
        {pos: [0, 4, 13], state: "minecraft:deepslate_bricks"},
        {pos: [1, 4, 10], state: "minecraft:deepslate_tiles"},
        {pos: [2, 4, 10], state: "minecraft:deepslate_tiles"},
        {pos: [3, 4, 7], state: "minecraft:deepslate_bricks"},
        {pos: [3, 4, 10], state: "minecraft:deepslate_tile_stairs{facing:west,half:top,shape:straight,waterlogged:false}"},
        {pos: [3, 4, 13], state: "minecraft:deepslate_bricks"},
        {pos: [14, 4, 7], state: "minecraft:deepslate_bricks"},
        {pos: [14, 4, 10], state: "minecraft:deepslate_tile_stairs{facing:east,half:top,shape:straight,waterlogged:false}"},
        {pos: [14, 4, 13], state: "minecraft:deepslate_bricks"},
        {pos: [15, 4, 10], state: "minecraft:deepslate_tiles"},
        {pos: [16, 4, 10], state: "minecraft:deepslate_tiles"},
        {pos: [17, 4, 7], state: "minecraft:deepslate_bricks"},
        {pos: [17, 4, 10], state: "minecraft:deepslate_bricks"},
        {pos: [17, 4, 13], state: "minecraft:deepslate_bricks"},
        {pos: [0, 5, 6], state: "minecraft:deepslate_bricks"},
        {pos: [0, 5, 7], state: "minecraft:deepslate_bricks"},
        {pos: [0, 5, 8], state: "minecraft:gray_wool"},
        {pos: [0, 5, 9], state: "minecraft:gray_wool"},
        {pos: [0, 5, 10], state: "minecraft:deepslate_bricks"},
        {pos: [0, 5, 11], state: "minecraft:gray_wool"},
        {pos: [0, 5, 12], state: "minecraft:gray_wool"},
        {pos: [0, 5, 13], state: "minecraft:deepslate_bricks"},
        {pos: [0, 5, 14], state: "minecraft:deepslate_bricks"},
        {pos: [1, 5, 6], state: "minecraft:deepslate_bricks"},
        {pos: [1, 5, 7], state: "minecraft:deepslate_bricks"},
        {pos: [1, 5, 8], state: "minecraft:gray_wool"},
        {pos: [1, 5, 9], state: "minecraft:gray_wool"},
        {pos: [1, 5, 10], state: "minecraft:deepslate_bricks"},
        {pos: [1, 5, 11], state: "minecraft:gray_wool"},
        {pos: [1, 5, 12], state: "minecraft:gray_wool"},
        {pos: [1, 5, 13], state: "minecraft:deepslate_bricks"},
        {pos: [1, 5, 14], state: "minecraft:deepslate_bricks"},
        {pos: [2, 5, 7], state: "minecraft:soul_lantern{hanging:true,waterlogged:false}"},
        {pos: [2, 5, 10], state: "minecraft:deepslate_bricks"},
        {pos: [2, 5, 13], state: "minecraft:soul_lantern{hanging:true,waterlogged:false}"},
        {pos: [3, 5, 7], state: "minecraft:deepslate_bricks"},
        {pos: [3, 5, 10], state: "minecraft:deepslate_bricks"},
        {pos: [3, 5, 13], state: "minecraft:deepslate_bricks"},
        {pos: [4, 5, 7], state: "minecraft:deepslate_brick_stairs{facing:west,half:top,shape:straight,waterlogged:false}"},
        {pos: [4, 5, 10], state: "minecraft:deepslate_brick_stairs{facing:west,half:top,shape:straight,waterlogged:false}"},
        {pos: [4, 5, 13], state: "minecraft:deepslate_brick_stairs{facing:west,half:top,shape:straight,waterlogged:false}"},
        {pos: [13, 5, 7], state: "minecraft:deepslate_brick_stairs{facing:east,half:top,shape:straight,waterlogged:false}"},
        {pos: [13, 5, 10], state: "minecraft:deepslate_brick_stairs{facing:east,half:top,shape:straight,waterlogged:false}"},
        {pos: [13, 5, 13], state: "minecraft:deepslate_brick_stairs{facing:east,half:top,shape:straight,waterlogged:false}"},
        {pos: [14, 5, 7], state: "minecraft:deepslate_bricks"},
        {pos: [14, 5, 10], state: "minecraft:deepslate_bricks"},
        {pos: [14, 5, 13], state: "minecraft:deepslate_bricks"},
        {pos: [15, 5, 7], state: "minecraft:soul_lantern{hanging:true,waterlogged:false}"},
        {pos: [15, 5, 10], state: "minecraft:deepslate_bricks"},
        {pos: [15, 5, 13], state: "minecraft:soul_lantern{hanging:true,waterlogged:false}"},
        {pos: [16, 5, 7], state: "minecraft:deepslate_bricks"},
        {pos: [16, 5, 8], state: "minecraft:gray_wool"},
        {pos: [16, 5, 9], state: "minecraft:gray_wool"},
        {pos: [16, 5, 10], state: "minecraft:deepslate_bricks"},
        {pos: [16, 5, 11], state: "minecraft:gray_wool"},
        {pos: [16, 5, 12], state: "minecraft:gray_wool"},
        {pos: [16, 5, 13], state: "minecraft:deepslate_bricks"},
        {pos: [16, 5, 14], state: "minecraft:deepslate_bricks"},
        {pos: [17, 5, 7], state: "minecraft:deepslate_bricks"},
        {pos: [17, 5, 8], state: "minecraft:gray_wool"},
        {pos: [17, 5, 9], state: "minecraft:gray_wool"},
        {pos: [17, 5, 10], state: "minecraft:deepslate_bricks"},
        {pos: [17, 5, 11], state: "minecraft:gray_wool"},
        {pos: [17, 5, 12], state: "minecraft:gray_wool"},
        {pos: [17, 5, 13], state: "minecraft:deepslate_bricks"},
        {pos: [17, 5, 14], state: "minecraft:deepslate_bricks"},
        {pos: [0, 6, 7], state: "minecraft:deepslate_bricks"},
        {pos: [0, 6, 10], state: "minecraft:deepslate_bricks"},
        {pos: [0, 6, 13], state: "minecraft:deepslate_bricks"},
        {pos: [1, 6, 6], state: "minecraft:deepslate_bricks"},
        {pos: [1, 6, 7], state: "minecraft:deepslate_bricks"},
        {pos: [1, 6, 8], state: "minecraft:deepslate_tile_stairs{facing:east,half:bottom,shape:straight,waterlogged:false}"},
        {pos: [1, 6, 9], state: "minecraft:deepslate_tile_stairs{facing:east,half:bottom,shape:straight,waterlogged:false}"},
        {pos: [1, 6, 10], state: "minecraft:deepslate_bricks"},
        {pos: [1, 6, 11], state: "minecraft:deepslate_tile_stairs{facing:east,half:bottom,shape:straight,waterlogged:false}"},
        {pos: [1, 6, 12], state: "minecraft:deepslate_tile_stairs{facing:east,half:bottom,shape:straight,waterlogged:false}"},
        {pos: [1, 6, 13], state: "minecraft:deepslate_bricks"},
        {pos: [1, 6, 14], state: "minecraft:deepslate_bricks"},
        {pos: [2, 6, 6], state: "minecraft:deepslate_bricks"},
        {pos: [2, 6, 7], state: "minecraft:deepslate_bricks"},
        {pos: [2, 6, 8], state: "minecraft:gray_wool"},
        {pos: [2, 6, 9], state: "minecraft:gray_wool"},
        {pos: [2, 6, 10], state: "minecraft:deepslate_bricks"},
        {pos: [2, 6, 11], state: "minecraft:gray_wool"},
        {pos: [2, 6, 12], state: "minecraft:gray_wool"},
        {pos: [2, 6, 13], state: "minecraft:deepslate_bricks"},
        {pos: [2, 6, 14], state: "minecraft:deepslate_bricks"},
        {pos: [3, 6, 6], state: "minecraft:deepslate_bricks"},
        {pos: [3, 6, 7], state: "minecraft:deepslate_bricks"},
        {pos: [3, 6, 8], state: "minecraft:gray_wool"},
        {pos: [3, 6, 9], state: "minecraft:gray_wool"},
        {pos: [3, 6, 10], state: "minecraft:deepslate_bricks"},
        {pos: [3, 6, 11], state: "minecraft:gray_wool"},
        {pos: [3, 6, 12], state: "minecraft:gray_wool"},
        {pos: [3, 6, 13], state: "minecraft:deepslate_bricks"},
        {pos: [3, 6, 14], state: "minecraft:deepslate_bricks"},
        {pos: [4, 6, 6], state: "minecraft:deepslate_bricks"},
        {pos: [4, 6, 7], state: "minecraft:deepslate_bricks"},
        {pos: [4, 6, 10], state: "minecraft:deepslate_bricks"},
        {pos: [4, 6, 13], state: "minecraft:deepslate_bricks"},
        {pos: [4, 6, 14], state: "minecraft:deepslate_bricks"},
        {pos: [5, 6, 7], state: "minecraft:deepslate_brick_stairs{facing:west,half:top,shape:straight,waterlogged:false}"},
        {pos: [5, 6, 10], state: "minecraft:deepslate_brick_stairs{facing:west,half:top,shape:straight,waterlogged:false}"},
        {pos: [5, 6, 13], state: "minecraft:deepslate_brick_stairs{facing:west,half:top,shape:straight,waterlogged:false}"},
        {pos: [12, 6, 7], state: "minecraft:deepslate_brick_stairs{facing:east,half:top,shape:straight,waterlogged:false}"},
        {pos: [12, 6, 10], state: "minecraft:deepslate_brick_stairs{facing:east,half:top,shape:straight,waterlogged:false}"},
        {pos: [12, 6, 13], state: "minecraft:deepslate_brick_stairs{facing:east,half:top,shape:straight,waterlogged:false}"},
        {pos: [13, 6, 6], state: "minecraft:deepslate_bricks"},
        {pos: [13, 6, 7], state: "minecraft:deepslate_bricks"},
        {pos: [13, 6, 10], state: "minecraft:deepslate_bricks"},
        {pos: [13, 6, 13], state: "minecraft:deepslate_bricks"},
        {pos: [13, 6, 14], state: "minecraft:deepslate_bricks"},
        {pos: [14, 6, 6], state: "minecraft:deepslate_bricks"},
        {pos: [14, 6, 7], state: "minecraft:deepslate_bricks"},
        {pos: [14, 6, 8], state: "minecraft:gray_wool"},
        {pos: [14, 6, 9], state: "minecraft:gray_wool"},
        {pos: [14, 6, 10], state: "minecraft:deepslate_bricks"},
        {pos: [14, 6, 11], state: "minecraft:gray_wool"},
        {pos: [14, 6, 12], state: "minecraft:gray_wool"},
        {pos: [14, 6, 13], state: "minecraft:deepslate_bricks"},
        {pos: [14, 6, 14], state: "minecraft:deepslate_bricks"},
        {pos: [15, 6, 6], state: "minecraft:deepslate_bricks"},
        {pos: [15, 6, 7], state: "minecraft:deepslate_bricks"},
        {pos: [15, 6, 8], state: "minecraft:gray_wool"},
        {pos: [15, 6, 9], state: "minecraft:gray_wool"},
        {pos: [15, 6, 10], state: "minecraft:deepslate_bricks"},
        {pos: [15, 6, 11], state: "minecraft:gray_wool"},
        {pos: [15, 6, 12], state: "minecraft:gray_wool"},
        {pos: [15, 6, 13], state: "minecraft:deepslate_bricks"},
        {pos: [15, 6, 14], state: "minecraft:deepslate_bricks"},
        {pos: [16, 6, 6], state: "minecraft:deepslate_bricks"},
        {pos: [16, 6, 7], state: "minecraft:deepslate_bricks"},
        {pos: [16, 6, 8], state: "minecraft:deepslate_tile_stairs{facing:west,half:bottom,shape:straight,waterlogged:false}"},
        {pos: [16, 6, 9], state: "minecraft:deepslate_tile_stairs{facing:west,half:bottom,shape:straight,waterlogged:false}"},
        {pos: [16, 6, 10], state: "minecraft:deepslate_bricks"},
        {pos: [16, 6, 11], state: "minecraft:deepslate_tile_stairs{facing:west,half:bottom,shape:straight,waterlogged:false}"},
        {pos: [16, 6, 12], state: "minecraft:deepslate_tile_stairs{facing:west,half:bottom,shape:straight,waterlogged:false}"},
        {pos: [16, 6, 13], state: "minecraft:deepslate_bricks"},
        {pos: [16, 6, 14], state: "minecraft:deepslate_bricks"},
        {pos: [17, 6, 6], state: "minecraft:deepslate_bricks"},
        {pos: [17, 6, 7], state: "minecraft:deepslate_bricks"},
        {pos: [17, 6, 10], state: "minecraft:deepslate_bricks"},
        {pos: [17, 6, 13], state: "minecraft:deepslate_bricks"},
        {pos: [0, 7, 7], state: "minecraft:deepslate_bricks"},
        {pos: [0, 7, 10], state: "minecraft:deepslate_bricks"},
        {pos: [0, 7, 13], state: "minecraft:deepslate_bricks"},
        {pos: [3, 7, 6], state: "minecraft:deepslate_bricks"},
        {pos: [3, 7, 7], state: "minecraft:deepslate_bricks"},
        {pos: [3, 7, 8], state: "minecraft:deepslate_tile_stairs{facing:east,half:bottom,shape:straight,waterlogged:false}"},
        {pos: [3, 7, 9], state: "minecraft:deepslate_tile_stairs{facing:east,half:bottom,shape:straight,waterlogged:false}"},
        {pos: [3, 7, 10], state: "minecraft:deepslate_bricks"},
        {pos: [3, 7, 11], state: "minecraft:deepslate_tile_stairs{facing:east,half:bottom,shape:straight,waterlogged:false}"},
        {pos: [3, 7, 12], state: "minecraft:deepslate_tile_stairs{facing:east,half:bottom,shape:straight,waterlogged:false}"},
        {pos: [3, 7, 13], state: "minecraft:deepslate_bricks"},
        {pos: [3, 7, 14], state: "minecraft:deepslate_bricks"},
        {pos: [4, 7, 6], state: "minecraft:deepslate_bricks"},
        {pos: [4, 7, 7], state: "minecraft:deepslate_bricks"},
        {pos: [4, 7, 8], state: "minecraft:gray_wool"},
        {pos: [4, 7, 9], state: "minecraft:gray_wool"},
        {pos: [4, 7, 10], state: "minecraft:deepslate_bricks"},
        {pos: [4, 7, 11], state: "minecraft:gray_wool"},
        {pos: [4, 7, 12], state: "minecraft:gray_wool"},
        {pos: [4, 7, 13], state: "minecraft:deepslate_bricks"},
        {pos: [4, 7, 14], state: "minecraft:deepslate_bricks"},
        {pos: [5, 7, 6], state: "minecraft:deepslate_bricks"},
        {pos: [5, 7, 7], state: "minecraft:deepslate_bricks"},
        {pos: [5, 7, 8], state: "minecraft:gray_wool"},
        {pos: [5, 7, 9], state: "minecraft:gray_wool"},
        {pos: [5, 7, 10], state: "minecraft:deepslate_bricks"},
        {pos: [5, 7, 11], state: "minecraft:gray_wool"},
        {pos: [5, 7, 12], state: "minecraft:gray_wool"},
        {pos: [5, 7, 13], state: "minecraft:deepslate_bricks"},
        {pos: [5, 7, 14], state: "minecraft:deepslate_bricks"},
        {pos: [6, 7, 7], state: "minecraft:deepslate_brick_stairs{facing:west,half:top,shape:straight,waterlogged:false}"},
        {pos: [6, 7, 10], state: "minecraft:deepslate_brick_stairs{facing:west,half:top,shape:straight,waterlogged:false}"},
        {pos: [6, 7, 13], state: "minecraft:deepslate_brick_stairs{facing:west,half:top,shape:straight,waterlogged:false}"},
        {pos: [11, 7, 7], state: "minecraft:deepslate_brick_stairs{facing:east,half:top,shape:straight,waterlogged:false}"},
        {pos: [11, 7, 10], state: "minecraft:deepslate_brick_stairs{facing:east,half:top,shape:straight,waterlogged:false}"},
        {pos: [11, 7, 13], state: "minecraft:deepslate_brick_stairs{facing:east,half:top,shape:straight,waterlogged:false}"},
        {pos: [12, 7, 6], state: "minecraft:deepslate_bricks"},
        {pos: [12, 7, 7], state: "minecraft:deepslate_bricks"},
        {pos: [12, 7, 8], state: "minecraft:gray_wool"},
        {pos: [12, 7, 9], state: "minecraft:gray_wool"},
        {pos: [12, 7, 10], state: "minecraft:deepslate_bricks"},
        {pos: [12, 7, 11], state: "minecraft:gray_wool"},
        {pos: [12, 7, 12], state: "minecraft:gray_wool"},
        {pos: [12, 7, 13], state: "minecraft:deepslate_bricks"},
        {pos: [12, 7, 14], state: "minecraft:deepslate_bricks"},
        {pos: [13, 7, 6], state: "minecraft:deepslate_bricks"},
        {pos: [13, 7, 7], state: "minecraft:deepslate_bricks"},
        {pos: [13, 7, 8], state: "minecraft:gray_wool"},
        {pos: [13, 7, 9], state: "minecraft:gray_wool"},
        {pos: [13, 7, 10], state: "minecraft:deepslate_bricks"},
        {pos: [13, 7, 11], state: "minecraft:gray_wool"},
        {pos: [13, 7, 12], state: "minecraft:gray_wool"},
        {pos: [13, 7, 13], state: "minecraft:deepslate_bricks"},
        {pos: [13, 7, 14], state: "minecraft:deepslate_bricks"},
        {pos: [14, 7, 7], state: "minecraft:deepslate_bricks"},
        {pos: [14, 7, 8], state: "minecraft:deepslate_tile_stairs{facing:west,half:bottom,shape:straight,waterlogged:false}"},
        {pos: [14, 7, 9], state: "minecraft:deepslate_tile_stairs{facing:west,half:bottom,shape:straight,waterlogged:false}"},
        {pos: [14, 7, 10], state: "minecraft:deepslate_bricks"},
        {pos: [14, 7, 11], state: "minecraft:deepslate_tile_stairs{facing:west,half:bottom,shape:straight,waterlogged:false}"},
        {pos: [14, 7, 12], state: "minecraft:deepslate_tile_stairs{facing:west,half:bottom,shape:straight,waterlogged:false}"},
        {pos: [14, 7, 13], state: "minecraft:deepslate_bricks"},
        {pos: [14, 7, 14], state: "minecraft:deepslate_bricks"},
        {pos: [17, 7, 7], state: "minecraft:deepslate_bricks"},
        {pos: [17, 7, 10], state: "minecraft:deepslate_bricks"},
        {pos: [17, 7, 13], state: "minecraft:deepslate_bricks"},
        {pos: [0, 8, 7], state: "minecraft:deepslate_bricks"},
        {pos: [0, 8, 10], state: "minecraft:deepslate_bricks"},
        {pos: [0, 8, 13], state: "minecraft:deepslate_bricks"},
        {pos: [1, 8, 7], state: "minecraft:deepslate_bricks"},
        {pos: [1, 8, 10], state: "minecraft:deepslate_bricks"},
        {pos: [1, 8, 13], state: "minecraft:deepslate_bricks"},
        {pos: [2, 8, 7], state: "minecraft:deepslate_bricks"},
        {pos: [2, 8, 10], state: "minecraft:deepslate_bricks"},
        {pos: [2, 8, 13], state: "minecraft:deepslate_bricks"},
        {pos: [3, 8, 7], state: "minecraft:deepslate_bricks"},
        {pos: [3, 8, 10], state: "minecraft:deepslate_bricks"},
        {pos: [3, 8, 13], state: "minecraft:deepslate_bricks"},
        {pos: [5, 8, 6], state: "minecraft:deepslate_bricks"},
        {pos: [5, 8, 7], state: "minecraft:deepslate_bricks"},
        {pos: [5, 8, 8], state: "minecraft:deepslate_tile_stairs{facing:east,half:bottom,shape:straight,waterlogged:false}"},
        {pos: [5, 8, 9], state: "minecraft:deepslate_tile_stairs{facing:east,half:bottom,shape:straight,waterlogged:false}"},
        {pos: [5, 8, 10], state: "minecraft:deepslate_bricks"},
        {pos: [5, 8, 11], state: "minecraft:deepslate_tile_stairs{facing:east,half:bottom,shape:straight,waterlogged:false}"},
        {pos: [5, 8, 12], state: "minecraft:deepslate_tile_stairs{facing:east,half:bottom,shape:straight,waterlogged:false}"},
        {pos: [5, 8, 13], state: "minecraft:deepslate_bricks"},
        {pos: [5, 8, 14], state: "minecraft:deepslate_bricks"},
        {pos: [6, 8, 6], state: "minecraft:deepslate_bricks"},
        {pos: [6, 8, 7], state: "minecraft:deepslate_bricks"},
        {pos: [6, 8, 8], state: "minecraft:gray_wool"},
        {pos: [6, 8, 9], state: "minecraft:gray_wool"},
        {pos: [6, 8, 10], state: "minecraft:deepslate_bricks"},
        {pos: [6, 8, 11], state: "minecraft:gray_wool"},
        {pos: [6, 8, 12], state: "minecraft:gray_wool"},
        {pos: [6, 8, 13], state: "minecraft:deepslate_bricks"},
        {pos: [6, 8, 14], state: "minecraft:deepslate_bricks"},
        {pos: [7, 8, 6], state: "minecraft:deepslate_bricks"},
        {pos: [7, 8, 7], state: "minecraft:deepslate_bricks"},
        {pos: [7, 8, 8], state: "minecraft:gray_wool"},
        {pos: [7, 8, 9], state: "minecraft:gray_wool"},
        {pos: [7, 8, 10], state: "minecraft:deepslate_bricks"},
        {pos: [7, 8, 11], state: "minecraft:gray_wool"},
        {pos: [7, 8, 12], state: "minecraft:gray_wool"},
        {pos: [7, 8, 13], state: "minecraft:deepslate_brick_stairs{facing:west,half:top,shape:straight,waterlogged:false}"},
        {pos: [7, 8, 14], state: "minecraft:deepslate_bricks"},
        {pos: [8, 8, 6], state: "minecraft:deepslate_bricks"},
        {pos: [8, 8, 7], state: "minecraft:deepslate_bricks"},
        {pos: [8, 8, 8], state: "minecraft:gray_wool"},
        {pos: [8, 8, 9], state: "minecraft:gray_wool"},
        {pos: [8, 8, 10], state: "minecraft:deepslate_bricks"},
        {pos: [8, 8, 11], state: "minecraft:gray_wool"},
        {pos: [8, 8, 12], state: "minecraft:gray_wool"},
        {pos: [8, 8, 14], state: "minecraft:deepslate_bricks"},
        {pos: [9, 8, 6], state: "minecraft:deepslate_bricks"},
        {pos: [9, 8, 7], state: "minecraft:deepslate_bricks"},
        {pos: [9, 8, 8], state: "minecraft:gray_wool"},
        {pos: [9, 8, 9], state: "minecraft:gray_wool"},
        {pos: [9, 8, 10], state: "minecraft:deepslate_bricks"},
        {pos: [9, 8, 11], state: "minecraft:gray_wool"},
        {pos: [9, 8, 12], state: "minecraft:gray_wool"},
        {pos: [9, 8, 14], state: "minecraft:deepslate_bricks"},
        {pos: [10, 8, 6], state: "minecraft:deepslate_bricks"},
        {pos: [10, 8, 7], state: "minecraft:deepslate_bricks"},
        {pos: [10, 8, 8], state: "minecraft:gray_wool"},
        {pos: [10, 8, 9], state: "minecraft:gray_wool"},
        {pos: [10, 8, 10], state: "minecraft:deepslate_bricks"},
        {pos: [10, 8, 11], state: "minecraft:gray_wool"},
        {pos: [10, 8, 12], state: "minecraft:gray_wool"},
        {pos: [10, 8, 13], state: "minecraft:deepslate_brick_stairs{facing:east,half:top,shape:straight,waterlogged:false}"},
        {pos: [10, 8, 14], state: "minecraft:deepslate_bricks"},
        {pos: [11, 8, 6], state: "minecraft:deepslate_bricks"},
        {pos: [11, 8, 7], state: "minecraft:deepslate_bricks"},
        {pos: [11, 8, 8], state: "minecraft:gray_wool"},
        {pos: [11, 8, 9], state: "minecraft:gray_wool"},
        {pos: [11, 8, 10], state: "minecraft:deepslate_bricks"},
        {pos: [11, 8, 11], state: "minecraft:gray_wool"},
        {pos: [11, 8, 12], state: "minecraft:gray_wool"},
        {pos: [11, 8, 13], state: "minecraft:deepslate_bricks"},
        {pos: [11, 8, 14], state: "minecraft:deepslate_bricks"},
        {pos: [12, 8, 6], state: "minecraft:deepslate_bricks"},
        {pos: [12, 8, 7], state: "minecraft:deepslate_bricks"},
        {pos: [12, 8, 8], state: "minecraft:deepslate_tile_stairs{facing:west,half:bottom,shape:straight,waterlogged:false}"},
        {pos: [12, 8, 9], state: "minecraft:deepslate_tile_stairs{facing:west,half:bottom,shape:straight,waterlogged:false}"},
        {pos: [12, 8, 10], state: "minecraft:deepslate_bricks"},
        {pos: [12, 8, 11], state: "minecraft:deepslate_tile_stairs{facing:west,half:bottom,shape:straight,waterlogged:false}"},
        {pos: [12, 8, 12], state: "minecraft:deepslate_tile_stairs{facing:west,half:bottom,shape:straight,waterlogged:false}"},
        {pos: [12, 8, 13], state: "minecraft:deepslate_bricks"},
        {pos: [12, 8, 14], state: "minecraft:deepslate_bricks"},
        {pos: [14, 8, 7], state: "minecraft:deepslate_bricks"},
        {pos: [14, 8, 10], state: "minecraft:deepslate_bricks"},
        {pos: [14, 8, 13], state: "minecraft:deepslate_bricks"},
        {pos: [15, 8, 7], state: "minecraft:deepslate_bricks"},
        {pos: [15, 8, 10], state: "minecraft:deepslate_bricks"},
        {pos: [15, 8, 13], state: "minecraft:deepslate_bricks"},
        {pos: [16, 8, 7], state: "minecraft:deepslate_bricks"},
        {pos: [16, 8, 10], state: "minecraft:deepslate_bricks"},
        {pos: [16, 8, 13], state: "minecraft:deepslate_bricks"},
        {pos: [17, 8, 7], state: "minecraft:deepslate_bricks"},
        {pos: [17, 8, 10], state: "minecraft:deepslate_bricks"},
        {pos: [17, 8, 13], state: "minecraft:deepslate_bricks"},
        {pos: [0, 9, 7], state: "minecraft:deepslate_bricks"},
        {pos: [0, 9, 10], state: "minecraft:deepslate_bricks"},
        {pos: [0, 9, 13], state: "minecraft:deepslate_bricks"},
        {pos: [3, 9, 7], state: "minecraft:deepslate_bricks"},
        {pos: [3, 9, 10], state: "minecraft:deepslate_bricks"},
        {pos: [3, 9, 13], state: "minecraft:deepslate_bricks"},
        {pos: [6, 9, 7], state: "minecraft:deepslate_bricks"},
        {pos: [6, 9, 10], state: "minecraft:deepslate_bricks"},
        {pos: [6, 9, 13], state: "minecraft:deepslate_bricks"},
        {pos: [7, 9, 7], state: "minecraft:deepslate_bricks"},
        {pos: [7, 9, 10], state: "minecraft:deepslate_bricks"},
        {pos: [7, 9, 13], state: "minecraft:deepslate_bricks"},
        {pos: [8, 9, 7], state: "minecraft:deepslate_bricks"},
        {pos: [8, 9, 10], state: "minecraft:deepslate_bricks"},
        {pos: [8, 9, 13], state: "minecraft:deepslate_bricks"},
        {pos: [9, 9, 7], state: "minecraft:deepslate_bricks"},
        {pos: [9, 9, 10], state: "minecraft:deepslate_bricks"},
        {pos: [9, 9, 13], state: "minecraft:deepslate_bricks"},
        {pos: [10, 9, 7], state: "minecraft:deepslate_bricks"},
        {pos: [10, 9, 10], state: "minecraft:deepslate_bricks"},
        {pos: [10, 9, 13], state: "minecraft:deepslate_bricks"},
        {pos: [11, 9, 7], state: "minecraft:deepslate_bricks"},
        {pos: [11, 9, 10], state: "minecraft:deepslate_bricks"},
        {pos: [11, 9, 13], state: "minecraft:deepslate_bricks"},
        {pos: [14, 9, 7], state: "minecraft:deepslate_bricks"},
        {pos: [14, 9, 10], state: "minecraft:deepslate_bricks"},
        {pos: [14, 9, 13], state: "minecraft:deepslate_bricks"},
        {pos: [17, 9, 7], state: "minecraft:deepslate_bricks"},
        {pos: [17, 9, 10], state: "minecraft:deepslate_bricks"},
        {pos: [17, 9, 13], state: "minecraft:deepslate_bricks"},
        {pos: [4, 10, 7], state: "minecraft:soul_lantern{hanging:true,waterlogged:false}"},
        {pos: [4, 10, 10], state: "minecraft:soul_lantern{hanging:true,waterlogged:false}"},
        {pos: [4, 10, 13], state: "minecraft:soul_lantern{hanging:true,waterlogged:false}"},
        {pos: [5, 10, 7], state: "minecraft:deepslate_bricks"},
        {pos: [5, 10, 10], state: "minecraft:deepslate_bricks"},
        {pos: [5, 10, 13], state: "minecraft:deepslate_bricks"},
        {pos: [6, 10, 7], state: "minecraft:deepslate_bricks"},
        {pos: [6, 10, 10], state: "minecraft:deepslate_bricks"},
        {pos: [6, 10, 13], state: "minecraft:deepslate_bricks"},
        {pos: [11, 10, 7], state: "minecraft:deepslate_bricks"},
        {pos: [11, 10, 10], state: "minecraft:deepslate_bricks"},
        {pos: [11, 10, 13], state: "minecraft:deepslate_bricks"},
        {pos: [12, 10, 7], state: "minecraft:deepslate_bricks"},
        {pos: [12, 10, 10], state: "minecraft:deepslate_bricks"},
        {pos: [12, 10, 13], state: "minecraft:deepslate_bricks"},
        {pos: [13, 10, 7], state: "minecraft:soul_lantern{hanging:true,waterlogged:false}"},
        {pos: [13, 10, 10], state: "minecraft:soul_lantern{hanging:true,waterlogged:false}"},
        {pos: [13, 10, 13], state: "minecraft:soul_lantern{hanging:true,waterlogged:false}"},
        {pos: [4, 11, 7], state: "minecraft:deepslate_bricks"},
        {pos: [4, 11, 10], state: "minecraft:deepslate_bricks"},
        {pos: [4, 11, 13], state: "minecraft:deepslate_bricks"},
        {pos: [5, 11, 7], state: "minecraft:deepslate_bricks"},
        {pos: [5, 11, 10], state: "minecraft:deepslate_bricks"},
        {pos: [5, 11, 13], state: "minecraft:deepslate_bricks"},
        {pos: [12, 11, 7], state: "minecraft:deepslate_bricks"},
        {pos: [12, 11, 10], state: "minecraft:deepslate_bricks"},
        {pos: [12, 11, 13], state: "minecraft:deepslate_bricks"},
        {pos: [13, 11, 7], state: "minecraft:deepslate_bricks"},
        {pos: [13, 11, 10], state: "minecraft:deepslate_bricks"},
        {pos: [13, 11, 13], state: "minecraft:deepslate_bricks"},
        {pos: [4, 12, 7], state: "minecraft:deepslate_bricks"},
        {pos: [4, 12, 10], state: "minecraft:deepslate_bricks"},
        {pos: [4, 12, 13], state: "minecraft:deepslate_bricks"},
        {pos: [5, 12, 7], state: "minecraft:deepslate_bricks"},
        {pos: [5, 12, 10], state: "minecraft:deepslate_bricks"},
        {pos: [5, 12, 13], state: "minecraft:deepslate_bricks"},
        {pos: [12, 12, 7], state: "minecraft:deepslate_bricks"},
        {pos: [12, 12, 10], state: "minecraft:deepslate_bricks"},
        {pos: [12, 12, 13], state: "minecraft:deepslate_bricks"},
        {pos: [13, 12, 7], state: "minecraft:deepslate_bricks"},
        {pos: [13, 12, 10], state: "minecraft:deepslate_bricks"},
        {pos: [13, 12, 13], state: "minecraft:deepslate_bricks"},
        {pos: [5, 13, 7], state: "minecraft:deepslate_bricks"},
        {pos: [5, 13, 8], state: "minecraft:deepslate_bricks"},
        {pos: [5, 13, 9], state: "minecraft:deepslate_bricks"},
        {pos: [5, 13, 10], state: "minecraft:deepslate_bricks"},
        {pos: [5, 13, 11], state: "minecraft:deepslate_bricks"},
        {pos: [5, 13, 12], state: "minecraft:deepslate_bricks"},
        {pos: [5, 13, 13], state: "minecraft:deepslate_bricks"},
        {pos: [6, 13, 7], state: "minecraft:deepslate_bricks"},
        {pos: [6, 13, 10], state: "minecraft:deepslate_bricks"},
        {pos: [6, 13, 13], state: "minecraft:deepslate_bricks"},
        {pos: [11, 13, 7], state: "minecraft:deepslate_bricks"},
        {pos: [11, 13, 10], state: "minecraft:deepslate_bricks"},
        {pos: [11, 13, 13], state: "minecraft:deepslate_bricks"},
        {pos: [12, 13, 7], state: "minecraft:deepslate_bricks"},
        {pos: [12, 13, 8], state: "minecraft:deepslate_bricks"},
        {pos: [12, 13, 9], state: "minecraft:deepslate_bricks"},
        {pos: [12, 13, 10], state: "minecraft:deepslate_bricks"},
        {pos: [12, 13, 11], state: "minecraft:deepslate_bricks"},
        {pos: [12, 13, 12], state: "minecraft:deepslate_bricks"},
        {pos: [12, 13, 13], state: "minecraft:deepslate_bricks"},
        {pos: [6, 14, 7], state: "minecraft:deepslate_bricks"},
        {pos: [6, 14, 10], state: "minecraft:deepslate_bricks"},
        {pos: [6, 14, 13], state: "minecraft:deepslate_bricks"},
        {pos: [7, 14, 7], state: "minecraft:deepslate_bricks"},
        {pos: [7, 14, 10], state: "minecraft:deepslate_bricks"},
        {pos: [7, 14, 13], state: "minecraft:deepslate_bricks"},
        {pos: [8, 14, 7], state: "minecraft:deepslate_bricks"},
        {pos: [8, 14, 10], state: "minecraft:deepslate_bricks"},
        {pos: [8, 14, 13], state: "minecraft:deepslate_bricks"},
        {pos: [9, 14, 7], state: "minecraft:deepslate_bricks"},
        {pos: [9, 14, 10], state: "minecraft:deepslate_bricks"},
        {pos: [9, 14, 13], state: "minecraft:deepslate_bricks"},
        {pos: [10, 14, 7], state: "minecraft:deepslate_bricks"},
        {pos: [10, 14, 10], state: "minecraft:deepslate_bricks"},
        {pos: [10, 14, 13], state: "minecraft:deepslate_bricks"},
        {pos: [11, 14, 7], state: "minecraft:deepslate_bricks"},
        {pos: [11, 14, 10], state: "minecraft:deepslate_bricks"},
        {pos: [11, 14, 13], state: "minecraft:deepslate_bricks"}
    ],
    entities: [],
    palette: [
        "minecraft:deepslate_tiles",
        "minecraft:gray_wool",
        "minecraft:deepslate_bricks",
        "minecraft:chiseled_deepslate",
        "minecraft:deepslate_tile_slab{type:bottom,waterlogged:false}",
        "minecraft:deepslate_tile_stairs{facing:west,half:bottom,shape:straight,waterlogged:false}",
        "minecraft:deepslate_tile_stairs{facing:east,half:bottom,shape:straight,waterlogged:false}",
        "minecraft:deepslate_tile_stairs{facing:west,half:top,shape:straight,waterlogged:false}",
        "minecraft:deepslate_tile_stairs{facing:east,half:top,shape:straight,waterlogged:false}",
        "minecraft:soul_lantern{hanging:true,waterlogged:false}",
        "minecraft:deepslate_brick_stairs{facing:west,half:top,shape:straight,waterlogged:false}",
        "minecraft:deepslate_brick_stairs{facing:east,half:top,shape:straight,waterlogged:false}",
        "minecraft:jigsaw{orientation:west_up}",
        "minecraft:jigsaw{orientation:north_up}",
        "minecraft:jigsaw{orientation:south_up}"
    ]
}
